#######################################################################
# +-----------------------------------------------------------------+ #
# |                            BO3 object                           | #
# +-----------------------------------------------------------------+ #
#######################################################################

# This is the config file of a custom object.
# If you add this object correctly to your BiomeConfigs, it will spawn in the world.

# This is the creator of this BO3 object
Author: BO3 BulkEdit (by LanToaster)

# A short description of this BO3 object
Description: This Object was Created with BO3_BulkEdit

# The BO3 version, don't change this! It can be used by external applications to do a version check.
Version: 3

# The settings mode, WriteAll, WriteWithoutComments or WriteDisable. See WorldConfig.
SettingsMode: WriteDisable


#######################################################################
# +-----------------------------------------------------------------+ #
# |                          Main settings                          | #
# +-----------------------------------------------------------------+ #
#######################################################################

# This needs to be set to true to spawn the object in the Tree and Sapling resources.
Tree: true

# The frequency of the BO3 from 1 to 200. Tries this many times to spawn this BO3 when using the CustomObject(...) resource.
# Ignored by Tree(..), Sapling(..) and CustomStructure(..)
Frequency: 1

# The rarity of the BO3 from 0 to 100. Each spawn attempt has rarity% chance to succeed when using the CustomObject(...) resource.
# Ignored by Tree(..), Sapling(..) and CustomStructure(..)
Rarity: 100.0

# If you set this to true, the BO3 will be placed with a random rotation.
RotateRandomly: true

# The spawn height of the BO3 - randomY, highestBlock or highestSolidBlock.
SpawnHeight: highestSolidBlock
SpawnHeightOffset: -1
# The height limits for the BO3.
MinHeight: 0

MaxHeight: 65

# Objects can have other objects attacthed to it: branches. Branches can also
# have branches attached to it, which can also have branches, etc. This is the
# maximum branch depth for this objects.
MaxBranchDepth: 10

# When spawned with the UseWorld keyword, this BO3 should NOT spawn in the following biomes.
# If you writer.write the BO3 name directly in the BiomeConfigs, this will be ignored.
ExcludedBiomes: All


#######################################################################
# +-----------------------------------------------------------------+ #
# |                      Source block settings                      | #
# +-----------------------------------------------------------------+ #
#######################################################################

# The block(s) the BO3 should spawn in.
SourceBlocks: AIR,GRASS,DIRT,DIRT:1,STONE,DIRT:2,SAND,GRAVEL

# The maximum percentage of the BO3 that can be outside the SourceBlock.
# The BO3 won't be placed on a location with more blocks outside the SourceBlock than this percentage.
MaxPercentageOutsideSourceBlock: 0

# What to do when a block is about to be placed outside the SourceBlock? (dontPlace, placeAnyway)
OutsideSourceBlock: dontPlace


#######################################################################
# +-----------------------------------------------------------------+ #
# |                              Blocks                             | #
# +-----------------------------------------------------------------+ #
#######################################################################

# All the blocks used in the BO3 are listed here. Possible blocks:
# Block(x,y,z,id[.data][,nbtfile.nbt)
# RandomBlock(x,y,z,id[:data][,nbtfile.nbt],chance[,id[:data][,nbtfile.nbt],chance[,...]])
# So RandomBlock(0,0,0,CHEST,chest.nbt,50,CHEST,anotherchest.nbt,100) will spawn a chest at
# the BO3 origin, and give it a 50% chance to have the contents of chest.nbt, or, if that
# fails, a 100% percent chance to have the contents of anotherchest.nbt.
Block(0,0,-14,STONE:0)
Block(2,0,-14,STONE:0)
Block(3,0,-14,STONE:0)
Block(4,0,-14,STONE:0)
Block(-2,0,-13,STONE:0)
Block(-1,0,-13,STONE:0)
Block(0,0,-13,STONE:0)
Block(1,0,-13,STONE:0)
Block(2,0,-13,STONE:0)
Block(3,0,-13,STONE:0)
Block(4,0,-13,STONE:0)
Block(5,0,-13,STONE:0)
Block(-3,0,-12,STONE:0)
Block(-2,0,-12,STONE:0)
Block(-1,0,-12,STONE:0)
Block(0,0,-12,STONE:0)
Block(1,0,-12,STONE:0)
Block(2,0,-12,STONE:0)
Block(3,0,-12,STONE:0)
Block(4,0,-12,STONE:0)
Block(5,0,-12,STONE:0)
Block(6,0,-12,STONE:0)
Block(-5,0,-11,STONE:0)
Block(-4,0,-11,STONE:0)
Block(-3,0,-11,STONE:0)
Block(-2,0,-11,STONE:0)
Block(-1,0,-11,STONE:0)
Block(0,0,-11,STONE:0)
Block(1,0,-11,STONE:0)
Block(2,0,-11,STONE:0)
Block(3,0,-11,STONE:0)
Block(4,0,-11,STONE:0)
Block(5,0,-11,STONE:0)
Block(6,0,-11,STONE:0)
Block(7,0,-11,STONE:0)
Block(-7,0,-10,STONE:0)
Block(-6,0,-10,STONE:0)
Block(-5,0,-10,STONE:0)
Block(-4,0,-10,STONE:0)
Block(-3,0,-10,STONE:0)
Block(-2,0,-10,STONE:0)
Block(-1,0,-10,STONE:0)
Block(0,0,-10,STONE:0)
Block(1,0,-10,STONE:0)
Block(2,0,-10,STONE:0)
Block(3,0,-10,STONE:0)
Block(4,0,-10,STONE:0)
Block(5,0,-10,STONE:0)
Block(6,0,-10,STONE:0)
Block(7,0,-10,STONE:0)
Block(8,0,-10,STONE:0)
Block(-8,0,-9,STONE:0)
Block(-7,0,-9,STONE:0)
Block(-6,0,-9,STONE:0)
Block(-5,0,-9,STONE:0)
Block(-4,0,-9,STONE:0)
Block(-3,0,-9,STONE:0)
Block(-2,0,-9,STONE:0)
Block(-1,0,-9,STONE:0)
Block(0,0,-9,STONE:0)
Block(1,0,-9,STONE:0)
Block(2,0,-9,STONE:0)
Block(3,0,-9,STONE:0)
Block(4,0,-9,STONE:0)
Block(5,0,-9,STONE:0)
Block(6,0,-9,STONE:0)
Block(7,0,-9,STONE:0)
Block(8,0,-9,STONE:0)
Block(-8,0,-8,STONE:0)
Block(-7,0,-8,STONE:0)
Block(-6,0,-8,STONE:0)
Block(-5,0,-8,STONE:0)
Block(-4,0,-8,STONE:0)
Block(-3,0,-8,STONE:0)
Block(-2,0,-8,STONE:0)
Block(-1,0,-8,STONE:0)
Block(0,0,-8,STONE:0)
Block(1,0,-8,STONE:0)
Block(2,0,-8,STONE:0)
Block(3,0,-8,STONE:0)
Block(4,0,-8,STONE:0)
Block(5,0,-8,STONE:0)
Block(6,0,-8,STONE:0)
Block(7,0,-8,STONE:0)
Block(-6,0,-7,STONE:0)
Block(-5,0,-7,STONE:0)
Block(-4,0,-7,STONE:0)
Block(-3,0,-7,STONE:0)
Block(0,0,-7,STONE:0)
Block(1,0,-7,STONE:0)
Block(2,0,-7,STONE:0)
Block(3,0,-7,STONE:0)
Block(4,0,-7,STONE:0)
Block(5,0,-7,STONE:0)
Block(-6,0,-6,STONE:0)
Block(-5,0,-6,STONE:0)
Block(-4,0,-6,STONE:0)
Block(-3,0,-6,STONE:0)
Block(-1,0,-6,STONE:0)
Block(0,0,-6,STONE:0)
Block(1,0,-6,STONE:0)
Block(2,0,-6,STONE:0)
Block(3,0,-6,STONE:0)
Block(4,0,-6,STONE:0)
Block(-6,0,-5,STONE:0)
Block(-5,0,-5,STONE:0)
Block(-1,0,-5,STONE:0)
Block(0,0,-5,STONE:0)
Block(1,0,-5,STONE:0)
Block(2,0,-5,STONE:0)
Block(3,0,-5,STONE:0)
Block(4,0,-5,STONE:0)
Block(-6,0,-4,STONE:0)
Block(3,0,-4,STONE:0)
Block(-6,0,4,STONE:0)
Block(-10,0,5,STONE:0)
Block(-9,0,5,STONE:0)
Block(-8,0,5,STONE:0)
Block(-7,0,5,STONE:0)
Block(-6,0,5,STONE:0)
Block(-5,0,5,STONE:0)
Block(-4,0,5,STONE:0)
Block(-3,0,5,STONE:0)
Block(-10,0,6,STONE:0)
Block(-9,0,6,STONE:0)
Block(-8,0,6,STONE:0)
Block(-7,0,6,STONE:0)
Block(-6,0,6,STONE:0)
Block(-5,0,6,STONE:0)
Block(-4,0,6,STONE:0)
Block(-3,0,6,STONE:0)
Block(-2,0,6,STONE:0)
Block(2,0,6,STONE:0)
Block(-9,0,7,STONE:0)
Block(-8,0,7,STONE:0)
Block(-7,0,7,STONE:0)
Block(-6,0,7,STONE:0)
Block(-5,0,7,STONE:0)
Block(-4,0,7,STONE:0)
Block(-3,0,7,STONE:0)
Block(-2,0,7,STONE:0)
Block(-1,0,7,STONE:0)
Block(1,0,7,STONE:0)
Block(2,0,7,STONE:0)
Block(3,0,7,STONE:0)
Block(-7,0,8,STONE:0)
Block(-6,0,8,STONE:0)
Block(-4,0,8,STONE:0)
Block(-3,0,8,STONE:0)
Block(-2,0,8,STONE:0)
Block(0,0,8,STONE:0)
Block(1,0,8,STONE:0)
Block(2,0,8,STONE:0)
Block(3,0,8,STONE:0)
Block(4,0,8,STONE:0)
Block(-7,0,9,STONE:0)
Block(-6,0,9,STONE:0)
Block(-5,0,9,STONE:0)
Block(-4,0,9,STONE:0)
Block(-3,0,9,STONE:0)
Block(-1,0,9,STONE:0)
Block(0,0,9,STONE:0)
Block(1,0,9,STONE:0)
Block(2,0,9,STONE:0)
Block(3,0,9,STONE:0)
Block(-8,0,10,STONE:0)
Block(-7,0,10,STONE:0)
Block(-6,0,10,STONE:0)
Block(-5,0,10,STONE:0)
Block(-4,0,10,STONE:0)
Block(-3,0,10,STONE:0)
Block(-2,0,10,STONE:0)
Block(-1,0,10,STONE:0)
Block(0,0,10,STONE:0)
Block(1,0,10,STONE:0)
Block(2,0,10,STONE:0)
Block(-6,0,11,STONE:0)
Block(-5,0,11,STONE:0)
Block(-4,0,11,STONE:0)
Block(-3,0,11,STONE:0)
Block(-2,0,11,STONE:0)
Block(-1,0,11,STONE:0)
Block(0,0,11,STONE:0)
Block(1,0,11,STONE:0)
Block(2,0,11,STONE:0)
Block(-5,0,12,STONE:0)
Block(-4,0,12,STONE:0)
Block(-3,0,12,STONE:0)
Block(-2,0,12,STONE:0)
Block(-1,0,12,STONE:0)
Block(0,0,12,STONE:0)
Block(1,0,12,STONE:0)
Block(2,0,12,STONE:0)
Block(3,0,12,STONE:0)
Block(-5,0,13,STONE:0)
Block(-2,0,13,STONE:0)
Block(-1,0,13,STONE:0)
Block(0,0,13,STONE:0)
Block(1,0,13,STONE:0)
Block(2,0,13,STONE:0)
Block(-1,0,14,STONE:0)
Block(0,0,14,STONE:0)
Block(-1,1,-13,STONE:0)
Block(0,1,-13,STONE:0)
Block(1,1,-13,STONE:0)
Block(2,1,-13,STONE:0)
Block(3,1,-13,STONE:0)
Block(4,1,-13,STONE:0)
Block(-3,1,-12,STONE:0)
Block(-2,1,-12,STONE:0)
Block(-1,1,-12,STONE:0)
Block(0,1,-12,STONE:0)
Block(1,1,-12,STONE:0)
Block(2,1,-12,STONE:0)
Block(3,1,-12,STONE:0)
Block(4,1,-12,STONE:0)
Block(5,1,-12,STONE:0)
Block(6,1,-12,STONE:0)
Block(-3,1,-11,STONE:0)
Block(-2,1,-11,STONE:0)
Block(-1,1,-11,STONE:0)
Block(0,1,-11,STONE:0)
Block(1,1,-11,STONE:0)
Block(2,1,-11,STONE:0)
Block(3,1,-11,STONE:0)
Block(4,1,-11,STONE:0)
Block(5,1,-11,STONE:0)
Block(6,1,-11,STONE:0)
Block(7,1,-11,STONE:0)
Block(-6,1,-10,STONE:0)
Block(-5,1,-10,STONE:0)
Block(-4,1,-10,STONE:0)
Block(-3,1,-10,STONE:0)
Block(-2,1,-10,STONE:0)
Block(-1,1,-10,STONE:0)
Block(0,1,-10,STONE:0)
Block(1,1,-10,STONE:0)
Block(2,1,-10,STONE:0)
Block(3,1,-10,STONE:0)
Block(4,1,-10,STONE:0)
Block(5,1,-10,STONE:0)
Block(6,1,-10,STONE:0)
Block(7,1,-10,STONE:0)
Block(8,1,-10,STONE:0)
Block(-6,1,-9,STONE:0)
Block(-5,1,-9,STONE:0)
Block(-4,1,-9,STONE:0)
Block(-3,1,-9,STONE:0)
Block(-2,1,-9,STONE:0)
Block(-1,1,-9,STONE:0)
Block(0,1,-9,STONE:0)
Block(1,1,-9,STONE:0)
Block(2,1,-9,STONE:0)
Block(3,1,-9,STONE:0)
Block(4,1,-9,STONE:0)
Block(5,1,-9,STONE:0)
Block(6,1,-9,STONE:0)
Block(7,1,-9,STONE:0)
Block(-5,1,-8,STONE:0)
Block(-4,1,-8,STONE:0)
Block(-3,1,-8,STONE:0)
Block(-2,1,-8,STONE:0)
Block(-1,1,-8,STONE:0)
Block(0,1,-8,STONE:0)
Block(1,1,-8,STONE:0)
Block(2,1,-8,STONE:0)
Block(3,1,-8,STONE:0)
Block(4,1,-8,STONE:0)
Block(5,1,-8,STONE:0)
Block(6,1,-8,STONE:0)
Block(7,1,-8,STONE:0)
Block(-5,1,-7,STONE:0)
Block(-4,1,-7,STONE:0)
Block(-3,1,-7,STONE:0)
Block(-2,1,-7,STONE:0)
Block(-1,1,-7,STONE:0)
Block(0,1,-7,STONE:0)
Block(1,1,-7,STONE:0)
Block(2,1,-7,STONE:0)
Block(3,1,-7,STONE:0)
Block(4,1,-7,STONE:0)
Block(5,1,-7,STONE:0)
Block(-2,1,-6,STONE:0)
Block(-1,1,-6,STONE:0)
Block(0,1,-6,STONE:0)
Block(1,1,-6,STONE:0)
Block(2,1,-6,STONE:0)
Block(3,1,-6,STONE:0)
Block(4,1,-6,STONE:0)
Block(1,1,-5,STONE:0)
Block(2,1,-5,STONE:0)
Block(3,1,-5,STONE:0)
Block(-7,1,5,STONE:0)
Block(-6,1,5,STONE:0)
Block(-5,1,5,STONE:0)
Block(-4,1,5,STONE:0)
Block(-3,1,5,STONE:0)
Block(-9,1,6,STONE:0)
Block(-8,1,6,STONE:0)
Block(-7,1,6,STONE:0)
Block(-6,1,6,STONE:0)
Block(-5,1,6,STONE:0)
Block(-4,1,6,STONE:0)
Block(-3,1,6,STONE:0)
Block(-2,1,6,STONE:0)
Block(-8,1,7,STONE:0)
Block(-7,1,7,STONE:0)
Block(-6,1,7,STONE:0)
Block(-5,1,7,STONE:0)
Block(-4,1,7,STONE:0)
Block(-3,1,7,STONE:0)
Block(-2,1,7,STONE:0)
Block(-1,1,7,STONE:0)
Block(1,1,7,STONE:0)
Block(2,1,7,STONE:0)
Block(3,1,7,STONE:0)
Block(-6,1,8,STONE:0)
Block(-5,1,8,STONE:0)
Block(-4,1,8,STONE:0)
Block(-3,1,8,STONE:0)
Block(-2,1,8,STONE:0)
Block(0,1,8,STONE:0)
Block(1,1,8,STONE:0)
Block(2,1,8,STONE:0)
Block(3,1,8,STONE:0)
Block(4,1,8,STONE:0)
Block(-6,1,9,STONE:0)
Block(-5,1,9,STONE:0)
Block(-4,1,9,STONE:0)
Block(-3,1,9,STONE:0)
Block(-2,1,9,STONE:0)
Block(-1,1,9,STONE:0)
Block(0,1,9,STONE:0)
Block(1,1,9,STONE:0)
Block(2,1,9,STONE:0)
Block(3,1,9,STONE:0)
Block(4,1,9,STONE:0)
Block(5,1,9,STONE:0)
Block(-6,1,10,STONE:0)
Block(-5,1,10,STONE:0)
Block(-4,1,10,STONE:0)
Block(-3,1,10,STONE:0)
Block(-2,1,10,STONE:0)
Block(-1,1,10,STONE:0)
Block(0,1,10,STONE:0)
Block(1,1,10,STONE:0)
Block(2,1,10,STONE:0)
Block(3,1,10,STONE:0)
Block(4,1,10,STONE:0)
Block(-5,1,11,STONE:0)
Block(-4,1,11,STONE:0)
Block(-3,1,11,STONE:0)
Block(-2,1,11,STONE:0)
Block(-1,1,11,STONE:0)
Block(0,1,11,STONE:0)
Block(1,1,11,STONE:0)
Block(2,1,11,STONE:0)
Block(3,1,11,STONE:0)
Block(-5,1,12,STONE:0)
Block(-4,1,12,STONE:0)
Block(-3,1,12,STONE:0)
Block(-2,1,12,STONE:0)
Block(-1,1,12,STONE:0)
Block(0,1,12,STONE:0)
Block(1,1,12,STONE:0)
Block(2,1,12,STONE:0)
Block(3,1,12,STONE:0)
Block(-2,1,13,STONE:0)
Block(-1,1,13,STONE:0)
Block(0,1,13,STONE:0)
Block(2,2,-13,STONE:0)
Block(3,2,-13,STONE:0)
Block(-1,2,-12,STONE:0)
Block(0,2,-12,STONE:0)
Block(1,2,-12,STONE:0)
Block(2,2,-12,STONE:0)
Block(3,2,-12,STONE:0)
Block(4,2,-12,STONE:0)
Block(5,2,-12,STONE:0)
Block(-2,2,-11,STONE:0)
Block(-1,2,-11,STONE:0)
Block(0,2,-11,STONE:0)
Block(1,2,-11,STONE:0)
Block(2,2,-11,STONE:0)
Block(3,2,-11,STONE:0)
Block(4,2,-11,STONE:0)
Block(5,2,-11,STONE:0)
Block(6,2,-11,STONE:0)
Block(-2,2,-10,STONE:0)
Block(-1,2,-10,STONE:0)
Block(0,2,-10,STONE:0)
Block(1,2,-10,STONE:0)
Block(2,2,-10,STONE:0)
Block(3,2,-10,STONE:0)
Block(4,2,-10,STONE:0)
Block(5,2,-10,STONE:0)
Block(6,2,-10,STONE:0)
Block(7,2,-10,STONE:0)
Block(-2,2,-9,STONE:0)
Block(-1,2,-9,STONE:0)
Block(1,2,-9,STONE:0)
Block(2,2,-9,STONE:0)
Block(3,2,-9,STONE:0)
Block(4,2,-9,STONE:0)
Block(5,2,-9,STONE:0)
Block(6,2,-9,STONE:0)
Block(7,2,-9,STONE:0)
Block(-2,2,-8,STONE:0)
Block(-1,2,-8,STONE:0)
Block(0,2,-8,STONE:0)
Block(1,2,-8,STONE:0)
Block(2,2,-8,STONE:0)
Block(3,2,-8,STONE:0)
Block(4,2,-8,STONE:0)
Block(5,2,-8,STONE:0)
Block(6,2,-8,STONE:0)
Block(-1,2,-7,STONE:0)
Block(0,2,-7,STONE:0)
Block(1,2,-7,STONE:0)
Block(2,2,-7,STONE:0)
Block(3,2,-7,STONE:0)
Block(4,2,-7,STONE:0)
Block(5,2,-7,STONE:0)
Block(0,2,-6,STONE:0)
Block(1,2,-6,STONE:0)
Block(2,2,-6,STONE:0)
Block(3,2,-6,STONE:0)
Block(4,2,-6,STONE:0)
Block(2,2,-5,STONE:0)
Block(-6,2,5,STONE:0)
Block(-5,2,5,STONE:0)
Block(-4,2,5,STONE:0)
Block(-7,2,6,STONE:0)
Block(-6,2,6,STONE:0)
Block(-5,2,6,STONE:0)
Block(-4,2,6,STONE:0)
Block(-3,2,6,STONE:0)
Block(-2,2,6,STONE:0)
Block(-8,2,7,STONE:0)
Block(-7,2,7,STONE:0)
Block(-6,2,7,STONE:0)
Block(-5,2,7,STONE:0)
Block(-4,2,7,STONE:0)
Block(-3,2,7,STONE:0)
Block(-1,2,7,STONE:0)
Block(1,2,7,STONE:0)
Block(2,2,7,STONE:0)
Block(-6,2,8,STONE:0)
Block(-4,2,8,STONE:0)
Block(-3,2,8,STONE:0)
Block(-2,2,8,STONE:0)
Block(-1,2,8,STONE:0)
Block(0,2,8,STONE:0)
Block(1,2,8,STONE:0)
Block(2,2,8,STONE:0)
Block(3,2,8,STONE:0)
Block(-5,2,9,STONE:0)
Block(-4,2,9,STONE:0)
Block(-3,2,9,STONE:0)
Block(-2,2,9,STONE:0)
Block(-1,2,9,STONE:0)
Block(0,2,9,STONE:0)
Block(1,2,9,STONE:0)
Block(2,2,9,STONE:0)
Block(3,2,9,STONE:0)
Block(4,2,9,STONE:0)
Block(-5,2,10,STONE:0)
Block(-4,2,10,STONE:0)
Block(-3,2,10,STONE:0)
Block(-2,2,10,STONE:0)
Block(-1,2,10,STONE:0)
Block(0,2,10,STONE:0)
Block(1,2,10,STONE:0)
Block(2,2,10,STONE:0)
Block(3,2,10,STONE:0)
Block(4,2,10,STONE:0)
Block(-5,2,11,STONE:0)
Block(-4,2,11,STONE:0)
Block(-3,2,11,STONE:0)
Block(-2,2,11,STONE:0)
Block(-1,2,11,STONE:0)
Block(0,2,11,STONE:0)
Block(1,2,11,STONE:0)
Block(3,2,11,STONE:0)
Block(-4,2,12,STONE:0)
Block(-3,2,12,STONE:0)
Block(-2,2,12,STONE:0)
Block(-1,2,12,STONE:0)
Block(0,2,12,STONE:0)
Block(1,3,-12,STONE:0)
Block(2,3,-12,STONE:0)
Block(3,3,-12,STONE:0)
Block(4,3,-12,STONE:0)
Block(5,3,-12,STONE:0)
Block(0,3,-11,STONE:0)
Block(1,3,-11,STONE:0)
Block(2,3,-11,STONE:0)
Block(3,3,-11,STONE:0)
Block(4,3,-11,STONE:0)
Block(5,3,-11,STONE:0)
Block(-1,3,-10,STONE:0)
Block(0,3,-10,STONE:0)
Block(1,3,-10,STONE:0)
Block(2,3,-10,STONE:0)
Block(3,3,-10,STONE:0)
Block(4,3,-10,STONE:0)
Block(5,3,-10,STONE:0)
Block(-1,3,-9,STONE:0)
Block(0,3,-9,STONE:0)
Block(1,3,-9,STONE:0)
Block(2,3,-9,STONE:0)
Block(3,3,-9,STONE:0)
Block(4,3,-9,STONE:0)
Block(5,3,-9,STONE:0)
Block(6,3,-9,STONE:0)
Block(-1,3,-8,STONE:0)
Block(0,3,-8,STONE:0)
Block(1,3,-8,STONE:0)
Block(2,3,-8,STONE:0)
Block(3,3,-8,STONE:0)
Block(4,3,-8,STONE:0)
Block(5,3,-8,STONE:0)
Block(-1,3,-7,STONE:0)
Block(0,3,-7,STONE:0)
Block(1,3,-7,STONE:0)
Block(2,3,-7,STONE:0)
Block(3,3,-7,STONE:0)
Block(4,3,-7,STONE:0)
Block(0,3,-6,STONE:0)
Block(1,3,-6,STONE:0)
Block(-5,3,5,STONE:0)
Block(-6,3,6,STONE:0)
Block(-5,3,6,STONE:0)
Block(-4,3,6,STONE:0)
Block(-3,3,6,STONE:0)
Block(-6,3,7,STONE:0)
Block(-5,3,7,STONE:0)
Block(-4,3,7,STONE:0)
Block(-3,3,7,STONE:0)
Block(-2,3,7,STONE:0)
Block(-1,3,7,STONE:0)
Block(0,3,7,STONE:0)
Block(-6,3,8,STONE:0)
Block(-5,3,8,STONE:0)
Block(-4,3,8,STONE:0)
Block(-3,3,8,STONE:0)
Block(-2,3,8,STONE:0)
Block(-1,3,8,STONE:0)
Block(0,3,8,STONE:0)
Block(1,3,8,STONE:0)
Block(2,3,8,STONE:0)
Block(-5,3,9,STONE:0)
Block(-4,3,9,STONE:0)
Block(-3,3,9,STONE:0)
Block(-2,3,9,STONE:0)
Block(-1,3,9,STONE:0)
Block(0,3,9,STONE:0)
Block(1,3,9,STONE:0)
Block(2,3,9,STONE:0)
Block(3,3,9,STONE:0)
Block(-4,3,10,STONE:0)
Block(-3,3,10,STONE:0)
Block(-2,3,10,STONE:0)
Block(-1,3,10,STONE:0)
Block(0,3,10,STONE:0)
Block(1,3,10,STONE:0)
Block(2,3,10,STONE:0)
Block(3,3,10,STONE:0)
Block(-4,3,11,STONE:0)
Block(-3,3,11,STONE:0)
Block(-2,3,11,STONE:0)
Block(-1,3,11,STONE:0)
Block(1,3,11,STONE:0)
Block(-3,3,12,STONE:0)
Block(-2,3,12,STONE:0)
Block(-1,3,12,STONE:0)
Block(1,4,-11,STONE:0)
Block(2,4,-11,STONE:0)
Block(3,4,-11,STONE:0)
Block(4,4,-11,STONE:0)
Block(0,4,-10,STONE:0)
Block(1,4,-10,STONE:0)
Block(2,4,-10,STONE:0)
Block(3,4,-10,STONE:0)
Block(4,4,-10,STONE:0)
Block(5,4,-10,STONE:0)
Block(-1,4,-9,STONE:0)
Block(0,4,-9,STONE:0)
Block(1,4,-9,STONE:0)
Block(2,4,-9,STONE:0)
Block(3,4,-9,STONE:0)
Block(4,4,-9,STONE:0)
Block(5,4,-9,STONE:0)
Block(-1,4,-8,STONE:0)
Block(0,4,-8,STONE:0)
Block(1,4,-8,STONE:0)
Block(2,4,-8,STONE:0)
Block(3,4,-8,STONE:0)
Block(4,4,-8,STONE:0)
Block(-1,4,-7,STONE:0)
Block(0,4,-7,STONE:0)
Block(1,4,-7,STONE:0)
Block(2,4,-7,STONE:0)
Block(3,4,-7,STONE:0)
Block(-1,4,-6,STONE:0)
Block(0,4,-6,STONE:0)
Block(1,4,-6,STONE:0)
Block(2,4,-6,STONE:0)
Block(0,4,-5,STONE:0)
Block(-5,4,6,STONE:0)
Block(-4,4,6,STONE:0)
Block(-3,4,6,STONE:0)
Block(-6,4,7,STONE:0)
Block(-5,4,7,STONE:0)
Block(-4,4,7,STONE:0)
Block(-3,4,7,STONE:0)
Block(-2,4,7,STONE:0)
Block(-1,4,7,STONE:0)
Block(0,4,7,STONE:0)
Block(1,4,7,STONE:0)
Block(-5,4,8,STONE:0)
Block(-4,4,8,STONE:0)
Block(-3,4,8,STONE:0)
Block(-2,4,8,STONE:0)
Block(-1,4,8,STONE:0)
Block(0,4,8,STONE:0)
Block(1,4,8,STONE:0)
Block(2,4,8,STONE:0)
Block(-4,4,9,STONE:0)
Block(-3,4,9,STONE:0)
Block(-2,4,9,STONE:0)
Block(-1,4,9,STONE:0)
Block(0,4,9,STONE:0)
Block(1,4,9,STONE:0)
Block(2,4,9,STONE:0)
Block(-4,4,10,STONE:0)
Block(-3,4,10,STONE:0)
Block(-2,4,10,STONE:0)
Block(-1,4,10,STONE:0)
Block(0,4,10,STONE:0)
Block(1,4,10,STONE:0)
Block(2,4,10,STONE:0)
Block(-3,4,11,STONE:0)
Block(-2,4,11,STONE:0)
Block(-1,4,11,STONE:0)
Block(0,4,11,STONE:0)
Block(-2,4,12,STONE:0)
Block(2,5,-10,STONE:0)
Block(3,5,-10,STONE:0)
Block(4,5,-10,STONE:0)
Block(-1,5,-9,STONE:0)
Block(0,5,-9,STONE:0)
Block(1,5,-9,STONE:0)
Block(2,5,-9,STONE:0)
Block(3,5,-9,STONE:0)
Block(4,5,-9,STONE:0)
Block(-1,5,-8,STONE:0)
Block(0,5,-8,STONE:0)
Block(1,5,-8,STONE:0)
Block(2,5,-8,STONE:0)
Block(3,5,-8,STONE:0)
Block(4,5,-8,STONE:0)
Block(-2,5,-7,STONE:0)
Block(-1,5,-7,STONE:0)
Block(0,5,-7,STONE:0)
Block(1,5,-7,STONE:0)
Block(2,5,-7,STONE:0)
Block(3,5,-7,STONE:0)
Block(-2,5,-6,STONE:0)
Block(-1,5,-6,STONE:0)
Block(0,5,-6,STONE:0)
Block(1,5,-6,STONE:0)
Block(2,5,-6,STONE:0)
Block(0,5,-5,STONE:0)
Block(-5,5,6,STONE:0)
Block(-4,5,6,STONE:0)
Block(-3,5,6,STONE:0)
Block(-5,5,7,STONE:0)
Block(-4,5,7,STONE:0)
Block(-3,5,7,STONE:0)
Block(-2,5,7,STONE:0)
Block(-1,5,7,STONE:0)
Block(0,5,7,STONE:0)
Block(-5,5,8,STONE:0)
Block(-4,5,8,STONE:0)
Block(-3,5,8,STONE:0)
Block(-2,5,8,STONE:0)
Block(-1,5,8,STONE:0)
Block(0,5,8,STONE:0)
Block(1,5,8,STONE:0)
Block(-4,5,9,STONE:0)
Block(-3,5,9,STONE:0)
Block(-2,5,9,STONE:0)
Block(-1,5,9,STONE:0)
Block(0,5,9,STONE:0)
Block(1,5,9,STONE:0)
Block(-3,5,10,STONE:0)
Block(-2,5,10,STONE:0)
Block(-1,5,10,STONE:0)
Block(0,5,10,STONE:0)
Block(1,5,10,STONE:0)
Block(-3,5,11,STONE:0)
Block(-2,5,11,STONE:0)
Block(-1,5,11,STONE:0)
Block(0,5,11,STONE:0)
Block(0,6,-9,STONE:0)
Block(1,6,-9,STONE:0)
Block(2,6,-9,STONE:0)
Block(3,6,-9,STONE:0)
Block(4,6,-9,STONE:0)
Block(-1,6,-8,STONE:0)
Block(0,6,-8,STONE:0)
Block(1,6,-8,STONE:0)
Block(2,6,-8,STONE:0)
Block(3,6,-8,STONE:0)
Block(4,6,-8,STONE:0)
Block(-2,6,-7,STONE:0)
Block(-1,6,-7,STONE:0)
Block(0,6,-7,STONE:0)
Block(1,6,-7,STONE:0)
Block(2,6,-7,STONE:0)
Block(3,6,-7,STONE:0)
Block(-3,6,-6,STONE:0)
Block(-2,6,-6,STONE:0)
Block(-1,6,-6,STONE:0)
Block(0,6,-6,STONE:0)
Block(1,6,-6,STONE:0)
Block(2,6,-6,STONE:0)
Block(-4,6,6,STONE:0)
Block(-3,6,6,STONE:0)
Block(-2,6,6,STONE:0)
Block(-5,6,7,STONE:0)
Block(-4,6,7,STONE:0)
Block(-3,6,7,STONE:0)
Block(-2,6,7,STONE:0)
Block(-1,6,7,STONE:0)
Block(-4,6,8,STONE:0)
Block(-3,6,8,STONE:0)
Block(-2,6,8,STONE:0)
Block(-1,6,8,STONE:0)
Block(0,6,8,STONE:0)
Block(1,6,8,STONE:0)
Block(-3,6,9,STONE:0)
Block(-2,6,9,STONE:0)
Block(-1,6,9,STONE:0)
Block(0,6,9,STONE:0)
Block(-3,6,10,STONE:0)
Block(-2,6,10,STONE:0)
Block(-1,6,10,STONE:0)
Block(0,6,10,STONE:0)
Block(2,7,-9,STONE:0)
Block(-1,7,-8,STONE:0)
Block(0,7,-8,STONE:0)
Block(1,7,-8,STONE:0)
Block(2,7,-8,STONE:0)
Block(3,7,-8,STONE:0)
Block(-2,7,-7,STONE:0)
Block(-1,7,-7,STONE:0)
Block(0,7,-7,STONE:0)
Block(1,7,-7,STONE:0)
Block(2,7,-7,STONE:0)
Block(3,7,-7,STONE:0)
Block(-3,7,-6,STONE:0)
Block(-2,7,-6,STONE:0)
Block(-1,7,-6,STONE:0)
Block(1,7,-6,STONE:0)
Block(2,7,-6,STONE:0)
Block(-3,7,-5,STONE:0)
Block(-2,7,-5,STONE:0)
Block(-4,7,6,STONE:0)
Block(-3,7,6,STONE:0)
Block(-2,7,6,STONE:0)
Block(-5,7,7,STONE:0)
Block(-4,7,7,STONE:0)
Block(-3,7,7,STONE:0)
Block(-2,7,7,STONE:0)
Block(-1,7,7,STONE:0)
Block(-4,7,8,STONE:0)
Block(-3,7,8,STONE:0)
Block(-2,7,8,STONE:0)
Block(-1,7,8,STONE:0)
Block(0,7,8,STONE:0)
Block(-3,7,9,STONE:0)
Block(-2,7,9,STONE:0)
Block(-1,7,9,STONE:0)
Block(0,7,9,STONE:0)
Block(-2,7,10,STONE:0)
Block(-1,7,10,STONE:0)
Block(-1,8,-8,STONE:0)
Block(1,8,-8,STONE:0)
Block(2,8,-8,STONE:0)
Block(3,8,-8,STONE:0)
Block(-2,8,-7,STONE:0)
Block(-1,8,-7,STONE:0)
Block(0,8,-7,STONE:0)
Block(1,8,-7,STONE:0)
Block(2,8,-7,STONE:0)
Block(3,8,-7,STONE:0)
Block(-3,8,-6,STONE:0)
Block(-2,8,-6,STONE:0)
Block(-1,8,-6,STONE:0)
Block(0,8,-6,STONE:0)
Block(1,8,-6,STONE:0)
Block(2,8,-6,STONE:0)
Block(-3,8,-5,STONE:0)
Block(-2,8,-5,STONE:0)
Block(-1,8,-5,STONE:0)
Block(0,8,-5,STONE:0)
Block(-4,8,6,STONE:0)
Block(-3,8,6,STONE:0)
Block(-2,8,6,STONE:0)
Block(-5,8,7,STONE:0)
Block(-4,8,7,STONE:0)
Block(-3,8,7,STONE:0)
Block(-2,8,7,STONE:0)
Block(-1,8,7,STONE:0)
Block(-4,8,8,STONE:0)
Block(-3,8,8,STONE:0)
Block(-2,8,8,STONE:0)
Block(-1,8,8,STONE:0)
Block(0,8,8,STONE:0)
Block(-2,8,9,STONE:0)
Block(-1,8,9,STONE:0)
Block(-2,9,-7,STONE:0)
Block(-1,9,-7,STONE:0)
Block(0,9,-7,STONE:0)
Block(1,9,-7,STONE:0)
Block(2,9,-7,STONE:0)
Block(3,9,-7,STONE:0)
Block(-4,9,-6,STONE:0)
Block(-3,9,-6,STONE:0)
Block(-2,9,-6,STONE:0)
Block(-1,9,-6,STONE:0)
Block(0,9,-6,STONE:0)
Block(1,9,-6,STONE:0)
Block(2,9,-6,STONE:0)
Block(-4,9,-5,STONE:0)
Block(-3,9,-5,STONE:0)
Block(-2,9,-5,STONE:0)
Block(-1,9,-5,STONE:0)
Block(0,9,-5,STONE:0)
Block(1,9,-5,STONE:0)
Block(-2,9,-4,STONE:0)
Block(-1,9,-4,STONE:0)
Block(-5,9,6,STONE:0)
Block(-4,9,6,STONE:0)
Block(-3,9,6,STONE:0)
Block(-2,9,6,STONE:0)
Block(-5,9,7,STONE:0)
Block(-4,9,7,STONE:0)
Block(-3,9,7,STONE:0)
Block(-2,9,7,STONE:0)
Block(-1,9,7,STONE:0)
Block(-4,9,8,STONE:0)
Block(-3,9,8,STONE:0)
Block(-2,9,8,STONE:0)
Block(-1,9,8,STONE:0)
Block(0,9,8,STONE:0)
Block(-1,9,9,STONE:0)
Block(1,10,-7,STONE:0)
Block(2,10,-7,STONE:0)
Block(-3,10,-6,STONE:0)
Block(-2,10,-6,STONE:0)
Block(-1,10,-6,STONE:0)
Block(0,10,-6,STONE:0)
Block(1,10,-6,STONE:0)
Block(2,10,-6,STONE:0)
Block(-3,10,-5,STONE:0)
Block(-2,10,-5,STONE:0)
Block(-1,10,-5,STONE:0)
Block(0,10,-5,STONE:0)
Block(1,10,-5,STONE:0)
Block(2,10,-5,STONE:0)
Block(-3,10,-4,STONE:0)
Block(-2,10,-4,STONE:0)
Block(-1,10,-4,STONE:0)
Block(0,10,-4,STONE:0)
Block(1,10,-4,STONE:0)
Block(-3,10,-3,STONE:0)
Block(-2,10,-3,STONE:0)
Block(-4,10,5,STONE:0)
Block(-3,10,5,STONE:0)
Block(-2,10,5,STONE:0)
Block(-5,10,6,STONE:0)
Block(-4,10,6,STONE:0)
Block(-3,10,6,STONE:0)
Block(-2,10,6,STONE:0)
Block(-1,10,6,STONE:0)
Block(-5,10,7,STONE:0)
Block(-4,10,7,STONE:0)
Block(-3,10,7,STONE:0)
Block(-2,10,7,STONE:0)
Block(-1,10,7,STONE:0)
Block(-4,10,8,STONE:0)
Block(-3,10,8,STONE:0)
Block(-2,10,8,STONE:0)
Block(-1,10,8,STONE:0)
Block(-2,11,-6,STONE:0)
Block(-1,11,-6,STONE:0)
Block(0,11,-6,STONE:0)
Block(1,11,-6,STONE:0)
Block(-3,11,-5,STONE:0)
Block(-2,11,-5,STONE:0)
Block(-1,11,-5,STONE:0)
Block(0,11,-5,STONE:0)
Block(1,11,-5,STONE:0)
Block(2,11,-5,STONE:0)
Block(-3,11,-4,STONE:0)
Block(-2,11,-4,STONE:0)
Block(-1,11,-4,STONE:0)
Block(0,11,-4,STONE:0)
Block(1,11,-4,STONE:0)
Block(2,11,-4,STONE:0)
Block(-3,11,-3,STONE:0)
Block(-2,11,-3,STONE:0)
Block(-1,11,-3,STONE:0)
Block(0,11,-3,STONE:0)
Block(1,11,-3,STONE:0)
Block(-3,11,-2,STONE:0)
Block(-2,11,-2,STONE:0)
Block(-5,11,4,STONE:0)
Block(-5,11,5,STONE:0)
Block(-4,11,5,STONE:0)
Block(-3,11,5,STONE:0)
Block(-2,11,5,STONE:0)
Block(-1,11,5,STONE:0)
Block(-5,11,6,STONE:0)
Block(-4,11,6,STONE:0)
Block(-3,11,6,STONE:0)
Block(-2,11,6,STONE:0)
Block(-1,11,6,STONE:0)
Block(-5,11,7,STONE:0)
Block(-4,11,7,STONE:0)
Block(-3,11,7,STONE:0)
Block(-2,11,7,STONE:0)
Block(-1,11,7,STONE:0)
Block(-4,11,8,STONE:0)
Block(-3,11,8,STONE:0)
Block(-2,11,8,STONE:0)
Block(-3,12,-5,STONE:0)
Block(-2,12,-5,STONE:0)
Block(-1,12,-5,STONE:0)
Block(0,12,-5,STONE:0)
Block(1,12,-5,STONE:0)
Block(2,12,-5,STONE:0)
Block(-4,12,-4,STONE:0)
Block(-3,12,-4,STONE:0)
Block(-2,12,-4,STONE:0)
Block(-1,12,-4,STONE:0)
Block(0,12,-4,STONE:0)
Block(1,12,-4,STONE:0)
Block(2,12,-4,STONE:0)
Block(-4,12,-3,STONE:0)
Block(-3,12,-3,STONE:0)
Block(-2,12,-3,STONE:0)
Block(-1,12,-3,STONE:0)
Block(0,12,-3,STONE:0)
Block(1,12,-3,STONE:0)
Block(2,12,-3,STONE:0)
Block(-4,12,-2,STONE:0)
Block(-3,12,-2,STONE:0)
Block(-2,12,-2,STONE:0)
Block(0,12,-2,STONE:0)
Block(1,12,-2,STONE:0)
Block(-3,12,-1,STONE:0)
Block(-2,12,-1,STONE:0)
Block(1,12,-1,STONE:0)
Block(-5,12,3,STONE:0)
Block(-4,12,3,STONE:0)
Block(-5,12,4,STONE:0)
Block(-4,12,4,STONE:0)
Block(-3,12,4,STONE:0)
Block(-2,12,4,STONE:0)
Block(-6,12,5,STONE:0)
Block(-5,12,5,STONE:0)
Block(-4,12,5,STONE:0)
Block(-3,12,5,STONE:0)
Block(-2,12,5,STONE:0)
Block(-1,12,5,STONE:0)
Block(-5,12,6,STONE:0)
Block(-4,12,6,STONE:0)
Block(-3,12,6,STONE:0)
Block(-2,12,6,STONE:0)
Block(-1,12,6,STONE:0)
Block(-4,12,7,STONE:0)
Block(-3,12,7,STONE:0)
Block(-2,12,7,STONE:0)
Block(-1,12,7,STONE:0)
Block(-3,12,8,STONE:0)
Block(-2,12,8,STONE:0)
Block(-2,13,-5,STONE:0)
Block(-1,13,-5,STONE:0)
Block(0,13,-5,STONE:0)
Block(1,13,-5,STONE:0)
Block(-3,13,-4,STONE:0)
Block(-2,13,-4,STONE:0)
Block(-1,13,-4,STONE:0)
Block(0,13,-4,STONE:0)
Block(1,13,-4,STONE:0)
Block(2,13,-4,STONE:0)
Block(-4,13,-3,STONE:0)
Block(-3,13,-3,STONE:0)
Block(-2,13,-3,STONE:0)
Block(-1,13,-3,STONE:0)
Block(0,13,-3,STONE:0)
Block(1,13,-3,STONE:0)
Block(2,13,-3,STONE:0)
Block(-4,13,-2,STONE:0)
Block(-3,13,-2,STONE:0)
Block(-2,13,-2,STONE:0)
Block(-1,13,-2,STONE:0)
Block(0,13,-2,STONE:0)
Block(1,13,-2,STONE:0)
Block(2,13,-2,STONE:0)
Block(-4,13,-1,STONE:0)
Block(-3,13,-1,STONE:0)
Block(-2,13,-1,STONE:0)
Block(-1,13,-1,STONE:0)
Block(0,13,-1,STONE:0)
Block(-4,13,0,STONE:0)
Block(-3,13,0,STONE:0)
Block(-2,13,0,STONE:0)
Block(-1,13,0,STONE:0)
Block(0,13,0,STONE:0)
Block(-4,13,1,STONE:0)
Block(-3,13,1,STONE:0)
Block(-5,13,2,STONE:0)
Block(-4,13,2,STONE:0)
Block(-3,13,2,STONE:0)
Block(-6,13,3,STONE:0)
Block(-5,13,3,STONE:0)
Block(-4,13,3,STONE:0)
Block(-3,13,3,STONE:0)
Block(-2,13,3,STONE:0)
Block(-6,13,4,STONE:0)
Block(-5,13,4,STONE:0)
Block(-4,13,4,STONE:0)
Block(-3,13,4,STONE:0)
Block(-2,13,4,STONE:0)
Block(-1,13,4,STONE:0)
Block(-6,13,5,STONE:0)
Block(-5,13,5,STONE:0)
Block(-4,13,5,STONE:0)
Block(-3,13,5,STONE:0)
Block(-2,13,5,STONE:0)
Block(-1,13,5,STONE:0)
Block(-5,13,6,STONE:0)
Block(-4,13,6,STONE:0)
Block(-3,13,6,STONE:0)
Block(-2,13,6,STONE:0)
Block(-1,13,6,STONE:0)
Block(-4,13,7,STONE:0)
Block(-3,13,7,STONE:0)
Block(-2,13,7,STONE:0)
Block(-1,13,7,STONE:0)
Block(-3,13,8,STONE:0)
Block(-2,14,-4,STONE:0)
Block(-1,14,-4,STONE:0)
Block(0,14,-4,STONE:0)
Block(1,14,-4,STONE:0)
Block(-3,14,-3,STONE:0)
Block(-2,14,-3,STONE:0)
Block(-1,14,-3,STONE:0)
Block(0,14,-3,STONE:0)
Block(1,14,-3,STONE:0)
Block(2,14,-3,STONE:0)
Block(-4,14,-2,STONE:0)
Block(-3,14,-2,STONE:0)
Block(-2,14,-2,STONE:0)
Block(-1,14,-2,STONE:0)
Block(0,14,-2,STONE:0)
Block(1,14,-2,STONE:0)
Block(-4,14,-1,STONE:0)
Block(-3,14,-1,STONE:0)
Block(-2,14,-1,STONE:0)
Block(-1,14,-1,STONE:0)
Block(0,14,-1,STONE:0)
Block(1,14,-1,STONE:0)
Block(-5,14,0,STONE:0)
Block(-4,14,0,STONE:0)
Block(-3,14,0,STONE:0)
Block(-2,14,0,STONE:0)
Block(-1,14,0,STONE:0)
Block(0,14,0,STONE:0)
Block(-6,14,1,STONE:0)
Block(-5,14,1,STONE:0)
Block(-4,14,1,STONE:0)
Block(-3,14,1,STONE:0)
Block(-2,14,1,STONE:0)
Block(-1,14,1,STONE:0)
Block(0,14,1,STONE:0)
Block(-6,14,2,STONE:0)
Block(-5,14,2,STONE:0)
Block(-4,14,2,STONE:0)
Block(-3,14,2,STONE:0)
Block(-2,14,2,STONE:0)
Block(-6,14,3,STONE:0)
Block(-5,14,3,STONE:0)
Block(-4,14,3,STONE:0)
Block(-3,14,3,STONE:0)
Block(-2,14,3,STONE:0)
Block(-6,14,4,STONE:0)
Block(-5,14,4,STONE:0)
Block(-4,14,4,STONE:0)
Block(-3,14,4,STONE:0)
Block(-2,14,4,STONE:0)
Block(-1,14,4,STONE:0)
Block(-5,14,5,STONE:0)
Block(-4,14,5,STONE:0)
Block(-3,14,5,STONE:0)
Block(-2,14,5,STONE:0)
Block(-1,14,5,STONE:0)
Block(-4,14,6,STONE:0)
Block(-3,14,6,STONE:0)
Block(-2,14,6,STONE:0)
Block(-1,14,6,STONE:0)
Block(-3,14,7,STONE:0)
Block(-2,14,7,STONE:0)
Block(-2,15,-3,STONE:0)
Block(-1,15,-3,STONE:0)
Block(0,15,-3,STONE:0)
Block(-4,15,-2,STONE:0)
Block(-3,15,-2,STONE:0)
Block(-2,15,-2,STONE:0)
Block(-1,15,-2,STONE:0)
Block(0,15,-2,STONE:0)
Block(-5,15,-1,STONE:0)
Block(-4,15,-1,STONE:0)
Block(-3,15,-1,STONE:0)
Block(-2,15,-1,STONE:0)
Block(-1,15,-1,STONE:0)
Block(0,15,-1,STONE:0)
Block(1,15,-1,STONE:0)
Block(-5,15,0,STONE:0)
Block(-4,15,0,STONE:0)
Block(-3,15,0,STONE:0)
Block(-2,15,0,STONE:0)
Block(-1,15,0,STONE:0)
Block(0,15,0,STONE:0)
Block(-5,15,1,STONE:0)
Block(-4,15,1,STONE:0)
Block(-3,15,1,STONE:0)
Block(-2,15,1,STONE:0)
Block(-1,15,1,STONE:0)
Block(0,15,1,STONE:0)
Block(-5,15,2,STONE:0)
Block(-4,15,2,STONE:0)
Block(-3,15,2,STONE:0)
Block(-2,15,2,STONE:0)
Block(-1,15,2,STONE:0)
Block(-5,15,3,STONE:0)
Block(-4,15,3,STONE:0)
Block(-3,15,3,STONE:0)
Block(-2,15,3,STONE:0)
Block(-5,15,4,STONE:0)
Block(-4,15,4,STONE:0)
Block(-3,15,4,STONE:0)
Block(-2,15,4,STONE:0)
Block(-1,15,4,STONE:0)
Block(-5,15,5,STONE:0)
Block(-4,15,5,STONE:0)
Block(-3,15,5,STONE:0)
Block(-2,15,5,STONE:0)
Block(-1,15,5,STONE:0)
Block(0,15,5,STONE:0)
Block(-4,15,6,STONE:0)
Block(-3,15,6,STONE:0)
Block(-2,15,6,STONE:0)
Block(-1,15,6,STONE:0)
Block(-2,15,7,STONE:0)
Block(-3,16,-2,STONE:0)
Block(-2,16,-2,STONE:0)
Block(-1,16,-2,STONE:0)
Block(-4,16,-1,STONE:0)
Block(-3,16,-1,STONE:0)
Block(-2,16,-1,STONE:0)
Block(-1,16,-1,STONE:0)
Block(0,16,-1,STONE:0)
Block(-4,16,0,STONE:0)
Block(-3,16,0,STONE:0)
Block(-2,16,0,STONE:0)
Block(-1,16,0,STONE:0)
Block(0,16,0,STONE:0)
Block(-5,16,1,STONE:0)
Block(-4,16,1,STONE:0)
Block(-3,16,1,STONE:0)
Block(-2,16,1,STONE:0)
Block(-1,16,1,STONE:0)
Block(0,16,1,STONE:0)
Block(-5,16,2,STONE:0)
Block(-4,16,2,STONE:0)
Block(-3,16,2,STONE:0)
Block(-2,16,2,STONE:0)
Block(-1,16,2,STONE:0)
Block(-5,16,3,STONE:0)
Block(-4,16,3,STONE:0)
Block(-3,16,3,STONE:0)
Block(-2,16,3,STONE:0)
Block(-1,16,3,STONE:0)
Block(0,16,3,STONE:0)
Block(-5,16,4,STONE:0)
Block(-4,16,4,STONE:0)
Block(-3,16,4,STONE:0)
Block(-2,16,4,STONE:0)
Block(-1,16,4,STONE:0)
Block(0,16,4,STONE:0)
Block(-4,16,5,STONE:0)
Block(-3,16,5,STONE:0)
Block(-2,16,5,STONE:0)
Block(-1,16,5,STONE:0)
Block(0,16,5,STONE:0)
Block(-3,16,6,STONE:0)
Block(-2,16,6,STONE:0)
Block(-1,17,0,STONE:0)
Block(-4,17,1,STONE:0)
Block(-2,17,1,STONE:0)
Block(-1,17,1,STONE:0)
Block(-3,17,2,STONE:0)
Block(-2,17,2,STONE:0)
Block(-1,17,2,STONE:0)
Block(-3,17,3,STONE:0)
Block(-2,17,3,STONE:0)
Block(-1,17,3,STONE:0)
Block(0,17,3,STONE:0)
Block(-2,17,4,STONE:0)
Block(-1,17,4,STONE:0)

#######################################################################
# +-----------------------------------------------------------------+ #
# |                            BO3 checks                           | #
# +-----------------------------------------------------------------+ #
#######################################################################

# Require a condition at a certain location in order for the BO3 to be spawned.
# BlockCheck(x,y,z,BlockName[,BlockName[,...]]) - one of the blocks must be at the location
# BlockCheckNot(x,y,z,BlockName[,BlockName[,...]]) - all the blocks must not be at the location
# LightCheck(x,y,z,minLightLevel,maxLightLevel) - light must be between min and max (inclusive)

# You can use "Solid" as a BlockName for matching all solid blocks or "All" to match all blocks that aren't air.

# Examples:
BlockCheck(0,-1,0,GRASS,DIRT,DIRT:2,STONE,SAND,GRAVEL)
#   BlockCheck(0,-1,0,Solid)       Require any solid block just below the object
#   BlockCheck(0,-1,0,WOOL)        Require any type of wool just below the object
#   BlockCheck(0,-1,0,WOOL:0)      Require white wool just below the object
#   BlockCheckNot(0,-1,0,WOOL:0)   Require that there is no white wool below the object
#   LightCheck(0,0,0,0,1)          Require almost complete darkness just below the object

#######################################################################
# +-----------------------------------------------------------------+ #
# |                             Branches                            | #
# +-----------------------------------------------------------------+ #
#######################################################################

# Branches are objects that will spawn when this object spawns when it is used in
# the CustomStructure resource. Branches can also have branches, making complex
# structures possible. See the wiki for more details.

# Regular Branches spawn each branch with an independent chance of spawning.
# Branch(x,y,z,branchName,rotation,chance[,anotherBranchName,rotation,chance[,...]][IndividualChance])
# branchName - name of the object to spawn.
# rotation - NORTH, SOUTH, EAST or WEST.
# IndividualChance - The chance each branch has to spawn, assumed to be 100 when left blank

# Weighted Branches spawn branches with a dependent chance of spawning.
# WeightedBranch(x,y,z,branchName,rotation,chance[,anotherBranchName,rotation,chance[,...]][MaxChanceOutOf])
# MaxChanceOutOf - The chance all branches have to spawn out of, assumed to be 100 when left blank
