#######################################################################
# +-----------------------------------------------------------------+ #
# |                            BO3 object                           | #
# +-----------------------------------------------------------------+ #
#######################################################################

# This is the config file of a custom object.
# If you add this object correctly to your BiomeConfigs, it will spawn in the world.

# This is the creator of this BO3 object
Author: BO3 BulkEdit (by LanToaster)

# A short description of this BO3 object
Description: This Object was Created with BO3_BulkEdit

# The BO3 version, don't change this! It can be used by external applications to do a version check.
Version: 3

# The settings mode, WriteAll, WriteWithoutComments or WriteDisable. See WorldConfig.
SettingsMode: WriteDisable


#######################################################################
# +-----------------------------------------------------------------+ #
# |                          Main settings                          | #
# +-----------------------------------------------------------------+ #
#######################################################################

# This needs to be set to true to spawn the object in the Tree and Sapling resources.
Tree: true

# The frequency of the BO3 from 1 to 200. Tries this many times to spawn this BO3 when using the CustomObject(...) resource.
# Ignored by Tree(..), Sapling(..) and CustomStructure(..)
Frequency: 200

# The rarity of the BO3 from 0 to 100. Each spawn attempt has rarity% chance to succeed when using the CustomObject(...) resource.
# Ignored by Tree(..), Sapling(..) and CustomStructure(..)
Rarity: 100

# If you set this to true, the BO3 will be placed with a random rotation.
RotateRandomly: True

# The spawn height of the BO3 - randomY, highestBlock or highestSolidBlock.
SpawnHeight: highestSolidBlock

# The height limits for the BO3.
MinHeight: 0

MaxHeight: 72

# Objects can have other objects attacthed to it: branches. Branches can also
# have branches attached to it, which can also have branches, etc. This is the
# maximum branch depth for this objects.
MaxBranchDepth: 10

# When spawned with the UseWorld keyword, this BO3 should NOT spawn in the following biomes.
# If you writer.write the BO3 name directly in the BiomeConfigs, this will be ignored.
ExcludedBiomes: All


#######################################################################
# +-----------------------------------------------------------------+ #
# |                      Source block settings                      | #
# +-----------------------------------------------------------------+ #
#######################################################################

# The block(s) the BO3 should spawn in.
SourceBlocks: AIR

# The maximum percentage of the BO3 that can be outside the SourceBlock.
# The BO3 won't be placed on a location with more blocks outside the SourceBlock than this percentage.
MaxPercentageOutsideSourceBlock: 0

# What to do when a block is about to be placed outside the SourceBlock? (dontPlace, placeAnyway)
OutsideSourceBlock: dontPlace


#######################################################################
# +-----------------------------------------------------------------+ #
# |                              Blocks                             | #
# +-----------------------------------------------------------------+ #
#######################################################################

# All the blocks used in the BO3 are listed here. Possible blocks:
# Block(x,y,z,id[.data][,nbtfile.nbt)
# RandomBlock(x,y,z,id[:data][,nbtfile.nbt],chance[,id[:data][,nbtfile.nbt],chance[,...]])
# So RandomBlock(0,0,0,CHEST,chest.nbt,50,CHEST,anotherchest.nbt,100) will spawn a chest at
# the BO3 origin, and give it a 50% chance to have the contents of chest.nbt, or, if that
# fails, a 100% percent chance to have the contents of anotherchest.nbt.
Block(2,0,-4,LOG:12)
Block(3,0,-4,LOG:12)
Block(0,0,-3,LOG:12)
Block(1,0,-3,LOG:12)
Block(2,0,-3,LOG:12)
Block(3,0,-3,LOG:12)
Block(4,0,-3,LOG:12)
Block(-1,0,-2,LOG:12)
Block(1,0,-2,LOG:12)
Block(2,0,-2,LOG:12)
Block(4,0,-1,LOG:12)
Block(2,1,-4,LOG:12)
Block(3,1,-4,LOG:12)
Block(0,1,-3,LOG:12)
Block(1,1,-3,LOG:12)
Block(2,1,-3,LOG:12)
Block(3,1,-3,LOG:12)
Block(4,1,-3,LOG:12)
Block(2,1,-2,LOG:12)
Block(4,1,-1,LOG:12)
Block(3,2,-4,LOG:12)
Block(1,2,-3,LOG:12)
Block(2,2,-3,LOG:12)
Block(3,2,-3,LOG:12)
Block(4,2,-3,LOG:12)
Block(2,2,-2,LOG:12)
Block(3,2,-2,LOG:12)
Block(4,2,-1,LOG:12)
Block(1,3,-3,LOG:12)
Block(2,3,-3,LOG:12)
Block(3,3,-3,LOG:12)
Block(4,3,-3,LOG:12)
Block(3,3,-2,LOG:12)
Block(2,4,-3,LOG:12)
Block(3,4,-3,LOG:12)
Block(4,4,-3,LOG:12)
Block(3,4,-2,LOG:12)
Block(2,5,-3,LOG:12)
Block(3,5,-3,LOG:12)
Block(4,5,-3,LOG:12)
Block(-7,5,-2,LEAVES:4)
Block(3,5,-2,LOG:12)
Block(-1,5,4,LEAVES:4)
Block(-6,6,-6,LEAVES:4)
Block(-9,6,-5,LEAVES:4)
Block(-6,6,-5,LEAVES:4)
Block(1,6,-3,LOG:12)
Block(2,6,-3,LOG:12)
Block(3,6,-3,LOG:12)
Block(4,6,-3,LOG:12)
Block(13,6,-3,LEAVES:12)
Block(-10,6,-2,LEAVES:4)
Block(9,6,-2,LEAVES:4)
Block(-9,6,-1,LEAVES:4)
Block(1,6,1,LEAVES:4)
Block(1,6,2,LEAVES:4)
Block(-3,6,3,LEAVES:4)
Block(-1,6,3,LEAVES:4)
Block(6,6,4,LEAVES:12)
Block(-1,6,5,LEAVES:4)
Block(-3,7,-11,LEAVES:4)
Block(6,7,-11,LEAVES:4)
Block(-3,7,-10,LEAVES:4)
Block(-2,7,-10,LEAVES:4)
Block(-5,7,-9,LEAVES:4)
Block(5,7,-9,LEAVES:4)
Block(6,7,-9,LEAVES:4)
Block(6,7,-8,LEAVES:4)
Block(-7,7,-6,LEAVES:4)
Block(-6,7,-5,LEAVES:4)
Block(-4,7,-5,LEAVES:4)
Block(-7,7,-4,LEAVES:4)
Block(-4,7,-4,LEAVES:4)
Block(12,7,-4,LEAVES:12)
Block(-11,7,-3,LEAVES:4)
Block(-10,7,-3,LEAVES:4)
Block(1,7,-3,LOG:12)
Block(2,7,-3,LOG:12)
Block(3,7,-3,LOG:12)
Block(4,7,-3,LOG:12)
Block(14,7,-3,LEAVES:4)
Block(-10,7,-2,LEAVES:4)
Block(9,7,-2,LEAVES:4)
Block(14,7,-2,LEAVES:12)
Block(-9,7,-1,LEAVES:4)
Block(-7,7,-1,LEAVES:4)
Block(11,7,-1,LEAVES:4)
Block(12,7,-1,LEAVES:4)
Block(-5,7,0,LEAVES:12)
Block(10,7,0,LEAVES:4)
Block(13,7,0,LEAVES:4)
Block(-1,7,1,LEAVES:4)
Block(-4,7,3,LEAVES:4)
Block(-2,7,3,LEAVES:4)
Block(-1,7,4,LEAVES:4)
Block(-4,7,5,LEAVES:4)
Block(6,7,6,LEAVES:12)
Block(7,7,6,LEAVES:12)
Block(9,7,7,LEAVES:4)
Block(3,8,-10,LEAVES:4)
Block(8,8,-10,LEAVES:4)
Block(-3,8,-9,LEAVES:4)
Block(0,8,-9,LEAVES:4)
Block(5,8,-9,LEAVES:4)
Block(3,8,-8,LEAVES:4)
Block(-7,8,-7,LEAVES:4)
Block(-3,8,-7,LEAVES:4)
Block(6,8,-7,LEAVES:4)
Block(-7,8,-6,LEAVES:4)
Block(-6,8,-6,LEAVES:4)
Block(5,8,-6,LEAVES:4)
Block(10,8,-5,LEAVES:4)
Block(-11,8,-4,LEAVES:4)
Block(13,8,-4,LEAVES:4)
Block(-11,8,-3,LEAVES:4)
Block(-9,8,-3,LEAVES:4)
Block(-7,8,-3,LEAVES:4)
Block(-3,8,-3,LEAVES:4)
Block(1,8,-3,LOG:12)
Block(2,8,-3,LOG:12)
Block(4,8,-3,LOG:12)
Block(5,8,-3,LOG:12)
Block(6,8,-3,LOG:12)
Block(7,8,-3,LOG:12)
Block(8,8,-3,LOG:12)
Block(-11,8,-2,LEAVES:4)
Block(4,8,-2,LOG:12)
Block(12,8,-2,LEAVES:4)
Block(-7,8,-1,LEAVES:4)
Block(4,8,-1,LOG:12)
Block(9,8,-1,LEAVES:4)
Block(-8,8,0,LEAVES:4)
Block(-4,8,0,LEAVES:12)
Block(1,8,0,LEAVES:4)
Block(4,8,0,LOG:12)
Block(11,8,0,LEAVES:4)
Block(12,8,0,LEAVES:4)
Block(13,8,0,LEAVES:4)
Block(1,8,1,LEAVES:4)
Block(-4,8,2,LEAVES:4)
Block(1,8,2,LEAVES:4)
Block(-2,8,3,LEAVES:4)
Block(-4,8,4,LEAVES:4)
Block(-1,8,6,LEAVES:4)
Block(5,8,6,LEAVES:12)
Block(6,8,6,LEAVES:12)
Block(6,8,7,LEAVES:4)
Block(9,8,8,LEAVES:4)
Block(7,8,9,LEAVES:4)
Block(-5,9,-12,LEAVES:4)
Block(6,9,-12,LEAVES:4)
Block(-1,9,-11,LEAVES:4)
Block(3,9,-11,LEAVES:4)
Block(-5,9,-10,LEAVES:4)
Block(-2,9,-10,LEAVES:4)
Block(0,9,-10,LEAVES:4)
Block(4,9,-10,LEAVES:4)
Block(-7,9,-9,LEAVES:4)
Block(-5,9,-9,LEAVES:4)
Block(-1,9,-9,LEAVES:4)
Block(6,9,-9,LEAVES:4)
Block(8,9,-9,LEAVES:4)
Block(0,9,-8,LEAVES:4)
Block(1,9,-8,LEAVES:4)
Block(4,9,-8,LEAVES:4)
Block(5,9,-8,LEAVES:4)
Block(6,9,-8,LEAVES:4)
Block(-9,9,-7,LEAVES:4)
Block(-7,9,-7,LEAVES:4)
Block(0,9,-7,LEAVES:4)
Block(1,9,-7,LEAVES:4)
Block(3,9,-7,LEAVES:4)
Block(-7,9,-6,LEAVES:4)
Block(-3,9,-6,LEAVES:4)
Block(-2,9,-6,LEAVES:4)
Block(1,9,-6,LEAVES:4)
Block(10,9,-6,LEAVES:4)
Block(12,9,-6,LEAVES:4)
Block(14,9,-6,LEAVES:4)
Block(-11,9,-5,LEAVES:4)
Block(-6,9,-5,LEAVES:4)
Block(-5,9,-5,LEAVES:4)
Block(11,9,-5,LEAVES:4)
Block(-7,9,-4,LEAVES:4)
Block(9,9,-4,LEAVES:4)
Block(-7,9,-3,LOG:12)
Block(-6,9,-3,LOG:12)
Block(-5,9,-3,LOG:12)
Block(1,9,-3,LOG:12)
Block(2,9,-3,LOG:12)
Block(4,9,-3,LOG:12)
Block(-3,9,-2,LEAVES:12)
Block(8,9,-2,LEAVES:12)
Block(9,9,-2,LOG:12)
Block(10,9,-2,LOG:12)
Block(11,9,-2,LOG:12)
Block(12,9,-2,LOG:12)
Block(14,9,-2,LEAVES:4)
Block(-5,9,-1,LEAVES:12)
Block(-3,9,-1,LEAVES:12)
Block(8,9,-1,LEAVES:12)
Block(10,9,-1,LEAVES:4)
Block(12,9,-1,LEAVES:4)
Block(14,9,-1,LEAVES:4)
Block(-7,9,0,LEAVES:4)
Block(-1,9,0,LEAVES:4)
Block(2,9,0,LEAVES:4)
Block(8,9,0,LEAVES:12)
Block(13,9,0,LEAVES:4)
Block(0,9,1,LEAVES:4)
Block(2,9,1,LEAVES:4)
Block(5,9,1,LOG:12)
Block(9,9,1,LEAVES:4)
Block(-4,9,2,LEAVES:4)
Block(-2,9,2,LEAVES:4)
Block(0,9,2,LEAVES:4)
Block(1,9,2,LOG:12)
Block(2,9,2,LOG:12)
Block(3,9,2,LOG:12)
Block(4,9,2,LOG:12)
Block(5,9,2,LOG:12)
Block(-5,9,3,LEAVES:4)
Block(-4,9,3,LEAVES:4)
Block(-1,9,3,LOG:12)
Block(0,9,3,LOG:12)
Block(2,9,3,LEAVES:4)
Block(3,9,3,LEAVES:4)
Block(5,9,3,LOG:12)
Block(-5,9,4,LEAVES:4)
Block(5,9,4,LEAVES:12)
Block(2,9,5,LEAVES:4)
Block(9,9,5,LEAVES:4)
Block(-2,9,6,LEAVES:4)
Block(-1,9,6,LEAVES:4)
Block(0,9,6,LEAVES:4)
Block(2,9,6,LEAVES:12)
Block(6,9,6,LEAVES:12)
Block(10,9,6,LEAVES:4)
Block(-3,9,7,LEAVES:4)
Block(6,9,7,LEAVES:4)
Block(5,9,9,LEAVES:4)
Block(6,9,9,LEAVES:4)
Block(7,9,9,LEAVES:4)
Block(5,9,10,LEAVES:4)
Block(-4,10,-13,LEAVES:4)
Block(6,10,-13,LEAVES:4)
Block(7,10,-12,LEAVES:4)
Block(-4,10,-11,LEAVES:4)
Block(9,10,-11,LEAVES:4)
Block(-7,10,-9,LEAVES:4)
Block(-5,10,-9,LEAVES:4)
Block(6,10,-9,LEAVES:4)
Block(6,10,-8,LEAVES:4)
Block(-3,10,-7,LEAVES:4)
Block(2,10,-7,LEAVES:4)
Block(3,10,-7,LEAVES:4)
Block(-2,10,-6,LOG:12)
Block(4,10,-6,LEAVES:4)
Block(5,10,-6,LOG:12)
Block(13,10,-6,LEAVES:4)
Block(-7,10,-5,LEAVES:4)
Block(-4,10,-5,LEAVES:4)
Block(-2,10,-5,LOG:12)
Block(5,10,-5,LOG:12)
Block(-9,10,-4,LEAVES:4)
Block(-2,10,-4,LOG:12)
Block(5,10,-4,LOG:12)
Block(9,10,-4,LEAVES:4)
Block(-9,10,-3,LEAVES:4)
Block(-8,10,-3,LEAVES:4)
Block(-7,10,-3,LEAVES:4)
Block(-4,10,-3,LOG:12)
Block(-3,10,-3,LOG:12)
Block(-2,10,-3,LOG:12)
Block(-1,10,-3,LOG:12)
Block(0,10,-3,LOG:12)
Block(2,10,-3,LOG:12)
Block(4,10,-3,LOG:12)
Block(10,10,-3,LEAVES:4)
Block(-8,10,-2,LEAVES:4)
Block(11,10,-2,LEAVES:4)
Block(13,10,-2,LEAVES:4)
Block(-4,10,-1,LEAVES:12)
Block(11,10,-1,LEAVES:4)
Block(15,10,-1,LEAVES:4)
Block(16,10,-1,LEAVES:4)
Block(13,10,0,LEAVES:4)
Block(14,10,0,LEAVES:4)
Block(-7,10,1,LEAVES:4)
Block(11,10,1,LEAVES:4)
Block(-5,10,2,LEAVES:4)
Block(4,10,2,LOG:12)
Block(6,10,2,LEAVES:12)
Block(-1,10,3,LEAVES:4)
Block(-3,10,4,LEAVES:4)
Block(-2,10,4,LEAVES:4)
Block(2,10,4,LEAVES:12)
Block(6,10,4,LOG:12)
Block(-3,10,5,LEAVES:4)
Block(6,10,5,LOG:12)
Block(6,10,6,LOG:12)
Block(7,10,6,LEAVES:12)
Block(9,10,6,LEAVES:4)
Block(3,10,8,LEAVES:4)
Block(5,10,8,LEAVES:4)
Block(3,10,9,LEAVES:4)
Block(7,10,9,LEAVES:4)
Block(-4,11,-13,LEAVES:4)
Block(6,11,-13,LEAVES:4)
Block(0,11,-12,LEAVES:4)
Block(-3,11,-11,LEAVES:4)
Block(4,11,-11,LEAVES:4)
Block(-3,11,-10,LEAVES:4)
Block(1,11,-10,LEAVES:4)
Block(2,11,-10,LEAVES:4)
Block(6,11,-10,LEAVES:4)
Block(9,11,-10,LEAVES:4)
Block(-7,11,-9,LEAVES:4)
Block(-4,11,-9,LEAVES:4)
Block(-3,11,-9,LOG:12)
Block(-2,11,-9,LEAVES:4)
Block(3,11,-9,LEAVES:4)
Block(4,11,-9,LEAVES:4)
Block(6,11,-9,LOG:12)
Block(7,11,-9,LEAVES:4)
Block(8,11,-9,LEAVES:4)
Block(9,11,-9,LEAVES:4)
Block(10,11,-9,LEAVES:4)
Block(-7,11,-8,LEAVES:4)
Block(-5,11,-8,LEAVES:4)
Block(-3,11,-8,LOG:12)
Block(-1,11,-8,LEAVES:4)
Block(0,11,-8,LEAVES:4)
Block(3,11,-8,LEAVES:4)
Block(5,11,-8,LEAVES:4)
Block(6,11,-8,LOG:12)
Block(-3,11,-7,LOG:12)
Block(0,11,-7,LEAVES:4)
Block(3,11,-7,LEAVES:4)
Block(5,11,-7,LEAVES:4)
Block(6,11,-7,LOG:12)
Block(-7,11,-6,LEAVES:4)
Block(-3,11,-6,LEAVES:4)
Block(1,11,-6,LEAVES:4)
Block(3,11,-6,LEAVES:4)
Block(7,11,-6,LEAVES:4)
Block(-5,11,-5,LEAVES:4)
Block(-3,11,-5,LEAVES:4)
Block(-1,11,-5,LEAVES:4)
Block(3,11,-5,LEAVES:4)
Block(4,11,-5,LEAVES:4)
Block(8,11,-5,LEAVES:4)
Block(12,11,-5,LEAVES:4)
Block(1,11,-4,LEAVES:4)
Block(10,11,-4,LEAVES:4)
Block(14,11,-4,LEAVES:4)
Block(15,11,-4,LEAVES:4)
Block(-9,11,-3,LEAVES:4)
Block(-7,11,-3,LEAVES:4)
Block(0,11,-3,LOG:12)
Block(2,11,-3,LOG:12)
Block(5,11,-3,LOG:12)
Block(13,11,-3,LEAVES:4)
Block(10,11,-2,LEAVES:4)
Block(12,11,-2,LEAVES:4)
Block(10,11,-1,LEAVES:4)
Block(11,11,-1,LEAVES:4)
Block(-5,11,0,LEAVES:12)
Block(1,11,0,LEAVES:4)
Block(9,11,0,LEAVES:4)
Block(11,11,0,LEAVES:4)
Block(0,11,2,LEAVES:4)
Block(4,11,2,LOG:12)
Block(6,11,2,LEAVES:12)
Block(7,11,2,LEAVES:12)
Block(-3,11,3,LEAVES:4)
Block(-2,11,3,LEAVES:4)
Block(1,11,3,LEAVES:4)
Block(2,11,4,LEAVES:4)
Block(9,11,4,LEAVES:4)
Block(-2,11,5,LEAVES:4)
Block(7,11,5,LEAVES:12)
Block(-1,11,6,LEAVES:4)
Block(4,11,6,LEAVES:12)
Block(5,11,7,LEAVES:12)
Block(10,11,7,LEAVES:4)
Block(6,11,9,LEAVES:4)
Block(7,11,10,LEAVES:4)
Block(-2,12,-13,LEAVES:4)
Block(-2,12,-12,LEAVES:4)
Block(-4,12,-11,LEAVES:4)
Block(4,12,-11,LEAVES:4)
Block(9,12,-11,LEAVES:4)
Block(-5,12,-10,LEAVES:4)
Block(-1,12,-10,LEAVES:4)
Block(2,12,-10,LEAVES:4)
Block(5,12,-10,LEAVES:4)
Block(10,12,-10,LEAVES:4)
Block(-4,12,-9,LEAVES:4)
Block(-3,12,-9,LEAVES:4)
Block(3,12,-9,LEAVES:4)
Block(4,12,-9,LEAVES:4)
Block(7,12,-9,LEAVES:4)
Block(0,12,-8,LEAVES:4)
Block(3,12,-8,LEAVES:4)
Block(4,12,-8,LEAVES:4)
Block(8,12,-8,LEAVES:4)
Block(-3,12,-7,LEAVES:4)
Block(6,12,-7,LEAVES:4)
Block(7,12,-7,LEAVES:4)
Block(-5,12,-6,LEAVES:4)
Block(4,12,-6,LEAVES:4)
Block(-8,12,-5,LEAVES:4)
Block(-7,12,-5,LEAVES:4)
Block(5,12,-5,LEAVES:4)
Block(13,12,-5,LEAVES:4)
Block(-9,12,-4,LEAVES:4)
Block(2,12,-4,LOG:12)
Block(10,12,-4,LEAVES:4)
Block(-9,12,-3,LEAVES:4)
Block(-6,12,-3,LEAVES:4)
Block(0,12,-3,LOG:12)
Block(5,12,-3,LOG:12)
Block(10,12,-3,LEAVES:4)
Block(10,12,-2,LEAVES:4)
Block(14,12,-2,LEAVES:4)
Block(15,12,-2,LEAVES:4)
Block(14,12,-1,LEAVES:4)
Block(-7,12,0,LEAVES:4)
Block(-2,12,0,LEAVES:4)
Block(14,12,0,LEAVES:4)
Block(-2,12,2,LEAVES:4)
Block(4,12,2,LOG:12)
Block(-3,12,3,LEAVES:4)
Block(8,12,3,LEAVES:12)
Block(1,12,5,LEAVES:4)
Block(0,12,6,LEAVES:4)
Block(3,12,6,LEAVES:12)
Block(4,12,8,LEAVES:4)
Block(7,12,8,LEAVES:4)
Block(9,12,8,LEAVES:4)
Block(6,12,9,LEAVES:4)
Block(7,12,9,LEAVES:4)
Block(6,12,10,LEAVES:4)
Block(6,13,-13,LEAVES:4)
Block(-4,13,-12,LEAVES:4)
Block(7,13,-12,LEAVES:4)
Block(-3,13,-11,LEAVES:4)
Block(1,13,-11,LEAVES:4)
Block(-3,13,-10,LEAVES:4)
Block(3,13,-10,LEAVES:4)
Block(4,13,-10,LEAVES:4)
Block(-1,13,-9,LEAVES:4)
Block(0,13,-9,LEAVES:4)
Block(3,13,-9,LEAVES:4)
Block(5,13,-8,LEAVES:4)
Block(-4,13,-7,LEAVES:4)
Block(-3,13,-7,LEAVES:4)
Block(-1,13,-7,LEAVES:4)
Block(0,13,-7,LEAVES:4)
Block(1,13,-7,LOG:12)
Block(5,13,-7,LEAVES:4)
Block(-1,13,-6,LEAVES:4)
Block(1,13,-6,LOG:12)
Block(3,13,-6,LEAVES:4)
Block(7,13,-6,LEAVES:4)
Block(8,13,-6,LEAVES:4)
Block(-3,13,-5,LEAVES:4)
Block(1,13,-5,LOG:12)
Block(3,13,-5,LEAVES:4)
Block(2,13,-4,LOG:12)
Block(3,13,-4,LEAVES:4)
Block(12,13,-4,LEAVES:4)
Block(-9,13,-3,LEAVES:4)
Block(-7,13,-3,LEAVES:4)
Block(-1,13,-3,LOG:12)
Block(1,13,-3,LEAVES:4)
Block(5,13,-3,LOG:12)
Block(13,13,-3,LEAVES:4)
Block(12,13,-1,LEAVES:4)
Block(12,13,0,LEAVES:4)
Block(-3,13,3,LEAVES:4)
Block(-1,13,3,LEAVES:4)
Block(3,13,3,LOG:12)
Block(-1,13,5,LEAVES:4)
Block(3,13,6,LEAVES:12)
Block(8,13,6,LEAVES:12)
Block(6,13,9,LEAVES:4)
Block(7,13,9,LEAVES:4)
Block(8,14,-11,LEAVES:4)
Block(6,14,-10,LEAVES:4)
Block(-5,14,-9,LEAVES:4)
Block(-1,14,-9,LEAVES:4)
Block(0,14,-9,LEAVES:4)
Block(3,14,-9,LEAVES:4)
Block(5,14,-9,LEAVES:4)
Block(7,14,-9,LEAVES:4)
Block(-4,14,-8,LEAVES:4)
Block(1,14,-8,LEAVES:4)
Block(2,14,-8,LEAVES:4)
Block(3,14,-8,LEAVES:4)
Block(-2,14,-7,LEAVES:4)
Block(4,14,-7,LEAVES:4)
Block(1,14,-6,LEAVES:4)
Block(0,14,-5,LEAVES:4)
Block(2,14,-4,LOG:12)
Block(-1,14,-3,LOG:12)
Block(6,14,-3,LOG:12)
Block(3,14,3,LOG:12)
Block(6,14,4,LEAVES:4)
Block(6,14,5,LEAVES:4)
Block(6,15,-11,LEAVES:4)
Block(0,15,-10,LEAVES:4)
Block(7,15,-10,LEAVES:4)
Block(2,15,-9,LEAVES:4)
Block(6,15,-9,LEAVES:4)
Block(-2,15,-8,LEAVES:4)
Block(1,15,-8,LEAVES:4)
Block(6,15,-8,LEAVES:4)
Block(-2,15,-7,LEAVES:4)
Block(4,15,-7,LEAVES:4)
Block(0,15,-5,LEAVES:4)
Block(3,15,-5,LEAVES:4)
Block(2,15,-4,LOG:12)
Block(3,15,-4,LEAVES:4)
Block(-1,15,-3,LOG:12)
Block(6,15,-3,LOG:12)
Block(3,15,3,LOG:12)
Block(1,16,-10,LEAVES:4)
Block(1,16,-9,LEAVES:4)
Block(3,16,-9,LEAVES:4)
Block(-2,16,-8,LEAVES:4)
Block(1,16,-8,LEAVES:4)
Block(3,16,-7,LEAVES:4)
Block(1,16,-5,LEAVES:4)
Block(2,16,-5,LOG:12)
Block(-2,16,-3,LOG:12)
Block(6,16,-3,LOG:12)
Block(8,16,-3,LEAVES:4)
Block(2,16,4,LOG:12)
Block(0,17,-8,LEAVES:4)
Block(1,17,-8,LEAVES:4)
Block(3,17,-8,LEAVES:4)
Block(1,17,-7,LEAVES:4)
Block(3,17,-7,LEAVES:4)
Block(2,17,-6,LEAVES:4)
Block(5,17,-6,LEAVES:4)
Block(6,17,-6,LEAVES:4)
Block(-4,17,-5,LEAVES:4)
Block(2,17,-5,LOG:12)
Block(5,17,-5,LEAVES:4)
Block(6,17,-5,LEAVES:4)
Block(-5,17,-4,LEAVES:4)
Block(-3,17,-4,LEAVES:4)
Block(-1,17,-4,LEAVES:4)
Block(0,17,-4,LEAVES:4)
Block(8,17,-4,LEAVES:4)
Block(-5,17,-3,LEAVES:4)
Block(-2,17,-3,LOG:12)
Block(4,17,-3,LEAVES:4)
Block(6,17,-3,LOG:12)
Block(7,17,-3,LEAVES:4)
Block(9,17,-3,LEAVES:4)
Block(-5,17,-2,LEAVES:4)
Block(1,17,-2,LEAVES:4)
Block(4,17,-2,LEAVES:4)
Block(-4,17,-1,LEAVES:4)
Block(8,17,-1,LEAVES:4)
Block(8,17,0,LEAVES:4)
Block(2,17,4,LOG:12)
Block(3,17,5,LEAVES:4)
Block(0,18,-8,LEAVES:4)
Block(1,18,-6,LEAVES:4)
Block(2,18,-6,LEAVES:4)
Block(7,18,-6,LEAVES:4)
Block(-3,18,-5,LEAVES:4)
Block(2,18,-5,LOG:12)
Block(3,18,-5,LEAVES:4)
Block(-5,18,-4,LEAVES:4)
Block(10,18,-4,LEAVES:4)
Block(-4,18,-3,LEAVES:4)
Block(-2,18,-3,LOG:12)
Block(7,18,-3,LOG:12)
Block(11,18,-3,LEAVES:4)
Block(4,18,-2,LEAVES:4)
Block(5,18,-2,LEAVES:4)
Block(-2,18,-1,LEAVES:4)
Block(2,18,-1,LEAVES:4)
Block(3,18,-1,LEAVES:4)
Block(5,18,0,LEAVES:4)
Block(7,18,0,LEAVES:4)
Block(0,18,3,LEAVES:4)
Block(3,18,3,LEAVES:4)
Block(2,18,4,LOG:12)
Block(-2,18,5,LEAVES:4)
Block(0,18,5,LEAVES:4)
Block(-2,18,6,LEAVES:4)
Block(1,18,6,LEAVES:4)
Block(0,18,8,LEAVES:4)
Block(0,19,-9,LEAVES:4)
Block(-1,19,-7,LEAVES:4)
Block(4,19,-7,LEAVES:4)
Block(-2,19,-6,LEAVES:4)
Block(-1,19,-6,LEAVES:4)
Block(3,19,-6,LEAVES:4)
Block(5,19,-6,LEAVES:4)
Block(9,19,-6,LEAVES:4)
Block(1,19,-5,LEAVES:4)
Block(2,19,-5,LOG:12)
Block(-1,19,-4,LEAVES:4)
Block(9,19,-4,LEAVES:4)
Block(-8,19,-3,LEAVES:4)
Block(-4,19,-3,LEAVES:4)
Block(-3,19,-3,LOG:12)
Block(-2,19,-3,LEAVES:4)
Block(-1,19,-3,LEAVES:4)
Block(1,19,-3,LEAVES:4)
Block(3,19,-3,LEAVES:4)
Block(6,19,-3,LEAVES:4)
Block(7,19,-3,LOG:12)
Block(9,19,-3,LEAVES:4)
Block(10,19,-3,LEAVES:4)
Block(-7,19,-2,LEAVES:4)
Block(-1,19,-2,LEAVES:4)
Block(2,19,-2,LEAVES:4)
Block(9,19,-1,LEAVES:4)
Block(2,19,2,LEAVES:4)
Block(-2,19,4,LEAVES:4)
Block(0,19,4,LEAVES:4)
Block(1,19,4,LEAVES:4)
Block(2,19,4,LEAVES:4)
Block(4,19,4,LEAVES:4)
Block(1,19,5,LOG:12)
Block(3,19,7,LEAVES:4)
Block(1,20,-8,LEAVES:4)
Block(2,20,-7,LEAVES:4)
Block(3,20,-7,LEAVES:4)
Block(-7,20,-6,LEAVES:4)
Block(4,20,-6,LEAVES:4)
Block(-2,20,-5,LEAVES:4)
Block(3,20,-5,LEAVES:4)
Block(5,20,-5,LEAVES:4)
Block(-8,20,-4,LEAVES:4)
Block(-5,20,-4,LEAVES:4)
Block(-3,20,-3,LOG:12)
Block(-1,20,-3,LEAVES:4)
Block(3,20,-3,LEAVES:4)
Block(4,20,-3,LEAVES:4)
Block(7,20,-3,LOG:12)
Block(8,20,-3,LEAVES:4)
Block(9,20,-3,LEAVES:4)
Block(10,20,-3,LEAVES:4)
Block(11,20,-3,LEAVES:4)
Block(7,20,-2,LEAVES:4)
Block(9,20,-2,LEAVES:4)
Block(11,20,-2,LEAVES:4)
Block(2,20,-1,LEAVES:4)
Block(7,20,-1,LEAVES:4)
Block(8,20,-1,LEAVES:4)
Block(-3,20,0,LEAVES:4)
Block(-2,20,0,LEAVES:4)
Block(-1,20,0,LEAVES:4)
Block(7,20,0,LEAVES:4)
Block(0,20,1,LEAVES:4)
Block(6,20,1,LEAVES:4)
Block(1,20,4,LEAVES:4)
Block(1,20,5,LOG:12)
Block(4,20,5,LEAVES:4)
Block(1,20,6,LEAVES:4)
Block(3,20,6,LEAVES:4)
Block(1,20,7,LEAVES:4)
Block(1,20,8,LEAVES:4)
Block(2,21,-8,LEAVES:4)
Block(-5,21,-7,LEAVES:4)
Block(1,21,-7,LEAVES:4)
Block(-6,21,-6,LEAVES:4)
Block(-4,21,-6,LEAVES:4)
Block(-3,21,-6,LEAVES:4)
Block(2,21,-6,LEAVES:4)
Block(3,21,-6,LEAVES:4)
Block(4,21,-6,LEAVES:4)
Block(6,21,-6,LEAVES:4)
Block(0,21,-5,LEAVES:4)
Block(10,21,-5,LEAVES:4)
Block(-6,21,-4,LEAVES:4)
Block(-4,21,-4,LEAVES:4)
Block(-1,21,-4,LEAVES:4)
Block(0,21,-4,LEAVES:4)
Block(2,21,-4,LEAVES:4)
Block(5,21,-4,LEAVES:4)
Block(8,21,-4,LEAVES:4)
Block(-7,21,-3,LEAVES:4)
Block(-4,21,-3,LOG:12)
Block(-3,21,-3,LEAVES:4)
Block(0,21,-3,LEAVES:4)
Block(3,21,-3,LEAVES:4)
Block(0,21,-2,LEAVES:4)
Block(4,21,-2,LEAVES:4)
Block(9,21,-2,LEAVES:4)
Block(11,21,-2,LEAVES:4)
Block(-3,21,-1,LEAVES:4)
Block(-2,21,-1,LEAVES:4)
Block(0,21,-1,LEAVES:4)
Block(5,21,-1,LEAVES:4)
Block(8,21,-1,LEAVES:4)
Block(10,21,-1,LEAVES:4)
Block(7,21,0,LEAVES:4)
Block(-4,21,1,LEAVES:4)
Block(-2,21,1,LEAVES:4)
Block(-1,21,2,LEAVES:4)
Block(-3,21,3,LEAVES:4)
Block(4,21,4,LEAVES:4)
Block(-1,21,5,LEAVES:4)
Block(1,21,5,LOG:12)
Block(3,21,5,LEAVES:4)
Block(-3,21,7,LEAVES:4)
Block(-1,21,7,LEAVES:4)
Block(-1,21,8,LEAVES:4)
Block(-3,22,-7,LEAVES:4)
Block(3,22,-7,LEAVES:4)
Block(-7,22,-6,LEAVES:4)
Block(9,22,-6,LEAVES:4)
Block(-2,22,-5,LEAVES:4)
Block(2,22,-5,LEAVES:4)
Block(-4,22,-4,LEAVES:4)
Block(2,22,-4,LEAVES:4)
Block(4,22,-4,LEAVES:4)
Block(5,22,-4,LEAVES:4)
Block(-7,22,-3,LEAVES:4)
Block(-4,22,-3,LEAVES:4)
Block(-3,22,-3,LEAVES:4)
Block(-2,22,-2,LEAVES:4)
Block(2,22,-2,LEAVES:4)
Block(3,22,-2,LEAVES:4)
Block(4,22,-2,LEAVES:4)
Block(10,22,-2,LEAVES:4)
Block(-4,22,1,LEAVES:4)
Block(1,22,3,LEAVES:4)
Block(3,22,3,LEAVES:4)
Block(-1,22,5,LEAVES:4)
Block(1,22,5,LEAVES:4)
Block(0,22,7,LEAVES:4)
Block(-1,22,8,LEAVES:4)
Block(-4,23,-6,LEAVES:4)
Block(8,23,-6,LEAVES:4)
Block(1,23,-5,LEAVES:4)
Block(2,23,-5,LEAVES:4)
Block(4,23,-5,LEAVES:4)
Block(5,23,-5,LEAVES:4)
Block(7,23,-5,LEAVES:4)
Block(0,23,-3,LEAVES:4)
Block(5,23,-3,LEAVES:4)
Block(-1,23,-1,LEAVES:4)
Block(9,23,-1,LEAVES:4)
Block(1,23,5,LEAVES:4)
Block(2,23,5,LEAVES:4)
Block(5,23,5,LEAVES:4)
Block(2,23,6,LEAVES:4)
Block(-1,23,8,LEAVES:4)
Block(7,24,-5,LEAVES:4)
Block(8,24,-4,LEAVES:4)
Block(-3,24,-1,LEAVES:4)
Block(-1,24,4,LEAVES:4)
Block(0,24,4,LEAVES:4)
Block(4,24,4,LEAVES:4)
Block(1,24,6,LEAVES:4)
Block(-1,24,7,LEAVES:4)
Block(1,24,8,LEAVES:4)
Block(-2,25,-3,LEAVES:4)
Block(-4,25,-1,LEAVES:4)
Block(1,25,3,LEAVES:4)
Block(1,25,4,LEAVES:4)
Block(0,25,5,LEAVES:4)
Block(2,25,5,LEAVES:4)

#######################################################################
# +-----------------------------------------------------------------+ #
# |                            BO3 checks                           | #
# +-----------------------------------------------------------------+ #
#######################################################################

# Require a condition at a certain location in order for the BO3 to be spawned.
# BlockCheck(x,y,z,BlockName[,BlockName[,...]]) - one of the blocks must be at the location
# BlockCheckNot(x,y,z,BlockName[,BlockName[,...]]) - all the blocks must not be at the location
# LightCheck(x,y,z,minLightLevel,maxLightLevel) - light must be between min and max (inclusive)

# You can use "Solid" as a BlockName for matching all solid blocks or "All" to match all blocks that aren't air.

# Examples:
BlockCheck(0,-1,0,GRASS,DIRT,DIRT:2,SAND)
#   BlockCheck(0,-1,0,Solid)       Require any solid block just below the object
#   BlockCheck(0,-1,0,WOOL)        Require any type of wool just below the object
#   BlockCheck(0,-1,0,WOOL:0)      Require white wool just below the object
#   BlockCheckNot(0,-1,0,WOOL:0)   Require that there is no white wool below the object
#   LightCheck(0,0,0,0,1)          Require almost complete darkness just below the object

#######################################################################
# +-----------------------------------------------------------------+ #
# |                             Branches                            | #
# +-----------------------------------------------------------------+ #
#######################################################################

# Branches are objects that will spawn when this object spawns when it is used in
# the CustomStructure resource. Branches can also have branches, making complex
# structures possible. See the wiki for more details.

# Regular Branches spawn each branch with an independent chance of spawning.
# Branch(x,y,z,branchName,rotation,chance[,anotherBranchName,rotation,chance[,...]][IndividualChance])
# branchName - name of the object to spawn.
# rotation - NORTH, SOUTH, EAST or WEST.
# IndividualChance - The chance each branch has to spawn, assumed to be 100 when left blank

# Weighted Branches spawn branches with a dependent chance of spawning.
# WeightedBranch(x,y,z,branchName,rotation,chance[,anotherBranchName,rotation,chance[,...]][MaxChanceOutOf])
# MaxChanceOutOf - The chance all branches have to spawn out of, assumed to be 100 when left blank
BlockCheck(0,-1,0,GRASS)
