#######################################################################
# +-----------------------------------------------------------------+ #
# |                            BO3 object                           | #
# +-----------------------------------------------------------------+ #
#######################################################################

# This is the config file of a custom object.
# If you add this object correctly to your BiomeConfigs, it will spawn in the world.

# This is the creator of this BO3 object
Author: BO3 BulkEdit (by LanToaster)

# A short description of this BO3 object
Description: This Object was Created with BO3_BulkEdit

# The BO3 version, don't change this! It can be used by external applications to do a version check.
Version: 3

# The settings mode, WriteAll, WriteWithoutComments or WriteDisable. See WorldConfig.
SettingsMode: WriteDisable


#######################################################################
# +-----------------------------------------------------------------+ #
# |                          Main settings                          | #
# +-----------------------------------------------------------------+ #
#######################################################################

# This needs to be set to true to spawn the object in the Tree and Sapling resources.
Tree: true

# The frequency of the BO3 from 1 to 200. Tries this many times to spawn this BO3 when using the CustomObject(...) resource.
# Ignored by Tree(..), Sapling(..) and CustomStructure(..)
Frequency: 1

# The rarity of the BO3 from 0 to 100. Each spawn attempt has rarity% chance to succeed when using the CustomObject(...) resource.
# Ignored by Tree(..), Sapling(..) and CustomStructure(..)
Rarity: 100

# If you set this to true, the BO3 will be placed with a random rotation.
RotateRandomly: True

# The spawn height of the BO3 - randomY, highestBlock or highestSolidBlock.
SpawnHeight: highestSolidBlock

# The height limits for the BO3.
MinHeight: 0

MaxHeight: 72

# Objects can have other objects attacthed to it: branches. Branches can also
# have branches attached to it, which can also have branches, etc. This is the
# maximum branch depth for this objects.
MaxBranchDepth: 10

# When spawned with the UseWorld keyword, this BO3 should NOT spawn in the following biomes.
# If you writer.write the BO3 name directly in the BiomeConfigs, this will be ignored.
ExcludedBiomes: All


#######################################################################
# +-----------------------------------------------------------------+ #
# |                      Source block settings                      | #
# +-----------------------------------------------------------------+ #
#######################################################################

# The block(s) the BO3 should spawn in.
SourceBlocks: AIR

# The maximum percentage of the BO3 that can be outside the SourceBlock.
# The BO3 won't be placed on a location with more blocks outside the SourceBlock than this percentage.
MaxPercentageOutsideSourceBlock: 0

# What to do when a block is about to be placed outside the SourceBlock? (dontPlace, placeAnyway)
OutsideSourceBlock: dontPlace


#######################################################################
# +-----------------------------------------------------------------+ #
# |                              Blocks                             | #
# +-----------------------------------------------------------------+ #
#######################################################################

# All the blocks used in the BO3 are listed here. Possible blocks:
# Block(x,y,z,id[.data][,nbtfile.nbt)
# RandomBlock(x,y,z,id[:data][,nbtfile.nbt],chance[,id[:data][,nbtfile.nbt],chance[,...]])
# So RandomBlock(0,0,0,CHEST,chest.nbt,50,CHEST,anotherchest.nbt,100) will spawn a chest at
# the BO3 origin, and give it a 50% chance to have the contents of chest.nbt, or, if that
# fails, a 100% percent chance to have the contents of anotherchest.nbt.
Block(-1,-3,-4,LOG:14)
Block(2,-3,-3,LOG:14)
Block(1,-3,-2,LOG:14)
Block(4,-3,-2,LOG:14)
Block(-1,-3,-1,LOG:14)
Block(1,-3,-1,LOG:14)
Block(2,-3,-1,LOG:14)
Block(4,-3,0,LOG:14)
Block(1,-3,1,LOG:14)
Block(-1,-2,-4,LOG:14)
Block(0,-2,-3,LOG:14)
Block(2,-2,-3,LOG:14)
Block(1,-2,-2,LOG:14)
Block(4,-2,-2,LOG:14)
Block(0,-2,-1,LOG:14)
Block(1,-2,-1,LOG:14)
Block(2,-2,-1,LOG:14)
Block(3,-2,-1,LOG:14)
Block(1,-2,0,LOG:14)
Block(4,-2,0,LOG:14)
Block(0,-1,-3,LOG:14)
Block(2,-1,-3,LOG:14)
Block(1,-1,-2,LOG:14)
Block(2,-1,-2,LOG:14)
Block(1,-1,-1,LOG:14)
Block(2,-1,-1,LOG:14)
Block(3,-1,-1,LOG:14)
Block(0,0,-3,LOG:14)
Block(2,0,-3,LOG:14)
Block(1,0,-2,LOG:14)
Block(2,0,-2,LOG:14)
Block(1,0,-1,LOG:14)
Block(2,0,-1,LOG:14)
Block(3,0,-1,LOG:14)
Block(1,1,-2,LOG:14)
Block(2,1,-2,LOG:14)
Block(1,1,-1,LOG:14)
Block(2,1,-1,LOG:14)
Block(1,2,-2,LOG:14)
Block(2,2,-2,LOG:14)
Block(1,2,-1,LOG:14)
Block(2,2,-1,LOG:14)
Block(1,3,-2,LOG:14)
Block(2,3,-2,LOG:14)
Block(1,3,-1,LOG:14)
Block(2,3,-1,LOG:14)
Block(1,4,-2,LOG:14)
Block(2,4,-2,LOG:14)
Block(1,4,-1,LOG:14)
Block(2,4,-1,LOG:14)
Block(1,5,-2,LOG:14)
Block(2,5,-2,LOG:14)
Block(1,5,-1,LOG:14)
Block(2,5,-1,LOG:14)
Block(1,6,-2,LOG:14)
Block(2,6,-2,LOG:14)
Block(1,6,-1,LOG:14)
Block(2,6,-1,LOG:14)
Block(1,7,-2,LOG:14)
Block(2,7,-2,LOG:14)
Block(1,7,-1,LOG:14)
Block(2,7,-1,LOG:14)
Block(1,8,-2,LOG:14)
Block(2,8,-2,LOG:14)
Block(1,8,-1,LOG:14)
Block(2,8,-1,LOG:14)
Block(1,9,-2,LOG:14)
Block(2,9,-2,LOG:14)
Block(1,9,-1,LOG:14)
Block(2,9,-1,LOG:14)
Block(1,10,-2,LOG:14)
Block(2,10,-2,LOG:14)
Block(1,10,-1,LOG:14)
Block(2,10,-1,LOG:14)
Block(1,11,-2,LOG:14)
Block(2,11,-2,LOG:14)
Block(1,11,-1,LOG:14)
Block(2,11,-1,LOG:14)
Block(1,12,-2,LOG:14)
Block(2,12,-2,LOG:14)
Block(1,12,-1,LOG:14)
Block(2,12,-1,LOG:14)
Block(1,13,-2,LOG:14)
Block(2,13,-2,LOG:14)
Block(1,13,-1,LOG:14)
Block(2,13,-1,LOG:14)
Block(1,14,-2,LOG:14)
Block(2,14,-2,LOG:14)
Block(1,14,-1,LOG:14)
Block(2,14,-1,LOG:14)
Block(1,15,-2,LOG:14)
Block(2,15,-2,LOG:14)
Block(1,15,-1,LOG:14)
Block(2,15,-1,LOG:14)
Block(1,16,-2,LOG:14)
Block(2,16,-2,LOG:14)
Block(1,16,-1,LOG:14)
Block(2,16,-1,LOG:14)
Block(1,17,-2,LOG:14)
Block(2,17,-2,LOG:14)
Block(1,17,-1,LOG:14)
Block(2,17,-1,LOG:14)
Block(1,18,-2,LOG:14)
Block(2,18,-2,LOG:14)
Block(1,18,-1,LOG:14)
Block(2,18,-1,LOG:14)
Block(1,19,-2,LOG:14)
Block(2,19,-2,LOG:14)
Block(1,19,-1,LOG:14)
Block(2,19,-1,LOG:14)
Block(1,20,-2,LOG:14)
Block(2,20,-2,LOG:14)
Block(1,20,-1,LOG:14)
Block(2,20,-1,LOG:14)
Block(1,21,-2,LOG:14)
Block(2,21,-2,LOG:14)
Block(1,21,-1,LOG:14)
Block(2,21,-1,LOG:14)
Block(1,22,-2,LOG:14)
Block(2,22,-2,LOG:14)
Block(1,22,-1,LOG:14)
Block(2,22,-1,LOG:14)
Block(1,23,-2,LOG:14)
Block(2,23,-2,LOG:14)
Block(2,23,-1,LOG:14)
Block(1,24,-2,LOG:14)
Block(2,24,-2,LOG:14)
Block(2,24,-1,LOG:14)
Block(1,25,-2,LOG:14)
Block(2,25,-2,LOG:14)
Block(2,25,-1,LOG:14)
Block(1,26,-2,LOG:14)
Block(2,26,-2,LOG:14)
Block(2,26,-1,LOG:14)
Block(1,27,-2,LOG:14)
Block(2,27,-2,LOG:14)
Block(2,27,-1,LOG:14)
Block(1,28,-2,LOG:14)
Block(2,28,-2,LOG:14)
Block(2,28,-1,LOG:14)
Block(1,29,-2,LOG:14)
Block(2,29,-2,LOG:14)
Block(2,29,-1,LOG:14)
Block(1,30,-2,LOG:14)
Block(2,30,-2,LOG:14)
Block(2,30,-1,LOG:14)
Block(1,31,-2,LOG:14)
Block(2,31,-1,LOG:14)
Block(1,32,-2,LOG:14)
Block(2,32,-1,LOG:14)
Block(1,33,-2,LOG:14)
Block(2,33,-1,LOG:14)
Block(1,34,-2,LOG:14)
Block(2,34,-1,LOG:14)
Block(1,35,-2,LOG:14)
Block(2,35,-1,LOG:14)
Block(-2,36,-5,LEAVES:4)
Block(-2,36,-4,LEAVES:4)
Block(0,36,-3,LOG:14)
Block(-4,36,-2,LEAVES:4)
Block(-3,36,-2,LEAVES:4)
Block(1,36,-2,LOG:14)
Block(2,36,-1,LOG:14)
Block(3,36,0,LEAVES:4)
Block(2,36,1,LEAVES:4)
Block(3,36,1,LEAVES:4)
Block(0,37,-7,LEAVES:4)
Block(-2,37,-6,LEAVES:4)
Block(-2,37,-5,LEAVES:4)
Block(0,37,-5,LEAVES:4)
Block(-3,37,-3,LEAVES:4)
Block(-1,37,-3,LOG:14)
Block(-5,37,-2,LEAVES:4)
Block(1,37,-2,LOG:14)
Block(2,37,-1,LOG:14)
Block(-5,37,0,LEAVES:4)
Block(1,37,0,LEAVES:4)
Block(2,37,0,LEAVES:4)
Block(0,37,3,LEAVES:4)
Block(1,37,3,LEAVES:4)
Block(5,37,3,LEAVES:4)
Block(-2,38,-7,LEAVES:4)
Block(-1,38,-7,LEAVES:4)
Block(-1,38,-6,LEAVES:4)
Block(0,38,-6,LEAVES:4)
Block(1,38,-6,LEAVES:4)
Block(-5,38,-5,LEAVES:4)
Block(-4,38,-5,LEAVES:4)
Block(-2,38,-5,LEAVES:4)
Block(-4,38,-4,LEAVES:4)
Block(-2,38,-4,LOG:14)
Block(-1,38,-4,LEAVES:4)
Block(-5,38,-3,LEAVES:4)
Block(-6,38,-2,LEAVES:4)
Block(-4,38,-2,LEAVES:4)
Block(-3,38,-2,LEAVES:4)
Block(-2,38,-2,LOG:14)
Block(1,38,-2,LOG:14)
Block(3,38,-1,LEAVES:4)
Block(2,38,0,LOG:14)
Block(3,38,0,LEAVES:4)
Block(-4,38,1,LEAVES:4)
Block(3,38,1,LEAVES:4)
Block(5,38,2,LEAVES:4)
Block(-2,38,3,LEAVES:4)
Block(0,38,3,LEAVES:4)
Block(1,38,3,LEAVES:4)
Block(2,38,3,LEAVES:4)
Block(3,38,3,LEAVES:4)
Block(0,38,4,LEAVES:4)
Block(-2,38,5,LEAVES:4)
Block(3,39,-9,LEAVES:4)
Block(-2,39,-8,LEAVES:4)
Block(-1,39,-8,LEAVES:4)
Block(2,39,-8,LEAVES:4)
Block(-3,39,-7,LEAVES:4)
Block(-1,39,-7,LEAVES:4)
Block(-2,39,-6,LEAVES:4)
Block(-1,39,-6,LEAVES:4)
Block(-5,39,-5,LEAVES:4)
Block(-4,39,-5,LEAVES:4)
Block(-3,39,-5,LEAVES:4)
Block(-2,39,-5,LOG:14)
Block(-1,39,-5,LEAVES:4)
Block(-4,39,-4,LEAVES:4)
Block(-3,39,-4,LEAVES:4)
Block(-2,39,-4,LEAVES:4)
Block(-1,39,-4,LEAVES:4)
Block(-4,39,-3,LEAVES:4)
Block(-2,39,-3,LEAVES:4)
Block(-1,39,-3,LEAVES:4)
Block(1,39,-3,LOG:14)
Block(-5,39,-2,LEAVES:4)
Block(-3,39,-2,LOG:14)
Block(-2,39,-2,LEAVES:4)
Block(-1,39,-2,LEAVES:4)
Block(1,39,-2,LOG:14)
Block(2,39,-2,LOG:14)
Block(-6,39,-1,LEAVES:4)
Block(-5,39,-1,LEAVES:4)
Block(-3,39,-1,LEAVES:4)
Block(-1,39,-1,LEAVES:4)
Block(2,39,-1,LEAVES:4)
Block(-4,39,0,LEAVES:4)
Block(-3,39,0,LEAVES:4)
Block(-2,39,0,LEAVES:4)
Block(-1,39,0,LEAVES:4)
Block(3,39,0,LEAVES:4)
Block(4,39,0,LEAVES:4)
Block(5,39,0,LEAVES:4)
Block(-1,39,1,LEAVES:4)
Block(0,39,1,LEAVES:4)
Block(1,39,1,LOG:14)
Block(2,39,1,LEAVES:4)
Block(3,39,1,LOG:14)
Block(4,39,1,LEAVES:4)
Block(6,39,1,LEAVES:4)
Block(0,39,2,LEAVES:4)
Block(1,39,2,LOG:14)
Block(3,39,2,LEAVES:4)
Block(6,39,2,LEAVES:4)
Block(0,39,3,LEAVES:4)
Block(1,39,3,LEAVES:4)
Block(3,39,3,LEAVES:4)
Block(4,39,3,LEAVES:4)
Block(-1,39,4,LEAVES:4)
Block(2,39,4,LEAVES:4)
Block(3,39,4,LEAVES:4)
Block(0,39,5,LEAVES:4)
Block(1,40,-8,LEAVES:4)
Block(-4,40,-5,LEAVES:4)
Block(-5,40,-4,LEAVES:4)
Block(-4,40,-4,LEAVES:4)
Block(-3,40,-4,LEAVES:4)
Block(2,40,-4,LOG:14)
Block(-3,40,-3,LEAVES:4)
Block(-2,40,-3,LEAVES:4)
Block(-1,40,-3,LEAVES:4)
Block(0,40,-3,LEAVES:4)
Block(-2,40,-2,LEAVES:4)
Block(1,40,-2,LOG:14)
Block(2,40,-2,LOG:14)
Block(3,40,-1,LEAVES:4)
Block(5,40,-1,LEAVES:4)
Block(-3,40,0,LEAVES:4)
Block(-1,40,0,LEAVES:4)
Block(-1,40,1,LEAVES:4)
Block(0,40,1,LEAVES:4)
Block(1,40,1,LEAVES:4)
Block(2,40,2,LEAVES:4)
Block(3,40,2,LEAVES:4)
Block(-1,40,3,LEAVES:4)
Block(0,40,3,LOG:14)
Block(1,40,3,LEAVES:4)
Block(3,40,3,LEAVES:4)
Block(5,40,3,LEAVES:4)
Block(0,40,4,LEAVES:4)
Block(3,40,4,LEAVES:4)
Block(0,40,5,LEAVES:4)
Block(0,41,-9,LEAVES:4)
Block(-1,41,-8,LEAVES:4)
Block(1,41,-8,LEAVES:4)
Block(2,41,-8,LEAVES:4)
Block(4,41,-8,LEAVES:4)
Block(5,41,-8,LEAVES:4)
Block(-1,41,-7,LEAVES:4)
Block(0,41,-7,LEAVES:4)
Block(4,41,-7,LEAVES:4)
Block(-1,41,-6,LEAVES:4)
Block(2,41,-6,LEAVES:4)
Block(4,41,-6,LEAVES:4)
Block(-1,41,-5,LEAVES:4)
Block(-2,41,-4,LEAVES:4)
Block(2,41,-4,LOG:14)
Block(-1,41,-3,LEAVES:4)
Block(1,41,-2,LOG:14)
Block(3,41,-2,LOG:14)
Block(-2,41,-1,LEAVES:4)
Block(1,41,-1,LEAVES:4)
Block(-2,41,0,LEAVES:4)
Block(0,41,0,LEAVES:4)
Block(1,41,0,LEAVES:4)
Block(4,41,0,LEAVES:4)
Block(-2,41,1,LEAVES:4)
Block(0,41,1,LEAVES:4)
Block(4,41,1,LEAVES:4)
Block(0,41,2,LEAVES:4)
Block(3,41,2,LEAVES:4)
Block(0,41,3,LEAVES:4)
Block(1,41,3,LEAVES:4)
Block(2,41,3,LEAVES:4)
Block(3,41,3,LEAVES:4)
Block(-3,41,4,LEAVES:4)
Block(-2,41,4,LEAVES:4)
Block(1,41,4,LEAVES:4)
Block(3,41,4,LEAVES:4)
Block(-2,41,5,LEAVES:4)
Block(-1,41,6,LEAVES:4)
Block(1,42,-11,LEAVES:4)
Block(2,42,-11,LEAVES:4)
Block(1,42,-10,LEAVES:4)
Block(2,42,-10,LEAVES:4)
Block(7,42,-10,LEAVES:4)
Block(0,42,-9,LEAVES:4)
Block(4,42,-9,LEAVES:4)
Block(-1,42,-8,LEAVES:4)
Block(0,42,-8,LEAVES:4)
Block(2,42,-8,LOG:14)
Block(3,42,-8,LEAVES:4)
Block(5,42,-8,LEAVES:4)
Block(1,42,-7,LEAVES:4)
Block(2,42,-7,LOG:14)
Block(3,42,-7,LEAVES:4)
Block(7,42,-7,LEAVES:4)
Block(3,42,-6,LEAVES:4)
Block(6,42,-6,LEAVES:4)
Block(-2,42,-5,LEAVES:4)
Block(2,42,-5,LEAVES:4)
Block(3,42,-5,LOG:14)
Block(8,42,-4,LEAVES:4)
Block(9,42,-4,LEAVES:4)
Block(10,42,-4,LEAVES:4)
Block(9,42,-3,LEAVES:4)
Block(1,42,-2,LOG:14)
Block(4,42,-2,LOG:14)
Block(5,42,-1,LOG:14)
Block(3,42,0,LEAVES:4)
Block(11,42,0,LEAVES:4)
Block(3,42,1,LEAVES:4)
Block(9,42,1,LEAVES:4)
Block(10,42,1,LEAVES:4)
Block(11,42,1,LEAVES:4)
Block(-1,42,2,LEAVES:4)
Block(10,42,2,LEAVES:4)
Block(11,42,2,LEAVES:4)
Block(-2,42,4,LEAVES:4)
Block(0,42,4,LEAVES:4)
Block(-2,42,5,LEAVES:4)
Block(1,43,-11,LEAVES:4)
Block(2,43,-11,LEAVES:4)
Block(7,43,-10,LEAVES:4)
Block(1,43,-9,LEAVES:4)
Block(0,43,-8,LEAVES:4)
Block(2,43,-8,LEAVES:4)
Block(5,43,-8,LEAVES:4)
Block(7,43,-8,LEAVES:4)
Block(4,43,-7,LOG:14)
Block(7,43,-7,LEAVES:4)
Block(-2,43,-6,LEAVES:4)
Block(2,43,-6,LEAVES:4)
Block(3,43,-6,LOG:14)
Block(5,43,-6,LEAVES:4)
Block(8,43,-6,LEAVES:4)
Block(11,43,-6,LEAVES:4)
Block(-3,43,-5,LEAVES:4)
Block(6,43,-5,LEAVES:4)
Block(9,43,-5,LEAVES:4)
Block(11,43,-5,LEAVES:4)
Block(5,43,-4,LEAVES:4)
Block(7,43,-4,LEAVES:4)
Block(9,43,-4,LEAVES:4)
Block(10,43,-4,LEAVES:4)
Block(0,43,-3,LOG:14)
Block(2,43,-3,LOG:14)
Block(5,43,-3,LOG:14)
Block(7,43,-3,LEAVES:4)
Block(11,43,-3,LEAVES:4)
Block(8,43,-2,LOG:14)
Block(10,43,-2,LEAVES:4)
Block(-8,43,-1,LEAVES:12)
Block(2,43,-1,LOG:14)
Block(6,43,-1,LOG:14)
Block(7,43,-1,LOG:14)
Block(9,43,-1,LEAVES:4)
Block(11,43,-1,LEAVES:4)
Block(-7,43,0,LEAVES:12)
Block(8,43,0,LOG:14)
Block(11,43,0,LEAVES:4)
Block(6,43,1,LEAVES:4)
Block(8,43,1,LEAVES:4)
Block(12,43,1,LEAVES:4)
Block(8,43,2,LEAVES:4)
Block(9,43,2,LEAVES:4)
Block(-1,43,3,LEAVES:4)
Block(0,43,3,LEAVES:4)
Block(7,43,3,LEAVES:4)
Block(4,44,-11,LEAVES:4)
Block(5,44,-10,LEAVES:4)
Block(6,44,-10,LEAVES:4)
Block(2,44,-9,LEAVES:4)
Block(3,44,-9,LEAVES:4)
Block(4,44,-9,LEAVES:4)
Block(6,44,-9,LEAVES:4)
Block(7,44,-9,LEAVES:4)
Block(2,44,-8,LEAVES:4)
Block(3,44,-8,LEAVES:4)
Block(5,44,-8,LOG:14)
Block(7,44,-8,LEAVES:4)
Block(2,44,-7,LEAVES:4)
Block(5,44,-7,LEAVES:4)
Block(8,44,-7,LEAVES:4)
Block(-4,44,-6,LEAVES:4)
Block(0,44,-6,LEAVES:4)
Block(2,44,-6,LEAVES:4)
Block(8,44,-6,LEAVES:4)
Block(11,44,-6,LEAVES:4)
Block(-3,44,-5,LEAVES:4)
Block(-2,44,-5,LEAVES:4)
Block(4,44,-5,LEAVES:4)
Block(5,44,-5,LEAVES:4)
Block(6,44,-5,LEAVES:4)
Block(-4,44,-4,LEAVES:4)
Block(-1,44,-4,LEAVES:4)
Block(2,44,-4,LOG:14)
Block(6,44,-4,LOG:14)
Block(8,44,-4,LEAVES:4)
Block(9,44,-4,LEAVES:4)
Block(10,44,-4,LEAVES:4)
Block(11,44,-4,LEAVES:4)
Block(12,44,-4,LEAVES:4)
Block(13,44,-4,LEAVES:4)
Block(-8,44,-3,LEAVES:12)
Block(-1,44,-3,LOG:14)
Block(0,44,-3,LEAVES:4)
Block(6,44,-3,LEAVES:4)
Block(7,44,-3,LEAVES:4)
Block(8,44,-3,LEAVES:4)
Block(9,44,-3,LOG:14)
Block(10,44,-3,LEAVES:4)
Block(-9,44,-2,LEAVES:4)
Block(-7,44,-1,LEAVES:12)
Block(1,44,-1,LOG:14)
Block(-7,44,0,LEAVES:12)
Block(-6,44,0,LEAVES:12)
Block(3,44,0,LOG:14)
Block(6,44,0,LOG:14)
Block(9,44,0,LOG:14)
Block(11,44,0,LEAVES:4)
Block(-8,44,1,LEAVES:12)
Block(-6,44,1,LEAVES:12)
Block(7,44,1,LEAVES:4)
Block(10,44,1,LEAVES:4)
Block(13,44,1,LEAVES:4)
Block(6,44,2,LEAVES:4)
Block(7,44,2,LEAVES:4)
Block(8,44,2,LEAVES:4)
Block(10,44,2,LEAVES:4)
Block(5,44,3,LEAVES:4)
Block(5,44,4,LEAVES:4)
Block(3,45,-10,LEAVES:4)
Block(3,45,-9,LEAVES:4)
Block(1,45,-8,LEAVES:4)
Block(2,45,-8,LEAVES:4)
Block(3,45,-8,LEAVES:4)
Block(5,45,-8,LEAVES:4)
Block(6,45,-8,LEAVES:4)
Block(7,45,-8,LEAVES:4)
Block(-3,45,-7,LEAVES:4)
Block(2,45,-7,LEAVES:4)
Block(5,45,-7,LEAVES:4)
Block(7,45,-7,LEAVES:4)
Block(9,45,-7,LEAVES:4)
Block(-2,45,-6,LEAVES:4)
Block(5,45,-6,LEAVES:4)
Block(7,45,-6,LEAVES:4)
Block(8,45,-6,LEAVES:4)
Block(11,45,-6,LEAVES:4)
Block(-4,45,-5,LEAVES:4)
Block(-3,45,-5,LEAVES:4)
Block(1,45,-5,LEAVES:4)
Block(7,45,-5,LOG:14)
Block(8,45,-5,LEAVES:4)
Block(9,45,-5,LEAVES:4)
Block(10,45,-5,LEAVES:4)
Block(13,45,-5,LEAVES:4)
Block(-1,45,-4,LOG:14)
Block(0,45,-4,LEAVES:4)
Block(3,45,-4,LOG:14)
Block(5,45,-4,LEAVES:4)
Block(6,45,-4,LEAVES:4)
Block(8,45,-4,LEAVES:4)
Block(9,45,-4,LEAVES:4)
Block(10,45,-4,LOG:14)
Block(13,45,-4,LEAVES:4)
Block(-3,45,-3,LEAVES:4)
Block(7,45,-3,LEAVES:4)
Block(10,45,-3,LEAVES:4)
Block(11,45,-3,LEAVES:4)
Block(12,45,-3,LEAVES:4)
Block(13,45,-3,LEAVES:4)
Block(-9,45,-2,LEAVES:4)
Block(-7,45,-2,LEAVES:12)
Block(-6,45,-2,LEAVES:12)
Block(-2,45,-2,LOG:14)
Block(8,45,-2,LEAVES:4)
Block(10,45,-2,LEAVES:4)
Block(11,45,-2,LEAVES:4)
Block(-9,45,-1,LEAVES:4)
Block(-7,45,-1,LOG:14)
Block(-6,45,-1,LEAVES:12)
Block(-4,45,-1,LOG:14)
Block(-3,45,-1,LOG:14)
Block(1,45,-1,LOG:14)
Block(6,45,-1,LEAVES:4)
Block(7,45,-1,LEAVES:4)
Block(9,45,-1,LEAVES:4)
Block(10,45,-1,LEAVES:4)
Block(-6,45,0,LEAVES:12)
Block(0,45,0,LOG:14)
Block(3,45,0,LOG:14)
Block(8,45,0,LEAVES:4)
Block(10,45,0,LEAVES:4)
Block(-8,45,1,LEAVES:12)
Block(6,45,1,LEAVES:4)
Block(7,45,1,LOG:14)
Block(8,45,1,LEAVES:4)
Block(10,45,1,LOG:14)
Block(5,45,2,LEAVES:4)
Block(7,45,2,LEAVES:4)
Block(10,45,2,LEAVES:4)
Block(6,45,3,LEAVES:4)
Block(8,45,3,LEAVES:4)
Block(9,45,3,LEAVES:4)
Block(10,45,3,LEAVES:4)
Block(7,45,4,LEAVES:4)
Block(9,45,4,LEAVES:4)
Block(10,45,4,LEAVES:4)
Block(6,45,5,LEAVES:4)
Block(6,46,-10,LEAVES:4)
Block(3,46,-9,LEAVES:4)
Block(4,46,-9,LEAVES:4)
Block(-2,46,-7,LEAVES:4)
Block(-1,46,-7,LEAVES:4)
Block(6,46,-7,LEAVES:4)
Block(-5,46,-6,LEAVES:4)
Block(-4,46,-6,LEAVES:4)
Block(-3,46,-6,LEAVES:4)
Block(0,46,-6,LEAVES:4)
Block(7,46,-6,LEAVES:4)
Block(12,46,-6,LEAVES:4)
Block(-4,46,-5,LEAVES:4)
Block(-2,46,-5,LOG:14)
Block(3,46,-5,LOG:14)
Block(4,46,-5,LEAVES:4)
Block(7,46,-5,LEAVES:4)
Block(10,46,-5,LEAVES:4)
Block(-4,46,-4,LEAVES:4)
Block(0,46,-4,LEAVES:4)
Block(9,46,-4,LEAVES:4)
Block(10,46,-4,LEAVES:4)
Block(-6,46,-3,LEAVES:12)
Block(13,46,-3,LEAVES:4)
Block(-7,46,-2,LEAVES:12)
Block(-6,46,-2,LEAVES:12)
Block(-5,46,-2,LEAVES:12)
Block(-1,46,-2,LEAVES:4)
Block(7,46,-2,LEAVES:4)
Block(10,46,-2,LEAVES:4)
Block(11,46,-2,LEAVES:4)
Block(-8,46,-1,LEAVES:12)
Block(-6,46,-1,LOG:14)
Block(-5,46,-1,LOG:14)
Block(-4,46,-1,LEAVES:12)
Block(7,46,-1,LEAVES:4)
Block(9,46,-1,LEAVES:4)
Block(10,46,-1,LEAVES:4)
Block(11,46,-1,LEAVES:4)
Block(-7,46,0,LEAVES:12)
Block(0,46,0,LOG:14)
Block(5,46,0,LEAVES:4)
Block(9,46,0,LEAVES:4)
Block(11,46,0,LEAVES:4)
Block(-6,46,1,LEAVES:12)
Block(4,46,1,LOG:14)
Block(8,46,1,LEAVES:4)
Block(9,46,1,LEAVES:4)
Block(4,46,2,LEAVES:4)
Block(6,46,2,LEAVES:4)
Block(7,46,2,LOG:14)
Block(4,46,3,LEAVES:4)
Block(8,46,3,LEAVES:4)
Block(9,46,3,LEAVES:4)
Block(10,46,3,LEAVES:4)
Block(6,46,4,LEAVES:4)
Block(6,46,5,LEAVES:4)
Block(7,46,5,LEAVES:4)
Block(8,46,5,LEAVES:4)
Block(6,47,-9,LEAVES:4)
Block(-2,47,-8,LEAVES:4)
Block(5,47,-8,LEAVES:4)
Block(7,47,-7,LEAVES:4)
Block(8,47,-7,LEAVES:4)
Block(10,47,-6,LEAVES:4)
Block(11,47,-6,LEAVES:4)
Block(-3,47,-5,LOG:14)
Block(-2,47,-5,LEAVES:4)
Block(-1,47,-5,LOG:14)
Block(1,47,-5,LEAVES:4)
Block(4,47,-5,LOG:14)
Block(7,47,-5,LEAVES:4)
Block(10,47,-5,LEAVES:4)
Block(-5,47,-4,LEAVES:12)
Block(-2,47,-4,LEAVES:4)
Block(7,47,-4,LEAVES:4)
Block(8,47,-4,LEAVES:4)
Block(11,47,-4,LEAVES:4)
Block(12,47,-4,LEAVES:4)
Block(-7,47,-3,LEAVES:12)
Block(-6,47,-3,LEAVES:12)
Block(-4,47,-3,LEAVES:12)
Block(5,47,-3,LEAVES:4)
Block(10,47,-3,LEAVES:4)
Block(-8,47,-2,LEAVES:12)
Block(-7,47,-2,LEAVES:12)
Block(-6,47,-2,LOG:14)
Block(-5,47,-2,LEAVES:12)
Block(-8,47,-1,LEAVES:12)
Block(-7,47,-1,LEAVES:12)
Block(-6,47,-1,LEAVES:12)
Block(-4,47,-1,LEAVES:12)
Block(-1,47,-1,LOG:14)
Block(7,47,-1,LEAVES:4)
Block(8,47,-1,LEAVES:4)
Block(-7,47,0,LEAVES:12)
Block(-6,47,0,LEAVES:12)
Block(10,47,0,LEAVES:4)
Block(0,47,1,LOG:14)
Block(4,47,1,LOG:14)
Block(8,47,1,LEAVES:4)
Block(10,47,1,LEAVES:4)
Block(12,47,1,LEAVES:4)
Block(4,47,2,LEAVES:4)
Block(7,47,2,LEAVES:4)
Block(10,47,2,LEAVES:4)
Block(4,47,3,LEAVES:4)
Block(6,47,3,LEAVES:4)
Block(9,47,3,LEAVES:4)
Block(12,47,3,LEAVES:4)
Block(5,47,4,LEAVES:4)
Block(8,47,5,LEAVES:4)
Block(-2,48,-7,LEAVES:4)
Block(-3,48,-6,LOG:14)
Block(-1,48,-6,LOG:14)
Block(5,48,-6,LOG:14)
Block(-2,48,-5,LEAVES:4)
Block(7,48,-5,LEAVES:4)
Block(8,48,-5,LEAVES:4)
Block(9,48,-5,LEAVES:4)
Block(-2,48,-4,LEAVES:4)
Block(4,48,-4,LOG:14)
Block(7,48,-4,LEAVES:4)
Block(-8,48,-2,LEAVES:12)
Block(-7,48,-2,LEAVES:12)
Block(-6,48,-2,LEAVES:12)
Block(-4,48,-1,LEAVES:12)
Block(-2,48,-1,LOG:14)
Block(-7,48,0,LEAVES:12)
Block(-6,48,0,LEAVES:12)
Block(5,48,0,LOG:14)
Block(1,48,1,LOG:14)
Block(10,48,1,LEAVES:4)
Block(11,48,1,LEAVES:4)
Block(5,48,2,LOG:14)
Block(6,48,2,LEAVES:4)
Block(8,48,2,LEAVES:4)
Block(5,48,3,LEAVES:4)
Block(7,48,3,LEAVES:12)
Block(9,48,3,LEAVES:4)
Block(5,48,4,LEAVES:4)
Block(6,48,5,LEAVES:12)
Block(4,49,-7,LOG:14)
Block(-4,49,-6,LOG:14)
Block(-2,49,-6,LEAVES:4)
Block(0,49,-6,LOG:14)
Block(6,49,-6,LOG:14)
Block(-1,49,-5,LEAVES:12)
Block(-2,49,-4,LEAVES:12)
Block(-1,49,-4,LEAVES:12)
Block(0,49,-4,LEAVES:12)
Block(4,49,-4,LOG:14)
Block(0,49,-3,LEAVES:12)
Block(-6,49,-2,LEAVES:12)
Block(-5,49,-2,LEAVES:12)
Block(-3,49,-2,LOG:14)
Block(0,49,-2,LEAVES:12)
Block(1,49,-2,LEAVES:12)
Block(-7,49,-1,LEAVES:12)
Block(-5,49,-1,LEAVES:12)
Block(1,49,-1,LEAVES:12)
Block(-2,49,0,LOG:14)
Block(2,49,0,LOG:14)
Block(6,49,0,LOG:14)
Block(7,49,0,LOG:14)
Block(7,49,1,LEAVES:4)
Block(1,49,2,LOG:14)
Block(6,49,2,LEAVES:12)
Block(7,49,2,LEAVES:12)
Block(6,49,3,LOG:14)
Block(7,49,3,LEAVES:4)
Block(6,49,4,LEAVES:12)
Block(7,49,4,LEAVES:12)
Block(5,49,5,LEAVES:12)
Block(6,50,-10,LEAVES:12)
Block(4,50,-9,LEAVES:12)
Block(5,50,-9,LEAVES:12)
Block(4,50,-8,LOG:14)
Block(-5,50,-7,LEAVES:12)
Block(-4,50,-7,LOG:14)
Block(0,50,-7,LOG:14)
Block(7,50,-6,LOG:14)
Block(0,50,-5,LOG:14)
Block(1,50,-5,LEAVES:12)
Block(-6,50,-4,LEAVES:12)
Block(-4,50,-4,LEAVES:12)
Block(-2,50,-4,LEAVES:12)
Block(-1,50,-4,LEAVES:12)
Block(0,50,-4,LEAVES:12)
Block(1,50,-4,LEAVES:12)
Block(4,50,-4,LEAVES:12)
Block(-5,50,-3,LEAVES:12)
Block(-4,50,-3,LOG:14)
Block(2,50,-3,LEAVES:12)
Block(4,50,-3,LEAVES:12)
Block(5,50,-3,LOG:14)
Block(-5,50,-2,LEAVES:12)
Block(-1,50,-2,LEAVES:12)
Block(0,50,-2,LEAVES:12)
Block(2,50,-2,LOG:14)
Block(3,50,-2,LEAVES:12)
Block(8,50,-2,LEAVES:12)
Block(9,50,-2,LEAVES:12)
Block(0,50,-1,LEAVES:12)
Block(1,50,-1,LEAVES:12)
Block(2,50,-1,LOG:14)
Block(3,50,-1,LEAVES:12)
Block(7,50,-1,LOG:14)
Block(9,50,-1,LEAVES:12)
Block(-5,50,0,LEAVES:12)
Block(-4,50,0,LEAVES:12)
Block(-3,50,0,LOG:14)
Block(8,50,0,LEAVES:12)
Block(-3,50,1,LEAVES:12)
Block(1,50,2,LOG:14)
Block(2,50,2,LEAVES:12)
Block(7,50,2,LEAVES:12)
Block(-1,50,3,LEAVES:12)
Block(0,50,3,LEAVES:12)
Block(1,50,3,LEAVES:12)
Block(2,50,3,LEAVES:12)
Block(6,50,3,LEAVES:12)
Block(0,50,4,LEAVES:12)
Block(1,50,4,LEAVES:12)
Block(2,50,4,LEAVES:12)
Block(6,50,4,LEAVES:12)
Block(7,50,4,LOG:14)
Block(8,50,4,LEAVES:12)
Block(9,50,4,LEAVES:12)
Block(-1,50,5,LEAVES:12)
Block(8,50,5,LEAVES:12)
Block(6,51,-11,LEAVES:4)
Block(-5,51,-10,LEAVES:4)
Block(3,51,-10,LEAVES:12)
Block(4,51,-10,LEAVES:12)
Block(-7,51,-9,LEAVES:4)
Block(-5,51,-9,LEAVES:12)
Block(-4,51,-9,LEAVES:12)
Block(1,51,-9,LEAVES:12)
Block(3,51,-9,LEAVES:12)
Block(4,51,-9,LEAVES:12)
Block(5,51,-9,LEAVES:12)
Block(-7,51,-8,LEAVES:4)
Block(1,51,-8,LEAVES:12)
Block(2,51,-8,LEAVES:12)
Block(4,51,-8,LOG:14)
Block(5,51,-8,LEAVES:12)
Block(-5,51,-7,LOG:14)
Block(-3,51,-7,LEAVES:12)
Block(1,51,-7,LOG:14)
Block(2,51,-7,LEAVES:12)
Block(3,51,-7,LEAVES:12)
Block(8,51,-7,LOG:14)
Block(-6,51,-6,LEAVES:4)
Block(-1,51,-6,LEAVES:12)
Block(0,51,-6,LEAVES:12)
Block(-6,51,-5,LEAVES:12)
Block(-5,51,-5,LEAVES:12)
Block(-1,51,-5,LEAVES:12)
Block(2,51,-5,LEAVES:12)
Block(3,51,-5,LEAVES:12)
Block(-7,51,-4,LEAVES:4)
Block(-6,51,-4,LEAVES:12)
Block(-5,51,-4,LEAVES:12)
Block(-2,51,-4,LEAVES:12)
Block(-1,51,-4,LOG:14)
Block(0,51,-4,LEAVES:12)
Block(1,51,-4,LEAVES:12)
Block(3,51,-4,LEAVES:12)
Block(-7,51,-3,LEAVES:4)
Block(-4,51,-3,LOG:14)
Block(-1,51,-3,LEAVES:12)
Block(0,51,-3,LEAVES:12)
Block(1,51,-3,LEAVES:12)
Block(3,51,-3,LOG:14)
Block(4,51,-3,LEAVES:12)
Block(5,51,-3,LOG:14)
Block(7,51,-3,LEAVES:12)
Block(-3,51,-2,LEAVES:12)
Block(-2,51,-2,LEAVES:12)
Block(-1,51,-2,LEAVES:12)
Block(0,51,-2,LEAVES:12)
Block(1,51,-2,LOG:14)
Block(3,51,-2,LEAVES:12)
Block(-6,51,-1,LEAVES:12)
Block(-4,51,-1,LEAVES:12)
Block(-3,51,-1,LEAVES:12)
Block(0,51,-1,LEAVES:12)
Block(1,51,-1,LEAVES:12)
Block(2,51,-1,LEAVES:12)
Block(3,51,-1,LEAVES:12)
Block(4,51,-1,LEAVES:12)
Block(6,51,-1,LEAVES:12)
Block(7,51,-1,LOG:14)
Block(8,51,-1,LEAVES:12)
Block(9,51,-1,LEAVES:12)
Block(10,51,-1,LEAVES:4)
Block(10,51,0,LEAVES:4)
Block(-4,51,1,LEAVES:12)
Block(-3,51,1,LOG:14)
Block(0,51,1,LEAVES:12)
Block(2,51,1,LEAVES:12)
Block(-4,51,2,LEAVES:12)
Block(-1,51,2,LEAVES:12)
Block(0,51,2,LEAVES:12)
Block(1,51,2,LEAVES:12)
Block(2,51,2,LEAVES:12)
Block(-4,51,3,LEAVES:12)
Block(-3,51,3,LEAVES:12)
Block(-1,51,3,LEAVES:12)
Block(0,51,3,LOG:14)
Block(-1,51,4,LEAVES:12)
Block(1,51,4,LEAVES:12)
Block(3,51,4,LEAVES:12)
Block(5,51,4,LEAVES:12)
Block(6,51,4,LEAVES:12)
Block(8,51,4,LEAVES:12)
Block(-1,51,5,LEAVES:12)
Block(0,51,5,LEAVES:12)
Block(8,51,5,LEAVES:12)
Block(-2,51,6,LEAVES:12)
Block(-1,51,6,LEAVES:12)
Block(6,51,6,LEAVES:4)
Block(5,52,-11,LEAVES:4)
Block(9,52,-11,LEAVES:4)
Block(10,52,-11,LEAVES:4)
Block(-5,52,-10,LEAVES:4)
Block(-4,52,-10,LEAVES:4)
Block(3,52,-10,LEAVES:12)
Block(4,52,-10,LEAVES:12)
Block(5,52,-10,LEAVES:12)
Block(-7,52,-9,LEAVES:4)
Block(-3,52,-9,LEAVES:4)
Block(3,52,-9,LEAVES:12)
Block(5,52,-9,LOG:14)
Block(6,52,-9,LEAVES:12)
Block(7,52,-9,LEAVES:12)
Block(8,52,-9,LEAVES:12)
Block(9,52,-9,LEAVES:12)
Block(10,52,-9,LEAVES:4)
Block(-7,52,-8,LEAVES:4)
Block(-6,52,-8,LEAVES:4)
Block(-5,52,-8,LOG:14)
Block(-4,52,-8,LEAVES:4)
Block(0,52,-8,LEAVES:12)
Block(1,52,-8,LOG:14)
Block(2,52,-8,LEAVES:12)
Block(3,52,-8,LEAVES:12)
Block(4,52,-8,LEAVES:12)
Block(5,52,-8,LEAVES:12)
Block(6,52,-8,LEAVES:12)
Block(7,52,-8,LEAVES:12)
Block(8,52,-8,LEAVES:12)
Block(9,52,-8,LOG:14)
Block(11,52,-8,LEAVES:4)
Block(-5,52,-7,LEAVES:4)
Block(-3,52,-7,LEAVES:4)
Block(3,52,-7,LEAVES:12)
Block(4,52,-7,LEAVES:12)
Block(5,52,-7,LEAVES:12)
Block(6,52,-7,LEAVES:12)
Block(-6,52,-6,LEAVES:4)
Block(-4,52,-6,LEAVES:4)
Block(2,52,-6,LEAVES:12)
Block(3,52,-6,LEAVES:12)
Block(8,52,-6,LOG:14)
Block(-5,52,-5,LEAVES:12)
Block(-1,52,-5,LEAVES:12)
Block(0,52,-5,LEAVES:12)
Block(4,52,-5,LEAVES:12)
Block(-6,52,-4,LEAVES:12)
Block(-4,52,-4,LEAVES:12)
Block(-3,52,-4,LEAVES:12)
Block(-2,52,-4,LEAVES:12)
Block(1,52,-4,LEAVES:12)
Block(2,52,-4,LEAVES:12)
Block(5,52,-4,LEAVES:12)
Block(-7,52,-3,LEAVES:4)
Block(-6,52,-3,LEAVES:12)
Block(-5,52,-3,LOG:14)
Block(-4,52,-3,LEAVES:12)
Block(-3,52,-3,LEAVES:12)
Block(0,52,-3,LEAVES:12)
Block(1,52,-3,LEAVES:12)
Block(2,52,-3,LEAVES:12)
Block(3,52,-3,LOG:14)
Block(5,52,-3,LEAVES:12)
Block(7,52,-3,LEAVES:12)
Block(8,52,-3,LEAVES:12)
Block(-6,52,-2,LEAVES:12)
Block(-1,52,-2,LEAVES:12)
Block(1,52,-2,LEAVES:12)
Block(2,52,-2,LEAVES:12)
Block(3,52,-2,LEAVES:12)
Block(-6,52,-1,LEAVES:12)
Block(-4,52,-1,LEAVES:12)
Block(0,52,-1,LEAVES:12)
Block(1,52,-1,LEAVES:12)
Block(2,52,-1,LEAVES:12)
Block(3,52,-1,LEAVES:12)
Block(6,52,-1,LEAVES:12)
Block(7,52,-1,LEAVES:12)
Block(8,52,-1,LOG:14)
Block(10,52,-1,LEAVES:4)
Block(-6,52,0,LEAVES:12)
Block(-2,52,0,LEAVES:12)
Block(2,52,0,LEAVES:12)
Block(6,52,0,LEAVES:12)
Block(8,52,0,LEAVES:12)
Block(-4,52,1,LOG:14)
Block(-3,52,1,LEAVES:12)
Block(-2,52,1,LEAVES:12)
Block(1,52,1,LEAVES:12)
Block(9,52,1,LEAVES:12)
Block(-2,52,2,LEAVES:12)
Block(1,52,2,LEAVES:12)
Block(-3,52,3,LEAVES:12)
Block(0,52,3,LEAVES:12)
Block(1,52,3,LOG:14)
Block(2,52,3,LEAVES:12)
Block(-1,52,4,LOG:14)
Block(0,52,4,LEAVES:12)
Block(1,52,4,LEAVES:12)
Block(7,52,4,LEAVES:12)
Block(8,52,4,LEAVES:12)
Block(-1,52,5,LEAVES:12)
Block(0,52,5,LEAVES:12)
Block(1,52,5,LEAVES:12)
Block(2,52,5,LEAVES:12)
Block(7,52,5,LEAVES:4)
Block(8,52,5,LEAVES:4)
Block(-1,52,6,LEAVES:12)
Block(5,53,-11,LEAVES:4)
Block(9,53,-11,LEAVES:4)
Block(-6,53,-10,LEAVES:4)
Block(1,53,-10,LEAVES:4)
Block(3,53,-10,LEAVES:4)
Block(7,53,-10,LEAVES:4)
Block(8,53,-10,LEAVES:4)
Block(10,53,-10,LEAVES:4)
Block(2,53,-9,LEAVES:4)
Block(3,53,-9,LEAVES:4)
Block(5,53,-9,LEAVES:4)
Block(9,53,-9,LOG:14)
Block(10,53,-9,LEAVES:4)
Block(-7,53,-8,LEAVES:4)
Block(-5,53,-8,LEAVES:4)
Block(-3,53,-8,LEAVES:4)
Block(0,53,-8,LEAVES:4)
Block(1,53,-8,LEAVES:4)
Block(2,53,-8,LOG:14)
Block(3,53,-8,LEAVES:4)
Block(4,53,-8,LEAVES:4)
Block(-3,53,-7,LEAVES:4)
Block(2,53,-7,LEAVES:4)
Block(3,53,-7,LEAVES:4)
Block(4,53,-7,LEAVES:4)
Block(5,53,-7,LEAVES:4)
Block(6,53,-7,LEAVES:4)
Block(9,53,-7,LEAVES:4)
Block(10,53,-7,LEAVES:4)
Block(-6,53,-6,LEAVES:4)
Block(-5,53,-6,LEAVES:4)
Block(-4,53,-6,LEAVES:4)
Block(2,53,-6,LEAVES:12)
Block(3,53,-6,LEAVES:12)
Block(-5,53,-5,LEAVES:4)
Block(-2,53,-5,LEAVES:12)
Block(-1,53,-5,LEAVES:12)
Block(0,53,-5,LEAVES:12)
Block(3,53,-5,LEAVES:12)
Block(4,53,-5,LEAVES:12)
Block(8,53,-5,LOG:14)
Block(-6,53,-4,LEAVES:12)
Block(-4,53,-4,LEAVES:12)
Block(-3,53,-4,LEAVES:12)
Block(-2,53,-4,LEAVES:12)
Block(-1,53,-4,LEAVES:12)
Block(8,53,-4,LEAVES:4)
Block(10,53,-4,LEAVES:4)
Block(-6,53,-3,LEAVES:12)
Block(-5,53,-3,LEAVES:12)
Block(-4,53,-3,LEAVES:12)
Block(-3,53,-3,LEAVES:12)
Block(1,53,-3,LEAVES:12)
Block(3,53,-3,LEAVES:12)
Block(5,53,-3,LEAVES:12)
Block(7,53,-3,LEAVES:4)
Block(8,53,-3,LEAVES:4)
Block(9,53,-3,LEAVES:4)
Block(-5,53,-2,LEAVES:12)
Block(-3,53,-2,LEAVES:12)
Block(1,53,-2,LEAVES:12)
Block(2,53,-2,LEAVES:12)
Block(3,53,-2,LEAVES:12)
Block(5,53,-2,LEAVES:12)
Block(6,53,-2,LEAVES:12)
Block(7,53,-2,LEAVES:4)
Block(8,53,-2,LEAVES:4)
Block(-4,53,-1,LEAVES:12)
Block(1,53,-1,LEAVES:12)
Block(7,53,-1,LEAVES:4)
Block(8,53,-1,LEAVES:4)
Block(-4,53,0,LEAVES:12)
Block(8,53,0,LEAVES:4)
Block(-4,53,1,LEAVES:12)
Block(-3,53,1,LEAVES:12)
Block(1,53,1,LEAVES:12)
Block(7,53,1,LEAVES:4)
Block(-6,53,2,LEAVES:12)
Block(-4,53,2,LEAVES:12)
Block(-3,53,2,LEAVES:12)
Block(-1,53,2,LEAVES:12)
Block(1,53,2,LEAVES:12)
Block(-1,53,3,LEAVES:12)
Block(1,53,3,LEAVES:12)
Block(3,53,3,LEAVES:12)
Block(-1,53,4,LEAVES:12)
Block(1,53,4,LEAVES:12)
Block(1,53,5,LEAVES:12)
Block(-1,53,6,LEAVES:12)
Block(10,54,-10,LEAVES:4)
Block(11,54,-10,LEAVES:4)
Block(4,54,-9,LEAVES:4)
Block(5,54,-9,LEAVES:4)
Block(8,54,-9,LEAVES:4)
Block(9,54,-9,LEAVES:4)
Block(-6,54,-8,LEAVES:4)
Block(-4,54,-8,LEAVES:4)
Block(2,54,-8,LEAVES:4)
Block(4,54,-8,LEAVES:4)
Block(5,54,-8,LEAVES:4)
Block(11,54,-8,LEAVES:4)
Block(3,54,-7,LEAVES:4)
Block(8,54,-7,LEAVES:4)
Block(9,54,-7,LEAVES:4)
Block(2,54,-6,LEAVES:12)
Block(8,54,-5,LEAVES:4)
Block(10,54,-5,LEAVES:4)
Block(-5,54,-4,LEAVES:4)
Block(3,54,-4,LEAVES:12)
Block(4,54,-4,LEAVES:12)
Block(9,54,-4,LOG:14)
Block(-5,54,-3,LEAVES:4)
Block(-4,54,-3,LEAVES:4)
Block(3,54,-3,LEAVES:12)
Block(4,54,-3,LEAVES:12)
Block(9,54,-3,LEAVES:4)
Block(10,54,-3,LEAVES:4)
Block(-5,54,-2,LEAVES:4)
Block(-4,54,-2,LEAVES:4)
Block(4,54,-2,LEAVES:12)
Block(9,54,-2,LEAVES:4)
Block(10,54,-2,LEAVES:4)
Block(7,54,-1,LEAVES:4)
Block(8,54,-1,LEAVES:4)
Block(9,54,-1,LEAVES:4)
Block(10,54,-1,LEAVES:4)
Block(-3,54,0,LEAVES:12)
Block(8,54,0,LEAVES:4)
Block(-5,54,1,LEAVES:4)
Block(-3,54,1,LEAVES:12)
Block(-5,54,2,LEAVES:4)
Block(0,54,4,LEAVES:4)
Block(-1,54,5,LEAVES:4)
Block(10,55,-10,LEAVES:4)
Block(1,55,-9,LEAVES:4)
Block(2,55,-9,LEAVES:4)
Block(10,55,-9,LEAVES:4)
Block(3,55,-8,LEAVES:4)
Block(9,55,-8,LEAVES:4)
Block(2,55,-7,LEAVES:4)
Block(8,55,-5,LEAVES:4)
Block(10,55,-5,LEAVES:4)
Block(7,55,-3,LEAVES:4)
Block(9,55,-3,LOG:14)
Block(11,55,-3,LEAVES:4)
Block(8,55,-2,LEAVES:4)
Block(9,55,-2,LEAVES:4)
Block(10,55,-2,LEAVES:4)
Block(8,55,-1,LEAVES:4)
Block(9,55,-1,LEAVES:4)
Block(10,55,-1,LEAVES:4)
Block(9,56,-5,LEAVES:4)
Block(10,56,-5,LEAVES:4)
Block(9,56,-4,LEAVES:4)
Block(9,56,-3,LEAVES:4)
Block(11,56,-3,LEAVES:4)
Block(8,56,-2,LEAVES:4)
Block(8,56,-1,LEAVES:4)
Block(9,56,-1,LEAVES:4)

#######################################################################
# +-----------------------------------------------------------------+ #
# |                            BO3 checks                           | #
# +-----------------------------------------------------------------+ #
#######################################################################

# Require a condition at a certain location in order for the BO3 to be spawned.
# BlockCheck(x,y,z,BlockName[,BlockName[,...]]) - one of the blocks must be at the location
# BlockCheckNot(x,y,z,BlockName[,BlockName[,...]]) - all the blocks must not be at the location
# LightCheck(x,y,z,minLightLevel,maxLightLevel) - light must be between min and max (inclusive)

# You can use "Solid" as a BlockName for matching all solid blocks or "All" to match all blocks that aren't air.

# Examples:
BlockCheck(0,-1,0,GRASS,DIRT,DIRT:2,SAND)
#   BlockCheck(0,-1,0,Solid)       Require any solid block just below the object
#   BlockCheck(0,-1,0,WOOL)        Require any type of wool just below the object
#   BlockCheck(0,-1,0,WOOL:0)      Require white wool just below the object
#   BlockCheckNot(0,-1,0,WOOL:0)   Require that there is no white wool below the object
#   LightCheck(0,0,0,0,1)          Require almost complete darkness just below the object

#######################################################################
# +-----------------------------------------------------------------+ #
# |                             Branches                            | #
# +-----------------------------------------------------------------+ #
#######################################################################

# Branches are objects that will spawn when this object spawns when it is used in
# the CustomStructure resource. Branches can also have branches, making complex
# structures possible. See the wiki for more details.

# Regular Branches spawn each branch with an independent chance of spawning.
# Branch(x,y,z,branchName,rotation,chance[,anotherBranchName,rotation,chance[,...]][IndividualChance])
# branchName - name of the object to spawn.
# rotation - NORTH, SOUTH, EAST or WEST.
# IndividualChance - The chance each branch has to spawn, assumed to be 100 when left blank

# Weighted Branches spawn branches with a dependent chance of spawning.
# WeightedBranch(x,y,z,branchName,rotation,chance[,anotherBranchName,rotation,chance[,...]][MaxChanceOutOf])
# MaxChanceOutOf - The chance all branches have to spawn out of, assumed to be 100 when left blank
BlockCheck(0,-1,0,GRASS)
