#######################################################################
# +-----------------------------------------------------------------+ #
# |                            BO3 object                           | #
# +-----------------------------------------------------------------+ #
#######################################################################

# The descriptions in this file are accurate only for TerrainControl and OTG.
# For MCW and OTG+ these descriptions are only accurate if the BO3 is used as a CustomObject.
# MCW and OTG+ completely reimplemented CustomStructure, check the MCW/OTG+ documentation for more information.

# This is the config file of a custom object.
# If you add this object correctly to your BiomeConfigs, it will spawn in the world.

# This is the creator of this BO3 object
Author: Unknown

# A short description of this BO3 object
Description: This BO3 was converted from a schematic using OTGEdit. The author and description information of the schematic could not be found. If you know who the author of the schematic is then please add this information.

# The BO3 version, don't change this! It can be used by external applications to do a version check.
Version: 3

# The settings mode, WriteAll, WriteWithoutComments or WriteDisable. See WorldConfig.
SettingsMode: WriteDisable

#######################################################################
# +-----------------------------------------------------------------+ #
# |                          Main settings                          | #
# +-----------------------------------------------------------------+ #
#######################################################################

# This needs to be set to true to spawn the object in the Tree and Sapling resources.
Tree: true

# The frequency of the BO3 from 1 to 200. Tries this many times to spawn this BO3 when using the CustomObject(...) resource.
# Ignored by Tree(..), Sapling(..) and CustomStructure(..)
Frequency: 40

# The rarity of the BO3 from 0 to 100. Each spawn attempt has rarity% chance to succeed when using the CustomObject(...) resource.
# Ignored by Tree(..), Sapling(..) and CustomStructure(..)
Rarity: 100.0

# If you set this to true, the BO3 will be placed with a random rotation.
RotateRandomly: true

# The spawn height of the BO3 - randomY, highestBlock or highestSolidBlock.
SpawnHeight: highestSolidBlock
SpawnHeightOffset: -2
# The height limits for the BO3.
MinHeight: 0

MaxHeight: 256

# Objects can have other objects attached to it: branches. Branches can also
# have branches attached to it, which can also have branches, etc. This is the
# maximum branch depth for this objects.
MaxBranchDepth: 10

# When spawned with the UseWorld keyword, this BO3 should NOT spawn in the following biomes.
# If you writer.write the BO3 name directly in the BiomeConfigs, this will be ignored.
ExcludedBiomes: All

# To optimise this BO3 for faster loading times you can use Notepad++ to find/replace comments and abbreviate things.
# Notepad++ find/replace with regex:
# Find: ^[#;].* replace to nothing removes all lines starting with # 
# Find: ^\s*$ replace to nothing removes most empty lines 
# Notepad++ find/replace without regex:
# *Warning: This will only work for OTG 1.10.2 v21 / OTG 1.11.2 v6 or higher. B( is not recognised by lower versions.
# Find: Block( replace to B(

#######################################################################
# +-----------------------------------------------------------------+ #
# |                      Source block settings                      | #
# +-----------------------------------------------------------------+ #
#######################################################################

# The block(s) the BO3 should spawn in.
SourceBlocks: AIR,GRASS,DIRT

# The maximum percentage of the BO3 that can be outside the SourceBlock.
# The BO3 won't be placed on a location with more blocks outside the SourceBlock than this percentage.
MaxPercentageOutsideSourceBlock: 0

# What to do when a block is about to be placed outside the SourceBlock? (dontPlace, placeAnyway)
OutsideSourceBlock: dontPlace

#######################################################################
# +-----------------------------------------------------------------+ #
# |                              Blocks                             | #
# +-----------------------------------------------------------------+ #
#######################################################################

# All the blocks used in the BO3 are listed here. Possible blocks:
# Block(x,y,z,id[.data][,nbtfile.nbt) or B(x,y,z,id[.data][,nbtfile.nbt)
# RandomBlock(x,y,z,id[:data][,nbtfile.nbt],chance[,id[:data][,nbtfile.nbt],chance[,...]])
# So RandomBlock(0,0,0,CHEST,chest.nbt,50,CHEST,anotherchest.nbt,100) will spawn a chest at
# the BO3 origin, and give it a 50% chance to have the contents of chest.nbt, or, if that
# fails, a 100% percent chance to have the contents of anotherchest.nbt.

Block(-13,12,9,LEAVES:12)
Block(-13,13,7,LEAVES:12)
Block(-12,12,9,LEAVES:12)
Block(-12,13,4,LEAVES:12)
Block(-12,13,7,LEAVES:12)
Block(-12,14,7,LEAVES:12)
Block(-11,11,15,LEAVES:12)
Block(-11,12,6,LEAVES:12)
Block(-11,12,9,LEAVES:12)
Block(-11,12,13,LEAVES:12)
Block(-11,13,4,LEAVES:12)
Block(-11,13,5,LEAVES:12)
Block(-11,13,9,LEAVES:12)
Block(-11,13,12,LEAVES:12)
Block(-11,14,7,LEAVES:12)
Block(-11,14,8,LEAVES:12)
Block(-10,11,4,LEAVES:12)
Block(-10,11,5,LEAVES:12)
Block(-10,11,10,LEAVES:12)
Block(-10,11,11,LEAVES:12)
Block(-10,11,15,LEAVES:12)
Block(-10,12,7,LEAVES:12)
Block(-10,12,10,LEAVES:12)
Block(-10,12,13,LEAVES:12)
Block(-10,13,5,LEAVES:12)
Block(-10,13,6,LEAVES:12)
Block(-10,13,8,LEAVES:12)
Block(-10,13,9,LEAVES:12)
Block(-10,13,12,LEAVES:12)
Block(-10,13,13,LEAVES:12)
Block(-10,14,5,LEAVES:12)
Block(-10,14,6,LEAVES:12)
Block(-10,14,8,LEAVES:12)
Block(-10,15,9,LEAVES:12)
Block(-10,15,10,LEAVES:12)
Block(-9,11,5,LEAVES:12)
Block(-9,11,9,LEAVES:12)
Block(-9,11,10,LEAVES:12)
Block(-9,11,12,LEAVES:12)
Block(-9,11,15,LEAVES:12)
Block(-9,12,1,LEAVES:12)
Block(-9,12,2,LEAVES:12)
Block(-9,12,7,LEAVES:12)
Block(-9,12,8,LEAVES:12)
Block(-9,12,9,LEAVES:12)
Block(-9,12,10,LEAVES:12)
Block(-9,12,11,LEAVES:12)
Block(-9,12,15,LEAVES:12)
Block(-9,12,18,LEAVES:12)
Block(-9,13,0,LEAVES:12)
Block(-9,13,2,LEAVES:12)
Block(-9,13,6,LEAVES:12)
Block(-9,13,8,LEAVES:12)
Block(-9,13,11,LEAVES:12)
Block(-9,13,12,LEAVES:12)
Block(-9,13,13,LEAVES:12)
Block(-9,13,14,LEAVES:12)
Block(-9,14,6,LEAVES:12)
Block(-9,14,8,LEAVES:12)
Block(-9,14,11,LEAVES:12)
Block(-9,15,8,LEAVES:12)
Block(-9,15,9,LEAVES:12)
Block(-8,10,10,LEAVES:12)
Block(-8,10,11,LEAVES:12)
Block(-8,10,16,LEAVES:12)
Block(-8,10,17,LEAVES:12)
Block(-8,11,5,LEAVES:12)
Block(-8,11,6,LEAVES:12)
Block(-8,11,13,LEAVES:12)
Block(-8,12,2,LEAVES:12)
Block(-8,12,7,LEAVES:12)
Block(-8,12,8,LEAVES:12)
Block(-8,12,11,LEAVES:12)
Block(-8,12,12,LEAVES:12)
Block(-8,12,14,LEAVES:12)
Block(-8,12,15,LEAVES:12)
Block(-8,12,18,LEAVES:12)
Block(-8,13,-3,LEAVES:12)
Block(-8,13,0,LEAVES:12)
Block(-8,13,2,LEAVES:12)
Block(-8,13,3,LEAVES:12)
Block(-8,13,4,LEAVES:12)
Block(-8,13,11,LEAVES:12)
Block(-8,13,12,LEAVES:12)
Block(-8,13,14,LEAVES:12)
Block(-8,14,0,LEAVES:12)
Block(-8,14,4,LEAVES:12)
Block(-8,14,5,LEAVES:12)
Block(-8,14,6,LEAVES:12)
Block(-8,14,7,LEAVES:12)
Block(-8,14,8,LEAVES:12)
Block(-8,14,9,LEAVES:12)
Block(-8,14,10,LEAVES:12)
Block(-8,14,11,LEAVES:12)
Block(-8,14,15,LEAVES:12)
Block(-8,14,16,LEAVES:12)
Block(-8,15,5,LEAVES:12)
Block(-7,10,10,LEAVES:12)
Block(-7,10,11,LEAVES:12)
Block(-7,10,12,LEAVES:12)
Block(-7,10,15,LEAVES:12)
Block(-7,10,16,LEAVES:12)
Block(-7,11,6,LEAVES:12)
Block(-7,11,7,LEAVES:12)
Block(-7,11,8,LEAVES:12)
Block(-7,11,10,LEAVES:12)
Block(-7,11,13,LEAVES:12)
Block(-7,11,14,LEAVES:12)
Block(-7,11,15,LEAVES:12)
Block(-7,11,19,LEAVES:12)
Block(-7,12,-1,LEAVES:12)
Block(-7,12,2,LEAVES:12)
Block(-7,12,7,LEAVES:12)
Block(-7,12,8,LEAVES:12)
Block(-7,12,12,LEAVES:12)
Block(-7,12,13,LEAVES:12)
Block(-7,12,14,LEAVES:12)
Block(-7,12,17,LEAVES:12)
Block(-7,12,18,LEAVES:12)
Block(-7,13,-3,LEAVES:12)
Block(-7,13,-2,LEAVES:12)
Block(-7,13,2,LEAVES:12)
Block(-7,13,4,LEAVES:12)
Block(-7,13,5,LEAVES:12)
Block(-7,13,7,LEAVES:12)
Block(-7,13,12,LEAVES:12)
Block(-7,13,14,LEAVES:12)
Block(-7,13,17,LEAVES:12)
Block(-7,14,0,LEAVES:12)
Block(-7,14,1,LEAVES:12)
Block(-7,14,7,LEAVES:12)
Block(-7,14,8,LEAVES:12)
Block(-7,14,14,LEAVES:12)
Block(-7,14,15,LEAVES:12)
Block(-7,15,4,LEAVES:12)
Block(-7,15,5,LEAVES:12)
Block(-7,15,8,LEAVES:12)
Block(-6,10,11,LEAVES:12)
Block(-6,10,12,LEAVES:12)
Block(-6,11,-3,LEAVES:12)
Block(-6,11,-2,LEAVES:12)
Block(-6,11,3,LEAVES:12)
Block(-6,11,4,LEAVES:12)
Block(-6,11,6,LEAVES:12)
Block(-6,11,9,LEAVES:12)
Block(-6,11,10,LEAVES:12)
Block(-6,11,13,LEAVES:12)
Block(-6,11,14,LEAVES:12)
Block(-6,11,15,LOG2:12)
Block(-6,11,19,LEAVES:12)
Block(-6,12,0,LEAVES:12)
Block(-6,12,3,LEAVES:12)
Block(-6,12,8,LEAVES:12)
Block(-6,12,9,LEAVES:12)
Block(-6,12,10,LEAVES:12)
Block(-6,12,11,LEAVES:12)
Block(-6,12,12,LEAVES:12)
Block(-6,12,14,LEAVES:12)
Block(-6,12,17,LEAVES:12)
Block(-6,13,-2,LEAVES:12)
Block(-6,13,-1,LEAVES:12)
Block(-6,13,1,LEAVES:12)
Block(-6,13,2,LEAVES:12)
Block(-6,13,3,LEAVES:12)
Block(-6,13,4,LEAVES:12)
Block(-6,13,5,LEAVES:12)
Block(-6,13,7,LEAVES:12)
Block(-6,13,9,LEAVES:12)
Block(-6,13,10,LEAVES:12)
Block(-6,13,11,LEAVES:12)
Block(-6,13,12,LEAVES:12)
Block(-6,13,13,LEAVES:12)
Block(-6,13,14,LEAVES:12)
Block(-6,13,15,LEAVES:12)
Block(-6,13,16,LEAVES:12)
Block(-6,13,17,LEAVES:12)
Block(-6,14,-2,LEAVES:12)
Block(-6,14,-1,LEAVES:12)
Block(-6,14,1,LEAVES:12)
Block(-6,14,3,LEAVES:12)
Block(-6,14,5,LEAVES:12)
Block(-6,14,10,LEAVES:12)
Block(-6,14,11,LEAVES:12)
Block(-6,15,2,LEAVES:12)
Block(-6,15,3,LEAVES:12)
Block(-6,15,8,LEAVES:12)
Block(-5,9,16,LEAVES:12)
Block(-5,9,17,LEAVES:12)
Block(-5,9,18,LEAVES:12)
Block(-5,10,12,LEAVES:12)
Block(-5,10,13,LEAVES:12)
Block(-5,10,16,LEAVES:12)
Block(-5,11,-2,LEAVES:12)
Block(-5,11,2,LEAVES:12)
Block(-5,11,3,LEAVES:12)
Block(-5,11,5,LEAVES:12)
Block(-5,11,6,LEAVES:12)
Block(-5,11,13,LEAVES:12)
Block(-5,11,16,LEAVES:12)
Block(-5,11,18,LEAVES:12)
Block(-5,11,19,LEAVES:12)
Block(-5,11,20,LEAVES:12)
Block(-5,12,0,LEAVES:12)
Block(-5,12,1,LEAVES:12)
Block(-5,12,2,LEAVES:12)
Block(-5,12,3,LEAVES:12)
Block(-5,12,10,LEAVES:12)
Block(-5,12,14,LOG2:12)
Block(-5,12,15,LEAVES:12)
Block(-5,12,19,LEAVES:12)
Block(-5,12,22,LEAVES:12)
Block(-5,13,-1,LEAVES:12)
Block(-5,13,1,LEAVES:12)
Block(-5,13,4,LEAVES:12)
Block(-5,13,5,LEAVES:12)
Block(-5,13,8,LOG2:12)
Block(-5,13,9,LOG2:12)
Block(-5,13,13,LEAVES:12)
Block(-5,13,14,LEAVES:12)
Block(-5,13,17,LEAVES:12)
Block(-5,13,18,LEAVES:12)
Block(-5,14,-1,LEAVES:12)
Block(-5,14,1,LEAVES:12)
Block(-5,14,2,LEAVES:12)
Block(-5,14,3,LEAVES:12)
Block(-5,14,4,LEAVES:12)
Block(-5,14,5,LEAVES:12)
Block(-5,14,10,LEAVES:12)
Block(-5,14,11,LEAVES:12)
Block(-5,14,14,LEAVES:12)
Block(-5,14,15,LEAVES:12)
Block(-5,15,1,LEAVES:12)
Block(-5,15,2,LEAVES:12)
Block(-5,15,7,LEAVES:12)
Block(-5,15,8,LEAVES:12)
Block(-5,15,13,LEAVES:12)
Block(-4,10,12,LEAVES:12)
Block(-4,10,14,LEAVES:12)
Block(-4,10,15,LEAVES:12)
Block(-4,10,16,LEAVES:12)
Block(-4,10,20,LEAVES:12)
Block(-4,10,21,LEAVES:12)
Block(-4,11,-2,LEAVES:12)
Block(-4,11,-1,LEAVES:12)
Block(-4,11,4,LEAVES:12)
Block(-4,11,5,LEAVES:12)
Block(-4,11,9,LEAVES:12)
Block(-4,11,15,LEAVES:12)
Block(-4,11,17,LEAVES:12)
Block(-4,11,18,LEAVES:12)
Block(-4,12,0,LOG2:12)
Block(-4,12,1,LEAVES:12)
Block(-4,12,2,LEAVES:12)
Block(-4,12,9,LEAVES:12)
Block(-4,12,10,LEAVES:12)
Block(-4,12,11,LEAVES:12)
Block(-4,12,13,LOG2:12)
Block(-4,12,14,LEAVES:12)
Block(-4,12,15,LEAVES:12)
Block(-4,12,16,LEAVES:12)
Block(-4,12,17,LEAVES:12)
Block(-4,12,18,LEAVES:12)
Block(-4,12,19,LEAVES:12)
Block(-4,12,22,LEAVES:12)
Block(-4,13,-4,LEAVES:12)
Block(-4,13,-3,LEAVES:12)
Block(-4,13,5,LEAVES:12)
Block(-4,13,8,LEAVES:12)
Block(-4,13,11,LEAVES:12)
Block(-4,13,14,LEAVES:12)
Block(-4,13,15,LEAVES:12)
Block(-4,13,16,LEAVES:12)
Block(-4,13,18,LEAVES:12)
Block(-4,14,-3,LEAVES:12)
Block(-4,14,-2,LEAVES:12)
Block(-4,14,-1,LEAVES:12)
Block(-4,14,0,LEAVES:12)
Block(-4,14,1,LEAVES:12)
Block(-4,14,2,LEAVES:12)
Block(-4,14,3,LEAVES:12)
Block(-4,14,4,LEAVES:12)
Block(-4,14,5,LEAVES:12)
Block(-4,14,8,LEAVES:12)
Block(-4,14,9,LOG2:12)
Block(-4,14,10,LOG2:12)
Block(-4,14,11,LEAVES:12)
Block(-4,14,12,LEAVES:12)
Block(-4,14,14,LEAVES:12)
Block(-4,14,15,LEAVES:12)
Block(-4,14,19,LEAVES:12)
Block(-4,14,20,LEAVES:12)
Block(-4,15,-2,LEAVES:12)
Block(-4,15,10,LEAVES:12)
Block(-4,15,13,LEAVES:12)
Block(-4,16,13,LEAVES:12)
Block(-3,10,3,LEAVES:12)
Block(-3,10,4,LEAVES:12)
Block(-3,10,5,LEAVES:12)
Block(-3,10,11,LEAVES:12)
Block(-3,10,12,LEAVES:12)
Block(-3,10,15,LEAVES:12)
Block(-3,10,19,LEAVES:12)
Block(-3,10,20,LEAVES:12)
Block(-3,11,-1,LEAVES:12)
Block(-3,11,0,LEAVES:12)
Block(-3,11,3,LEAVES:12)
Block(-3,11,8,LEAVES:12)
Block(-3,11,9,LEAVES:12)
Block(-3,11,11,LEAVES:12)
Block(-3,11,12,LEAVES:12)
Block(-3,11,17,LEAVES:12)
Block(-3,11,18,LEAVES:12)
Block(-3,11,19,LEAVES:12)
Block(-3,12,0,LEAVES:12)
Block(-3,12,5,LEAVES:12)
Block(-3,12,6,LEAVES:12)
Block(-3,12,7,LEAVES:12)
Block(-3,12,9,LEAVES:12)
Block(-3,12,10,LEAVES:12)
Block(-3,12,12,LEAVES:12)
Block(-3,12,13,LOG2:12)
Block(-3,12,14,LEAVES:12)
Block(-3,12,16,LEAVES:12)
Block(-3,12,18,LEAVES:12)
Block(-3,12,21,LEAVES:12)
Block(-3,12,22,LEAVES:12)
Block(-3,13,-3,LEAVES:12)
Block(-3,13,0,LEAVES:12)
Block(-3,13,1,LOG2:12)
Block(-3,13,2,LOG2:12)
Block(-3,13,4,LEAVES:12)
Block(-3,13,5,LEAVES:12)
Block(-3,13,7,LEAVES:12)
Block(-3,13,8,LEAVES:12)
Block(-3,13,9,LEAVES:12)
Block(-3,13,11,LEAVES:12)
Block(-3,13,13,LOG2:12)
Block(-3,13,16,LEAVES:12)
Block(-3,13,17,LEAVES:12)
Block(-3,13,18,LEAVES:12)
Block(-3,13,21,LEAVES:12)
Block(-3,14,0,LEAVES:12)
Block(-3,14,1,LEAVES:12)
Block(-3,14,7,LEAVES:12)
Block(-3,14,8,LEAVES:12)
Block(-3,14,10,LOG2:12)
Block(-3,14,12,LEAVES:12)
Block(-3,14,13,LEAVES:12)
Block(-3,14,14,LEAVES:12)
Block(-3,14,15,LEAVES:12)
Block(-3,14,18,LEAVES:12)
Block(-3,14,19,LEAVES:12)
Block(-3,15,-3,LEAVES:12)
Block(-3,15,-2,LEAVES:12)
Block(-3,15,1,LEAVES:12)
Block(-3,15,8,LEAVES:12)
Block(-3,15,10,LEAVES:12)
Block(-3,15,11,LEAVES:12)
Block(-3,15,15,LEAVES:12)
Block(-3,15,18,LEAVES:12)
Block(-3,16,6,LEAVES:12)
Block(-3,16,13,LEAVES:12)
Block(-3,16,14,LEAVES:12)
Block(-2,10,10,LEAVES:12)
Block(-2,10,11,LEAVES:12)
Block(-2,10,15,LEAVES:12)
Block(-2,10,16,LEAVES:12)
Block(-2,11,-1,LEAVES:12)
Block(-2,11,2,LEAVES:12)
Block(-2,11,3,LEAVES:12)
Block(-2,11,8,LEAVES:12)
Block(-2,11,15,LEAVES:12)
Block(-2,11,17,LEAVES:12)
Block(-2,11,18,LEAVES:12)
Block(-2,12,-4,LEAVES:12)
Block(-2,12,2,LEAVES:12)
Block(-2,12,4,LEAVES:12)
Block(-2,12,5,LEAVES:12)
Block(-2,12,10,LEAVES:12)
Block(-2,12,11,LEAVES:12)
Block(-2,12,12,LEAVES:12)
Block(-2,12,13,LEAVES:12)
Block(-2,12,14,LEAVES:12)
Block(-2,12,15,LEAVES:12)
Block(-2,13,-4,LEAVES:12)
Block(-2,13,-3,LEAVES:12)
Block(-2,13,-2,LEAVES:12)
Block(-2,13,0,LEAVES:12)
Block(-2,13,1,LEAVES:12)
Block(-2,13,3,LEAVES:12)
Block(-2,13,4,LEAVES:12)
Block(-2,13,10,LEAVES:12)
Block(-2,13,11,LEAVES:12)
Block(-2,13,14,LEAVES:12)
Block(-2,13,15,LEAVES:12)
Block(-2,13,16,LEAVES:12)
Block(-2,13,17,LEAVES:12)
Block(-2,13,18,LEAVES:12)
Block(-2,13,19,LEAVES:12)
Block(-2,13,20,LEAVES:12)
Block(-2,13,21,LEAVES:12)
Block(-2,14,-4,LEAVES:12)
Block(-2,14,-2,LEAVES:12)
Block(-2,14,2,LOG2:12)
Block(-2,14,7,LEAVES:12)
Block(-2,14,13,LEAVES:12)
Block(-2,14,15,LEAVES:12)
Block(-2,15,1,LEAVES:12)
Block(-2,15,8,LEAVES:12)
Block(-2,15,11,LEAVES:12)
Block(-2,15,12,LEAVES:12)
Block(-2,15,14,LEAVES:12)
Block(-2,15,15,LEAVES:12)
Block(-2,15,18,LEAVES:12)
Block(-2,16,3,LEAVES:12)
Block(-2,16,6,LEAVES:12)
Block(-2,16,11,LEAVES:12)
Block(-2,16,12,LEAVES:12)
Block(-2,16,14,LEAVES:12)
Block(-2,17,6,LEAVES:12)
Block(-2,17,15,LEAVES:12)
Block(-2,17,16,LEAVES:12)
Block(-1,0,8,LOG2:12)
Block(-1,1,8,LOG2:12)
Block(-1,2,8,LOG2:12)
Block(-1,3,8,LOG2:12)
Block(-1,9,20,LEAVES:12)
Block(-1,9,21,LEAVES:12)
Block(-1,9,22,LEAVES:12)
Block(-1,10,16,LEAVES:12)
Block(-1,10,17,LEAVES:12)
Block(-1,10,19,LEAVES:12)
Block(-1,10,20,LEAVES:12)
Block(-1,11,-2,LEAVES:12)
Block(-1,11,-1,LEAVES:12)
Block(-1,11,15,LEAVES:12)
Block(-1,11,16,LEAVES:12)
Block(-1,11,17,LEAVES:12)
Block(-1,11,22,LEAVES:12)
Block(-1,11,23,LEAVES:12)
Block(-1,11,24,LEAVES:12)
Block(-1,12,-4,LEAVES:12)
Block(-1,12,10,LEAVES:12)
Block(-1,12,11,LEAVES:12)
Block(-1,12,14,LEAVES:12)
Block(-1,12,18,LOG2:12)
Block(-1,12,19,LEAVES:12)
Block(-1,13,1,LEAVES:12)
Block(-1,13,5,LOG2:12)
Block(-1,13,12,LOG2:12)
Block(-1,13,13,LEAVES:12)
Block(-1,13,14,LEAVES:12)
Block(-1,13,15,LEAVES:12)
Block(-1,13,16,LEAVES:12)
Block(-1,13,17,LEAVES:12)
Block(-1,13,18,LEAVES:12)
Block(-1,14,-4,LEAVES:12)
Block(-1,14,-2,LEAVES:12)
Block(-1,14,3,LOG2:12)
Block(-1,14,4,LOG2:12)
Block(-1,14,5,LOG2:12)
Block(-1,14,7,LEAVES:12)
Block(-1,14,8,LEAVES:12)
Block(-1,14,10,LOG2:12)
Block(-1,14,11,LOG2:12)
Block(-1,14,13,LEAVES:12)
Block(-1,14,14,LEAVES:12)
Block(-1,14,15,LEAVES:12)
Block(-1,14,18,LEAVES:12)
Block(-1,15,0,LEAVES:12)
Block(-1,15,1,LEAVES:12)
Block(-1,15,5,LEAVES:12)
Block(-1,15,8,LEAVES:12)
Block(-1,15,9,LOG2:12)
Block(-1,15,10,LOG2:12)
Block(-1,15,12,LEAVES:12)
Block(-1,15,14,LEAVES:12)
Block(-1,15,17,LEAVES:12)
Block(-1,15,18,LEAVES:12)
Block(-1,16,3,LEAVES:12)
Block(-1,16,4,LEAVES:12)
Block(-1,16,8,LEAVES:12)
Block(-1,16,11,LEAVES:12)
Block(-1,16,12,LEAVES:12)
Block(-1,16,14,LEAVES:12)
Block(-1,16,17,LEAVES:12)
Block(-1,17,6,LEAVES:12)
Block(-1,17,7,LEAVES:12)
Block(-1,17,14,LEAVES:12)
Block(-1,17,15,LEAVES:12)
Block(0,0,8,LOG2:12)
Block(0,1,8,LOG2:12)
Block(0,2,8,LOG2:12)
Block(0,3,8,LOG2:12)
Block(0,3,9,LOG2:12)
Block(0,4,8,LOG2:12)
Block(0,4,9,LOG2:12)
Block(0,5,8,LOG2:12)
Block(0,5,9,LOG2:12)
Block(0,6,8,LOG2:12)
Block(0,6,9,LOG2:12)
Block(0,7,8,LOG2:12)
Block(0,10,16,LEAVES:12)
Block(0,10,19,LEAVES:12)
Block(0,10,20,LEAVES:12)
Block(0,11,-3,LEAVES:12)
Block(0,11,-2,LEAVES:12)
Block(0,11,6,LEAVES:12)
Block(0,11,13,LEAVES:12)
Block(0,11,14,LEAVES:12)
Block(0,11,16,LEAVES:12)
Block(0,11,17,LEAVES:12)
Block(0,11,19,LEAVES:12)
Block(0,11,21,LEAVES:12)
Block(0,11,22,LEAVES:12)
Block(0,12,2,LEAVES:12)
Block(0,12,4,LEAVES:12)
Block(0,12,7,LOG2:12)
Block(0,12,10,LEAVES:12)
Block(0,12,11,LOG2:12)
Block(0,12,13,LEAVES:12)
Block(0,12,14,LEAVES:12)
Block(0,12,15,LEAVES:12)
Block(0,12,18,LEAVES:12)
Block(0,12,19,LEAVES:12)
Block(0,12,20,LEAVES:12)
Block(0,12,21,LEAVES:12)
Block(0,13,-2,LEAVES:12)
Block(0,13,1,LEAVES:12)
Block(0,13,2,LEAVES:12)
Block(0,13,5,LOG2:12)
Block(0,13,6,LOG2:12)
Block(0,13,11,LOG2:12)
Block(0,13,12,LEAVES:12)
Block(0,13,13,LEAVES:12)
Block(0,13,15,LEAVES:12)
Block(0,13,16,LOG2:12)
Block(0,13,17,LOG2:12)
Block(0,13,20,LEAVES:12)
Block(0,14,-2,LEAVES:12)
Block(0,14,1,LEAVES:12)
Block(0,14,3,LEAVES:12)
Block(0,14,4,LEAVES:12)
Block(0,14,5,LEAVES:12)
Block(0,14,9,LEAVES:12)
Block(0,14,10,LEAVES:12)
Block(0,14,13,LEAVES:12)
Block(0,14,14,LEAVES:12)
Block(0,14,18,LEAVES:12)
Block(0,15,6,LEAVES:12)
Block(0,15,8,LOG2:12)
Block(0,15,10,LEAVES:12)
Block(0,16,4,LEAVES:12)
Block(0,16,5,LEAVES:12)
Block(0,16,7,LEAVES:12)
Block(0,16,8,LEAVES:12)
Block(0,16,10,LEAVES:12)
Block(0,16,11,LEAVES:12)
Block(0,16,12,LEAVES:12)
Block(0,16,13,LEAVES:12)
Block(0,16,14,LEAVES:12)
Block(0,16,15,LEAVES:12)
Block(0,16,16,LEAVES:12)
Block(0,16,17,LEAVES:12)
Block(0,17,4,LEAVES:12)
Block(0,17,5,LEAVES:12)
Block(0,17,7,LEAVES:12)
Block(0,17,11,LEAVES:12)
Block(0,18,8,LEAVES:12)
Block(0,18,9,LEAVES:12)
Block(1,6,9,LOG2:12)
Block(1,7,9,LOG2:12)
Block(1,8,8,LOG2:12)
Block(1,8,9,LOG2:12)
Block(1,9,8,LOG2:12)
Block(1,9,9,LOG2:12)
Block(1,9,10,LOG2:12)
Block(1,10,8,LOG2:12)
Block(1,10,10,LOG2:12)
Block(1,10,15,LEAVES:12)
Block(1,10,16,LEAVES:12)
Block(1,10,19,LEAVES:12)
Block(1,11,6,LEAVES:12)
Block(1,11,7,LOG2:12)
Block(1,11,8,LOG2:12)
Block(1,11,10,LOG2:12)
Block(1,11,12,LEAVES:12)
Block(1,11,13,LEAVES:12)
Block(1,11,14,LEAVES:12)
Block(1,11,15,LEAVES:12)
Block(1,11,19,LEAVES:12)
Block(1,11,22,LEAVES:12)
Block(1,12,1,LEAVES:12)
Block(1,12,2,LEAVES:12)
Block(1,12,3,LEAVES:12)
Block(1,12,4,LEAVES:12)
Block(1,12,7,LOG2:12)
Block(1,12,10,LOG2:12)
Block(1,12,11,LOG2:12)
Block(1,12,16,LEAVES:12)
Block(1,12,17,LEAVES:12)
Block(1,12,18,LEAVES:12)
Block(1,13,-3,LEAVES:12)
Block(1,13,-2,LEAVES:12)
Block(1,13,4,LEAVES:12)
Block(1,13,6,LEAVES:12)
Block(1,13,11,LEAVES:12)
Block(1,13,12,LEAVES:12)
Block(1,13,13,LEAVES:12)
Block(1,13,15,LEAVES:12)
Block(1,13,20,LEAVES:12)
Block(1,13,21,LEAVES:12)
Block(1,14,0,LEAVES:12)
Block(1,14,1,LEAVES:12)
Block(1,14,4,LEAVES:12)
Block(1,14,8,LEAVES:12)
Block(1,14,9,LEAVES:12)
Block(1,14,13,LEAVES:12)
Block(1,14,17,LEAVES:12)
Block(1,14,18,LEAVES:12)
Block(1,14,19,LEAVES:12)
Block(1,14,20,LEAVES:12)
Block(1,15,0,LEAVES:12)
Block(1,15,1,LEAVES:12)
Block(1,15,6,LEAVES:12)
Block(1,15,7,LOG2:12)
Block(1,15,10,LEAVES:12)
Block(1,15,14,LOG2:12)
Block(1,16,1,LEAVES:12)
Block(1,16,5,LEAVES:12)
Block(1,16,7,LOG2:12)
Block(1,16,10,LEAVES:12)
Block(1,16,11,LEAVES:12)
Block(1,16,13,LEAVES:12)
Block(1,16,14,LEAVES:12)
Block(1,17,5,LEAVES:12)
Block(1,17,7,LEAVES:12)
Block(1,17,10,LEAVES:12)
Block(1,17,11,LEAVES:12)
Block(1,17,14,LEAVES:12)
Block(1,18,7,LEAVES:12)
Block(1,18,8,LEAVES:12)
Block(2,9,14,LEAVES:12)
Block(2,9,15,LEAVES:12)
Block(2,9,20,LEAVES:12)
Block(2,9,21,LEAVES:12)
Block(2,10,14,LEAVES:12)
Block(2,10,15,LEAVES:12)
Block(2,10,17,LEAVES:12)
Block(2,11,3,LEAVES:12)
Block(2,11,6,LEAVES:12)
Block(2,11,12,LEAVES:12)
Block(2,11,15,LEAVES:12)
Block(2,11,16,LEAVES:12)
Block(2,11,18,LEAVES:12)
Block(2,11,19,LEAVES:12)
Block(2,11,22,LEAVES:12)
Block(2,12,1,LEAVES:12)
Block(2,12,2,LEAVES:12)
Block(2,12,3,LEAVES:12)
Block(2,12,4,LEAVES:12)
Block(2,12,6,LEAVES:12)
Block(2,12,7,LOG2:12)
Block(2,12,9,LEAVES:12)
Block(2,12,11,LOG2:12)
Block(2,12,13,LEAVES:12)
Block(2,12,15,LEAVES:12)
Block(2,12,16,LEAVES:12)
Block(2,12,18,LEAVES:12)
Block(2,12,19,LEAVES:12)
Block(2,13,-3,LEAVES:12)
Block(2,13,4,LEAVES:12)
Block(2,13,5,LEAVES:12)
Block(2,13,7,LOG2:12)
Block(2,13,11,LOG2:12)
Block(2,13,12,LOG2:12)
Block(2,13,18,LEAVES:12)
Block(2,13,19,LEAVES:12)
Block(2,13,20,LEAVES:12)
Block(2,13,21,LEAVES:12)
Block(2,13,22,LEAVES:12)
Block(2,14,0,LEAVES:12)
Block(2,14,4,LEAVES:12)
Block(2,14,5,LEAVES:12)
Block(2,14,9,LEAVES:12)
Block(2,14,15,LEAVES:12)
Block(2,14,17,LEAVES:12)
Block(2,14,18,LEAVES:12)
Block(2,15,6,LEAVES:12)
Block(2,15,7,LEAVES:12)
Block(2,15,9,LEAVES:12)
Block(2,15,10,LEAVES:12)
Block(2,15,11,LEAVES:12)
Block(2,15,13,LOG2:12)
Block(2,15,14,LEAVES:12)
Block(2,15,15,LEAVES:12)
Block(2,15,16,LEAVES:12)
Block(2,15,17,LEAVES:12)
Block(2,16,1,LEAVES:12)
Block(2,16,2,LEAVES:12)
Block(2,16,3,LEAVES:12)
Block(2,16,9,LEAVES:12)
Block(2,16,11,LEAVES:12)
Block(2,16,16,LEAVES:12)
Block(2,17,3,LEAVES:12)
Block(2,17,4,LEAVES:12)
Block(2,17,5,LEAVES:12)
Block(2,17,6,LEAVES:12)
Block(2,17,7,LEAVES:12)
Block(2,17,8,LEAVES:12)
Block(2,17,9,LEAVES:12)
Block(2,17,10,LEAVES:12)
Block(2,17,14,LEAVES:12)
Block(2,18,4,LEAVES:12)
Block(3,9,15,LEAVES:12)
Block(3,9,19,LEAVES:12)
Block(3,9,20,LEAVES:12)
Block(3,10,1,LEAVES:12)
Block(3,10,2,LEAVES:12)
Block(3,10,7,LEAVES:12)
Block(3,10,8,LEAVES:12)
Block(3,10,11,LEAVES:12)
Block(3,10,12,LEAVES:12)
Block(3,10,17,LEAVES:12)
Block(3,10,18,LEAVES:12)
Block(3,10,19,LEAVES:12)
Block(3,11,4,LEAVES:12)
Block(3,11,12,LEAVES:12)
Block(3,11,16,LEAVES:12)
Block(3,11,18,LEAVES:12)
Block(3,11,19,LEAVES:12)
Block(3,11,20,LEAVES:12)
Block(3,11,21,LEAVES:12)
Block(3,11,22,LEAVES:12)
Block(3,12,2,LEAVES:12)
Block(3,12,3,LEAVES:12)
Block(3,12,5,LEAVES:12)
Block(3,12,6,LEAVES:12)
Block(3,12,9,LEAVES:12)
Block(3,12,13,LEAVES:12)
Block(3,12,14,LEAVES:12)
Block(3,12,15,LOG2:12)
Block(3,12,16,LEAVES:12)
Block(3,12,18,LEAVES:12)
Block(3,12,21,LEAVES:12)
Block(3,12,23,LEAVES:12)
Block(3,13,2,LEAVES:12)
Block(3,13,3,LEAVES:12)
Block(3,13,5,LEAVES:12)
Block(3,13,7,LOG2:12)
Block(3,13,8,LEAVES:12)
Block(3,13,9,LEAVES:12)
Block(3,13,10,LEAVES:12)
Block(3,13,11,LOG2:12)
Block(3,13,12,LEAVES:12)
Block(3,13,15,LOG2:12)
Block(3,13,17,LEAVES:12)
Block(3,13,18,LEAVES:12)
Block(3,13,19,LEAVES:12)
Block(3,14,5,LEAVES:12)
Block(3,14,6,LEAVES:12)
Block(3,14,7,LEAVES:12)
Block(3,14,8,LEAVES:12)
Block(3,14,9,LEAVES:12)
Block(3,14,11,LOG2:12)
Block(3,15,6,LEAVES:12)
Block(3,15,11,LOG2:12)
Block(3,15,12,LOG2:12)
Block(3,15,13,LOG2:12)
Block(3,15,14,LEAVES:12)
Block(3,16,3,LEAVES:12)
Block(3,16,6,LEAVES:12)
Block(3,16,7,LOG2:12)
Block(3,16,8,LEAVES:12)
Block(3,16,9,LEAVES:12)
Block(3,16,11,LEAVES:12)
Block(3,16,16,LEAVES:12)
Block(3,16,17,LEAVES:12)
Block(3,17,6,LEAVES:12)
Block(3,17,7,LEAVES:12)
Block(3,17,13,LEAVES:12)
Block(3,17,14,LEAVES:12)
Block(3,18,3,LEAVES:12)
Block(3,18,4,LEAVES:12)
Block(3,18,7,LEAVES:12)
Block(4,9,15,LEAVES:12)
Block(4,9,16,LEAVES:12)
Block(4,10,2,LEAVES:12)
Block(4,10,6,LEAVES:12)
Block(4,10,7,LEAVES:12)
Block(4,10,17,LEAVES:12)
Block(4,10,18,LEAVES:12)
Block(4,11,-2,LEAVES:12)
Block(4,11,-1,LEAVES:12)
Block(4,11,4,LEAVES:12)
Block(4,11,5,LEAVES:12)
Block(4,11,6,LEAVES:12)
Block(4,11,12,LEAVES:12)
Block(4,11,13,LEAVES:12)
Block(4,11,14,LEAVES:12)
Block(4,11,18,LEAVES:12)
Block(4,11,20,LEAVES:12)
Block(4,11,21,LEAVES:12)
Block(4,12,-1,LEAVES:12)
Block(4,12,3,LEAVES:12)
Block(4,12,5,LEAVES:12)
Block(4,12,8,LEAVES:12)
Block(4,12,9,LEAVES:12)
Block(4,12,10,LEAVES:12)
Block(4,12,13,LEAVES:12)
Block(4,12,14,LEAVES:12)
Block(4,12,15,LOG2:12)
Block(4,12,16,LOG2:12)
Block(4,12,17,LOG2:12)
Block(4,12,18,LEAVES:12)
Block(4,12,19,LEAVES:12)
Block(4,12,20,LEAVES:12)
Block(4,12,21,LEAVES:12)
Block(4,13,3,LEAVES:12)
Block(4,13,5,LEAVES:12)
Block(4,13,6,LOG2:12)
Block(4,13,8,LEAVES:12)
Block(4,13,9,LEAVES:12)
Block(4,13,10,LEAVES:12)
Block(4,13,11,LEAVES:12)
Block(4,13,13,LEAVES:12)
Block(4,13,15,LEAVES:12)
Block(4,13,16,LEAVES:12)
Block(4,13,17,LEAVES:12)
Block(4,14,5,LEAVES:12)
Block(4,14,6,LOG2:12)
Block(4,14,8,LEAVES:12)
Block(4,14,9,LEAVES:12)
Block(4,14,12,LEAVES:12)
Block(4,14,15,LEAVES:12)
Block(4,15,2,LEAVES:12)
Block(4,15,8,LEAVES:12)
Block(4,15,10,LEAVES:12)
Block(4,15,11,LEAVES:12)
Block(4,15,14,LEAVES:12)
Block(4,15,15,LEAVES:12)
Block(4,16,2,LEAVES:12)
Block(4,16,3,LEAVES:12)
Block(4,16,4,LEAVES:12)
Block(4,16,6,LEAVES:12)
Block(4,16,7,LEAVES:12)
Block(4,16,8,LEAVES:12)
Block(4,16,9,LEAVES:12)
Block(4,16,10,LEAVES:12)
Block(4,16,11,LEAVES:12)
Block(4,16,14,LEAVES:12)
Block(4,16,17,LEAVES:12)
Block(4,16,18,LEAVES:12)
Block(4,17,2,LEAVES:12)
Block(4,17,4,LEAVES:12)
Block(4,17,9,LEAVES:12)
Block(4,18,7,LEAVES:12)
Block(5,8,20,LEAVES:12)
Block(5,8,21,LEAVES:12)
Block(5,8,22,LEAVES:12)
Block(5,9,16,LEAVES:12)
Block(5,9,17,LEAVES:12)
Block(5,9,20,LEAVES:12)
Block(5,10,2,LEAVES:12)
Block(5,10,3,LEAVES:12)
Block(5,10,17,LEAVES:12)
Block(5,10,22,LEAVES:12)
Block(5,10,23,LEAVES:12)
Block(5,10,24,LEAVES:12)
Block(5,11,4,LEAVES:12)
Block(5,11,5,LEAVES:12)
Block(5,11,8,LEAVES:12)
Block(5,11,9,LEAVES:12)
Block(5,11,14,LEAVES:12)
Block(5,11,15,LEAVES:12)
Block(5,11,18,LOG2:12)
Block(5,11,19,LOG2:12)
Block(5,12,-1,LEAVES:12)
Block(5,12,0,LEAVES:12)
Block(5,12,1,LEAVES:12)
Block(5,12,11,LEAVES:12)
Block(5,12,17,LEAVES:12)
Block(5,12,18,LEAVES:12)
Block(5,13,1,LEAVES:12)
Block(5,13,2,LEAVES:12)
Block(5,13,3,LEAVES:12)
Block(5,13,4,LEAVES:12)
Block(5,13,5,LEAVES:12)
Block(5,13,6,LEAVES:12)
Block(5,13,7,LEAVES:12)
Block(5,13,8,LEAVES:12)
Block(5,13,9,LEAVES:12)
Block(5,13,10,LEAVES:12)
Block(5,13,12,LEAVES:12)
Block(5,13,13,LEAVES:12)
Block(5,13,14,LEAVES:12)
Block(5,13,15,LEAVES:12)
Block(5,13,16,LEAVES:12)
Block(5,13,18,LEAVES:12)
Block(5,14,2,LEAVES:12)
Block(5,14,4,LEAVES:12)
Block(5,14,5,LEAVES:12)
Block(5,14,9,LEAVES:12)
Block(5,14,10,LEAVES:12)
Block(5,14,11,LOG2:12)
Block(5,14,12,LEAVES:12)
Block(5,14,15,LEAVES:12)
Block(5,14,16,LEAVES:12)
Block(5,15,1,LEAVES:12)
Block(5,15,2,LEAVES:12)
Block(5,15,10,LEAVES:12)
Block(5,15,11,LEAVES:12)
Block(5,15,13,LEAVES:12)
Block(5,15,14,LEAVES:12)
Block(5,15,19,LEAVES:12)
Block(5,16,7,LEAVES:12)
Block(5,16,13,LEAVES:12)
Block(5,16,14,LEAVES:12)
Block(5,17,0,LEAVES:12)
Block(5,17,1,LEAVES:12)
Block(5,17,2,LEAVES:12)
Block(5,17,4,LEAVES:12)
Block(5,17,9,LEAVES:12)
Block(5,17,10,LEAVES:12)
Block(5,18,6,LEAVES:12)
Block(5,18,7,LEAVES:12)
Block(6,9,7,LEAVES:12)
Block(6,9,8,LEAVES:12)
Block(6,9,9,LEAVES:12)
Block(6,9,16,LEAVES:12)
Block(6,9,19,LEAVES:12)
Block(6,9,20,LEAVES:12)
Block(6,10,3,LEAVES:12)
Block(6,10,4,LEAVES:12)
Block(6,10,7,LEAVES:12)
Block(6,10,13,LEAVES:12)
Block(6,10,19,LEAVES:12)
Block(6,10,21,LEAVES:12)
Block(6,10,22,LEAVES:12)
Block(6,11,4,LEAVES:12)
Block(6,11,9,LEAVES:12)
Block(6,11,10,LEAVES:12)
Block(6,11,11,LEAVES:12)
Block(6,11,13,LEAVES:12)
Block(6,11,14,LEAVES:12)
Block(6,11,15,LEAVES:12)
Block(6,11,17,LEAVES:12)
Block(6,11,18,LEAVES:12)
Block(6,11,19,LEAVES:12)
Block(6,11,20,LEAVES:12)
Block(6,11,21,LEAVES:12)
Block(6,12,1,LEAVES:12)
Block(6,12,4,LEAVES:12)
Block(6,12,5,LEAVES:12)
Block(6,12,6,LEAVES:12)
Block(6,12,11,LEAVES:12)
Block(6,12,12,LEAVES:12)
Block(6,12,13,LEAVES:12)
Block(6,12,15,LEAVES:12)
Block(6,12,20,LEAVES:12)
Block(6,13,4,LEAVES:12)
Block(6,13,5,LEAVES:12)
Block(6,13,6,LEAVES:12)
Block(6,13,10,LEAVES:12)
Block(6,13,12,LEAVES:12)
Block(6,13,15,LEAVES:12)
Block(6,13,16,LEAVES:12)
Block(6,13,18,LEAVES:12)
Block(6,14,1,LEAVES:12)
Block(6,14,2,LEAVES:12)
Block(6,14,3,LEAVES:12)
Block(6,14,4,LEAVES:12)
Block(6,14,5,LEAVES:12)
Block(6,14,10,LEAVES:12)
Block(6,14,11,LOG2:12)
Block(6,14,12,LEAVES:12)
Block(6,14,15,LEAVES:12)
Block(6,14,16,LEAVES:12)
Block(6,14,17,LEAVES:12)
Block(6,15,1,LEAVES:12)
Block(6,15,8,LEAVES:12)
Block(6,15,10,LEAVES:12)
Block(6,15,12,LEAVES:12)
Block(6,15,13,LEAVES:12)
Block(6,16,4,LEAVES:12)
Block(6,16,7,LEAVES:12)
Block(6,16,8,LEAVES:12)
Block(6,16,13,LEAVES:12)
Block(6,17,4,LEAVES:12)
Block(6,17,7,LEAVES:12)
Block(6,17,10,LEAVES:12)
Block(6,17,11,LEAVES:12)
Block(7,9,15,LEAVES:12)
Block(7,9,16,LEAVES:12)
Block(7,10,3,LEAVES:12)
Block(7,10,6,LEAVES:12)
Block(7,10,7,LEAVES:12)
Block(7,10,12,LEAVES:12)
Block(7,10,13,LEAVES:12)
Block(7,11,0,LEAVES:12)
Block(7,11,6,LEAVES:12)
Block(7,11,8,LEAVES:12)
Block(7,11,9,LEAVES:12)
Block(7,11,10,LEAVES:12)
Block(7,11,18,LEAVES:12)
Block(7,12,0,LEAVES:12)
Block(7,12,1,LEAVES:12)
Block(7,12,2,LEAVES:12)
Block(7,12,4,LEAVES:12)
Block(7,12,5,LEAVES:12)
Block(7,12,6,LEAVES:12)
Block(7,12,7,LEAVES:12)
Block(7,12,8,LEAVES:12)
Block(7,12,11,LEAVES:12)
Block(7,12,12,LEAVES:12)
Block(7,12,13,LEAVES:12)
Block(7,12,15,LEAVES:12)
Block(7,12,20,LEAVES:12)
Block(7,12,21,LEAVES:12)
Block(7,13,0,LEAVES:12)
Block(7,13,2,LEAVES:12)
Block(7,13,6,LEAVES:12)
Block(7,13,7,LEAVES:12)
Block(7,13,8,LEAVES:12)
Block(7,13,17,LEAVES:12)
Block(7,13,18,LEAVES:12)
Block(7,14,5,LEAVES:12)
Block(7,14,8,LEAVES:12)
Block(7,14,9,LEAVES:12)
Block(7,14,10,LEAVES:12)
Block(7,14,11,LOG2:12)
Block(7,14,12,LOG2:12)
Block(7,14,13,LEAVES:12)
Block(7,14,14,LEAVES:12)
Block(7,14,15,LEAVES:12)
Block(7,15,8,LEAVES:12)
Block(7,15,9,LEAVES:12)
Block(7,16,3,LEAVES:12)
Block(7,16,4,LEAVES:12)
Block(7,16,12,LEAVES:12)
Block(7,17,6,LEAVES:12)
Block(7,17,7,LEAVES:12)
Block(8,9,14,LEAVES:12)
Block(8,9,15,LEAVES:12)
Block(8,10,2,LEAVES:12)
Block(8,10,3,LEAVES:12)
Block(8,10,12,LEAVES:12)
Block(8,10,14,LEAVES:12)
Block(8,10,15,LEAVES:12)
Block(8,10,16,LEAVES:12)
Block(8,10,19,LEAVES:12)
Block(8,11,-1,LEAVES:12)
Block(8,11,0,LEAVES:12)
Block(8,11,10,LEAVES:12)
Block(8,11,11,LEAVES:12)
Block(8,11,14,LEAVES:12)
Block(8,11,15,LEAVES:12)
Block(8,11,18,LEAVES:12)
Block(8,11,19,LEAVES:12)
Block(8,12,5,LEAVES:12)
Block(8,12,11,LEAVES:12)
Block(8,12,15,LEAVES:12)
Block(8,12,16,LEAVES:12)
Block(8,12,17,LEAVES:12)
Block(8,12,18,LEAVES:12)
Block(8,12,21,LEAVES:12)
Block(8,12,22,LEAVES:12)
Block(8,13,-2,LEAVES:12)
Block(8,13,-1,LEAVES:12)
Block(8,13,0,LEAVES:12)
Block(8,13,2,LEAVES:12)
Block(8,13,7,LEAVES:12)
Block(8,13,8,LEAVES:12)
Block(8,13,11,LEAVES:12)
Block(8,13,12,LOG2:12)
Block(8,14,4,LEAVES:12)
Block(8,14,5,LEAVES:12)
Block(8,14,11,LEAVES:12)
Block(8,14,12,LEAVES:12)
Block(8,15,8,LEAVES:12)
Block(8,15,9,LEAVES:12)
Block(8,15,10,LEAVES:12)
Block(8,15,12,LEAVES:12)
Block(8,16,3,LEAVES:12)
Block(8,17,6,LEAVES:12)
Block(9,10,1,LEAVES:12)
Block(9,10,2,LEAVES:12)
Block(9,10,19,LEAVES:12)
Block(9,10,20,LEAVES:12)
Block(9,11,-1,LEAVES:12)
Block(9,11,6,LEAVES:12)
Block(9,11,10,LEAVES:12)
Block(9,11,13,LEAVES:12)
Block(9,11,14,LEAVES:12)
Block(9,11,15,LEAVES:12)
Block(9,11,23,LEAVES:12)
Block(9,12,2,LEAVES:12)
Block(9,12,5,LEAVES:12)
Block(9,12,6,LEAVES:12)
Block(9,12,7,LEAVES:12)
Block(9,12,13,LEAVES:12)
Block(9,12,15,LEAVES:12)
Block(9,12,16,LEAVES:12)
Block(9,12,17,LEAVES:12)
Block(9,12,18,LEAVES:12)
Block(9,13,2,LEAVES:12)
Block(9,13,5,LEAVES:12)
Block(9,13,7,LEAVES:12)
Block(9,13,8,LEAVES:12)
Block(9,13,9,LEAVES:12)
Block(9,13,11,LEAVES:12)
Block(9,13,12,LOG2:12)
Block(9,13,13,LEAVES:12)
Block(9,13,14,LEAVES:12)
Block(9,13,15,LEAVES:12)
Block(9,14,7,LEAVES:12)
Block(9,14,9,LEAVES:12)
Block(9,14,14,LEAVES:12)
Block(9,15,12,LEAVES:12)
Block(10,10,20,LEAVES:12)
Block(10,10,21,LEAVES:12)
Block(10,11,6,LEAVES:12)
Block(10,11,7,LEAVES:12)
Block(10,11,9,LEAVES:12)
Block(10,11,10,LEAVES:12)
Block(10,11,14,LEAVES:12)
Block(10,12,1,LEAVES:12)
Block(10,12,2,LEAVES:12)
Block(10,12,6,LEAVES:12)
Block(10,12,7,LEAVES:12)
Block(10,12,10,LEAVES:12)
Block(10,12,17,LEAVES:12)
Block(10,13,4,LEAVES:12)
Block(10,13,5,LEAVES:12)
Block(10,13,12,LEAVES:12)
Block(10,14,5,LEAVES:12)
Block(10,14,6,LEAVES:12)
Block(10,14,7,LEAVES:12)
Block(10,14,9,LEAVES:12)
Block(10,14,14,LEAVES:12)
Block(10,14,15,LEAVES:12)
Block(10,15,11,LEAVES:12)
Block(10,15,12,LEAVES:12)
Block(11,11,7,LEAVES:12)
Block(11,11,8,LEAVES:12)
Block(11,11,9,LEAVES:12)
Block(11,12,1,LEAVES:12)
Block(11,12,6,LEAVES:12)
Block(11,12,13,LEAVES:12)
Block(11,13,4,LEAVES:12)
Block(11,13,9,LEAVES:12)
Block(11,13,12,LEAVES:12)
Block(11,13,13,LEAVES:12)
Block(11,14,9,LEAVES:12)
Block(11,14,12,LEAVES:12)
Block(11,14,15,LEAVES:12)
Block(11,14,16,LEAVES:12)
Block(12,12,13,LEAVES:12)
Block(12,12,14,LEAVES:12)
Block(12,13,8,LEAVES:12)
Block(12,13,9,LEAVES:12)
Block(12,13,17,LEAVES:12)
Block(12,14,11,LEAVES:12)
Block(12,14,12,LEAVES:12)
Block(13,12,14,LEAVES:12)
Block(13,12,15,LEAVES:12)
Block(13,13,8,LEAVES:12)
Block(13,14,11,LEAVES:12)


#######################################################################
# +-----------------------------------------------------------------+ #
# |                             Entities                            | #
# +-----------------------------------------------------------------+ #
#######################################################################

# Entity() spawns an entity instead of a block. The entity is spawned only once when the BO3 is spawned.
# Entities are persistent by default so they don't de-spawn when no player is near, they are only unloaded.
# Usage: Entity(x,y,z,mobName,groupSize,NameTagOrNBTFileName) or Entity(x,y,z,mobName,groupSize)
# Use /tc entities or /otg entities to get a list of entities that can be used as mobName, this includes entities added by other mods.
# NameTagOrNBTFileName can be either a nametag for the mob or an nbt file (such as mymobinfo.nbt or mymobinfo.txt).
# When using a text file you can use the same mob spawning parameters used with the /summon command to equip the
# entity and give it custom attributes etc. You can copy the DATA part of a summon command including surrounding
# curly braces to a .txt file, for instance for: "/summon Skeleton x y z {DATA}"

#######################################################################
# +-----------------------------------------------------------------+ #
# |                            BO3 checks                           | #
# +-----------------------------------------------------------------+ #
#######################################################################

# Require a condition at a certain location in order for the BO3 to be spawned.
# BlockCheck(x,y,z,BlockName[,BlockName[,...]]) - one of the blocks must be at the location
# BlockCheckNot(x,y,z,BlockName[,BlockName[,...]]) - all the blocks must not be at the location
# LightCheck(x,y,z,minLightLevel,maxLightLevel) - light must be between min and max (inclusive)

# You can use "Solid" as a BlockName for matching all solid blocks or "All" to match all blocks that aren't air.

# Examples:
BlockCheck(0,-1,0,GRASS,DIRT,DIRT:2,STONE)
#   BlockCheck(0,-1,0,Solid)       Require any solid block just below the object
#   BlockCheck(0,-1,0,WOOL)        Require any type of wool just below the object
#   BlockCheck(0,-1,0,WOOL:0)      Require white wool just below the object
#   BlockCheckNot(0,-1,0,WOOL:0)   Require that there is no white wool below the object
#   LightCheck(0,0,0,0,1)          Require almost complete darkness just below the object

