#######################################################################
# +-----------------------------------------------------------------+ #
# |                            BO3 object                           | #
# +-----------------------------------------------------------------+ #
#######################################################################

# The descriptions in this file are accurate only for TerrainControl and OTG.
# For MCW and OTG+ these descriptions are only accurate if the BO3 is used as a CustomObject.
# MCW and OTG+ completely reimplemented CustomStructure, check the MCW/OTG+ documentation for more information.

# This is the config file of a custom object.
# If you add this object correctly to your BiomeConfigs, it will spawn in the world.

# This is the creator of this BO3 object
Author: Unknown

# A short description of this BO3 object
Description: This BO3 was converted from a schematic using OTGEdit. The author and description information of the schematic could not be found. If you know who the author of the schematic is then please add this information.

# The BO3 version, don't change this! It can be used by external applications to do a version check.
Version: 3

# The settings mode, WriteAll, WriteWithoutComments or WriteDisable. See WorldConfig.
SettingsMode: WriteDisable

#######################################################################
# +-----------------------------------------------------------------+ #
# |                          Main settings                          | #
# +-----------------------------------------------------------------+ #
#######################################################################

# This needs to be set to true to spawn the object in the Tree and Sapling resources.
Tree: true

# The frequency of the BO3 from 1 to 200. Tries this many times to spawn this BO3 when using the CustomObject(...) resource.
# Ignored by Tree(..), Sapling(..) and CustomStructure(..)
Frequency: 40

# The rarity of the BO3 from 0 to 100. Each spawn attempt has rarity% chance to succeed when using the CustomObject(...) resource.
# Ignored by Tree(..), Sapling(..) and CustomStructure(..)
Rarity: 100.0

# If you set this to true, the BO3 will be placed with a random rotation.
RotateRandomly: true

# The spawn height of the BO3 - randomY, highestBlock or highestSolidBlock.
SpawnHeight: highestSolidBlock
SpawnHeightOffset: -2
# The height limits for the BO3.
MinHeight: 0

MaxHeight: 256

# Objects can have other objects attached to it: branches. Branches can also
# have branches attached to it, which can also have branches, etc. This is the
# maximum branch depth for this objects.
MaxBranchDepth: 10

# When spawned with the UseWorld keyword, this BO3 should NOT spawn in the following biomes.
# If you writer.write the BO3 name directly in the BiomeConfigs, this will be ignored.
ExcludedBiomes: All

# To optimise this BO3 for faster loading times you can use Notepad++ to find/replace comments and abbreviate things.
# Notepad++ find/replace with regex:
# Find: ^[#;].* replace to nothing removes all lines starting with # 
# Find: ^\s*$ replace to nothing removes most empty lines 
# Notepad++ find/replace without regex:
# *Warning: This will only work for OTG 1.10.2 v21 / OTG 1.11.2 v6 or higher. B( is not recognised by lower versions.
# Find: Block( replace to B(

#######################################################################
# +-----------------------------------------------------------------+ #
# |                      Source block settings                      | #
# +-----------------------------------------------------------------+ #
#######################################################################

# The block(s) the BO3 should spawn in.
SourceBlocks: AIR,GRASS,DIRT

# The maximum percentage of the BO3 that can be outside the SourceBlock.
# The BO3 won't be placed on a location with more blocks outside the SourceBlock than this percentage.
MaxPercentageOutsideSourceBlock: 0

# What to do when a block is about to be placed outside the SourceBlock? (dontPlace, placeAnyway)
OutsideSourceBlock: dontPlace

#######################################################################
# +-----------------------------------------------------------------+ #
# |                              Blocks                             | #
# +-----------------------------------------------------------------+ #
#######################################################################

# All the blocks used in the BO3 are listed here. Possible blocks:
# Block(x,y,z,id[.data][,nbtfile.nbt) or B(x,y,z,id[.data][,nbtfile.nbt)
# RandomBlock(x,y,z,id[:data][,nbtfile.nbt],chance[,id[:data][,nbtfile.nbt],chance[,...]])
# So RandomBlock(0,0,0,CHEST,chest.nbt,50,CHEST,anotherchest.nbt,100) will spawn a chest at
# the BO3 origin, and give it a 50% chance to have the contents of chest.nbt, or, if that
# fails, a 100% percent chance to have the contents of anotherchest.nbt.

Block(-10,13,10,LEAVES:12)
Block(-10,14,8,LEAVES:12)
Block(-10,15,18,LEAVES:12)
Block(-10,16,16,LEAVES:12)
Block(-9,13,10,LEAVES:12)
Block(-9,14,5,LEAVES:12)
Block(-9,14,8,LEAVES:12)
Block(-9,15,8,LEAVES:12)
Block(-9,15,18,LEAVES:12)
Block(-9,16,13,LEAVES:12)
Block(-9,16,16,LEAVES:12)
Block(-9,17,16,LEAVES:12)
Block(-8,13,7,LEAVES:12)
Block(-8,13,10,LEAVES:12)
Block(-8,14,5,LEAVES:12)
Block(-8,14,6,LEAVES:12)
Block(-8,14,10,LEAVES:12)
Block(-8,14,13,LEAVES:12)
Block(-8,15,8,LEAVES:12)
Block(-8,15,9,LEAVES:12)
Block(-8,15,15,LEAVES:12)
Block(-8,15,18,LEAVES:12)
Block(-8,16,13,LEAVES:12)
Block(-8,16,14,LEAVES:12)
Block(-8,16,18,LEAVES:12)
Block(-8,16,21,LEAVES:12)
Block(-8,17,16,LEAVES:12)
Block(-8,17,17,LEAVES:12)
Block(-7,12,5,LEAVES:12)
Block(-7,12,6,LEAVES:12)
Block(-7,12,11,LEAVES:12)
Block(-7,12,12,LEAVES:12)
Block(-7,13,8,LEAVES:12)
Block(-7,14,6,LEAVES:12)
Block(-7,14,7,LEAVES:12)
Block(-7,14,9,LEAVES:12)
Block(-7,14,10,LEAVES:12)
Block(-7,14,13,LEAVES:12)
Block(-7,14,14,LEAVES:12)
Block(-7,14,19,LEAVES:12)
Block(-7,14,20,LEAVES:12)
Block(-7,15,6,LEAVES:12)
Block(-7,15,7,LEAVES:12)
Block(-7,15,8,LEAVES:12)
Block(-7,15,9,LEAVES:12)
Block(-7,15,16,LEAVES:12)
Block(-7,16,6,LEAVES:12)
Block(-7,16,10,LEAVES:12)
Block(-7,16,11,LEAVES:12)
Block(-7,16,14,LEAVES:12)
Block(-7,16,15,LEAVES:12)
Block(-7,16,17,LEAVES:12)
Block(-7,16,18,LEAVES:12)
Block(-7,16,21,LEAVES:12)
Block(-7,17,14,LEAVES:12)
Block(-7,17,15,LEAVES:12)
Block(-7,17,17,LEAVES:12)
Block(-7,18,18,LEAVES:12)
Block(-7,18,19,LEAVES:12)
Block(-6,12,6,LEAVES:12)
Block(-6,12,10,LEAVES:12)
Block(-6,12,11,LEAVES:12)
Block(-6,13,2,LEAVES:12)
Block(-6,13,3,LEAVES:12)
Block(-6,13,8,LEAVES:12)
Block(-6,13,9,LEAVES:12)
Block(-6,13,10,LEAVES:12)
Block(-6,14,3,LEAVES:12)
Block(-6,14,7,LEAVES:12)
Block(-6,14,9,LEAVES:12)
Block(-6,14,12,LEAVES:12)
Block(-6,14,13,LEAVES:12)
Block(-6,14,14,LEAVES:12)
Block(-6,14,18,LEAVES:12)
Block(-6,14,19,LEAVES:12)
Block(-6,15,7,LEAVES:12)
Block(-6,15,8,LEAVES:12)
Block(-6,15,9,LEAVES:12)
Block(-6,15,10,LEAVES:12)
Block(-6,15,11,LEAVES:12)
Block(-6,15,12,LEAVES:12)
Block(-6,15,16,LEAVES:12)
Block(-6,15,17,LEAVES:12)
Block(-6,15,18,LEAVES:12)
Block(-6,16,3,LEAVES:12)
Block(-6,16,6,LEAVES:12)
Block(-6,16,9,LEAVES:12)
Block(-6,16,10,LEAVES:12)
Block(-6,16,11,LEAVES:12)
Block(-6,16,15,LEAVES:12)
Block(-6,16,17,LEAVES:12)
Block(-6,16,20,LEAVES:12)
Block(-6,16,21,LEAVES:12)
Block(-6,17,6,LEAVES:12)
Block(-6,17,15,LEAVES:12)
Block(-6,17,17,LEAVES:12)
Block(-6,17,20,LEAVES:12)
Block(-6,18,17,LEAVES:12)
Block(-6,18,18,LEAVES:12)
Block(-5,12,4,LEAVES:12)
Block(-5,12,6,LEAVES:12)
Block(-5,12,7,LEAVES:12)
Block(-5,13,2,LEAVES:12)
Block(-5,13,8,LEAVES:12)
Block(-5,13,9,LEAVES:12)
Block(-5,14,3,LEAVES:12)
Block(-5,14,4,LEAVES:12)
Block(-5,14,5,LEAVES:12)
Block(-5,14,14,LEAVES:12)
Block(-5,14,15,LEAVES:12)
Block(-5,15,5,LEAVES:12)
Block(-5,15,6,LEAVES:12)
Block(-5,15,7,LEAVES:12)
Block(-5,15,8,LEAVES:12)
Block(-5,15,9,LEAVES:12)
Block(-5,15,10,LEAVES:12)
Block(-5,15,11,LEAVES:12)
Block(-5,15,12,LEAVES:12)
Block(-5,15,16,LEAVES:12)
Block(-5,15,17,LEAVES:12)
Block(-5,16,3,LEAVES:12)
Block(-5,16,4,LEAVES:12)
Block(-5,16,6,LEAVES:12)
Block(-5,16,8,LEAVES:12)
Block(-5,16,11,LEAVES:12)
Block(-5,16,12,LEAVES:12)
Block(-5,16,13,LEAVES:12)
Block(-5,17,6,LEAVES:12)
Block(-5,17,7,LEAVES:12)
Block(-5,17,13,LEAVES:12)
Block(-5,17,14,LEAVES:12)
Block(-5,17,15,LEAVES:12)
Block(-5,17,16,LEAVES:12)
Block(-5,17,17,LEAVES:12)
Block(-5,17,18,LEAVES:12)
Block(-5,17,19,LEAVES:12)
Block(-5,17,20,LEAVES:12)
Block(-5,18,14,LEAVES:12)
Block(-4,11,11,LEAVES:12)
Block(-4,11,12,LEAVES:12)
Block(-4,11,13,LEAVES:12)
Block(-4,12,4,LEAVES:12)
Block(-4,12,7,LEAVES:12)
Block(-4,12,8,LEAVES:12)
Block(-4,12,11,LEAVES:12)
Block(-4,13,-1,LEAVES:12)
Block(-4,13,2,LEAVES:12)
Block(-4,13,8,LEAVES:12)
Block(-4,13,13,LEAVES:12)
Block(-4,13,14,LEAVES:12)
Block(-4,13,15,LEAVES:12)
Block(-4,13,19,LEAVES:12)
Block(-4,13,20,LEAVES:12)
Block(-4,13,21,LEAVES:12)
Block(-4,14,2,LEAVES:12)
Block(-4,14,3,LEAVES:12)
Block(-4,14,4,LEAVES:12)
Block(-4,14,5,LEAVES:12)
Block(-4,14,8,LEAVES:12)
Block(-4,14,9,LOG2:12)
Block(-4,14,10,LOG2:12)
Block(-4,14,15,LEAVES:12)
Block(-4,14,16,LEAVES:12)
Block(-4,14,19,LEAVES:12)
Block(-4,15,6,LEAVES:12)
Block(-4,15,8,LEAVES:12)
Block(-4,15,9,LEAVES:12)
Block(-4,15,16,LEAVES:12)
Block(-4,15,21,LEAVES:12)
Block(-4,15,22,LEAVES:12)
Block(-4,15,23,LEAVES:12)
Block(-4,16,4,LEAVES:12)
Block(-4,16,5,LEAVES:12)
Block(-4,16,6,LEAVES:12)
Block(-4,16,7,LEAVES:12)
Block(-4,16,8,LEAVES:12)
Block(-4,16,9,LEAVES:12)
Block(-4,16,11,LEAVES:12)
Block(-4,16,13,LEAVES:12)
Block(-4,16,16,LEAVES:12)
Block(-4,16,17,LOG2:12)
Block(-4,17,4,LEAVES:12)
Block(-4,17,5,LEAVES:12)
Block(-4,17,7,LEAVES:12)
Block(-4,17,16,LEAVES:12)
Block(-4,17,17,LEAVES:12)
Block(-4,18,8,LEAVES:12)
Block(-4,18,9,LEAVES:12)
Block(-4,18,13,LEAVES:12)
Block(-4,18,14,LEAVES:12)
Block(-4,18,17,LEAVES:12)
Block(-3,12,1,LEAVES:12)
Block(-3,12,4,LEAVES:12)
Block(-3,12,7,LEAVES:12)
Block(-3,12,10,LEAVES:12)
Block(-3,12,11,LEAVES:12)
Block(-3,13,-1,LEAVES:12)
Block(-3,13,0,LEAVES:12)
Block(-3,13,4,LEAVES:12)
Block(-3,13,7,LEAVES:12)
Block(-3,13,10,LEAVES:12)
Block(-3,13,12,LEAVES:12)
Block(-3,13,13,LEAVES:12)
Block(-3,14,2,LEAVES:12)
Block(-3,14,3,LEAVES:12)
Block(-3,14,4,LEAVES:12)
Block(-3,14,5,LEAVES:12)
Block(-3,14,6,LEAVES:12)
Block(-3,14,8,LEAVES:12)
Block(-3,14,9,LEAVES:12)
Block(-3,14,11,LEAVES:12)
Block(-3,14,12,LEAVES:12)
Block(-3,14,15,LEAVES:12)
Block(-3,14,18,LEAVES:12)
Block(-3,14,19,LEAVES:12)
Block(-3,15,0,LEAVES:12)
Block(-3,15,1,LEAVES:12)
Block(-3,15,4,LEAVES:12)
Block(-3,15,6,LEAVES:12)
Block(-3,15,7,LEAVES:12)
Block(-3,15,8,LEAVES:12)
Block(-3,15,10,LOG2:12)
Block(-3,15,11,LEAVES:12)
Block(-3,15,12,LEAVES:12)
Block(-3,15,18,LEAVES:12)
Block(-3,15,20,LEAVES:12)
Block(-3,15,21,LEAVES:12)
Block(-3,15,24,LEAVES:12)
Block(-3,16,1,LEAVES:12)
Block(-3,16,5,LEAVES:12)
Block(-3,16,7,LEAVES:12)
Block(-3,16,9,LEAVES:12)
Block(-3,16,10,LEAVES:12)
Block(-3,16,11,LEAVES:12)
Block(-3,16,12,LEAVES:12)
Block(-3,16,13,LEAVES:12)
Block(-3,16,14,LEAVES:12)
Block(-3,16,16,LEAVES:12)
Block(-3,16,17,LOG2:12)
Block(-3,16,18,LEAVES:12)
Block(-3,16,19,LEAVES:12)
Block(-3,16,20,LEAVES:12)
Block(-3,16,22,LEAVES:12)
Block(-3,17,5,LEAVES:12)
Block(-3,17,7,LEAVES:12)
Block(-3,17,10,LEAVES:12)
Block(-3,17,12,LEAVES:12)
Block(-3,17,14,LEAVES:12)
Block(-3,17,19,LEAVES:12)
Block(-3,18,7,LEAVES:12)
Block(-3,18,8,LEAVES:12)
Block(-3,18,17,LEAVES:12)
Block(-2,11,-1,LEAVES:12)
Block(-2,11,0,LEAVES:12)
Block(-2,11,5,LEAVES:12)
Block(-2,11,6,LEAVES:12)
Block(-2,12,2,LEAVES:12)
Block(-2,12,6,LEAVES:12)
Block(-2,12,7,LEAVES:12)
Block(-2,13,0,LEAVES:12)
Block(-2,13,1,LEAVES:12)
Block(-2,13,3,LEAVES:12)
Block(-2,13,4,LEAVES:12)
Block(-2,13,7,LEAVES:12)
Block(-2,14,0,LEAVES:12)
Block(-2,14,1,LEAVES:12)
Block(-2,14,3,LEAVES:12)
Block(-2,14,4,LEAVES:12)
Block(-2,14,5,LEAVES:12)
Block(-2,14,9,LEAVES:12)
Block(-2,14,14,LEAVES:12)
Block(-2,14,15,LEAVES:12)
Block(-2,15,2,LEAVES:12)
Block(-2,15,3,LEAVES:12)
Block(-2,15,4,LEAVES:12)
Block(-2,15,5,LEAVES:12)
Block(-2,15,6,LEAVES:12)
Block(-2,15,7,LEAVES:12)
Block(-2,15,10,LOG2:12)
Block(-2,15,11,LOG2:12)
Block(-2,15,12,LEAVES:12)
Block(-2,15,24,LEAVES:12)
Block(-2,16,1,LEAVES:12)
Block(-2,16,2,LEAVES:12)
Block(-2,16,3,LEAVES:12)
Block(-2,16,8,LEAVES:12)
Block(-2,16,9,LEAVES:12)
Block(-2,16,16,LOG2:12)
Block(-2,16,17,LOG2:12)
Block(-2,16,19,LEAVES:12)
Block(-2,16,22,LEAVES:12)
Block(-2,17,3,LEAVES:12)
Block(-2,17,4,LEAVES:12)
Block(-2,17,5,LEAVES:12)
Block(-2,17,6,LEAVES:12)
Block(-2,17,7,LEAVES:12)
Block(-2,17,8,LEAVES:12)
Block(-2,17,9,LEAVES:12)
Block(-2,17,10,LEAVES:12)
Block(-2,17,11,LEAVES:12)
Block(-2,17,12,LEAVES:12)
Block(-2,17,14,LEAVES:12)
Block(-2,17,19,LEAVES:12)
Block(-2,17,20,LEAVES:12)
Block(-2,17,22,LEAVES:12)
Block(-2,18,4,LEAVES:12)
Block(-2,18,16,LEAVES:12)
Block(-2,18,17,LEAVES:12)
Block(-1,11,0,LEAVES:12)
Block(-1,11,4,LEAVES:12)
Block(-1,11,5,LEAVES:12)
Block(-1,12,-4,LEAVES:12)
Block(-1,12,-3,LEAVES:12)
Block(-1,12,2,LEAVES:12)
Block(-1,12,3,LEAVES:12)
Block(-1,12,4,LEAVES:12)
Block(-1,12,5,LEAVES:12)
Block(-1,12,6,LEAVES:12)
Block(-1,13,-3,LEAVES:12)
Block(-1,13,1,LEAVES:12)
Block(-1,13,3,LEAVES:12)
Block(-1,13,6,LEAVES:12)
Block(-1,13,7,LEAVES:12)
Block(-1,13,9,LEAVES:12)
Block(-1,13,10,LEAVES:12)
Block(-1,13,11,LEAVES:12)
Block(-1,14,1,LEAVES:12)
Block(-1,14,3,LEAVES:12)
Block(-1,14,5,LEAVES:12)
Block(-1,14,6,LEAVES:12)
Block(-1,14,9,LEAVES:12)
Block(-1,14,10,LEAVES:12)
Block(-1,14,13,LEAVES:12)
Block(-1,14,14,LEAVES:12)
Block(-1,15,3,LEAVES:12)
Block(-1,15,4,LEAVES:12)
Block(-1,15,6,LEAVES:12)
Block(-1,15,9,LEAVES:12)
Block(-1,15,11,LOG2:12)
Block(-1,15,12,LEAVES:12)
Block(-1,15,13,LEAVES:12)
Block(-1,15,18,LEAVES:12)
Block(-1,15,21,LEAVES:12)
Block(-1,15,24,LEAVES:12)
Block(-1,16,3,LEAVES:12)
Block(-1,16,7,LOG2:12)
Block(-1,16,11,LOG2:12)
Block(-1,16,14,LEAVES:12)
Block(-1,16,16,LOG2:12)
Block(-1,16,17,LEAVES:12)
Block(-1,16,18,LEAVES:12)
Block(-1,16,19,LEAVES:12)
Block(-1,16,20,LEAVES:12)
Block(-1,16,24,LEAVES:12)
Block(-1,16,27,LEAVES:12)
Block(-1,17,6,LEAVES:12)
Block(-1,17,7,LEAVES:12)
Block(-1,17,14,LEAVES:12)
Block(-1,17,15,LOG2:12)
Block(-1,17,16,LOG2:12)
Block(-1,17,17,LEAVES:12)
Block(-1,17,20,LEAVES:12)
Block(-1,17,21,LEAVES:12)
Block(-1,17,22,LEAVES:12)
Block(-1,17,23,LEAVES:12)
Block(-1,18,3,LEAVES:12)
Block(-1,18,4,LEAVES:12)
Block(-1,18,7,LEAVES:12)
Block(0,11,0,LEAVES:12)
Block(0,11,1,LEAVES:12)
Block(0,12,2,LEAVES:12)
Block(0,12,3,LEAVES:12)
Block(0,13,-3,LEAVES:12)
Block(0,13,-2,LEAVES:12)
Block(0,13,-1,LEAVES:12)
Block(0,13,10,LEAVES:12)
Block(0,13,11,LEAVES:12)
Block(0,14,-1,LEAVES:12)
Block(0,14,0,LEAVES:12)
Block(0,14,1,LEAVES:12)
Block(0,14,2,LEAVES:12)
Block(0,14,3,LEAVES:12)
Block(0,14,4,LEAVES:12)
Block(0,14,5,LEAVES:12)
Block(0,14,6,LEAVES:12)
Block(0,14,8,LEAVES:12)
Block(0,14,9,LEAVES:12)
Block(0,14,14,LEAVES:12)
Block(0,14,19,LEAVES:12)
Block(0,14,20,LEAVES:12)
Block(0,14,25,LEAVES:12)
Block(0,14,26,LEAVES:12)
Block(0,15,0,LEAVES:12)
Block(0,15,2,LEAVES:12)
Block(0,15,8,LEAVES:12)
Block(0,15,9,LEAVES:12)
Block(0,15,10,LEAVES:12)
Block(0,15,11,LEAVES:12)
Block(0,15,18,LEAVES:12)
Block(0,15,19,LEAVES:12)
Block(0,15,22,LEAVES:12)
Block(0,16,2,LEAVES:12)
Block(0,16,3,LEAVES:12)
Block(0,16,4,LEAVES:12)
Block(0,16,6,LEAVES:12)
Block(0,16,7,LOG2:12)
Block(0,16,9,LEAVES:12)
Block(0,16,10,LEAVES:12)
Block(0,16,12,LOG2:12)
Block(0,16,13,LEAVES:12)
Block(0,16,14,LEAVES:12)
Block(0,16,20,LEAVES:12)
Block(0,16,21,LEAVES:12)
Block(0,16,22,LEAVES:12)
Block(0,16,23,LEAVES:12)
Block(0,16,24,LEAVES:12)
Block(0,16,27,LEAVES:12)
Block(0,17,2,LEAVES:12)
Block(0,17,4,LEAVES:12)
Block(0,17,8,LOG2:12)
Block(0,17,9,LEAVES:12)
Block(0,17,15,LOG2:12)
Block(0,17,16,LEAVES:12)
Block(0,17,17,LEAVES:12)
Block(0,17,20,LEAVES:12)
Block(0,17,21,LEAVES:12)
Block(0,17,23,LEAVES:12)
Block(0,18,7,LEAVES:12)
Block(0,18,9,LEAVES:12)
Block(0,18,24,LEAVES:12)
Block(0,18,25,LEAVES:12)
Block(0,19,7,LEAVES:12)
Block(1,10,5,LEAVES:12)
Block(1,10,6,LEAVES:12)
Block(1,10,7,LEAVES:12)
Block(1,11,1,LEAVES:12)
Block(1,11,2,LEAVES:12)
Block(1,11,5,LEAVES:12)
Block(1,12,2,LEAVES:12)
Block(1,12,7,LEAVES:12)
Block(1,12,8,LEAVES:12)
Block(1,12,9,LEAVES:12)
Block(1,13,-1,LEAVES:12)
Block(1,13,2,LEAVES:12)
Block(1,13,3,LOG2:12)
Block(1,13,11,LEAVES:12)
Block(1,13,12,LEAVES:12)
Block(1,14,2,LEAVES:12)
Block(1,14,3,LEAVES:12)
Block(1,14,4,LEAVES:12)
Block(1,14,5,LEAVES:12)
Block(1,14,20,LEAVES:12)
Block(1,14,24,LEAVES:12)
Block(1,14,25,LEAVES:12)
Block(1,15,-1,LEAVES:12)
Block(1,15,0,LEAVES:12)
Block(1,15,1,LEAVES:12)
Block(1,15,2,LEAVES:12)
Block(1,15,3,LEAVES:12)
Block(1,15,8,LEAVES:12)
Block(1,15,16,LEAVES:12)
Block(1,15,17,LEAVES:12)
Block(1,15,19,LEAVES:12)
Block(1,15,20,LEAVES:12)
Block(1,15,22,LEAVES:12)
Block(1,15,23,LEAVES:12)
Block(1,15,24,LEAVES:12)
Block(1,16,7,LEAVES:12)
Block(1,16,12,LOG2:12)
Block(1,16,13,LEAVES:12)
Block(1,16,17,LEAVES:12)
Block(1,16,21,LEAVES:12)
Block(1,16,23,LEAVES:12)
Block(1,16,26,LEAVES:12)
Block(1,16,27,LEAVES:12)
Block(1,17,0,LEAVES:12)
Block(1,17,1,LEAVES:12)
Block(1,17,2,LEAVES:12)
Block(1,17,4,LEAVES:12)
Block(1,17,8,LOG2:12)
Block(1,17,9,LOG2:12)
Block(1,17,10,LEAVES:12)
Block(1,17,14,LOG2:12)
Block(1,17,16,LEAVES:12)
Block(1,17,21,LEAVES:12)
Block(1,17,23,LEAVES:12)
Block(1,17,26,LEAVES:12)
Block(1,18,6,LEAVES:12)
Block(1,18,7,LEAVES:12)
Block(1,18,9,LEAVES:12)
Block(1,18,23,LEAVES:12)
Block(1,18,24,LEAVES:12)
Block(1,19,4,LEAVES:12)
Block(1,19,7,LEAVES:12)
Block(1,20,7,LEAVES:12)
Block(2,11,1,LEAVES:12)
Block(2,11,4,LEAVES:12)
Block(2,11,5,LEAVES:12)
Block(2,12,-2,LEAVES:12)
Block(2,12,4,LEAVES:12)
Block(2,12,6,LEAVES:12)
Block(2,12,7,LEAVES:12)
Block(2,13,-2,LEAVES:12)
Block(2,13,-1,LEAVES:12)
Block(2,13,0,LEAVES:12)
Block(2,13,2,LEAVES:12)
Block(2,13,3,LOG2:12)
Block(2,13,5,LEAVES:12)
Block(2,13,6,LEAVES:12)
Block(2,14,-2,LEAVES:12)
Block(2,14,0,LEAVES:12)
Block(2,14,3,LEAVES:12)
Block(2,14,4,LOG2:12)
Block(2,14,5,LEAVES:12)
Block(2,14,20,LEAVES:12)
Block(2,14,21,LEAVES:12)
Block(2,15,1,LEAVES:12)
Block(2,15,3,LEAVES:12)
Block(2,15,8,LEAVES:12)
Block(2,15,22,LEAVES:12)
Block(2,15,23,LEAVES:12)
Block(2,16,4,LEAVES:12)
Block(2,16,7,LEAVES:12)
Block(2,16,8,LEAVES:12)
Block(2,16,11,LOG2:12)
Block(2,16,12,LOG2:12)
Block(2,16,13,LOG2:12)
Block(2,16,14,LOG2:12)
Block(2,16,17,LEAVES:12)
Block(2,16,18,LEAVES:12)
Block(2,16,19,LEAVES:12)
Block(2,17,4,LEAVES:12)
Block(2,17,7,LEAVES:12)
Block(2,17,9,LOG2:12)
Block(2,17,10,LOG2:12)
Block(2,17,11,LOG2:12)
Block(2,17,14,LOG2:12)
Block(2,17,19,LEAVES:12)
Block(2,17,20,LEAVES:12)
Block(2,17,21,LEAVES:12)
Block(2,17,22,LEAVES:12)
Block(2,17,23,LEAVES:12)
Block(2,17,24,LEAVES:12)
Block(2,17,25,LEAVES:12)
Block(2,17,26,LEAVES:12)
Block(2,18,6,LEAVES:12)
Block(2,18,9,LEAVES:12)
Block(2,18,20,LEAVES:12)
Block(2,19,4,LEAVES:12)
Block(2,19,5,LEAVES:12)
Block(2,19,9,LEAVES:12)
Block(2,19,12,LEAVES:12)
Block(2,20,7,LEAVES:12)
Block(2,20,8,LEAVES:12)
Block(3,11,0,LEAVES:12)
Block(3,11,1,LEAVES:12)
Block(3,12,-3,LEAVES:12)
Block(3,12,-2,LEAVES:12)
Block(3,12,12,LOG2:12)
Block(3,13,3,LEAVES:12)
Block(3,13,12,LOG2:12)
Block(3,13,25,LEAVES:12)
Block(3,13,26,LEAVES:12)
Block(3,13,27,LEAVES:12)
Block(3,14,-4,LEAVES:12)
Block(3,14,-3,LEAVES:12)
Block(3,14,-2,LEAVES:12)
Block(3,14,0,LEAVES:12)
Block(3,14,3,LEAVES:12)
Block(3,14,4,LOG2:12)
Block(3,14,5,LOG2:12)
Block(3,14,6,LOG2:12)
Block(3,14,12,LOG2:12)
Block(3,14,21,LEAVES:12)
Block(3,14,22,LEAVES:12)
Block(3,14,25,LEAVES:12)
Block(3,15,1,LEAVES:12)
Block(3,15,2,LEAVES:12)
Block(3,15,3,LEAVES:12)
Block(3,15,8,LEAVES:12)
Block(3,15,9,LEAVES:12)
Block(3,15,13,LOG2:12)
Block(3,15,22,LEAVES:12)
Block(3,15,27,LEAVES:12)
Block(3,15,28,LEAVES:12)
Block(3,15,29,LEAVES:12)
Block(3,16,3,LEAVES:12)
Block(3,16,4,LEAVES:12)
Block(3,16,12,LEAVES:12)
Block(3,16,13,LOG2:12)
Block(3,16,19,LEAVES:12)
Block(3,16,21,LOG2:12)
Block(3,16,23,LOG2:12)
Block(3,17,4,LEAVES:12)
Block(3,17,5,LEAVES:12)
Block(3,17,6,LEAVES:12)
Block(3,17,7,LEAVES:12)
Block(3,17,10,LEAVES:12)
Block(3,17,11,LEAVES:12)
Block(3,17,21,LOG2:12)
Block(3,17,22,LEAVES:12)
Block(3,17,23,LEAVES:12)
Block(3,18,7,LEAVES:12)
Block(3,18,19,LEAVES:12)
Block(3,18,20,LEAVES:12)
Block(3,18,23,LEAVES:12)
Block(3,19,5,LEAVES:12)
Block(3,19,6,LEAVES:12)
Block(3,19,8,LEAVES:12)
Block(3,19,9,LEAVES:12)
Block(3,19,12,LEAVES:12)
Block(3,20,5,LEAVES:12)
Block(3,20,6,LEAVES:12)
Block(3,20,8,LEAVES:12)
Block(3,21,9,LEAVES:12)
Block(3,21,10,LEAVES:12)
Block(4,8,11,LOG2:12)
Block(4,9,11,LOG2:12)
Block(4,10,11,LOG2:12)
Block(4,10,12,LOG2:12)
Block(4,11,-1,LEAVES:12)
Block(4,11,0,LEAVES:12)
Block(4,11,11,LOG2:12)
Block(4,11,12,LOG2:12)
Block(4,12,-3,LEAVES:12)
Block(4,12,4,LEAVES:12)
Block(4,12,11,LOG2:12)
Block(4,12,12,LOG2:12)
Block(4,13,0,LEAVES:12)
Block(4,13,3,LEAVES:12)
Block(4,13,4,LEAVES:12)
Block(4,13,10,LOG2:12)
Block(4,13,11,LOG2:12)
Block(4,13,12,LOG2:12)
Block(4,13,13,LOG2:12)
Block(4,14,0,LEAVES:12)
Block(4,14,3,LEAVES:12)
Block(4,14,6,LOG2:12)
Block(4,14,7,LEAVES:12)
Block(4,14,9,LOG2:12)
Block(4,14,10,LOG2:12)
Block(4,14,12,LOG2:12)
Block(4,14,13,LOG2:12)
Block(4,14,21,LEAVES:12)
Block(4,14,24,LEAVES:12)
Block(4,14,25,LEAVES:12)
Block(4,15,-2,LEAVES:12)
Block(4,15,1,LEAVES:12)
Block(4,15,6,LOG2:12)
Block(4,15,9,LOG2:12)
Block(4,15,10,LEAVES:12)
Block(4,15,12,LOG2:12)
Block(4,15,13,LOG2:12)
Block(4,15,18,LEAVES:12)
Block(4,15,24,LEAVES:12)
Block(4,15,26,LEAVES:12)
Block(4,15,27,LEAVES:12)
Block(4,16,1,LEAVES:12)
Block(4,16,3,LEAVES:12)
Block(4,16,18,LEAVES:12)
Block(4,16,19,LEAVES:12)
Block(4,16,20,LEAVES:12)
Block(4,16,22,LEAVES:12)
Block(4,16,23,LEAVES:12)
Block(4,16,24,LEAVES:12)
Block(4,16,25,LEAVES:12)
Block(4,16,26,LEAVES:12)
Block(4,17,5,LEAVES:12)
Block(4,17,6,LEAVES:12)
Block(4,17,9,LEAVES:12)
Block(4,17,10,LEAVES:12)
Block(4,17,18,LEAVES:12)
Block(4,17,21,LOG2:12)
Block(4,17,25,LEAVES:12)
Block(4,18,1,LEAVES:12)
Block(4,18,2,LEAVES:12)
Block(4,18,7,LEAVES:12)
Block(4,18,8,LEAVES:12)
Block(4,18,9,LEAVES:12)
Block(4,18,23,LEAVES:12)
Block(4,19,2,LEAVES:12)
Block(4,19,6,LEAVES:12)
Block(4,19,8,LEAVES:12)
Block(4,19,11,LEAVES:12)
Block(4,19,12,LEAVES:12)
Block(4,20,6,LEAVES:12)
Block(4,20,8,LEAVES:12)
Block(4,20,11,LEAVES:12)
Block(4,21,8,LEAVES:12)
Block(4,21,9,LEAVES:12)
Block(5,0,10,LOG2:12)
Block(5,1,10,LOG2:12)
Block(5,2,10,LOG2:12)
Block(5,3,10,LOG2:12)
Block(5,4,10,LOG2:12)
Block(5,5,10,LOG2:12)
Block(5,5,11,LOG2:12)
Block(5,6,10,LOG2:12)
Block(5,6,11,LOG2:12)
Block(5,7,10,LOG2:12)
Block(5,7,11,LOG2:12)
Block(5,8,10,LOG2:12)
Block(5,8,11,LOG2:12)
Block(5,9,10,LOG2:12)
Block(5,9,11,LOG2:12)
Block(5,10,10,LOG2:12)
Block(5,10,11,LOG2:12)
Block(5,11,11,LOG2:12)
Block(5,12,4,LEAVES:12)
Block(5,12,5,LEAVES:12)
Block(5,13,-1,LEAVES:12)
Block(5,13,0,LEAVES:12)
Block(5,13,8,LEAVES:12)
Block(5,14,0,LEAVES:12)
Block(5,14,2,LEAVES:12)
Block(5,14,3,LEAVES:12)
Block(5,14,20,LEAVES:12)
Block(5,14,21,LEAVES:12)
Block(5,15,-2,LEAVES:12)
Block(5,15,-1,LEAVES:12)
Block(5,15,3,LEAVES:12)
Block(5,15,6,LEAVES:12)
Block(5,15,7,LOG2:12)
Block(5,15,8,LOG2:12)
Block(5,15,9,LOG2:12)
Block(5,15,13,LOG2:12)
Block(5,15,17,LEAVES:12)
Block(5,15,18,LEAVES:12)
Block(5,16,1,LEAVES:12)
Block(5,16,2,LEAVES:12)
Block(5,16,12,LOG2:12)
Block(5,16,13,LOG2:12)
Block(5,16,14,LOG2:12)
Block(5,16,15,LOG2:12)
Block(5,16,19,LOG2:12)
Block(5,16,23,LEAVES:12)
Block(5,17,5,LEAVES:12)
Block(5,17,6,LEAVES:12)
Block(5,17,11,LOG2:12)
Block(5,17,12,LOG2:12)
Block(5,17,16,LEAVES:12)
Block(5,17,17,LEAVES:12)
Block(5,17,18,LEAVES:12)
Block(5,17,19,LOG2:12)
Block(5,17,20,LEAVES:12)
Block(5,17,25,LEAVES:12)
Block(5,17,26,LEAVES:12)
Block(5,18,7,LEAVES:12)
Block(5,18,8,LEAVES:12)
Block(5,18,11,LOG2:12)
Block(5,18,17,LEAVES:12)
Block(5,18,22,LEAVES:12)
Block(5,18,23,LEAVES:12)
Block(5,19,2,LEAVES:12)
Block(5,19,3,LEAVES:12)
Block(5,19,4,LEAVES:12)
Block(5,19,10,LOG2:12)
Block(5,19,11,LOG2:12)
Block(5,20,4,LEAVES:12)
Block(5,20,5,LEAVES:12)
Block(5,20,6,LEAVES:12)
Block(5,20,7,LEAVES:12)
Block(5,20,8,LEAVES:12)
Block(5,20,9,LEAVES:12)
Block(5,20,10,LEAVES:12)
Block(5,20,11,LEAVES:12)
Block(5,21,5,LEAVES:12)
Block(6,0,9,LOG2:12)
Block(6,0,10,LOG2:12)
Block(6,0,11,LOG2:12)
Block(6,1,9,LOG2:12)
Block(6,1,10,LOG2:12)
Block(6,1,11,LOG2:12)
Block(6,2,9,LOG2:12)
Block(6,2,10,LOG2:12)
Block(6,3,9,LOG2:12)
Block(6,3,10,LOG2:12)
Block(6,4,9,LOG2:12)
Block(6,4,10,LOG2:12)
Block(6,5,10,LOG2:12)
Block(6,6,10,LOG2:12)
Block(6,7,10,LOG2:12)
Block(6,12,5,LEAVES:12)
Block(6,12,6,LEAVES:12)
Block(6,13,-2,LEAVES:12)
Block(6,13,-1,LEAVES:12)
Block(6,13,4,LEAVES:12)
Block(6,13,5,LEAVES:12)
Block(6,13,22,LEAVES:12)
Block(6,14,1,LEAVES:12)
Block(6,14,2,LEAVES:12)
Block(6,14,19,LEAVES:12)
Block(6,14,20,LEAVES:12)
Block(6,15,-1,LEAVES:12)
Block(6,15,0,LEAVES:12)
Block(6,15,2,LEAVES:12)
Block(6,15,3,LEAVES:12)
Block(6,15,6,LEAVES:12)
Block(6,15,9,LOG2:12)
Block(6,15,17,LEAVES:12)
Block(6,15,24,LEAVES:12)
Block(6,16,-1,LEAVES:12)
Block(6,16,0,LEAVES:12)
Block(6,16,2,LEAVES:12)
Block(6,16,5,LOG2:12)
Block(6,16,7,LOG2:12)
Block(6,16,9,LOG2:12)
Block(6,16,10,LEAVES:12)
Block(6,16,11,LEAVES:12)
Block(6,16,12,LEAVES:12)
Block(6,16,15,LOG2:12)
Block(6,16,16,LOG2:12)
Block(6,16,20,LEAVES:12)
Block(6,16,23,LEAVES:12)
Block(6,16,24,LEAVES:12)
Block(6,17,-1,LEAVES:12)
Block(6,17,3,LEAVES:12)
Block(6,17,4,LEAVES:12)
Block(6,17,6,LEAVES:12)
Block(6,17,7,LEAVES:12)
Block(6,17,10,LEAVES:12)
Block(6,17,15,LOG2:12)
Block(6,17,19,LEAVES:12)
Block(6,17,20,LEAVES:12)
Block(6,17,23,LEAVES:12)
Block(6,17,26,LEAVES:12)
Block(6,17,27,LEAVES:12)
Block(6,18,7,LEAVES:12)
Block(6,18,12,LEAVES:12)
Block(6,18,13,LEAVES:12)
Block(6,18,14,LEAVES:12)
Block(6,18,17,LEAVES:12)
Block(6,19,4,LEAVES:12)
Block(6,19,7,LEAVES:12)
Block(6,19,8,LOG2:12)
Block(6,19,9,LOG2:12)
Block(6,19,10,LOG2:12)
Block(6,19,17,LEAVES:12)
Block(6,20,7,LEAVES:12)
Block(6,20,8,LEAVES:12)
Block(6,21,4,LEAVES:12)
Block(6,21,5,LEAVES:12)
Block(6,21,8,LEAVES:12)
Block(7,13,-1,LEAVES:12)
Block(7,13,3,LEAVES:12)
Block(7,13,4,LEAVES:12)
Block(7,13,22,LEAVES:12)
Block(7,14,-5,LEAVES:12)
Block(7,14,-4,LEAVES:12)
Block(7,14,1,LEAVES:12)
Block(7,14,2,LEAVES:12)
Block(7,14,3,LEAVES:12)
Block(7,14,17,LEAVES:12)
Block(7,14,20,LEAVES:12)
Block(7,15,-4,LEAVES:12)
Block(7,15,0,LEAVES:12)
Block(7,15,2,LEAVES:12)
Block(7,15,5,LEAVES:12)
Block(7,15,6,LEAVES:12)
Block(7,15,20,LEAVES:12)
Block(7,15,24,LEAVES:12)
Block(7,15,25,LEAVES:12)
Block(7,16,0,LEAVES:12)
Block(7,16,2,LEAVES:12)
Block(7,16,4,LOG2:12)
Block(7,16,9,LOG2:12)
Block(7,16,17,LOG2:12)
Block(7,16,18,LOG2:12)
Block(7,16,19,LEAVES:12)
Block(7,16,20,LEAVES:12)
Block(7,16,28,LEAVES:12)
Block(7,17,2,LEAVES:12)
Block(7,17,3,LEAVES:12)
Block(7,17,6,LEAVES:12)
Block(7,17,9,LEAVES:12)
Block(7,17,10,LEAVES:12)
Block(7,17,14,LEAVES:12)
Block(7,17,15,LOG2:12)
Block(7,17,16,LEAVES:12)
Block(7,17,19,LEAVES:12)
Block(7,17,22,LEAVES:12)
Block(7,17,23,LEAVES:12)
Block(7,18,3,LEAVES:12)
Block(7,18,9,LEAVES:12)
Block(7,18,11,LEAVES:12)
Block(7,18,12,LEAVES:12)
Block(7,18,14,LEAVES:12)
Block(7,18,15,LOG2:12)
Block(7,18,19,LEAVES:12)
Block(7,18,22,LEAVES:12)
Block(7,19,3,LEAVES:12)
Block(7,19,4,LEAVES:12)
Block(7,19,5,LEAVES:12)
Block(7,19,7,LOG2:12)
Block(7,19,8,LOG2:12)
Block(7,19,9,LEAVES:12)
Block(7,19,10,LEAVES:12)
Block(7,19,11,LEAVES:12)
Block(7,19,17,LEAVES:12)
Block(7,19,18,LEAVES:12)
Block(7,20,3,LEAVES:12)
Block(7,20,5,LEAVES:12)
Block(7,20,10,LEAVES:12)
Block(7,21,8,LEAVES:12)
Block(8,13,-1,LEAVES:12)
Block(8,13,0,LEAVES:12)
Block(8,13,19,LEAVES:12)
Block(8,13,22,LEAVES:12)
Block(8,14,1,LEAVES:12)
Block(8,14,2,LEAVES:12)
Block(8,14,17,LEAVES:12)
Block(8,14,18,LEAVES:12)
Block(8,14,22,LEAVES:12)
Block(8,14,25,LEAVES:12)
Block(8,15,-4,LEAVES:12)
Block(8,15,-3,LEAVES:12)
Block(8,15,-2,LEAVES:12)
Block(8,15,3,LOG2:12)
Block(8,15,4,LOG2:12)
Block(8,15,8,LEAVES:12)
Block(8,15,19,LOG2:12)
Block(8,15,20,LEAVES:12)
Block(8,15,21,LEAVES:12)
Block(8,15,25,LEAVES:12)
Block(8,15,26,LEAVES:12)
Block(8,16,-2,LEAVES:12)
Block(8,16,-1,LEAVES:12)
Block(8,16,0,LEAVES:12)
Block(8,16,1,LEAVES:12)
Block(8,16,2,LEAVES:12)
Block(8,16,3,LEAVES:12)
Block(8,16,4,LOG2:12)
Block(8,16,5,LEAVES:12)
Block(8,16,6,LEAVES:12)
Block(8,16,9,LOG2:12)
Block(8,16,14,LEAVES:12)
Block(8,16,15,LEAVES:12)
Block(8,16,18,LOG2:12)
Block(8,16,19,LEAVES:12)
Block(8,16,20,LEAVES:12)
Block(8,16,21,LEAVES:12)
Block(8,17,-1,LEAVES:12)
Block(8,17,5,LEAVES:12)
Block(8,17,6,LEAVES:12)
Block(8,17,14,LEAVES:12)
Block(8,17,17,LEAVES:12)
Block(8,17,22,LEAVES:12)
Block(8,18,2,LEAVES:12)
Block(8,18,3,LEAVES:12)
Block(8,18,9,LEAVES:12)
Block(8,18,12,LEAVES:12)
Block(8,18,15,LEAVES:12)
Block(8,18,16,LOG2:12)
Block(8,18,18,LEAVES:12)
Block(8,18,19,LEAVES:12)
Block(8,18,22,LEAVES:12)
Block(8,19,8,LEAVES:12)
Block(8,19,12,LEAVES:12)
Block(8,19,15,LEAVES:12)
Block(8,19,16,LEAVES:12)
Block(8,19,18,LEAVES:12)
Block(8,20,1,LEAVES:12)
Block(8,20,2,LEAVES:12)
Block(8,20,3,LEAVES:12)
Block(8,20,5,LEAVES:12)
Block(8,20,10,LEAVES:12)
Block(8,20,11,LEAVES:12)
Block(8,20,19,LEAVES:12)
Block(8,20,20,LEAVES:12)
Block(8,21,7,LEAVES:12)
Block(8,21,8,LEAVES:12)
Block(9,12,4,LEAVES:12)
Block(9,12,5,LEAVES:12)
Block(9,12,6,LEAVES:12)
Block(9,12,17,LEAVES:12)
Block(9,12,18,LEAVES:12)
Block(9,12,23,LEAVES:12)
Block(9,12,24,LEAVES:12)
Block(9,13,0,LEAVES:12)
Block(9,13,1,LEAVES:12)
Block(9,13,4,LEAVES:12)
Block(9,13,20,LEAVES:12)
Block(9,14,1,LEAVES:12)
Block(9,14,6,LEAVES:12)
Block(9,14,7,LEAVES:12)
Block(9,14,8,LEAVES:12)
Block(9,14,18,LEAVES:12)
Block(9,14,19,LEAVES:12)
Block(9,14,21,LEAVES:12)
Block(9,14,22,LEAVES:12)
Block(9,14,25,LEAVES:12)
Block(9,15,-2,LEAVES:12)
Block(9,15,1,LEAVES:12)
Block(9,15,2,LOG2:12)
Block(9,15,3,LOG2:12)
Block(9,15,8,LEAVES:12)
Block(9,15,18,LEAVES:12)
Block(9,15,21,LEAVES:12)
Block(9,16,1,LEAVES:12)
Block(9,16,2,LEAVES:12)
Block(9,16,3,LEAVES:12)
Block(9,16,6,LEAVES:12)
Block(9,16,9,LOG2:12)
Block(9,16,15,LEAVES:12)
Block(9,16,19,LEAVES:12)
Block(9,16,20,LEAVES:12)
Block(9,16,22,LEAVES:12)
Block(9,16,23,LEAVES:12)
Block(9,17,-2,LEAVES:12)
Block(9,17,-1,LEAVES:12)
Block(9,17,2,LEAVES:12)
Block(9,17,4,LEAVES:12)
Block(9,17,5,LEAVES:12)
Block(9,17,6,LEAVES:12)
Block(9,17,8,LOG2:12)
Block(9,17,9,LOG2:12)
Block(9,17,10,LOG2:12)
Block(9,17,11,LEAVES:12)
Block(9,17,12,LEAVES:12)
Block(9,17,14,LEAVES:12)
Block(9,17,17,LEAVES:12)
Block(9,17,18,LEAVES:12)
Block(9,17,19,LEAVES:12)
Block(9,18,2,LEAVES:12)
Block(9,18,9,LEAVES:12)
Block(9,18,10,LEAVES:12)
Block(9,18,12,LEAVES:12)
Block(9,18,14,LEAVES:12)
Block(9,18,16,LEAVES:12)
Block(9,18,18,LEAVES:12)
Block(9,18,21,LEAVES:12)
Block(9,18,22,LEAVES:12)
Block(9,19,5,LEAVES:12)
Block(9,19,8,LEAVES:12)
Block(9,19,9,LEAVES:12)
Block(9,19,12,LEAVES:12)
Block(9,19,13,LEAVES:12)
Block(9,19,16,LEAVES:12)
Block(9,19,18,LEAVES:12)
Block(9,19,21,LEAVES:12)
Block(9,20,5,LEAVES:12)
Block(9,20,8,LEAVES:12)
Block(9,20,11,LEAVES:12)
Block(9,20,12,LEAVES:12)
Block(9,20,18,LEAVES:12)
Block(9,20,19,LEAVES:12)
Block(10,12,18,LEAVES:12)
Block(10,12,22,LEAVES:12)
Block(10,12,23,LEAVES:12)
Block(10,13,0,LEAVES:12)
Block(10,13,3,LEAVES:12)
Block(10,13,4,LEAVES:12)
Block(10,13,14,LEAVES:12)
Block(10,13,15,LEAVES:12)
Block(10,13,20,LEAVES:12)
Block(10,13,21,LEAVES:12)
Block(10,13,22,LEAVES:12)
Block(10,14,-3,LEAVES:12)
Block(10,14,3,LEAVES:12)
Block(10,14,5,LEAVES:12)
Block(10,14,6,LEAVES:12)
Block(10,14,15,LEAVES:12)
Block(10,14,19,LEAVES:12)
Block(10,14,21,LEAVES:12)
Block(10,14,24,LEAVES:12)
Block(10,14,25,LEAVES:12)
Block(10,15,-3,LEAVES:12)
Block(10,15,-2,LEAVES:12)
Block(10,15,-1,LEAVES:12)
Block(10,15,1,LEAVES:12)
Block(10,15,2,LEAVES:12)
Block(10,15,3,LEAVES:12)
Block(10,15,4,LEAVES:12)
Block(10,15,5,LEAVES:12)
Block(10,15,8,LEAVES:12)
Block(10,15,20,LOG2:12)
Block(10,15,21,LEAVES:12)
Block(10,15,24,LEAVES:12)
Block(10,16,-3,LEAVES:12)
Block(10,16,-1,LEAVES:12)
Block(10,16,3,LEAVES:12)
Block(10,16,4,LEAVES:12)
Block(10,16,8,LEAVES:12)
Block(10,16,9,LEAVES:12)
Block(10,16,10,LEAVES:12)
Block(10,16,11,LEAVES:12)
Block(10,16,15,LEAVES:12)
Block(10,16,16,LEAVES:12)
Block(10,16,21,LEAVES:12)
Block(10,16,22,LEAVES:12)
Block(10,17,2,LEAVES:12)
Block(10,17,6,LEAVES:12)
Block(10,17,7,LEAVES:12)
Block(10,17,12,LOG2:12)
Block(10,17,17,LEAVES:12)
Block(10,17,18,LEAVES:12)
Block(10,18,9,LEAVES:12)
Block(10,18,10,LEAVES:12)
Block(10,18,11,LEAVES:12)
Block(10,18,12,LEAVES:12)
Block(10,18,13,LEAVES:12)
Block(10,18,14,LEAVES:12)
Block(10,19,4,LEAVES:12)
Block(10,19,5,LEAVES:12)
Block(10,19,10,LEAVES:12)
Block(10,19,11,LEAVES:12)
Block(10,19,13,LEAVES:12)
Block(10,19,14,LEAVES:12)
Block(10,19,15,LEAVES:12)
Block(10,19,16,LEAVES:12)
Block(10,19,17,LEAVES:12)
Block(10,19,18,LEAVES:12)
Block(10,19,19,LEAVES:12)
Block(10,19,20,LEAVES:12)
Block(10,19,21,LEAVES:12)
Block(10,20,7,LEAVES:12)
Block(10,20,8,LEAVES:12)
Block(10,20,14,LEAVES:12)
Block(10,20,15,LEAVES:12)
Block(11,12,18,LEAVES:12)
Block(11,12,19,LEAVES:12)
Block(11,13,-1,LEAVES:12)
Block(11,13,0,LEAVES:12)
Block(11,13,20,LEAVES:12)
Block(11,13,21,LEAVES:12)
Block(11,14,-4,LEAVES:12)
Block(11,14,-3,LEAVES:12)
Block(11,14,3,LEAVES:12)
Block(11,14,4,LEAVES:12)
Block(11,14,9,LEAVES:12)
Block(11,14,10,LEAVES:12)
Block(11,14,15,LEAVES:12)
Block(11,14,16,LEAVES:12)
Block(11,14,17,LEAVES:12)
Block(11,15,2,LEAVES:12)
Block(11,15,6,LEAVES:12)
Block(11,15,17,LEAVES:12)
Block(11,15,18,LEAVES:12)
Block(11,15,19,LEAVES:12)
Block(11,15,20,LEAVES:12)
Block(11,15,21,LEAVES:12)
Block(11,15,22,LEAVES:12)
Block(11,15,23,LEAVES:12)
Block(11,15,24,LEAVES:12)
Block(11,16,-5,LEAVES:12)
Block(11,16,-4,LEAVES:12)
Block(11,16,-3,LEAVES:12)
Block(11,16,-1,LEAVES:12)
Block(11,16,4,LEAVES:12)
Block(11,16,5,LEAVES:12)
Block(11,16,7,LEAVES:12)
Block(11,16,8,LEAVES:12)
Block(11,16,10,LEAVES:12)
Block(11,16,11,LEAVES:12)
Block(11,16,14,LEAVES:12)
Block(11,16,15,LEAVES:12)
Block(11,16,16,LEAVES:12)
Block(11,16,17,LEAVES:12)
Block(11,16,18,LEAVES:12)
Block(11,16,20,LEAVES:12)
Block(11,17,1,LEAVES:12)
Block(11,17,2,LEAVES:12)
Block(11,17,4,LEAVES:12)
Block(11,17,5,LEAVES:12)
Block(11,17,6,LEAVES:12)
Block(11,17,7,LEAVES:12)
Block(11,17,12,LOG2:12)
Block(11,17,13,LEAVES:12)
Block(11,17,14,LEAVES:12)
Block(11,17,17,LEAVES:12)
Block(11,17,22,LEAVES:12)
Block(11,17,23,LEAVES:12)
Block(11,17,24,LEAVES:12)
Block(11,18,7,LEAVES:12)
Block(11,18,8,LEAVES:12)
Block(11,18,9,LEAVES:12)
Block(11,18,10,LEAVES:12)
Block(11,18,11,LEAVES:12)
Block(11,18,12,LOG2:12)
Block(11,18,14,LEAVES:12)
Block(11,18,16,LEAVES:12)
Block(11,18,17,LEAVES:12)
Block(11,18,18,LOG2:12)
Block(11,19,4,LEAVES:12)
Block(11,19,11,LEAVES:12)
Block(11,19,13,LEAVES:12)
Block(11,19,16,LEAVES:12)
Block(11,19,17,LEAVES:12)
Block(11,19,18,LEAVES:12)
Block(11,20,7,LEAVES:12)
Block(11,20,13,LEAVES:12)
Block(11,20,14,LEAVES:12)
Block(11,20,15,LEAVES:12)
Block(11,20,18,LEAVES:12)
Block(12,11,23,LEAVES:12)
Block(12,11,24,LEAVES:12)
Block(12,11,25,LEAVES:12)
Block(12,12,19,LEAVES:12)
Block(12,12,20,LEAVES:12)
Block(12,12,23,LEAVES:12)
Block(12,13,-2,LEAVES:12)
Block(12,13,-1,LEAVES:12)
Block(12,13,20,LEAVES:12)
Block(12,13,25,LEAVES:12)
Block(12,13,26,LEAVES:12)
Block(12,13,27,LEAVES:12)
Block(12,14,-4,LEAVES:12)
Block(12,14,3,LEAVES:12)
Block(12,14,4,LEAVES:12)
Block(12,14,8,LEAVES:12)
Block(12,14,9,LEAVES:12)
Block(12,14,17,LEAVES:12)
Block(12,14,20,LEAVES:12)
Block(12,14,21,LOG2:12)
Block(12,15,-1,LEAVES:12)
Block(12,15,0,LEAVES:12)
Block(12,15,1,LEAVES:12)
Block(12,15,2,LEAVES:12)
Block(12,15,3,LEAVES:12)
Block(12,15,6,LEAVES:12)
Block(12,15,7,LEAVES:12)
Block(12,15,8,LEAVES:12)
Block(12,15,20,LEAVES:12)
Block(12,15,21,LEAVES:12)
Block(12,16,-1,LEAVES:12)
Block(12,16,1,LEAVES:12)
Block(12,16,2,LEAVES:12)
Block(12,16,5,LEAVES:12)
Block(12,16,6,LEAVES:12)
Block(12,16,10,LEAVES:12)
Block(12,16,11,LEAVES:12)
Block(12,16,16,LEAVES:12)
Block(12,16,17,LEAVES:12)
Block(12,16,18,LEAVES:12)
Block(12,16,19,LEAVES:12)
Block(12,16,20,LEAVES:12)
Block(12,16,21,LEAVES:12)
Block(12,17,5,LEAVES:12)
Block(12,17,7,LOG2:12)
Block(12,17,8,LOG2:12)
Block(12,17,10,LEAVES:12)
Block(12,17,12,LEAVES:12)
Block(12,17,13,LEAVES:12)
Block(12,17,19,LEAVES:12)
Block(12,17,21,LEAVES:12)
Block(12,17,22,LEAVES:12)
Block(12,18,7,LEAVES:12)
Block(12,18,8,LEAVES:12)
Block(12,18,9,LEAVES:12)
Block(12,18,14,LEAVES:12)
Block(12,18,15,LEAVES:12)
Block(12,18,17,LEAVES:12)
Block(12,18,18,LEAVES:12)
Block(12,18,19,LEAVES:12)
Block(12,18,20,LEAVES:12)
Block(12,18,21,LEAVES:12)
Block(12,19,9,LEAVES:12)
Block(12,19,10,LEAVES:12)
Block(12,19,11,LEAVES:12)
Block(12,19,12,LEAVES:12)
Block(12,19,13,LEAVES:12)
Block(12,19,14,LEAVES:12)
Block(12,19,15,LEAVES:12)
Block(12,19,16,LEAVES:12)
Block(12,19,20,LEAVES:12)
Block(12,20,10,LEAVES:12)
Block(12,20,18,LEAVES:12)
Block(13,12,19,LEAVES:12)
Block(13,12,22,LEAVES:12)
Block(13,12,23,LEAVES:12)
Block(13,13,16,LEAVES:12)
Block(13,13,22,LEAVES:12)
Block(13,13,24,LEAVES:12)
Block(13,13,25,LEAVES:12)
Block(13,14,3,LEAVES:12)
Block(13,14,4,LEAVES:12)
Block(13,14,5,LEAVES:12)
Block(13,14,16,LEAVES:12)
Block(13,14,17,LEAVES:12)
Block(13,14,18,LEAVES:12)
Block(13,14,20,LEAVES:12)
Block(13,14,21,LEAVES:12)
Block(13,14,22,LEAVES:12)
Block(13,14,23,LEAVES:12)
Block(13,14,24,LEAVES:12)
Block(13,15,-2,LEAVES:12)
Block(13,15,-1,LEAVES:12)
Block(13,15,6,LEAVES:12)
Block(13,15,7,LEAVES:12)
Block(13,15,15,LEAVES:12)
Block(13,15,16,LEAVES:12)
Block(13,15,17,LEAVES:12)
Block(13,15,18,LEAVES:12)
Block(13,15,23,LEAVES:12)
Block(13,16,1,LEAVES:12)
Block(13,16,2,LEAVES:12)
Block(13,16,3,LEAVES:12)
Block(13,16,11,LEAVES:12)
Block(13,16,12,LEAVES:12)
Block(13,16,15,LEAVES:12)
Block(13,16,16,LEAVES:12)
Block(13,16,21,LEAVES:12)
Block(13,17,3,LEAVES:12)
Block(13,17,4,LEAVES:12)
Block(13,17,5,LEAVES:12)
Block(13,17,6,LEAVES:12)
Block(13,17,7,LEAVES:12)
Block(13,17,8,LEAVES:12)
Block(13,17,9,LEAVES:12)
Block(13,17,10,LEAVES:12)
Block(13,17,12,LEAVES:12)
Block(13,17,13,LEAVES:12)
Block(13,17,17,LEAVES:12)
Block(13,17,18,LEAVES:12)
Block(13,17,19,LEAVES:12)
Block(13,18,4,LEAVES:12)
Block(13,18,9,LEAVES:12)
Block(13,18,12,LEAVES:12)
Block(13,18,18,LEAVES:12)
Block(13,19,11,LEAVES:12)
Block(13,19,12,LEAVES:12)
Block(13,19,13,LEAVES:12)
Block(13,19,15,LEAVES:12)
Block(13,19,20,LEAVES:12)
Block(13,19,21,LEAVES:12)
Block(13,20,9,LEAVES:12)
Block(13,20,10,LEAVES:12)
Block(13,20,13,LEAVES:12)
Block(13,20,17,LEAVES:12)
Block(13,20,18,LEAVES:12)
Block(14,12,18,LEAVES:12)
Block(14,12,19,LEAVES:12)
Block(14,13,9,LEAVES:12)
Block(14,13,10,LEAVES:12)
Block(14,13,11,LEAVES:12)
Block(14,13,15,LEAVES:12)
Block(14,13,16,LEAVES:12)
Block(14,14,4,LEAVES:12)
Block(14,14,5,LEAVES:12)
Block(14,14,6,LEAVES:12)
Block(14,14,9,LEAVES:12)
Block(14,14,21,LEAVES:12)
Block(14,15,-2,LEAVES:12)
Block(14,15,6,LEAVES:12)
Block(14,15,11,LEAVES:12)
Block(14,15,12,LEAVES:12)
Block(14,15,13,LEAVES:12)
Block(14,15,14,LEAVES:12)
Block(14,15,15,LEAVES:12)
Block(14,15,16,LEAVES:12)
Block(14,15,18,LEAVES:12)
Block(14,15,23,LEAVES:12)
Block(14,15,24,LEAVES:12)
Block(14,16,1,LEAVES:12)
Block(14,16,3,LEAVES:12)
Block(14,16,6,LEAVES:12)
Block(14,16,7,LOG2:12)
Block(14,16,11,LEAVES:12)
Block(14,16,14,LEAVES:12)
Block(14,16,15,LEAVES:12)
Block(14,16,20,LEAVES:12)
Block(14,16,21,LEAVES:12)
Block(14,17,6,LEAVES:12)
Block(14,17,7,LEAVES:12)
Block(14,17,8,LEAVES:12)
Block(14,17,12,LEAVES:12)
Block(14,17,14,LEAVES:12)
Block(14,17,16,LEAVES:12)
Block(14,17,17,LEAVES:12)
Block(14,17,19,LEAVES:12)
Block(14,18,3,LEAVES:12)
Block(14,18,4,LEAVES:12)
Block(14,18,7,LEAVES:12)
Block(14,18,8,LEAVES:12)
Block(14,18,9,LEAVES:12)
Block(14,18,10,LEAVES:12)
Block(14,18,12,LEAVES:12)
Block(14,18,13,LEAVES:12)
Block(14,18,14,LEAVES:12)
Block(14,18,15,LEAVES:12)
Block(14,18,16,LEAVES:12)
Block(14,18,18,LEAVES:12)
Block(14,18,19,LEAVES:12)
Block(14,19,8,LEAVES:12)
Block(14,19,10,LEAVES:12)
Block(14,19,15,LEAVES:12)
Block(14,19,18,LEAVES:12)
Block(14,19,21,LEAVES:12)
Block(14,19,22,LEAVES:12)
Block(14,20,13,LEAVES:12)
Block(15,12,17,LEAVES:12)
Block(15,12,18,LEAVES:12)
Block(15,13,15,LEAVES:12)
Block(15,13,22,LEAVES:12)
Block(15,14,5,LEAVES:12)
Block(15,14,8,LEAVES:12)
Block(15,14,9,LEAVES:12)
Block(15,14,18,LEAVES:12)
Block(15,14,21,LEAVES:12)
Block(15,14,22,LEAVES:12)
Block(15,15,2,LEAVES:12)
Block(15,15,8,LEAVES:12)
Block(15,15,10,LEAVES:12)
Block(15,15,11,LEAVES:12)
Block(15,15,18,LEAVES:12)
Block(15,15,21,LEAVES:12)
Block(15,15,24,LEAVES:12)
Block(15,15,25,LEAVES:12)
Block(15,16,2,LEAVES:12)
Block(15,16,3,LEAVES:12)
Block(15,16,4,LEAVES:12)
Block(15,16,6,LEAVES:12)
Block(15,16,7,LEAVES:12)
Block(15,16,8,LEAVES:12)
Block(15,16,9,LEAVES:12)
Block(15,16,10,LEAVES:12)
Block(15,16,11,LEAVES:12)
Block(15,17,2,LEAVES:12)
Block(15,17,4,LEAVES:12)
Block(15,17,7,LEAVES:12)
Block(15,17,8,LEAVES:12)
Block(15,17,9,LEAVES:12)
Block(15,17,19,LEAVES:12)
Block(15,17,20,LEAVES:12)
Block(15,18,7,LEAVES:12)
Block(15,18,13,LEAVES:12)
Block(15,18,14,LEAVES:12)
Block(15,18,15,LEAVES:12)
Block(15,18,23,LEAVES:12)
Block(15,19,6,LEAVES:12)
Block(15,19,7,LEAVES:12)
Block(15,19,8,LEAVES:12)
Block(15,19,10,LEAVES:12)
Block(15,19,15,LEAVES:12)
Block(15,19,16,LEAVES:12)
Block(15,19,17,LEAVES:12)
Block(15,19,18,LEAVES:12)
Block(15,20,12,LEAVES:12)
Block(15,20,13,LEAVES:12)
Block(16,13,22,LEAVES:12)
Block(16,13,23,LEAVES:12)
Block(16,14,4,LEAVES:12)
Block(16,14,5,LEAVES:12)
Block(16,14,17,LEAVES:12)
Block(16,14,18,LEAVES:12)
Block(16,14,26,LEAVES:12)
Block(16,15,1,LEAVES:12)
Block(16,15,2,LEAVES:12)
Block(16,15,20,LEAVES:12)
Block(16,15,21,LEAVES:12)
Block(16,16,7,LEAVES:12)
Block(16,16,9,LEAVES:12)
Block(16,16,10,LEAVES:12)
Block(16,17,0,LEAVES:12)
Block(16,17,1,LEAVES:12)
Block(16,17,2,LEAVES:12)
Block(16,17,4,LEAVES:12)
Block(16,17,7,LEAVES:12)
Block(16,17,9,LEAVES:12)
Block(16,17,10,LEAVES:12)
Block(16,17,14,LEAVES:12)
Block(16,17,20,LEAVES:12)
Block(16,17,21,LEAVES:12)
Block(16,18,6,LEAVES:12)
Block(16,18,7,LEAVES:12)
Block(16,18,10,LEAVES:12)
Block(16,18,13,LEAVES:12)
Block(16,18,14,LEAVES:12)
Block(16,19,10,LEAVES:12)
Block(16,19,13,LEAVES:12)
Block(16,19,16,LEAVES:12)
Block(16,19,17,LEAVES:12)
Block(17,13,23,LEAVES:12)
Block(17,13,24,LEAVES:12)
Block(17,14,3,LEAVES:12)
Block(17,14,4,LEAVES:12)
Block(17,14,17,LEAVES:12)
Block(17,15,1,LEAVES:12)
Block(17,15,8,LEAVES:12)
Block(17,15,20,LEAVES:12)
Block(17,16,4,LEAVES:12)
Block(17,16,7,LEAVES:12)
Block(17,16,8,LEAVES:12)
Block(17,17,4,LEAVES:12)
Block(17,17,7,LEAVES:12)
Block(17,17,10,LEAVES:12)
Block(17,17,11,LEAVES:12)
Block(17,17,14,LEAVES:12)
Block(17,17,15,LEAVES:12)
Block(17,18,9,LEAVES:12)
Block(17,18,10,LEAVES:12)
Block(17,18,18,LEAVES:12)
Block(17,19,12,LEAVES:12)
Block(17,19,13,LEAVES:12)
Block(18,15,8,LEAVES:12)
Block(18,15,9,LEAVES:12)
Block(18,16,3,LEAVES:12)
Block(18,16,4,LEAVES:12)
Block(18,16,12,LEAVES:12)
Block(18,17,6,LEAVES:12)
Block(18,17,7,LEAVES:12)
Block(18,17,15,LEAVES:12)
Block(18,17,16,LEAVES:12)
Block(18,18,9,LEAVES:12)
Block(18,19,12,LEAVES:12)
Block(19,15,9,LEAVES:12)
Block(19,15,10,LEAVES:12)
Block(19,16,3,LEAVES:12)
Block(19,17,6,LEAVES:12)


#######################################################################
# +-----------------------------------------------------------------+ #
# |                             Entities                            | #
# +-----------------------------------------------------------------+ #
#######################################################################

# Entity() spawns an entity instead of a block. The entity is spawned only once when the BO3 is spawned.
# Entities are persistent by default so they don't de-spawn when no player is near, they are only unloaded.
# Usage: Entity(x,y,z,mobName,groupSize,NameTagOrNBTFileName) or Entity(x,y,z,mobName,groupSize)
# Use /tc entities or /otg entities to get a list of entities that can be used as mobName, this includes entities added by other mods.
# NameTagOrNBTFileName can be either a nametag for the mob or an nbt file (such as mymobinfo.nbt or mymobinfo.txt).
# When using a text file you can use the same mob spawning parameters used with the /summon command to equip the
# entity and give it custom attributes etc. You can copy the DATA part of a summon command including surrounding
# curly braces to a .txt file, for instance for: "/summon Skeleton x y z {DATA}"

#######################################################################
# +-----------------------------------------------------------------+ #
# |                            BO3 checks                           | #
# +-----------------------------------------------------------------+ #
#######################################################################

# Require a condition at a certain location in order for the BO3 to be spawned.
# BlockCheck(x,y,z,BlockName[,BlockName[,...]]) - one of the blocks must be at the location
# BlockCheckNot(x,y,z,BlockName[,BlockName[,...]]) - all the blocks must not be at the location
# LightCheck(x,y,z,minLightLevel,maxLightLevel) - light must be between min and max (inclusive)

# You can use "Solid" as a BlockName for matching all solid blocks or "All" to match all blocks that aren't air.

# Examples:
BlockCheck(0,-1,0,GRASS,DIRT,DIRT:2,STONE)
#   BlockCheck(0,-1,0,Solid)       Require any solid block just below the object
#   BlockCheck(0,-1,0,WOOL)        Require any type of wool just below the object
#   BlockCheck(0,-1,0,WOOL:0)      Require white wool just below the object
#   BlockCheckNot(0,-1,0,WOOL:0)   Require that there is no white wool below the object
#   LightCheck(0,0,0,0,1)          Require almost complete darkness just below the object

