#######################################################################
# +-----------------------------------------------------------------+ #
# |                            BO3 object                           | #
# +-----------------------------------------------------------------+ #
#######################################################################

# This is the config file of a custom object.
# If you add this object correctly to your BiomeConfigs, it will spawn in the world.

# This is the creator of this BO3 object
Author: BO3 BulkEdit (by LanToaster)

# A short description of this BO3 object
Description: This Object was Created with BO3_BulkEdit

# The BO3 version, don't change this! It can be used by external applications to do a version check.
Version: 3

# The settings mode, WriteAll, WriteWithoutComments or WriteDisable. See WorldConfig.
SettingsMode: WriteDisable


#######################################################################
# +-----------------------------------------------------------------+ #
# |                          Main settings                          | #
# +-----------------------------------------------------------------+ #
#######################################################################

# This needs to be set to true to spawn the object in the Tree and Sapling resources.
Tree: true

# The frequency of the BO3 from 1 to 200. Tries this many times to spawn this BO3 when using the CustomObject(...) resource.
# Ignored by Tree(..), Sapling(..) and CustomStructure(..)
Frequency: 1

# The rarity of the BO3 from 0 to 100. Each spawn attempt has rarity% chance to succeed when using the CustomObject(...) resource.
# Ignored by Tree(..), Sapling(..) and CustomStructure(..)
Rarity: 100

# If you set this to true, the BO3 will be placed with a random rotation.
RotateRandomly: True

# The spawn height of the BO3 - randomY, highestBlock or highestSolidBlock.
SpawnHeight: highestSolidBlock

# The height limits for the BO3.
MinHeight: 0

MaxHeight: 200

# Objects can have other objects attacthed to it: branches. Branches can also
# have branches attached to it, which can also have branches, etc. This is the
# maximum branch depth for this objects.
MaxBranchDepth: 10

# When spawned with the UseWorld keyword, this BO3 should NOT spawn in the following biomes.
# If you writer.write the BO3 name directly in the BiomeConfigs, this will be ignored.
ExcludedBiomes: All


#######################################################################
# +-----------------------------------------------------------------+ #
# |                      Source block settings                      | #
# +-----------------------------------------------------------------+ #
#######################################################################

# The block(s) the BO3 should spawn in.
SourceBlocks: AIR

# The maximum percentage of the BO3 that can be outside the SourceBlock.
# The BO3 won't be placed on a location with more blocks outside the SourceBlock than this percentage.
MaxPercentageOutsideSourceBlock: 0

# What to do when a block is about to be placed outside the SourceBlock? (dontPlace, placeAnyway)
OutsideSourceBlock: dontPlace


#######################################################################
# +-----------------------------------------------------------------+ #
# |                              Blocks                             | #
# +-----------------------------------------------------------------+ #
#######################################################################

# All the blocks used in the BO3 are listed here. Possible blocks:
# Block(x,y,z,id[.data][,nbtfile.nbt)
# RandomBlock(x,y,z,id[:data][,nbtfile.nbt],chance[,id[:data][,nbtfile.nbt],chance[,...]])
# So RandomBlock(0,0,0,CHEST,chest.nbt,50,CHEST,anotherchest.nbt,100) will spawn a chest at
# the BO3 origin, and give it a 50% chance to have the contents of chest.nbt, or, if that
# fails, a 100% percent chance to have the contents of anotherchest.nbt.

Block(5,0,-4,LOG:12)
Block(4,0,-3,LOG:12)
Block(5,0,-3,LOG:12)
Block(6,0,-3,LOG:12)
Block(7,0,-3,LEAVES:13)
Block(4,0,-2,LOG:12)
Block(6,0,-2,LOG:12)
Block(7,0,-2,LEAVES:13)
Block(8,0,-2,LEAVES:13)
Block(9,0,-2,LEAVES:13)
Block(4,0,-1,LOG:12)
Block(5,0,-1,LOG:12)
Block(6,0,-1,LOG:12)
Block(7,0,-1,LEAVES:13)
Block(8,0,-1,LEAVES:13)
Block(7,0,0,LEAVES:13)
Block(8,0,0,LEAVES:13)
Block(2,1,-5,LEAVES:14)
Block(3,1,-5,LEAVES:14)
Block(2,1,-4,LEAVES:14)
Block(4,1,-4,LEAVES:14)
Block(5,1,-4,LEAVES:14)
Block(6,1,-4,LEAVES:14)
Block(3,1,-3,LEAVES:14)
Block(4,1,-3,LOG:12)
Block(5,1,-3,LOG:12)
Block(6,1,-3,LOG:12)
Block(7,1,-3,LEAVES:13)
Block(4,1,-2,LOG:12)
Block(6,1,-2,LOG:12)
Block(7,1,-2,LEAVES:13)
Block(8,1,-2,LEAVES:13)
Block(9,1,-2,LEAVES:13)
Block(4,1,-1,LOG:12)
Block(5,1,-1,LOG:12)
Block(6,1,-1,LOG:12)
Block(7,1,-1,LEAVES:13)
Block(8,1,-1,LEAVES:13)
Block(7,1,0,LEAVES:13)
Block(8,1,0,LEAVES:13)
Block(2,2,-5,LEAVES:14)
Block(3,2,-5,LEAVES:14)
Block(4,2,-5,LEAVES:14)
Block(5,2,-5,LEAVES:14)
Block(2,2,-4,LEAVES:14)
Block(3,2,-4,LEAVES:14)
Block(4,2,-4,LEAVES:14)
Block(5,2,-4,LEAVES:14)
Block(6,2,-4,LEAVES:14)
Block(3,2,-3,LEAVES:14)
Block(4,2,-3,LEAVES:14)
Block(5,2,-3,LOG:12)
Block(3,2,-2,LEAVES:14)
Block(4,2,-2,LOG:12)
Block(5,2,-2,LOG:12)
Block(6,2,-2,LOG:12)
Block(7,2,-2,LEAVES:13)
Block(8,2,-2,LEAVES:13)
Block(4,2,-1,LOG:12)
Block(5,2,-1,LOG:12)
Block(6,2,-1,LOG:12)
Block(7,2,-1,LEAVES:13)
Block(8,2,-1,LEAVES:13)
Block(7,2,0,LEAVES:13)
Block(4,3,-5,LEAVES:14)
Block(5,3,-5,LEAVES:14)
Block(6,3,-5,LEAVES:14)
Block(2,3,-4,LEAVES:14)
Block(3,3,-4,LEAVES:14)
Block(4,3,-4,LEAVES:14)
Block(5,3,-4,LEAVES:14)
Block(6,3,-4,LEAVES:14)
Block(3,3,-3,LEAVES:14)
Block(4,3,-3,LEAVES:14)
Block(5,3,-3,LEAVES:14)
Block(6,3,-3,LEAVES:14)
Block(4,3,-2,LOG:12)
Block(5,3,-2,LOG:12)
Block(6,3,-2,LOG:12)
Block(7,3,-2,LEAVES:13)
Block(8,3,-2,LEAVES:13)
Block(5,3,-1,LOG:12)
Block(6,3,-1,LOG:12)
Block(7,3,-1,LEAVES:13)
Block(8,3,-1,LEAVES:13)
Block(3,4,-5,LEAVES:14)
Block(4,4,-5,LEAVES:14)
Block(5,4,-5,LEAVES:14)
Block(2,4,-4,LEAVES:14)
Block(3,4,-4,LEAVES:14)
Block(4,4,-4,LEAVES:14)
Block(5,4,-4,LEAVES:14)
Block(6,4,-4,LEAVES:14)
Block(7,4,-4,LEAVES:14)
Block(4,4,-3,LEAVES:14)
Block(5,4,-3,LEAVES:14)
Block(6,4,-3,LEAVES:14)
Block(4,4,-2,LOG:12)
Block(5,4,-2,LOG:12)
Block(6,4,-2,LOG:12)
Block(7,4,-2,LEAVES:13)
Block(8,4,-2,LEAVES:13)
Block(5,4,-1,LOG:12)
Block(6,4,-1,LOG:12)
Block(7,4,-1,LEAVES:13)
Block(8,4,-1,LEAVES:13)
Block(9,5,-6,LEAVES:13)
Block(3,5,-5,LEAVES:14)
Block(4,5,-5,LEAVES:14)
Block(5,5,-5,LEAVES:14)
Block(3,5,-4,LEAVES:14)
Block(4,5,-4,LEAVES:14)
Block(5,5,-4,LEAVES:14)
Block(6,5,-4,LEAVES:14)
Block(7,5,-4,LEAVES:14)
Block(4,5,-3,LEAVES:14)
Block(5,5,-3,LEAVES:14)
Block(6,5,-3,LEAVES:14)
Block(7,5,-3,LEAVES:14)
Block(4,5,-2,LOG:12)
Block(5,5,-2,LOG:12)
Block(6,5,-2,LOG:12)
Block(7,5,-2,LEAVES:13)
Block(8,5,-2,LEAVES:13)
Block(11,5,-2,LEAVES:13)
Block(5,5,-1,LOG:12)
Block(6,5,-1,LOG:12)
Block(7,5,-1,LEAVES:13)
Block(8,5,-1,LEAVES:13)
Block(0,6,-7,LEAVES:5)
Block(1,6,-7,LEAVES:13)
Block(2,6,-7,LEAVES:13)
Block(1,6,-6,LEAVES:13)
Block(2,6,-6,LEAVES:13)
Block(8,6,-6,LEAVES:13)
Block(9,6,-6,LEAVES:13)
Block(11,6,-6,LEAVES:13)
Block(12,6,-6,LEAVES:13)
Block(13,6,-6,LEAVES:5)
Block(4,6,-5,LEAVES:14)
Block(8,6,-5,LEAVES:13)
Block(9,6,-5,LEAVES:13)
Block(10,6,-5,LEAVES:13)
Block(11,6,-5,LEAVES:13)
Block(12,6,-5,LEAVES:13)
Block(-2,6,-4,LEAVES:5)
Block(-1,6,-4,LEAVES:5)
Block(3,6,-4,LEAVES:14)
Block(4,6,-4,LEAVES:14)
Block(5,6,-4,LEAVES:14)
Block(6,6,-4,LEAVES:14)
Block(11,6,-4,LEAVES:13)
Block(12,6,-4,LEAVES:13)
Block(-1,6,-3,LEAVES:5)
Block(5,6,-3,LOG:12)
Block(10,6,-3,LEAVES:13)
Block(11,6,-3,LEAVES:13)
Block(4,6,-2,LOG:12)
Block(5,6,-2,LOG:12)
Block(6,6,-2,LOG:12)
Block(8,6,-2,LEAVES:13)
Block(10,6,-2,LEAVES:13)
Block(5,6,-1,LOG:12)
Block(6,6,-1,LOG:12)
Block(8,6,-1,LEAVES:13)
Block(3,6,3,LEAVES:13)
Block(4,6,3,LEAVES:13)
Block(7,6,3,LEAVES:13)
Block(3,6,4,LEAVES:5)
Block(4,6,4,LEAVES:5)
Block(7,6,4,LEAVES:5)
Block(8,6,4,LEAVES:5)
Block(4,6,5,LEAVES:5)
Block(5,6,5,LEAVES:5)
Block(6,6,5,LEAVES:5)
Block(7,6,5,LEAVES:5)
Block(5,6,6,LEAVES:5)
Block(6,6,6,LEAVES:5)
Block(-2,7,-7,LEAVES:5)
Block(-1,7,-7,LEAVES:5)
Block(-2,7,-6,LEAVES:5)
Block(-1,7,-6,LEAVES:5)
Block(0,7,-6,LEAVES:13)
Block(1,7,-6,LEAVES:13)
Block(2,7,-6,LEAVES:13)
Block(-2,7,-5,LEAVES:5)
Block(-1,7,-5,LEAVES:5)
Block(0,7,-5,LEAVES:13)
Block(1,7,-5,LEAVES:13)
Block(2,7,-5,LEAVES:13)
Block(4,7,-5,LEAVES:14)
Block(8,7,-5,LEAVES:13)
Block(9,7,-5,LEAVES:13)
Block(10,7,-5,LEAVES:13)
Block(11,7,-5,LEAVES:13)
Block(-1,7,-4,LEAVES:5)
Block(0,7,-4,LEAVES:13)
Block(4,7,-4,LEAVES:14)
Block(5,7,-4,LEAVES:14)
Block(8,7,-4,LEAVES:13)
Block(9,7,-4,LEAVES:13)
Block(10,7,-4,LEAVES:13)
Block(11,7,-4,LEAVES:13)
Block(0,7,-3,LEAVES:13)
Block(1,7,-3,LEAVES:13)
Block(5,7,-3,LOG:12)
Block(9,7,-3,LEAVES:13)
Block(10,7,-3,LEAVES:13)
Block(4,7,-2,LOG:12)
Block(5,7,-2,LOG:12)
Block(6,7,-2,LOG:12)
Block(8,7,-2,LOG:12)
Block(9,7,-2,LEAVES:13)
Block(5,7,-1,LOG:12)
Block(6,7,-1,LOG:12)
Block(10,7,-1,LEAVES:13)
Block(10,7,0,LEAVES:13)
Block(11,7,0,LEAVES:13)
Block(11,7,1,LEAVES:13)
Block(4,7,2,LEAVES:13)
Block(6,7,2,LEAVES:13)
Block(1,7,3,LEAVES:13)
Block(4,7,3,LEAVES:13)
Block(5,7,3,LEAVES:13)
Block(6,7,3,LEAVES:13)
Block(7,7,3,LEAVES:13)
Block(8,7,3,LEAVES:13)
Block(5,7,4,LEAVES:5)
Block(6,7,4,LEAVES:5)
Block(5,7,5,LEAVES:5)
Block(6,7,5,LEAVES:5)
Block(5,7,6,LEAVES:5)
Block(5,8,-9,LEAVES:5)
Block(7,8,-9,LEAVES:5)
Block(4,8,-8,LEAVES:5)
Block(5,8,-8,LEAVES:5)
Block(7,8,-8,LEAVES:5)
Block(3,8,-7,LEAVES:13)
Block(4,8,-7,LEAVES:13)
Block(7,8,-7,LEAVES:13)
Block(8,8,-7,LEAVES:13)
Block(7,8,-6,LEAVES:13)
Block(8,8,-6,LEAVES:13)
Block(0,8,-5,LEAVES:13)
Block(2,8,-5,LEAVES:13)
Block(0,8,-4,LEAVES:13)
Block(1,8,-4,LEAVES:13)
Block(2,8,-4,LEAVES:13)
Block(3,8,-4,LEAVES:13)
Block(7,8,-4,LEAVES:13)
Block(8,8,-4,LEAVES:13)
Block(9,8,-4,LEAVES:13)
Block(1,8,-3,LEAVES:13)
Block(2,8,-3,LEAVES:13)
Block(4,8,-3,LEAVES:13)
Block(5,8,-3,LEAVES:13)
Block(6,8,-3,LEAVES:13)
Block(7,8,-3,LEAVES:13)
Block(8,8,-3,LEAVES:13)
Block(9,8,-3,LEAVES:13)
Block(-1,8,-2,LEAVES:5)
Block(4,8,-2,LEAVES:13)
Block(5,8,-2,LOG:12)
Block(6,8,-2,LOG:12)
Block(7,8,-2,LEAVES:13)
Block(8,8,-2,LEAVES:13)
Block(-1,8,-1,LEAVES:5)
Block(0,8,-1,LEAVES:13)
Block(1,8,-1,LEAVES:13)
Block(4,8,-1,LEAVES:13)
Block(5,8,-1,LOG:12)
Block(6,8,-1,LEAVES:13)
Block(9,8,-1,LEAVES:13)
Block(-1,8,0,LEAVES:5)
Block(0,8,0,LEAVES:13)
Block(1,8,0,LEAVES:13)
Block(5,8,0,LEAVES:13)
Block(9,8,0,LEAVES:13)
Block(10,8,0,LEAVES:13)
Block(-1,8,1,LEAVES:5)
Block(4,8,1,LEAVES:13)
Block(5,8,1,LEAVES:13)
Block(6,8,1,LEAVES:13)
Block(9,8,1,LEAVES:13)
Block(10,8,1,LEAVES:13)
Block(11,8,1,LEAVES:13)
Block(-1,8,2,LEAVES:5)
Block(0,8,2,LEAVES:13)
Block(1,8,2,LEAVES:13)
Block(2,8,2,LEAVES:13)
Block(4,8,2,LEAVES:13)
Block(5,8,2,LEAVES:13)
Block(6,8,2,LEAVES:13)
Block(7,8,2,LEAVES:13)
Block(8,8,2,LEAVES:13)
Block(9,8,2,LEAVES:13)
Block(10,8,2,LEAVES:13)
Block(11,8,2,LEAVES:13)
Block(0,8,3,LEAVES:5)
Block(1,8,3,LEAVES:13)
Block(8,8,3,LEAVES:13)
Block(9,8,3,LEAVES:13)
Block(10,8,3,LEAVES:13)
Block(11,8,3,LEAVES:5)
Block(4,8,4,LEAVES:5)
Block(8,8,4,LEAVES:5)
Block(11,8,4,LEAVES:5)
Block(5,8,5,LEAVES:5)
Block(7,8,5,LEAVES:5)
Block(6,9,-10,LEAVES:5)
Block(5,9,-9,LEAVES:5)
Block(6,9,-9,LEAVES:5)
Block(5,9,-8,LEAVES:5)
Block(6,9,-8,LEAVES:5)
Block(5,9,-7,LEAVES:13)
Block(6,9,-7,LEAVES:13)
Block(9,9,-7,LEAVES:13)
Block(10,9,-7,LEAVES:5)
Block(4,9,-6,LEAVES:13)
Block(5,9,-6,LEAVES:13)
Block(6,9,-6,LEAVES:13)
Block(7,9,-6,LEAVES:13)
Block(9,9,-6,LEAVES:13)
Block(11,9,-6,LEAVES:13)
Block(6,9,-5,LEAVES:13)
Block(7,9,-5,LEAVES:13)
Block(12,9,-5,LEAVES:13)
Block(-2,9,-4,LEAVES:5)
Block(-1,9,-4,LEAVES:5)
Block(0,9,-4,LEAVES:13)
Block(1,9,-4,LEAVES:13)
Block(2,9,-4,LEAVES:13)
Block(3,9,-4,LEAVES:13)
Block(11,9,-4,LEAVES:13)
Block(12,9,-4,LEAVES:13)
Block(-2,9,-3,LEAVES:5)
Block(-1,9,-3,LEAVES:5)
Block(2,9,-3,LEAVES:13)
Block(3,9,-3,LEAVES:13)
Block(4,9,-3,LEAVES:13)
Block(5,9,-3,LEAVES:13)
Block(6,9,-3,LEAVES:13)
Block(7,9,-3,LEAVES:13)
Block(8,9,-3,LEAVES:13)
Block(11,9,-3,LEAVES:13)
Block(-1,9,-2,LEAVES:5)
Block(3,9,-2,LEAVES:13)
Block(4,9,-2,LEAVES:13)
Block(5,9,-2,LOG:12)
Block(6,9,-2,LOG:12)
Block(7,9,-2,LEAVES:13)
Block(0,9,-1,LEAVES:13)
Block(1,9,-1,LEAVES:13)
Block(2,9,-1,LEAVES:13)
Block(4,9,-1,LEAVES:13)
Block(5,9,-1,LEAVES:13)
Block(6,9,-1,LEAVES:13)
Block(8,9,-1,LEAVES:13)
Block(1,9,0,LEAVES:13)
Block(2,9,0,LEAVES:13)
Block(5,9,0,LEAVES:13)
Block(6,9,0,LEAVES:13)
Block(8,9,0,LEAVES:13)
Block(9,9,0,LEAVES:13)
Block(0,9,1,LEAVES:13)
Block(1,9,1,LEAVES:13)
Block(2,9,1,LEAVES:13)
Block(3,9,1,LEAVES:13)
Block(5,9,1,LEAVES:13)
Block(6,9,1,LEAVES:13)
Block(7,9,1,LEAVES:13)
Block(8,9,1,LEAVES:13)
Block(9,9,1,LEAVES:13)
Block(-1,9,2,LEAVES:5)
Block(0,9,2,LEAVES:13)
Block(8,9,2,LEAVES:13)
Block(9,9,2,LEAVES:13)
Block(4,9,3,LEAVES:13)
Block(5,9,3,LEAVES:13)
Block(7,9,3,LEAVES:13)
Block(8,9,3,LEAVES:13)
Block(4,9,4,LEAVES:5)
Block(5,9,4,LEAVES:5)
Block(6,9,4,LEAVES:5)
Block(7,9,4,LEAVES:5)
Block(6,9,5,LEAVES:5)
Block(7,9,5,LEAVES:5)
Block(5,10,-6,LEAVES:13)
Block(9,10,-6,LEAVES:13)
Block(11,10,-6,LEAVES:13)
Block(5,10,-5,LEAVES:13)
Block(6,10,-5,LEAVES:13)
Block(9,10,-5,LEAVES:13)
Block(10,10,-5,LEAVES:13)
Block(11,10,-5,LEAVES:13)
Block(-2,10,-4,LEAVES:5)
Block(-1,10,-4,LEAVES:5)
Block(0,10,-4,LEAVES:13)
Block(1,10,-4,LEAVES:13)
Block(2,10,-4,LEAVES:13)
Block(3,10,-4,LEAVES:13)
Block(4,10,-4,LEAVES:13)
Block(5,10,-4,LEAVES:13)
Block(6,10,-4,LEAVES:13)
Block(10,10,-4,LEAVES:13)
Block(11,10,-4,LEAVES:13)
Block(-1,10,-3,LEAVES:5)
Block(0,10,-3,LEAVES:13)
Block(3,10,-3,LEAVES:13)
Block(4,10,-3,LEAVES:13)
Block(5,10,-3,LEAVES:13)
Block(6,10,-3,LEAVES:13)
Block(10,10,-3,LEAVES:13)
Block(1,10,-2,LEAVES:13)
Block(4,10,-2,LEAVES:13)
Block(5,10,-2,LEAVES:13)
Block(6,10,-2,LEAVES:13)
Block(7,10,-2,LEAVES:13)
Block(1,10,-1,LEAVES:13)
Block(2,10,-1,LEAVES:13)
Block(3,10,-1,LEAVES:13)
Block(5,10,-1,LEAVES:13)
Block(6,10,-1,LEAVES:13)
Block(7,10,-1,LEAVES:13)
Block(2,10,0,LEAVES:13)
Block(3,10,0,LEAVES:13)
Block(5,10,0,LEAVES:13)
Block(6,10,0,LEAVES:13)
Block(7,10,0,LEAVES:13)
Block(8,10,0,LEAVES:13)
Block(7,10,1,LEAVES:13)
Block(4,10,2,LEAVES:13)
Block(5,10,2,LEAVES:13)
Block(7,10,2,LEAVES:13)
Block(5,10,3,LEAVES:13)
Block(6,10,3,LEAVES:13)
Block(7,10,3,LEAVES:13)
Block(6,10,4,LEAVES:5)
Block(7,10,4,LEAVES:5)
Block(2,11,-6,LEAVES:13)
Block(3,11,-6,LEAVES:13)
Block(3,11,-5,LEAVES:13)
Block(4,11,-5,LEAVES:13)
Block(8,11,-5,LEAVES:13)
Block(9,11,-5,LEAVES:13)
Block(10,11,-5,LEAVES:13)
Block(11,11,-5,LEAVES:13)
Block(0,11,-4,LEAVES:13)
Block(5,11,-4,LEAVES:13)
Block(8,11,-4,LEAVES:13)
Block(9,11,-4,LEAVES:13)
Block(10,11,-4,LEAVES:13)
Block(0,11,-3,LEAVES:13)
Block(1,11,-3,LEAVES:13)
Block(2,11,-3,LEAVES:13)
Block(3,11,-3,LEAVES:13)
Block(4,11,-3,LEAVES:13)
Block(5,11,-3,LEAVES:13)
Block(6,11,-3,LEAVES:13)
Block(9,11,-3,LEAVES:13)
Block(1,11,-2,LEAVES:13)
Block(2,11,-2,LEAVES:13)
Block(4,11,-2,LEAVES:13)
Block(5,11,-2,LEAVES:13)
Block(6,11,-2,LEAVES:13)
Block(7,11,-2,LEAVES:13)
Block(3,11,-1,LEAVES:13)
Block(4,11,-1,LEAVES:13)
Block(5,11,-1,LEAVES:13)
Block(6,11,-1,LEAVES:13)
Block(7,11,-1,LEAVES:13)
Block(12,11,-1,LEAVES:13)
Block(4,11,0,LEAVES:13)
Block(5,11,1,LEAVES:13)
Block(6,11,1,LEAVES:13)
Block(7,11,1,LEAVES:13)
Block(2,11,2,LEAVES:13)
Block(5,11,2,LEAVES:13)
Block(6,11,2,LEAVES:13)
Block(7,11,2,LEAVES:13)
Block(2,11,3,LEAVES:13)
Block(6,11,3,LEAVES:13)
Block(3,11,4,LEAVES:5)
Block(5,11,4,LEAVES:5)
Block(6,11,4,LEAVES:5)
Block(3,11,5,LEAVES:5)
Block(4,11,5,LEAVES:5)
Block(5,11,5,LEAVES:5)
Block(-1,12,-7,LEAVES:5)
Block(0,12,-7,LEAVES:5)
Block(-1,12,-6,LEAVES:5)
Block(0,12,-6,LEAVES:5)
Block(1,12,-6,LEAVES:13)
Block(2,12,-6,LEAVES:13)
Block(0,12,-5,LEAVES:5)
Block(2,12,-5,LEAVES:13)
Block(3,12,-5,LEAVES:13)
Block(4,12,-5,LEAVES:13)
Block(11,12,-5,LEAVES:5)
Block(0,12,-4,LEAVES:5)
Block(1,12,-4,LEAVES:13)
Block(4,12,-4,LEAVES:13)
Block(7,12,-4,LEAVES:13)
Block(8,12,-4,LEAVES:13)
Block(9,12,-4,LEAVES:13)
Block(10,12,-4,LEAVES:13)
Block(11,12,-4,LEAVES:5)
Block(12,12,-4,LEAVES:5)
Block(1,12,-3,LEAVES:13)
Block(2,12,-3,LEAVES:13)
Block(3,12,-3,LEAVES:13)
Block(4,12,-3,LEAVES:13)
Block(5,12,-3,LEAVES:13)
Block(6,12,-3,LEAVES:13)
Block(7,12,-3,LEAVES:13)
Block(8,12,-3,LEAVES:13)
Block(12,12,-3,LEAVES:5)
Block(1,12,-2,LEAVES:13)
Block(2,12,-2,LEAVES:13)
Block(3,12,-2,LEAVES:13)
Block(4,12,-2,LEAVES:13)
Block(5,12,-2,LEAVES:13)
Block(6,12,-2,LEAVES:13)
Block(11,12,-2,LEAVES:5)
Block(12,12,-2,LEAVES:5)
Block(13,12,-2,LEAVES:5)
Block(4,12,-1,LEAVES:13)
Block(5,12,-1,LEAVES:13)
Block(6,12,-1,LEAVES:13)
Block(7,12,-1,LEAVES:13)
Block(11,12,-1,LEAVES:5)
Block(12,12,-1,LEAVES:5)
Block(5,12,0,LEAVES:13)
Block(6,12,0,LEAVES:13)
Block(5,12,1,LEAVES:13)
Block(6,12,1,LEAVES:13)
Block(2,12,2,LEAVES:13)
Block(3,12,2,LEAVES:13)
Block(3,12,3,LEAVES:13)
Block(5,12,3,LEAVES:13)
Block(6,12,3,LEAVES:13)
Block(3,12,4,LEAVES:5)
Block(4,12,4,LEAVES:5)
Block(5,12,4,LEAVES:5)
Block(4,12,5,LEAVES:5)
Block(0,13,-6,LEAVES:5)
Block(1,13,-6,LEAVES:13)
Block(0,13,-5,LEAVES:5)
Block(1,13,-5,LEAVES:13)
Block(2,13,-5,LEAVES:13)
Block(3,13,-5,LEAVES:13)
Block(1,13,-4,LEAVES:13)
Block(2,13,-4,LEAVES:13)
Block(3,13,-4,LEAVES:13)
Block(4,13,-4,LEAVES:13)
Block(10,13,-4,LEAVES:13)
Block(2,13,-3,LEAVES:13)
Block(4,13,-3,LEAVES:13)
Block(5,13,-3,LEAVES:13)
Block(6,13,-3,LEAVES:13)
Block(7,13,-3,LEAVES:13)
Block(10,13,-3,LEAVES:13)
Block(11,13,-3,LEAVES:5)
Block(12,13,-3,LEAVES:5)
Block(3,13,-2,LEAVES:13)
Block(4,13,-2,LEAVES:13)
Block(5,13,-2,LEAVES:13)
Block(6,13,-2,LEAVES:13)
Block(7,13,-2,LEAVES:13)
Block(10,13,-2,LEAVES:13)
Block(11,13,-2,LEAVES:5)
Block(4,13,-1,LEAVES:13)
Block(5,13,-1,LEAVES:13)
Block(6,13,-1,LEAVES:13)
Block(10,13,-1,LEAVES:13)
Block(5,13,0,LEAVES:13)
Block(6,13,0,LEAVES:13)
Block(3,13,1,LEAVES:13)
Block(3,13,2,LEAVES:13)
Block(4,13,2,LEAVES:13)
Block(5,13,2,LEAVES:13)
Block(6,13,2,LEAVES:13)
Block(4,13,3,LEAVES:13)
Block(5,13,3,LEAVES:13)
Block(4,13,4,LEAVES:5)
Block(6,14,-7,LEAVES:5)
Block(7,14,-7,LEAVES:5)
Block(8,14,-7,LEAVES:5)
Block(9,14,-7,LEAVES:5)
Block(5,14,-6,LEAVES:13)
Block(6,14,-6,LEAVES:13)
Block(8,14,-6,LEAVES:13)
Block(1,14,-5,LEAVES:13)
Block(2,14,-5,LEAVES:13)
Block(5,14,-5,LEAVES:13)
Block(8,14,-5,LEAVES:13)
Block(1,14,-4,LEAVES:13)
Block(2,14,-4,LEAVES:13)
Block(3,14,-4,LEAVES:13)
Block(4,14,-4,LEAVES:13)
Block(8,14,-4,LEAVES:13)
Block(0,14,-3,LEAVES:5)
Block(1,14,-3,LEAVES:13)
Block(2,14,-3,LEAVES:13)
Block(3,14,-3,LEAVES:13)
Block(4,14,-3,LEAVES:13)
Block(5,14,-3,LEAVES:13)
Block(6,14,-3,LEAVES:13)
Block(8,14,-3,LEAVES:13)
Block(9,14,-3,LEAVES:13)
Block(10,14,-3,LEAVES:13)
Block(3,14,-2,LEAVES:13)
Block(4,14,-2,LEAVES:13)
Block(5,14,-2,LEAVES:13)
Block(6,14,-2,LEAVES:13)
Block(7,14,-2,LEAVES:13)
Block(9,14,-2,LEAVES:13)
Block(10,14,-2,LEAVES:13)
Block(0,14,-1,LEAVES:5)
Block(1,14,-1,LEAVES:13)
Block(4,14,-1,LEAVES:13)
Block(5,14,-1,LEAVES:13)
Block(6,14,-1,LEAVES:13)
Block(9,14,-1,LEAVES:13)
Block(1,14,0,LEAVES:13)
Block(4,14,0,LEAVES:13)
Block(5,14,0,LEAVES:13)
Block(4,14,1,LEAVES:13)
Block(5,14,1,LEAVES:13)
Block(6,14,1,LEAVES:13)
Block(4,14,2,LEAVES:13)
Block(5,14,2,LEAVES:13)
Block(9,14,2,LEAVES:13)
Block(8,14,3,LEAVES:13)
Block(9,14,3,LEAVES:13)
Block(6,14,4,LEAVES:5)
Block(7,14,4,LEAVES:5)
Block(9,15,-8,LEAVES:5)
Block(7,15,-7,LEAVES:5)
Block(8,15,-7,LEAVES:5)
Block(6,15,-6,LEAVES:13)
Block(7,15,-6,LEAVES:13)
Block(8,15,-6,LEAVES:13)
Block(5,15,-5,LEAVES:13)
Block(6,15,-5,LEAVES:13)
Block(8,15,-5,LEAVES:13)
Block(3,15,-4,LEAVES:13)
Block(7,15,-4,LEAVES:13)
Block(8,15,-4,LEAVES:13)
Block(1,15,-3,LEAVES:13)
Block(2,15,-3,LEAVES:13)
Block(3,15,-3,LEAVES:13)
Block(4,15,-3,LEAVES:13)
Block(5,15,-3,LEAVES:13)
Block(7,15,-3,LEAVES:13)
Block(8,15,-3,LEAVES:13)
Block(1,15,-2,LEAVES:13)
Block(4,15,-2,LEAVES:13)
Block(5,15,-2,LEAVES:13)
Block(6,15,-2,LEAVES:13)
Block(7,15,-2,LEAVES:13)
Block(8,15,-2,LEAVES:13)
Block(9,15,-2,LEAVES:13)
Block(1,15,-1,LEAVES:13)
Block(2,15,-1,LEAVES:13)
Block(5,15,-1,LEAVES:13)
Block(6,15,-1,LEAVES:13)
Block(4,15,0,LEAVES:13)
Block(5,15,0,LEAVES:13)
Block(6,15,0,LEAVES:13)
Block(5,15,1,LEAVES:13)
Block(8,15,1,LEAVES:13)
Block(6,15,2,LEAVES:13)
Block(8,15,2,LEAVES:13)
Block(6,15,3,LEAVES:13)
Block(7,15,3,LEAVES:13)
Block(8,15,3,LEAVES:13)
Block(7,15,4,LEAVES:5)
Block(8,15,4,LEAVES:5)
Block(7,16,-6,LEAVES:13)
Block(8,16,-6,LEAVES:13)
Block(4,16,-5,LEAVES:13)
Block(6,16,-5,LEAVES:13)
Block(7,16,-5,LEAVES:13)
Block(2,16,-4,LEAVES:13)
Block(5,16,-4,LEAVES:13)
Block(6,16,-4,LEAVES:13)
Block(7,16,-4,LEAVES:13)
Block(2,16,-3,LEAVES:13)
Block(3,16,-3,LEAVES:13)
Block(4,16,-3,LEAVES:13)
Block(5,16,-3,LEAVES:13)
Block(7,16,-3,LEAVES:13)
Block(1,16,-2,LEAVES:13)
Block(2,16,-2,LEAVES:13)
Block(3,16,-2,LEAVES:13)
Block(5,16,-2,LEAVES:13)
Block(6,16,-2,LEAVES:13)
Block(7,16,-2,LEAVES:13)
Block(2,16,-1,LEAVES:13)
Block(3,16,-1,LEAVES:13)
Block(5,16,-1,LEAVES:13)
Block(6,16,-1,LEAVES:13)
Block(2,16,1,LEAVES:13)
Block(6,16,1,LEAVES:13)
Block(7,16,1,LEAVES:13)
Block(8,16,1,LEAVES:13)
Block(6,16,2,LEAVES:13)
Block(7,16,2,LEAVES:13)
Block(3,16,3,LEAVES:13)
Block(4,16,3,LEAVES:13)
Block(5,16,3,LEAVES:13)
Block(7,16,3,LEAVES:13)
Block(2,17,-6,LEAVES:13)
Block(3,17,-6,LEAVES:13)
Block(2,17,-5,LEAVES:13)
Block(3,17,-5,LEAVES:13)
Block(4,17,-5,LEAVES:13)
Block(7,17,-5,LEAVES:13)
Block(2,17,-4,LEAVES:13)
Block(4,17,-4,LEAVES:13)
Block(5,17,-4,LEAVES:13)
Block(6,17,-4,LEAVES:13)
Block(7,17,-4,LEAVES:13)
Block(2,17,-3,LEAVES:13)
Block(3,17,-3,LEAVES:13)
Block(5,17,-3,LEAVES:13)
Block(6,17,-3,LEAVES:13)
Block(7,17,-3,LEAVES:13)
Block(9,17,-3,LEAVES:13)
Block(10,17,-3,LEAVES:13)
Block(3,17,-2,LEAVES:13)
Block(4,17,-2,LEAVES:13)
Block(5,17,-2,LOG:12)
Block(6,17,-2,LEAVES:13)
Block(10,17,-2,LEAVES:13)
Block(11,17,-2,LEAVES:5)
Block(3,17,-1,LEAVES:13)
Block(4,17,-1,LEAVES:13)
Block(5,17,-1,LOG:12)
Block(6,17,-1,LOG:12)
Block(10,17,-1,LEAVES:13)
Block(11,17,-1,LEAVES:5)
Block(6,17,0,LEAVES:13)
Block(7,17,0,LEAVES:13)
Block(10,17,0,LEAVES:13)
Block(3,17,1,LEAVES:13)
Block(6,17,1,LEAVES:13)
Block(7,17,1,LEAVES:13)
Block(3,17,2,LEAVES:13)
Block(4,17,2,LEAVES:13)
Block(5,17,2,LEAVES:13)
Block(3,17,3,LEAVES:13)
Block(4,17,3,LEAVES:13)
Block(5,18,-6,LEAVES:13)
Block(2,18,-5,LEAVES:13)
Block(3,18,-5,LEAVES:13)
Block(3,18,-4,LEAVES:13)
Block(4,18,-4,LEAVES:13)
Block(5,18,-4,LEAVES:13)
Block(8,18,-4,LEAVES:13)
Block(3,18,-3,LEAVES:13)
Block(5,18,-3,LEAVES:13)
Block(6,18,-3,LEAVES:13)
Block(9,18,-3,LEAVES:13)
Block(4,18,-2,LEAVES:13)
Block(5,18,-2,LOG:12)
Block(6,18,-2,LOG:12)
Block(8,18,-2,LEAVES:13)
Block(9,18,-2,LEAVES:13)
Block(10,18,-2,LEAVES:13)
Block(5,18,-1,LOG:12)
Block(6,18,-1,LEAVES:13)
Block(8,18,-1,LEAVES:13)
Block(9,18,-1,LEAVES:13)
Block(10,18,-1,LEAVES:13)
Block(4,18,0,LEAVES:13)
Block(6,18,0,LEAVES:13)
Block(4,18,1,LEAVES:13)
Block(5,18,1,LEAVES:13)
Block(4,18,2,LEAVES:13)
Block(6,19,-7,LEAVES:5)
Block(7,19,-7,LEAVES:5)
Block(8,19,-7,LEAVES:5)
Block(5,19,-6,LEAVES:13)
Block(6,19,-6,LEAVES:13)
Block(7,19,-6,LEAVES:13)
Block(8,19,-6,LEAVES:13)
Block(5,19,-5,LEAVES:13)
Block(7,19,-5,LEAVES:13)
Block(3,19,-4,LEAVES:13)
Block(4,19,-4,LEAVES:13)
Block(7,19,-4,LEAVES:13)
Block(2,19,-3,LEAVES:13)
Block(4,19,-3,LEAVES:13)
Block(5,19,-3,LEAVES:13)
Block(7,19,-3,LEAVES:13)
Block(1,19,-2,LEAVES:13)
Block(2,19,-2,LEAVES:13)
Block(4,19,-2,LEAVES:13)
Block(5,19,-2,LOG:12)
Block(6,19,-2,LOG:12)
Block(7,19,-2,LEAVES:13)
Block(8,19,-2,LEAVES:13)
Block(0,19,-1,LEAVES:5)
Block(1,19,-1,LEAVES:13)
Block(5,19,-1,LOG:12)
Block(6,19,-1,LOG:12)
Block(7,19,-1,LEAVES:13)
Block(8,19,-1,LEAVES:13)
Block(1,19,0,LEAVES:13)
Block(2,19,0,LEAVES:13)
Block(4,19,0,LEAVES:13)
Block(5,19,0,LEAVES:13)
Block(9,19,1,LEAVES:13)
Block(8,19,2,LEAVES:13)
Block(9,19,2,LEAVES:13)
Block(7,19,3,LEAVES:13)
Block(8,19,3,LEAVES:13)
Block(9,19,3,LEAVES:13)
Block(7,20,-7,LEAVES:5)
Block(6,20,-6,LEAVES:13)
Block(7,20,-6,LEAVES:13)
Block(5,20,-5,LEAVES:13)
Block(6,20,-5,LEAVES:13)
Block(7,20,-5,LEAVES:13)
Block(5,20,-4,LEAVES:13)
Block(6,20,-4,LEAVES:13)
Block(7,20,-4,LEAVES:13)
Block(5,20,-3,LEAVES:13)
Block(6,20,-3,LEAVES:13)
Block(7,20,-3,LEAVES:13)
Block(2,20,-2,LEAVES:13)
Block(3,20,-2,LEAVES:13)
Block(4,20,-2,LEAVES:13)
Block(5,20,-2,LEAVES:13)
Block(6,20,-2,LEAVES:13)
Block(7,20,-2,LEAVES:13)
Block(1,20,-1,LEAVES:13)
Block(2,20,-1,LEAVES:13)
Block(3,20,-1,LEAVES:13)
Block(5,20,-1,LEAVES:13)
Block(6,20,-1,LOG:12)
Block(7,20,-1,LEAVES:13)
Block(3,20,0,LEAVES:13)
Block(7,20,1,LEAVES:13)
Block(8,20,1,LEAVES:13)
Block(7,20,2,LEAVES:13)
Block(8,20,2,LEAVES:13)
Block(6,21,-5,LEAVES:13)
Block(7,21,-5,LEAVES:13)
Block(6,21,-4,LEAVES:13)
Block(7,21,-4,LEAVES:13)
Block(5,21,-3,LEAVES:13)
Block(6,21,-3,LEAVES:13)
Block(3,21,-2,LEAVES:13)
Block(4,21,-2,LEAVES:13)
Block(5,21,-2,LOG:12)
Block(6,21,-2,LOG:12)
Block(10,21,-2,LEAVES:13)
Block(3,21,-1,LEAVES:13)
Block(4,21,-1,LEAVES:13)
Block(5,21,-1,LEAVES:13)
Block(6,21,-1,LEAVES:13)
Block(7,21,-1,LEAVES:13)
Block(10,21,-1,LEAVES:13)
Block(3,21,0,LEAVES:13)
Block(6,21,0,LEAVES:13)
Block(7,21,0,LEAVES:13)
Block(9,21,0,LEAVES:13)
Block(10,21,0,LEAVES:13)
Block(3,21,1,LEAVES:13)
Block(5,21,1,LEAVES:13)
Block(6,21,1,LEAVES:13)
Block(7,21,1,LEAVES:13)
Block(2,21,2,LEAVES:13)
Block(4,21,2,LEAVES:13)
Block(5,21,2,LEAVES:13)
Block(5,22,-7,LEAVES:5)
Block(4,22,-6,LEAVES:13)
Block(5,22,-6,LEAVES:13)
Block(6,22,-6,LEAVES:13)
Block(4,22,-5,LEAVES:13)
Block(5,22,-3,LEAVES:13)
Block(6,22,-3,LEAVES:13)
Block(4,22,-2,LEAVES:13)
Block(5,22,-2,LEAVES:13)
Block(6,22,-2,LEAVES:13)
Block(9,22,-2,LEAVES:13)
Block(4,22,-1,LEAVES:13)
Block(5,22,-1,LEAVES:13)
Block(6,22,-1,LEAVES:13)
Block(9,22,-1,LEAVES:13)
Block(10,22,-1,LEAVES:13)
Block(3,22,0,LEAVES:13)
Block(4,22,0,LEAVES:13)
Block(6,22,0,LEAVES:13)
Block(8,22,0,LEAVES:13)
Block(9,22,0,LEAVES:13)
Block(3,22,1,LEAVES:13)
Block(4,22,1,LEAVES:13)
Block(5,22,1,LEAVES:13)
Block(2,22,2,LEAVES:13)
Block(3,22,2,LEAVES:13)
Block(4,22,2,LEAVES:13)
Block(2,22,3,LEAVES:13)
Block(5,23,-6,LEAVES:13)
Block(4,23,-5,LEAVES:13)
Block(5,23,-5,LEAVES:13)
Block(6,23,-5,LEAVES:13)
Block(4,23,-3,LEAVES:13)
Block(5,23,-3,LEAVES:13)
Block(6,23,-3,LEAVES:13)
Block(4,23,-2,LEAVES:13)
Block(5,23,-2,LEAVES:13)
Block(6,23,-2,LEAVES:13)
Block(7,23,-2,LEAVES:13)
Block(8,23,-2,LEAVES:13)
Block(9,23,-2,LEAVES:13)
Block(4,23,-1,LEAVES:13)
Block(5,23,-1,LEAVES:13)
Block(6,23,-1,LEAVES:13)
Block(7,23,-1,LEAVES:13)
Block(8,23,-1,LEAVES:13)
Block(9,23,-1,LEAVES:13)
Block(4,23,0,LEAVES:13)
Block(5,23,0,LEAVES:13)
Block(8,23,0,LEAVES:13)
Block(3,23,1,LEAVES:13)
Block(4,23,1,LEAVES:13)
Block(5,23,1,LEAVES:13)
Block(3,23,2,LEAVES:13)
Block(5,24,-5,LEAVES:13)
Block(5,24,-4,LEAVES:13)
Block(6,24,-4,LEAVES:13)
Block(5,24,-3,LEAVES:13)
Block(6,24,-3,LEAVES:13)
Block(5,24,-2,LEAVES:13)
Block(6,24,-2,LEAVES:13)
Block(7,24,-2,LEAVES:13)
Block(8,24,-2,LEAVES:13)
Block(4,24,-1,LEAVES:13)
Block(5,24,-1,LEAVES:13)
Block(6,24,-1,LEAVES:13)
Block(7,24,-1,LEAVES:13)
Block(8,24,-1,LEAVES:13)
Block(4,24,0,LEAVES:13)
Block(5,24,0,LEAVES:13)
Block(4,24,1,LEAVES:13)
Block(7,25,-5,LEAVES:13)
Block(8,25,-5,LEAVES:13)
Block(9,25,-5,LEAVES:13)
Block(2,25,-4,LEAVES:13)
Block(9,25,-4,LEAVES:13)
Block(1,25,-3,LEAVES:13)
Block(5,25,-3,LEAVES:13)
Block(6,25,-3,LEAVES:13)
Block(9,25,-3,LEAVES:13)
Block(1,25,-2,LEAVES:13)
Block(5,25,-2,LEAVES:13)
Block(6,25,-2,LEAVES:13)
Block(7,25,-2,LEAVES:13)
Block(5,25,-1,LEAVES:13)
Block(6,25,-1,LEAVES:13)
Block(7,25,-1,LEAVES:13)
Block(5,25,0,LEAVES:13)
Block(8,25,0,LEAVES:13)
Block(5,25,1,LEAVES:13)
Block(6,25,1,LEAVES:13)
Block(8,25,1,LEAVES:13)
Block(6,25,2,LEAVES:13)
Block(8,25,2,LEAVES:13)
Block(7,25,3,LEAVES:13)
Block(8,25,3,LEAVES:13)
Block(7,26,-5,LEAVES:13)
Block(8,26,-5,LEAVES:13)
Block(1,26,-4,LEAVES:13)
Block(2,26,-4,LEAVES:13)
Block(3,26,-4,LEAVES:13)
Block(7,26,-4,LEAVES:13)
Block(8,26,-4,LEAVES:13)
Block(9,26,-4,LEAVES:13)
Block(1,26,-3,LEAVES:13)
Block(2,26,-3,LEAVES:13)
Block(8,26,-3,LEAVES:13)
Block(9,26,-3,LEAVES:13)
Block(2,26,-2,LEAVES:13)
Block(5,26,-2,LEAVES:13)
Block(6,26,-2,LEAVES:13)
Block(5,26,-1,LEAVES:13)
Block(6,26,-1,LEAVES:13)
Block(7,26,0,LEAVES:13)
Block(8,26,0,LEAVES:13)
Block(6,26,1,LEAVES:13)
Block(7,26,1,LEAVES:13)
Block(8,26,1,LEAVES:13)
Block(6,26,2,LEAVES:13)
Block(7,26,2,LEAVES:13)
Block(7,26,3,LEAVES:13)
Block(4,27,-5,LEAVES:13)
Block(6,27,-5,LEAVES:13)
Block(3,27,-4,LEAVES:13)
Block(6,27,-4,LEAVES:13)
Block(7,27,-4,LEAVES:13)
Block(8,27,-4,LEAVES:13)
Block(2,27,-3,LEAVES:13)
Block(3,27,-3,LEAVES:13)
Block(7,27,-3,LEAVES:13)
Block(8,27,-3,LEAVES:13)
Block(3,27,-2,LEAVES:13)
Block(5,27,-2,LOG:12)
Block(6,27,-2,LEAVES:13)
Block(2,27,-1,LEAVES:13)
Block(5,27,-1,LOG:12)
Block(6,27,-1,LOG:12)
Block(9,27,-1,LEAVES:13)
Block(2,27,0,LEAVES:13)
Block(6,27,0,LEAVES:13)
Block(7,27,0,LEAVES:13)
Block(9,27,0,LEAVES:13)
Block(2,27,1,LEAVES:13)
Block(3,27,1,LEAVES:13)
Block(4,27,1,LEAVES:13)
Block(6,27,1,LEAVES:13)
Block(7,27,1,LEAVES:13)
Block(8,27,1,LEAVES:13)
Block(9,27,1,LEAVES:13)
Block(7,27,2,LEAVES:13)
Block(4,28,-6,LEAVES:13)
Block(5,28,-6,LEAVES:13)
Block(4,28,-5,LEAVES:13)
Block(5,28,-5,LEAVES:13)
Block(6,28,-5,LEAVES:13)
Block(4,28,-4,LEAVES:13)
Block(6,28,-4,LEAVES:13)
Block(4,28,-3,LEAVES:13)
Block(6,28,-3,LEAVES:13)
Block(7,28,-3,LEAVES:13)
Block(4,28,-2,LEAVES:13)
Block(5,28,-2,LOG:12)
Block(6,28,-2,LOG:12)
Block(7,28,-2,LEAVES:13)
Block(3,28,-1,LEAVES:13)
Block(5,28,-1,LOG:12)
Block(6,28,-1,LEAVES:13)
Block(7,28,-1,LEAVES:13)
Block(9,28,-1,LEAVES:13)
Block(2,28,0,LEAVES:13)
Block(3,28,0,LEAVES:13)
Block(6,28,0,LEAVES:13)
Block(7,28,0,LEAVES:13)
Block(9,28,0,LEAVES:13)
Block(2,28,1,LEAVES:13)
Block(3,28,1,LEAVES:13)
Block(4,28,1,LEAVES:13)
Block(7,28,1,LEAVES:13)
Block(8,28,1,LEAVES:13)
Block(9,28,1,LEAVES:13)
Block(5,29,-5,LEAVES:13)
Block(4,29,-4,LEAVES:13)
Block(5,29,-4,LEAVES:13)
Block(6,29,-4,LEAVES:13)
Block(6,29,-3,LEAVES:13)
Block(4,29,-2,LEAVES:13)
Block(5,29,-2,LEAVES:13)
Block(6,29,-2,LEAVES:13)
Block(3,29,-1,LEAVES:13)
Block(4,29,-1,LEAVES:13)
Block(5,29,-1,LOG:12)
Block(6,29,-1,LEAVES:13)
Block(8,29,-1,LEAVES:13)
Block(3,29,0,LEAVES:13)
Block(4,29,0,LEAVES:13)
Block(6,29,0,LEAVES:13)
Block(7,29,0,LEAVES:13)
Block(8,29,0,LEAVES:13)
Block(5,30,-4,LEAVES:13)
Block(6,30,-4,LEAVES:13)
Block(5,30,-3,LEAVES:13)
Block(6,30,-3,LEAVES:13)
Block(7,30,-3,LEAVES:13)
Block(4,30,-2,LEAVES:13)
Block(5,30,-2,LOG:12)
Block(6,30,-2,LOG:12)
Block(4,30,-1,LEAVES:13)
Block(5,30,-1,LOG:12)
Block(6,30,-1,LOG:12)
Block(7,30,-1,LEAVES:13)
Block(8,30,-1,LEAVES:13)
Block(4,30,0,LEAVES:13)
Block(5,30,0,LEAVES:13)
Block(7,30,0,LEAVES:13)
Block(3,31,-4,LEAVES:13)
Block(7,31,-4,LEAVES:13)
Block(8,31,-4,LEAVES:13)
Block(5,31,-3,LEAVES:13)
Block(6,31,-3,LEAVES:13)
Block(8,31,-3,LEAVES:13)
Block(5,31,-2,LOG:12)
Block(6,31,-2,LOG:12)
Block(4,31,-1,LEAVES:13)
Block(5,31,-1,LEAVES:13)
Block(6,31,-1,LEAVES:13)
Block(7,31,-1,LEAVES:13)
Block(8,31,-1,LEAVES:13)
Block(4,31,0,LEAVES:13)
Block(6,31,0,LEAVES:13)
Block(7,31,0,LEAVES:13)
Block(5,31,1,LEAVES:13)
Block(6,31,1,LEAVES:13)
Block(8,31,1,LEAVES:13)
Block(6,32,-4,LEAVES:13)
Block(7,32,-4,LEAVES:13)
Block(8,32,-4,LEAVES:13)
Block(2,32,-3,LEAVES:13)
Block(3,32,-3,LEAVES:13)
Block(5,32,-3,LEAVES:13)
Block(6,32,-3,LEAVES:13)
Block(8,32,-3,LEAVES:13)
Block(2,32,-2,LEAVES:13)
Block(3,32,-2,LEAVES:13)
Block(5,32,-2,LEAVES:13)
Block(6,32,-2,LOG:12)
Block(8,32,-2,LEAVES:13)
Block(5,32,-1,LEAVES:13)
Block(6,32,-1,LEAVES:13)
Block(7,32,-1,LEAVES:13)
Block(7,32,0,LEAVES:13)
Block(5,32,1,LEAVES:13)
Block(6,32,1,LEAVES:13)
Block(7,32,1,LEAVES:13)
Block(6,32,2,LEAVES:13)
Block(7,32,2,LEAVES:13)
Block(5,33,-5,LEAVES:13)
Block(6,33,-5,LEAVES:13)
Block(3,33,-3,LEAVES:13)
Block(4,33,-3,LEAVES:13)
Block(6,33,-3,LEAVES:13)
Block(7,33,-3,LEAVES:13)
Block(3,33,-2,LEAVES:13)
Block(4,33,-2,LEAVES:13)
Block(5,33,-2,LOG:12)
Block(6,33,-2,LOG:12)
Block(7,33,-2,LEAVES:13)
Block(3,33,-1,LEAVES:13)
Block(5,33,-1,LEAVES:13)
Block(6,33,-1,LEAVES:13)
Block(7,33,-1,LEAVES:13)
Block(8,33,-1,LEAVES:13)
Block(9,33,-1,LEAVES:13)
Block(3,33,0,LEAVES:13)
Block(4,33,0,LEAVES:13)
Block(6,33,0,LEAVES:13)
Block(7,33,0,LEAVES:13)
Block(8,33,0,LEAVES:13)
Block(4,33,1,LEAVES:13)
Block(6,33,1,LEAVES:13)
Block(7,33,1,LEAVES:13)
Block(4,34,-5,LEAVES:13)
Block(5,34,-5,LEAVES:13)
Block(5,34,-4,LEAVES:13)
Block(6,34,-4,LEAVES:13)
Block(4,34,-2,LEAVES:13)
Block(5,34,-2,LEAVES:13)
Block(6,34,-2,LEAVES:13)
Block(8,34,-2,LEAVES:13)
Block(4,34,-1,LEAVES:13)
Block(5,34,-1,LOG:12)
Block(6,34,-1,LEAVES:13)
Block(7,34,-1,LEAVES:13)
Block(8,34,-1,LEAVES:13)
Block(4,34,0,LEAVES:13)
Block(6,34,0,LEAVES:13)
Block(7,34,0,LEAVES:13)
Block(4,34,1,LEAVES:13)
Block(5,35,-4,LEAVES:13)
Block(3,35,-3,LEAVES:13)
Block(4,35,-3,LEAVES:13)
Block(5,35,-3,LEAVES:13)
Block(6,35,-3,LEAVES:13)
Block(8,35,-3,LEAVES:13)
Block(5,35,-2,LOG:12)
Block(6,35,-2,LOG:12)
Block(8,35,-2,LEAVES:13)
Block(4,35,-1,LEAVES:13)
Block(5,35,-1,LEAVES:13)
Block(6,35,-1,LOG:12)
Block(7,35,-1,LEAVES:13)
Block(8,35,-1,LEAVES:13)
Block(4,35,0,LEAVES:13)
Block(5,35,0,LEAVES:13)
Block(5,35,1,LEAVES:13)
Block(6,35,1,LEAVES:13)
Block(4,36,-3,LEAVES:13)
Block(5,36,-3,LEAVES:13)
Block(6,36,-3,LEAVES:13)
Block(8,36,-3,LEAVES:13)
Block(4,36,-2,LEAVES:13)
Block(5,36,-2,LOG:12)
Block(6,36,-2,LOG:12)
Block(7,36,-2,LEAVES:13)
Block(8,36,-2,LEAVES:13)
Block(5,36,-1,LEAVES:13)
Block(6,36,-1,LEAVES:13)
Block(7,36,-1,LEAVES:13)
Block(8,36,-1,LEAVES:13)
Block(4,36,0,LEAVES:13)
Block(5,36,0,LEAVES:13)
Block(6,36,0,LEAVES:13)
Block(6,36,1,LEAVES:13)
Block(6,37,-4,LEAVES:13)
Block(4,37,-2,LEAVES:13)
Block(5,37,-2,LEAVES:13)
Block(6,37,-2,LOG:12)
Block(7,37,-2,LEAVES:13)
Block(5,37,-1,LEAVES:13)
Block(6,37,-1,LOG:12)
Block(7,37,-1,LEAVES:13)
Block(5,37,0,LEAVES:13)
Block(6,37,0,LEAVES:13)
Block(5,38,-4,LEAVES:13)
Block(6,38,-4,LEAVES:13)
Block(6,38,-3,LEAVES:13)
Block(7,38,-3,LEAVES:13)
Block(5,38,-2,LEAVES:13)
Block(6,38,-2,LOG:12)
Block(7,38,-2,LEAVES:13)
Block(4,38,-1,LEAVES:13)
Block(5,38,-1,LEAVES:13)
Block(6,38,-1,LOG:12)
Block(8,38,-1,LEAVES:13)
Block(4,38,0,LEAVES:13)
Block(7,38,0,LEAVES:13)
Block(5,39,-3,LEAVES:13)
Block(6,39,-3,LEAVES:13)
Block(5,39,-2,LEAVES:13)
Block(6,39,-2,LEAVES:13)
Block(7,39,-2,LEAVES:13)
Block(4,39,-1,LEAVES:13)
Block(5,39,-1,LEAVES:13)
Block(6,39,-1,LEAVES:13)
Block(7,39,-1,LEAVES:13)
Block(8,39,-1,LEAVES:13)
Block(4,39,0,LEAVES:13)
Block(7,39,0,LEAVES:13)
Block(5,40,-3,LEAVES:13)
Block(6,40,-3,LEAVES:13)
Block(5,40,-2,LEAVES:13)
Block(6,40,-2,LEAVES:13)
Block(7,40,-2,LEAVES:13)
Block(5,40,-1,LEAVES:13)
Block(6,40,-1,LEAVES:13)
Block(7,40,-1,LEAVES:13)
Block(6,41,-3,LEAVES:13)
Block(4,41,-2,LEAVES:13)
Block(5,41,-2,LEAVES:13)
Block(6,41,-2,LEAVES:13)
Block(7,41,-2,LEAVES:13)
Block(5,41,-1,LEAVES:13)
Block(6,41,-1,LEAVES:13)
Block(6,42,-3,LEAVES:13)
Block(4,42,-2,LEAVES:13)
Block(5,42,-2,LEAVES:13)
Block(6,42,-2,LEAVES:13)
Block(7,42,-2,LEAVES:13)
Block(6,42,-1,LOG:12)
Block(5,42,0,LEAVES:13)
Block(6,42,0,LEAVES:13)
Block(7,42,0,LEAVES:13)
Block(4,43,-2,LEAVES:13)
Block(5,43,-2,LEAVES:13)
Block(6,43,-2,LEAVES:13)
Block(6,43,-1,LOG:12)
Block(6,43,0,LEAVES:13)
Block(5,44,-2,LEAVES:13)
Block(6,44,-2,LOG:12)
Block(6,44,-1,LEAVES:13)
Block(6,45,-3,LEAVES:13)
Block(6,45,-2,LOG:12)
Block(4,45,-1,LEAVES:13)
Block(6,45,-1,LOG:12)
Block(7,45,-1,LEAVES:13)
Block(4,45,0,LEAVES:13)
Block(7,45,0,LEAVES:13)
Block(5,46,-3,LEAVES:13)
Block(6,46,-3,LEAVES:13)
Block(6,46,-2,LEAVES:13)
Block(5,46,-1,LEAVES:13)
Block(6,46,-1,LEAVES:13)
Block(7,46,-1,LEAVES:13)
Block(6,47,-2,LEAVES:13)
Block(5,47,-1,LEAVES:13)
Block(6,47,-1,LEAVES:13)
Block(6,48,-2,LEAVES:13)


#######################################################################
# +-----------------------------------------------------------------+ #
# |                            BO3 checks                           | #
# +-----------------------------------------------------------------+ #
#######################################################################

# Require a condition at a certain location in order for the BO3 to be spawned.
# BlockCheck(x,y,z,BlockName[,BlockName[,...]]) - one of the blocks must be at the location
# BlockCheckNot(x,y,z,BlockName[,BlockName[,...]]) - all the blocks must not be at the location
# LightCheck(x,y,z,minLightLevel,maxLightLevel) - light must be between min and max (inclusive)

# You can use "Solid" as a BlockName for matching all solid blocks or "All" to match all blocks that aren't air.

# Examples:
BlockCheck(0,-1,0,GRASS,DIRT,DIRT:2)
#   BlockCheck(0,-1,0,Solid)       Require any solid block just below the object
#   BlockCheck(0,-1,0,WOOL)        Require any type of wool just below the object
#   BlockCheck(0,-1,0,WOOL:0)      Require white wool just below the object
#   BlockCheckNot(0,-1,0,WOOL:0)   Require that there is no white wool below the object
#   LightCheck(0,0,0,0,1)          Require almost complete darkness just below the object

#######################################################################
# +-----------------------------------------------------------------+ #
# |                             Branches                            | #
# +-----------------------------------------------------------------+ #
#######################################################################

# Branches are objects that will spawn when this object spawns when it is used in
# the CustomStructure resource. Branches can also have branches, making complex
# structures possible. See the wiki for more details.

# Regular Branches spawn each branch with an independent chance of spawning.
# Branch(x,y,z,branchName,rotation,chance[,anotherBranchName,rotation,chance[,...]][IndividualChance])
# branchName - name of the object to spawn.
# rotation - NORTH, SOUTH, EAST or WEST.
# IndividualChance - The chance each branch has to spawn, assumed to be 100 when left blank

# Weighted Branches spawn branches with a dependent chance of spawning.
# WeightedBranch(x,y,z,branchName,rotation,chance[,anotherBranchName,rotation,chance[,...]][MaxChanceOutOf])
# MaxChanceOutOf - The chance all branches have to spawn out of, assumed to be 100 when left blank
 
