#######################################################################
# +-----------------------------------------------------------------+ #
# |                            BO3 object                           | #
# +-----------------------------------------------------------------+ #
#######################################################################

# The descriptions in this file are accurate only for TerrainControl and OTG.
# For MCW and OTG+ these descriptions are only accurate if the BO3 is used as a CustomObject.
# MCW and OTG+ completely reimplemented CustomStructure, check the MCW/OTG+ documentation for more information.

# This is the config file of a custom object.
# If you add this object correctly to your BiomeConfigs, it will spawn in the world.

# This is the creator of this BO3 object
Author: Unknown

# A short description of this BO3 object
Description: This BO3 was converted from a schematic using OTGEdit. The author and description information of the schematic could not be found. If you know who the author of the schematic is then please add this information.

# The BO3 version, don't change this! It can be used by external applications to do a version check.
Version: 3

# The settings mode, WriteAll, WriteWithoutComments or WriteDisable. See WorldConfig.
SettingsMode: WriteDisable

#######################################################################
# +-----------------------------------------------------------------+ #
# |                          Main settings                          | #
# +-----------------------------------------------------------------+ #
#######################################################################

# This needs to be set to true to spawn the object in the Tree and Sapling resources.
Tree: true

# The frequency of the BO3 from 1 to 200. Tries this many times to spawn this BO3 when using the CustomObject(...) resource.
# Ignored by Tree(..), Sapling(..) and CustomStructure(..)
Frequency: 40

# The rarity of the BO3 from 0 to 100. Each spawn attempt has rarity% chance to succeed when using the CustomObject(...) resource.
# Ignored by Tree(..), Sapling(..) and CustomStructure(..)
Rarity: 100.0

# If you set this to true, the BO3 will be placed with a random rotation.
RotateRandomly: true

# The spawn height of the BO3 - randomY, highestBlock or highestSolidBlock.
SpawnHeight: highestSolidBlock
SpawnHeightOffset: -1
# The height limits for the BO3.
MinHeight: 0

MaxHeight: 75

# Objects can have other objects attached to it: branches. Branches can also
# have branches attached to it, which can also have branches, etc. This is the
# maximum branch depth for this objects.
MaxBranchDepth: 10

# When spawned with the UseWorld keyword, this BO3 should NOT spawn in the following biomes.
# If you writer.write the BO3 name directly in the BiomeConfigs, this will be ignored.
ExcludedBiomes: All

# To optimise this BO3 for faster loading times you can use Notepad++ to find/replace comments and abbreviate things.
# Notepad++ find/replace with regex:
# Find: ^[#;].* replace to nothing removes all lines starting with # 
# Find: ^\s*$ replace to nothing removes most empty lines 
# Notepad++ find/replace without regex:
# *Warning: This will only work for OTG 1.10.2 v21 / OTG 1.11.2 v6 or higher. B( is not recognised by lower versions.
# Find: Block( replace to B(

#######################################################################
# +-----------------------------------------------------------------+ #
# |                      Source block settings                      | #
# +-----------------------------------------------------------------+ #
#######################################################################

# The block(s) the BO3 should spawn in.
SourceBlocks: AIR,GRASS,DIRT,DIRT:1,SAND

# The maximum percentage of the BO3 that can be outside the SourceBlock.
# The BO3 won't be placed on a location with more blocks outside the SourceBlock than this percentage.
MaxPercentageOutsideSourceBlock: 0

# What to do when a block is about to be placed outside the SourceBlock? (dontPlace, placeAnyway)
OutsideSourceBlock: dontPlace

#######################################################################
# +-----------------------------------------------------------------+ #
# |                              Blocks                             | #
# +-----------------------------------------------------------------+ #
#######################################################################

# All the blocks used in the BO3 are listed here. Possible blocks:
# Block(x,y,z,id[.data][,nbtfile.nbt) or B(x,y,z,id[.data][,nbtfile.nbt)
# RandomBlock(x,y,z,id[:data][,nbtfile.nbt],chance[,id[:data][,nbtfile.nbt],chance[,...]])
# So RandomBlock(0,0,0,CHEST,chest.nbt,50,CHEST,anotherchest.nbt,100) will spawn a chest at
# the BO3 origin, and give it a 50% chance to have the contents of chest.nbt, or, if that
# fails, a 100% percent chance to have the contents of anotherchest.nbt.

Block(-2,10,7,LEAVES2:12)
Block(-2,11,7,LEAVES2:12)
Block(-2,12,6,LEAVES2:12)
Block(-1,7,5,LEAVES2:12)
Block(-1,7,7,LEAVES2:12)
Block(-1,9,6,LEAVES2:12)
Block(-1,11,4,LEAVES2:12)
Block(-1,12,4,LEAVES2:12)
Block(0,8,6,162:12)
Block(0,9,4,LEAVES2:12)
Block(0,9,5,LEAVES2:12)
Block(0,9,6,LEAVES2:12)
Block(0,10,4,LEAVES2:12)
Block(0,12,4,LEAVES2:12)
Block(0,12,7,LEAVES2:12)
Block(0,13,4,LEAVES2:12)
Block(0,13,7,LEAVES2:12)
Block(0,14,3,LEAVES2:12)
Block(1,7,4,LEAVES2:12)
Block(1,7,6,LEAVES2:12)
Block(1,7,7,162:12)
Block(1,8,5,LEAVES2:12)
Block(1,8,6,LEAVES2:12)
Block(1,8,7,162:12)
Block(1,9,2,LEAVES2:12)
Block(1,9,4,LEAVES2:12)
Block(1,9,5,LEAVES2:12)
Block(1,9,6,LEAVES2:12)
Block(1,10,7,LEAVES2:12)
Block(1,11,3,LEAVES2:12)
Block(1,11,7,LEAVES2:12)
Block(1,13,1,LEAVES2:12)
Block(1,13,5,LEAVES2:12)
Block(1,13,11,LEAVES2:12)
Block(1,14,1,LEAVES2:12)
Block(1,14,5,LEAVES2:12)
Block(1,14,11,LEAVES2:12)
Block(1,15,5,LEAVES2:12)
Block(1,15,10,LEAVES2:12)
Block(2,7,7,162:12)
Block(2,8,7,LEAVES2:12)
Block(2,9,13,LEAVES2:12)
Block(2,10,3,162:12)
Block(2,10,5,LEAVES2:12)
Block(2,10,9,LEAVES2:12)
Block(2,10,11,LEAVES2:12)
Block(2,10,13,LEAVES2:12)
Block(2,11,1,LEAVES2:12)
Block(2,11,2,LEAVES2:12)
Block(2,11,3,LEAVES2:12)
Block(2,11,5,LEAVES2:12)
Block(2,11,12,LEAVES2:12)
Block(2,12,1,LEAVES2:12)
Block(2,12,5,LEAVES2:12)
Block(2,12,10,LEAVES2:12)
Block(2,14,4,LEAVES2:12)
Block(2,14,7,LEAVES2:12)
Block(2,14,8,LEAVES2:12)
Block(2,15,4,LEAVES2:12)
Block(2,15,7,LEAVES2:12)
Block(2,15,8,LEAVES2:12)
Block(2,16,6,LEAVES2:12)
Block(3,6,11,LEAVES2:12)
Block(3,6,13,LEAVES2:12)
Block(3,7,7,162:12)
Block(3,8,12,LEAVES2:12)
Block(3,9,1,LEAVES2:12)
Block(3,9,3,LEAVES2:12)
Block(3,9,4,162:12)
Block(3,9,5,162:12)
Block(3,10,2,LEAVES2:12)
Block(3,10,3,LEAVES2:12)
Block(3,10,4,162:12)
Block(3,10,9,162:12)
Block(3,10,10,LEAVES2:12)
Block(3,11,2,LEAVES2:12)
Block(3,11,3,LEAVES2:12)
Block(3,11,5,LEAVES2:12)
Block(3,11,7,LEAVES2:12)
Block(3,11,9,162:12)
Block(3,11,10,162:12)
Block(3,12,4,LEAVES2:12)
Block(3,12,8,LEAVES2:12)
Block(3,12,9,LEAVES2:12)
Block(3,12,10,LEAVES2:12)
Block(3,13,4,LEAVES2:12)
Block(3,13,6,LEAVES2:12)
Block(3,13,8,LEAVES2:12)
Block(3,15,2,LEAVES2:12)
Block(3,15,4,LEAVES2:12)
Block(3,15,11,LEAVES2:12)
Block(3,16,2,LEAVES2:12)
Block(3,16,4,LEAVES2:12)
Block(3,16,11,LEAVES2:12)
Block(3,17,2,LEAVES2:12)
Block(4,6,7,162:12)
Block(4,6,11,162:12)
Block(4,7,7,162:12)
Block(4,7,12,162:12)
Block(4,8,7,162:12)
Block(4,8,10,LEAVES2:12)
Block(4,8,11,LEAVES2:12)
Block(4,8,12,LEAVES2:12)
Block(4,9,5,162:12)
Block(4,9,6,162:12)
Block(4,9,7,162:12)
Block(4,9,8,162:12)
Block(4,9,10,LEAVES2:12)
Block(4,10,4,LEAVES2:12)
Block(4,10,6,162:12)
Block(4,10,8,162:12)
Block(4,10,9,162:12)
Block(4,10,10,LEAVES2:12)
Block(4,11,6,162:12)
Block(4,11,9,LEAVES2:12)
Block(4,11,10,LEAVES2:12)
Block(4,11,13,LEAVES2:12)
Block(4,12,2,LEAVES2:12)
Block(4,12,6,162:12)
Block(4,12,9,LEAVES2:12)
Block(4,12,10,LEAVES2:12)
Block(4,12,13,LEAVES2:12)
Block(4,13,2,LEAVES2:12)
Block(4,13,4,LEAVES2:12)
Block(4,13,5,LEAVES2:12)
Block(4,13,6,LEAVES2:12)
Block(4,13,11,LEAVES2:12)
Block(4,14,2,LEAVES2:12)
Block(4,14,4,LEAVES2:12)
Block(4,14,11,LEAVES2:12)
Block(4,16,7,LEAVES2:12)
Block(4,16,9,LEAVES2:12)
Block(4,17,7,LEAVES2:12)
Block(4,17,9,LEAVES2:12)
Block(4,18,9,LEAVES2:12)
Block(5,0,6,162:12)
Block(5,0,7,162:12)
Block(5,1,6,162:12)
Block(5,1,7,162:12)
Block(5,2,6,162:12)
Block(5,2,7,162:12)
Block(5,3,6,162:12)
Block(5,3,7,162:12)
Block(5,4,7,162:12)
Block(5,5,7,162:12)
Block(5,5,8,162:12)
Block(5,5,9,162:12)
Block(5,5,10,162:12)
Block(5,6,6,162:12)
Block(5,6,7,162:12)
Block(5,6,10,162:12)
Block(5,6,12,LEAVES2:12)
Block(5,7,11,LEAVES2:12)
Block(5,7,12,LEAVES2:12)
Block(5,8,11,LEAVES2:12)
Block(5,8,12,LEAVES2:12)
Block(5,9,13,LEAVES2:12)
Block(5,10,4,LEAVES2:12)
Block(5,10,13,LEAVES2:12)
Block(5,11,4,LEAVES2:12)
Block(5,11,6,LEAVES2:12)
Block(5,11,11,LEAVES2:12)
Block(5,12,3,LEAVES2:12)
Block(5,12,5,LEAVES2:12)
Block(5,12,6,LEAVES2:12)
Block(5,12,11,LEAVES2:12)
Block(5,13,5,LEAVES2:12)
Block(5,13,6,LEAVES2:12)
Block(5,13,9,LEAVES2:12)
Block(5,13,11,LEAVES2:12)
Block(5,14,7,LEAVES2:12)
Block(5,14,9,LEAVES2:12)
Block(5,14,11,LEAVES2:12)
Block(5,15,7,LEAVES2:12)
Block(5,15,9,LEAVES2:12)
Block(5,17,5,LEAVES2:12)
Block(5,18,5,LEAVES2:12)
Block(5,19,5,LEAVES2:12)
Block(6,3,7,162:12)
Block(6,6,5,162:12)
Block(6,6,6,162:12)
Block(6,7,2,LEAVES2:12)
Block(6,7,4,162:12)
Block(6,7,5,162:12)
Block(6,7,13,LEAVES2:12)
Block(6,8,4,162:12)
Block(6,9,3,LEAVES2:12)
Block(6,9,11,LEAVES2:12)
Block(6,10,11,LEAVES2:12)
Block(6,11,1,LEAVES2:12)
Block(6,11,11,LEAVES2:12)
Block(6,12,1,LEAVES2:12)
Block(6,12,7,LEAVES2:12)
Block(6,14,5,LEAVES2:12)
Block(6,15,5,LEAVES2:12)
Block(6,16,5,LEAVES2:12)
Block(7,3,7,162:12)
Block(7,4,7,162:12)
Block(7,7,10,LEAVES2:12)
Block(7,8,3,162:12)
Block(7,8,10,LEAVES2:12)
Block(7,9,1,LEAVES2:12)
Block(7,9,2,LEAVES2:12)
Block(7,9,3,LEAVES2:12)
Block(7,9,9,LEAVES2:12)
Block(7,10,1,LEAVES2:12)
Block(7,12,4,LEAVES2:12)
Block(7,13,4,LEAVES2:12)
Block(8,4,7,162:12)
Block(8,4,8,162:12)
Block(8,4,10,LEAVES2:12)
Block(8,6,9,LEAVES2:12)
Block(8,7,1,LEAVES2:12)
Block(8,7,3,LEAVES2:12)
Block(8,8,2,LEAVES2:12)
Block(8,8,3,LEAVES2:12)
Block(8,8,7,LEAVES2:12)
Block(8,9,2,LEAVES2:12)
Block(8,9,3,LEAVES2:12)
Block(8,9,7,LEAVES2:12)
Block(8,10,4,LEAVES2:12)
Block(8,11,4,LEAVES2:12)
Block(8,13,2,LEAVES2:12)
Block(8,14,2,LEAVES2:12)
Block(8,15,2,LEAVES2:12)
Block(9,4,8,162:12)
Block(9,5,9,162:12)
Block(9,6,7,LEAVES2:12)
Block(9,6,8,LEAVES2:12)
Block(9,6,9,LEAVES2:12)
Block(9,7,7,LEAVES2:12)
Block(9,8,4,LEAVES2:12)
Block(9,9,10,LEAVES2:12)
Block(9,10,2,LEAVES2:12)
Block(9,10,10,LEAVES2:12)
Block(9,11,2,LEAVES2:12)
Block(9,12,2,LEAVES2:12)
Block(10,4,7,LEAVES2:12)
Block(10,4,9,LEAVES2:12)
Block(10,5,8,LEAVES2:12)
Block(10,5,9,LEAVES2:12)
Block(10,6,8,LEAVES2:12)
Block(10,6,9,LEAVES2:12)
Block(10,7,10,LEAVES2:12)
Block(10,8,10,LEAVES2:12)
Block(10,10,8,LEAVES2:12)
Block(10,11,8,LEAVES2:12)
Block(10,12,8,LEAVES2:12)
Block(11,5,10,LEAVES2:12)
Block(11,7,8,LEAVES2:12)
Block(11,8,8,LEAVES2:12)
Block(11,9,8,LEAVES2:12)


#######################################################################
# +-----------------------------------------------------------------+ #
# |                             Entities                            | #
# +-----------------------------------------------------------------+ #
#######################################################################

# Entity() spawns an entity instead of a block. The entity is spawned only once when the BO3 is spawned.
# Entities are persistent by default so they don't de-spawn when no player is near, they are only unloaded.
# Usage: Entity(x,y,z,mobName,groupSize,NameTagOrNBTFileName) or Entity(x,y,z,mobName,groupSize)
# Use /tc entities or /otg entities to get a list of entities that can be used as mobName, this includes entities added by other mods.
# NameTagOrNBTFileName can be either a nametag for the mob or an nbt file (such as mymobinfo.nbt or mymobinfo.txt).
# When using a text file you can use the same mob spawning parameters used with the /summon command to equip the
# entity and give it custom attributes etc. You can copy the DATA part of a summon command including surrounding
# curly braces to a .txt file, for instance for: "/summon Skeleton x y z {DATA}"

#######################################################################
# +-----------------------------------------------------------------+ #
# |                            BO3 checks                           | #
# +-----------------------------------------------------------------+ #
#######################################################################

# Require a condition at a certain location in order for the BO3 to be spawned.
# BlockCheck(x,y,z,BlockName[,BlockName[,...]]) - one of the blocks must be at the location
# BlockCheckNot(x,y,z,BlockName[,BlockName[,...]]) - all the blocks must not be at the location
# LightCheck(x,y,z,minLightLevel,maxLightLevel) - light must be between min and max (inclusive)

# You can use "Solid" as a BlockName for matching all solid blocks or "All" to match all blocks that aren't air.

# Examples:
BlockCheck(0,-1,0,GRASS,DIRT,DIRT:2,SAND)
#   BlockCheck(0,-1,0,Solid)       Require any solid block just below the object
#   BlockCheck(0,-1,0,WOOL)        Require any type of wool just below the object
#   BlockCheck(0,-1,0,WOOL:0)      Require white wool just below the object
#   BlockCheckNot(0,-1,0,WOOL:0)   Require that there is no white wool below the object
#   LightCheck(0,0,0,0,1)          Require almost complete darkness just below the object

