#######################################################################
# +-----------------------------------------------------------------+ #
# |                            BO3 object                           | #
# +-----------------------------------------------------------------+ #
#######################################################################

# The descriptions in this file are accurate only for TerrainControl and OTG.
# For MCW and OTG+ these descriptions are only accurate if the BO3 is used as a CustomObject.
# MCW and OTG+ completely reimplemented CustomStructure, check the MCW/OTG+ documentation for more information.

# This is the config file of a custom object.
# If you add this object correctly to your BiomeConfigs, it will spawn in the world.

# This is the creator of this BO3 object
Author: Unknown

# A short description of this BO3 object
Description: This BO3 was converted from a schematic using OTGEdit. The author and description information of the schematic could not be found. If you know who the author of the schematic is then please add this information.

# The BO3 version, don't change this! It can be used by external applications to do a version check.
Version: 3

# The settings mode, WriteAll, WriteWithoutComments or WriteDisable. See WorldConfig.
SettingsMode: WriteDisable

#######################################################################
# +-----------------------------------------------------------------+ #
# |                          Main settings                          | #
# +-----------------------------------------------------------------+ #
#######################################################################

# This needs to be set to true to spawn the object in the Tree and Sapling resources.
Tree: true

# The frequency of the BO3 from 1 to 200. Tries this many times to spawn this BO3 when using the CustomObject(...) resource.
# Ignored by Tree(..), Sapling(..) and CustomStructure(..)
Frequency: 40

# The rarity of the BO3 from 0 to 100. Each spawn attempt has rarity% chance to succeed when using the CustomObject(...) resource.
# Ignored by Tree(..), Sapling(..) and CustomStructure(..)
Rarity: 100.0

# If you set this to true, the BO3 will be placed with a random rotation.
RotateRandomly: true

# The spawn height of the BO3 - randomY, highestBlock or highestSolidBlock.
SpawnHeight: highestSolidBlock
SpawnHeightOffset: -1
# The height limits for the BO3.
MinHeight: 0

MaxHeight: 75

# Objects can have other objects attached to it: branches. Branches can also
# have branches attached to it, which can also have branches, etc. This is the
# maximum branch depth for this objects.
MaxBranchDepth: 10

# When spawned with the UseWorld keyword, this BO3 should NOT spawn in the following biomes.
# If you writer.write the BO3 name directly in the BiomeConfigs, this will be ignored.
ExcludedBiomes: All

# To optimise this BO3 for faster loading times you can use Notepad++ to find/replace comments and abbreviate things.
# Notepad++ find/replace with regex:
# Find: ^[#;].* replace to nothing removes all lines starting with # 
# Find: ^\s*$ replace to nothing removes most empty lines 
# Notepad++ find/replace without regex:
# *Warning: This will only work for OTG 1.10.2 v21 / OTG 1.11.2 v6 or higher. B( is not recognised by lower versions.
# Find: Block( replace to B(

#######################################################################
# +-----------------------------------------------------------------+ #
# |                      Source block settings                      | #
# +-----------------------------------------------------------------+ #
#######################################################################

# The block(s) the BO3 should spawn in.
SourceBlocks: AIR,GRASS,DIRT,DIRT:1,SAND

# The maximum percentage of the BO3 that can be outside the SourceBlock.
# The BO3 won't be placed on a location with more blocks outside the SourceBlock than this percentage.
MaxPercentageOutsideSourceBlock: 0

# What to do when a block is about to be placed outside the SourceBlock? (dontPlace, placeAnyway)
OutsideSourceBlock: dontPlace

#######################################################################
# +-----------------------------------------------------------------+ #
# |                              Blocks                             | #
# +-----------------------------------------------------------------+ #
#######################################################################

# All the blocks used in the BO3 are listed here. Possible blocks:
# Block(x,y,z,id[.data][,nbtfile.nbt) or B(x,y,z,id[.data][,nbtfile.nbt)
# RandomBlock(x,y,z,id[:data][,nbtfile.nbt],chance[,id[:data][,nbtfile.nbt],chance[,...]])
# So RandomBlock(0,0,0,CHEST,chest.nbt,50,CHEST,anotherchest.nbt,100) will spawn a chest at
# the BO3 origin, and give it a 50% chance to have the contents of chest.nbt, or, if that
# fails, a 100% percent chance to have the contents of anotherchest.nbt.

Block(-2,10,12,LEAVES2:12)
Block(-2,11,12,LEAVES2:12)
Block(-2,12,11,LEAVES2:12)
Block(-1,6,7,LEAVES2:12)
Block(-1,7,7,LEAVES2:12)
Block(-1,7,10,LEAVES2:12)
Block(-1,7,12,LEAVES2:12)
Block(-1,8,6,LEAVES2:12)
Block(-1,9,11,LEAVES2:12)
Block(-1,11,9,LEAVES2:12)
Block(-1,12,9,LEAVES2:12)
Block(0,3,5,LEAVES2:12)
Block(0,3,7,LEAVES2:12)
Block(0,5,6,LEAVES2:12)
Block(0,7,4,LEAVES2:12)
Block(0,8,4,LEAVES2:12)
Block(0,8,11,162:12)
Block(0,9,9,LEAVES2:12)
Block(0,9,10,LEAVES2:12)
Block(0,9,11,LEAVES2:12)
Block(0,10,9,LEAVES2:12)
Block(0,11,9,162:12)
Block(0,12,12,LEAVES2:12)
Block(0,13,12,LEAVES2:12)
Block(1,4,6,162:12)
Block(1,5,4,LEAVES2:12)
Block(1,5,5,LEAVES2:12)
Block(1,5,6,LEAVES2:12)
Block(1,6,4,LEAVES2:12)
Block(1,7,9,162:12)
Block(1,7,10,162:12)
Block(1,7,11,LEAVES2:12)
Block(1,8,7,LEAVES2:12)
Block(1,8,10,162:12)
Block(1,8,11,LEAVES2:12)
Block(1,9,7,LEAVES2:12)
Block(1,9,10,LEAVES2:12)
Block(1,9,11,LEAVES2:12)
Block(1,10,10,162:12)
Block(1,10,12,LEAVES2:12)
Block(1,11,10,162:12)
Block(1,11,12,LEAVES2:12)
Block(1,13,10,LEAVES2:12)
Block(1,14,10,LEAVES2:12)
Block(1,14,11,LEAVES2:12)
Block(1,15,10,LEAVES2:12)
Block(1,15,11,LEAVES2:12)
Block(1,16,10,LEAVES2:12)
Block(2,3,4,LEAVES2:12)
Block(2,3,6,LEAVES2:12)
Block(2,3,7,162:12)
Block(2,4,5,LEAVES2:12)
Block(2,4,6,LEAVES2:12)
Block(2,4,7,162:12)
Block(2,5,5,LEAVES2:12)
Block(2,5,6,LEAVES2:12)
Block(2,6,7,LEAVES2:12)
Block(2,7,7,LEAVES2:12)
Block(2,7,9,162:12)
Block(2,8,12,LEAVES2:12)
Block(2,9,5,LEAVES2:12)
Block(2,10,5,LEAVES2:12)
Block(2,10,10,162:12)
Block(2,11,5,LEAVES2:12)
Block(2,11,9,LEAVES2:12)
Block(2,11,10,LEAVES2:12)
Block(2,11,11,LEAVES2:12)
Block(2,12,10,LEAVES2:12)
Block(2,13,10,LEAVES2:12)
Block(2,15,8,LEAVES2:12)
Block(2,16,8,LEAVES2:12)
Block(3,3,7,162:12)
Block(3,3,8,162:12)
Block(3,4,7,LEAVES2:12)
Block(3,6,5,LEAVES2:12)
Block(3,6,9,162:12)
Block(3,7,5,LEAVES2:12)
Block(3,7,9,162:12)
Block(3,8,5,LEAVES2:12)
Block(3,8,9,162:12)
Block(3,8,15,LEAVES2:12)
Block(3,9,9,162:12)
Block(3,9,10,162:12)
Block(3,9,15,LEAVES2:12)
Block(3,10,10,162:12)
Block(3,10,14,LEAVES2:12)
Block(3,11,10,162:12)
Block(3,12,10,162:12)
Block(3,13,8,LEAVES2:12)
Block(3,13,9,LEAVES2:12)
Block(3,13,10,LEAVES2:12)
Block(3,14,8,LEAVES2:12)
Block(3,16,11,LEAVES2:12)
Block(3,17,11,LEAVES2:12)
Block(4,0,8,162:12)
Block(4,0,9,162:12)
Block(4,1,8,162:12)
Block(4,1,9,162:12)
Block(4,2,8,162:12)
Block(4,2,9,162:12)
Block(4,3,8,162:12)
Block(4,3,9,162:12)
Block(4,4,9,162:12)
Block(4,5,9,162:12)
Block(4,5,10,162:12)
Block(4,5,11,162:12)
Block(4,5,12,162:12)
Block(4,5,13,LEAVES2:12)
Block(4,5,15,LEAVES2:12)
Block(4,6,7,162:12)
Block(4,6,8,162:12)
Block(4,6,9,162:12)
Block(4,6,12,162:12)
Block(4,7,7,162:12)
Block(4,7,14,LEAVES2:12)
Block(4,9,9,162:12)
Block(4,9,12,LEAVES2:12)
Block(4,10,12,LEAVES2:12)
Block(4,11,8,LEAVES2:12)
Block(4,11,10,LEAVES2:12)
Block(4,12,9,LEAVES2:12)
Block(4,12,10,LEAVES2:12)
Block(4,13,9,LEAVES2:12)
Block(4,13,10,LEAVES2:12)
Block(4,14,11,LEAVES2:12)
Block(4,15,11,LEAVES2:12)
Block(4,17,9,LEAVES2:12)
Block(4,18,9,LEAVES2:12)
Block(4,19,9,LEAVES2:12)
Block(5,4,9,162:12)
Block(5,6,13,162:12)
Block(5,6,14,162:12)
Block(5,7,6,162:12)
Block(5,7,12,LEAVES2:12)
Block(5,7,13,LEAVES2:12)
Block(5,7,14,LEAVES2:12)
Block(5,8,5,162:12)
Block(5,8,12,LEAVES2:12)
Block(5,9,9,162:12)
Block(5,10,9,162:12)
Block(5,10,15,LEAVES2:12)
Block(5,11,15,LEAVES2:12)
Block(5,12,11,LEAVES2:12)
Block(5,13,11,LEAVES2:12)
Block(5,14,9,LEAVES2:12)
Block(5,14,10,LEAVES2:12)
Block(5,15,9,LEAVES2:12)
Block(5,16,9,LEAVES2:12)
Block(6,4,9,162:12)
Block(6,5,12,LEAVES2:12)
Block(6,5,14,LEAVES2:12)
Block(6,6,13,LEAVES2:12)
Block(6,6,14,LEAVES2:12)
Block(6,7,8,LEAVES2:12)
Block(6,7,13,LEAVES2:12)
Block(6,7,14,LEAVES2:12)
Block(6,8,8,LEAVES2:12)
Block(6,8,15,LEAVES2:12)
Block(6,9,7,LEAVES2:12)
Block(6,9,9,LEAVES2:12)
Block(6,9,11,LEAVES2:12)
Block(6,9,15,LEAVES2:12)
Block(6,10,9,162:12)
Block(6,11,10,LEAVES2:12)
Block(6,11,13,LEAVES2:12)
Block(6,12,13,LEAVES2:12)
Block(6,13,8,LEAVES2:12)
Block(6,13,13,LEAVES2:12)
Block(6,14,8,LEAVES2:12)
Block(7,4,6,LEAVES2:12)
Block(7,4,8,162:12)
Block(7,5,8,162:12)
Block(7,6,7,LEAVES2:12)
Block(7,6,15,LEAVES2:12)
Block(7,8,5,LEAVES2:12)
Block(7,8,13,LEAVES2:12)
Block(7,9,5,LEAVES2:12)
Block(7,9,13,LEAVES2:12)
Block(7,10,10,162:12)
Block(7,10,13,LEAVES2:12)
Block(7,11,8,LEAVES2:12)
Block(7,11,9,LEAVES2:12)
Block(7,11,10,LEAVES2:12)
Block(7,12,8,LEAVES2:12)
Block(7,14,11,LEAVES2:12)
Block(7,15,11,LEAVES2:12)
Block(8,5,7,162:12)
Block(8,6,5,LEAVES2:12)
Block(8,6,6,LEAVES2:12)
Block(8,6,7,LEAVES2:12)
Block(8,7,5,LEAVES2:12)
Block(8,9,8,LEAVES2:12)
Block(8,9,10,LEAVES2:12)
Block(8,10,8,LEAVES2:12)
Block(8,10,9,LEAVES2:12)
Block(8,10,10,LEAVES2:12)
Block(8,11,9,LEAVES2:12)
Block(8,11,10,LEAVES2:12)
Block(8,12,11,LEAVES2:12)
Block(8,13,11,LEAVES2:12)
Block(8,15,9,LEAVES2:12)
Block(8,16,9,LEAVES2:12)
Block(8,17,9,LEAVES2:12)
Block(9,4,5,LEAVES2:12)
Block(9,4,7,LEAVES2:12)
Block(9,5,6,LEAVES2:12)
Block(9,5,7,LEAVES2:12)
Block(9,6,6,LEAVES2:12)
Block(9,6,7,LEAVES2:12)
Block(9,7,8,LEAVES2:12)
Block(9,8,8,LEAVES2:12)
Block(9,10,6,LEAVES2:12)
Block(9,10,11,LEAVES2:12)
Block(9,11,6,LEAVES2:12)
Block(9,12,6,LEAVES2:12)
Block(9,12,9,LEAVES2:12)
Block(9,13,9,LEAVES2:12)
Block(9,14,9,LEAVES2:12)
Block(10,5,8,LEAVES2:12)
Block(10,7,6,LEAVES2:12)
Block(10,8,6,LEAVES2:12)
Block(10,9,6,LEAVES2:12)


#######################################################################
# +-----------------------------------------------------------------+ #
# |                             Entities                            | #
# +-----------------------------------------------------------------+ #
#######################################################################

# Entity() spawns an entity instead of a block. The entity is spawned only once when the BO3 is spawned.
# Entities are persistent by default so they don't de-spawn when no player is near, they are only unloaded.
# Usage: Entity(x,y,z,mobName,groupSize,NameTagOrNBTFileName) or Entity(x,y,z,mobName,groupSize)
# Use /tc entities or /otg entities to get a list of entities that can be used as mobName, this includes entities added by other mods.
# NameTagOrNBTFileName can be either a nametag for the mob or an nbt file (such as mymobinfo.nbt or mymobinfo.txt).
# When using a text file you can use the same mob spawning parameters used with the /summon command to equip the
# entity and give it custom attributes etc. You can copy the DATA part of a summon command including surrounding
# curly braces to a .txt file, for instance for: "/summon Skeleton x y z {DATA}"

#######################################################################
# +-----------------------------------------------------------------+ #
# |                            BO3 checks                           | #
# +-----------------------------------------------------------------+ #
#######################################################################

# Require a condition at a certain location in order for the BO3 to be spawned.
# BlockCheck(x,y,z,BlockName[,BlockName[,...]]) - one of the blocks must be at the location
# BlockCheckNot(x,y,z,BlockName[,BlockName[,...]]) - all the blocks must not be at the location
# LightCheck(x,y,z,minLightLevel,maxLightLevel) - light must be between min and max (inclusive)

# You can use "Solid" as a BlockName for matching all solid blocks or "All" to match all blocks that aren't air.

# Examples:
BlockCheck(0,-1,0,GRASS,DIRT,DIRT:2,SAND)
#   BlockCheck(0,-1,0,Solid)       Require any solid block just below the object
#   BlockCheck(0,-1,0,WOOL)        Require any type of wool just below the object
#   BlockCheck(0,-1,0,WOOL:0)      Require white wool just below the object
#   BlockCheckNot(0,-1,0,WOOL:0)   Require that there is no white wool below the object
#   LightCheck(0,0,0,0,1)          Require almost complete darkness just below the object

