#######################################################################
# +-----------------------------------------------------------------+ #
# |                            BO3 object                           | #
# +-----------------------------------------------------------------+ #
#######################################################################

# The descriptions in this file are accurate only for TerrainControl and OTG.
# For MCW and OTG+ these descriptions are only accurate if the BO3 is used as a CustomObject.
# MCW and OTG+ completely reimplemented CustomStructure, check the MCW/OTG+ documentation for more information.

# This is the config file of a custom object.
# If you add this object correctly to your BiomeConfigs, it will spawn in the world.

# This is the creator of this BO3 object
Author: Unknown

# A short description of this BO3 object
Description: This BO3 was converted from a schematic using OTGEdit. The author and description information of the schematic could not be found. If you know who the author of the schematic is then please add this information.

# The BO3 version, don't change this! It can be used by external applications to do a version check.
Version: 3

# The settings mode, WriteAll, WriteWithoutComments or WriteDisable. See WorldConfig.
SettingsMode: WriteDisable

#######################################################################
# +-----------------------------------------------------------------+ #
# |                          Main settings                          | #
# +-----------------------------------------------------------------+ #
#######################################################################

# This needs to be set to true to spawn the object in the Tree and Sapling resources.
Tree: tree

# The frequency of the BO3 from 1 to 200. Tries this many times to spawn this BO3 when using the CustomObject(...) resource.
# Ignored by Tree(..), Sapling(..) and CustomStructure(..)
Frequency: 40

# The rarity of the BO3 from 0 to 100. Each spawn attempt has rarity% chance to succeed when using the CustomObject(...) resource.
# Ignored by Tree(..), Sapling(..) and CustomStructure(..)
Rarity: 100.0

# If you set this to true, the BO3 will be placed with a random rotation.
RotateRandomly: false

# The spawn height of the BO3 - randomY, highestBlock or highestSolidBlock.
SpawnHeight: highestSolidBlock
SpawnHeightOffset: -1
# The height limits for the BO3.
MinHeight: 0

MaxHeight: 256

# Objects can have other objects attached to it: branches. Branches can also
# have branches attached to it, which can also have branches, etc. This is the
# maximum branch depth for this objects.
MaxBranchDepth: 10

# When spawned with the UseWorld keyword, this BO3 should NOT spawn in the following biomes.
# If you writer.write the BO3 name directly in the BiomeConfigs, this will be ignored.
ExcludedBiomes: All

# To optimise this BO3 for faster loading times you can use Notepad++ to find/replace comments and abbreviate things.
# Notepad++ find/replace with regex:
# Find: ^[#;].* replace to nothing removes all lines starting with # 
# Find: ^\s*$ replace to nothing removes most empty lines 
# Notepad++ find/replace without regex:
# *Warning: This will only work for OTG 1.10.2 v21 / OTG 1.11.2 v6 or higher. B( is not recognised by lower versions.
# Find: Block( replace to B(

#######################################################################
# +-----------------------------------------------------------------+ #
# |                      Source block settings                      | #
# +-----------------------------------------------------------------+ #
#######################################################################

# The block(s) the BO3 should spawn in.
SourceBlocks: AIR,GRASS,DIRT,STONE

# The maximum percentage of the BO3 that can be outside the SourceBlock.
# The BO3 won't be placed on a location with more blocks outside the SourceBlock than this percentage.
MaxPercentageOutsideSourceBlock: 0

# What to do when a block is about to be placed outside the SourceBlock? (dontPlace, placeAnyway)
OutsideSourceBlock: dontPlace

#######################################################################
# +-----------------------------------------------------------------+ #
# |                              Blocks                             | #
# +-----------------------------------------------------------------+ #
#######################################################################

# All the blocks used in the BO3 are listed here. Possible blocks:
# Block(x,y,z,id[.data][,nbtfile.nbt) or B(x,y,z,id[.data][,nbtfile.nbt)
# RandomBlock(x,y,z,id[:data][,nbtfile.nbt],chance[,id[:data][,nbtfile.nbt],chance[,...]])
# So RandomBlock(0,0,0,CHEST,chest.nbt,50,CHEST,anotherchest.nbt,100) will spawn a chest at
# the BO3 origin, and give it a 50% chance to have the contents of chest.nbt, or, if that
# fails, a 100% percent chance to have the contents of anotherchest.nbt.

Block(-13,20,9,LEAVES:12)
Block(-13,21,8,LEAVES:12)
Block(-12,17,7,LEAVES:12)
Block(-12,18,8,LEAVES:12)
Block(-12,20,8,LEAVES:12)
Block(-12,20,9,LEAVES:12)
Block(-12,20,10,LEAVES:12)
Block(-12,21,7,LEAVES:12)
Block(-12,21,8,LEAVES:12)
Block(-12,21,9,LEAVES:12)
Block(-12,22,5,LEAVES:12)
Block(-12,22,8,LEAVES:12)
Block(-11,17,6,LEAVES:12)
Block(-11,17,7,LEAVES:12)
Block(-11,17,8,LEAVES:12)
Block(-11,18,4,LEAVES:12)
Block(-11,18,7,LEAVES:12)
Block(-11,18,8,LEAVES:12)
Block(-11,18,9,LEAVES:12)
Block(-11,19,5,LEAVES:12)
Block(-11,19,8,LEAVES:12)
Block(-11,20,9,LEAVES:12)
Block(-11,21,5,LEAVES:12)
Block(-11,21,8,LEAVES:12)
Block(-11,21,9,LEAVES:12)
Block(-11,21,10,LEAVES:12)
Block(-11,22,4,LEAVES:12)
Block(-11,22,5,LEAVES:12)
Block(-11,22,6,LEAVES:12)
Block(-11,22,9,LEAVES:12)
Block(-11,23,5,LEAVES:12)
Block(-11,23,8,LEAVES:12)
Block(-11,24,9,LEAVES:12)
Block(-10,17,7,LEAVES:12)
Block(-10,18,3,LEAVES:12)
Block(-10,18,4,LEAVES:12)
Block(-10,18,5,LEAVES:12)
Block(-10,18,6,LEAVES:12)
Block(-10,18,7,LEAVES:12)
Block(-10,18,8,LEAVES:12)
Block(-10,19,4,LEAVES:12)
Block(-10,19,5,LEAVES:12)
Block(-10,19,6,LEAVES:12)
Block(-10,19,7,LEAVES:12)
Block(-10,19,8,LEAVES:12)
Block(-10,20,5,LEAVES:12)
Block(-10,20,7,LEAVES:12)
Block(-10,21,4,LEAVES:12)
Block(-10,21,5,LEAVES:12)
Block(-10,21,6,LEAVES:12)
Block(-10,21,9,LEAVES:12)
Block(-10,22,5,LEAVES:12)
Block(-10,22,6,LEAVES:12)
Block(-10,22,7,LEAVES:12)
Block(-10,22,9,LEAVES:12)
Block(-10,22,12,LEAVES:12)
Block(-10,23,6,LEAVES:12)
Block(-10,23,7,LEAVES:12)
Block(-10,23,8,LEAVES:12)
Block(-10,23,9,LEAVES:12)
Block(-10,23,11,LEAVES:12)
Block(-10,24,8,LEAVES:12)
Block(-10,24,9,LEAVES:12)
Block(-10,24,10,LEAVES:12)
Block(-10,25,9,LEAVES:12)
Block(-10,26,0,LEAVES:12)
Block(-10,27,1,LEAVES:12)
Block(-10,29,-1,LEAVES:12)
Block(-10,30,-2,LEAVES:12)
Block(-9,17,3,LEAVES:12)
Block(-9,18,2,LEAVES:12)
Block(-9,18,4,LEAVES:12)
Block(-9,18,7,LEAVES:12)
Block(-9,19,-1,LEAVES:12)
Block(-9,19,3,LEAVES:12)
Block(-9,19,4,LEAVES:12)
Block(-9,19,5,LEAVES:12)
Block(-9,19,11,LEAVES:12)
Block(-9,20,0,LEAVES:12)
Block(-9,20,4,LEAVES:12)
Block(-9,20,6,LEAVES:12)
Block(-9,20,7,17:12)
Block(-9,20,8,LEAVES:12)
Block(-9,20,10,LEAVES:12)
Block(-9,21,5,LEAVES:12)
Block(-9,21,7,LEAVES:12)
Block(-9,21,9,LEAVES:12)
Block(-9,22,6,LEAVES:12)
Block(-9,22,8,LEAVES:12)
Block(-9,22,9,LEAVES:12)
Block(-9,22,10,LEAVES:12)
Block(-9,22,11,LEAVES:12)
Block(-9,22,12,LEAVES:12)
Block(-9,22,13,LEAVES:12)
Block(-9,23,8,LEAVES:12)
Block(-9,23,9,LEAVES:12)
Block(-9,23,10,LEAVES:12)
Block(-9,23,11,LEAVES:12)
Block(-9,23,12,LEAVES:12)
Block(-9,24,7,LEAVES:12)
Block(-9,24,8,LEAVES:12)
Block(-9,24,9,LEAVES:12)
Block(-9,24,11,LEAVES:12)
Block(-9,25,8,LEAVES:12)
Block(-9,26,-1,LEAVES:12)
Block(-9,26,0,LEAVES:12)
Block(-9,26,1,LEAVES:12)
Block(-9,27,0,LEAVES:12)
Block(-9,27,1,LEAVES:12)
Block(-9,27,2,LEAVES:12)
Block(-9,28,1,LEAVES:12)
Block(-9,28,2,LEAVES:12)
Block(-9,29,-2,LEAVES:12)
Block(-9,29,-1,LEAVES:12)
Block(-9,29,0,LEAVES:12)
Block(-9,29,3,LEAVES:12)
Block(-9,30,-3,LEAVES:12)
Block(-9,30,-2,LEAVES:12)
Block(-9,30,-1,LEAVES:12)
Block(-9,31,-2,LEAVES:12)
Block(-8,16,0,LEAVES:12)
Block(-8,17,-1,LEAVES:12)
Block(-8,17,2,LEAVES:12)
Block(-8,17,3,LEAVES:12)
Block(-8,17,4,LEAVES:12)
Block(-8,18,0,LEAVES:12)
Block(-8,18,1,LEAVES:12)
Block(-8,18,2,LEAVES:12)
Block(-8,18,3,LEAVES:12)
Block(-8,19,-2,LEAVES:12)
Block(-8,19,-1,LEAVES:12)
Block(-8,19,0,LEAVES:12)
Block(-8,19,2,LEAVES:12)
Block(-8,19,4,LEAVES:12)
Block(-8,19,7,17:12)
Block(-8,19,10,LEAVES:12)
Block(-8,19,11,LEAVES:12)
Block(-8,19,12,LEAVES:12)
Block(-8,20,-1,LEAVES:12)
Block(-8,20,0,LEAVES:12)
Block(-8,20,1,LEAVES:12)
Block(-8,20,6,LEAVES:12)
Block(-8,20,7,LEAVES:12)
Block(-8,20,8,LEAVES:12)
Block(-8,20,9,LEAVES:12)
Block(-8,20,10,LEAVES:12)
Block(-8,20,11,LEAVES:12)
Block(-8,21,0,LEAVES:12)
Block(-8,21,6,LEAVES:12)
Block(-8,21,7,LEAVES:12)
Block(-8,21,8,LEAVES:12)
Block(-8,21,9,LEAVES:12)
Block(-8,21,10,17:12)
Block(-8,22,7,LEAVES:12)
Block(-8,22,8,LEAVES:12)
Block(-8,22,9,LEAVES:12)
Block(-8,22,10,LEAVES:12)
Block(-8,22,11,LEAVES:12)
Block(-8,22,12,LEAVES:12)
Block(-8,23,8,LEAVES:12)
Block(-8,23,10,LEAVES:12)
Block(-8,23,11,LEAVES:12)
Block(-8,24,7,LEAVES:12)
Block(-8,24,8,LEAVES:12)
Block(-8,25,-4,LEAVES:12)
Block(-8,26,-3,LEAVES:12)
Block(-8,26,0,LEAVES:12)
Block(-8,26,1,LEAVES:12)
Block(-8,26,2,LEAVES:12)
Block(-8,27,1,LEAVES:12)
Block(-8,28,-1,LEAVES:12)
Block(-8,28,1,LEAVES:12)
Block(-8,28,2,LEAVES:12)
Block(-8,28,3,LEAVES:12)
Block(-8,29,-2,LEAVES:12)
Block(-8,29,-1,LEAVES:12)
Block(-8,29,2,LEAVES:12)
Block(-8,29,3,LEAVES:12)
Block(-8,29,4,LEAVES:12)
Block(-8,30,-2,LEAVES:12)
Block(-8,30,-1,LEAVES:12)
Block(-8,30,0,LEAVES:12)
Block(-8,30,3,LEAVES:12)
Block(-8,31,-1,LEAVES:12)
Block(-8,31,4,LEAVES:12)
Block(-8,32,5,LEAVES:12)
Block(-8,34,-1,LEAVES:12)
Block(-8,34,7,LEAVES:12)
Block(-8,35,-2,LEAVES:12)
Block(-8,35,6,LEAVES:12)
Block(-8,37,-3,LEAVES:12)
Block(-8,38,-2,LEAVES:12)
Block(-7,0,3,17:12)
Block(-7,0,4,17:12)
Block(-7,16,-1,LEAVES:12)
Block(-7,16,0,LEAVES:12)
Block(-7,16,1,LEAVES:12)
Block(-7,17,-2,LEAVES:12)
Block(-7,17,-1,LEAVES:12)
Block(-7,17,0,LEAVES:12)
Block(-7,17,2,LEAVES:12)
Block(-7,17,3,LEAVES:12)
Block(-7,17,4,LEAVES:12)
Block(-7,18,-1,LEAVES:12)
Block(-7,18,0,LEAVES:12)
Block(-7,18,1,LEAVES:12)
Block(-7,18,2,LEAVES:12)
Block(-7,18,3,LEAVES:12)
Block(-7,18,4,LEAVES:12)
Block(-7,18,5,17:12)
Block(-7,18,6,17:12)
Block(-7,19,-2,LEAVES:12)
Block(-7,19,-1,LEAVES:12)
Block(-7,19,0,LEAVES:12)
Block(-7,19,2,17:12)
Block(-7,19,3,LEAVES:12)
Block(-7,19,4,LEAVES:12)
Block(-7,19,5,LEAVES:12)
Block(-7,19,6,17:12)
Block(-7,19,7,17:12)
Block(-7,19,8,17:12)
Block(-7,19,9,LEAVES:12)
Block(-7,19,10,LEAVES:12)
Block(-7,19,11,LEAVES:12)
Block(-7,20,-2,LEAVES:12)
Block(-7,20,-1,LEAVES:12)
Block(-7,20,0,LEAVES:12)
Block(-7,20,4,LEAVES:12)
Block(-7,20,8,LEAVES:12)
Block(-7,20,9,17:12)
Block(-7,20,10,LEAVES:12)
Block(-7,21,-1,LEAVES:12)
Block(-7,21,4,LEAVES:12)
Block(-7,21,7,LEAVES:12)
Block(-7,21,9,LEAVES:12)
Block(-7,22,4,LEAVES:12)
Block(-7,22,8,LEAVES:12)
Block(-7,22,9,LEAVES:12)
Block(-7,22,11,LEAVES:12)
Block(-7,23,7,LEAVES:12)
Block(-7,24,6,LEAVES:12)
Block(-7,24,7,LEAVES:12)
Block(-7,24,8,LEAVES:12)
Block(-7,25,-5,LEAVES:12)
Block(-7,25,-4,LEAVES:12)
Block(-7,25,-3,LEAVES:12)
Block(-7,25,7,LEAVES:12)
Block(-7,26,-4,LEAVES:12)
Block(-7,26,-3,LEAVES:12)
Block(-7,26,-2,LEAVES:12)
Block(-7,26,0,LEAVES:12)
Block(-7,26,1,LEAVES:12)
Block(-7,26,2,LEAVES:12)
Block(-7,27,-3,LEAVES:12)
Block(-7,27,0,LEAVES:12)
Block(-7,28,-2,LEAVES:12)
Block(-7,28,-1,LEAVES:12)
Block(-7,28,0,17:12)
Block(-7,28,1,17:12)
Block(-7,28,2,LEAVES:12)
Block(-7,29,-3,LEAVES:12)
Block(-7,29,-2,LEAVES:12)
Block(-7,29,-1,LEAVES:12)
Block(-7,29,0,LEAVES:12)
Block(-7,29,1,LEAVES:12)
Block(-7,29,2,LEAVES:12)
Block(-7,29,3,LEAVES:12)
Block(-7,30,-2,LEAVES:12)
Block(-7,30,-1,LEAVES:12)
Block(-7,30,1,LEAVES:12)
Block(-7,30,2,LEAVES:12)
Block(-7,31,3,LEAVES:12)
Block(-7,31,4,LEAVES:12)
Block(-7,31,5,LEAVES:12)
Block(-7,32,4,LEAVES:12)
Block(-7,32,5,LEAVES:12)
Block(-7,32,6,LEAVES:12)
Block(-7,32,9,LEAVES:12)
Block(-7,33,5,LEAVES:12)
Block(-7,33,8,LEAVES:12)
Block(-7,34,-2,LEAVES:12)
Block(-7,34,-1,LEAVES:12)
Block(-7,34,0,LEAVES:12)
Block(-7,34,6,LEAVES:12)
Block(-7,34,7,LEAVES:12)
Block(-7,34,8,LEAVES:12)
Block(-7,35,-3,LEAVES:12)
Block(-7,35,-2,LEAVES:12)
Block(-7,35,-1,LEAVES:12)
Block(-7,35,1,LEAVES:12)
Block(-7,35,5,LEAVES:12)
Block(-7,35,6,LEAVES:12)
Block(-7,35,7,LEAVES:12)
Block(-7,36,-2,LEAVES:12)
Block(-7,36,6,LEAVES:12)
Block(-7,37,-4,LEAVES:12)
Block(-7,37,-3,LEAVES:12)
Block(-7,37,-2,LEAVES:12)
Block(-7,37,2,LEAVES:12)
Block(-7,38,-3,LEAVES:12)
Block(-7,38,-2,LEAVES:12)
Block(-7,38,-1,LEAVES:12)
Block(-7,38,3,LEAVES:12)
Block(-7,38,6,LEAVES:12)
Block(-7,39,-2,LEAVES:12)
Block(-7,39,5,LEAVES:12)
Block(-7,40,3,LEAVES:12)
Block(-7,41,2,LEAVES:12)
Block(-6,0,2,17:12)
Block(-6,0,3,17:12)
Block(-6,1,2,17:12)
Block(-6,1,3,17:12)
Block(-6,16,-3,LEAVES:12)
Block(-6,16,-2,LEAVES:12)
Block(-6,16,-1,LEAVES:12)
Block(-6,16,0,LEAVES:12)
Block(-6,17,-2,LEAVES:12)
Block(-6,17,-1,LEAVES:12)
Block(-6,17,1,LEAVES:12)
Block(-6,17,3,LEAVES:12)
Block(-6,18,-2,LEAVES:12)
Block(-6,18,-1,LEAVES:12)
Block(-6,18,0,LEAVES:12)
Block(-6,18,1,LEAVES:12)
Block(-6,18,2,LEAVES:12)
Block(-6,18,3,LEAVES:12)
Block(-6,18,4,LEAVES:12)
Block(-6,18,6,17:12)
Block(-6,19,-1,LEAVES:12)
Block(-6,19,1,LEAVES:12)
Block(-6,19,2,17:12)
Block(-6,19,3,LEAVES:12)
Block(-6,19,4,LEAVES:12)
Block(-6,19,5,LEAVES:12)
Block(-6,19,6,LEAVES:12)
Block(-6,19,10,LEAVES:12)
Block(-6,20,-1,LEAVES:12)
Block(-6,20,2,LEAVES:12)
Block(-6,20,3,17:12)
Block(-6,20,4,LEAVES:12)
Block(-6,20,5,LEAVES:12)
Block(-6,21,3,LEAVES:12)
Block(-6,21,4,LEAVES:12)
Block(-6,21,5,LEAVES:12)
Block(-6,21,9,LEAVES:12)
Block(-6,21,11,LEAVES:12)
Block(-6,22,3,LEAVES:12)
Block(-6,22,4,LEAVES:12)
Block(-6,22,5,LEAVES:12)
Block(-6,22,12,LEAVES:12)
Block(-6,23,4,LEAVES:12)
Block(-6,23,6,LEAVES:12)
Block(-6,23,7,LEAVES:12)
Block(-6,23,8,LEAVES:12)
Block(-6,24,7,LEAVES:12)
Block(-6,24,8,LEAVES:12)
Block(-6,24,9,LEAVES:12)
Block(-6,24,14,LEAVES:12)
Block(-6,25,-4,LEAVES:12)
Block(-6,25,-3,LEAVES:12)
Block(-6,25,-2,LEAVES:12)
Block(-6,25,8,LEAVES:12)
Block(-6,25,13,LEAVES:12)
Block(-6,26,-3,LEAVES:12)
Block(-6,26,-1,LEAVES:12)
Block(-6,26,0,LEAVES:12)
Block(-6,26,1,LEAVES:12)
Block(-6,26,2,LEAVES:12)
Block(-6,26,3,LEAVES:12)
Block(-6,27,-2,LEAVES:12)
Block(-6,27,-1,LEAVES:12)
Block(-6,27,0,LEAVES:12)
Block(-6,27,1,17:12)
Block(-6,27,2,LEAVES:12)
Block(-6,28,-1,LEAVES:12)
Block(-6,28,0,LEAVES:12)
Block(-6,28,2,LEAVES:12)
Block(-6,29,-2,LEAVES:12)
Block(-6,29,-1,LEAVES:12)
Block(-6,29,0,LEAVES:12)
Block(-6,29,1,LEAVES:12)
Block(-6,29,2,LEAVES:12)
Block(-6,30,-1,LEAVES:12)
Block(-6,30,0,LEAVES:12)
Block(-6,30,1,LEAVES:12)
Block(-6,30,2,LEAVES:12)
Block(-6,31,1,LEAVES:12)
Block(-6,31,4,LEAVES:12)
Block(-6,31,5,LEAVES:12)
Block(-6,31,6,LEAVES:12)
Block(-6,32,5,LEAVES:12)
Block(-6,32,8,LEAVES:12)
Block(-6,32,9,LEAVES:12)
Block(-6,32,10,LEAVES:12)
Block(-6,33,6,LEAVES:12)
Block(-6,33,7,LEAVES:12)
Block(-6,33,8,LEAVES:12)
Block(-6,33,9,LEAVES:12)
Block(-6,34,-3,LEAVES:12)
Block(-6,34,-2,LEAVES:12)
Block(-6,34,-1,LEAVES:12)
Block(-6,34,7,LEAVES:12)
Block(-6,34,8,LEAVES:12)
Block(-6,35,-2,LEAVES:12)
Block(-6,35,0,LEAVES:12)
Block(-6,35,1,LEAVES:12)
Block(-6,35,2,LEAVES:12)
Block(-6,35,6,LEAVES:12)
Block(-6,35,7,LEAVES:12)
Block(-6,35,8,LEAVES:12)
Block(-6,35,9,LEAVES:12)
Block(-6,36,0,LEAVES:12)
Block(-6,36,1,LEAVES:12)
Block(-6,36,7,LEAVES:12)
Block(-6,36,8,LEAVES:12)
Block(-6,37,-3,LEAVES:12)
Block(-6,37,1,LEAVES:12)
Block(-6,37,2,LEAVES:12)
Block(-6,37,3,LEAVES:12)
Block(-6,38,-4,LEAVES:12)
Block(-6,38,-3,LEAVES:12)
Block(-6,38,-2,LEAVES:12)
Block(-6,38,2,LEAVES:12)
Block(-6,38,3,LEAVES:12)
Block(-6,38,4,LEAVES:12)
Block(-6,38,5,LEAVES:12)
Block(-6,38,6,LEAVES:12)
Block(-6,38,7,LEAVES:12)
Block(-6,39,-3,LEAVES:12)
Block(-6,39,3,LEAVES:12)
Block(-6,39,4,17:12)
Block(-6,39,5,LEAVES:12)
Block(-6,39,6,LEAVES:12)
Block(-6,39,7,LEAVES:12)
Block(-6,40,2,LEAVES:12)
Block(-6,40,3,LEAVES:12)
Block(-6,40,4,LEAVES:12)
Block(-6,40,5,LEAVES:12)
Block(-6,41,1,LEAVES:12)
Block(-6,41,2,LEAVES:12)
Block(-6,41,3,LEAVES:12)
Block(-6,42,2,LEAVES:12)
Block(-5,0,1,17:12)
Block(-5,0,2,17:12)
Block(-5,0,3,17:12)
Block(-5,1,2,17:12)
Block(-5,1,3,17:12)
Block(-5,2,2,17:12)
Block(-5,2,3,17:12)
Block(-5,11,-4,LEAVES:12)
Block(-5,12,-3,LEAVES:12)
Block(-5,14,-5,LEAVES:12)
Block(-5,14,-2,LEAVES:12)
Block(-5,15,-6,LEAVES:12)
Block(-5,16,-4,LEAVES:12)
Block(-5,16,-3,LEAVES:12)
Block(-5,16,-2,LEAVES:12)
Block(-5,16,-1,LEAVES:12)
Block(-5,16,4,LEAVES:12)
Block(-5,17,-3,LEAVES:12)
Block(-5,17,-2,LEAVES:12)
Block(-5,17,-1,LEAVES:12)
Block(-5,17,0,LEAVES:12)
Block(-5,17,1,LEAVES:12)
Block(-5,17,2,LEAVES:12)
Block(-5,17,3,LEAVES:12)
Block(-5,17,6,17:12)
Block(-5,17,7,17:12)
Block(-5,18,-2,LEAVES:12)
Block(-5,18,-1,LEAVES:12)
Block(-5,18,0,LEAVES:12)
Block(-5,18,1,LEAVES:12)
Block(-5,18,2,LEAVES:12)
Block(-5,18,3,LEAVES:12)
Block(-5,18,4,LEAVES:12)
Block(-5,18,6,17:12)
Block(-5,19,1,LEAVES:12)
Block(-5,19,2,17:12)
Block(-5,19,3,LEAVES:12)
Block(-5,19,4,LEAVES:12)
Block(-5,19,5,LEAVES:12)
Block(-5,19,9,LEAVES:12)
Block(-5,19,10,LEAVES:12)
Block(-5,19,11,LEAVES:12)
Block(-5,20,3,LEAVES:12)
Block(-5,20,4,LEAVES:12)
Block(-5,20,10,LEAVES:12)
Block(-5,21,3,LEAVES:12)
Block(-5,21,4,LEAVES:12)
Block(-5,21,5,LEAVES:12)
Block(-5,21,10,LEAVES:12)
Block(-5,21,11,LEAVES:12)
Block(-5,21,12,LEAVES:12)
Block(-5,22,2,LEAVES:12)
Block(-5,22,3,LEAVES:12)
Block(-5,22,4,LEAVES:12)
Block(-5,22,8,LEAVES:12)
Block(-5,22,11,LEAVES:12)
Block(-5,22,12,LEAVES:12)
Block(-5,22,13,LEAVES:12)
Block(-5,22,16,LEAVES:12)
Block(-5,23,-8,LEAVES:12)
Block(-5,23,3,LEAVES:12)
Block(-5,23,7,LEAVES:12)
Block(-5,23,12,LEAVES:12)
Block(-5,23,15,LEAVES:12)
Block(-5,24,-7,LEAVES:12)
Block(-5,24,8,LEAVES:12)
Block(-5,24,13,LEAVES:12)
Block(-5,24,14,LEAVES:12)
Block(-5,24,15,LEAVES:12)
Block(-5,25,-8,LEAVES:12)
Block(-5,25,-3,LEAVES:12)
Block(-5,25,-1,LEAVES:12)
Block(-5,25,6,LEAVES:12)
Block(-5,25,8,LEAVES:12)
Block(-5,25,12,LEAVES:12)
Block(-5,25,13,LEAVES:12)
Block(-5,25,14,LEAVES:12)
Block(-5,26,-2,LEAVES:12)
Block(-5,26,-1,LEAVES:12)
Block(-5,26,0,LEAVES:12)
Block(-5,26,1,LEAVES:12)
Block(-5,26,2,LEAVES:12)
Block(-5,26,3,LEAVES:12)
Block(-5,26,4,LEAVES:12)
Block(-5,26,5,LEAVES:12)
Block(-5,26,9,LEAVES:12)
Block(-5,26,13,LEAVES:12)
Block(-5,27,-1,17:12)
Block(-5,27,0,LEAVES:12)
Block(-5,27,1,17:12)
Block(-5,27,2,LEAVES:12)
Block(-5,27,3,LEAVES:12)
Block(-5,28,0,LEAVES:12)
Block(-5,28,2,LEAVES:12)
Block(-5,29,-2,LEAVES:12)
Block(-5,29,-1,LEAVES:12)
Block(-5,29,0,LEAVES:12)
Block(-5,29,1,LEAVES:12)
Block(-5,29,2,LEAVES:12)
Block(-5,30,-1,LEAVES:12)
Block(-5,30,0,LEAVES:12)
Block(-5,30,1,LEAVES:12)
Block(-5,31,0,LEAVES:12)
Block(-5,31,5,LEAVES:12)
Block(-5,31,7,LEAVES:12)
Block(-5,32,7,LEAVES:12)
Block(-5,32,8,LEAVES:12)
Block(-5,32,9,LEAVES:12)
Block(-5,33,1,17:12)
Block(-5,33,6,17:12)
Block(-5,33,7,17:12)
Block(-5,33,8,LEAVES:12)
Block(-5,34,-2,LEAVES:12)
Block(-5,34,8,LEAVES:12)
Block(-5,35,1,LEAVES:12)
Block(-5,35,2,LEAVES:12)
Block(-5,35,3,LEAVES:12)
Block(-5,35,6,LEAVES:12)
Block(-5,35,7,LEAVES:12)
Block(-5,35,8,LEAVES:12)
Block(-5,35,9,LEAVES:12)
Block(-5,35,10,LEAVES:12)
Block(-5,36,-3,LEAVES:12)
Block(-5,36,-1,LEAVES:12)
Block(-5,36,0,LEAVES:12)
Block(-5,36,1,LEAVES:12)
Block(-5,36,2,LEAVES:12)
Block(-5,36,4,LEAVES:12)
Block(-5,36,7,LEAVES:12)
Block(-5,36,8,LEAVES:12)
Block(-5,36,9,LEAVES:12)
Block(-5,37,-1,LEAVES:12)
Block(-5,37,1,LEAVES:12)
Block(-5,37,2,LEAVES:12)
Block(-5,37,5,LEAVES:12)
Block(-5,37,8,LEAVES:12)
Block(-5,38,-3,LEAVES:12)
Block(-5,38,1,LEAVES:12)
Block(-5,38,2,LEAVES:12)
Block(-5,38,3,LEAVES:12)
Block(-5,38,5,17:12)
Block(-5,38,6,LEAVES:12)
Block(-5,38,7,LEAVES:12)
Block(-5,39,2,LEAVES:12)
Block(-5,39,3,LEAVES:12)
Block(-5,39,4,17:12)
Block(-5,39,5,LEAVES:12)
Block(-5,39,6,LEAVES:12)
Block(-5,39,7,LEAVES:12)
Block(-5,39,8,LEAVES:12)
Block(-5,40,1,LEAVES:12)
Block(-5,40,2,LEAVES:12)
Block(-5,40,3,LEAVES:12)
Block(-5,40,4,LEAVES:12)
Block(-5,40,5,LEAVES:12)
Block(-5,40,6,LEAVES:12)
Block(-5,40,7,LEAVES:12)
Block(-5,41,2,LEAVES:12)
Block(-4,0,-4,17:12)
Block(-4,0,-3,17:12)
Block(-4,0,2,17:12)
Block(-4,1,2,17:12)
Block(-4,2,2,17:12)
Block(-4,2,3,17:12)
Block(-4,8,-4,LEAVES:12)
Block(-4,11,-5,LEAVES:12)
Block(-4,11,-4,LEAVES:12)
Block(-4,11,-3,LEAVES:12)
Block(-4,12,-4,LEAVES:12)
Block(-4,12,-3,LEAVES:12)
Block(-4,12,-2,LEAVES:12)
Block(-4,13,-3,LEAVES:12)
Block(-4,13,-2,LEAVES:12)
Block(-4,14,-6,LEAVES:12)
Block(-4,14,-5,LEAVES:12)
Block(-4,14,-4,LEAVES:12)
Block(-4,14,-3,LEAVES:12)
Block(-4,14,-2,LEAVES:12)
Block(-4,14,-1,LEAVES:12)
Block(-4,15,-7,LEAVES:12)
Block(-4,15,-6,LEAVES:12)
Block(-4,15,-5,LEAVES:12)
Block(-4,15,-2,LEAVES:12)
Block(-4,15,-1,LEAVES:12)
Block(-4,16,-6,LEAVES:12)
Block(-4,16,-3,LEAVES:12)
Block(-4,16,3,LEAVES:12)
Block(-4,16,4,LEAVES:12)
Block(-4,16,5,LEAVES:12)
Block(-4,17,-4,LEAVES:12)
Block(-4,17,-3,LEAVES:12)
Block(-4,17,-2,LEAVES:12)
Block(-4,17,-1,LEAVES:12)
Block(-4,17,0,LEAVES:12)
Block(-4,17,1,LEAVES:12)
Block(-4,17,2,LEAVES:12)
Block(-4,17,3,LEAVES:12)
Block(-4,17,4,LEAVES:12)
Block(-4,17,6,17:12)
Block(-4,18,-3,LEAVES:12)
Block(-4,18,0,LEAVES:12)
Block(-4,18,1,LEAVES:12)
Block(-4,18,2,17:12)
Block(-4,18,3,LEAVES:12)
Block(-4,18,4,LEAVES:12)
Block(-4,18,5,LEAVES:12)
Block(-4,19,-4,LEAVES:12)
Block(-4,19,1,LEAVES:12)
Block(-4,19,2,LEAVES:12)
Block(-4,19,3,LEAVES:12)
Block(-4,19,4,LEAVES:12)
Block(-4,19,10,LEAVES:12)
Block(-4,20,-6,LEAVES:12)
Block(-4,20,-3,LEAVES:12)
Block(-4,20,5,LEAVES:12)
Block(-4,21,-7,LEAVES:12)
Block(-4,21,1,LEAVES:12)
Block(-4,21,4,LEAVES:12)
Block(-4,21,11,LEAVES:12)
Block(-4,21,12,LEAVES:12)
Block(-4,21,13,LEAVES:12)
Block(-4,22,3,LEAVES:12)
Block(-4,22,7,LEAVES:12)
Block(-4,22,8,LEAVES:12)
Block(-4,22,9,LEAVES:12)
Block(-4,22,12,LEAVES:12)
Block(-4,22,15,LEAVES:12)
Block(-4,22,16,LEAVES:12)
Block(-4,22,17,LEAVES:12)
Block(-4,23,-9,LEAVES:12)
Block(-4,23,-8,LEAVES:12)
Block(-4,23,-7,LEAVES:12)
Block(-4,23,6,LEAVES:12)
Block(-4,23,7,LEAVES:12)
Block(-4,23,8,LEAVES:12)
Block(-4,23,12,LEAVES:12)
Block(-4,23,13,LEAVES:12)
Block(-4,23,14,LEAVES:12)
Block(-4,23,15,LEAVES:12)
Block(-4,23,16,LEAVES:12)
Block(-4,24,-8,LEAVES:12)
Block(-4,24,-7,LEAVES:12)
Block(-4,24,-6,LEAVES:12)
Block(-4,24,7,17:12)
Block(-4,24,11,LEAVES:12)
Block(-4,24,14,LEAVES:12)
Block(-4,24,15,LEAVES:12)
Block(-4,25,-9,LEAVES:12)
Block(-4,25,-8,LEAVES:12)
Block(-4,25,-7,LEAVES:12)
Block(-4,25,-4,LEAVES:12)
Block(-4,25,-2,LEAVES:12)
Block(-4,25,-1,LEAVES:12)
Block(-4,25,0,17:12)
Block(-4,25,1,17:12)
Block(-4,25,5,LEAVES:12)
Block(-4,25,6,LEAVES:12)
Block(-4,25,7,LEAVES:12)
Block(-4,25,8,LEAVES:12)
Block(-4,25,9,LEAVES:12)
Block(-4,25,13,LEAVES:12)
Block(-4,25,14,LEAVES:12)
Block(-4,25,15,LEAVES:12)
Block(-4,26,-8,LEAVES:12)
Block(-4,26,-1,LEAVES:12)
Block(-4,26,0,LEAVES:12)
Block(-4,26,1,17:12)
Block(-4,26,2,17:12)
Block(-4,26,3,LEAVES:12)
Block(-4,26,4,LEAVES:12)
Block(-4,26,5,LEAVES:12)
Block(-4,26,6,LEAVES:12)
Block(-4,26,8,LEAVES:12)
Block(-4,26,9,LEAVES:12)
Block(-4,26,10,LEAVES:12)
Block(-4,26,14,LEAVES:12)
Block(-4,27,1,17:12)
Block(-4,27,2,LEAVES:12)
Block(-4,27,5,LEAVES:12)
Block(-4,27,9,LEAVES:12)
Block(-4,27,14,LEAVES:12)
Block(-4,28,-2,LEAVES:12)
Block(-4,28,-1,LEAVES:12)
Block(-4,28,0,LEAVES:12)
Block(-4,29,-3,LEAVES:12)
Block(-4,29,-2,LEAVES:12)
Block(-4,29,-1,LEAVES:12)
Block(-4,29,0,LEAVES:12)
Block(-4,29,1,LEAVES:12)
Block(-4,30,-2,LEAVES:12)
Block(-4,30,0,LEAVES:12)
Block(-4,31,6,LEAVES:12)
Block(-4,31,7,LEAVES:12)
Block(-4,31,8,LEAVES:12)
Block(-4,32,7,17:12)
Block(-4,32,8,LEAVES:12)
Block(-4,33,-1,LEAVES:12)
Block(-4,33,0,17:12)
Block(-4,33,1,17:12)
Block(-4,33,7,17:12)
Block(-4,33,8,LEAVES:12)
Block(-4,34,0,LEAVES:12)
Block(-4,34,1,17:12)
Block(-4,34,6,LEAVES:12)
Block(-4,34,7,LEAVES:12)
Block(-4,34,8,LEAVES:12)
Block(-4,34,9,LEAVES:12)
Block(-4,34,12,LEAVES:12)
Block(-4,35,-3,LEAVES:12)
Block(-4,35,2,LEAVES:12)
Block(-4,35,5,LEAVES:12)
Block(-4,35,6,LEAVES:12)
Block(-4,35,7,LEAVES:12)
Block(-4,35,8,LEAVES:12)
Block(-4,35,9,LEAVES:12)
Block(-4,35,11,LEAVES:12)
Block(-4,36,-4,LEAVES:12)
Block(-4,36,-3,LEAVES:12)
Block(-4,36,-2,LEAVES:12)
Block(-4,36,0,LEAVES:12)
Block(-4,36,1,LEAVES:12)
Block(-4,36,2,LEAVES:12)
Block(-4,36,3,LEAVES:12)
Block(-4,36,4,LEAVES:12)
Block(-4,36,5,LEAVES:12)
Block(-4,36,6,LEAVES:12)
Block(-4,36,8,LEAVES:12)
Block(-4,37,-3,LEAVES:12)
Block(-4,37,-1,LEAVES:12)
Block(-4,37,0,17:12)
Block(-4,37,1,LEAVES:12)
Block(-4,37,4,LEAVES:12)
Block(-4,37,5,LEAVES:12)
Block(-4,37,6,LEAVES:12)
Block(-4,37,7,LEAVES:12)
Block(-4,38,-3,LEAVES:12)
Block(-4,38,-1,LEAVES:12)
Block(-4,38,2,LEAVES:12)
Block(-4,38,5,17:12)
Block(-4,38,6,LEAVES:12)
Block(-4,38,8,LEAVES:12)
Block(-4,39,2,LEAVES:12)
Block(-4,39,5,LEAVES:12)
Block(-4,39,6,LEAVES:12)
Block(-4,39,7,LEAVES:12)
Block(-4,39,9,LEAVES:12)
Block(-4,40,0,LEAVES:12)
Block(-4,40,2,LEAVES:12)
Block(-4,40,3,LEAVES:12)
Block(-4,40,4,LEAVES:12)
Block(-4,40,5,LEAVES:12)
Block(-4,40,6,LEAVES:12)
Block(-4,41,4,LEAVES:12)
Block(-4,41,5,LEAVES:12)
Block(-4,41,7,LEAVES:12)
Block(-4,42,6,LEAVES:12)
Block(-4,43,4,LEAVES:12)
Block(-4,44,3,LEAVES:12)
Block(-3,0,-3,17:12)
Block(-3,0,-2,17:12)
Block(-3,0,-1,17:12)
Block(-3,0,0,17:12)
Block(-3,0,2,17:12)
Block(-3,0,3,17:12)
Block(-3,0,4,17:12)
Block(-3,0,5,17:12)
Block(-3,1,0,17:12)
Block(-3,1,1,17:12)
Block(-3,1,2,17:12)
Block(-3,2,2,17:12)
Block(-3,3,2,17:12)
Block(-3,4,2,17:12)
Block(-3,8,-5,LEAVES:12)
Block(-3,8,-4,LEAVES:12)
Block(-3,8,-3,LEAVES:12)
Block(-3,9,-4,LEAVES:12)
Block(-3,11,-4,LEAVES:12)
Block(-3,11,-3,LEAVES:12)
Block(-3,11,-2,LEAVES:12)
Block(-3,12,-3,LEAVES:12)
Block(-3,12,-1,LEAVES:12)
Block(-3,13,-3,17:12)
Block(-3,13,-2,LEAVES:12)
Block(-3,13,-1,LEAVES:12)
Block(-3,14,-5,LEAVES:12)
Block(-3,14,-2,LEAVES:12)
Block(-3,14,-1,LEAVES:12)
Block(-3,14,0,LEAVES:12)
Block(-3,15,-6,LEAVES:12)
Block(-3,15,-5,LEAVES:12)
Block(-3,15,-4,LEAVES:12)
Block(-3,15,-1,LEAVES:12)
Block(-3,16,-5,LEAVES:12)
Block(-3,16,-1,LEAVES:12)
Block(-3,16,0,17:12)
Block(-3,16,1,17:12)
Block(-3,16,4,LEAVES:12)
Block(-3,17,-3,LEAVES:12)
Block(-3,17,0,LEAVES:12)
Block(-3,17,1,LEAVES:12)
Block(-3,17,2,17:12)
Block(-3,17,3,LEAVES:12)
Block(-3,17,4,LEAVES:12)
Block(-3,17,5,17:12)
Block(-3,17,6,17:12)
Block(-3,18,-1,LEAVES:12)
Block(-3,18,1,LEAVES:12)
Block(-3,18,2,17:12)
Block(-3,18,3,17:12)
Block(-3,18,4,LEAVES:12)
Block(-3,19,-5,LEAVES:12)
Block(-3,19,-4,LEAVES:12)
Block(-3,19,-3,LEAVES:12)
Block(-3,19,5,LEAVES:12)
Block(-3,20,-7,LEAVES:12)
Block(-3,20,-6,LEAVES:12)
Block(-3,20,-5,LEAVES:12)
Block(-3,20,-4,LEAVES:12)
Block(-3,20,-3,LEAVES:12)
Block(-3,20,-2,LEAVES:12)
Block(-3,20,1,LEAVES:12)
Block(-3,20,4,LEAVES:12)
Block(-3,20,5,LEAVES:12)
Block(-3,20,6,LEAVES:12)
Block(-3,21,-8,LEAVES:12)
Block(-3,21,-7,LEAVES:12)
Block(-3,21,-6,LEAVES:12)
Block(-3,21,-3,LEAVES:12)
Block(-3,21,0,LEAVES:12)
Block(-3,21,1,LEAVES:12)
Block(-3,21,2,LEAVES:12)
Block(-3,21,5,LEAVES:12)
Block(-3,21,12,LEAVES:12)
Block(-3,21,14,LEAVES:12)
Block(-3,22,-7,LEAVES:12)
Block(-3,22,-4,LEAVES:12)
Block(-3,22,1,LEAVES:12)
Block(-3,22,6,LEAVES:12)
Block(-3,22,7,LEAVES:12)
Block(-3,22,8,LEAVES:12)
Block(-3,22,14,LEAVES:12)
Block(-3,22,15,LEAVES:12)
Block(-3,22,16,LEAVES:12)
Block(-3,23,-8,LEAVES:12)
Block(-3,23,6,LEAVES:12)
Block(-3,23,7,LEAVES:12)
Block(-3,23,11,LEAVES:12)
Block(-3,23,12,LEAVES:12)
Block(-3,23,13,LEAVES:12)
Block(-3,23,14,17:12)
Block(-3,23,15,LEAVES:12)
Block(-3,24,-9,LEAVES:12)
Block(-3,24,-8,LEAVES:12)
Block(-3,24,-7,LEAVES:12)
Block(-3,24,-4,LEAVES:12)
Block(-3,24,8,17:12)
Block(-3,24,10,LEAVES:12)
Block(-3,24,11,LEAVES:12)
Block(-3,24,12,LEAVES:12)
Block(-3,24,15,LEAVES:12)
Block(-3,25,-8,LEAVES:12)
Block(-3,25,-5,LEAVES:12)
Block(-3,25,-4,LEAVES:12)
Block(-3,25,-3,LEAVES:12)
Block(-3,25,-2,LEAVES:12)
Block(-3,25,-1,LEAVES:12)
Block(-3,25,0,17:12)
Block(-3,25,3,17:12)
Block(-3,25,6,LEAVES:12)
Block(-3,25,7,LEAVES:12)
Block(-3,25,8,LEAVES:12)
Block(-3,25,10,LEAVES:12)
Block(-3,25,11,LEAVES:12)
Block(-3,25,13,LEAVES:12)
Block(-3,25,14,LEAVES:12)
Block(-3,25,15,LEAVES:12)
Block(-3,26,-4,LEAVES:12)
Block(-3,26,-3,LEAVES:12)
Block(-3,26,-2,LEAVES:12)
Block(-3,26,-1,LEAVES:12)
Block(-3,26,0,LEAVES:12)
Block(-3,26,2,17:12)
Block(-3,26,3,17:12)
Block(-3,26,5,LEAVES:12)
Block(-3,26,6,LEAVES:12)
Block(-3,26,7,LEAVES:12)
Block(-3,26,8,LEAVES:12)
Block(-3,26,9,LEAVES:12)
Block(-3,26,13,17:12)
Block(-3,27,-4,LEAVES:12)
Block(-3,27,-1,LEAVES:12)
Block(-3,27,6,LEAVES:12)
Block(-3,27,8,LEAVES:12)
Block(-3,27,13,LEAVES:12)
Block(-3,27,14,LEAVES:12)
Block(-3,27,15,LEAVES:12)
Block(-3,28,-3,LEAVES:12)
Block(-3,28,-2,LEAVES:12)
Block(-3,28,-1,LEAVES:12)
Block(-3,28,0,LEAVES:12)
Block(-3,28,1,LEAVES:12)
Block(-3,28,14,LEAVES:12)
Block(-3,29,-4,LEAVES:12)
Block(-3,29,-3,LEAVES:12)
Block(-3,29,-2,LEAVES:12)
Block(-3,29,0,LEAVES:12)
Block(-3,29,1,LEAVES:12)
Block(-3,29,2,LEAVES:12)
Block(-3,30,-3,LEAVES:12)
Block(-3,30,1,LEAVES:12)
Block(-3,31,5,LEAVES:12)
Block(-3,31,6,LEAVES:12)
Block(-3,31,7,LEAVES:12)
Block(-3,31,9,LEAVES:12)
Block(-3,32,6,17:12)
Block(-3,32,7,17:12)
Block(-3,33,-2,LEAVES:12)
Block(-3,33,-1,LEAVES:12)
Block(-3,33,0,LEAVES:12)
Block(-3,33,7,LEAVES:12)
Block(-3,33,8,LEAVES:12)
Block(-3,33,9,LEAVES:12)
Block(-3,34,-4,LEAVES:12)
Block(-3,34,-1,LEAVES:12)
Block(-3,34,0,LEAVES:12)
Block(-3,34,1,17:12)
Block(-3,34,5,LEAVES:12)
Block(-3,34,6,LEAVES:12)
Block(-3,34,7,LEAVES:12)
Block(-3,34,8,LEAVES:12)
Block(-3,34,9,LEAVES:12)
Block(-3,34,10,LEAVES:12)
Block(-3,34,11,LEAVES:12)
Block(-3,34,12,LEAVES:12)
Block(-3,34,13,LEAVES:12)
Block(-3,35,-4,LEAVES:12)
Block(-3,35,-3,LEAVES:12)
Block(-3,35,-2,LEAVES:12)
Block(-3,35,0,LEAVES:12)
Block(-3,35,4,LEAVES:12)
Block(-3,35,5,LEAVES:12)
Block(-3,35,6,LEAVES:12)
Block(-3,35,8,LEAVES:12)
Block(-3,35,9,LEAVES:12)
Block(-3,35,10,LEAVES:12)
Block(-3,35,11,LEAVES:12)
Block(-3,35,12,LEAVES:12)
Block(-3,36,-3,LEAVES:12)
Block(-3,36,-2,LEAVES:12)
Block(-3,36,-1,LEAVES:12)
Block(-3,36,0,LEAVES:12)
Block(-3,36,1,LEAVES:12)
Block(-3,36,4,LEAVES:12)
Block(-3,36,5,LEAVES:12)
Block(-3,36,6,LEAVES:12)
Block(-3,36,7,17:12)
Block(-3,36,8,17:12)
Block(-3,36,9,LEAVES:12)
Block(-3,36,11,LEAVES:12)
Block(-3,37,-3,LEAVES:12)
Block(-3,37,-2,LEAVES:12)
Block(-3,37,0,LEAVES:12)
Block(-3,37,1,LEAVES:12)
Block(-3,37,2,LEAVES:12)
Block(-3,37,5,LEAVES:12)
Block(-3,37,6,LEAVES:12)
Block(-3,37,7,17:12)
Block(-3,38,-4,LEAVES:12)
Block(-3,38,-3,LEAVES:12)
Block(-3,38,-2,LEAVES:12)
Block(-3,38,1,LEAVES:12)
Block(-3,38,2,LEAVES:12)
Block(-3,38,5,17:12)
Block(-3,38,7,LEAVES:12)
Block(-3,38,8,LEAVES:12)
Block(-3,38,9,LEAVES:12)
Block(-3,39,-3,LEAVES:12)
Block(-3,39,0,LEAVES:12)
Block(-3,39,1,LEAVES:12)
Block(-3,39,2,LEAVES:12)
Block(-3,39,3,LEAVES:12)
Block(-3,39,5,LEAVES:12)
Block(-3,39,6,LEAVES:12)
Block(-3,39,7,LEAVES:12)
Block(-3,39,8,LEAVES:12)
Block(-3,39,9,LEAVES:12)
Block(-3,39,10,LEAVES:12)
Block(-3,40,-1,LEAVES:12)
Block(-3,40,0,LEAVES:12)
Block(-3,40,1,LEAVES:12)
Block(-3,40,2,LEAVES:12)
Block(-3,40,3,LEAVES:12)
Block(-3,40,4,LEAVES:12)
Block(-3,40,5,LEAVES:12)
Block(-3,40,9,LEAVES:12)
Block(-3,41,0,LEAVES:12)
Block(-3,41,3,LEAVES:12)
Block(-3,41,4,LEAVES:12)
Block(-3,41,5,LEAVES:12)
Block(-3,41,6,LEAVES:12)
Block(-3,41,7,LEAVES:12)
Block(-3,41,8,LEAVES:12)
Block(-3,42,4,LEAVES:12)
Block(-3,42,5,LEAVES:12)
Block(-3,42,6,LEAVES:12)
Block(-3,42,7,LEAVES:12)
Block(-3,43,3,LEAVES:12)
Block(-3,43,4,LEAVES:12)
Block(-3,43,5,LEAVES:12)
Block(-3,43,6,LEAVES:12)
Block(-3,44,2,LEAVES:12)
Block(-3,44,3,LEAVES:12)
Block(-3,44,4,LEAVES:12)
Block(-3,45,3,LEAVES:12)
Block(-2,0,-2,17:12)
Block(-2,0,-1,17:12)
Block(-2,0,0,17:12)
Block(-2,0,1,17:12)
Block(-2,0,2,17:12)
Block(-2,0,3,17:12)
Block(-2,0,4,17:12)
Block(-2,1,-2,17:12)
Block(-2,1,-1,17:12)
Block(-2,1,0,17:12)
Block(-2,1,1,17:12)
Block(-2,1,2,17:12)
Block(-2,1,3,17:12)
Block(-2,2,0,17:12)
Block(-2,2,1,17:12)
Block(-2,2,2,17:12)
Block(-2,2,3,17:12)
Block(-2,3,0,17:12)
Block(-2,3,1,17:12)
Block(-2,3,2,17:12)
Block(-2,3,3,17:12)
Block(-2,4,0,17:12)
Block(-2,4,1,17:12)
Block(-2,4,2,17:12)
Block(-2,5,2,17:12)
Block(-2,8,-4,LEAVES:12)
Block(-2,10,-3,LEAVES:12)
Block(-2,11,-4,LEAVES:12)
Block(-2,11,-3,LEAVES:12)
Block(-2,12,-2,LEAVES:12)
Block(-2,12,-1,LEAVES:12)
Block(-2,12,0,LEAVES:12)
Block(-2,13,-3,17:12)
Block(-2,13,-2,LEAVES:12)
Block(-2,13,-1,LEAVES:12)
Block(-2,14,-4,LEAVES:12)
Block(-2,14,-3,LEAVES:12)
Block(-2,14,-2,LEAVES:12)
Block(-2,14,-1,LEAVES:12)
Block(-2,14,0,17:12)
Block(-2,15,-5,LEAVES:12)
Block(-2,15,-3,LEAVES:12)
Block(-2,15,-2,LEAVES:12)
Block(-2,15,-1,LEAVES:12)
Block(-2,15,3,LEAVES:12)
Block(-2,16,0,LEAVES:12)
Block(-2,16,1,LEAVES:12)
Block(-2,17,-1,LEAVES:12)
Block(-2,17,1,LEAVES:12)
Block(-2,17,4,LEAVES:12)
Block(-2,17,5,17:12)
Block(-2,18,-2,LEAVES:12)
Block(-2,18,-1,LEAVES:12)
Block(-2,18,0,LEAVES:12)
Block(-2,18,4,17:12)
Block(-2,19,-4,LEAVES:12)
Block(-2,19,-3,LEAVES:12)
Block(-2,19,-2,LEAVES:12)
Block(-2,19,-1,LEAVES:12)
Block(-2,19,4,LEAVES:12)
Block(-2,19,5,LEAVES:12)
Block(-2,19,6,LEAVES:12)
Block(-2,20,-6,LEAVES:12)
Block(-2,20,-3,LEAVES:12)
Block(-2,20,0,LEAVES:12)
Block(-2,20,1,LEAVES:12)
Block(-2,20,2,LEAVES:12)
Block(-2,20,3,LEAVES:12)
Block(-2,20,4,LEAVES:12)
Block(-2,20,5,LEAVES:12)
Block(-2,20,10,LEAVES:12)
Block(-2,21,-8,LEAVES:12)
Block(-2,21,-7,LEAVES:12)
Block(-2,21,-6,LEAVES:12)
Block(-2,21,-5,LEAVES:12)
Block(-2,21,-4,LEAVES:12)
Block(-2,21,-3,LEAVES:12)
Block(-2,21,-2,LEAVES:12)
Block(-2,21,1,LEAVES:12)
Block(-2,21,2,LEAVES:12)
Block(-2,21,3,LEAVES:12)
Block(-2,21,4,LEAVES:12)
Block(-2,21,9,LEAVES:12)
Block(-2,21,13,LEAVES:12)
Block(-2,21,14,LEAVES:12)
Block(-2,21,15,LEAVES:12)
Block(-2,22,-7,LEAVES:12)
Block(-2,22,-6,LEAVES:12)
Block(-2,22,-5,LEAVES:12)
Block(-2,22,-4,LEAVES:12)
Block(-2,22,-3,LEAVES:12)
Block(-2,22,2,LEAVES:12)
Block(-2,22,7,LEAVES:12)
Block(-2,22,9,LEAVES:12)
Block(-2,22,14,LEAVES:12)
Block(-2,22,15,LEAVES:12)
Block(-2,23,-6,LEAVES:12)
Block(-2,23,-4,LEAVES:12)
Block(-2,23,3,17:12)
Block(-2,23,5,LEAVES:12)
Block(-2,23,6,LEAVES:12)
Block(-2,23,7,17:12)
Block(-2,23,10,LEAVES:12)
Block(-2,23,11,LEAVES:12)
Block(-2,23,12,LEAVES:12)
Block(-2,23,13,17:12)
Block(-2,23,14,17:12)
Block(-2,24,-8,LEAVES:12)
Block(-2,24,-5,LEAVES:12)
Block(-2,24,-4,LEAVES:12)
Block(-2,24,-3,LEAVES:12)
Block(-2,24,3,17:12)
Block(-2,24,4,17:12)
Block(-2,24,6,LEAVES:12)
Block(-2,24,8,LEAVES:12)
Block(-2,24,11,LEAVES:12)
Block(-2,24,13,LEAVES:12)
Block(-2,24,14,LEAVES:12)
Block(-2,24,15,LEAVES:12)
Block(-2,25,-8,LEAVES:12)
Block(-2,25,-6,LEAVES:12)
Block(-2,25,-5,LEAVES:12)
Block(-2,25,-4,LEAVES:12)
Block(-2,25,-2,LEAVES:12)
Block(-2,25,3,17:12)
Block(-2,25,4,17:12)
Block(-2,25,6,LEAVES:12)
Block(-2,25,9,LEAVES:12)
Block(-2,25,10,LEAVES:12)
Block(-2,25,11,LEAVES:12)
Block(-2,25,12,17:12)
Block(-2,25,13,LEAVES:12)
Block(-2,25,14,LEAVES:12)
Block(-2,25,15,LEAVES:12)
Block(-2,25,16,LEAVES:12)
Block(-2,26,-5,LEAVES:12)
Block(-2,26,-4,LEAVES:12)
Block(-2,26,-3,LEAVES:12)
Block(-2,26,-2,LEAVES:12)
Block(-2,26,-1,LEAVES:12)
Block(-2,26,2,17:12)
Block(-2,26,3,17:12)
Block(-2,26,6,LEAVES:12)
Block(-2,26,7,LEAVES:12)
Block(-2,26,8,LEAVES:12)
Block(-2,26,9,LEAVES:12)
Block(-2,26,10,LEAVES:12)
Block(-2,26,13,LEAVES:12)
Block(-2,26,15,LEAVES:12)
Block(-2,27,-5,LEAVES:12)
Block(-2,27,-4,LEAVES:12)
Block(-2,27,-3,LEAVES:12)
Block(-2,27,9,LEAVES:12)
Block(-2,27,12,LEAVES:12)
Block(-2,27,13,LEAVES:12)
Block(-2,27,14,LEAVES:12)
Block(-2,28,-4,LEAVES:12)
Block(-2,28,-2,LEAVES:12)
Block(-2,28,0,LEAVES:12)
Block(-2,28,13,LEAVES:12)
Block(-2,29,-3,LEAVES:12)
Block(-2,29,1,LEAVES:12)
Block(-2,30,9,LEAVES:12)
Block(-2,31,6,LEAVES:12)
Block(-2,31,8,LEAVES:12)
Block(-2,31,9,LEAVES:12)
Block(-2,31,10,LEAVES:12)
Block(-2,32,5,17:12)
Block(-2,32,6,17:12)
Block(-2,32,9,LEAVES:12)
Block(-2,32,10,LEAVES:12)
Block(-2,33,-1,LEAVES:12)
Block(-2,33,8,LEAVES:12)
Block(-2,34,-5,LEAVES:12)
Block(-2,34,-4,LEAVES:12)
Block(-2,34,-3,LEAVES:12)
Block(-2,34,-2,LEAVES:12)
Block(-2,34,-1,LEAVES:12)
Block(-2,34,0,LEAVES:12)
Block(-2,34,1,17:12)
Block(-2,34,6,LEAVES:12)
Block(-2,34,7,LEAVES:12)
Block(-2,34,8,LEAVES:12)
Block(-2,34,9,LEAVES:12)
Block(-2,34,12,LEAVES:12)
Block(-2,35,-4,LEAVES:12)
Block(-2,35,-3,LEAVES:12)
Block(-2,35,-2,LEAVES:12)
Block(-2,35,-1,LEAVES:12)
Block(-2,35,0,LEAVES:12)
Block(-2,35,1,17:12)
Block(-2,35,2,17:12)
Block(-2,35,3,17:12)
Block(-2,35,5,LEAVES:12)
Block(-2,35,6,LEAVES:12)
Block(-2,35,7,LEAVES:12)
Block(-2,35,8,LEAVES:12)
Block(-2,35,9,LEAVES:12)
Block(-2,35,11,LEAVES:12)
Block(-2,35,12,LEAVES:12)
Block(-2,35,13,LEAVES:12)
Block(-2,36,-3,LEAVES:12)
Block(-2,36,-2,LEAVES:12)
Block(-2,36,-1,LEAVES:12)
Block(-2,36,0,LEAVES:12)
Block(-2,36,1,17:12)
Block(-2,36,5,LEAVES:12)
Block(-2,36,6,LEAVES:12)
Block(-2,36,8,LEAVES:12)
Block(-2,36,12,LEAVES:12)
Block(-2,37,-4,LEAVES:12)
Block(-2,37,-3,LEAVES:12)
Block(-2,37,-2,LEAVES:12)
Block(-2,37,-1,LEAVES:12)
Block(-2,37,0,LEAVES:12)
Block(-2,37,1,LEAVES:12)
Block(-2,37,4,LEAVES:12)
Block(-2,37,5,LEAVES:12)
Block(-2,37,6,LEAVES:12)
Block(-2,37,7,LEAVES:12)
Block(-2,37,10,LEAVES:12)
Block(-2,38,-3,LEAVES:12)
Block(-2,38,-2,LEAVES:12)
Block(-2,38,-1,LEAVES:12)
Block(-2,38,0,LEAVES:12)
Block(-2,38,1,LEAVES:12)
Block(-2,38,2,LEAVES:12)
Block(-2,38,3,LEAVES:12)
Block(-2,38,5,17:12)
Block(-2,38,6,LEAVES:12)
Block(-2,38,7,LEAVES:12)
Block(-2,38,8,LEAVES:12)
Block(-2,38,9,LEAVES:12)
Block(-2,38,10,LEAVES:12)
Block(-2,39,-2,LEAVES:12)
Block(-2,39,-1,LEAVES:12)
Block(-2,39,0,LEAVES:12)
Block(-2,39,1,LEAVES:12)
Block(-2,39,2,LEAVES:12)
Block(-2,39,3,LEAVES:12)
Block(-2,39,4,LEAVES:12)
Block(-2,39,5,LEAVES:12)
Block(-2,39,6,LEAVES:12)
Block(-2,39,7,LEAVES:12)
Block(-2,39,8,LEAVES:12)
Block(-2,39,9,LEAVES:12)
Block(-2,40,-2,LEAVES:12)
Block(-2,40,-1,LEAVES:12)
Block(-2,40,0,LEAVES:12)
Block(-2,40,3,LEAVES:12)
Block(-2,40,4,LEAVES:12)
Block(-2,40,5,LEAVES:12)
Block(-2,40,7,LEAVES:12)
Block(-2,41,-1,LEAVES:12)
Block(-2,41,2,LEAVES:12)
Block(-2,41,3,LEAVES:12)
Block(-2,41,4,LEAVES:12)
Block(-2,41,5,LEAVES:12)
Block(-2,41,7,LEAVES:12)
Block(-2,42,3,LEAVES:12)
Block(-2,42,4,17:12)
Block(-2,42,5,17:12)
Block(-2,42,6,LEAVES:12)
Block(-2,42,7,LEAVES:12)
Block(-2,42,8,LEAVES:12)
Block(-2,43,2,LEAVES:12)
Block(-2,43,3,LEAVES:12)
Block(-2,43,4,LEAVES:12)
Block(-2,43,6,LEAVES:12)
Block(-2,43,7,LEAVES:12)
Block(-2,44,3,LEAVES:12)
Block(-1,0,1,17:12)
Block(-1,0,2,17:12)
Block(-1,0,3,17:12)
Block(-1,1,-1,17:12)
Block(-1,1,0,17:12)
Block(-1,1,1,17:12)
Block(-1,1,2,17:12)
Block(-1,1,3,17:12)
Block(-1,2,0,17:12)
Block(-1,2,1,17:12)
Block(-1,2,2,17:12)
Block(-1,2,3,17:12)
Block(-1,3,-1,17:12)
Block(-1,3,0,17:12)
Block(-1,3,1,17:12)
Block(-1,3,2,17:12)
Block(-1,3,3,17:12)
Block(-1,4,-1,17:12)
Block(-1,4,0,17:12)
Block(-1,4,1,17:12)
Block(-1,4,2,17:12)
Block(-1,4,3,17:12)
Block(-1,5,0,17:12)
Block(-1,5,1,17:12)
Block(-1,5,2,17:12)
Block(-1,6,2,17:12)
Block(-1,8,-5,LEAVES:12)
Block(-1,8,-4,LEAVES:12)
Block(-1,8,-3,LEAVES:12)
Block(-1,9,-4,LEAVES:12)
Block(-1,9,-2,LEAVES:12)
Block(-1,10,-4,17:12)
Block(-1,10,-3,17:12)
Block(-1,10,-2,17:12)
Block(-1,10,-1,LEAVES:12)
Block(-1,11,-5,LEAVES:12)
Block(-1,11,-4,LEAVES:12)
Block(-1,11,-3,LEAVES:12)
Block(-1,11,-2,17:12)
Block(-1,12,-6,LEAVES:12)
Block(-1,12,-4,LEAVES:12)
Block(-1,12,-3,LEAVES:12)
Block(-1,12,-2,17:12)
Block(-1,12,-1,LEAVES:12)
Block(-1,13,-7,LEAVES:12)
Block(-1,13,-2,LEAVES:12)
Block(-1,13,-1,LEAVES:12)
Block(-1,13,0,17:12)
Block(-1,14,-3,LEAVES:12)
Block(-1,14,-2,LEAVES:12)
Block(-1,14,-1,LEAVES:12)
Block(-1,15,-8,LEAVES:12)
Block(-1,15,-6,LEAVES:12)
Block(-1,15,-4,LEAVES:12)
Block(-1,15,-3,LEAVES:12)
Block(-1,15,-2,LEAVES:12)
Block(-1,15,-1,LEAVES:12)
Block(-1,15,0,LEAVES:12)
Block(-1,15,2,LEAVES:12)
Block(-1,15,3,LEAVES:12)
Block(-1,15,4,LEAVES:12)
Block(-1,16,-9,LEAVES:12)
Block(-1,16,-5,LEAVES:12)
Block(-1,16,-3,LEAVES:12)
Block(-1,16,-1,LEAVES:12)
Block(-1,16,3,LEAVES:12)
Block(-1,17,-2,LEAVES:12)
Block(-1,17,-1,LEAVES:12)
Block(-1,17,0,LEAVES:12)
Block(-1,17,4,17:12)
Block(-1,17,5,17:12)
Block(-1,18,-3,LEAVES:12)
Block(-1,18,-2,LEAVES:12)
Block(-1,18,-1,LEAVES:12)
Block(-1,18,3,17:12)
Block(-1,18,4,17:12)
Block(-1,19,-3,LEAVES:12)
Block(-1,19,-2,LEAVES:12)
Block(-1,19,5,LEAVES:12)
Block(-1,20,-5,LEAVES:12)
Block(-1,20,1,LEAVES:12)
Block(-1,20,2,17:12)
Block(-1,20,4,LEAVES:12)
Block(-1,20,9,LEAVES:12)
Block(-1,20,10,LEAVES:12)
Block(-1,20,11,LEAVES:12)
Block(-1,21,-9,LEAVES:12)
Block(-1,21,-8,LEAVES:12)
Block(-1,21,-7,LEAVES:12)
Block(-1,21,-6,LEAVES:12)
Block(-1,21,-3,LEAVES:12)
Block(-1,21,2,LEAVES:12)
Block(-1,21,3,17:12)
Block(-1,21,8,LEAVES:12)
Block(-1,21,9,LEAVES:12)
Block(-1,21,10,LEAVES:12)
Block(-1,21,12,LEAVES:12)
Block(-1,21,13,LEAVES:12)
Block(-1,21,14,LEAVES:12)
Block(-1,22,-8,LEAVES:12)
Block(-1,22,-7,LEAVES:12)
Block(-1,22,-6,LEAVES:12)
Block(-1,22,-4,LEAVES:12)
Block(-1,22,-3,LEAVES:12)
Block(-1,22,-2,LEAVES:12)
Block(-1,22,1,17:12)
Block(-1,22,2,17:12)
Block(-1,22,3,17:12)
Block(-1,22,4,17:12)
Block(-1,22,5,17:12)
Block(-1,22,6,17:12)
Block(-1,22,7,17:12)
Block(-1,22,8,LEAVES:12)
Block(-1,22,9,LEAVES:12)
Block(-1,22,10,LEAVES:12)
Block(-1,22,13,LEAVES:12)
Block(-1,22,14,LEAVES:12)
Block(-1,22,15,LEAVES:12)
Block(-1,23,-8,LEAVES:12)
Block(-1,23,-7,LEAVES:12)
Block(-1,23,-6,LEAVES:12)
Block(-1,23,-5,17:12)
Block(-1,23,-4,17:12)
Block(-1,23,-3,LEAVES:12)
Block(-1,23,2,17:12)
Block(-1,23,3,17:12)
Block(-1,23,4,17:12)
Block(-1,23,5,LEAVES:12)
Block(-1,23,6,LEAVES:12)
Block(-1,23,7,17:12)
Block(-1,23,8,17:12)
Block(-1,23,9,LEAVES:12)
Block(-1,23,10,LEAVES:12)
Block(-1,23,11,LEAVES:12)
Block(-1,23,12,LEAVES:12)
Block(-1,23,14,LEAVES:12)
Block(-1,24,-9,LEAVES:12)
Block(-1,24,-8,LEAVES:12)
Block(-1,24,-7,LEAVES:12)
Block(-1,24,-4,LEAVES:12)
Block(-1,24,2,17:12)
Block(-1,24,3,17:12)
Block(-1,24,4,17:12)
Block(-1,24,5,LEAVES:12)
Block(-1,24,6,LEAVES:12)
Block(-1,24,7,LEAVES:12)
Block(-1,24,8,LEAVES:12)
Block(-1,24,9,17:12)
Block(-1,24,10,17:12)
Block(-1,24,11,17:12)
Block(-1,24,12,17:12)
Block(-1,24,13,17:12)
Block(-1,24,14,LEAVES:12)
Block(-1,24,15,LEAVES:12)
Block(-1,24,16,LEAVES:12)
Block(-1,25,-9,LEAVES:12)
Block(-1,25,-8,LEAVES:12)
Block(-1,25,-7,LEAVES:12)
Block(-1,25,-6,LEAVES:12)
Block(-1,25,-5,LEAVES:12)
Block(-1,25,3,17:12)
Block(-1,25,4,17:12)
Block(-1,25,6,LEAVES:12)
Block(-1,25,7,LEAVES:12)
Block(-1,25,8,LEAVES:12)
Block(-1,25,10,LEAVES:12)
Block(-1,25,11,LEAVES:12)
Block(-1,25,12,17:12)
Block(-1,25,13,LEAVES:12)
Block(-1,25,15,LEAVES:12)
Block(-1,25,16,LEAVES:12)
Block(-1,25,17,LEAVES:12)
Block(-1,26,-8,LEAVES:12)
Block(-1,26,-7,LEAVES:12)
Block(-1,26,-3,LEAVES:12)
Block(-1,26,4,17:12)
Block(-1,26,6,LEAVES:12)
Block(-1,26,7,LEAVES:12)
Block(-1,26,8,LEAVES:12)
Block(-1,26,9,LEAVES:12)
Block(-1,26,10,LEAVES:12)
Block(-1,26,11,LEAVES:12)
Block(-1,26,12,LEAVES:12)
Block(-1,26,16,LEAVES:12)
Block(-1,27,-6,LEAVES:12)
Block(-1,27,-4,LEAVES:12)
Block(-1,27,-3,LEAVES:12)
Block(-1,27,-2,LEAVES:12)
Block(-1,27,4,17:12)
Block(-1,27,7,LEAVES:12)
Block(-1,27,9,LEAVES:12)
Block(-1,27,10,LEAVES:12)
Block(-1,27,11,LEAVES:12)
Block(-1,27,13,LEAVES:12)
Block(-1,28,-3,LEAVES:12)
Block(-1,28,4,17:12)
Block(-1,28,8,LEAVES:12)
Block(-1,30,5,17:12)
Block(-1,30,8,LEAVES:12)
Block(-1,30,9,LEAVES:12)
Block(-1,30,10,LEAVES:12)
Block(-1,30,11,LEAVES:12)
Block(-1,31,5,17:12)
Block(-1,31,9,LEAVES:12)
Block(-1,31,10,LEAVES:12)
Block(-1,31,11,LEAVES:12)
Block(-1,32,5,17:12)
Block(-1,32,8,17:12)
Block(-1,32,9,17:12)
Block(-1,32,10,LEAVES:12)
Block(-1,33,-2,LEAVES:12)
Block(-1,33,8,LEAVES:12)
Block(-1,33,9,17:12)
Block(-1,33,10,17:12)
Block(-1,33,11,17:12)
Block(-1,34,-4,LEAVES:12)
Block(-1,34,-1,LEAVES:12)
Block(-1,34,4,17:12)
Block(-1,34,7,LEAVES:12)
Block(-1,34,8,LEAVES:12)
Block(-1,34,9,LEAVES:12)
Block(-1,35,-5,LEAVES:12)
Block(-1,35,-4,LEAVES:12)
Block(-1,35,-3,LEAVES:12)
Block(-1,35,2,17:12)
Block(-1,35,3,17:12)
Block(-1,35,4,17:12)
Block(-1,35,6,LEAVES:12)
Block(-1,35,7,LEAVES:12)
Block(-1,35,8,LEAVES:12)
Block(-1,35,10,LEAVES:12)
Block(-1,35,12,LEAVES:12)
Block(-1,36,-4,LEAVES:12)
Block(-1,36,-2,LEAVES:12)
Block(-1,36,-1,17:12)
Block(-1,36,4,17:12)
Block(-1,36,5,LEAVES:12)
Block(-1,36,6,LEAVES:12)
Block(-1,36,7,LEAVES:12)
Block(-1,36,9,17:12)
Block(-1,37,-3,LEAVES:12)
Block(-1,37,0,LEAVES:12)
Block(-1,37,1,LEAVES:12)
Block(-1,37,4,17:12)
Block(-1,37,5,LEAVES:12)
Block(-1,37,6,LEAVES:12)
Block(-1,37,9,LEAVES:12)
Block(-1,37,10,LEAVES:12)
Block(-1,37,11,LEAVES:12)
Block(-1,38,-2,LEAVES:12)
Block(-1,38,0,LEAVES:12)
Block(-1,38,1,LEAVES:12)
Block(-1,38,2,LEAVES:12)
Block(-1,38,3,17:12)
Block(-1,38,4,17:12)
Block(-1,38,5,17:12)
Block(-1,38,6,LEAVES:12)
Block(-1,38,7,LEAVES:12)
Block(-1,38,8,LEAVES:12)
Block(-1,38,9,LEAVES:12)
Block(-1,38,10,LEAVES:12)
Block(-1,39,0,LEAVES:12)
Block(-1,39,1,LEAVES:12)
Block(-1,39,2,LEAVES:12)
Block(-1,39,3,LEAVES:12)
Block(-1,39,4,LEAVES:12)
Block(-1,39,5,LEAVES:12)
Block(-1,39,6,17:12)
Block(-1,39,7,LEAVES:12)
Block(-1,39,8,LEAVES:12)
Block(-1,39,9,LEAVES:12)
Block(-1,40,-1,LEAVES:12)
Block(-1,40,3,LEAVES:12)
Block(-1,40,4,LEAVES:12)
Block(-1,40,5,17:12)
Block(-1,40,7,LEAVES:12)
Block(-1,40,8,LEAVES:12)
Block(-1,41,3,LEAVES:12)
Block(-1,41,4,LEAVES:12)
Block(-1,41,5,17:12)
Block(-1,42,-1,LEAVES:12)
Block(-1,42,3,LEAVES:12)
Block(-1,42,7,LEAVES:12)
Block(-1,43,0,LEAVES:12)
Block(-1,43,3,LEAVES:12)
Block(-1,43,4,LEAVES:12)
Block(-1,43,5,LEAVES:12)
Block(-1,43,6,LEAVES:12)
Block(-1,43,7,LEAVES:12)
Block(-1,44,6,LEAVES:12)
Block(0,0,2,17:12)
Block(0,1,2,17:12)
Block(0,1,3,17:12)
Block(0,2,0,17:12)
Block(0,2,1,17:12)
Block(0,2,2,17:12)
Block(0,3,0,17:12)
Block(0,3,1,17:12)
Block(0,3,2,17:12)
Block(0,3,3,17:12)
Block(0,4,-1,17:12)
Block(0,4,0,17:12)
Block(0,4,1,17:12)
Block(0,4,2,162:1)
Block(0,4,3,17:12)
Block(0,5,0,17:12)
Block(0,5,1,17:12)
Block(0,5,2,17:12)
Block(0,5,3,17:12)
Block(0,6,1,17:12)
Block(0,6,2,17:12)
Block(0,6,3,17:12)
Block(0,7,2,17:12)
Block(0,8,-6,LEAVES:12)
Block(0,8,-5,LEAVES:12)
Block(0,8,-4,LEAVES:12)
Block(0,9,-5,LEAVES:12)
Block(0,9,-4,LEAVES:12)
Block(0,9,-3,LEAVES:12)
Block(0,9,-2,LEAVES:12)
Block(0,9,-1,LEAVES:12)
Block(0,10,-4,LEAVES:12)
Block(0,10,-2,LEAVES:12)
Block(0,10,-1,LEAVES:12)
Block(0,10,0,LEAVES:12)
Block(0,11,-6,LEAVES:12)
Block(0,11,-5,LEAVES:12)
Block(0,11,-4,LEAVES:12)
Block(0,11,-3,LEAVES:12)
Block(0,11,-2,17:12)
Block(0,11,-1,17:12)
Block(0,11,0,17:12)
Block(0,12,-7,LEAVES:12)
Block(0,12,-6,LEAVES:12)
Block(0,12,-5,LEAVES:12)
Block(0,12,-4,LEAVES:12)
Block(0,12,-3,17:12)
Block(0,12,-2,17:12)
Block(0,12,0,17:12)
Block(0,13,-8,LEAVES:12)
Block(0,13,-7,LEAVES:12)
Block(0,13,-6,LEAVES:12)
Block(0,13,-4,LEAVES:12)
Block(0,13,-2,LEAVES:12)
Block(0,13,-1,LEAVES:12)
Block(0,13,0,17:12)
Block(0,14,-7,LEAVES:12)
Block(0,14,-4,LEAVES:12)
Block(0,14,-3,LEAVES:12)
Block(0,14,-2,LEAVES:12)
Block(0,14,-1,LEAVES:12)
Block(0,14,0,LEAVES:12)
Block(0,15,-9,LEAVES:12)
Block(0,15,-8,LEAVES:12)
Block(0,15,-7,LEAVES:12)
Block(0,15,-6,LEAVES:12)
Block(0,15,-5,LEAVES:12)
Block(0,15,-4,LEAVES:12)
Block(0,15,-3,LEAVES:12)
Block(0,15,-1,LEAVES:12)
Block(0,15,0,LEAVES:12)
Block(0,15,1,LEAVES:12)
Block(0,15,2,LEAVES:12)
Block(0,15,3,LEAVES:12)
Block(0,16,-10,LEAVES:12)
Block(0,16,-9,LEAVES:12)
Block(0,16,-8,LEAVES:12)
Block(0,16,-6,LEAVES:12)
Block(0,16,-5,LEAVES:12)
Block(0,16,-4,LEAVES:12)
Block(0,16,0,LEAVES:12)
Block(0,16,2,LEAVES:12)
Block(0,16,3,17:12)
Block(0,17,-9,LEAVES:12)
Block(0,17,-5,LEAVES:12)
Block(0,17,-1,LEAVES:12)
Block(0,17,3,17:12)
Block(0,17,4,17:12)
Block(0,18,-6,LEAVES:12)
Block(0,18,-3,LEAVES:12)
Block(0,18,-2,LEAVES:12)
Block(0,18,3,17:12)
Block(0,18,4,17:12)
Block(0,19,-4,LEAVES:12)
Block(0,19,-3,LEAVES:12)
Block(0,19,-2,LEAVES:12)
Block(0,19,2,17:12)
Block(0,19,3,17:12)
Block(0,20,-6,LEAVES:12)
Block(0,20,-5,17:12)
Block(0,20,-3,LEAVES:12)
Block(0,20,0,17:12)
Block(0,20,1,17:12)
Block(0,20,2,17:12)
Block(0,20,3,17:12)
Block(0,20,8,LEAVES:12)
Block(0,20,9,LEAVES:12)
Block(0,20,10,LEAVES:12)
Block(0,21,-8,LEAVES:12)
Block(0,21,-7,LEAVES:12)
Block(0,21,-6,LEAVES:12)
Block(0,21,-4,LEAVES:12)
Block(0,21,-3,17:12)
Block(0,21,-1,17:12)
Block(0,21,0,17:12)
Block(0,21,1,17:12)
Block(0,21,2,17:12)
Block(0,21,3,17:12)
Block(0,21,4,17:12)
Block(0,21,9,LEAVES:12)
Block(0,21,11,LEAVES:12)
Block(0,21,12,LEAVES:12)
Block(0,21,13,LEAVES:12)
Block(0,22,-9,LEAVES:12)
Block(0,22,-8,LEAVES:12)
Block(0,22,-7,LEAVES:12)
Block(0,22,-5,LEAVES:12)
Block(0,22,-3,LEAVES:12)
Block(0,22,2,17:12)
Block(0,22,4,17:12)
Block(0,22,5,17:12)
Block(0,22,6,17:12)
Block(0,22,9,LEAVES:12)
Block(0,22,10,LEAVES:12)
Block(0,22,11,LEAVES:12)
Block(0,22,12,LEAVES:12)
Block(0,22,14,LEAVES:12)
Block(0,23,-9,LEAVES:12)
Block(0,23,-8,LEAVES:12)
Block(0,23,-7,LEAVES:12)
Block(0,23,-5,LEAVES:12)
Block(0,23,-4,LEAVES:12)
Block(0,23,-3,17:12)
Block(0,23,2,17:12)
Block(0,23,5,LEAVES:12)
Block(0,23,8,LEAVES:12)
Block(0,23,9,LEAVES:12)
Block(0,23,10,LEAVES:12)
Block(0,23,11,LEAVES:12)
Block(0,23,12,LEAVES:12)
Block(0,23,13,LEAVES:12)
Block(0,24,-9,LEAVES:12)
Block(0,24,-8,LEAVES:12)
Block(0,24,-7,LEAVES:12)
Block(0,24,-6,LEAVES:12)
Block(0,24,-4,LEAVES:12)
Block(0,24,1,LEAVES:12)
Block(0,24,4,17:12)
Block(0,24,6,LEAVES:12)
Block(0,24,7,LEAVES:12)
Block(0,24,8,LEAVES:12)
Block(0,24,9,17:12)
Block(0,24,10,LEAVES:12)
Block(0,24,11,LEAVES:12)
Block(0,24,12,LEAVES:12)
Block(0,24,15,LEAVES:12)
Block(0,25,-9,LEAVES:12)
Block(0,25,-8,LEAVES:12)
Block(0,25,-7,LEAVES:12)
Block(0,25,-5,LEAVES:12)
Block(0,25,0,LEAVES:12)
Block(0,25,4,17:12)
Block(0,25,6,LEAVES:12)
Block(0,25,7,LEAVES:12)
Block(0,25,8,LEAVES:12)
Block(0,25,9,LEAVES:12)
Block(0,25,10,LEAVES:12)
Block(0,25,11,LEAVES:12)
Block(0,25,16,LEAVES:12)
Block(0,26,-8,LEAVES:12)
Block(0,26,-7,LEAVES:12)
Block(0,26,-6,LEAVES:12)
Block(0,26,-3,LEAVES:12)
Block(0,26,4,17:12)
Block(0,26,7,LEAVES:12)
Block(0,26,8,LEAVES:12)
Block(0,26,9,LEAVES:12)
Block(0,26,10,LEAVES:12)
Block(0,26,11,LEAVES:12)
Block(0,27,-7,LEAVES:12)
Block(0,27,-6,LEAVES:12)
Block(0,27,-5,LEAVES:12)
Block(0,27,-3,LEAVES:12)
Block(0,27,-2,LEAVES:12)
Block(0,27,4,17:12)
Block(0,27,5,17:12)
Block(0,27,8,LEAVES:12)
Block(0,27,9,LEAVES:12)
Block(0,27,10,LEAVES:12)
Block(0,27,11,LEAVES:12)
Block(0,27,12,LEAVES:12)
Block(0,28,-6,LEAVES:12)
Block(0,28,4,17:12)
Block(0,28,5,17:12)
Block(0,28,7,LEAVES:12)
Block(0,28,8,LEAVES:12)
Block(0,28,9,LEAVES:12)
Block(0,28,11,LEAVES:12)
Block(0,29,5,17:12)
Block(0,29,8,LEAVES:12)
Block(0,30,-1,LEAVES:12)
Block(0,30,5,17:12)
Block(0,30,9,LEAVES:12)
Block(0,30,10,LEAVES:12)
Block(0,30,11,LEAVES:12)
Block(0,30,12,LEAVES:12)
Block(0,31,1,17:12)
Block(0,31,2,17:12)
Block(0,31,3,17:12)
Block(0,31,4,17:12)
Block(0,31,5,17:12)
Block(0,31,8,17:12)
Block(0,31,10,LEAVES:12)
Block(0,31,11,LEAVES:12)
Block(0,32,8,LEAVES:12)
Block(0,33,-3,LEAVES:12)
Block(0,33,-2,LEAVES:12)
Block(0,33,-1,LEAVES:12)
Block(0,33,4,17:12)
Block(0,33,7,LEAVES:12)
Block(0,33,8,LEAVES:12)
Block(0,33,9,LEAVES:12)
Block(0,33,11,LEAVES:12)
Block(0,33,12,LEAVES:12)
Block(0,34,-2,LEAVES:12)
Block(0,34,4,17:12)
Block(0,34,7,LEAVES:12)
Block(0,34,8,LEAVES:12)
Block(0,34,9,LEAVES:12)
Block(0,34,10,LEAVES:12)
Block(0,35,-4,LEAVES:12)
Block(0,35,2,LEAVES:12)
Block(0,35,7,LEAVES:12)
Block(0,35,9,LEAVES:12)
Block(0,35,10,LEAVES:12)
Block(0,35,11,LEAVES:12)
Block(0,36,-2,LEAVES:12)
Block(0,36,1,LEAVES:12)
Block(0,36,6,LEAVES:12)
Block(0,36,8,17:12)
Block(0,36,9,LEAVES:12)
Block(0,36,10,LEAVES:12)
Block(0,37,-1,17:12)
Block(0,37,0,LEAVES:12)
Block(0,37,1,LEAVES:12)
Block(0,37,2,LEAVES:12)
Block(0,37,6,LEAVES:12)
Block(0,37,7,LEAVES:12)
Block(0,37,8,LEAVES:12)
Block(0,37,9,LEAVES:12)
Block(0,37,10,LEAVES:12)
Block(0,38,-1,LEAVES:12)
Block(0,38,0,LEAVES:12)
Block(0,38,1,LEAVES:12)
Block(0,38,2,LEAVES:12)
Block(0,38,6,LEAVES:12)
Block(0,38,7,LEAVES:12)
Block(0,38,8,LEAVES:12)
Block(0,38,9,LEAVES:12)
Block(0,38,10,LEAVES:12)
Block(0,39,0,LEAVES:12)
Block(0,39,3,17:12)
Block(0,39,4,LEAVES:12)
Block(0,39,6,LEAVES:12)
Block(0,39,7,LEAVES:12)
Block(0,39,8,LEAVES:12)
Block(0,39,9,LEAVES:12)
Block(0,40,1,LEAVES:12)
Block(0,40,4,LEAVES:12)
Block(0,40,6,LEAVES:12)
Block(0,40,7,LEAVES:12)
Block(0,40,8,LEAVES:12)
Block(0,41,3,LEAVES:12)
Block(0,41,4,LEAVES:12)
Block(0,41,5,LEAVES:12)
Block(0,41,7,LEAVES:12)
Block(0,42,-2,LEAVES:12)
Block(0,42,-1,LEAVES:12)
Block(0,42,0,LEAVES:12)
Block(0,42,2,LEAVES:12)
Block(0,42,3,LEAVES:12)
Block(0,42,4,LEAVES:12)
Block(0,43,-1,LEAVES:12)
Block(0,43,0,LEAVES:12)
Block(0,43,1,LEAVES:12)
Block(0,43,3,LEAVES:12)
Block(0,43,4,LEAVES:12)
Block(0,43,5,LEAVES:12)
Block(0,43,6,LEAVES:12)
Block(0,44,0,LEAVES:12)
Block(0,44,5,LEAVES:12)
Block(0,44,6,LEAVES:12)
Block(0,44,7,LEAVES:12)
Block(0,45,6,LEAVES:12)
Block(1,0,2,17:12)
Block(1,0,3,17:12)
Block(1,1,2,17:12)
Block(1,1,3,17:12)
Block(1,2,2,17:12)
Block(1,3,1,17:12)
Block(1,3,2,17:12)
Block(1,4,0,17:12)
Block(1,4,1,17:12)
Block(1,4,2,17:12)
Block(1,4,3,17:12)
Block(1,5,-1,17:12)
Block(1,5,0,17:12)
Block(1,5,1,17:12)
Block(1,5,2,17:12)
Block(1,6,0,17:12)
Block(1,6,1,17:12)
Block(1,6,2,17:12)
Block(1,6,3,17:12)
Block(1,7,1,17:12)
Block(1,7,2,17:12)
Block(1,7,3,17:12)
Block(1,8,-5,LEAVES:12)
Block(1,8,1,17:12)
Block(1,8,2,17:12)
Block(1,8,3,17:12)
Block(1,9,-4,LEAVES:12)
Block(1,9,-2,LEAVES:12)
Block(1,9,-1,LEAVES:12)
Block(1,9,0,LEAVES:12)
Block(1,9,2,17:12)
Block(1,9,3,17:12)
Block(1,9,4,17:12)
Block(1,10,-1,LEAVES:12)
Block(1,10,3,17:12)
Block(1,10,4,17:12)
Block(1,11,-7,LEAVES:12)
Block(1,11,-6,LEAVES:12)
Block(1,11,-5,LEAVES:12)
Block(1,11,3,17:12)
Block(1,11,4,17:12)
Block(1,11,5,17:12)
Block(1,12,-8,LEAVES:12)
Block(1,12,-7,LEAVES:12)
Block(1,12,-6,LEAVES:12)
Block(1,12,-5,LEAVES:12)
Block(1,12,-4,LEAVES:12)
Block(1,12,-2,LEAVES:12)
Block(1,12,0,17:12)
Block(1,12,1,17:12)
Block(1,12,2,17:12)
Block(1,12,3,17:12)
Block(1,12,4,17:12)
Block(1,12,5,17:12)
Block(1,12,13,LEAVES:12)
Block(1,13,-8,LEAVES:12)
Block(1,13,-7,LEAVES:12)
Block(1,13,-5,LEAVES:12)
Block(1,13,-4,17:12)
Block(1,13,-3,LEAVES:12)
Block(1,13,-2,LEAVES:12)
Block(1,13,-1,LEAVES:12)
Block(1,13,4,17:12)
Block(1,13,12,LEAVES:12)
Block(1,14,-6,17:12)
Block(1,14,-5,17:12)
Block(1,14,-4,17:12)
Block(1,14,-3,LEAVES:12)
Block(1,14,-2,LEAVES:12)
Block(1,14,-1,LEAVES:12)
Block(1,14,9,LEAVES:12)
Block(1,15,-8,LEAVES:12)
Block(1,15,-7,LEAVES:12)
Block(1,15,-6,LEAVES:12)
Block(1,15,-4,LEAVES:12)
Block(1,15,0,LEAVES:12)
Block(1,15,2,LEAVES:12)
Block(1,15,3,17:12)
Block(1,15,4,17:12)
Block(1,15,10,LEAVES:12)
Block(1,16,-9,LEAVES:12)
Block(1,16,-8,LEAVES:12)
Block(1,16,-7,LEAVES:12)
Block(1,16,-6,LEAVES:12)
Block(1,16,-5,LEAVES:12)
Block(1,16,3,17:12)
Block(1,16,4,17:12)
Block(1,17,-8,LEAVES:12)
Block(1,17,-6,LEAVES:12)
Block(1,17,3,17:12)
Block(1,17,4,17:12)
Block(1,18,-7,LEAVES:12)
Block(1,18,-6,LEAVES:12)
Block(1,18,-5,LEAVES:12)
Block(1,18,-4,LEAVES:12)
Block(1,18,-3,LEAVES:12)
Block(1,18,-2,LEAVES:12)
Block(1,18,2,17:12)
Block(1,18,3,17:12)
Block(1,18,4,17:12)
Block(1,19,-7,LEAVES:12)
Block(1,19,-6,LEAVES:12)
Block(1,19,-5,LEAVES:12)
Block(1,19,-4,LEAVES:12)
Block(1,19,-3,LEAVES:12)
Block(1,19,2,17:12)
Block(1,19,3,17:12)
Block(1,19,4,17:12)
Block(1,20,-7,LEAVES:12)
Block(1,20,-6,LEAVES:12)
Block(1,20,-4,LEAVES:12)
Block(1,20,-3,LEAVES:12)
Block(1,20,-2,LEAVES:12)
Block(1,20,2,17:12)
Block(1,20,3,17:12)
Block(1,20,9,LEAVES:12)
Block(1,21,-8,LEAVES:12)
Block(1,21,-7,LEAVES:12)
Block(1,21,-6,LEAVES:12)
Block(1,21,-5,LEAVES:12)
Block(1,21,-4,LEAVES:12)
Block(1,21,-3,LEAVES:12)
Block(1,21,-2,17:12)
Block(1,21,-1,17:12)
Block(1,21,2,17:12)
Block(1,21,3,17:12)
Block(1,21,12,LEAVES:12)
Block(1,21,13,LEAVES:12)
Block(1,21,14,LEAVES:12)
Block(1,22,-8,LEAVES:12)
Block(1,22,-7,LEAVES:12)
Block(1,22,-6,LEAVES:12)
Block(1,22,-5,LEAVES:12)
Block(1,22,-4,LEAVES:12)
Block(1,22,-3,17:12)
Block(1,22,-2,17:12)
Block(1,22,-1,17:12)
Block(1,22,8,LEAVES:12)
Block(1,22,10,LEAVES:12)
Block(1,22,11,LEAVES:12)
Block(1,22,12,LEAVES:12)
Block(1,22,13,LEAVES:12)
Block(1,23,-8,LEAVES:12)
Block(1,23,-7,LEAVES:12)
Block(1,23,-6,17:12)
Block(1,23,-5,17:12)
Block(1,23,-4,LEAVES:12)
Block(1,23,-3,LEAVES:12)
Block(1,23,-1,17:12)
Block(1,23,9,LEAVES:12)
Block(1,23,10,LEAVES:12)
Block(1,23,12,LEAVES:12)
Block(1,23,13,LEAVES:12)
Block(1,23,14,LEAVES:12)
Block(1,24,-8,LEAVES:12)
Block(1,24,-7,LEAVES:12)
Block(1,24,-4,LEAVES:12)
Block(1,24,0,LEAVES:12)
Block(1,24,1,LEAVES:12)
Block(1,24,2,LEAVES:12)
Block(1,24,7,LEAVES:12)
Block(1,24,8,LEAVES:12)
Block(1,24,9,17:12)
Block(1,24,10,LEAVES:12)
Block(1,24,11,LEAVES:12)
Block(1,24,12,LEAVES:12)
Block(1,24,13,LEAVES:12)
Block(1,25,-8,LEAVES:12)
Block(1,25,-7,LEAVES:12)
Block(1,25,-3,LEAVES:12)
Block(1,25,-1,LEAVES:12)
Block(1,25,0,LEAVES:12)
Block(1,25,1,LEAVES:12)
Block(1,25,4,17:12)
Block(1,25,7,LEAVES:12)
Block(1,25,9,17:12)
Block(1,25,10,LEAVES:12)
Block(1,25,11,LEAVES:12)
Block(1,25,12,LEAVES:12)
Block(1,26,-9,LEAVES:12)
Block(1,26,-7,LEAVES:12)
Block(1,26,-4,LEAVES:12)
Block(1,26,-3,LEAVES:12)
Block(1,26,-2,LEAVES:12)
Block(1,26,0,LEAVES:12)
Block(1,26,7,LEAVES:12)
Block(1,26,8,LEAVES:12)
Block(1,26,10,17:12)
Block(1,26,11,LEAVES:12)
Block(1,26,12,LEAVES:12)
Block(1,27,-8,LEAVES:12)
Block(1,27,-7,LEAVES:12)
Block(1,27,-6,LEAVES:12)
Block(1,27,-3,LEAVES:12)
Block(1,27,-2,LEAVES:12)
Block(1,27,-1,LEAVES:12)
Block(1,27,4,17:12)
Block(1,27,7,LEAVES:12)
Block(1,27,8,LEAVES:12)
Block(1,27,9,LEAVES:12)
Block(1,27,10,LEAVES:12)
Block(1,27,11,LEAVES:12)
Block(1,27,12,LEAVES:12)
Block(1,27,13,LEAVES:12)
Block(1,28,-7,LEAVES:12)
Block(1,28,-2,LEAVES:12)
Block(1,28,-1,LEAVES:12)
Block(1,28,5,17:12)
Block(1,28,8,LEAVES:12)
Block(1,28,12,LEAVES:12)
Block(1,29,0,LEAVES:12)
Block(1,29,5,17:12)
Block(1,29,6,17:12)
Block(1,30,-2,LEAVES:12)
Block(1,30,-1,LEAVES:12)
Block(1,30,0,LEAVES:12)
Block(1,30,2,LEAVES:12)
Block(1,30,5,17:12)
Block(1,30,6,17:12)
Block(1,30,8,LEAVES:12)
Block(1,30,9,LEAVES:12)
Block(1,30,10,LEAVES:12)
Block(1,30,11,LEAVES:12)
Block(1,31,-1,LEAVES:12)
Block(1,31,1,17:12)
Block(1,31,4,17:12)
Block(1,31,5,17:12)
Block(1,31,7,LEAVES:12)
Block(1,31,8,17:12)
Block(1,31,10,LEAVES:12)
Block(1,31,11,LEAVES:12)
Block(1,31,12,LEAVES:12)
Block(1,32,0,17:12)
Block(1,32,1,17:12)
Block(1,32,4,17:12)
Block(1,32,5,17:12)
Block(1,32,7,LEAVES:12)
Block(1,32,8,LEAVES:12)
Block(1,32,9,LEAVES:12)
Block(1,32,10,LEAVES:12)
Block(1,32,11,LEAVES:12)
Block(1,33,-2,LEAVES:12)
Block(1,33,-1,LEAVES:12)
Block(1,33,0,LEAVES:12)
Block(1,33,4,17:12)
Block(1,33,5,17:12)
Block(1,33,8,LEAVES:12)
Block(1,33,9,LEAVES:12)
Block(1,33,10,LEAVES:12)
Block(1,33,11,LEAVES:12)
Block(1,34,-3,LEAVES:12)
Block(1,34,-2,LEAVES:12)
Block(1,34,-1,LEAVES:12)
Block(1,34,5,17:12)
Block(1,34,6,LEAVES:12)
Block(1,34,7,LEAVES:12)
Block(1,34,8,LEAVES:12)
Block(1,34,9,LEAVES:12)
Block(1,34,10,LEAVES:12)
Block(1,34,11,LEAVES:12)
Block(1,35,-5,LEAVES:12)
Block(1,35,-4,LEAVES:12)
Block(1,35,-3,LEAVES:12)
Block(1,35,-2,LEAVES:12)
Block(1,35,1,LEAVES:12)
Block(1,35,2,LEAVES:12)
Block(1,35,3,LEAVES:12)
Block(1,35,6,17:12)
Block(1,35,7,LEAVES:12)
Block(1,35,8,LEAVES:12)
Block(1,35,9,LEAVES:12)
Block(1,35,10,LEAVES:12)
Block(1,36,-4,LEAVES:12)
Block(1,36,-3,LEAVES:12)
Block(1,36,0,LEAVES:12)
Block(1,36,1,LEAVES:12)
Block(1,36,2,LEAVES:12)
Block(1,36,6,LEAVES:12)
Block(1,36,8,17:12)
Block(1,36,9,LEAVES:12)
Block(1,37,-2,LEAVES:12)
Block(1,37,1,LEAVES:12)
Block(1,37,5,LEAVES:12)
Block(1,37,6,LEAVES:12)
Block(1,37,7,LEAVES:12)
Block(1,37,8,LEAVES:12)
Block(1,37,9,LEAVES:12)
Block(1,37,10,LEAVES:12)
Block(1,38,-2,LEAVES:12)
Block(1,38,-1,LEAVES:12)
Block(1,38,0,LEAVES:12)
Block(1,38,1,LEAVES:12)
Block(1,38,2,LEAVES:12)
Block(1,38,3,LEAVES:12)
Block(1,38,5,LEAVES:12)
Block(1,38,6,LEAVES:12)
Block(1,38,7,LEAVES:12)
Block(1,38,8,LEAVES:12)
Block(1,38,9,LEAVES:12)
Block(1,38,10,LEAVES:12)
Block(1,38,11,LEAVES:12)
Block(1,39,-1,LEAVES:12)
Block(1,39,0,LEAVES:12)
Block(1,39,1,LEAVES:12)
Block(1,39,2,LEAVES:12)
Block(1,39,3,17:12)
Block(1,39,6,LEAVES:12)
Block(1,39,7,LEAVES:12)
Block(1,39,8,LEAVES:12)
Block(1,39,9,LEAVES:12)
Block(1,39,10,LEAVES:12)
Block(1,40,-1,LEAVES:12)
Block(1,40,0,LEAVES:12)
Block(1,40,1,LEAVES:12)
Block(1,40,2,17:12)
Block(1,40,3,17:12)
Block(1,40,4,LEAVES:12)
Block(1,40,5,LEAVES:12)
Block(1,40,6,LEAVES:12)
Block(1,40,7,LEAVES:12)
Block(1,40,8,LEAVES:12)
Block(1,40,9,LEAVES:12)
Block(1,41,1,LEAVES:12)
Block(1,41,2,LEAVES:12)
Block(1,41,3,LEAVES:12)
Block(1,41,4,LEAVES:12)
Block(1,41,6,LEAVES:12)
Block(1,41,7,LEAVES:12)
Block(1,41,8,LEAVES:12)
Block(1,42,-1,LEAVES:12)
Block(1,42,3,LEAVES:12)
Block(1,42,4,LEAVES:12)
Block(1,42,5,LEAVES:12)
Block(1,42,7,LEAVES:12)
Block(1,43,-2,LEAVES:12)
Block(1,43,-1,LEAVES:12)
Block(1,43,0,LEAVES:12)
Block(1,43,4,LEAVES:12)
Block(1,43,5,LEAVES:12)
Block(1,44,-1,LEAVES:12)
Block(1,44,6,LEAVES:12)
Block(2,0,2,17:12)
Block(2,0,3,17:12)
Block(2,0,4,17:12)
Block(2,4,1,17:12)
Block(2,5,0,17:12)
Block(2,5,1,17:12)
Block(2,5,2,17:12)
Block(2,6,0,17:12)
Block(2,6,1,17:12)
Block(2,6,2,17:12)
Block(2,7,1,17:12)
Block(2,7,2,17:12)
Block(2,7,3,17:12)
Block(2,8,1,17:12)
Block(2,8,2,17:12)
Block(2,8,3,17:12)
Block(2,8,4,17:12)
Block(2,9,-1,LEAVES:12)
Block(2,9,2,17:12)
Block(2,9,3,17:12)
Block(2,9,4,17:12)
Block(2,10,2,17:12)
Block(2,10,3,17:12)
Block(2,10,4,17:12)
Block(2,10,5,17:12)
Block(2,11,-6,LEAVES:12)
Block(2,11,2,17:12)
Block(2,11,3,17:12)
Block(2,11,4,17:12)
Block(2,11,5,17:12)
Block(2,12,-7,LEAVES:12)
Block(2,12,-5,LEAVES:12)
Block(2,12,-3,LEAVES:12)
Block(2,12,-2,LEAVES:12)
Block(2,12,-1,LEAVES:12)
Block(2,12,2,17:12)
Block(2,12,3,17:12)
Block(2,12,4,17:12)
Block(2,12,5,17:12)
Block(2,12,12,LEAVES:12)
Block(2,12,13,LEAVES:12)
Block(2,12,14,LEAVES:12)
Block(2,13,-9,LEAVES:12)
Block(2,13,-8,LEAVES:12)
Block(2,13,-7,LEAVES:12)
Block(2,13,-4,LEAVES:12)
Block(2,13,-3,LEAVES:12)
Block(2,13,-2,LEAVES:12)
Block(2,13,2,17:12)
Block(2,13,3,17:12)
Block(2,13,4,17:12)
Block(2,13,5,17:12)
Block(2,13,11,LEAVES:12)
Block(2,13,12,LEAVES:12)
Block(2,13,13,LEAVES:12)
Block(2,14,-8,LEAVES:12)
Block(2,14,-3,LEAVES:12)
Block(2,14,2,17:12)
Block(2,14,3,17:12)
Block(2,14,4,17:12)
Block(2,14,5,17:12)
Block(2,14,8,LEAVES:12)
Block(2,14,9,LEAVES:12)
Block(2,14,10,LEAVES:12)
Block(2,14,12,LEAVES:12)
Block(2,15,-8,LEAVES:12)
Block(2,15,1,LEAVES:12)
Block(2,15,2,17:12)
Block(2,15,3,17:12)
Block(2,15,4,17:12)
Block(2,15,9,LEAVES:12)
Block(2,15,10,LEAVES:12)
Block(2,15,11,LEAVES:12)
Block(2,16,-8,LEAVES:12)
Block(2,16,-7,LEAVES:12)
Block(2,16,-6,LEAVES:12)
Block(2,16,-5,LEAVES:12)
Block(2,16,0,LEAVES:12)
Block(2,16,2,17:12)
Block(2,16,3,17:12)
Block(2,16,4,17:12)
Block(2,16,10,LEAVES:12)
Block(2,16,11,LEAVES:12)
Block(2,17,-7,LEAVES:12)
Block(2,17,-6,LEAVES:12)
Block(2,17,-5,LEAVES:12)
Block(2,17,3,17:12)
Block(2,17,4,17:12)
Block(2,17,12,LEAVES:12)
Block(2,18,-8,LEAVES:12)
Block(2,18,-7,LEAVES:12)
Block(2,18,-6,LEAVES:12)
Block(2,18,-3,LEAVES:12)
Block(2,18,-2,LEAVES:12)
Block(2,19,-7,LEAVES:12)
Block(2,19,-6,LEAVES:12)
Block(2,19,-5,LEAVES:12)
Block(2,19,-4,LEAVES:12)
Block(2,19,-1,LEAVES:12)
Block(2,20,-8,LEAVES:12)
Block(2,20,-7,LEAVES:12)
Block(2,20,-6,LEAVES:12)
Block(2,20,-3,LEAVES:12)
Block(2,20,-2,LEAVES:12)
Block(2,21,-9,LEAVES:12)
Block(2,21,-8,LEAVES:12)
Block(2,21,-7,LEAVES:12)
Block(2,21,-6,LEAVES:12)
Block(2,21,-4,LEAVES:12)
Block(2,21,-3,LEAVES:12)
Block(2,21,-2,LEAVES:12)
Block(2,21,8,LEAVES:12)
Block(2,21,10,LEAVES:12)
Block(2,21,13,LEAVES:12)
Block(2,21,14,LEAVES:12)
Block(2,21,15,LEAVES:12)
Block(2,22,-8,LEAVES:12)
Block(2,22,-7,LEAVES:12)
Block(2,22,-5,LEAVES:12)
Block(2,22,-4,17:12)
Block(2,22,-3,17:12)
Block(2,22,7,LEAVES:12)
Block(2,22,8,LEAVES:12)
Block(2,22,9,LEAVES:12)
Block(2,22,11,LEAVES:12)
Block(2,22,12,LEAVES:12)
Block(2,22,14,LEAVES:12)
Block(2,23,-8,LEAVES:12)
Block(2,23,-7,LEAVES:12)
Block(2,23,-6,LEAVES:12)
Block(2,23,-5,LEAVES:12)
Block(2,23,-4,LEAVES:12)
Block(2,23,-3,LEAVES:12)
Block(2,23,-2,LEAVES:12)
Block(2,23,8,LEAVES:12)
Block(2,23,10,17:12)
Block(2,23,11,17:12)
Block(2,23,13,LEAVES:12)
Block(2,24,-7,LEAVES:12)
Block(2,24,-6,17:12)
Block(2,24,-3,LEAVES:12)
Block(2,24,-1,17:12)
Block(2,24,1,LEAVES:12)
Block(2,24,10,LEAVES:12)
Block(2,24,11,LEAVES:12)
Block(2,24,12,LEAVES:12)
Block(2,25,-9,LEAVES:12)
Block(2,25,-4,LEAVES:12)
Block(2,25,-3,LEAVES:12)
Block(2,25,-2,LEAVES:12)
Block(2,25,0,LEAVES:12)
Block(2,25,1,LEAVES:12)
Block(2,25,2,17:12)
Block(2,25,3,LEAVES:12)
Block(2,25,4,17:12)
Block(2,25,7,LEAVES:12)
Block(2,25,10,LEAVES:12)
Block(2,25,11,LEAVES:12)
Block(2,25,12,LEAVES:12)
Block(2,25,14,LEAVES:12)
Block(2,26,-10,LEAVES:12)
Block(2,26,-9,LEAVES:12)
Block(2,26,-8,LEAVES:12)
Block(2,26,-5,LEAVES:12)
Block(2,26,-4,LEAVES:12)
Block(2,26,-3,LEAVES:12)
Block(2,26,-1,LEAVES:12)
Block(2,26,0,LEAVES:12)
Block(2,26,1,LEAVES:12)
Block(2,26,2,LEAVES:12)
Block(2,26,6,LEAVES:12)
Block(2,26,7,LEAVES:12)
Block(2,26,8,LEAVES:12)
Block(2,26,10,LEAVES:12)
Block(2,26,11,LEAVES:12)
Block(2,27,-9,LEAVES:12)
Block(2,27,-7,LEAVES:12)
Block(2,27,-4,LEAVES:12)
Block(2,27,-3,LEAVES:12)
Block(2,27,-2,LEAVES:12)
Block(2,27,7,LEAVES:12)
Block(2,27,8,LEAVES:12)
Block(2,27,10,LEAVES:12)
Block(2,27,11,LEAVES:12)
Block(2,27,12,LEAVES:12)
Block(2,28,-3,LEAVES:12)
Block(2,28,-2,LEAVES:12)
Block(2,28,-1,LEAVES:12)
Block(2,28,0,LEAVES:12)
Block(2,28,1,17:12)
Block(2,28,11,LEAVES:12)
Block(2,29,-1,LEAVES:12)
Block(2,29,0,LEAVES:12)
Block(2,29,1,LEAVES:12)
Block(2,30,-1,LEAVES:12)
Block(2,30,0,LEAVES:12)
Block(2,30,1,LEAVES:12)
Block(2,30,2,LEAVES:12)
Block(2,30,3,LEAVES:12)
Block(2,30,5,17:12)
Block(2,30,7,LEAVES:12)
Block(2,30,8,LEAVES:12)
Block(2,30,9,LEAVES:12)
Block(2,30,10,LEAVES:12)
Block(2,31,-2,LEAVES:12)
Block(2,31,-1,LEAVES:12)
Block(2,31,0,LEAVES:12)
Block(2,31,2,LEAVES:12)
Block(2,31,4,17:12)
Block(2,31,5,17:12)
Block(2,31,6,LEAVES:12)
Block(2,31,7,LEAVES:12)
Block(2,31,8,17:12)
Block(2,31,10,LEAVES:12)
Block(2,31,11,LEAVES:12)
Block(2,32,-1,LEAVES:12)
Block(2,32,0,17:12)
Block(2,32,7,LEAVES:12)
Block(2,32,8,LEAVES:12)
Block(2,32,9,17:12)
Block(2,32,10,17:12)
Block(2,32,11,LEAVES:12)
Block(2,32,12,LEAVES:12)
Block(2,33,-1,LEAVES:12)
Block(2,33,4,17:12)
Block(2,33,9,LEAVES:12)
Block(2,33,10,LEAVES:12)
Block(2,33,11,LEAVES:12)
Block(2,33,12,LEAVES:12)
Block(2,34,-2,LEAVES:12)
Block(2,34,-1,LEAVES:12)
Block(2,34,4,17:12)
Block(2,34,5,LEAVES:12)
Block(2,34,6,LEAVES:12)
Block(2,34,7,LEAVES:12)
Block(2,34,9,LEAVES:12)
Block(2,34,10,LEAVES:12)
Block(2,34,11,LEAVES:12)
Block(2,35,-4,LEAVES:12)
Block(2,35,-3,LEAVES:12)
Block(2,35,-2,LEAVES:12)
Block(2,35,0,LEAVES:12)
Block(2,35,1,LEAVES:12)
Block(2,35,2,LEAVES:12)
Block(2,35,6,LEAVES:12)
Block(2,35,7,17:12)
Block(2,35,8,LEAVES:12)
Block(2,35,9,LEAVES:12)
Block(2,35,10,LEAVES:12)
Block(2,36,-5,LEAVES:12)
Block(2,36,-4,LEAVES:12)
Block(2,36,-3,LEAVES:12)
Block(2,36,-2,LEAVES:12)
Block(2,36,1,LEAVES:12)
Block(2,36,5,LEAVES:12)
Block(2,36,6,LEAVES:12)
Block(2,36,7,17:12)
Block(2,36,8,17:12)
Block(2,36,9,LEAVES:12)
Block(2,37,-4,LEAVES:12)
Block(2,37,-3,LEAVES:12)
Block(2,37,-2,LEAVES:12)
Block(2,37,-1,LEAVES:12)
Block(2,37,0,LEAVES:12)
Block(2,37,4,LEAVES:12)
Block(2,37,5,LEAVES:12)
Block(2,37,6,LEAVES:12)
Block(2,37,8,17:12)
Block(2,37,9,LEAVES:12)
Block(2,38,-2,LEAVES:12)
Block(2,38,-1,LEAVES:12)
Block(2,38,2,LEAVES:12)
Block(2,38,3,LEAVES:12)
Block(2,38,4,LEAVES:12)
Block(2,38,5,LEAVES:12)
Block(2,38,6,LEAVES:12)
Block(2,38,7,LEAVES:12)
Block(2,38,8,LEAVES:12)
Block(2,38,10,LEAVES:12)
Block(2,39,-2,LEAVES:12)
Block(2,39,-1,LEAVES:12)
Block(2,39,0,LEAVES:12)
Block(2,39,1,LEAVES:12)
Block(2,39,2,LEAVES:12)
Block(2,39,3,LEAVES:12)
Block(2,39,4,LEAVES:12)
Block(2,39,6,LEAVES:12)
Block(2,39,7,LEAVES:12)
Block(2,39,9,LEAVES:12)
Block(2,39,10,LEAVES:12)
Block(2,39,11,LEAVES:12)
Block(2,40,-2,LEAVES:12)
Block(2,40,-1,LEAVES:12)
Block(2,40,0,LEAVES:12)
Block(2,40,2,LEAVES:12)
Block(2,40,3,LEAVES:12)
Block(2,40,4,LEAVES:12)
Block(2,40,5,LEAVES:12)
Block(2,40,6,LEAVES:12)
Block(2,40,8,LEAVES:12)
Block(2,40,10,LEAVES:12)
Block(2,41,-1,LEAVES:12)
Block(2,41,1,LEAVES:12)
Block(2,41,2,LEAVES:12)
Block(2,41,3,LEAVES:12)
Block(2,41,4,LEAVES:12)
Block(2,41,7,LEAVES:12)
Block(2,41,8,LEAVES:12)
Block(2,41,9,LEAVES:12)
Block(2,42,2,LEAVES:12)
Block(2,42,3,LEAVES:12)
Block(2,42,4,LEAVES:12)
Block(2,42,8,LEAVES:12)
Block(2,43,-1,LEAVES:12)
Block(2,43,0,LEAVES:12)
Block(3,0,3,17:12)
Block(3,0,4,17:12)
Block(3,0,5,17:12)
Block(3,6,1,17:12)
Block(3,6,2,17:12)
Block(3,7,1,17:12)
Block(3,7,2,17:12)
Block(3,7,3,17:12)
Block(3,8,1,17:12)
Block(3,8,2,17:12)
Block(3,8,3,17:12)
Block(3,9,1,17:12)
Block(3,9,2,17:12)
Block(3,9,3,17:12)
Block(3,10,2,17:12)
Block(3,10,3,17:12)
Block(3,10,4,17:12)
Block(3,11,3,17:12)
Block(3,11,4,17:12)
Block(3,12,-6,LEAVES:12)
Block(3,12,-5,LEAVES:12)
Block(3,12,-4,LEAVES:12)
Block(3,12,-2,LEAVES:12)
Block(3,12,3,17:12)
Block(3,12,4,17:12)
Block(3,12,13,LEAVES:12)
Block(3,13,-10,LEAVES:12)
Block(3,13,-9,LEAVES:12)
Block(3,13,-8,LEAVES:12)
Block(3,13,-5,LEAVES:12)
Block(3,13,-3,LEAVES:12)
Block(3,13,2,17:12)
Block(3,13,3,17:12)
Block(3,13,4,17:12)
Block(3,13,5,17:12)
Block(3,13,6,17:12)
Block(3,13,12,LEAVES:12)
Block(3,13,13,LEAVES:12)
Block(3,13,14,LEAVES:12)
Block(3,14,-9,LEAVES:12)
Block(3,14,-8,LEAVES:12)
Block(3,14,-7,LEAVES:12)
Block(3,14,-6,LEAVES:12)
Block(3,14,1,17:12)
Block(3,14,2,17:12)
Block(3,14,3,17:12)
Block(3,14,4,17:12)
Block(3,14,5,17:12)
Block(3,14,6,17:12)
Block(3,14,9,LEAVES:12)
Block(3,14,11,LEAVES:12)
Block(3,14,13,LEAVES:12)
Block(3,15,-8,LEAVES:12)
Block(3,15,-7,LEAVES:12)
Block(3,15,0,LEAVES:12)
Block(3,15,1,LEAVES:12)
Block(3,15,2,17:12)
Block(3,15,3,17:12)
Block(3,15,4,17:12)
Block(3,15,5,17:12)
Block(3,15,6,17:12)
Block(3,15,8,LEAVES:12)
Block(3,15,9,LEAVES:12)
Block(3,15,10,LEAVES:12)
Block(3,16,-8,LEAVES:12)
Block(3,16,-7,LEAVES:12)
Block(3,16,-6,LEAVES:12)
Block(3,16,-5,LEAVES:12)
Block(3,16,-4,LEAVES:12)
Block(3,16,-2,LEAVES:12)
Block(3,16,-1,LEAVES:12)
Block(3,16,0,LEAVES:12)
Block(3,16,1,LEAVES:12)
Block(3,16,4,17:12)
Block(3,16,6,LEAVES:12)
Block(3,16,9,LEAVES:12)
Block(3,16,10,LEAVES:12)
Block(3,16,11,LEAVES:12)
Block(3,16,12,LEAVES:12)
Block(3,17,-7,LEAVES:12)
Block(3,17,-6,LEAVES:12)
Block(3,17,-5,LEAVES:12)
Block(3,17,-3,LEAVES:12)
Block(3,17,0,LEAVES:12)
Block(3,17,11,LEAVES:12)
Block(3,17,12,LEAVES:12)
Block(3,17,13,LEAVES:12)
Block(3,18,-7,LEAVES:12)
Block(3,18,-6,LEAVES:12)
Block(3,18,-3,LEAVES:12)
Block(3,18,-2,LEAVES:12)
Block(3,18,-1,LEAVES:12)
Block(3,18,12,LEAVES:12)
Block(3,19,-8,LEAVES:12)
Block(3,19,-7,LEAVES:12)
Block(3,19,-6,LEAVES:12)
Block(3,19,-2,LEAVES:12)
Block(3,19,-1,LEAVES:12)
Block(3,19,0,LEAVES:12)
Block(3,19,9,LEAVES:12)
Block(3,20,-9,LEAVES:12)
Block(3,20,-8,LEAVES:12)
Block(3,20,-7,LEAVES:12)
Block(3,20,-6,LEAVES:12)
Block(3,20,-3,LEAVES:12)
Block(3,20,-2,LEAVES:12)
Block(3,20,-1,LEAVES:12)
Block(3,20,6,LEAVES:12)
Block(3,21,-8,LEAVES:12)
Block(3,21,-7,LEAVES:12)
Block(3,21,-6,LEAVES:12)
Block(3,21,-5,LEAVES:12)
Block(3,21,-3,LEAVES:12)
Block(3,21,-2,LEAVES:12)
Block(3,21,5,LEAVES:12)
Block(3,21,7,LEAVES:12)
Block(3,21,8,LEAVES:12)
Block(3,21,9,LEAVES:12)
Block(3,21,10,LEAVES:12)
Block(3,21,11,LEAVES:12)
Block(3,21,12,LEAVES:12)
Block(3,21,13,LEAVES:12)
Block(3,21,14,LEAVES:12)
Block(3,22,-8,LEAVES:12)
Block(3,22,-7,LEAVES:12)
Block(3,22,-6,LEAVES:12)
Block(3,22,-5,LEAVES:12)
Block(3,22,-4,17:12)
Block(3,22,-2,LEAVES:12)
Block(3,22,8,LEAVES:12)
Block(3,22,9,LEAVES:12)
Block(3,22,10,LEAVES:12)
Block(3,22,11,LEAVES:12)
Block(3,22,12,LEAVES:12)
Block(3,22,13,LEAVES:12)
Block(3,22,14,LEAVES:12)
Block(3,22,15,LEAVES:12)
Block(3,23,-7,LEAVES:12)
Block(3,23,-4,LEAVES:12)
Block(3,23,-3,LEAVES:12)
Block(3,23,6,LEAVES:12)
Block(3,23,9,LEAVES:12)
Block(3,23,11,LEAVES:12)
Block(3,23,12,17:12)
Block(3,23,14,LEAVES:12)
Block(3,24,-2,LEAVES:12)
Block(3,24,5,LEAVES:12)
Block(3,24,10,LEAVES:12)
Block(3,24,11,LEAVES:12)
Block(3,24,12,LEAVES:12)
Block(3,24,14,LEAVES:12)
Block(3,25,-10,LEAVES:12)
Block(3,25,-9,LEAVES:12)
Block(3,25,-8,LEAVES:12)
Block(3,25,-5,LEAVES:12)
Block(3,25,-3,LEAVES:12)
Block(3,25,-2,LEAVES:12)
Block(3,25,-1,LEAVES:12)
Block(3,25,1,LEAVES:12)
Block(3,25,2,LEAVES:12)
Block(3,25,3,LEAVES:12)
Block(3,25,4,17:12)
Block(3,25,6,LEAVES:12)
Block(3,25,7,LEAVES:12)
Block(3,25,8,LEAVES:12)
Block(3,25,9,LEAVES:12)
Block(3,25,10,LEAVES:12)
Block(3,25,11,LEAVES:12)
Block(3,25,13,LEAVES:12)
Block(3,25,14,LEAVES:12)
Block(3,25,15,LEAVES:12)
Block(3,26,-9,LEAVES:12)
Block(3,26,-8,LEAVES:12)
Block(3,26,-7,LEAVES:12)
Block(3,26,-6,LEAVES:12)
Block(3,26,-5,LEAVES:12)
Block(3,26,-4,LEAVES:12)
Block(3,26,-3,LEAVES:12)
Block(3,26,-2,LEAVES:12)
Block(3,26,-1,LEAVES:12)
Block(3,26,0,LEAVES:12)
Block(3,26,1,17:12)
Block(3,26,2,LEAVES:12)
Block(3,26,3,LEAVES:12)
Block(3,26,7,LEAVES:12)
Block(3,26,8,LEAVES:12)
Block(3,26,9,LEAVES:12)
Block(3,26,10,LEAVES:12)
Block(3,26,11,LEAVES:12)
Block(3,26,12,LEAVES:12)
Block(3,26,14,LEAVES:12)
Block(3,27,-8,LEAVES:12)
Block(3,27,-5,LEAVES:12)
Block(3,27,-3,LEAVES:12)
Block(3,27,-1,17:12)
Block(3,27,0,17:12)
Block(3,27,1,LEAVES:12)
Block(3,27,2,LEAVES:12)
Block(3,27,8,LEAVES:12)
Block(3,27,9,LEAVES:12)
Block(3,27,10,LEAVES:12)
Block(3,27,11,LEAVES:12)
Block(3,28,-3,LEAVES:12)
Block(3,28,-2,LEAVES:12)
Block(3,28,-1,LEAVES:12)
Block(3,28,0,LEAVES:12)
Block(3,28,1,LEAVES:12)
Block(3,28,3,LEAVES:12)
Block(3,28,10,LEAVES:12)
Block(3,28,11,LEAVES:12)
Block(3,28,12,LEAVES:12)
Block(3,29,0,LEAVES:12)
Block(3,29,4,LEAVES:12)
Block(3,29,11,LEAVES:12)
Block(3,30,0,LEAVES:12)
Block(3,30,2,LEAVES:12)
Block(3,30,6,LEAVES:12)
Block(3,30,7,LEAVES:12)
Block(3,30,8,LEAVES:12)
Block(3,30,9,LEAVES:12)
Block(3,30,10,LEAVES:12)
Block(3,30,11,LEAVES:12)
Block(3,31,-1,LEAVES:12)
Block(3,31,4,17:12)
Block(3,31,7,LEAVES:12)
Block(3,31,10,LEAVES:12)
Block(3,31,11,LEAVES:12)
Block(3,31,12,LEAVES:12)
Block(3,32,0,LEAVES:12)
Block(3,32,1,LEAVES:12)
Block(3,32,11,LEAVES:12)
Block(3,33,-1,LEAVES:12)
Block(3,33,0,LEAVES:12)
Block(3,33,7,LEAVES:12)
Block(3,33,9,LEAVES:12)
Block(3,33,11,LEAVES:12)
Block(3,34,-3,LEAVES:12)
Block(3,34,4,17:12)
Block(3,34,5,17:12)
Block(3,34,6,LEAVES:12)
Block(3,34,7,LEAVES:12)
Block(3,34,8,LEAVES:12)
Block(3,34,10,LEAVES:12)
Block(3,34,11,LEAVES:12)
Block(3,34,12,LEAVES:12)
Block(3,35,-4,LEAVES:12)
Block(3,35,-3,LEAVES:12)
Block(3,35,-2,LEAVES:12)
Block(3,35,-1,LEAVES:12)
Block(3,35,1,LEAVES:12)
Block(3,35,3,17:12)
Block(3,35,4,17:12)
Block(3,35,7,LEAVES:12)
Block(3,35,8,LEAVES:12)
Block(3,35,9,LEAVES:12)
Block(3,35,11,LEAVES:12)
Block(3,36,-4,LEAVES:12)
Block(3,36,-3,LEAVES:12)
Block(3,36,-2,LEAVES:12)
Block(3,36,-1,LEAVES:12)
Block(3,36,6,LEAVES:12)
Block(3,36,8,LEAVES:12)
Block(3,37,-2,LEAVES:12)
Block(3,37,0,17:12)
Block(3,37,1,17:12)
Block(3,37,5,LEAVES:12)
Block(3,37,8,LEAVES:12)
Block(3,37,9,17:12)
Block(3,38,-2,LEAVES:12)
Block(3,38,-1,17:12)
Block(3,38,0,17:12)
Block(3,38,3,LEAVES:12)
Block(3,38,6,LEAVES:12)
Block(3,39,-2,LEAVES:12)
Block(3,39,-1,LEAVES:12)
Block(3,39,0,LEAVES:12)
Block(3,39,2,LEAVES:12)
Block(3,39,3,LEAVES:12)
Block(3,39,4,LEAVES:12)
Block(3,39,5,LEAVES:12)
Block(3,39,8,LEAVES:12)
Block(3,39,10,LEAVES:12)
Block(3,40,-1,LEAVES:12)
Block(3,40,4,LEAVES:12)
Block(3,40,5,LEAVES:12)
Block(3,40,6,LEAVES:12)
Block(3,41,3,LEAVES:12)
Block(3,41,4,LEAVES:12)
Block(3,41,5,LEAVES:12)
Block(3,41,8,LEAVES:12)
Block(3,42,0,LEAVES:12)
Block(3,42,2,LEAVES:12)
Block(3,42,3,LEAVES:12)
Block(3,42,4,LEAVES:12)
Block(3,43,-1,LEAVES:12)
Block(3,43,0,LEAVES:12)
Block(3,43,1,LEAVES:12)
Block(3,43,3,LEAVES:12)
Block(3,44,0,LEAVES:12)
Block(4,0,4,17:12)
Block(4,7,2,17:12)
Block(4,12,-5,LEAVES:12)
Block(4,12,-4,LEAVES:12)
Block(4,12,-3,LEAVES:12)
Block(4,13,-9,LEAVES:12)
Block(4,13,-6,LEAVES:12)
Block(4,13,-5,LEAVES:12)
Block(4,13,-4,LEAVES:12)
Block(4,13,2,17:12)
Block(4,13,13,LEAVES:12)
Block(4,14,-8,LEAVES:12)
Block(4,14,-5,LEAVES:12)
Block(4,14,-2,LEAVES:12)
Block(4,14,0,17:12)
Block(4,14,1,17:12)
Block(4,14,5,17:12)
Block(4,14,6,17:12)
Block(4,14,9,LEAVES:12)
Block(4,15,-8,LEAVES:12)
Block(4,15,-7,LEAVES:12)
Block(4,15,-6,LEAVES:12)
Block(4,15,-1,LEAVES:12)
Block(4,15,0,LEAVES:12)
Block(4,15,1,LEAVES:12)
Block(4,15,6,17:12)
Block(4,15,7,17:12)
Block(4,15,9,LEAVES:12)
Block(4,15,10,17:12)
Block(4,15,11,17:12)
Block(4,15,13,LEAVES:12)
Block(4,16,-7,LEAVES:12)
Block(4,16,-6,LEAVES:12)
Block(4,16,-5,LEAVES:12)
Block(4,16,-4,LEAVES:12)
Block(4,16,-3,LEAVES:12)
Block(4,16,-2,LEAVES:12)
Block(4,16,-1,LEAVES:12)
Block(4,16,0,LEAVES:12)
Block(4,16,5,LEAVES:12)
Block(4,16,6,LEAVES:12)
Block(4,16,7,LEAVES:12)
Block(4,16,10,17:12)
Block(4,16,11,LEAVES:12)
Block(4,16,12,LEAVES:12)
Block(4,16,13,LEAVES:12)
Block(4,17,-6,LEAVES:12)
Block(4,17,-4,LEAVES:12)
Block(4,17,-3,LEAVES:12)
Block(4,17,-2,LEAVES:12)
Block(4,17,-1,LEAVES:12)
Block(4,17,0,LEAVES:12)
Block(4,17,1,LEAVES:12)
Block(4,17,6,LEAVES:12)
Block(4,17,10,17:12)
Block(4,17,12,LEAVES:12)
Block(4,18,-5,LEAVES:12)
Block(4,18,-3,17:12)
Block(4,18,-2,LEAVES:12)
Block(4,18,-1,LEAVES:12)
Block(4,18,0,LEAVES:12)
Block(4,18,9,LEAVES:12)
Block(4,19,-7,LEAVES:12)
Block(4,19,-6,LEAVES:12)
Block(4,19,-4,LEAVES:12)
Block(4,19,-3,LEAVES:12)
Block(4,19,-2,LEAVES:12)
Block(4,19,-1,LEAVES:12)
Block(4,19,2,LEAVES:12)
Block(4,19,8,LEAVES:12)
Block(4,19,9,LEAVES:12)
Block(4,19,10,LEAVES:12)
Block(4,20,-8,LEAVES:12)
Block(4,20,-7,LEAVES:12)
Block(4,20,-6,LEAVES:12)
Block(4,20,-5,LEAVES:12)
Block(4,20,-4,LEAVES:12)
Block(4,20,-3,LEAVES:12)
Block(4,20,-2,LEAVES:12)
Block(4,20,3,LEAVES:12)
Block(4,20,5,LEAVES:12)
Block(4,20,6,LEAVES:12)
Block(4,20,7,LEAVES:12)
Block(4,20,9,LEAVES:12)
Block(4,21,-7,LEAVES:12)
Block(4,21,-6,LEAVES:12)
Block(4,21,-5,LEAVES:12)
Block(4,21,-4,LEAVES:12)
Block(4,21,-3,LEAVES:12)
Block(4,21,-2,LEAVES:12)
Block(4,21,4,LEAVES:12)
Block(4,21,5,LEAVES:12)
Block(4,21,6,LEAVES:12)
Block(4,21,8,LEAVES:12)
Block(4,21,10,LEAVES:12)
Block(4,21,11,LEAVES:12)
Block(4,21,12,LEAVES:12)
Block(4,21,13,LEAVES:12)
Block(4,22,-9,LEAVES:12)
Block(4,22,-8,LEAVES:12)
Block(4,22,-7,LEAVES:12)
Block(4,22,-3,LEAVES:12)
Block(4,22,-2,LEAVES:12)
Block(4,22,-1,LEAVES:12)
Block(4,22,3,LEAVES:12)
Block(4,22,5,LEAVES:12)
Block(4,22,9,LEAVES:12)
Block(4,22,10,LEAVES:12)
Block(4,22,11,LEAVES:12)
Block(4,22,12,LEAVES:12)
Block(4,22,13,LEAVES:12)
Block(4,22,14,LEAVES:12)
Block(4,23,-8,LEAVES:12)
Block(4,23,-7,LEAVES:12)
Block(4,23,-6,LEAVES:12)
Block(4,23,-2,LEAVES:12)
Block(4,23,2,LEAVES:12)
Block(4,23,5,LEAVES:12)
Block(4,23,6,LEAVES:12)
Block(4,23,7,LEAVES:12)
Block(4,23,10,LEAVES:12)
Block(4,23,11,LEAVES:12)
Block(4,23,12,LEAVES:12)
Block(4,24,-7,LEAVES:12)
Block(4,24,-3,LEAVES:12)
Block(4,24,-2,LEAVES:12)
Block(4,24,-1,LEAVES:12)
Block(4,24,4,LEAVES:12)
Block(4,24,5,LEAVES:12)
Block(4,24,6,LEAVES:12)
Block(4,24,11,LEAVES:12)
Block(4,24,12,LEAVES:12)
Block(4,24,13,LEAVES:12)
Block(4,24,14,LEAVES:12)
Block(4,24,15,LEAVES:12)
Block(4,25,-9,LEAVES:12)
Block(4,25,-6,LEAVES:12)
Block(4,25,-5,LEAVES:12)
Block(4,25,-4,LEAVES:12)
Block(4,25,-3,LEAVES:12)
Block(4,25,-2,LEAVES:12)
Block(4,25,1,LEAVES:12)
Block(4,25,2,LEAVES:12)
Block(4,25,3,LEAVES:12)
Block(4,25,5,LEAVES:12)
Block(4,25,7,LEAVES:12)
Block(4,25,10,LEAVES:12)
Block(4,25,11,LEAVES:12)
Block(4,25,12,LEAVES:12)
Block(4,25,13,LEAVES:12)
Block(4,25,14,LEAVES:12)
Block(4,26,-8,LEAVES:12)
Block(4,26,-7,LEAVES:12)
Block(4,26,-6,LEAVES:12)
Block(4,26,-5,LEAVES:12)
Block(4,26,-4,LEAVES:12)
Block(4,26,-3,LEAVES:12)
Block(4,26,-2,LEAVES:12)
Block(4,26,-1,LEAVES:12)
Block(4,26,0,LEAVES:12)
Block(4,26,1,LEAVES:12)
Block(4,26,2,LEAVES:12)
Block(4,26,3,17:12)
Block(4,26,8,LEAVES:12)
Block(4,26,9,LEAVES:12)
Block(4,26,10,LEAVES:12)
Block(4,26,11,LEAVES:12)
Block(4,26,13,LEAVES:12)
Block(4,27,-6,LEAVES:12)
Block(4,27,-3,LEAVES:12)
Block(4,27,-2,LEAVES:12)
Block(4,27,-1,LEAVES:12)
Block(4,27,0,LEAVES:12)
Block(4,27,1,LEAVES:12)
Block(4,27,2,LEAVES:12)
Block(4,27,10,LEAVES:12)
Block(4,28,-4,LEAVES:12)
Block(4,28,-3,LEAVES:12)
Block(4,28,-2,LEAVES:12)
Block(4,28,0,LEAVES:12)
Block(4,28,1,LEAVES:12)
Block(4,28,2,LEAVES:12)
Block(4,28,3,LEAVES:12)
Block(4,28,4,LEAVES:12)
Block(4,28,11,LEAVES:12)
Block(4,29,-3,LEAVES:12)
Block(4,29,3,LEAVES:12)
Block(4,29,4,LEAVES:12)
Block(4,29,5,LEAVES:12)
Block(4,30,3,LEAVES:12)
Block(4,30,4,LEAVES:12)
Block(4,30,7,LEAVES:12)
Block(4,30,10,LEAVES:12)
Block(4,30,11,LEAVES:12)
Block(4,30,12,LEAVES:12)
Block(4,31,-2,LEAVES:12)
Block(4,31,-1,LEAVES:12)
Block(4,31,0,LEAVES:12)
Block(4,31,4,17:12)
Block(4,31,11,LEAVES:12)
Block(4,32,-1,LEAVES:12)
Block(4,33,6,LEAVES:12)
Block(4,33,7,LEAVES:12)
Block(4,33,8,LEAVES:12)
Block(4,34,-4,LEAVES:12)
Block(4,34,-3,LEAVES:12)
Block(4,34,-2,LEAVES:12)
Block(4,34,1,LEAVES:12)
Block(4,34,5,LEAVES:12)
Block(4,34,6,17:12)
Block(4,34,7,LEAVES:12)
Block(4,34,8,LEAVES:12)
Block(4,34,9,LEAVES:12)
Block(4,34,11,LEAVES:12)
Block(4,35,-3,LEAVES:12)
Block(4,35,-2,LEAVES:12)
Block(4,35,-1,LEAVES:12)
Block(4,35,0,LEAVES:12)
Block(4,35,1,LEAVES:12)
Block(4,35,2,LEAVES:12)
Block(4,35,3,17:12)
Block(4,35,8,LEAVES:12)
Block(4,35,9,LEAVES:12)
Block(4,36,-2,LEAVES:12)
Block(4,36,-1,LEAVES:12)
Block(4,36,1,LEAVES:12)
Block(4,36,2,17:12)
Block(4,36,3,17:12)
Block(4,36,8,LEAVES:12)
Block(4,36,12,LEAVES:12)
Block(4,37,1,17:12)
Block(4,37,2,17:12)
Block(4,37,6,LEAVES:12)
Block(4,37,9,LEAVES:12)
Block(4,37,10,LEAVES:12)
Block(4,38,-2,LEAVES:12)
Block(4,38,-1,LEAVES:12)
Block(4,38,0,LEAVES:12)
Block(4,38,5,LEAVES:12)
Block(4,38,8,LEAVES:12)
Block(4,39,-3,LEAVES:12)
Block(4,39,-2,LEAVES:12)
Block(4,39,-1,LEAVES:12)
Block(4,39,0,LEAVES:12)
Block(4,39,1,LEAVES:12)
Block(4,39,4,LEAVES:12)
Block(4,39,7,LEAVES:12)
Block(4,39,8,LEAVES:12)
Block(4,39,9,LEAVES:12)
Block(4,40,-2,LEAVES:12)
Block(4,40,0,LEAVES:12)
Block(4,40,5,LEAVES:12)
Block(4,40,8,LEAVES:12)
Block(4,41,4,LEAVES:12)
Block(4,42,-1,LEAVES:12)
Block(4,42,0,LEAVES:12)
Block(4,42,1,LEAVES:12)
Block(4,42,3,LEAVES:12)
Block(4,43,0,LEAVES:12)
Block(4,43,1,LEAVES:12)
Block(4,43,2,LEAVES:12)
Block(4,44,1,LEAVES:12)
Block(5,12,-4,LEAVES:12)
Block(5,13,-5,LEAVES:12)
Block(5,13,9,LEAVES:12)
Block(5,14,-3,LEAVES:12)
Block(5,14,-2,LEAVES:12)
Block(5,14,-1,LEAVES:12)
Block(5,14,0,17:12)
Block(5,14,8,LEAVES:12)
Block(5,14,9,LEAVES:12)
Block(5,14,10,LEAVES:12)
Block(5,14,12,17:12)
Block(5,14,13,LEAVES:12)
Block(5,15,-7,LEAVES:12)
Block(5,15,-5,LEAVES:12)
Block(5,15,-2,LEAVES:12)
Block(5,15,-1,LEAVES:12)
Block(5,15,0,LEAVES:12)
Block(5,15,7,17:12)
Block(5,15,8,17:12)
Block(5,15,9,LEAVES:12)
Block(5,15,10,LEAVES:12)
Block(5,15,12,LEAVES:12)
Block(5,15,13,LEAVES:12)
Block(5,15,14,LEAVES:12)
Block(5,16,-6,LEAVES:12)
Block(5,16,-4,LEAVES:12)
Block(5,16,-3,LEAVES:12)
Block(5,16,-2,LEAVES:12)
Block(5,16,-1,17:12)
Block(5,16,0,17:12)
Block(5,16,3,LEAVES:12)
Block(5,16,6,LEAVES:12)
Block(5,16,7,17:12)
Block(5,16,8,17:12)
Block(5,16,9,17:12)
Block(5,16,10,LEAVES:12)
Block(5,16,12,LEAVES:12)
Block(5,16,13,LEAVES:12)
Block(5,17,-4,LEAVES:12)
Block(5,17,-3,LEAVES:12)
Block(5,17,-2,LEAVES:12)
Block(5,17,-1,17:12)
Block(5,17,0,LEAVES:12)
Block(5,17,4,LEAVES:12)
Block(5,17,5,17:12)
Block(5,17,6,LEAVES:12)
Block(5,17,7,17:12)
Block(5,17,10,LEAVES:12)
Block(5,17,13,LEAVES:12)
Block(5,18,-5,LEAVES:12)
Block(5,18,-3,LEAVES:12)
Block(5,18,-2,17:12)
Block(5,18,-1,LEAVES:12)
Block(5,18,0,LEAVES:12)
Block(5,18,1,LEAVES:12)
Block(5,18,5,17:12)
Block(5,18,7,LEAVES:12)
Block(5,18,8,LEAVES:12)
Block(5,18,9,LEAVES:12)
Block(5,18,10,LEAVES:12)
Block(5,18,12,LEAVES:12)
Block(5,19,-7,LEAVES:12)
Block(5,19,-6,LEAVES:12)
Block(5,19,-5,LEAVES:12)
Block(5,19,-4,LEAVES:12)
Block(5,19,-3,LEAVES:12)
Block(5,19,-2,LEAVES:12)
Block(5,19,-1,LEAVES:12)
Block(5,19,0,LEAVES:12)
Block(5,19,1,LEAVES:12)
Block(5,19,2,LEAVES:12)
Block(5,19,3,LEAVES:12)
Block(5,19,6,LEAVES:12)
Block(5,19,7,LEAVES:12)
Block(5,19,8,LEAVES:12)
Block(5,19,9,LEAVES:12)
Block(5,20,-7,LEAVES:12)
Block(5,20,-6,LEAVES:12)
Block(5,20,-5,LEAVES:12)
Block(5,20,-4,LEAVES:12)
Block(5,20,-3,LEAVES:12)
Block(5,20,2,LEAVES:12)
Block(5,20,3,LEAVES:12)
Block(5,20,4,LEAVES:12)
Block(5,20,6,LEAVES:12)
Block(5,20,7,LEAVES:12)
Block(5,20,8,LEAVES:12)
Block(5,21,-6,LEAVES:12)
Block(5,21,-5,LEAVES:12)
Block(5,21,-4,LEAVES:12)
Block(5,21,-3,LEAVES:12)
Block(5,21,-2,LEAVES:12)
Block(5,21,-1,LEAVES:12)
Block(5,21,3,LEAVES:12)
Block(5,21,5,LEAVES:12)
Block(5,21,6,LEAVES:12)
Block(5,21,7,LEAVES:12)
Block(5,21,11,LEAVES:12)
Block(5,21,12,LEAVES:12)
Block(5,21,13,LEAVES:12)
Block(5,21,14,LEAVES:12)
Block(5,22,-8,LEAVES:12)
Block(5,22,-5,LEAVES:12)
Block(5,22,-2,LEAVES:12)
Block(5,22,2,LEAVES:12)
Block(5,22,3,LEAVES:12)
Block(5,22,4,LEAVES:12)
Block(5,22,6,LEAVES:12)
Block(5,22,10,LEAVES:12)
Block(5,22,12,LEAVES:12)
Block(5,22,13,LEAVES:12)
Block(5,22,14,LEAVES:12)
Block(5,22,15,LEAVES:12)
Block(5,23,-7,LEAVES:12)
Block(5,23,1,LEAVES:12)
Block(5,23,2,LEAVES:12)
Block(5,23,3,LEAVES:12)
Block(5,23,6,LEAVES:12)
Block(5,23,10,LEAVES:12)
Block(5,23,11,LEAVES:12)
Block(5,23,12,LEAVES:12)
Block(5,23,13,LEAVES:12)
Block(5,23,14,LEAVES:12)
Block(5,24,-2,LEAVES:12)
Block(5,24,2,LEAVES:12)
Block(5,24,4,LEAVES:12)
Block(5,24,5,LEAVES:12)
Block(5,24,6,LEAVES:12)
Block(5,24,7,LEAVES:12)
Block(5,24,11,LEAVES:12)
Block(5,24,12,LEAVES:12)
Block(5,24,13,LEAVES:12)
Block(5,24,14,LEAVES:12)
Block(5,25,-5,LEAVES:12)
Block(5,25,-4,LEAVES:12)
Block(5,25,-3,LEAVES:12)
Block(5,25,-2,LEAVES:12)
Block(5,25,2,LEAVES:12)
Block(5,25,3,LEAVES:12)
Block(5,25,6,LEAVES:12)
Block(5,25,11,LEAVES:12)
Block(5,25,12,LEAVES:12)
Block(5,25,13,LEAVES:12)
Block(5,26,-6,LEAVES:12)
Block(5,26,-3,LEAVES:12)
Block(5,26,-2,LEAVES:12)
Block(5,26,-1,LEAVES:12)
Block(5,26,0,LEAVES:12)
Block(5,26,1,LEAVES:12)
Block(5,26,2,17:12)
Block(5,26,3,17:12)
Block(5,26,4,17:12)
Block(5,26,10,LEAVES:12)
Block(5,27,-2,LEAVES:12)
Block(5,27,-1,LEAVES:12)
Block(5,27,0,LEAVES:12)
Block(5,27,1,LEAVES:12)
Block(5,27,2,17:12)
Block(5,28,-3,LEAVES:12)
Block(5,28,-2,LEAVES:12)
Block(5,28,-1,LEAVES:12)
Block(5,28,0,LEAVES:12)
Block(5,28,3,LEAVES:12)
Block(5,28,7,LEAVES:12)
Block(5,29,-4,LEAVES:12)
Block(5,29,-3,LEAVES:12)
Block(5,29,-2,LEAVES:12)
Block(5,29,2,LEAVES:12)
Block(5,29,3,LEAVES:12)
Block(5,29,4,LEAVES:12)
Block(5,30,-3,LEAVES:12)
Block(5,30,2,LEAVES:12)
Block(5,30,3,LEAVES:12)
Block(5,30,4,LEAVES:12)
Block(5,30,11,LEAVES:12)
Block(5,31,-3,LEAVES:12)
Block(5,31,-2,LEAVES:12)
Block(5,31,-1,LEAVES:12)
Block(5,31,3,LEAVES:12)
Block(5,31,4,17:12)
Block(5,31,5,17:12)
Block(5,32,-2,LEAVES:12)
Block(5,32,-1,LEAVES:12)
Block(5,32,0,LEAVES:12)
Block(5,32,5,17:12)
Block(5,33,-1,LEAVES:12)
Block(5,33,7,LEAVES:12)
Block(5,34,-3,LEAVES:12)
Block(5,34,0,LEAVES:12)
Block(5,34,1,LEAVES:12)
Block(5,34,2,LEAVES:12)
Block(5,34,4,LEAVES:12)
Block(5,34,5,LEAVES:12)
Block(5,34,6,17:12)
Block(5,34,7,LEAVES:12)
Block(5,34,8,LEAVES:12)
Block(5,35,-2,LEAVES:12)
Block(5,35,-1,LEAVES:12)
Block(5,35,0,LEAVES:12)
Block(5,35,1,LEAVES:12)
Block(5,35,5,LEAVES:12)
Block(5,35,6,17:12)
Block(5,35,7,17:12)
Block(5,35,8,LEAVES:12)
Block(5,35,9,LEAVES:12)
Block(5,35,10,LEAVES:12)
Block(5,36,-2,LEAVES:12)
Block(5,36,-1,LEAVES:12)
Block(5,36,0,LEAVES:12)
Block(5,36,7,LEAVES:12)
Block(5,36,8,LEAVES:12)
Block(5,36,9,LEAVES:12)
Block(5,36,11,LEAVES:12)
Block(5,36,12,LEAVES:12)
Block(5,36,13,LEAVES:12)
Block(5,37,-1,LEAVES:12)
Block(5,37,5,LEAVES:12)
Block(5,37,6,LEAVES:12)
Block(5,37,7,LEAVES:12)
Block(5,37,8,LEAVES:12)
Block(5,37,12,LEAVES:12)
Block(5,38,-3,LEAVES:12)
Block(5,38,-2,LEAVES:12)
Block(5,38,-1,LEAVES:12)
Block(5,38,0,LEAVES:12)
Block(5,38,1,LEAVES:12)
Block(5,38,4,LEAVES:12)
Block(5,38,5,LEAVES:12)
Block(5,38,6,LEAVES:12)
Block(5,38,7,LEAVES:12)
Block(5,38,8,LEAVES:12)
Block(5,38,9,LEAVES:12)
Block(5,39,-4,LEAVES:12)
Block(5,39,-3,LEAVES:12)
Block(5,39,-2,LEAVES:12)
Block(5,39,0,LEAVES:12)
Block(5,39,1,LEAVES:12)
Block(5,39,2,LEAVES:12)
Block(5,39,5,LEAVES:12)
Block(5,39,6,LEAVES:12)
Block(5,39,7,LEAVES:12)
Block(5,39,8,LEAVES:12)
Block(5,40,-3,LEAVES:12)
Block(5,40,1,LEAVES:12)
Block(5,40,7,LEAVES:12)
Block(5,42,0,LEAVES:12)
Block(5,43,1,LEAVES:12)
Block(6,13,8,LEAVES:12)
Block(6,13,9,LEAVES:12)
Block(6,13,10,LEAVES:12)
Block(6,14,-3,LEAVES:12)
Block(6,14,-2,LEAVES:12)
Block(6,14,7,17:12)
Block(6,14,9,LEAVES:12)
Block(6,14,10,LEAVES:12)
Block(6,14,11,LEAVES:12)
Block(6,14,12,LEAVES:12)
Block(6,14,13,LEAVES:12)
Block(6,14,14,LEAVES:12)
Block(6,15,-6,LEAVES:12)
Block(6,15,-5,LEAVES:12)
Block(6,15,-4,LEAVES:12)
Block(6,15,-3,LEAVES:12)
Block(6,15,-2,LEAVES:12)
Block(6,15,-1,LEAVES:12)
Block(6,15,8,LEAVES:12)
Block(6,15,9,LEAVES:12)
Block(6,15,10,LEAVES:12)
Block(6,15,11,LEAVES:12)
Block(6,15,12,LEAVES:12)
Block(6,15,13,LEAVES:12)
Block(6,16,-5,LEAVES:12)
Block(6,16,-4,LEAVES:12)
Block(6,16,-3,LEAVES:12)
Block(6,16,-2,LEAVES:12)
Block(6,16,-1,17:12)
Block(6,16,0,17:12)
Block(6,16,2,LEAVES:12)
Block(6,16,3,LEAVES:12)
Block(6,16,4,LEAVES:12)
Block(6,16,7,LEAVES:12)
Block(6,16,8,17:12)
Block(6,16,9,17:12)
Block(6,16,10,LEAVES:12)
Block(6,16,11,LEAVES:12)
Block(6,16,12,LEAVES:12)
Block(6,17,-5,LEAVES:12)
Block(6,17,-4,LEAVES:12)
Block(6,17,-3,LEAVES:12)
Block(6,17,-2,LEAVES:12)
Block(6,17,0,LEAVES:12)
Block(6,17,3,LEAVES:12)
Block(6,17,4,LEAVES:12)
Block(6,17,5,LEAVES:12)
Block(6,17,6,LEAVES:12)
Block(6,17,7,LEAVES:12)
Block(6,17,9,LEAVES:12)
Block(6,17,10,LEAVES:12)
Block(6,17,11,LEAVES:12)
Block(6,17,12,LEAVES:12)
Block(6,17,13,LEAVES:12)
Block(6,17,14,LEAVES:12)
Block(6,18,-6,LEAVES:12)
Block(6,18,-5,LEAVES:12)
Block(6,18,-4,LEAVES:12)
Block(6,18,-3,LEAVES:12)
Block(6,18,-2,LEAVES:12)
Block(6,18,-1,LEAVES:12)
Block(6,18,0,LEAVES:12)
Block(6,18,4,LEAVES:12)
Block(6,18,5,17:12)
Block(6,18,6,LEAVES:12)
Block(6,18,7,LEAVES:12)
Block(6,18,8,17:12)
Block(6,18,9,LEAVES:12)
Block(6,18,10,LEAVES:12)
Block(6,18,11,LEAVES:12)
Block(6,18,12,LEAVES:12)
Block(6,18,13,LEAVES:12)
Block(6,19,-6,LEAVES:12)
Block(6,19,-5,LEAVES:12)
Block(6,19,-4,LEAVES:12)
Block(6,19,-3,LEAVES:12)
Block(6,19,-2,LEAVES:12)
Block(6,19,-1,LEAVES:12)
Block(6,19,0,LEAVES:12)
Block(6,19,2,LEAVES:12)
Block(6,19,3,LEAVES:12)
Block(6,19,4,LEAVES:12)
Block(6,19,5,LEAVES:12)
Block(6,19,6,LEAVES:12)
Block(6,19,7,LEAVES:12)
Block(6,19,8,LEAVES:12)
Block(6,19,12,LEAVES:12)
Block(6,20,-6,LEAVES:12)
Block(6,20,-5,LEAVES:12)
Block(6,20,-4,LEAVES:12)
Block(6,20,-3,LEAVES:12)
Block(6,20,-2,LEAVES:12)
Block(6,20,-1,LEAVES:12)
Block(6,20,3,LEAVES:12)
Block(6,20,4,LEAVES:12)
Block(6,20,6,LEAVES:12)
Block(6,20,7,LEAVES:12)
Block(6,20,8,LEAVES:12)
Block(6,21,-5,LEAVES:12)
Block(6,21,-3,LEAVES:12)
Block(6,21,-2,LEAVES:12)
Block(6,21,6,LEAVES:12)
Block(6,21,7,LEAVES:12)
Block(6,21,13,LEAVES:12)
Block(6,21,14,LEAVES:12)
Block(6,21,15,LEAVES:12)
Block(6,22,1,LEAVES:12)
Block(6,22,2,LEAVES:12)
Block(6,22,3,LEAVES:12)
Block(6,22,14,LEAVES:12)
Block(6,23,2,LEAVES:12)
Block(6,23,11,LEAVES:12)
Block(6,24,3,LEAVES:12)
Block(6,24,4,LEAVES:12)
Block(6,24,5,LEAVES:12)
Block(6,24,6,LEAVES:12)
Block(6,24,10,LEAVES:12)
Block(6,24,11,LEAVES:12)
Block(6,24,12,LEAVES:12)
Block(6,25,-3,LEAVES:12)
Block(6,25,2,LEAVES:12)
Block(6,25,3,LEAVES:12)
Block(6,25,4,LEAVES:12)
Block(6,25,5,17:12)
Block(6,25,7,LEAVES:12)
Block(6,25,11,LEAVES:12)
Block(6,26,-2,LEAVES:12)
Block(6,26,-1,LEAVES:12)
Block(6,26,1,LEAVES:12)
Block(6,26,3,LEAVES:12)
Block(6,26,5,LEAVES:12)
Block(6,27,0,LEAVES:12)
Block(6,27,1,17:12)
Block(6,27,2,17:12)
Block(6,27,3,LEAVES:12)
Block(6,27,7,LEAVES:12)
Block(6,28,-2,LEAVES:12)
Block(6,28,5,LEAVES:12)
Block(6,28,6,LEAVES:12)
Block(6,28,7,LEAVES:12)
Block(6,28,8,LEAVES:12)
Block(6,29,-3,LEAVES:12)
Block(6,29,0,LEAVES:12)
Block(6,29,1,LEAVES:12)
Block(6,29,3,LEAVES:12)
Block(6,29,7,LEAVES:12)
Block(6,30,-1,LEAVES:12)
Block(6,30,3,LEAVES:12)
Block(6,30,4,LEAVES:12)
Block(6,30,5,LEAVES:12)
Block(6,30,7,LEAVES:12)
Block(6,31,-2,LEAVES:12)
Block(6,31,2,LEAVES:12)
Block(6,31,3,LEAVES:12)
Block(6,31,4,LEAVES:12)
Block(6,32,-1,LEAVES:12)
Block(6,32,3,LEAVES:12)
Block(6,32,5,17:12)
Block(6,32,6,17:12)
Block(6,33,7,LEAVES:12)
Block(6,34,1,LEAVES:12)
Block(6,34,3,LEAVES:12)
Block(6,34,5,LEAVES:12)
Block(6,34,6,LEAVES:12)
Block(6,34,7,LEAVES:12)
Block(6,34,8,LEAVES:12)
Block(6,35,0,LEAVES:12)
Block(6,35,4,LEAVES:12)
Block(6,35,5,LEAVES:12)
Block(6,35,6,LEAVES:12)
Block(6,35,7,17:12)
Block(6,35,8,LEAVES:12)
Block(6,35,9,LEAVES:12)
Block(6,36,-1,LEAVES:12)
Block(6,36,5,LEAVES:12)
Block(6,36,6,LEAVES:12)
Block(6,36,7,17:12)
Block(6,36,8,LEAVES:12)
Block(6,36,9,LEAVES:12)
Block(6,36,10,LEAVES:12)
Block(6,36,11,LEAVES:12)
Block(6,36,12,LEAVES:12)
Block(6,37,4,LEAVES:12)
Block(6,37,5,LEAVES:12)
Block(6,37,6,LEAVES:12)
Block(6,37,8,LEAVES:12)
Block(6,37,9,LEAVES:12)
Block(6,37,11,LEAVES:12)
Block(6,37,12,LEAVES:12)
Block(6,37,13,LEAVES:12)
Block(6,38,-2,LEAVES:12)
Block(6,38,0,LEAVES:12)
Block(6,38,5,LEAVES:12)
Block(6,38,8,LEAVES:12)
Block(6,38,12,LEAVES:12)
Block(6,39,-3,LEAVES:12)
Block(6,39,1,LEAVES:12)
Block(6,39,7,LEAVES:12)
Block(7,12,-1,LEAVES:12)
Block(7,13,9,LEAVES:12)
Block(7,14,-4,LEAVES:12)
Block(7,14,-3,LEAVES:12)
Block(7,14,-2,LEAVES:12)
Block(7,14,7,17:12)
Block(7,14,10,LEAVES:12)
Block(7,14,11,LEAVES:12)
Block(7,14,12,LEAVES:12)
Block(7,14,13,LEAVES:12)
Block(7,15,-5,LEAVES:12)
Block(7,15,-3,LEAVES:12)
Block(7,15,-2,LEAVES:12)
Block(7,15,-1,LEAVES:12)
Block(7,15,0,LEAVES:12)
Block(7,15,2,LEAVES:12)
Block(7,15,9,LEAVES:12)
Block(7,15,12,LEAVES:12)
Block(7,15,13,LEAVES:12)
Block(7,15,14,LEAVES:12)
Block(7,16,-6,LEAVES:12)
Block(7,16,-5,LEAVES:12)
Block(7,16,-4,LEAVES:12)
Block(7,16,-2,17:12)
Block(7,16,-1,17:12)
Block(7,16,0,LEAVES:12)
Block(7,16,3,LEAVES:12)
Block(7,16,4,LEAVES:12)
Block(7,16,5,LEAVES:12)
Block(7,16,6,LEAVES:12)
Block(7,16,7,LEAVES:12)
Block(7,16,8,LEAVES:12)
Block(7,16,9,17:12)
Block(7,16,10,LEAVES:12)
Block(7,16,13,LEAVES:12)
Block(7,17,-6,LEAVES:12)
Block(7,17,-5,LEAVES:12)
Block(7,17,-4,LEAVES:12)
Block(7,17,-3,LEAVES:12)
Block(7,17,-2,17:12)
Block(7,17,-1,LEAVES:12)
Block(7,17,0,LEAVES:12)
Block(7,17,1,LEAVES:12)
Block(7,17,4,LEAVES:12)
Block(7,17,5,LEAVES:12)
Block(7,17,6,LEAVES:12)
Block(7,17,7,LEAVES:12)
Block(7,17,10,LEAVES:12)
Block(7,17,13,LEAVES:12)
Block(7,18,-5,LEAVES:12)
Block(7,18,-3,17:12)
Block(7,18,-2,LEAVES:12)
Block(7,18,-1,LEAVES:12)
Block(7,18,0,LEAVES:12)
Block(7,18,5,LEAVES:12)
Block(7,18,6,LEAVES:12)
Block(7,18,7,LEAVES:12)
Block(7,18,12,LEAVES:12)
Block(7,18,13,LEAVES:12)
Block(7,18,14,LEAVES:12)
Block(7,19,-5,LEAVES:12)
Block(7,19,-4,LEAVES:12)
Block(7,19,-3,LEAVES:12)
Block(7,19,-2,LEAVES:12)
Block(7,19,-1,LEAVES:12)
Block(7,19,0,LEAVES:12)
Block(7,19,1,LEAVES:12)
Block(7,19,3,LEAVES:12)
Block(7,19,5,LEAVES:12)
Block(7,19,6,LEAVES:12)
Block(7,19,8,LEAVES:12)
Block(7,19,10,LEAVES:12)
Block(7,19,13,LEAVES:12)
Block(7,20,-5,LEAVES:12)
Block(7,20,-4,LEAVES:12)
Block(7,20,-3,LEAVES:12)
Block(7,20,-2,LEAVES:12)
Block(7,20,-1,LEAVES:12)
Block(7,20,0,LEAVES:12)
Block(7,20,5,LEAVES:12)
Block(7,20,6,LEAVES:12)
Block(7,20,7,LEAVES:12)
Block(7,20,8,LEAVES:12)
Block(7,20,9,LEAVES:12)
Block(7,21,-2,LEAVES:12)
Block(7,21,6,LEAVES:12)
Block(7,21,7,LEAVES:12)
Block(7,21,8,LEAVES:12)
Block(7,21,14,LEAVES:12)
Block(7,22,2,LEAVES:12)
Block(7,22,7,LEAVES:12)
Block(7,23,3,LEAVES:12)
Block(7,24,3,LEAVES:12)
Block(7,24,4,LEAVES:12)
Block(7,24,5,LEAVES:12)
Block(7,24,6,LEAVES:12)
Block(7,24,7,LEAVES:12)
Block(7,24,11,LEAVES:12)
Block(7,25,3,LEAVES:12)
Block(7,25,4,LEAVES:12)
Block(7,25,5,LEAVES:12)
Block(7,25,6,LEAVES:12)
Block(7,25,7,LEAVES:12)
Block(7,25,8,LEAVES:12)
Block(7,26,-2,LEAVES:12)
Block(7,26,-1,LEAVES:12)
Block(7,26,0,LEAVES:12)
Block(7,26,3,LEAVES:12)
Block(7,26,4,LEAVES:12)
Block(7,26,7,LEAVES:12)
Block(7,27,-1,LEAVES:12)
Block(7,27,0,LEAVES:12)
Block(7,27,1,LEAVES:12)
Block(7,27,2,17:12)
Block(7,27,3,LEAVES:12)
Block(7,27,4,LEAVES:12)
Block(7,27,5,LEAVES:12)
Block(7,27,6,LEAVES:12)
Block(7,27,7,LEAVES:12)
Block(7,27,8,LEAVES:12)
Block(7,28,0,LEAVES:12)
Block(7,28,1,LEAVES:12)
Block(7,28,2,17:12)
Block(7,28,3,LEAVES:12)
Block(7,28,4,LEAVES:12)
Block(7,28,5,LEAVES:12)
Block(7,28,6,LEAVES:12)
Block(7,28,7,LEAVES:12)
Block(7,29,-1,LEAVES:12)
Block(7,29,0,LEAVES:12)
Block(7,29,1,LEAVES:12)
Block(7,29,2,LEAVES:12)
Block(7,29,5,LEAVES:12)
Block(7,29,6,LEAVES:12)
Block(7,30,-2,LEAVES:12)
Block(7,30,-1,LEAVES:12)
Block(7,30,0,LEAVES:12)
Block(7,30,1,LEAVES:12)
Block(7,30,4,LEAVES:12)
Block(7,30,6,LEAVES:12)
Block(7,30,7,LEAVES:12)
Block(7,30,8,LEAVES:12)
Block(7,31,-1,LEAVES:12)
Block(7,31,3,LEAVES:12)
Block(7,31,7,LEAVES:12)
Block(7,32,4,LEAVES:12)
Block(7,32,6,17:12)
Block(7,33,3,LEAVES:12)
Block(7,33,6,LEAVES:12)
Block(7,33,7,LEAVES:12)
Block(7,33,8,LEAVES:12)
Block(7,34,2,LEAVES:12)
Block(7,34,3,LEAVES:12)
Block(7,34,4,LEAVES:12)
Block(7,34,5,LEAVES:12)
Block(7,34,6,LEAVES:12)
Block(7,34,7,LEAVES:12)
Block(7,34,9,LEAVES:12)
Block(7,35,3,LEAVES:12)
Block(7,35,5,LEAVES:12)
Block(7,35,6,LEAVES:12)
Block(7,35,8,LEAVES:12)
Block(7,36,5,LEAVES:12)
Block(7,36,7,17:12)
Block(7,36,9,LEAVES:12)
Block(7,36,11,LEAVES:12)
Block(7,37,5,LEAVES:12)
Block(7,37,6,LEAVES:12)
Block(7,37,7,LEAVES:12)
Block(7,37,8,LEAVES:12)
Block(7,37,9,LEAVES:12)
Block(7,37,12,LEAVES:12)
Block(7,38,8,LEAVES:12)
Block(8,12,-2,LEAVES:12)
Block(8,12,-1,LEAVES:12)
Block(8,12,0,LEAVES:12)
Block(8,13,-1,LEAVES:12)
Block(8,14,-3,LEAVES:12)
Block(8,14,-2,LEAVES:12)
Block(8,14,-1,LEAVES:12)
Block(8,14,2,LEAVES:12)
Block(8,14,12,LEAVES:12)
Block(8,14,13,LEAVES:12)
Block(8,14,14,LEAVES:12)
Block(8,15,-6,LEAVES:12)
Block(8,15,-5,LEAVES:12)
Block(8,15,-4,LEAVES:12)
Block(8,15,-3,LEAVES:12)
Block(8,15,-2,17:12)
Block(8,15,-1,LEAVES:12)
Block(8,15,1,LEAVES:12)
Block(8,15,2,LEAVES:12)
Block(8,15,3,LEAVES:12)
Block(8,15,13,LEAVES:12)
Block(8,16,-5,LEAVES:12)
Block(8,16,-3,LEAVES:12)
Block(8,16,-2,17:12)
Block(8,16,-1,LEAVES:12)
Block(8,16,0,LEAVES:12)
Block(8,16,1,LEAVES:12)
Block(8,16,2,LEAVES:12)
Block(8,16,4,LEAVES:12)
Block(8,16,5,LEAVES:12)
Block(8,16,6,LEAVES:12)
Block(8,16,7,LEAVES:12)
Block(8,16,9,LEAVES:12)
Block(8,16,10,17:12)
Block(8,16,11,LEAVES:12)
Block(8,17,-5,LEAVES:12)
Block(8,17,-3,LEAVES:12)
Block(8,17,-2,LEAVES:12)
Block(8,17,-1,LEAVES:12)
Block(8,17,0,LEAVES:12)
Block(8,17,6,LEAVES:12)
Block(8,17,8,LEAVES:12)
Block(8,17,10,17:12)
Block(8,17,11,LEAVES:12)
Block(8,18,-3,LEAVES:12)
Block(8,18,-2,LEAVES:12)
Block(8,18,-1,LEAVES:12)
Block(8,18,0,LEAVES:12)
Block(8,18,1,LEAVES:12)
Block(8,18,5,LEAVES:12)
Block(8,18,10,17:12)
Block(8,18,13,LEAVES:12)
Block(8,19,-4,LEAVES:12)
Block(8,19,-2,LEAVES:12)
Block(8,19,-1,LEAVES:12)
Block(8,19,0,LEAVES:12)
Block(8,19,8,LEAVES:12)
Block(8,19,9,LEAVES:12)
Block(8,19,10,LEAVES:12)
Block(8,19,11,LEAVES:12)
Block(8,20,-2,LEAVES:12)
Block(8,20,-1,LEAVES:12)
Block(8,20,6,LEAVES:12)
Block(8,20,7,LEAVES:12)
Block(8,20,8,LEAVES:12)
Block(8,20,9,LEAVES:12)
Block(8,20,10,LEAVES:12)
Block(8,21,5,LEAVES:12)
Block(8,21,6,LEAVES:12)
Block(8,21,7,LEAVES:12)
Block(8,21,8,LEAVES:12)
Block(8,21,9,LEAVES:12)
Block(8,22,6,LEAVES:12)
Block(8,23,2,LEAVES:12)
Block(8,23,3,LEAVES:12)
Block(8,23,4,LEAVES:12)
Block(8,24,3,LEAVES:12)
Block(8,24,4,LEAVES:12)
Block(8,24,5,LEAVES:12)
Block(8,24,6,LEAVES:12)
Block(8,24,7,LEAVES:12)
Block(8,24,8,LEAVES:12)
Block(8,25,4,LEAVES:12)
Block(8,25,7,LEAVES:12)
Block(8,26,-1,LEAVES:12)
Block(8,27,-2,LEAVES:12)
Block(8,27,-1,LEAVES:12)
Block(8,27,0,LEAVES:12)
Block(8,27,3,LEAVES:12)
Block(8,27,4,LEAVES:12)
Block(8,27,5,LEAVES:12)
Block(8,27,6,LEAVES:12)
Block(8,27,7,LEAVES:12)
Block(8,28,-1,LEAVES:12)
Block(8,28,0,LEAVES:12)
Block(8,28,1,17:12)
Block(8,28,2,LEAVES:12)
Block(8,28,3,LEAVES:12)
Block(8,28,4,LEAVES:12)
Block(8,28,5,LEAVES:12)
Block(8,28,6,LEAVES:12)
Block(8,29,-2,LEAVES:12)
Block(8,29,-1,LEAVES:12)
Block(8,29,0,LEAVES:12)
Block(8,29,1,LEAVES:12)
Block(8,29,2,LEAVES:12)
Block(8,29,3,LEAVES:12)
Block(8,29,4,LEAVES:12)
Block(8,30,-1,LEAVES:12)
Block(8,30,2,LEAVES:12)
Block(8,30,5,LEAVES:12)
Block(8,30,6,LEAVES:12)
Block(8,30,7,LEAVES:12)
Block(8,31,5,LEAVES:12)
Block(8,31,6,LEAVES:12)
Block(8,31,7,LEAVES:12)
Block(8,31,8,LEAVES:12)
Block(8,32,4,LEAVES:12)
Block(8,32,7,LEAVES:12)
Block(8,33,2,LEAVES:12)
Block(8,33,3,LEAVES:12)
Block(8,33,4,LEAVES:12)
Block(8,33,6,LEAVES:12)
Block(8,33,7,LEAVES:12)
Block(8,33,9,LEAVES:12)
Block(8,34,3,LEAVES:12)
Block(8,34,4,LEAVES:12)
Block(8,34,5,LEAVES:12)
Block(8,34,6,LEAVES:12)
Block(8,34,8,LEAVES:12)
Block(8,34,9,LEAVES:12)
Block(8,34,10,LEAVES:12)
Block(8,35,4,LEAVES:12)
Block(8,35,5,LEAVES:12)
Block(8,35,7,LEAVES:12)
Block(8,35,9,LEAVES:12)
Block(8,36,4,LEAVES:12)
Block(8,36,5,LEAVES:12)
Block(8,36,6,LEAVES:12)
Block(8,37,5,LEAVES:12)
Block(8,37,6,LEAVES:12)
Block(8,37,7,LEAVES:12)
Block(8,37,8,LEAVES:12)
Block(8,38,7,LEAVES:12)
Block(8,38,8,LEAVES:12)
Block(8,38,9,LEAVES:12)
Block(8,39,8,LEAVES:12)
Block(9,12,-1,LEAVES:12)
Block(9,12,0,LEAVES:12)
Block(9,12,1,LEAVES:12)
Block(9,12,2,LEAVES:12)
Block(9,13,-2,LEAVES:12)
Block(9,13,-1,LEAVES:12)
Block(9,13,0,LEAVES:12)
Block(9,13,3,LEAVES:12)
Block(9,14,-3,LEAVES:12)
Block(9,14,-2,LEAVES:12)
Block(9,14,-1,LEAVES:12)
Block(9,14,0,17:12)
Block(9,14,1,LEAVES:12)
Block(9,14,2,LEAVES:12)
Block(9,14,3,LEAVES:12)
Block(9,14,13,LEAVES:12)
Block(9,15,-5,LEAVES:12)
Block(9,15,-4,LEAVES:12)
Block(9,15,-3,LEAVES:12)
Block(9,15,-1,LEAVES:12)
Block(9,15,0,LEAVES:12)
