#######################################################################
# +-----------------------------------------------------------------+ #
# |                            BO3 object                           | #
# +-----------------------------------------------------------------+ #
#######################################################################

# The descriptions in this file are accurate only for TerrainControl and OTG.
# For MCW and OTG+ these descriptions are only accurate if the BO3 is used as a CustomObject.
# MCW and OTG+ completely reimplemented CustomStructure, check the MCW/OTG+ documentation for more information.

# This is the config file of a custom object.
# If you add this object correctly to your BiomeConfigs, it will spawn in the world.

# This is the creator of this BO3 object
Author: Unknown

# A short description of this BO3 object
Description: This BO3 was converted from a schematic using OTGEdit. The author and description information of the schematic could not be found. If you know who the author of the schematic is then please add this information.

# The BO3 version, don't change this! It can be used by external applications to do a version check.
Version: 3

# The settings mode, WriteAll, WriteWithoutComments or WriteDisable. See WorldConfig.
SettingsMode: WriteDisable

#######################################################################
# +-----------------------------------------------------------------+ #
# |                          Main settings                          | #
# +-----------------------------------------------------------------+ #
#######################################################################

# This needs to be set to true to spawn the object in the Tree and Sapling resources.
Tree: tree

# The frequency of the BO3 from 1 to 200. Tries this many times to spawn this BO3 when using the CustomObject(...) resource.
# Ignored by Tree(..), Sapling(..) and CustomStructure(..)
Frequency: 40

# The rarity of the BO3 from 0 to 100. Each spawn attempt has rarity% chance to succeed when using the CustomObject(...) resource.
# Ignored by Tree(..), Sapling(..) and CustomStructure(..)
Rarity: 100.0

# If you set this to true, the BO3 will be placed with a random rotation.
RotateRandomly: false

# The spawn height of the BO3 - randomY, highestBlock or highestSolidBlock.
SpawnHeight: highestSolidBlock
SpawnHeightOffset: -1
# The height limits for the BO3.
MinHeight: 0

MaxHeight: 256

# Objects can have other objects attached to it: branches. Branches can also
# have branches attached to it, which can also have branches, etc. This is the
# maximum branch depth for this objects.
MaxBranchDepth: 10

# When spawned with the UseWorld keyword, this BO3 should NOT spawn in the following biomes.
# If you writer.write the BO3 name directly in the BiomeConfigs, this will be ignored.
ExcludedBiomes: All

# To optimise this BO3 for faster loading times you can use Notepad++ to find/replace comments and abbreviate things.
# Notepad++ find/replace with regex:
# Find: ^[#;].* replace to nothing removes all lines starting with # 
# Find: ^\s*$ replace to nothing removes most empty lines 
# Notepad++ find/replace without regex:
# *Warning: This will only work for OTG 1.10.2 v21 / OTG 1.11.2 v6 or higher. B( is not recognised by lower versions.
# Find: Block( replace to B(

#######################################################################
# +-----------------------------------------------------------------+ #
# |                      Source block settings                      | #
# +-----------------------------------------------------------------+ #
#######################################################################

# The block(s) the BO3 should spawn in.
SourceBlocks: AIR,GRASS,DIRT,STONE

# The maximum percentage of the BO3 that can be outside the SourceBlock.
# The BO3 won't be placed on a location with more blocks outside the SourceBlock than this percentage.
MaxPercentageOutsideSourceBlock: 0

# What to do when a block is about to be placed outside the SourceBlock? (dontPlace, placeAnyway)
OutsideSourceBlock: dontPlace

#######################################################################
# +-----------------------------------------------------------------+ #
# |                              Blocks                             | #
# +-----------------------------------------------------------------+ #
#######################################################################

# All the blocks used in the BO3 are listed here. Possible blocks:
# Block(x,y,z,id[.data][,nbtfile.nbt) or B(x,y,z,id[.data][,nbtfile.nbt)
# RandomBlock(x,y,z,id[:data][,nbtfile.nbt],chance[,id[:data][,nbtfile.nbt],chance[,...]])
# So RandomBlock(0,0,0,CHEST,chest.nbt,50,CHEST,anotherchest.nbt,100) will spawn a chest at
# the BO3 origin, and give it a 50% chance to have the contents of chest.nbt, or, if that
# fails, a 100% percent chance to have the contents of anotherchest.nbt.

Block(-11,20,11,LEAVES:12)
Block(-11,21,10,LEAVES:12)
Block(-10,17,9,LEAVES:12)
Block(-10,18,10,LEAVES:12)
Block(-10,20,10,LEAVES:12)
Block(-10,20,11,LEAVES:12)
Block(-10,20,12,LEAVES:12)
Block(-10,21,9,LEAVES:12)
Block(-10,21,10,LEAVES:12)
Block(-10,21,11,LEAVES:12)
Block(-10,22,7,LEAVES:12)
Block(-10,22,10,LEAVES:12)
Block(-9,17,8,LEAVES:12)
Block(-9,17,9,LEAVES:12)
Block(-9,17,10,LEAVES:12)
Block(-9,18,6,LEAVES:12)
Block(-9,18,9,LEAVES:12)
Block(-9,18,10,LEAVES:12)
Block(-9,18,11,LEAVES:12)
Block(-9,19,7,LEAVES:12)
Block(-9,19,10,LEAVES:12)
Block(-9,20,11,LEAVES:12)
Block(-9,21,7,LEAVES:12)
Block(-9,21,10,LEAVES:12)
Block(-9,21,11,LEAVES:12)
Block(-9,21,12,LEAVES:12)
Block(-9,22,6,LEAVES:12)
Block(-9,22,7,LEAVES:12)
Block(-9,22,8,LEAVES:12)
Block(-9,22,11,LEAVES:12)
Block(-9,23,7,LEAVES:12)
Block(-9,23,10,LEAVES:12)
Block(-9,24,11,LEAVES:12)
Block(-8,17,9,LEAVES:12)
Block(-8,18,5,LEAVES:12)
Block(-8,18,6,LEAVES:12)
Block(-8,18,7,LEAVES:12)
Block(-8,18,8,LEAVES:12)
Block(-8,18,9,LEAVES:12)
Block(-8,18,10,LEAVES:12)
Block(-8,19,6,LEAVES:12)
Block(-8,19,7,LEAVES:12)
Block(-8,19,8,LEAVES:12)
Block(-8,19,9,LEAVES:12)
Block(-8,19,10,LEAVES:12)
Block(-8,20,7,LEAVES:12)
Block(-8,20,9,LEAVES:12)
Block(-8,21,6,LEAVES:12)
Block(-8,21,7,LEAVES:12)
Block(-8,21,8,LEAVES:12)
Block(-8,21,11,LEAVES:12)
Block(-8,22,7,LEAVES:12)
Block(-8,22,8,LEAVES:12)
Block(-8,22,9,LEAVES:12)
Block(-8,22,11,LEAVES:12)
Block(-8,22,14,LEAVES:12)
Block(-8,23,8,LEAVES:12)
Block(-8,23,9,LEAVES:12)
Block(-8,23,10,LEAVES:12)
Block(-8,23,11,LEAVES:12)
Block(-8,23,13,LEAVES:12)
Block(-8,24,10,LEAVES:12)
Block(-8,24,11,LEAVES:12)
Block(-8,24,12,LEAVES:12)
Block(-8,25,11,LEAVES:12)
Block(-8,26,2,LEAVES:12)
Block(-8,27,3,LEAVES:12)
Block(-8,29,1,LEAVES:12)
Block(-8,30,0,LEAVES:12)
Block(-7,17,5,LEAVES:12)
Block(-7,18,4,LEAVES:12)
Block(-7,18,6,LEAVES:12)
Block(-7,18,9,LEAVES:12)
Block(-7,19,1,LEAVES:12)
Block(-7,19,5,LEAVES:12)
Block(-7,19,6,LEAVES:12)
Block(-7,19,7,LEAVES:12)
Block(-7,19,13,LEAVES:12)
Block(-7,20,2,LEAVES:12)
Block(-7,20,6,LEAVES:12)
Block(-7,20,8,LEAVES:12)
Block(-7,20,9,17:12)
Block(-7,20,10,LEAVES:12)
Block(-7,20,12,LEAVES:12)
Block(-7,21,7,LEAVES:12)
Block(-7,21,9,LEAVES:12)
Block(-7,21,11,LEAVES:12)
Block(-7,22,8,LEAVES:12)
Block(-7,22,10,LEAVES:12)
Block(-7,22,11,LEAVES:12)
Block(-7,22,12,LEAVES:12)
Block(-7,22,13,LEAVES:12)
Block(-7,22,14,LEAVES:12)
Block(-7,22,15,LEAVES:12)
Block(-7,23,10,LEAVES:12)
Block(-7,23,11,LEAVES:12)
Block(-7,23,12,LEAVES:12)
Block(-7,23,13,LEAVES:12)
Block(-7,23,14,LEAVES:12)
Block(-7,24,9,LEAVES:12)
Block(-7,24,10,LEAVES:12)
Block(-7,24,11,LEAVES:12)
Block(-7,24,13,LEAVES:12)
Block(-7,25,10,LEAVES:12)
Block(-7,26,1,LEAVES:12)
Block(-7,26,2,LEAVES:12)
Block(-7,26,3,LEAVES:12)
Block(-7,27,2,LEAVES:12)
Block(-7,27,3,LEAVES:12)
Block(-7,27,4,LEAVES:12)
Block(-7,28,3,LEAVES:12)
Block(-7,28,4,LEAVES:12)
Block(-7,29,0,LEAVES:12)
Block(-7,29,1,LEAVES:12)
Block(-7,29,2,LEAVES:12)
Block(-7,29,5,LEAVES:12)
Block(-7,30,-1,LEAVES:12)
Block(-7,30,0,LEAVES:12)
Block(-7,30,1,LEAVES:12)
Block(-7,31,0,LEAVES:12)
Block(-6,16,2,LEAVES:12)
Block(-6,17,1,LEAVES:12)
Block(-6,17,4,LEAVES:12)
Block(-6,17,5,LEAVES:12)
Block(-6,17,6,LEAVES:12)
Block(-6,18,2,LEAVES:12)
Block(-6,18,3,LEAVES:12)
Block(-6,18,4,LEAVES:12)
Block(-6,18,5,LEAVES:12)
Block(-6,19,0,LEAVES:12)
Block(-6,19,1,LEAVES:12)
Block(-6,19,2,LEAVES:12)
Block(-6,19,4,LEAVES:12)
Block(-6,19,6,LEAVES:12)
Block(-6,19,9,17:12)
Block(-6,19,12,LEAVES:12)
Block(-6,19,13,LEAVES:12)
Block(-6,19,14,LEAVES:12)
Block(-6,20,1,LEAVES:12)
Block(-6,20,2,LEAVES:12)
Block(-6,20,3,LEAVES:12)
Block(-6,20,8,LEAVES:12)
Block(-6,20,9,LEAVES:12)
Block(-6,20,10,LEAVES:12)
Block(-6,20,11,LEAVES:12)
Block(-6,20,12,LEAVES:12)
Block(-6,20,13,LEAVES:12)
Block(-6,21,2,LEAVES:12)
Block(-6,21,8,LEAVES:12)
Block(-6,21,9,LEAVES:12)
Block(-6,21,10,LEAVES:12)
Block(-6,21,11,LEAVES:12)
Block(-6,21,12,17:12)
Block(-6,22,9,LEAVES:12)
Block(-6,22,10,LEAVES:12)
Block(-6,22,11,LEAVES:12)
Block(-6,22,12,LEAVES:12)
Block(-6,22,13,LEAVES:12)
Block(-6,22,14,LEAVES:12)
Block(-6,23,10,LEAVES:12)
Block(-6,23,12,LEAVES:12)
Block(-6,23,13,LEAVES:12)
Block(-6,24,9,LEAVES:12)
Block(-6,24,10,LEAVES:12)
Block(-6,25,-2,LEAVES:12)
Block(-6,26,-1,LEAVES:12)
Block(-6,26,2,LEAVES:12)
Block(-6,26,3,LEAVES:12)
Block(-6,26,4,LEAVES:12)
Block(-6,27,3,LEAVES:12)
Block(-6,28,1,LEAVES:12)
Block(-6,28,3,LEAVES:12)
Block(-6,28,4,LEAVES:12)
Block(-6,28,5,LEAVES:12)
Block(-6,29,0,LEAVES:12)
Block(-6,29,1,LEAVES:12)
Block(-6,29,4,LEAVES:12)
Block(-6,29,5,LEAVES:12)
Block(-6,29,6,LEAVES:12)
Block(-6,30,0,LEAVES:12)
Block(-6,30,1,LEAVES:12)
Block(-6,30,2,LEAVES:12)
Block(-6,30,5,LEAVES:12)
Block(-6,31,1,LEAVES:12)
Block(-6,31,6,LEAVES:12)
Block(-6,32,7,LEAVES:12)
Block(-6,34,1,LEAVES:12)
Block(-6,34,9,LEAVES:12)
Block(-6,35,0,LEAVES:12)
Block(-6,35,8,LEAVES:12)
Block(-6,37,-1,LEAVES:12)
Block(-6,38,0,LEAVES:12)
Block(-5,0,5,17:12)
Block(-5,0,6,17:12)
Block(-5,16,1,LEAVES:12)
Block(-5,16,2,LEAVES:12)
Block(-5,16,3,LEAVES:12)
Block(-5,17,0,LEAVES:12)
Block(-5,17,1,LEAVES:12)
Block(-5,17,2,LEAVES:12)
Block(-5,17,4,LEAVES:12)
Block(-5,17,5,LEAVES:12)
Block(-5,17,6,LEAVES:12)
Block(-5,18,1,LEAVES:12)
Block(-5,18,2,LEAVES:12)
Block(-5,18,3,LEAVES:12)
Block(-5,18,4,LEAVES:12)
Block(-5,18,5,LEAVES:12)
Block(-5,18,6,LEAVES:12)
Block(-5,18,7,17:12)
Block(-5,18,8,17:12)
Block(-5,19,0,LEAVES:12)
Block(-5,19,1,LEAVES:12)
Block(-5,19,2,LEAVES:12)
Block(-5,19,4,17:12)
Block(-5,19,5,LEAVES:12)
Block(-5,19,6,LEAVES:12)
Block(-5,19,7,LEAVES:12)
Block(-5,19,8,17:12)
Block(-5,19,9,17:12)
Block(-5,19,10,17:12)
Block(-5,19,11,LEAVES:12)
Block(-5,19,12,LEAVES:12)
Block(-5,19,13,LEAVES:12)
Block(-5,20,0,LEAVES:12)
Block(-5,20,1,LEAVES:12)
Block(-5,20,2,LEAVES:12)
Block(-5,20,6,LEAVES:12)
Block(-5,20,10,LEAVES:12)
Block(-5,20,11,17:12)
Block(-5,20,12,LEAVES:12)
Block(-5,21,1,LEAVES:12)
Block(-5,21,6,LEAVES:12)
Block(-5,21,9,LEAVES:12)
Block(-5,21,11,LEAVES:12)
Block(-5,22,6,LEAVES:12)
Block(-5,22,10,LEAVES:12)
Block(-5,22,11,LEAVES:12)
Block(-5,22,13,LEAVES:12)
Block(-5,23,9,LEAVES:12)
Block(-5,24,8,LEAVES:12)
Block(-5,24,9,LEAVES:12)
Block(-5,24,10,LEAVES:12)
Block(-5,25,-3,LEAVES:12)
Block(-5,25,-2,LEAVES:12)
Block(-5,25,-1,LEAVES:12)
Block(-5,25,9,LEAVES:12)
Block(-5,26,-2,LEAVES:12)
Block(-5,26,-1,LEAVES:12)
Block(-5,26,0,LEAVES:12)
Block(-5,26,2,LEAVES:12)
Block(-5,26,3,LEAVES:12)
Block(-5,26,4,LEAVES:12)
Block(-5,27,-1,LEAVES:12)
Block(-5,27,2,LEAVES:12)
Block(-5,28,0,LEAVES:12)
Block(-5,28,1,LEAVES:12)
Block(-5,28,2,17:12)
Block(-5,28,3,17:12)
Block(-5,28,4,LEAVES:12)
Block(-5,29,-1,LEAVES:12)
Block(-5,29,0,LEAVES:12)
Block(-5,29,1,LEAVES:12)
Block(-5,29,2,LEAVES:12)
Block(-5,29,3,LEAVES:12)
Block(-5,29,4,LEAVES:12)
Block(-5,29,5,LEAVES:12)
Block(-5,30,0,LEAVES:12)
Block(-5,30,1,LEAVES:12)
Block(-5,30,3,LEAVES:12)
Block(-5,30,4,LEAVES:12)
Block(-5,31,5,LEAVES:12)
Block(-5,31,6,LEAVES:12)
Block(-5,31,7,LEAVES:12)
Block(-5,32,6,LEAVES:12)
Block(-5,32,7,LEAVES:12)
Block(-5,32,8,LEAVES:12)
Block(-5,32,11,LEAVES:12)
Block(-5,33,7,LEAVES:12)
Block(-5,33,10,LEAVES:12)
Block(-5,34,0,LEAVES:12)
Block(-5,34,1,LEAVES:12)
Block(-5,34,2,LEAVES:12)
Block(-5,34,8,LEAVES:12)
Block(-5,34,9,LEAVES:12)
Block(-5,34,10,LEAVES:12)
Block(-5,35,-1,LEAVES:12)
Block(-5,35,0,LEAVES:12)
Block(-5,35,1,LEAVES:12)
Block(-5,35,3,LEAVES:12)
Block(-5,35,7,LEAVES:12)
Block(-5,35,8,LEAVES:12)
Block(-5,35,9,LEAVES:12)
Block(-5,36,0,LEAVES:12)
Block(-5,36,8,LEAVES:12)
Block(-5,37,-2,LEAVES:12)
Block(-5,37,-1,LEAVES:12)
Block(-5,37,0,LEAVES:12)
Block(-5,37,4,LEAVES:12)
Block(-5,38,-1,LEAVES:12)
Block(-5,38,0,LEAVES:12)
Block(-5,38,1,LEAVES:12)
Block(-5,38,5,LEAVES:12)
Block(-5,38,8,LEAVES:12)
Block(-5,39,0,LEAVES:12)
Block(-5,39,7,LEAVES:12)
Block(-5,40,5,LEAVES:12)
Block(-5,41,4,LEAVES:12)
Block(-4,0,4,17:12)
Block(-4,0,5,17:12)
Block(-4,1,4,17:12)
Block(-4,1,5,17:12)
Block(-4,16,-1,LEAVES:12)
Block(-4,16,0,LEAVES:12)
Block(-4,16,1,LEAVES:12)
Block(-4,16,2,LEAVES:12)
Block(-4,17,0,LEAVES:12)
Block(-4,17,1,LEAVES:12)
Block(-4,17,3,LEAVES:12)
Block(-4,17,5,LEAVES:12)
Block(-4,18,0,LEAVES:12)
Block(-4,18,1,LEAVES:12)
Block(-4,18,2,LEAVES:12)
Block(-4,18,3,LEAVES:12)
Block(-4,18,4,LEAVES:12)
Block(-4,18,5,LEAVES:12)
Block(-4,18,6,LEAVES:12)
Block(-4,18,8,17:12)
Block(-4,19,1,LEAVES:12)
Block(-4,19,3,LEAVES:12)
Block(-4,19,4,17:12)
Block(-4,19,5,LEAVES:12)
Block(-4,19,6,LEAVES:12)
Block(-4,19,7,LEAVES:12)
Block(-4,19,8,LEAVES:12)
Block(-4,19,12,LEAVES:12)
Block(-4,20,1,LEAVES:12)
Block(-4,20,4,LEAVES:12)
Block(-4,20,5,17:12)
Block(-4,20,6,LEAVES:12)
Block(-4,20,7,LEAVES:12)
Block(-4,21,5,LEAVES:12)
Block(-4,21,6,LEAVES:12)
Block(-4,21,7,LEAVES:12)
Block(-4,21,11,LEAVES:12)
Block(-4,21,13,LEAVES:12)
Block(-4,22,5,LEAVES:12)
Block(-4,22,6,LEAVES:12)
Block(-4,22,7,LEAVES:12)
Block(-4,22,14,LEAVES:12)
Block(-4,23,6,LEAVES:12)
Block(-4,23,8,LEAVES:12)
Block(-4,23,9,LEAVES:12)
Block(-4,23,10,LEAVES:12)
Block(-4,24,9,LEAVES:12)
Block(-4,24,10,LEAVES:12)
Block(-4,24,11,LEAVES:12)
Block(-4,24,16,LEAVES:12)
Block(-4,25,-2,LEAVES:12)
Block(-4,25,-1,LEAVES:12)
Block(-4,25,0,LEAVES:12)
Block(-4,25,10,LEAVES:12)
Block(-4,25,15,LEAVES:12)
Block(-4,26,-1,LEAVES:12)
Block(-4,26,1,LEAVES:12)
Block(-4,26,2,LEAVES:12)
Block(-4,26,3,LEAVES:12)
Block(-4,26,4,LEAVES:12)
Block(-4,26,5,LEAVES:12)
Block(-4,27,0,LEAVES:12)
Block(-4,27,1,LEAVES:12)
Block(-4,27,2,LEAVES:12)
Block(-4,27,3,17:12)
Block(-4,27,4,LEAVES:12)
Block(-4,28,1,LEAVES:12)
Block(-4,28,2,LEAVES:12)
Block(-4,28,4,LEAVES:12)
Block(-4,29,0,LEAVES:12)
Block(-4,29,1,LEAVES:12)
Block(-4,29,2,LEAVES:12)
Block(-4,29,3,LEAVES:12)
Block(-4,29,4,LEAVES:12)
Block(-4,30,1,LEAVES:12)
Block(-4,30,2,LEAVES:12)
Block(-4,30,3,LEAVES:12)
Block(-4,30,4,LEAVES:12)
Block(-4,31,3,LEAVES:12)
Block(-4,31,6,LEAVES:12)
Block(-4,31,7,LEAVES:12)
Block(-4,31,8,LEAVES:12)
Block(-4,32,7,LEAVES:12)
Block(-4,32,10,LEAVES:12)
Block(-4,32,11,LEAVES:12)
Block(-4,32,12,LEAVES:12)
Block(-4,33,8,LEAVES:12)
Block(-4,33,9,LEAVES:12)
Block(-4,33,10,LEAVES:12)
Block(-4,33,11,LEAVES:12)
Block(-4,34,-1,LEAVES:12)
Block(-4,34,0,LEAVES:12)
Block(-4,34,1,LEAVES:12)
Block(-4,34,9,LEAVES:12)
Block(-4,34,10,LEAVES:12)
Block(-4,35,0,LEAVES:12)
Block(-4,35,2,LEAVES:12)
Block(-4,35,3,LEAVES:12)
Block(-4,35,4,LEAVES:12)
Block(-4,35,8,LEAVES:12)
Block(-4,35,9,LEAVES:12)
Block(-4,35,10,LEAVES:12)
Block(-4,35,11,LEAVES:12)
Block(-4,36,2,LEAVES:12)
Block(-4,36,3,LEAVES:12)
Block(-4,36,9,LEAVES:12)
Block(-4,36,10,LEAVES:12)
Block(-4,37,-1,LEAVES:12)
Block(-4,37,3,LEAVES:12)
Block(-4,37,4,LEAVES:12)
Block(-4,37,5,LEAVES:12)
Block(-4,38,-2,LEAVES:12)
Block(-4,38,-1,LEAVES:12)
Block(-4,38,0,LEAVES:12)
Block(-4,38,4,LEAVES:12)
Block(-4,38,5,LEAVES:12)
Block(-4,38,6,LEAVES:12)
Block(-4,38,7,LEAVES:12)
Block(-4,38,8,LEAVES:12)
Block(-4,38,9,LEAVES:12)
Block(-4,39,-1,LEAVES:12)
Block(-4,39,5,LEAVES:12)
Block(-4,39,6,17:12)
Block(-4,39,7,LEAVES:12)
Block(-4,39,8,LEAVES:12)
Block(-4,39,9,LEAVES:12)
Block(-4,40,4,LEAVES:12)
Block(-4,40,5,LEAVES:12)
Block(-4,40,6,LEAVES:12)
Block(-4,40,7,LEAVES:12)
Block(-4,41,3,LEAVES:12)
Block(-4,41,4,LEAVES:12)
Block(-4,41,5,LEAVES:12)
Block(-4,42,4,LEAVES:12)
Block(-3,0,3,17:12)
Block(-3,0,4,17:12)
Block(-3,0,5,17:12)
Block(-3,1,4,17:12)
Block(-3,1,5,17:12)
Block(-3,2,4,17:12)
Block(-3,2,5,17:12)
Block(-3,11,-2,LEAVES:12)
Block(-3,12,-1,LEAVES:12)
Block(-3,14,-3,LEAVES:12)
Block(-3,14,0,LEAVES:12)
Block(-3,15,-4,LEAVES:12)
Block(-3,16,-2,LEAVES:12)
Block(-3,16,-1,LEAVES:12)
Block(-3,16,0,LEAVES:12)
Block(-3,16,1,LEAVES:12)
Block(-3,16,6,LEAVES:12)
Block(-3,17,-1,LEAVES:12)
Block(-3,17,0,LEAVES:12)
Block(-3,17,1,LEAVES:12)
Block(-3,17,2,LEAVES:12)
Block(-3,17,3,LEAVES:12)
Block(-3,17,4,LEAVES:12)
Block(-3,17,5,LEAVES:12)
Block(-3,17,8,17:12)
Block(-3,17,9,17:12)
Block(-3,18,0,LEAVES:12)
Block(-3,18,1,LEAVES:12)
Block(-3,18,2,LEAVES:12)
Block(-3,18,3,LEAVES:12)
Block(-3,18,4,LEAVES:12)
Block(-3,18,5,LEAVES:12)
Block(-3,18,6,LEAVES:12)
Block(-3,18,8,17:12)
Block(-3,19,3,LEAVES:12)
Block(-3,19,4,17:12)
Block(-3,19,5,LEAVES:12)
Block(-3,19,6,LEAVES:12)
Block(-3,19,7,LEAVES:12)
Block(-3,19,11,LEAVES:12)
Block(-3,19,12,LEAVES:12)
Block(-3,19,13,LEAVES:12)
Block(-3,20,5,LEAVES:12)
Block(-3,20,6,LEAVES:12)
Block(-3,20,12,LEAVES:12)
Block(-3,21,5,LEAVES:12)
Block(-3,21,6,LEAVES:12)
Block(-3,21,7,LEAVES:12)
Block(-3,21,12,LEAVES:12)
Block(-3,21,13,LEAVES:12)
Block(-3,21,14,LEAVES:12)
Block(-3,22,4,LEAVES:12)
Block(-3,22,5,LEAVES:12)
Block(-3,22,6,LEAVES:12)
Block(-3,22,10,LEAVES:12)
Block(-3,22,13,LEAVES:12)
Block(-3,22,14,LEAVES:12)
Block(-3,22,15,LEAVES:12)
Block(-3,22,18,LEAVES:12)
Block(-3,23,-6,LEAVES:12)
Block(-3,23,5,LEAVES:12)
Block(-3,23,9,LEAVES:12)
Block(-3,23,14,LEAVES:12)
Block(-3,23,17,LEAVES:12)
Block(-3,24,-5,LEAVES:12)
Block(-3,24,10,LEAVES:12)
Block(-3,24,15,LEAVES:12)
Block(-3,24,16,LEAVES:12)
Block(-3,24,17,LEAVES:12)
Block(-3,25,-6,LEAVES:12)
Block(-3,25,-1,LEAVES:12)
Block(-3,25,1,LEAVES:12)
Block(-3,25,8,LEAVES:12)
Block(-3,25,10,LEAVES:12)
Block(-3,25,14,LEAVES:12)
Block(-3,25,15,LEAVES:12)
Block(-3,25,16,LEAVES:12)
Block(-3,26,0,LEAVES:12)
Block(-3,26,1,LEAVES:12)
Block(-3,26,2,LEAVES:12)
Block(-3,26,3,LEAVES:12)
Block(-3,26,4,LEAVES:12)
Block(-3,26,5,LEAVES:12)
Block(-3,26,6,LEAVES:12)
Block(-3,26,7,LEAVES:12)
Block(-3,26,11,LEAVES:12)
Block(-3,26,15,LEAVES:12)
Block(-3,27,1,17:12)
Block(-3,27,2,LEAVES:12)
Block(-3,27,3,17:12)
Block(-3,27,4,LEAVES:12)
Block(-3,27,5,LEAVES:12)
Block(-3,28,2,LEAVES:12)
Block(-3,28,4,LEAVES:12)
Block(-3,29,0,LEAVES:12)
Block(-3,29,1,LEAVES:12)
Block(-3,29,2,LEAVES:12)
Block(-3,29,3,LEAVES:12)
Block(-3,29,4,LEAVES:12)
Block(-3,30,1,LEAVES:12)
Block(-3,30,2,LEAVES:12)
Block(-3,30,3,LEAVES:12)
Block(-3,31,2,LEAVES:12)
Block(-3,31,7,LEAVES:12)
Block(-3,31,9,LEAVES:12)
Block(-3,32,9,LEAVES:12)
Block(-3,32,10,LEAVES:12)
Block(-3,32,11,LEAVES:12)
Block(-3,33,3,17:12)
Block(-3,33,8,17:12)
Block(-3,33,9,17:12)
Block(-3,33,10,LEAVES:12)
Block(-3,34,0,LEAVES:12)
Block(-3,34,10,LEAVES:12)
Block(-3,35,3,LEAVES:12)
Block(-3,35,4,LEAVES:12)
Block(-3,35,5,LEAVES:12)
Block(-3,35,8,LEAVES:12)
Block(-3,35,9,LEAVES:12)
Block(-3,35,10,LEAVES:12)
Block(-3,35,11,LEAVES:12)
Block(-3,35,12,LEAVES:12)
Block(-3,36,-1,LEAVES:12)
Block(-3,36,1,LEAVES:12)
Block(-3,36,2,LEAVES:12)
Block(-3,36,3,LEAVES:12)
Block(-3,36,4,LEAVES:12)
Block(-3,36,6,LEAVES:12)
Block(-3,36,9,LEAVES:12)
Block(-3,36,10,LEAVES:12)
Block(-3,36,11,LEAVES:12)
Block(-3,37,1,LEAVES:12)
Block(-3,37,3,LEAVES:12)
Block(-3,37,4,LEAVES:12)
Block(-3,37,7,LEAVES:12)
Block(-3,37,10,LEAVES:12)
Block(-3,38,-1,LEAVES:12)
Block(-3,38,3,LEAVES:12)
Block(-3,38,4,LEAVES:12)
Block(-3,38,5,LEAVES:12)
Block(-3,38,7,17:12)
Block(-3,38,8,LEAVES:12)
Block(-3,38,9,LEAVES:12)
Block(-3,39,4,LEAVES:12)
Block(-3,39,5,LEAVES:12)
Block(-3,39,6,17:12)
Block(-3,39,7,LEAVES:12)
Block(-3,39,8,LEAVES:12)
Block(-3,39,9,LEAVES:12)
Block(-3,39,10,LEAVES:12)
Block(-3,40,3,LEAVES:12)
Block(-3,40,4,LEAVES:12)
Block(-3,40,5,LEAVES:12)
Block(-3,40,6,LEAVES:12)
Block(-3,40,7,LEAVES:12)
Block(-3,40,8,LEAVES:12)
Block(-3,40,9,LEAVES:12)
Block(-3,41,4,LEAVES:12)
Block(-2,0,-2,17:12)
Block(-2,0,-1,17:12)
Block(-2,0,4,17:12)
Block(-2,1,4,17:12)
Block(-2,2,4,17:12)
Block(-2,2,5,17:12)
Block(-2,8,-2,LEAVES:12)
Block(-2,11,-3,LEAVES:12)
Block(-2,11,-2,LEAVES:12)
Block(-2,11,-1,LEAVES:12)
Block(-2,12,-2,LEAVES:12)
Block(-2,12,-1,LEAVES:12)
Block(-2,12,0,LEAVES:12)
Block(-2,13,-1,LEAVES:12)
Block(-2,13,0,LEAVES:12)
Block(-2,14,-4,LEAVES:12)
Block(-2,14,-3,LEAVES:12)
Block(-2,14,-2,LEAVES:12)
Block(-2,14,-1,LEAVES:12)
Block(-2,14,0,LEAVES:12)
Block(-2,14,1,LEAVES:12)
Block(-2,15,-5,LEAVES:12)
Block(-2,15,-4,LEAVES:12)
Block(-2,15,-3,LEAVES:12)
Block(-2,15,0,LEAVES:12)
Block(-2,15,1,LEAVES:12)
Block(-2,16,-4,LEAVES:12)
Block(-2,16,-1,LEAVES:12)
Block(-2,16,5,LEAVES:12)
Block(-2,16,6,LEAVES:12)
Block(-2,16,7,LEAVES:12)
Block(-2,17,-2,LEAVES:12)
Block(-2,17,-1,LEAVES:12)
Block(-2,17,0,LEAVES:12)
Block(-2,17,1,LEAVES:12)
Block(-2,17,2,LEAVES:12)
Block(-2,17,3,LEAVES:12)
Block(-2,17,4,LEAVES:12)
Block(-2,17,5,LEAVES:12)
Block(-2,17,6,LEAVES:12)
Block(-2,17,8,17:12)
Block(-2,18,-1,LEAVES:12)
Block(-2,18,2,LEAVES:12)
Block(-2,18,3,LEAVES:12)
Block(-2,18,4,17:12)
Block(-2,18,5,LEAVES:12)
Block(-2,18,6,LEAVES:12)
Block(-2,18,7,LEAVES:12)
Block(-2,19,-2,LEAVES:12)
Block(-2,19,3,LEAVES:12)
Block(-2,19,4,LEAVES:12)
Block(-2,19,5,LEAVES:12)
Block(-2,19,6,LEAVES:12)
Block(-2,19,12,LEAVES:12)
Block(-2,20,-4,LEAVES:12)
Block(-2,20,-1,LEAVES:12)
Block(-2,20,7,LEAVES:12)
Block(-2,21,-5,LEAVES:12)
Block(-2,21,3,LEAVES:12)
Block(-2,21,6,LEAVES:12)
Block(-2,21,13,LEAVES:12)
Block(-2,21,14,LEAVES:12)
Block(-2,21,15,LEAVES:12)
Block(-2,22,5,LEAVES:12)
Block(-2,22,9,LEAVES:12)
Block(-2,22,10,LEAVES:12)
Block(-2,22,11,LEAVES:12)
Block(-2,22,14,LEAVES:12)
Block(-2,22,17,LEAVES:12)
Block(-2,22,18,LEAVES:12)
Block(-2,22,19,LEAVES:12)
Block(-2,23,-7,LEAVES:12)
Block(-2,23,-6,LEAVES:12)
Block(-2,23,-5,LEAVES:12)
Block(-2,23,8,LEAVES:12)
Block(-2,23,9,LEAVES:12)
Block(-2,23,10,LEAVES:12)
Block(-2,23,14,LEAVES:12)
Block(-2,23,15,LEAVES:12)
Block(-2,23,16,LEAVES:12)
Block(-2,23,17,LEAVES:12)
Block(-2,23,18,LEAVES:12)
Block(-2,24,-6,LEAVES:12)
Block(-2,24,-5,LEAVES:12)
Block(-2,24,-4,LEAVES:12)
Block(-2,24,9,17:12)
Block(-2,24,13,LEAVES:12)
Block(-2,24,16,LEAVES:12)
Block(-2,24,17,LEAVES:12)
Block(-2,25,-7,LEAVES:12)
Block(-2,25,-6,LEAVES:12)
Block(-2,25,-5,LEAVES:12)
Block(-2,25,-2,LEAVES:12)
Block(-2,25,0,LEAVES:12)
Block(-2,25,1,LEAVES:12)
Block(-2,25,2,17:12)
Block(-2,25,3,17:12)
Block(-2,25,7,LEAVES:12)
Block(-2,25,8,LEAVES:12)
Block(-2,25,9,LEAVES:12)
Block(-2,25,10,LEAVES:12)
Block(-2,25,11,LEAVES:12)
Block(-2,25,15,LEAVES:12)
Block(-2,25,16,LEAVES:12)
Block(-2,25,17,LEAVES:12)
Block(-2,26,-6,LEAVES:12)
Block(-2,26,1,LEAVES:12)
Block(-2,26,2,LEAVES:12)
Block(-2,26,3,17:12)
Block(-2,26,4,17:12)
Block(-2,26,5,LEAVES:12)
Block(-2,26,6,LEAVES:12)
Block(-2,26,7,LEAVES:12)
Block(-2,26,8,LEAVES:12)
Block(-2,26,10,LEAVES:12)
Block(-2,26,11,LEAVES:12)
Block(-2,26,12,LEAVES:12)
Block(-2,26,16,LEAVES:12)
Block(-2,27,3,17:12)
Block(-2,27,4,LEAVES:12)
Block(-2,27,7,LEAVES:12)
Block(-2,27,11,LEAVES:12)
Block(-2,27,16,LEAVES:12)
Block(-2,28,0,LEAVES:12)
Block(-2,28,1,LEAVES:12)
Block(-2,28,2,LEAVES:12)
Block(-2,29,-1,LEAVES:12)
Block(-2,29,0,LEAVES:12)
Block(-2,29,1,LEAVES:12)
Block(-2,29,2,LEAVES:12)
Block(-2,29,3,LEAVES:12)
Block(-2,30,0,LEAVES:12)
Block(-2,30,2,LEAVES:12)
Block(-2,31,8,LEAVES:12)
Block(-2,31,9,LEAVES:12)
Block(-2,31,10,LEAVES:12)
Block(-2,32,9,17:12)
Block(-2,32,10,LEAVES:12)
Block(-2,33,1,LEAVES:12)
Block(-2,33,2,17:12)
Block(-2,33,3,17:12)
Block(-2,33,9,17:12)
Block(-2,33,10,LEAVES:12)
Block(-2,34,2,LEAVES:12)
Block(-2,34,3,17:12)
Block(-2,34,8,LEAVES:12)
Block(-2,34,9,LEAVES:12)
Block(-2,34,10,LEAVES:12)
Block(-2,34,11,LEAVES:12)
Block(-2,34,14,LEAVES:12)
Block(-2,35,-1,LEAVES:12)
Block(-2,35,4,LEAVES:12)
Block(-2,35,7,LEAVES:12)
Block(-2,35,8,LEAVES:12)
Block(-2,35,9,LEAVES:12)
Block(-2,35,10,LEAVES:12)
Block(-2,35,11,LEAVES:12)
Block(-2,35,13,LEAVES:12)
Block(-2,36,-2,LEAVES:12)
Block(-2,36,-1,LEAVES:12)
Block(-2,36,0,LEAVES:12)
Block(-2,36,2,LEAVES:12)
Block(-2,36,3,LEAVES:12)
Block(-2,36,4,LEAVES:12)
Block(-2,36,5,LEAVES:12)
Block(-2,36,6,LEAVES:12)
Block(-2,36,7,LEAVES:12)
Block(-2,36,8,LEAVES:12)
Block(-2,36,10,LEAVES:12)
Block(-2,37,-1,LEAVES:12)
Block(-2,37,1,LEAVES:12)
Block(-2,37,2,17:12)
Block(-2,37,3,LEAVES:12)
Block(-2,37,6,LEAVES:12)
Block(-2,37,7,LEAVES:12)
Block(-2,37,8,LEAVES:12)
Block(-2,37,9,LEAVES:12)
Block(-2,38,-1,LEAVES:12)
Block(-2,38,1,LEAVES:12)
Block(-2,38,4,LEAVES:12)
Block(-2,38,7,17:12)
Block(-2,38,8,LEAVES:12)
Block(-2,38,10,LEAVES:12)
Block(-2,39,4,LEAVES:12)
Block(-2,39,7,LEAVES:12)
Block(-2,39,8,LEAVES:12)
Block(-2,39,9,LEAVES:12)
Block(-2,39,11,LEAVES:12)
Block(-2,40,2,LEAVES:12)
Block(-2,40,4,LEAVES:12)
Block(-2,40,5,LEAVES:12)
Block(-2,40,6,LEAVES:12)
Block(-2,40,7,LEAVES:12)
Block(-2,40,8,LEAVES:12)
Block(-2,41,6,LEAVES:12)
Block(-2,41,7,LEAVES:12)
Block(-2,41,9,LEAVES:12)
Block(-2,42,8,LEAVES:12)
Block(-2,43,6,LEAVES:12)
Block(-2,44,5,LEAVES:12)
Block(-1,0,-1,17:12)
Block(-1,0,0,17:12)
Block(-1,0,1,17:12)
Block(-1,0,2,17:12)
Block(-1,0,4,17:12)
Block(-1,0,5,17:12)
Block(-1,0,6,17:12)
Block(-1,0,7,17:12)
Block(-1,1,2,17:12)
Block(-1,1,3,17:12)
Block(-1,1,4,17:12)
Block(-1,2,4,17:12)
Block(-1,3,4,17:12)
Block(-1,4,4,17:12)
Block(-1,8,-3,LEAVES:12)
Block(-1,8,-2,LEAVES:12)
Block(-1,8,-1,LEAVES:12)
Block(-1,9,-2,LEAVES:12)
Block(-1,11,-2,LEAVES:12)
Block(-1,11,-1,LEAVES:12)
Block(-1,11,0,LEAVES:12)
Block(-1,12,-1,LEAVES:12)
Block(-1,12,1,LEAVES:12)
Block(-1,13,-1,17:12)
Block(-1,13,0,LEAVES:12)
Block(-1,13,1,LEAVES:12)
Block(-1,14,-3,LEAVES:12)
Block(-1,14,0,LEAVES:12)
Block(-1,14,1,LEAVES:12)
Block(-1,14,2,LEAVES:12)
Block(-1,15,-4,LEAVES:12)
Block(-1,15,-3,LEAVES:12)
Block(-1,15,-2,LEAVES:12)
Block(-1,15,1,LEAVES:12)
Block(-1,16,-3,LEAVES:12)
Block(-1,16,1,LEAVES:12)
Block(-1,16,2,17:12)
Block(-1,16,3,17:12)
Block(-1,16,6,LEAVES:12)
Block(-1,17,-1,LEAVES:12)
Block(-1,17,2,LEAVES:12)
Block(-1,17,3,LEAVES:12)
Block(-1,17,4,17:12)
Block(-1,17,5,LEAVES:12)
Block(-1,17,6,LEAVES:12)
Block(-1,17,7,17:12)
Block(-1,17,8,17:12)
Block(-1,18,1,LEAVES:12)
Block(-1,18,3,LEAVES:12)
Block(-1,18,4,17:12)
Block(-1,18,5,17:12)
Block(-1,18,6,LEAVES:12)
Block(-1,19,-3,LEAVES:12)
Block(-1,19,-2,LEAVES:12)
Block(-1,19,-1,LEAVES:12)
Block(-1,19,7,LEAVES:12)
Block(-1,20,-5,LEAVES:12)
Block(-1,20,-4,LEAVES:12)
Block(-1,20,-3,LEAVES:12)
Block(-1,20,-2,LEAVES:12)
Block(-1,20,-1,LEAVES:12)
Block(-1,20,0,LEAVES:12)
Block(-1,20,3,LEAVES:12)
Block(-1,20,6,LEAVES:12)
Block(-1,20,7,LEAVES:12)
Block(-1,20,8,LEAVES:12)
Block(-1,21,-6,LEAVES:12)
Block(-1,21,-5,LEAVES:12)
Block(-1,21,-4,LEAVES:12)
Block(-1,21,-1,LEAVES:12)
Block(-1,21,2,LEAVES:12)
Block(-1,21,3,LEAVES:12)
Block(-1,21,4,LEAVES:12)
Block(-1,21,7,LEAVES:12)
Block(-1,21,14,LEAVES:12)
Block(-1,21,16,LEAVES:12)
Block(-1,22,-5,LEAVES:12)
Block(-1,22,-2,LEAVES:12)
Block(-1,22,3,LEAVES:12)
Block(-1,22,8,LEAVES:12)
Block(-1,22,9,LEAVES:12)
Block(-1,22,10,LEAVES:12)
Block(-1,22,16,LEAVES:12)
Block(-1,22,17,LEAVES:12)
Block(-1,22,18,LEAVES:12)
Block(-1,23,-6,LEAVES:12)
Block(-1,23,8,LEAVES:12)
Block(-1,23,9,LEAVES:12)
Block(-1,23,13,LEAVES:12)
Block(-1,23,14,LEAVES:12)
Block(-1,23,15,LEAVES:12)
Block(-1,23,16,17:12)
Block(-1,23,17,LEAVES:12)
Block(-1,24,-7,LEAVES:12)
Block(-1,24,-6,LEAVES:12)
Block(-1,24,-5,LEAVES:12)
Block(-1,24,-2,LEAVES:12)
Block(-1,24,10,17:12)
Block(-1,24,12,LEAVES:12)
Block(-1,24,13,LEAVES:12)
Block(-1,24,14,LEAVES:12)
Block(-1,24,17,LEAVES:12)
Block(-1,25,-6,LEAVES:12)
Block(-1,25,-3,LEAVES:12)
Block(-1,25,-2,LEAVES:12)
Block(-1,25,-1,LEAVES:12)
Block(-1,25,0,LEAVES:12)
Block(-1,25,1,LEAVES:12)
Block(-1,25,2,17:12)
Block(-1,25,5,17:12)
Block(-1,25,8,LEAVES:12)
Block(-1,25,9,LEAVES:12)
Block(-1,25,10,LEAVES:12)
Block(-1,25,12,LEAVES:12)
Block(-1,25,13,LEAVES:12)
Block(-1,25,15,LEAVES:12)
Block(-1,25,16,LEAVES:12)
Block(-1,25,17,LEAVES:12)
Block(-1,26,-2,LEAVES:12)
Block(-1,26,-1,LEAVES:12)
Block(-1,26,0,LEAVES:12)
Block(-1,26,1,LEAVES:12)
Block(-1,26,2,LEAVES:12)
Block(-1,26,4,17:12)
Block(-1,26,5,17:12)
Block(-1,26,7,LEAVES:12)
Block(-1,26,8,LEAVES:12)
Block(-1,26,9,LEAVES:12)
Block(-1,26,10,LEAVES:12)
Block(-1,26,11,LEAVES:12)
Block(-1,26,15,17:12)
Block(-1,27,-2,LEAVES:12)
Block(-1,27,1,LEAVES:12)
Block(-1,27,8,LEAVES:12)
Block(-1,27,10,LEAVES:12)
Block(-1,27,15,LEAVES:12)
Block(-1,27,16,LEAVES:12)
Block(-1,27,17,LEAVES:12)
Block(-1,28,-1,LEAVES:12)
Block(-1,28,0,LEAVES:12)
Block(-1,28,1,LEAVES:12)
Block(-1,28,2,LEAVES:12)
Block(-1,28,3,LEAVES:12)
Block(-1,28,16,LEAVES:12)
Block(-1,29,-2,LEAVES:12)
Block(-1,29,-1,LEAVES:12)
Block(-1,29,0,LEAVES:12)
Block(-1,29,2,LEAVES:12)
Block(-1,29,3,LEAVES:12)
Block(-1,29,4,LEAVES:12)
Block(-1,30,-1,LEAVES:12)
Block(-1,30,3,LEAVES:12)
Block(-1,31,7,LEAVES:12)
Block(-1,31,8,LEAVES:12)
Block(-1,31,9,LEAVES:12)
Block(-1,31,11,LEAVES:12)
Block(-1,32,8,17:12)
Block(-1,32,9,17:12)
Block(-1,33,0,LEAVES:12)
Block(-1,33,1,LEAVES:12)
Block(-1,33,2,LEAVES:12)
Block(-1,33,9,LEAVES:12)
Block(-1,33,10,LEAVES:12)
Block(-1,33,11,LEAVES:12)
Block(-1,34,-2,LEAVES:12)
Block(-1,34,1,LEAVES:12)
Block(-1,34,2,LEAVES:12)
Block(-1,34,3,17:12)
Block(-1,34,7,LEAVES:12)
Block(-1,34,8,LEAVES:12)
Block(-1,34,9,LEAVES:12)
Block(-1,34,10,LEAVES:12)
Block(-1,34,11,LEAVES:12)
Block(-1,34,12,LEAVES:12)
Block(-1,34,13,LEAVES:12)
Block(-1,34,14,LEAVES:12)
Block(-1,34,15,LEAVES:12)
Block(-1,35,-2,LEAVES:12)
Block(-1,35,-1,LEAVES:12)
Block(-1,35,0,LEAVES:12)
Block(-1,35,2,LEAVES:12)
Block(-1,35,6,LEAVES:12)
Block(-1,35,7,LEAVES:12)
Block(-1,35,8,LEAVES:12)
Block(-1,35,10,LEAVES:12)
Block(-1,35,11,LEAVES:12)
Block(-1,35,12,LEAVES:12)
Block(-1,35,13,LEAVES:12)
Block(-1,35,14,LEAVES:12)
Block(-1,36,-1,LEAVES:12)
Block(-1,36,0,LEAVES:12)
Block(-1,36,1,LEAVES:12)
Block(-1,36,2,LEAVES:12)
Block(-1,36,3,LEAVES:12)
Block(-1,36,6,LEAVES:12)
Block(-1,36,7,LEAVES:12)
Block(-1,36,8,LEAVES:12)
Block(-1,36,9,17:12)
Block(-1,36,10,17:12)
Block(-1,36,11,LEAVES:12)
Block(-1,36,13,LEAVES:12)
Block(-1,37,-1,LEAVES:12)
Block(-1,37,0,LEAVES:12)
Block(-1,37,2,LEAVES:12)
Block(-1,37,3,LEAVES:12)
Block(-1,37,4,LEAVES:12)
Block(-1,37,7,LEAVES:12)
Block(-1,37,8,LEAVES:12)
Block(-1,37,9,17:12)
Block(-1,38,-2,LEAVES:12)
Block(-1,38,-1,LEAVES:12)
Block(-1,38,0,LEAVES:12)
Block(-1,38,3,LEAVES:12)
Block(-1,38,4,LEAVES:12)
Block(-1,38,7,17:12)
Block(-1,38,9,LEAVES:12)
Block(-1,38,10,LEAVES:12)
Block(-1,38,11,LEAVES:12)
Block(-1,39,-1,LEAVES:12)
Block(-1,39,2,LEAVES:12)
Block(-1,39,3,LEAVES:12)
Block(-1,39,4,LEAVES:12)
Block(-1,39,5,LEAVES:12)
Block(-1,39,7,LEAVES:12)
Block(-1,39,8,LEAVES:12)
Block(-1,39,9,LEAVES:12)
Block(-1,39,10,LEAVES:12)
Block(-1,39,11,LEAVES:12)
Block(-1,39,12,LEAVES:12)
Block(-1,40,1,LEAVES:12)
Block(-1,40,2,LEAVES:12)
Block(-1,40,3,LEAVES:12)
Block(-1,40,4,LEAVES:12)
Block(-1,40,5,LEAVES:12)
Block(-1,40,6,LEAVES:12)
Block(-1,40,7,LEAVES:12)
Block(-1,40,11,LEAVES:12)
Block(-1,41,2,LEAVES:12)
Block(-1,41,5,LEAVES:12)
Block(-1,41,6,LEAVES:12)
Block(-1,41,7,LEAVES:12)
Block(-1,41,8,LEAVES:12)
Block(-1,41,9,LEAVES:12)
Block(-1,41,10,LEAVES:12)
Block(-1,42,6,LEAVES:12)
Block(-1,42,7,LEAVES:12)
Block(-1,42,8,LEAVES:12)
Block(-1,42,9,LEAVES:12)
Block(-1,43,5,LEAVES:12)
Block(-1,43,6,LEAVES:12)
Block(-1,43,7,LEAVES:12)
Block(-1,43,8,LEAVES:12)
Block(-1,44,4,LEAVES:12)
Block(-1,44,5,LEAVES:12)
Block(-1,44,6,LEAVES:12)
Block(-1,45,5,LEAVES:12)
Block(0,0,0,17:12)
Block(0,0,1,17:12)
Block(0,0,2,17:12)
Block(0,0,3,17:12)
Block(0,0,4,17:12)
Block(0,0,5,17:12)
Block(0,0,6,17:12)
Block(0,1,0,17:12)
Block(0,1,1,17:12)
Block(0,1,2,17:12)
Block(0,1,3,17:12)
Block(0,1,4,17:12)
Block(0,1,5,17:12)
Block(0,2,2,17:12)
Block(0,2,3,17:12)
Block(0,2,4,17:12)
Block(0,2,5,17:12)
Block(0,3,2,17:12)
Block(0,3,3,17:12)
Block(0,3,4,17:12)
Block(0,3,5,17:12)
Block(0,4,2,17:12)
Block(0,4,3,17:12)
Block(0,4,4,17:12)
Block(0,5,4,17:12)
Block(0,8,-2,LEAVES:12)
Block(0,10,-1,LEAVES:12)
Block(0,11,-2,LEAVES:12)
Block(0,11,-1,LEAVES:12)
Block(0,12,0,LEAVES:12)
Block(0,12,1,LEAVES:12)
Block(0,12,2,LEAVES:12)
Block(0,13,-1,17:12)
Block(0,13,0,LEAVES:12)
Block(0,13,1,LEAVES:12)
Block(0,14,-2,LEAVES:12)
Block(0,14,-1,LEAVES:12)
Block(0,14,0,LEAVES:12)
Block(0,14,1,LEAVES:12)
Block(0,14,2,17:12)
Block(0,15,-3,LEAVES:12)
Block(0,15,-1,LEAVES:12)
Block(0,15,0,LEAVES:12)
Block(0,15,1,LEAVES:12)
Block(0,15,5,LEAVES:12)
Block(0,16,2,LEAVES:12)
Block(0,16,3,LEAVES:12)
Block(0,17,1,LEAVES:12)
Block(0,17,3,LEAVES:12)
Block(0,17,6,LEAVES:12)
Block(0,17,7,17:12)
Block(0,18,0,LEAVES:12)
Block(0,18,1,LEAVES:12)
Block(0,18,2,LEAVES:12)
Block(0,18,6,17:12)
Block(0,19,-2,LEAVES:12)
Block(0,19,-1,LEAVES:12)
Block(0,19,0,LEAVES:12)
Block(0,19,1,LEAVES:12)
Block(0,19,6,LEAVES:12)
Block(0,19,7,LEAVES:12)
Block(0,19,8,LEAVES:12)
Block(0,20,-4,LEAVES:12)
Block(0,20,-1,LEAVES:12)
Block(0,20,2,LEAVES:12)
Block(0,20,3,LEAVES:12)
Block(0,20,4,LEAVES:12)
Block(0,20,5,LEAVES:12)
Block(0,20,6,LEAVES:12)
Block(0,20,7,LEAVES:12)
Block(0,20,12,LEAVES:12)
Block(0,21,-6,LEAVES:12)
Block(0,21,-5,LEAVES:12)
Block(0,21,-4,LEAVES:12)
Block(0,21,-3,LEAVES:12)
Block(0,21,-2,LEAVES:12)
Block(0,21,-1,LEAVES:12)
Block(0,21,0,LEAVES:12)
Block(0,21,3,LEAVES:12)
Block(0,21,4,LEAVES:12)
Block(0,21,5,LEAVES:12)
Block(0,21,6,LEAVES:12)
Block(0,21,11,LEAVES:12)
Block(0,21,15,LEAVES:12)
Block(0,21,16,LEAVES:12)
Block(0,21,17,LEAVES:12)
Block(0,22,-5,LEAVES:12)
Block(0,22,-4,LEAVES:12)
Block(0,22,-3,LEAVES:12)
Block(0,22,-2,LEAVES:12)
Block(0,22,-1,LEAVES:12)
Block(0,22,4,LEAVES:12)
Block(0,22,9,LEAVES:12)
Block(0,22,11,LEAVES:12)
Block(0,22,16,LEAVES:12)
Block(0,22,17,LEAVES:12)
Block(0,23,-4,LEAVES:12)
Block(0,23,-2,LEAVES:12)
Block(0,23,5,17:12)
Block(0,23,7,LEAVES:12)
Block(0,23,8,LEAVES:12)
Block(0,23,9,17:12)
Block(0,23,12,LEAVES:12)
Block(0,23,13,LEAVES:12)
Block(0,23,14,LEAVES:12)
Block(0,23,15,17:12)
Block(0,23,16,17:12)
Block(0,24,-6,LEAVES:12)
Block(0,24,-3,LEAVES:12)
Block(0,24,-2,LEAVES:12)
Block(0,24,-1,LEAVES:12)
Block(0,24,5,17:12)
Block(0,24,6,17:12)
Block(0,24,8,LEAVES:12)
Block(0,24,10,LEAVES:12)
Block(0,24,13,LEAVES:12)
Block(0,24,15,LEAVES:12)
Block(0,24,16,LEAVES:12)
Block(0,24,17,LEAVES:12)
Block(0,25,-6,LEAVES:12)
Block(0,25,-4,LEAVES:12)
Block(0,25,-3,LEAVES:12)
Block(0,25,-2,LEAVES:12)
Block(0,25,0,LEAVES:12)
Block(0,25,5,17:12)
Block(0,25,6,17:12)
Block(0,25,8,LEAVES:12)
Block(0,25,11,LEAVES:12)
Block(0,25,12,LEAVES:12)
Block(0,25,13,LEAVES:12)
Block(0,25,14,17:12)
Block(0,25,15,LEAVES:12)
Block(0,25,16,LEAVES:12)
Block(0,25,17,LEAVES:12)
Block(0,25,18,LEAVES:12)
Block(0,26,-3,LEAVES:12)
Block(0,26,-2,LEAVES:12)
Block(0,26,-1,LEAVES:12)
Block(0,26,0,LEAVES:12)
Block(0,26,1,LEAVES:12)
Block(0,26,4,17:12)
Block(0,26,5,17:12)
Block(0,26,8,LEAVES:12)
Block(0,26,9,LEAVES:12)
Block(0,26,10,LEAVES:12)
Block(0,26,11,LEAVES:12)
Block(0,26,12,LEAVES:12)
Block(0,26,15,LEAVES:12)
Block(0,26,17,LEAVES:12)
Block(0,27,-3,LEAVES:12)
Block(0,27,-2,LEAVES:12)
Block(0,27,-1,LEAVES:12)
Block(0,27,11,LEAVES:12)
Block(0,27,14,LEAVES:12)
Block(0,27,15,LEAVES:12)
Block(0,27,16,LEAVES:12)
Block(0,28,-2,LEAVES:12)
Block(0,28,0,LEAVES:12)
Block(0,28,2,LEAVES:12)
Block(0,28,15,LEAVES:12)
Block(0,29,-1,LEAVES:12)
Block(0,29,3,LEAVES:12)
Block(0,30,11,LEAVES:12)
Block(0,31,8,LEAVES:12)
Block(0,31,10,LEAVES:12)
Block(0,31,11,LEAVES:12)
Block(0,31,12,LEAVES:12)
Block(0,32,7,17:12)
Block(0,32,8,17:12)
Block(0,32,11,LEAVES:12)
Block(0,32,12,LEAVES:12)
Block(0,33,1,LEAVES:12)
Block(0,33,10,LEAVES:12)
Block(0,34,-3,LEAVES:12)
Block(0,34,-2,LEAVES:12)
Block(0,34,-1,LEAVES:12)
Block(0,34,0,LEAVES:12)
Block(0,34,1,LEAVES:12)
Block(0,34,2,LEAVES:12)
Block(0,34,3,17:12)
Block(0,34,8,LEAVES:12)
Block(0,34,9,LEAVES:12)
Block(0,34,10,LEAVES:12)
Block(0,34,11,LEAVES:12)
Block(0,34,14,LEAVES:12)
Block(0,35,-2,LEAVES:12)
Block(0,35,-1,LEAVES:12)
Block(0,35,0,LEAVES:12)
Block(0,35,1,LEAVES:12)
Block(0,35,2,LEAVES:12)
Block(0,35,3,17:12)
Block(0,35,4,17:12)
Block(0,35,5,17:12)
Block(0,35,7,LEAVES:12)
Block(0,35,8,LEAVES:12)
Block(0,35,9,LEAVES:12)
Block(0,35,10,LEAVES:12)
Block(0,35,11,LEAVES:12)
Block(0,35,13,LEAVES:12)
Block(0,35,14,LEAVES:12)
Block(0,35,15,LEAVES:12)
Block(0,36,-1,LEAVES:12)
Block(0,36,0,LEAVES:12)
Block(0,36,1,LEAVES:12)
Block(0,36,2,LEAVES:12)
Block(0,36,3,17:12)
Block(0,36,7,LEAVES:12)
Block(0,36,8,LEAVES:12)
Block(0,36,10,LEAVES:12)
Block(0,36,14,LEAVES:12)
Block(0,37,-2,LEAVES:12)
Block(0,37,-1,LEAVES:12)
Block(0,37,0,LEAVES:12)
Block(0,37,1,LEAVES:12)
Block(0,37,2,LEAVES:12)
Block(0,37,3,LEAVES:12)
Block(0,37,6,LEAVES:12)
Block(0,37,7,LEAVES:12)
Block(0,37,8,LEAVES:12)
Block(0,37,9,LEAVES:12)
Block(0,37,12,LEAVES:12)
Block(0,38,-1,LEAVES:12)
Block(0,38,0,LEAVES:12)
Block(0,38,1,LEAVES:12)
Block(0,38,2,LEAVES:12)
Block(0,38,3,LEAVES:12)
Block(0,38,4,LEAVES:12)
Block(0,38,5,LEAVES:12)
Block(0,38,7,17:12)
Block(0,38,8,LEAVES:12)
Block(0,38,9,LEAVES:12)
Block(0,38,10,LEAVES:12)
Block(0,38,11,LEAVES:12)
Block(0,38,12,LEAVES:12)
Block(0,39,0,LEAVES:12)
Block(0,39,1,LEAVES:12)
Block(0,39,2,LEAVES:12)
Block(0,39,3,LEAVES:12)
Block(0,39,4,LEAVES:12)
Block(0,39,5,LEAVES:12)
Block(0,39,6,LEAVES:12)
Block(0,39,7,LEAVES:12)
Block(0,39,8,LEAVES:12)
Block(0,39,9,LEAVES:12)
Block(0,39,10,LEAVES:12)
Block(0,39,11,LEAVES:12)
Block(0,40,0,LEAVES:12)
Block(0,40,1,LEAVES:12)
Block(0,40,2,LEAVES:12)
Block(0,40,5,LEAVES:12)
Block(0,40,6,LEAVES:12)
Block(0,40,7,LEAVES:12)
Block(0,40,9,LEAVES:12)
Block(0,41,1,LEAVES:12)
Block(0,41,4,LEAVES:12)
Block(0,41,5,LEAVES:12)
Block(0,41,6,LEAVES:12)
Block(0,41,7,LEAVES:12)
Block(0,41,9,LEAVES:12)
Block(0,42,5,LEAVES:12)
Block(0,42,6,17:12)
Block(0,42,7,17:12)
Block(0,42,8,LEAVES:12)
Block(0,42,9,LEAVES:12)
Block(0,42,10,LEAVES:12)
Block(0,43,4,LEAVES:12)
Block(0,43,5,LEAVES:12)
Block(0,43,6,LEAVES:12)
Block(0,43,8,LEAVES:12)
Block(0,43,9,LEAVES:12)
Block(0,44,5,LEAVES:12)
Block(1,0,3,17:12)
Block(1,0,4,17:12)
Block(1,0,5,17:12)
Block(1,1,1,17:12)
Block(1,1,2,17:12)
Block(1,1,3,17:12)
Block(1,1,4,17:12)
Block(1,1,5,17:12)
Block(1,2,2,17:12)
Block(1,2,3,17:12)
Block(1,2,4,17:12)
Block(1,2,5,17:12)
Block(1,3,1,17:12)
Block(1,3,2,17:12)
Block(1,3,3,17:12)
Block(1,3,4,17:12)
Block(1,3,5,17:12)
Block(1,4,1,17:12)
Block(1,4,2,17:12)
Block(1,4,3,17:12)
Block(1,4,4,17:12)
Block(1,4,5,17:12)
Block(1,5,2,17:12)
Block(1,5,3,17:12)
Block(1,5,4,17:12)
Block(1,6,4,17:12)
Block(1,8,-3,LEAVES:12)
Block(1,8,-2,LEAVES:12)
Block(1,8,-1,LEAVES:12)
Block(1,9,-2,LEAVES:12)
Block(1,9,0,LEAVES:12)
Block(1,10,-2,17:12)
Block(1,10,-1,17:12)
Block(1,10,0,17:12)
Block(1,10,1,LEAVES:12)
Block(1,11,-3,LEAVES:12)
Block(1,11,-2,LEAVES:12)
Block(1,11,-1,LEAVES:12)
Block(1,11,0,17:12)
Block(1,12,-4,LEAVES:12)
Block(1,12,-2,LEAVES:12)
Block(1,12,-1,LEAVES:12)
Block(1,12,0,17:12)
Block(1,12,1,LEAVES:12)
Block(1,13,-5,LEAVES:12)
Block(1,13,0,LEAVES:12)
Block(1,13,1,LEAVES:12)
Block(1,13,2,17:12)
Block(1,14,-1,LEAVES:12)
Block(1,14,0,LEAVES:12)
Block(1,14,1,LEAVES:12)
Block(1,15,-6,LEAVES:12)
Block(1,15,-4,LEAVES:12)
Block(1,15,-2,LEAVES:12)
Block(1,15,-1,LEAVES:12)
Block(1,15,0,LEAVES:12)
Block(1,15,1,LEAVES:12)
Block(1,15,2,LEAVES:12)
Block(1,15,4,LEAVES:12)
Block(1,15,5,LEAVES:12)
Block(1,15,6,LEAVES:12)
Block(1,16,-7,LEAVES:12)
Block(1,16,-3,LEAVES:12)
Block(1,16,-1,LEAVES:12)
Block(1,16,1,LEAVES:12)
Block(1,16,5,LEAVES:12)
Block(1,17,0,LEAVES:12)
Block(1,17,1,LEAVES:12)
Block(1,17,2,LEAVES:12)
Block(1,17,6,17:12)
Block(1,17,7,17:12)
Block(1,18,-1,LEAVES:12)
Block(1,18,0,LEAVES:12)
Block(1,18,1,LEAVES:12)
Block(1,18,5,17:12)
Block(1,18,6,17:12)
Block(1,19,-1,LEAVES:12)
Block(1,19,0,LEAVES:12)
Block(1,19,7,LEAVES:12)
Block(1,20,-3,LEAVES:12)
Block(1,20,3,LEAVES:12)
Block(1,20,4,17:12)
Block(1,20,6,LEAVES:12)
Block(1,20,11,LEAVES:12)
Block(1,20,12,LEAVES:12)
Block(1,20,13,LEAVES:12)
Block(1,21,-7,LEAVES:12)
Block(1,21,-6,LEAVES:12)
Block(1,21,-5,LEAVES:12)
Block(1,21,-4,LEAVES:12)
Block(1,21,-1,LEAVES:12)
Block(1,21,4,LEAVES:12)
Block(1,21,5,17:12)
Block(1,21,10,LEAVES:12)
Block(1,21,11,LEAVES:12)
Block(1,21,12,LEAVES:12)
Block(1,21,14,LEAVES:12)
Block(1,21,15,LEAVES:12)
Block(1,21,16,LEAVES:12)
Block(1,22,-6,LEAVES:12)
Block(1,22,-5,LEAVES:12)
Block(1,22,-4,LEAVES:12)
Block(1,22,-2,LEAVES:12)
Block(1,22,-1,LEAVES:12)
Block(1,22,0,LEAVES:12)
Block(1,22,3,17:12)
Block(1,22,4,17:12)
Block(1,22,5,17:12)
Block(1,22,6,17:12)
Block(1,22,7,17:12)
Block(1,22,8,17:12)
Block(1,22,9,17:12)
Block(1,22,10,LEAVES:12)
Block(1,22,11,LEAVES:12)
Block(1,22,12,LEAVES:12)
Block(1,22,15,LEAVES:12)
Block(1,22,16,LEAVES:12)
Block(1,22,17,LEAVES:12)
Block(1,23,-6,LEAVES:12)
Block(1,23,-5,LEAVES:12)
Block(1,23,-4,LEAVES:12)
Block(1,23,-3,17:12)
Block(1,23,-2,17:12)
Block(1,23,-1,LEAVES:12)
Block(1,23,4,17:12)
Block(1,23,5,17:12)
Block(1,23,6,17:12)
Block(1,23,7,LEAVES:12)
Block(1,23,8,LEAVES:12)
Block(1,23,9,17:12)
Block(1,23,10,17:12)
Block(1,23,11,LEAVES:12)
Block(1,23,12,LEAVES:12)
Block(1,23,13,LEAVES:12)
Block(1,23,14,LEAVES:12)
Block(1,23,16,LEAVES:12)
Block(1,24,-7,LEAVES:12)
Block(1,24,-6,LEAVES:12)
Block(1,24,-5,LEAVES:12)
Block(1,24,-2,LEAVES:12)
Block(1,24,4,17:12)
Block(1,24,5,17:12)
Block(1,24,6,17:12)
Block(1,24,7,LEAVES:12)
Block(1,24,8,LEAVES:12)
Block(1,24,9,LEAVES:12)
Block(1,24,10,LEAVES:12)
Block(1,24,11,17:12)
Block(1,24,12,17:12)
Block(1,24,13,17:12)
Block(1,24,14,17:12)
Block(1,24,15,17:12)
Block(1,24,16,LEAVES:12)
Block(1,24,17,LEAVES:12)
Block(1,24,18,LEAVES:12)
Block(1,25,-7,LEAVES:12)
Block(1,25,-6,LEAVES:12)
Block(1,25,-5,LEAVES:12)
Block(1,25,-4,LEAVES:12)
Block(1,25,-3,LEAVES:12)
Block(1,25,5,17:12)
Block(1,25,6,17:12)
Block(1,25,8,LEAVES:12)
Block(1,25,9,LEAVES:12)
Block(1,25,10,LEAVES:12)
Block(1,25,12,LEAVES:12)
Block(1,25,13,LEAVES:12)
Block(1,25,14,17:12)
Block(1,25,15,LEAVES:12)
Block(1,25,17,LEAVES:12)
Block(1,25,18,LEAVES:12)
Block(1,25,19,LEAVES:12)
Block(1,26,-6,LEAVES:12)
Block(1,26,-5,LEAVES:12)
Block(1,26,-1,LEAVES:12)
Block(1,26,6,17:12)
Block(1,26,8,LEAVES:12)
Block(1,26,9,LEAVES:12)
Block(1,26,10,LEAVES:12)
Block(1,26,11,LEAVES:12)
Block(1,26,12,LEAVES:12)
Block(1,26,13,LEAVES:12)
Block(1,26,14,LEAVES:12)
Block(1,26,18,LEAVES:12)
Block(1,27,-4,LEAVES:12)
Block(1,27,-2,LEAVES:12)
Block(1,27,-1,LEAVES:12)
Block(1,27,0,LEAVES:12)
Block(1,27,6,17:12)
Block(1,27,9,LEAVES:12)
Block(1,27,11,LEAVES:12)
Block(1,27,12,LEAVES:12)
Block(1,27,13,LEAVES:12)
Block(1,27,15,LEAVES:12)
Block(1,28,-1,LEAVES:12)
Block(1,28,6,17:12)
Block(1,28,10,LEAVES:12)
Block(1,30,7,17:12)
Block(1,30,10,LEAVES:12)
Block(1,30,11,LEAVES:12)
Block(1,30,12,LEAVES:12)
Block(1,30,13,LEAVES:12)
Block(1,31,7,17:12)
Block(1,31,11,LEAVES:12)
Block(1,31,12,LEAVES:12)
Block(1,31,13,LEAVES:12)
Block(1,32,7,17:12)
Block(1,32,10,17:12)
Block(1,32,11,17:12)
Block(1,32,12,LEAVES:12)
Block(1,33,0,LEAVES:12)
Block(1,33,10,LEAVES:12)
Block(1,33,11,17:12)
Block(1,33,12,17:12)
Block(1,33,13,17:12)
Block(1,34,-2,LEAVES:12)
Block(1,34,1,LEAVES:12)
Block(1,34,6,17:12)
Block(1,34,9,LEAVES:12)
Block(1,34,10,LEAVES:12)
Block(1,34,11,LEAVES:12)
Block(1,35,-3,LEAVES:12)
Block(1,35,-2,LEAVES:12)
Block(1,35,-1,LEAVES:12)
Block(1,35,4,17:12)
Block(1,35,5,17:12)
Block(1,35,6,17:12)
Block(1,35,8,LEAVES:12)
Block(1,35,9,LEAVES:12)
Block(1,35,10,LEAVES:12)
Block(1,35,12,LEAVES:12)
Block(1,35,14,LEAVES:12)
Block(1,36,-2,LEAVES:12)
Block(1,36,0,LEAVES:12)
Block(1,36,1,17:12)
Block(1,36,6,17:12)
Block(1,36,7,LEAVES:12)
Block(1,36,8,LEAVES:12)
Block(1,36,9,LEAVES:12)
Block(1,36,11,17:12)
Block(1,37,-1,LEAVES:12)
Block(1,37,2,LEAVES:12)
Block(1,37,3,LEAVES:12)
Block(1,37,6,17:12)
Block(1,37,7,LEAVES:12)
Block(1,37,8,LEAVES:12)
Block(1,37,11,LEAVES:12)
Block(1,37,12,LEAVES:12)
Block(1,37,13,LEAVES:12)
Block(1,38,0,LEAVES:12)
Block(1,38,2,LEAVES:12)
Block(1,38,3,LEAVES:12)
Block(1,38,4,LEAVES:12)
Block(1,38,5,17:12)
Block(1,38,6,17:12)
Block(1,38,7,17:12)
Block(1,38,8,LEAVES:12)
Block(1,38,9,LEAVES:12)
Block(1,38,10,LEAVES:12)
Block(1,38,11,LEAVES:12)
Block(1,38,12,LEAVES:12)
Block(1,39,2,LEAVES:12)
Block(1,39,3,LEAVES:12)
Block(1,39,4,LEAVES:12)
Block(1,39,5,LEAVES:12)
Block(1,39,6,LEAVES:12)
Block(1,39,7,LEAVES:12)
Block(1,39,8,17:12)
Block(1,39,9,LEAVES:12)
Block(1,39,10,LEAVES:12)
Block(1,39,11,LEAVES:12)
Block(1,40,1,LEAVES:12)
Block(1,40,5,LEAVES:12)
Block(1,40,6,LEAVES:12)
Block(1,40,7,17:12)
Block(1,40,9,LEAVES:12)
Block(1,40,10,LEAVES:12)
Block(1,41,5,LEAVES:12)
Block(1,41,6,LEAVES:12)
Block(1,41,7,17:12)
Block(1,42,1,LEAVES:12)
Block(1,42,5,LEAVES:12)
Block(1,42,9,LEAVES:12)
Block(1,43,2,LEAVES:12)
Block(1,43,5,LEAVES:12)
Block(1,43,6,LEAVES:12)
Block(1,43,7,LEAVES:12)
Block(1,43,8,LEAVES:12)
Block(1,43,9,LEAVES:12)
Block(1,44,8,LEAVES:12)
Block(2,0,4,17:12)
Block(2,1,4,17:12)
Block(2,1,5,17:12)
Block(2,2,2,17:12)
Block(2,2,3,17:12)
Block(2,2,4,17:12)
Block(2,3,2,17:12)
Block(2,3,3,17:12)
Block(2,3,4,17:12)
Block(2,3,5,17:12)
Block(2,4,1,17:12)
Block(2,4,2,17:12)
Block(2,4,3,17:12)
Block(2,4,4,162:1)
Block(2,4,5,17:12)
Block(2,5,2,17:12)
Block(2,5,3,17:12)
Block(2,5,4,17:12)
Block(2,5,5,17:12)
Block(2,6,3,17:12)
Block(2,6,4,17:12)
Block(2,6,5,17:12)
Block(2,7,4,17:12)
Block(2,8,-4,LEAVES:12)
Block(2,8,-3,LEAVES:12)
Block(2,8,-2,LEAVES:12)
Block(2,9,-3,LEAVES:12)
Block(2,9,-2,LEAVES:12)
Block(2,9,-1,LEAVES:12)
Block(2,9,0,LEAVES:12)
Block(2,9,1,LEAVES:12)
Block(2,10,-2,LEAVES:12)
Block(2,10,0,LEAVES:12)
Block(2,10,1,LEAVES:12)
Block(2,10,2,LEAVES:12)
Block(2,11,-4,LEAVES:12)
Block(2,11,-3,LEAVES:12)
Block(2,11,-2,LEAVES:12)
Block(2,11,-1,LEAVES:12)
Block(2,11,0,17:12)
Block(2,11,1,17:12)
Block(2,11,2,17:12)
Block(2,12,-5,LEAVES:12)
Block(2,12,-4,LEAVES:12)
Block(2,12,-3,LEAVES:12)
Block(2,12,-2,LEAVES:12)
Block(2,12,-1,17:12)
Block(2,12,0,17:12)
Block(2,12,2,17:12)
Block(2,13,-6,LEAVES:12)
Block(2,13,-5,LEAVES:12)
Block(2,13,-4,LEAVES:12)
Block(2,13,-2,LEAVES:12)
Block(2,13,0,LEAVES:12)
Block(2,13,1,LEAVES:12)
Block(2,13,2,17:12)
Block(2,14,-5,LEAVES:12)
Block(2,14,-2,LEAVES:12)
Block(2,14,-1,LEAVES:12)
Block(2,14,0,LEAVES:12)
Block(2,14,1,LEAVES:12)
Block(2,14,2,LEAVES:12)
Block(2,15,-7,LEAVES:12)
Block(2,15,-6,LEAVES:12)
Block(2,15,-5,LEAVES:12)
Block(2,15,-4,LEAVES:12)
Block(2,15,-3,LEAVES:12)
Block(2,15,-2,LEAVES:12)
Block(2,15,-1,LEAVES:12)
Block(2,15,1,LEAVES:12)
Block(2,15,2,LEAVES:12)
Block(2,15,3,LEAVES:12)
Block(2,15,4,LEAVES:12)
Block(2,15,5,LEAVES:12)
Block(2,16,-8,LEAVES:12)
Block(2,16,-7,LEAVES:12)
Block(2,16,-6,LEAVES:12)
Block(2,16,-4,LEAVES:12)
Block(2,16,-3,LEAVES:12)
Block(2,16,-2,LEAVES:12)
Block(2,16,2,LEAVES:12)
Block(2,16,4,LEAVES:12)
Block(2,16,5,17:12)
Block(2,17,-7,LEAVES:12)
Block(2,17,-3,LEAVES:12)
Block(2,17,1,LEAVES:12)
Block(2,17,5,17:12)
Block(2,17,6,17:12)
Block(2,18,-4,LEAVES:12)
Block(2,18,-1,LEAVES:12)
Block(2,18,0,LEAVES:12)
Block(2,18,5,17:12)
Block(2,18,6,17:12)
Block(2,19,-2,LEAVES:12)
Block(2,19,-1,LEAVES:12)
Block(2,19,0,LEAVES:12)
Block(2,19,4,17:12)
Block(2,19,5,17:12)
Block(2,20,-4,LEAVES:12)
Block(2,20,-3,17:12)
Block(2,20,-1,LEAVES:12)
Block(2,20,2,17:12)
Block(2,20,3,17:12)
Block(2,20,4,17:12)
Block(2,20,5,17:12)
Block(2,20,10,LEAVES:12)
Block(2,20,11,LEAVES:12)
Block(2,20,12,LEAVES:12)
Block(2,21,-6,LEAVES:12)
Block(2,21,-5,LEAVES:12)
Block(2,21,-4,LEAVES:12)
Block(2,21,-2,LEAVES:12)
Block(2,21,-1,17:12)
Block(2,21,1,17:12)
Block(2,21,2,17:12)
Block(2,21,3,17:12)
Block(2,21,4,17:12)
Block(2,21,5,17:12)
Block(2,21,6,17:12)
Block(2,21,11,LEAVES:12)
Block(2,21,13,LEAVES:12)
Block(2,21,14,LEAVES:12)
Block(2,21,15,LEAVES:12)
Block(2,22,-7,LEAVES:12)
Block(2,22,-6,LEAVES:12)
Block(2,22,-5,LEAVES:12)
Block(2,22,-3,LEAVES:12)
Block(2,22,-1,LEAVES:12)
Block(2,22,4,17:12)
Block(2,22,6,17:12)
Block(2,22,7,17:12)
Block(2,22,8,17:12)
Block(2,22,11,LEAVES:12)
Block(2,22,12,LEAVES:12)
Block(2,22,13,LEAVES:12)
Block(2,22,14,LEAVES:12)
Block(2,22,16,LEAVES:12)
Block(2,23,-7,LEAVES:12)
Block(2,23,-6,LEAVES:12)
Block(2,23,-5,LEAVES:12)
Block(2,23,-3,LEAVES:12)
Block(2,23,-2,LEAVES:12)
Block(2,23,-1,17:12)
Block(2,23,4,17:12)
Block(2,23,7,LEAVES:12)
Block(2,23,10,LEAVES:12)
Block(2,23,11,LEAVES:12)
Block(2,23,12,LEAVES:12)
Block(2,23,13,LEAVES:12)
Block(2,23,14,LEAVES:12)
Block(2,23,15,LEAVES:12)
Block(2,24,-7,LEAVES:12)
Block(2,24,-6,LEAVES:12)
Block(2,24,-5,LEAVES:12)
Block(2,24,-4,LEAVES:12)
Block(2,24,-2,LEAVES:12)
Block(2,24,3,LEAVES:12)
Block(2,24,6,17:12)
Block(2,24,8,LEAVES:12)
Block(2,24,9,LEAVES:12)
Block(2,24,10,LEAVES:12)
Block(2,24,11,17:12)
Block(2,24,12,LEAVES:12)
Block(2,24,13,LEAVES:12)
Block(2,24,14,LEAVES:12)
Block(2,24,17,LEAVES:12)
Block(2,25,-7,LEAVES:12)
Block(2,25,-6,LEAVES:12)
Block(2,25,-5,LEAVES:12)
Block(2,25,-3,LEAVES:12)
Block(2,25,2,LEAVES:12)
Block(2,25,6,17:12)
Block(2,25,8,LEAVES:12)
Block(2,25,9,LEAVES:12)
Block(2,25,10,LEAVES:12)
Block(2,25,11,LEAVES:12)
Block(2,25,12,LEAVES:12)
Block(2,25,13,LEAVES:12)
Block(2,25,18,LEAVES:12)
Block(2,26,-6,LEAVES:12)
Block(2,26,-5,LEAVES:12)
Block(2,26,-4,LEAVES:12)
Block(2,26,-1,LEAVES:12)
Block(2,26,6,17:12)
Block(2,26,9,LEAVES:12)
Block(2,26,10,LEAVES:12)
Block(2,26,11,LEAVES:12)
Block(2,26,12,LEAVES:12)
Block(2,26,13,LEAVES:12)
Block(2,27,-5,LEAVES:12)
Block(2,27,-4,LEAVES:12)
Block(2,27,-3,LEAVES:12)
Block(2,27,-1,LEAVES:12)
Block(2,27,0,LEAVES:12)
Block(2,27,6,17:12)
Block(2,27,7,17:12)
Block(2,27,10,LEAVES:12)
Block(2,27,11,LEAVES:12)
Block(2,27,12,LEAVES:12)
Block(2,27,13,LEAVES:12)
Block(2,27,14,LEAVES:12)
Block(2,28,-4,LEAVES:12)
Block(2,28,6,17:12)
Block(2,28,7,17:12)
Block(2,28,9,LEAVES:12)
Block(2,28,10,LEAVES:12)
Block(2,28,11,LEAVES:12)
Block(2,28,13,LEAVES:12)
Block(2,29,7,17:12)
Block(2,29,10,LEAVES:12)
Block(2,30,1,LEAVES:12)
Block(2,30,7,17:12)
Block(2,30,11,LEAVES:12)
Block(2,30,12,LEAVES:12)
Block(2,30,13,LEAVES:12)
Block(2,30,14,LEAVES:12)
Block(2,31,3,17:12)
Block(2,31,4,17:12)
Block(2,31,5,17:12)
Block(2,31,6,17:12)
Block(2,31,7,17:12)
Block(2,31,10,17:12)
Block(2,31,12,LEAVES:12)
Block(2,31,13,LEAVES:12)
Block(2,32,10,LEAVES:12)
Block(2,33,-1,LEAVES:12)
Block(2,33,0,LEAVES:12)
Block(2,33,1,LEAVES:12)
Block(2,33,6,17:12)
Block(2,33,9,LEAVES:12)
Block(2,33,10,LEAVES:12)
Block(2,33,11,LEAVES:12)
Block(2,33,13,LEAVES:12)
Block(2,33,14,LEAVES:12)
Block(2,34,0,LEAVES:12)
Block(2,34,6,17:12)
Block(2,34,9,LEAVES:12)
Block(2,34,10,LEAVES:12)
Block(2,34,11,LEAVES:12)
Block(2,34,12,LEAVES:12)
Block(2,35,-2,LEAVES:12)
Block(2,35,4,LEAVES:12)
Block(2,35,9,LEAVES:12)
Block(2,35,11,LEAVES:12)
Block(2,35,12,LEAVES:12)
Block(2,35,13,LEAVES:12)
Block(2,36,0,LEAVES:12)
Block(2,36,3,LEAVES:12)
Block(2,36,8,LEAVES:12)
Block(2,36,10,17:12)
Block(2,36,11,LEAVES:12)
Block(2,36,12,LEAVES:12)
Block(2,37,1,17:12)
Block(2,37,2,LEAVES:12)
Block(2,37,3,LEAVES:12)
Block(2,37,4,LEAVES:12)
Block(2,37,8,LEAVES:12)
Block(2,37,9,LEAVES:12)
Block(2,37,10,LEAVES:12)
Block(2,37,11,LEAVES:12)
Block(2,37,12,LEAVES:12)
Block(2,38,1,LEAVES:12)
Block(2,38,2,LEAVES:12)
Block(2,38,3,LEAVES:12)
Block(2,38,4,LEAVES:12)
Block(2,38,8,LEAVES:12)
Block(2,38,9,LEAVES:12)
Block(2,38,10,LEAVES:12)
Block(2,38,11,LEAVES:12)
Block(2,38,12,LEAVES:12)
Block(2,39,2,LEAVES:12)
Block(2,39,5,17:12)
Block(2,39,6,LEAVES:12)
Block(2,39,8,LEAVES:12)
Block(2,39,9,LEAVES:12)
Block(2,39,10,LEAVES:12)
Block(2,39,11,LEAVES:12)
Block(2,40,3,LEAVES:12)
Block(2,40,6,LEAVES:12)
Block(2,40,8,LEAVES:12)
Block(2,40,9,LEAVES:12)
Block(2,40,10,LEAVES:12)
Block(2,41,5,LEAVES:12)
Block(2,41,6,LEAVES:12)
Block(2,41,7,LEAVES:12)
Block(2,41,9,LEAVES:12)
Block(2,42,0,LEAVES:12)
Block(2,42,1,LEAVES:12)
Block(2,42,2,LEAVES:12)
Block(2,42,4,LEAVES:12)
Block(2,42,5,LEAVES:12)
Block(2,42,6,LEAVES:12)
Block(2,43,1,LEAVES:12)
Block(2,43,2,LEAVES:12)
Block(2,43,3,LEAVES:12)
Block(2,43,5,LEAVES:12)
Block(2,43,6,LEAVES:12)
Block(2,43,7,LEAVES:12)
Block(2,43,8,LEAVES:12)
Block(2,44,2,LEAVES:12)
Block(2,44,7,LEAVES:12)
Block(2,44,8,LEAVES:12)
Block(2,44,9,LEAVES:12)
Block(2,45,8,LEAVES:12)
Block(3,0,4,17:12)
Block(3,0,5,17:12)
Block(3,1,4,17:12)
Block(3,1,5,17:12)
Block(3,2,4,17:12)
Block(3,3,3,17:12)
Block(3,3,4,17:12)
Block(3,4,2,17:12)
Block(3,4,3,17:12)
Block(3,4,4,17:12)
Block(3,4,5,17:12)
Block(3,5,1,17:12)
Block(3,5,2,17:12)
Block(3,5,3,17:12)
Block(3,5,4,17:12)
Block(3,6,2,17:12)
Block(3,6,3,17:12)
Block(3,6,4,17:12)
Block(3,6,5,17:12)
Block(3,7,3,17:12)
Block(3,7,4,17:12)
Block(3,7,5,17:12)
Block(3,8,-3,LEAVES:12)
Block(3,8,3,17:12)
Block(3,8,4,17:12)
Block(3,8,5,17:12)
Block(3,9,-2,LEAVES:12)
Block(3,9,0,LEAVES:12)
Block(3,9,1,LEAVES:12)
Block(3,9,2,LEAVES:12)
Block(3,9,4,17:12)
Block(3,9,5,17:12)
Block(3,9,6,17:12)
Block(3,10,1,LEAVES:12)
Block(3,10,5,17:12)
Block(3,10,6,17:12)
Block(3,11,-5,LEAVES:12)
Block(3,11,-4,LEAVES:12)
Block(3,11,-3,LEAVES:12)
Block(3,11,5,17:12)
Block(3,11,6,17:12)
Block(3,11,7,17:12)
Block(3,12,-6,LEAVES:12)
Block(3,12,-5,LEAVES:12)
Block(3,12,-4,LEAVES:12)
Block(3,12,-3,LEAVES:12)
Block(3,12,-2,LEAVES:12)
Block(3,12,0,LEAVES:12)
Block(3,12,2,17:12)
Block(3,12,3,17:12)
Block(3,12,4,17:12)
Block(3,12,5,17:12)
Block(3,12,6,17:12)
Block(3,12,7,17:12)
Block(3,12,15,LEAVES:12)
Block(3,13,-6,LEAVES:12)
Block(3,13,-5,LEAVES:12)
Block(3,13,-3,LEAVES:12)
Block(3,13,-2,17:12)
Block(3,13,-1,LEAVES:12)
Block(3,13,0,LEAVES:12)
Block(3,13,1,LEAVES:12)
Block(3,13,6,17:12)
Block(3,13,14,LEAVES:12)
Block(3,14,-4,17:12)
Block(3,14,-3,17:12)
Block(3,14,-2,17:12)
Block(3,14,-1,LEAVES:12)
Block(3,14,0,LEAVES:12)
Block(3,14,1,LEAVES:12)
Block(3,14,11,LEAVES:12)
Block(3,15,-6,LEAVES:12)
Block(3,15,-5,LEAVES:12)
Block(3,15,-4,LEAVES:12)
Block(3,15,-2,LEAVES:12)
Block(3,15,2,LEAVES:12)
Block(3,15,4,LEAVES:12)
Block(3,15,5,17:12)
Block(3,15,6,17:12)
Block(3,15,12,LEAVES:12)
Block(3,16,-7,LEAVES:12)
Block(3,16,-6,LEAVES:12)
Block(3,16,-5,LEAVES:12)
Block(3,16,-4,LEAVES:12)
Block(3,16,-3,LEAVES:12)
Block(3,16,5,17:12)
Block(3,16,6,17:12)
Block(3,17,-6,LEAVES:12)
Block(3,17,-4,LEAVES:12)
Block(3,17,5,17:12)
Block(3,17,6,17:12)
Block(3,18,-5,LEAVES:12)
Block(3,18,-4,LEAVES:12)
Block(3,18,-3,LEAVES:12)
Block(3,18,-2,LEAVES:12)
Block(3,18,-1,LEAVES:12)
Block(3,18,0,LEAVES:12)
Block(3,18,4,17:12)
Block(3,18,5,17:12)
Block(3,18,6,17:12)
Block(3,19,-5,LEAVES:12)
Block(3,19,-4,LEAVES:12)
Block(3,19,-3,LEAVES:12)
Block(3,19,-2,LEAVES:12)
Block(3,19,-1,LEAVES:12)
Block(3,19,4,17:12)
Block(3,19,5,17:12)
Block(3,19,6,17:12)
Block(3,20,-5,LEAVES:12)
Block(3,20,-4,LEAVES:12)
Block(3,20,-2,LEAVES:12)
Block(3,20,-1,LEAVES:12)
Block(3,20,0,LEAVES:12)
Block(3,20,4,17:12)
Block(3,20,5,17:12)
Block(3,20,11,LEAVES:12)
Block(3,21,-6,LEAVES:12)
Block(3,21,-5,LEAVES:12)
Block(3,21,-4,LEAVES:12)
Block(3,21,-3,LEAVES:12)
Block(3,21,-2,LEAVES:12)
Block(3,21,-1,LEAVES:12)
Block(3,21,0,17:12)
Block(3,21,1,17:12)
Block(3,21,4,17:12)
Block(3,21,5,17:12)
Block(3,21,14,LEAVES:12)
Block(3,21,15,LEAVES:12)
Block(3,21,16,LEAVES:12)
Block(3,22,-6,LEAVES:12)
Block(3,22,-5,LEAVES:12)
Block(3,22,-4,LEAVES:12)
Block(3,22,-3,LEAVES:12)
Block(3,22,-2,LEAVES:12)
Block(3,22,-1,17:12)
Block(3,22,0,17:12)
Block(3,22,1,17:12)
Block(3,22,10,LEAVES:12)
Block(3,22,12,LEAVES:12)
Block(3,22,13,LEAVES:12)
Block(3,22,14,LEAVES:12)
Block(3,22,15,LEAVES:12)
Block(3,23,-6,LEAVES:12)
Block(3,23,-5,LEAVES:12)
Block(3,23,-4,17:12)
Block(3,23,-3,17:12)
Block(3,23,-2,LEAVES:12)
Block(3,23,-1,LEAVES:12)
Block(3,23,1,17:12)
Block(3,23,11,LEAVES:12)
Block(3,23,12,LEAVES:12)
Block(3,23,14,LEAVES:12)
Block(3,23,15,LEAVES:12)
Block(3,23,16,LEAVES:12)
Block(3,24,-6,LEAVES:12)
Block(3,24,-5,LEAVES:12)
Block(3,24,-2,LEAVES:12)
Block(3,24,2,LEAVES:12)
Block(3,24,3,LEAVES:12)
Block(3,24,4,LEAVES:12)
Block(3,24,9,LEAVES:12)
Block(3,24,10,LEAVES:12)
Block(3,24,11,17:12)
Block(3,24,12,LEAVES:12)
Block(3,24,13,LEAVES:12)
Block(3,24,14,LEAVES:12)
Block(3,24,15,LEAVES:12)
Block(3,25,-6,LEAVES:12)
Block(3,25,-5,LEAVES:12)
Block(3,25,-1,LEAVES:12)
Block(3,25,1,LEAVES:12)
Block(3,25,2,LEAVES:12)
Block(3,25,3,LEAVES:12)
Block(3,25,6,17:12)
Block(3,25,9,LEAVES:12)
Block(3,25,11,17:12)
Block(3,25,12,LEAVES:12)
Block(3,25,13,LEAVES:12)
Block(3,25,14,LEAVES:12)
Block(3,26,-7,LEAVES:12)
Block(3,26,-5,LEAVES:12)
Block(3,26,-2,LEAVES:12)
Block(3,26,-1,LEAVES:12)
Block(3,26,0,LEAVES:12)
Block(3,26,2,LEAVES:12)
Block(3,26,9,LEAVES:12)
Block(3,26,10,LEAVES:12)
Block(3,26,12,17:12)
Block(3,26,13,LEAVES:12)
Block(3,26,14,LEAVES:12)
Block(3,27,-6,LEAVES:12)
Block(3,27,-5,LEAVES:12)
Block(3,27,-4,LEAVES:12)
Block(3,27,-1,LEAVES:12)
Block(3,27,0,LEAVES:12)
Block(3,27,1,LEAVES:12)
Block(3,27,6,17:12)
Block(3,27,9,LEAVES:12)
Block(3,27,10,LEAVES:12)
Block(3,27,11,LEAVES:12)
Block(3,27,12,LEAVES:12)
Block(3,27,13,LEAVES:12)
Block(3,27,14,LEAVES:12)
Block(3,27,15,LEAVES:12)
Block(3,28,-5,LEAVES:12)
Block(3,28,0,LEAVES:12)
Block(3,28,1,LEAVES:12)
Block(3,28,7,17:12)
Block(3,28,10,LEAVES:12)
Block(3,28,14,LEAVES:12)
Block(3,29,2,LEAVES:12)
Block(3,29,7,17:12)
Block(3,29,8,17:12)
Block(3,30,0,LEAVES:12)
Block(3,30,1,LEAVES:12)
Block(3,30,2,LEAVES:12)
Block(3,30,4,LEAVES:12)
Block(3,30,7,17:12)
Block(3,30,8,17:12)
Block(3,30,10,LEAVES:12)
Block(3,30,11,LEAVES:12)
Block(3,30,12,LEAVES:12)
Block(3,30,13,LEAVES:12)
Block(3,31,1,LEAVES:12)
Block(3,31,3,17:12)
Block(3,31,6,17:12)
Block(3,31,7,17:12)
Block(3,31,9,LEAVES:12)
Block(3,31,10,17:12)
Block(3,31,12,LEAVES:12)
Block(3,31,13,LEAVES:12)
Block(3,31,14,LEAVES:12)
Block(3,32,2,17:12)
Block(3,32,3,17:12)
Block(3,32,6,17:12)
Block(3,32,7,17:12)
Block(3,32,9,LEAVES:12)
Block(3,32,10,LEAVES:12)
Block(3,32,11,LEAVES:12)
Block(3,32,12,LEAVES:12)
Block(3,32,13,LEAVES:12)
Block(3,33,0,LEAVES:12)
Block(3,33,1,LEAVES:12)
Block(3,33,2,LEAVES:12)
Block(3,33,6,17:12)
Block(3,33,7,17:12)
Block(3,33,10,LEAVES:12)
Block(3,33,11,LEAVES:12)
Block(3,33,12,LEAVES:12)
Block(3,33,13,LEAVES:12)
Block(3,34,-1,LEAVES:12)
Block(3,34,0,LEAVES:12)
Block(3,34,1,LEAVES:12)
Block(3,34,7,17:12)
Block(3,34,8,LEAVES:12)
Block(3,34,9,LEAVES:12)
Block(3,34,10,LEAVES:12)
Block(3,34,11,LEAVES:12)
Block(3,34,12,LEAVES:12)
Block(3,34,13,LEAVES:12)
Block(3,35,-3,LEAVES:12)
Block(3,35,-2,LEAVES:12)
Block(3,35,-1,LEAVES:12)
Block(3,35,0,LEAVES:12)
Block(3,35,3,LEAVES:12)
Block(3,35,4,LEAVES:12)
Block(3,35,5,LEAVES:12)
Block(3,35,8,17:12)
Block(3,35,9,LEAVES:12)
Block(3,35,10,LEAVES:12)
Block(3,35,11,LEAVES:12)
Block(3,35,12,LEAVES:12)
Block(3,36,-2,LEAVES:12)
Block(3,36,-1,LEAVES:12)
Block(3,36,2,LEAVES:12)
Block(3,36,3,LEAVES:12)
Block(3,36,4,LEAVES:12)
Block(3,36,8,LEAVES:12)
Block(3,36,10,17:12)
Block(3,36,11,LEAVES:12)
Block(3,37,0,LEAVES:12)
Block(3,37,3,LEAVES:12)
Block(3,37,7,LEAVES:12)
Block(3,37,8,LEAVES:12)
Block(3,37,9,LEAVES:12)
Block(3,37,10,LEAVES:12)
Block(3,37,11,LEAVES:12)
Block(3,37,12,LEAVES:12)
Block(3,38,0,LEAVES:12)
Block(3,38,1,LEAVES:12)
Block(3,38,2,LEAVES:12)
Block(3,38,3,LEAVES:12)
Block(3,38,4,LEAVES:12)
Block(3,38,5,LEAVES:12)
Block(3,38,7,LEAVES:12)
Block(3,38,8,LEAVES:12)
Block(3,38,9,LEAVES:12)
Block(3,38,10,LEAVES:12)
Block(3,38,11,LEAVES:12)
Block(3,38,12,LEAVES:12)
Block(3,38,13,LEAVES:12)
Block(3,39,1,LEAVES:12)
Block(3,39,2,LEAVES:12)
Block(3,39,3,LEAVES:12)
Block(3,39,4,LEAVES:12)
Block(3,39,5,17:12)
Block(3,39,8,LEAVES:12)
Block(3,39,9,LEAVES:12)
Block(3,39,10,LEAVES:12)
Block(3,39,11,LEAVES:12)
Block(3,39,12,LEAVES:12)
Block(3,40,1,LEAVES:12)
Block(3,40,2,LEAVES:12)
Block(3,40,3,LEAVES:12)
Block(3,40,4,17:12)
Block(3,40,5,17:12)
Block(3,40,6,LEAVES:12)
Block(3,40,7,LEAVES:12)
Block(3,40,8,LEAVES:12)
Block(3,40,9,LEAVES:12)
Block(3,40,10,LEAVES:12)
Block(3,40,11,LEAVES:12)
Block(3,41,3,LEAVES:12)
Block(3,41,4,LEAVES:12)
Block(3,41,5,LEAVES:12)
Block(3,41,6,LEAVES:12)
Block(3,41,8,LEAVES:12)
Block(3,41,9,LEAVES:12)
Block(3,41,10,LEAVES:12)
Block(3,42,1,LEAVES:12)
Block(3,42,5,LEAVES:12)
Block(3,42,6,LEAVES:12)
Block(3,42,7,LEAVES:12)
Block(3,42,9,LEAVES:12)
Block(3,43,0,LEAVES:12)
Block(3,43,1,LEAVES:12)
Block(3,43,2,LEAVES:12)
Block(3,43,6,LEAVES:12)
Block(3,43,7,LEAVES:12)
Block(3,44,1,LEAVES:12)
Block(3,44,8,LEAVES:12)
Block(4,0,4,17:12)
Block(4,0,5,17:12)
Block(4,0,6,17:12)
Block(4,4,3,17:12)
Block(4,5,2,17:12)
Block(4,5,3,17:12)
Block(4,5,4,17:12)
Block(4,6,2,17:12)
Block(4,6,3,17:12)
Block(4,6,4,17:12)
Block(4,7,3,17:12)
Block(4,7,4,17:12)
Block(4,7,5,17:12)
Block(4,8,3,17:12)
Block(4,8,4,17:12)
Block(4,8,5,17:12)
Block(4,8,6,17:12)
Block(4,9,1,LEAVES:12)
Block(4,9,4,17:12)
Block(4,9,5,17:12)
Block(4,9,6,17:12)
Block(4,10,4,17:12)
Block(4,10,5,17:12)
Block(4,10,6,17:12)
Block(4,10,7,17:12)
Block(4,11,-4,LEAVES:12)
Block(4,11,4,17:12)
Block(4,11,5,17:12)
Block(4,11,6,17:12)
Block(4,11,7,17:12)
Block(4,12,-5,LEAVES:12)
Block(4,12,-3,LEAVES:12)
Block(4,12,-1,LEAVES:12)
Block(4,12,0,LEAVES:12)
Block(4,12,1,LEAVES:12)
Block(4,12,4,17:12)
Block(4,12,5,17:12)
Block(4,12,6,17:12)
Block(4,12,7,17:12)
Block(4,12,14,LEAVES:12)
Block(4,12,15,LEAVES:12)
Block(4,12,16,LEAVES:12)
Block(4,13,-7,LEAVES:12)
Block(4,13,-6,LEAVES:12)
Block(4,13,-5,LEAVES:12)
Block(4,13,-2,LEAVES:12)
Block(4,13,-1,LEAVES:12)
Block(4,13,0,LEAVES:12)
Block(4,13,4,17:12)
Block(4,13,5,17:12)
Block(4,13,6,17:12)
Block(4,13,7,17:12)
Block(4,13,13,LEAVES:12)
Block(4,13,14,LEAVES:12)
Block(4,13,15,LEAVES:12)
Block(4,14,-6,LEAVES:12)
Block(4,14,-1,LEAVES:12)
Block(4,14,4,17:12)
Block(4,14,5,17:12)
Block(4,14,6,17:12)
Block(4,14,7,17:12)
Block(4,14,10,LEAVES:12)
Block(4,14,11,LEAVES:12)
Block(4,14,12,LEAVES:12)
Block(4,14,14,LEAVES:12)
Block(4,15,-6,LEAVES:12)
Block(4,15,3,LEAVES:12)
Block(4,15,4,17:12)
Block(4,15,5,17:12)
Block(4,15,6,17:12)
Block(4,15,11,LEAVES:12)
Block(4,15,12,LEAVES:12)
Block(4,15,13,LEAVES:12)
Block(4,16,-6,LEAVES:12)
Block(4,16,-5,LEAVES:12)
Block(4,16,-4,LEAVES:12)
Block(4,16,-3,LEAVES:12)
Block(4,16,2,LEAVES:12)
Block(4,16,4,17:12)
Block(4,16,5,17:12)
Block(4,16,6,17:12)
Block(4,16,12,LEAVES:12)
Block(4,16,13,LEAVES:12)
Block(4,17,-5,LEAVES:12)
Block(4,17,-4,LEAVES:12)
Block(4,17,-3,LEAVES:12)
Block(4,17,5,17:12)
Block(4,17,6,17:12)
Block(4,17,14,LEAVES:12)
Block(4,18,-6,LEAVES:12)
Block(4,18,-5,LEAVES:12)
Block(4,18,-4,LEAVES:12)
Block(4,18,-1,LEAVES:12)
Block(4,18,0,LEAVES:12)
Block(4,19,-5,LEAVES:12)
Block(4,19,-4,LEAVES:12)
Block(4,19,-3,LEAVES:12)
Block(4,19,-2,LEAVES:12)
Block(4,19,1,LEAVES:12)
Block(4,20,-6,LEAVES:12)
Block(4,20,-5,LEAVES:12)
Block(4,20,-4,LEAVES:12)
Block(4,20,-1,LEAVES:12)
Block(4,20,0,LEAVES:12)
Block(4,21,-7,LEAVES:12)
Block(4,21,-6,LEAVES:12)
Block(4,21,-5,LEAVES:12)
Block(4,21,-4,LEAVES:12)
Block(4,21,-2,LEAVES:12)
Block(4,21,-1,LEAVES:12)
Block(4,21,0,LEAVES:12)
Block(4,21,10,LEAVES:12)
Block(4,21,12,LEAVES:12)
Block(4,21,15,LEAVES:12)
Block(4,21,16,LEAVES:12)
Block(4,21,17,LEAVES:12)
Block(4,22,-6,LEAVES:12)
Block(4,22,-5,LEAVES:12)
Block(4,22,-3,LEAVES:12)
Block(4,22,-2,17:12)
Block(4,22,-1,17:12)
Block(4,22,9,LEAVES:12)
Block(4,22,10,LEAVES:12)
Block(4,22,11,LEAVES:12)
Block(4,22,13,LEAVES:12)
Block(4,22,14,LEAVES:12)
Block(4,22,16,LEAVES:12)
Block(4,23,-6,LEAVES:12)
Block(4,23,-5,LEAVES:12)
Block(4,23,-4,LEAVES:12)
Block(4,23,-3,LEAVES:12)
Block(4,23,-2,LEAVES:12)
Block(4,23,-1,LEAVES:12)
Block(4,23,0,LEAVES:12)
Block(4,23,10,LEAVES:12)
Block(4,23,12,17:12)
Block(4,23,13,17:12)
Block(4,23,15,LEAVES:12)
Block(4,24,-5,LEAVES:12)
Block(4,24,-4,17:12)
Block(4,24,-1,LEAVES:12)
Block(4,24,1,17:12)
Block(4,24,3,LEAVES:12)
Block(4,24,12,LEAVES:12)
Block(4,24,13,LEAVES:12)
Block(4,24,14,LEAVES:12)
Block(4,25,-7,LEAVES:12)
Block(4,25,-2,LEAVES:12)
Block(4,25,-1,LEAVES:12)
Block(4,25,0,LEAVES:12)
Block(4,25,2,LEAVES:12)
Block(4,25,3,LEAVES:12)
Block(4,25,4,17:12)
Block(4,25,5,LEAVES:12)
Block(4,25,6,17:12)
Block(4,25,9,LEAVES:12)
Block(4,25,12,LEAVES:12)
Block(4,25,13,LEAVES:12)
Block(4,25,14,LEAVES:12)
Block(4,25,16,LEAVES:12)
Block(4,26,-8,LEAVES:12)
Block(4,26,-7,LEAVES:12)
Block(4,26,-6,LEAVES:12)
Block(4,26,-3,LEAVES:12)
Block(4,26,-2,LEAVES:12)
Block(4,26,-1,LEAVES:12)
Block(4,26,1,LEAVES:12)
Block(4,26,2,LEAVES:12)
Block(4,26,3,LEAVES:12)
Block(4,26,4,LEAVES:12)
Block(4,26,8,LEAVES:12)
Block(4,26,9,LEAVES:12)
Block(4,26,10,LEAVES:12)
Block(4,26,12,LEAVES:12)
Block(4,26,13,LEAVES:12)
Block(4,27,-7,LEAVES:12)
Block(4,27,-5,LEAVES:12)
Block(4,27,-2,LEAVES:12)
Block(4,27,-1,LEAVES:12)
Block(4,27,0,LEAVES:12)
Block(4,27,9,LEAVES:12)
Block(4,27,10,LEAVES:12)
Block(4,27,12,LEAVES:12)
Block(4,27,13,LEAVES:12)
Block(4,27,14,LEAVES:12)
Block(4,28,-1,LEAVES:12)
Block(4,28,0,LEAVES:12)
Block(4,28,1,LEAVES:12)
Block(4,28,2,LEAVES:12)
Block(4,28,3,17:12)
Block(4,28,13,LEAVES:12)
Block(4,29,1,LEAVES:12)
Block(4,29,2,LEAVES:12)
Block(4,29,3,LEAVES:12)
Block(4,30,1,LEAVES:12)
Block(4,30,2,LEAVES:12)
Block(4,30,3,LEAVES:12)
Block(4,30,4,LEAVES:12)
Block(4,30,5,LEAVES:12)
Block(4,30,7,17:12)
Block(4,30,9,LEAVES:12)
Block(4,30,10,LEAVES:12)
Block(4,30,11,LEAVES:12)
Block(4,30,12,LEAVES:12)
Block(4,31,0,LEAVES:12)
Block(4,31,1,LEAVES:12)
Block(4,31,2,LEAVES:12)
Block(4,31,4,LEAVES:12)
Block(4,31,6,17:12)
Block(4,31,7,17:12)
Block(4,31,8,LEAVES:12)
Block(4,31,9,LEAVES:12)
Block(4,31,10,17:12)
Block(4,31,12,LEAVES:12)
Block(4,31,13,LEAVES:12)
Block(4,32,1,LEAVES:12)
Block(4,32,2,17:12)
Block(4,32,9,LEAVES:12)
Block(4,32,10,LEAVES:12)
Block(4,32,11,17:12)
Block(4,32,12,17:12)
Block(4,32,13,LEAVES:12)
Block(4,32,14,LEAVES:12)
Block(4,33,1,LEAVES:12)
Block(4,33,6,17:12)
Block(4,33,11,LEAVES:12)
Block(4,33,12,LEAVES:12)
Block(4,33,13,LEAVES:12)
Block(4,33,14,LEAVES:12)
Block(4,34,0,LEAVES:12)
Block(4,34,1,LEAVES:12)
Block(4,34,6,17:12)
Block(4,34,7,LEAVES:12)
Block(4,34,8,LEAVES:12)
Block(4,34,9,LEAVES:12)
Block(4,34,11,LEAVES:12)
Block(4,34,12,LEAVES:12)
Block(4,34,13,LEAVES:12)
Block(4,35,-2,LEAVES:12)
Block(4,35,-1,LEAVES:12)
Block(4,35,0,LEAVES:12)
Block(4,35,2,LEAVES:12)
Block(4,35,3,LEAVES:12)
Block(4,35,4,LEAVES:12)
Block(4,35,8,LEAVES:12)
Block(4,35,9,17:12)
Block(4,35,10,LEAVES:12)
Block(4,35,11,LEAVES:12)
Block(4,35,12,LEAVES:12)
Block(4,36,-3,LEAVES:12)
Block(4,36,-2,LEAVES:12)
Block(4,36,-1,LEAVES:12)
Block(4,36,0,LEAVES:12)
Block(4,36,3,LEAVES:12)
Block(4,36,7,LEAVES:12)
Block(4,36,8,LEAVES:12)
Block(4,36,9,17:12)
Block(4,36,10,17:12)
Block(4,36,11,LEAVES:12)
Block(4,37,-2,LEAVES:12)
Block(4,37,-1,LEAVES:12)
Block(4,37,0,LEAVES:12)
Block(4,37,1,LEAVES:12)
Block(4,37,2,LEAVES:12)
Block(4,37,6,LEAVES:12)
Block(4,37,7,LEAVES:12)
Block(4,37,8,LEAVES:12)
Block(4,37,10,17:12)
Block(4,37,11,LEAVES:12)
Block(4,38,0,LEAVES:12)
Block(4,38,1,LEAVES:12)
Block(4,38,4,LEAVES:12)
Block(4,38,5,LEAVES:12)
Block(4,38,6,LEAVES:12)
Block(4,38,7,LEAVES:12)
Block(4,38,8,LEAVES:12)
Block(4,38,9,LEAVES:12)
Block(4,38,10,LEAVES:12)
Block(4,38,12,LEAVES:12)
Block(4,39,0,LEAVES:12)
Block(4,39,1,LEAVES:12)
Block(4,39,2,LEAVES:12)
Block(4,39,3,LEAVES:12)
Block(4,39,4,LEAVES:12)
Block(4,39,5,LEAVES:12)
Block(4,39,6,LEAVES:12)
Block(4,39,8,LEAVES:12)
Block(4,39,9,LEAVES:12)
Block(4,39,11,LEAVES:12)
Block(4,39,12,LEAVES:12)
Block(4,39,13,LEAVES:12)
Block(4,40,0,LEAVES:12)
Block(4,40,1,LEAVES:12)
Block(4,40,2,LEAVES:12)
Block(4,40,4,LEAVES:12)
Block(4,40,5,LEAVES:12)
Block(4,40,6,LEAVES:12)
Block(4,40,7,LEAVES:12)
Block(4,40,8,LEAVES:12)
Block(4,40,10,LEAVES:12)
Block(4,40,12,LEAVES:12)
Block(4,41,1,LEAVES:12)
Block(4,41,3,LEAVES:12)
Block(4,41,4,LEAVES:12)
Block(4,41,5,LEAVES:12)
Block(4,41,6,LEAVES:12)
Block(4,41,9,LEAVES:12)
Block(4,41,10,LEAVES:12)
Block(4,41,11,LEAVES:12)
Block(4,42,4,LEAVES:12)
Block(4,42,5,LEAVES:12)
Block(4,42,6,LEAVES:12)
Block(4,42,10,LEAVES:12)
Block(4,43,1,LEAVES:12)
Block(4,43,2,LEAVES:12)
Block(5,0,5,17:12)
Block(5,0,6,17:12)
Block(5,0,7,17:12)
Block(5,6,3,17:12)
Block(5,6,4,17:12)
Block(5,7,3,17:12)
Block(5,7,4,17:12)
Block(5,7,5,17:12)
Block(5,8,3,17:12)
Block(5,8,4,17:12)
Block(5,8,5,17:12)
Block(5,9,3,17:12)
Block(5,9,4,17:12)
Block(5,9,5,17:12)
Block(5,10,4,17:12)
Block(5,10,5,17:12)
Block(5,10,6,17:12)
Block(5,11,5,17:12)
Block(5,11,6,17:12)
Block(5,12,-4,LEAVES:12)
Block(5,12,-3,LEAVES:12)
Block(5,12,-2,LEAVES:12)
Block(5,12,0,LEAVES:12)
Block(5,12,5,17:12)
Block(5,12,6,17:12)
Block(5,12,15,LEAVES:12)
Block(5,13,-8,LEAVES:12)
Block(5,13,-7,LEAVES:12)
Block(5,13,-6,LEAVES:12)
Block(5,13,-3,LEAVES:12)
Block(5,13,-1,LEAVES:12)
Block(5,13,4,17:12)
Block(5,13,5,17:12)
Block(5,13,6,17:12)
Block(5,13,7,17:12)
Block(5,13,8,17:12)
Block(5,13,14,LEAVES:12)
Block(5,13,15,LEAVES:12)
Block(5,13,16,LEAVES:12)
Block(5,14,-7,LEAVES:12)
Block(5,14,-6,LEAVES:12)
Block(5,14,-5,LEAVES:12)
Block(5,14,-4,LEAVES:12)
Block(5,14,3,17:12)
Block(5,14,4,17:12)
Block(5,14,5,17:12)
Block(5,14,6,17:12)
Block(5,14,7,17:12)
Block(5,14,8,17:12)
Block(5,14,11,LEAVES:12)
Block(5,14,13,LEAVES:12)
Block(5,14,15,LEAVES:12)
Block(5,15,-6,LEAVES:12)
Block(5,15,-5,LEAVES:12)
Block(5,15,2,LEAVES:12)
Block(5,15,3,LEAVES:12)
Block(5,15,4,17:12)
Block(5,15,5,17:12)
Block(5,15,6,17:12)
Block(5,15,7,17:12)
Block(5,15,8,17:12)
Block(5,15,10,LEAVES:12)
Block(5,15,11,LEAVES:12)
Block(5,15,12,LEAVES:12)
Block(5,16,-6,LEAVES:12)
Block(5,16,-5,LEAVES:12)
Block(5,16,-4,LEAVES:12)
Block(5,16,-3,LEAVES:12)
Block(5,16,-2,LEAVES:12)
Block(5,16,0,LEAVES:12)
Block(5,16,1,LEAVES:12)
Block(5,16,2,LEAVES:12)
Block(5,16,3,LEAVES:12)
Block(5,16,6,17:12)
Block(5,16,8,LEAVES:12)
Block(5,16,11,LEAVES:12)
Block(5,16,12,LEAVES:12)
Block(5,16,13,LEAVES:12)
Block(5,16,14,LEAVES:12)
Block(5,17,-5,LEAVES:12)
Block(5,17,-4,LEAVES:12)
Block(5,17,-3,LEAVES:12)
Block(5,17,-1,LEAVES:12)
Block(5,17,2,LEAVES:12)
Block(5,17,13,LEAVES:12)
Block(5,17,14,LEAVES:12)
Block(5,17,15,LEAVES:12)
Block(5,18,-5,LEAVES:12)
Block(5,18,-4,LEAVES:12)
Block(5,18,-1,LEAVES:12)
Block(5,18,0,LEAVES:12)
Block(5,18,1,LEAVES:12)
Block(5,18,14,LEAVES:12)
Block(5,19,-6,LEAVES:12)
Block(5,19,-5,LEAVES:12)
Block(5,19,-4,LEAVES:12)
Block(5,19,0,LEAVES:12)
Block(5,19,1,LEAVES:12)
Block(5,19,2,LEAVES:12)
Block(5,19,11,LEAVES:12)
Block(5,20,-7,LEAVES:12)
Block(5,20,-6,LEAVES:12)
Block(5,20,-5,LEAVES:12)
Block(5,20,-4,LEAVES:12)
Block(5,20,-1,LEAVES:12)
Block(5,20,0,LEAVES:12)
Block(5,20,1,LEAVES:12)
Block(5,20,8,LEAVES:12)
Block(5,21,-6,LEAVES:12)
Block(5,21,-5,LEAVES:12)
Block(5,21,-4,LEAVES:12)
Block(5,21,-3,LEAVES:12)
Block(5,21,-1,LEAVES:12)
Block(5,21,0,LEAVES:12)
Block(5,21,7,LEAVES:12)
Block(5,21,9,LEAVES:12)
Block(5,21,10,LEAVES:12)
Block(5,21,11,LEAVES:12)
Block(5,21,12,LEAVES:12)
Block(5,21,13,LEAVES:12)
Block(5,21,14,LEAVES:12)
Block(5,21,15,LEAVES:12)
Block(5,21,16,LEAVES:12)
Block(5,22,-6,LEAVES:12)
Block(5,22,-5,LEAVES:12)
Block(5,22,-4,LEAVES:12)
Block(5,22,-3,LEAVES:12)
Block(5,22,-2,17:12)
Block(5,22,0,LEAVES:12)
Block(5,22,10,LEAVES:12)
Block(5,22,11,LEAVES:12)
Block(5,22,12,LEAVES:12)
Block(5,22,13,LEAVES:12)
Block(5,22,14,LEAVES:12)
Block(5,22,15,LEAVES:12)
Block(5,22,16,LEAVES:12)
Block(5,22,17,LEAVES:12)
Block(5,23,-5,LEAVES:12)
Block(5,23,-2,LEAVES:12)
Block(5,23,-1,LEAVES:12)
Block(5,23,8,LEAVES:12)
Block(5,23,11,LEAVES:12)
Block(5,23,13,LEAVES:12)
Block(5,23,14,17:12)
Block(5,23,16,LEAVES:12)
Block(5,24,0,LEAVES:12)
Block(5,24,7,LEAVES:12)
Block(5,24,12,LEAVES:12)
Block(5,24,13,LEAVES:12)
Block(5,24,14,LEAVES:12)
Block(5,24,16,LEAVES:12)
Block(5,25,-8,LEAVES:12)
Block(5,25,-7,LEAVES:12)
Block(5,25,-6,LEAVES:12)
Block(5,25,-3,LEAVES:12)
Block(5,25,-1,LEAVES:12)
Block(5,25,0,LEAVES:12)
Block(5,25,1,LEAVES:12)
Block(5,25,3,LEAVES:12)
Block(5,25,4,LEAVES:12)
Block(5,25,5,LEAVES:12)
Block(5,25,6,17:12)
Block(5,25,8,LEAVES:12)
Block(5,25,9,LEAVES:12)
Block(5,25,10,LEAVES:12)
Block(5,25,11,LEAVES:12)
Block(5,25,12,LEAVES:12)
Block(5,25,13,LEAVES:12)
Block(5,25,15,LEAVES:12)
Block(5,25,16,LEAVES:12)
Block(5,25,17,LEAVES:12)
Block(5,26,-7,LEAVES:12)
Block(5,26,-6,LEAVES:12)
Block(5,26,-5,LEAVES:12)
Block(5,26,-4,LEAVES:12)
Block(5,26,-3,LEAVES:12)
Block(5,26,-2,LEAVES:12)
Block(5,26,-1,LEAVES:12)
Block(5,26,0,LEAVES:12)
Block(5,26,1,LEAVES:12)
Block(5,26,2,LEAVES:12)
Block(5,26,3,17:12)
Block(5,26,4,LEAVES:12)
Block(5,26,5,LEAVES:12)
Block(5,26,9,LEAVES:12)
Block(5,26,10,LEAVES:12)
Block(5,26,11,LEAVES:12)
Block(5,26,12,LEAVES:12)
Block(5,26,13,LEAVES:12)
Block(5,26,14,LEAVES:12)
Block(5,26,16,LEAVES:12)
Block(5,27,-6,LEAVES:12)
Block(5,27,-3,LEAVES:12)
Block(5,27,-1,LEAVES:12)
Block(5,27,1,17:12)
Block(5,27,2,17:12)
Block(5,27,3,LEAVES:12)
Block(5,27,4,LEAVES:12)
Block(5,27,10,LEAVES:12)
Block(5,27,11,LEAVES:12)
Block(5,27,12,LEAVES:12)
Block(5,27,13,LEAVES:12)
Block(5,28,-1,LEAVES:12)
Block(5,28,0,LEAVES:12)
Block(5,28,1,LEAVES:12)
Block(5,28,2,LEAVES:12)
Block(5,28,3,LEAVES:12)
Block(5,28,5,LEAVES:12)
Block(5,28,12,LEAVES:12)
Block(5,28,13,LEAVES:12)
Block(5,28,14,LEAVES:12)
Block(5,29,2,LEAVES:12)
Block(5,29,6,LEAVES:12)
Block(5,29,13,LEAVES:12)
Block(5,30,2,LEAVES:12)
Block(5,30,4,LEAVES:12)
Block(5,30,8,LEAVES:12)
Block(5,30,9,LEAVES:12)
Block(5,30,10,LEAVES:12)
Block(5,30,11,LEAVES:12)
Block(5,30,12,LEAVES:12)
Block(5,30,13,LEAVES:12)
Block(5,31,1,LEAVES:12)
Block(5,31,6,17:12)
Block(5,31,9,LEAVES:12)
Block(5,31,12,LEAVES:12)
Block(5,31,13,LEAVES:12)
Block(5,31,14,LEAVES:12)
Block(5,32,2,LEAVES:12)
Block(5,32,3,LEAVES:12)
Block(5,32,13,LEAVES:12)
Block(5,33,1,LEAVES:12)
Block(5,33,2,LEAVES:12)
Block(5,33,9,LEAVES:12)
Block(5,33,11,LEAVES:12)
Block(5,33,13,LEAVES:12)
Block(5,34,-1,LEAVES:12)
Block(5,34,6,17:12)
Block(5,34,7,17:12)
Block(5,34,8,LEAVES:12)
Block(5,34,9,LEAVES:12)
Block(5,34,10,LEAVES:12)
Block(5,34,12,LEAVES:12)
Block(5,34,13,LEAVES:12)
Block(5,34,14,LEAVES:12)
Block(5,35,-2,LEAVES:12)
Block(5,35,-1,LEAVES:12)
Block(5,35,0,LEAVES:12)
Block(5,35,1,LEAVES:12)
Block(5,35,3,LEAVES:12)
Block(5,35,5,17:12)
Block(5,35,6,17:12)
Block(5,35,9,LEAVES:12)
Block(5,35,10,LEAVES:12)
Block(5,35,11,LEAVES:12)
Block(5,35,13,LEAVES:12)
Block(5,36,-2,LEAVES:12)
Block(5,36,-1,LEAVES:12)
Block(5,36,0,LEAVES:12)
Block(5,36,1,LEAVES:12)
Block(5,36,8,LEAVES:12)
Block(5,36,10,LEAVES:12)
Block(5,37,0,LEAVES:12)
Block(5,37,2,17:12)
Block(5,37,3,17:12)
Block(5,37,7,LEAVES:12)
Block(5,37,10,LEAVES:12)
Block(5,37,11,17:12)
Block(5,38,0,LEAVES:12)
Block(5,38,1,17:12)
Block(5,38,2,17:12)
Block(5,38,5,LEAVES:12)
Block(5,38,8,LEAVES:12)
Block(5,39,0,LEAVES:12)
Block(5,39,1,LEAVES:12)
Block(5,39,2,LEAVES:12)
Block(5,39,4,LEAVES:12)
Block(5,39,5,LEAVES:12)
Block(5,39,6,LEAVES:12)
Block(5,39,7,LEAVES:12)
Block(5,39,10,LEAVES:12)
Block(5,39,12,LEAVES:12)
Block(5,40,1,LEAVES:12)
Block(5,40,6,LEAVES:12)
Block(5,40,7,LEAVES:12)
Block(5,40,8,LEAVES:12)
Block(5,41,5,LEAVES:12)
Block(5,41,6,LEAVES:12)
Block(5,41,7,LEAVES:12)
Block(5,41,10,LEAVES:12)
Block(5,42,2,LEAVES:12)
Block(5,42,4,LEAVES:12)
Block(5,42,5,LEAVES:12)
Block(5,42,6,LEAVES:12)
Block(5,43,1,LEAVES:12)
Block(5,43,2,LEAVES:12)
Block(5,43,3,LEAVES:12)
Block(5,43,5,LEAVES:12)
Block(5,44,2,LEAVES:12)
Block(6,0,6,17:12)
Block(6,7,4,17:12)
Block(6,12,-3,LEAVES:12)
Block(6,12,-2,LEAVES:12)
Block(6,12,-1,LEAVES:12)
Block(6,13,-7,LEAVES:12)
Block(6,13,-4,LEAVES:12)
Block(6,13,-3,LEAVES:12)
Block(6,13,-2,LEAVES:12)
Block(6,13,4,17:12)
Block(6,13,15,LEAVES:12)
Block(6,14,-6,LEAVES:12)
Block(6,14,-3,LEAVES:12)
Block(6,14,0,LEAVES:12)
Block(6,14,2,17:12)
Block(6,14,3,17:12)
Block(6,14,7,17:12)
Block(6,14,8,17:12)
Block(6,14,11,LEAVES:12)
Block(6,15,-6,LEAVES:12)
Block(6,15,-5,LEAVES:12)
Block(6,15,-4,LEAVES:12)
Block(6,15,1,LEAVES:12)
Block(6,15,2,LEAVES:12)
Block(6,15,3,LEAVES:12)
Block(6,15,8,17:12)
Block(6,15,9,17:12)
Block(6,15,11,LEAVES:12)
Block(6,15,12,17:12)
Block(6,15,13,17:12)
Block(6,15,15,LEAVES:12)
Block(6,16,-5,LEAVES:12)
Block(6,16,-4,LEAVES:12)
Block(6,16,-3,LEAVES:12)
Block(6,16,-2,LEAVES:12)
Block(6,16,-1,LEAVES:12)
Block(6,16,0,LEAVES:12)
Block(6,16,1,LEAVES:12)
Block(6,16,2,LEAVES:12)
Block(6,16,7,LEAVES:12)
Block(6,16,8,LEAVES:12)
Block(6,16,9,LEAVES:12)
Block(6,16,12,17:12)
Block(6,16,13,LEAVES:12)
Block(6,16,14,LEAVES:12)
Block(6,16,15,LEAVES:12)
Block(6,17,-4,LEAVES:12)
Block(6,17,-2,LEAVES:12)
Block(6,17,-1,LEAVES:12)
Block(6,17,0,LEAVES:12)
Block(6,17,1,LEAVES:12)
Block(6,17,2,LEAVES:12)
Block(6,17,3,LEAVES:12)
Block(6,17,8,LEAVES:12)
Block(6,17,12,17:12)
Block(6,17,14,LEAVES:12)
Block(6,18,-3,LEAVES:12)
Block(6,18,-1,17:12)
Block(6,18,0,LEAVES:12)
Block(6,18,1,LEAVES:12)
Block(6,18,2,LEAVES:12)
Block(6,18,11,LEAVES:12)
Block(6,19,-5,LEAVES:12)
Block(6,19,-4,LEAVES:12)
Block(6,19,-2,LEAVES:12)
Block(6,19,-1,LEAVES:12)
Block(6,19,0,LEAVES:12)
Block(6,19,1,LEAVES:12)
Block(6,19,4,LEAVES:12)
Block(6,19,10,LEAVES:12)
Block(6,19,11,LEAVES:12)
Block(6,19,12,LEAVES:12)
Block(6,20,-6,LEAVES:12)
Block(6,20,-5,LEAVES:12)
Block(6,20,-4,LEAVES:12)
Block(6,20,-3,LEAVES:12)
Block(6,20,-2,LEAVES:12)
Block(6,20,-1,LEAVES:12)
Block(6,20,0,LEAVES:12)
Block(6,20,5,LEAVES:12)
Block(6,20,7,LEAVES:12)
Block(6,20,8,LEAVES:12)
Block(6,20,9,LEAVES:12)
Block(6,20,11,LEAVES:12)
Block(6,21,-5,LEAVES:12)
Block(6,21,-4,LEAVES:12)
Block(6,21,-3,LEAVES:12)
Block(6,21,-2,LEAVES:12)
Block(6,21,-1,LEAVES:12)
Block(6,21,0,LEAVES:12)
Block(6,21,6,LEAVES:12)
Block(6,21,7,LEAVES:12)
Block(6,21,8,LEAVES:12)
Block(6,21,10,LEAVES:12)
Block(6,21,12,LEAVES:12)
Block(6,21,13,LEAVES:12)
Block(6,21,14,LEAVES:12)
Block(6,21,15,LEAVES:12)
Block(6,22,-7,LEAVES:12)
Block(6,22,-6,LEAVES:12)
Block(6,22,-5,LEAVES:12)
Block(6,22,-1,LEAVES:12)
Block(6,22,0,LEAVES:12)
Block(6,22,1,LEAVES:12)
Block(6,22,5,LEAVES:12)
Block(6,22,7,LEAVES:12)
Block(6,22,11,LEAVES:12)
Block(6,22,12,LEAVES:12)
Block(6,22,13,LEAVES:12)
Block(6,22,14,LEAVES:12)
Block(6,22,15,LEAVES:12)
Block(6,22,16,LEAVES:12)
Block(6,23,-6,LEAVES:12)
Block(6,23,-5,LEAVES:12)
Block(6,23,-4,LEAVES:12)
Block(6,23,0,LEAVES:12)
Block(6,23,4,LEAVES:12)
Block(6,23,7,LEAVES:12)
Block(6,23,8,LEAVES:12)
Block(6,23,9,LEAVES:12)
Block(6,23,12,LEAVES:12)
Block(6,23,13,LEAVES:12)
Block(6,23,14,LEAVES:12)
Block(6,24,-5,LEAVES:12)
Block(6,24,-1,LEAVES:12)
Block(6,24,0,LEAVES:12)
Block(6,24,1,LEAVES:12)
Block(6,24,6,LEAVES:12)
Block(6,24,7,LEAVES:12)
Block(6,24,8,LEAVES:12)
Block(6,24,13,LEAVES:12)
Block(6,24,14,LEAVES:12)
Block(6,24,15,LEAVES:12)
Block(6,24,16,LEAVES:12)
Block(6,24,17,LEAVES:12)
Block(6,25,-7,LEAVES:12)
Block(6,25,-4,LEAVES:12)
Block(6,25,-3,LEAVES:12)
Block(6,25,-2,LEAVES:12)
Block(6,25,-1,LEAVES:12)
Block(6,25,0,LEAVES:12)
Block(6,25,3,LEAVES:12)
Block(6,25,4,LEAVES:12)
Block(6,25,5,LEAVES:12)
Block(6,25,7,LEAVES:12)
Block(6,25,9,LEAVES:12)
Block(6,25,12,LEAVES:12)
Block(6,25,13,LEAVES:12)
Block(6,25,14,LEAVES:12)
Block(6,25,15,LEAVES:12)
Block(6,25,16,LEAVES:12)
Block(6,26,-6,LEAVES:12)
Block(6,26,-5,LEAVES:12)
Block(6,26,-4,LEAVES:12)
Block(6,26,-3,LEAVES:12)
Block(6,26,-2,LEAVES:12)
Block(6,26,-1,LEAVES:12)
Block(6,26,0,LEAVES:12)
Block(6,26,1,LEAVES:12)
Block(6,26,2,LEAVES:12)
Block(6,26,3,LEAVES:12)
Block(6,26,4,LEAVES:12)
Block(6,26,5,17:12)
Block(6,26,10,LEAVES:12)
Block(6,26,11,LEAVES:12)
Block(6,26,12,LEAVES:12)
Block(6,26,13,LEAVES:12)
Block(6,26,15,LEAVES:12)
Block(6,27,-4,LEAVES:12)
Block(6,27,-1,LEAVES:12)
Block(6,27,0,LEAVES:12)
Block(6,27,1,LEAVES:12)
Block(6,27,2,LEAVES:12)
Block(6,27,3,LEAVES:12)
Block(6,27,4,LEAVES:12)
Block(6,27,12,LEAVES:12)
Block(6,28,-2,LEAVES:12)
Block(6,28,-1,LEAVES:12)
Block(6,28,0,LEAVES:12)
Block(6,28,2,LEAVES:12)
Block(6,28,3,LEAVES:12)
Block(6,28,4,LEAVES:12)
Block(6,28,5,LEAVES:12)
Block(6,28,6,LEAVES:12)
Block(6,28,13,LEAVES:12)
Block(6,29,-1,LEAVES:12)
Block(6,29,5,LEAVES:12)
Block(6,29,6,LEAVES:12)
Block(6,29,7,LEAVES:12)
Block(6,30,5,LEAVES:12)
Block(6,30,6,LEAVES:12)
Block(6,30,9,LEAVES:12)
Block(6,30,12,LEAVES:12)
Block(6,30,13,LEAVES:12)
Block(6,30,14,LEAVES:12)
Block(6,31,0,LEAVES:12)
Block(6,31,1,LEAVES:12)
Block(6,31,2,LEAVES:12)
Block(6,31,6,17:12)
Block(6,31,13,LEAVES:12)
Block(6,32,1,LEAVES:12)
Block(6,33,8,LEAVES:12)
Block(6,33,9,LEAVES:12)
Block(6,33,10,LEAVES:12)
Block(6,34,-2,LEAVES:12)
Block(6,34,-1,LEAVES:12)
Block(6,34,0,LEAVES:12)
Block(6,34,3,LEAVES:12)
Block(6,34,7,LEAVES:12)
Block(6,34,8,17:12)
Block(6,34,9,LEAVES:12)
Block(6,34,10,LEAVES:12)
Block(6,34,11,LEAVES:12)
Block(6,34,13,LEAVES:12)
Block(6,35,-1,LEAVES:12)
Block(6,35,0,LEAVES:12)
Block(6,35,1,LEAVES:12)
Block(6,35,2,LEAVES:12)
Block(6,35,3,LEAVES:12)
Block(6,35,4,LEAVES:12)
Block(6,35,5,17:12)
Block(6,35,10,LEAVES:12)
Block(6,35,11,LEAVES:12)
Block(6,36,0,LEAVES:12)
Block(6,36,1,LEAVES:12)
Block(6,36,3,LEAVES:12)
Block(6,36,4,17:12)
Block(6,36,5,17:12)
Block(6,36,10,LEAVES:12)
Block(6,36,14,LEAVES:12)
Block(6,37,3,17:12)
Block(6,37,4,17:12)
Block(6,37,8,LEAVES:12)
Block(6,37,11,LEAVES:12)
Block(6,37,12,LEAVES:12)
Block(6,38,0,LEAVES:12)
Block(6,38,1,LEAVES:12)
Block(6,38,2,LEAVES:12)
Block(6,38,7,LEAVES:12)
Block(6,38,10,LEAVES:12)
Block(6,39,-1,LEAVES:12)
Block(6,39,0,LEAVES:12)
Block(6,39,1,LEAVES:12)
Block(6,39,2,LEAVES:12)
Block(6,39,3,LEAVES:12)
Block(6,39,6,LEAVES:12)
Block(6,39,9,LEAVES:12)
Block(6,39,10,LEAVES:12)
Block(6,39,11,LEAVES:12)
Block(6,40,0,LEAVES:12)
Block(6,40,2,LEAVES:12)
Block(6,40,7,LEAVES:12)
Block(6,40,10,LEAVES:12)
Block(6,41,6,LEAVES:12)
Block(6,42,1,LEAVES:12)
Block(6,42,2,LEAVES:12)
Block(6,42,3,LEAVES:12)
Block(6,42,5,LEAVES:12)
Block(6,43,2,LEAVES:12)
Block(6,43,3,LEAVES:12)
Block(6,43,4,LEAVES:12)
Block(6,44,3,LEAVES:12)
Block(7,12,-2,LEAVES:12)
Block(7,13,-3,LEAVES:12)
Block(7,13,11,LEAVES:12)
Block(7,14,-1,LEAVES:12)
Block(7,14,0,LEAVES:12)
Block(7,14,1,LEAVES:12)
Block(7,14,2,17:12)
Block(7,14,10,LEAVES:12)
Block(7,14,11,LEAVES:12)
Block(7,14,12,LEAVES:12)
Block(7,14,14,17:12)
Block(7,14,15,LEAVES:12)
Block(7,15,-5,LEAVES:12)
Block(7,15,-3,LEAVES:12)
Block(7,15,0,LEAVES:12)
Block(7,15,1,LEAVES:12)
Block(7,15,2,LEAVES:12)
Block(7,15,9,17:12)
Block(7,15,10,17:12)
Block(7,15,11,LEAVES:12)
Block(7,15,12,LEAVES:12)
Block(7,15,14,LEAVES:12)
Block(7,15,15,LEAVES:12)
Block(7,15,16,LEAVES:12)
Block(7,16,-4,LEAVES:12)
Block(7,16,-2,LEAVES:12)
Block(7,16,-1,LEAVES:12)
Block(7,16,0,LEAVES:12)
Block(7,16,1,17:12)
Block(7,16,2,17:12)
Block(7,16,5,LEAVES:12)
Block(7,16,8,LEAVES:12)
Block(7,16,9,17:12)
Block(7,16,10,17:12)
Block(7,16,11,17:12)
Block(7,16,12,LEAVES:12)
Block(7,16,14,LEAVES:12)
Block(7,16,15,LEAVES:12)
Block(7,17,-2,LEAVES:12)
Block(7,17,-1,LEAVES:12)
Block(7,17,0,LEAVES:12)
Block(7,17,1,17:12)
Block(7,17,2,LEAVES:12)
Block(7,17,6,LEAVES:12)
Block(7,17,7,17:12)
Block(7,17,8,LEAVES:12)
Block(7,17,9,17:12)
Block(7,17,12,LEAVES:12)
Block(7,17,15,LEAVES:12)
Block(7,18,-3,LEAVES:12)
Block(7,18,-1,LEAVES:12)
Block(7,18,0,17:12)
Block(7,18,1,LEAVES:12)
Block(7,18,2,LEAVES:12)
Block(7,18,3,LEAVES:12)
Block(7,18,7,17:12)
Block(7,18,9,LEAVES:12)
Block(7,18,10,LEAVES:12)
Block(7,18,11,LEAVES:12)
Block(7,18,12,LEAVES:12)
Block(7,18,14,LEAVES:12)
Block(7,19,-5,LEAVES:12)
Block(7,19,-4,LEAVES:12)
Block(7,19,-3,LEAVES:12)
Block(7,19,-2,LEAVES:12)
Block(7,19,-1,LEAVES:12)
Block(7,19,0,LEAVES:12)
Block(7,19,1,LEAVES:12)
Block(7,19,2,LEAVES:12)
Block(7,19,3,LEAVES:12)
Block(7,19,4,LEAVES:12)
Block(7,19,5,LEAVES:12)
Block(7,19,8,LEAVES:12)
Block(7,19,9,LEAVES:12)
Block(7,19,10,LEAVES:12)
Block(7,19,11,LEAVES:12)
Block(7,20,-5,LEAVES:12)
Block(7,20,-4,LEAVES:12)
Block(7,20,-3,LEAVES:12)
Block(7,20,-2,LEAVES:12)
Block(7,20,-1,LEAVES:12)
Block(7,20,4,LEAVES:12)
Block(7,20,5,LEAVES:12)
Block(7,20,6,LEAVES:12)
Block(7,20,8,LEAVES:12)
Block(7,20,9,LEAVES:12)
Block(7,20,10,LEAVES:12)
Block(7,21,-4,LEAVES:12)
Block(7,21,-3,LEAVES:12)
Block(7,21,-2,LEAVES:12)
Block(7,21,-1,LEAVES:12)
Block(7,21,0,LEAVES:12)
Block(7,21,1,LEAVES:12)
Block(7,21,5,LEAVES:12)
Block(7,21,7,LEAVES:12)
Block(7,21,8,LEAVES:12)
Block(7,21,9,LEAVES:12)
Block(7,21,13,LEAVES:12)
Block(7,21,14,LEAVES:12)
Block(7,21,15,LEAVES:12)
Block(7,21,16,LEAVES:12)
Block(7,22,-6,LEAVES:12)
Block(7,22,-3,LEAVES:12)
Block(7,22,0,LEAVES:12)
Block(7,22,4,LEAVES:12)
Block(7,22,5,LEAVES:12)
Block(7,22,6,LEAVES:12)
Block(7,22,8,LEAVES:12)
Block(7,22,12,LEAVES:12)
Block(7,22,14,LEAVES:12)
Block(7,22,15,LEAVES:12)
Block(7,22,16,LEAVES:12)
Block(7,22,17,LEAVES:12)
Block(7,23,-5,LEAVES:12)
Block(7,23,3,LEAVES:12)
Block(7,23,4,LEAVES:12)
Block(7,23,5,LEAVES:12)
Block(7,23,8,LEAVES:12)
Block(7,23,12,LEAVES:12)
Block(7,23,13,LEAVES:12)
Block(7,23,14,LEAVES:12)
Block(7,23,15,LEAVES:12)
Block(7,23,16,LEAVES:12)
Block(7,24,0,LEAVES:12)
Block(7,24,4,LEAVES:12)
Block(7,24,6,LEAVES:12)
Block(7,24,7,LEAVES:12)
Block(7,24,8,LEAVES:12)
Block(7,24,9,LEAVES:12)
Block(7,24,13,LEAVES:12)
Block(7,24,14,LEAVES:12)
Block(7,24,15,LEAVES:12)
Block(7,24,16,LEAVES:12)
Block(7,25,-3,LEAVES:12)
Block(7,25,-2,LEAVES:12)
Block(7,25,-1,LEAVES:12)
Block(7,25,0,LEAVES:12)
Block(7,25,4,LEAVES:12)
Block(7,25,5,LEAVES:12)
Block(7,25,8,LEAVES:12)
Block(7,25,13,LEAVES:12)
Block(7,25,14,LEAVES:12)
Block(7,25,15,LEAVES:12)
Block(7,26,-4,LEAVES:12)
Block(7,26,-1,LEAVES:12)
Block(7,26,0,LEAVES:12)
Block(7,26,1,LEAVES:12)
Block(7,26,2,LEAVES:12)
Block(7,26,3,LEAVES:12)
Block(7,26,4,17:12)
Block(7,26,5,17:12)
Block(7,26,6,17:12)
Block(7,26,12,LEAVES:12)
Block(7,27,0,LEAVES:12)
Block(7,27,1,LEAVES:12)
Block(7,27,2,LEAVES:12)
Block(7,27,3,LEAVES:12)
Block(7,27,4,17:12)
Block(7,28,-1,LEAVES:12)
Block(7,28,0,LEAVES:12)
Block(7,28,1,LEAVES:12)
Block(7,28,2,LEAVES:12)
Block(7,28,5,LEAVES:12)
Block(7,28,9,LEAVES:12)
Block(7,29,-2,LEAVES:12)
Block(7,29,-1,LEAVES:12)
Block(7,29,0,LEAVES:12)
Block(7,29,4,LEAVES:12)
Block(7,29,5,LEAVES:12)
Block(7,29,6,LEAVES:12)
Block(7,30,-1,LEAVES:12)
Block(7,30,4,LEAVES:12)
Block(7,30,5,LEAVES:12)
Block(7,30,6,LEAVES:12)
Block(7,30,13,LEAVES:12)
Block(7,31,-1,LEAVES:12)
Block(7,31,0,LEAVES:12)
Block(7,31,1,LEAVES:12)
Block(7,31,5,LEAVES:12)
Block(7,31,6,17:12)
Block(7,31,7,17:12)
Block(7,32,0,LEAVES:12)
Block(7,32,1,LEAVES:12)
Block(7,32,2,LEAVES:12)
Block(7,32,7,17:12)
Block(7,33,1,LEAVES:12)
Block(7,33,9,LEAVES:12)
Block(7,34,-1,LEAVES:12)
Block(7,34,2,LEAVES:12)
Block(7,34,3,LEAVES:12)
Block(7,34,4,LEAVES:12)
Block(7,34,6,LEAVES:12)
Block(7,34,7,LEAVES:12)
Block(7,34,8,17:12)
Block(7,34,9,LEAVES:12)
Block(7,34,10,LEAVES:12)
Block(7,35,0,LEAVES:12)
Block(7,35,1,LEAVES:12)
Block(7,35,2,LEAVES:12)
Block(7,35,3,LEAVES:12)
Block(7,35,7,LEAVES:12)
Block(7,35,8,17:12)
Block(7,35,9,17:12)
Block(7,35,10,LEAVES:12)
Block(7,35,11,LEAVES:12)
Block(7,35,12,LEAVES:12)
Block(7,36,0,LEAVES:12)
Block(7,36,1,LEAVES:12)
Block(7,36,2,LEAVES:12)
Block(7,36,9,LEAVES:12)
Block(7,36,10,LEAVES:12)
Block(7,36,11,LEAVES:12)
Block(7,36,13,LEAVES:12)
Block(7,36,14,LEAVES:12)
Block(7,36,15,LEAVES:12)
Block(7,37,1,LEAVES:12)
Block(7,37,7,LEAVES:12)
Block(7,37,8,LEAVES:12)
Block(7,37,9,LEAVES:12)
Block(7,37,10,LEAVES:12)
Block(7,37,14,LEAVES:12)
Block(7,38,-1,LEAVES:12)
Block(7,38,0,LEAVES:12)
Block(7,38,1,LEAVES:12)
Block(7,38,2,LEAVES:12)
Block(7,38,3,LEAVES:12)
Block(7,38,6,LEAVES:12)
Block(7,38,7,LEAVES:12)
Block(7,38,8,LEAVES:12)
Block(7,38,9,LEAVES:12)
Block(7,38,10,LEAVES:12)
Block(7,38,11,LEAVES:12)
Block(7,39,-2,LEAVES:12)
Block(7,39,-1,LEAVES:12)
Block(7,39,0,LEAVES:12)
Block(7,39,2,LEAVES:12)
Block(7,39,3,LEAVES:12)
Block(7,39,4,LEAVES:12)
Block(7,39,7,LEAVES:12)
Block(7,39,8,LEAVES:12)
Block(7,39,9,LEAVES:12)
Block(7,39,10,LEAVES:12)
Block(7,40,-1,LEAVES:12)
Block(7,40,3,LEAVES:12)
Block(7,40,9,LEAVES:12)
Block(7,42,2,LEAVES:12)
Block(7,43,3,LEAVES:12)
Block(8,13,10,LEAVES:12)
Block(8,13,11,LEAVES:12)
Block(8,13,12,LEAVES:12)
Block(8,14,-1,LEAVES:12)
Block(8,14,0,LEAVES:12)
Block(8,14,9,17:12)
Block(8,14,11,LEAVES:12)
Block(8,14,12,LEAVES:12)
Block(8,14,13,LEAVES:12)
Block(8,14,14,LEAVES:12)
Block(8,14,15,LEAVES:12)
Block(8,14,16,LEAVES:12)
Block(8,15,-4,LEAVES:12)
Block(8,15,-3,LEAVES:12)
Block(8,15,-2,LEAVES:12)
Block(8,15,-1,LEAVES:12)
Block(8,15,0,LEAVES:12)
Block(8,15,1,LEAVES:12)
Block(8,15,10,LEAVES:12)
Block(8,15,11,LEAVES:12)
Block(8,15,12,LEAVES:12)
Block(8,15,13,LEAVES:12)
Block(8,15,14,LEAVES:12)
Block(8,15,15,LEAVES:12)
Block(8,16,-3,LEAVES:12)
Block(8,16,-2,LEAVES:12)
Block(8,16,-1,LEAVES:12)
Block(8,16,0,LEAVES:12)
Block(8,16,1,17:12)
Block(8,16,2,17:12)
Block(8,16,4,LEAVES:12)
Block(8,16,5,LEAVES:12)
Block(8,16,6,LEAVES:12)
Block(8,16,9,LEAVES:12)
Block(8,16,10,17:12)
Block(8,16,11,17:12)
Block(8,16,12,LEAVES:12)
Block(8,16,13,LEAVES:12)
Block(8,16,14,LEAVES:12)
Block(8,17,-3,LEAVES:12)
Block(8,17,-2,LEAVES:12)
Block(8,17,-1,LEAVES:12)
Block(8,17,0,LEAVES:12)
Block(8,17,2,LEAVES:12)
Block(8,17,5,LEAVES:12)
Block(8,17,6,LEAVES:12)
Block(8,17,7,LEAVES:12)
Block(8,17,8,LEAVES:12)
Block(8,17,9,LEAVES:12)
Block(8,17,11,LEAVES:12)
Block(8,17,12,LEAVES:12)
Block(8,17,13,LEAVES:12)
Block(8,17,14,LEAVES:12)
Block(8,17,15,LEAVES:12)
Block(8,17,16,LEAVES:12)
Block(8,18,-4,LEAVES:12)
Block(8,18,-3,LEAVES:12)
Block(8,18,-2,LEAVES:12)
Block(8,18,-1,LEAVES:12)
Block(8,18,0,LEAVES:12)
Block(8,18,1,LEAVES:12)
Block(8,18,2,LEAVES:12)
Block(8,18,6,LEAVES:12)
Block(8,18,7,17:12)
Block(8,18,8,LEAVES:12)
Block(8,18,9,LEAVES:12)
Block(8,18,10,17:12)
Block(8,18,11,LEAVES:12)
Block(8,18,12,LEAVES:12)
Block(8,18,13,LEAVES:12)
Block(8,18,14,LEAVES:12)
Block(8,18,15,LEAVES:12)
Block(8,19,-4,LEAVES:12)
Block(8,19,-3,LEAVES:12)
Block(8,19,-2,LEAVES:12)
Block(8,19,-1,LEAVES:12)
Block(8,19,0,LEAVES:12)
Block(8,19,1,LEAVES:12)
Block(8,19,2,LEAVES:12)
Block(8,19,4,LEAVES:12)
Block(8,19,5,LEAVES:12)
Block(8,19,6,LEAVES:12)
Block(8,19,7,LEAVES:12)
Block(8,19,8,LEAVES:12)
Block(8,19,9,LEAVES:12)
Block(8,19,10,LEAVES:12)
Block(8,19,14,LEAVES:12)
Block(8,20,-4,LEAVES:12)
Block(8,20,-3,LEAVES:12)
Block(8,20,-2,LEAVES:12)
Block(8,20,-1,LEAVES:12)
Block(8,20,0,LEAVES:12)
Block(8,20,1,LEAVES:12)
Block(8,20,5,LEAVES:12)
Block(8,20,6,LEAVES:12)
Block(8,20,8,LEAVES:12)
Block(8,20,9,LEAVES:12)
Block(8,20,10,LEAVES:12)
Block(8,21,-3,LEAVES:12)
Block(8,21,-1,LEAVES:12)
Block(8,21,0,LEAVES:12)
Block(8,21,8,LEAVES:12)
Block(8,21,9,LEAVES:12)
Block(8,21,15,LEAVES:12)
Block(8,21,16,LEAVES:12)
Block(8,21,17,LEAVES:12)
Block(8,22,3,LEAVES:12)
Block(8,22,4,LEAVES:12)
Block(8,22,5,LEAVES:12)
Block(8,22,16,LEAVES:12)
Block(8,23,4,LEAVES:12)
Block(8,23,13,LEAVES:12)
Block(8,24,5,LEAVES:12)
Block(8,24,6,LEAVES:12)
Block(8,24,7,LEAVES:12)
Block(8,24,8,LEAVES:12)
Block(8,24,12,LEAVES:12)
Block(8,24,13,LEAVES:12)
Block(8,24,14,LEAVES:12)
Block(8,25,-1,LEAVES:12)
Block(8,25,4,LEAVES:12)
Block(8,25,5,LEAVES:12)
Block(8,25,6,LEAVES:12)
Block(8,25,7,17:12)
Block(8,25,9,LEAVES:12)
Block(8,25,13,LEAVES:12)
Block(8,26,0,LEAVES:12)
Block(8,26,1,LEAVES:12)
Block(8,26,3,LEAVES:12)
Block(8,26,5,LEAVES:12)
Block(8,26,7,LEAVES:12)
Block(8,27,2,LEAVES:12)
Block(8,27,3,17:12)
Block(8,27,4,17:12)
Block(8,27,5,LEAVES:12)
Block(8,27,9,LEAVES:12)
Block(8,28,0,LEAVES:12)
Block(8,28,7,LEAVES:12)
Block(8,28,8,LEAVES:12)
Block(8,28,9,LEAVES:12)
Block(8,28,10,LEAVES:12)
Block(8,29,-1,LEAVES:12)
Block(8,29,2,LEAVES:12)
Block(8,29,3,LEAVES:12)
Block(8,29,5,LEAVES:12)
Block(8,29,9,LEAVES:12)
Block(8,30,1,LEAVES:12)
Block(8,30,5,LEAVES:12)
Block(8,30,6,LEAVES:12)
Block(8,30,7,LEAVES:12)
Block(8,30,9,LEAVES:12)
Block(8,31,0,LEAVES:12)
Block(8,31,4,LEAVES:12)
Block(8,31,5,LEAVES:12)
Block(8,31,6,LEAVES:12)
Block(8,32,1,LEAVES:12)
Block(8,32,5,LEAVES:12)
Block(8,32,7,17:12)
Block(8,32,8,17:12)
Block(8,33,9,LEAVES:12)
Block(8,34,3,LEAVES:12)
Block(8,34,5,LEAVES:12)
Block(8,34,7,LEAVES:12)
Block(8,34,8,LEAVES:12)
Block(8,34,9,LEAVES:12)
Block(8,34,10,LEAVES:12)
Block(8,35,2,LEAVES:12)
Block(8,35,6,LEAVES:12)
Block(8,35,7,LEAVES:12)
Block(8,35,8,LEAVES:12)
Block(8,35,9,17:12)
Block(8,35,10,LEAVES:12)
Block(8,35,11,LEAVES:12)
Block(8,36,1,LEAVES:12)
Block(8,36,7,LEAVES:12)
Block(8,36,8,LEAVES:12)
Block(8,36,9,17:12)
Block(8,36,10,LEAVES:12)
Block(8,36,11,LEAVES:12)
Block(8,36,12,LEAVES:12)
Block(8,36,13,LEAVES:12)
Block(8,36,14,LEAVES:12)
Block(8,37,6,LEAVES:12)
Block(8,37,7,LEAVES:12)
Block(8,37,8,LEAVES:12)
Block(8,37,10,LEAVES:12)
Block(8,37,11,LEAVES:12)
Block(8,37,13,LEAVES:12)
Block(8,37,14,LEAVES:12)
Block(8,37,15,LEAVES:12)
Block(8,38,0,LEAVES:12)
Block(8,38,2,LEAVES:12)
Block(8,38,7,LEAVES:12)
Block(8,38,10,LEAVES:12)
Block(8,38,14,LEAVES:12)
Block(8,39,-1,LEAVES:12)
Block(8,39,3,LEAVES:12)
Block(8,39,9,LEAVES:12)
Block(9,12,1,LEAVES:12)
Block(9,13,11,LEAVES:12)
Block(9,14,-2,LEAVES:12)
Block(9,14,-1,LEAVES:12)
Block(9,14,0,LEAVES:12)
Block(9,14,9,17:12)
Block(9,14,12,LEAVES:12)
Block(9,14,13,LEAVES:12)
Block(9,14,14,LEAVES:12)
Block(9,14,15,LEAVES:12)
Block(9,15,-3,LEAVES:12)
Block(9,15,-1,LEAVES:12)
Block(9,15,0,LEAVES:12)
Block(9,15,1,LEAVES:12)
Block(9,15,2,LEAVES:12)
Block(9,15,4,LEAVES:12)
Block(9,15,11,LEAVES:12)
Block(9,15,14,LEAVES:12)
Block(9,15,15,LEAVES:12)
Block(9,15,16,LEAVES:12)
Block(9,16,-4,LEAVES:12)
Block(9,16,-3,LEAVES:12)
Block(9,16,-2,LEAVES:12)
Block(9,16,0,17:12)
Block(9,16,1,17:12)
Block(9,16,2,LEAVES:12)
Block(9,16,5,LEAVES:12)
Block(9,16,6,LEAVES:12)
Block(9,16,7,LEAVES:12)
Block(9,16,8,LEAVES:12)
Block(9,16,9,LEAVES:12)
Block(9,16,10,LEAVES:12)
Block(9,16,11,17:12)
Block(9,16,12,LEAVES:12)
Block(9,16,15,LEAVES:12)
Block(9,17,-4,LEAVES:12)
Block(9,17,-3,LEAVES:12)
Block(9,17,-2,LEAVES:12)
Block(9,17,-1,LEAVES:12)
Block(9,17,0,17:12)
Block(9,17,1,LEAVES:12)
Block(9,17,2,LEAVES:12)
Block(9,17,3,LEAVES:12)
Block(9,17,6,LEAVES:12)
Block(9,17,7,LEAVES:12)
Block(9,17,8,LEAVES:12)
Block(9,17,9,LEAVES:12)
Block(9,17,12,LEAVES:12)
Block(9,17,15,LEAVES:12)
Block(9,18,-3,LEAVES:12)
Block(9,18,-1,17:12)
Block(9,18,0,LEAVES:12)
Block(9,18,1,LEAVES:12)
Block(9,18,2,LEAVES:12)
Block(9,18,7,LEAVES:12)
Block(9,18,8,LEAVES:12)
Block(9,18,9,LEAVES:12)
Block(9,18,14,LEAVES:12)
Block(9,18,15,LEAVES:12)
Block(9,18,16,LEAVES:12)
Block(9,19,-3,LEAVES:12)
Block(9,19,-2,LEAVES:12)
Block(9,19,-1,LEAVES:12)
Block(9,19,0,LEAVES:12)
Block(9,19,1,LEAVES:12)
Block(9,19,2,LEAVES:12)
Block(9,19,3,LEAVES:12)
Block(9,19,5,LEAVES:12)
Block(9,19,7,LEAVES:12)
Block(9,19,8,LEAVES:12)
Block(9,19,10,LEAVES:12)
Block(9,19,12,LEAVES:12)
Block(9,19,15,LEAVES:12)
Block(9,20,-3,LEAVES:12)
Block(9,20,-2,LEAVES:12)
Block(9,20,-1,LEAVES:12)
Block(9,20,0,LEAVES:12)
Block(9,20,1,LEAVES:12)
Block(9,20,2,LEAVES:12)
Block(9,20,7,LEAVES:12)
Block(9,20,8,LEAVES:12)
Block(9,20,9,LEAVES:12)
Block(9,20,10,LEAVES:12)
Block(9,20,11,LEAVES:12)
Block(9,21,0,LEAVES:12)
Block(9,21,8,LEAVES:12)
Block(9,21,9,LEAVES:12)
Block(9,21,10,LEAVES:12)
Block(9,21,16,LEAVES:12)
Block(9,22,4,LEAVES:12)
Block(9,22,9,LEAVES:12)
Block(9,23,5,LEAVES:12)
Block(9,24,5,LEAVES:12)
Block(9,24,6,LEAVES:12)
Block(9,24,7,LEAVES:12)
Block(9,24,8,LEAVES:12)
Block(9,24,9,LEAVES:12)
Block(9,24,13,LEAVES:12)
Block(9,25,5,LEAVES:12)
Block(9,25,6,LEAVES:12)
Block(9,25,7,LEAVES:12)
Block(9,25,8,LEAVES:12)
Block(9,25,9,LEAVES:12)
Block(9,25,10,LEAVES:12)
Block(9,26,0,LEAVES:12)
Block(9,26,1,LEAVES:12)
Block(9,26,2,LEAVES:12)
Block(9,26,5,LEAVES:12)
Block(9,26,6,LEAVES:12)
Block(9,26,9,LEAVES:12)
Block(9,27,1,LEAVES:12)
Block(9,27,2,LEAVES:12)
Block(9,27,3,LEAVES:12)
Block(9,27,4,17:12)
Block(9,27,5,LEAVES:12)
Block(9,27,6,LEAVES:12)
Block(9,27,7,LEAVES:12)
Block(9,27,8,LEAVES:12)
Block(9,27,9,LEAVES:12)
Block(9,27,10,LEAVES:12)
Block(9,28,2,LEAVES:12)
Block(9,28,3,LEAVES:12)
Block(9,28,4,17:12)
Block(9,28,5,LEAVES:12)
Block(9,28,6,LEAVES:12)
Block(9,28,7,LEAVES:12)
Block(9,28,8,LEAVES:12)
Block(9,28,9,LEAVES:12)
Block(9,29,1,LEAVES:12)
Block(9,29,2,LEAVES:12)
Block(9,29,3,LEAVES:12)
Block(9,29,4,LEAVES:12)
Block(9,29,7,LEAVES:12)
Block(9,29,8,LEAVES:12)
Block(9,30,0,LEAVES:12)
Block(9,30,1,LEAVES:12)
Block(9,30,2,LEAVES:12)
Block(9,30,3,LEAVES:12)
Block(9,30,6,LEAVES:12)
Block(9,30,8,LEAVES:12)
Block(9,30,9,LEAVES:12)
Block(9,30,10,LEAVES:12)
Block(9,31,1,LEAVES:12)
Block(9,31,5,LEAVES:12)
Block(9,31,9,LEAVES:12)
Block(9,32,6,LEAVES:12)
Block(9,32,8,17:12)
Block(9,33,5,LEAVES:12)
Block(9,33,8,LEAVES:12)
Block(9,33,9,LEAVES:12)
Block(9,33,10,LEAVES:12)
Block(9,34,4,LEAVES:12)
Block(9,34,5,LEAVES:12)
Block(9,34,6,LEAVES:12)
Block(9,34,7,LEAVES:12)
Block(9,34,8,LEAVES:12)
Block(9,34,9,LEAVES:12)
Block(9,34,11,LEAVES:12)
Block(9,35,5,LEAVES:12)
Block(9,35,7,LEAVES:12)
Block(9,35,8,LEAVES:12)
Block(9,35,10,LEAVES:12)
Block(9,36,7,LEAVES:12)
Block(9,36,9,17:12)
Block(9,36,11,LEAVES:12)
Block(9,36,13,LEAVES:12)
Block(9,37,7,LEAVES:12)
Block(9,37,8,LEAVES:12)
Block(9,37,9,LEAVES:12)
Block(9,37,10,LEAVES:12)
Block(9,37,11,LEAVES:12)
Block(9,37,14,LEAVES:12)
Block(9,38,10,LEAVES:12)
Block(10,12,0,LEAVES:12)
Block(10,12,1,LEAVES:12)
Block(10,12,2,LEAVES:12)
Block(10,13,1,LEAVES:12)
Block(10,14,-1,LEAVES:12)
Block(10,14,0,LEAVES:12)
Block(10,14,1,LEAVES:12)
Block(10,14,4,LEAVES:12)
Block(10,14,14,LEAVES:12)
Block(10,14,15,LEAVES:12)
Block(10,14,16,LEAVES:12)
Block(10,15,-4,LEAVES:12)
Block(10,15,-3,LEAVES:12)
Block(10,15,-2,LEAVES:12)
Block(10,15,-1,LEAVES:12)
Block(10,15,0,17:12)
Block(10,15,1,LEAVES:12)
Block(10,15,3,LEAVES:12)
Block(10,15,4,LEAVES:12)
Block(10,15,5,LEAVES:12)
Block(10,15,15,LEAVES:12)
Block(10,16,-3,LEAVES:12)
Block(10,16,-1,LEAVES:12)
Block(10,16,0,17:12)
Block(10,16,1,LEAVES:12)
Block(10,16,2,LEAVES:12)
Block(10,16,3,LEAVES:12)
Block(10,16,4,LEAVES:12)
Block(10,16,6,LEAVES:12)
Block(10,16,7,LEAVES:12)
Block(10,16,8,LEAVES:12)
Block(10,16,9,LEAVES:12)
Block(10,16,11,LEAVES:12)
Block(10,16,12,17:12)
Block(10,16,13,LEAVES:12)
Block(10,17,-3,LEAVES:12)
Block(10,17,-1,LEAVES:12)
Block(10,17,0,LEAVES:12)
Block(10,17,1,LEAVES:12)
Block(10,17,2,LEAVES:12)
Block(10,17,8,LEAVES:12)
Block(10,17,10,LEAVES:12)
Block(10,17,12,17:12)
Block(10,17,13,LEAVES:12)
Block(10,18,-1,LEAVES:12)
Block(10,18,0,LEAVES:12)
Block(10,18,1,LEAVES:12)
Block(10,18,2,LEAVES:12)
Block(10,18,3,LEAVES:12)
Block(10,18,7,LEAVES:12)
Block(10,18,12,17:12)
Block(10,18,15,LEAVES:12)
Block(10,19,-2,LEAVES:12)
Block(10,19,0,LEAVES:12)
Block(10,19,1,LEAVES:12)
Block(10,19,2,LEAVES:12)
Block(10,19,10,LEAVES:12)
Block(10,19,11,LEAVES:12)
Block(10,19,12,LEAVES:12)
Block(10,19,13,LEAVES:12)
Block(10,20,0,LEAVES:12)
Block(10,20,1,LEAVES:12)
Block(10,20,8,LEAVES:12)
Block(10,20,9,LEAVES:12)
Block(10,20,10,LEAVES:12)
Block(10,20,11,LEAVES:12)
Block(10,20,12,LEAVES:12)
Block(10,21,7,LEAVES:12)
Block(10,21,8,LEAVES:12)
Block(10,21,9,LEAVES:12)
Block(10,21,10,LEAVES:12)
Block(10,21,11,LEAVES:12)
Block(10,22,8,LEAVES:12)
Block(10,23,4,LEAVES:12)
Block(10,23,5,LEAVES:12)
Block(10,23,6,LEAVES:12)
Block(10,24,5,LEAVES:12)
Block(10,24,6,LEAVES:12)
Block(10,24,7,LEAVES:12)
Block(10,24,8,LEAVES:12)
Block(10,24,9,LEAVES:12)
Block(10,24,10,LEAVES:12)
Block(10,25,6,LEAVES:12)
Block(10,25,9,LEAVES:12)
Block(10,26,1,LEAVES:12)
Block(10,27,0,LEAVES:12)
Block(10,27,1,LEAVES:12)
Block(10,27,2,LEAVES:12)
Block(10,27,5,LEAVES:12)
Block(10,27,6,LEAVES:12)
Block(10,27,7,LEAVES:12)
Block(10,27,8,LEAVES:12)
Block(10,27,9,LEAVES:12)
Block(10,28,1,LEAVES:12)
Block(10,28,2,LEAVES:12)
Block(10,28,3,17:12)
Block(10,28,4,LEAVES:12)
Block(10,28,5,LEAVES:12)
Block(10,28,6,LEAVES:12)
Block(10,28,7,LEAVES:12)
Block(10,28,8,LEAVES:12)
Block(10,29,0,LEAVES:12)
Block(10,29,1,LEAVES:12)
Block(10,29,2,LEAVES:12)
Block(10,29,3,LEAVES:12)
Block(10,29,4,LEAVES:12)
Block(10,29,5,LEAVES:12)
Block(10,29,6,LEAVES:12)
Block(10,30,1,LEAVES:12)
Block(10,30,4,LEAVES:12)
Block(10,30,7,LEAVES:12)
Block(10,30,8,LEAVES:12)
Block(10,30,9,LEAVES:12)
Block(10,31,7,LEAVES:12)
Block(10,31,8,LEAVES:12)
Block(10,31,9,LEAVES:12)
Block(10,31,10,LEAVES:12)
Block(10,32,6,LEAVES:12)
Block(10,32,9,LEAVES:12)
Block(10,33,4,LEAVES:12)
Block(10,33,5,LEAVES:12)
Block(10,33,6,LEAVES:12)
Block(10,33,8,LEAVES:12)
Block(10,33,9,LEAVES:12)
Block(10,33,11,LEAVES:12)
Block(10,34,5,LEAVES:12)
Block(10,34,6,LEAVES:12)
Block(10,34,7,LEAVES:12)
Block(10,34,8,LEAVES:12)
Block(10,34,10,LEAVES:12)
Block(10,34,11,LEAVES:12)
Block(10,34,12,LEAVES:12)
Block(10,35,6,LEAVES:12)
Block(10,35,7,LEAVES:12)
Block(10,35,9,LEAVES:12)
Block(10,35,11,LEAVES:12)
Block(10,36,6,LEAVES:12)
Block(10,36,7,LEAVES:12)
Block(10,36,8,LEAVES:12)
Block(10,37,7,LEAVES:12)
Block(10,37,8,LEAVES:12)
Block(10,37,9,LEAVES:12)
Block(10,37,10,LEAVES:12)
Block(10,38,9,LEAVES:12)
Block(10,38,10,LEAVES:12)
Block(10,38,11,LEAVES:12)
Block(10,39,10,LEAVES:12)
Block(11,12,1,LEAVES:12)
Block(11,12,2,LEAVES:12)
Block(11,12,3,LEAVES:12)
Block(11,12,4,LEAVES:12)
Block(11,13,0,LEAVES:12)
Block(11,13,1,LEAVES:12)
Block(11,13,2,LEAVES:12)
Block(11,13,5,LEAVES:12)
Block(11,14,-1,LEAVES:12)
Block(11,14,0,LEAVES:12)
Block(11,14,1,LEAVES:12)
Block(11,14,2,17:12)
Block(11,14,3,LEAVES:12)
Block(11,14,4,LEAVES:12)
Block(11,14,5,LEAVES:12)
Block(11,14,15,LEAVES:12)
Block(11,15,-3,LEAVES:12)
Block(11,15,-2,LEAVES:12)
Block(11,15,-1,LEAVES:12)
Block(11,15,1,LEAVES:12)
Block(11,15,2,LEAVES:12)
Block(11,15,3,LEAVES:12)
Block(11,15,4,LEAVES:12)
Block(11,15,14,LEAVES:12)
Block(11,16,-4,LEAVES:12)
Block(11,16,-3,LEAVES:12)
Block(11,16,-2,LEAVES:12)
Block(11,16,-1,LEAVES:12)
Block(11,16,1,LEAVES:12)
Block(11,16,2,LEAVES:12)
Block(11,16,3,LEAVES:12)
Block(11,16,5,LEAVES:12)
Block(11,16,6,LEAVES:12)
Block(11,16,7,LEAVES:12)
Block(11,16,8,LEAVES:12)
Block(11,16,10,LEAVES:12)
Block(11,16,11,LEAVES:12)
Block(11,16,12,LEAVES:12)
Block(11,16,13,LEAVES:12)
Block(11,16,14,LEAVES:12)
Block(11,17,-4,LEAVES:12)
Block(11,17,-3,LEAVES:12)
