#######################################################################
# +-----------------------------------------------------------------+ #
# |                            BO3 object                           | #
# +-----------------------------------------------------------------+ #
#######################################################################

# This is the config file of a custom object.
# If you add this object correctly to your BiomeConfigs, it will spawn in the world.

# This is the creator of this BO3 object
Author: BO3 BulkEdit (by LanToaster)

# A short description of this BO3 object
Description: This Object was Created with BO3_BulkEdit

# The BO3 version, don't change this! It can be used by external applications to do a version check.
Version: 3

# The settings mode, WriteAll, WriteWithoutComments or WriteDisable. See WorldConfig.
SettingsMode: WriteDisable


#######################################################################
# +-----------------------------------------------------------------+ #
# |                          Main settings                          | #
# +-----------------------------------------------------------------+ #
#######################################################################

# This needs to be set to true to spawn the object in the Tree and Sapling resources.
Tree: true

# The frequency of the BO3 from 1 to 200. Tries this many times to spawn this BO3 when using the CustomObject(...) resource.
# Ignored by Tree(..), Sapling(..) and CustomStructure(..)
Frequency: 1

# The rarity of the BO3 from 0 to 100. Each spawn attempt has rarity% chance to succeed when using the CustomObject(...) resource.
# Ignored by Tree(..), Sapling(..) and CustomStructure(..)
Rarity: 100.0

# If you set this to true, the BO3 will be placed with a random rotation.
RotateRandomly: true

# The spawn height of the BO3 - randomY, highestBlock or highestSolidBlock.
SpawnHeight: highestSolidBlock
SpawnHeightOffset: -2
# The height limits for the BO3.
MinHeight: 0

MaxHeight: 256

# Objects can have other objects attacthed to it: branches. Branches can also
# have branches attached to it, which can also have branches, etc. This is the
# maximum branch depth for this objects.
MaxBranchDepth: 10

# When spawned with the UseWorld keyword, this BO3 should NOT spawn in the following biomes.
# If you writer.write the BO3 name directly in the BiomeConfigs, this will be ignored.
ExcludedBiomes: All


#######################################################################
# +-----------------------------------------------------------------+ #
# |                      Source block settings                      | #
# +-----------------------------------------------------------------+ #
#######################################################################

# The block(s) the BO3 should spawn in.
SourceBlocks: AIR,GRASS,DIRT,STONE

# The maximum percentage of the BO3 that can be outside the SourceBlock.
# The BO3 won't be placed on a location with more blocks outside the SourceBlock than this percentage.
MaxPercentageOutsideSourceBlock: 0

# What to do when a block is about to be placed outside the SourceBlock? (dontPlace, placeAnyway)
OutsideSourceBlock: dontPlace


#######################################################################
# +-----------------------------------------------------------------+ #
# |                              Blocks                             | #
# +-----------------------------------------------------------------+ #
#######################################################################

# All the blocks used in the BO3 are listed here. Possible blocks:
# Block(x,y,z,id[.data][,nbtfile.nbt)
# RandomBlock(x,y,z,id[:data][,nbtfile.nbt],chance[,id[:data][,nbtfile.nbt],chance[,...]])
# So RandomBlock(0,0,0,CHEST,chest.nbt,50,CHEST,anotherchest.nbt,100) will spawn a chest at
# the BO3 origin, and give it a 50% chance to have the contents of chest.nbt, or, if that
# fails, a 100% percent chance to have the contents of anotherchest.nbt.
Block(-1,0,-3,LOG:12)
Block(0,0,-3,LOG:12)
Block(1,0,-3,LOG:12)
Block(-2,0,-2,LOG:12)
Block(-1,0,-2,LOG:12)
Block(0,0,-2,LOG:12)
Block(1,0,-2,LOG:12)
Block(2,0,-2,LOG:12)
Block(-3,0,-1,LOG:12)
Block(-2,0,-1,LOG:12)
Block(-1,0,-1,LOG:12)
Block(0,0,-1,LOG:12)
Block(1,0,-1,LOG:12)
Block(2,0,-1,LOG:12)
Block(3,0,-1,LOG:12)
Block(-4,0,0,LOG:12)
Block(-3,0,0,LOG:12)
Block(-2,0,0,LOG:12)
Block(-1,0,0,LOG:12)
Block(0,0,0,LOG:12)
Block(1,0,0,LOG:12)
Block(2,0,0,LOG:12)
Block(3,0,0,LOG:12)
Block(-3,0,1,LOG:12)
Block(-2,0,1,LOG:12)
Block(-1,0,1,LOG:12)
Block(0,0,1,LOG:12)
Block(1,0,1,LOG:12)
Block(2,0,1,LOG:12)
Block(3,0,1,LOG:12)
Block(-2,0,2,LOG:12)
Block(-1,0,2,LOG:12)
Block(0,0,2,LOG:12)
Block(1,0,2,LOG:12)
Block(2,0,2,LOG:12)
Block(-1,0,3,LOG:12)
Block(0,0,3,LOG:12)
Block(1,0,3,LOG:12)
Block(0,1,-3,LOG:12)
Block(-2,1,-2,LOG:12)
Block(-1,1,-2,LOG:12)
Block(0,1,-2,LOG:12)
Block(1,1,-2,LOG:12)
Block(2,1,-2,LOG:12)
Block(-2,1,-1,LOG:12)
Block(-1,1,-1,LOG:12)
Block(0,1,-1,LOG:12)
Block(1,1,-1,LOG:12)
Block(2,1,-1,LOG:12)
Block(-3,1,0,LOG:12)
Block(-2,1,0,LOG:12)
Block(-1,1,0,LOG:12)
Block(0,1,0,LOG:12)
Block(1,1,0,LOG:12)
Block(2,1,0,LOG:12)
Block(3,1,0,LOG:12)
Block(-2,1,1,LOG:12)
Block(-1,1,1,LOG:12)
Block(0,1,1,LOG:12)
Block(1,1,1,LOG:12)
Block(2,1,1,LOG:12)
Block(-2,1,2,LOG:12)
Block(-1,1,2,LOG:12)
Block(0,1,2,LOG:12)
Block(1,1,2,LOG:12)
Block(2,1,2,LOG:12)
Block(0,1,3,LOG:12)
Block(-1,2,-2,LOG:12)
Block(0,2,-2,LOG:12)
Block(1,2,-2,LOG:12)
Block(-2,2,-1,LOG:12)
Block(-1,2,-1,LOG:12)
Block(0,2,-1,LOG:12)
Block(1,2,-1,LOG:12)
Block(2,2,-1,LOG:12)
Block(-3,2,0,LOG:12)
Block(-2,2,0,LOG:12)
Block(-1,2,0,LOG:12)
Block(0,2,0,LOG:12)
Block(1,2,0,LOG:12)
Block(2,2,0,LOG:12)
Block(-2,2,1,LOG:12)
Block(-1,2,1,LOG:12)
Block(0,2,1,LOG:12)
Block(1,2,1,LOG:12)
Block(2,2,1,LOG:12)
Block(-1,2,2,LOG:12)
Block(0,2,2,LOG:12)
Block(1,2,2,LOG:12)
Block(0,3,-2,LOG:12)
Block(-1,3,-1,LOG:12)
Block(0,3,-1,LOG:12)
Block(1,3,-1,LOG:12)
Block(-2,3,0,LOG:12)
Block(-1,3,0,LOG:12)
Block(0,3,0,LOG:12)
Block(1,3,0,LOG:12)
Block(2,3,0,LOG:12)
Block(-1,3,1,LOG:12)
Block(0,3,1,LOG:12)
Block(1,3,1,LOG:12)
Block(0,3,2,LOG:12)
Block(0,4,-2,LOG:12)
Block(-1,4,-1,LOG:12)
Block(0,4,-1,LOG:12)
Block(1,4,-1,LOG:12)
Block(-2,4,0,LOG:12)
Block(-1,4,0,LOG:12)
Block(0,4,0,LOG:12)
Block(1,4,0,LOG:12)
Block(2,4,0,LOG:12)
Block(-1,4,1,LOG:12)
Block(0,4,1,LOG:12)
Block(1,4,1,LOG:12)
Block(0,4,2,LOG:12)
Block(-1,5,-1,LOG:12)
Block(0,5,-1,LOG:12)
Block(1,5,-1,LOG:12)
Block(-1,5,0,LOG:12)
Block(0,5,0,LOG:12)
Block(1,5,0,LOG:12)
Block(-1,5,1,LOG:12)
Block(0,5,1,LOG:12)
Block(1,5,1,LOG:12)
Block(-1,6,-1,LOG:12)
Block(0,6,-1,LOG:12)
Block(1,6,-1,LOG:12)
Block(-1,6,0,LOG:12)
Block(0,6,0,LOG:12)
Block(1,6,0,LOG:12)
Block(-1,6,1,LOG:12)
Block(0,6,1,LOG:12)
Block(1,6,1,LOG:12)
Block(-1,7,-1,LOG:12)
Block(0,7,-1,LOG:12)
Block(1,7,-1,LOG:12)
Block(-1,7,0,LOG:12)
Block(0,7,0,LOG:12)
Block(1,7,0,LOG:12)
Block(-1,7,1,LOG:12)
Block(0,7,1,LOG:12)
Block(1,7,1,LOG:12)
Block(-1,8,-1,LOG:12)
Block(0,8,-1,LOG:12)
Block(1,8,-1,LOG:12)
Block(-1,8,0,LOG:12)
Block(0,8,0,LOG:12)
Block(1,8,0,LOG:12)
Block(-1,8,1,LOG:12)
Block(0,8,1,LOG:12)
Block(1,8,1,LOG:12)
Block(-1,9,-1,LOG:12)
Block(0,9,-1,LOG:12)
Block(1,9,-1,LOG:12)
Block(-1,9,0,LOG:12)
Block(0,9,0,LOG:12)
Block(1,9,0,LOG:12)
Block(-1,9,1,LOG:12)
Block(0,9,1,LOG:12)
Block(1,9,1,LOG:12)
Block(-1,10,-1,LOG:12)
Block(0,10,-1,LOG:12)
Block(1,10,-1,LOG:12)
Block(-1,10,0,LOG:12)
Block(0,10,0,LOG:12)
Block(1,10,0,LOG:12)
Block(-1,10,1,LOG:12)
Block(0,10,1,LOG:12)
Block(1,10,1,LOG:12)
Block(0,11,-1,LOG:12)
Block(-1,11,0,LOG:12)
Block(0,11,0,LOG:12)
Block(1,11,0,LOG:12)
Block(0,11,1,LOG:12)
Block(0,12,-1,LOG:12)
Block(-1,12,0,LOG:12)
Block(0,12,0,LOG:12)
Block(1,12,0,LOG:12)
Block(0,12,1,LOG:12)
Block(0,13,-1,LOG:12)
Block(-1,13,0,LOG:12)
Block(0,13,0,LOG:12)
Block(1,13,0,LOG:12)
Block(0,13,1,LOG:12)
Block(0,14,-1,LOG:12)
Block(-1,14,0,LOG:12)
Block(0,14,0,LOG:12)
Block(1,14,0,LOG:12)
Block(0,14,1,LOG:12)
Block(0,15,-1,LOG:12)
Block(-1,15,0,LOG:12)
Block(0,15,0,LOG:12)
Block(1,15,0,LOG:12)
Block(0,15,1,LOG:12)
Block(0,16,-1,LOG:12)
Block(-1,16,0,LOG:12)
Block(0,16,0,LOG:12)
Block(1,16,0,LOG:12)
Block(0,16,1,LOG:12)
Block(0,17,-1,LOG:12)
Block(-1,17,0,LOG:12)
Block(0,17,0,LOG:12)
Block(1,17,0,LOG:12)
Block(0,17,1,LOG:12)
Block(0,18,-1,LOG:12)
Block(-1,18,0,LOG:12)
Block(0,18,0,LOG:12)
Block(1,18,0,LOG:12)
Block(0,18,1,LOG:12)
Block(0,19,-2,LOG:12)
Block(-1,19,-1,LOG:12)
Block(0,19,-1,LOG:12)
Block(1,19,-1,LOG:12)
Block(-2,19,0,LOG:12)
Block(-1,19,0,LOG:12)
Block(0,19,0,LOG:12)
Block(1,19,0,LOG:12)
Block(2,19,0,LOG:12)
Block(-1,19,1,LOG:12)
Block(0,19,1,LOG:12)
Block(1,19,1,LOG:12)
Block(0,19,2,LOG:12)
Block(0,20,-2,LOG:12)
Block(-1,20,-1,LOG:12)
Block(0,20,-1,LOG:12)
Block(1,20,-1,LOG:12)
Block(3,20,-1,LEAVES:0)
Block(-2,20,0,LOG:12)
Block(-1,20,0,LOG:12)
Block(0,20,0,LOG:12)
Block(1,20,0,LOG:12)
Block(2,20,0,LOG:12)
Block(3,20,0,LEAVES:0)
Block(4,20,0,LEAVES:0)
Block(5,20,0,LEAVES:0)
Block(-1,20,1,LOG:12)
Block(0,20,1,LOG:12)
Block(1,20,1,LOG:12)
Block(4,20,1,LEAVES:0)
Block(5,20,1,LEAVES:0)
Block(0,20,2,LOG:12)
Block(-5,21,-5,LEAVES:0)
Block(4,21,-5,LEAVES:0)
Block(-5,21,-4,LEAVES:0)
Block(-4,21,-4,LEAVES:0)
Block(-3,21,-4,LEAVES:0)
Block(-1,21,-4,LEAVES:0)
Block(0,21,-4,LEAVES:0)
Block(4,21,-4,LEAVES:0)
Block(-4,21,-3,LEAVES:0)
Block(-3,21,-3,LEAVES:0)
Block(-1,21,-3,LEAVES:0)
Block(0,21,-3,LOG:12)
Block(1,21,-3,LEAVES:0)
Block(3,21,-3,LEAVES:0)
Block(-2,21,-2,LOG:12)
Block(-1,21,-2,LOG:12)
Block(0,21,-2,LOG:12)
Block(1,21,-2,LOG:12)
Block(2,21,-2,LOG:12)
Block(3,21,-2,LEAVES:0)
Block(4,21,-2,LEAVES:0)
Block(5,21,-2,LEAVES:0)
Block(-2,21,-1,LOG:12)
Block(-1,21,-1,LOG:12)
Block(0,21,-1,LOG:12)
Block(1,21,-1,LOG:12)
Block(2,21,-1,LOG:12)
Block(4,21,-1,LEAVES:0)
Block(-6,21,0,LEAVES:0)
Block(-5,21,0,LEAVES:0)
Block(-4,21,0,LEAVES:0)
Block(-3,21,0,LOG:12)
Block(-2,21,0,LOG:12)
Block(-1,21,0,LOG:12)
Block(0,21,0,LOG:12)
Block(1,21,0,LOG:12)
Block(2,21,0,LOG:12)
Block(3,21,0,LOG:12)
Block(4,21,0,LEAVES:0)
Block(5,21,0,LEAVES:0)
Block(-5,21,1,LEAVES:0)
Block(-2,21,1,LOG:12)
Block(-1,21,1,LOG:12)
Block(0,21,1,LOG:12)
Block(1,21,1,LOG:12)
Block(2,21,1,LOG:12)
Block(3,21,1,LEAVES:0)
Block(4,21,1,LEAVES:0)
Block(-2,21,2,LOG:12)
Block(-1,21,2,LOG:12)
Block(0,21,2,LOG:12)
Block(1,21,2,LOG:12)
Block(2,21,2,LOG:12)
Block(-4,21,3,LEAVES:0)
Block(-3,21,3,LEAVES:0)
Block(0,21,3,LOG:12)
Block(3,21,3,LEAVES:0)
Block(-4,21,4,LEAVES:0)
Block(0,21,4,LEAVES:0)
Block(1,21,4,LEAVES:0)
Block(3,21,4,LEAVES:0)
Block(4,21,4,LEAVES:0)
Block(-4,21,5,LEAVES:0)
Block(0,21,5,LEAVES:0)
Block(1,21,5,LEAVES:0)
Block(4,21,5,LEAVES:0)
Block(0,21,6,LEAVES:0)
Block(1,21,6,LEAVES:0)
Block(-4,22,-9,LEAVES:0)
Block(-3,22,-9,LEAVES:0)
Block(1,22,-9,LEAVES:0)
Block(2,22,-9,LEAVES:0)
Block(-4,22,-8,LEAVES:0)
Block(-2,22,-8,LEAVES:0)
Block(0,22,-8,LEAVES:0)
Block(3,22,-8,LEAVES:0)
Block(4,22,-8,LEAVES:0)
Block(5,22,-8,LEAVES:0)
Block(-7,22,-7,LEAVES:0)
Block(-6,22,-7,LEAVES:0)
Block(-1,22,-7,LEAVES:0)
Block(3,22,-7,LEAVES:0)
Block(5,22,-7,LEAVES:0)
Block(7,22,-7,LEAVES:0)
Block(-7,22,-6,LEAVES:0)
Block(-6,22,-6,LEAVES:0)
Block(-5,22,-6,LEAVES:0)
Block(-3,22,-6,LEAVES:0)
Block(-1,22,-6,LEAVES:0)
Block(0,22,-6,LEAVES:0)
Block(1,22,-6,LEAVES:0)
Block(5,22,-6,LEAVES:0)
Block(6,22,-6,LEAVES:0)
Block(7,22,-6,LEAVES:0)
Block(8,22,-6,LEAVES:0)
Block(-6,22,-5,LEAVES:0)
Block(-5,22,-5,LEAVES:0)
Block(-4,22,-5,LEAVES:0)
Block(-2,22,-5,LEAVES:0)
Block(0,22,-5,LEAVES:0)
Block(1,22,-5,LEAVES:0)
Block(2,22,-5,LEAVES:0)
Block(6,22,-5,LEAVES:0)
Block(7,22,-5,LEAVES:0)
Block(8,22,-5,LEAVES:0)
Block(9,22,-5,LEAVES:0)
Block(-8,22,-4,LEAVES:0)
Block(-7,22,-4,LEAVES:0)
Block(-6,22,-4,LEAVES:0)
Block(-5,22,-4,LEAVES:0)
Block(-4,22,-4,LEAVES:0)
Block(-2,22,-4,LEAVES:0)
Block(0,22,-4,LOG:8)
Block(1,22,-4,LEAVES:0)
Block(2,22,-4,LEAVES:0)
Block(4,22,-4,LEAVES:0)
Block(5,22,-4,LEAVES:0)
Block(6,22,-4,LEAVES:0)
Block(7,22,-4,LEAVES:0)
Block(9,22,-4,LEAVES:0)
Block(-8,22,-3,LEAVES:0)
Block(-7,22,-3,LEAVES:0)
Block(-3,22,-3,LOG:4)
Block(0,22,-3,LOG:12)
Block(3,22,-3,LOG:8)
Block(-9,22,-2,LEAVES:0)
Block(-6,22,-2,LEAVES:0)
Block(-5,22,-2,LEAVES:0)
Block(-4,22,-2,LEAVES:0)
Block(-2,22,-2,LOG:12)
Block(-1,22,-2,LOG:12)
Block(0,22,-2,LOG:12)
Block(1,22,-2,LOG:12)
Block(2,22,-2,LOG:12)
Block(4,22,-2,LEAVES:0)
Block(5,22,-2,LEAVES:0)
Block(-7,22,-1,LEAVES:0)
Block(-5,22,-1,LEAVES:0)
Block(-2,22,-1,LOG:12)
Block(-1,22,-1,LOG:12)
Block(0,22,-1,LOG:12)
Block(1,22,-1,LOG:12)
Block(2,22,-1,LOG:12)
Block(3,22,-1,LEAVES:0)
Block(4,22,-1,LEAVES:0)
Block(5,22,-1,LEAVES:0)
Block(8,22,-1,LEAVES:0)
Block(9,22,-1,LEAVES:0)
Block(-9,22,0,LEAVES:0)
Block(-7,22,0,LEAVES:0)
Block(-4,22,0,LOG:4)
Block(-3,22,0,LOG:12)
Block(-2,22,0,LOG:12)
Block(-1,22,0,LOG:12)
Block(0,22,0,LOG:12)
Block(1,22,0,LOG:12)
Block(2,22,0,LOG:12)
Block(3,22,0,LOG:12)
Block(4,22,0,LOG:4)
Block(5,22,0,LEAVES:0)
Block(6,22,0,LEAVES:0)
Block(7,22,0,LEAVES:0)
Block(8,22,0,LEAVES:0)
Block(-8,22,1,LEAVES:0)
Block(-7,22,1,LEAVES:0)
Block(-3,22,1,LEAVES:0)
Block(-2,22,1,LOG:12)
Block(-1,22,1,LOG:12)
Block(0,22,1,LOG:12)
Block(1,22,1,LOG:12)
Block(2,22,1,LOG:12)
Block(4,22,1,LEAVES:0)
Block(5,22,1,LEAVES:0)
Block(6,22,1,LEAVES:0)
Block(-8,22,2,LEAVES:0)
Block(-6,22,2,LEAVES:0)
Block(-5,22,2,LEAVES:0)
Block(-4,22,2,LEAVES:0)
Block(-3,22,2,LEAVES:0)
Block(-2,22,2,LOG:12)
Block(-1,22,2,LOG:12)
Block(0,22,2,LOG:12)
Block(1,22,2,LOG:12)
Block(2,22,2,LOG:12)
Block(3,22,2,LEAVES:0)
Block(4,22,2,LEAVES:0)
Block(5,22,2,LEAVES:0)
Block(8,22,2,LEAVES:0)
Block(9,22,2,LEAVES:0)
Block(-7,22,3,LEAVES:0)
Block(-5,22,3,LEAVES:0)
Block(-3,22,3,LOG:8)
Block(-2,22,3,LEAVES:0)
Block(-1,22,3,LEAVES:0)
Block(0,22,3,LOG:12)
Block(2,22,3,LEAVES:0)
Block(3,22,3,LOG:4)
Block(4,22,3,LEAVES:0)
Block(6,22,3,LEAVES:0)
Block(7,22,3,LEAVES:0)
Block(8,22,3,LEAVES:0)
Block(9,22,3,LEAVES:0)
Block(-5,22,4,LEAVES:0)
Block(-2,22,4,LEAVES:0)
Block(-1,22,4,LEAVES:0)
Block(0,22,4,LOG:8)
Block(3,22,4,LEAVES:0)
Block(4,22,4,LEAVES:0)
Block(5,22,4,LEAVES:0)
Block(6,22,4,LEAVES:0)
Block(7,22,4,LEAVES:0)
Block(8,22,4,LEAVES:0)
Block(-9,22,5,LEAVES:0)
Block(-6,22,5,LEAVES:0)
Block(-5,22,5,LEAVES:0)
Block(-4,22,5,LEAVES:0)
Block(-2,22,5,LEAVES:0)
Block(5,22,5,LEAVES:0)
Block(9,22,5,LEAVES:0)
Block(10,22,5,LEAVES:0)
Block(-8,22,6,LEAVES:0)
Block(-7,22,6,LEAVES:0)
Block(-6,22,6,LEAVES:0)
Block(-5,22,6,LEAVES:0)
Block(-4,22,6,LEAVES:0)
Block(-2,22,6,LEAVES:0)
Block(-1,22,6,LEAVES:0)
Block(0,22,6,LEAVES:0)
Block(4,22,6,LEAVES:0)
Block(6,22,6,LEAVES:0)
Block(7,22,6,LEAVES:0)
Block(8,22,6,LEAVES:0)
Block(-8,22,7,LEAVES:0)
Block(-6,22,7,LEAVES:0)
Block(-5,22,7,LEAVES:0)
Block(-4,22,7,LEAVES:0)
Block(0,22,7,LEAVES:0)
Block(1,22,7,LEAVES:0)
Block(6,22,7,LEAVES:0)
Block(7,22,7,LEAVES:0)
Block(8,22,7,LEAVES:0)
Block(10,22,7,LEAVES:0)
Block(-6,22,8,LEAVES:0)
Block(-5,22,8,LEAVES:0)
Block(-1,22,8,LEAVES:0)
Block(0,22,8,LEAVES:0)
Block(2,22,8,LEAVES:0)
Block(3,22,8,LEAVES:0)
Block(6,22,8,LEAVES:0)
Block(7,22,8,LEAVES:0)
Block(8,22,8,LEAVES:0)
Block(-6,22,9,LEAVES:0)
Block(-5,22,9,LEAVES:0)
Block(-4,22,9,LEAVES:0)
Block(0,22,9,LEAVES:0)
Block(2,22,9,LEAVES:0)
Block(-1,23,-13,LEAVES:0)
Block(0,23,-13,LEAVES:0)
Block(1,23,-13,LEAVES:0)
Block(2,23,-13,LEAVES:0)
Block(3,23,-13,LEAVES:0)
Block(-8,23,-12,LEAVES:0)
Block(-7,23,-12,LEAVES:0)
Block(-6,23,-12,LEAVES:0)
Block(-5,23,-12,LEAVES:0)
Block(-4,23,-12,LEAVES:0)
Block(-2,23,-12,LEAVES:0)
Block(-1,23,-12,LEAVES:0)
Block(0,23,-12,LEAVES:0)
Block(1,23,-12,LEAVES:0)
Block(3,23,-12,LEAVES:0)
Block(4,23,-12,LEAVES:0)
Block(7,23,-12,LEAVES:0)
Block(8,23,-12,LEAVES:0)
Block(-10,23,-11,LEAVES:0)
Block(-9,23,-11,LEAVES:0)
Block(-7,23,-11,LEAVES:0)
Block(-6,23,-11,LEAVES:0)
Block(-5,23,-11,LEAVES:0)
Block(-4,23,-11,LEAVES:0)
Block(-2,23,-11,LEAVES:0)
Block(-1,23,-11,LEAVES:0)
Block(0,23,-11,LEAVES:0)
Block(2,23,-11,LEAVES:0)
Block(3,23,-11,LEAVES:0)
Block(4,23,-11,LEAVES:0)
Block(6,23,-11,LEAVES:0)
Block(8,23,-11,LEAVES:0)
Block(10,23,-11,LEAVES:0)
Block(11,23,-11,LEAVES:0)
Block(-11,23,-10,LEAVES:0)
Block(-10,23,-10,LEAVES:0)
Block(-9,23,-10,LEAVES:0)
Block(-7,23,-10,LEAVES:0)
Block(-6,23,-10,LEAVES:0)
Block(-5,23,-10,LEAVES:0)
Block(-4,23,-10,LEAVES:0)
Block(-2,23,-10,LEAVES:0)
Block(-1,23,-10,LEAVES:0)
Block(0,23,-10,LEAVES:0)
Block(2,23,-10,LEAVES:0)
Block(4,23,-10,LEAVES:0)
Block(5,23,-10,LEAVES:0)
Block(8,23,-10,LEAVES:0)
Block(9,23,-10,LEAVES:0)
Block(10,23,-10,LEAVES:0)
Block(-7,23,-9,LEAVES:0)
Block(-6,23,-9,LEAVES:0)
Block(-3,23,-9,LEAVES:0)
Block(-2,23,-9,LEAVES:0)
Block(1,23,-9,LEAVES:0)
Block(2,23,-9,LEAVES:0)
Block(3,23,-9,LEAVES:0)
Block(5,23,-9,LEAVES:0)
Block(7,23,-9,LEAVES:0)
Block(8,23,-9,LEAVES:0)
Block(10,23,-9,LEAVES:0)
Block(-12,23,-8,LEAVES:0)
Block(-11,23,-8,LEAVES:0)
Block(-10,23,-8,LEAVES:0)
Block(-7,23,-8,LEAVES:0)
Block(-6,23,-8,LEAVES:0)
Block(-5,23,-8,LEAVES:0)
Block(-3,23,-8,LEAVES:0)
Block(-2,23,-8,LEAVES:0)
Block(-1,23,-8,LEAVES:0)
Block(0,23,-8,LEAVES:0)
Block(2,23,-8,LEAVES:0)
Block(3,23,-8,LEAVES:0)
Block(5,23,-8,LEAVES:0)
Block(6,23,-8,LEAVES:0)
Block(7,23,-8,LEAVES:0)
Block(8,23,-8,LEAVES:0)
Block(9,23,-8,LEAVES:0)
Block(-12,23,-7,LEAVES:0)
Block(-11,23,-7,LEAVES:0)
Block(-10,23,-7,LEAVES:0)
Block(-8,23,-7,LEAVES:0)
Block(-7,23,-7,LEAVES:0)
Block(-6,23,-7,LEAVES:0)
Block(-4,23,-7,LEAVES:0)
Block(-3,23,-7,LEAVES:0)
Block(-2,23,-7,LEAVES:0)
Block(0,23,-7,LEAVES:0)
Block(1,23,-7,LEAVES:0)
Block(5,23,-7,LEAVES:0)
Block(7,23,-7,LEAVES:0)
Block(10,23,-7,LEAVES:0)
Block(11,23,-7,LEAVES:0)
Block(12,23,-7,LEAVES:0)
Block(-11,23,-6,LEAVES:0)
Block(-10,23,-6,LEAVES:0)
Block(-8,23,-6,LEAVES:0)
Block(-7,23,-6,LEAVES:0)
Block(-6,23,-6,LEAVES:0)
Block(-4,23,-6,LEAVES:0)
Block(-1,23,-6,LEAVES:0)
Block(0,23,-6,LOG:8)
Block(1,23,-6,LEAVES:0)
Block(2,23,-6,LEAVES:0)
Block(4,23,-6,LEAVES:0)
Block(5,23,-6,LEAVES:0)
Block(7,23,-6,LEAVES:0)
Block(8,23,-6,LEAVES:0)
Block(10,23,-6,LEAVES:0)
Block(11,23,-6,LEAVES:0)
Block(12,23,-6,LEAVES:0)
Block(-12,23,-5,LEAVES:0)
Block(-11,23,-5,LEAVES:0)
Block(-9,23,-5,LEAVES:0)
Block(-8,23,-5,LEAVES:0)
Block(-5,23,-5,LOG:4)
Block(-4,23,-5,LEAVES:0)
Block(-3,23,-5,LEAVES:0)
Block(-1,23,-5,LEAVES:0)
Block(0,23,-5,LOG:8)
Block(1,23,-5,LEAVES:0)
Block(2,23,-5,LEAVES:0)
Block(5,23,-5,LOG:8)
Block(6,23,-5,LEAVES:0)
Block(7,23,-5,LEAVES:0)
Block(8,23,-5,LEAVES:0)
Block(11,23,-5,LEAVES:0)
Block(12,23,-5,LEAVES:0)
Block(13,23,-5,LEAVES:0)
Block(-11,23,-4,LEAVES:0)
Block(-8,23,-4,LEAVES:0)
Block(-7,23,-4,LEAVES:0)
Block(-6,23,-4,LEAVES:0)
Block(-5,23,-4,LEAVES:0)
Block(-4,23,-4,LOG:4)
Block(-3,23,-4,LEAVES:0)
Block(-2,23,-4,LEAVES:0)
Block(0,23,-4,LOG:8)
Block(2,23,-4,LEAVES:0)
Block(3,23,-4,LEAVES:0)
Block(4,23,-4,LOG:8)
Block(5,23,-4,LEAVES:0)
Block(6,23,-4,LEAVES:0)
Block(7,23,-4,LEAVES:0)
Block(10,23,-4,LEAVES:0)
Block(11,23,-4,LEAVES:0)
Block(12,23,-4,LEAVES:0)
Block(13,23,-4,LEAVES:0)
Block(-10,23,-3,LEAVES:0)
Block(-9,23,-3,LEAVES:0)
Block(-8,23,-3,LEAVES:0)
Block(-7,23,-3,LEAVES:0)
Block(-6,23,-3,LEAVES:0)
Block(-4,23,-3,LEAVES:0)
Block(-3,23,-3,LEAVES:0)
Block(-2,23,-3,LEAVES:0)
Block(-1,23,-3,LEAVES:0)
Block(0,23,-3,LOG:8)
Block(2,23,-3,LEAVES:0)
Block(3,23,-3,LEAVES:0)
Block(5,23,-3,LEAVES:0)
Block(6,23,-3,LEAVES:0)
Block(8,23,-3,LEAVES:0)
Block(10,23,-3,LEAVES:0)
Block(12,23,-3,LEAVES:0)
Block(-8,23,-2,LEAVES:0)
Block(-7,23,-2,LEAVES:0)
Block(-5,23,-2,LEAVES:0)
Block(-4,23,-2,LEAVES:0)
Block(-3,23,-2,LEAVES:0)
Block(-2,23,-2,LOG:12)
Block(-1,23,-2,LEAVES:0)
Block(0,23,-2,LOG:8)
Block(1,23,-2,LEAVES:0)
Block(2,23,-2,LOG:12)
Block(3,23,-2,LEAVES:0)
Block(4,23,-2,LEAVES:0)
Block(5,23,-2,LEAVES:0)
Block(8,23,-2,LEAVES:0)
Block(13,23,-2,LEAVES:0)
Block(-13,23,-1,LEAVES:0)
Block(-9,23,-1,LEAVES:0)
Block(-8,23,-1,LEAVES:0)
Block(-7,23,-1,LEAVES:0)
Block(-6,23,-1,LEAVES:0)
Block(-1,23,-1,LOG:12)
Block(0,23,-1,LOG:8)
Block(1,23,-1,LOG:12)
Block(2,23,-1,LEAVES:0)
Block(3,23,-1,LEAVES:0)
Block(4,23,-1,LEAVES:0)
Block(8,23,-1,LEAVES:0)
Block(13,23,-1,LEAVES:0)
Block(14,23,-1,LEAVES:0)
Block(-14,23,0,LEAVES:0)
Block(-13,23,0,LEAVES:0)
Block(-12,23,0,LEAVES:0)
Block(-9,23,0,LEAVES:0)
Block(-8,23,0,LEAVES:0)
Block(-7,23,0,LEAVES:0)
Block(-6,23,0,LOG:4)
Block(-5,23,0,LOG:4)
Block(-4,23,0,LOG:4)
Block(-3,23,0,LOG:4)
Block(-2,23,0,LOG:4)
Block(-1,23,0,LOG:4)
Block(0,23,0,LOG:12)
Block(1,23,0,LOG:4)
Block(2,23,0,LOG:4)
Block(3,23,0,LOG:4)
Block(4,23,0,LOG:4)
Block(5,23,0,LOG:4)
Block(6,23,0,LOG:4)
Block(7,23,0,LEAVES:0)
Block(10,23,0,LEAVES:0)
Block(11,23,0,LEAVES:0)
Block(12,23,0,LEAVES:0)
Block(13,23,0,LEAVES:0)
Block(14,23,0,LEAVES:0)
Block(-8,23,1,LEAVES:0)
Block(-7,23,1,LEAVES:0)
Block(-6,23,1,LEAVES:0)
Block(-5,23,1,LEAVES:0)
Block(-3,23,1,LEAVES:0)
Block(-1,23,1,LOG:12)
Block(0,23,1,LOG:8)
Block(1,23,1,LOG:12)
Block(2,23,1,LEAVES:0)
Block(3,23,1,LEAVES:0)
Block(4,23,1,LEAVES:0)
Block(5,23,1,LEAVES:0)
Block(6,23,1,LEAVES:0)
Block(8,23,1,LEAVES:0)
Block(9,23,1,LEAVES:0)
Block(-10,23,2,LEAVES:0)
Block(-9,23,2,LEAVES:0)
Block(-8,23,2,LEAVES:0)
Block(-6,23,2,LEAVES:0)
Block(-5,23,2,LEAVES:0)
Block(-4,23,2,LEAVES:0)
Block(-3,23,2,LEAVES:0)
Block(-2,23,2,LOG:12)
Block(0,23,2,LOG:8)
Block(1,23,2,LEAVES:0)
Block(2,23,2,LOG:12)
Block(3,23,2,LEAVES:0)
Block(4,23,2,LEAVES:0)
Block(5,23,2,LEAVES:0)
Block(6,23,2,LEAVES:0)
Block(7,23,2,LEAVES:0)
Block(8,23,2,LEAVES:0)
Block(9,23,2,LEAVES:0)
Block(10,23,2,LEAVES:0)
Block(11,23,2,LEAVES:0)
Block(-11,23,3,LEAVES:0)
Block(-7,23,3,LEAVES:0)
Block(-6,23,3,LEAVES:0)
Block(-4,23,3,LEAVES:0)
Block(-3,23,3,LEAVES:0)
Block(-2,23,3,LEAVES:0)
Block(0,23,3,LOG:8)
Block(1,23,3,LEAVES:0)
Block(2,23,3,LEAVES:0)
Block(3,23,3,LEAVES:0)
Block(4,23,3,LEAVES:0)
Block(5,23,3,LEAVES:0)
Block(6,23,3,LEAVES:0)
Block(8,23,3,LEAVES:0)
Block(10,23,3,LEAVES:0)
Block(11,23,3,LEAVES:0)
Block(12,23,3,LEAVES:0)
Block(-11,23,4,LEAVES:0)
Block(-10,23,4,LEAVES:0)
Block(-9,23,4,LEAVES:0)
Block(-7,23,4,LEAVES:0)
Block(-6,23,4,LEAVES:0)
Block(-5,23,4,LEAVES:0)
Block(-4,23,4,LOG:8)
Block(-3,23,4,LEAVES:0)
Block(-2,23,4,LEAVES:0)
Block(-1,23,4,LEAVES:0)
Block(0,23,4,LOG:8)
Block(1,23,4,LEAVES:0)
Block(2,23,4,LEAVES:0)
Block(3,23,4,LEAVES:0)
Block(4,23,4,LOG:4)
Block(5,23,4,LEAVES:0)
Block(6,23,4,LEAVES:0)
Block(7,23,4,LEAVES:0)
Block(8,23,4,LEAVES:0)
Block(10,23,4,LEAVES:0)
Block(11,23,4,LEAVES:0)
Block(-10,23,5,LEAVES:0)
Block(-9,23,5,LEAVES:0)
Block(-6,23,5,LEAVES:0)
Block(-5,23,5,LOG:8)
Block(-4,23,5,LEAVES:0)
Block(-2,23,5,LEAVES:0)
Block(0,23,5,LOG:8)
Block(1,23,5,LEAVES:0)
Block(2,23,5,LEAVES:0)
Block(4,23,5,LEAVES:0)
Block(5,23,5,LOG:4)
Block(6,23,5,LEAVES:0)
Block(7,23,5,LEAVES:0)
Block(8,23,5,LEAVES:0)
Block(11,23,5,LEAVES:0)
Block(-12,23,6,LEAVES:0)
Block(-9,23,6,LEAVES:0)
Block(-8,23,6,LEAVES:0)
Block(-7,23,6,LEAVES:0)
Block(-6,23,6,LEAVES:0)
Block(-5,23,6,LEAVES:0)
Block(-4,23,6,LEAVES:0)
Block(-3,23,6,LEAVES:0)
Block(-1,23,6,LEAVES:0)
Block(0,23,6,LOG:8)
Block(1,23,6,LEAVES:0)
Block(2,23,6,LEAVES:0)
Block(3,23,6,LEAVES:0)
Block(4,23,6,LEAVES:0)
Block(5,23,6,LEAVES:0)
Block(6,23,6,LEAVES:0)
Block(7,23,6,LEAVES:0)
Block(8,23,6,LEAVES:0)
Block(9,23,6,LEAVES:0)
Block(11,23,6,LEAVES:0)
Block(12,23,6,LEAVES:0)
Block(-12,23,7,LEAVES:0)
Block(-11,23,7,LEAVES:0)
Block(-10,23,7,LEAVES:0)
Block(-9,23,7,LEAVES:0)
Block(-8,23,7,LEAVES:0)
Block(-7,23,7,LEAVES:0)
Block(-6,23,7,LEAVES:0)
Block(-5,23,7,LEAVES:0)
Block(-1,23,7,LEAVES:0)
Block(0,23,7,LEAVES:0)
Block(1,23,7,LEAVES:0)
Block(3,23,7,LEAVES:0)
Block(6,23,7,LEAVES:0)
Block(7,23,7,LEAVES:0)
Block(8,23,7,LEAVES:0)
Block(9,23,7,LEAVES:0)
Block(10,23,7,LEAVES:0)
Block(11,23,7,LEAVES:0)
Block(12,23,7,LEAVES:0)
Block(13,23,7,LEAVES:0)
Block(-11,23,8,LEAVES:0)
Block(-10,23,8,LEAVES:0)
Block(-8,23,8,LEAVES:0)
Block(-7,23,8,LEAVES:0)
Block(-6,23,8,LEAVES:0)
Block(-5,23,8,LEAVES:0)
Block(-4,23,8,LEAVES:0)
Block(-2,23,8,LEAVES:0)
Block(-1,23,8,LEAVES:0)
Block(0,23,8,LEAVES:0)
Block(1,23,8,LEAVES:0)
Block(3,23,8,LEAVES:0)
Block(5,23,8,LEAVES:0)
Block(8,23,8,LEAVES:0)
Block(9,23,8,LEAVES:0)
Block(10,23,8,LEAVES:0)
Block(12,23,8,LEAVES:0)
Block(-12,23,9,LEAVES:0)
Block(-11,23,9,LEAVES:0)
Block(-10,23,9,LEAVES:0)
Block(-9,23,9,LEAVES:0)
Block(-6,23,9,LEAVES:0)
Block(-2,23,9,LEAVES:0)
Block(-1,23,9,LEAVES:0)
Block(0,23,9,LEAVES:0)
Block(1,23,9,LEAVES:0)
Block(3,23,9,LEAVES:0)
Block(7,23,9,LEAVES:0)
Block(10,23,9,LEAVES:0)
Block(-11,23,10,LEAVES:0)
Block(-10,23,10,LEAVES:0)
Block(-9,23,10,LEAVES:0)
Block(-7,23,10,LEAVES:0)
Block(-5,23,10,LEAVES:0)
Block(-3,23,10,LEAVES:0)
Block(0,23,10,LEAVES:0)
Block(1,23,10,LEAVES:0)
Block(2,23,10,LEAVES:0)
Block(3,23,10,LEAVES:0)
Block(4,23,10,LEAVES:0)
Block(9,23,10,LEAVES:0)
Block(10,23,10,LEAVES:0)
Block(-10,23,11,LEAVES:0)
Block(-9,23,11,LEAVES:0)
Block(-8,23,11,LEAVES:0)
Block(-7,23,11,LEAVES:0)
Block(-4,23,11,LEAVES:0)
Block(-3,23,11,LEAVES:0)
Block(-2,23,11,LEAVES:0)
Block(-1,23,11,LEAVES:0)
Block(0,23,11,LEAVES:0)
Block(2,23,11,LEAVES:0)
Block(3,23,11,LEAVES:0)
Block(4,23,11,LEAVES:0)
Block(5,23,11,LEAVES:0)
Block(6,23,11,LEAVES:0)
Block(7,23,11,LEAVES:0)
Block(9,23,11,LEAVES:0)
Block(10,23,11,LEAVES:0)
Block(11,23,11,LEAVES:0)
Block(-7,23,12,LEAVES:0)
Block(-6,23,12,LEAVES:0)
Block(-4,23,12,LEAVES:9)
Block(-3,23,12,LEAVES:0)
Block(-1,23,12,LEAVES:0)
Block(0,23,12,LEAVES:0)
Block(2,23,12,LEAVES:0)
Block(4,23,12,LEAVES:0)
Block(5,23,12,LEAVES:0)
Block(6,23,12,LEAVES:0)
Block(7,23,12,LEAVES:0)
Block(8,23,12,LEAVES:0)
Block(-7,23,13,LEAVES:0)
Block(-5,23,13,LEAVES:0)
Block(-1,23,13,LEAVES:0)
Block(0,23,13,LEAVES:0)
Block(1,23,13,LEAVES:0)
Block(3,23,13,LEAVES:0)
Block(5,23,13,LEAVES:0)
Block(-1,24,-15,LEAVES:0)
Block(0,24,-15,LEAVES:0)
Block(-1,24,-14,LEAVES:0)
Block(0,24,-14,LEAVES:0)
Block(1,24,-14,LEAVES:0)
Block(3,24,-14,LEAVES:0)
Block(4,24,-14,LEAVES:0)
Block(-8,24,-13,LEAVES:0)
Block(-7,24,-13,LEAVES:0)
Block(-2,24,-13,LEAVES:0)
Block(-1,24,-13,LEAVES:0)
Block(0,24,-13,LEAVES:0)
Block(1,24,-13,LEAVES:0)
Block(2,24,-13,LEAVES:0)
Block(3,24,-13,LEAVES:0)
Block(7,24,-13,LEAVES:0)
Block(-11,24,-12,LEAVES:0)
Block(-9,24,-12,LEAVES:0)
Block(-8,24,-12,LEAVES:0)
Block(-7,24,-12,LEAVES:0)
Block(-6,24,-12,LEAVES:0)
Block(-5,24,-12,LEAVES:0)
Block(-4,24,-12,LEAVES:0)
Block(-2,24,-12,LEAVES:0)
Block(-1,24,-12,LEAVES:0)
Block(0,24,-12,LEAVES:0)
Block(1,24,-12,LEAVES:0)
Block(2,24,-12,LEAVES:0)
Block(3,24,-12,LEAVES:0)
Block(4,24,-12,LEAVES:0)
Block(5,24,-12,LEAVES:0)
Block(6,24,-12,LEAVES:0)
Block(8,24,-12,LEAVES:0)
Block(9,24,-12,LEAVES:0)
Block(10,24,-12,LEAVES:0)
Block(-7,24,-11,LEAVES:0)
Block(-6,24,-11,LEAVES:0)
Block(-4,24,-11,LEAVES:0)
Block(-3,24,-11,LEAVES:0)
Block(-2,24,-11,LEAVES:0)
Block(0,24,-11,LEAVES:0)
Block(2,24,-11,LEAVES:0)
Block(4,24,-11,LEAVES:0)
Block(5,24,-11,LEAVES:0)
Block(6,24,-11,LEAVES:0)
Block(7,24,-11,LEAVES:0)
Block(8,24,-11,LEAVES:0)
Block(9,24,-11,LEAVES:0)
Block(10,24,-11,LEAVES:0)
Block(11,24,-11,LEAVES:0)
Block(-12,24,-10,LEAVES:0)
Block(-11,24,-10,LEAVES:0)
Block(-10,24,-10,LEAVES:0)
Block(-9,24,-10,LEAVES:0)
Block(-8,24,-10,LEAVES:0)
Block(-7,24,-10,LEAVES:0)
Block(-6,24,-10,LEAVES:0)
Block(-5,24,-10,LEAVES:0)
Block(-4,24,-10,LEAVES:0)
Block(-3,24,-10,LEAVES:0)
Block(-1,24,-10,LEAVES:0)
Block(0,24,-10,LEAVES:0)
Block(1,24,-10,LEAVES:0)
Block(3,24,-10,LEAVES:0)
Block(4,24,-10,LEAVES:0)
Block(5,24,-10,LEAVES:0)
Block(6,24,-10,LEAVES:0)
Block(7,24,-10,LEAVES:0)
Block(8,24,-10,LEAVES:0)
Block(10,24,-10,LEAVES:0)
Block(-11,24,-9,LEAVES:0)
Block(-9,24,-9,LEAVES:0)
Block(-8,24,-9,LEAVES:0)
Block(-7,24,-9,LEAVES:0)
Block(-6,24,-9,LEAVES:0)
Block(-4,24,-9,LEAVES:0)
Block(-3,24,-9,LEAVES:0)
Block(-2,24,-9,LEAVES:0)
Block(-1,24,-9,LEAVES:0)
Block(0,24,-9,LOG:8)
Block(1,24,-9,LEAVES:0)
Block(2,24,-9,LEAVES:0)
Block(3,24,-9,LEAVES:0)
Block(4,24,-9,LEAVES:0)
Block(5,24,-9,LEAVES:0)
Block(6,24,-9,LEAVES:0)
Block(7,24,-9,LEAVES:0)
Block(8,24,-9,LEAVES:0)
Block(10,24,-9,LEAVES:0)
Block(11,24,-9,LEAVES:0)
Block(12,24,-9,LEAVES:0)
Block(-11,24,-8,LEAVES:0)
Block(-9,24,-8,LEAVES:0)
Block(-8,24,-8,LEAVES:0)
Block(-7,24,-8,LEAVES:0)
Block(-6,24,-8,LOG:4)
Block(-5,24,-8,LOG:4)
Block(-3,24,-8,LOG:4)
Block(-2,24,-8,LOG:4)
Block(-1,24,-8,LOG:4)
Block(0,24,-8,LOG:8)
Block(1,24,-8,LOG:4)
Block(2,24,-8,LOG:4)
Block(3,24,-8,LOG:4)
Block(4,24,-8,LEAVES:0)
Block(5,24,-8,LOG:4)
Block(6,24,-8,LOG:4)
Block(7,24,-8,LEAVES:0)
Block(8,24,-8,LEAVES:0)
Block(11,24,-8,LEAVES:0)
Block(-13,24,-7,LEAVES:0)
Block(-12,24,-7,LEAVES:0)
Block(-11,24,-7,LEAVES:0)
Block(-10,24,-7,LEAVES:0)
Block(-9,24,-7,LEAVES:0)
Block(-8,24,-7,LEAVES:0)
Block(-7,24,-7,LOG:4)
Block(-6,24,-7,LEAVES:0)
Block(-5,24,-7,LEAVES:0)
Block(-4,24,-7,LEAVES:0)
Block(-3,24,-7,LEAVES:0)
Block(-2,24,-7,LEAVES:0)
Block(-1,24,-7,LEAVES:0)
Block(0,24,-7,LOG:8)
Block(1,24,-7,LEAVES:0)
Block(2,24,-7,LEAVES:0)
Block(3,24,-7,LEAVES:0)
Block(4,24,-7,LEAVES:0)
Block(5,24,-7,LEAVES:0)
Block(6,24,-7,LEAVES:0)
Block(7,24,-7,LOG:8)
Block(8,24,-7,LEAVES:0)
Block(9,24,-7,LEAVES:0)
Block(10,24,-7,LEAVES:0)
Block(11,24,-7,LEAVES:0)
Block(12,24,-7,LEAVES:0)
Block(13,24,-7,LEAVES:0)
Block(-13,24,-6,LEAVES:0)
Block(-12,24,-6,LEAVES:0)
Block(-11,24,-6,LEAVES:0)
Block(-10,24,-6,LEAVES:0)
Block(-8,24,-6,LOG:8)
Block(-7,24,-6,LEAVES:0)
Block(-6,24,-6,LOG:4)
Block(-5,24,-6,LEAVES:0)
Block(-4,24,-6,LEAVES:0)
Block(-3,24,-6,LEAVES:0)
Block(3,24,-6,LEAVES:0)
Block(4,24,-6,LEAVES:0)
Block(5,24,-6,LEAVES:0)
Block(6,24,-6,LOG:8)
Block(7,24,-6,LEAVES:0)
Block(8,24,-6,LOG:8)
Block(9,24,-6,LEAVES:0)
Block(10,24,-6,LEAVES:0)
Block(11,24,-6,LEAVES:0)
Block(12,24,-6,LEAVES:0)
Block(13,24,-6,LEAVES:0)
Block(14,24,-6,LEAVES:0)
Block(-13,24,-5,LEAVES:0)
Block(-11,24,-5,LEAVES:0)
Block(-10,24,-5,LEAVES:0)
Block(-9,24,-5,LEAVES:0)
Block(-8,24,-5,LOG:8)
Block(-7,24,-5,LEAVES:0)
Block(-6,24,-5,LEAVES:0)
Block(-5,24,-5,LEAVES:0)
Block(-4,24,-5,LEAVES:0)
Block(-3,24,-5,LEAVES:0)
Block(-1,24,-5,LEAVES:0)
Block(2,24,-5,LEAVES:0)
Block(3,24,-5,LEAVES:0)
Block(4,24,-5,LEAVES:0)
Block(5,24,-5,LEAVES:0)
Block(6,24,-5,LEAVES:0)
Block(7,24,-5,LEAVES:0)
Block(8,24,-5,LOG:8)
Block(9,24,-5,LEAVES:0)
Block(10,24,-5,LEAVES:0)
Block(11,24,-5,LEAVES:0)
Block(12,24,-5,LEAVES:0)
Block(13,24,-5,LEAVES:0)
Block(-13,24,-4,LEAVES:0)
Block(-12,24,-4,LEAVES:0)
Block(-11,24,-4,LEAVES:0)
Block(-10,24,-4,LEAVES:0)
Block(-9,24,-4,LEAVES:0)
Block(-8,24,-4,LEAVES:0)
Block(-7,24,-4,LEAVES:0)
Block(-6,24,-4,LEAVES:0)
Block(-5,24,-4,LEAVES:0)
Block(-3,24,-4,LEAVES:0)
Block(-2,24,-4,LEAVES:0)
Block(-1,24,-4,LEAVES:0)
Block(0,24,-4,LEAVES:0)
Block(1,24,-4,LEAVES:0)
Block(2,24,-4,LEAVES:0)
Block(3,24,-4,LEAVES:0)
Block(4,24,-4,LEAVES:0)
Block(5,24,-4,LEAVES:0)
Block(6,24,-4,LEAVES:0)
Block(7,24,-4,LEAVES:0)
Block(8,24,-4,LEAVES:0)
Block(10,24,-4,LEAVES:0)
Block(11,24,-4,LEAVES:0)
Block(12,24,-4,LEAVES:0)
Block(13,24,-4,LEAVES:0)
Block(14,24,-4,LEAVES:0)
Block(-13,24,-3,LEAVES:0)
Block(-12,24,-3,LEAVES:0)
Block(-11,24,-3,LEAVES:0)
Block(-10,24,-3,LEAVES:0)
Block(-8,24,-3,LOG:8)
Block(-7,24,-3,LEAVES:0)
Block(-4,24,-3,LEAVES:0)
Block(-3,24,-3,LEAVES:0)
Block(-2,24,-3,LEAVES:0)
Block(-1,24,-3,LEAVES:0)
Block(0,24,-3,LEAVES:0)
Block(2,24,-3,LEAVES:0)
Block(3,24,-3,LEAVES:0)
Block(4,24,-3,LEAVES:0)
Block(6,24,-3,LEAVES:0)
Block(8,24,-3,LOG:8)
Block(11,24,-3,LEAVES:0)
Block(12,24,-3,LEAVES:0)
Block(14,24,-3,LEAVES:0)
Block(-10,24,-2,LEAVES:0)
Block(-9,24,-2,LEAVES:0)
Block(-8,24,-2,LOG:8)
Block(-7,24,-2,LEAVES:0)
Block(-6,24,-2,LEAVES:0)
Block(-5,24,-2,LEAVES:0)
Block(-4,24,-2,LEAVES:0)
Block(-3,24,-2,LEAVES:0)
Block(-2,24,-2,LOG:12)
Block(-1,24,-2,LEAVES:0)
Block(0,24,-2,LEAVES:0)
Block(1,24,-2,LEAVES:0)
Block(2,24,-2,LOG:12)
Block(3,24,-2,LEAVES:0)
Block(4,24,-2,LEAVES:0)
Block(5,24,-2,LEAVES:0)
Block(8,24,-2,LOG:8)
Block(9,24,-2,LEAVES:0)
Block(10,24,-2,LEAVES:0)
Block(11,24,-2,LEAVES:0)
Block(12,24,-2,LEAVES:0)
Block(13,24,-2,LEAVES:0)
Block(14,24,-2,LEAVES:0)
Block(15,24,-2,LEAVES:0)
Block(-10,24,-1,LEAVES:0)
Block(-9,24,-1,LEAVES:0)
Block(-8,24,-1,LOG:8)
Block(-7,24,-1,LEAVES:0)
Block(-6,24,-1,LEAVES:0)
Block(-5,24,-1,LEAVES:0)
Block(-4,24,-1,LEAVES:0)
Block(-3,24,-1,LEAVES:0)
Block(-2,24,-1,LEAVES:0)
Block(0,24,-1,LEAVES:0)
Block(1,24,-1,LEAVES:0)
Block(2,24,-1,LEAVES:0)
Block(3,24,-1,LEAVES:0)
Block(4,24,-1,LEAVES:0)
Block(5,24,-1,LEAVES:0)
Block(6,24,-1,LEAVES:0)
Block(8,24,-1,LOG:8)
Block(9,24,-1,LEAVES:0)
Block(10,24,-1,LEAVES:0)
Block(13,24,-1,LEAVES:0)
Block(14,24,-1,LEAVES:0)
Block(15,24,-1,LEAVES:0)
Block(-15,24,0,LEAVES:0)
Block(-14,24,0,LEAVES:0)
Block(-13,24,0,LEAVES:0)
Block(-12,24,0,LEAVES:0)
Block(-10,24,0,LEAVES:0)
Block(-9,24,0,LOG:4)
Block(-8,24,0,LOG:4)
Block(-7,24,0,LOG:4)
Block(-5,24,0,LEAVES:0)
Block(-4,24,0,LEAVES:0)
Block(-3,24,0,LEAVES:0)
Block(-2,24,0,LEAVES:0)
Block(-1,24,0,LEAVES:0)
Block(0,24,0,LOG:12)
Block(1,24,0,LEAVES:0)
Block(2,24,0,LEAVES:0)
Block(3,24,0,LEAVES:0)
Block(4,24,0,LEAVES:0)
Block(5,24,0,LEAVES:0)
Block(6,24,0,LEAVES:0)
Block(7,24,0,LOG:4)
Block(8,24,0,LOG:4)
Block(9,24,0,LOG:4)
Block(10,24,0,LEAVES:0)
Block(11,24,0,LEAVES:0)
Block(12,24,0,LEAVES:0)
Block(13,24,0,LEAVES:0)
Block(14,24,0,LEAVES:0)
Block(15,24,0,LEAVES:0)
Block(-14,24,1,LEAVES:0)
Block(-13,24,1,LEAVES:0)
Block(-12,24,1,LEAVES:0)
Block(-11,24,1,LEAVES:0)
Block(-10,24,1,LEAVES:0)
Block(-9,24,1,LEAVES:0)
Block(-8,24,1,LOG:8)
Block(-7,24,1,LEAVES:0)
Block(-6,24,1,LEAVES:0)
Block(-5,24,1,LEAVES:0)
Block(-4,24,1,LEAVES:0)
Block(-3,24,1,LEAVES:0)
Block(-2,24,1,LEAVES:0)
Block(-1,24,1,LEAVES:0)
Block(0,24,1,LEAVES:0)
Block(1,24,1,LEAVES:0)
Block(2,24,1,LEAVES:0)
Block(4,24,1,LEAVES:0)
Block(5,24,1,LEAVES:0)
Block(8,24,1,LOG:8)
Block(9,24,1,LEAVES:0)
Block(10,24,1,LEAVES:0)
Block(11,24,1,LEAVES:0)
Block(12,24,1,LEAVES:0)
Block(13,24,1,LEAVES:0)
Block(15,24,1,LEAVES:0)
Block(-14,24,2,LEAVES:0)
Block(-12,24,2,LEAVES:0)
Block(-11,24,2,LEAVES:0)
Block(-10,24,2,LEAVES:0)
Block(-9,24,2,LEAVES:0)
Block(-8,24,2,LOG:8)
Block(-7,24,2,LEAVES:0)
Block(-6,24,2,LEAVES:0)
Block(-5,24,2,LEAVES:0)
Block(-4,24,2,LEAVES:0)
Block(-3,24,2,LEAVES:0)
Block(-2,24,2,LOG:12)
Block(0,24,2,LEAVES:0)
Block(2,24,2,LOG:12)
Block(3,24,2,LEAVES:0)
Block(4,24,2,LEAVES:0)
Block(7,24,2,LEAVES:0)
Block(8,24,2,LOG:8)
Block(9,24,2,LEAVES:0)
Block(10,24,2,LEAVES:0)
Block(11,24,2,LEAVES:0)
Block(12,24,2,LEAVES:0)
Block(13,24,2,LEAVES:0)
Block(14,24,2,LEAVES:0)
Block(-12,24,3,LEAVES:0)
Block(-11,24,3,LEAVES:0)
Block(-10,24,3,LEAVES:0)
Block(-9,24,3,LEAVES:0)
Block(-8,24,3,LOG:8)
Block(-7,24,3,LEAVES:0)
Block(-6,24,3,LEAVES:0)
Block(-5,24,3,LEAVES:0)
Block(-4,24,3,LEAVES:0)
Block(-2,24,3,LEAVES:0)
Block(-1,24,3,LEAVES:0)
Block(0,24,3,LEAVES:0)
Block(6,24,3,LEAVES:0)
Block(7,24,3,LEAVES:0)
Block(8,24,3,LOG:8)
Block(9,24,3,LEAVES:0)
Block(10,24,3,LEAVES:0)
Block(12,24,3,LEAVES:0)
Block(13,24,3,LEAVES:0)
Block(-13,24,4,LEAVES:0)
Block(-12,24,4,LEAVES:0)
Block(-11,24,4,LEAVES:0)
Block(-10,24,4,LEAVES:0)
Block(-9,24,4,LEAVES:0)
Block(-8,24,4,LEAVES:0)
Block(-7,24,4,LEAVES:0)
Block(-6,24,4,LEAVES:0)
Block(-5,24,4,LEAVES:0)
Block(-4,24,4,LEAVES:0)
Block(-3,24,4,LEAVES:0)
Block(-2,24,4,LEAVES:0)
Block(-1,24,4,LEAVES:0)
Block(0,24,4,LEAVES:0)
Block(1,24,4,LEAVES:0)
Block(2,24,4,LEAVES:0)
Block(3,24,4,LEAVES:0)
Block(4,24,4,LEAVES:0)
Block(5,24,4,LEAVES:0)
Block(6,24,4,LEAVES:0)
Block(7,24,4,LEAVES:0)
Block(9,24,4,LEAVES:0)
Block(10,24,4,LEAVES:0)
Block(11,24,4,LEAVES:0)
Block(12,24,4,LEAVES:0)
Block(13,24,4,LEAVES:0)
Block(-12,24,5,LEAVES:0)
Block(-11,24,5,LEAVES:0)
Block(-10,24,5,LEAVES:0)
Block(-8,24,5,LOG:8)
Block(-7,24,5,LEAVES:0)
Block(-6,24,5,LEAVES:0)
Block(-5,24,5,LEAVES:0)
Block(-4,24,5,LEAVES:0)
Block(-3,24,5,LEAVES:0)
Block(-2,24,5,LEAVES:0)
Block(-1,24,5,LEAVES:0)
Block(0,24,5,LEAVES:0)
Block(2,24,5,LEAVES:0)
Block(4,24,5,LEAVES:0)
Block(5,24,5,LEAVES:0)
Block(6,24,5,LEAVES:0)
Block(7,24,5,LEAVES:0)
Block(8,24,5,LOG:8)
Block(9,24,5,LEAVES:0)
Block(11,24,5,LEAVES:0)
Block(12,24,5,LEAVES:0)
Block(-13,24,6,LEAVES:0)
Block(-12,24,6,LEAVES:0)
Block(-11,24,6,LEAVES:0)
Block(-10,24,6,LEAVES:0)
Block(-9,24,6,LEAVES:0)
Block(-8,24,6,LOG:8)
Block(-7,24,6,LEAVES:0)
Block(-6,24,6,LOG:8)
Block(-5,24,6,LEAVES:0)
Block(-4,24,6,LEAVES:0)
Block(-3,24,6,LEAVES:0)
Block(-2,24,6,LEAVES:0)
Block(-1,24,6,LEAVES:0)
Block(0,24,6,LEAVES:0)
Block(1,24,6,LEAVES:0)
Block(2,24,6,LEAVES:0)
Block(3,24,6,LEAVES:0)
Block(4,24,6,LEAVES:0)
Block(5,24,6,LEAVES:0)
Block(6,24,6,LOG:4)
Block(7,24,6,LEAVES:0)
Block(8,24,6,LOG:8)
Block(9,24,6,LEAVES:0)
Block(10,24,6,LEAVES:0)
Block(11,24,6,LEAVES:0)
Block(13,24,6,LEAVES:0)
Block(-12,24,7,LEAVES:0)
Block(-11,24,7,LEAVES:0)
Block(-10,24,7,LEAVES:0)
Block(-8,24,7,LEAVES:0)
Block(-7,24,7,LOG:8)
Block(-6,24,7,LEAVES:0)
Block(-5,24,7,LEAVES:0)
Block(-3,24,7,LEAVES:0)
Block(-2,24,7,LEAVES:0)
Block(-1,24,7,LEAVES:0)
Block(0,24,7,LOG:8)
Block(1,24,7,LEAVES:0)
Block(2,24,7,LEAVES:0)
Block(3,24,7,LEAVES:0)
Block(4,24,7,LEAVES:0)
Block(5,24,7,LEAVES:0)
Block(6,24,7,LEAVES:0)
Block(7,24,7,LOG:4)
Block(8,24,7,LEAVES:0)
Block(9,24,7,LEAVES:0)
Block(10,24,7,LEAVES:0)
Block(11,24,7,LEAVES:0)
Block(12,24,7,LEAVES:0)
Block(13,24,7,LEAVES:0)
Block(14,24,7,LEAVES:0)
Block(-13,24,8,LEAVES:0)
Block(-12,24,8,LEAVES:0)
Block(-11,24,8,LEAVES:0)
Block(-10,24,8,LEAVES:0)
Block(-9,24,8,LEAVES:0)
Block(-8,24,8,LEAVES:0)
Block(-7,24,8,LEAVES:0)
Block(-6,24,8,LOG:4)
Block(-5,24,8,LOG:4)
Block(-4,24,8,LEAVES:0)
Block(-3,24,8,LOG:4)
Block(-2,24,8,LOG:4)
Block(-1,24,8,LOG:4)
Block(0,24,8,LOG:8)
Block(1,24,8,LOG:4)
Block(2,24,8,LOG:4)
Block(3,24,8,LOG:4)
Block(4,24,8,LEAVES:0)
Block(5,24,8,LOG:4)
Block(6,24,8,LOG:4)
Block(8,24,8,LEAVES:0)
Block(9,24,8,LEAVES:0)
Block(10,24,8,LEAVES:0)
Block(-13,24,9,LEAVES:0)
Block(-12,24,9,LEAVES:0)
Block(-11,24,9,LEAVES:0)
Block(-10,24,9,LEAVES:0)
Block(-9,24,9,LEAVES:0)
Block(-8,24,9,LEAVES:0)
Block(-7,24,9,LEAVES:0)
Block(-6,24,9,LEAVES:0)
Block(-5,24,9,LEAVES:0)
Block(-4,24,9,LEAVES:0)
Block(-3,24,9,LEAVES:0)
Block(-2,24,9,LEAVES:0)
Block(-1,24,9,LEAVES:0)
Block(0,24,9,LOG:8)
Block(1,24,9,LEAVES:0)
Block(2,24,9,LEAVES:0)
Block(3,24,9,LEAVES:0)
Block(4,24,9,LEAVES:0)
Block(5,24,9,LEAVES:0)
Block(6,24,9,LEAVES:0)
Block(7,24,9,LEAVES:0)
Block(8,24,9,LEAVES:0)
Block(10,24,9,LEAVES:0)
Block(11,24,9,LEAVES:0)
Block(12,24,9,LEAVES:0)
Block(13,24,9,LEAVES:0)
Block(-12,24,10,LEAVES:0)
Block(-11,24,10,LEAVES:0)
Block(-10,24,10,LEAVES:0)
Block(-9,24,10,LEAVES:0)
Block(-8,24,10,LEAVES:0)
Block(-7,24,10,LEAVES:0)
Block(-6,24,10,LEAVES:0)
Block(-5,24,10,LEAVES:0)
Block(-4,24,10,LEAVES:0)
Block(-3,24,10,LEAVES:0)
Block(-2,24,10,LEAVES:0)
Block(-1,24,10,LEAVES:0)
Block(0,24,10,LEAVES:0)
Block(1,24,10,LEAVES:0)
Block(2,24,10,LEAVES:0)
Block(3,24,10,LEAVES:0)
Block(4,24,10,LEAVES:0)
Block(7,24,10,LEAVES:0)
Block(8,24,10,LEAVES:0)
Block(9,24,10,LEAVES:0)
Block(10,24,10,LEAVES:0)
Block(11,24,10,LEAVES:0)
Block(12,24,10,LEAVES:0)
Block(-11,24,11,LEAVES:0)
Block(-10,24,11,LEAVES:0)
Block(-8,24,11,LEAVES:9)
Block(-7,24,11,LEAVES:0)
Block(-6,24,11,LEAVES:0)
Block(-5,24,11,LEAVES:0)
Block(-4,24,11,LEAVES:0)
Block(-3,24,11,LEAVES:0)
Block(-2,24,11,LEAVES:0)
Block(-1,24,11,LEAVES:0)
Block(0,24,11,LEAVES:0)
Block(1,24,11,LEAVES:0)
Block(2,24,11,LEAVES:0)
Block(3,24,11,LEAVES:0)
Block(4,24,11,LEAVES:0)
Block(6,24,11,LEAVES:0)
Block(7,24,11,LEAVES:0)
Block(9,24,11,LEAVES:0)
Block(10,24,11,LEAVES:0)
Block(-7,24,12,LEAVES:0)
Block(-6,24,12,LEAVES:0)
Block(-4,24,12,LEAVES:0)
Block(-3,24,12,LEAVES:0)
Block(-2,24,12,LEAVES:0)
Block(-1,24,12,LEAVES:0)
Block(1,24,12,LEAVES:0)
Block(2,24,12,LEAVES:0)
Block(4,24,12,LEAVES:0)
Block(5,24,12,LEAVES:0)
Block(7,24,12,LEAVES:0)
Block(9,24,12,LEAVES:0)
Block(-6,24,13,LEAVES:0)
Block(-5,24,13,LEAVES:0)
Block(-4,24,13,LEAVES:0)
Block(-1,24,13,LEAVES:0)
Block(0,24,13,LEAVES:0)
Block(2,24,13,LEAVES:0)
Block(3,24,13,LEAVES:0)
Block(4,24,13,LEAVES:0)
Block(5,24,13,LEAVES:0)
Block(7,24,13,LEAVES:0)
Block(-7,24,14,LEAVES:0)
Block(0,24,14,LEAVES:0)
Block(2,24,14,LEAVES:0)
Block(3,24,14,LEAVES:0)
Block(4,24,14,LEAVES:0)
Block(0,24,15,LEAVES:0)
Block(-1,25,-15,LEAVES:0)
Block(0,25,-15,LEAVES:0)
Block(1,25,-15,LEAVES:0)
Block(-1,25,-14,LEAVES:0)
Block(0,25,-14,LEAVES:0)
Block(2,25,-14,LEAVES:0)
Block(3,25,-14,LEAVES:0)
Block(-6,25,-13,LEAVES:0)
Block(-5,25,-13,LEAVES:0)
Block(-4,25,-13,LEAVES:0)
Block(-2,25,-13,LEAVES:0)
Block(-1,25,-13,LEAVES:0)
Block(0,25,-13,LOG:8)
Block(1,25,-13,LEAVES:0)
Block(2,25,-13,LEAVES:0)
Block(3,25,-13,LEAVES:0)
Block(4,25,-13,LEAVES:0)
Block(5,25,-13,LEAVES:0)
Block(6,25,-13,LEAVES:0)
Block(7,25,-13,LEAVES:0)
Block(8,25,-13,LEAVES:0)
Block(10,25,-13,LEAVES:0)
Block(-11,25,-12,LEAVES:0)
Block(-10,25,-12,LEAVES:0)
Block(-9,25,-12,LEAVES:0)
Block(-8,25,-12,LEAVES:0)
Block(-7,25,-12,LEAVES:0)
Block(-6,25,-12,LEAVES:0)
Block(-5,25,-12,LEAVES:0)
Block(-4,25,-12,LEAVES:0)
Block(-3,25,-12,LEAVES:0)
Block(-2,25,-12,LEAVES:0)
Block(-1,25,-12,LEAVES:0)
Block(0,25,-12,LOG:8)
Block(1,25,-12,LEAVES:0)
Block(3,25,-12,LEAVES:0)
Block(4,25,-12,LEAVES:0)
Block(5,25,-12,LEAVES:0)
Block(6,25,-12,LEAVES:0)
Block(7,25,-12,LEAVES:0)
Block(8,25,-12,LEAVES:0)
Block(9,25,-12,LEAVES:0)
Block(10,25,-12,LEAVES:0)
Block(11,25,-12,LEAVES:0)
Block(-10,25,-11,LOG:8)
Block(-9,25,-11,LEAVES:0)
Block(-8,25,-11,LEAVES:0)
Block(-7,25,-11,LOG:4)
Block(-6,25,-11,LEAVES:0)
Block(-5,25,-11,LEAVES:0)
Block(-4,25,-11,LOG:4)
Block(-3,25,-11,LOG:4)
Block(-2,25,-11,LOG:4)
Block(-1,25,-11,LOG:4)
Block(0,25,-11,LOG:8)
Block(1,25,-11,LOG:4)
Block(2,25,-11,LOG:4)
Block(3,25,-11,LOG:4)
Block(4,25,-11,LOG:4)
Block(5,25,-11,LEAVES:0)
Block(6,25,-11,LEAVES:0)
Block(7,25,-11,LOG:8)
Block(8,25,-11,LEAVES:0)
Block(9,25,-11,LEAVES:0)
Block(10,25,-11,LOG:8)
Block(11,25,-11,LEAVES:0)
Block(-12,25,-10,LEAVES:0)
Block(-11,25,-10,LOG:4)
Block(-10,25,-10,LOG:4)
Block(-9,25,-10,LEAVES:0)
Block(-8,25,-10,LOG:4)
Block(-7,25,-10,LEAVES:0)
Block(-6,25,-10,LEAVES:0)
Block(-5,25,-10,LEAVES:0)
Block(-4,25,-10,LEAVES:0)
Block(-3,25,-10,LEAVES:0)
Block(-2,25,-10,LEAVES:0)
Block(-1,25,-10,LEAVES:0)
Block(0,25,-10,LOG:8)
Block(1,25,-10,LEAVES:0)
Block(3,25,-10,LEAVES:0)
Block(4,25,-10,LEAVES:0)
Block(5,25,-10,LEAVES:0)
Block(6,25,-10,LEAVES:0)
Block(8,25,-10,LOG:8)
Block(9,25,-10,LEAVES:0)
Block(10,25,-10,LOG:8)
Block(11,25,-10,LOG:4)
Block(12,25,-10,LEAVES:0)
Block(-12,25,-9,LEAVES:0)
Block(-11,25,-9,LEAVES:0)
Block(-10,25,-9,LEAVES:0)
Block(-9,25,-9,LOG:4)
Block(-8,25,-9,LEAVES:0)
Block(-7,25,-9,LEAVES:0)
Block(-6,25,-9,LEAVES:0)
Block(-5,25,-9,LEAVES:0)
Block(-4,25,-9,LEAVES:0)
Block(-3,25,-9,LEAVES:0)
Block(-2,25,-9,LEAVES:0)
Block(-1,25,-9,LEAVES:0)
Block(0,25,-9,LEAVES:0)
Block(1,25,-9,LEAVES:0)
Block(2,25,-9,LEAVES:0)
Block(3,25,-9,LEAVES:0)
Block(4,25,-9,LEAVES:0)
Block(5,25,-9,LEAVES:0)
Block(6,25,-9,LEAVES:0)
Block(7,25,-9,LEAVES:0)
Block(8,25,-9,LEAVES:0)
Block(9,25,-9,LOG:8)
Block(10,25,-9,LEAVES:0)
Block(11,25,-9,LEAVES:0)
Block(12,25,-9,LEAVES:0)
Block(-12,25,-8,LEAVES:0)
Block(-11,25,-8,LEAVES:0)
Block(-10,25,-8,LOG:4)
Block(-9,25,-8,LEAVES:0)
Block(-8,25,-8,LOG:4)
Block(-7,25,-8,LEAVES:0)
Block(-6,25,-8,LEAVES:0)
Block(-5,25,-8,LEAVES:0)
Block(-4,25,-8,LEAVES:0)
Block(-3,25,-8,LEAVES:0)
Block(-2,25,-8,LEAVES:0)
Block(-1,25,-8,LEAVES:0)
Block(0,25,-8,LEAVES:0)
Block(1,25,-8,LEAVES:0)
Block(2,25,-8,LEAVES:0)
Block(3,25,-8,LEAVES:0)
Block(4,25,-8,LEAVES:0)
Block(5,25,-8,LEAVES:0)
Block(6,25,-8,LEAVES:0)
Block(8,25,-8,LOG:8)
Block(9,25,-8,LEAVES:0)
Block(10,25,-8,LOG:8)
Block(11,25,-8,LEAVES:0)
Block(13,25,-8,LEAVES:0)
Block(-13,25,-7,LEAVES:0)
Block(-12,25,-7,LEAVES:0)
Block(-11,25,-7,LOG:4)
Block(-10,25,-7,LEAVES:0)
Block(-9,25,-7,LEAVES:0)
Block(-8,25,-7,LEAVES:0)
Block(-7,25,-7,LEAVES:0)
Block(-6,25,-7,LEAVES:0)
Block(-5,25,-7,LEAVES:0)
Block(-4,25,-7,LEAVES:0)
Block(-3,25,-7,LEAVES:0)
Block(-2,25,-7,LEAVES:0)
Block(-1,25,-7,LEAVES:0)
Block(0,25,-7,LEAVES:0)
Block(1,25,-7,LEAVES:0)
Block(2,25,-7,LEAVES:0)
Block(3,25,-7,LEAVES:0)
Block(5,25,-7,LEAVES:0)
Block(6,25,-7,LEAVES:0)
Block(7,25,-7,LEAVES:0)
Block(8,25,-7,LEAVES:0)
Block(9,25,-7,LEAVES:0)
Block(10,25,-7,LEAVES:0)
Block(11,25,-7,LOG:8)
Block(12,25,-7,LEAVES:0)
Block(13,25,-7,LEAVES:0)
Block(-12,25,-6,LEAVES:0)
Block(-11,25,-6,LEAVES:0)
Block(-9,25,-6,LEAVES:0)
Block(-8,25,-6,LEAVES:0)
Block(-7,25,-6,LEAVES:0)
Block(-6,25,-6,LEAVES:0)
Block(-4,25,-6,LEAVES:0)
Block(-3,25,-6,LEAVES:0)
Block(-2,25,-6,LEAVES:0)
Block(-1,25,-6,LEAVES:0)
Block(2,25,-6,LEAVES:0)
Block(3,25,-6,LEAVES:0)
Block(4,25,-6,LEAVES:0)
Block(6,25,-6,LEAVES:0)
Block(7,25,-6,LEAVES:0)
Block(8,25,-6,LEAVES:0)
Block(9,25,-6,LEAVES:0)
Block(10,25,-6,LEAVES:0)
Block(11,25,-6,LEAVES:0)
Block(12,25,-6,LEAVES:0)
Block(13,25,-6,LEAVES:0)
Block(-13,25,-5,LEAVES:0)
Block(-12,25,-5,LEAVES:0)
Block(-11,25,-5,LEAVES:0)
Block(-10,25,-5,LEAVES:0)
Block(-9,25,-5,LEAVES:0)
Block(-8,25,-5,LEAVES:0)
Block(-7,25,-5,LEAVES:0)
Block(-6,25,-5,LEAVES:0)
Block(-5,25,-5,LEAVES:0)
Block(-4,25,-5,LEAVES:0)
Block(-3,25,-5,LEAVES:0)
Block(-2,25,-5,LEAVES:0)
Block(-1,25,-5,LEAVES:0)
Block(0,25,-5,LEAVES:0)
Block(1,25,-5,LEAVES:0)
Block(2,25,-5,LEAVES:0)
Block(4,25,-5,LEAVES:0)
Block(6,25,-5,LEAVES:0)
Block(7,25,-5,LEAVES:0)
Block(9,25,-5,LEAVES:0)
Block(10,25,-5,LEAVES:0)
Block(11,25,-5,LEAVES:0)
Block(12,25,-5,LEAVES:0)
Block(13,25,-5,LEAVES:0)
Block(14,25,-5,LEAVES:0)
Block(-13,25,-4,LEAVES:0)
Block(-12,25,-4,LEAVES:0)
Block(-11,25,-4,LOG:8)
Block(-10,25,-4,LEAVES:0)
Block(-9,25,-4,LEAVES:0)
Block(-8,25,-4,LEAVES:0)
Block(-7,25,-4,LEAVES:0)
Block(-6,25,-4,LEAVES:0)
Block(-5,25,-4,LEAVES:0)
Block(-4,25,-4,LEAVES:0)
Block(-3,25,-4,LEAVES:0)
Block(-2,25,-4,LEAVES:0)
Block(-1,25,-4,LEAVES:0)
Block(0,25,-4,LEAVES:0)
Block(1,25,-4,LEAVES:0)
Block(2,25,-4,LEAVES:0)
Block(3,25,-4,LEAVES:0)
Block(4,25,-4,LEAVES:0)
Block(5,25,-4,LEAVES:0)
Block(6,25,-4,LEAVES:0)
Block(7,25,-4,LEAVES:0)
Block(8,25,-4,LEAVES:0)
Block(9,25,-4,LEAVES:0)
Block(10,25,-4,LEAVES:0)
Block(11,25,-4,LOG:8)
Block(12,25,-4,LEAVES:0)
Block(13,25,-4,LEAVES:0)
Block(-13,25,-3,LEAVES:0)
Block(-12,25,-3,LEAVES:0)
Block(-11,25,-3,LOG:8)
Block(-10,25,-3,LEAVES:0)
Block(-9,25,-3,LEAVES:0)
Block(-8,25,-3,LEAVES:0)
Block(-6,25,-3,LEAVES:0)
Block(-5,25,-3,LEAVES:0)
Block(-4,25,-3,LEAVES:0)
Block(-3,25,-3,LEAVES:0)
Block(-2,25,-3,LEAVES:0)
Block(-1,25,-3,LEAVES:0)
Block(0,25,-3,LEAVES:0)
Block(1,25,-3,LEAVES:0)
Block(2,25,-3,LEAVES:0)
Block(3,25,-3,LEAVES:0)
Block(4,25,-3,LEAVES:0)
Block(5,25,-3,LEAVES:0)
Block(6,25,-3,LEAVES:0)
Block(7,25,-3,LEAVES:0)
Block(8,25,-3,LEAVES:0)
Block(9,25,-3,LEAVES:0)
Block(11,25,-3,LOG:8)
Block(12,25,-3,LEAVES:0)
Block(13,25,-3,LEAVES:0)
Block(-13,25,-2,LEAVES:0)
Block(-12,25,-2,LEAVES:0)
Block(-11,25,-2,LOG:8)
Block(-10,25,-2,LEAVES:0)
Block(-9,25,-2,LEAVES:0)
Block(-8,25,-2,LEAVES:0)
Block(-5,25,-2,LEAVES:0)
Block(-4,25,-2,LEAVES:0)
Block(-3,25,-2,LEAVES:0)
Block(-2,25,-2,LOG:12)
Block(-1,25,-2,LEAVES:0)
Block(0,25,-2,LEAVES:0)
Block(1,25,-2,LEAVES:0)
Block(2,25,-2,LOG:12)
Block(3,25,-2,LEAVES:0)
Block(4,25,-2,LEAVES:0)
Block(5,25,-2,LEAVES:0)
Block(6,25,-2,LEAVES:0)
Block(8,25,-2,LEAVES:0)
Block(9,25,-2,LEAVES:0)
Block(10,25,-2,LEAVES:0)
Block(11,25,-2,LOG:8)
Block(12,25,-2,LEAVES:0)
Block(13,25,-2,LEAVES:0)
Block(14,25,-2,LEAVES:0)
Block(-14,25,-1,LEAVES:0)
Block(-13,25,-1,LEAVES:0)
Block(-12,25,-1,LEAVES:0)
Block(-11,25,-1,LOG:8)
Block(-10,25,-1,LEAVES:0)
Block(-8,25,-1,LEAVES:0)
Block(-7,25,-1,LEAVES:0)
Block(-6,25,-1,LEAVES:0)
Block(-5,25,-1,LEAVES:0)
Block(-3,25,-1,LEAVES:0)
Block(-2,25,-1,LEAVES:0)
Block(-1,25,-1,LEAVES:0)
Block(0,25,-1,LEAVES:0)
Block(1,25,-1,LEAVES:0)
Block(2,25,-1,LEAVES:0)
Block(3,25,-1,LEAVES:0)
Block(4,25,-1,LEAVES:0)
Block(6,25,-1,LEAVES:0)
Block(7,25,-1,LEAVES:0)
Block(8,25,-1,LEAVES:0)
Block(9,25,-1,LEAVES:0)
Block(10,25,-1,LEAVES:0)
Block(11,25,-1,LOG:8)
Block(12,25,-1,LEAVES:0)
Block(13,25,-1,LEAVES:0)
Block(14,25,-1,LEAVES:0)
Block(15,25,-1,LEAVES:0)
Block(-15,25,0,LEAVES:0)
Block(-13,25,0,LOG:4)
Block(-12,25,0,LOG:4)
Block(-11,25,0,LOG:4)
Block(-10,25,0,LOG:4)
Block(-9,25,0,LEAVES:0)
Block(-8,25,0,LEAVES:0)
Block(-6,25,0,LEAVES:0)
Block(-5,25,0,LEAVES:0)
Block(-4,25,0,LEAVES:0)
Block(-3,25,0,LEAVES:0)
Block(-2,25,0,LEAVES:0)
Block(-1,25,0,LEAVES:0)
Block(0,25,0,LOG:12)
Block(1,25,0,LEAVES:0)
Block(2,25,0,LEAVES:0)
Block(3,25,0,LEAVES:0)
Block(4,25,0,LEAVES:0)
Block(5,25,0,LEAVES:0)
Block(6,25,0,LEAVES:0)
Block(7,25,0,LEAVES:0)
Block(8,25,0,LEAVES:0)
Block(9,25,0,LEAVES:0)
Block(10,25,0,LOG:4)
Block(11,25,0,LOG:4)
Block(12,25,0,LOG:4)
Block(13,25,0,LOG:4)
Block(14,25,0,LEAVES:0)
Block(15,25,0,LEAVES:0)
Block(-14,25,1,LEAVES:0)
Block(-13,25,1,LEAVES:0)
Block(-11,25,1,LOG:8)
Block(-10,25,1,LEAVES:0)
Block(-9,25,1,LEAVES:0)
Block(-8,25,1,LEAVES:0)
Block(-7,25,1,LEAVES:0)
Block(-6,25,1,LEAVES:0)
Block(-5,25,1,LEAVES:0)
Block(-4,25,1,LEAVES:0)
Block(-3,25,1,LEAVES:0)
Block(-2,25,1,LEAVES:0)
Block(-1,25,1,LEAVES:0)
Block(1,25,1,LEAVES:0)
Block(2,25,1,LEAVES:0)
Block(3,25,1,LEAVES:0)
Block(4,25,1,LEAVES:0)
Block(7,25,1,LEAVES:0)
Block(8,25,1,LEAVES:0)
Block(9,25,1,LEAVES:0)
Block(10,25,1,LEAVES:0)
Block(11,25,1,LOG:8)
Block(12,25,1,LEAVES:0)
Block(13,25,1,LEAVES:0)
Block(14,25,1,LEAVES:0)
Block(-13,25,2,LEAVES:0)
Block(-12,25,2,LEAVES:0)
Block(-11,25,2,LOG:8)
Block(-10,25,2,LEAVES:0)
Block(-9,25,2,LEAVES:0)
Block(-8,25,2,LEAVES:0)
Block(-7,25,2,LEAVES:0)
Block(-6,25,2,LEAVES:0)
Block(-5,25,2,LEAVES:0)
Block(-4,25,2,LEAVES:0)
Block(-3,25,2,LEAVES:0)
Block(-2,25,2,LOG:12)
Block(-1,25,2,LEAVES:0)
Block(0,25,2,LEAVES:0)
Block(1,25,2,LEAVES:0)
Block(2,25,2,LOG:12)
Block(3,25,2,LEAVES:0)
Block(4,25,2,LEAVES:0)
Block(6,25,2,LEAVES:0)
Block(8,25,2,LEAVES:0)
Block(10,25,2,LEAVES:0)
Block(11,25,2,LOG:8)
Block(12,25,2,LEAVES:0)
Block(13,25,2,LEAVES:0)
Block(14,25,2,LEAVES:0)
Block(-13,25,3,LEAVES:0)
Block(-11,25,3,LOG:8)
Block(-10,25,3,LEAVES:0)
Block(-9,25,3,LEAVES:0)
Block(-8,25,3,LEAVES:0)
Block(-7,25,3,LEAVES:0)
Block(-6,25,3,LEAVES:0)
Block(-4,25,3,LEAVES:0)
Block(-3,25,3,LEAVES:0)
Block(-2,25,3,LEAVES:0)
Block(-1,25,3,LEAVES:0)
Block(0,25,3,LEAVES:0)
Block(1,25,3,LEAVES:0)
Block(2,25,3,LEAVES:0)
Block(3,25,3,LEAVES:0)
Block(4,25,3,LEAVES:0)
Block(6,25,3,LEAVES:0)
Block(7,25,3,LEAVES:0)
Block(8,25,3,LEAVES:0)
Block(9,25,3,LEAVES:0)
Block(10,25,3,LEAVES:0)
Block(11,25,3,LOG:8)
Block(12,25,3,LEAVES:0)
Block(13,25,3,LEAVES:0)
Block(-13,25,4,LEAVES:0)
Block(-12,25,4,LEAVES:0)
Block(-11,25,4,LOG:8)
Block(-10,25,4,LEAVES:0)
Block(-9,25,4,LEAVES:0)
Block(-8,25,4,LEAVES:0)
Block(-7,25,4,LEAVES:0)
Block(-6,25,4,LEAVES:0)
Block(-5,25,4,LEAVES:0)
Block(-4,25,4,LEAVES:0)
Block(-3,25,4,LEAVES:0)
Block(-2,25,4,LEAVES:0)
Block(-1,25,4,LEAVES:0)
Block(2,25,4,LEAVES:0)
Block(3,25,4,LEAVES:0)
Block(4,25,4,LEAVES:0)
Block(5,25,4,LEAVES:0)
Block(6,25,4,LEAVES:0)
Block(8,25,4,LEAVES:0)
Block(9,25,4,LEAVES:0)
Block(10,25,4,LEAVES:0)
Block(11,25,4,LOG:8)
Block(12,25,4,LEAVES:0)
Block(13,25,4,LEAVES:0)
Block(-12,25,5,LEAVES:0)
Block(-11,25,5,LEAVES:0)
Block(-10,25,5,LEAVES:0)
Block(-9,25,5,LEAVES:0)
Block(-8,25,5,LEAVES:0)
Block(-7,25,5,LEAVES:0)
Block(-6,25,5,LEAVES:0)
Block(-5,25,5,LEAVES:0)
Block(-4,25,5,LEAVES:0)
Block(-3,25,5,LEAVES:0)
Block(-2,25,5,LEAVES:0)
Block(-1,25,5,LEAVES:0)
Block(0,25,5,LEAVES:0)
Block(3,25,5,LEAVES:0)
Block(4,25,5,LEAVES:0)
Block(5,25,5,LEAVES:0)
Block(6,25,5,LEAVES:0)
Block(7,25,5,LEAVES:0)
Block(8,25,5,LEAVES:0)
Block(10,25,5,LEAVES:0)
Block(11,25,5,LEAVES:0)
Block(12,25,5,LEAVES:0)
Block(13,25,5,LEAVES:0)
Block(-11,25,6,LEAVES:0)
Block(-10,25,6,LEAVES:0)
Block(-9,25,6,LEAVES:0)
Block(-8,25,6,LEAVES:0)
Block(-7,25,6,LEAVES:0)
Block(-6,25,6,LEAVES:0)
Block(-5,25,6,LEAVES:0)
Block(-4,25,6,LEAVES:0)
Block(-2,25,6,LEAVES:0)
Block(-1,25,6,LEAVES:0)
Block(0,25,6,LEAVES:0)
Block(1,25,6,LEAVES:0)
Block(2,25,6,LEAVES:0)
Block(3,25,6,LEAVES:0)
Block(5,25,6,LEAVES:0)
Block(6,25,6,LEAVES:0)
Block(7,25,6,LEAVES:0)
Block(8,25,6,LEAVES:0)
Block(9,25,6,LEAVES:0)
Block(10,25,6,LEAVES:0)
Block(11,25,6,LEAVES:0)
Block(12,25,6,LEAVES:0)
Block(13,25,6,LEAVES:0)
Block(14,25,6,LEAVES:0)
Block(-13,25,7,LEAVES:0)
Block(-12,25,7,LEAVES:0)
Block(-11,25,7,LOG:8)
Block(-10,25,7,LEAVES:0)
Block(-9,25,7,LEAVES:0)
Block(-8,25,7,LEAVES:0)
Block(-7,25,7,LEAVES:0)
Block(-6,25,7,LEAVES:0)
Block(-5,25,7,LEAVES:0)
Block(-4,25,7,LEAVES:0)
Block(-3,25,7,LEAVES:0)
Block(-2,25,7,LEAVES:0)
Block(-1,25,7,LEAVES:0)
Block(0,25,7,LEAVES:0)
Block(1,25,7,LEAVES:0)
Block(2,25,7,LEAVES:0)
Block(4,25,7,LEAVES:0)
Block(5,25,7,LEAVES:0)
Block(6,25,7,LEAVES:0)
Block(7,25,7,LEAVES:0)
Block(8,25,7,LEAVES:0)
Block(9,25,7,LEAVES:0)
Block(10,25,7,LEAVES:0)
Block(11,25,7,LOG:4)
Block(12,25,7,LEAVES:0)
Block(13,25,7,LEAVES:0)
Block(-13,25,8,LEAVES:0)
Block(-12,25,8,LEAVES:0)
Block(-11,25,8,LEAVES:0)
Block(-10,25,8,LOG:8)
Block(-9,25,8,LEAVES:0)
Block(-8,25,8,LOG:8)
Block(-7,25,8,LEAVES:0)
Block(-6,25,8,LEAVES:0)
Block(-5,25,8,LEAVES:0)
Block(-4,25,8,LEAVES:0)
Block(-3,25,8,LEAVES:0)
Block(-2,25,8,LEAVES:0)
Block(-1,25,8,LEAVES:0)
Block(0,25,8,LEAVES:0)
Block(1,25,8,LEAVES:0)
Block(2,25,8,LEAVES:0)
Block(3,25,8,LEAVES:0)
Block(4,25,8,LEAVES:0)
Block(5,25,8,LEAVES:0)
Block(6,25,8,LEAVES:0)
Block(8,25,8,LOG:4)
Block(9,25,8,LEAVES:0)
Block(10,25,8,LOG:4)
Block(11,25,8,LEAVES:0)
Block(12,25,8,LEAVES:0)
Block(-13,25,9,LEAVES:0)
Block(-12,25,9,LEAVES:0)
Block(-11,25,9,LEAVES:0)
Block(-10,25,9,LEAVES:0)
Block(-9,25,9,LOG:8)
Block(-8,25,9,LEAVES:0)
Block(-7,25,9,LEAVES:0)
Block(-5,25,9,LEAVES:0)
Block(-4,25,9,LEAVES:0)
Block(-3,25,9,LEAVES:0)
Block(-2,25,9,LEAVES:0)
Block(-1,25,9,LEAVES:0)
Block(0,25,9,LEAVES:0)
Block(1,25,9,LEAVES:0)
Block(2,25,9,LEAVES:0)
Block(3,25,9,LEAVES:0)
Block(4,25,9,LEAVES:0)
Block(6,25,9,LEAVES:0)
Block(7,25,9,LEAVES:0)
Block(8,25,9,LEAVES:0)
Block(9,25,9,LOG:4)
Block(10,25,9,LEAVES:0)
Block(11,25,9,LEAVES:0)
Block(12,25,9,LEAVES:0)
Block(13,25,9,LEAVES:0)
Block(-13,25,10,LEAVES:0)
Block(-12,25,10,LEAVES:0)
Block(-11,25,10,LOG:4)
Block(-10,25,10,LOG:8)
Block(-9,25,10,LEAVES:0)
Block(-8,25,10,LOG:8)
Block(-7,25,10,LEAVES:0)
Block(-6,25,10,LEAVES:0)
Block(-5,25,10,LEAVES:0)
Block(-4,25,10,LEAVES:0)
Block(-3,25,10,LEAVES:0)
Block(-2,25,10,LEAVES:0)
Block(-1,25,10,LEAVES:0)
Block(0,25,10,LOG:8)
Block(1,25,10,LEAVES:0)
Block(2,25,10,LEAVES:0)
Block(3,25,10,LEAVES:0)
Block(4,25,10,LEAVES:0)
Block(5,25,10,LEAVES:0)
Block(6,25,10,LEAVES:0)
Block(7,25,10,LEAVES:0)
Block(8,25,10,LOG:4)
Block(9,25,10,LEAVES:0)
Block(10,25,10,LOG:4)
Block(11,25,10,LOG:4)
Block(12,25,10,LEAVES:0)
Block(-12,25,11,LEAVES:0)
Block(-11,25,11,LEAVES:0)
Block(-10,25,11,LOG:8)
Block(-8,25,11,LEAVES:0)
Block(-7,25,11,LOG:8)
Block(-6,25,11,LEAVES:0)
Block(-5,25,11,LEAVES:0)
Block(-4,25,11,LOG:4)
Block(-3,25,11,LOG:4)
Block(-2,25,11,LOG:4)
Block(-1,25,11,LOG:4)
Block(0,25,11,LOG:8)
Block(1,25,11,LOG:4)
Block(2,25,11,LOG:4)
Block(3,25,11,LOG:4)
Block(4,25,11,LOG:4)
Block(5,25,11,LEAVES:0)
Block(6,25,11,LEAVES:0)
Block(7,25,11,LOG:4)
Block(8,25,11,LEAVES:0)
Block(9,25,11,LEAVES:0)
Block(10,25,11,LOG:8)
Block(11,25,11,LEAVES:0)
Block(12,25,11,LEAVES:0)
Block(-11,25,12,LEAVES:0)
Block(-10,25,12,LEAVES:0)
Block(-8,25,12,LEAVES:0)
Block(-7,25,12,LEAVES:0)
Block(-6,25,12,LEAVES:0)
Block(-5,25,12,LEAVES:0)
Block(-4,25,12,LEAVES:0)
Block(-3,25,12,LEAVES:0)
Block(-2,25,12,LEAVES:0)
Block(-1,25,12,LEAVES:0)
Block(0,25,12,LOG:8)
Block(1,25,12,LEAVES:0)
Block(2,25,12,LEAVES:0)
Block(3,25,12,LEAVES:0)
Block(4,25,12,LEAVES:0)
Block(5,25,12,LEAVES:0)
Block(6,25,12,LEAVES:0)
Block(7,25,12,LEAVES:0)
Block(9,25,12,LEAVES:0)
Block(10,25,12,LEAVES:0)
Block(11,25,12,LEAVES:0)
Block(-8,25,13,LEAVES:0)
Block(-7,25,13,LEAVES:0)
Block(-6,25,13,LEAVES:0)
Block(-5,25,13,LEAVES:0)
Block(-4,25,13,LEAVES:0)
Block(-2,25,13,LEAVES:0)
Block(-1,25,13,LEAVES:0)
Block(0,25,13,LOG:8)
Block(1,25,13,LEAVES:0)
Block(2,25,13,LEAVES:0)
Block(3,25,13,LEAVES:0)
Block(4,25,13,LEAVES:0)
Block(5,25,13,LEAVES:0)
Block(6,25,13,LEAVES:0)
Block(7,25,13,LEAVES:0)
Block(8,25,13,LEAVES:0)
Block(-6,25,14,LEAVES:0)
Block(-5,25,14,LEAVES:0)
Block(-2,25,14,LEAVES:0)
Block(-1,25,14,LEAVES:0)
Block(1,25,14,LEAVES:0)
Block(2,25,14,LEAVES:0)
Block(3,25,14,LEAVES:0)
Block(4,25,14,LEAVES:0)
Block(-1,25,15,LEAVES:0)
Block(0,25,15,LEAVES:0)
Block(-1,26,-15,LEAVES:0)
Block(0,26,-15,LEAVES:0)
Block(-2,26,-14,LEAVES:0)
Block(-1,26,-14,LEAVES:0)
Block(-4,26,-13,LEAVES:0)
Block(-2,26,-13,LEAVES:0)
Block(-1,26,-13,LEAVES:0)
Block(0,26,-13,LEAVES:0)
Block(1,26,-13,LEAVES:0)
Block(2,26,-13,LEAVES:0)
Block(4,26,-13,LEAVES:0)
Block(5,26,-13,LEAVES:0)
Block(8,26,-13,LEAVES:0)
Block(9,26,-13,LEAVES:0)
Block(-11,26,-12,LEAVES:0)
Block(-9,26,-12,LEAVES:0)
Block(-8,26,-12,LEAVES:0)
Block(-7,26,-12,LEAVES:0)
Block(-4,26,-12,LEAVES:0)
Block(-3,26,-12,LEAVES:0)
Block(-2,26,-12,LEAVES:0)
Block(-1,26,-12,LEAVES:0)
Block(1,26,-12,LEAVES:0)
Block(4,26,-12,LEAVES:0)
Block(5,26,-12,LEAVES:0)
Block(6,26,-12,LEAVES:0)
Block(7,26,-12,LEAVES:0)
Block(8,26,-12,LEAVES:0)
Block(9,26,-12,LEAVES:0)
Block(10,26,-12,LEAVES:0)
Block(-12,26,-11,LEAVES:0)
Block(-11,26,-11,LEAVES:0)
Block(-10,26,-11,LEAVES:0)
Block(-9,26,-11,LEAVES:0)
Block(-7,26,-11,LEAVES:0)
Block(-5,26,-11,LEAVES:0)
Block(-4,26,-11,LEAVES:0)
Block(-3,26,-11,LEAVES:0)
Block(-1,26,-11,LEAVES:0)
Block(0,26,-11,LEAVES:0)
Block(1,26,-11,LEAVES:0)
Block(2,26,-11,LEAVES:0)
Block(3,26,-11,LEAVES:0)
Block(4,26,-11,LEAVES:0)
Block(5,26,-11,LEAVES:0)
Block(6,26,-11,LEAVES:0)
Block(7,26,-11,LEAVES:0)
Block(9,26,-11,LEAVES:0)
Block(10,26,-11,LEAVES:0)
Block(12,26,-11,LEAVES:0)
Block(-11,26,-10,LEAVES:0)
Block(-10,26,-10,LEAVES:0)
Block(-9,26,-10,LEAVES:0)
Block(-8,26,-10,LEAVES:0)
Block(-7,26,-10,LEAVES:0)
Block(-6,26,-10,LEAVES:0)
Block(-4,26,-10,LEAVES:0)
Block(-3,26,-10,LEAVES:0)
Block(-1,26,-10,LEAVES:0)
Block(0,26,-10,LEAVES:0)
Block(1,26,-10,LEAVES:0)
Block(2,26,-10,LEAVES:0)
Block(3,26,-10,LEAVES:0)
Block(4,26,-10,LEAVES:0)
Block(6,26,-10,LEAVES:0)
Block(7,26,-10,LEAVES:0)
Block(8,26,-10,LEAVES:0)
Block(9,26,-10,LEAVES:0)
Block(10,26,-10,LEAVES:0)
Block(11,26,-10,LEAVES:0)
Block(-12,26,-9,LEAVES:0)
Block(-11,26,-9,LEAVES:0)
Block(-10,26,-9,LEAVES:0)
Block(-9,26,-9,LEAVES:0)
Block(-7,26,-9,LEAVES:0)
Block(-6,26,-9,LEAVES:0)
Block(-5,26,-9,LEAVES:0)
Block(-4,26,-9,LEAVES:0)
Block(-3,26,-9,LEAVES:0)
Block(-2,26,-9,LEAVES:0)
Block(-1,26,-9,LEAVES:0)
Block(0,26,-9,LEAVES:0)
Block(2,26,-9,LEAVES:0)
Block(4,26,-9,LEAVES:0)
Block(5,26,-9,LEAVES:0)
Block(6,26,-9,LEAVES:0)
Block(7,26,-9,LEAVES:0)
Block(8,26,-9,LEAVES:0)
Block(10,26,-9,LEAVES:0)
Block(11,26,-9,LEAVES:0)
Block(12,26,-9,LEAVES:0)
Block(-12,26,-8,LEAVES:0)
Block(-10,26,-8,LEAVES:0)
Block(-9,26,-8,LEAVES:0)
Block(-8,26,-8,LEAVES:0)
Block(-7,26,-8,LEAVES:0)
Block(-6,26,-8,LEAVES:0)
Block(-5,26,-8,LEAVES:0)
Block(-4,26,-8,LEAVES:0)
Block(-3,26,-8,LEAVES:0)
Block(-2,26,-8,LOG:8)
Block(0,26,-8,LEAVES:0)
Block(1,26,-8,LEAVES:0)
Block(2,26,-8,LOG:8)
Block(3,26,-8,LEAVES:0)
Block(4,26,-8,LEAVES:0)
Block(6,26,-8,LEAVES:0)
Block(8,26,-8,LEAVES:0)
Block(9,26,-8,LEAVES:0)
Block(10,26,-8,LEAVES:0)
Block(11,26,-8,LEAVES:0)
Block(12,26,-8,LEAVES:0)
Block(13,26,-8,LEAVES:0)
Block(-13,26,-7,LEAVES:0)
Block(-12,26,-7,LEAVES:0)
Block(-11,26,-7,LEAVES:0)
Block(-10,26,-7,LEAVES:0)
Block(-9,26,-7,LEAVES:0)
Block(-8,26,-7,LEAVES:0)
Block(-6,26,-7,LEAVES:0)
Block(-5,26,-7,LEAVES:0)
Block(-4,26,-7,LEAVES:0)
Block(-3,26,-7,LEAVES:0)
Block(-2,26,-7,LOG:8)
Block(-1,26,-7,LEAVES:0)
Block(0,26,-7,LEAVES:0)
Block(1,26,-7,LEAVES:0)
Block(2,26,-7,LOG:8)
Block(4,26,-7,LEAVES:0)
Block(5,26,-7,LEAVES:0)
Block(6,26,-7,LEAVES:0)
Block(7,26,-7,LEAVES:0)
Block(8,26,-7,LEAVES:0)
Block(9,26,-7,LEAVES:0)
Block(10,26,-7,LEAVES:0)
Block(11,26,-7,LEAVES:0)
Block(12,26,-7,LEAVES:0)
Block(13,26,-7,LEAVES:0)
Block(-13,26,-6,LEAVES:0)
Block(-12,26,-6,LEAVES:0)
Block(-11,26,-6,LEAVES:0)
Block(-10,26,-6,LEAVES:0)
Block(-7,26,-6,LEAVES:0)
Block(-6,26,-6,LEAVES:0)
Block(-5,26,-6,LEAVES:0)
Block(-4,26,-6,LOG:4)
Block(-3,26,-6,LOG:4)
Block(-2,26,-6,LOG:8)
Block(-1,26,-6,LEAVES:0)
Block(2,26,-6,LOG:8)
Block(3,26,-6,LOG:4)
Block(4,26,-6,LOG:4)
Block(5,26,-6,LEAVES:0)
Block(6,26,-6,LEAVES:0)
Block(7,26,-6,LEAVES:0)
Block(8,26,-6,LEAVES:0)
Block(9,26,-6,LEAVES:0)
Block(10,26,-6,LEAVES:0)
Block(11,26,-6,LEAVES:0)
Block(12,26,-6,LEAVES:0)
Block(13,26,-6,LEAVES:0)
Block(-13,26,-5,LEAVES:0)
Block(-12,26,-5,LEAVES:0)
Block(-11,26,-5,LEAVES:0)
Block(-10,26,-5,LEAVES:0)
Block(-8,26,-5,LEAVES:0)
Block(-7,26,-5,LEAVES:0)
Block(-6,26,-5,LEAVES:0)
Block(-5,26,-5,LEAVES:0)
Block(-4,26,-5,LEAVES:0)
Block(-2,26,-5,LOG:8)
Block(-1,26,-5,LEAVES:0)
Block(0,26,-5,LEAVES:0)
Block(2,26,-5,LOG:8)
Block(3,26,-5,LEAVES:0)
Block(4,26,-5,LEAVES:0)
Block(5,26,-5,LEAVES:0)
Block(6,26,-5,LEAVES:0)
Block(7,26,-5,LEAVES:0)
Block(8,26,-5,LEAVES:0)
Block(9,26,-5,LEAVES:0)
Block(10,26,-5,LEAVES:0)
Block(11,26,-5,LEAVES:0)
Block(14,26,-5,LEAVES:0)
Block(-13,26,-4,LEAVES:0)
Block(-12,26,-4,LEAVES:0)
Block(-11,26,-4,LEAVES:0)
Block(-10,26,-4,LEAVES:0)
Block(-9,26,-4,LEAVES:0)
Block(-8,26,-4,LEAVES:0)
Block(-7,26,-4,LEAVES:0)
Block(-6,26,-4,LOG:8)
Block(-5,26,-4,LEAVES:0)
Block(-4,26,-4,LEAVES:0)
Block(-3,26,-4,LEAVES:0)
Block(-2,26,-4,LOG:8)
Block(-1,26,-4,LEAVES:0)
Block(0,26,-4,LEAVES:0)
Block(1,26,-4,LEAVES:0)
Block(2,26,-4,LOG:8)
Block(4,26,-4,LEAVES:0)
Block(5,26,-4,LEAVES:0)
Block(6,26,-4,LOG:8)
Block(8,26,-4,LEAVES:0)
Block(9,26,-4,LEAVES:0)
Block(10,26,-4,LEAVES:0)
Block(11,26,-4,LEAVES:0)
Block(12,26,-4,LEAVES:0)
Block(13,26,-4,LEAVES:0)
Block(-12,26,-3,LEAVES:0)
Block(-11,26,-3,LEAVES:0)
Block(-10,26,-3,LEAVES:0)
Block(-9,26,-3,LEAVES:0)
Block(-8,26,-3,LEAVES:0)
Block(-7,26,-3,LEAVES:0)
Block(-6,26,-3,LOG:8)
Block(-5,26,-3,LEAVES:0)
Block(-4,26,-3,LEAVES:0)
Block(-3,26,-3,LEAVES:0)
Block(-2,26,-3,LOG:8)
Block(0,26,-3,LEAVES:0)
Block(1,26,-3,LEAVES:0)
Block(2,26,-3,LOG:8)
Block(4,26,-3,LEAVES:0)
Block(6,26,-3,LOG:8)
Block(9,26,-3,LEAVES:0)
Block(10,26,-3,LEAVES:0)
Block(11,26,-3,LEAVES:0)
Block(12,26,-3,LEAVES:0)
Block(-13,26,-2,LEAVES:0)
Block(-12,26,-2,LEAVES:0)
Block(-11,26,-2,LEAVES:0)
Block(-10,26,-2,LEAVES:0)
Block(-8,26,-2,LOG:4)
Block(-7,26,-2,LOG:4)
Block(-6,26,-2,LOG:4)
Block(-5,26,-2,LOG:4)
Block(-4,26,-2,LOG:4)
Block(-3,26,-2,LOG:4)
Block(-2,26,-2,LEAVES:0)
Block(-1,26,-2,LEAVES:0)
Block(0,26,-2,LEAVES:0)
Block(1,26,-2,LEAVES:0)
Block(2,26,-2,LEAVES:0)
Block(3,26,-2,LOG:4)
Block(4,26,-2,LOG:4)
Block(5,26,-2,LOG:4)
Block(6,26,-2,LOG:4)
Block(7,26,-2,LOG:4)
Block(8,26,-2,LOG:4)
Block(9,26,-2,LEAVES:0)
Block(10,26,-2,LEAVES:0)
Block(11,26,-2,LEAVES:0)
Block(12,26,-2,LEAVES:0)
Block(13,26,-2,LEAVES:0)
Block(14,26,-2,LEAVES:0)
Block(15,26,-2,LEAVES:0)
Block(-15,26,-1,LEAVES:0)
Block(-14,26,-1,LEAVES:0)
Block(-13,26,-1,LEAVES:0)
Block(-11,26,-1,LEAVES:0)
Block(-10,26,-1,LEAVES:0)
Block(-9,26,-1,LEAVES:0)
Block(-8,26,-1,LEAVES:0)
Block(-4,26,-1,LEAVES:0)
Block(-3,26,-1,LEAVES:0)
Block(-2,26,-1,LEAVES:0)
Block(0,26,-1,LEAVES:0)
Block(1,26,-1,LEAVES:0)
Block(2,26,-1,LEAVES:0)
Block(3,26,-1,LEAVES:0)
Block(4,26,-1,LEAVES:0)
Block(5,26,-1,LEAVES:0)
Block(6,26,-1,LEAVES:0)
Block(7,26,-1,LEAVES:0)
Block(8,26,-1,LEAVES:0)
Block(9,26,-1,LEAVES:0)
Block(10,26,-1,LEAVES:0)
Block(11,26,-1,LEAVES:0)
Block(12,26,-1,LEAVES:0)
Block(13,26,-1,LEAVES:0)
Block(-11,26,0,LEAVES:0)
Block(-10,26,0,LEAVES:0)
Block(-9,26,0,LEAVES:0)
Block(-8,26,0,LEAVES:0)
Block(-7,26,0,LEAVES:0)
Block(-5,26,0,LEAVES:0)
Block(-4,26,0,LEAVES:0)
Block(-3,26,0,LEAVES:0)
Block(-2,26,0,LEAVES:0)
Block(-1,26,0,LEAVES:0)
Block(0,26,0,LOG:12)
Block(1,26,0,LEAVES:0)
Block(2,26,0,LEAVES:0)
Block(3,26,0,LEAVES:0)
Block(4,26,0,LEAVES:0)
Block(7,26,0,LEAVES:0)
Block(8,26,0,LEAVES:0)
Block(9,26,0,LEAVES:0)
Block(10,26,0,LEAVES:0)
Block(11,26,0,LEAVES:0)
Block(12,26,0,LEAVES:0)
Block(13,26,0,LEAVES:0)
Block(-13,26,1,LEAVES:0)
Block(-12,26,1,LEAVES:0)
Block(-11,26,1,LEAVES:0)
Block(-10,26,1,LEAVES:0)
Block(-9,26,1,LEAVES:0)
Block(-8,26,1,LEAVES:0)
Block(-7,26,1,LEAVES:0)
Block(-6,26,1,LEAVES:0)
Block(-5,26,1,LEAVES:0)
Block(-3,26,1,LEAVES:0)
Block(-2,26,1,LEAVES:0)
Block(-1,26,1,LEAVES:0)
Block(1,26,1,LEAVES:0)
Block(3,26,1,LEAVES:0)
Block(4,26,1,LEAVES:0)
Block(5,26,1,LEAVES:0)
Block(7,26,1,LEAVES:0)
Block(8,26,1,LEAVES:0)
Block(9,26,1,LEAVES:0)
Block(10,26,1,LEAVES:0)
Block(11,26,1,LEAVES:0)
Block(13,26,1,LEAVES:0)
Block(14,26,1,LEAVES:0)
Block(-14,26,2,LEAVES:0)
Block(-13,26,2,LEAVES:0)
Block(-12,26,2,LEAVES:0)
Block(-11,26,2,LEAVES:0)
Block(-10,26,2,LEAVES:0)
Block(-9,26,2,LEAVES:0)
Block(-8,26,2,LOG:4)
Block(-7,26,2,LOG:4)
Block(-6,26,2,LOG:4)
Block(-5,26,2,LOG:4)
Block(-4,26,2,LOG:4)
Block(-3,26,2,LOG:4)
Block(-2,26,2,LEAVES:0)
Block(-1,26,2,LEAVES:0)
Block(0,26,2,LEAVES:0)
Block(1,26,2,LEAVES:0)
Block(2,26,2,LEAVES:0)
Block(3,26,2,LOG:4)
Block(4,26,2,LOG:4)
Block(5,26,2,LOG:4)
Block(6,26,2,LOG:4)
Block(7,26,2,LOG:4)
Block(8,26,2,LOG:4)
Block(9,26,2,LEAVES:0)
Block(10,26,2,LEAVES:0)
Block(11,26,2,LEAVES:0)
Block(12,26,2,LEAVES:0)
Block(-13,26,3,LEAVES:0)
Block(-11,26,3,LEAVES:0)
Block(-10,26,3,LEAVES:0)
Block(-9,26,3,LEAVES:0)
Block(-8,26,3,LEAVES:0)
Block(-7,26,3,LEAVES:0)
Block(-6,26,3,LOG:8)
Block(-4,26,3,LEAVES:0)
Block(-3,26,3,LEAVES:0)
Block(-2,26,3,LOG:8)
Block(0,26,3,LEAVES:0)
Block(1,26,3,LEAVES:0)
Block(2,26,3,LOG:8)
Block(3,26,3,LEAVES:0)
Block(4,26,3,LEAVES:0)
Block(5,26,3,LEAVES:0)
Block(6,26,3,LOG:8)
Block(7,26,3,LEAVES:0)
Block(8,26,3,LEAVES:0)
Block(9,26,3,LEAVES:0)
Block(10,26,3,LEAVES:0)
Block(11,26,3,LEAVES:0)
Block(12,26,3,LEAVES:0)
Block(13,26,3,LEAVES:0)
Block(-11,26,4,LEAVES:0)
Block(-10,26,4,LEAVES:0)
Block(-9,26,4,LEAVES:0)
Block(-8,26,4,LEAVES:0)
Block(-7,26,4,LEAVES:0)
Block(-6,26,4,LOG:8)
Block(-5,26,4,LEAVES:0)
Block(-4,26,4,LEAVES:0)
Block(-3,26,4,LEAVES:0)
Block(-2,26,4,LOG:8)
Block(-1,26,4,LEAVES:0)
Block(0,26,4,LEAVES:0)
Block(2,26,4,LOG:8)
Block(4,26,4,LEAVES:0)
Block(5,26,4,LEAVES:0)
Block(6,26,4,LOG:8)
Block(7,26,4,LEAVES:0)
Block(9,26,4,LEAVES:0)
Block(10,26,4,LEAVES:0)
Block(11,26,4,LEAVES:0)
Block(12,26,4,LEAVES:0)
Block(13,26,4,LEAVES:0)
Block(-13,26,5,LEAVES:0)
Block(-12,26,5,LEAVES:9)
Block(-10,26,5,LEAVES:0)
Block(-9,26,5,LEAVES:0)
Block(-8,26,5,LEAVES:0)
Block(-7,26,5,LEAVES:0)
Block(-6,26,5,LEAVES:0)
Block(-5,26,5,LEAVES:0)
Block(-4,26,5,LEAVES:0)
Block(-2,26,5,LOG:8)
Block(2,26,5,LOG:8)
Block(4,26,5,LEAVES:0)
Block(5,26,5,LEAVES:0)
Block(6,26,5,LEAVES:0)
Block(7,26,5,LEAVES:0)
Block(8,26,5,LEAVES:0)
Block(9,26,5,LEAVES:0)
Block(10,26,5,LEAVES:0)
Block(11,26,5,LEAVES:0)
Block(12,26,5,LEAVES:0)
Block(-13,26,6,LEAVES:0)
Block(-12,26,6,LEAVES:0)
Block(-11,26,6,LEAVES:0)
Block(-9,26,6,LEAVES:0)
Block(-7,26,6,LEAVES:0)
Block(-6,26,6,LEAVES:0)
Block(-5,26,6,LEAVES:0)
Block(-4,26,6,LOG:4)
Block(-3,26,6,LOG:4)
Block(-2,26,6,LOG:8)
Block(-1,26,6,LEAVES:0)
Block(2,26,6,LOG:8)
Block(3,26,6,LOG:4)
Block(4,26,6,LOG:4)
Block(5,26,6,LEAVES:0)
Block(6,26,6,LEAVES:0)
Block(7,26,6,LEAVES:0)
Block(8,26,6,LEAVES:0)
Block(9,26,6,LEAVES:0)
Block(10,26,6,LEAVES:0)
Block(11,26,6,LEAVES:0)
Block(12,26,6,LEAVES:0)
Block(-13,26,7,LEAVES:0)
Block(-12,26,7,LEAVES:0)
Block(-11,26,7,LEAVES:0)
Block(-10,26,7,LEAVES:0)
Block(-9,26,7,LEAVES:0)
Block(-7,26,7,LEAVES:0)
Block(-6,26,7,LEAVES:0)
Block(-5,26,7,LEAVES:0)
Block(-4,26,7,LEAVES:0)
Block(-3,26,7,LEAVES:0)
Block(-2,26,7,LOG:8)
Block(-1,26,7,LEAVES:0)
Block(0,26,7,LEAVES:0)
Block(1,26,7,LEAVES:0)
Block(2,26,7,LOG:8)
Block(3,26,7,LEAVES:0)
Block(4,26,7,LEAVES:0)
Block(5,26,7,LEAVES:0)
Block(6,26,7,LEAVES:0)
Block(7,26,7,LEAVES:0)
Block(8,26,7,LEAVES:0)
Block(9,26,7,LEAVES:0)
Block(10,26,7,LEAVES:0)
Block(11,26,7,LEAVES:0)
Block(12,26,7,LEAVES:0)
Block(13,26,7,LEAVES:0)
Block(14,26,7,LEAVES:0)
Block(-13,26,8,LEAVES:0)
Block(-12,26,8,LEAVES:0)
Block(-10,26,8,LEAVES:0)
Block(-8,26,8,LEAVES:0)
Block(-6,26,8,LEAVES:0)
Block(-5,26,8,LEAVES:0)
Block(-4,26,8,LEAVES:0)
Block(-3,26,8,LEAVES:0)
Block(-2,26,8,LOG:8)
Block(-1,26,8,LEAVES:0)
Block(0,26,8,LEAVES:0)
Block(1,26,8,LEAVES:0)
Block(2,26,8,LOG:8)
Block(4,26,8,LEAVES:0)
Block(5,26,8,LEAVES:0)
Block(6,26,8,LEAVES:0)
Block(7,26,8,LEAVES:0)
Block(8,26,8,LEAVES:0)
Block(9,26,8,LEAVES:0)
Block(10,26,8,LEAVES:0)
Block(11,26,8,LEAVES:0)
Block(12,26,8,LEAVES:0)
Block(13,26,8,LEAVES:0)
Block(-13,26,9,LEAVES:0)
Block(-12,26,9,LEAVES:0)
Block(-11,26,9,LEAVES:0)
Block(-10,26,9,LEAVES:0)
Block(-8,26,9,LEAVES:0)
Block(-7,26,9,LEAVES:0)
Block(-5,26,9,LEAVES:0)
Block(-4,26,9,LEAVES:0)
Block(-3,26,9,LEAVES:0)
Block(-2,26,9,LEAVES:0)
Block(0,26,9,LEAVES:0)
Block(2,26,9,LEAVES:0)
Block(3,26,9,LEAVES:0)
Block(4,26,9,LEAVES:0)
Block(7,26,9,LEAVES:0)
Block(8,26,9,LEAVES:0)
Block(10,26,9,LEAVES:0)
Block(11,26,9,LEAVES:0)
Block(-11,26,10,LEAVES:0)
Block(-10,26,10,LEAVES:0)
Block(-8,26,10,LEAVES:0)
Block(-7,26,10,LEAVES:0)
Block(-6,26,10,LEAVES:0)
Block(-4,26,10,LEAVES:0)
Block(-3,26,10,LEAVES:0)
Block(-2,26,10,LEAVES:0)
Block(-1,26,10,LEAVES:0)
Block(1,26,10,LEAVES:0)
Block(2,26,10,LEAVES:0)
Block(3,26,10,LEAVES:0)
Block(4,26,10,LEAVES:0)
Block(5,26,10,LEAVES:0)
Block(6,26,10,LEAVES:0)
Block(7,26,10,LEAVES:0)
Block(8,26,10,LEAVES:0)
Block(9,26,10,LEAVES:0)
Block(10,26,10,LEAVES:0)
Block(11,26,10,LEAVES:0)
Block(12,26,10,LEAVES:0)
Block(-11,26,11,LEAVES:0)
Block(-9,26,11,LEAVES:0)
Block(-8,26,11,LEAVES:0)
Block(-7,26,11,LEAVES:0)
Block(-6,26,11,LEAVES:0)
Block(-5,26,11,LEAVES:0)
Block(-4,26,11,LEAVES:0)
Block(-3,26,11,LEAVES:0)
Block(-2,26,11,LEAVES:0)
Block(-1,26,11,LEAVES:0)
Block(0,26,11,LEAVES:0)
Block(1,26,11,LEAVES:0)
Block(2,26,11,LEAVES:0)
Block(4,26,11,LEAVES:0)
Block(5,26,11,LEAVES:0)
Block(6,26,11,LEAVES:0)
Block(7,26,11,LEAVES:0)
Block(-10,26,12,LEAVES:0)
Block(-9,26,12,LEAVES:0)
Block(-7,26,12,LEAVES:0)
Block(-6,26,12,LEAVES:0)
Block(-5,26,12,LEAVES:0)
Block(-4,26,12,LEAVES:0)
Block(-3,26,12,LEAVES:0)
Block(-2,26,12,LEAVES:0)
Block(-1,26,12,LEAVES:0)
Block(1,26,12,LEAVES:0)
Block(2,26,12,LEAVES:0)
Block(3,26,12,LEAVES:0)
Block(4,26,12,LEAVES:0)
Block(5,26,12,LEAVES:0)
Block(6,26,12,LEAVES:0)
Block(7,26,12,LEAVES:0)
Block(9,26,12,LEAVES:0)
Block(-8,26,13,LEAVES:0)
Block(-5,26,13,LEAVES:0)
Block(-4,26,13,LEAVES:0)
Block(-1,26,13,LEAVES:0)
Block(0,26,13,LEAVES:0)
Block(2,26,13,LEAVES:0)
Block(3,26,13,LEAVES:0)
Block(4,26,13,LEAVES:0)
Block(8,26,13,LEAVES:0)
Block(-7,26,14,LEAVES:0)
Block(-6,26,14,LEAVES:0)
Block(-5,26,14,LEAVES:0)
Block(-1,26,14,LEAVES:0)
Block(0,26,14,LEAVES:0)
Block(4,26,14,LEAVES:0)
Block(-1,26,15,LEAVES:0)
Block(0,26,15,LEAVES:0)
Block(1,26,15,LEAVES:0)
Block(0,27,-14,LEAVES:0)
Block(1,27,-14,LEAVES:0)
Block(-1,27,-13,LEAVES:0)
Block(0,27,-13,LEAVES:0)
Block(1,27,-13,LEAVES:0)
Block(3,27,-13,LEAVES:0)
Block(4,27,-13,LEAVES:0)
Block(-5,27,-12,LEAVES:0)
Block(-4,27,-12,LEAVES:0)
Block(-1,27,-12,LEAVES:0)
Block(0,27,-12,LEAVES:0)
Block(1,27,-12,LEAVES:0)
Block(2,27,-12,LEAVES:0)
Block(3,27,-12,LEAVES:0)
Block(4,27,-12,LEAVES:0)
Block(6,27,-12,LEAVES:0)
Block(9,27,-12,LEAVES:0)
Block(-11,27,-11,LEAVES:0)
Block(-10,27,-11,LEAVES:0)
Block(-6,27,-11,LEAVES:0)
Block(-5,27,-11,LEAVES:0)
Block(-3,27,-11,LEAVES:0)
Block(-1,27,-11,LEAVES:0)
Block(0,27,-11,LEAVES:0)
Block(3,27,-11,LEAVES:0)
Block(4,27,-11,LEAVES:0)
Block(5,27,-11,LEAVES:0)
Block(7,27,-11,LEAVES:0)
Block(8,27,-11,LEAVES:0)
Block(9,27,-11,LEAVES:0)
Block(10,27,-11,LEAVES:0)
Block(11,27,-11,LEAVES:0)
Block(-11,27,-10,LEAVES:0)
Block(-10,27,-10,LEAVES:0)
Block(-9,27,-10,LEAVES:0)
Block(-7,27,-10,LEAVES:0)
Block(-5,27,-10,LEAVES:0)
Block(-2,27,-10,LEAVES:0)
Block(-1,27,-10,LEAVES:0)
Block(0,27,-10,LEAVES:0)
Block(2,27,-10,LEAVES:0)
Block(3,27,-10,LEAVES:0)
Block(4,27,-10,LEAVES:0)
Block(8,27,-10,LEAVES:0)
Block(9,27,-10,LEAVES:0)
Block(10,27,-10,LEAVES:0)
Block(-8,27,-9,LEAVES:0)
Block(-7,27,-9,LEAVES:0)
Block(-6,27,-9,LEAVES:0)
Block(1,27,-9,LEAVES:0)
Block(2,27,-9,LEAVES:0)
Block(3,27,-9,LEAVES:0)
Block(4,27,-9,LEAVES:0)
Block(8,27,-9,LEAVES:0)
Block(10,27,-9,LEAVES:0)
Block(-9,27,-8,LEAVES:0)
Block(-8,27,-8,LEAVES:0)
Block(-7,27,-8,LEAVES:0)
Block(-6,27,-8,LEAVES:0)
Block(-3,27,-8,LEAVES:0)
Block(-2,27,-8,LEAVES:0)
Block(-1,27,-8,LEAVES:0)
Block(0,27,-8,LEAVES:0)
Block(1,27,-8,LEAVES:0)
Block(4,27,-8,LEAVES:0)
Block(5,27,-8,LEAVES:0)
Block(8,27,-8,LEAVES:0)
Block(9,27,-8,LEAVES:0)
Block(11,27,-8,LEAVES:0)
Block(-12,27,-7,LEAVES:0)
Block(-9,27,-7,LEAVES:0)
Block(-7,27,-7,LEAVES:0)
Block(-5,27,-7,LEAVES:0)
Block(-3,27,-7,LEAVES:0)
Block(0,27,-7,LEAVES:0)
Block(2,27,-7,LEAVES:0)
Block(6,27,-7,LEAVES:0)
Block(8,27,-7,LEAVES:0)
Block(10,27,-7,LEAVES:0)
Block(12,27,-7,LEAVES:0)
Block(-12,27,-6,LEAVES:0)
Block(-11,27,-6,LEAVES:0)
Block(-6,27,-6,LEAVES:0)
Block(-4,27,-6,LEAVES:0)
Block(-3,27,-6,LEAVES:0)
Block(-2,27,-6,LEAVES:0)
Block(-1,27,-6,LEAVES:0)
Block(3,27,-6,LEAVES:0)
Block(4,27,-6,LEAVES:0)
Block(5,27,-6,LEAVES:0)
Block(7,27,-6,LEAVES:0)
Block(11,27,-6,LEAVES:0)
Block(12,27,-6,LEAVES:0)
Block(-12,27,-5,LEAVES:0)
Block(-11,27,-5,LEAVES:0)
Block(-4,27,-5,LEAVES:0)
Block(-2,27,-5,LEAVES:0)
Block(0,27,-5,LEAVES:0)
Block(2,27,-5,LEAVES:0)
Block(3,27,-5,LEAVES:0)
Block(5,27,-5,LEAVES:0)
Block(6,27,-5,LEAVES:0)
Block(8,27,-5,LEAVES:0)
Block(11,27,-5,LEAVES:0)
Block(12,27,-5,LEAVES:0)
Block(-12,27,-4,LEAVES:0)
Block(-11,27,-4,LEAVES:0)
Block(-10,27,-4,LEAVES:0)
Block(-9,27,-4,LEAVES:0)
Block(-5,27,-4,LEAVES:0)
Block(-4,27,-4,LEAVES:0)
Block(-3,27,-4,LEAVES:0)
Block(-2,27,-4,LEAVES:0)
Block(-1,27,-4,LEAVES:0)
Block(0,27,-4,LEAVES:0)
Block(2,27,-4,LEAVES:0)
Block(3,27,-4,LEAVES:0)
Block(4,27,-4,LEAVES:0)
Block(6,27,-4,LEAVES:0)
Block(7,27,-4,LEAVES:0)
Block(8,27,-4,LEAVES:0)
Block(9,27,-4,LEAVES:0)
Block(10,27,-4,LEAVES:0)
Block(-9,27,-3,LEAVES:0)
Block(-7,27,-3,LEAVES:0)
Block(-6,27,-3,LEAVES:0)
Block(-3,27,-3,LEAVES:0)
Block(-2,27,-3,LEAVES:0)
Block(0,27,-3,LEAVES:0)
Block(1,27,-3,LEAVES:0)
Block(2,27,-3,LEAVES:0)
Block(3,27,-3,LEAVES:0)
Block(4,27,-3,LEAVES:0)
Block(5,27,-3,LEAVES:0)
Block(6,27,-3,LEAVES:0)
Block(7,27,-3,LEAVES:0)
Block(10,27,-3,LEAVES:0)
Block(-10,27,-2,LEAVES:0)
Block(-9,27,-2,LEAVES:0)
Block(-8,27,-2,LEAVES:0)
Block(-6,27,-2,LEAVES:0)
Block(-4,27,-2,LEAVES:0)
Block(-3,27,-2,LEAVES:0)
Block(-2,27,-2,LEAVES:0)
Block(1,27,-2,LEAVES:0)
Block(2,27,-2,LEAVES:0)
Block(3,27,-2,LEAVES:0)
Block(5,27,-2,LEAVES:0)
Block(7,27,-2,LEAVES:0)
Block(8,27,-2,LEAVES:0)
Block(9,27,-2,LEAVES:0)
Block(10,27,-2,LEAVES:0)
Block(12,27,-2,LEAVES:0)
Block(14,27,-2,LEAVES:0)
Block(-10,27,-1,LEAVES:0)
Block(-9,27,-1,LEAVES:0)
Block(-8,27,-1,LEAVES:0)
Block(-5,27,-1,LEAVES:0)
Block(-3,27,-1,LEAVES:0)
Block(-1,27,-1,LEAVES:0)
Block(0,27,-1,LEAVES:0)
Block(1,27,-1,LEAVES:0)
Block(2,27,-1,LEAVES:0)
Block(3,27,-1,LEAVES:0)
Block(7,27,-1,LEAVES:0)
Block(8,27,-1,LEAVES:0)
Block(13,27,-1,LEAVES:0)
Block(-13,27,0,LEAVES:0)
Block(-12,27,0,LEAVES:0)
Block(-9,27,0,LEAVES:0)
Block(-8,27,0,LEAVES:0)
Block(-7,27,0,LEAVES:0)
Block(-4,27,0,LEAVES:0)
Block(-2,27,0,LEAVES:0)
Block(-1,27,0,LEAVES:0)
Block(0,27,0,LEAVES:0)
Block(1,27,0,LEAVES:0)
Block(2,27,0,LEAVES:0)
Block(3,27,0,LEAVES:0)
Block(4,27,0,LEAVES:0)
Block(7,27,0,LEAVES:0)
Block(8,27,0,LEAVES:0)
Block(9,27,0,LEAVES:0)
Block(11,27,0,LEAVES:0)
Block(12,27,0,LEAVES:0)
Block(13,27,0,LEAVES:0)
Block(14,27,0,LEAVES:0)
Block(-14,27,1,LEAVES:0)
Block(-13,27,1,LEAVES:0)
Block(-8,27,1,LEAVES:0)
Block(-6,27,1,LEAVES:0)
Block(-3,27,1,LEAVES:0)
Block(-2,27,1,LEAVES:0)
Block(-1,27,1,LEAVES:0)
Block(1,27,1,LEAVES:0)
Block(2,27,1,LEAVES:0)
Block(3,27,1,LEAVES:0)
Block(4,27,1,LEAVES:0)
Block(7,27,1,LEAVES:0)
Block(8,27,1,LEAVES:0)
Block(9,27,1,LEAVES:0)
Block(12,27,1,LEAVES:0)
Block(-13,27,2,LEAVES:0)
Block(-12,27,2,LEAVES:0)
Block(-11,27,2,LEAVES:0)
Block(-10,27,2,LEAVES:0)
Block(-9,27,2,LEAVES:0)
Block(-8,27,2,LEAVES:0)
Block(-7,27,2,LEAVES:0)
Block(-6,27,2,LEAVES:0)
Block(-5,27,2,LEAVES:0)
Block(-4,27,2,LEAVES:0)
Block(-3,27,2,LEAVES:0)
Block(-2,27,2,LEAVES:0)
Block(-1,27,2,LEAVES:0)
Block(0,27,2,LEAVES:0)
Block(1,27,2,LEAVES:0)
Block(2,27,2,LEAVES:0)
Block(3,27,2,LEAVES:0)
Block(4,27,2,LEAVES:0)
Block(5,27,2,LEAVES:0)
Block(6,27,2,LEAVES:0)
Block(7,27,2,LEAVES:0)
Block(8,27,2,LEAVES:0)
Block(10,27,2,LEAVES:0)
Block(11,27,2,LEAVES:0)
Block(12,27,2,LEAVES:0)
Block(-13,27,3,LEAVES:0)
Block(-12,27,3,LEAVES:0)
Block(-11,27,3,LEAVES:0)
Block(-10,27,3,LEAVES:0)
Block(-8,27,3,LEAVES:0)
Block(-6,27,3,LEAVES:0)
Block(-5,27,3,LEAVES:0)
Block(-4,27,3,LEAVES:0)
Block(-3,27,3,LEAVES:0)
Block(0,27,3,LEAVES:0)
Block(2,27,3,LEAVES:0)
Block(3,27,3,LEAVES:0)
Block(4,27,3,LEAVES:0)
Block(5,27,3,LEAVES:0)
Block(7,27,3,LEAVES:0)
Block(8,27,3,LEAVES:0)
Block(9,27,3,LEAVES:0)
Block(10,27,3,LEAVES:0)
Block(11,27,3,LEAVES:0)
Block(12,27,3,LEAVES:0)
Block(-12,27,4,LEAVES:0)
Block(-11,27,4,LEAVES:0)
Block(-10,27,4,LEAVES:0)
Block(-7,27,4,LEAVES:0)
Block(-6,27,4,LEAVES:0)
Block(-5,27,4,LEAVES:0)
Block(-4,27,4,LEAVES:0)
Block(-3,27,4,LEAVES:0)
Block(-2,27,4,LEAVES:0)
Block(0,27,4,LEAVES:0)
Block(3,27,4,LEAVES:0)
Block(4,27,4,LEAVES:0)
Block(6,27,4,LEAVES:0)
Block(7,27,4,LEAVES:0)
Block(8,27,4,LEAVES:0)
Block(10,27,4,LEAVES:0)
Block(11,27,4,LEAVES:0)
Block(12,27,4,LEAVES:0)
Block(-11,27,5,LEAVES:0)
Block(-10,27,5,LEAVES:0)
Block(-8,27,5,LEAVES:0)
Block(-7,27,5,LEAVES:0)
Block(-6,27,5,LEAVES:0)
Block(-5,27,5,LEAVES:0)
Block(-4,27,5,LEAVES:0)
Block(-3,27,5,LEAVES:0)
Block(-1,27,5,LEAVES:0)
Block(2,27,5,LEAVES:0)
Block(5,27,5,LEAVES:0)
Block(6,27,5,LEAVES:0)
Block(8,27,5,LEAVES:0)
Block(10,27,5,LEAVES:0)
Block(11,27,5,LEAVES:0)
Block(-7,27,6,LEAVES:0)
Block(-6,27,6,LEAVES:0)
Block(-3,27,6,LEAVES:0)
Block(-2,27,6,LEAVES:0)
Block(2,27,6,LEAVES:0)
Block(4,27,6,LEAVES:0)
Block(6,27,6,LEAVES:0)
Block(10,27,6,LEAVES:0)
Block(11,27,6,LEAVES:0)
Block(12,27,6,LEAVES:0)
Block(-12,27,7,LEAVES:0)
Block(-11,27,7,LEAVES:0)
Block(-10,27,7,LEAVES:0)
Block(-7,27,7,LEAVES:0)
Block(-4,27,7,LEAVES:0)
Block(-2,27,7,LEAVES:0)
Block(1,27,7,LEAVES:0)
Block(3,27,7,LEAVES:0)
Block(4,27,7,LEAVES:0)
Block(5,27,7,LEAVES:0)
Block(6,27,7,LEAVES:0)
Block(7,27,7,LEAVES:0)
Block(8,27,7,LEAVES:0)
Block(9,27,7,LEAVES:0)
Block(10,27,7,LEAVES:0)
Block(11,27,7,LEAVES:0)
Block(12,27,7,LEAVES:0)
Block(-12,27,8,LEAVES:0)
Block(-10,27,8,LEAVES:0)
Block(-7,27,8,LEAVES:0)
Block(-6,27,8,LEAVES:0)
Block(-5,27,8,LEAVES:0)
Block(-4,27,8,LEAVES:0)
Block(-3,27,8,LEAVES:0)
Block(-2,27,8,LEAVES:0)
Block(-1,27,8,LEAVES:0)
Block(0,27,8,LEAVES:0)
Block(2,27,8,LEAVES:0)
Block(3,27,8,LEAVES:0)
Block(4,27,8,LEAVES:0)
Block(7,27,8,LEAVES:0)
Block(8,27,8,LEAVES:0)
Block(10,27,8,LEAVES:0)
Block(11,27,8,LEAVES:0)
Block(12,27,8,LEAVES:0)
Block(-11,27,9,LEAVES:0)
Block(-10,27,9,LEAVES:0)
Block(-9,27,9,LEAVES:0)
Block(-1,27,9,LEAVES:0)
Block(2,27,9,LEAVES:0)
Block(3,27,9,LEAVES:0)
Block(4,27,9,LEAVES:0)
Block(7,27,9,LEAVES:0)
Block(8,27,9,LEAVES:0)
Block(-12,27,10,LEAVES:0)
Block(-11,27,10,LEAVES:0)
Block(-10,27,10,LEAVES:0)
Block(-9,27,10,LEAVES:0)
Block(-8,27,10,LEAVES:0)
Block(-7,27,10,LEAVES:0)
Block(-4,27,10,LEAVES:0)
Block(-3,27,10,LEAVES:0)
Block(-2,27,10,LEAVES:0)
Block(-1,27,10,LEAVES:0)
Block(0,27,10,LEAVES:0)
Block(1,27,10,LEAVES:0)
Block(3,27,10,LEAVES:0)
Block(4,27,10,LEAVES:0)
Block(5,27,10,LEAVES:0)
Block(6,27,10,LEAVES:0)
Block(7,27,10,LEAVES:0)
Block(8,27,10,LEAVES:0)
Block(11,27,10,LEAVES:0)
Block(-11,27,11,LEAVES:0)
Block(-10,27,11,LEAVES:0)
Block(-8,27,11,LEAVES:0)
Block(-7,27,11,LEAVES:0)
Block(-6,27,11,LEAVES:0)
Block(-4,27,11,LEAVES:0)
Block(-1,27,11,LEAVES:0)
Block(0,27,11,LEAVES:0)
Block(3,27,11,LEAVES:0)
Block(4,27,11,LEAVES:0)
Block(5,27,11,LEAVES:0)
Block(6,27,11,LEAVES:0)
Block(7,27,11,LEAVES:0)
Block(8,27,11,LEAVES:0)
Block(9,27,11,LEAVES:0)
Block(10,27,11,LEAVES:0)
Block(11,27,11,LEAVES:0)
Block(-7,27,12,LEAVES:0)
Block(-5,27,12,LEAVES:0)
Block(-4,27,12,LEAVES:0)
Block(-3,27,12,LEAVES:0)
Block(-1,27,12,LEAVES:0)
Block(1,27,12,LEAVES:0)
Block(2,27,12,LEAVES:0)
Block(3,27,12,LEAVES:0)
Block(4,27,12,LEAVES:0)
Block(5,27,12,LEAVES:0)
Block(7,27,12,LEAVES:0)
Block(-6,27,13,LEAVES:0)
Block(-5,27,13,LEAVES:0)
Block(3,27,13,LEAVES:0)
Block(4,27,13,LEAVES:0)
Block(5,27,13,LEAVES:0)
Block(0,27,14,LEAVES:0)
Block(1,27,14,LEAVES:0)
Block(-1,28,-9,LEAVES:0)
Block(1,28,-9,LEAVES:0)
Block(2,28,-9,LEAVES:0)
Block(3,28,-9,LEAVES:0)
Block(-3,28,-8,LEAVES:0)
Block(-1,28,-8,LEAVES:0)
Block(1,28,-8,LEAVES:0)
Block(2,28,-8,LEAVES:0)
Block(3,28,-8,LEAVES:0)
Block(-4,28,-7,LEAVES:0)
Block(2,28,-7,LEAVES:0)
Block(-3,28,-6,LEAVES:0)
Block(3,28,-6,LEAVES:0)
Block(-6,28,-5,LEAVES:0)
Block(-4,28,-5,LEAVES:0)
Block(-3,28,-5,LEAVES:0)
Block(1,28,-5,LEAVES:0)
Block(3,28,-5,LEAVES:0)
Block(6,28,-5,LEAVES:0)
Block(-7,28,-4,LEAVES:0)
Block(-6,28,-4,LEAVES:0)
Block(-5,28,-4,LEAVES:0)
Block(-2,28,-4,LEAVES:0)
Block(1,28,-4,LEAVES:0)
Block(2,28,-4,LEAVES:0)
Block(3,28,-4,LEAVES:0)
Block(5,28,-4,LEAVES:0)
Block(-8,28,-3,LEAVES:0)
Block(-7,28,-3,LEAVES:0)
Block(3,28,-3,LEAVES:0)
Block(4,28,-3,LEAVES:0)
Block(8,28,-3,LEAVES:0)
Block(-8,28,-2,LEAVES:0)
Block(-7,28,-2,LEAVES:0)
Block(-5,28,-2,LEAVES:0)
Block(-4,28,-2,LEAVES:0)
Block(-3,28,-2,LEAVES:0)
Block(2,28,-2,LEAVES:0)
Block(3,28,-2,LEAVES:0)
Block(4,28,-2,LEAVES:0)
Block(7,28,-2,LEAVES:0)
Block(8,28,-2,LEAVES:0)
Block(9,28,-2,LEAVES:0)
Block(-4,28,-1,LEAVES:0)
Block(-1,28,-1,LEAVES:0)
Block(0,28,-1,LEAVES:0)
Block(1,28,-1,LEAVES:0)
Block(2,28,-1,LEAVES:0)
Block(7,28,-1,LEAVES:0)
Block(8,28,-1,LEAVES:0)
Block(9,28,-1,LEAVES:0)
Block(0,28,0,LEAVES:0)
Block(1,28,0,LEAVES:0)
Block(3,28,0,LEAVES:0)
Block(4,28,0,LEAVES:0)
Block(8,28,0,LEAVES:0)
Block(9,28,0,LEAVES:0)
Block(-12,28,1,LEAVES:0)
Block(-11,28,1,LEAVES:0)
Block(-8,28,1,LEAVES:0)
Block(-7,28,1,LEAVES:0)
Block(-5,28,1,LEAVES:0)
Block(-4,28,1,LEAVES:0)
Block(-3,28,1,LEAVES:0)
Block(1,28,1,LEAVES:0)
Block(3,28,1,LEAVES:0)
Block(4,28,1,LEAVES:0)
Block(7,28,1,LEAVES:0)
Block(8,28,1,LEAVES:0)
Block(10,28,1,LEAVES:0)
Block(-12,28,2,LEAVES:0)
Block(-10,28,2,LEAVES:0)
Block(-9,28,2,LEAVES:0)
Block(-8,28,2,LEAVES:0)
Block(-7,28,2,LEAVES:0)
Block(-4,28,2,LEAVES:0)
Block(-2,28,2,LEAVES:0)
Block(2,28,2,LEAVES:9)
Block(3,28,2,LEAVES:0)
Block(5,28,2,LEAVES:0)
Block(9,28,2,LEAVES:0)
Block(-12,28,3,LEAVES:0)
Block(-11,28,3,LEAVES:0)
Block(-10,28,3,LEAVES:0)
Block(-9,28,3,LEAVES:0)
Block(-8,28,3,LEAVES:0)
Block(-7,28,3,LEAVES:0)
Block(-6,28,3,LEAVES:0)
Block(-5,28,3,LEAVES:0)
Block(-2,28,3,LEAVES:0)
Block(1,28,3,LEAVES:0)
Block(2,28,3,LEAVES:0)
Block(5,28,3,LEAVES:0)
Block(6,28,3,LEAVES:0)
Block(-6,28,4,LEAVES:0)
Block(-5,28,4,LEAVES:0)
Block(-3,28,4,LEAVES:0)
Block(4,28,4,LEAVES:0)
Block(6,28,4,LEAVES:0)
Block(-6,28,5,LEAVES:0)
Block(4,28,5,LEAVES:0)
Block(5,28,5,LEAVES:0)
Block(6,28,5,LEAVES:0)
Block(-5,28,6,LEAVES:0)
Block(-4,28,6,LEAVES:0)
Block(-3,28,6,LEAVES:0)
Block(5,28,6,LEAVES:0)
Block(7,28,6,LEAVES:0)
Block(8,28,6,LEAVES:0)
Block(-5,28,7,LEAVES:0)
Block(-4,28,7,LEAVES:0)
Block(-2,28,7,LEAVES:0)
Block(2,28,7,LEAVES:0)
Block(3,28,7,LEAVES:0)
Block(4,28,7,LEAVES:0)
Block(7,28,7,LEAVES:0)
Block(8,28,7,LEAVES:0)
Block(9,28,7,LEAVES:0)
Block(-3,28,8,LEAVES:0)
Block(-2,28,8,LEAVES:0)
Block(-1,28,8,LEAVES:0)
Block(1,28,8,LEAVES:0)
Block(2,28,8,LEAVES:0)
Block(8,28,8,LEAVES:0)
Block(9,28,8,LEAVES:0)
Block(-2,28,9,LEAVES:0)
Block(1,28,9,LEAVES:0)

#######################################################################
# +-----------------------------------------------------------------+ #
# |                            BO3 checks                           | #
# +-----------------------------------------------------------------+ #
#######################################################################

# Require a condition at a certain location in order for the BO3 to be spawned.
# BlockCheck(x,y,z,BlockName[,BlockName[,...]]) - one of the blocks must be at the location
# BlockCheckNot(x,y,z,BlockName[,BlockName[,...]]) - all the blocks must not be at the location
# LightCheck(x,y,z,minLightLevel,maxLightLevel) - light must be between min and max (inclusive)

# You can use "Solid" as a BlockName for matching all solid blocks or "All" to match all blocks that aren't air.

# Examples:
BlockCheck(0,-1,0,GRASS,DIRT,DIRT:2,SAND,STONE)
#   BlockCheck(0,-1,0,Solid)       Require any solid block just below the object
#   BlockCheck(0,-1,0,WOOL)        Require any type of wool just below the object
#   BlockCheck(0,-1,0,WOOL:0)      Require white wool just below the object
#   BlockCheckNot(0,-1,0,WOOL:0)   Require that there is no white wool below the object
#   LightCheck(0,0,0,0,1)          Require almost complete darkness just below the object

#######################################################################
# +-----------------------------------------------------------------+ #
# |                             Branches                            | #
# +-----------------------------------------------------------------+ #
#######################################################################

# Branches are objects that will spawn when this object spawns when it is used in
# the CustomStructure resource. Branches can also have branches, making complex
# structures possible. See the wiki for more details.

# Regular Branches spawn each branch with an independent chance of spawning.
# Branch(x,y,z,branchName,rotation,chance[,anotherBranchName,rotation,chance[,...]][IndividualChance])
# branchName - name of the object to spawn.
# rotation - NORTH, SOUTH, EAST or WEST.
# IndividualChance - The chance each branch has to spawn, assumed to be 100 when left blank

# Weighted Branches spawn branches with a dependent chance of spawning.
# WeightedBranch(x,y,z,branchName,rotation,chance[,anotherBranchName,rotation,chance[,...]][MaxChanceOutOf])
# MaxChanceOutOf - The chance all branches have to spawn out of, assumed to be 100 when left blank
