#######################################################################
# +-----------------------------------------------------------------+ #
# |                            BO3 object                           | #
# +-----------------------------------------------------------------+ #
#######################################################################

# The descriptions in this file are accurate only for TerrainControl and OTG.
# For MCW and OTG+ these descriptions are only accurate if the BO3 is used as a CustomObject.
# MCW and OTG+ completely reimplemented CustomStructure, check the MCW/OTG+ documentation for more information.

# This is the config file of a custom object.
# If you add this object correctly to your BiomeConfigs, it will spawn in the world.

# This is the creator of this BO3 object
Author: Unknown

# A short description of this BO3 object
Description: This BO3 was converted from a schematic using OTGEdit. The author and description information of the schematic could not be found. If you know who the author of the schematic is then please add this information.

# The BO3 version, don't change this! It can be used by external applications to do a version check.
Version: 3

# The settings mode, WriteAll, WriteWithoutComments or WriteDisable. See WorldConfig.
SettingsMode: WriteDisable

#######################################################################
# +-----------------------------------------------------------------+ #
# |                          Main settings                          | #
# +-----------------------------------------------------------------+ #
#######################################################################

# This needs to be set to true to spawn the object in the Tree and Sapling resources.
Tree: true

# The frequency of the BO3 from 1 to 200. Tries this many times to spawn this BO3 when using the CustomObject(...) resource.
# Ignored by Tree(..), Sapling(..) and CustomStructure(..)
Frequency: 40

# The rarity of the BO3 from 0 to 100. Each spawn attempt has rarity% chance to succeed when using the CustomObject(...) resource.
# Ignored by Tree(..), Sapling(..) and CustomStructure(..)
Rarity: 100.0

# If you set this to true, the BO3 will be placed with a random rotation.
RotateRandomly: true

# The spawn height of the BO3 - randomY, highestBlock or highestSolidBlock.
SpawnHeight: highestSolidBlock
SpawnHeightOffset: -14
# The height limits for the BO3.
MinHeight: 112

MaxHeight: 140

# Objects can have other objects attached to it: branches. Branches can also
# have branches attached to it, which can also have branches, etc. This is the
# maximum branch depth for this objects.
MaxBranchDepth: 10

# When spawned with the UseWorld keyword, this BO3 should NOT spawn in the following biomes.
# If you writer.write the BO3 name directly in the BiomeConfigs, this will be ignored.
ExcludedBiomes: All

# To optimise this BO3 for faster loading times you can use Notepad++ to find/replace comments and abbreviate things.
# Notepad++ find/replace with regex:
# Find: ^[#;].* replace to nothing removes all lines starting with # 
# Find: ^\s*$ replace to nothing removes most empty lines 
# Notepad++ find/replace without regex:
# *Warning: This will only work for OTG 1.10.2 v21 / OTG 1.11.2 v6 or higher. B( is not recognised by lower versions.
# Find: Block( replace to B(

#######################################################################
# +-----------------------------------------------------------------+ #
# |                      Source block settings                      | #
# +-----------------------------------------------------------------+ #
#######################################################################

# The block(s) the BO3 should spawn in.
SourceBlocks: AIR,GRASS,DIRT,STONE,SAND,GRAVEL,CLAY,STATIONARY_WATER,FLOWING_WATER


# The maximum percentage of the BO3 that can be outside the SourceBlock.
# The BO3 won't be placed on a location with more blocks outside the SourceBlock than this percentage.
MaxPercentageOutsideSourceBlock: 0

# What to do when a block is about to be placed outside the SourceBlock? (dontPlace, placeAnyway)
OutsideSourceBlock: dontPlace

#######################################################################
# +-----------------------------------------------------------------+ #
# |                              Blocks                             | #
# +-----------------------------------------------------------------+ #
#######################################################################

# All the blocks used in the BO3 are listed here. Possible blocks:
# Block(x,y,z,id[.data][,nbtfile.nbt) or B(x,y,z,id[.data][,nbtfile.nbt)
# RandomBlock(x,y,z,id[:data][,nbtfile.nbt],chance[,id[:data][,nbtfile.nbt],chance[,...]])
# So RandomBlock(0,0,0,CHEST,chest.nbt,50,CHEST,anotherchest.nbt,100) will spawn a chest at
# the BO3 origin, and give it a 50% chance to have the contents of chest.nbt, or, if that
# fails, a 100% percent chance to have the contents of anotherchest.nbt.

Block(-14,17,11,STONE)
Block(-14,20,12,STONE)
Block(-13,9,2,STONE)
Block(-13,10,1,STONE)
Block(-13,10,2,STONE)
Block(-13,10,3,STONE)
Block(-13,11,2,STONE)
Block(-13,11,3,STONE)
Block(-13,11,4,STONE)
Block(-13,12,3,STONE)
Block(-13,12,4,STONE)
Block(-13,12,5,STONE)
Block(-13,13,4,STONE)
Block(-13,13,5,STONE)
Block(-13,13,6,STONE)
Block(-13,14,5,STONE)
Block(-13,14,6,STONE)
Block(-13,14,7,STONE)
Block(-13,14,8,STONE)
Block(-13,15,7,STONE)
Block(-13,15,8,STONE)
Block(-13,15,9,STONE)
Block(-13,15,10,STONE)
Block(-13,16,8,STONE)
Block(-13,16,9,STONE)
Block(-13,16,10,STONE)
Block(-13,16,11,STONE)
Block(-13,16,12,STONE)
Block(-13,17,8,STONE)
Block(-13,17,9,STONE)
Block(-13,17,10,STONE)
Block(-13,17,11,STONE)
Block(-13,17,12,STONE)
Block(-13,18,8,STONE)
Block(-13,18,9,STONE)
Block(-13,18,10,STONE)
Block(-13,18,11,STONE)
Block(-13,18,12,STONE)
Block(-13,19,8,STONE)
Block(-13,19,9,STONE)
Block(-13,19,10,STONE)
Block(-13,19,11,STONE)
Block(-13,19,12,STONE)
Block(-13,20,8,STONE)
Block(-13,20,9,STONE)
Block(-13,20,10,STONE)
Block(-13,20,11,STONE)
Block(-13,20,12,STONE)
Block(-13,20,13,STONE)
Block(-13,21,9,STONE)
Block(-13,21,10,STONE)
Block(-13,21,11,STONE)
Block(-13,21,12,STONE)
Block(-13,21,13,STONE)
Block(-13,22,9,STONE)
Block(-13,22,10,STONE)
Block(-13,22,11,STONE)
Block(-13,22,12,STONE)
Block(-13,22,13,STONE)
Block(-13,23,10,STONE)
Block(-13,23,11,STONE)
Block(-13,23,12,STONE)
Block(-13,24,10,STONE)
Block(-13,24,11,STONE)
Block(-13,25,11,STONE)
Block(-12,9,0,STONE)
Block(-12,9,1,STONE)
Block(-12,9,2,STONE)
Block(-12,9,3,STONE)
Block(-12,10,-2,STONE)
Block(-12,10,-1,STONE)
Block(-12,10,0,STONE)
Block(-12,10,1,STONE)
Block(-12,10,2,STONE)
Block(-12,10,3,STONE)
Block(-12,10,4,STONE)
Block(-12,11,-1,STONE)
Block(-12,11,0,STONE)
Block(-12,11,1,STONE)
Block(-12,11,2,STONE)
Block(-12,11,3,STONE)
Block(-12,11,4,STONE)
Block(-12,11,5,STONE)
Block(-12,12,-1,STONE)
Block(-12,12,0,STONE)
Block(-12,12,1,STONE)
Block(-12,12,2,STONE)
Block(-12,12,3,STONE)
Block(-12,12,4,STONE)
Block(-12,12,5,STONE)
Block(-12,12,6,STONE)
Block(-12,13,0,STONE)
Block(-12,13,1,STONE)
Block(-12,13,2,STONE)
Block(-12,13,3,STONE)
Block(-12,13,4,STONE)
Block(-12,13,5,STONE)
Block(-12,13,6,STONE)
Block(-12,13,7,STONE)
Block(-12,13,8,STONE)
Block(-12,14,0,STONE)
Block(-12,14,1,STONE)
Block(-12,14,2,STONE)
Block(-12,14,3,STONE)
Block(-12,14,4,STONE)
Block(-12,14,5,STONE)
Block(-12,14,6,STONE)
Block(-12,14,7,STONE)
Block(-12,14,8,STONE)
Block(-12,14,9,STONE)
Block(-12,15,1,STONE)
Block(-12,15,2,STONE)
Block(-12,15,3,STONE)
Block(-12,15,4,STONE)
Block(-12,15,5,STONE)
Block(-12,15,6,STONE)
Block(-12,15,7,STONE)
Block(-12,15,8,STONE)
Block(-12,15,9,STONE)
Block(-12,15,10,STONE)
Block(-12,15,11,STONE)
Block(-12,16,2,STONE)
Block(-12,16,3,STONE)
Block(-12,16,4,STONE)
Block(-12,16,5,STONE)
Block(-12,16,6,STONE)
Block(-12,16,7,STONE)
Block(-12,16,8,STONE)
Block(-12,16,9,STONE)
Block(-12,16,10,STONE)
Block(-12,16,11,STONE)
Block(-12,16,12,STONE)
Block(-12,16,13,STONE)
Block(-12,17,3,STONE)
Block(-12,17,4,STONE)
Block(-12,17,5,STONE)
Block(-12,17,6,STONE)
Block(-12,17,7,STONE)
Block(-12,17,8,STONE)
Block(-12,17,9,STONE)
Block(-12,17,10,STONE)
Block(-12,17,11,STONE)
Block(-12,17,12,STONE)
Block(-12,17,13,STONE)
Block(-12,18,3,STONE)
Block(-12,18,4,STONE)
Block(-12,18,5,STONE)
Block(-12,18,6,STONE)
Block(-12,18,7,STONE)
Block(-12,18,8,STONE)
Block(-12,18,9,STONE)
Block(-12,18,10,STONE)
Block(-12,18,11,STONE)
Block(-12,18,12,STONE)
Block(-12,18,13,STONE)
Block(-12,19,4,STONE)
Block(-12,19,5,STONE)
Block(-12,19,6,STONE)
Block(-12,19,7,STONE)
Block(-12,19,8,STONE)
Block(-12,19,9,STONE)
Block(-12,19,10,STONE)
Block(-12,19,11,STONE)
Block(-12,19,12,STONE)
Block(-12,19,13,STONE)
Block(-12,19,14,STONE)
Block(-12,20,4,STONE)
Block(-12,20,5,STONE)
Block(-12,20,6,STONE)
Block(-12,20,7,STONE)
Block(-12,20,8,STONE)
Block(-12,20,9,STONE)
Block(-12,20,10,STONE)
Block(-12,20,11,STONE)
Block(-12,20,12,STONE)
Block(-12,20,13,STONE)
Block(-12,20,14,STONE)
Block(-12,21,4,STONE)
Block(-12,21,5,STONE)
Block(-12,21,6,STONE)
Block(-12,21,7,STONE)
Block(-12,21,8,STONE)
Block(-12,21,9,STONE)
Block(-12,21,10,STONE)
Block(-12,21,11,STONE)
Block(-12,21,12,STONE)
Block(-12,21,13,STONE)
Block(-12,21,14,STONE)
Block(-12,22,5,STONE)
Block(-12,22,6,STONE)
Block(-12,22,7,STONE)
Block(-12,22,8,STONE)
Block(-12,22,9,STONE)
Block(-12,22,10,STONE)
Block(-12,22,11,STONE)
Block(-12,22,12,STONE)
Block(-12,22,13,STONE)
Block(-12,22,14,STONE)
Block(-12,23,6,STONE)
Block(-12,23,7,STONE)
Block(-12,23,8,STONE)
Block(-12,23,9,STONE)
Block(-12,23,10,STONE)
Block(-12,23,11,STONE)
Block(-12,23,12,STONE)
Block(-12,23,13,STONE)
Block(-12,24,7,STONE)
Block(-12,24,8,STONE)
Block(-12,24,9,STONE)
Block(-12,24,10,STONE)
Block(-12,24,11,STONE)
Block(-12,24,12,STONE)
Block(-12,25,7,STONE)
Block(-12,25,8,STONE)
Block(-12,25,9,STONE)
Block(-12,25,10,STONE)
Block(-12,25,11,STONE)
Block(-12,25,12,STONE)
Block(-12,26,8,STONE)
Block(-12,26,9,STONE)
Block(-12,26,10,STONE)
Block(-12,26,11,STONE)
Block(-12,27,8,STONE)
Block(-12,27,9,STONE)
Block(-12,27,10,STONE)
Block(-12,28,8,STONE)
Block(-12,28,9,STONE)
Block(-12,28,10,STONE)
Block(-12,29,8,STONE)
Block(-12,29,9,STONE)
Block(-12,30,8,STONE)
Block(-11,8,3,STONE)
Block(-11,9,0,STONE)
Block(-11,9,1,STONE)
Block(-11,9,2,STONE)
Block(-11,9,3,STONE)
Block(-11,9,4,STONE)
Block(-11,9,5,STONE)
Block(-11,10,-3,STONE)
Block(-11,10,-2,STONE)
Block(-11,10,-1,STONE)
Block(-11,10,0,STONE)
Block(-11,10,1,STONE)
Block(-11,10,2,STONE)
Block(-11,10,3,STONE)
Block(-11,10,4,STONE)
Block(-11,10,5,STONE)
Block(-11,10,6,STONE)
Block(-11,11,-5,STONE)
Block(-11,11,-4,STONE)
Block(-11,11,-3,STONE)
Block(-11,11,-2,STONE)
Block(-11,11,-1,STONE)
Block(-11,11,0,STONE)
Block(-11,11,1,STONE)
Block(-11,11,2,STONE)
Block(-11,11,3,STONE)
Block(-11,11,4,STONE)
Block(-11,11,5,STONE)
Block(-11,11,6,STONE)
Block(-11,11,7,STONE)
Block(-11,12,-5,STONE)
Block(-11,12,-4,STONE)
Block(-11,12,-3,STONE)
Block(-11,12,-2,STONE)
Block(-11,12,-1,STONE)
Block(-11,12,0,STONE)
Block(-11,12,1,STONE)
Block(-11,12,2,STONE)
Block(-11,12,3,STONE)
Block(-11,12,4,STONE)
Block(-11,12,5,STONE)
Block(-11,12,6,STONE)
Block(-11,12,7,STONE)
Block(-11,12,8,STONE)
Block(-11,13,-5,STONE)
Block(-11,13,-4,STONE)
Block(-11,13,-3,STONE)
Block(-11,13,-2,STONE)
Block(-11,13,-1,STONE)
Block(-11,13,0,STONE)
Block(-11,13,1,STONE)
Block(-11,13,2,STONE)
Block(-11,13,3,STONE)
Block(-11,13,4,STONE)
Block(-11,13,5,STONE)
Block(-11,13,6,STONE)
Block(-11,13,7,STONE)
Block(-11,13,8,STONE)
Block(-11,13,9,STONE)
Block(-11,14,-4,STONE)
Block(-11,14,-3,STONE)
Block(-11,14,-2,STONE)
Block(-11,14,-1,STONE)
Block(-11,14,0,STONE)
Block(-11,14,1,STONE)
Block(-11,14,2,STONE)
Block(-11,14,3,STONE)
Block(-11,14,4,STONE)
Block(-11,14,5,STONE)
Block(-11,14,6,STONE)
Block(-11,14,7,STONE)
Block(-11,14,8,STONE)
Block(-11,14,9,STONE)
Block(-11,14,10,STONE)
Block(-11,14,11,STONE)
Block(-11,15,-3,STONE)
Block(-11,15,-2,STONE)
Block(-11,15,-1,STONE)
Block(-11,15,0,STONE)
Block(-11,15,1,STONE)
Block(-11,15,2,STONE)
Block(-11,15,3,STONE)
Block(-11,15,4,STONE)
Block(-11,15,5,STONE)
Block(-11,15,6,STONE)
Block(-11,15,7,STONE)
Block(-11,15,8,STONE)
Block(-11,15,9,STONE)
Block(-11,15,10,STONE)
Block(-11,15,11,STONE)
Block(-11,15,12,STONE)
Block(-11,15,13,STONE)
Block(-11,16,-3,STONE)
Block(-11,16,-2,STONE)
Block(-11,16,-1,STONE)
Block(-11,16,0,STONE)
Block(-11,16,1,STONE)
Block(-11,16,2,STONE)
Block(-11,16,3,STONE)
Block(-11,16,4,STONE)
Block(-11,16,5,STONE)
Block(-11,16,6,STONE)
Block(-11,16,7,STONE)
Block(-11,16,8,STONE)
Block(-11,16,9,STONE)
Block(-11,16,10,STONE)
Block(-11,16,11,STONE)
Block(-11,16,12,STONE)
Block(-11,16,13,STONE)
Block(-11,16,14,STONE)
Block(-11,17,-2,STONE)
Block(-11,17,-1,STONE)
Block(-11,17,0,STONE)
Block(-11,17,1,STONE)
Block(-11,17,2,STONE)
Block(-11,17,3,STONE)
Block(-11,17,4,STONE)
Block(-11,17,5,STONE)
Block(-11,17,6,STONE)
Block(-11,17,7,STONE)
Block(-11,17,8,STONE)
Block(-11,17,9,STONE)
Block(-11,17,10,STONE)
Block(-11,17,11,STONE)
Block(-11,17,12,STONE)
Block(-11,17,13,STONE)
Block(-11,17,14,STONE)
Block(-11,18,-2,STONE)
Block(-11,18,-1,STONE)
Block(-11,18,0,STONE)
Block(-11,18,1,STONE)
Block(-11,18,2,STONE)
Block(-11,18,3,STONE)
Block(-11,18,4,STONE)
Block(-11,18,5,STONE)
Block(-11,18,6,STONE)
Block(-11,18,7,STONE)
Block(-11,18,8,STONE)
Block(-11,18,9,STONE)
Block(-11,18,10,STONE)
Block(-11,18,11,STONE)
Block(-11,18,12,STONE)
Block(-11,18,13,STONE)
Block(-11,18,14,STONE)
Block(-11,19,-1,STONE)
Block(-11,19,0,STONE)
Block(-11,19,1,STONE)
Block(-11,19,2,STONE)
Block(-11,19,3,STONE)
Block(-11,19,4,STONE)
Block(-11,19,5,STONE)
Block(-11,19,6,STONE)
Block(-11,19,7,STONE)
Block(-11,19,8,STONE)
Block(-11,19,9,STONE)
Block(-11,19,10,STONE)
Block(-11,19,11,STONE)
Block(-11,19,12,STONE)
Block(-11,19,13,STONE)
Block(-11,19,14,STONE)
Block(-11,19,15,STONE)
Block(-11,20,-1,STONE)
Block(-11,20,0,STONE)
Block(-11,20,1,STONE)
Block(-11,20,2,STONE)
Block(-11,20,3,STONE)
Block(-11,20,4,STONE)
Block(-11,20,5,STONE)
Block(-11,20,6,STONE)
Block(-11,20,7,STONE)
Block(-11,20,8,STONE)
Block(-11,20,9,STONE)
Block(-11,20,10,STONE)
Block(-11,20,11,STONE)
Block(-11,20,12,STONE)
Block(-11,20,13,STONE)
Block(-11,20,14,STONE)
Block(-11,20,15,STONE)
Block(-11,21,0,STONE)
Block(-11,21,1,STONE)
Block(-11,21,2,STONE)
Block(-11,21,3,STONE)
Block(-11,21,4,STONE)
Block(-11,21,5,STONE)
Block(-11,21,6,STONE)
Block(-11,21,7,STONE)
Block(-11,21,8,STONE)
Block(-11,21,9,STONE)
Block(-11,21,10,STONE)
Block(-11,21,11,STONE)
Block(-11,21,12,STONE)
Block(-11,21,13,STONE)
Block(-11,21,14,STONE)
Block(-11,21,15,STONE)
Block(-11,22,0,STONE)
Block(-11,22,1,STONE)
Block(-11,22,2,STONE)
Block(-11,22,3,STONE)
Block(-11,22,4,STONE)
Block(-11,22,5,STONE)
Block(-11,22,6,STONE)
Block(-11,22,7,STONE)
Block(-11,22,8,STONE)
Block(-11,22,9,STONE)
Block(-11,22,10,STONE)
Block(-11,22,11,STONE)
Block(-11,22,12,STONE)
Block(-11,22,13,STONE)
Block(-11,22,14,STONE)
Block(-11,22,15,STONE)
Block(-11,23,0,STONE)
Block(-11,23,1,STONE)
Block(-11,23,2,STONE)
Block(-11,23,3,STONE)
Block(-11,23,4,STONE)
Block(-11,23,5,STONE)
Block(-11,23,6,STONE)
Block(-11,23,7,STONE)
Block(-11,23,8,STONE)
Block(-11,23,9,STONE)
Block(-11,23,10,STONE)
Block(-11,23,11,STONE)
Block(-11,23,12,STONE)
Block(-11,23,13,STONE)
Block(-11,23,14,STONE)
Block(-11,24,0,STONE)
Block(-11,24,1,STONE)
Block(-11,24,2,STONE)
Block(-11,24,3,STONE)
Block(-11,24,4,STONE)
Block(-11,24,5,STONE)
Block(-11,24,6,STONE)
Block(-11,24,7,STONE)
Block(-11,24,8,STONE)
Block(-11,24,9,STONE)
Block(-11,24,10,STONE)
Block(-11,24,11,STONE)
Block(-11,24,12,STONE)
Block(-11,24,13,STONE)
Block(-11,25,1,STONE)
Block(-11,25,2,STONE)
Block(-11,25,3,STONE)
Block(-11,25,4,STONE)
Block(-11,25,5,STONE)
Block(-11,25,6,STONE)
Block(-11,25,7,STONE)
Block(-11,25,8,STONE)
Block(-11,25,9,STONE)
Block(-11,25,10,STONE)
Block(-11,25,11,STONE)
Block(-11,25,12,STONE)
Block(-11,25,13,STONE)
Block(-11,26,3,STONE)
Block(-11,26,4,STONE)
Block(-11,26,5,STONE)
Block(-11,26,6,STONE)
Block(-11,26,7,STONE)
Block(-11,26,8,STONE)
Block(-11,26,9,STONE)
Block(-11,26,10,STONE)
Block(-11,26,11,STONE)
Block(-11,26,12,STONE)
Block(-11,27,4,STONE)
Block(-11,27,5,STONE)
Block(-11,27,6,STONE)
Block(-11,27,7,STONE)
Block(-11,27,8,STONE)
Block(-11,27,9,STONE)
Block(-11,27,10,STONE)
Block(-11,27,11,STONE)
Block(-11,28,4,STONE)
Block(-11,28,5,STONE)
Block(-11,28,6,STONE)
Block(-11,28,7,STONE)
Block(-11,28,8,STONE)
Block(-11,28,9,STONE)
Block(-11,28,10,STONE)
Block(-11,29,5,STONE)
Block(-11,29,6,STONE)
Block(-11,29,7,STONE)
Block(-11,29,8,STONE)
Block(-11,29,9,STONE)
Block(-11,29,10,STONE)
Block(-11,30,5,STONE)
Block(-11,30,6,STONE)
Block(-11,30,7,STONE)
Block(-11,30,8,STONE)
Block(-11,30,9,STONE)
Block(-11,31,5,STONE)
Block(-11,31,6,STONE)
Block(-11,31,7,STONE)
Block(-11,31,8,STONE)
Block(-11,32,6,STONE)
Block(-10,8,3,STONE)
Block(-10,8,4,STONE)
Block(-10,8,5,STONE)
Block(-10,9,0,STONE)
Block(-10,9,1,STONE)
Block(-10,9,2,STONE)
Block(-10,9,3,STONE)
Block(-10,9,4,STONE)
Block(-10,9,5,STONE)
Block(-10,9,6,STONE)
Block(-10,10,-4,STONE)
Block(-10,10,-3,STONE)
Block(-10,10,-2,STONE)
Block(-10,10,-1,STONE)
Block(-10,10,0,STONE)
Block(-10,10,1,STONE)
Block(-10,10,2,STONE)
Block(-10,10,3,STONE)
Block(-10,10,4,STONE)
Block(-10,10,5,STONE)
Block(-10,10,6,STONE)
Block(-10,10,7,STONE)
Block(-10,11,-7,STONE)
Block(-10,11,-6,STONE)
Block(-10,11,-5,STONE)
Block(-10,11,-4,STONE)
Block(-10,11,-3,STONE)
Block(-10,11,-2,STONE)
Block(-10,11,-1,STONE)
Block(-10,11,0,STONE)
Block(-10,11,1,STONE)
Block(-10,11,2,STONE)
Block(-10,11,3,STONE)
Block(-10,11,4,STONE)
Block(-10,11,5,STONE)
Block(-10,11,6,STONE)
Block(-10,11,7,STONE)
Block(-10,11,8,STONE)
Block(-10,12,-8,STONE)
Block(-10,12,-7,STONE)
Block(-10,12,-6,STONE)
Block(-10,12,-5,STONE)
Block(-10,12,-4,STONE)
Block(-10,12,-3,STONE)
Block(-10,12,-2,STONE)
Block(-10,12,-1,STONE)
Block(-10,12,0,STONE)
Block(-10,12,1,STONE)
Block(-10,12,2,STONE)
Block(-10,12,3,STONE)
Block(-10,12,4,STONE)
Block(-10,12,5,STONE)
Block(-10,12,6,STONE)
Block(-10,12,7,STONE)
Block(-10,12,8,STONE)
Block(-10,12,9,STONE)
Block(-10,13,-8,STONE)
Block(-10,13,-7,STONE)
Block(-10,13,-6,STONE)
Block(-10,13,-5,STONE)
Block(-10,13,-4,STONE)
Block(-10,13,-3,STONE)
Block(-10,13,-2,STONE)
Block(-10,13,-1,STONE)
Block(-10,13,0,STONE)
Block(-10,13,1,STONE)
Block(-10,13,2,STONE)
Block(-10,13,3,STONE)
Block(-10,13,4,STONE)
Block(-10,13,5,STONE)
Block(-10,13,6,STONE)
Block(-10,13,7,STONE)
Block(-10,13,8,STONE)
Block(-10,13,9,STONE)
Block(-10,13,10,STONE)
Block(-10,13,11,STONE)
Block(-10,14,-8,STONE)
Block(-10,14,-7,STONE)
Block(-10,14,-6,STONE)
Block(-10,14,-5,STONE)
Block(-10,14,-4,STONE)
Block(-10,14,-3,STONE)
Block(-10,14,-2,STONE)
Block(-10,14,-1,STONE)
Block(-10,14,0,STONE)
Block(-10,14,1,STONE)
Block(-10,14,2,STONE)
Block(-10,14,3,STONE)
Block(-10,14,4,STONE)
Block(-10,14,5,STONE)
Block(-10,14,6,STONE)
Block(-10,14,7,STONE)
Block(-10,14,8,STONE)
Block(-10,14,9,STONE)
Block(-10,14,10,STONE)
Block(-10,14,11,STONE)
Block(-10,14,12,STONE)
Block(-10,14,13,STONE)
Block(-10,15,-8,STONE)
Block(-10,15,-7,STONE)
Block(-10,15,-6,STONE)
Block(-10,15,-5,STONE)
Block(-10,15,-4,STONE)
Block(-10,15,-3,STONE)
Block(-10,15,-2,STONE)
Block(-10,15,-1,STONE)
Block(-10,15,0,STONE)
Block(-10,15,1,STONE)
Block(-10,15,2,STONE)
Block(-10,15,3,STONE)
Block(-10,15,4,STONE)
Block(-10,15,5,STONE)
Block(-10,15,6,STONE)
Block(-10,15,7,STONE)
Block(-10,15,8,STONE)
Block(-10,15,9,STONE)
Block(-10,15,10,STONE)
Block(-10,15,11,STONE)
Block(-10,15,12,STONE)
Block(-10,15,13,STONE)
Block(-10,15,14,STONE)
Block(-10,16,-8,STONE)
Block(-10,16,-7,STONE)
Block(-10,16,-6,STONE)
Block(-10,16,-5,STONE)
Block(-10,16,-4,STONE)
Block(-10,16,-3,STONE)
Block(-10,16,-2,STONE)
Block(-10,16,-1,STONE)
Block(-10,16,0,STONE)
Block(-10,16,1,STONE)
Block(-10,16,2,STONE)
Block(-10,16,3,STONE)
Block(-10,16,4,STONE)
Block(-10,16,5,STONE)
Block(-10,16,6,STONE)
Block(-10,16,7,STONE)
Block(-10,16,8,STONE)
Block(-10,16,9,STONE)
Block(-10,16,10,STONE)
Block(-10,16,11,STONE)
Block(-10,16,12,STONE)
Block(-10,16,13,STONE)
Block(-10,16,14,STONE)
Block(-10,16,15,STONE)
Block(-10,17,-7,STONE)
Block(-10,17,-6,STONE)
Block(-10,17,-5,STONE)
Block(-10,17,-4,STONE)
Block(-10,17,-3,STONE)
Block(-10,17,-2,STONE)
Block(-10,17,-1,STONE)
Block(-10,17,0,STONE)
Block(-10,17,1,STONE)
Block(-10,17,2,STONE)
Block(-10,17,3,STONE)
Block(-10,17,4,STONE)
Block(-10,17,5,STONE)
Block(-10,17,6,STONE)
Block(-10,17,7,STONE)
Block(-10,17,8,STONE)
Block(-10,17,9,STONE)
Block(-10,17,10,STONE)
Block(-10,17,11,STONE)
Block(-10,17,12,STONE)
Block(-10,17,13,STONE)
Block(-10,17,14,STONE)
Block(-10,17,15,STONE)
Block(-10,18,-6,STONE)
Block(-10,18,-5,STONE)
Block(-10,18,-4,STONE)
Block(-10,18,-3,STONE)
Block(-10,18,-2,STONE)
Block(-10,18,-1,STONE)
Block(-10,18,0,STONE)
Block(-10,18,1,STONE)
Block(-10,18,2,STONE)
Block(-10,18,3,STONE)
Block(-10,18,4,STONE)
Block(-10,18,5,STONE)
Block(-10,18,6,STONE)
Block(-10,18,7,STONE)
Block(-10,18,8,STONE)
Block(-10,18,9,STONE)
Block(-10,18,10,STONE)
Block(-10,18,11,STONE)
Block(-10,18,12,STONE)
Block(-10,18,13,STONE)
Block(-10,18,14,STONE)
Block(-10,18,15,STONE)
Block(-10,18,16,STONE)
Block(-10,19,-6,STONE)
Block(-10,19,-5,STONE)
Block(-10,19,-4,STONE)
Block(-10,19,-3,STONE)
Block(-10,19,-2,STONE)
Block(-10,19,-1,STONE)
Block(-10,19,0,STONE)
Block(-10,19,1,STONE)
Block(-10,19,2,STONE)
Block(-10,19,3,STONE)
Block(-10,19,4,STONE)
Block(-10,19,5,STONE)
Block(-10,19,6,STONE)
Block(-10,19,7,STONE)
Block(-10,19,8,STONE)
Block(-10,19,9,STONE)
Block(-10,19,10,STONE)
Block(-10,19,11,STONE)
Block(-10,19,12,STONE)
Block(-10,19,13,STONE)
Block(-10,19,14,STONE)
Block(-10,19,15,STONE)
Block(-10,19,16,STONE)
Block(-10,20,-5,STONE)
Block(-10,20,-4,STONE)
Block(-10,20,-3,STONE)
Block(-10,20,-2,STONE)
Block(-10,20,-1,STONE)
Block(-10,20,0,STONE)
Block(-10,20,1,STONE)
Block(-10,20,2,STONE)
Block(-10,20,3,STONE)
Block(-10,20,4,STONE)
Block(-10,20,5,STONE)
Block(-10,20,6,STONE)
Block(-10,20,7,STONE)
Block(-10,20,8,STONE)
Block(-10,20,9,STONE)
Block(-10,20,10,STONE)
Block(-10,20,11,STONE)
Block(-10,20,12,STONE)
Block(-10,20,13,STONE)
Block(-10,20,14,STONE)
Block(-10,20,15,STONE)
Block(-10,20,16,STONE)
Block(-10,20,17,STONE)
Block(-10,21,-4,STONE)
Block(-10,21,-3,STONE)
Block(-10,21,-2,STONE)
Block(-10,21,-1,STONE)
Block(-10,21,0,STONE)
Block(-10,21,1,STONE)
Block(-10,21,2,STONE)
Block(-10,21,3,STONE)
Block(-10,21,4,STONE)
Block(-10,21,5,STONE)
Block(-10,21,6,STONE)
Block(-10,21,7,STONE)
Block(-10,21,8,STONE)
Block(-10,21,9,STONE)
Block(-10,21,10,STONE)
Block(-10,21,11,STONE)
Block(-10,21,12,STONE)
Block(-10,21,13,STONE)
Block(-10,21,14,STONE)
Block(-10,21,15,STONE)
Block(-10,21,16,STONE)
Block(-10,21,17,STONE)
Block(-10,22,-4,STONE)
Block(-10,22,-3,STONE)
Block(-10,22,-2,STONE)
Block(-10,22,-1,STONE)
Block(-10,22,0,STONE)
Block(-10,22,1,STONE)
Block(-10,22,2,STONE)
Block(-10,22,3,STONE)
Block(-10,22,4,STONE)
Block(-10,22,5,STONE)
Block(-10,22,6,STONE)
Block(-10,22,7,STONE)
Block(-10,22,8,STONE)
Block(-10,22,9,STONE)
Block(-10,22,10,STONE)
Block(-10,22,11,STONE)
Block(-10,22,12,STONE)
Block(-10,22,13,STONE)
Block(-10,22,14,STONE)
Block(-10,22,15,STONE)
Block(-10,22,16,STONE)
Block(-10,23,-4,STONE)
Block(-10,23,-3,STONE)
Block(-10,23,-2,STONE)
Block(-10,23,-1,STONE)
Block(-10,23,0,STONE)
Block(-10,23,1,STONE)
Block(-10,23,2,STONE)
Block(-10,23,3,STONE)
Block(-10,23,4,STONE)
Block(-10,23,5,STONE)
Block(-10,23,6,STONE)
Block(-10,23,7,STONE)
Block(-10,23,8,STONE)
Block(-10,23,9,STONE)
Block(-10,23,10,STONE)
Block(-10,23,11,STONE)
Block(-10,23,12,STONE)
Block(-10,23,13,STONE)
Block(-10,23,14,STONE)
Block(-10,23,15,STONE)
Block(-10,24,-3,STONE)
Block(-10,24,-2,STONE)
Block(-10,24,-1,STONE)
Block(-10,24,0,STONE)
Block(-10,24,1,STONE)
Block(-10,24,2,STONE)
Block(-10,24,3,STONE)
Block(-10,24,4,STONE)
Block(-10,24,5,STONE)
Block(-10,24,6,STONE)
Block(-10,24,7,STONE)
Block(-10,24,8,STONE)
Block(-10,24,9,STONE)
Block(-10,24,10,STONE)
Block(-10,24,11,STONE)
Block(-10,24,12,STONE)
Block(-10,24,13,STONE)
Block(-10,24,14,STONE)
Block(-10,25,-3,STONE)
Block(-10,25,-2,STONE)
Block(-10,25,-1,STONE)
Block(-10,25,0,STONE)
Block(-10,25,1,STONE)
Block(-10,25,2,STONE)
Block(-10,25,3,STONE)
Block(-10,25,4,STONE)
Block(-10,25,5,STONE)
Block(-10,25,6,STONE)
Block(-10,25,7,STONE)
Block(-10,25,8,STONE)
Block(-10,25,9,STONE)
Block(-10,25,10,STONE)
Block(-10,25,11,STONE)
Block(-10,25,12,STONE)
Block(-10,25,13,STONE)
Block(-10,25,14,STONE)
Block(-10,26,-2,STONE)
Block(-10,26,-1,STONE)
Block(-10,26,0,STONE)
Block(-10,26,1,STONE)
Block(-10,26,2,STONE)
Block(-10,26,3,STONE)
Block(-10,26,4,STONE)
Block(-10,26,5,STONE)
Block(-10,26,6,STONE)
Block(-10,26,7,STONE)
Block(-10,26,8,STONE)
Block(-10,26,9,STONE)
Block(-10,26,10,STONE)
Block(-10,26,11,STONE)
Block(-10,26,12,STONE)
Block(-10,26,13,STONE)
Block(-10,27,-2,STONE)
Block(-10,27,-1,STONE)
Block(-10,27,0,STONE)
Block(-10,27,1,STONE)
Block(-10,27,2,STONE)
Block(-10,27,3,STONE)
Block(-10,27,4,STONE)
Block(-10,27,5,STONE)
Block(-10,27,6,STONE)
Block(-10,27,7,STONE)
Block(-10,27,8,STONE)
Block(-10,27,9,STONE)
Block(-10,27,10,STONE)
Block(-10,27,11,STONE)
Block(-10,27,12,STONE)
Block(-10,28,-1,STONE)
Block(-10,28,0,STONE)
Block(-10,28,1,STONE)
Block(-10,28,2,STONE)
Block(-10,28,3,STONE)
Block(-10,28,4,STONE)
Block(-10,28,5,STONE)
Block(-10,28,6,STONE)
Block(-10,28,7,STONE)
Block(-10,28,8,STONE)
Block(-10,28,9,STONE)
Block(-10,28,10,STONE)
Block(-10,28,11,STONE)
Block(-10,29,1,STONE)
Block(-10,29,2,STONE)
Block(-10,29,3,STONE)
Block(-10,29,4,STONE)
Block(-10,29,5,STONE)
Block(-10,29,6,STONE)
Block(-10,29,7,STONE)
Block(-10,29,8,STONE)
Block(-10,29,9,STONE)
Block(-10,29,10,STONE)
Block(-10,29,11,STONE)
Block(-10,30,3,STONE)
Block(-10,30,4,STONE)
Block(-10,30,5,STONE)
Block(-10,30,6,STONE)
Block(-10,30,7,STONE)
Block(-10,30,8,STONE)
Block(-10,30,9,STONE)
Block(-10,31,4,STONE)
Block(-10,31,5,STONE)
Block(-10,31,6,STONE)
Block(-10,31,7,STONE)
Block(-10,31,8,STONE)
Block(-10,32,6,STONE)
Block(-10,32,7,STONE)
Block(-9,8,3,STONE)
Block(-9,8,4,STONE)
Block(-9,8,5,STONE)
Block(-9,8,6,STONE)
Block(-9,9,0,STONE)
Block(-9,9,1,STONE)
Block(-9,9,2,STONE)
Block(-9,9,3,STONE)
Block(-9,9,4,STONE)
Block(-9,9,5,STONE)
Block(-9,9,6,STONE)
Block(-9,9,7,STONE)
Block(-9,9,8,STONE)
Block(-9,10,-4,STONE)
Block(-9,10,-3,STONE)
Block(-9,10,-2,STONE)
Block(-9,10,-1,STONE)
Block(-9,10,0,STONE)
Block(-9,10,1,STONE)
Block(-9,10,2,STONE)
Block(-9,10,3,STONE)
Block(-9,10,4,STONE)
Block(-9,10,5,STONE)
Block(-9,10,6,STONE)
Block(-9,10,7,STONE)
Block(-9,10,8,STONE)
Block(-9,11,-8,STONE)
Block(-9,11,-7,STONE)
Block(-9,11,-6,STONE)
Block(-9,11,-5,STONE)
Block(-9,11,-4,STONE)
Block(-9,11,-3,STONE)
Block(-9,11,-2,STONE)
Block(-9,11,-1,STONE)
Block(-9,11,0,STONE)
Block(-9,11,1,STONE)
Block(-9,11,2,STONE)
Block(-9,11,3,STONE)
Block(-9,11,4,STONE)
Block(-9,11,5,STONE)
Block(-9,11,6,STONE)
Block(-9,11,7,STONE)
Block(-9,11,8,STONE)
Block(-9,11,9,STONE)
Block(-9,11,10,STONE)
Block(-9,12,-8,STONE)
Block(-9,12,-7,STONE)
Block(-9,12,-6,STONE)
Block(-9,12,-5,STONE)
Block(-9,12,-4,STONE)
Block(-9,12,-3,STONE)
Block(-9,12,-2,STONE)
Block(-9,12,-1,STONE)
Block(-9,12,0,STONE)
Block(-9,12,1,STONE)
Block(-9,12,2,STONE)
Block(-9,12,3,STONE)
Block(-9,12,4,STONE)
Block(-9,12,5,STONE)
Block(-9,12,6,STONE)
Block(-9,12,7,STONE)
Block(-9,12,8,STONE)
Block(-9,12,9,STONE)
Block(-9,12,10,STONE)
Block(-9,12,11,STONE)
Block(-9,12,12,STONE)
Block(-9,13,-9,STONE)
Block(-9,13,-8,STONE)
Block(-9,13,-7,STONE)
Block(-9,13,-6,STONE)
Block(-9,13,-5,STONE)
Block(-9,13,-4,STONE)
Block(-9,13,-3,STONE)
Block(-9,13,-2,STONE)
Block(-9,13,-1,STONE)
Block(-9,13,0,STONE)
Block(-9,13,1,STONE)
Block(-9,13,2,STONE)
Block(-9,13,3,STONE)
Block(-9,13,4,STONE)
Block(-9,13,5,STONE)
Block(-9,13,6,STONE)
Block(-9,13,7,STONE)
Block(-9,13,8,STONE)
Block(-9,13,9,STONE)
Block(-9,13,10,STONE)
Block(-9,13,11,STONE)
Block(-9,13,12,STONE)
Block(-9,13,13,STONE)
Block(-9,13,14,STONE)
Block(-9,14,-9,STONE)
Block(-9,14,-8,STONE)
Block(-9,14,-7,STONE)
Block(-9,14,-6,STONE)
Block(-9,14,-5,STONE)
Block(-9,14,-4,STONE)
Block(-9,14,-3,STONE)
Block(-9,14,-2,STONE)
Block(-9,14,-1,STONE)
Block(-9,14,0,STONE)
Block(-9,14,1,STONE)
Block(-9,14,2,STONE)
Block(-9,14,3,STONE)
Block(-9,14,4,STONE)
Block(-9,14,5,STONE)
Block(-9,14,6,STONE)
Block(-9,14,7,STONE)
Block(-9,14,8,STONE)
Block(-9,14,9,STONE)
Block(-9,14,10,STONE)
Block(-9,14,11,STONE)
Block(-9,14,12,STONE)
Block(-9,14,13,STONE)
Block(-9,14,14,STONE)
Block(-9,14,15,STONE)
Block(-9,14,16,STONE)
Block(-9,14,17,STONE)
Block(-9,15,-9,STONE)
Block(-9,15,-8,STONE)
Block(-9,15,-7,STONE)
Block(-9,15,-6,STONE)
Block(-9,15,-5,STONE)
Block(-9,15,-4,STONE)
Block(-9,15,-3,STONE)
Block(-9,15,-2,STONE)
Block(-9,15,-1,STONE)
Block(-9,15,0,STONE)
Block(-9,15,1,STONE)
Block(-9,15,2,STONE)
Block(-9,15,3,STONE)
Block(-9,15,4,STONE)
Block(-9,15,5,STONE)
Block(-9,15,6,STONE)
Block(-9,15,7,STONE)
Block(-9,15,8,STONE)
Block(-9,15,9,STONE)
Block(-9,15,10,STONE)
Block(-9,15,11,STONE)
Block(-9,15,12,STONE)
Block(-9,15,13,STONE)
Block(-9,15,14,STONE)
Block(-9,15,15,STONE)
Block(-9,15,16,STONE)
Block(-9,15,17,STONE)
Block(-9,16,-8,STONE)
Block(-9,16,-7,STONE)
Block(-9,16,-6,STONE)
Block(-9,16,-5,STONE)
Block(-9,16,-4,STONE)
Block(-9,16,-3,STONE)
Block(-9,16,-2,STONE)
Block(-9,16,-1,STONE)
Block(-9,16,0,STONE)
Block(-9,16,1,STONE)
Block(-9,16,2,STONE)
Block(-9,16,3,STONE)
Block(-9,16,4,STONE)
Block(-9,16,5,STONE)
Block(-9,16,6,STONE)
Block(-9,16,7,STONE)
Block(-9,16,8,STONE)
Block(-9,16,9,STONE)
Block(-9,16,10,STONE)
Block(-9,16,11,STONE)
Block(-9,16,12,STONE)
Block(-9,16,13,STONE)
Block(-9,16,14,STONE)
Block(-9,16,15,STONE)
Block(-9,16,16,STONE)
Block(-9,16,17,STONE)
Block(-9,16,18,STONE)
Block(-9,17,-8,STONE)
Block(-9,17,-7,STONE)
Block(-9,17,-6,STONE)
Block(-9,17,-5,STONE)
Block(-9,17,-4,STONE)
Block(-9,17,-3,STONE)
Block(-9,17,-2,STONE)
Block(-9,17,-1,STONE)
Block(-9,17,0,STONE)
Block(-9,17,1,STONE)
Block(-9,17,2,STONE)
Block(-9,17,3,STONE)
Block(-9,17,4,STONE)
Block(-9,17,5,STONE)
Block(-9,17,6,STONE)
Block(-9,17,7,STONE)
Block(-9,17,8,STONE)
Block(-9,17,9,STONE)
Block(-9,17,10,STONE)
Block(-9,17,11,STONE)
Block(-9,17,12,STONE)
Block(-9,17,13,STONE)
Block(-9,17,14,STONE)
Block(-9,17,15,STONE)
Block(-9,17,16,STONE)
Block(-9,17,17,STONE)
Block(-9,17,18,STONE)
Block(-9,18,-7,STONE)
Block(-9,18,-6,STONE)
Block(-9,18,-5,STONE)
Block(-9,18,-4,STONE)
Block(-9,18,-3,STONE)
Block(-9,18,-2,STONE)
Block(-9,18,-1,STONE)
Block(-9,18,0,STONE)
Block(-9,18,1,STONE)
Block(-9,18,2,STONE)
Block(-9,18,3,STONE)
Block(-9,18,4,STONE)
Block(-9,18,5,STONE)
Block(-9,18,6,STONE)
Block(-9,18,7,STONE)
Block(-9,18,8,STONE)
Block(-9,18,9,STONE)
Block(-9,18,10,STONE)
Block(-9,18,11,STONE)
Block(-9,18,12,STONE)
Block(-9,18,13,STONE)
Block(-9,18,14,STONE)
Block(-9,18,15,STONE)
Block(-9,18,16,STONE)
Block(-9,18,17,STONE)
Block(-9,18,18,STONE)
Block(-9,19,-6,STONE)
Block(-9,19,-5,STONE)
Block(-9,19,-4,STONE)
Block(-9,19,-3,STONE)
Block(-9,19,-2,STONE)
Block(-9,19,-1,STONE)
Block(-9,19,0,STONE)
Block(-9,19,1,STONE)
Block(-9,19,2,STONE)
Block(-9,19,3,STONE)
Block(-9,19,4,STONE)
Block(-9,19,5,STONE)
Block(-9,19,6,STONE)
Block(-9,19,7,STONE)
Block(-9,19,8,STONE)
Block(-9,19,9,STONE)
Block(-9,19,10,STONE)
Block(-9,19,11,STONE)
Block(-9,19,12,STONE)
Block(-9,19,13,STONE)
Block(-9,19,14,STONE)
Block(-9,19,15,STONE)
Block(-9,19,16,STONE)
Block(-9,19,17,STONE)
Block(-9,19,18,STONE)
Block(-9,20,-5,STONE)
Block(-9,20,-4,STONE)
Block(-9,20,-3,STONE)
Block(-9,20,-2,STONE)
Block(-9,20,-1,STONE)
Block(-9,20,0,STONE)
Block(-9,20,1,STONE)
Block(-9,20,2,STONE)
Block(-9,20,3,STONE)
Block(-9,20,4,STONE)
Block(-9,20,5,STONE)
Block(-9,20,6,STONE)
Block(-9,20,7,STONE)
Block(-9,20,8,STONE)
Block(-9,20,9,STONE)
Block(-9,20,10,STONE)
Block(-9,20,11,STONE)
Block(-9,20,12,STONE)
Block(-9,20,13,STONE)
Block(-9,20,14,STONE)
Block(-9,20,15,STONE)
Block(-9,20,16,STONE)
Block(-9,20,17,STONE)
Block(-9,20,18,STONE)
Block(-9,20,19,STONE)
Block(-9,21,-5,STONE)
Block(-9,21,-4,STONE)
Block(-9,21,-3,STONE)
Block(-9,21,-2,STONE)
Block(-9,21,-1,STONE)
Block(-9,21,0,STONE)
Block(-9,21,1,STONE)
Block(-9,21,2,STONE)
Block(-9,21,3,STONE)
Block(-9,21,4,STONE)
Block(-9,21,5,STONE)
Block(-9,21,6,STONE)
Block(-9,21,7,STONE)
Block(-9,21,8,STONE)
Block(-9,21,9,STONE)
Block(-9,21,10,STONE)
Block(-9,21,11,STONE)
Block(-9,21,12,STONE)
Block(-9,21,13,STONE)
Block(-9,21,14,STONE)
Block(-9,21,15,STONE)
Block(-9,21,16,STONE)
Block(-9,21,17,STONE)
Block(-9,21,18,STONE)
Block(-9,21,19,STONE)
Block(-9,22,-4,STONE)
Block(-9,22,-3,STONE)
Block(-9,22,-2,STONE)
Block(-9,22,-1,STONE)
Block(-9,22,0,STONE)
Block(-9,22,1,STONE)
Block(-9,22,2,STONE)
Block(-9,22,3,STONE)
Block(-9,22,4,STONE)
Block(-9,22,5,STONE)
Block(-9,22,6,STONE)
Block(-9,22,7,STONE)
Block(-9,22,8,STONE)
Block(-9,22,9,STONE)
Block(-9,22,10,STONE)
Block(-9,22,11,STONE)
Block(-9,22,12,STONE)
Block(-9,22,13,STONE)
Block(-9,22,14,STONE)
Block(-9,22,15,STONE)
Block(-9,22,16,STONE)
Block(-9,22,17,STONE)
Block(-9,22,18,STONE)
Block(-9,23,-4,STONE)
Block(-9,23,-3,STONE)
Block(-9,23,-2,STONE)
Block(-9,23,-1,STONE)
Block(-9,23,0,STONE)
Block(-9,23,1,STONE)
Block(-9,23,2,STONE)
Block(-9,23,3,STONE)
Block(-9,23,4,STONE)
Block(-9,23,5,STONE)
Block(-9,23,6,STONE)
Block(-9,23,7,STONE)
Block(-9,23,8,STONE)
Block(-9,23,9,STONE)
Block(-9,23,10,STONE)
Block(-9,23,11,STONE)
Block(-9,23,12,STONE)
Block(-9,23,13,STONE)
Block(-9,23,14,STONE)
Block(-9,23,15,STONE)
Block(-9,23,16,STONE)
Block(-9,23,17,STONE)
Block(-9,24,-4,STONE)
Block(-9,24,-3,STONE)
Block(-9,24,-2,STONE)
Block(-9,24,-1,STONE)
Block(-9,24,0,STONE)
Block(-9,24,1,STONE)
Block(-9,24,2,STONE)
Block(-9,24,3,STONE)
Block(-9,24,4,STONE)
Block(-9,24,5,STONE)
Block(-9,24,6,STONE)
Block(-9,24,7,STONE)
Block(-9,24,8,STONE)
Block(-9,24,9,STONE)
Block(-9,24,10,STONE)
Block(-9,24,11,STONE)
Block(-9,24,12,STONE)
Block(-9,24,13,STONE)
Block(-9,24,14,STONE)
Block(-9,24,15,STONE)
Block(-9,24,16,STONE)
Block(-9,25,-3,STONE)
Block(-9,25,-2,STONE)
Block(-9,25,-1,STONE)
Block(-9,25,0,STONE)
Block(-9,25,1,STONE)
Block(-9,25,2,STONE)
Block(-9,25,3,STONE)
Block(-9,25,4,STONE)
Block(-9,25,5,STONE)
Block(-9,25,6,STONE)
Block(-9,25,7,STONE)
Block(-9,25,8,STONE)
Block(-9,25,9,STONE)
Block(-9,25,10,STONE)
Block(-9,25,11,STONE)
Block(-9,25,12,STONE)
Block(-9,25,13,STONE)
Block(-9,25,14,STONE)
Block(-9,25,15,STONE)
Block(-9,26,-2,STONE)
Block(-9,26,-1,STONE)
Block(-9,26,0,STONE)
Block(-9,26,1,STONE)
Block(-9,26,2,STONE)
Block(-9,26,3,STONE)
Block(-9,26,4,STONE)
Block(-9,26,5,STONE)
Block(-9,26,6,STONE)
Block(-9,26,7,STONE)
Block(-9,26,8,STONE)
Block(-9,26,9,STONE)
Block(-9,26,10,STONE)
Block(-9,26,11,STONE)
Block(-9,26,12,STONE)
Block(-9,26,13,STONE)
Block(-9,26,14,STONE)
Block(-9,27,-2,STONE)
Block(-9,27,-1,STONE)
Block(-9,27,0,STONE)
Block(-9,27,1,STONE)
Block(-9,27,2,STONE)
Block(-9,27,3,STONE)
Block(-9,27,4,STONE)
Block(-9,27,5,STONE)
Block(-9,27,6,STONE)
Block(-9,27,7,STONE)
Block(-9,27,8,STONE)
Block(-9,27,9,STONE)
Block(-9,27,10,STONE)
Block(-9,27,11,STONE)
Block(-9,27,12,STONE)
Block(-9,27,13,STONE)
Block(-9,28,-1,STONE)
Block(-9,28,0,STONE)
Block(-9,28,1,STONE)
Block(-9,28,2,STONE)
Block(-9,28,3,STONE)
Block(-9,28,4,STONE)
Block(-9,28,5,STONE)
Block(-9,28,6,STONE)
Block(-9,28,7,STONE)
Block(-9,28,8,STONE)
Block(-9,28,9,STONE)
Block(-9,28,10,STONE)
Block(-9,28,11,STONE)
Block(-9,28,12,STONE)
Block(-9,29,0,STONE)
Block(-9,29,1,STONE)
Block(-9,29,2,STONE)
Block(-9,29,3,STONE)
Block(-9,29,4,STONE)
Block(-9,29,5,STONE)
Block(-9,29,6,STONE)
Block(-9,29,7,STONE)
Block(-9,29,8,STONE)
Block(-9,29,9,STONE)
Block(-9,29,10,STONE)
Block(-9,29,11,STONE)
Block(-9,30,2,STONE)
Block(-9,30,3,STONE)
Block(-9,30,4,STONE)
Block(-9,30,5,STONE)
Block(-9,30,6,STONE)
Block(-9,30,7,STONE)
Block(-9,30,8,STONE)
Block(-9,30,9,STONE)
Block(-9,30,10,STONE)
Block(-9,31,4,STONE)
Block(-9,31,5,STONE)
Block(-9,31,6,STONE)
Block(-9,31,7,STONE)
Block(-9,31,8,STONE)
Block(-9,32,5,STONE)
Block(-9,32,6,STONE)
Block(-9,32,7,STONE)
Block(-8,8,3,STONE)
Block(-8,8,4,STONE)
Block(-8,8,5,STONE)
Block(-8,8,6,STONE)
Block(-8,8,7,STONE)
Block(-8,9,0,STONE)
Block(-8,9,1,STONE)
Block(-8,9,2,STONE)
Block(-8,9,3,STONE)
Block(-8,9,4,STONE)
Block(-8,9,5,STONE)
Block(-8,9,6,STONE)
Block(-8,9,7,STONE)
Block(-8,9,8,STONE)
Block(-8,9,9,STONE)
Block(-8,10,-5,STONE)
Block(-8,10,-4,STONE)
Block(-8,10,-3,STONE)
Block(-8,10,-2,STONE)
Block(-8,10,-1,STONE)
Block(-8,10,0,STONE)
Block(-8,10,1,STONE)
Block(-8,10,2,STONE)
Block(-8,10,3,STONE)
Block(-8,10,4,STONE)
Block(-8,10,5,STONE)
Block(-8,10,6,STONE)
Block(-8,10,7,STONE)
Block(-8,10,8,STONE)
Block(-8,10,9,STONE)
Block(-8,10,10,STONE)
Block(-8,11,-9,STONE)
Block(-8,11,-8,STONE)
Block(-8,11,-7,STONE)
Block(-8,11,-6,STONE)
Block(-8,11,-5,STONE)
Block(-8,11,-4,STONE)
Block(-8,11,-3,STONE)
Block(-8,11,-2,STONE)
Block(-8,11,-1,STONE)
Block(-8,11,0,STONE)
Block(-8,11,1,STONE)
Block(-8,11,2,STONE)
Block(-8,11,3,STONE)
Block(-8,11,4,STONE)
Block(-8,11,5,STONE)
Block(-8,11,6,STONE)
Block(-8,11,7,STONE)
Block(-8,11,8,STONE)
Block(-8,11,9,STONE)
Block(-8,11,10,STONE)
Block(-8,11,11,STONE)
Block(-8,11,12,STONE)
Block(-8,12,-9,STONE)
Block(-8,12,-8,STONE)
Block(-8,12,-7,STONE)
Block(-8,12,-6,STONE)
Block(-8,12,-5,STONE)
Block(-8,12,-4,STONE)
Block(-8,12,-3,STONE)
Block(-8,12,-2,STONE)
Block(-8,12,-1,STONE)
Block(-8,12,0,STONE)
Block(-8,12,1,STONE)
Block(-8,12,2,STONE)
Block(-8,12,3,STONE)
Block(-8,12,4,STONE)
Block(-8,12,5,STONE)
Block(-8,12,6,STONE)
Block(-8,12,7,STONE)
Block(-8,12,8,STONE)
Block(-8,12,9,STONE)
Block(-8,12,10,STONE)
Block(-8,12,11,STONE)
Block(-8,12,12,STONE)
Block(-8,12,13,STONE)
Block(-8,12,14,STONE)
Block(-8,13,-9,STONE)
Block(-8,13,-8,STONE)
Block(-8,13,-7,STONE)
Block(-8,13,-6,STONE)
Block(-8,13,-5,STONE)
Block(-8,13,-4,STONE)
Block(-8,13,-3,STONE)
Block(-8,13,-2,STONE)
Block(-8,13,-1,STONE)
Block(-8,13,0,STONE)
Block(-8,13,1,STONE)
Block(-8,13,2,STONE)
Block(-8,13,3,STONE)
Block(-8,13,4,STONE)
Block(-8,13,5,STONE)
Block(-8,13,6,STONE)
Block(-8,13,7,STONE)
Block(-8,13,8,STONE)
Block(-8,13,9,STONE)
Block(-8,13,10,STONE)
Block(-8,13,11,STONE)
Block(-8,13,12,STONE)
Block(-8,13,13,STONE)
Block(-8,13,14,STONE)
Block(-8,13,15,STONE)
Block(-8,13,16,STONE)
Block(-8,13,17,STONE)
Block(-8,13,18,STONE)
Block(-8,13,19,STONE)
Block(-8,14,-9,STONE)
Block(-8,14,-8,STONE)
Block(-8,14,-7,STONE)
Block(-8,14,-6,STONE)
Block(-8,14,-5,STONE)
Block(-8,14,-4,STONE)
Block(-8,14,-3,STONE)
Block(-8,14,-2,STONE)
Block(-8,14,-1,STONE)
Block(-8,14,0,STONE)
Block(-8,14,1,STONE)
Block(-8,14,2,STONE)
Block(-8,14,3,STONE)
Block(-8,14,4,STONE)
Block(-8,14,5,STONE)
Block(-8,14,6,STONE)
Block(-8,14,7,STONE)
Block(-8,14,8,STONE)
Block(-8,14,9,STONE)
Block(-8,14,10,STONE)
Block(-8,14,11,STONE)
Block(-8,14,12,STONE)
Block(-8,14,13,STONE)
Block(-8,14,14,STONE)
Block(-8,14,15,STONE)
Block(-8,14,16,STONE)
Block(-8,14,17,STONE)
Block(-8,14,18,STONE)
Block(-8,14,19,STONE)
Block(-8,15,-9,STONE)
Block(-8,15,-8,STONE)
Block(-8,15,-7,STONE)
Block(-8,15,-6,STONE)
Block(-8,15,-5,STONE)
Block(-8,15,-4,STONE)
Block(-8,15,-3,STONE)
Block(-8,15,-2,STONE)
Block(-8,15,-1,STONE)
Block(-8,15,0,STONE)
Block(-8,15,1,STONE)
Block(-8,15,2,STONE)
Block(-8,15,3,STONE)
Block(-8,15,4,STONE)
Block(-8,15,5,STONE)
Block(-8,15,6,STONE)
Block(-8,15,7,STONE)
Block(-8,15,8,STONE)
Block(-8,15,9,STONE)
Block(-8,15,10,STONE)
Block(-8,15,11,STONE)
Block(-8,15,12,STONE)
Block(-8,15,13,STONE)
Block(-8,15,14,STONE)
Block(-8,15,15,STONE)
Block(-8,15,16,STONE)
Block(-8,15,17,STONE)
Block(-8,15,18,STONE)
Block(-8,15,19,STONE)
Block(-8,16,-8,STONE)
Block(-8,16,-7,STONE)
Block(-8,16,-6,STONE)
Block(-8,16,-5,STONE)
Block(-8,16,-4,STONE)
Block(-8,16,-3,STONE)
Block(-8,16,-2,STONE)
Block(-8,16,-1,STONE)
Block(-8,16,0,STONE)
Block(-8,16,1,STONE)
Block(-8,16,2,STONE)
Block(-8,16,3,STONE)
Block(-8,16,4,STONE)
Block(-8,16,5,STONE)
Block(-8,16,6,STONE)
Block(-8,16,7,STONE)
Block(-8,16,8,STONE)
Block(-8,16,9,STONE)
Block(-8,16,10,STONE)
Block(-8,16,11,STONE)
Block(-8,16,12,STONE)
Block(-8,16,13,STONE)
Block(-8,16,14,STONE)
Block(-8,16,15,STONE)
Block(-8,16,16,STONE)
Block(-8,16,17,STONE)
Block(-8,16,18,STONE)
Block(-8,16,19,STONE)
Block(-8,17,-8,STONE)
Block(-8,17,-7,STONE)
Block(-8,17,-6,STONE)
Block(-8,17,-5,STONE)
Block(-8,17,-4,STONE)
Block(-8,17,-3,STONE)
Block(-8,17,-2,STONE)
Block(-8,17,-1,STONE)
Block(-8,17,0,STONE)
Block(-8,17,1,STONE)
Block(-8,17,2,STONE)
Block(-8,17,3,STONE)
Block(-8,17,4,STONE)
Block(-8,17,5,STONE)
Block(-8,17,6,STONE)
Block(-8,17,7,STONE)
Block(-8,17,8,STONE)
Block(-8,17,9,STONE)
Block(-8,17,10,STONE)
Block(-8,17,11,STONE)
Block(-8,17,12,STONE)
Block(-8,17,13,STONE)
Block(-8,17,14,STONE)
Block(-8,17,15,STONE)
Block(-8,17,16,STONE)
Block(-8,17,17,STONE)
Block(-8,17,18,STONE)
Block(-8,17,19,STONE)
Block(-8,18,-7,STONE)
Block(-8,18,-6,STONE)
Block(-8,18,-5,STONE)
Block(-8,18,-4,STONE)
Block(-8,18,-3,STONE)
Block(-8,18,-2,STONE)
Block(-8,18,-1,STONE)
Block(-8,18,0,STONE)
Block(-8,18,1,STONE)
Block(-8,18,2,STONE)
Block(-8,18,3,STONE)
Block(-8,18,4,STONE)
Block(-8,18,5,STONE)
Block(-8,18,6,STONE)
Block(-8,18,7,STONE)
Block(-8,18,8,STONE)
Block(-8,18,9,STONE)
Block(-8,18,10,STONE)
Block(-8,18,11,STONE)
Block(-8,18,12,STONE)
Block(-8,18,13,STONE)
Block(-8,18,14,STONE)
Block(-8,18,15,STONE)
Block(-8,18,16,STONE)
Block(-8,18,17,STONE)
Block(-8,18,18,STONE)
Block(-8,18,19,STONE)
Block(-8,19,-7,STONE)
Block(-8,19,-6,STONE)
Block(-8,19,-5,STONE)
Block(-8,19,-4,STONE)
Block(-8,19,-3,STONE)
Block(-8,19,-2,STONE)
Block(-8,19,-1,STONE)
Block(-8,19,0,STONE)
Block(-8,19,1,STONE)
Block(-8,19,2,STONE)
Block(-8,19,3,STONE)
Block(-8,19,4,STONE)
Block(-8,19,5,STONE)
Block(-8,19,6,STONE)
Block(-8,19,7,STONE)
Block(-8,19,8,STONE)
Block(-8,19,9,STONE)
Block(-8,19,10,STONE)
Block(-8,19,11,STONE)
Block(-8,19,12,STONE)
Block(-8,19,13,STONE)
Block(-8,19,14,STONE)
Block(-8,19,15,STONE)
Block(-8,19,16,STONE)
Block(-8,19,17,STONE)
Block(-8,19,18,STONE)
Block(-8,19,19,STONE)
Block(-8,20,-6,STONE)
Block(-8,20,-5,STONE)
Block(-8,20,-4,STONE)
Block(-8,20,-3,STONE)
Block(-8,20,-2,STONE)
Block(-8,20,-1,STONE)
Block(-8,20,0,STONE)
Block(-8,20,1,STONE)
Block(-8,20,2,STONE)
Block(-8,20,3,STONE)
Block(-8,20,4,STONE)
Block(-8,20,5,STONE)
Block(-8,20,6,STONE)
Block(-8,20,7,STONE)
Block(-8,20,8,STONE)
Block(-8,20,9,STONE)
Block(-8,20,10,STONE)
Block(-8,20,11,STONE)
Block(-8,20,12,STONE)
Block(-8,20,13,STONE)
Block(-8,20,14,STONE)
Block(-8,20,15,STONE)
Block(-8,20,16,STONE)
Block(-8,20,17,STONE)
Block(-8,20,18,STONE)
Block(-8,20,19,STONE)
Block(-8,21,-5,STONE)
Block(-8,21,-4,STONE)
Block(-8,21,-3,STONE)
Block(-8,21,-2,STONE)
Block(-8,21,-1,STONE)
Block(-8,21,0,STONE)
Block(-8,21,1,STONE)
Block(-8,21,2,STONE)
Block(-8,21,3,STONE)
Block(-8,21,4,STONE)
Block(-8,21,5,STONE)
Block(-8,21,6,STONE)
Block(-8,21,7,STONE)
Block(-8,21,8,STONE)
Block(-8,21,9,STONE)
Block(-8,21,10,STONE)
Block(-8,21,11,STONE)
Block(-8,21,12,STONE)
Block(-8,21,13,STONE)
Block(-8,21,14,STONE)
Block(-8,21,15,STONE)
Block(-8,21,16,STONE)
Block(-8,21,17,STONE)
Block(-8,21,18,STONE)
Block(-8,21,19,STONE)
Block(-8,22,-4,STONE)
Block(-8,22,-3,STONE)
Block(-8,22,-2,STONE)
Block(-8,22,-1,STONE)
Block(-8,22,0,STONE)
Block(-8,22,1,STONE)
Block(-8,22,2,STONE)
Block(-8,22,3,STONE)
Block(-8,22,4,STONE)
Block(-8,22,5,STONE)
Block(-8,22,6,STONE)
Block(-8,22,7,STONE)
Block(-8,22,8,STONE)
Block(-8,22,9,STONE)
Block(-8,22,10,STONE)
Block(-8,22,11,STONE)
Block(-8,22,12,STONE)
Block(-8,22,13,STONE)
Block(-8,22,14,STONE)
Block(-8,22,15,STONE)
Block(-8,22,16,STONE)
Block(-8,22,17,STONE)
Block(-8,22,18,STONE)
Block(-8,22,19,STONE)
Block(-8,23,-4,STONE)
Block(-8,23,-3,STONE)
Block(-8,23,-2,STONE)
Block(-8,23,-1,STONE)
Block(-8,23,0,STONE)
Block(-8,23,1,STONE)
Block(-8,23,2,STONE)
Block(-8,23,3,STONE)
Block(-8,23,4,STONE)
Block(-8,23,5,STONE)
Block(-8,23,6,STONE)
Block(-8,23,7,STONE)
Block(-8,23,8,STONE)
Block(-8,23,9,STONE)
Block(-8,23,10,STONE)
Block(-8,23,11,STONE)
Block(-8,23,12,STONE)
Block(-8,23,13,STONE)
Block(-8,23,14,STONE)
Block(-8,23,15,STONE)
Block(-8,23,16,STONE)
Block(-8,23,17,STONE)
Block(-8,23,18,STONE)
Block(-8,24,-4,STONE)
Block(-8,24,-3,STONE)
Block(-8,24,-2,STONE)
Block(-8,24,-1,STONE)
Block(-8,24,0,STONE)
Block(-8,24,1,STONE)
Block(-8,24,2,STONE)
Block(-8,24,3,STONE)
Block(-8,24,4,STONE)
Block(-8,24,5,STONE)
Block(-8,24,6,STONE)
Block(-8,24,7,STONE)
Block(-8,24,8,STONE)
Block(-8,24,9,STONE)
Block(-8,24,10,STONE)
Block(-8,24,11,STONE)
Block(-8,24,12,STONE)
Block(-8,24,13,STONE)
Block(-8,24,14,STONE)
Block(-8,24,15,STONE)
Block(-8,24,16,STONE)
Block(-8,24,17,STONE)
Block(-8,25,-3,STONE)
Block(-8,25,-2,STONE)
Block(-8,25,-1,STONE)
Block(-8,25,0,STONE)
Block(-8,25,1,STONE)
Block(-8,25,2,STONE)
Block(-8,25,3,STONE)
Block(-8,25,4,STONE)
Block(-8,25,5,STONE)
Block(-8,25,6,STONE)
Block(-8,25,7,STONE)
Block(-8,25,8,STONE)
Block(-8,25,9,STONE)
Block(-8,25,10,STONE)
Block(-8,25,11,STONE)
Block(-8,25,12,STONE)
Block(-8,25,13,STONE)
Block(-8,25,14,STONE)
Block(-8,25,15,STONE)
Block(-8,25,16,STONE)
Block(-8,26,-2,STONE)
Block(-8,26,-1,STONE)
Block(-8,26,0,STONE)
Block(-8,26,1,STONE)
Block(-8,26,2,STONE)
Block(-8,26,3,STONE)
Block(-8,26,4,STONE)
Block(-8,26,5,STONE)
Block(-8,26,6,STONE)
Block(-8,26,7,STONE)
Block(-8,26,8,STONE)
Block(-8,26,9,STONE)
Block(-8,26,10,STONE)
Block(-8,26,11,STONE)
Block(-8,26,12,STONE)
Block(-8,26,13,STONE)
Block(-8,26,14,STONE)
Block(-8,26,15,STONE)
Block(-8,27,-2,STONE)
Block(-8,27,-1,STONE)
Block(-8,27,0,STONE)
Block(-8,27,1,STONE)
Block(-8,27,2,STONE)
Block(-8,27,3,STONE)
Block(-8,27,4,STONE)
Block(-8,27,5,STONE)
Block(-8,27,6,STONE)
Block(-8,27,7,STONE)
Block(-8,27,8,STONE)
Block(-8,27,9,STONE)
Block(-8,27,10,STONE)
Block(-8,27,11,STONE)
Block(-8,27,12,STONE)
Block(-8,27,13,STONE)
Block(-8,27,14,STONE)
Block(-8,28,-1,STONE)
Block(-8,28,0,STONE)
Block(-8,28,1,STONE)
Block(-8,28,2,STONE)
Block(-8,28,3,STONE)
Block(-8,28,4,STONE)
Block(-8,28,5,STONE)
Block(-8,28,6,STONE)
Block(-8,28,7,STONE)
Block(-8,28,8,STONE)
Block(-8,28,9,STONE)
Block(-8,28,10,STONE)
Block(-8,28,11,STONE)
Block(-8,28,12,STONE)
Block(-8,28,13,STONE)
Block(-8,29,0,STONE)
Block(-8,29,1,STONE)
Block(-8,29,2,STONE)
Block(-8,29,3,STONE)
Block(-8,29,4,STONE)
Block(-8,29,5,STONE)
Block(-8,29,6,STONE)
Block(-8,29,7,STONE)
Block(-8,29,8,STONE)
Block(-8,29,9,STONE)
Block(-8,29,10,STONE)
Block(-8,29,11,STONE)
Block(-8,29,12,STONE)
Block(-8,30,1,STONE)
Block(-8,30,2,STONE)
Block(-8,30,3,STONE)
Block(-8,30,4,STONE)
Block(-8,30,5,STONE)
Block(-8,30,6,STONE)
Block(-8,30,7,STONE)
Block(-8,30,8,STONE)
Block(-8,30,9,STONE)
Block(-8,30,10,STONE)
Block(-8,31,3,STONE)
Block(-8,31,4,STONE)
Block(-8,31,5,STONE)
Block(-8,31,6,STONE)
Block(-8,31,7,STONE)
Block(-8,31,8,STONE)
Block(-8,31,9,STONE)
Block(-8,32,5,STONE)
Block(-8,32,6,STONE)
Block(-8,32,7,STONE)
Block(-8,32,8,STONE)
Block(-8,33,6,STONE)
Block(-7,7,6,STONE)
Block(-7,8,3,STONE)
Block(-7,8,4,STONE)
Block(-7,8,5,STONE)
Block(-7,8,6,STONE)
Block(-7,8,7,STONE)
Block(-7,8,8,STONE)
Block(-7,9,0,STONE)
Block(-7,9,1,STONE)
Block(-7,9,2,STONE)
Block(-7,9,3,STONE)
Block(-7,9,4,STONE)
Block(-7,9,5,STONE)
Block(-7,9,6,STONE)
Block(-7,9,7,STONE)
Block(-7,9,8,STONE)
Block(-7,9,9,STONE)
Block(-7,9,10,STONE)
Block(-7,9,11,STONE)
Block(-7,10,-5,STONE)
Block(-7,10,-4,STONE)
Block(-7,10,-3,STONE)
Block(-7,10,-2,STONE)
Block(-7,10,-1,STONE)
Block(-7,10,0,STONE)
Block(-7,10,1,STONE)
Block(-7,10,2,STONE)
Block(-7,10,3,STONE)
Block(-7,10,4,STONE)
Block(-7,10,5,STONE)
Block(-7,10,6,STONE)
Block(-7,10,7,STONE)
Block(-7,10,8,STONE)
Block(-7,10,9,STONE)
Block(-7,10,10,STONE)
Block(-7,10,11,STONE)
Block(-7,10,12,STONE)
Block(-7,10,13,STONE)
Block(-7,11,-9,STONE)
Block(-7,11,-8,STONE)
Block(-7,11,-7,STONE)
Block(-7,11,-6,STONE)
Block(-7,11,-5,STONE)
Block(-7,11,-4,STONE)
Block(-7,11,-3,STONE)
Block(-7,11,-2,STONE)
Block(-7,11,-1,STONE)
Block(-7,11,0,STONE)
Block(-7,11,1,STONE)
Block(-7,11,2,STONE)
Block(-7,11,3,STONE)
Block(-7,11,4,STONE)
Block(-7,11,5,STONE)
Block(-7,11,6,STONE)
Block(-7,11,7,STONE)
Block(-7,11,8,STONE)
Block(-7,11,9,STONE)
Block(-7,11,10,STONE)
Block(-7,11,11,STONE)
Block(-7,11,12,STONE)
Block(-7,11,13,STONE)
Block(-7,11,14,STONE)
Block(-7,11,15,STONE)
Block(-7,12,-9,STONE)
Block(-7,12,-8,STONE)
Block(-7,12,-7,STONE)
Block(-7,12,-6,STONE)
Block(-7,12,-5,STONE)
Block(-7,12,-4,STONE)
Block(-7,12,-3,STONE)
Block(-7,12,-2,STONE)
Block(-7,12,-1,STONE)
Block(-7,12,0,STONE)
Block(-7,12,1,STONE)
Block(-7,12,2,STONE)
Block(-7,12,3,STONE)
Block(-7,12,4,STONE)
Block(-7,12,5,STONE)
Block(-7,12,6,STONE)
Block(-7,12,7,STONE)
Block(-7,12,8,STONE)
Block(-7,12,9,STONE)
Block(-7,12,10,STONE)
Block(-7,12,11,STONE)
Block(-7,12,12,STONE)
Block(-7,12,13,STONE)
Block(-7,12,14,STONE)
Block(-7,12,15,STONE)
Block(-7,12,16,STONE)
Block(-7,12,17,STONE)
Block(-7,12,18,STONE)
Block(-7,13,-9,STONE)
Block(-7,13,-8,STONE)
Block(-7,13,-7,STONE)
Block(-7,13,-6,STONE)
Block(-7,13,-5,STONE)
Block(-7,13,-4,STONE)
Block(-7,13,-3,STONE)
Block(-7,13,-2,STONE)
Block(-7,13,-1,STONE)
Block(-7,13,0,STONE)
Block(-7,13,1,STONE)
Block(-7,13,2,STONE)
Block(-7,13,3,STONE)
Block(-7,13,4,STONE)
Block(-7,13,5,STONE)
Block(-7,13,6,STONE)
Block(-7,13,7,STONE)
Block(-7,13,8,STONE)
Block(-7,13,9,STONE)
Block(-7,13,10,STONE)
Block(-7,13,11,STONE)
Block(-7,13,12,STONE)
Block(-7,13,13,STONE)
Block(-7,13,14,STONE)
Block(-7,13,15,STONE)
Block(-7,13,16,STONE)
Block(-7,13,17,STONE)
Block(-7,13,18,STONE)
Block(-7,13,19,STONE)
Block(-7,14,-9,STONE)
Block(-7,14,-8,STONE)
Block(-7,14,-7,STONE)
Block(-7,14,-6,STONE)
Block(-7,14,-5,STONE)
Block(-7,14,-4,STONE)
Block(-7,14,-3,STONE)
Block(-7,14,-2,STONE)
Block(-7,14,-1,STONE)
Block(-7,14,0,STONE)
Block(-7,14,1,STONE)
Block(-7,14,2,STONE)
Block(-7,14,3,STONE)
Block(-7,14,4,STONE)
Block(-7,14,5,STONE)
Block(-7,14,6,STONE)
Block(-7,14,7,STONE)
Block(-7,14,8,STONE)
Block(-7,14,9,STONE)
Block(-7,14,10,STONE)
Block(-7,14,11,STONE)
Block(-7,14,12,STONE)
Block(-7,14,13,STONE)
Block(-7,14,14,STONE)
Block(-7,14,15,STONE)
Block(-7,14,16,STONE)
Block(-7,14,17,STONE)
Block(-7,14,18,STONE)
Block(-7,14,19,STONE)
Block(-7,15,-9,STONE)
Block(-7,15,-8,STONE)
Block(-7,15,-7,STONE)
Block(-7,15,-6,STONE)
Block(-7,15,-5,STONE)
Block(-7,15,-4,STONE)
Block(-7,15,-3,STONE)
Block(-7,15,-2,STONE)
Block(-7,15,-1,STONE)
Block(-7,15,0,STONE)
Block(-7,15,1,STONE)
Block(-7,15,2,STONE)
Block(-7,15,3,STONE)
Block(-7,15,4,STONE)
Block(-7,15,5,STONE)
Block(-7,15,6,STONE)
Block(-7,15,7,STONE)
Block(-7,15,8,STONE)
Block(-7,15,9,STONE)
Block(-7,15,10,STONE)
Block(-7,15,11,STONE)
Block(-7,15,12,STONE)
Block(-7,15,13,STONE)
Block(-7,15,14,STONE)
Block(-7,15,15,STONE)
Block(-7,15,16,STONE)
Block(-7,15,17,STONE)
Block(-7,15,18,STONE)
Block(-7,15,19,STONE)
Block(-7,16,-8,STONE)
Block(-7,16,-7,STONE)
Block(-7,16,-6,STONE)
Block(-7,16,-5,STONE)
Block(-7,16,-4,STONE)
Block(-7,16,-3,STONE)
Block(-7,16,-2,STONE)
Block(-7,16,-1,STONE)
Block(-7,16,0,STONE)
Block(-7,16,1,STONE)
Block(-7,16,2,STONE)
Block(-7,16,3,STONE)
Block(-7,16,4,STONE)
Block(-7,16,5,STONE)
Block(-7,16,6,STONE)
Block(-7,16,7,STONE)
Block(-7,16,8,STONE)
Block(-7,16,9,STONE)
Block(-7,16,10,STONE)
Block(-7,16,11,STONE)
Block(-7,16,12,STONE)
Block(-7,16,13,STONE)
Block(-7,16,14,STONE)
Block(-7,16,15,STONE)
Block(-7,16,16,STONE)
Block(-7,16,17,STONE)
Block(-7,16,18,STONE)
Block(-7,16,19,STONE)
Block(-7,17,-8,STONE)
Block(-7,17,-7,STONE)
Block(-7,17,-6,STONE)
Block(-7,17,-5,STONE)
Block(-7,17,-4,STONE)
Block(-7,17,-3,STONE)
Block(-7,17,-2,STONE)
Block(-7,17,-1,STONE)
Block(-7,17,0,STONE)
Block(-7,17,1,STONE)
Block(-7,17,2,STONE)
Block(-7,17,3,STONE)
Block(-7,17,4,STONE)
Block(-7,17,5,STONE)
Block(-7,17,6,STONE)
Block(-7,17,7,STONE)
Block(-7,17,8,STONE)
Block(-7,17,9,STONE)
Block(-7,17,10,STONE)
Block(-7,17,11,STONE)
Block(-7,17,12,STONE)
Block(-7,17,13,STONE)
Block(-7,17,14,STONE)
Block(-7,17,15,STONE)
Block(-7,17,16,STONE)
Block(-7,17,17,STONE)
Block(-7,17,18,STONE)
Block(-7,17,19,STONE)
Block(-7,18,-7,STONE)
Block(-7,18,-6,STONE)
Block(-7,18,-5,STONE)
Block(-7,18,-4,STONE)
Block(-7,18,-3,STONE)
Block(-7,18,-2,STONE)
Block(-7,18,-1,STONE)
Block(-7,18,0,STONE)
Block(-7,18,1,STONE)
Block(-7,18,2,STONE)
Block(-7,18,3,STONE)
Block(-7,18,4,STONE)
Block(-7,18,5,STONE)
Block(-7,18,6,STONE)
Block(-7,18,7,STONE)
Block(-7,18,8,STONE)
Block(-7,18,9,STONE)
Block(-7,18,10,STONE)
Block(-7,18,11,STONE)
Block(-7,18,12,STONE)
Block(-7,18,13,STONE)
Block(-7,18,14,STONE)
Block(-7,18,15,STONE)
Block(-7,18,16,STONE)
Block(-7,18,17,STONE)
Block(-7,18,18,STONE)
Block(-7,18,19,STONE)
Block(-7,19,-7,STONE)
Block(-7,19,-6,STONE)
Block(-7,19,-5,STONE)
Block(-7,19,-4,STONE)
Block(-7,19,-3,STONE)
Block(-7,19,-2,STONE)
Block(-7,19,-1,STONE)
Block(-7,19,0,STONE)
Block(-7,19,1,STONE)
Block(-7,19,2,STONE)
Block(-7,19,3,STONE)
Block(-7,19,4,STONE)
Block(-7,19,5,STONE)
Block(-7,19,6,STONE)
Block(-7,19,7,STONE)
Block(-7,19,8,STONE)
Block(-7,19,9,STONE)
Block(-7,19,10,STONE)
Block(-7,19,11,STONE)
Block(-7,19,12,STONE)
Block(-7,19,13,STONE)
Block(-7,19,14,STONE)
Block(-7,19,15,STONE)
Block(-7,19,16,STONE)
Block(-7,19,17,STONE)
Block(-7,19,18,STONE)
Block(-7,19,19,STONE)
Block(-7,20,-6,STONE)
Block(-7,20,-5,STONE)
Block(-7,20,-4,STONE)
Block(-7,20,-3,STONE)
Block(-7,20,-2,STONE)
Block(-7,20,-1,STONE)
Block(-7,20,0,STONE)
Block(-7,20,1,STONE)
Block(-7,20,2,STONE)
Block(-7,20,3,STONE)
Block(-7,20,4,STONE)
Block(-7,20,5,STONE)
Block(-7,20,6,STONE)
Block(-7,20,7,STONE)
Block(-7,20,8,STONE)
Block(-7,20,9,STONE)
Block(-7,20,10,STONE)
Block(-7,20,11,STONE)
Block(-7,20,12,STONE)
Block(-7,20,13,STONE)
Block(-7,20,14,STONE)
Block(-7,20,15,STONE)
Block(-7,20,16,STONE)
Block(-7,20,17,STONE)
Block(-7,20,18,STONE)
Block(-7,20,19,STONE)
Block(-7,21,-5,STONE)
Block(-7,21,-4,STONE)
Block(-7,21,-3,STONE)
Block(-7,21,-2,STONE)
Block(-7,21,-1,STONE)
Block(-7,21,0,STONE)
Block(-7,21,1,STONE)
Block(-7,21,2,STONE)
Block(-7,21,3,STONE)
Block(-7,21,4,STONE)
Block(-7,21,5,STONE)
Block(-7,21,6,STONE)
Block(-7,21,7,STONE)
Block(-7,21,8,STONE)
Block(-7,21,9,STONE)
Block(-7,21,10,STONE)
Block(-7,21,11,STONE)
Block(-7,21,12,STONE)
Block(-7,21,13,STONE)
Block(-7,21,14,STONE)
Block(-7,21,15,STONE)
Block(-7,21,16,STONE)
Block(-7,21,17,STONE)
Block(-7,21,18,STONE)
Block(-7,21,19,STONE)
Block(-7,22,-5,STONE)
Block(-7,22,-4,STONE)
Block(-7,22,-3,STONE)
Block(-7,22,-2,STONE)
Block(-7,22,-1,STONE)
Block(-7,22,0,STONE)
Block(-7,22,1,STONE)
Block(-7,22,2,STONE)
Block(-7,22,3,STONE)
Block(-7,22,4,STONE)
Block(-7,22,5,STONE)
Block(-7,22,6,STONE)
Block(-7,22,7,STONE)
Block(-7,22,8,STONE)
Block(-7,22,9,STONE)
Block(-7,22,10,STONE)
Block(-7,22,11,STONE)
Block(-7,22,12,STONE)
Block(-7,22,13,STONE)
Block(-7,22,14,STONE)
Block(-7,22,15,STONE)
Block(-7,22,16,STONE)
Block(-7,22,17,STONE)
Block(-7,22,18,STONE)
Block(-7,22,19,STONE)
Block(-7,23,-4,STONE)
Block(-7,23,-3,STONE)
Block(-7,23,-2,STONE)
Block(-7,23,-1,STONE)
Block(-7,23,0,STONE)
Block(-7,23,1,STONE)
Block(-7,23,2,STONE)
Block(-7,23,3,STONE)
Block(-7,23,4,STONE)
Block(-7,23,5,STONE)
Block(-7,23,6,STONE)
Block(-7,23,7,STONE)
Block(-7,23,8,STONE)
Block(-7,23,9,STONE)
Block(-7,23,10,STONE)
Block(-7,23,11,STONE)
Block(-7,23,12,STONE)
Block(-7,23,13,STONE)
Block(-7,23,14,STONE)
Block(-7,23,15,STONE)
Block(-7,23,16,STONE)
Block(-7,23,17,STONE)
Block(-7,23,18,STONE)
Block(-7,23,19,STONE)
Block(-7,24,-4,STONE)
Block(-7,24,-3,STONE)
Block(-7,24,-2,STONE)
Block(-7,24,-1,STONE)
Block(-7,24,0,STONE)
Block(-7,24,1,STONE)
Block(-7,24,2,STONE)
Block(-7,24,3,STONE)
Block(-7,24,4,STONE)
Block(-7,24,5,STONE)
Block(-7,24,6,STONE)
Block(-7,24,7,STONE)
Block(-7,24,8,STONE)
Block(-7,24,9,STONE)
Block(-7,24,10,STONE)
Block(-7,24,11,STONE)
Block(-7,24,12,STONE)
Block(-7,24,13,STONE)
Block(-7,24,14,STONE)
Block(-7,24,15,STONE)
Block(-7,24,16,STONE)
Block(-7,24,17,STONE)
Block(-7,24,18,STONE)
Block(-7,24,19,STONE)
Block(-7,25,-3,STONE)
Block(-7,25,-2,STONE)
Block(-7,25,-1,STONE)
Block(-7,25,0,STONE)
Block(-7,25,1,STONE)
Block(-7,25,2,STONE)
Block(-7,25,3,STONE)
Block(-7,25,4,STONE)
Block(-7,25,5,STONE)
Block(-7,25,6,STONE)
Block(-7,25,7,STONE)
Block(-7,25,8,STONE)
Block(-7,25,9,STONE)
Block(-7,25,10,STONE)
Block(-7,25,11,STONE)
Block(-7,25,12,STONE)
Block(-7,25,13,STONE)
Block(-7,25,14,STONE)
Block(-7,25,15,STONE)
Block(-7,25,16,STONE)
Block(-7,25,17,STONE)
Block(-7,25,18,STONE)
Block(-7,26,-2,STONE)
Block(-7,26,-1,STONE)
Block(-7,26,0,STONE)
Block(-7,26,1,STONE)
Block(-7,26,2,STONE)
Block(-7,26,3,STONE)
Block(-7,26,4,STONE)
Block(-7,26,5,STONE)
Block(-7,26,6,STONE)
Block(-7,26,7,STONE)
Block(-7,26,8,STONE)
Block(-7,26,9,STONE)
Block(-7,26,10,STONE)
Block(-7,26,11,STONE)
Block(-7,26,12,STONE)
Block(-7,26,13,STONE)
Block(-7,26,14,STONE)
Block(-7,26,15,STONE)
Block(-7,26,16,STONE)
Block(-7,26,17,STONE)
Block(-7,27,-2,STONE)
Block(-7,27,-1,STONE)
Block(-7,27,0,STONE)
Block(-7,27,1,STONE)
Block(-7,27,2,STONE)
Block(-7,27,3,STONE)
Block(-7,27,4,STONE)
Block(-7,27,5,STONE)
Block(-7,27,6,STONE)
Block(-7,27,7,STONE)
Block(-7,27,8,STONE)
Block(-7,27,9,STONE)
Block(-7,27,10,STONE)
Block(-7,27,11,STONE)
Block(-7,27,12,STONE)
Block(-7,27,13,STONE)
Block(-7,27,14,STONE)
Block(-7,27,15,STONE)
Block(-7,28,-1,STONE)
Block(-7,28,0,STONE)
Block(-7,28,1,STONE)
Block(-7,28,2,STONE)
Block(-7,28,3,STONE)
Block(-7,28,4,STONE)
Block(-7,28,5,STONE)
Block(-7,28,6,STONE)
Block(-7,28,7,STONE)
Block(-7,28,8,STONE)
Block(-7,28,9,STONE)
Block(-7,28,10,STONE)
Block(-7,28,11,STONE)
Block(-7,28,12,STONE)
Block(-7,28,13,STONE)
Block(-7,28,14,STONE)
Block(-7,29,0,STONE)
Block(-7,29,1,STONE)
Block(-7,29,2,STONE)
Block(-7,29,3,STONE)
Block(-7,29,4,STONE)
Block(-7,29,5,STONE)
Block(-7,29,6,STONE)
Block(-7,29,7,STONE)
Block(-7,29,8,STONE)
Block(-7,29,9,STONE)
Block(-7,29,10,STONE)
Block(-7,29,11,STONE)
Block(-7,29,12,STONE)
Block(-7,30,1,STONE)
Block(-7,30,2,STONE)
Block(-7,30,3,STONE)
Block(-7,30,4,STONE)
Block(-7,30,5,STONE)
Block(-7,30,6,STONE)
Block(-7,30,7,STONE)
Block(-7,30,8,STONE)
Block(-7,30,9,STONE)
Block(-7,30,10,STONE)
Block(-7,30,11,STONE)
Block(-7,31,3,STONE)
Block(-7,31,4,STONE)
Block(-7,31,5,STONE)
Block(-7,31,6,STONE)
Block(-7,31,7,STONE)
Block(-7,31,8,STONE)
Block(-7,31,9,STONE)
Block(-7,32,4,STONE)
Block(-7,32,5,STONE)
Block(-7,32,6,STONE)
Block(-7,32,7,STONE)
Block(-7,32,8,STONE)
Block(-7,33,6,STONE)
Block(-6,7,6,STONE)
Block(-6,7,7,STONE)
Block(-6,8,3,STONE)
Block(-6,8,4,STONE)
Block(-6,8,5,STONE)
Block(-6,8,6,STONE)
Block(-6,8,7,STONE)
Block(-6,8,8,STONE)
Block(-6,8,9,STONE)
Block(-6,9,0,STONE)
Block(-6,9,1,STONE)
Block(-6,9,2,STONE)
Block(-6,9,3,STONE)
Block(-6,9,4,STONE)
Block(-6,9,5,STONE)
Block(-6,9,6,STONE)
Block(-6,9,7,STONE)
Block(-6,9,8,STONE)
Block(-6,9,9,STONE)
Block(-6,9,10,STONE)
Block(-6,9,11,STONE)
Block(-6,9,12,STONE)
Block(-6,9,13,STONE)
Block(-6,10,-5,STONE)
Block(-6,10,-4,STONE)
Block(-6,10,-3,STONE)
Block(-6,10,-2,STONE)
Block(-6,10,-1,STONE)
Block(-6,10,0,STONE)
Block(-6,10,1,STONE)
Block(-6,10,2,STONE)
Block(-6,10,3,STONE)
Block(-6,10,4,STONE)
Block(-6,10,5,STONE)
Block(-6,10,6,STONE)
Block(-6,10,7,STONE)
Block(-6,10,8,STONE)
Block(-6,10,9,STONE)
Block(-6,10,10,STONE)
Block(-6,10,11,STONE)
Block(-6,10,12,STONE)
Block(-6,10,13,STONE)
Block(-6,10,14,STONE)
Block(-6,10,15,STONE)
Block(-6,10,16,STONE)
Block(-6,11,-10,STONE)
Block(-6,11,-9,STONE)
Block(-6,11,-8,STONE)
Block(-6,11,-7,STONE)
Block(-6,11,-6,STONE)
Block(-6,11,-5,STONE)
Block(-6,11,-4,STONE)
Block(-6,11,-3,STONE)
Block(-6,11,-2,STONE)
Block(-6,11,-1,STONE)
Block(-6,11,0,STONE)
Block(-6,11,1,STONE)
Block(-6,11,2,STONE)
Block(-6,11,3,STONE)
Block(-6,11,4,STONE)
Block(-6,11,5,STONE)
Block(-6,11,6,STONE)
Block(-6,11,7,STONE)
Block(-6,11,8,STONE)
Block(-6,11,9,STONE)
Block(-6,11,10,STONE)
Block(-6,11,11,STONE)
Block(-6,11,12,STONE)
Block(-6,11,13,STONE)
Block(-6,11,14,STONE)
Block(-6,11,15,STONE)
Block(-6,11,16,STONE)
Block(-6,11,17,STONE)
Block(-6,12,-10,STONE)
Block(-6,12,-9,STONE)
Block(-6,12,-8,STONE)
Block(-6,12,-7,STONE)
Block(-6,12,-6,STONE)
Block(-6,12,-5,STONE)
Block(-6,12,-4,STONE)
Block(-6,12,-3,STONE)
Block(-6,12,-2,STONE)
Block(-6,12,-1,STONE)
Block(-6,12,0,STONE)
Block(-6,12,1,STONE)
Block(-6,12,2,STONE)
Block(-6,12,3,STONE)
Block(-6,12,4,STONE)
Block(-6,12,5,STONE)
Block(-6,12,6,STONE)
Block(-6,12,7,STONE)
Block(-6,12,8,STONE)
Block(-6,12,9,STONE)
Block(-6,12,10,STONE)
Block(-6,12,11,STONE)
Block(-6,12,12,STONE)
Block(-6,12,13,STONE)
Block(-6,12,14,STONE)
Block(-6,12,15,STONE)
Block(-6,12,16,STONE)
Block(-6,12,17,STONE)
Block(-6,12,18,STONE)
Block(-6,13,-10,STONE)
Block(-6,13,-9,STONE)
Block(-6,13,-8,STONE)
Block(-6,13,-7,STONE)
Block(-6,13,-6,STONE)
Block(-6,13,-5,STONE)
Block(-6,13,-4,STONE)
Block(-6,13,-3,STONE)
Block(-6,13,-2,STONE)
Block(-6,13,-1,STONE)
Block(-6,13,0,STONE)
Block(-6,13,1,STONE)
Block(-6,13,2,STONE)
Block(-6,13,3,STONE)
Block(-6,13,4,STONE)
Block(-6,13,5,STONE)
Block(-6,13,6,STONE)
Block(-6,13,7,STONE)
Block(-6,13,8,STONE)
Block(-6,13,9,STONE)
Block(-6,13,10,STONE)
Block(-6,13,11,STONE)
Block(-6,13,12,STONE)
Block(-6,13,13,STONE)
Block(-6,13,14,STONE)
Block(-6,13,15,STONE)
Block(-6,13,16,STONE)
Block(-6,13,17,STONE)
Block(-6,13,18,STONE)
Block(-6,13,19,STONE)
Block(-6,14,-9,STONE)
Block(-6,14,-8,STONE)
Block(-6,14,-7,STONE)
Block(-6,14,-6,STONE)
Block(-6,14,-5,STONE)
Block(-6,14,-4,STONE)
Block(-6,14,-3,STONE)
Block(-6,14,-2,STONE)
Block(-6,14,-1,STONE)
Block(-6,14,0,STONE)
Block(-6,14,1,STONE)
Block(-6,14,2,STONE)
Block(-6,14,3,STONE)
Block(-6,14,4,STONE)
Block(-6,14,5,STONE)
Block(-6,14,6,STONE)
Block(-6,14,7,STONE)
Block(-6,14,8,STONE)
Block(-6,14,9,STONE)
Block(-6,14,10,STONE)
Block(-6,14,11,STONE)
Block(-6,14,12,STONE)
Block(-6,14,13,STONE)
Block(-6,14,14,STONE)
Block(-6,14,15,STONE)
Block(-6,14,16,STONE)
Block(-6,14,17,STONE)
Block(-6,14,18,STONE)
Block(-6,14,19,STONE)
Block(-6,15,-9,STONE)
Block(-6,15,-8,STONE)
Block(-6,15,-7,STONE)
Block(-6,15,-6,STONE)
Block(-6,15,-5,STONE)
Block(-6,15,-4,STONE)
Block(-6,15,-3,STONE)
Block(-6,15,-2,STONE)
Block(-6,15,-1,STONE)
Block(-6,15,0,STONE)
Block(-6,15,1,STONE)
Block(-6,15,2,STONE)
Block(-6,15,3,STONE)
Block(-6,15,4,STONE)
Block(-6,15,5,STONE)
Block(-6,15,6,STONE)
Block(-6,15,7,STONE)
Block(-6,15,8,STONE)
Block(-6,15,9,STONE)
Block(-6,15,10,STONE)
Block(-6,15,11,STONE)
Block(-6,15,12,STONE)
Block(-6,15,13,STONE)
Block(-6,15,14,STONE)
Block(-6,15,15,STONE)
Block(-6,15,16,STONE)
Block(-6,15,17,STONE)
Block(-6,15,18,STONE)
Block(-6,15,19,STONE)
Block(-6,16,-8,STONE)
Block(-6,16,-7,STONE)
Block(-6,16,-6,STONE)
Block(-6,16,-5,STONE)
Block(-6,16,-4,STONE)
Block(-6,16,-3,STONE)
Block(-6,16,-2,STONE)
Block(-6,16,-1,STONE)
Block(-6,16,0,STONE)
Block(-6,16,1,STONE)
Block(-6,16,2,STONE)
Block(-6,16,3,STONE)
Block(-6,16,4,STONE)
Block(-6,16,5,STONE)
Block(-6,16,6,STONE)
Block(-6,16,7,STONE)
Block(-6,16,8,STONE)
Block(-6,16,9,STONE)
Block(-6,16,10,STONE)
Block(-6,16,11,STONE)
Block(-6,16,12,STONE)
Block(-6,16,13,STONE)
Block(-6,16,14,STONE)
Block(-6,16,15,STONE)
Block(-6,16,16,STONE)
Block(-6,16,17,STONE)
Block(-6,16,18,STONE)
Block(-6,16,19,STONE)
Block(-6,17,-8,STONE)
Block(-6,17,-7,STONE)
Block(-6,17,-6,STONE)
Block(-6,17,-5,STONE)
Block(-6,17,-4,STONE)
Block(-6,17,-3,STONE)
Block(-6,17,-2,STONE)
Block(-6,17,-1,STONE)
Block(-6,17,0,STONE)
Block(-6,17,1,STONE)
Block(-6,17,2,STONE)
Block(-6,17,3,STONE)
Block(-6,17,4,STONE)
Block(-6,17,5,STONE)
Block(-6,17,6,STONE)
Block(-6,17,7,STONE)
Block(-6,17,8,STONE)
Block(-6,17,9,STONE)
Block(-6,17,10,STONE)
Block(-6,17,11,STONE)
Block(-6,17,12,STONE)
Block(-6,17,13,STONE)
Block(-6,17,14,STONE)
Block(-6,17,15,STONE)
Block(-6,17,16,STONE)
Block(-6,17,17,STONE)
Block(-6,17,18,STONE)
Block(-6,17,19,STONE)
Block(-6,18,-7,STONE)
Block(-6,18,-6,STONE)
Block(-6,18,-5,STONE)
Block(-6,18,-4,STONE)
Block(-6,18,-3,STONE)
Block(-6,18,-2,STONE)
Block(-6,18,-1,STONE)
Block(-6,18,0,STONE)
Block(-6,18,1,STONE)
Block(-6,18,2,STONE)
Block(-6,18,3,STONE)
Block(-6,18,4,STONE)
Block(-6,18,5,STONE)
Block(-6,18,6,STONE)
Block(-6,18,7,STONE)
Block(-6,18,8,STONE)
Block(-6,18,9,STONE)
Block(-6,18,10,STONE)
Block(-6,18,11,STONE)
Block(-6,18,12,STONE)
Block(-6,18,13,STONE)
Block(-6,18,14,STONE)
Block(-6,18,15,STONE)
Block(-6,18,16,STONE)
Block(-6,18,17,STONE)
Block(-6,18,18,STONE)
Block(-6,18,19,STONE)
Block(-6,19,-7,STONE)
Block(-6,19,-6,STONE)
Block(-6,19,-5,STONE)
Block(-6,19,-4,STONE)
Block(-6,19,-3,STONE)
Block(-6,19,-2,STONE)
Block(-6,19,-1,STONE)
Block(-6,19,0,STONE)
Block(-6,19,1,STONE)
Block(-6,19,2,STONE)
Block(-6,19,3,STONE)
Block(-6,19,4,STONE)
Block(-6,19,5,STONE)
Block(-6,19,6,STONE)
Block(-6,19,7,STONE)
Block(-6,19,8,STONE)
Block(-6,19,9,STONE)
Block(-6,19,10,STONE)
Block(-6,19,11,STONE)
Block(-6,19,12,STONE)
Block(-6,19,13,STONE)
Block(-6,19,14,STONE)
Block(-6,19,15,STONE)
Block(-6,19,16,STONE)
Block(-6,19,17,STONE)
Block(-6,19,18,STONE)
Block(-6,19,19,STONE)
Block(-6,20,-6,STONE)
Block(-6,20,-5,STONE)
Block(-6,20,-4,STONE)
Block(-6,20,-3,STONE)
Block(-6,20,-2,STONE)
Block(-6,20,-1,STONE)
Block(-6,20,0,STONE)
Block(-6,20,1,STONE)
Block(-6,20,2,STONE)
Block(-6,20,3,STONE)
Block(-6,20,4,STONE)
Block(-6,20,5,STONE)
Block(-6,20,6,STONE)
Block(-6,20,7,STONE)
Block(-6,20,8,STONE)
Block(-6,20,9,STONE)
Block(-6,20,10,STONE)
Block(-6,20,11,STONE)
Block(-6,20,12,STONE)
Block(-6,20,13,STONE)
Block(-6,20,14,STONE)
Block(-6,20,15,STONE)
Block(-6,20,16,STONE)
Block(-6,20,17,STONE)
Block(-6,20,18,STONE)
Block(-6,20,19,STONE)
Block(-6,21,-6,STONE)
Block(-6,21,-5,STONE)
Block(-6,21,-4,STONE)
Block(-6,21,-3,STONE)
Block(-6,21,-2,STONE)
Block(-6,21,-1,STONE)
Block(-6,21,0,STONE)
Block(-6,21,1,STONE)
Block(-6,21,2,STONE)
Block(-6,21,3,STONE)
Block(-6,21,4,STONE)
Block(-6,21,5,STONE)
Block(-6,21,6,STONE)
Block(-6,21,7,STONE)
Block(-6,21,8,STONE)
Block(-6,21,9,STONE)
Block(-6,21,10,STONE)
Block(-6,21,11,STONE)
Block(-6,21,12,STONE)
Block(-6,21,13,STONE)
Block(-6,21,14,STONE)
Block(-6,21,15,STONE)
Block(-6,21,16,STONE)
Block(-6,21,17,STONE)
Block(-6,21,18,STONE)
Block(-6,21,19,STONE)
Block(-6,22,-5,STONE)
Block(-6,22,-4,STONE)
Block(-6,22,-3,STONE)
Block(-6,22,-2,STONE)
Block(-6,22,-1,STONE)
Block(-6,22,0,STONE)
Block(-6,22,1,STONE)
Block(-6,22,2,STONE)
Block(-6,22,3,STONE)
Block(-6,22,4,STONE)
Block(-6,22,5,STONE)
Block(-6,22,6,STONE)
Block(-6,22,7,STONE)
Block(-6,22,8,STONE)
Block(-6,22,9,STONE)
Block(-6,22,10,STONE)
Block(-6,22,11,STONE)
Block(-6,22,12,STONE)
Block(-6,22,13,STONE)
Block(-6,22,14,STONE)
Block(-6,22,15,STONE)
Block(-6,22,16,STONE)
Block(-6,22,17,STONE)
Block(-6,22,18,STONE)
Block(-6,22,19,STONE)
Block(-6,23,-4,STONE)
Block(-6,23,-3,STONE)
Block(-6,23,-2,STONE)
Block(-6,23,-1,STONE)
Block(-6,23,0,STONE)
Block(-6,23,1,STONE)
Block(-6,23,2,STONE)
Block(-6,23,3,STONE)
Block(-6,23,4,STONE)
Block(-6,23,5,STONE)
Block(-6,23,6,STONE)
Block(-6,23,7,STONE)
Block(-6,23,8,STONE)
Block(-6,23,9,STONE)
Block(-6,23,10,STONE)
Block(-6,23,11,STONE)
Block(-6,23,12,STONE)
Block(-6,23,13,STONE)
Block(-6,23,14,STONE)
Block(-6,23,15,STONE)
Block(-6,23,16,STONE)
Block(-6,23,17,STONE)
Block(-6,23,18,STONE)
Block(-6,23,19,STONE)
Block(-6,24,-4,STONE)
Block(-6,24,-3,STONE)
Block(-6,24,-2,STONE)
Block(-6,24,-1,STONE)
Block(-6,24,0,STONE)
Block(-6,24,1,STONE)
Block(-6,24,2,STONE)
Block(-6,24,3,STONE)
Block(-6,24,4,STONE)
Block(-6,24,5,STONE)
Block(-6,24,6,STONE)
Block(-6,24,7,STONE)
Block(-6,24,8,STONE)
Block(-6,24,9,STONE)
Block(-6,24,10,STONE)
Block(-6,24,11,STONE)
Block(-6,24,12,STONE)
Block(-6,24,13,STONE)
Block(-6,24,14,STONE)
Block(-6,24,15,STONE)
Block(-6,24,16,STONE)
Block(-6,24,17,STONE)
Block(-6,24,18,STONE)
Block(-6,24,19,STONE)
Block(-6,24,20,STONE)
Block(-6,25,-3,STONE)
Block(-6,25,-2,STONE)
Block(-6,25,-1,STONE)
Block(-6,25,0,STONE)
Block(-6,25,1,STONE)
Block(-6,25,2,STONE)
Block(-6,25,3,STONE)
Block(-6,25,4,STONE)
Block(-6,25,5,STONE)
Block(-6,25,6,STONE)
Block(-6,25,7,STONE)
Block(-6,25,8,STONE)
Block(-6,25,9,STONE)
Block(-6,25,10,STONE)
Block(-6,25,11,STONE)
Block(-6,25,12,STONE)
Block(-6,25,13,STONE)
Block(-6,25,14,STONE)
Block(-6,25,15,STONE)
Block(-6,25,16,STONE)
Block(-6,25,17,STONE)
Block(-6,25,18,STONE)
Block(-6,25,19,STONE)
Block(-6,26,-3,STONE)
Block(-6,26,-2,STONE)
Block(-6,26,-1,STONE)
Block(-6,26,0,STONE)
Block(-6,26,1,STONE)
Block(-6,26,2,STONE)
Block(-6,26,3,STONE)
Block(-6,26,4,STONE)
Block(-6,26,5,STONE)
Block(-6,26,6,STONE)
Block(-6,26,7,STONE)
Block(-6,26,8,STONE)
Block(-6,26,9,STONE)
Block(-6,26,10,STONE)
Block(-6,26,11,STONE)
Block(-6,26,12,STONE)
Block(-6,26,13,STONE)
Block(-6,26,14,STONE)
Block(-6,26,15,STONE)
Block(-6,26,16,STONE)
Block(-6,26,17,STONE)
Block(-6,26,18,STONE)
Block(-6,27,-2,STONE)
Block(-6,27,-1,STONE)
Block(-6,27,0,STONE)
Block(-6,27,1,STONE)
Block(-6,27,2,STONE)
Block(-6,27,3,STONE)
Block(-6,27,4,STONE)
Block(-6,27,5,STONE)
Block(-6,27,6,STONE)
Block(-6,27,7,STONE)
Block(-6,27,8,STONE)
Block(-6,27,9,STONE)
Block(-6,27,10,STONE)
Block(-6,27,11,STONE)
Block(-6,27,12,STONE)
Block(-6,27,13,STONE)
Block(-6,27,14,STONE)
Block(-6,27,15,STONE)
Block(-6,27,16,STONE)
Block(-6,27,17,STONE)
Block(-6,28,-1,STONE)
Block(-6,28,0,STONE)
Block(-6,28,1,STONE)
Block(-6,28,2,STONE)
Block(-6,28,3,STONE)
Block(-6,28,4,STONE)
Block(-6,28,5,STONE)
Block(-6,28,6,STONE)
Block(-6,28,7,STONE)
Block(-6,28,8,STONE)
Block(-6,28,9,STONE)
Block(-6,28,10,STONE)
Block(-6,28,11,STONE)
Block(-6,28,12,STONE)
Block(-6,28,13,STONE)
Block(-6,28,14,STONE)
Block(-6,28,15,STONE)
Block(-6,29,-1,STONE)
Block(-6,29,0,STONE)
Block(-6,29,1,STONE)
Block(-6,29,2,STONE)
Block(-6,29,3,STONE)
Block(-6,29,4,STONE)
Block(-6,29,5,STONE)
Block(-6,29,6,STONE)
Block(-6,29,7,STONE)
Block(-6,29,8,STONE)
Block(-6,29,9,STONE)
Block(-6,29,10,STONE)
Block(-6,29,11,STONE)
Block(-6,29,12,STONE)
Block(-6,29,13,STONE)
Block(-6,30,1,STONE)
Block(-6,30,2,STONE)
Block(-6,30,3,STONE)
Block(-6,30,4,STONE)
Block(-6,30,5,STONE)
Block(-6,30,6,STONE)
Block(-6,30,7,STONE)
Block(-6,30,8,STONE)
Block(-6,30,9,STONE)
Block(-6,30,10,STONE)
Block(-6,30,11,STONE)
Block(-6,31,2,STONE)
Block(-6,31,3,STONE)
Block(-6,31,4,STONE)
Block(-6,31,5,STONE)
Block(-6,31,6,STONE)
Block(-6,31,7,STONE)
Block(-6,31,8,STONE)
Block(-6,31,9,STONE)
Block(-6,31,10,STONE)
Block(-6,32,4,STONE)
Block(-6,32,5,STONE)
Block(-6,32,6,STONE)
Block(-6,32,7,STONE)
Block(-6,32,8,STONE)
Block(-6,33,5,STONE)
Block(-6,33,6,STONE)
Block(-6,33,7,STONE)
Block(-5,7,5,STONE)
Block(-5,7,6,STONE)
Block(-5,7,7,STONE)
Block(-5,7,8,STONE)
Block(-5,8,3,STONE)
Block(-5,8,4,STONE)
Block(-5,8,5,STONE)
Block(-5,8,6,STONE)
Block(-5,8,7,STONE)
Block(-5,8,8,STONE)
Block(-5,8,9,STONE)
Block(-5,8,10,STONE)
Block(-5,8,11,STONE)
Block(-5,9,-1,STONE)
Block(-5,9,0,STONE)
Block(-5,9,1,STONE)
Block(-5,9,2,STONE)
Block(-5,9,3,STONE)
Block(-5,9,4,STONE)
Block(-5,9,5,STONE)
Block(-5,9,6,STONE)
Block(-5,9,7,STONE)
Block(-5,9,8,STONE)
Block(-5,9,9,STONE)
Block(-5,9,10,STONE)
Block(-5,9,11,STONE)
Block(-5,9,12,STONE)
Block(-5,9,13,STONE)
Block(-5,9,14,STONE)
Block(-5,10,-6,STONE)
Block(-5,10,-5,STONE)
Block(-5,10,-4,STONE)
Block(-5,10,-3,STONE)
Block(-5,10,-2,STONE)
Block(-5,10,-1,STONE)
Block(-5,10,0,STONE)
Block(-5,10,1,STONE)
Block(-5,10,2,STONE)
Block(-5,10,3,STONE)
Block(-5,10,4,STONE)
Block(-5,10,5,STONE)
Block(-5,10,6,STONE)
Block(-5,10,7,STONE)
Block(-5,10,8,STONE)
Block(-5,10,9,STONE)
Block(-5,10,10,STONE)
Block(-5,10,11,STONE)
Block(-5,10,12,STONE)
Block(-5,10,13,STONE)
Block(-5,10,14,STONE)
Block(-5,10,15,STONE)
Block(-5,10,16,STONE)
Block(-5,11,-10,STONE)
Block(-5,11,-9,STONE)
Block(-5,11,-8,STONE)
Block(-5,11,-7,STONE)
Block(-5,11,-6,STONE)
Block(-5,11,-5,STONE)
Block(-5,11,-4,STONE)
Block(-5,11,-3,STONE)
Block(-5,11,-2,STONE)
Block(-5,11,-1,STONE)
Block(-5,11,0,STONE)
Block(-5,11,1,STONE)
Block(-5,11,2,STONE)
Block(-5,11,3,STONE)
Block(-5,11,4,STONE)
Block(-5,11,5,STONE)
Block(-5,11,6,STONE)
Block(-5,11,7,STONE)
Block(-5,11,8,STONE)
Block(-5,11,9,STONE)
Block(-5,11,10,STONE)
Block(-5,11,11,STONE)
Block(-5,11,12,STONE)
Block(-5,11,13,STONE)
Block(-5,11,14,STONE)
Block(-5,11,15,STONE)
Block(-5,11,16,STONE)
Block(-5,11,17,STONE)
Block(-5,12,-10,STONE)
Block(-5,12,-9,STONE)
Block(-5,12,-8,STONE)
Block(-5,12,-7,STONE)
Block(-5,12,-6,STONE)
Block(-5,12,-5,STONE)
Block(-5,12,-4,STONE)
Block(-5,12,-3,STONE)
Block(-5,12,-2,STONE)
Block(-5,12,-1,STONE)
Block(-5,12,0,STONE)
Block(-5,12,1,STONE)
Block(-5,12,2,STONE)
Block(-5,12,3,STONE)
Block(-5,12,4,STONE)
Block(-5,12,5,STONE)
Block(-5,12,6,STONE)
Block(-5,12,7,STONE)
Block(-5,12,8,STONE)
Block(-5,12,9,STONE)
Block(-5,12,10,STONE)
Block(-5,12,11,STONE)
Block(-5,12,12,STONE)
Block(-5,12,13,STONE)
Block(-5,12,14,STONE)
Block(-5,12,15,STONE)
Block(-5,12,16,STONE)
Block(-5,12,17,STONE)
Block(-5,12,18,STONE)
Block(-5,13,-10,STONE)
Block(-5,13,-9,STONE)
Block(-5,13,-8,STONE)
Block(-5,13,-7,STONE)
Block(-5,13,-6,STONE)
Block(-5,13,-5,STONE)
Block(-5,13,-4,STONE)
Block(-5,13,-3,STONE)
Block(-5,13,-2,STONE)
Block(-5,13,-1,STONE)
Block(-5,13,0,STONE)
Block(-5,13,1,STONE)
Block(-5,13,2,STONE)
Block(-5,13,3,STONE)
Block(-5,13,4,STONE)
Block(-5,13,5,STONE)
Block(-5,13,6,STONE)
Block(-5,13,7,STONE)
Block(-5,13,8,STONE)
Block(-5,13,9,STONE)
Block(-5,13,10,STONE)
Block(-5,13,11,STONE)
Block(-5,13,12,STONE)
Block(-5,13,13,STONE)
Block(-5,13,14,STONE)
Block(-5,13,15,STONE)
Block(-5,13,16,STONE)
Block(-5,13,17,STONE)
Block(-5,13,18,STONE)
Block(-5,13,19,STONE)
Block(-5,14,-9,STONE)
Block(-5,14,-8,STONE)
Block(-5,14,-7,STONE)
Block(-5,14,-6,STONE)
Block(-5,14,-5,STONE)
Block(-5,14,-4,STONE)
Block(-5,14,-3,STONE)
Block(-5,14,-2,STONE)
Block(-5,14,-1,STONE)
Block(-5,14,0,STONE)
Block(-5,14,1,STONE)
Block(-5,14,2,STONE)
Block(-5,14,3,STONE)
Block(-5,14,4,STONE)
Block(-5,14,5,STONE)
Block(-5,14,6,STONE)
Block(-5,14,7,STONE)
Block(-5,14,8,STONE)
Block(-5,14,9,STONE)
Block(-5,14,10,STONE)
Block(-5,14,11,STONE)
Block(-5,14,12,STONE)
Block(-5,14,13,STONE)
Block(-5,14,14,STONE)
Block(-5,14,15,STONE)
Block(-5,14,16,STONE)
Block(-5,14,17,STONE)
Block(-5,14,18,STONE)
Block(-5,14,19,STONE)
Block(-5,14,20,STONE)
Block(-5,15,-9,STONE)
Block(-5,15,-8,STONE)
Block(-5,15,-7,STONE)
Block(-5,15,-6,STONE)
Block(-5,15,-5,STONE)
Block(-5,15,-4,STONE)
Block(-5,15,-3,STONE)
Block(-5,15,-2,STONE)
Block(-5,15,-1,STONE)
Block(-5,15,0,STONE)
Block(-5,15,1,STONE)
Block(-5,15,2,STONE)
Block(-5,15,3,STONE)
Block(-5,15,4,STONE)
Block(-5,15,5,STONE)
Block(-5,15,6,STONE)
Block(-5,15,7,STONE)
Block(-5,15,8,STONE)
Block(-5,15,9,STONE)
Block(-5,15,10,STONE)
Block(-5,15,11,STONE)
Block(-5,15,12,STONE)
Block(-5,15,13,STONE)
Block(-5,15,14,STONE)
Block(-5,15,15,STONE)
Block(-5,15,16,STONE)
Block(-5,15,17,STONE)
Block(-5,15,18,STONE)
Block(-5,15,19,STONE)
Block(-5,15,20,STONE)
Block(-5,16,-9,STONE)
Block(-5,16,-8,STONE)
Block(-5,16,-7,STONE)
Block(-5,16,-6,STONE)
Block(-5,16,-5,STONE)
Block(-5,16,-4,STONE)
Block(-5,16,-3,STONE)
Block(-5,16,-2,STONE)
Block(-5,16,-1,STONE)
Block(-5,16,0,STONE)
Block(-5,16,1,STONE)
Block(-5,16,2,STONE)
Block(-5,16,3,STONE)
Block(-5,16,4,STONE)
Block(-5,16,5,STONE)
Block(-5,16,6,STONE)
Block(-5,16,7,STONE)
Block(-5,16,8,STONE)
Block(-5,16,9,STONE)
Block(-5,16,10,STONE)
Block(-5,16,11,STONE)
Block(-5,16,12,STONE)
Block(-5,16,13,STONE)
Block(-5,16,14,STONE)
Block(-5,16,15,STONE)
Block(-5,16,16,STONE)
Block(-5,16,17,STONE)
Block(-5,16,18,STONE)
Block(-5,16,19,STONE)
Block(-5,16,20,STONE)
Block(-5,17,-8,STONE)
Block(-5,17,-7,STONE)
Block(-5,17,-6,STONE)
Block(-5,17,-5,STONE)
Block(-5,17,-4,STONE)
Block(-5,17,-3,STONE)
Block(-5,17,-2,STONE)
Block(-5,17,-1,STONE)
Block(-5,17,0,STONE)
Block(-5,17,1,STONE)
Block(-5,17,2,STONE)
Block(-5,17,3,STONE)
Block(-5,17,4,STONE)
Block(-5,17,5,STONE)
Block(-5,17,6,STONE)
Block(-5,17,7,STONE)
Block(-5,17,8,STONE)
Block(-5,17,9,STONE)
Block(-5,17,10,STONE)
Block(-5,17,11,STONE)
Block(-5,17,12,STONE)
Block(-5,17,13,STONE)
Block(-5,17,14,STONE)
Block(-5,17,15,STONE)
Block(-5,17,16,STONE)
Block(-5,17,17,STONE)
Block(-5,17,18,STONE)
Block(-5,17,19,STONE)
Block(-5,17,20,STONE)
Block(-5,18,-7,STONE)
Block(-5,18,-6,STONE)
Block(-5,18,-5,STONE)
Block(-5,18,-4,STONE)
Block(-5,18,-3,STONE)
Block(-5,18,-2,STONE)
Block(-5,18,-1,STONE)
Block(-5,18,0,STONE)
Block(-5,18,1,STONE)
Block(-5,18,2,STONE)
Block(-5,18,3,STONE)
Block(-5,18,4,STONE)
Block(-5,18,5,STONE)
Block(-5,18,6,STONE)
Block(-5,18,7,STONE)
Block(-5,18,8,STONE)
Block(-5,18,9,STONE)
Block(-5,18,10,STONE)
Block(-5,18,11,STONE)
Block(-5,18,12,STONE)
Block(-5,18,13,STONE)
Block(-5,18,14,STONE)
Block(-5,18,15,STONE)
Block(-5,18,16,STONE)
Block(-5,18,17,STONE)
Block(-5,18,18,STONE)
Block(-5,18,19,STONE)
Block(-5,18,20,STONE)
Block(-5,19,-7,STONE)
Block(-5,19,-6,STONE)
Block(-5,19,-5,STONE)
Block(-5,19,-4,STONE)
Block(-5,19,-3,STONE)
Block(-5,19,-2,STONE)
Block(-5,19,-1,STONE)
Block(-5,19,0,STONE)
Block(-5,19,1,STONE)
Block(-5,19,2,STONE)
Block(-5,19,3,STONE)
Block(-5,19,4,STONE)
Block(-5,19,5,STONE)
Block(-5,19,6,STONE)
Block(-5,19,7,STONE)
Block(-5,19,8,STONE)
Block(-5,19,9,STONE)
Block(-5,19,10,STONE)
Block(-5,19,11,STONE)
Block(-5,19,12,STONE)
Block(-5,19,13,STONE)
Block(-5,19,14,STONE)
Block(-5,19,15,STONE)
Block(-5,19,16,STONE)
Block(-5,19,17,STONE)
Block(-5,19,18,STONE)
Block(-5,19,19,STONE)
Block(-5,19,20,STONE)
Block(-5,20,-6,STONE)
Block(-5,20,-5,STONE)
Block(-5,20,-4,STONE)
Block(-5,20,-3,STONE)
Block(-5,20,-2,STONE)
Block(-5,20,-1,STONE)
Block(-5,20,0,STONE)
Block(-5,20,1,STONE)
Block(-5,20,2,STONE)
Block(-5,20,3,STONE)
Block(-5,20,4,STONE)
Block(-5,20,5,STONE)
Block(-5,20,6,STONE)
Block(-5,20,7,STONE)
Block(-5,20,8,STONE)
Block(-5,20,9,STONE)
Block(-5,20,10,STONE)
Block(-5,20,11,STONE)
Block(-5,20,12,STONE)
Block(-5,20,13,STONE)
Block(-5,20,14,STONE)
Block(-5,20,15,STONE)
Block(-5,20,16,STONE)
Block(-5,20,17,STONE)
Block(-5,20,18,STONE)
Block(-5,20,19,STONE)
Block(-5,20,20,STONE)
Block(-5,21,-6,STONE)
Block(-5,21,-5,STONE)
Block(-5,21,-4,STONE)
Block(-5,21,-3,STONE)
Block(-5,21,-2,STONE)
Block(-5,21,-1,STONE)
Block(-5,21,0,STONE)
Block(-5,21,1,STONE)
Block(-5,21,2,STONE)
Block(-5,21,3,STONE)
Block(-5,21,4,STONE)
Block(-5,21,5,STONE)
Block(-5,21,6,STONE)
Block(-5,21,7,STONE)
Block(-5,21,8,STONE)
Block(-5,21,9,STONE)
Block(-5,21,10,STONE)
Block(-5,21,11,STONE)
Block(-5,21,12,STONE)
Block(-5,21,13,STONE)
Block(-5,21,14,STONE)
Block(-5,21,15,STONE)
Block(-5,21,16,STONE)
Block(-5,21,17,STONE)
Block(-5,21,18,STONE)
Block(-5,21,19,STONE)
Block(-5,21,20,STONE)
Block(-5,22,-5,STONE)
Block(-5,22,-4,STONE)
Block(-5,22,-3,STONE)
Block(-5,22,-2,STONE)
Block(-5,22,-1,STONE)
Block(-5,22,0,STONE)
Block(-5,22,1,STONE)
Block(-5,22,2,STONE)
Block(-5,22,3,STONE)
Block(-5,22,4,STONE)
Block(-5,22,5,STONE)
Block(-5,22,6,STONE)
Block(-5,22,7,STONE)
Block(-5,22,8,STONE)
Block(-5,22,9,STONE)
Block(-5,22,10,STONE)
Block(-5,22,11,STONE)
Block(-5,22,12,STONE)
Block(-5,22,13,STONE)
Block(-5,22,14,STONE)
Block(-5,22,15,STONE)
Block(-5,22,16,STONE)
Block(-5,22,17,STONE)
Block(-5,22,18,STONE)
Block(-5,22,19,STONE)
Block(-5,22,20,STONE)
Block(-5,23,-5,STONE)
Block(-5,23,-4,STONE)
Block(-5,23,-3,STONE)
Block(-5,23,-2,STONE)
Block(-5,23,-1,STONE)
Block(-5,23,0,STONE)
Block(-5,23,1,STONE)
Block(-5,23,2,STONE)
Block(-5,23,3,STONE)
Block(-5,23,4,STONE)
Block(-5,23,5,STONE)
Block(-5,23,6,STONE)
Block(-5,23,7,STONE)
Block(-5,23,8,STONE)
Block(-5,23,9,STONE)
Block(-5,23,10,STONE)
Block(-5,23,11,STONE)
Block(-5,23,12,STONE)
Block(-5,23,13,STONE)
Block(-5,23,14,STONE)
Block(-5,23,15,STONE)
Block(-5,23,16,STONE)
Block(-5,23,17,STONE)
Block(-5,23,18,STONE)
Block(-5,23,19,STONE)
Block(-5,23,20,STONE)
Block(-5,24,-4,STONE)
Block(-5,24,-3,STONE)
Block(-5,24,-2,STONE)
Block(-5,24,-1,STONE)
Block(-5,24,0,STONE)
Block(-5,24,1,STONE)
Block(-5,24,2,STONE)
Block(-5,24,3,STONE)
Block(-5,24,4,STONE)
Block(-5,24,5,STONE)
Block(-5,24,6,STONE)
Block(-5,24,7,STONE)
Block(-5,24,8,STONE)
Block(-5,24,9,STONE)
Block(-5,24,10,STONE)
Block(-5,24,11,STONE)
Block(-5,24,12,STONE)
Block(-5,24,13,STONE)
Block(-5,24,14,STONE)
Block(-5,24,15,STONE)
Block(-5,24,16,STONE)
Block(-5,24,17,STONE)
Block(-5,24,18,STONE)
Block(-5,24,19,STONE)
Block(-5,24,20,STONE)
Block(-5,25,-3,STONE)
Block(-5,25,-2,STONE)
Block(-5,25,-1,STONE)
Block(-5,25,0,STONE)
Block(-5,25,1,STONE)
Block(-5,25,2,STONE)
Block(-5,25,3,STONE)
Block(-5,25,4,STONE)
Block(-5,25,5,STONE)
Block(-5,25,6,STONE)
Block(-5,25,7,STONE)
Block(-5,25,8,STONE)
Block(-5,25,9,STONE)
Block(-5,25,10,STONE)
Block(-5,25,11,STONE)
Block(-5,25,12,STONE)
Block(-5,25,13,STONE)
Block(-5,25,14,STONE)
Block(-5,25,15,STONE)
Block(-5,25,16,STONE)
Block(-5,25,17,STONE)
Block(-5,25,18,STONE)
Block(-5,25,19,STONE)
Block(-5,25,20,STONE)
Block(-5,26,-3,STONE)
Block(-5,26,-2,STONE)
Block(-5,26,-1,STONE)
Block(-5,26,0,STONE)
Block(-5,26,1,STONE)
Block(-5,26,2,STONE)
Block(-5,26,3,STONE)
Block(-5,26,4,STONE)
Block(-5,26,5,STONE)
Block(-5,26,6,STONE)
Block(-5,26,7,STONE)
Block(-5,26,8,STONE)
Block(-5,26,9,STONE)
Block(-5,26,10,STONE)
Block(-5,26,11,STONE)
Block(-5,26,12,STONE)
Block(-5,26,13,STONE)
Block(-5,26,14,STONE)
Block(-5,26,15,STONE)
Block(-5,26,16,STONE)
Block(-5,26,17,STONE)
Block(-5,26,18,STONE)
Block(-5,26,19,STONE)
Block(-5,27,-2,STONE)
Block(-5,27,-1,STONE)
Block(-5,27,0,STONE)
Block(-5,27,1,STONE)
Block(-5,27,2,STONE)
Block(-5,27,3,STONE)
Block(-5,27,4,STONE)
Block(-5,27,5,STONE)
Block(-5,27,6,STONE)
Block(-5,27,7,STONE)
Block(-5,27,8,STONE)
Block(-5,27,9,STONE)
Block(-5,27,10,STONE)
Block(-5,27,11,STONE)
Block(-5,27,12,STONE)
Block(-5,27,13,STONE)
Block(-5,27,14,STONE)
Block(-5,27,15,STONE)
Block(-5,27,16,STONE)
Block(-5,27,17,STONE)
Block(-5,28,-1,STONE)
Block(-5,28,0,STONE)
Block(-5,28,1,STONE)
Block(-5,28,2,STONE)
Block(-5,28,3,STONE)
Block(-5,28,4,STONE)
Block(-5,28,5,STONE)
Block(-5,28,6,STONE)
Block(-5,28,7,STONE)
Block(-5,28,8,STONE)
Block(-5,28,9,STONE)
Block(-5,28,10,STONE)
Block(-5,28,11,STONE)
Block(-5,28,12,STONE)
Block(-5,28,13,STONE)
Block(-5,28,14,STONE)
Block(-5,28,15,STONE)
Block(-5,28,16,STONE)
Block(-5,29,-1,STONE)
Block(-5,29,0,STONE)
Block(-5,29,1,STONE)
Block(-5,29,2,STONE)
Block(-5,29,3,STONE)
Block(-5,29,4,STONE)
Block(-5,29,5,STONE)
Block(-5,29,6,STONE)
Block(-5,29,7,STONE)
Block(-5,29,8,STONE)
Block(-5,29,9,STONE)
Block(-5,29,10,STONE)
Block(-5,29,11,STONE)
Block(-5,29,12,STONE)
Block(-5,29,13,STONE)
Block(-5,29,14,STONE)
Block(-5,30,1,STONE)
Block(-5,30,2,STONE)
Block(-5,30,3,STONE)
Block(-5,30,4,STONE)
Block(-5,30,5,STONE)
Block(-5,30,6,STONE)
Block(-5,30,7,STONE)
Block(-5,30,8,STONE)
Block(-5,30,9,STONE)
Block(-5,30,10,STONE)
Block(-5,30,11,STONE)
Block(-5,30,12,STONE)
Block(-5,31,2,STONE)
Block(-5,31,3,STONE)
Block(-5,31,4,STONE)
Block(-5,31,5,STONE)
Block(-5,31,6,STONE)
Block(-5,31,7,STONE)
Block(-5,31,8,STONE)
Block(-5,31,9,STONE)
Block(-5,31,10,STONE)
Block(-5,32,3,STONE)
Block(-5,32,4,STONE)
Block(-5,32,5,STONE)
Block(-5,32,6,STONE)
Block(-5,32,7,STONE)
Block(-5,32,8,STONE)
Block(-5,32,9,STONE)
Block(-5,33,5,STONE)
Block(-5,33,6,STONE)
Block(-5,33,7,STONE)
Block(-4,7,5,STONE)
Block(-4,7,6,STONE)
Block(-4,7,7,STONE)
Block(-4,7,8,STONE)
Block(-4,7,9,STONE)
Block(-4,8,3,STONE)
Block(-4,8,4,STONE)
Block(-4,8,5,STONE)
Block(-4,8,6,STONE)
Block(-4,8,7,STONE)
Block(-4,8,8,STONE)
Block(-4,8,9,STONE)
Block(-4,8,10,STONE)
Block(-4,8,11,STONE)
Block(-4,8,12,STONE)
Block(-4,8,13,STONE)
Block(-4,9,-1,STONE)
Block(-4,9,0,STONE)
Block(-4,9,1,STONE)
Block(-4,9,2,STONE)
Block(-4,9,3,STONE)
Block(-4,9,4,STONE)
Block(-4,9,5,STONE)
Block(-4,9,6,STONE)
Block(-4,9,7,STONE)
Block(-4,9,8,STONE)
Block(-4,9,9,STONE)
Block(-4,9,10,STONE)
Block(-4,9,11,STONE)
Block(-4,9,12,STONE)
Block(-4,9,13,STONE)
Block(-4,9,14,STONE)
Block(-4,9,15,STONE)
Block(-4,9,16,STONE)
Block(-4,10,-6,STONE)
Block(-4,10,-5,STONE)
Block(-4,10,-4,STONE)
Block(-4,10,-3,STONE)
Block(-4,10,-2,STONE)
Block(-4,10,-1,STONE)
Block(-4,10,0,STONE)
Block(-4,10,1,STONE)
Block(-4,10,2,STONE)
Block(-4,10,3,STONE)
Block(-4,10,4,STONE)
Block(-4,10,5,STONE)
Block(-4,10,6,STONE)
Block(-4,10,7,STONE)
Block(-4,10,8,STONE)
Block(-4,10,9,STONE)
Block(-4,10,10,STONE)
Block(-4,10,11,STONE)
Block(-4,10,12,STONE)
Block(-4,10,13,STONE)
Block(-4,10,14,STONE)
Block(-4,10,15,STONE)
Block(-4,10,16,STONE)
Block(-4,11,-10,STONE)
Block(-4,11,-9,STONE)
Block(-4,11,-8,STONE)
Block(-4,11,-7,STONE)
Block(-4,11,-6,STONE)
Block(-4,11,-5,STONE)
Block(-4,11,-4,STONE)
Block(-4,11,-3,STONE)
Block(-4,11,-2,STONE)
Block(-4,11,-1,STONE)
Block(-4,11,0,STONE)
Block(-4,11,1,STONE)
Block(-4,11,2,STONE)
Block(-4,11,3,STONE)
Block(-4,11,4,STONE)
Block(-4,11,5,STONE)
Block(-4,11,6,STONE)
Block(-4,11,7,STONE)
Block(-4,11,8,STONE)
Block(-4,11,9,STONE)
Block(-4,11,10,STONE)
Block(-4,11,11,STONE)
Block(-4,11,12,STONE)
Block(-4,11,13,STONE)
Block(-4,11,14,STONE)
Block(-4,11,15,STONE)
Block(-4,11,16,STONE)
Block(-4,11,17,STONE)
Block(-4,12,-10,STONE)
Block(-4,12,-9,STONE)
Block(-4,12,-8,STONE)
Block(-4,12,-7,STONE)
Block(-4,12,-6,STONE)
Block(-4,12,-5,STONE)
Block(-4,12,-4,STONE)
Block(-4,12,-3,STONE)
Block(-4,12,-2,STONE)
Block(-4,12,-1,STONE)
Block(-4,12,0,STONE)
Block(-4,12,1,STONE)
Block(-4,12,2,STONE)
Block(-4,12,3,STONE)
Block(-4,12,4,STONE)
Block(-4,12,5,STONE)
Block(-4,12,6,STONE)
Block(-4,12,7,STONE)
Block(-4,12,8,STONE)
Block(-4,12,9,STONE)
Block(-4,12,10,STONE)
Block(-4,12,11,STONE)
Block(-4,12,12,STONE)
Block(-4,12,13,STONE)
Block(-4,12,14,STONE)
Block(-4,12,15,STONE)
Block(-4,12,16,STONE)
Block(-4,12,17,STONE)
Block(-4,12,18,STONE)
Block(-4,13,-10,STONE)
Block(-4,13,-9,STONE)
Block(-4,13,-8,STONE)
Block(-4,13,-7,STONE)
Block(-4,13,-6,STONE)
Block(-4,13,-5,STONE)
Block(-4,13,-4,STONE)
Block(-4,13,-3,STONE)
Block(-4,13,-2,STONE)
Block(-4,13,-1,STONE)
Block(-4,13,0,STONE)
Block(-4,13,1,STONE)
Block(-4,13,2,STONE)
Block(-4,13,3,STONE)
Block(-4,13,4,STONE)
Block(-4,13,5,STONE)
Block(-4,13,6,STONE)
Block(-4,13,7,STONE)
Block(-4,13,8,STONE)
Block(-4,13,9,STONE)
Block(-4,13,10,STONE)
Block(-4,13,11,STONE)
Block(-4,13,12,STONE)
Block(-4,13,13,STONE)
Block(-4,13,14,STONE)
Block(-4,13,15,STONE)
Block(-4,13,16,STONE)
Block(-4,13,17,STONE)
Block(-4,13,18,STONE)
Block(-4,13,19,STONE)
Block(-4,14,-10,STONE)
Block(-4,14,-9,STONE)
Block(-4,14,-8,STONE)
Block(-4,14,-7,STONE)
Block(-4,14,-6,STONE)
Block(-4,14,-5,STONE)
Block(-4,14,-4,STONE)
Block(-4,14,-3,STONE)
Block(-4,14,-2,STONE)
Block(-4,14,-1,STONE)
Block(-4,14,0,STONE)
Block(-4,14,1,STONE)
Block(-4,14,2,STONE)
Block(-4,14,3,STONE)
Block(-4,14,4,STONE)
Block(-4,14,5,STONE)
Block(-4,14,6,STONE)
Block(-4,14,7,STONE)
Block(-4,14,8,STONE)
Block(-4,14,9,STONE)
Block(-4,14,10,STONE)
Block(-4,14,11,STONE)
Block(-4,14,12,STONE)
Block(-4,14,13,STONE)
Block(-4,14,14,STONE)
Block(-4,14,15,STONE)
Block(-4,14,16,STONE)
Block(-4,14,17,STONE)
Block(-4,14,18,STONE)
Block(-4,14,19,STONE)
Block(-4,14,20,STONE)
Block(-4,15,-9,STONE)
Block(-4,15,-8,STONE)
Block(-4,15,-7,STONE)
Block(-4,15,-6,STONE)
Block(-4,15,-5,STONE)
Block(-4,15,-4,STONE)
Block(-4,15,-3,STONE)
Block(-4,15,-2,STONE)
Block(-4,15,-1,STONE)
Block(-4,15,0,STONE)
Block(-4,15,1,STONE)
Block(-4,15,2,STONE)
Block(-4,15,3,STONE)
Block(-4,15,4,STONE)
Block(-4,15,5,STONE)
Block(-4,15,6,STONE)
Block(-4,15,7,STONE)
Block(-4,15,8,STONE)
Block(-4,15,9,STONE)
Block(-4,15,10,STONE)
Block(-4,15,11,STONE)
Block(-4,15,12,STONE)
Block(-4,15,13,STONE)
Block(-4,15,14,STONE)
Block(-4,15,15,STONE)
Block(-4,15,16,STONE)
Block(-4,15,17,STONE)
Block(-4,15,18,STONE)
Block(-4,15,19,STONE)
Block(-4,15,20,STONE)
Block(-4,16,-9,STONE)
Block(-4,16,-8,STONE)
Block(-4,16,-7,STONE)
Block(-4,16,-6,STONE)
Block(-4,16,-5,STONE)
Block(-4,16,-4,STONE)
Block(-4,16,-3,STONE)
Block(-4,16,-2,STONE)
Block(-4,16,-1,STONE)
Block(-4,16,0,STONE)
Block(-4,16,1,STONE)
Block(-4,16,2,STONE)
Block(-4,16,3,STONE)
Block(-4,16,4,STONE)
Block(-4,16,5,STONE)
Block(-4,16,6,STONE)
Block(-4,16,7,STONE)
Block(-4,16,8,STONE)
Block(-4,16,9,STONE)
Block(-4,16,10,STONE)
Block(-4,16,11,STONE)
Block(-4,16,12,STONE)
Block(-4,16,13,STONE)
Block(-4,16,14,STONE)
Block(-4,16,15,STONE)
Block(-4,16,16,STONE)
Block(-4,16,17,STONE)
Block(-4,16,18,STONE)
Block(-4,16,19,STONE)
Block(-4,16,20,STONE)
Block(-4,17,-8,STONE)
Block(-4,17,-7,STONE)
Block(-4,17,-6,STONE)
Block(-4,17,-5,STONE)
Block(-4,17,-4,STONE)
Block(-4,17,-3,STONE)
Block(-4,17,-2,STONE)
Block(-4,17,-1,STONE)
Block(-4,17,0,STONE)
Block(-4,17,1,STONE)
Block(-4,17,2,STONE)
Block(-4,17,3,STONE)
Block(-4,17,4,STONE)
Block(-4,17,5,STONE)
Block(-4,17,6,STONE)
Block(-4,17,7,STONE)
Block(-4,17,8,STONE)
Block(-4,17,9,STONE)
Block(-4,17,10,STONE)
Block(-4,17,11,STONE)
Block(-4,17,12,STONE)
Block(-4,17,13,STONE)
Block(-4,17,14,STONE)
Block(-4,17,15,STONE)
Block(-4,17,16,STONE)
Block(-4,17,17,STONE)
Block(-4,17,18,STONE)
Block(-4,17,19,STONE)
Block(-4,17,20,STONE)
Block(-4,18,-8,STONE)
Block(-4,18,-7,STONE)
Block(-4,18,-6,STONE)
Block(-4,18,-5,STONE)
Block(-4,18,-4,STONE)
Block(-4,18,-3,STONE)
Block(-4,18,-2,STONE)
Block(-4,18,-1,STONE)
Block(-4,18,0,STONE)
Block(-4,18,1,STONE)
Block(-4,18,2,STONE)
Block(-4,18,3,STONE)
Block(-4,18,4,STONE)
Block(-4,18,5,STONE)
Block(-4,18,6,STONE)
Block(-4,18,7,STONE)
Block(-4,18,8,STONE)
Block(-4,18,9,STONE)
Block(-4,18,10,STONE)
Block(-4,18,11,STONE)
Block(-4,18,12,STONE)
Block(-4,18,13,STONE)
Block(-4,18,14,STONE)
Block(-4,18,15,STONE)
Block(-4,18,16,STONE)
Block(-4,18,17,STONE)
Block(-4,18,18,STONE)
Block(-4,18,19,STONE)
Block(-4,18,20,STONE)
Block(-4,19,-7,STONE)
Block(-4,19,-6,STONE)
Block(-4,19,-5,STONE)
Block(-4,19,-4,STONE)
Block(-4,19,-3,STONE)
Block(-4,19,-2,STONE)
Block(-4,19,-1,STONE)
Block(-4,19,0,STONE)
Block(-4,19,1,STONE)
Block(-4,19,2,STONE)
Block(-4,19,3,STONE)
Block(-4,19,4,STONE)
Block(-4,19,5,STONE)
Block(-4,19,6,STONE)
Block(-4,19,7,STONE)
Block(-4,19,8,STONE)
Block(-4,19,9,STONE)
Block(-4,19,10,STONE)
Block(-4,19,11,STONE)
Block(-4,19,12,STONE)
Block(-4,19,13,STONE)
Block(-4,19,14,STONE)
Block(-4,19,15,STONE)
Block(-4,19,16,STONE)
Block(-4,19,17,STONE)
Block(-4,19,18,STONE)
Block(-4,19,19,STONE)
Block(-4,19,20,STONE)
Block(-4,20,-6,STONE)
Block(-4,20,-5,STONE)
Block(-4,20,-4,STONE)
Block(-4,20,-3,STONE)
Block(-4,20,-2,STONE)
Block(-4,20,-1,STONE)
Block(-4,20,0,STONE)
Block(-4,20,1,STONE)
Block(-4,20,2,STONE)
Block(-4,20,3,STONE)
Block(-4,20,4,STONE)
Block(-4,20,5,STONE)
Block(-4,20,6,STONE)
Block(-4,20,7,STONE)
Block(-4,20,8,STONE)
Block(-4,20,9,STONE)
Block(-4,20,10,STONE)
Block(-4,20,11,STONE)
Block(-4,20,12,STONE)
Block(-4,20,13,STONE)
Block(-4,20,14,STONE)
Block(-4,20,15,STONE)
Block(-4,20,16,STONE)
Block(-4,20,17,STONE)
Block(-4,20,18,STONE)
Block(-4,20,19,STONE)
Block(-4,20,20,STONE)
Block(-4,21,-6,STONE)
Block(-4,21,-5,STONE)
Block(-4,21,-4,STONE)
Block(-4,21,-3,STONE)
Block(-4,21,-2,STONE)
Block(-4,21,-1,STONE)
Block(-4,21,0,STONE)
Block(-4,21,1,STONE)
Block(-4,21,2,STONE)
Block(-4,21,3,STONE)
Block(-4,21,4,STONE)
Block(-4,21,5,STONE)
Block(-4,21,6,STONE)
Block(-4,21,7,STONE)
Block(-4,21,8,STONE)
Block(-4,21,9,STONE)
Block(-4,21,10,STONE)
Block(-4,21,11,STONE)
Block(-4,21,12,STONE)
Block(-4,21,13,STONE)
Block(-4,21,14,STONE)
Block(-4,21,15,STONE)
Block(-4,21,16,STONE)
Block(-4,21,17,STONE)
Block(-4,21,18,STONE)
Block(-4,21,19,STONE)
Block(-4,21,20,STONE)
Block(-4,22,-5,STONE)
Block(-4,22,-4,STONE)
Block(-4,22,-3,STONE)
Block(-4,22,-2,STONE)
Block(-4,22,-1,STONE)
Block(-4,22,0,STONE)
Block(-4,22,1,STONE)
Block(-4,22,2,STONE)
Block(-4,22,3,STONE)
Block(-4,22,4,STONE)
Block(-4,22,5,STONE)
Block(-4,22,6,STONE)
Block(-4,22,7,STONE)
Block(-4,22,8,STONE)
Block(-4,22,9,STONE)
Block(-4,22,10,STONE)
Block(-4,22,11,STONE)
Block(-4,22,12,STONE)
Block(-4,22,13,STONE)
Block(-4,22,14,STONE)
Block(-4,22,15,STONE)
Block(-4,22,16,STONE)
Block(-4,22,17,STONE)
Block(-4,22,18,STONE)
Block(-4,22,19,STONE)
Block(-4,22,20,STONE)
Block(-4,23,-5,STONE)
Block(-4,23,-4,STONE)
Block(-4,23,-3,STONE)
Block(-4,23,-2,STONE)
Block(-4,23,-1,STONE)
Block(-4,23,0,STONE)
Block(-4,23,1,STONE)
Block(-4,23,2,STONE)
Block(-4,23,3,STONE)
Block(-4,23,4,STONE)
Block(-4,23,5,STONE)
Block(-4,23,6,STONE)
Block(-4,23,7,STONE)
Block(-4,23,8,STONE)
Block(-4,23,9,STONE)
Block(-4,23,10,STONE)
Block(-4,23,11,STONE)
Block(-4,23,12,STONE)
Block(-4,23,13,STONE)
Block(-4,23,14,STONE)
Block(-4,23,15,STONE)
Block(-4,23,16,STONE)
Block(-4,23,17,STONE)
Block(-4,23,18,STONE)
Block(-4,23,19,STONE)
Block(-4,23,20,STONE)
Block(-4,24,-4,STONE)
Block(-4,24,-3,STONE)
Block(-4,24,-2,STONE)
Block(-4,24,-1,STONE)
Block(-4,24,0,STONE)
Block(-4,24,1,STONE)
Block(-4,24,2,STONE)
Block(-4,24,3,STONE)
Block(-4,24,4,STONE)
Block(-4,24,5,STONE)
Block(-4,24,6,STONE)
Block(-4,24,7,STONE)
Block(-4,24,8,STONE)
Block(-4,24,9,STONE)
Block(-4,24,10,STONE)
Block(-4,24,11,STONE)
Block(-4,24,12,STONE)
Block(-4,24,13,STONE)
Block(-4,24,14,STONE)
Block(-4,24,15,STONE)
Block(-4,24,16,STONE)
Block(-4,24,17,STONE)
Block(-4,24,18,STONE)
Block(-4,24,19,STONE)
Block(-4,24,20,STONE)
Block(-4,25,-3,STONE)
Block(-4,25,-2,STONE)
Block(-4,25,-1,STONE)
Block(-4,25,0,STONE)
Block(-4,25,1,STONE)
Block(-4,25,2,STONE)
Block(-4,25,3,STONE)
Block(-4,25,4,STONE)
Block(-4,25,5,STONE)
Block(-4,25,6,STONE)
Block(-4,25,7,STONE)
Block(-4,25,8,STONE)
Block(-4,25,9,STONE)
Block(-4,25,10,STONE)
Block(-4,25,11,STONE)
Block(-4,25,12,STONE)
Block(-4,25,13,STONE)
Block(-4,25,14,STONE)
Block(-4,25,15,STONE)
Block(-4,25,16,STONE)
Block(-4,25,17,STONE)
Block(-4,25,18,STONE)
Block(-4,25,19,STONE)
Block(-4,25,20,STONE)
Block(-4,26,-3,STONE)
Block(-4,26,-2,STONE)
Block(-4,26,-1,STONE)
Block(-4,26,0,STONE)
Block(-4,26,1,STONE)
Block(-4,26,2,STONE)
Block(-4,26,3,STONE)
Block(-4,26,4,STONE)
Block(-4,26,5,STONE)
Block(-4,26,6,STONE)
Block(-4,26,7,STONE)
Block(-4,26,8,STONE)
Block(-4,26,9,STONE)
Block(-4,26,10,STONE)
Block(-4,26,11,STONE)
Block(-4,26,12,STONE)
Block(-4,26,13,STONE)
Block(-4,26,14,STONE)
Block(-4,26,15,STONE)
Block(-4,26,16,STONE)
Block(-4,26,17,STONE)
Block(-4,26,18,STONE)
Block(-4,26,19,STONE)
Block(-4,27,-2,STONE)
Block(-4,27,-1,STONE)
Block(-4,27,0,STONE)
Block(-4,27,1,STONE)
Block(-4,27,2,STONE)
Block(-4,27,3,STONE)
Block(-4,27,4,STONE)
Block(-4,27,5,STONE)
Block(-4,27,6,STONE)
Block(-4,27,7,STONE)
Block(-4,27,8,STONE)
Block(-4,27,9,STONE)
Block(-4,27,10,STONE)
Block(-4,27,11,STONE)
Block(-4,27,12,STONE)
Block(-4,27,13,STONE)
Block(-4,27,14,STONE)
Block(-4,27,15,STONE)
Block(-4,27,16,STONE)
Block(-4,27,17,STONE)
Block(-4,27,18,STONE)
Block(-4,28,-2,STONE)
Block(-4,28,-1,STONE)
Block(-4,28,0,STONE)
Block(-4,28,1,STONE)
Block(-4,28,2,STONE)
Block(-4,28,3,STONE)
Block(-4,28,4,STONE)
Block(-4,28,5,STONE)
Block(-4,28,6,STONE)
Block(-4,28,7,STONE)
Block(-4,28,8,STONE)
Block(-4,28,9,STONE)
Block(-4,28,10,STONE)
Block(-4,28,11,STONE)
Block(-4,28,12,STONE)
Block(-4,28,13,STONE)
Block(-4,28,14,STONE)
Block(-4,28,15,STONE)
Block(-4,28,16,STONE)
Block(-4,29,-1,STONE)
Block(-4,29,0,STONE)
Block(-4,29,1,STONE)
Block(-4,29,2,STONE)
Block(-4,29,3,STONE)
Block(-4,29,4,STONE)
Block(-4,29,5,STONE)
Block(-4,29,6,STONE)
Block(-4,29,7,STONE)
Block(-4,29,8,STONE)
Block(-4,29,9,STONE)
Block(-4,29,10,STONE)
Block(-4,29,11,STONE)
Block(-4,29,12,STONE)
Block(-4,29,13,STONE)
Block(-4,29,14,STONE)
Block(-4,30,0,STONE)
Block(-4,30,1,STONE)
Block(-4,30,2,STONE)
Block(-4,30,3,STONE)
Block(-4,30,4,STONE)
Block(-4,30,5,STONE)
Block(-4,30,6,STONE)
Block(-4,30,7,STONE)
Block(-4,30,8,STONE)
Block(-4,30,9,STONE)
Block(-4,30,10,STONE)
Block(-4,30,11,STONE)
Block(-4,30,12,STONE)
Block(-4,30,13,STONE)
Block(-4,31,2,STONE)
Block(-4,31,3,STONE)
Block(-4,31,4,STONE)
Block(-4,31,5,STONE)
Block(-4,31,6,STONE)
Block(-4,31,7,STONE)
Block(-4,31,8,STONE)
Block(-4,31,9,STONE)
Block(-4,31,10,STONE)
Block(-4,31,11,STONE)
Block(-4,32,3,STONE)
Block(-4,32,4,STONE)
Block(-4,32,5,STONE)
Block(-4,32,6,STONE)
Block(-4,32,7,STONE)
Block(-4,32,8,STONE)
Block(-4,32,9,STONE)
Block(-4,33,5,STONE)
Block(-4,33,6,STONE)
Block(-4,33,7,STONE)
Block(-4,34,6,STONE)
Block(-3,6,7,STONE)
Block(-3,6,8,STONE)
Block(-3,7,5,STONE)
Block(-3,7,6,STONE)
Block(-3,7,7,STONE)
Block(-3,7,8,STONE)
Block(-3,7,9,STONE)
Block(-3,7,10,STONE)
Block(-3,7,11,STONE)
Block(-3,8,3,STONE)
Block(-3,8,4,STONE)
Block(-3,8,5,STONE)
Block(-3,8,6,STONE)
Block(-3,8,7,STONE)
Block(-3,8,8,STONE)
Block(-3,8,9,STONE)
Block(-3,8,10,STONE)
Block(-3,8,11,STONE)
Block(-3,8,12,STONE)
Block(-3,8,13,STONE)
Block(-3,8,14,STONE)
Block(-3,9,-4,STONE)
Block(-3,9,-3,STONE)
Block(-3,9,-2,STONE)
Block(-3,9,-1,STONE)
Block(-3,9,0,STONE)
Block(-3,9,1,STONE)
Block(-3,9,2,STONE)
Block(-3,9,3,STONE)
Block(-3,9,4,STONE)
Block(-3,9,5,STONE)
Block(-3,9,6,STONE)
Block(-3,9,7,STONE)
Block(-3,9,8,STONE)
Block(-3,9,9,STONE)
Block(-3,9,10,STONE)
Block(-3,9,11,STONE)
Block(-3,9,12,STONE)
Block(-3,9,13,STONE)
Block(-3,9,14,STONE)
Block(-3,9,15,STONE)
Block(-3,9,16,STONE)
Block(-3,10,-7,STONE)
Block(-3,10,-6,STONE)
Block(-3,10,-5,STONE)
Block(-3,10,-4,STONE)
Block(-3,10,-3,STONE)
Block(-3,10,-2,STONE)
Block(-3,10,-1,STONE)
Block(-3,10,0,STONE)
Block(-3,10,1,STONE)
Block(-3,10,2,STONE)
Block(-3,10,3,STONE)
Block(-3,10,4,STONE)
Block(-3,10,5,STONE)
Block(-3,10,6,STONE)
Block(-3,10,7,STONE)
Block(-3,10,8,STONE)
Block(-3,10,9,STONE)
Block(-3,10,10,STONE)
Block(-3,10,11,STONE)
Block(-3,10,12,STONE)
Block(-3,10,13,STONE)
Block(-3,10,14,STONE)
Block(-3,10,15,STONE)
Block(-3,10,16,STONE)
Block(-3,11,-10,STONE)
Block(-3,11,-9,STONE)
Block(-3,11,-8,STONE)
Block(-3,11,-7,STONE)
Block(-3,11,-6,STONE)
Block(-3,11,-5,STONE)
Block(-3,11,-4,STONE)
Block(-3,11,-3,STONE)
Block(-3,11,-2,STONE)
Block(-3,11,-1,STONE)
Block(-3,11,0,STONE)
Block(-3,11,1,STONE)
Block(-3,11,2,STONE)
Block(-3,11,3,STONE)
Block(-3,11,4,STONE)
Block(-3,11,5,STONE)
Block(-3,11,6,STONE)
Block(-3,11,7,STONE)
Block(-3,11,8,STONE)
Block(-3,11,9,STONE)
Block(-3,11,10,STONE)
Block(-3,11,11,STONE)
Block(-3,11,12,STONE)
Block(-3,11,13,STONE)
Block(-3,11,14,STONE)
Block(-3,11,15,STONE)
Block(-3,11,16,STONE)
Block(-3,11,17,STONE)
Block(-3,12,-10,STONE)
Block(-3,12,-9,STONE)
Block(-3,12,-8,STONE)
Block(-3,12,-7,STONE)
Block(-3,12,-6,STONE)
Block(-3,12,-5,STONE)
Block(-3,12,-4,STONE)
Block(-3,12,-3,STONE)
Block(-3,12,-2,STONE)
Block(-3,12,-1,STONE)
Block(-3,12,0,STONE)
Block(-3,12,1,STONE)
Block(-3,12,2,STONE)
Block(-3,12,3,STONE)
Block(-3,12,4,STONE)
Block(-3,12,5,STONE)
Block(-3,12,6,STONE)
Block(-3,12,7,STONE)
Block(-3,12,8,STONE)
Block(-3,12,9,STONE)
Block(-3,12,10,STONE)
Block(-3,12,11,STONE)
Block(-3,12,12,STONE)
Block(-3,12,13,STONE)
Block(-3,12,14,STONE)
Block(-3,12,15,STONE)
Block(-3,12,16,STONE)
Block(-3,12,17,STONE)
Block(-3,12,18,STONE)
Block(-3,13,-10,STONE)
Block(-3,13,-9,STONE)
Block(-3,13,-8,STONE)
Block(-3,13,-7,STONE)
Block(-3,13,-6,STONE)
Block(-3,13,-5,STONE)
Block(-3,13,-4,STONE)
Block(-3,13,-3,STONE)
Block(-3,13,-2,STONE)
Block(-3,13,-1,STONE)
Block(-3,13,0,STONE)
Block(-3,13,1,STONE)
Block(-3,13,2,STONE)
Block(-3,13,3,STONE)
Block(-3,13,4,STONE)
Block(-3,13,5,STONE)
Block(-3,13,6,STONE)
Block(-3,13,7,STONE)
Block(-3,13,8,STONE)
Block(-3,13,9,STONE)
Block(-3,13,10,STONE)
Block(-3,13,11,STONE)
Block(-3,13,12,STONE)
Block(-3,13,13,STONE)
Block(-3,13,14,STONE)
Block(-3,13,15,STONE)
Block(-3,13,16,STONE)
Block(-3,13,17,STONE)
Block(-3,13,18,STONE)
Block(-3,13,19,STONE)
Block(-3,14,-10,STONE)
Block(-3,14,-9,STONE)
Block(-3,14,-8,STONE)
Block(-3,14,-7,STONE)
Block(-3,14,-6,STONE)
Block(-3,14,-5,STONE)
Block(-3,14,-4,STONE)
Block(-3,14,-3,STONE)
Block(-3,14,-2,STONE)
Block(-3,14,-1,STONE)
Block(-3,14,0,STONE)
Block(-3,14,1,STONE)
Block(-3,14,2,STONE)
Block(-3,14,3,STONE)
Block(-3,14,4,STONE)
Block(-3,14,5,STONE)
Block(-3,14,6,STONE)
Block(-3,14,7,STONE)
Block(-3,14,8,STONE)
Block(-3,14,9,STONE)
Block(-3,14,10,STONE)
Block(-3,14,11,STONE)
Block(-3,14,12,STONE)
Block(-3,14,13,STONE)
Block(-3,14,14,STONE)
Block(-3,14,15,STONE)
Block(-3,14,16,STONE)
Block(-3,14,17,STONE)
Block(-3,14,18,STONE)
Block(-3,14,19,STONE)
Block(-3,14,20,STONE)
Block(-3,15,-9,STONE)
Block(-3,15,-8,STONE)
Block(-3,15,-7,STONE)
Block(-3,15,-6,STONE)
Block(-3,15,-5,STONE)
Block(-3,15,-4,STONE)
Block(-3,15,-3,STONE)
Block(-3,15,-2,STONE)
Block(-3,15,-1,STONE)
Block(-3,15,0,STONE)
Block(-3,15,1,STONE)
Block(-3,15,2,STONE)
Block(-3,15,3,STONE)
Block(-3,15,4,STONE)
Block(-3,15,5,STONE)
Block(-3,15,6,STONE)
Block(-3,15,7,STONE)
Block(-3,15,8,STONE)
Block(-3,15,9,STONE)
Block(-3,15,10,STONE)
Block(-3,15,11,STONE)
Block(-3,15,12,STONE)
Block(-3,15,13,STONE)
Block(-3,15,14,STONE)
Block(-3,15,15,STONE)
Block(-3,15,16,STONE)
Block(-3,15,17,STONE)
Block(-3,15,18,STONE)
Block(-3,15,19,STONE)
Block(-3,15,20,STONE)
Block(-3,16,-9,STONE)
Block(-3,16,-8,STONE)
Block(-3,16,-7,STONE)
Block(-3,16,-6,STONE)
Block(-3,16,-5,STONE)
Block(-3,16,-4,STONE)
Block(-3,16,-3,STONE)
Block(-3,16,-2,STONE)
Block(-3,16,-1,STONE)
Block(-3,16,0,STONE)
Block(-3,16,1,STONE)
Block(-3,16,2,STONE)
Block(-3,16,3,STONE)
Block(-3,16,4,STONE)
Block(-3,16,5,STONE)
Block(-3,16,6,STONE)
Block(-3,16,7,STONE)
Block(-3,16,8,STONE)
Block(-3,16,9,STONE)
Block(-3,16,10,STONE)
Block(-3,16,11,STONE)
Block(-3,16,12,STONE)
Block(-3,16,13,STONE)
Block(-3,16,14,STONE)
Block(-3,16,15,STONE)
Block(-3,16,16,STONE)
Block(-3,16,17,STONE)
Block(-3,16,18,STONE)
Block(-3,16,19,STONE)
Block(-3,16,20,STONE)
Block(-3,17,-8,STONE)
Block(-3,17,-7,STONE)
