#######################################################################
# +-----------------------------------------------------------------+ #
# |                            BO3 object                           | #
# +-----------------------------------------------------------------+ #
#######################################################################

# This is the config file of a custom object.
# If you add this object correctly to your BiomeConfigs, it will spawn in the world.

# This is the creator of this BO3 object
Author: BO3 BulkEdit (by LanToaster)

# A short description of this BO3 object
Description: This Object was Created with BO3_BulkEdit

# The BO3 version, don't change this! It can be used by external applications to do a version check.
Version: 3

# The settings mode, WriteAll, WriteWithoutComments or WriteDisable. See WorldConfig.
SettingsMode: WriteDisable


#######################################################################
# +-----------------------------------------------------------------+ #
# |                          Main settings                          | #
# +-----------------------------------------------------------------+ #
#######################################################################

# This needs to be set to true to spawn the object in the Tree and Sapling resources.
Tree: true

# The frequency of the BO3 from 1 to 200. Tries this many times to spawn this BO3 when using the CustomObject(...) resource.
# Ignored by Tree(..), Sapling(..) and CustomStructure(..)
Frequency: 1

# The rarity of the BO3 from 0 to 100. Each spawn attempt has rarity% chance to succeed when using the CustomObject(...) resource.
# Ignored by Tree(..), Sapling(..) and CustomStructure(..)
Rarity: 100.0

# If you set this to true, the BO3 will be placed with a random rotation.
RotateRandomly: true

# The spawn height of the BO3 - randomY, highestBlock or highestSolidBlock.
SpawnHeight: highestSolidBlock
SpawnHeightOffset: -1
# The height limits for the BO3.
MinHeight: 0

MaxHeight: 256

# Objects can have other objects attacthed to it: branches. Branches can also
# have branches attached to it, which can also have branches, etc. This is the
# maximum branch depth for this objects.
MaxBranchDepth: 10

# When spawned with the UseWorld keyword, this BO3 should NOT spawn in the following biomes.
# If you writer.write the BO3 name directly in the BiomeConfigs, this will be ignored.
ExcludedBiomes: All


#######################################################################
# +-----------------------------------------------------------------+ #
# |                      Source block settings                      | #
# +-----------------------------------------------------------------+ #
#######################################################################

# The block(s) the BO3 should spawn in.
SourceBlocks: AIR, DIRT, GRASS

# The maximum percentage of the BO3 that can be outside the SourceBlock.
# The BO3 won't be placed on a location with more blocks outside the SourceBlock than this percentage.
MaxPercentageOutsideSourceBlock: 50

# What to do when a block is about to be placed outside the SourceBlock? (dontPlace, placeAnyway)
MaxPercentageOutsideSourceBlock: 5


#######################################################################
# +-----------------------------------------------------------------+ #
# |                              Blocks                             | #
# +-----------------------------------------------------------------+ #
#######################################################################

# All the blocks used in the BO3 are listed here. Possible blocks:
# Block(x,y,z,id[.data][,nbtfile.nbt)
# RandomBlock(x,y,z,id[:data][,nbtfile.nbt],chance[,id[:data][,nbtfile.nbt],chance[,...]])
# So RandomBlock(0,0,0,CHEST,chest.nbt,50,CHEST,anotherchest.nbt,100) will spawn a chest at
# the BO3 origin, and give it a 50% chance to have the contents of chest.nbt, or, if that
# fails, a 100% percent chance to have the contents of anotherchest.nbt.
Block(-6,0,-2,LOG:12)
Block(-4,0,-2,LOG:12)
Block(-6,0,-1,LOG:12)
Block(-4,0,-1,LOG:12)
Block(-3,0,-1,LOG:12)
Block(-5,0,0,LOG:12)
Block(-4,0,0,LOG:12)
Block(-3,0,0,LOG:12)
Block(-2,0,0,LOG:12)
Block(-6,0,1,LOG:12)
Block(-5,0,1,LOG:12)
Block(-4,0,1,LOG:12)
Block(-3,0,1,LOG:12)
Block(-2,0,1,LOG:12)
Block(-1,0,1,LOG:12)
Block(-6,0,2,LOG:12)
Block(-4,0,2,LOG:12)
Block(-3,0,2,LOG:12)
Block(-2,0,2,LOG:12)
Block(-1,0,2,LOG:12)
Block(-6,0,3,LOG:12)
Block(-4,0,3,LOG:12)
Block(-3,0,3,LOG:12)
Block(-2,0,3,LOG:12)
Block(-1,0,3,LOG:12)
Block(0,0,3,LOG:12)
Block(-3,0,4,LOG:12)
Block(-2,0,4,LOG:12)
Block(-1,0,4,LOG:12)
Block(1,0,4,LOG:12)
Block(-3,0,5,LOG:12)
Block(-5,1,0,LOG:12)
Block(-4,1,0,LOG:12)
Block(-4,1,1,LOG:12)
Block(-3,1,1,LOG:12)
Block(-2,1,1,LOG:12)
Block(-6,1,2,LOG:12)
Block(-4,1,2,LOG:12)
Block(-3,1,2,LOG:12)
Block(-2,1,2,LOG:12)
Block(-3,1,3,LOG:12)
Block(-2,1,3,LOG:12)
Block(-3,1,4,LOG:12)
Block(-4,2,0,LOG:12)
Block(-3,2,0,LOG:12)
Block(-2,2,0,LOG:12)
Block(-4,2,1,LOG:12)
Block(-3,2,1,LOG:12)
Block(-2,2,1,LOG:12)
Block(-4,2,2,LOG:12)
Block(-3,2,2,LOG:12)
Block(-2,2,2,LOG:12)
Block(-3,2,3,LOG:12)
Block(-2,2,3,LOG:12)
Block(-4,3,0,LOG:12)
Block(-3,3,0,LOG:12)
Block(-4,3,1,LOG:12)
Block(-3,3,1,LOG:12)
Block(-2,3,1,LOG:12)
Block(-4,3,2,LOG:12)
Block(-3,3,2,LOG:12)
Block(-2,3,2,LOG:12)
Block(-1,3,2,LOG:12)
Block(-3,3,3,LOG:12)
Block(-4,4,1,LOG:12)
Block(-3,4,1,LOG:12)
Block(-2,4,1,LOG:12)
Block(-4,4,2,LOG:12)
Block(-3,4,2,LOG:12)
Block(-2,4,2,LOG:12)
Block(-3,5,0,LOG:12)
Block(-2,5,0,LOG:12)
Block(-4,5,1,LOG:12)
Block(-3,5,1,LOG:12)
Block(-3,5,2,LOG:12)
Block(-2,5,2,LOG:12)
Block(-4,6,0,LOG:12)
Block(-2,6,0,LOG:12)
Block(-4,6,1,LOG:12)
Block(-3,6,1,LOG:12)
Block(-2,6,1,LOG:12)
Block(-3,6,2,LOG:12)
Block(-4,7,0,LOG:12)
Block(-2,7,0,LOG:12)
Block(-4,7,1,LOG:12)
Block(-3,7,1,LOG:12)
Block(-2,7,1,LOG:12)
Block(-2,7,2,LOG:12)
Block(-4,8,0,LOG:12)
Block(-2,8,0,LOG:12)
Block(-4,8,1,LOG:12)
Block(-3,8,1,LOG:12)
Block(-2,8,1,LOG:12)
Block(-3,8,2,LOG:12)
Block(-2,8,2,LOG:12)
Block(-1,8,2,LOG:12)
Block(-4,9,0,LOG:12)
Block(-3,9,0,LOG:12)
Block(-2,9,0,LOG:12)
Block(-4,9,1,LOG:12)
Block(-3,9,1,LOG:12)
Block(-2,9,1,LOG:12)
Block(-1,9,1,LOG:12)
Block(-3,9,2,LOG:12)
Block(-2,9,2,LOG:12)
Block(-1,9,2,LOG:12)
Block(-2,9,3,LOG:12)
Block(-1,9,3,LOG:12)
Block(-1,9,4,LOG:12)
Block(0,9,4,LOG:12)
Block(1,9,4,LOG:12)
Block(2,9,5,LEAVES:0)
Block(2,9,6,LEAVES:0)
Block(4,9,6,LEAVES:0)
Block(6,9,6,LEAVES:0)
Block(7,9,6,LEAVES:0)
Block(-3,10,0,LOG:12)
Block(-3,10,1,LOG:12)
Block(-2,10,1,LOG:12)
Block(-3,10,2,LOG:12)
Block(-2,10,2,LOG:12)
Block(-2,10,3,LOG:12)
Block(-1,10,3,LOG:12)
Block(6,10,3,LEAVES:0)
Block(7,10,3,LEAVES:0)
Block(-1,10,4,LOG:12)
Block(0,10,4,LOG:12)
Block(1,10,4,LOG:12)
Block(1,10,5,LOG:12)
Block(2,10,5,LOG:12)
Block(4,10,5,LEAVES:0)
Block(8,10,5,LEAVES:0)
Block(1,10,6,LEAVES:0)
Block(2,10,6,LEAVES:0)
Block(4,10,6,LEAVES:0)
Block(5,10,6,LEAVES:0)
Block(6,10,6,LEAVES:0)
Block(7,10,6,LEAVES:0)
Block(8,10,6,LEAVES:0)
Block(9,10,6,LEAVES:0)
Block(4,10,7,LEAVES:0)
Block(4,10,8,LEAVES:0)
Block(5,10,8,LEAVES:0)
Block(-3,11,0,LOG:12)
Block(-4,11,1,LOG:12)
Block(-3,11,1,LOG:12)
Block(-2,11,1,LOG:12)
Block(-3,11,2,LOG:12)
Block(2,11,2,LOG:12)
Block(0,11,3,LEAVES:0)
Block(6,11,3,LEAVES:0)
Block(8,11,3,LEAVES:0)
Block(2,11,4,LEAVES:0)
Block(9,11,4,LEAVES:0)
Block(2,11,5,LOG:12)
Block(2,11,6,LOG:12)
Block(3,11,6,LEAVES:0)
Block(4,11,6,LEAVES:0)
Block(5,11,6,LEAVES:0)
Block(6,11,6,LEAVES:0)
Block(7,11,6,LOG:12)
Block(0,11,7,LEAVES:0)
Block(1,11,7,LEAVES:0)
Block(5,11,7,LEAVES:0)
Block(6,11,7,LEAVES:0)
Block(4,11,8,LEAVES:0)
Block(6,11,9,LEAVES:0)
Block(7,11,9,LEAVES:0)
Block(8,11,9,LEAVES:0)
Block(6,11,10,LEAVES:0)
Block(-3,12,0,LOG:12)
Block(-2,12,0,LOG:12)
Block(-4,12,1,LOG:12)
Block(-3,12,1,LOG:12)
Block(-2,12,1,LOG:12)
Block(-4,12,2,LOG:12)
Block(-3,12,2,LOG:12)
Block(6,12,2,LEAVES:0)
Block(1,12,3,LEAVES:0)
Block(2,12,3,LEAVES:0)
Block(6,12,3,LEAVES:0)
Block(8,12,3,LEAVES:0)
Block(2,12,4,LEAVES:0)
Block(3,12,4,LEAVES:0)
Block(6,12,4,LEAVES:0)
Block(0,12,5,LEAVES:0)
Block(1,12,5,LEAVES:0)
Block(2,12,5,LEAVES:0)
Block(10,12,5,LEAVES:8)
Block(2,12,6,LOG:12)
Block(3,12,6,LOG:12)
Block(4,12,6,LEAVES:0)
Block(6,12,6,LEAVES:0)
Block(7,12,6,LEAVES:0)
Block(8,12,6,LEAVES:8)
Block(9,12,6,LEAVES:0)
Block(1,12,7,LEAVES:0)
Block(2,12,7,LEAVES:0)
Block(3,12,7,LOG:12)
Block(4,12,7,LOG:12)
Block(2,12,8,LEAVES:0)
Block(4,12,8,LEAVES:0)
Block(5,12,8,LEAVES:0)
Block(9,12,8,LEAVES:0)
Block(4,12,9,LEAVES:0)
Block(6,12,9,LEAVES:0)
Block(5,12,10,LEAVES:0)
Block(-3,13,-3,LOG:12)
Block(-3,13,-2,LOG:12)
Block(-3,13,-1,LOG:12)
Block(-4,13,0,LOG:12)
Block(-3,13,0,LOG:12)
Block(-2,13,0,LOG:12)
Block(-4,13,1,LOG:12)
Block(-3,13,1,LOG:12)
Block(-2,13,1,LOG:12)
Block(-4,13,2,LOG:12)
Block(-3,13,2,LOG:12)
Block(2,13,2,LEAVES:0)
Block(3,13,2,LEAVES:0)
Block(5,13,2,LOG:12)
Block(6,13,2,LOG:12)
Block(2,13,3,LEAVES:0)
Block(3,13,3,LEAVES:0)
Block(4,13,3,LEAVES:0)
Block(5,13,3,LEAVES:0)
Block(6,13,3,LOG:12)
Block(9,13,3,LEAVES:8)
Block(3,13,4,LEAVES:0)
Block(5,13,4,LEAVES:0)
Block(6,13,4,LEAVES:0)
Block(1,13,5,LEAVES:0)
Block(2,13,5,LEAVES:0)
Block(3,13,5,LEAVES:0)
Block(5,13,5,LEAVES:0)
Block(6,13,5,LEAVES:0)
Block(7,13,5,LEAVES:0)
Block(10,13,5,LEAVES:8)
Block(0,13,6,LEAVES:0)
Block(1,13,6,LEAVES:0)
Block(2,13,6,LEAVES:0)
Block(3,13,6,LEAVES:0)
Block(4,13,6,LEAVES:0)
Block(6,13,6,LEAVES:0)
Block(7,13,6,LEAVES:0)
Block(8,13,6,LEAVES:0)
Block(9,13,6,LEAVES:0)
Block(10,13,6,LEAVES:8)
Block(0,13,7,LEAVES:0)
Block(1,13,7,LEAVES:0)
Block(2,13,7,LEAVES:0)
Block(4,13,7,LOG:12)
Block(5,13,7,LOG:12)
Block(6,13,7,LEAVES:0)
Block(7,13,7,LEAVES:0)
Block(3,13,8,LEAVES:0)
Block(4,13,8,LOG:12)
Block(5,13,8,LOG:12)
Block(6,13,8,LEAVES:0)
Block(7,13,8,LEAVES:8)
Block(8,13,8,LEAVES:0)
Block(1,13,9,LEAVES:0)
Block(2,13,9,LEAVES:0)
Block(3,13,9,LEAVES:0)
Block(4,13,9,LEAVES:0)
Block(5,13,9,LEAVES:0)
Block(6,13,9,LEAVES:0)
Block(7,13,9,LEAVES:0)
Block(3,13,10,LEAVES:4)
Block(4,13,10,LOG:12)
Block(6,13,10,LEAVES:0)
Block(4,13,11,LEAVES:4)
Block(-3,14,-4,LOG:12)
Block(-2,14,-4,LOG:12)
Block(-3,14,-3,LOG:12)
Block(-4,14,0,LOG:12)
Block(-4,14,1,LOG:12)
Block(-3,14,1,LOG:12)
Block(-2,14,1,LOG:12)
Block(-4,14,2,LOG:12)
Block(-3,14,2,LOG:12)
Block(5,14,2,LEAVES:0)
Block(6,14,2,LEAVES:0)
Block(2,14,3,LEAVES:0)
Block(3,14,3,LEAVES:0)
Block(5,14,3,LEAVES:0)
Block(2,14,4,LEAVES:0)
Block(3,14,4,LEAVES:0)
Block(2,14,5,LEAVES:0)
Block(3,14,5,LEAVES:0)
Block(4,14,5,LEAVES:0)
Block(6,14,5,LEAVES:0)
Block(7,14,5,LEAVES:0)
Block(1,14,6,LEAVES:0)
Block(3,14,6,LEAVES:0)
Block(4,14,6,LEAVES:0)
Block(5,14,6,LEAVES:0)
Block(9,14,6,LEAVES:8)
Block(2,14,7,LEAVES:0)
Block(3,14,7,LEAVES:0)
Block(5,14,7,LEAVES:0)
Block(6,14,7,LEAVES:0)
Block(9,14,7,LEAVES:8)
Block(1,14,8,LEAVES:0)
Block(2,14,8,LEAVES:0)
Block(3,14,8,LEAVES:0)
Block(4,14,8,LEAVES:0)
Block(5,14,8,LOG:12)
Block(6,14,8,LOG:12)
Block(7,14,8,LEAVES:0)
Block(1,14,9,LEAVES:0)
Block(2,14,9,LEAVES:0)
Block(3,14,9,LEAVES:0)
Block(4,14,9,LEAVES:0)
Block(6,14,9,LOG:12)
Block(7,14,9,LEAVES:0)
Block(4,14,10,LEAVES:0)
Block(6,14,10,LEAVES:0)
Block(8,14,10,LEAVES:0)
Block(4,14,11,LEAVES:4)
Block(5,14,11,LEAVES:0)
Block(6,14,11,LEAVES:0)
Block(-2,15,-5,LOG:12)
Block(1,15,-5,LEAVES:0)
Block(-2,15,-4,LOG:12)
Block(2,15,-4,LEAVES:0)
Block(-1,15,-3,LEAVES:0)
Block(0,15,-3,LEAVES:0)
Block(1,15,-3,LEAVES:0)
Block(2,15,-3,LEAVES:0)
Block(3,15,-3,LEAVES:0)
Block(1,15,-1,LOG:12)
Block(-4,15,0,LOG:12)
Block(-3,15,0,LOG:12)
Block(-2,15,0,LOG:12)
Block(-5,15,1,LEAVES:0)
Block(-4,15,1,LOG:12)
Block(-3,15,1,LOG:12)
Block(-2,15,1,LOG:12)
Block(-1,15,1,LEAVES:0)
Block(0,15,1,LEAVES:0)
Block(-4,15,2,LOG:12)
Block(-3,15,2,LOG:12)
Block(-7,15,3,LEAVES:0)
Block(-6,15,3,LEAVES:0)
Block(-5,15,3,LEAVES:0)
Block(-2,15,3,LEAVES:0)
Block(3,15,3,LOG:12)
Block(6,15,3,LEAVES:0)
Block(-8,15,4,LEAVES:0)
Block(-6,15,4,LEAVES:0)
Block(2,15,4,LEAVES:0)
Block(3,15,4,LEAVES:0)
Block(5,15,4,LEAVES:0)
Block(-8,15,5,LEAVES:0)
Block(-7,15,5,LEAVES:0)
Block(-5,15,5,LEAVES:0)
Block(1,15,5,LOG:12)
Block(3,15,5,LEAVES:0)
Block(4,15,5,LEAVES:0)
Block(5,15,5,LEAVES:0)
Block(6,15,5,LEAVES:0)
Block(1,15,6,LEAVES:0)
Block(2,15,6,LEAVES:0)
Block(3,15,6,LEAVES:0)
Block(5,15,6,LEAVES:0)
Block(6,15,6,LEAVES:0)
Block(7,15,6,LEAVES:0)
Block(9,15,6,LEAVES:8)
Block(0,15,7,LEAVES:0)
Block(3,15,7,LEAVES:0)
Block(5,15,7,LEAVES:0)
Block(6,15,7,LEAVES:0)
Block(7,15,7,LEAVES:0)
Block(2,15,8,LEAVES:0)
Block(4,15,8,LEAVES:0)
Block(5,15,8,LOG:12)
Block(6,15,8,LEAVES:0)
Block(8,15,8,LEAVES:0)
Block(0,15,9,LEAVES:0)
Block(2,15,9,LEAVES:0)
Block(3,15,9,LEAVES:0)
Block(4,15,9,LEAVES:0)
Block(5,15,9,LEAVES:4)
Block(6,15,9,LOG:12)
Block(7,15,9,LOG:12)
Block(8,15,9,LEAVES:12)
Block(4,15,10,LEAVES:0)
Block(6,15,10,LEAVES:0)
Block(7,15,10,LEAVES:4)
Block(4,15,11,LEAVES:0)
Block(5,15,11,LEAVES:0)
Block(-2,16,-6,LOG:12)
Block(1,16,-6,LEAVES:0)
Block(-2,16,-5,LOG:12)
Block(-1,16,-5,LEAVES:0)
Block(1,16,-5,LEAVES:0)
Block(-6,16,-4,LEAVES:8)
Block(-2,16,-4,LEAVES:0)
Block(2,16,-4,LEAVES:0)
Block(4,16,-4,LEAVES:0)
Block(-10,16,-3,LEAVES:0)
Block(-6,16,-3,LEAVES:0)
Block(-1,16,-3,LEAVES:0)
Block(0,16,-3,LEAVES:0)
Block(1,16,-3,LOG:12)
Block(2,16,-3,LEAVES:0)
Block(3,16,-3,LEAVES:0)
Block(-7,16,-2,LEAVES:0)
Block(-6,16,-2,LEAVES:0)
Block(-3,16,-2,LEAVES:0)
Block(-1,16,-2,LEAVES:0)
Block(1,16,-2,LEAVES:0)
Block(-6,16,-1,LOG:12)
Block(-5,16,-1,LOG:12)
Block(-6,16,0,LEAVES:0)
Block(-5,16,0,LOG:12)
Block(-4,16,0,LOG:12)
Block(-3,16,0,LOG:12)
Block(-2,16,0,LOG:12)
Block(-1,16,0,LEAVES:0)
Block(-7,16,1,LEAVES:0)
Block(-5,16,1,LEAVES:0)
Block(-4,16,1,LOG:12)
Block(-3,16,1,LOG:12)
Block(-2,16,1,LOG:12)
Block(-1,16,1,LEAVES:0)
Block(0,16,1,LEAVES:0)
Block(-8,16,2,LEAVES:0)
Block(-7,16,2,LEAVES:0)
Block(-5,16,2,LOG:12)
Block(-4,16,2,LOG:12)
Block(-3,16,2,LOG:12)
Block(-2,16,2,LOG:12)
Block(0,16,2,LEAVES:0)
Block(-9,16,3,LEAVES:0)
Block(-8,16,3,LEAVES:0)
Block(-7,16,3,LEAVES:0)
Block(-6,16,3,LEAVES:0)
Block(-4,16,3,LEAVES:0)
Block(-3,16,3,LEAVES:0)
Block(-2,16,3,LEAVES:0)
Block(2,16,3,LEAVES:0)
Block(3,16,3,LEAVES:0)
Block(-8,16,4,LEAVES:0)
Block(-7,16,4,LEAVES:0)
Block(-6,16,4,LEAVES:0)
Block(-3,16,4,LEAVES:0)
Block(-2,16,4,LEAVES:0)
Block(1,16,4,LEAVES:0)
Block(2,16,4,LEAVES:0)
Block(3,16,4,LOG:12)
Block(4,16,4,LEAVES:0)
Block(5,16,4,LEAVES:0)
Block(6,16,4,LEAVES:0)
Block(-8,16,5,LEAVES:0)
Block(-7,16,5,LEAVES:0)
Block(-4,16,5,LEAVES:0)
Block(1,16,5,LEAVES:0)
Block(2,16,5,LEAVES:0)
Block(3,16,5,LEAVES:0)
Block(4,16,5,LEAVES:0)
Block(-9,16,6,LEAVES:0)
Block(-8,16,6,LEAVES:0)
Block(0,16,6,LEAVES:0)
Block(1,16,6,LEAVES:0)
Block(3,16,6,LEAVES:0)
Block(4,16,6,LEAVES:0)
Block(5,16,6,LEAVES:0)
Block(6,16,6,LEAVES:0)
Block(-9,16,7,LEAVES:0)
Block(0,16,7,LEAVES:0)
Block(1,16,7,LEAVES:0)
Block(2,16,7,LEAVES:0)
Block(3,16,7,LOG:12)
Block(4,16,7,LEAVES:0)
Block(5,16,7,LEAVES:0)
Block(0,16,8,LEAVES:0)
Block(2,16,8,LEAVES:0)
Block(3,16,8,LEAVES:0)
Block(5,16,8,LEAVES:0)
Block(6,16,8,LEAVES:0)
Block(7,16,8,LEAVES:0)
Block(8,16,8,LEAVES:0)
Block(1,16,9,LEAVES:0)
Block(3,16,9,LEAVES:0)
Block(7,16,9,LOG:12)
Block(8,16,9,LEAVES:0)
Block(4,16,10,LEAVES:0)
Block(6,16,10,LEAVES:4)
Block(7,16,10,LEAVES:0)
Block(8,16,10,LEAVES:0)
Block(9,16,10,LEAVES:0)
Block(4,16,11,LEAVES:12)
Block(5,16,11,LEAVES:4)
Block(6,16,11,LEAVES:4)
Block(6,16,12,LEAVES:0)
Block(7,16,12,LEAVES:0)
Block(8,16,12,LEAVES:4)
Block(1,17,-9,LEAVES:0)
Block(-1,17,-8,LEAVES:0)
Block(-4,17,-7,LEAVES:8)
Block(-2,17,-6,LOG:12)
Block(1,17,-6,LEAVES:0)
Block(2,17,-6,LEAVES:0)
Block(-9,17,-5,LEAVES:0)
Block(-6,17,-5,LEAVES:0)
Block(2,17,-5,LEAVES:0)
Block(4,17,-5,LEAVES:0)
Block(-4,17,-4,LEAVES:0)
Block(-3,17,-4,LEAVES:0)
Block(2,17,-4,LEAVES:0)
Block(4,17,-4,LEAVES:0)
Block(-8,17,-3,LEAVES:0)
Block(-7,17,-3,LOG:12)
Block(-6,17,-3,LEAVES:0)
Block(-5,17,-3,LEAVES:0)
Block(-2,17,-3,LEAVES:0)
Block(-1,17,-3,LEAVES:0)
Block(0,17,-3,LEAVES:0)
Block(1,17,-3,LEAVES:0)
Block(3,17,-3,LEAVES:0)
Block(-7,17,-2,LOG:12)
Block(-6,17,-2,LOG:12)
Block(-5,17,-2,LEAVES:0)
Block(-3,17,-2,LEAVES:0)
Block(-2,17,-2,LEAVES:0)
Block(-1,17,-2,LEAVES:0)
Block(-10,17,-1,LEAVES:0)
Block(-9,17,-1,LEAVES:0)
Block(-6,17,-1,LOG:12)
Block(-2,17,-1,LEAVES:0)
Block(-1,17,-1,LOG:12)
Block(0,17,-1,LOG:12)
Block(2,17,-1,LEAVES:0)
Block(-9,17,0,LEAVES:0)
Block(-8,17,0,LEAVES:0)
Block(-7,17,0,LEAVES:0)
Block(-5,17,0,LOG:12)
Block(-4,17,0,LEAVES:0)
Block(-3,17,0,LOG:12)
Block(-2,17,0,LOG:12)
Block(-1,17,0,LOG:12)
Block(0,17,0,LEAVES:0)
Block(1,17,0,LEAVES:0)
Block(-8,17,1,LEAVES:0)
Block(-7,17,1,LEAVES:0)
Block(-6,17,1,LEAVES:0)
Block(-5,17,1,LOG:12)
Block(-4,17,1,LOG:12)
Block(-3,17,1,LOG:12)
Block(-2,17,1,LOG:12)
Block(1,17,1,LOG:12)
Block(3,17,1,LEAVES:0)
Block(-7,17,2,LEAVES:0)
Block(-6,17,2,LEAVES:0)
Block(-5,17,2,LOG:12)
Block(-4,17,2,LOG:12)
Block(-3,17,2,LOG:12)
Block(-2,17,2,LOG:12)
Block(-1,17,2,LOG:12)
Block(2,17,2,LEAVES:0)
Block(3,17,2,LEAVES:0)
Block(4,17,2,LEAVES:0)
Block(-7,17,3,LEAVES:0)
Block(-6,17,3,LOG:12)
Block(-5,17,3,LOG:12)
Block(-4,17,3,LEAVES:0)
Block(-2,17,3,LEAVES:0)
Block(-1,17,3,LOG:12)
Block(0,17,3,LOG:12)
Block(2,17,3,LEAVES:0)
Block(4,17,3,LEAVES:0)
Block(-7,17,4,LOG:12)
Block(-6,17,4,LOG:12)
Block(-2,17,4,LEAVES:0)
Block(0,17,4,LOG:12)
Block(1,17,4,LEAVES:0)
Block(2,17,4,LEAVES:0)
Block(4,17,4,LEAVES:0)
Block(5,17,4,LEAVES:0)
Block(6,17,4,LEAVES:0)
Block(-9,17,5,LEAVES:0)
Block(-7,17,5,LEAVES:0)
Block(-6,17,5,LEAVES:0)
Block(-2,17,5,LEAVES:0)
Block(0,17,5,LEAVES:0)
Block(1,17,5,LEAVES:0)
Block(3,17,5,LEAVES:0)
Block(4,17,5,LEAVES:0)
Block(-9,17,6,LEAVES:0)
Block(-8,17,6,LEAVES:0)
Block(-6,17,6,LEAVES:0)
Block(-5,17,6,LEAVES:0)
Block(-4,17,6,LEAVES:0)
Block(-2,17,6,LEAVES:0)
Block(-1,17,6,LEAVES:0)
Block(0,17,6,LEAVES:0)
Block(1,17,6,LEAVES:0)
Block(2,17,6,LEAVES:0)
Block(3,17,6,LEAVES:0)
Block(4,17,6,LEAVES:0)
Block(5,17,6,LEAVES:8)
Block(6,17,6,LEAVES:8)
Block(-9,17,7,LEAVES:0)
Block(-5,17,7,LEAVES:0)
Block(-1,17,7,LEAVES:0)
Block(3,17,7,LEAVES:0)
Block(4,17,7,LEAVES:0)
Block(6,17,7,LEAVES:0)
Block(7,17,7,LEAVES:0)
Block(8,17,7,LEAVES:8)
Block(-9,17,8,LEAVES:0)
Block(2,17,8,LEAVES:0)
Block(3,17,8,LEAVES:0)
Block(4,17,8,LEAVES:0)
Block(5,17,8,LEAVES:0)
Block(6,17,8,LEAVES:0)
Block(8,17,8,LEAVES:0)
Block(9,17,8,LEAVES:0)
Block(10,17,8,LEAVES:8)
Block(0,17,9,LEAVES:0)
Block(1,17,9,LEAVES:0)
Block(2,17,9,LEAVES:0)
Block(5,17,9,LEAVES:0)
Block(6,17,9,LEAVES:0)
Block(7,17,9,LOG:12)
Block(8,17,9,LEAVES:0)
Block(2,17,10,LEAVES:0)
Block(3,17,10,LEAVES:0)
Block(4,17,10,LOG:12)
Block(5,17,10,LEAVES:0)
Block(7,17,10,LEAVES:4)
Block(8,17,10,LEAVES:12)
Block(9,17,10,LEAVES:0)
Block(4,17,11,LEAVES:0)
Block(6,17,11,LEAVES:0)
Block(8,17,11,LEAVES:12)
Block(9,17,11,LEAVES:0)
Block(5,17,12,LEAVES:0)
Block(6,17,12,LEAVES:0)
Block(7,17,12,LOG:12)
Block(8,17,12,LEAVES:12)
Block(6,17,13,LEAVES:4)
Block(7,17,13,LEAVES:12)
Block(8,17,13,LEAVES:12)
Block(0,18,-11,LEAVES:0)
Block(1,18,-11,LEAVES:0)
Block(0,18,-10,LEAVES:0)
Block(2,18,-10,LEAVES:0)
Block(-10,18,-9,LEAVES:0)
Block(-9,18,-9,LEAVES:0)
Block(-1,18,-9,LEAVES:0)
Block(0,18,-9,LEAVES:0)
Block(1,18,-9,LOG:12)
Block(-4,18,-8,LEAVES:8)
Block(-1,18,-8,LEAVES:0)
Block(1,18,-8,LEAVES:0)
Block(-9,18,-7,LEAVES:0)
Block(-8,18,-7,LEAVES:8)
Block(-5,18,-7,LEAVES:8)
Block(-4,18,-7,LEAVES:8)
Block(-2,18,-7,LOG:12)
Block(-1,18,-7,LOG:12)
Block(1,18,-7,LEAVES:0)
Block(2,18,-7,LEAVES:0)
Block(-6,18,-6,LEAVES:0)
Block(-4,18,-6,LEAVES:0)
Block(-3,18,-6,LEAVES:0)
Block(-2,18,-6,LOG:12)
Block(-1,18,-6,LOG:12)
Block(3,18,-6,LEAVES:0)
Block(5,18,-6,LEAVES:0)
Block(6,18,-6,LEAVES:0)
Block(-13,18,-5,LEAVES:0)
Block(-9,18,-5,LEAVES:0)
Block(-7,18,-5,LEAVES:0)
Block(-6,18,-5,LEAVES:8)
Block(-5,18,-5,LEAVES:0)
Block(-3,18,-5,LEAVES:0)
Block(1,18,-5,LEAVES:0)
Block(3,18,-5,LEAVES:0)
Block(5,18,-5,LEAVES:0)
Block(-9,18,-4,LEAVES:0)
Block(-6,18,-4,LEAVES:0)
Block(-5,18,-4,LEAVES:0)
Block(-4,18,-4,LEAVES:0)
Block(-3,18,-4,LEAVES:0)
Block(4,18,-4,LEAVES:0)
Block(-9,18,-3,LEAVES:0)
Block(-8,18,-3,LOG:12)
Block(-6,18,-3,LEAVES:0)
Block(-4,18,-3,LEAVES:0)
Block(-3,18,-3,LEAVES:0)
Block(-2,18,-3,LOG:12)
Block(-1,18,-3,LEAVES:0)
Block(1,18,-3,LOG:12)
Block(2,18,-3,LEAVES:0)
Block(3,18,-3,LEAVES:0)
Block(5,18,-3,LEAVES:0)
Block(-10,18,-2,LEAVES:0)
Block(-8,18,-2,LOG:12)
Block(-7,18,-2,LOG:12)
Block(-6,18,-2,LOG:12)
Block(-5,18,-2,LEAVES:0)
Block(-2,18,-2,LEAVES:0)
Block(-1,18,-2,LEAVES:0)
Block(0,18,-2,LOG:12)
Block(1,18,-2,LOG:12)
Block(3,18,-2,LEAVES:0)
Block(5,18,-2,LEAVES:0)
Block(-10,18,-1,LEAVES:0)
Block(-9,18,-1,LEAVES:0)
Block(-8,18,-1,LEAVES:0)
Block(-6,18,-1,LEAVES:0)
Block(-5,18,-1,LEAVES:0)
Block(-4,18,-1,LEAVES:0)
Block(-2,18,-1,LEAVES:0)
Block(-1,18,-1,LOG:12)
Block(0,18,-1,LOG:12)
Block(1,18,-1,LEAVES:0)
Block(-12,18,0,LEAVES:0)
Block(-9,18,0,LEAVES:0)
Block(-8,18,0,LEAVES:0)
Block(-7,18,0,LEAVES:0)
Block(-6,18,0,LEAVES:0)
Block(-5,18,0,LEAVES:0)
Block(-4,18,0,LOG:12)
Block(-3,18,0,LOG:12)
Block(-2,18,0,LEAVES:0)
Block(0,18,0,LEAVES:0)
Block(2,18,0,LEAVES:0)
Block(-9,18,1,LEAVES:0)
Block(-8,18,1,LEAVES:0)
Block(-7,18,1,LEAVES:0)
Block(-6,18,1,LEAVES:0)
Block(-5,18,1,LEAVES:0)
Block(-4,18,1,LOG:12)
Block(-3,18,1,LOG:12)
Block(-2,18,1,LOG:12)
Block(1,18,1,LEAVES:0)
Block(4,18,1,LEAVES:0)
Block(-11,18,2,LEAVES:0)
Block(-8,18,2,LEAVES:0)
Block(-7,18,2,LEAVES:0)
Block(-5,18,2,LEAVES:0)
Block(-4,18,2,LOG:12)
Block(-3,18,2,LOG:12)
Block(0,18,2,LEAVES:0)
Block(2,18,2,LEAVES:0)
Block(4,18,2,LEAVES:0)
Block(5,18,2,LEAVES:0)
Block(-10,18,3,LEAVES:0)
Block(-9,18,3,LEAVES:0)
Block(-8,18,3,LEAVES:0)
Block(-7,18,3,LEAVES:0)
Block(-6,18,3,LOG:12)
Block(-4,18,3,LOG:12)
Block(-3,18,3,LOG:12)
Block(-2,18,3,LEAVES:0)
Block(-1,18,3,LOG:12)
Block(0,18,3,LOG:12)
Block(1,18,3,LEAVES:0)
Block(2,18,3,LEAVES:0)
Block(3,18,3,LEAVES:0)
Block(-8,18,4,LEAVES:0)
Block(-7,18,4,LOG:12)
Block(-6,18,4,LEAVES:0)
Block(-5,18,4,LEAVES:0)
Block(-3,18,4,LEAVES:0)
Block(-1,18,4,LEAVES:0)
Block(0,18,4,LOG:12)
Block(1,18,4,LOG:12)
Block(2,18,4,LEAVES:0)
Block(3,18,4,LEAVES:0)
Block(5,18,4,LEAVES:0)
Block(6,18,4,LEAVES:8)
Block(-10,18,5,LEAVES:12)
Block(-9,18,5,LEAVES:12)
Block(-8,18,5,LOG:12)
Block(-7,18,5,LOG:12)
Block(-5,18,5,LEAVES:0)
Block(-3,18,5,LEAVES:0)
Block(-2,18,5,LEAVES:0)
Block(0,18,5,LEAVES:0)
Block(1,18,5,LEAVES:0)
Block(2,18,5,LEAVES:0)
Block(3,18,5,LEAVES:0)
Block(4,18,5,LEAVES:0)
Block(5,18,5,LEAVES:8)
Block(6,18,5,LEAVES:8)
Block(-11,18,6,LEAVES:4)
Block(-10,18,6,LEAVES:4)
Block(-9,18,6,LEAVES:4)
Block(-6,18,6,LEAVES:0)
Block(-1,18,6,LEAVES:0)
Block(0,18,6,LEAVES:0)
Block(1,18,6,LEAVES:0)
Block(2,18,6,LEAVES:0)
Block(3,18,6,LEAVES:0)
Block(5,18,6,LEAVES:0)
Block(6,18,6,LEAVES:0)
Block(-12,18,7,LEAVES:12)
Block(-11,18,7,LEAVES:4)
Block(-10,18,7,LOG:12)
Block(-9,18,7,LEAVES:0)
Block(-8,18,7,LOG:12)
Block(0,18,7,LOG:12)
Block(2,18,7,LEAVES:0)
Block(3,18,7,LEAVES:0)
Block(4,18,7,LEAVES:0)
Block(5,18,7,LEAVES:0)
Block(-14,18,8,LEAVES:0)
Block(-12,18,8,LEAVES:0)
Block(-11,18,8,LEAVES:0)
Block(-10,18,8,LEAVES:0)
Block(-7,18,8,LEAVES:0)
Block(0,18,8,LEAVES:0)
Block(1,18,8,LEAVES:0)
Block(2,18,8,LEAVES:0)
Block(3,18,8,LEAVES:0)
Block(4,18,8,LEAVES:0)
Block(5,18,8,LEAVES:0)
Block(6,18,8,LEAVES:0)
Block(7,18,8,LEAVES:0)
Block(1,18,9,LEAVES:0)
Block(2,18,9,LEAVES:0)
Block(3,18,9,LEAVES:0)
Block(4,18,9,LEAVES:4)
Block(5,18,9,LOG:12)
Block(6,18,9,LOG:12)
Block(7,18,9,LEAVES:12)
Block(-9,18,10,LEAVES:0)
Block(1,18,10,LEAVES:0)
Block(2,18,10,LEAVES:0)
Block(3,18,10,LEAVES:0)
Block(5,18,10,LEAVES:0)
Block(6,18,10,LEAVES:4)
Block(7,18,10,LEAVES:0)
Block(3,18,11,LEAVES:0)
Block(4,18,11,LEAVES:0)
Block(5,18,11,LEAVES:0)
Block(6,18,11,LEAVES:4)
Block(7,18,11,LEAVES:0)
Block(8,18,11,LEAVES:12)
Block(6,18,12,LEAVES:0)
Block(7,18,12,LEAVES:12)
Block(8,18,12,LEAVES:4)
Block(-9,19,-12,LEAVES:8)
Block(-3,19,-12,LEAVES:0)
Block(-9,19,-10,LEAVES:8)
Block(-1,19,-10,LEAVES:0)
Block(0,19,-10,LEAVES:0)
Block(2,19,-10,LEAVES:0)
Block(-10,19,-9,LEAVES:0)
Block(-9,19,-9,LOG:12)
Block(-7,19,-9,LEAVES:0)
Block(-2,19,-9,LOG:12)
Block(-1,19,-9,LEAVES:0)
Block(0,19,-9,LEAVES:0)
Block(1,19,-9,LEAVES:0)
Block(2,19,-9,LOG:12)
Block(3,19,-9,LEAVES:0)
Block(-12,19,-8,LEAVES:0)
Block(-11,19,-8,LEAVES:0)
Block(-10,19,-8,LEAVES:0)
Block(-9,19,-8,LEAVES:0)
Block(-4,19,-8,LEAVES:8)
Block(-1,19,-8,LOG:12)
Block(4,19,-8,LEAVES:0)
Block(-11,19,-7,LEAVES:0)
Block(-10,19,-7,LEAVES:0)
Block(-9,19,-7,LEAVES:0)
Block(-8,19,-7,LEAVES:8)
Block(-7,19,-7,LEAVES:0)
Block(-2,19,-7,LEAVES:0)
Block(-1,19,-7,LOG:12)
Block(1,19,-7,LEAVES:0)
Block(3,19,-7,LEAVES:0)
Block(-13,19,-6,LEAVES:0)
Block(-12,19,-6,LEAVES:0)
Block(-11,19,-6,LEAVES:0)
Block(-9,19,-6,LEAVES:0)
Block(-7,19,-6,LEAVES:0)
Block(-6,19,-6,LEAVES:8)
Block(-5,19,-6,LEAVES:0)
Block(-3,19,-6,LEAVES:0)
Block(-2,19,-6,LEAVES:0)
Block(-1,19,-6,LOG:12)
Block(1,19,-6,LEAVES:0)
Block(2,19,-6,LEAVES:0)
Block(3,19,-6,LEAVES:0)
Block(4,19,-6,LEAVES:0)
Block(-14,19,-5,LEAVES:0)
Block(-13,19,-5,LEAVES:0)
Block(-12,19,-5,LEAVES:0)
Block(-7,19,-5,LEAVES:0)
Block(-6,19,-5,LEAVES:0)
Block(-5,19,-5,LEAVES:0)
Block(-4,19,-5,LEAVES:0)
Block(-3,19,-5,LEAVES:0)
Block(-2,19,-5,LEAVES:0)
Block(-1,19,-5,LEAVES:0)
Block(1,19,-5,LEAVES:0)
Block(2,19,-5,LEAVES:0)
Block(3,19,-5,LEAVES:0)
Block(5,19,-5,LEAVES:0)
Block(7,19,-5,LEAVES:0)
Block(-12,19,-4,LEAVES:0)
Block(-10,19,-4,LEAVES:0)
Block(-9,19,-4,LEAVES:0)
Block(-8,19,-4,LEAVES:0)
Block(-7,19,-4,LEAVES:0)
Block(-6,19,-4,LEAVES:0)
Block(-5,19,-4,LEAVES:0)
Block(-4,19,-4,LEAVES:0)
Block(-2,19,-4,LEAVES:0)
Block(-1,19,-4,LEAVES:0)
Block(0,19,-4,LEAVES:0)
Block(1,19,-4,LOG:12)
Block(2,19,-4,LOG:12)
Block(3,19,-4,LOG:12)
Block(4,19,-4,LEAVES:0)
Block(5,19,-4,LEAVES:0)
Block(-13,19,-3,LEAVES:4)
Block(-12,19,-3,LOG:12)
Block(-10,19,-3,LOG:12)
Block(-9,19,-3,LOG:12)
Block(-8,19,-3,LOG:12)
Block(-7,19,-3,LEAVES:0)
Block(-4,19,-3,LEAVES:0)
Block(-3,19,-3,LEAVES:0)
Block(-2,19,-3,LEAVES:0)
Block(-1,19,-3,LEAVES:0)
Block(0,19,-3,LEAVES:0)
Block(1,19,-3,LOG:12)
Block(2,19,-3,LOG:12)
Block(5,19,-3,LEAVES:0)
Block(-12,19,-2,LEAVES:0)
Block(-9,19,-2,LEAVES:0)
Block(-8,19,-2,LEAVES:0)
Block(-6,19,-2,LEAVES:0)
Block(-5,19,-2,LEAVES:0)
Block(-4,19,-2,LEAVES:0)
Block(-3,19,-2,LOG:12)
Block(-2,19,-2,LEAVES:0)
Block(-1,19,-2,LEAVES:0)
Block(0,19,-2,LEAVES:0)
Block(1,19,-2,LEAVES:0)
Block(2,19,-2,LEAVES:0)
Block(3,19,-2,LEAVES:0)
Block(-13,19,-1,LEAVES:4)
Block(-12,19,-1,LOG:12)
Block(-9,19,-1,LEAVES:0)
Block(-7,19,-1,LOG:12)
Block(-6,19,-1,LEAVES:0)
Block(-5,19,-1,LEAVES:0)
Block(-4,19,-1,LEAVES:0)
Block(-3,19,-1,LEAVES:0)
Block(-2,19,-1,LEAVES:0)
Block(-1,19,-1,LEAVES:0)
Block(0,19,-1,LEAVES:0)
Block(1,19,-1,LEAVES:0)
Block(3,19,-1,LEAVES:0)
Block(4,19,-1,LEAVES:0)
Block(5,19,-1,LEAVES:0)
Block(-13,19,0,LEAVES:0)
Block(-12,19,0,LEAVES:0)
Block(-11,19,0,LEAVES:0)
Block(-9,19,0,LEAVES:0)
Block(-8,19,0,LEAVES:0)
Block(-7,19,0,LEAVES:0)
Block(-6,19,0,LEAVES:0)
Block(-5,19,0,LEAVES:0)
Block(-4,19,0,LEAVES:0)
Block(-3,19,0,LOG:12)
Block(-2,19,0,LEAVES:0)
Block(-1,19,0,LEAVES:0)
Block(0,19,0,LOG:12)
Block(1,19,0,LEAVES:0)
Block(2,19,0,LEAVES:0)
Block(3,19,0,LEAVES:0)
Block(4,19,0,LEAVES:0)
Block(-10,19,1,LEAVES:0)
Block(-9,19,1,LEAVES:0)
Block(-8,19,1,LEAVES:0)
Block(-7,19,1,LEAVES:0)
Block(-6,19,1,LEAVES:0)
Block(-5,19,1,LEAVES:0)
Block(-4,19,1,LOG:12)
Block(-3,19,1,LOG:12)
Block(-2,19,1,LOG:12)
Block(-1,19,1,LEAVES:0)
Block(0,19,1,LEAVES:0)
Block(1,19,1,LEAVES:0)
Block(-12,19,2,LEAVES:0)
Block(-11,19,2,LEAVES:0)
Block(-9,19,2,LEAVES:0)
Block(-8,19,2,LEAVES:0)
Block(-7,19,2,LEAVES:0)
Block(-6,19,2,LOG:12)
Block(-5,19,2,LEAVES:0)
Block(-4,19,2,LEAVES:0)
Block(-3,19,2,LEAVES:0)
Block(-2,19,2,LEAVES:0)
Block(-1,19,2,LOG:12)
Block(1,19,2,LEAVES:0)
Block(2,19,2,LEAVES:0)
Block(-10,19,3,LEAVES:0)
Block(-9,19,3,LEAVES:0)
Block(-8,19,3,LEAVES:0)
Block(-7,19,3,LEAVES:0)
Block(-6,19,3,LEAVES:0)
Block(-5,19,3,LEAVES:0)
Block(-4,19,3,LEAVES:0)
Block(-3,19,3,LOG:12)
Block(-2,19,3,LEAVES:0)
Block(-1,19,3,LEAVES:0)
Block(0,19,3,LEAVES:0)
Block(1,19,3,LOG:12)
Block(2,19,3,LEAVES:0)
Block(3,19,3,LEAVES:0)
Block(4,19,3,LEAVES:0)
Block(-11,19,4,LEAVES:0)
Block(-9,19,4,LEAVES:0)
Block(-7,19,4,LOG:12)
Block(-5,19,4,LEAVES:0)
Block(-4,19,4,LEAVES:0)
Block(-3,19,4,LOG:12)
Block(-2,19,4,LEAVES:0)
Block(-1,19,4,LEAVES:0)
Block(0,19,4,LEAVES:0)
Block(1,19,4,LOG:12)
Block(2,19,4,LEAVES:0)
Block(3,19,4,LEAVES:0)
Block(4,19,4,LOG:12)
Block(5,19,4,LEAVES:0)
Block(6,19,4,LEAVES:0)
Block(-11,19,5,LEAVES:0)
Block(-10,19,5,LEAVES:0)
Block(-9,19,5,LEAVES:0)
Block(-8,19,5,LOG:12)
Block(-7,19,5,LOG:12)
Block(-6,19,5,LEAVES:0)
Block(-5,19,5,LEAVES:0)
Block(-3,19,5,LOG:12)
Block(-2,19,5,LOG:12)
Block(-1,19,5,LEAVES:0)
Block(0,19,5,LEAVES:0)
Block(1,19,5,LOG:12)
Block(2,19,5,LOG:12)
Block(3,19,5,LEAVES:0)
Block(5,19,5,LEAVES:0)
Block(-11,19,6,LEAVES:0)
Block(-10,19,6,LEAVES:0)
Block(-9,19,6,LOG:12)
Block(-8,19,6,LOG:12)
Block(-5,19,6,LEAVES:0)
Block(-3,19,6,LEAVES:0)
Block(-2,19,6,LEAVES:0)
Block(-1,19,6,LEAVES:0)
Block(0,19,6,LEAVES:0)
Block(1,19,6,LEAVES:0)
Block(2,19,6,LEAVES:0)
Block(4,19,6,LEAVES:0)
Block(5,19,6,LEAVES:0)
Block(6,19,6,LEAVES:0)
Block(-14,19,7,LEAVES:0)
Block(-11,19,7,LEAVES:0)
Block(-10,19,7,LEAVES:0)
Block(-8,19,7,LEAVES:0)
Block(-7,19,7,LEAVES:0)
Block(-6,19,7,LEAVES:0)
Block(-4,19,7,LEAVES:0)
Block(-2,19,7,LEAVES:0)
Block(-1,19,7,LEAVES:0)
Block(0,19,7,LEAVES:0)
Block(1,19,7,LEAVES:0)
Block(3,19,7,LEAVES:0)
Block(4,19,7,LEAVES:0)
Block(5,19,7,LEAVES:0)
Block(6,19,7,LEAVES:0)
Block(7,19,7,LEAVES:0)
Block(-15,19,8,LEAVES:0)
Block(-14,19,8,LEAVES:0)
Block(-12,19,8,LEAVES:4)
Block(-11,19,8,LEAVES:0)
Block(-10,19,8,LEAVES:0)
Block(-7,19,8,LEAVES:0)
Block(-6,19,8,LEAVES:0)
Block(1,19,8,LEAVES:0)
Block(2,19,8,LEAVES:0)
Block(3,19,8,LEAVES:0)
Block(4,19,8,LEAVES:0)
Block(6,19,8,LEAVES:0)
Block(-9,19,9,LEAVES:0)
Block(-7,19,9,LEAVES:0)
Block(-6,19,9,LEAVES:0)
Block(1,19,9,LEAVES:4)
Block(3,19,9,LEAVES:0)
Block(4,19,9,LEAVES:0)
Block(5,19,9,LEAVES:0)
Block(6,19,9,LEAVES:4)
Block(7,19,9,LEAVES:12)
Block(-9,19,10,LEAVES:12)
Block(3,19,10,LEAVES:4)
Block(4,19,10,LEAVES:12)
Block(5,19,10,LEAVES:12)
Block(6,19,10,LEAVES:4)
Block(4,19,11,LEAVES:4)
Block(5,19,11,LEAVES:4)
Block(6,19,11,LEAVES:4)
Block(-1,20,-13,LEAVES:0)
Block(-10,20,-12,LEAVES:8)
Block(-2,20,-12,LEAVES:0)
Block(-1,20,-12,LEAVES:0)
Block(-6,20,-11,LEAVES:8)
Block(-2,20,-11,LEAVES:0)
Block(0,20,-11,LEAVES:0)
Block(2,20,-11,LEAVES:0)
Block(-10,20,-10,LEAVES:0)
Block(-8,20,-10,LEAVES:8)
Block(-5,20,-10,LEAVES:0)
Block(-1,20,-10,LEAVES:0)
Block(-12,20,-9,LEAVES:0)
Block(-11,20,-9,LEAVES:0)
Block(-10,20,-9,LEAVES:0)
Block(-9,20,-9,LEAVES:0)
Block(-8,20,-9,LEAVES:8)
Block(-7,20,-9,LEAVES:8)
Block(-6,20,-9,LEAVES:0)
Block(-1,20,-9,LOG:12)
Block(0,20,-9,LEAVES:0)
Block(3,20,-9,LEAVES:0)
Block(6,20,-9,LEAVES:0)
Block(-11,20,-8,LEAVES:0)
Block(-10,20,-8,LEAVES:0)
Block(-9,20,-8,LEAVES:0)
Block(-8,20,-8,LEAVES:0)
Block(-7,20,-8,LEAVES:0)
Block(-5,20,-8,LEAVES:8)
Block(-4,20,-8,LEAVES:0)
Block(-3,20,-8,LEAVES:8)
Block(-1,20,-8,LOG:12)
Block(1,20,-8,LEAVES:0)
Block(2,20,-8,LEAVES:0)
Block(3,20,-8,LEAVES:0)
Block(-11,20,-7,LEAVES:0)
Block(-10,20,-7,LEAVES:0)
Block(-9,20,-7,LEAVES:0)
Block(-8,20,-7,LEAVES:0)
Block(-6,20,-7,LEAVES:8)
Block(-5,20,-7,LEAVES:0)
Block(-4,20,-7,LEAVES:0)
Block(-1,20,-7,LEAVES:0)
Block(0,20,-7,LEAVES:0)
Block(1,20,-7,LEAVES:0)
Block(4,20,-7,LEAVES:0)
Block(6,20,-7,LEAVES:0)
Block(-12,20,-6,LEAVES:0)
Block(-11,20,-6,LEAVES:0)
Block(-10,20,-6,LEAVES:0)
Block(-9,20,-6,LEAVES:0)
Block(-8,20,-6,LEAVES:8)
Block(-7,20,-6,LEAVES:0)
Block(-6,20,-6,LEAVES:0)
Block(-5,20,-6,LEAVES:8)
Block(-4,20,-6,LEAVES:0)
Block(-3,20,-6,LEAVES:0)
Block(-2,20,-6,LEAVES:0)
Block(0,20,-6,LEAVES:0)
Block(1,20,-6,LEAVES:0)
Block(3,20,-6,LEAVES:0)
Block(4,20,-6,LEAVES:0)
Block(7,20,-6,LEAVES:0)
Block(8,20,-6,LEAVES:0)
Block(-14,20,-5,LEAVES:0)
Block(-13,20,-5,LEAVES:0)
Block(-12,20,-5,LEAVES:0)
Block(-11,20,-5,LEAVES:0)
Block(-10,20,-5,LEAVES:0)
Block(-9,20,-5,LEAVES:0)
Block(-8,20,-5,LEAVES:0)
Block(-7,20,-5,LEAVES:0)
Block(-6,20,-5,LEAVES:0)
Block(-5,20,-5,LEAVES:0)
Block(-3,20,-5,LEAVES:0)
Block(-2,20,-5,LEAVES:0)
Block(-1,20,-5,LEAVES:0)
Block(0,20,-5,LEAVES:0)
Block(1,20,-5,LEAVES:0)
Block(2,20,-5,LOG:12)
Block(3,20,-5,LOG:12)
Block(4,20,-5,LEAVES:0)
Block(6,20,-5,LEAVES:0)
Block(-12,20,-4,LEAVES:0)
Block(-9,20,-4,LOG:12)
Block(-8,20,-4,LEAVES:0)
Block(-7,20,-4,LEAVES:0)
Block(-6,20,-4,LEAVES:0)
Block(-5,20,-4,LEAVES:0)
Block(-4,20,-4,LEAVES:0)
Block(-3,20,-4,LEAVES:0)
Block(-2,20,-4,LEAVES:0)
Block(2,20,-4,LOG:12)
Block(3,20,-4,LEAVES:0)
Block(-14,20,-3,LEAVES:0)
Block(-13,20,-3,LEAVES:4)
Block(-12,20,-3,LEAVES:0)
Block(-11,20,-3,LEAVES:0)
Block(-10,20,-3,LEAVES:0)
Block(-9,20,-3,LOG:12)
Block(-8,20,-3,LOG:12)
Block(-7,20,-3,LEAVES:0)
Block(-6,20,-3,LEAVES:0)
Block(-5,20,-3,LEAVES:0)
Block(-4,20,-3,LEAVES:0)
Block(-3,20,-3,LEAVES:0)
Block(-2,20,-3,LEAVES:0)
Block(-1,20,-3,LEAVES:0)
Block(0,20,-3,LEAVES:0)
Block(1,20,-3,LEAVES:0)
Block(3,20,-3,LEAVES:0)
Block(-12,20,-2,LEAVES:0)
Block(-11,20,-2,LEAVES:0)
Block(-10,20,-2,LEAVES:0)
Block(-9,20,-2,LEAVES:0)
Block(-8,20,-2,LEAVES:0)
Block(-7,20,-2,LEAVES:0)
Block(-6,20,-2,LOG:12)
Block(-5,20,-2,LEAVES:0)
Block(-4,20,-2,LEAVES:0)
Block(-3,20,-2,LEAVES:0)
Block(-2,20,-2,LEAVES:0)
Block(0,20,-2,LEAVES:0)
Block(2,20,-2,LEAVES:0)
Block(-13,20,-1,LEAVES:4)
Block(-12,20,-1,LEAVES:0)
Block(-11,20,-1,LEAVES:0)
Block(-10,20,-1,LEAVES:0)
Block(-9,20,-1,LEAVES:0)
Block(-8,20,-1,LEAVES:0)
Block(-7,20,-1,LEAVES:0)
Block(-6,20,-1,LEAVES:0)
Block(-5,20,-1,LEAVES:0)
Block(-4,20,-1,LEAVES:0)
Block(-3,20,-1,LEAVES:0)
Block(-2,20,-1,LEAVES:0)
Block(-1,20,-1,LEAVES:0)
Block(0,20,-1,LOG:12)
Block(2,20,-1,LOG:12)
Block(3,20,-1,LEAVES:0)
Block(4,20,-1,LEAVES:0)
Block(-13,20,0,LEAVES:0)
Block(-12,20,0,LEAVES:0)
Block(-10,20,0,LEAVES:0)
Block(-9,20,0,LEAVES:0)
Block(-8,20,0,LEAVES:0)
Block(-6,20,0,LEAVES:0)
Block(-4,20,0,LEAVES:0)
Block(-3,20,0,LOG:12)
Block(0,20,0,LEAVES:0)
Block(1,20,0,LEAVES:0)
Block(2,20,0,LEAVES:0)
Block(-13,20,1,LEAVES:0)
Block(-10,20,1,LEAVES:0)
Block(-9,20,1,LEAVES:0)
Block(-8,20,1,LEAVES:0)
Block(-7,20,1,LEAVES:0)
Block(-6,20,1,LEAVES:0)
Block(-5,20,1,LEAVES:0)
Block(-4,20,1,LOG:12)
Block(-3,20,1,LEAVES:0)
Block(-2,20,1,LEAVES:0)
Block(-1,20,1,LEAVES:0)
Block(1,20,1,LEAVES:0)
Block(-13,20,2,LEAVES:0)
Block(-12,20,2,LEAVES:0)
Block(-11,20,2,LEAVES:0)
Block(-10,20,2,LEAVES:0)
Block(-9,20,2,LOG:12)
Block(-8,20,2,LEAVES:0)
Block(-7,20,2,LEAVES:0)
Block(-6,20,2,LEAVES:0)
Block(-5,20,2,LEAVES:0)
Block(-4,20,2,LEAVES:0)
Block(-3,20,2,LEAVES:0)
Block(-1,20,2,LEAVES:0)
Block(3,20,2,LEAVES:0)
Block(4,20,2,LEAVES:0)
Block(-11,20,3,LEAVES:0)
Block(-10,20,3,LEAVES:0)
Block(-9,20,3,LEAVES:0)
Block(-7,20,3,LEAVES:0)
Block(-5,20,3,LEAVES:0)
Block(-4,20,3,LEAVES:0)
Block(-3,20,3,LOG:12)
Block(-2,20,3,LEAVES:0)
Block(-1,20,3,LEAVES:0)
Block(1,20,3,LEAVES:0)
Block(2,20,3,LEAVES:0)
Block(5,20,3,LEAVES:0)
Block(-10,20,4,LEAVES:0)
Block(-9,20,4,LEAVES:0)
Block(-8,20,4,LEAVES:0)
Block(-7,20,4,LEAVES:0)
Block(-6,20,4,LEAVES:0)
Block(-5,20,4,LEAVES:0)
Block(-4,20,4,LEAVES:0)
Block(-3,20,4,LOG:12)
Block(-2,20,4,LEAVES:0)
Block(-1,20,4,LEAVES:0)
Block(0,20,4,LEAVES:0)
Block(1,20,4,LEAVES:0)
Block(2,20,4,LEAVES:0)
Block(3,20,4,LOG:12)
Block(4,20,4,LEAVES:0)
Block(5,20,4,LEAVES:0)
Block(-11,20,5,LEAVES:0)
Block(-10,20,5,LEAVES:0)
Block(-8,20,5,LEAVES:0)
Block(-7,20,5,LEAVES:0)
Block(-5,20,5,LEAVES:0)
Block(-4,20,5,LEAVES:0)
Block(-3,20,5,LOG:12)
Block(-2,20,5,LEAVES:0)
Block(-1,20,5,LEAVES:0)
Block(0,20,5,LEAVES:0)
Block(1,20,5,LOG:12)
Block(2,20,5,LOG:12)
Block(5,20,5,LEAVES:0)
Block(-12,20,6,LEAVES:0)
Block(-11,20,6,LEAVES:0)
Block(-9,20,6,LOG:12)
Block(-8,20,6,LOG:12)
Block(-7,20,6,LEAVES:0)
Block(-6,20,6,LEAVES:0)
Block(-5,20,6,LEAVES:0)
Block(-4,20,6,LOG:12)
Block(-3,20,6,LOG:12)
Block(-2,20,6,LEAVES:0)
Block(-1,20,6,LEAVES:0)
Block(0,20,6,LOG:12)
Block(1,20,6,LOG:12)
Block(3,20,6,LEAVES:0)
Block(5,20,6,LEAVES:0)
Block(6,20,6,LEAVES:0)
Block(-15,20,7,LEAVES:12)
Block(-14,20,7,LEAVES:12)
Block(-11,20,7,LEAVES:0)
Block(-10,20,7,LOG:12)
Block(-9,20,7,LOG:12)
Block(-8,20,7,LEAVES:0)
Block(-7,20,7,LEAVES:0)
Block(-5,20,7,LEAVES:0)
Block(-4,20,7,LOG:12)
Block(-1,20,7,LEAVES:0)
Block(0,20,7,LEAVES:0)
Block(1,20,7,LEAVES:0)
Block(2,20,7,LEAVES:0)
Block(3,20,7,LEAVES:0)
Block(4,20,7,LEAVES:0)
Block(5,20,7,LEAVES:0)
Block(-15,20,8,LEAVES:12)
Block(-14,20,8,LOG:12)
Block(-13,20,8,LEAVES:0)
Block(-11,20,8,LEAVES:0)
Block(-10,20,8,LEAVES:0)
Block(-8,20,8,LEAVES:0)
Block(-7,20,8,LEAVES:0)
Block(-3,20,8,LEAVES:0)
Block(-2,20,8,LEAVES:0)
Block(0,20,8,LEAVES:0)
Block(1,20,8,LEAVES:0)
Block(4,20,8,LEAVES:0)
Block(6,20,8,LEAVES:0)
Block(-13,20,9,LEAVES:0)
Block(-12,20,9,LEAVES:12)
Block(-10,20,9,LEAVES:12)
Block(-9,20,9,LEAVES:0)
Block(-8,20,9,LEAVES:0)
Block(-7,20,9,LEAVES:0)
Block(-2,20,9,LEAVES:0)
Block(1,20,9,LEAVES:0)
Block(2,20,9,LEAVES:0)
Block(3,20,9,LEAVES:0)
Block(5,20,9,LEAVES:0)
Block(6,20,9,LEAVES:0)
Block(-14,20,10,LEAVES:0)
Block(-10,20,10,LEAVES:12)
Block(-9,20,10,LEAVES:12)
Block(-8,20,10,LEAVES:12)
Block(-7,20,10,LOG:12)
Block(-4,20,10,LEAVES:12)
Block(-14,20,11,LEAVES:12)
Block(-10,20,11,LEAVES:0)
Block(-7,20,11,LEAVES:4)
Block(5,20,11,LEAVES:0)
Block(-9,20,12,LEAVES:12)
Block(-7,20,12,LEAVES:4)
Block(-6,20,12,LEAVES:0)
Block(-10,21,-13,LEAVES:8)
Block(-3,21,-13,LEAVES:0)
Block(-2,21,-13,LEAVES:0)
Block(-10,21,-12,LEAVES:8)
Block(-9,21,-12,LEAVES:8)
Block(-8,21,-12,LEAVES:8)
Block(-4,21,-12,LEAVES:0)
Block(-2,21,-12,LEAVES:0)
Block(-1,21,-12,LEAVES:0)
Block(0,21,-12,LEAVES:12)
Block(-9,21,-11,LEAVES:8)
Block(-7,21,-11,LEAVES:0)
Block(-5,21,-11,LEAVES:0)
Block(-4,21,-11,LEAVES:0)
Block(-3,21,-11,LEAVES:0)
Block(-2,21,-11,LEAVES:0)
Block(0,21,-11,LOG:12)
Block(2,21,-11,LEAVES:0)
Block(3,21,-11,LEAVES:0)
Block(-9,21,-10,LEAVES:0)
Block(-6,21,-10,LEAVES:0)
Block(-5,21,-10,LEAVES:0)
Block(-4,21,-10,LEAVES:0)
Block(-3,21,-10,LEAVES:0)
Block(-1,21,-10,LOG:12)
Block(0,21,-10,LOG:12)
Block(1,21,-10,LEAVES:0)
Block(2,21,-10,LEAVES:0)
Block(3,21,-10,LEAVES:0)
Block(-13,21,-9,LEAVES:0)
Block(-10,21,-9,LEAVES:0)
Block(-9,21,-9,LEAVES:0)
Block(-8,21,-9,LEAVES:0)
Block(-7,21,-9,LEAVES:0)
Block(-6,21,-9,LEAVES:0)
Block(-4,21,-9,LEAVES:0)
Block(-3,21,-9,LEAVES:0)
Block(-2,21,-9,LEAVES:0)
Block(-1,21,-9,LOG:12)
Block(0,21,-9,LEAVES:0)
Block(3,21,-9,LEAVES:0)
Block(6,21,-9,LEAVES:0)
Block(-10,21,-8,LEAVES:0)
Block(-9,21,-8,LEAVES:0)
Block(-8,21,-8,LEAVES:8)
Block(-6,21,-8,LEAVES:8)
Block(-5,21,-8,LEAVES:0)
Block(-4,21,-8,LEAVES:0)
Block(-2,21,-8,LEAVES:0)
Block(0,21,-8,LEAVES:0)
Block(1,21,-8,LEAVES:0)
Block(2,21,-8,LEAVES:0)
Block(5,21,-8,LEAVES:0)
Block(-15,21,-7,LEAVES:12)
Block(-14,21,-7,LEAVES:12)
Block(-10,21,-7,LEAVES:0)
Block(-9,21,-7,LEAVES:0)
Block(-8,21,-7,LEAVES:8)
Block(-7,21,-7,LEAVES:8)
Block(-6,21,-7,LEAVES:0)
Block(-4,21,-7,LEAVES:0)
Block(-3,21,-7,LEAVES:0)
Block(-2,21,-7,LEAVES:0)
Block(0,21,-7,LEAVES:0)
Block(1,21,-7,LEAVES:0)
Block(8,21,-7,LEAVES:0)
Block(-12,21,-6,LEAVES:0)
Block(-11,21,-6,LEAVES:0)
Block(-10,21,-6,LEAVES:0)
Block(-9,21,-6,LEAVES:0)
Block(-8,21,-6,LEAVES:0)
Block(-7,21,-6,LEAVES:0)
Block(-6,21,-6,LEAVES:0)
Block(-5,21,-6,LEAVES:0)
Block(-4,21,-6,LEAVES:0)
Block(-3,21,-6,LEAVES:0)
Block(-2,21,-6,LEAVES:0)
Block(-1,21,-6,LOG:12)
Block(0,21,-6,LEAVES:0)
Block(7,21,-6,LEAVES:0)
Block(-14,21,-5,LEAVES:12)
Block(-11,21,-5,LOG:12)
Block(-10,21,-5,LOG:12)
Block(-9,21,-5,LEAVES:0)
Block(-8,21,-5,LEAVES:0)
Block(-7,21,-5,LEAVES:0)
Block(-5,21,-5,LEAVES:0)
Block(-4,21,-5,LOG:12)
Block(-3,21,-5,LEAVES:0)
Block(-2,21,-5,LEAVES:0)
Block(-1,21,-5,LEAVES:0)
Block(1,21,-5,LEAVES:0)
Block(3,21,-5,LOG:12)
Block(5,21,-5,LEAVES:0)
Block(6,21,-5,LEAVES:0)
Block(7,21,-5,LEAVES:0)
Block(-11,21,-4,LEAVES:0)
Block(-10,21,-4,LOG:12)
Block(-9,21,-4,LOG:12)
Block(-8,21,-4,LEAVES:0)
Block(-7,21,-4,LEAVES:0)
Block(-6,21,-4,LEAVES:0)
Block(-5,21,-4,LEAVES:0)
Block(-4,21,-4,LEAVES:0)
Block(-3,21,-4,LEAVES:0)
Block(-2,21,-4,LEAVES:0)
Block(-1,21,-4,LEAVES:0)
Block(1,21,-4,LEAVES:0)
Block(-14,21,-3,LEAVES:0)
Block(-12,21,-3,LEAVES:0)
Block(-11,21,-3,LEAVES:0)
Block(-10,21,-3,LEAVES:0)
Block(-9,21,-3,LEAVES:0)
Block(-8,21,-3,LEAVES:0)
Block(-7,21,-3,LEAVES:0)
Block(-6,21,-3,LEAVES:0)
Block(-5,21,-3,LEAVES:0)
Block(-3,21,-3,LEAVES:0)
Block(-1,21,-3,LEAVES:0)
Block(0,21,-3,LEAVES:0)
Block(1,21,-3,LEAVES:0)
Block(3,21,-3,LEAVES:0)
Block(4,21,-3,LEAVES:0)
Block(6,21,-3,LEAVES:0)
Block(7,21,-3,LEAVES:0)
Block(-12,21,-2,LEAVES:4)
Block(-11,21,-2,LEAVES:0)
Block(-10,21,-2,LEAVES:0)
Block(-9,21,-2,LEAVES:0)
Block(-8,21,-2,LEAVES:0)
Block(-7,21,-2,LEAVES:0)
Block(-6,21,-2,LEAVES:0)
Block(-5,21,-2,LEAVES:0)
Block(-4,21,-2,LEAVES:0)
Block(-3,21,-2,LEAVES:0)
Block(-2,21,-2,LEAVES:0)
Block(-1,21,-2,LEAVES:0)
Block(0,21,-2,LEAVES:0)
Block(2,21,-2,LEAVES:0)
Block(3,21,-2,LEAVES:0)
Block(4,21,-2,LEAVES:0)
Block(-13,21,-1,LEAVES:0)
Block(-12,21,-1,LEAVES:0)
Block(-10,21,-1,LEAVES:0)
Block(-9,21,-1,LEAVES:0)
Block(-8,21,-1,LEAVES:0)
Block(-7,21,-1,LEAVES:0)
Block(-6,21,-1,LEAVES:0)
Block(-5,21,-1,LEAVES:0)
Block(-4,21,-1,LEAVES:0)
Block(-3,21,-1,LOG:12)
Block(-2,21,-1,LEAVES:0)
Block(0,21,-1,LEAVES:0)
Block(1,21,-1,LEAVES:0)
Block(3,21,-1,LEAVES:0)
Block(-11,21,0,LEAVES:0)
Block(-10,21,0,LEAVES:0)
Block(-9,21,0,LEAVES:0)
Block(-8,21,0,LEAVES:0)
Block(-7,21,0,LEAVES:0)
Block(-6,21,0,LEAVES:0)
Block(-5,21,0,LOG:12)
Block(-4,21,0,LEAVES:0)
Block(-3,21,0,LOG:12)
Block(-2,21,0,LEAVES:0)
Block(-1,21,0,LEAVES:0)
Block(0,21,0,LEAVES:0)
Block(1,21,0,LEAVES:0)
Block(2,21,0,LEAVES:0)
Block(-13,21,1,LEAVES:0)
Block(-12,21,1,LEAVES:0)
Block(-11,21,1,LEAVES:0)
Block(-10,21,1,LOG:12)
Block(-9,21,1,LEAVES:0)
Block(-7,21,1,LEAVES:0)
Block(-6,21,1,LEAVES:0)
Block(-5,21,1,LEAVES:0)
Block(-4,21,1,LEAVES:0)
Block(-3,21,1,LEAVES:0)
Block(-2,21,1,LEAVES:0)
Block(-1,21,1,LEAVES:0)
Block(0,21,1,LEAVES:0)
Block(1,21,1,LEAVES:0)
Block(2,21,1,LEAVES:0)
Block(3,21,1,LEAVES:0)
Block(-12,21,2,LEAVES:0)
Block(-9,21,2,LEAVES:0)
Block(-8,21,2,LEAVES:0)
Block(-7,21,2,LEAVES:0)
Block(-6,21,2,LEAVES:0)
Block(-5,21,2,LEAVES:0)
Block(-4,21,2,LEAVES:0)
Block(-2,21,2,LEAVES:0)
Block(-1,21,2,LEAVES:0)
Block(0,21,2,LEAVES:0)
Block(3,21,2,LEAVES:0)
Block(-12,21,3,LEAVES:0)
Block(-11,21,3,LEAVES:0)
Block(-9,21,3,LEAVES:0)
Block(-8,21,3,LEAVES:0)
Block(-7,21,3,LEAVES:0)
Block(-6,21,3,LEAVES:0)
Block(-5,21,3,LEAVES:0)
Block(-4,21,3,LEAVES:0)
Block(-2,21,3,LEAVES:0)
Block(-1,21,3,LEAVES:0)
Block(0,21,3,LEAVES:0)
Block(1,21,3,LEAVES:0)
Block(2,21,3,LEAVES:0)
Block(3,21,3,LEAVES:0)
Block(-10,21,4,LEAVES:0)
Block(-9,21,4,LEAVES:0)
Block(-8,21,4,LEAVES:0)
Block(-7,21,4,LEAVES:0)
Block(-5,21,4,LEAVES:0)
Block(-3,21,4,LEAVES:0)
Block(-2,21,4,LEAVES:0)
Block(-1,21,4,LEAVES:0)
Block(0,21,4,LEAVES:0)
Block(1,21,4,LEAVES:0)
Block(2,21,4,LOG:12)
Block(3,21,4,LEAVES:0)
Block(4,21,4,LEAVES:0)
Block(5,21,4,LEAVES:0)
Block(-12,21,5,LEAVES:0)
Block(-11,21,5,LEAVES:0)
Block(-10,21,5,LEAVES:0)
Block(-9,21,5,LEAVES:0)
Block(-8,21,5,LEAVES:0)
Block(-7,21,5,LEAVES:0)
Block(-5,21,5,LEAVES:0)
Block(-3,21,5,LEAVES:0)
Block(-2,21,5,LEAVES:0)
Block(-1,21,5,LEAVES:0)
Block(0,21,5,LEAVES:0)
Block(1,21,5,LEAVES:0)
Block(2,21,5,LOG:12)
Block(3,21,5,LEAVES:0)
Block(4,21,5,LEAVES:0)
Block(6,21,5,LEAVES:0)
Block(-11,21,6,LEAVES:0)
Block(-9,21,6,LEAVES:0)
Block(-8,21,6,LEAVES:0)
Block(-7,21,6,LEAVES:0)
Block(-6,21,6,LEAVES:0)
Block(-5,21,6,LEAVES:0)
Block(-4,21,6,LOG:12)
Block(-3,21,6,LEAVES:0)
Block(-2,21,6,LEAVES:0)
Block(-1,21,6,LOG:12)
Block(0,21,6,LOG:12)
Block(1,21,6,LEAVES:0)
Block(2,21,6,LOG:12)
Block(3,21,6,LOG:12)
Block(4,21,6,LEAVES:0)
Block(5,21,6,LEAVES:0)
Block(6,21,6,LEAVES:0)
Block(7,21,6,LEAVES:0)
Block(-14,21,7,LEAVES:12)
Block(-13,21,7,LEAVES:0)
Block(-12,21,7,LEAVES:0)
Block(-11,21,7,LEAVES:0)
Block(-10,21,7,LOG:12)
Block(-9,21,7,LOG:12)
Block(-8,21,7,LEAVES:0)
Block(-7,21,7,LEAVES:0)
Block(-5,21,7,LEAVES:0)
Block(-4,21,7,LOG:12)
Block(-3,21,7,LEAVES:4)
Block(-1,21,7,LOG:12)
Block(1,21,7,LEAVES:0)
Block(2,21,7,LEAVES:0)
Block(6,21,7,LEAVES:0)
Block(-15,21,8,LEAVES:0)
Block(-14,21,8,LEAVES:0)
Block(-13,21,8,LEAVES:0)
Block(-12,21,8,LEAVES:0)
Block(-11,21,8,LOG:12)
Block(-10,21,8,LOG:12)
Block(-9,21,8,LEAVES:0)
Block(-8,21,8,LEAVES:0)
Block(-7,21,8,LEAVES:0)
Block(-4,21,8,LOG:12)
Block(-2,21,8,LEAVES:0)
Block(-1,21,8,LEAVES:0)
Block(0,21,8,LEAVES:0)
Block(5,21,8,LEAVES:0)
Block(6,21,8,LEAVES:0)
Block(-15,21,9,LEAVES:0)
Block(-14,21,9,LEAVES:12)
Block(-13,21,9,LEAVES:12)
Block(-12,21,9,LEAVES:0)
Block(-11,21,9,LEAVES:0)
Block(-8,21,9,LEAVES:0)
Block(-7,21,9,LEAVES:0)
Block(-6,21,9,LEAVES:0)
Block(-3,21,9,LEAVES:0)
Block(-2,21,9,LEAVES:0)
Block(1,21,9,LEAVES:0)
Block(6,21,9,LEAVES:0)
Block(-15,21,10,LEAVES:0)
Block(-14,21,10,LEAVES:12)
Block(-13,21,10,LEAVES:12)
Block(-12,21,10,LEAVES:12)
Block(-11,21,10,LEAVES:0)
Block(-7,21,10,LEAVES:0)
Block(-5,21,10,LEAVES:0)
Block(-4,21,10,LEAVES:12)
Block(-3,21,10,LEAVES:12)
Block(-13,21,11,LEAVES:12)
Block(-12,21,11,LEAVES:0)
Block(-8,21,11,LEAVES:12)
Block(-7,21,11,LEAVES:4)
Block(-4,21,11,LEAVES:12)
Block(-8,21,12,LEAVES:12)
Block(-5,21,12,LEAVES:0)
Block(-12,22,-13,LEAVES:0)
Block(-9,22,-13,LEAVES:0)
Block(-2,22,-13,LEAVES:0)
Block(-1,22,-13,LEAVES:0)
Block(0,22,-13,LEAVES:12)
Block(1,22,-13,LEAVES:12)
Block(-13,22,-12,LEAVES:0)
Block(-11,22,-12,LEAVES:0)
Block(-7,22,-12,LEAVES:0)
Block(-2,22,-12,LEAVES:0)
Block(-1,22,-12,LEAVES:4)
Block(0,22,-12,LEAVES:12)
Block(1,22,-12,LEAVES:12)
Block(-12,22,-11,LEAVES:0)
Block(-11,22,-11,LEAVES:0)
Block(-10,22,-11,LEAVES:0)
Block(-7,22,-11,LEAVES:0)
Block(-5,22,-11,LEAVES:0)
Block(-1,22,-11,LEAVES:0)
Block(0,22,-11,LEAVES:4)
Block(1,22,-11,LEAVES:4)
Block(2,22,-11,LEAVES:0)
Block(-11,22,-10,LEAVES:0)
Block(-9,22,-10,LEAVES:0)
Block(-8,22,-10,LEAVES:0)
Block(-7,22,-10,LOG:12)
Block(-4,22,-10,LEAVES:0)
Block(-1,22,-10,LEAVES:0)
Block(1,22,-10,LEAVES:0)
Block(2,22,-10,LEAVES:0)
Block(3,22,-10,LEAVES:0)
Block(-14,22,-9,LEAVES:0)
Block(-13,22,-9,LEAVES:0)
Block(-12,22,-9,LEAVES:0)
Block(-10,22,-9,LEAVES:0)
Block(-9,22,-9,LEAVES:0)
Block(-8,22,-9,LEAVES:0)
Block(-7,22,-9,LEAVES:0)
Block(-6,22,-9,LEAVES:0)
Block(-5,22,-9,LEAVES:0)
Block(-3,22,-9,LEAVES:0)
Block(-2,22,-9,LEAVES:0)
Block(2,22,-9,LEAVES:0)
Block(3,22,-9,LEAVES:0)
Block(4,22,-9,LEAVES:0)
Block(5,22,-9,LEAVES:0)
Block(6,22,-9,LEAVES:4)
Block(7,22,-9,LEAVES:4)
Block(-13,22,-8,LEAVES:0)
Block(-10,22,-8,LEAVES:0)
Block(-9,22,-8,LEAVES:0)
Block(-8,22,-8,LEAVES:0)
Block(-7,22,-8,LEAVES:0)
Block(-6,22,-8,LEAVES:0)
Block(-5,22,-8,LEAVES:0)
Block(-4,22,-8,LEAVES:0)
Block(-2,22,-8,LEAVES:0)
Block(0,22,-8,LEAVES:0)
Block(3,22,-8,LEAVES:0)
Block(4,22,-8,LEAVES:0)
Block(6,22,-8,LEAVES:0)
Block(7,22,-8,LEAVES:4)
Block(8,22,-8,LEAVES:0)
Block(-15,22,-7,LEAVES:12)
Block(-14,22,-7,LEAVES:0)
Block(-13,22,-7,LEAVES:0)
Block(-12,22,-7,LEAVES:0)
Block(-11,22,-7,LEAVES:0)
Block(-10,22,-7,LEAVES:0)
Block(-9,22,-7,LEAVES:0)
Block(-8,22,-7,LEAVES:0)
Block(-7,22,-7,LEAVES:0)
Block(-6,22,-7,LEAVES:0)
Block(-5,22,-7,LEAVES:0)
Block(-4,22,-7,LOG:12)
Block(-3,22,-7,LEAVES:0)
Block(-2,22,-7,LEAVES:0)
Block(0,22,-7,LEAVES:0)
Block(1,22,-7,LEAVES:0)
Block(3,22,-7,LEAVES:0)
Block(4,22,-7,LOG:12)
Block(6,22,-7,LEAVES:0)
Block(7,22,-7,LOG:12)
Block(8,22,-7,LEAVES:0)
Block(-15,22,-6,LEAVES:0)
Block(-12,22,-6,LEAVES:0)
Block(-11,22,-6,LOG:12)
Block(-10,22,-6,LEAVES:0)
Block(-9,22,-6,LEAVES:0)
Block(-8,22,-6,LEAVES:0)
Block(-7,22,-6,LEAVES:0)
Block(-6,22,-6,LEAVES:0)
Block(-4,22,-6,LEAVES:0)
Block(-1,22,-6,LEAVES:0)
Block(0,22,-6,LEAVES:0)
Block(1,22,-6,LEAVES:0)
Block(2,22,-6,LEAVES:0)
Block(3,22,-6,LOG:12)
Block(4,22,-6,LOG:12)
Block(5,22,-6,LEAVES:0)
Block(6,22,-6,LEAVES:0)
Block(8,22,-6,LEAVES:0)
Block(-15,22,-5,LEAVES:12)
Block(-14,22,-5,LEAVES:12)
Block(-13,22,-5,LEAVES:4)
Block(-12,22,-5,LEAVES:0)
Block(-11,22,-5,LOG:12)
Block(-10,22,-5,LOG:12)
Block(-9,22,-5,LEAVES:0)
Block(-8,22,-5,LEAVES:0)
Block(-7,22,-5,LEAVES:0)
Block(-6,22,-5,LEAVES:0)
Block(-5,22,-5,LEAVES:0)
Block(-4,22,-5,LEAVES:0)
Block(-3,22,-5,LEAVES:0)
Block(-2,22,-5,LEAVES:0)
Block(-1,22,-5,LEAVES:0)
Block(0,22,-5,LEAVES:0)
Block(1,22,-5,LEAVES:0)
Block(2,22,-5,LEAVES:0)
Block(3,22,-5,LOG:12)
Block(4,22,-5,LEAVES:0)
Block(5,22,-5,LEAVES:0)
Block(6,22,-5,LEAVES:0)
Block(8,22,-5,LEAVES:0)
Block(-14,22,-4,LEAVES:4)
Block(-13,22,-4,LEAVES:4)
Block(-12,22,-4,LOG:12)
Block(-10,22,-4,LEAVES:0)
Block(-9,22,-4,LEAVES:0)
Block(-8,22,-4,LEAVES:0)
Block(-7,22,-4,LOG:12)
Block(-6,22,-4,LEAVES:0)
Block(-5,22,-4,LEAVES:0)
Block(-4,22,-4,LEAVES:0)
Block(-3,22,-4,LEAVES:0)
Block(-1,22,-4,LEAVES:0)
Block(0,22,-4,LEAVES:0)
Block(1,22,-4,LEAVES:0)
Block(4,22,-4,LEAVES:0)
Block(6,22,-4,LEAVES:0)
Block(-14,22,-3,LEAVES:4)
Block(-13,22,-3,LEAVES:0)
Block(-12,22,-3,LEAVES:0)
Block(-11,22,-3,LEAVES:0)
Block(-10,22,-3,LEAVES:0)
Block(-9,22,-3,LEAVES:0)
Block(-8,22,-3,LEAVES:0)
Block(-7,22,-3,LEAVES:0)
Block(-6,22,-3,LEAVES:0)
Block(-5,22,-3,LEAVES:0)
Block(-2,22,-3,LOG:12)
Block(-1,22,-3,LEAVES:0)
Block(1,22,-3,LEAVES:0)
Block(2,22,-3,LEAVES:0)
Block(3,22,-3,LEAVES:0)
Block(4,22,-3,LEAVES:0)
Block(5,22,-3,LEAVES:0)
Block(7,22,-3,LEAVES:0)
Block(-12,22,-2,LEAVES:0)
Block(-10,22,-2,LEAVES:0)
Block(-9,22,-2,LEAVES:0)
Block(-8,22,-2,LEAVES:0)
Block(-7,22,-2,LEAVES:0)
Block(-6,22,-2,LEAVES:0)
Block(-5,22,-2,LEAVES:0)
Block(-4,22,-2,LEAVES:0)
Block(-2,22,-2,LOG:12)
Block(-1,22,-2,LEAVES:0)
Block(0,22,-2,LEAVES:0)
Block(1,22,-2,LEAVES:0)
Block(2,22,-2,LEAVES:0)
Block(3,22,-2,LEAVES:0)
Block(4,22,-2,LEAVES:0)
Block(-13,22,-1,LEAVES:0)
Block(-12,22,-1,LEAVES:0)
Block(-10,22,-1,LEAVES:0)
Block(-9,22,-1,LEAVES:0)
Block(-8,22,-1,LEAVES:0)
Block(-7,22,-1,LEAVES:0)
Block(-6,22,-1,LEAVES:0)
Block(-5,22,-1,LEAVES:0)
Block(-4,22,-1,LEAVES:0)
Block(-3,22,-1,LOG:12)
Block(-2,22,-1,LOG:12)
Block(-1,22,-1,LEAVES:0)
Block(0,22,-1,LEAVES:0)
Block(1,22,-1,LEAVES:0)
Block(3,22,-1,LOG:12)
Block(-13,22,0,LEAVES:0)
Block(-12,22,0,LEAVES:0)
Block(-11,22,0,LEAVES:0)
Block(-10,22,0,LEAVES:0)
Block(-9,22,0,LEAVES:0)
Block(-8,22,0,LEAVES:0)
Block(-7,22,0,LEAVES:0)
Block(-6,22,0,LEAVES:0)
Block(-5,22,0,LEAVES:0)
Block(-4,22,0,LEAVES:0)
Block(-3,22,0,LEAVES:0)
Block(0,22,0,LEAVES:0)
Block(1,22,0,LEAVES:0)
Block(2,22,0,LEAVES:0)
Block(3,22,0,LEAVES:0)
Block(5,22,0,LEAVES:0)
Block(-11,22,1,LEAVES:0)
Block(-9,22,1,LEAVES:0)
Block(-8,22,1,LEAVES:0)
Block(-7,22,1,LEAVES:0)
Block(-5,22,1,LEAVES:0)
Block(-4,22,1,LEAVES:0)
Block(-3,22,1,LEAVES:0)
Block(-2,22,1,LEAVES:0)
Block(-1,22,1,LEAVES:0)
Block(0,22,1,LEAVES:0)
Block(1,22,1,LEAVES:0)
Block(3,22,1,LEAVES:0)
Block(4,22,1,LEAVES:0)
Block(-12,22,2,LEAVES:0)
Block(-11,22,2,LEAVES:0)
Block(-10,22,2,LEAVES:0)
Block(-9,22,2,LEAVES:0)
Block(-8,22,2,LOG:12)
Block(-7,22,2,LEAVES:0)
Block(-6,22,2,LEAVES:0)
Block(-4,22,2,LEAVES:0)
Block(-3,22,2,LEAVES:0)
Block(-2,22,2,LEAVES:0)
Block(-1,22,2,LEAVES:0)
Block(0,22,2,LEAVES:0)
Block(1,22,2,LEAVES:0)
Block(2,22,2,LEAVES:0)
Block(3,22,2,LEAVES:0)
Block(4,22,2,LEAVES:0)
Block(-11,22,3,LEAVES:0)
Block(-10,22,3,LEAVES:0)
Block(-9,22,3,LEAVES:0)
Block(-8,22,3,LEAVES:0)
Block(-7,22,3,LEAVES:0)
Block(-5,22,3,LOG:12)
Block(-4,22,3,LEAVES:0)
Block(-3,22,3,LEAVES:0)
Block(-2,22,3,LEAVES:0)
Block(-1,22,3,LEAVES:0)
Block(0,22,3,LEAVES:0)
Block(1,22,3,LEAVES:0)
Block(2,22,3,LEAVES:0)
Block(3,22,3,LEAVES:0)
Block(4,22,3,LEAVES:0)
Block(-10,22,4,LEAVES:0)
Block(-9,22,4,LEAVES:0)
Block(-8,22,4,LEAVES:0)
Block(-4,22,4,LEAVES:0)
Block(-3,22,4,LEAVES:0)
Block(-2,22,4,LEAVES:0)
Block(-1,22,4,LEAVES:0)
Block(0,22,4,LEAVES:0)
Block(1,22,4,LEAVES:0)
Block(2,22,4,LEAVES:0)
Block(3,22,4,LEAVES:0)
Block(4,22,4,LEAVES:0)
Block(-11,22,5,LEAVES:0)
Block(-9,22,5,LEAVES:0)
Block(-8,22,5,LEAVES:0)
Block(-7,22,5,LEAVES:0)
Block(-5,22,5,LEAVES:0)
Block(-4,22,5,LEAVES:0)
Block(-3,22,5,LEAVES:0)
Block(-2,22,5,LEAVES:0)
Block(-1,22,5,LOG:12)
Block(0,22,5,LEAVES:0)
Block(1,22,5,LEAVES:0)
Block(2,22,5,LEAVES:0)
Block(3,22,5,LEAVES:0)
Block(4,22,5,LEAVES:0)
Block(-12,22,6,LEAVES:0)
Block(-11,22,6,LEAVES:0)
Block(-10,22,6,LEAVES:0)
Block(-9,22,6,LEAVES:0)
Block(-8,22,6,LEAVES:0)
Block(-7,22,6,LEAVES:0)
Block(-6,22,6,LEAVES:0)
Block(-5,22,6,LEAVES:0)
Block(-4,22,6,LEAVES:0)
Block(-3,22,6,LEAVES:0)
Block(-2,22,6,LEAVES:0)
Block(-1,22,6,LEAVES:0)
Block(0,22,6,LEAVES:0)
Block(1,22,6,LEAVES:0)
Block(2,22,6,LEAVES:0)
Block(3,22,6,LOG:12)
Block(4,22,6,LEAVES:0)
Block(5,22,6,LEAVES:0)
Block(-14,22,7,LEAVES:12)
Block(-13,22,7,LEAVES:12)
Block(-12,22,7,LEAVES:12)
Block(-11,22,7,LEAVES:12)
Block(-10,22,7,LEAVES:12)
Block(-8,22,7,LEAVES:0)
Block(-7,22,7,LEAVES:0)
Block(-6,22,7,LEAVES:0)
Block(-5,22,7,LEAVES:0)
Block(-4,22,7,LOG:12)
Block(-2,22,7,LEAVES:0)
Block(-1,22,7,LOG:12)
Block(0,22,7,LEAVES:0)
Block(1,22,7,LEAVES:0)
Block(2,22,7,LEAVES:0)
Block(3,22,7,LOG:12)
Block(5,22,7,LEAVES:0)
Block(-15,22,8,LEAVES:0)
Block(-14,22,8,LEAVES:12)
Block(-13,22,8,LEAVES:0)
Block(-12,22,8,LEAVES:12)
Block(-11,22,8,LEAVES:0)
Block(-10,22,8,LEAVES:0)
Block(-9,22,8,LEAVES:0)
Block(-8,22,8,LEAVES:0)
Block(-7,22,8,LEAVES:0)
Block(-6,22,8,LEAVES:0)
Block(-5,22,8,LOG:12)
Block(-4,22,8,LOG:12)
Block(-3,22,8,LEAVES:12)
Block(-2,22,8,LEAVES:0)
Block(-1,22,8,LEAVES:4)
Block(0,22,8,LEAVES:0)
Block(1,22,8,LEAVES:0)
Block(2,22,8,LEAVES:0)
Block(3,22,8,LEAVES:0)
Block(4,22,8,LOG:12)
Block(5,22,8,LEAVES:0)
Block(-14,22,9,LEAVES:12)
Block(-9,22,9,LEAVES:0)
Block(-7,22,9,LEAVES:0)
Block(-6,22,9,LEAVES:0)
Block(-5,22,9,LOG:12)
Block(-4,22,9,LEAVES:12)
Block(-1,22,9,LEAVES:4)
Block(0,22,9,LEAVES:0)
Block(3,22,9,LEAVES:0)
Block(4,22,9,LEAVES:0)
Block(5,22,9,LEAVES:0)
Block(6,22,9,LEAVES:0)
Block(-13,22,10,LEAVES:12)
Block(-6,22,10,LEAVES:0)
Block(-5,22,10,LEAVES:12)
Block(-4,22,10,LEAVES:12)
Block(5,22,10,LEAVES:0)
Block(-8,22,11,LEAVES:0)
Block(-6,22,11,LEAVES:12)
Block(-5,22,11,LEAVES:12)
Block(-5,22,12,LEAVES:0)
Block(-4,22,12,LEAVES:0)
Block(-4,22,13,LEAVES:12)
Block(-11,23,-13,LEAVES:0)
Block(-10,23,-13,LEAVES:0)
Block(-9,23,-13,LEAVES:0)
Block(-13,23,-12,LEAVES:0)
Block(-11,23,-12,LEAVES:0)
Block(-10,23,-12,LEAVES:0)
Block(-7,23,-12,LEAVES:0)
Block(-13,23,-11,LEAVES:4)
Block(-12,23,-11,LEAVES:0)
Block(-11,23,-11,LEAVES:4)
Block(-10,23,-11,LEAVES:4)
Block(-9,23,-11,LEAVES:4)
Block(-7,23,-11,LEAVES:0)
Block(-6,23,-11,LEAVES:4)
Block(-5,23,-11,LEAVES:4)
Block(-4,23,-11,LEAVES:4)
Block(0,23,-11,LEAVES:0)
Block(1,23,-11,LEAVES:4)
Block(-13,23,-10,LEAVES:0)
Block(-11,23,-10,LOG:12)
Block(-10,23,-10,LEAVES:0)
Block(-9,23,-10,LEAVES:0)
Block(-8,23,-10,LEAVES:0)
Block(-7,23,-10,LEAVES:0)
Block(-6,23,-10,LOG:12)
Block(-5,23,-10,LEAVES:0)
Block(-4,23,-10,LOG:12)
Block(-3,23,-10,LEAVES:0)
Block(-2,23,-10,LEAVES:0)
Block(-1,23,-10,LEAVES:0)
Block(1,23,-10,LEAVES:0)
Block(2,23,-10,LEAVES:0)
Block(4,23,-10,LEAVES:0)
Block(-14,23,-9,LEAVES:0)
Block(-13,23,-9,LEAVES:0)
Block(-12,23,-9,LEAVES:0)
Block(-9,23,-9,LEAVES:0)
Block(-6,23,-9,LEAVES:0)
Block(-5,23,-9,LEAVES:0)
Block(-4,23,-9,LEAVES:0)
Block(-3,23,-9,LEAVES:0)
Block(-2,23,-9,LEAVES:0)
Block(-1,23,-9,LEAVES:0)
Block(1,23,-9,LEAVES:0)
Block(3,23,-9,LEAVES:0)
Block(-14,23,-8,LEAVES:0)
Block(-12,23,-8,LOG:12)
Block(-8,23,-8,LEAVES:0)
Block(-7,23,-8,LEAVES:0)
Block(-6,23,-8,LEAVES:0)
Block(-5,23,-8,LEAVES:0)
Block(-2,23,-8,LEAVES:0)
Block(0,23,-8,LEAVES:0)
Block(1,23,-8,LEAVES:0)
Block(2,23,-8,LEAVES:0)
Block(3,23,-8,LEAVES:0)
Block(4,23,-8,LEAVES:0)
Block(6,23,-8,LEAVES:0)
Block(7,23,-8,LEAVES:0)
Block(-15,23,-7,LEAVES:0)
Block(-13,23,-7,LEAVES:0)
Block(-11,23,-7,LEAVES:0)
Block(-10,23,-7,LEAVES:0)
Block(-9,23,-7,LEAVES:0)
Block(-8,23,-7,LEAVES:0)
Block(-7,23,-7,LEAVES:0)
Block(-6,23,-7,LEAVES:0)
Block(-5,23,-7,LEAVES:0)
Block(-4,23,-7,LEAVES:0)
Block(-2,23,-7,LEAVES:0)
Block(2,23,-7,LEAVES:0)
Block(4,23,-7,LOG:12)
Block(5,23,-7,LEAVES:4)
Block(7,23,-7,LEAVES:0)
Block(8,23,-7,LEAVES:4)
Block(-15,23,-6,LEAVES:0)
Block(-14,23,-6,LEAVES:0)
Block(-13,23,-6,LEAVES:0)
Block(-12,23,-6,LOG:12)
Block(-11,23,-6,LOG:12)
Block(-10,23,-6,LOG:12)
Block(-9,23,-6,LEAVES:0)
Block(-8,23,-6,LEAVES:0)
Block(-7,23,-6,LEAVES:0)
Block(-5,23,-6,LEAVES:0)
Block(-4,23,-6,LEAVES:0)
Block(-3,23,-6,LEAVES:0)
Block(-2,23,-6,LEAVES:0)
Block(-1,23,-6,LEAVES:0)
Block(0,23,-6,LEAVES:0)
Block(1,23,-6,LEAVES:0)
Block(2,23,-6,LEAVES:0)
Block(3,23,-6,LEAVES:0)
Block(4,23,-6,LEAVES:0)
Block(5,23,-6,LEAVES:4)
Block(6,23,-6,LEAVES:4)
Block(7,23,-6,LEAVES:0)
Block(-15,23,-5,LEAVES:0)
Block(-13,23,-5,LEAVES:0)
Block(-12,23,-5,LEAVES:0)
Block(-11,23,-5,LEAVES:0)
Block(-9,23,-5,LEAVES:0)
Block(-7,23,-5,LEAVES:0)
Block(-6,23,-5,LEAVES:0)
Block(-5,23,-5,LEAVES:0)
Block(-4,23,-5,LEAVES:0)
Block(-3,23,-5,LEAVES:0)
Block(-2,23,-5,LEAVES:0)
Block(-1,23,-5,LEAVES:0)
Block(0,23,-5,LEAVES:0)
Block(1,23,-5,LEAVES:0)
Block(3,23,-5,LEAVES:0)
Block(4,23,-5,LEAVES:0)
Block(8,23,-5,LEAVES:0)
Block(-12,23,-4,LEAVES:0)
Block(-11,23,-4,LEAVES:0)
Block(-9,23,-4,LEAVES:0)
Block(-8,23,-4,LEAVES:0)
Block(-7,23,-4,LEAVES:0)
Block(-6,23,-4,LEAVES:0)
Block(-5,23,-4,LEAVES:0)
Block(-4,23,-4,LOG:12)
Block(-2,23,-4,LEAVES:0)
Block(-1,23,-4,LOG:12)
Block(0,23,-4,LEAVES:0)
Block(1,23,-4,LEAVES:0)
Block(2,23,-4,LEAVES:0)
Block(6,23,-4,LEAVES:0)
Block(-12,23,-3,LEAVES:0)
Block(-11,23,-3,LEAVES:0)
Block(-10,23,-3,LEAVES:0)
Block(-9,23,-3,LEAVES:0)
Block(-8,23,-3,LEAVES:0)
Block(-7,23,-3,LEAVES:0)
Block(-5,23,-3,LEAVES:0)
Block(-4,23,-3,LEAVES:0)
Block(-3,23,-3,LEAVES:0)
Block(-2,23,-3,LOG:12)
Block(-1,23,-3,LOG:12)
Block(0,23,-3,LEAVES:0)
Block(1,23,-3,LEAVES:0)
Block(2,23,-3,LEAVES:0)
Block(3,23,-3,LEAVES:0)
Block(4,23,-3,LEAVES:0)
Block(-13,23,-2,LEAVES:0)
Block(-12,23,-2,LEAVES:0)
Block(-11,23,-2,LEAVES:0)
Block(-10,23,-2,LEAVES:0)
Block(-8,23,-2,LEAVES:0)
Block(-7,23,-2,LEAVES:0)
Block(-6,23,-2,LEAVES:0)
Block(-5,23,-2,LEAVES:0)
Block(-4,23,-2,LEAVES:0)
Block(-3,23,-2,LEAVES:0)
Block(-2,23,-2,LOG:12)
Block(-1,23,-2,LEAVES:0)
Block(0,23,-2,LEAVES:0)
Block(1,23,-2,LEAVES:0)
Block(2,23,-2,LEAVES:0)
Block(3,23,-2,LEAVES:0)
Block(4,23,-2,LEAVES:0)
Block(-13,23,-1,LEAVES:0)
Block(-10,23,-1,LEAVES:0)
Block(-9,23,-1,LEAVES:0)
Block(-8,23,-1,LEAVES:0)
Block(-7,23,-1,LEAVES:0)
Block(-6,23,-1,LEAVES:0)
Block(-5,23,-1,LEAVES:0)
Block(-4,23,-1,LEAVES:0)
Block(-3,23,-1,LEAVES:0)
Block(-2,23,-1,LEAVES:0)
Block(-1,23,-1,LEAVES:0)
Block(0,23,-1,LEAVES:0)
Block(1,23,-1,LEAVES:0)
Block(2,23,-1,LEAVES:0)
Block(3,23,-1,LEAVES:0)
Block(-13,23,0,LEAVES:0)
Block(-12,23,0,LEAVES:0)
Block(-11,23,0,LEAVES:0)
Block(-10,23,0,LEAVES:0)
Block(-9,23,0,LEAVES:0)
Block(-8,23,0,LEAVES:0)
Block(-7,23,0,LEAVES:0)
Block(-6,23,0,LEAVES:0)
Block(-5,23,0,LEAVES:0)
Block(-4,23,0,LEAVES:0)
Block(-2,23,0,LEAVES:0)
Block(-1,23,0,LEAVES:0)
Block(1,23,0,LOG:12)
Block(2,23,0,LEAVES:0)
Block(3,23,0,LEAVES:0)
Block(-12,23,1,LEAVES:0)
Block(-11,23,1,LEAVES:0)
Block(-10,23,1,LEAVES:0)
Block(-9,23,1,LEAVES:0)
Block(-8,23,1,LEAVES:0)
Block(-7,23,1,LEAVES:0)
Block(-5,23,1,LEAVES:0)
Block(-4,23,1,LEAVES:0)
Block(-3,23,1,LEAVES:0)
Block(-2,23,1,LEAVES:0)
Block(-1,23,1,LEAVES:0)
Block(0,23,1,LEAVES:0)
Block(1,23,1,LEAVES:0)
Block(2,23,1,LEAVES:0)
Block(3,23,1,LOG:12)
Block(4,23,1,LEAVES:4)
Block(-11,23,2,LEAVES:0)
Block(-9,23,2,LEAVES:0)
Block(-8,23,2,LEAVES:0)
Block(-7,23,2,LEAVES:0)
Block(-5,23,2,LEAVES:0)
Block(-4,23,2,LEAVES:0)
Block(-3,23,2,LEAVES:0)
Block(-2,23,2,LEAVES:0)
Block(-1,23,2,LEAVES:0)
Block(0,23,2,LEAVES:0)
Block(1,23,2,LEAVES:0)
Block(2,23,2,LEAVES:0)
Block(3,23,2,LEAVES:0)
Block(5,23,2,LEAVES:0)
Block(-11,23,3,LEAVES:0)
Block(-7,23,3,LEAVES:0)
Block(-6,23,3,LEAVES:0)
Block(-5,23,3,LEAVES:0)
Block(-3,23,3,LEAVES:0)
Block(0,23,3,LEAVES:0)
Block(1,23,3,LEAVES:0)
Block(2,23,3,LEAVES:0)
Block(3,23,3,LOG:12)
Block(4,23,3,LEAVES:0)
Block(-10,23,4,LEAVES:12)
Block(-9,23,4,LEAVES:0)
Block(-8,23,4,LEAVES:0)
Block(-7,23,4,LEAVES:0)
Block(-6,23,4,LEAVES:0)
Block(-5,23,4,LEAVES:0)
Block(-4,23,4,LEAVES:0)
Block(-3,23,4,LEAVES:0)
Block(-1,23,4,LEAVES:0)
Block(0,23,4,LEAVES:0)
Block(1,23,4,LEAVES:0)
Block(2,23,4,LEAVES:0)
Block(3,23,4,LEAVES:0)
Block(4,23,4,LEAVES:0)
Block(5,23,4,LEAVES:0)
Block(-9,23,5,LEAVES:0)
Block(-7,23,5,LEAVES:0)
Block(-6,23,5,LEAVES:0)
Block(-5,23,5,LEAVES:0)
Block(-4,23,5,LEAVES:0)
Block(-3,23,5,LEAVES:0)
Block(-2,23,5,LEAVES:0)
Block(-1,23,5,LOG:12)
Block(0,23,5,LEAVES:0)
Block(1,23,5,LEAVES:0)
Block(2,23,5,LEAVES:0)
Block(3,23,5,LEAVES:0)
Block(4,23,5,LEAVES:0)
Block(-13,23,6,LEAVES:12)
Block(-12,23,6,LEAVES:12)
Block(-11,23,6,LEAVES:0)
Block(-10,23,6,LEAVES:0)
Block(-9,23,6,LEAVES:0)
Block(-8,23,6,LEAVES:0)
Block(-6,23,6,LOG:12)
Block(-5,23,6,LOG:12)
Block(-4,23,6,LEAVES:0)
Block(-3,23,6,LEAVES:0)
Block(-2,23,6,LEAVES:0)
Block(-1,23,6,LEAVES:0)
Block(0,23,6,LEAVES:0)
Block(1,23,6,LEAVES:0)
Block(3,23,6,LEAVES:0)
Block(4,23,6,LEAVES:12)
Block(-12,23,7,LEAVES:0)
Block(-11,23,7,LEAVES:0)
Block(-9,23,7,LEAVES:0)
Block(-8,23,7,LEAVES:0)
Block(-7,23,7,LEAVES:0)
Block(-6,23,7,LEAVES:0)
Block(-5,23,7,LEAVES:0)
Block(-4,23,7,LEAVES:0)
Block(-3,23,7,LEAVES:0)
Block(-1,23,7,LEAVES:0)
Block(0,23,7,LEAVES:0)
Block(1,23,7,LEAVES:0)
Block(3,23,7,LEAVES:0)
Block(-13,23,8,LEAVES:0)
Block(-11,23,8,LEAVES:0)
Block(-8,23,8,LOG:12)
Block(-7,23,8,LEAVES:0)
Block(-5,23,8,LEAVES:0)
Block(-4,23,8,LEAVES:0)
Block(-3,23,8,LEAVES:0)
Block(-1,23,8,LEAVES:0)
Block(0,23,8,LEAVES:0)
Block(2,23,8,LEAVES:0)
Block(4,23,8,LEAVES:12)
Block(5,23,8,LEAVES:12)
Block(-12,23,9,LEAVES:0)
Block(-11,23,9,LEAVES:0)
Block(-9,23,9,LEAVES:0)
Block(-8,23,9,LOG:12)
Block(-7,23,9,LEAVES:0)
Block(-6,23,9,LEAVES:0)
Block(-5,23,9,LOG:12)
Block(-3,23,9,LEAVES:0)
Block(-2,23,9,LEAVES:0)
Block(-1,23,9,LEAVES:0)
Block(0,23,9,LEAVES:0)
Block(3,23,9,LEAVES:0)
Block(-9,23,10,LEAVES:0)
Block(-8,23,10,LEAVES:0)
Block(-7,23,10,LEAVES:0)
Block(-6,23,10,LOG:12)
Block(-5,23,10,LOG:12)
Block(-4,23,10,LEAVES:0)
Block(-9,23,11,LEAVES:0)
Block(-8,23,11,LEAVES:0)
Block(-7,23,11,LEAVES:12)
Block(-6,23,11,LEAVES:12)
Block(-5,23,11,LEAVES:0)
Block(-4,23,11,LEAVES:0)
Block(-3,23,11,LEAVES:0)
Block(-8,23,12,LEAVES:0)
Block(-6,23,12,LEAVES:0)
Block(-5,23,12,LEAVES:0)
Block(-3,23,12,LEAVES:0)
Block(-10,24,-13,LEAVES:0)
Block(-9,24,-12,LEAVES:0)
Block(-11,24,-11,LEAVES:4)
Block(-10,24,-11,LEAVES:4)
Block(-8,24,-11,LEAVES:0)
Block(-7,24,-11,LEAVES:4)
Block(-6,24,-11,LEAVES:4)
Block(-5,24,-11,LEAVES:4)
Block(-4,24,-11,LEAVES:4)
Block(-3,24,-11,LEAVES:0)
Block(-1,24,-11,LEAVES:0)
Block(2,24,-11,LEAVES:4)
Block(-13,24,-10,LEAVES:0)
Block(-12,24,-10,LEAVES:0)
Block(-11,24,-10,LEAVES:0)
Block(-10,24,-10,LEAVES:0)
Block(-8,24,-10,LEAVES:0)
Block(-7,24,-10,LEAVES:0)
Block(-6,24,-10,LEAVES:0)
Block(-4,24,-10,LEAVES:0)
Block(-3,24,-10,LEAVES:0)
Block(-1,24,-10,LEAVES:0)
Block(2,24,-10,LEAVES:4)
Block(3,24,-10,LEAVES:4)
Block(4,24,-10,LEAVES:0)
Block(-14,24,-9,LEAVES:0)
Block(-13,24,-9,LEAVES:0)
Block(-11,24,-9,LEAVES:0)
Block(-9,24,-9,LEAVES:0)
Block(-6,24,-9,LEAVES:0)
Block(-5,24,-9,LEAVES:0)
Block(-4,24,-9,LEAVES:0)
Block(-3,24,-9,LEAVES:0)
Block(-2,24,-9,LEAVES:0)
Block(1,24,-9,LEAVES:0)
Block(2,24,-9,LEAVES:0)
Block(3,24,-9,LEAVES:0)
Block(6,24,-9,LEAVES:0)
Block(7,24,-9,LEAVES:4)
Block(-13,24,-8,LEAVES:0)
Block(-12,24,-8,LEAVES:0)
Block(-10,24,-8,LEAVES:0)
Block(-7,24,-8,LEAVES:0)
Block(-5,24,-8,LEAVES:0)
Block(-4,24,-8,LEAVES:0)
Block(-3,24,-8,LEAVES:0)
Block(-2,24,-8,LEAVES:0)
Block(0,24,-8,LEAVES:0)
Block(1,24,-8,LEAVES:0)
Block(4,24,-8,LEAVES:12)
Block(6,24,-8,LEAVES:0)
Block(7,24,-8,LEAVES:4)
Block(-13,24,-7,LEAVES:4)
Block(-12,24,-7,LEAVES:4)
Block(-11,24,-7,LEAVES:0)
Block(-10,24,-7,LEAVES:0)
Block(-9,24,-7,LEAVES:0)
Block(-8,24,-7,LEAVES:0)
Block(-6,24,-7,LEAVES:0)
Block(-4,24,-7,LEAVES:0)
Block(-1,24,-7,LEAVES:0)
Block(0,24,-7,LEAVES:0)
Block(1,24,-7,LEAVES:0)
Block(2,24,-7,LEAVES:0)
Block(3,24,-7,LEAVES:0)
Block(4,24,-7,LEAVES:4)
Block(5,24,-7,LEAVES:4)
Block(6,24,-7,LEAVES:0)
Block(7,24,-7,LEAVES:4)
Block(8,24,-7,LEAVES:4)
Block(-15,24,-6,LEAVES:0)
Block(-13,24,-6,LEAVES:0)
Block(-12,24,-6,LEAVES:0)
Block(-11,24,-6,LEAVES:4)
Block(-10,24,-6,LEAVES:0)
Block(-9,24,-6,LEAVES:0)
Block(-8,24,-6,LEAVES:0)
Block(-7,24,-6,LEAVES:0)
Block(-6,24,-6,LEAVES:0)
Block(-5,24,-6,LEAVES:0)
Block(-4,24,-6,LEAVES:0)
Block(-3,24,-6,LEAVES:0)
Block(-1,24,-6,LEAVES:0)
Block(0,24,-6,LOG:12)
Block(3,24,-6,LEAVES:0)
Block(5,24,-6,LEAVES:4)
Block(6,24,-6,LEAVES:4)
Block(7,24,-6,LOG:12)
Block(8,24,-6,LEAVES:0)
Block(-12,24,-5,LEAVES:0)
Block(-11,24,-5,LEAVES:0)
Block(-10,24,-5,LEAVES:0)
Block(-9,24,-5,LEAVES:0)
Block(-8,24,-5,LEAVES:0)
Block(-7,24,-5,LEAVES:0)
Block(-6,24,-5,LEAVES:0)
Block(-5,24,-5,LEAVES:0)
Block(-4,24,-5,LEAVES:0)
Block(-3,24,-5,LEAVES:0)
Block(-2,24,-5,LEAVES:0)
Block(-1,24,-5,LOG:12)
Block(0,24,-5,LOG:12)
Block(2,24,-5,LEAVES:0)
Block(3,24,-5,LEAVES:0)
Block(4,24,-5,LEAVES:0)
Block(7,24,-5,LEAVES:4)
Block(-11,24,-4,LEAVES:0)
Block(-10,24,-4,LEAVES:0)
Block(-9,24,-4,LEAVES:0)
Block(-8,24,-4,LEAVES:0)
Block(-7,24,-4,LEAVES:0)
Block(-6,24,-4,LEAVES:0)
Block(-5,24,-4,LEAVES:0)
Block(-4,24,-4,LEAVES:0)
Block(-3,24,-4,LEAVES:0)
Block(-2,24,-4,LOG:12)
Block(-1,24,-4,LOG:12)
Block(2,24,-4,LEAVES:0)
Block(3,24,-4,LEAVES:0)
Block(-11,24,-3,LEAVES:0)
Block(-10,24,-3,LEAVES:0)
Block(-9,24,-3,LEAVES:0)
Block(-8,24,-3,LEAVES:0)
Block(-7,24,-3,LEAVES:0)
Block(-6,24,-3,LEAVES:0)
Block(-5,24,-3,LEAVES:0)
Block(-4,24,-3,LEAVES:0)
Block(-3,24,-3,LEAVES:0)
Block(-2,24,-3,LOG:12)
Block(-1,24,-3,LEAVES:0)
Block(0,24,-3,LEAVES:0)
Block(3,24,-3,LEAVES:0)
Block(-11,24,-2,LEAVES:0)
Block(-10,24,-2,LEAVES:0)
Block(-6,24,-2,LEAVES:0)
Block(-5,24,-2,LEAVES:0)
Block(-4,24,-2,LEAVES:0)
Block(-3,24,-2,LEAVES:0)
Block(-1,24,-2,LEAVES:0)
Block(1,24,-2,LEAVES:0)
Block(2,24,-2,LEAVES:0)
Block(3,24,-2,LEAVES:0)
Block(-12,24,-1,LEAVES:0)
Block(-10,24,-1,LEAVES:0)
Block(-9,24,-1,LEAVES:0)
Block(-8,24,-1,LEAVES:0)
Block(-7,24,-1,LEAVES:0)
Block(-6,24,-1,LEAVES:0)
Block(-5,24,-1,LEAVES:0)
Block(-3,24,-1,LEAVES:0)
Block(-2,24,-1,LEAVES:0)
Block(-1,24,-1,LEAVES:0)
Block(0,24,-1,LEAVES:0)
Block(1,24,-1,LEAVES:0)
Block(2,24,-1,LEAVES:0)
Block(3,24,-1,LEAVES:0)
Block(5,24,-1,LEAVES:0)
Block(6,24,-1,LEAVES:0)
Block(-12,24,0,LEAVES:0)
Block(-11,24,0,LOG:12)
Block(-10,24,0,LEAVES:0)
Block(-9,24,0,LEAVES:0)
Block(-8,24,0,LEAVES:0)
Block(-7,24,0,LEAVES:0)
Block(-6,24,0,LEAVES:0)
Block(-5,24,0,LEAVES:0)
Block(-4,24,0,LEAVES:0)
Block(-3,24,0,LEAVES:0)
Block(-2,24,0,LEAVES:0)
Block(-1,24,0,LEAVES:0)
Block(0,24,0,LEAVES:0)
Block(1,24,0,LEAVES:0)
Block(2,24,0,LEAVES:0)
Block(3,24,0,LEAVES:0)
Block(4,24,0,LEAVES:0)
Block(5,24,0,LEAVES:0)
Block(-11,24,1,LEAVES:0)
Block(-10,24,1,LEAVES:0)
Block(-9,24,1,LEAVES:0)
Block(-7,24,1,LEAVES:0)
Block(-5,24,1,LEAVES:0)
Block(-4,24,1,LEAVES:0)
Block(-2,24,1,LEAVES:0)
Block(-1,24,1,LEAVES:0)
Block(0,24,1,LEAVES:0)
Block(1,24,1,LEAVES:0)
Block(2,24,1,LEAVES:0)
Block(3,24,1,LEAVES:4)
Block(4,24,1,LEAVES:4)
Block(-10,24,2,LEAVES:0)
Block(-8,24,2,LEAVES:0)
Block(-7,24,2,LEAVES:0)
Block(-6,24,2,LEAVES:0)
Block(-4,24,2,LEAVES:0)
Block(-3,24,2,LEAVES:0)
Block(-2,24,2,LEAVES:0)
Block(-1,24,2,LOG:12)
Block(0,24,2,LEAVES:0)
Block(1,24,2,LEAVES:0)
Block(2,24,2,LEAVES:0)
Block(3,24,2,LEAVES:0)
Block(4,24,2,LEAVES:0)
Block(-9,24,3,LEAVES:0)
Block(-8,24,3,LEAVES:0)
Block(-7,24,3,LEAVES:0)
Block(-6,24,3,LEAVES:0)
Block(-5,24,3,LEAVES:0)
Block(-4,24,3,LEAVES:0)
Block(-3,24,3,LEAVES:0)
Block(-2,24,3,LEAVES:0)
Block(-1,24,3,LEAVES:0)
Block(0,24,3,LEAVES:0)
Block(2,24,3,LEAVES:0)
Block(3,24,3,LEAVES:0)
Block(5,24,3,LEAVES:0)
Block(-9,24,4,LEAVES:0)
Block(-8,24,4,LEAVES:0)
Block(-7,24,4,LEAVES:0)
Block(-6,24,4,LEAVES:0)
Block(-5,24,4,LEAVES:0)
Block(-4,24,4,LEAVES:0)
Block(-3,24,4,LEAVES:0)
Block(-2,24,4,LEAVES:0)
Block(-1,24,4,LEAVES:0)
Block(0,24,4,LEAVES:0)
Block(1,24,4,LEAVES:0)
Block(2,24,4,LEAVES:0)
Block(3,24,4,LEAVES:0)
Block(4,24,4,LEAVES:0)
Block(-7,24,5,LEAVES:0)
Block(-6,24,5,LOG:12)
Block(-5,24,5,LEAVES:0)
Block(-4,24,5,LEAVES:0)
Block(-3,24,5,LEAVES:0)
Block(-2,24,5,LEAVES:0)
Block(0,24,5,LEAVES:0)
Block(1,24,5,LEAVES:0)
Block(2,24,5,LEAVES:0)
Block(3,24,5,LEAVES:0)
Block(-9,24,6,LEAVES:0)
Block(-8,24,6,LEAVES:0)
Block(-7,24,6,LEAVES:0)
Block(-6,24,6,LEAVES:0)
Block(-3,24,6,LEAVES:0)
Block(-1,24,6,LEAVES:0)
Block(0,24,6,LEAVES:0)
Block(1,24,6,LEAVES:0)
Block(2,24,6,LEAVES:0)
Block(3,24,6,LEAVES:0)
Block(-11,24,7,LEAVES:0)
Block(-5,24,7,LEAVES:0)
Block(0,24,7,LEAVES:0)
Block(2,24,7,LEAVES:0)
Block(4,24,7,LEAVES:0)
Block(5,24,7,LEAVES:12)
Block(6,24,7,LEAVES:12)
Block(-11,24,8,LEAVES:0)
Block(-10,24,8,LEAVES:0)
Block(-9,24,8,LEAVES:0)
Block(-7,24,8,LEAVES:0)
Block(-6,24,8,LEAVES:0)
Block(-5,24,8,LEAVES:0)
Block(-4,24,8,LEAVES:0)
Block(-3,24,8,LEAVES:0)
Block(-2,24,8,LEAVES:0)
Block(-1,24,8,LEAVES:0)
Block(2,24,8,LEAVES:0)
Block(3,24,8,LEAVES:4)
Block(4,24,8,LEAVES:12)
Block(5,24,8,LEAVES:12)
Block(-11,24,9,LEAVES:0)
Block(-9,24,9,LEAVES:0)
Block(-8,24,9,LEAVES:0)
Block(-6,24,9,LEAVES:0)
Block(-5,24,9,LEAVES:0)
Block(-3,24,9,LEAVES:0)
Block(-1,24,9,LEAVES:0)
Block(-9,24,10,LEAVES:0)
Block(-7,24,10,LEAVES:0)
Block(-6,24,10,LEAVES:0)
Block(-5,24,10,LEAVES:0)
Block(-7,24,11,LEAVES:0)
Block(-6,24,11,LEAVES:12)
Block(-5,24,11,LEAVES:12)
Block(-4,24,11,LEAVES:0)
Block(-6,24,12,LEAVES:12)
Block(-10,25,-12,LEAVES:0)
Block(-10,25,-11,LEAVES:0)
Block(-9,25,-11,LEAVES:0)
Block(-8,25,-11,LEAVES:4)
Block(-6,25,-11,LEAVES:0)
Block(-5,25,-11,LEAVES:0)
Block(0,25,-11,LEAVES:4)
Block(1,25,-11,LEAVES:4)
Block(2,25,-11,LEAVES:4)
Block(-12,25,-10,LEAVES:0)
Block(-11,25,-10,LEAVES:4)
Block(-10,25,-10,LOG:12)
Block(-9,25,-10,LEAVES:0)
Block(-8,25,-10,LEAVES:0)
Block(-7,25,-10,LEAVES:0)
Block(-6,25,-10,LEAVES:0)
Block(-5,25,-10,LEAVES:0)
Block(-3,25,-10,LEAVES:12)
Block(-1,25,-10,LEAVES:0)
Block(0,25,-10,LEAVES:0)
Block(1,25,-10,LEAVES:4)
Block(2,25,-10,LOG:12)
Block(3,25,-10,LEAVES:4)
Block(4,25,-10,LEAVES:0)
Block(-13,25,-9,LEAVES:0)
Block(-12,25,-9,LEAVES:0)
Block(-11,25,-9,LEAVES:0)
Block(-10,25,-9,LEAVES:0)
Block(-9,25,-9,LEAVES:0)
Block(-8,25,-9,LEAVES:0)
Block(-4,25,-9,LEAVES:0)
Block(-3,25,-9,LEAVES:0)
Block(-2,25,-9,LEAVES:4)
Block(-1,25,-9,LEAVES:0)
Block(0,25,-9,LEAVES:0)
Block(1,25,-9,LEAVES:0)
Block(2,25,-9,LEAVES:0)
Block(3,25,-9,LEAVES:0)
Block(-13,25,-8,LEAVES:0)
Block(-12,25,-8,LEAVES:0)
Block(-10,25,-8,LEAVES:0)
Block(-9,25,-8,LEAVES:0)
Block(-8,25,-8,LEAVES:0)
Block(-5,25,-8,LEAVES:0)
Block(-3,25,-8,LEAVES:0)
Block(-2,25,-8,LEAVES:0)
Block(-1,25,-8,LEAVES:0)
Block(1,25,-8,LOG:12)
Block(4,25,-8,LEAVES:12)
Block(5,25,-8,LEAVES:0)
Block(6,25,-8,LEAVES:0)
Block(-11,25,-7,LEAVES:0)
Block(-10,25,-7,LEAVES:0)
Block(-9,25,-7,LEAVES:0)
Block(-6,25,-7,LEAVES:0)
Block(-5,25,-7,LEAVES:0)
Block(-4,25,-7,LEAVES:0)
Block(-3,25,-7,LEAVES:0)
Block(-2,25,-7,LEAVES:0)
Block(-1,25,-7,LEAVES:0)
Block(0,25,-7,LOG:12)
Block(1,25,-7,LOG:12)
Block(3,25,-7,LEAVES:0)
Block(6,25,-7,LEAVES:12)
Block(7,25,-7,LEAVES:4)
Block(-11,25,-6,LEAVES:4)
Block(-10,25,-6,LEAVES:0)
Block(-9,25,-6,LEAVES:0)
Block(-8,25,-6,LEAVES:0)
Block(-7,25,-6,LEAVES:0)
Block(-6,25,-6,LEAVES:0)
Block(-5,25,-6,LEAVES:0)
Block(-3,25,-6,LOG:12)
Block(-2,25,-6,LEAVES:0)
Block(-1,25,-6,LEAVES:0)
Block(0,25,-6,LOG:12)
Block(1,25,-6,LEAVES:0)
Block(3,25,-6,LEAVES:0)
Block(5,25,-6,LEAVES:12)
Block(6,25,-6,LEAVES:12)
Block(7,25,-6,LEAVES:0)
Block(-10,25,-5,LEAVES:0)
Block(-9,25,-5,LEAVES:0)
Block(-7,25,-5,LEAVES:0)
Block(-6,25,-5,LEAVES:0)
Block(-3,25,-5,LEAVES:0)
Block(-2,25,-5,LEAVES:0)
Block(-1,25,-5,LEAVES:0)
Block(1,25,-5,LEAVES:0)
Block(6,25,-5,LEAVES:12)
Block(7,25,-5,LEAVES:4)
Block(8,25,-5,LEAVES:4)
Block(-11,25,-4,LEAVES:0)
Block(-10,25,-4,LEAVES:0)
Block(-9,25,-4,LEAVES:0)
Block(-7,25,-4,LEAVES:0)
Block(-6,25,-4,LEAVES:0)
Block(-5,25,-4,LEAVES:0)
Block(-4,25,-4,LEAVES:0)
Block(-3,25,-4,LEAVES:0)
Block(-2,25,-4,LEAVES:0)
Block(-1,25,-4,LEAVES:0)
Block(0,25,-4,LEAVES:0)
Block(1,25,-4,LEAVES:0)
Block(2,25,-4,LEAVES:0)
Block(3,25,-4,LEAVES:0)
Block(6,25,-4,LEAVES:0)
Block(-9,25,-3,LEAVES:0)
Block(-8,25,-3,LEAVES:0)
Block(-7,25,-3,LEAVES:0)
Block(-6,25,-3,LOG:12)
Block(-5,25,-3,LEAVES:0)
Block(-4,25,-3,LEAVES:0)
Block(-2,25,-3,LEAVES:0)
Block(0,25,-3,LEAVES:0)
Block(1,25,-3,LEAVES:0)
Block(2,25,-3,LEAVES:0)
Block(3,25,-3,LEAVES:0)
Block(-8,25,-2,LEAVES:0)
Block(-7,25,-2,LEAVES:0)
Block(-6,25,-2,LEAVES:0)
Block(-5,25,-2,LEAVES:0)
Block(-4,25,-2,LEAVES:0)
Block(-3,25,-2,LEAVES:0)
Block(-2,25,-2,LEAVES:0)
Block(-1,25,-2,LEAVES:0)
Block(0,25,-2,LEAVES:0)
Block(1,25,-2,LEAVES:0)
Block(2,25,-2,LEAVES:0)
Block(5,25,-2,LEAVES:0)
Block(6,25,-2,LEAVES:0)
Block(-11,25,-1,LEAVES:0)
Block(-9,25,-1,LEAVES:0)
Block(-8,25,-1,LEAVES:0)
Block(-6,25,-1,LOG:12)
Block(-4,25,-1,LEAVES:0)
Block(-3,25,-1,LOG:12)
Block(-2,25,-1,LEAVES:0)
Block(-1,25,-1,LEAVES:0)
Block(0,25,-1,LEAVES:0)
Block(1,25,-1,LOG:12)
Block(2,25,-1,LEAVES:0)
Block(3,25,-1,LEAVES:0)
Block(5,25,-1,LEAVES:0)
Block(6,25,-1,LEAVES:0)
Block(-11,25,0,LEAVES:0)
Block(-9,25,0,LEAVES:0)
Block(-8,25,0,LEAVES:0)
Block(-7,25,0,LEAVES:0)
Block(-6,25,0,LEAVES:0)
Block(-5,25,0,LEAVES:0)
Block(-4,25,0,LEAVES:0)
Block(-3,25,0,LEAVES:0)
Block(-2,25,0,LEAVES:0)
Block(-1,25,0,LEAVES:0)
Block(0,25,0,LEAVES:0)
Block(2,25,0,LEAVES:0)
Block(3,25,0,LEAVES:0)
Block(4,25,0,LEAVES:0)
Block(5,25,0,LOG:12)
Block(6,25,0,LEAVES:4)
Block(-10,25,1,LEAVES:0)
Block(-9,25,1,LEAVES:0)
Block(-8,25,1,LEAVES:0)
Block(-7,25,1,LEAVES:0)
Block(-6,25,1,LEAVES:0)
Block(-5,25,1,LEAVES:0)
Block(-4,25,1,LEAVES:0)
Block(-3,25,1,LEAVES:0)
Block(-2,25,1,LEAVES:0)
Block(-1,25,1,LEAVES:0)
Block(0,25,1,LEAVES:0)
Block(1,25,1,LEAVES:0)
Block(4,25,1,LEAVES:0)
Block(5,25,1,LEAVES:4)
Block(-10,25,2,LEAVES:0)
Block(-9,25,2,LEAVES:0)
Block(-8,25,2,LEAVES:0)
Block(-7,25,2,LEAVES:0)
Block(-6,25,2,LEAVES:0)
Block(-5,25,2,LEAVES:0)
Block(-4,25,2,LOG:12)
Block(-3,25,2,LEAVES:0)
Block(-2,25,2,LEAVES:0)
Block(-1,25,2,LOG:12)
Block(0,25,2,LEAVES:0)
Block(1,25,2,LEAVES:0)
Block(2,25,2,LEAVES:0)
Block(3,25,2,LEAVES:0)
Block(4,25,2,LEAVES:0)
Block(5,25,2,LEAVES:0)
Block(6,25,2,LEAVES:0)
Block(-8,25,3,LEAVES:0)
Block(-7,25,3,LEAVES:0)
Block(-6,25,3,LEAVES:0)
Block(-5,25,3,LEAVES:0)
Block(-3,25,3,LEAVES:0)
Block(-2,25,3,LEAVES:0)
Block(-1,25,3,LEAVES:0)
Block(1,25,3,LEAVES:0)
Block(2,25,3,LEAVES:0)
Block(3,25,3,LEAVES:0)
Block(5,25,3,LEAVES:0)
Block(-8,25,4,LEAVES:0)
Block(-6,25,4,LEAVES:0)
Block(-5,25,4,LEAVES:0)
Block(-4,25,4,LEAVES:0)
Block(-3,25,4,LEAVES:0)
Block(-2,25,4,LEAVES:0)
Block(-1,25,4,LEAVES:0)
Block(0,25,4,LEAVES:0)
Block(1,25,4,LEAVES:0)
Block(3,25,4,LEAVES:0)
Block(-7,25,5,LEAVES:0)
Block(-6,25,5,LEAVES:0)
Block(-5,25,5,LEAVES:0)
Block(-4,25,5,LEAVES:0)
Block(-3,25,5,LEAVES:0)
Block(-2,25,5,LEAVES:0)
Block(-1,25,5,LEAVES:0)
Block(0,25,5,LEAVES:0)
Block(2,25,5,LEAVES:0)
Block(3,25,5,LEAVES:0)
Block(-8,25,6,LEAVES:0)
Block(-3,25,6,LEAVES:0)
Block(2,25,6,LEAVES:0)
Block(-7,25,7,LEAVES:0)
Block(-6,25,7,LEAVES:0)
Block(-5,25,7,LEAVES:0)
Block(-4,25,7,LEAVES:0)
Block(-3,25,7,LEAVES:0)
Block(0,25,7,LEAVES:0)
Block(4,25,7,LEAVES:0)
Block(-9,25,8,LEAVES:0)
Block(-7,25,8,LEAVES:0)
Block(-6,25,8,LOG:12)
Block(-3,25,8,LEAVES:0)
Block(-1,25,8,LEAVES:0)
Block(5,25,8,LEAVES:0)
Block(-8,25,9,LEAVES:0)
Block(-6,25,9,LEAVES:0)
Block(-5,25,9,LEAVES:0)
Block(-8,25,10,LEAVES:0)
Block(-7,25,10,LEAVES:0)
Block(-6,25,10,LEAVES:0)
Block(-5,25,10,LEAVES:0)
Block(-4,25,10,LEAVES:0)
Block(-7,25,11,LEAVES:0)
Block(-6,25,11,LEAVES:0)
Block(-6,25,12,LEAVES:0)
Block(-6,25,13,LEAVES:12)
Block(-11,26,-11,LEAVES:12)
Block(-10,26,-11,LEAVES:0)
Block(-8,26,-11,LEAVES:0)
Block(-7,26,-11,LEAVES:0)
Block(1,26,-11,LEAVES:0)
Block(2,26,-11,LEAVES:4)
Block(3,26,-11,LEAVES:0)
Block(-11,26,-10,LEAVES:12)
Block(-10,26,-10,LEAVES:4)
Block(-9,26,-10,LEAVES:0)
Block(-7,26,-10,LEAVES:0)
Block(1,26,-10,LEAVES:4)
Block(2,26,-10,LEAVES:4)
Block(3,26,-10,LEAVES:4)
Block(4,26,-10,LEAVES:0)
Block(-12,26,-9,LEAVES:0)
Block(-11,26,-9,LEAVES:0)
Block(-10,26,-9,LEAVES:0)
Block(-9,26,-9,LEAVES:0)
Block(-8,26,-9,LEAVES:0)
Block(-3,26,-9,LEAVES:0)
Block(-1,26,-9,LEAVES:0)
Block(0,26,-9,LEAVES:4)
Block(1,26,-9,LEAVES:4)
Block(2,26,-9,LEAVES:4)
Block(-11,26,-8,LEAVES:0)
Block(-4,26,-8,LEAVES:0)
Block(0,26,-8,LEAVES:4)
Block(1,26,-8,LEAVES:4)
Block(2,26,-8,LEAVES:0)
Block(4,26,-8,LEAVES:12)
Block(-10,26,-7,LEAVES:0)
Block(-7,26,-7,LEAVES:0)
Block(-6,26,-7,LEAVES:0)
Block(-5,26,-7,LEAVES:0)
Block(-4,26,-7,LEAVES:0)
Block(-3,26,-7,LEAVES:0)
Block(-2,26,-7,LEAVES:0)
Block(-1,26,-7,LEAVES:0)
Block(0,26,-7,LEAVES:4)
Block(1,26,-7,LOG:12)
Block(2,26,-7,LEAVES:0)
Block(3,26,-7,LEAVES:0)
Block(4,26,-7,LEAVES:0)
Block(5,26,-7,LEAVES:0)
Block(-9,26,-6,LEAVES:0)
Block(-6,26,-6,LEAVES:0)
Block(-4,26,-6,LEAVES:0)
Block(-3,26,-6,LEAVES:0)
Block(-2,26,-6,LEAVES:0)
Block(-1,26,-6,LEAVES:0)
Block(0,26,-6,LEAVES:0)
Block(2,26,-6,LEAVES:0)
Block(4,26,-6,LEAVES:0)
Block(6,26,-6,LEAVES:12)
Block(-5,26,-5,LEAVES:0)
Block(-4,26,-5,LEAVES:0)
Block(-3,26,-5,LEAVES:0)
Block(-2,26,-5,LEAVES:0)
Block(-1,26,-5,LEAVES:0)
Block(0,26,-5,LEAVES:0)
Block(1,26,-5,LEAVES:0)
Block(2,26,-5,LEAVES:0)
Block(3,26,-5,LEAVES:0)
Block(6,26,-5,LEAVES:12)
Block(-7,26,-4,LEAVES:0)
Block(-5,26,-4,LEAVES:0)
Block(-3,26,-4,LEAVES:0)
Block(-2,26,-4,LEAVES:0)
Block(-1,26,-4,LEAVES:0)
Block(1,26,-4,LEAVES:0)
Block(2,26,-4,LEAVES:0)
Block(-9,26,-3,LEAVES:0)
Block(-7,26,-3,LEAVES:0)
Block(-6,26,-3,LOG:12)
Block(-5,26,-3,LEAVES:0)
Block(-4,26,-3,LEAVES:0)
Block(-3,26,-3,LEAVES:0)
Block(-2,26,-3,LEAVES:0)
Block(-1,26,-3,LEAVES:0)
Block(0,26,-3,LEAVES:0)
Block(1,26,-3,LEAVES:0)
Block(2,26,-3,LEAVES:0)
Block(-11,26,-2,LEAVES:0)
Block(-8,26,-2,LEAVES:0)
Block(-6,26,-2,LEAVES:0)
Block(-5,26,-2,LEAVES:0)
Block(-4,26,-2,LOG:12)
Block(-3,26,-2,LEAVES:0)
Block(-2,26,-2,LEAVES:0)
Block(-1,26,-2,LEAVES:0)
Block(0,26,-2,LEAVES:0)
Block(1,26,-2,LEAVES:0)
Block(2,26,-2,LEAVES:0)
Block(3,26,-2,LEAVES:0)
Block(-11,26,-1,LEAVES:0)
Block(-7,26,-1,LEAVES:0)
Block(-5,26,-1,LEAVES:0)
Block(-3,26,-1,LEAVES:0)
Block(-1,26,-1,LEAVES:0)
Block(0,26,-1,LEAVES:0)
Block(1,26,-1,LEAVES:0)
Block(2,26,-1,LEAVES:0)
Block(5,26,-1,LEAVES:12)
Block(6,26,-1,LEAVES:12)
Block(-9,26,0,LEAVES:0)
Block(-8,26,0,LEAVES:0)
Block(-7,26,0,LEAVES:0)
Block(-6,26,0,LEAVES:0)
Block(-5,26,0,LEAVES:0)
Block(-4,26,0,LEAVES:0)
Block(-2,26,0,LEAVES:0)
Block(-1,26,0,LEAVES:0)
Block(0,26,0,LEAVES:0)
Block(1,26,0,LEAVES:0)
Block(2,26,0,LEAVES:0)
Block(4,26,0,LEAVES:0)
Block(5,26,0,LEAVES:12)
Block(6,26,0,LEAVES:0)
Block(-7,26,1,LEAVES:0)
Block(-5,26,1,LEAVES:0)
Block(-3,26,1,LEAVES:0)
Block(-2,26,1,LEAVES:0)
Block(-1,26,1,LEAVES:0)
Block(0,26,1,LEAVES:0)
Block(2,26,1,LOG:12)
Block(4,26,1,LEAVES:0)
Block(6,26,1,LEAVES:0)
Block(-6,26,2,LEAVES:0)
Block(-5,26,2,LEAVES:0)
Block(-4,26,2,LEAVES:0)
Block(-3,26,2,LEAVES:0)
Block(-2,26,2,LEAVES:0)
Block(-1,26,2,LEAVES:0)
Block(0,26,2,LEAVES:0)
Block(1,26,2,LEAVES:0)
Block(2,26,2,LEAVES:0)
Block(-5,26,3,LEAVES:0)
Block(-3,26,3,LEAVES:0)
Block(-2,26,3,LEAVES:0)
Block(-1,26,3,LEAVES:0)
Block(0,26,3,LEAVES:0)
Block(1,26,3,LEAVES:0)
Block(2,26,3,LEAVES:0)
Block(3,26,3,LEAVES:0)
Block(4,26,3,LEAVES:0)
Block(5,26,3,LEAVES:0)
Block(-7,26,4,LEAVES:0)
Block(-6,26,4,LEAVES:0)
Block(-5,26,4,LEAVES:0)
Block(-4,26,4,LEAVES:0)
Block(-3,26,4,LEAVES:0)
Block(-2,26,4,LEAVES:0)
Block(-1,26,4,LEAVES:0)
Block(0,26,4,LEAVES:0)
Block(1,26,4,LEAVES:0)
Block(2,26,4,LEAVES:0)
Block(3,26,4,LEAVES:0)
Block(-7,26,5,LEAVES:0)
Block(-6,26,5,LEAVES:0)
Block(-4,26,5,LEAVES:0)
Block(-3,26,5,LEAVES:0)
Block(-2,26,5,LEAVES:0)
Block(-1,26,5,LEAVES:0)
Block(0,26,5,LEAVES:0)
Block(1,26,5,LEAVES:0)
Block(2,26,5,LEAVES:0)
Block(3,26,5,LEAVES:0)
Block(-7,26,6,LEAVES:0)
Block(-6,26,6,LEAVES:0)
Block(-4,26,6,LEAVES:0)
Block(-3,26,6,LEAVES:0)
Block(1,26,6,LEAVES:0)
Block(-8,26,7,LEAVES:12)
Block(-7,26,7,LEAVES:0)
Block(-6,26,7,LEAVES:0)
Block(-5,26,7,LEAVES:0)
Block(-3,26,7,LEAVES:0)
Block(-2,26,7,LEAVES:12)
Block(-8,26,8,LEAVES:12)
Block(-7,26,8,LEAVES:12)
Block(-6,26,8,LEAVES:0)
Block(-5,26,8,LEAVES:0)
Block(-4,26,8,LEAVES:0)
Block(-8,26,9,LEAVES:12)
Block(-6,26,9,LEAVES:0)
Block(-5,26,9,LEAVES:0)
Block(-4,26,9,LEAVES:0)
Block(-7,26,10,LEAVES:0)
Block(-6,26,10,LEAVES:0)
Block(-6,26,11,LEAVES:0)
Block(-7,27,-11,LEAVES:0)
Block(1,27,-11,LEAVES:4)
Block(-9,27,-10,LEAVES:4)
Block(-8,27,-10,LEAVES:0)
Block(-6,27,-10,LEAVES:0)
Block(-2,27,-10,LEAVES:0)
Block(2,27,-10,LEAVES:0)
Block(3,27,-10,LEAVES:4)
Block(4,27,-10,LEAVES:4)
Block(-6,27,-9,LEAVES:0)
Block(-5,27,-9,LEAVES:0)
Block(-4,27,-9,LEAVES:0)
Block(-2,27,-9,LEAVES:0)
Block(-1,27,-9,LEAVES:0)
Block(0,27,-9,LEAVES:4)
Block(2,27,-9,LEAVES:0)
Block(-7,27,-8,LEAVES:0)
Block(-6,27,-8,LEAVES:0)
Block(-5,27,-8,LEAVES:0)
Block(-4,27,-8,LEAVES:0)
Block(-3,27,-8,LEAVES:4)
Block(-2,27,-8,LEAVES:0)
Block(-1,27,-8,LEAVES:0)
Block(1,27,-8,LEAVES:4)
Block(2,27,-8,LEAVES:0)
Block(3,27,-8,LEAVES:0)
Block(-6,27,-7,LEAVES:0)
Block(-4,27,-7,LEAVES:0)
Block(-3,27,-7,LOG:12)
Block(-2,27,-7,LEAVES:0)
Block(-1,27,-7,LEAVES:0)
Block(1,27,-7,LEAVES:0)
Block(-7,27,-6,LEAVES:0)
Block(-6,27,-6,LEAVES:0)
Block(-5,27,-6,LEAVES:0)
Block(-4,27,-6,LEAVES:0)
Block(-3,27,-6,LEAVES:0)
Block(-2,27,-6,LEAVES:0)
Block(-8,27,-5,LEAVES:0)
Block(-7,27,-5,LEAVES:0)
Block(-6,27,-5,LEAVES:0)
Block(-5,27,-5,LEAVES:0)
Block(-4,27,-5,LEAVES:0)
Block(-2,27,-5,LEAVES:0)
Block(-1,27,-5,LEAVES:0)
Block(-6,27,-4,LEAVES:0)
Block(-5,27,-4,LOG:12)
Block(-4,27,-4,LEAVES:0)
Block(-3,27,-4,LEAVES:0)
Block(-2,27,-4,LEAVES:0)
Block(-1,27,-4,LEAVES:0)
Block(0,27,-4,LEAVES:0)
Block(1,27,-4,LEAVES:0)
Block(-7,27,-3,LEAVES:0)
Block(-5,27,-3,LEAVES:0)
Block(-4,27,-3,LEAVES:0)
Block(-3,27,-3,LEAVES:0)
Block(-1,27,-3,LEAVES:0)
Block(-8,27,-2,LEAVES:0)
Block(-7,27,-2,LEAVES:0)
Block(-6,27,-2,LEAVES:0)
Block(-5,27,-2,LEAVES:0)
Block(-4,27,-2,LEAVES:0)
Block(-3,27,-2,LEAVES:0)
Block(-2,27,-2,LEAVES:0)
Block(-1,27,-2,LEAVES:0)
Block(0,27,-2,LEAVES:0)
Block(1,27,-2,LEAVES:0)
Block(-7,27,-1,LEAVES:0)
Block(-6,27,-1,LEAVES:0)
Block(-5,27,-1,LEAVES:0)
Block(-3,27,-1,LEAVES:0)
Block(-2,27,-1,LEAVES:0)
Block(-1,27,-1,LEAVES:0)
Block(1,27,-1,LEAVES:0)
Block(2,27,-1,LEAVES:0)
Block(-7,27,0,LEAVES:0)
Block(-6,27,0,LEAVES:0)
Block(-5,27,0,LEAVES:0)
Block(-4,27,0,LEAVES:0)
Block(-3,27,0,LOG:12)
Block(-2,27,0,LEAVES:0)
Block(-1,27,0,LOG:12)
Block(0,27,0,LEAVES:0)
Block(1,27,0,LEAVES:0)
Block(2,27,0,LEAVES:0)
Block(5,27,0,LEAVES:0)
Block(6,27,0,LEAVES:0)
Block(-6,27,1,LEAVES:0)
Block(-5,27,1,LEAVES:0)
Block(-4,27,1,LEAVES:0)
Block(-3,27,1,LEAVES:0)
Block(-2,27,1,LEAVES:0)
Block(-1,27,1,LEAVES:0)
Block(0,27,1,LEAVES:0)
Block(2,27,1,LEAVES:0)
Block(-5,27,2,LEAVES:0)
Block(-4,27,2,LEAVES:0)
Block(-3,27,2,LEAVES:0)
Block(-2,27,2,LEAVES:0)
Block(-1,27,2,LEAVES:0)
Block(1,27,2,LEAVES:0)
Block(2,27,2,LEAVES:0)
Block(3,27,2,LEAVES:0)
Block(-7,27,3,LEAVES:0)
Block(-5,27,3,LEAVES:0)
Block(-4,27,3,LOG:12)
Block(-2,27,3,LEAVES:0)
Block(-1,27,3,LEAVES:0)
Block(1,27,3,LEAVES:4)
Block(3,27,3,LEAVES:0)
Block(-8,27,4,LEAVES:0)
Block(-7,27,4,LEAVES:0)
Block(-6,27,4,LEAVES:0)
Block(-5,27,4,LEAVES:0)
Block(-4,27,4,LOG:12)
Block(-3,27,4,LEAVES:0)
Block(-2,27,4,LEAVES:0)
Block(-1,27,4,LEAVES:0)
Block(0,27,4,LEAVES:0)
Block(2,27,4,LOG:12)
Block(3,27,4,LEAVES:4)
Block(-7,27,5,LEAVES:0)
Block(-6,27,5,LEAVES:0)
Block(-5,27,5,LEAVES:0)
Block(-3,27,5,LEAVES:0)
Block(-2,27,5,LEAVES:0)
Block(-1,27,5,LEAVES:0)
Block(0,27,5,LEAVES:0)
Block(1,27,5,LEAVES:0)
Block(2,27,5,LEAVES:0)
Block(-6,27,6,LEAVES:0)
Block(-5,27,6,LEAVES:0)
Block(-3,27,6,LEAVES:0)
Block(-2,27,6,LEAVES:0)
Block(-1,27,6,LEAVES:0)
Block(0,27,6,LEAVES:0)
Block(-8,27,7,LEAVES:12)
Block(-7,27,7,LEAVES:0)
Block(-6,27,7,LEAVES:0)
Block(-5,27,7,LEAVES:0)
Block(-4,27,7,LEAVES:0)
Block(-3,27,7,LEAVES:12)
Block(-6,27,8,LEAVES:0)
Block(-5,27,8,LEAVES:12)
Block(-4,27,8,LEAVES:0)
Block(-3,27,8,LEAVES:12)
Block(-6,27,9,LEAVES:12)
Block(-5,27,9,LEAVES:12)
Block(-3,27,9,LEAVES:12)
Block(-8,28,-10,LEAVES:0)
Block(-5,28,-10,LEAVES:0)
Block(2,28,-10,LEAVES:0)
Block(-7,28,-9,LEAVES:0)
Block(-6,28,-9,LEAVES:0)
Block(-2,28,-9,LEAVES:0)
Block(-1,28,-9,LEAVES:4)
Block(-7,28,-8,LEAVES:0)
Block(-6,28,-8,LEAVES:0)
Block(-5,28,-8,LEAVES:0)
Block(-4,28,-8,LEAVES:0)
Block(-3,28,-8,LEAVES:4)
Block(-1,28,-8,LEAVES:0)
Block(-7,28,-7,LEAVES:0)
Block(-6,28,-7,LEAVES:0)
Block(-5,28,-7,LEAVES:0)
Block(-4,28,-7,LEAVES:0)
Block(-1,28,-7,LEAVES:0)
Block(1,28,-7,LEAVES:0)
Block(2,28,-7,LEAVES:0)
Block(3,28,-7,LEAVES:0)
Block(-5,28,-6,LEAVES:0)
Block(-4,28,-6,LEAVES:0)
Block(-3,28,-6,LEAVES:0)
Block(-2,28,-6,LEAVES:0)
Block(-1,28,-6,LEAVES:0)
Block(1,28,-6,LEAVES:0)
Block(-7,28,-5,LEAVES:0)
Block(-4,28,-5,LEAVES:0)
Block(-3,28,-5,LEAVES:0)
Block(-1,28,-5,LEAVES:0)
Block(-7,28,-4,LEAVES:0)
Block(-6,28,-4,LEAVES:0)
Block(-5,28,-4,LEAVES:0)
Block(-3,28,-4,LEAVES:0)
Block(-2,28,-4,LEAVES:0)
Block(-1,28,-4,LEAVES:0)
Block(1,28,-4,LEAVES:0)
Block(-7,28,-3,LEAVES:12)
Block(-6,28,-3,LEAVES:12)
Block(-5,28,-3,LEAVES:0)
Block(-4,28,-3,LEAVES:0)
Block(-3,28,-3,LOG:12)
Block(-2,28,-3,LEAVES:0)
Block(0,28,-3,LEAVES:0)
Block(1,28,-3,LEAVES:0)
Block(-7,28,-2,LEAVES:12)
Block(-6,28,-2,LOG:12)
Block(-5,28,-2,LEAVES:0)
Block(-4,28,-2,LEAVES:0)
Block(-3,28,-2,LEAVES:0)
Block(-2,28,-2,LEAVES:0)
Block(-1,28,-2,LEAVES:0)
Block(0,28,-2,LOG:12)
Block(1,28,-2,LEAVES:0)
Block(2,28,-2,LEAVES:0)
Block(-7,28,-1,LEAVES:12)
Block(-6,28,-1,LEAVES:0)
Block(-5,28,-1,LEAVES:0)
Block(-4,28,-1,LEAVES:0)
Block(-3,28,-1,LEAVES:0)
Block(-1,28,-1,LEAVES:4)
Block(0,28,-1,LEAVES:0)
Block(1,28,-1,LEAVES:0)
Block(-7,28,0,LEAVES:0)
Block(-6,28,0,LEAVES:0)
Block(-4,28,0,LOG:12)
Block(-3,28,0,LEAVES:0)
Block(-2,28,0,LEAVES:0)
Block(-1,28,0,LEAVES:0)
Block(0,28,0,LEAVES:0)
Block(1,28,0,LEAVES:0)
Block(2,28,0,LEAVES:0)
Block(3,28,0,LEAVES:0)
Block(-8,28,1,LEAVES:12)
Block(-7,28,1,LEAVES:0)
Block(-6,28,1,LEAVES:0)
Block(-4,28,1,LEAVES:0)
Block(-3,28,1,LEAVES:0)
Block(-1,28,1,LEAVES:0)
Block(0,28,1,LEAVES:0)
Block(1,28,1,LEAVES:0)
Block(2,28,1,LEAVES:0)
Block(-5,28,2,LEAVES:0)
Block(-4,28,2,LEAVES:0)
Block(-3,28,2,LEAVES:0)
Block(-2,28,2,LEAVES:0)
Block(-1,28,2,LEAVES:0)
Block(0,28,2,LEAVES:0)
Block(1,28,2,LEAVES:4)
Block(2,28,2,LEAVES:4)
Block(-4,28,3,LEAVES:0)
Block(-2,28,3,LEAVES:0)
Block(-1,28,3,LEAVES:12)
Block(0,28,3,LEAVES:12)
Block(1,28,3,LOG:12)
Block(2,28,3,LEAVES:0)
Block(3,28,3,LEAVES:0)
Block(-7,28,4,LEAVES:0)
Block(-6,28,4,LEAVES:12)
Block(-5,28,4,LEAVES:0)
Block(-4,28,4,LEAVES:0)
Block(-3,28,4,LEAVES:0)
Block(-2,28,4,LEAVES:12)
Block(0,28,4,LEAVES:12)
Block(1,28,4,LEAVES:12)
Block(2,28,4,LEAVES:4)
Block(-5,28,5,LEAVES:0)
Block(-4,28,5,LEAVES:0)
Block(-3,28,5,LOG:12)
Block(-2,28,5,LEAVES:0)
Block(1,28,5,LEAVES:0)
Block(2,28,5,LEAVES:4)
Block(-7,28,6,LEAVES:12)
Block(-3,28,6,LEAVES:12)
Block(-2,28,6,LEAVES:0)
Block(-2,28,7,LEAVES:0)
Block(-6,28,8,LEAVES:0)
Block(-5,28,8,LEAVES:0)
Block(-4,28,8,LEAVES:12)
Block(-3,28,8,LEAVES:12)
Block(-4,29,-10,LEAVES:0)
Block(-7,29,-8,LEAVES:12)
Block(-6,29,-8,LEAVES:0)
Block(-4,29,-8,LEAVES:4)
Block(-2,29,-8,LEAVES:0)
Block(-7,29,-7,LEAVES:0)
Block(-6,29,-7,LOG:12)
Block(-5,29,-7,LEAVES:4)
Block(-4,29,-7,LEAVES:0)
Block(-3,29,-7,LEAVES:0)
Block(-2,29,-7,LEAVES:0)
Block(1,29,-7,LEAVES:0)
Block(-7,29,-6,LEAVES:0)
Block(-6,29,-6,LEAVES:0)
Block(-3,29,-6,LEAVES:0)
Block(1,29,-6,LEAVES:0)
Block(-5,29,-5,LEAVES:0)
Block(-4,29,-5,LEAVES:0)
Block(-5,29,-4,LEAVES:0)
Block(-4,29,-4,LEAVES:0)
Block(1,29,-4,LEAVES:0)
Block(-7,29,-3,LEAVES:12)
Block(-6,29,-3,LEAVES:4)
Block(-5,29,-3,LEAVES:12)
Block(-4,29,-3,LEAVES:0)
Block(-3,29,-3,LEAVES:4)
Block(-2,29,-3,LEAVES:4)
Block(0,29,-3,LEAVES:4)
Block(1,29,-3,LEAVES:0)
Block(-7,29,-2,LEAVES:0)
Block(-6,29,-2,LEAVES:12)
Block(-5,29,-2,LOG:12)
Block(-4,29,-2,LEAVES:0)
Block(-3,29,-2,LEAVES:0)
Block(0,29,-2,LEAVES:0)
Block(1,29,-2,LEAVES:4)
Block(-7,29,-1,LEAVES:12)
Block(-5,29,-1,LEAVES:0)
Block(-3,29,-1,LEAVES:0)
Block(0,29,-1,LEAVES:4)
Block(1,29,-1,LEAVES:0)
Block(2,29,-1,LEAVES:0)
Block(-7,29,0,LEAVES:0)
Block(-6,29,0,LEAVES:0)
Block(-5,29,0,LEAVES:4)
Block(-4,29,0,LEAVES:0)
Block(-1,29,0,LEAVES:0)
Block(2,29,0,LEAVES:0)
Block(-8,29,1,LEAVES:12)
Block(-6,29,1,LEAVES:0)
Block(-5,29,1,LEAVES:0)
Block(-4,29,1,LEAVES:0)
Block(0,29,1,LEAVES:4)
Block(2,29,1,LEAVES:0)
Block(-4,29,2,LEAVES:0)
Block(-3,29,2,LEAVES:0)
Block(-1,29,2,LEAVES:0)
Block(1,29,2,LEAVES:4)
Block(2,29,2,LEAVES:0)
Block(-6,29,3,LEAVES:12)
Block(-5,29,3,LEAVES:0)
Block(0,29,3,LEAVES:12)
Block(1,29,3,LEAVES:4)
Block(-5,29,4,LEAVES:12)
Block(-3,29,4,LEAVES:0)
Block(1,29,4,LEAVES:12)
Block(-4,29,5,LEAVES:12)
Block(-3,29,5,LEAVES:12)
Block(-2,29,5,LEAVES:12)
Block(-7,29,6,LEAVES:12)
Block(-6,29,6,LEAVES:12)
Block(-3,29,6,LEAVES:12)
Block(-6,30,-8,LEAVES:4)
Block(-5,30,-8,LEAVES:4)
Block(-4,30,-8,LEAVES:0)
Block(-3,30,-8,LEAVES:4)
Block(-7,30,-7,LEAVES:4)
Block(-6,30,-7,LEAVES:12)
Block(-5,30,-7,LEAVES:4)
Block(-4,30,-7,LOG:12)
Block(-3,30,-7,LEAVES:4)
Block(1,30,-7,LEAVES:0)
Block(-7,30,-6,LEAVES:4)
Block(-6,30,-6,LEAVES:0)
Block(-4,30,-6,LEAVES:0)
Block(-3,30,-6,LEAVES:4)
Block(-7,30,-5,LEAVES:0)
Block(-4,30,-5,LEAVES:0)
Block(-4,30,-4,LEAVES:0)
Block(-5,30,-3,LEAVES:4)
Block(-4,30,-3,LEAVES:0)
Block(-3,30,-3,LEAVES:0)
Block(-1,30,-3,LEAVES:0)
Block(0,30,-3,LEAVES:4)
Block(-7,30,-2,LEAVES:0)
Block(-6,30,-2,LEAVES:4)
Block(-5,30,-2,LEAVES:12)
Block(-4,30,-2,LEAVES:4)
Block(-3,30,-2,LEAVES:4)
Block(-2,30,-2,LEAVES:0)
Block(-1,30,-2,LEAVES:0)
Block(0,30,-2,LEAVES:0)
Block(-6,30,-1,LEAVES:4)
Block(-5,30,-1,LEAVES:4)
Block(-4,30,-1,LEAVES:4)
Block(-3,30,-1,LEAVES:0)
Block(-1,30,-1,LEAVES:0)
Block(-5,30,0,LEAVES:4)
Block(-4,30,0,LEAVES:4)
Block(-1,30,0,LEAVES:0)
Block(0,30,0,LEAVES:0)
Block(-4,30,1,LEAVES:0)
Block(-3,30,1,LEAVES:0)
Block(-1,30,1,LEAVES:0)
Block(-5,30,4,LEAVES:0)
Block(-5,30,6,LEAVES:12)
Block(-6,31,-8,LEAVES:12)
Block(-5,31,-8,LEAVES:4)
Block(-4,31,-8,LEAVES:4)
Block(-3,31,-8,LEAVES:4)
Block(-5,31,-7,LEAVES:0)
Block(-4,31,-7,LEAVES:4)
Block(-3,31,-7,LEAVES:4)
Block(-6,31,-6,LEAVES:0)
Block(-5,31,-6,LEAVES:0)
Block(-4,31,-6,LEAVES:4)
Block(-5,31,-5,LEAVES:0)
Block(-4,31,-5,LEAVES:0)
Block(-6,31,-2,LEAVES:0)
Block(-4,31,-1,LEAVES:12)
Block(-4,31,1,LEAVES:0)

#######################################################################
# +-----------------------------------------------------------------+ #
# |                            BO3 checks                           | #
# +-----------------------------------------------------------------+ #
#######################################################################

# Require a condition at a certain location in order for the BO3 to be spawned.
# BlockCheck(x,y,z,BlockName[,BlockName[,...]]) - one of the blocks must be at the location
# BlockCheckNot(x,y,z,BlockName[,BlockName[,...]]) - all the blocks must not be at the location
# LightCheck(x,y,z,minLightLevel,maxLightLevel) - light must be between min and max (inclusive)

# You can use "Solid" as a BlockName for matching all solid blocks or "All" to match all blocks that aren't air.

# Examples:
BlockCheck(0,-1,0,GRASS,DIRT:2,DIRT:1,DIRT)
#   BlockCheck(0,-1,0,Solid)       Require any solid block just below the object
#   BlockCheck(0,-1,0,WOOL)        Require any type of wool just below the object
#   BlockCheck(0,-1,0,WOOL:0)      Require white wool just below the object
#   BlockCheckNot(0,-1,0,WOOL:0)   Require that there is no white wool below the object
#   LightCheck(0,0,0,0,1)          Require almost complete darkness just below the object

#######################################################################
# +-----------------------------------------------------------------+ #
# |                             Branches                            | #
# +-----------------------------------------------------------------+ #
#######################################################################

# Branches are objects that will spawn when this object spawns when it is used in
# the CustomStructure resource. Branches can also have branches, making complex
# structures possible. See the wiki for more details.

# Regular Branches spawn each branch with an independent chance of spawning.
# Branch(x,y,z,branchName,rotation,chance[,anotherBranchName,rotation,chance[,...]][IndividualChance])
# branchName - name of the object to spawn.
# rotation - NORTH, SOUTH, EAST or WEST.
# IndividualChance - The chance each branch has to spawn, assumed to be 100 when left blank

# Weighted Branches spawn branches with a dependent chance of spawning.
# WeightedBranch(x,y,z,branchName,rotation,chance[,anotherBranchName,rotation,chance[,...]][MaxChanceOutOf])
# MaxChanceOutOf - The chance all branches have to spawn out of, assumed to be 100 when left blank
