#######################################################################
# +-----------------------------------------------------------------+ #
# |                            BO3 object                           | #
# +-----------------------------------------------------------------+ #
#######################################################################

# The descriptions in this file are accurate only for TerrainControl and OTG.
# For MCW and OTG+ these descriptions are only accurate if the BO3 is used as a CustomObject.
# MCW and OTG+ completely reimplemented CustomStructure, check the MCW/OTG+ documentation for more information.

# This is the config file of a custom object.
# If you add this object correctly to your BiomeConfigs, it will spawn in the world.

# This is the creator of this BO3 object
Author: Unknown

# A short description of this BO3 object
Description: This BO3 was converted from a schematic using OTGEdit. The author and description information of the schematic could not be found. If you know who the author of the schematic is then please add this information.

# The BO3 version, don't change this! It can be used by external applications to do a version check.
Version: 3

# The settings mode, WriteAll, WriteWithoutComments or WriteDisable. See WorldConfig.
SettingsMode: WriteDisable

#######################################################################
# +-----------------------------------------------------------------+ #
# |                          Main settings                          | #
# +-----------------------------------------------------------------+ #
#######################################################################

# This needs to be set to true to spawn the object in the Tree and Sapling resources.
Tree: true

# The frequency of the BO3 from 1 to 200. Tries this many times to spawn this BO3 when using the CustomObject(...) resource.
# Ignored by Tree(..), Sapling(..) and CustomStructure(..)
Frequency: 40

# The rarity of the BO3 from 0 to 100. Each spawn attempt has rarity% chance to succeed when using the CustomObject(...) resource.
# Ignored by Tree(..), Sapling(..) and CustomStructure(..)
Rarity: 100.0

# If you set this to true, the BO3 will be placed with a random rotation.
RotateRandomly: true

# The spawn height of the BO3 - randomY, highestBlock or highestSolidBlock.
SpawnHeight: highestSolidBlock
SpawnHeightOffset: -14
# The height limits for the BO3.
MinHeight: 112

MaxHeight: 140

# Objects can have other objects attached to it: branches. Branches can also
# have branches attached to it, which can also have branches, etc. This is the
# maximum branch depth for this objects.
MaxBranchDepth: 10

# When spawned with the UseWorld keyword, this BO3 should NOT spawn in the following biomes.
# If you writer.write the BO3 name directly in the BiomeConfigs, this will be ignored.
ExcludedBiomes: All

# To optimise this BO3 for faster loading times you can use Notepad++ to find/replace comments and abbreviate things.
# Notepad++ find/replace with regex:
# Find: ^[#;].* replace to nothing removes all lines starting with # 
# Find: ^\s*$ replace to nothing removes most empty lines 
# Notepad++ find/replace without regex:
# *Warning: This will only work for OTG 1.10.2 v21 / OTG 1.11.2 v6 or higher. B( is not recognised by lower versions.
# Find: Block( replace to B(

#######################################################################
# +-----------------------------------------------------------------+ #
# |                      Source block settings                      | #
# +-----------------------------------------------------------------+ #
#######################################################################

# The block(s) the BO3 should spawn in.
SourceBlocks: AIR,GRASS,DIRT,STONE,SAND,GRAVEL,CLAY,STATIONARY_WATER,FLOWING_WATER


# The maximum percentage of the BO3 that can be outside the SourceBlock.
# The BO3 won't be placed on a location with more blocks outside the SourceBlock than this percentage.
MaxPercentageOutsideSourceBlock: 0

# What to do when a block is about to be placed outside the SourceBlock? (dontPlace, placeAnyway)
OutsideSourceBlock: dontPlace

#######################################################################
# +-----------------------------------------------------------------+ #
# |                              Blocks                             | #
# +-----------------------------------------------------------------+ #
#######################################################################

# All the blocks used in the BO3 are listed here. Possible blocks:
# Block(x,y,z,id[.data][,nbtfile.nbt) or B(x,y,z,id[.data][,nbtfile.nbt)
# RandomBlock(x,y,z,id[:data][,nbtfile.nbt],chance[,id[:data][,nbtfile.nbt],chance[,...]])
# So RandomBlock(0,0,0,CHEST,chest.nbt,50,CHEST,anotherchest.nbt,100) will spawn a chest at
# the BO3 origin, and give it a 50% chance to have the contents of chest.nbt, or, if that
# fails, a 100% percent chance to have the contents of anotherchest.nbt.

Block(-7,16,2,STONE)
Block(-7,17,0,STONE)
Block(-7,17,1,STONE)
Block(-7,18,-2,STONE)
Block(-7,18,-1,STONE)
Block(-7,18,0,STONE)
Block(-7,18,1,STONE)
Block(-7,19,-2,STONE)
Block(-7,19,-1,STONE)
Block(-7,19,0,STONE)
Block(-7,19,1,STONE)
Block(-7,20,-2,STONE)
Block(-7,20,-1,STONE)
Block(-7,20,0,STONE)
Block(-7,20,1,STONE)
Block(-7,21,-2,STONE)
Block(-7,21,-1,STONE)
Block(-6,11,4,STONE)
Block(-6,12,3,STONE)
Block(-6,12,4,STONE)
Block(-6,13,2,STONE)
Block(-6,13,3,STONE)
Block(-6,13,4,STONE)
Block(-6,14,0,STONE)
Block(-6,14,1,STONE)
Block(-6,14,2,STONE)
Block(-6,14,3,STONE)
Block(-6,14,4,STONE)
Block(-6,15,-2,STONE)
Block(-6,15,-1,STONE)
Block(-6,15,0,STONE)
Block(-6,15,1,STONE)
Block(-6,15,2,STONE)
Block(-6,15,3,STONE)
Block(-6,15,4,STONE)
Block(-6,16,-4,STONE)
Block(-6,16,-3,STONE)
Block(-6,16,-2,STONE)
Block(-6,16,-1,STONE)
Block(-6,16,0,STONE)
Block(-6,16,1,STONE)
Block(-6,16,2,STONE)
Block(-6,16,3,STONE)
Block(-6,17,-4,STONE)
Block(-6,17,-3,STONE)
Block(-6,17,-2,STONE)
Block(-6,17,-1,STONE)
Block(-6,17,0,STONE)
Block(-6,17,1,STONE)
Block(-6,17,2,STONE)
Block(-6,17,3,STONE)
Block(-6,18,-4,STONE)
Block(-6,18,-3,STONE)
Block(-6,18,-2,STONE)
Block(-6,18,-1,STONE)
Block(-6,18,0,STONE)
Block(-6,18,1,STONE)
Block(-6,18,2,STONE)
Block(-6,18,3,STONE)
Block(-6,19,-4,STONE)
Block(-6,19,-3,STONE)
Block(-6,19,-2,STONE)
Block(-6,19,-1,STONE)
Block(-6,19,0,STONE)
Block(-6,19,1,STONE)
Block(-6,19,2,STONE)
Block(-6,19,3,STONE)
Block(-6,20,-4,STONE)
Block(-6,20,-3,STONE)
Block(-6,20,-2,STONE)
Block(-6,20,-1,STONE)
Block(-6,20,0,STONE)
Block(-6,20,1,STONE)
Block(-6,20,2,STONE)
Block(-6,21,-3,STONE)
Block(-6,21,-2,STONE)
Block(-6,21,-1,STONE)
Block(-6,21,0,STONE)
Block(-6,22,-3,STONE)
Block(-6,22,-2,STONE)
Block(-5,6,4,STONE)
Block(-5,6,5,STONE)
Block(-5,7,3,STONE)
Block(-5,7,4,STONE)
Block(-5,7,5,STONE)
Block(-5,8,2,STONE)
Block(-5,8,3,STONE)
Block(-5,8,4,STONE)
Block(-5,8,5,STONE)
Block(-5,9,1,STONE)
Block(-5,9,2,STONE)
Block(-5,9,3,STONE)
Block(-5,9,4,STONE)
Block(-5,9,5,STONE)
Block(-5,10,0,STONE)
Block(-5,10,1,STONE)
Block(-5,10,2,STONE)
Block(-5,10,3,STONE)
Block(-5,10,4,STONE)
Block(-5,10,5,STONE)
Block(-5,11,-1,STONE)
Block(-5,11,0,STONE)
Block(-5,11,1,STONE)
Block(-5,11,2,STONE)
Block(-5,11,3,STONE)
Block(-5,11,4,STONE)
Block(-5,11,5,STONE)
Block(-5,11,6,STONE)
Block(-5,12,-3,STONE)
Block(-5,12,-2,STONE)
Block(-5,12,-1,STONE)
Block(-5,12,0,STONE)
Block(-5,12,1,STONE)
Block(-5,12,2,STONE)
Block(-5,12,3,STONE)
Block(-5,12,4,STONE)
Block(-5,12,5,STONE)
Block(-5,12,6,STONE)
Block(-5,13,-5,STONE)
Block(-5,13,-4,STONE)
Block(-5,13,-3,STONE)
Block(-5,13,-2,STONE)
Block(-5,13,-1,STONE)
Block(-5,13,0,STONE)
Block(-5,13,1,STONE)
Block(-5,13,2,STONE)
Block(-5,13,3,STONE)
Block(-5,13,4,STONE)
Block(-5,13,5,STONE)
Block(-5,13,6,STONE)
Block(-5,14,-6,STONE)
Block(-5,14,-5,STONE)
Block(-5,14,-4,STONE)
Block(-5,14,-3,STONE)
Block(-5,14,-2,STONE)
Block(-5,14,-1,STONE)
Block(-5,14,0,STONE)
Block(-5,14,1,STONE)
Block(-5,14,2,STONE)
Block(-5,14,3,STONE)
Block(-5,14,4,STONE)
Block(-5,14,5,STONE)
Block(-5,15,-6,STONE)
Block(-5,15,-5,STONE)
Block(-5,15,-4,STONE)
Block(-5,15,-3,STONE)
Block(-5,15,-2,STONE)
Block(-5,15,-1,STONE)
Block(-5,15,0,STONE)
Block(-5,15,1,STONE)
Block(-5,15,2,STONE)
Block(-5,15,3,STONE)
Block(-5,15,4,STONE)
Block(-5,15,5,STONE)
Block(-5,16,-6,STONE)
Block(-5,16,-5,STONE)
Block(-5,16,-4,STONE)
Block(-5,16,-3,STONE)
Block(-5,16,-2,STONE)
Block(-5,16,-1,STONE)
Block(-5,16,0,STONE)
Block(-5,16,1,STONE)
Block(-5,16,2,STONE)
Block(-5,16,3,STONE)
Block(-5,16,4,STONE)
Block(-5,16,5,STONE)
Block(-5,17,-5,STONE)
Block(-5,17,-4,STONE)
Block(-5,17,-3,STONE)
Block(-5,17,-2,STONE)
Block(-5,17,-1,STONE)
Block(-5,17,0,STONE)
Block(-5,17,1,STONE)
Block(-5,17,2,STONE)
Block(-5,17,3,STONE)
Block(-5,17,4,STONE)
Block(-5,17,5,STONE)
Block(-5,18,-5,STONE)
Block(-5,18,-4,STONE)
Block(-5,18,-3,STONE)
Block(-5,18,-2,STONE)
Block(-5,18,-1,STONE)
Block(-5,18,0,STONE)
Block(-5,18,1,STONE)
Block(-5,18,2,STONE)
Block(-5,18,3,STONE)
Block(-5,18,4,STONE)
Block(-5,18,5,STONE)
Block(-5,19,-5,STONE)
Block(-5,19,-4,STONE)
Block(-5,19,-3,STONE)
Block(-5,19,-2,STONE)
Block(-5,19,-1,STONE)
Block(-5,19,0,STONE)
Block(-5,19,1,STONE)
Block(-5,19,2,STONE)
Block(-5,19,3,STONE)
Block(-5,19,4,STONE)
Block(-5,20,-5,STONE)
Block(-5,20,-4,STONE)
Block(-5,20,-3,STONE)
Block(-5,20,-2,STONE)
Block(-5,20,-1,STONE)
Block(-5,20,0,STONE)
Block(-5,20,1,STONE)
Block(-5,20,2,STONE)
Block(-5,20,3,STONE)
Block(-5,20,4,STONE)
Block(-5,21,-5,STONE)
Block(-5,21,-4,STONE)
Block(-5,21,-3,STONE)
Block(-5,21,-2,STONE)
Block(-5,21,-1,STONE)
Block(-5,21,0,STONE)
Block(-5,21,1,STONE)
Block(-5,21,2,STONE)
Block(-5,22,-4,STONE)
Block(-5,22,-3,STONE)
Block(-5,22,-2,STONE)
Block(-5,22,-1,STONE)
Block(-5,23,-4,STONE)
Block(-5,23,-3,STONE)
Block(-4,4,3,STONE)
Block(-4,4,4,STONE)
Block(-4,4,5,STONE)
Block(-4,4,6,STONE)
Block(-4,5,1,STONE)
Block(-4,5,2,STONE)
Block(-4,5,3,STONE)
Block(-4,5,4,STONE)
Block(-4,5,5,STONE)
Block(-4,5,6,STONE)
Block(-4,6,0,STONE)
Block(-4,6,1,STONE)
Block(-4,6,2,STONE)
Block(-4,6,3,STONE)
Block(-4,6,4,STONE)
Block(-4,6,5,STONE)
Block(-4,6,6,STONE)
Block(-4,7,-2,STONE)
Block(-4,7,-1,STONE)
Block(-4,7,0,STONE)
Block(-4,7,1,STONE)
Block(-4,7,2,STONE)
Block(-4,7,3,STONE)
Block(-4,7,4,STONE)
Block(-4,7,5,STONE)
Block(-4,7,6,STONE)
Block(-4,8,-3,STONE)
Block(-4,8,-2,STONE)
Block(-4,8,-1,STONE)
Block(-4,8,0,STONE)
Block(-4,8,1,STONE)
Block(-4,8,2,STONE)
Block(-4,8,3,STONE)
Block(-4,8,4,STONE)
Block(-4,8,5,STONE)
Block(-4,8,6,STONE)
Block(-4,9,-4,STONE)
Block(-4,9,-3,STONE)
Block(-4,9,-2,STONE)
Block(-4,9,-1,STONE)
Block(-4,9,0,STONE)
Block(-4,9,1,STONE)
Block(-4,9,2,STONE)
Block(-4,9,3,STONE)
Block(-4,9,4,STONE)
Block(-4,9,5,STONE)
Block(-4,9,6,STONE)
Block(-4,10,-6,STONE)
Block(-4,10,-5,STONE)
Block(-4,10,-4,STONE)
Block(-4,10,-3,STONE)
Block(-4,10,-2,STONE)
Block(-4,10,-1,STONE)
Block(-4,10,0,STONE)
Block(-4,10,1,STONE)
Block(-4,10,2,STONE)
Block(-4,10,3,STONE)
Block(-4,10,4,STONE)
Block(-4,10,5,STONE)
Block(-4,10,6,STONE)
Block(-4,10,7,STONE)
Block(-4,11,-6,STONE)
Block(-4,11,-5,STONE)
Block(-4,11,-4,STONE)
Block(-4,11,-3,STONE)
Block(-4,11,-2,STONE)
Block(-4,11,-1,STONE)
Block(-4,11,0,STONE)
Block(-4,11,1,STONE)
Block(-4,11,2,STONE)
Block(-4,11,3,STONE)
Block(-4,11,4,STONE)
Block(-4,11,5,STONE)
Block(-4,11,6,STONE)
Block(-4,11,7,STONE)
Block(-4,12,-7,STONE)
Block(-4,12,-6,STONE)
Block(-4,12,-5,STONE)
Block(-4,12,-4,STONE)
Block(-4,12,-3,STONE)
Block(-4,12,-2,STONE)
Block(-4,12,-1,STONE)
Block(-4,12,0,STONE)
Block(-4,12,1,STONE)
Block(-4,12,2,STONE)
Block(-4,12,3,STONE)
Block(-4,12,4,STONE)
Block(-4,12,5,STONE)
Block(-4,12,6,STONE)
Block(-4,12,7,STONE)
Block(-4,13,-7,STONE)
Block(-4,13,-6,STONE)
Block(-4,13,-5,STONE)
Block(-4,13,-4,STONE)
Block(-4,13,-3,STONE)
Block(-4,13,-2,STONE)
Block(-4,13,-1,STONE)
Block(-4,13,0,STONE)
Block(-4,13,1,STONE)
Block(-4,13,2,STONE)
Block(-4,13,3,STONE)
Block(-4,13,4,STONE)
Block(-4,13,5,STONE)
Block(-4,13,6,STONE)
Block(-4,13,7,STONE)
Block(-4,14,-6,STONE)
Block(-4,14,-5,STONE)
Block(-4,14,-4,STONE)
Block(-4,14,-3,STONE)
Block(-4,14,-2,STONE)
Block(-4,14,-1,STONE)
Block(-4,14,0,STONE)
Block(-4,14,1,STONE)
Block(-4,14,2,STONE)
Block(-4,14,3,STONE)
Block(-4,14,4,STONE)
Block(-4,14,5,STONE)
Block(-4,14,6,STONE)
Block(-4,14,7,STONE)
Block(-4,15,-6,STONE)
Block(-4,15,-5,STONE)
Block(-4,15,-4,STONE)
Block(-4,15,-3,STONE)
Block(-4,15,-2,STONE)
Block(-4,15,-1,STONE)
Block(-4,15,0,STONE)
Block(-4,15,1,STONE)
Block(-4,15,2,STONE)
Block(-4,15,3,STONE)
Block(-4,15,4,STONE)
Block(-4,15,5,STONE)
Block(-4,15,6,STONE)
Block(-4,15,7,STONE)
Block(-4,16,-6,STONE)
Block(-4,16,-5,STONE)
Block(-4,16,-4,STONE)
Block(-4,16,-3,STONE)
Block(-4,16,-2,STONE)
Block(-4,16,-1,STONE)
Block(-4,16,0,STONE)
Block(-4,16,1,STONE)
Block(-4,16,2,STONE)
Block(-4,16,3,STONE)
Block(-4,16,4,STONE)
Block(-4,16,5,STONE)
Block(-4,16,6,STONE)
Block(-4,16,7,STONE)
Block(-4,17,-6,STONE)
Block(-4,17,-5,STONE)
Block(-4,17,-4,STONE)
Block(-4,17,-3,STONE)
Block(-4,17,-2,STONE)
Block(-4,17,-1,STONE)
Block(-4,17,0,STONE)
Block(-4,17,1,STONE)
Block(-4,17,2,STONE)
Block(-4,17,3,STONE)
Block(-4,17,4,STONE)
Block(-4,17,5,STONE)
Block(-4,17,6,STONE)
Block(-4,18,-6,STONE)
Block(-4,18,-5,STONE)
Block(-4,18,-4,STONE)
Block(-4,18,-3,STONE)
Block(-4,18,-2,STONE)
Block(-4,18,-1,STONE)
Block(-4,18,0,STONE)
Block(-4,18,1,STONE)
Block(-4,18,2,STONE)
Block(-4,18,3,STONE)
Block(-4,18,4,STONE)
Block(-4,18,5,STONE)
Block(-4,18,6,STONE)
Block(-4,19,-6,STONE)
Block(-4,19,-5,STONE)
Block(-4,19,-4,STONE)
Block(-4,19,-3,STONE)
Block(-4,19,-2,STONE)
Block(-4,19,-1,STONE)
Block(-4,19,0,STONE)
Block(-4,19,1,STONE)
Block(-4,19,2,STONE)
Block(-4,19,3,STONE)
Block(-4,19,4,STONE)
Block(-4,19,5,STONE)
Block(-4,19,6,STONE)
Block(-4,20,-6,STONE)
Block(-4,20,-5,STONE)
Block(-4,20,-4,STONE)
Block(-4,20,-3,STONE)
Block(-4,20,-2,STONE)
Block(-4,20,-1,STONE)
Block(-4,20,0,STONE)
Block(-4,20,1,STONE)
Block(-4,20,2,STONE)
Block(-4,20,3,STONE)
Block(-4,20,4,STONE)
Block(-4,20,5,STONE)
Block(-4,20,6,STONE)
Block(-4,21,-6,STONE)
Block(-4,21,-5,STONE)
Block(-4,21,-4,STONE)
Block(-4,21,-3,STONE)
Block(-4,21,-2,STONE)
Block(-4,21,-1,STONE)
Block(-4,21,0,STONE)
Block(-4,21,1,STONE)
Block(-4,21,2,STONE)
Block(-4,21,3,STONE)
Block(-4,21,4,STONE)
Block(-4,22,-5,STONE)
Block(-4,22,-4,STONE)
Block(-4,22,-3,STONE)
Block(-4,22,-2,STONE)
Block(-4,22,-1,STONE)
Block(-4,22,0,STONE)
Block(-4,22,1,STONE)
Block(-4,23,-5,STONE)
Block(-4,23,-4,STONE)
Block(-4,23,-3,STONE)
Block(-4,23,-2,STONE)
Block(-4,23,-1,STONE)
Block(-4,24,-4,STONE)
Block(-4,24,-3,STONE)
Block(-3,3,0,STONE)
Block(-3,3,1,STONE)
Block(-3,3,2,STONE)
Block(-3,3,3,STONE)
Block(-3,3,4,STONE)
Block(-3,3,5,STONE)
Block(-3,3,6,STONE)
Block(-3,3,7,STONE)
Block(-3,4,-2,STONE)
Block(-3,4,-1,STONE)
Block(-3,4,0,STONE)
Block(-3,4,1,STONE)
Block(-3,4,2,STONE)
Block(-3,4,3,STONE)
Block(-3,4,4,STONE)
Block(-3,4,5,STONE)
Block(-3,4,6,STONE)
Block(-3,4,7,STONE)
Block(-3,5,-3,STONE)
Block(-3,5,-2,STONE)
Block(-3,5,-1,STONE)
Block(-3,5,0,STONE)
Block(-3,5,1,STONE)
Block(-3,5,2,STONE)
Block(-3,5,3,STONE)
Block(-3,5,4,STONE)
Block(-3,5,5,STONE)
Block(-3,5,6,STONE)
Block(-3,5,7,STONE)
Block(-3,6,-5,STONE)
Block(-3,6,-4,STONE)
Block(-3,6,-3,STONE)
Block(-3,6,-2,STONE)
Block(-3,6,-1,STONE)
Block(-3,6,0,STONE)
Block(-3,6,1,STONE)
Block(-3,6,2,STONE)
Block(-3,6,3,STONE)
Block(-3,6,4,STONE)
Block(-3,6,5,STONE)
Block(-3,6,6,STONE)
Block(-3,6,7,STONE)
Block(-3,7,-5,STONE)
Block(-3,7,-4,STONE)
Block(-3,7,-3,STONE)
Block(-3,7,-2,STONE)
Block(-3,7,-1,STONE)
Block(-3,7,0,STONE)
Block(-3,7,1,STONE)
Block(-3,7,2,STONE)
Block(-3,7,3,STONE)
Block(-3,7,4,STONE)
Block(-3,7,5,STONE)
Block(-3,7,6,STONE)
Block(-3,7,7,STONE)
Block(-3,8,-6,STONE)
Block(-3,8,-5,STONE)
Block(-3,8,-4,STONE)
Block(-3,8,-3,STONE)
Block(-3,8,-2,STONE)
Block(-3,8,-1,STONE)
Block(-3,8,0,STONE)
Block(-3,8,1,STONE)
Block(-3,8,2,STONE)
Block(-3,8,3,STONE)
Block(-3,8,4,STONE)
Block(-3,8,5,STONE)
Block(-3,8,6,STONE)
Block(-3,8,7,STONE)
Block(-3,9,-6,STONE)
Block(-3,9,-5,STONE)
Block(-3,9,-4,STONE)
Block(-3,9,-3,STONE)
Block(-3,9,-2,STONE)
Block(-3,9,-1,STONE)
Block(-3,9,0,STONE)
Block(-3,9,1,STONE)
Block(-3,9,2,STONE)
Block(-3,9,3,STONE)
Block(-3,9,4,STONE)
Block(-3,9,5,STONE)
Block(-3,9,6,STONE)
Block(-3,9,7,STONE)
Block(-3,9,8,STONE)
Block(-3,10,-7,STONE)
Block(-3,10,-6,STONE)
Block(-3,10,-5,STONE)
Block(-3,10,-4,STONE)
Block(-3,10,-3,STONE)
Block(-3,10,-2,STONE)
Block(-3,10,-1,STONE)
Block(-3,10,0,STONE)
Block(-3,10,1,STONE)
Block(-3,10,2,STONE)
Block(-3,10,3,STONE)
Block(-3,10,4,STONE)
Block(-3,10,5,STONE)
Block(-3,10,6,STONE)
Block(-3,10,7,STONE)
Block(-3,10,8,STONE)
Block(-3,11,-7,STONE)
Block(-3,11,-6,STONE)
Block(-3,11,-5,STONE)
Block(-3,11,-4,STONE)
Block(-3,11,-3,STONE)
Block(-3,11,-2,STONE)
Block(-3,11,-1,STONE)
Block(-3,11,0,STONE)
Block(-3,11,1,STONE)
Block(-3,11,2,STONE)
Block(-3,11,3,STONE)
Block(-3,11,4,STONE)
Block(-3,11,5,STONE)
Block(-3,11,6,STONE)
Block(-3,11,7,STONE)
Block(-3,11,8,STONE)
Block(-3,12,-7,STONE)
Block(-3,12,-6,STONE)
Block(-3,12,-5,STONE)
Block(-3,12,-4,STONE)
Block(-3,12,-3,STONE)
Block(-3,12,-2,STONE)
Block(-3,12,-1,STONE)
Block(-3,12,0,STONE)
Block(-3,12,1,STONE)
Block(-3,12,2,STONE)
Block(-3,12,3,STONE)
Block(-3,12,4,STONE)
Block(-3,12,5,STONE)
Block(-3,12,6,STONE)
Block(-3,12,7,STONE)
Block(-3,12,8,STONE)
Block(-3,13,-7,STONE)
Block(-3,13,-6,STONE)
Block(-3,13,-5,STONE)
Block(-3,13,-4,STONE)
Block(-3,13,-3,STONE)
Block(-3,13,-2,STONE)
Block(-3,13,-1,STONE)
Block(-3,13,0,STONE)
Block(-3,13,1,STONE)
Block(-3,13,2,STONE)
Block(-3,13,3,STONE)
Block(-3,13,4,STONE)
Block(-3,13,5,STONE)
Block(-3,13,6,STONE)
Block(-3,13,7,STONE)
Block(-3,13,8,STONE)
Block(-3,14,-7,STONE)
Block(-3,14,-6,STONE)
Block(-3,14,-5,STONE)
Block(-3,14,-4,STONE)
Block(-3,14,-3,STONE)
Block(-3,14,-2,STONE)
Block(-3,14,-1,STONE)
Block(-3,14,0,STONE)
Block(-3,14,1,STONE)
Block(-3,14,2,STONE)
Block(-3,14,3,STONE)
Block(-3,14,4,STONE)
Block(-3,14,5,STONE)
Block(-3,14,6,STONE)
Block(-3,14,7,STONE)
Block(-3,14,8,STONE)
Block(-3,15,-7,STONE)
Block(-3,15,-6,STONE)
Block(-3,15,-5,STONE)
Block(-3,15,-4,STONE)
Block(-3,15,-3,STONE)
Block(-3,15,-2,STONE)
Block(-3,15,-1,STONE)
Block(-3,15,0,STONE)
Block(-3,15,1,STONE)
Block(-3,15,2,STONE)
Block(-3,15,3,STONE)
Block(-3,15,4,STONE)
Block(-3,15,5,STONE)
Block(-3,15,6,STONE)
Block(-3,15,7,STONE)
Block(-3,15,8,STONE)
Block(-3,16,-7,STONE)
Block(-3,16,-6,STONE)
Block(-3,16,-5,STONE)
Block(-3,16,-4,STONE)
Block(-3,16,-3,STONE)
Block(-3,16,-2,STONE)
Block(-3,16,-1,STONE)
Block(-3,16,0,STONE)
Block(-3,16,1,STONE)
Block(-3,16,2,STONE)
Block(-3,16,3,STONE)
Block(-3,16,4,STONE)
Block(-3,16,5,STONE)
Block(-3,16,6,STONE)
Block(-3,16,7,STONE)
Block(-3,16,8,STONE)
Block(-3,17,-7,STONE)
Block(-3,17,-6,STONE)
Block(-3,17,-5,STONE)
Block(-3,17,-4,STONE)
Block(-3,17,-3,STONE)
Block(-3,17,-2,STONE)
Block(-3,17,-1,STONE)
Block(-3,17,0,STONE)
Block(-3,17,1,STONE)
Block(-3,17,2,STONE)
Block(-3,17,3,STONE)
Block(-3,17,4,STONE)
Block(-3,17,5,STONE)
Block(-3,17,6,STONE)
Block(-3,17,7,STONE)
Block(-3,17,8,STONE)
Block(-3,18,-7,STONE)
Block(-3,18,-6,STONE)
Block(-3,18,-5,STONE)
Block(-3,18,-4,STONE)
Block(-3,18,-3,STONE)
Block(-3,18,-2,STONE)
Block(-3,18,-1,STONE)
Block(-3,18,0,STONE)
Block(-3,18,1,STONE)
Block(-3,18,2,STONE)
Block(-3,18,3,STONE)
Block(-3,18,4,STONE)
Block(-3,18,5,STONE)
Block(-3,18,6,STONE)
Block(-3,18,7,STONE)
Block(-3,19,-7,STONE)
Block(-3,19,-6,STONE)
Block(-3,19,-5,STONE)
Block(-3,19,-4,STONE)
Block(-3,19,-3,STONE)
Block(-3,19,-2,STONE)
Block(-3,19,-1,STONE)
Block(-3,19,0,STONE)
Block(-3,19,1,STONE)
Block(-3,19,2,STONE)
Block(-3,19,3,STONE)
Block(-3,19,4,STONE)
Block(-3,19,5,STONE)
Block(-3,19,6,STONE)
Block(-3,19,7,STONE)
Block(-3,20,-7,STONE)
Block(-3,20,-6,STONE)
Block(-3,20,-5,STONE)
Block(-3,20,-4,STONE)
Block(-3,20,-3,STONE)
Block(-3,20,-2,STONE)
Block(-3,20,-1,STONE)
Block(-3,20,0,STONE)
Block(-3,20,1,STONE)
Block(-3,20,2,STONE)
Block(-3,20,3,STONE)
Block(-3,20,4,STONE)
Block(-3,20,5,STONE)
Block(-3,20,6,STONE)
Block(-3,20,7,STONE)
Block(-3,21,-7,STONE)
Block(-3,21,-6,STONE)
Block(-3,21,-5,STONE)
Block(-3,21,-4,STONE)
Block(-3,21,-3,STONE)
Block(-3,21,-2,STONE)
Block(-3,21,-1,STONE)
Block(-3,21,0,STONE)
Block(-3,21,1,STONE)
Block(-3,21,2,STONE)
Block(-3,21,3,STONE)
Block(-3,21,4,STONE)
Block(-3,21,5,STONE)
Block(-3,22,-6,STONE)
Block(-3,22,-5,STONE)
Block(-3,22,-4,STONE)
Block(-3,22,-3,STONE)
Block(-3,22,-2,STONE)
Block(-3,22,-1,STONE)
Block(-3,22,0,STONE)
Block(-3,22,1,STONE)
Block(-3,22,2,STONE)
Block(-3,23,-6,STONE)
Block(-3,23,-5,STONE)
Block(-3,23,-4,STONE)
Block(-3,23,-3,STONE)
Block(-3,23,-2,STONE)
Block(-3,23,-1,STONE)
Block(-3,23,0,STONE)
Block(-3,23,1,STONE)
Block(-3,24,-5,STONE)
Block(-3,24,-4,STONE)
Block(-3,24,-3,STONE)
Block(-3,24,-2,STONE)
Block(-3,24,-1,STONE)
Block(-3,25,-4,STONE)
Block(-2,2,-2,STONE)
Block(-2,2,-1,STONE)
Block(-2,2,0,STONE)
Block(-2,2,1,STONE)
Block(-2,2,2,STONE)
Block(-2,2,3,STONE)
Block(-2,2,4,STONE)
Block(-2,2,5,STONE)
Block(-2,2,6,STONE)
Block(-2,2,7,STONE)
Block(-2,3,-4,STONE)
Block(-2,3,-3,STONE)
Block(-2,3,-2,STONE)
Block(-2,3,-1,STONE)
Block(-2,3,0,STONE)
Block(-2,3,1,STONE)
Block(-2,3,2,STONE)
Block(-2,3,3,STONE)
Block(-2,3,4,STONE)
Block(-2,3,5,STONE)
Block(-2,3,6,STONE)
Block(-2,3,7,STONE)
Block(-2,3,8,STONE)
Block(-2,4,-5,STONE)
Block(-2,4,-4,STONE)
Block(-2,4,-3,STONE)
Block(-2,4,-2,STONE)
Block(-2,4,-1,STONE)
Block(-2,4,0,STONE)
Block(-2,4,1,STONE)
Block(-2,4,2,STONE)
Block(-2,4,3,STONE)
Block(-2,4,4,STONE)
Block(-2,4,5,STONE)
Block(-2,4,6,STONE)
Block(-2,4,7,STONE)
Block(-2,4,8,STONE)
Block(-2,5,-5,STONE)
Block(-2,5,-4,STONE)
Block(-2,5,-3,STONE)
Block(-2,5,-2,STONE)
Block(-2,5,-1,STONE)
Block(-2,5,0,STONE)
Block(-2,5,1,STONE)
Block(-2,5,2,STONE)
Block(-2,5,3,STONE)
Block(-2,5,4,STONE)
Block(-2,5,5,STONE)
Block(-2,5,6,STONE)
Block(-2,5,7,STONE)
Block(-2,5,8,STONE)
Block(-2,6,-6,STONE)
Block(-2,6,-5,STONE)
Block(-2,6,-4,STONE)
Block(-2,6,-3,STONE)
Block(-2,6,-2,STONE)
Block(-2,6,-1,STONE)
Block(-2,6,0,STONE)
Block(-2,6,1,STONE)
Block(-2,6,2,STONE)
Block(-2,6,3,STONE)
Block(-2,6,4,STONE)
Block(-2,6,5,STONE)
Block(-2,6,6,STONE)
Block(-2,6,7,STONE)
Block(-2,6,8,STONE)
Block(-2,7,-6,STONE)
Block(-2,7,-5,STONE)
Block(-2,7,-4,STONE)
Block(-2,7,-3,STONE)
Block(-2,7,-2,STONE)
Block(-2,7,-1,STONE)
Block(-2,7,0,STONE)
Block(-2,7,1,STONE)
Block(-2,7,2,STONE)
Block(-2,7,3,STONE)
Block(-2,7,4,STONE)
Block(-2,7,5,STONE)
Block(-2,7,6,STONE)
Block(-2,7,7,STONE)
Block(-2,7,8,STONE)
Block(-2,8,-7,STONE)
Block(-2,8,-6,STONE)
Block(-2,8,-5,STONE)
Block(-2,8,-4,STONE)
Block(-2,8,-3,STONE)
Block(-2,8,-2,STONE)
Block(-2,8,-1,STONE)
Block(-2,8,0,STONE)
Block(-2,8,1,STONE)
Block(-2,8,2,STONE)
Block(-2,8,3,STONE)
Block(-2,8,4,STONE)
Block(-2,8,5,STONE)
Block(-2,8,6,STONE)
Block(-2,8,7,STONE)
Block(-2,8,8,STONE)
Block(-2,9,-7,STONE)
Block(-2,9,-6,STONE)
Block(-2,9,-5,STONE)
Block(-2,9,-4,STONE)
Block(-2,9,-3,STONE)
Block(-2,9,-2,STONE)
Block(-2,9,-1,STONE)
Block(-2,9,0,STONE)
Block(-2,9,1,STONE)
Block(-2,9,2,STONE)
Block(-2,9,3,STONE)
Block(-2,9,4,STONE)
Block(-2,9,5,STONE)
Block(-2,9,6,STONE)
Block(-2,9,7,STONE)
Block(-2,9,8,STONE)
Block(-2,9,9,STONE)
Block(-2,10,-7,STONE)
Block(-2,10,-6,STONE)
Block(-2,10,-5,STONE)
Block(-2,10,-4,STONE)
Block(-2,10,-3,STONE)
Block(-2,10,-2,STONE)
Block(-2,10,-1,STONE)
Block(-2,10,0,STONE)
Block(-2,10,1,STONE)
Block(-2,10,2,STONE)
Block(-2,10,3,STONE)
Block(-2,10,4,STONE)
Block(-2,10,5,STONE)
Block(-2,10,6,STONE)
Block(-2,10,7,STONE)
Block(-2,10,8,STONE)
Block(-2,10,9,STONE)
Block(-2,11,-7,STONE)
Block(-2,11,-6,STONE)
Block(-2,11,-5,STONE)
Block(-2,11,-4,STONE)
Block(-2,11,-3,STONE)
Block(-2,11,-2,STONE)
Block(-2,11,-1,STONE)
Block(-2,11,0,STONE)
Block(-2,11,1,STONE)
Block(-2,11,2,STONE)
Block(-2,11,3,STONE)
Block(-2,11,4,STONE)
Block(-2,11,5,STONE)
Block(-2,11,6,STONE)
Block(-2,11,7,STONE)
Block(-2,11,8,STONE)
Block(-2,11,9,STONE)
Block(-2,12,-8,STONE)
Block(-2,12,-7,STONE)
Block(-2,12,-6,STONE)
Block(-2,12,-5,STONE)
Block(-2,12,-4,STONE)
Block(-2,12,-3,STONE)
Block(-2,12,-2,STONE)
Block(-2,12,-1,STONE)
Block(-2,12,0,STONE)
Block(-2,12,1,STONE)
Block(-2,12,2,STONE)
Block(-2,12,3,STONE)
Block(-2,12,4,STONE)
Block(-2,12,5,STONE)
Block(-2,12,6,STONE)
Block(-2,12,7,STONE)
Block(-2,12,8,STONE)
Block(-2,12,9,STONE)
Block(-2,12,10,STONE)
Block(-2,13,-8,STONE)
Block(-2,13,-7,STONE)
Block(-2,13,-6,STONE)
Block(-2,13,-5,STONE)
Block(-2,13,-4,STONE)
Block(-2,13,-3,STONE)
Block(-2,13,-2,STONE)
Block(-2,13,-1,STONE)
Block(-2,13,0,STONE)
Block(-2,13,1,STONE)
Block(-2,13,2,STONE)
Block(-2,13,3,STONE)
Block(-2,13,4,STONE)
Block(-2,13,5,STONE)
Block(-2,13,6,STONE)
Block(-2,13,7,STONE)
Block(-2,13,8,STONE)
Block(-2,13,9,STONE)
Block(-2,13,10,STONE)
Block(-2,14,-8,STONE)
Block(-2,14,-7,STONE)
Block(-2,14,-6,STONE)
Block(-2,14,-5,STONE)
Block(-2,14,-4,STONE)
Block(-2,14,-3,STONE)
Block(-2,14,-2,STONE)
Block(-2,14,-1,STONE)
Block(-2,14,0,STONE)
Block(-2,14,1,STONE)
Block(-2,14,2,STONE)
Block(-2,14,3,STONE)
Block(-2,14,4,STONE)
Block(-2,14,5,STONE)
Block(-2,14,6,STONE)
Block(-2,14,7,STONE)
Block(-2,14,8,STONE)
Block(-2,14,9,STONE)
Block(-2,14,10,STONE)
Block(-2,15,-8,STONE)
Block(-2,15,-7,STONE)
Block(-2,15,-6,STONE)
Block(-2,15,-5,STONE)
Block(-2,15,-4,STONE)
Block(-2,15,-3,STONE)
Block(-2,15,-2,STONE)
Block(-2,15,-1,STONE)
Block(-2,15,0,STONE)
Block(-2,15,1,STONE)
Block(-2,15,2,STONE)
Block(-2,15,3,STONE)
Block(-2,15,4,STONE)
Block(-2,15,5,STONE)
Block(-2,15,6,STONE)
Block(-2,15,7,STONE)
Block(-2,15,8,STONE)
Block(-2,15,9,STONE)
Block(-2,16,-8,STONE)
Block(-2,16,-7,STONE)
Block(-2,16,-6,STONE)
Block(-2,16,-5,STONE)
Block(-2,16,-4,STONE)
Block(-2,16,-3,STONE)
Block(-2,16,-2,STONE)
Block(-2,16,-1,STONE)
Block(-2,16,0,STONE)
Block(-2,16,1,STONE)
Block(-2,16,2,STONE)
Block(-2,16,3,STONE)
Block(-2,16,4,STONE)
Block(-2,16,5,STONE)
Block(-2,16,6,STONE)
Block(-2,16,7,STONE)
Block(-2,16,8,STONE)
Block(-2,16,9,STONE)
Block(-2,17,-8,STONE)
Block(-2,17,-7,STONE)
Block(-2,17,-6,STONE)
Block(-2,17,-5,STONE)
Block(-2,17,-4,STONE)
Block(-2,17,-3,STONE)
Block(-2,17,-2,STONE)
Block(-2,17,-1,STONE)
Block(-2,17,0,STONE)
Block(-2,17,1,STONE)
Block(-2,17,2,STONE)
Block(-2,17,3,STONE)
Block(-2,17,4,STONE)
Block(-2,17,5,STONE)
Block(-2,17,6,STONE)
Block(-2,17,7,STONE)
Block(-2,17,8,STONE)
Block(-2,17,9,STONE)
Block(-2,18,-8,STONE)
Block(-2,18,-7,STONE)
Block(-2,18,-6,STONE)
Block(-2,18,-5,STONE)
Block(-2,18,-4,STONE)
Block(-2,18,-3,STONE)
Block(-2,18,-2,STONE)
Block(-2,18,-1,STONE)
Block(-2,18,0,STONE)
Block(-2,18,1,STONE)
Block(-2,18,2,STONE)
Block(-2,18,3,STONE)
Block(-2,18,4,STONE)
Block(-2,18,5,STONE)
Block(-2,18,6,STONE)
Block(-2,18,7,STONE)
Block(-2,18,8,STONE)
Block(-2,18,9,STONE)
Block(-2,19,-8,STONE)
Block(-2,19,-7,STONE)
Block(-2,19,-6,STONE)
Block(-2,19,-5,STONE)
Block(-2,19,-4,STONE)
Block(-2,19,-3,STONE)
Block(-2,19,-2,STONE)
Block(-2,19,-1,STONE)
Block(-2,19,0,STONE)
Block(-2,19,1,STONE)
Block(-2,19,2,STONE)
Block(-2,19,3,STONE)
Block(-2,19,4,STONE)
Block(-2,19,5,STONE)
Block(-2,19,6,STONE)
Block(-2,19,7,STONE)
Block(-2,19,8,STONE)
Block(-2,20,-7,STONE)
Block(-2,20,-6,STONE)
Block(-2,20,-5,STONE)
Block(-2,20,-4,STONE)
Block(-2,20,-3,STONE)
Block(-2,20,-2,STONE)
Block(-2,20,-1,STONE)
Block(-2,20,0,STONE)
Block(-2,20,1,STONE)
Block(-2,20,2,STONE)
Block(-2,20,3,STONE)
Block(-2,20,4,STONE)
Block(-2,20,5,STONE)
Block(-2,20,6,STONE)
Block(-2,20,7,STONE)
Block(-2,20,8,STONE)
Block(-2,21,-7,STONE)
Block(-2,21,-6,STONE)
Block(-2,21,-5,STONE)
Block(-2,21,-4,STONE)
Block(-2,21,-3,STONE)
Block(-2,21,-2,STONE)
Block(-2,21,-1,STONE)
Block(-2,21,0,STONE)
Block(-2,21,1,STONE)
Block(-2,21,2,STONE)
Block(-2,21,3,STONE)
Block(-2,21,4,STONE)
Block(-2,21,5,STONE)
Block(-2,21,6,STONE)
Block(-2,21,7,STONE)
Block(-2,21,8,STONE)
Block(-2,22,-7,STONE)
Block(-2,22,-6,STONE)
Block(-2,22,-5,STONE)
Block(-2,22,-4,STONE)
Block(-2,22,-3,STONE)
Block(-2,22,-2,STONE)
Block(-2,22,-1,STONE)
Block(-2,22,0,STONE)
Block(-2,22,1,STONE)
Block(-2,22,2,STONE)
Block(-2,22,3,STONE)
Block(-2,22,4,STONE)
Block(-2,22,5,STONE)
Block(-2,23,-7,STONE)
Block(-2,23,-6,STONE)
Block(-2,23,-5,STONE)
Block(-2,23,-4,STONE)
Block(-2,23,-3,STONE)
Block(-2,23,-2,STONE)
Block(-2,23,-1,STONE)
Block(-2,23,0,STONE)
Block(-2,23,1,STONE)
Block(-2,23,2,STONE)
Block(-2,24,-6,STONE)
Block(-2,24,-5,STONE)
Block(-2,24,-4,STONE)
Block(-2,24,-3,STONE)
Block(-2,24,-2,STONE)
Block(-2,24,-1,STONE)
Block(-2,24,0,STONE)
Block(-2,25,-6,STONE)
Block(-2,25,-5,STONE)
Block(-2,25,-4,STONE)
Block(-2,25,-3,STONE)
Block(-2,25,-2,STONE)
Block(-2,26,-4,STONE)
Block(-1,1,0,STONE)
Block(-1,1,1,STONE)
Block(-1,1,2,STONE)
Block(-1,1,3,STONE)
Block(-1,1,4,STONE)
Block(-1,1,5,STONE)
Block(-1,1,6,STONE)
Block(-1,1,7,STONE)
Block(-1,1,8,STONE)
Block(-1,2,-3,STONE)
Block(-1,2,-2,STONE)
Block(-1,2,-1,STONE)
Block(-1,2,0,STONE)
Block(-1,2,1,STONE)
Block(-1,2,2,STONE)
Block(-1,2,3,STONE)
Block(-1,2,4,STONE)
Block(-1,2,5,STONE)
Block(-1,2,6,STONE)
Block(-1,2,7,STONE)
Block(-1,2,8,STONE)
Block(-1,3,-4,STONE)
Block(-1,3,-3,STONE)
Block(-1,3,-2,STONE)
Block(-1,3,-1,STONE)
Block(-1,3,0,STONE)
Block(-1,3,1,STONE)
Block(-1,3,2,STONE)
Block(-1,3,3,STONE)
Block(-1,3,4,STONE)
Block(-1,3,5,STONE)
Block(-1,3,6,STONE)
Block(-1,3,7,STONE)
Block(-1,3,8,STONE)
Block(-1,3,9,STONE)
Block(-1,4,-5,STONE)
Block(-1,4,-4,STONE)
Block(-1,4,-3,STONE)
Block(-1,4,-2,STONE)
Block(-1,4,-1,STONE)
Block(-1,4,0,STONE)
Block(-1,4,1,STONE)
Block(-1,4,2,STONE)
Block(-1,4,3,STONE)
Block(-1,4,4,STONE)
Block(-1,4,5,STONE)
Block(-1,4,6,STONE)
Block(-1,4,7,STONE)
Block(-1,4,8,STONE)
Block(-1,4,9,STONE)
Block(-1,5,-6,STONE)
Block(-1,5,-5,STONE)
Block(-1,5,-4,STONE)
Block(-1,5,-3,STONE)
Block(-1,5,-2,STONE)
Block(-1,5,-1,STONE)
Block(-1,5,0,STONE)
Block(-1,5,1,STONE)
Block(-1,5,2,STONE)
Block(-1,5,3,STONE)
Block(-1,5,4,STONE)
Block(-1,5,5,STONE)
Block(-1,5,6,STONE)
Block(-1,5,7,STONE)
Block(-1,5,8,STONE)
Block(-1,5,9,STONE)
Block(-1,6,-6,STONE)
Block(-1,6,-5,STONE)
Block(-1,6,-4,STONE)
Block(-1,6,-3,STONE)
Block(-1,6,-2,STONE)
Block(-1,6,-1,STONE)
Block(-1,6,0,STONE)
Block(-1,6,1,STONE)
Block(-1,6,2,STONE)
Block(-1,6,3,STONE)
Block(-1,6,4,STONE)
Block(-1,6,5,STONE)
Block(-1,6,6,STONE)
Block(-1,6,7,STONE)
Block(-1,6,8,STONE)
Block(-1,6,9,STONE)
Block(-1,7,-7,STONE)
Block(-1,7,-6,STONE)
Block(-1,7,-5,STONE)
Block(-1,7,-4,STONE)
Block(-1,7,-3,STONE)
Block(-1,7,-2,STONE)
Block(-1,7,-1,STONE)
Block(-1,7,0,STONE)
Block(-1,7,1,STONE)
Block(-1,7,2,STONE)
Block(-1,7,3,STONE)
Block(-1,7,4,STONE)
Block(-1,7,5,STONE)
Block(-1,7,6,STONE)
Block(-1,7,7,STONE)
Block(-1,7,8,STONE)
Block(-1,7,9,STONE)
Block(-1,8,-7,STONE)
Block(-1,8,-6,STONE)
Block(-1,8,-5,STONE)
Block(-1,8,-4,STONE)
Block(-1,8,-3,STONE)
Block(-1,8,-2,STONE)
Block(-1,8,-1,STONE)
Block(-1,8,0,STONE)
Block(-1,8,1,STONE)
Block(-1,8,2,STONE)
Block(-1,8,3,STONE)
Block(-1,8,4,STONE)
Block(-1,8,5,STONE)
Block(-1,8,6,STONE)
Block(-1,8,7,STONE)
Block(-1,8,8,STONE)
Block(-1,8,9,STONE)
Block(-1,8,10,STONE)
Block(-1,9,-7,STONE)
Block(-1,9,-6,STONE)
Block(-1,9,-5,STONE)
Block(-1,9,-4,STONE)
Block(-1,9,-3,STONE)
Block(-1,9,-2,STONE)
Block(-1,9,-1,STONE)
Block(-1,9,0,STONE)
Block(-1,9,1,STONE)
Block(-1,9,2,STONE)
Block(-1,9,3,STONE)
Block(-1,9,4,STONE)
Block(-1,9,5,STONE)
Block(-1,9,6,STONE)
Block(-1,9,7,STONE)
Block(-1,9,8,STONE)
Block(-1,9,9,STONE)
Block(-1,9,10,STONE)
Block(-1,10,-8,STONE)
Block(-1,10,-7,STONE)
Block(-1,10,-6,STONE)
Block(-1,10,-5,STONE)
Block(-1,10,-4,STONE)
Block(-1,10,-3,STONE)
Block(-1,10,-2,STONE)
Block(-1,10,-1,STONE)
Block(-1,10,0,STONE)
Block(-1,10,1,STONE)
Block(-1,10,2,STONE)
Block(-1,10,3,STONE)
Block(-1,10,4,STONE)
Block(-1,10,5,STONE)
Block(-1,10,6,STONE)
Block(-1,10,7,STONE)
Block(-1,10,8,STONE)
Block(-1,10,9,STONE)
Block(-1,10,10,STONE)
Block(-1,11,-8,STONE)
Block(-1,11,-7,STONE)
Block(-1,11,-6,STONE)
Block(-1,11,-5,STONE)
Block(-1,11,-4,STONE)
Block(-1,11,-3,STONE)
Block(-1,11,-2,STONE)
Block(-1,11,-1,STONE)
Block(-1,11,0,STONE)
Block(-1,11,1,STONE)
Block(-1,11,2,STONE)
Block(-1,11,3,STONE)
Block(-1,11,4,STONE)
Block(-1,11,5,STONE)
Block(-1,11,6,STONE)
Block(-1,11,7,STONE)
Block(-1,11,8,STONE)
Block(-1,11,9,STONE)
Block(-1,11,10,STONE)
Block(-1,12,-8,STONE)
Block(-1,12,-7,STONE)
Block(-1,12,-6,STONE)
Block(-1,12,-5,STONE)
Block(-1,12,-4,STONE)
Block(-1,12,-3,STONE)
Block(-1,12,-2,STONE)
Block(-1,12,-1,STONE)
Block(-1,12,0,STONE)
Block(-1,12,1,STONE)
Block(-1,12,2,STONE)
Block(-1,12,3,STONE)
Block(-1,12,4,STONE)
Block(-1,12,5,STONE)
Block(-1,12,6,STONE)
Block(-1,12,7,STONE)
Block(-1,12,8,STONE)
Block(-1,12,9,STONE)
Block(-1,12,10,STONE)
Block(-1,13,-9,STONE)
Block(-1,13,-8,STONE)
Block(-1,13,-7,STONE)
Block(-1,13,-6,STONE)
Block(-1,13,-5,STONE)
Block(-1,13,-4,STONE)
Block(-1,13,-3,STONE)
Block(-1,13,-2,STONE)
Block(-1,13,-1,STONE)
Block(-1,13,0,STONE)
Block(-1,13,1,STONE)
Block(-1,13,2,STONE)
Block(-1,13,3,STONE)
Block(-1,13,4,STONE)
Block(-1,13,5,STONE)
Block(-1,13,6,STONE)
Block(-1,13,7,STONE)
Block(-1,13,8,STONE)
Block(-1,13,9,STONE)
Block(-1,13,10,STONE)
Block(-1,14,-8,STONE)
Block(-1,14,-7,STONE)
Block(-1,14,-6,STONE)
Block(-1,14,-5,STONE)
Block(-1,14,-4,STONE)
Block(-1,14,-3,STONE)
Block(-1,14,-2,STONE)
Block(-1,14,-1,STONE)
Block(-1,14,0,STONE)
Block(-1,14,1,STONE)
Block(-1,14,2,STONE)
Block(-1,14,3,STONE)
Block(-1,14,4,STONE)
Block(-1,14,5,STONE)
Block(-1,14,6,STONE)
Block(-1,14,7,STONE)
Block(-1,14,8,STONE)
Block(-1,14,9,STONE)
Block(-1,14,10,STONE)
Block(-1,15,-8,STONE)
Block(-1,15,-7,STONE)
Block(-1,15,-6,STONE)
Block(-1,15,-5,STONE)
Block(-1,15,-4,STONE)
Block(-1,15,-3,STONE)
Block(-1,15,-2,STONE)
Block(-1,15,-1,STONE)
Block(-1,15,0,STONE)
Block(-1,15,1,STONE)
Block(-1,15,2,STONE)
Block(-1,15,3,STONE)
Block(-1,15,4,STONE)
Block(-1,15,5,STONE)
Block(-1,15,6,STONE)
Block(-1,15,7,STONE)
Block(-1,15,8,STONE)
Block(-1,15,9,STONE)
Block(-1,15,10,STONE)
Block(-1,16,-8,STONE)
Block(-1,16,-7,STONE)
Block(-1,16,-6,STONE)
Block(-1,16,-5,STONE)
Block(-1,16,-4,STONE)
Block(-1,16,-3,STONE)
Block(-1,16,-2,STONE)
Block(-1,16,-1,STONE)
Block(-1,16,0,STONE)
Block(-1,16,1,STONE)
Block(-1,16,2,STONE)
Block(-1,16,3,STONE)
Block(-1,16,4,STONE)
Block(-1,16,5,STONE)
Block(-1,16,6,STONE)
Block(-1,16,7,STONE)
Block(-1,16,8,STONE)
Block(-1,16,9,STONE)
Block(-1,16,10,STONE)
Block(-1,17,-8,STONE)
Block(-1,17,-7,STONE)
Block(-1,17,-6,STONE)
Block(-1,17,-5,STONE)
Block(-1,17,-4,STONE)
Block(-1,17,-3,STONE)
Block(-1,17,-2,STONE)
Block(-1,17,-1,STONE)
Block(-1,17,0,STONE)
Block(-1,17,1,STONE)
Block(-1,17,2,STONE)
Block(-1,17,3,STONE)
Block(-1,17,4,STONE)
Block(-1,17,5,STONE)
Block(-1,17,6,STONE)
Block(-1,17,7,STONE)
Block(-1,17,8,STONE)
Block(-1,17,9,STONE)
Block(-1,17,10,STONE)
Block(-1,18,-8,STONE)
Block(-1,18,-7,STONE)
Block(-1,18,-6,STONE)
Block(-1,18,-5,STONE)
Block(-1,18,-4,STONE)
Block(-1,18,-3,STONE)
Block(-1,18,-2,STONE)
Block(-1,18,-1,STONE)
Block(-1,18,0,STONE)
Block(-1,18,1,STONE)
Block(-1,18,2,STONE)
Block(-1,18,3,STONE)
Block(-1,18,4,STONE)
Block(-1,18,5,STONE)
Block(-1,18,6,STONE)
Block(-1,18,7,STONE)
Block(-1,18,8,STONE)
Block(-1,18,9,STONE)
Block(-1,18,10,STONE)
Block(-1,19,-8,STONE)
Block(-1,19,-7,STONE)
Block(-1,19,-6,STONE)
Block(-1,19,-5,STONE)
Block(-1,19,-4,STONE)
Block(-1,19,-3,STONE)
Block(-1,19,-2,STONE)
Block(-1,19,-1,STONE)
Block(-1,19,0,STONE)
Block(-1,19,1,STONE)
Block(-1,19,2,STONE)
Block(-1,19,3,STONE)
Block(-1,19,4,STONE)
Block(-1,19,5,STONE)
Block(-1,19,6,STONE)
Block(-1,19,7,STONE)
Block(-1,19,8,STONE)
Block(-1,19,9,STONE)
Block(-1,20,-8,STONE)
Block(-1,20,-7,STONE)
Block(-1,20,-6,STONE)
Block(-1,20,-5,STONE)
Block(-1,20,-4,STONE)
Block(-1,20,-3,STONE)
Block(-1,20,-2,STONE)
Block(-1,20,-1,STONE)
Block(-1,20,0,STONE)
Block(-1,20,1,STONE)
Block(-1,20,2,STONE)
Block(-1,20,3,STONE)
Block(-1,20,4,STONE)
Block(-1,20,5,STONE)
Block(-1,20,6,STONE)
Block(-1,20,7,STONE)
Block(-1,20,8,STONE)
Block(-1,20,9,STONE)
Block(-1,21,-8,STONE)
Block(-1,21,-7,STONE)
Block(-1,21,-6,STONE)
Block(-1,21,-5,STONE)
Block(-1,21,-4,STONE)
Block(-1,21,-3,STONE)
Block(-1,21,-2,STONE)
Block(-1,21,-1,STONE)
Block(-1,21,0,STONE)
Block(-1,21,1,STONE)
Block(-1,21,2,STONE)
Block(-1,21,3,STONE)
Block(-1,21,4,STONE)
Block(-1,21,5,STONE)
Block(-1,21,6,STONE)
Block(-1,21,7,STONE)
Block(-1,21,8,STONE)
Block(-1,21,9,STONE)
Block(-1,22,-8,STONE)
Block(-1,22,-7,STONE)
Block(-1,22,-6,STONE)
Block(-1,22,-5,STONE)
Block(-1,22,-4,STONE)
Block(-1,22,-3,STONE)
Block(-1,22,-2,STONE)
Block(-1,22,-1,STONE)
Block(-1,22,0,STONE)
Block(-1,22,1,STONE)
Block(-1,22,2,STONE)
Block(-1,22,3,STONE)
Block(-1,22,4,STONE)
Block(-1,22,5,STONE)
Block(-1,22,6,STONE)
Block(-1,22,7,STONE)
Block(-1,22,8,STONE)
Block(-1,22,9,STONE)
Block(-1,23,-7,STONE)
Block(-1,23,-6,STONE)
Block(-1,23,-5,STONE)
Block(-1,23,-4,STONE)
Block(-1,23,-3,STONE)
Block(-1,23,-2,STONE)
Block(-1,23,-1,STONE)
Block(-1,23,0,STONE)
Block(-1,23,1,STONE)
Block(-1,23,2,STONE)
Block(-1,23,3,STONE)
Block(-1,23,4,STONE)
Block(-1,23,5,STONE)
Block(-1,24,-7,STONE)
Block(-1,24,-6,STONE)
Block(-1,24,-5,STONE)
Block(-1,24,-4,STONE)
Block(-1,24,-3,STONE)
Block(-1,24,-2,STONE)
Block(-1,24,-1,STONE)
Block(-1,24,0,STONE)
Block(-1,24,1,STONE)
Block(-1,24,2,STONE)
Block(-1,25,-7,STONE)
Block(-1,25,-6,STONE)
Block(-1,25,-5,STONE)
Block(-1,25,-4,STONE)
Block(-1,25,-3,STONE)
Block(-1,25,-2,STONE)
Block(-1,25,-1,STONE)
Block(-1,25,0,STONE)
Block(-1,26,-6,STONE)
Block(-1,26,-5,STONE)
Block(-1,26,-4,STONE)
Block(-1,26,-3,STONE)
Block(0,1,-3,STONE)
Block(0,1,-2,STONE)
Block(0,1,-1,STONE)
Block(0,1,0,STONE)
Block(0,1,1,STONE)
Block(0,1,2,STONE)
Block(0,1,3,STONE)
Block(0,1,4,STONE)
Block(0,1,5,STONE)
Block(0,2,-4,STONE)
Block(0,2,-3,STONE)
Block(0,2,-2,STONE)
Block(0,2,-1,STONE)
Block(0,2,0,STONE)
Block(0,2,1,STONE)
Block(0,2,2,STONE)
Block(0,2,3,STONE)
Block(0,2,4,STONE)
Block(0,2,5,STONE)
Block(0,2,6,STONE)
Block(0,2,7,STONE)
Block(0,2,8,STONE)
Block(0,2,9,STONE)
Block(0,3,-5,STONE)
Block(0,3,-4,STONE)
Block(0,3,-3,STONE)
Block(0,3,-2,STONE)
Block(0,3,-1,STONE)
Block(0,3,0,STONE)
Block(0,3,1,STONE)
Block(0,3,2,STONE)
Block(0,3,3,STONE)
Block(0,3,4,STONE)
Block(0,3,5,STONE)
Block(0,3,6,STONE)
Block(0,3,7,STONE)
Block(0,3,8,STONE)
Block(0,3,9,STONE)
Block(0,4,-6,STONE)
Block(0,4,-5,STONE)
Block(0,4,-4,STONE)
Block(0,4,-3,STONE)
Block(0,4,-2,STONE)
Block(0,4,-1,STONE)
Block(0,4,0,STONE)
Block(0,4,1,STONE)
Block(0,4,2,STONE)
Block(0,4,3,STONE)
Block(0,4,4,STONE)
Block(0,4,5,STONE)
Block(0,4,6,STONE)
Block(0,4,7,STONE)
Block(0,4,8,STONE)
Block(0,4,9,STONE)
Block(0,4,10,STONE)
Block(0,5,-7,STONE)
Block(0,5,-6,STONE)
Block(0,5,-5,STONE)
Block(0,5,-4,STONE)
Block(0,5,-3,STONE)
Block(0,5,-2,STONE)
Block(0,5,-1,STONE)
Block(0,5,0,STONE)
Block(0,5,1,STONE)
Block(0,5,2,STONE)
Block(0,5,3,STONE)
Block(0,5,4,STONE)
Block(0,5,5,STONE)
Block(0,5,6,STONE)
Block(0,5,7,STONE)
Block(0,5,8,STONE)
Block(0,5,9,STONE)
Block(0,5,10,STONE)
Block(0,6,-7,STONE)
Block(0,6,-6,STONE)
Block(0,6,-5,STONE)
Block(0,6,-4,STONE)
Block(0,6,-3,STONE)
Block(0,6,-2,STONE)
Block(0,6,-1,STONE)
Block(0,6,0,STONE)
Block(0,6,1,STONE)
Block(0,6,2,STONE)
Block(0,6,3,STONE)
Block(0,6,4,STONE)
Block(0,6,5,STONE)
Block(0,6,6,STONE)
Block(0,6,7,STONE)
Block(0,6,8,STONE)
Block(0,6,9,STONE)
Block(0,6,10,STONE)
Block(0,7,-7,STONE)
Block(0,7,-6,STONE)
Block(0,7,-5,STONE)
Block(0,7,-4,STONE)
Block(0,7,-3,STONE)
Block(0,7,-2,STONE)
Block(0,7,-1,STONE)
Block(0,7,0,STONE)
Block(0,7,1,STONE)
Block(0,7,2,STONE)
Block(0,7,3,STONE)
Block(0,7,4,STONE)
Block(0,7,5,STONE)
Block(0,7,6,STONE)
Block(0,7,7,STONE)
Block(0,7,8,STONE)
Block(0,7,9,STONE)
Block(0,7,10,STONE)
Block(0,7,11,STONE)
Block(0,8,-8,STONE)
Block(0,8,-7,STONE)
Block(0,8,-6,STONE)
Block(0,8,-5,STONE)
Block(0,8,-4,STONE)
Block(0,8,-3,STONE)
Block(0,8,-2,STONE)
Block(0,8,-1,STONE)
Block(0,8,0,STONE)
Block(0,8,1,STONE)
Block(0,8,2,STONE)
Block(0,8,3,STONE)
Block(0,8,4,STONE)
Block(0,8,5,STONE)
Block(0,8,6,STONE)
Block(0,8,7,STONE)
Block(0,8,8,STONE)
Block(0,8,9,STONE)
Block(0,8,10,STONE)
Block(0,8,11,STONE)
Block(0,9,-8,STONE)
Block(0,9,-7,STONE)
Block(0,9,-6,STONE)
Block(0,9,-5,STONE)
Block(0,9,-4,STONE)
Block(0,9,-3,STONE)
Block(0,9,-2,STONE)
Block(0,9,-1,STONE)
Block(0,9,0,STONE)
Block(0,9,1,STONE)
Block(0,9,2,STONE)
Block(0,9,3,STONE)
Block(0,9,4,STONE)
Block(0,9,5,STONE)
Block(0,9,6,STONE)
Block(0,9,7,STONE)
Block(0,9,8,STONE)
Block(0,9,9,STONE)
Block(0,9,10,STONE)
Block(0,9,11,STONE)
Block(0,10,-8,STONE)
Block(0,10,-7,STONE)
Block(0,10,-6,STONE)
Block(0,10,-5,STONE)
Block(0,10,-4,STONE)
Block(0,10,-3,STONE)
Block(0,10,-2,STONE)
Block(0,10,-1,STONE)
Block(0,10,0,STONE)
Block(0,10,1,STONE)
Block(0,10,2,STONE)
Block(0,10,3,STONE)
Block(0,10,4,STONE)
Block(0,10,5,STONE)
Block(0,10,6,STONE)
Block(0,10,7,STONE)
Block(0,10,8,STONE)
Block(0,10,9,STONE)
Block(0,10,10,STONE)
Block(0,10,11,STONE)
Block(0,11,-9,STONE)
Block(0,11,-8,STONE)
Block(0,11,-7,STONE)
Block(0,11,-6,STONE)
Block(0,11,-5,STONE)
Block(0,11,-4,STONE)
Block(0,11,-3,STONE)
Block(0,11,-2,STONE)
Block(0,11,-1,STONE)
Block(0,11,0,STONE)
Block(0,11,1,STONE)
Block(0,11,2,STONE)
Block(0,11,3,STONE)
Block(0,11,4,STONE)
Block(0,11,5,STONE)
Block(0,11,6,STONE)
Block(0,11,7,STONE)
Block(0,11,8,STONE)
Block(0,11,9,STONE)
Block(0,11,10,STONE)
Block(0,11,11,STONE)
Block(0,12,-9,STONE)
Block(0,12,-8,STONE)
Block(0,12,-7,STONE)
Block(0,12,-6,STONE)
Block(0,12,-5,STONE)
Block(0,12,-4,STONE)
Block(0,12,-3,STONE)
Block(0,12,-2,STONE)
Block(0,12,-1,STONE)
Block(0,12,0,STONE)
Block(0,12,1,STONE)
Block(0,12,2,STONE)
Block(0,12,3,STONE)
Block(0,12,4,STONE)
Block(0,12,5,STONE)
Block(0,12,6,STONE)
Block(0,12,7,STONE)
Block(0,12,8,STONE)
Block(0,12,9,STONE)
Block(0,12,10,STONE)
Block(0,12,11,STONE)
Block(0,13,-9,STONE)
Block(0,13,-8,STONE)
Block(0,13,-7,STONE)
Block(0,13,-6,STONE)
Block(0,13,-5,STONE)
Block(0,13,-4,STONE)
Block(0,13,-3,STONE)
Block(0,13,-2,STONE)
Block(0,13,-1,STONE)
Block(0,13,0,STONE)
Block(0,13,1,STONE)
Block(0,13,2,STONE)
Block(0,13,3,STONE)
Block(0,13,4,STONE)
Block(0,13,5,STONE)
Block(0,13,6,STONE)
Block(0,13,7,STONE)
Block(0,13,8,STONE)
Block(0,13,9,STONE)
Block(0,13,10,STONE)
Block(0,13,11,STONE)
Block(0,14,-9,STONE)
Block(0,14,-8,STONE)
Block(0,14,-7,STONE)
Block(0,14,-6,STONE)
Block(0,14,-5,STONE)
Block(0,14,-4,STONE)
Block(0,14,-3,STONE)
Block(0,14,-2,STONE)
Block(0,14,-1,STONE)
Block(0,14,0,STONE)
Block(0,14,1,STONE)
Block(0,14,2,STONE)
Block(0,14,3,STONE)
Block(0,14,4,STONE)
Block(0,14,5,STONE)
Block(0,14,6,STONE)
Block(0,14,7,STONE)
Block(0,14,8,STONE)
Block(0,14,9,STONE)
Block(0,14,10,STONE)
Block(0,14,11,STONE)
Block(0,15,-9,STONE)
Block(0,15,-8,STONE)
Block(0,15,-7,STONE)
Block(0,15,-6,STONE)
Block(0,15,-5,STONE)
Block(0,15,-4,STONE)
Block(0,15,-3,STONE)
Block(0,15,-2,STONE)
Block(0,15,-1,STONE)
Block(0,15,0,STONE)
Block(0,15,1,STONE)
Block(0,15,2,STONE)
Block(0,15,3,STONE)
Block(0,15,4,STONE)
Block(0,15,5,STONE)
Block(0,15,6,STONE)
Block(0,15,7,STONE)
Block(0,15,8,STONE)
Block(0,15,9,STONE)
Block(0,15,10,STONE)
Block(0,15,11,STONE)
Block(0,16,-9,STONE)
Block(0,16,-8,STONE)
Block(0,16,-7,STONE)
Block(0,16,-6,STONE)
Block(0,16,-5,STONE)
Block(0,16,-4,STONE)
Block(0,16,-3,STONE)
Block(0,16,-2,STONE)
Block(0,16,-1,STONE)
Block(0,16,0,STONE)
Block(0,16,1,STONE)
Block(0,16,2,STONE)
Block(0,16,3,STONE)
Block(0,16,4,STONE)
Block(0,16,5,STONE)
Block(0,16,6,STONE)
Block(0,16,7,STONE)
Block(0,16,8,STONE)
Block(0,16,9,STONE)
Block(0,16,10,STONE)
Block(0,16,11,STONE)
Block(0,17,-9,STONE)
Block(0,17,-8,STONE)
Block(0,17,-7,STONE)
Block(0,17,-6,STONE)
Block(0,17,-5,STONE)
Block(0,17,-4,STONE)
Block(0,17,-3,STONE)
Block(0,17,-2,STONE)
Block(0,17,-1,STONE)
Block(0,17,0,STONE)
Block(0,17,1,STONE)
Block(0,17,2,STONE)
Block(0,17,3,STONE)
Block(0,17,4,STONE)
Block(0,17,5,STONE)
Block(0,17,6,STONE)
Block(0,17,7,STONE)
Block(0,17,8,STONE)
Block(0,17,9,STONE)
Block(0,17,10,STONE)
Block(0,17,11,STONE)
Block(0,18,-9,STONE)
Block(0,18,-8,STONE)
Block(0,18,-7,STONE)
Block(0,18,-6,STONE)
Block(0,18,-5,STONE)
Block(0,18,-4,STONE)
Block(0,18,-3,STONE)
Block(0,18,-2,STONE)
Block(0,18,-1,STONE)
Block(0,18,0,STONE)
Block(0,18,1,STONE)
Block(0,18,2,STONE)
Block(0,18,3,STONE)
Block(0,18,4,STONE)
Block(0,18,5,STONE)
Block(0,18,6,STONE)
Block(0,18,7,STONE)
Block(0,18,8,STONE)
Block(0,18,9,STONE)
Block(0,18,10,STONE)
Block(0,18,11,STONE)
Block(0,19,-9,STONE)
Block(0,19,-8,STONE)
Block(0,19,-7,STONE)
Block(0,19,-6,STONE)
Block(0,19,-5,STONE)
Block(0,19,-4,STONE)
Block(0,19,-3,STONE)
Block(0,19,-2,STONE)
Block(0,19,-1,STONE)
Block(0,19,0,STONE)
Block(0,19,1,STONE)
Block(0,19,2,STONE)
Block(0,19,3,STONE)
Block(0,19,4,STONE)
Block(0,19,5,STONE)
Block(0,19,6,STONE)
Block(0,19,7,STONE)
Block(0,19,8,STONE)
Block(0,19,9,STONE)
Block(0,19,10,STONE)
Block(0,20,-9,STONE)
Block(0,20,-8,STONE)
Block(0,20,-7,STONE)
Block(0,20,-6,STONE)
Block(0,20,-5,STONE)
Block(0,20,-4,STONE)
Block(0,20,-3,STONE)
Block(0,20,-2,STONE)
Block(0,20,-1,STONE)
Block(0,20,0,STONE)
Block(0,20,1,STONE)
Block(0,20,2,STONE)
Block(0,20,3,STONE)
Block(0,20,4,STONE)
Block(0,20,5,STONE)
Block(0,20,6,STONE)
Block(0,20,7,STONE)
Block(0,20,8,STONE)
Block(0,20,9,STONE)
Block(0,20,10,STONE)
Block(0,21,-9,STONE)
Block(0,21,-8,STONE)
Block(0,21,-7,STONE)
Block(0,21,-6,STONE)
Block(0,21,-5,STONE)
Block(0,21,-4,STONE)
Block(0,21,-3,STONE)
Block(0,21,-2,STONE)
Block(0,21,-1,STONE)
Block(0,21,0,STONE)
Block(0,21,1,STONE)
Block(0,21,2,STONE)
Block(0,21,3,STONE)
Block(0,21,4,STONE)
Block(0,21,5,STONE)
Block(0,21,6,STONE)
Block(0,21,7,STONE)
Block(0,21,8,STONE)
Block(0,21,9,STONE)
Block(0,21,10,STONE)
Block(0,22,-8,STONE)
Block(0,22,-7,STONE)
Block(0,22,-6,STONE)
Block(0,22,-5,STONE)
Block(0,22,-4,STONE)
Block(0,22,-3,STONE)
Block(0,22,-2,STONE)
Block(0,22,-1,STONE)
Block(0,22,0,STONE)
Block(0,22,1,STONE)
Block(0,22,2,STONE)
Block(0,22,3,STONE)
Block(0,22,4,STONE)
Block(0,22,5,STONE)
Block(0,22,6,STONE)
Block(0,22,7,STONE)
Block(0,22,8,STONE)
Block(0,22,9,STONE)
Block(0,22,10,STONE)
Block(0,23,-8,STONE)
Block(0,23,-7,STONE)
Block(0,23,-6,STONE)
Block(0,23,-5,STONE)
Block(0,23,-4,STONE)
Block(0,23,-3,STONE)
Block(0,23,-2,STONE)
Block(0,23,-1,STONE)
Block(0,23,0,STONE)
Block(0,23,1,STONE)
Block(0,23,2,STONE)
Block(0,23,3,STONE)
Block(0,23,4,STONE)
Block(0,23,5,STONE)
Block(0,23,6,STONE)
Block(0,23,7,STONE)
Block(0,23,8,STONE)
Block(0,23,9,STONE)
Block(0,24,-8,STONE)
Block(0,24,-7,STONE)
Block(0,24,-6,STONE)
Block(0,24,-5,STONE)
Block(0,24,-4,STONE)
Block(0,24,-3,STONE)
Block(0,24,-2,STONE)
Block(0,24,-1,STONE)
Block(0,24,0,STONE)
Block(0,24,1,STONE)
Block(0,24,2,STONE)
Block(0,24,3,STONE)
Block(0,24,4,STONE)
Block(0,25,-7,STONE)
Block(0,25,-6,STONE)
Block(0,25,-5,STONE)
Block(0,25,-4,STONE)
Block(0,25,-3,STONE)
Block(0,25,-2,STONE)
Block(0,25,-1,STONE)
Block(0,25,0,STONE)
Block(0,25,1,STONE)
Block(0,25,2,STONE)
Block(0,26,-6,STONE)
Block(0,26,-5,STONE)
Block(0,26,-4,STONE)
Block(0,26,-3,STONE)
Block(0,26,-2,STONE)
Block(0,26,-1,STONE)
Block(0,27,-5,STONE)
Block(0,27,-4,STONE)
Block(0,27,-3,STONE)
Block(1,1,-4,STONE)
Block(1,1,-3,STONE)
Block(1,1,-2,STONE)
Block(1,1,-1,STONE)
Block(1,1,0,STONE)
Block(1,1,1,STONE)
Block(1,1,2,STONE)
Block(1,1,3,STONE)
Block(1,2,-5,STONE)
Block(1,2,-4,STONE)
Block(1,2,-3,STONE)
Block(1,2,-2,STONE)
Block(1,2,-1,STONE)
Block(1,2,0,STONE)
Block(1,2,1,STONE)
Block(1,2,2,STONE)
Block(1,2,3,STONE)
Block(1,2,4,STONE)
Block(1,2,5,STONE)
Block(1,2,6,STONE)
Block(1,2,7,STONE)
Block(1,2,8,STONE)
Block(1,2,9,STONE)
Block(1,2,10,STONE)
Block(1,3,-6,STONE)
Block(1,3,-5,STONE)
Block(1,3,-4,STONE)
Block(1,3,-3,STONE)
Block(1,3,-2,STONE)
Block(1,3,-1,STONE)
Block(1,3,0,STONE)
Block(1,3,1,STONE)
Block(1,3,2,STONE)
Block(1,3,3,STONE)
Block(1,3,4,STONE)
Block(1,3,5,STONE)
Block(1,3,6,STONE)
Block(1,3,7,STONE)
Block(1,3,8,STONE)
Block(1,3,9,STONE)
Block(1,3,10,STONE)
Block(1,4,-6,STONE)
Block(1,4,-5,STONE)
Block(1,4,-4,STONE)
Block(1,4,-3,STONE)
Block(1,4,-2,STONE)
Block(1,4,-1,STONE)
Block(1,4,0,STONE)
Block(1,4,1,STONE)
Block(1,4,2,STONE)
Block(1,4,3,STONE)
Block(1,4,4,STONE)
Block(1,4,5,STONE)
Block(1,4,6,STONE)
Block(1,4,7,STONE)
Block(1,4,8,STONE)
Block(1,4,9,STONE)
Block(1,4,10,STONE)
Block(1,5,-7,STONE)
Block(1,5,-6,STONE)
Block(1,5,-5,STONE)
Block(1,5,-4,STONE)
Block(1,5,-3,STONE)
Block(1,5,-2,STONE)
Block(1,5,-1,STONE)
Block(1,5,0,STONE)
Block(1,5,1,STONE)
Block(1,5,2,STONE)
Block(1,5,3,STONE)
Block(1,5,4,STONE)
Block(1,5,5,STONE)
Block(1,5,6,STONE)
Block(1,5,7,STONE)
Block(1,5,8,STONE)
Block(1,5,9,STONE)
Block(1,5,10,STONE)
Block(1,5,11,STONE)
Block(1,6,-8,STONE)
Block(1,6,-7,STONE)
Block(1,6,-6,STONE)
Block(1,6,-5,STONE)
Block(1,6,-4,STONE)
Block(1,6,-3,STONE)
Block(1,6,-2,STONE)
Block(1,6,-1,STONE)
Block(1,6,0,STONE)
Block(1,6,1,STONE)
Block(1,6,2,STONE)
Block(1,6,3,STONE)
Block(1,6,4,STONE)
Block(1,6,5,STONE)
Block(1,6,6,STONE)
Block(1,6,7,STONE)
Block(1,6,8,STONE)
Block(1,6,9,STONE)
Block(1,6,10,STONE)
Block(1,6,11,STONE)
Block(1,7,-8,STONE)
Block(1,7,-7,STONE)
Block(1,7,-6,STONE)
Block(1,7,-5,STONE)
Block(1,7,-4,STONE)
Block(1,7,-3,STONE)
Block(1,7,-2,STONE)
Block(1,7,-1,STONE)
Block(1,7,0,STONE)
Block(1,7,1,STONE)
Block(1,7,2,STONE)
Block(1,7,3,STONE)
Block(1,7,4,STONE)
Block(1,7,5,STONE)
Block(1,7,6,STONE)
Block(1,7,7,STONE)
Block(1,7,8,STONE)
Block(1,7,9,STONE)
Block(1,7,10,STONE)
Block(1,7,11,STONE)
Block(1,8,-8,STONE)
Block(1,8,-7,STONE)
Block(1,8,-6,STONE)
Block(1,8,-5,STONE)
Block(1,8,-4,STONE)
Block(1,8,-3,STONE)
Block(1,8,-2,STONE)
Block(1,8,-1,STONE)
Block(1,8,0,STONE)
Block(1,8,1,STONE)
Block(1,8,2,STONE)
Block(1,8,3,STONE)
Block(1,8,4,STONE)
Block(1,8,5,STONE)
Block(1,8,6,STONE)
Block(1,8,7,STONE)
Block(1,8,8,STONE)
Block(1,8,9,STONE)
Block(1,8,10,STONE)
Block(1,8,11,STONE)
Block(1,8,12,STONE)
Block(1,9,-9,STONE)
Block(1,9,-8,STONE)
Block(1,9,-7,STONE)
Block(1,9,-6,STONE)
Block(1,9,-5,STONE)
Block(1,9,-4,STONE)
Block(1,9,-3,STONE)
Block(1,9,-2,STONE)
Block(1,9,-1,STONE)
Block(1,9,0,STONE)
Block(1,9,1,STONE)
Block(1,9,2,STONE)
Block(1,9,3,STONE)
Block(1,9,4,STONE)
Block(1,9,5,STONE)
Block(1,9,6,STONE)
Block(1,9,7,STONE)
Block(1,9,8,STONE)
Block(1,9,9,STONE)
Block(1,9,10,STONE)
Block(1,9,11,STONE)
Block(1,9,12,STONE)
Block(1,10,-9,STONE)
Block(1,10,-8,STONE)
Block(1,10,-7,STONE)
Block(1,10,-6,STONE)
Block(1,10,-5,STONE)
Block(1,10,-4,STONE)
Block(1,10,-3,STONE)
Block(1,10,-2,STONE)
Block(1,10,-1,STONE)
Block(1,10,0,STONE)
Block(1,10,1,STONE)
Block(1,10,2,STONE)
Block(1,10,3,STONE)
Block(1,10,4,STONE)
Block(1,10,5,STONE)
Block(1,10,6,STONE)
Block(1,10,7,STONE)
Block(1,10,8,STONE)
Block(1,10,9,STONE)
Block(1,10,10,STONE)
Block(1,10,11,STONE)
Block(1,10,12,STONE)
Block(1,11,-9,STONE)
Block(1,11,-8,STONE)
Block(1,11,-7,STONE)
Block(1,11,-6,STONE)
Block(1,11,-5,STONE)
Block(1,11,-4,STONE)
Block(1,11,-3,STONE)
Block(1,11,-2,STONE)
Block(1,11,-1,STONE)
Block(1,11,0,STONE)
Block(1,11,1,STONE)
Block(1,11,2,STONE)
Block(1,11,3,STONE)
Block(1,11,4,STONE)
Block(1,11,5,STONE)
Block(1,11,6,STONE)
Block(1,11,7,STONE)
Block(1,11,8,STONE)
Block(1,11,9,STONE)
Block(1,11,10,STONE)
Block(1,11,11,STONE)
Block(1,11,12,STONE)
Block(1,12,-9,STONE)
Block(1,12,-8,STONE)
Block(1,12,-7,STONE)
Block(1,12,-6,STONE)
Block(1,12,-5,STONE)
Block(1,12,-4,STONE)
Block(1,12,-3,STONE)
Block(1,12,-2,STONE)
Block(1,12,-1,STONE)
Block(1,12,0,STONE)
Block(1,12,1,STONE)
Block(1,12,2,STONE)
Block(1,12,3,STONE)
Block(1,12,4,STONE)
Block(1,12,5,STONE)
Block(1,12,6,STONE)
Block(1,12,7,STONE)
Block(1,12,8,STONE)
Block(1,12,9,STONE)
Block(1,12,10,STONE)
Block(1,12,11,STONE)
Block(1,12,12,STONE)
Block(1,13,-10,STONE)
Block(1,13,-9,STONE)
Block(1,13,-8,STONE)
Block(1,13,-7,STONE)
Block(1,13,-6,STONE)
Block(1,13,-5,STONE)
Block(1,13,-4,STONE)
Block(1,13,-3,STONE)
Block(1,13,-2,STONE)
Block(1,13,-1,STONE)
Block(1,13,0,STONE)
Block(1,13,1,STONE)
Block(1,13,2,STONE)
Block(1,13,3,STONE)
Block(1,13,4,STONE)
Block(1,13,5,STONE)
Block(1,13,6,STONE)
Block(1,13,7,STONE)
Block(1,13,8,STONE)
Block(1,13,9,STONE)
Block(1,13,10,STONE)
Block(1,13,11,STONE)
Block(1,13,12,STONE)
Block(1,14,-10,STONE)
Block(1,14,-9,STONE)
Block(1,14,-8,STONE)
Block(1,14,-7,STONE)
Block(1,14,-6,STONE)
Block(1,14,-5,STONE)
Block(1,14,-4,STONE)
Block(1,14,-3,STONE)
Block(1,14,-2,STONE)
Block(1,14,-1,STONE)
Block(1,14,0,STONE)
Block(1,14,1,STONE)
Block(1,14,2,STONE)
Block(1,14,3,STONE)
Block(1,14,4,STONE)
Block(1,14,5,STONE)
Block(1,14,6,STONE)
Block(1,14,7,STONE)
Block(1,14,8,STONE)
Block(1,14,9,STONE)
Block(1,14,10,STONE)
Block(1,14,11,STONE)
Block(1,14,12,STONE)
Block(1,15,-10,STONE)
Block(1,15,-9,STONE)
Block(1,15,-8,STONE)
Block(1,15,-7,STONE)
Block(1,15,-6,STONE)
Block(1,15,-5,STONE)
Block(1,15,-4,STONE)
Block(1,15,-3,STONE)
Block(1,15,-2,STONE)
Block(1,15,-1,STONE)
Block(1,15,0,STONE)
Block(1,15,1,STONE)
Block(1,15,2,STONE)
Block(1,15,3,STONE)
Block(1,15,4,STONE)
Block(1,15,5,STONE)
Block(1,15,6,STONE)
Block(1,15,7,STONE)
Block(1,15,8,STONE)
Block(1,15,9,STONE)
Block(1,15,10,STONE)
Block(1,15,11,STONE)
Block(1,15,12,STONE)
Block(1,16,-10,STONE)
Block(1,16,-9,STONE)
Block(1,16,-8,STONE)
Block(1,16,-7,STONE)
Block(1,16,-6,STONE)
Block(1,16,-5,STONE)
Block(1,16,-4,STONE)
Block(1,16,-3,STONE)
Block(1,16,-2,STONE)
Block(1,16,-1,STONE)
Block(1,16,0,STONE)
Block(1,16,1,STONE)
Block(1,16,2,STONE)
Block(1,16,3,STONE)
Block(1,16,4,STONE)
Block(1,16,5,STONE)
Block(1,16,6,STONE)
Block(1,16,7,STONE)
Block(1,16,8,STONE)
Block(1,16,9,STONE)
Block(1,16,10,STONE)
Block(1,16,11,STONE)
Block(1,16,12,STONE)
Block(1,17,-10,STONE)
Block(1,17,-9,STONE)
Block(1,17,-8,STONE)
Block(1,17,-7,STONE)
Block(1,17,-6,STONE)
Block(1,17,-5,STONE)
Block(1,17,-4,STONE)
Block(1,17,-3,STONE)
Block(1,17,-2,STONE)
Block(1,17,-1,STONE)
Block(1,17,0,STONE)
Block(1,17,1,STONE)
Block(1,17,2,STONE)
Block(1,17,3,STONE)
Block(1,17,4,STONE)
Block(1,17,5,STONE)
Block(1,17,6,STONE)
Block(1,17,7,STONE)
Block(1,17,8,STONE)
Block(1,17,9,STONE)
Block(1,17,10,STONE)
Block(1,17,11,STONE)
Block(1,18,-10,STONE)
Block(1,18,-9,STONE)
Block(1,18,-8,STONE)
Block(1,18,-7,STONE)
Block(1,18,-6,STONE)
Block(1,18,-5,STONE)
Block(1,18,-4,STONE)
Block(1,18,-3,STONE)
Block(1,18,-2,STONE)
Block(1,18,-1,STONE)
Block(1,18,0,STONE)
Block(1,18,1,STONE)
Block(1,18,2,STONE)
Block(1,18,3,STONE)
Block(1,18,4,STONE)
Block(1,18,5,STONE)
Block(1,18,6,STONE)
Block(1,18,7,STONE)
Block(1,18,8,STONE)
Block(1,18,9,STONE)
Block(1,18,10,STONE)
Block(1,18,11,STONE)
Block(1,19,-10,STONE)
Block(1,19,-9,STONE)
Block(1,19,-8,STONE)
Block(1,19,-7,STONE)
Block(1,19,-6,STONE)
Block(1,19,-5,STONE)
Block(1,19,-4,STONE)
Block(1,19,-3,STONE)
Block(1,19,-2,STONE)
Block(1,19,-1,STONE)
Block(1,19,0,STONE)
Block(1,19,1,STONE)
Block(1,19,2,STONE)
Block(1,19,3,STONE)
Block(1,19,4,STONE)
Block(1,19,5,STONE)
Block(1,19,6,STONE)
Block(1,19,7,STONE)
Block(1,19,8,STONE)
Block(1,19,9,STONE)
Block(1,19,10,STONE)
Block(1,19,11,STONE)
Block(1,20,-9,STONE)
Block(1,20,-8,STONE)
Block(1,20,-7,STONE)
Block(1,20,-6,STONE)
Block(1,20,-5,STONE)
Block(1,20,-4,STONE)
Block(1,20,-3,STONE)
Block(1,20,-2,STONE)
Block(1,20,-1,STONE)
Block(1,20,0,STONE)
Block(1,20,1,STONE)
Block(1,20,2,STONE)
Block(1,20,3,STONE)
Block(1,20,4,STONE)
Block(1,20,5,STONE)
Block(1,20,6,STONE)
Block(1,20,7,STONE)
Block(1,20,8,STONE)
Block(1,20,9,STONE)
Block(1,20,10,STONE)
Block(1,20,11,STONE)
Block(1,21,-9,STONE)
Block(1,21,-8,STONE)
Block(1,21,-7,STONE)
Block(1,21,-6,STONE)
Block(1,21,-5,STONE)
Block(1,21,-4,STONE)
Block(1,21,-3,STONE)
Block(1,21,-2,STONE)
Block(1,21,-1,STONE)
Block(1,21,0,STONE)
Block(1,21,1,STONE)
Block(1,21,2,STONE)
Block(1,21,3,STONE)
Block(1,21,4,STONE)
Block(1,21,5,STONE)
Block(1,21,6,STONE)
Block(1,21,7,STONE)
Block(1,21,8,STONE)
Block(1,21,9,STONE)
Block(1,21,10,STONE)
Block(1,21,11,STONE)
Block(1,22,-9,STONE)
Block(1,22,-8,STONE)
Block(1,22,-7,STONE)
Block(1,22,-6,STONE)
Block(1,22,-5,STONE)
Block(1,22,-4,STONE)
Block(1,22,-3,STONE)
Block(1,22,-2,STONE)
Block(1,22,-1,STONE)
Block(1,22,0,STONE)
Block(1,22,1,STONE)
Block(1,22,2,STONE)
Block(1,22,3,STONE)
Block(1,22,4,STONE)
Block(1,22,5,STONE)
Block(1,22,6,STONE)
Block(1,22,7,STONE)
Block(1,22,8,STONE)
Block(1,22,9,STONE)
Block(1,22,10,STONE)
Block(1,22,11,STONE)
Block(1,23,-9,STONE)
Block(1,23,-8,STONE)
Block(1,23,-7,STONE)
Block(1,23,-6,STONE)
Block(1,23,-5,STONE)
Block(1,23,-4,STONE)
Block(1,23,-3,STONE)
Block(1,23,-2,STONE)
Block(1,23,-1,STONE)
Block(1,23,0,STONE)
Block(1,23,1,STONE)
Block(1,23,2,STONE)
Block(1,23,3,STONE)
Block(1,23,4,STONE)
Block(1,23,5,STONE)
Block(1,23,6,STONE)
Block(1,23,7,STONE)
Block(1,23,8,STONE)
Block(1,23,9,STONE)
Block(1,23,10,STONE)
Block(1,24,-8,STONE)
Block(1,24,-7,STONE)
Block(1,24,-6,STONE)
Block(1,24,-5,STONE)
Block(1,24,-4,STONE)
Block(1,24,-3,STONE)
Block(1,24,-2,STONE)
Block(1,24,-1,STONE)
Block(1,24,0,STONE)
Block(1,24,1,STONE)
Block(1,24,2,STONE)
Block(1,24,3,STONE)
Block(1,24,4,STONE)
Block(1,24,5,STONE)
Block(1,24,6,STONE)
Block(1,24,7,STONE)
Block(1,24,8,STONE)
Block(1,25,-7,STONE)
Block(1,25,-6,STONE)
Block(1,25,-5,STONE)
Block(1,25,-4,STONE)
Block(1,25,-3,STONE)
Block(1,25,-2,STONE)
Block(1,25,-1,STONE)
Block(1,25,0,STONE)
Block(1,25,1,STONE)
Block(1,25,2,STONE)
Block(1,25,3,STONE)
Block(1,25,4,STONE)
Block(1,25,5,STONE)
Block(1,26,-6,STONE)
Block(1,26,-5,STONE)
Block(1,26,-4,STONE)
Block(1,26,-3,STONE)
Block(1,26,-2,STONE)
Block(1,26,-1,STONE)
Block(1,26,0,STONE)
Block(1,26,1,STONE)
Block(1,26,2,STONE)
Block(1,27,-5,STONE)
Block(1,27,-4,STONE)
Block(1,27,-3,STONE)
Block(1,27,-2,STONE)
Block(2,1,-4,STONE)
Block(2,1,-3,STONE)
Block(2,1,-2,STONE)
Block(2,1,-1,STONE)
Block(2,1,0,STONE)
Block(2,1,1,STONE)
Block(2,1,2,STONE)
Block(2,2,-5,STONE)
Block(2,2,-4,STONE)
Block(2,2,-3,STONE)
Block(2,2,-2,STONE)
Block(2,2,-1,STONE)
Block(2,2,0,STONE)
Block(2,2,1,STONE)
Block(2,2,2,STONE)
Block(2,2,3,STONE)
Block(2,2,4,STONE)
Block(2,2,5,STONE)
Block(2,2,6,STONE)
Block(2,2,7,STONE)
Block(2,2,8,STONE)
Block(2,2,9,STONE)
Block(2,3,-6,STONE)
Block(2,3,-5,STONE)
Block(2,3,-4,STONE)
Block(2,3,-3,STONE)
Block(2,3,-2,STONE)
Block(2,3,-1,STONE)
Block(2,3,0,STONE)
Block(2,3,1,STONE)
Block(2,3,2,STONE)
Block(2,3,3,STONE)
Block(2,3,4,STONE)
Block(2,3,5,STONE)
Block(2,3,6,STONE)
Block(2,3,7,STONE)
Block(2,3,8,STONE)
Block(2,3,9,STONE)
Block(2,3,10,STONE)
Block(2,4,-7,STONE)
Block(2,4,-6,STONE)
Block(2,4,-5,STONE)
Block(2,4,-4,STONE)
Block(2,4,-3,STONE)
Block(2,4,-2,STONE)
Block(2,4,-1,STONE)
Block(2,4,0,STONE)
Block(2,4,1,STONE)
Block(2,4,2,STONE)
Block(2,4,3,STONE)
Block(2,4,4,STONE)
Block(2,4,5,STONE)
Block(2,4,6,STONE)
Block(2,4,7,STONE)
Block(2,4,8,STONE)
Block(2,4,9,STONE)
Block(2,4,10,STONE)
Block(2,5,-8,STONE)
Block(2,5,-7,STONE)
Block(2,5,-6,STONE)
Block(2,5,-5,STONE)
Block(2,5,-4,STONE)
Block(2,5,-3,STONE)
Block(2,5,-2,STONE)
Block(2,5,-1,STONE)
Block(2,5,0,STONE)
Block(2,5,1,STONE)
Block(2,5,2,STONE)
Block(2,5,3,STONE)
Block(2,5,4,STONE)
Block(2,5,5,STONE)
Block(2,5,6,STONE)
Block(2,5,7,STONE)
Block(2,5,8,STONE)
Block(2,5,9,STONE)
Block(2,5,10,STONE)
Block(2,5,11,STONE)
Block(2,6,-8,STONE)
Block(2,6,-7,STONE)
Block(2,6,-6,STONE)
Block(2,6,-5,STONE)
Block(2,6,-4,STONE)
Block(2,6,-3,STONE)
Block(2,6,-2,STONE)
Block(2,6,-1,STONE)
Block(2,6,0,STONE)
Block(2,6,1,STONE)
Block(2,6,2,STONE)
Block(2,6,3,STONE)
Block(2,6,4,STONE)
Block(2,6,5,STONE)
Block(2,6,6,STONE)
Block(2,6,7,STONE)
Block(2,6,8,STONE)
Block(2,6,9,STONE)
Block(2,6,10,STONE)
Block(2,6,11,STONE)
Block(2,7,-8,STONE)
Block(2,7,-7,STONE)
Block(2,7,-6,STONE)
Block(2,7,-5,STONE)
Block(2,7,-4,STONE)
Block(2,7,-3,STONE)
Block(2,7,-2,STONE)
Block(2,7,-1,STONE)
Block(2,7,0,STONE)
Block(2,7,1,STONE)
Block(2,7,2,STONE)
Block(2,7,3,STONE)
Block(2,7,4,STONE)
Block(2,7,5,STONE)
Block(2,7,6,STONE)
Block(2,7,7,STONE)
Block(2,7,8,STONE)
Block(2,7,9,STONE)
Block(2,7,10,STONE)
Block(2,7,11,STONE)
Block(2,8,-9,STONE)
Block(2,8,-8,STONE)
Block(2,8,-7,STONE)
Block(2,8,-6,STONE)
Block(2,8,-5,STONE)
Block(2,8,-4,STONE)
Block(2,8,-3,STONE)
Block(2,8,-2,STONE)
Block(2,8,-1,STONE)
Block(2,8,0,STONE)
Block(2,8,1,STONE)
Block(2,8,2,STONE)
Block(2,8,3,STONE)
Block(2,8,4,STONE)
Block(2,8,5,STONE)
Block(2,8,6,STONE)
Block(2,8,7,STONE)
Block(2,8,8,STONE)
Block(2,8,9,STONE)
Block(2,8,10,STONE)
Block(2,8,11,STONE)
Block(2,8,12,STONE)
Block(2,9,-9,STONE)
Block(2,9,-8,STONE)
Block(2,9,-7,STONE)
Block(2,9,-6,STONE)
Block(2,9,-5,STONE)
Block(2,9,-4,STONE)
Block(2,9,-3,STONE)
Block(2,9,-2,STONE)
Block(2,9,-1,STONE)
Block(2,9,0,STONE)
Block(2,9,1,STONE)
Block(2,9,2,STONE)
Block(2,9,3,STONE)
Block(2,9,4,STONE)
Block(2,9,5,STONE)
Block(2,9,6,STONE)
Block(2,9,7,STONE)
Block(2,9,8,STONE)
Block(2,9,9,STONE)
Block(2,9,10,STONE)
Block(2,9,11,STONE)
Block(2,9,12,STONE)
Block(2,10,-9,STONE)
Block(2,10,-8,STONE)
Block(2,10,-7,STONE)
Block(2,10,-6,STONE)
Block(2,10,-5,STONE)
Block(2,10,-4,STONE)
Block(2,10,-3,STONE)
Block(2,10,-2,STONE)
Block(2,10,-1,STONE)
Block(2,10,0,STONE)
Block(2,10,1,STONE)
Block(2,10,2,STONE)
Block(2,10,3,STONE)
Block(2,10,4,STONE)
Block(2,10,5,STONE)
Block(2,10,6,STONE)
Block(2,10,7,STONE)
Block(2,10,8,STONE)
Block(2,10,9,STONE)
Block(2,10,10,STONE)
Block(2,10,11,STONE)
Block(2,10,12,STONE)
Block(2,11,-10,STONE)
Block(2,11,-9,STONE)
Block(2,11,-8,STONE)
Block(2,11,-7,STONE)
Block(2,11,-6,STONE)
Block(2,11,-5,STONE)
Block(2,11,-4,STONE)
Block(2,11,-3,STONE)
Block(2,11,-2,STONE)
Block(2,11,-1,STONE)
Block(2,11,0,STONE)
Block(2,11,1,STONE)
Block(2,11,2,STONE)
Block(2,11,3,STONE)
Block(2,11,4,STONE)
Block(2,11,5,STONE)
Block(2,11,6,STONE)
Block(2,11,7,STONE)
Block(2,11,8,STONE)
Block(2,11,9,STONE)
Block(2,11,10,STONE)
Block(2,11,11,STONE)
Block(2,11,12,STONE)
Block(2,12,-10,STONE)
Block(2,12,-9,STONE)
Block(2,12,-8,STONE)
Block(2,12,-7,STONE)
Block(2,12,-6,STONE)
Block(2,12,-5,STONE)
Block(2,12,-4,STONE)
Block(2,12,-3,STONE)
Block(2,12,-2,STONE)
Block(2,12,-1,STONE)
Block(2,12,0,STONE)
Block(2,12,1,STONE)
Block(2,12,2,STONE)
Block(2,12,3,STONE)
Block(2,12,4,STONE)
Block(2,12,5,STONE)
Block(2,12,6,STONE)
Block(2,12,7,STONE)
Block(2,12,8,STONE)
Block(2,12,9,STONE)
Block(2,12,10,STONE)
Block(2,12,11,STONE)
Block(2,12,12,STONE)
Block(2,13,-10,STONE)
Block(2,13,-9,STONE)
Block(2,13,-8,STONE)
Block(2,13,-7,STONE)
Block(2,13,-6,STONE)
Block(2,13,-5,STONE)
Block(2,13,-4,STONE)
Block(2,13,-3,STONE)
Block(2,13,-2,STONE)
Block(2,13,-1,STONE)
Block(2,13,0,STONE)
Block(2,13,1,STONE)
Block(2,13,2,STONE)
Block(2,13,3,STONE)
Block(2,13,4,STONE)
Block(2,13,5,STONE)
Block(2,13,6,STONE)
Block(2,13,7,STONE)
Block(2,13,8,STONE)
Block(2,13,9,STONE)
Block(2,13,10,STONE)
Block(2,13,11,STONE)
Block(2,13,12,STONE)
Block(2,14,-10,STONE)
Block(2,14,-9,STONE)
Block(2,14,-8,STONE)
Block(2,14,-7,STONE)
Block(2,14,-6,STONE)
Block(2,14,-5,STONE)
Block(2,14,-4,STONE)
Block(2,14,-3,STONE)
Block(2,14,-2,STONE)
Block(2,14,-1,STONE)
Block(2,14,0,STONE)
Block(2,14,1,STONE)
Block(2,14,2,STONE)
Block(2,14,3,STONE)
Block(2,14,4,STONE)
Block(2,14,5,STONE)
Block(2,14,6,STONE)
Block(2,14,7,STONE)
Block(2,14,8,STONE)
Block(2,14,9,STONE)
Block(2,14,10,STONE)
Block(2,14,11,STONE)
Block(2,14,12,STONE)
Block(2,15,-10,STONE)
Block(2,15,-9,STONE)
Block(2,15,-8,STONE)
Block(2,15,-7,STONE)
Block(2,15,-6,STONE)
Block(2,15,-5,STONE)
Block(2,15,-4,STONE)
Block(2,15,-3,STONE)
Block(2,15,-2,STONE)
Block(2,15,-1,STONE)
Block(2,15,0,STONE)
Block(2,15,1,STONE)
Block(2,15,2,STONE)
Block(2,15,3,STONE)
Block(2,15,4,STONE)
Block(2,15,5,STONE)
Block(2,15,6,STONE)
Block(2,15,7,STONE)
Block(2,15,8,STONE)
Block(2,15,9,STONE)
Block(2,15,10,STONE)
Block(2,15,11,STONE)
Block(2,15,12,STONE)
Block(2,16,-10,STONE)
Block(2,16,-9,STONE)
Block(2,16,-8,STONE)
Block(2,16,-7,STONE)
Block(2,16,-6,STONE)
Block(2,16,-5,STONE)
Block(2,16,-4,STONE)
Block(2,16,-3,STONE)
Block(2,16,-2,STONE)
Block(2,16,-1,STONE)
Block(2,16,0,STONE)
Block(2,16,1,STONE)
Block(2,16,2,STONE)
Block(2,16,3,STONE)
Block(2,16,4,STONE)
Block(2,16,5,STONE)
Block(2,16,6,STONE)
Block(2,16,7,STONE)
Block(2,16,8,STONE)
Block(2,16,9,STONE)
Block(2,16,10,STONE)
Block(2,16,11,STONE)
Block(2,16,12,STONE)
Block(2,17,-10,STONE)
Block(2,17,-9,STONE)
Block(2,17,-8,STONE)
Block(2,17,-7,STONE)
Block(2,17,-6,STONE)
Block(2,17,-5,STONE)
Block(2,17,-4,STONE)
Block(2,17,-3,STONE)
Block(2,17,-2,STONE)
Block(2,17,-1,STONE)
Block(2,17,0,STONE)
Block(2,17,1,STONE)
Block(2,17,2,STONE)
Block(2,17,3,STONE)
Block(2,17,4,STONE)
Block(2,17,5,STONE)
Block(2,17,6,STONE)
Block(2,17,7,STONE)
Block(2,17,8,STONE)
Block(2,17,9,STONE)
Block(2,17,10,STONE)
Block(2,17,11,STONE)
Block(2,17,12,STONE)
Block(2,18,-10,STONE)
Block(2,18,-9,STONE)
Block(2,18,-8,STONE)
Block(2,18,-7,STONE)
Block(2,18,-6,STONE)
Block(2,18,-5,STONE)
Block(2,18,-4,STONE)
Block(2,18,-3,STONE)
Block(2,18,-2,STONE)
Block(2,18,-1,STONE)
Block(2,18,0,STONE)
Block(2,18,1,STONE)
Block(2,18,2,STONE)
Block(2,18,3,STONE)
Block(2,18,4,STONE)
Block(2,18,5,STONE)
Block(2,18,6,STONE)
Block(2,18,7,STONE)
Block(2,18,8,STONE)
Block(2,18,9,STONE)
Block(2,18,10,STONE)
Block(2,18,11,STONE)
Block(2,18,12,STONE)
Block(2,19,-10,STONE)
Block(2,19,-9,STONE)
Block(2,19,-8,STONE)
Block(2,19,-7,STONE)
Block(2,19,-6,STONE)
Block(2,19,-5,STONE)
Block(2,19,-4,STONE)
Block(2,19,-3,STONE)
Block(2,19,-2,STONE)
Block(2,19,-1,STONE)
Block(2,19,0,STONE)
Block(2,19,1,STONE)
Block(2,19,2,STONE)
Block(2,19,3,STONE)
Block(2,19,4,STONE)
Block(2,19,5,STONE)
Block(2,19,6,STONE)
Block(2,19,7,STONE)
Block(2,19,8,STONE)
Block(2,19,9,STONE)
Block(2,19,10,STONE)
Block(2,19,11,STONE)
Block(2,19,12,STONE)
Block(2,20,-10,STONE)
Block(2,20,-9,STONE)
Block(2,20,-8,STONE)
Block(2,20,-7,STONE)
Block(2,20,-6,STONE)
Block(2,20,-5,STONE)
Block(2,20,-4,STONE)
Block(2,20,-3,STONE)
Block(2,20,-2,STONE)
Block(2,20,-1,STONE)
Block(2,20,0,STONE)
Block(2,20,1,STONE)
Block(2,20,2,STONE)
Block(2,20,3,STONE)
Block(2,20,4,STONE)
Block(2,20,5,STONE)
Block(2,20,6,STONE)
Block(2,20,7,STONE)
Block(2,20,8,STONE)
Block(2,20,9,STONE)
Block(2,20,10,STONE)
Block(2,20,11,STONE)
Block(2,20,12,STONE)
Block(2,21,-10,STONE)
Block(2,21,-9,STONE)
Block(2,21,-8,STONE)
Block(2,21,-7,STONE)
Block(2,21,-6,STONE)
Block(2,21,-5,STONE)
Block(2,21,-4,STONE)
Block(2,21,-3,STONE)
Block(2,21,-2,STONE)
Block(2,21,-1,STONE)
Block(2,21,0,STONE)
Block(2,21,1,STONE)
Block(2,21,2,STONE)
Block(2,21,3,STONE)
Block(2,21,4,STONE)
Block(2,21,5,STONE)
Block(2,21,6,STONE)
Block(2,21,7,STONE)
Block(2,21,8,STONE)
Block(2,21,9,STONE)
Block(2,21,10,STONE)
Block(2,21,11,STONE)
Block(2,21,12,STONE)
Block(2,22,-9,STONE)
Block(2,22,-8,STONE)
Block(2,22,-7,STONE)
Block(2,22,-6,STONE)
Block(2,22,-5,STONE)
Block(2,22,-4,STONE)
Block(2,22,-3,STONE)
Block(2,22,-2,STONE)
Block(2,22,-1,STONE)
Block(2,22,0,STONE)
Block(2,22,1,STONE)
Block(2,22,2,STONE)
Block(2,22,3,STONE)
Block(2,22,4,STONE)
Block(2,22,5,STONE)
Block(2,22,6,STONE)
Block(2,22,7,STONE)
Block(2,22,8,STONE)
Block(2,22,9,STONE)
Block(2,22,10,STONE)
Block(2,22,11,STONE)
Block(2,23,-9,STONE)
Block(2,23,-8,STONE)
Block(2,23,-7,STONE)
Block(2,23,-6,STONE)
Block(2,23,-5,STONE)
Block(2,23,-4,STONE)
Block(2,23,-3,STONE)
Block(2,23,-2,STONE)
Block(2,23,-1,STONE)
Block(2,23,0,STONE)
Block(2,23,1,STONE)
Block(2,23,2,STONE)
Block(2,23,3,STONE)
Block(2,23,4,STONE)
Block(2,23,5,STONE)
Block(2,23,6,STONE)
Block(2,23,7,STONE)
Block(2,23,8,STONE)
Block(2,23,9,STONE)
Block(2,23,10,STONE)
Block(2,23,11,STONE)
Block(2,24,-8,STONE)
Block(2,24,-7,STONE)
Block(2,24,-6,STONE)
Block(2,24,-5,STONE)
Block(2,24,-4,STONE)
Block(2,24,-3,STONE)
Block(2,24,-2,STONE)
Block(2,24,-1,STONE)
Block(2,24,0,STONE)
Block(2,24,1,STONE)
Block(2,24,2,STONE)
Block(2,24,3,STONE)
Block(2,24,4,STONE)
Block(2,24,5,STONE)
Block(2,24,6,STONE)
Block(2,24,7,STONE)
Block(2,24,8,STONE)
Block(2,24,9,STONE)
Block(2,24,10,STONE)
Block(2,25,-7,STONE)
Block(2,25,-6,STONE)
Block(2,25,-5,STONE)
Block(2,25,-4,STONE)
Block(2,25,-3,STONE)
Block(2,25,-2,STONE)
Block(2,25,-1,STONE)
Block(2,25,0,STONE)
Block(2,25,1,STONE)
Block(2,25,2,STONE)
Block(2,25,3,STONE)
Block(2,25,4,STONE)
Block(2,25,5,STONE)
Block(2,25,6,STONE)
Block(2,25,7,STONE)
Block(2,26,-6,STONE)
Block(2,26,-5,STONE)
Block(2,26,-4,STONE)
Block(2,26,-3,STONE)
Block(2,26,-2,STONE)
Block(2,26,-1,STONE)
Block(2,26,0,STONE)
Block(2,26,1,STONE)
Block(2,26,2,STONE)
Block(2,26,3,STONE)
Block(2,26,4,STONE)
Block(2,27,-5,STONE)
Block(2,27,-4,STONE)
Block(2,27,-3,STONE)
Block(3,1,-4,STONE)
Block(3,1,-3,STONE)
Block(3,1,-2,STONE)
Block(3,1,-1,STONE)
Block(3,1,0,STONE)
Block(3,2,-5,STONE)
Block(3,2,-4,STONE)
Block(3,2,-3,STONE)
Block(3,2,-2,STONE)
Block(3,2,-1,STONE)
Block(3,2,0,STONE)
Block(3,2,1,STONE)
Block(3,2,2,STONE)
Block(3,2,3,STONE)
Block(3,2,4,STONE)
Block(3,2,5,STONE)
Block(3,2,6,STONE)
Block(3,2,7,STONE)
Block(3,2,8,STONE)
Block(3,2,9,STONE)
Block(3,3,-6,STONE)
Block(3,3,-5,STONE)
Block(3,3,-4,STONE)
Block(3,3,-3,STONE)
Block(3,3,-2,STONE)
Block(3,3,-1,STONE)
Block(3,3,0,STONE)
Block(3,3,1,STONE)
Block(3,3,2,STONE)
Block(3,3,3,STONE)
Block(3,3,4,STONE)
Block(3,3,5,STONE)
Block(3,3,6,STONE)
Block(3,3,7,STONE)
Block(3,3,8,STONE)
Block(3,3,9,STONE)
Block(3,3,10,STONE)
Block(3,4,-6,STONE)
Block(3,4,-5,STONE)
Block(3,4,-4,STONE)
Block(3,4,-3,STONE)
Block(3,4,-2,STONE)
Block(3,4,-1,STONE)
Block(3,4,0,STONE)
Block(3,4,1,STONE)
Block(3,4,2,STONE)
Block(3,4,3,STONE)
Block(3,4,4,STONE)
Block(3,4,5,STONE)
Block(3,4,6,STONE)
Block(3,4,7,STONE)
Block(3,4,8,STONE)
Block(3,4,9,STONE)
Block(3,4,10,STONE)
Block(3,5,-7,STONE)
Block(3,5,-6,STONE)
Block(3,5,-5,STONE)
Block(3,5,-4,STONE)
Block(3,5,-3,STONE)
Block(3,5,-2,STONE)
Block(3,5,-1,STONE)
Block(3,5,0,STONE)
Block(3,5,1,STONE)
Block(3,5,2,STONE)
Block(3,5,3,STONE)
Block(3,5,4,STONE)
Block(3,5,5,STONE)
Block(3,5,6,STONE)
Block(3,5,7,STONE)
Block(3,5,8,STONE)
Block(3,5,9,STONE)
Block(3,5,10,STONE)
Block(3,5,11,STONE)
Block(3,6,-8,STONE)
Block(3,6,-7,STONE)
Block(3,6,-6,STONE)
Block(3,6,-5,STONE)
Block(3,6,-4,STONE)
Block(3,6,-3,STONE)
Block(3,6,-2,STONE)
Block(3,6,-1,STONE)
Block(3,6,0,STONE)
Block(3,6,1,STONE)
Block(3,6,2,STONE)
Block(3,6,3,STONE)
Block(3,6,4,STONE)
Block(3,6,5,STONE)
Block(3,6,6,STONE)
Block(3,6,7,STONE)
Block(3,6,8,STONE)
Block(3,6,9,STONE)
Block(3,6,10,STONE)
Block(3,6,11,STONE)
Block(3,7,-9,STONE)
Block(3,7,-8,STONE)
Block(3,7,-7,STONE)
Block(3,7,-6,STONE)
Block(3,7,-5,STONE)
Block(3,7,-4,STONE)
Block(3,7,-3,STONE)
Block(3,7,-2,STONE)
Block(3,7,-1,STONE)
Block(3,7,0,STONE)
Block(3,7,1,STONE)
Block(3,7,2,STONE)
Block(3,7,3,STONE)
Block(3,7,4,STONE)
Block(3,7,5,STONE)
Block(3,7,6,STONE)
Block(3,7,7,STONE)
Block(3,7,8,STONE)
Block(3,7,9,STONE)
Block(3,7,10,STONE)
Block(3,7,11,STONE)
Block(3,8,-9,STONE)
Block(3,8,-8,STONE)
Block(3,8,-7,STONE)
Block(3,8,-6,STONE)
Block(3,8,-5,STONE)
Block(3,8,-4,STONE)
Block(3,8,-3,STONE)
Block(3,8,-2,STONE)
Block(3,8,-1,STONE)
Block(3,8,0,STONE)
Block(3,8,1,STONE)
Block(3,8,2,STONE)
Block(3,8,3,STONE)
Block(3,8,4,STONE)
Block(3,8,5,STONE)
Block(3,8,6,STONE)
Block(3,8,7,STONE)
Block(3,8,8,STONE)
Block(3,8,9,STONE)
Block(3,8,10,STONE)
Block(3,8,11,STONE)
Block(3,9,-10,STONE)
Block(3,9,-9,STONE)
Block(3,9,-8,STONE)
Block(3,9,-7,STONE)
Block(3,9,-6,STONE)
Block(3,9,-5,STONE)
Block(3,9,-4,STONE)
Block(3,9,-3,STONE)
Block(3,9,-2,STONE)
Block(3,9,-1,STONE)
Block(3,9,0,STONE)
Block(3,9,1,STONE)
Block(3,9,2,STONE)
Block(3,9,3,STONE)
Block(3,9,4,STONE)
Block(3,9,5,STONE)
Block(3,9,6,STONE)
Block(3,9,7,STONE)
Block(3,9,8,STONE)
Block(3,9,9,STONE)
Block(3,9,10,STONE)
Block(3,9,11,STONE)
Block(3,9,12,STONE)
Block(3,10,-10,STONE)
Block(3,10,-9,STONE)
Block(3,10,-8,STONE)
Block(3,10,-7,STONE)
Block(3,10,-6,STONE)
Block(3,10,-5,STONE)
Block(3,10,-4,STONE)
Block(3,10,-3,STONE)
Block(3,10,-2,STONE)
Block(3,10,-1,STONE)
Block(3,10,0,STONE)
Block(3,10,1,STONE)
Block(3,10,2,STONE)
Block(3,10,3,STONE)
Block(3,10,4,STONE)
Block(3,10,5,STONE)
Block(3,10,6,STONE)
Block(3,10,7,STONE)
Block(3,10,8,STONE)
Block(3,10,9,STONE)
Block(3,10,10,STONE)
Block(3,10,11,STONE)
Block(3,10,12,STONE)
Block(3,11,-10,STONE)
Block(3,11,-9,STONE)
Block(3,11,-8,STONE)
Block(3,11,-7,STONE)
Block(3,11,-6,STONE)
Block(3,11,-5,STONE)
Block(3,11,-4,STONE)
Block(3,11,-3,STONE)
Block(3,11,-2,STONE)
Block(3,11,-1,STONE)
Block(3,11,0,STONE)
Block(3,11,1,STONE)
Block(3,11,2,STONE)
Block(3,11,3,STONE)
Block(3,11,4,STONE)
Block(3,11,5,STONE)
Block(3,11,6,STONE)
Block(3,11,7,STONE)
Block(3,11,8,STONE)
Block(3,11,9,STONE)
Block(3,11,10,STONE)
Block(3,11,11,STONE)
Block(3,11,12,STONE)
Block(3,11,13,STONE)
Block(3,12,-10,STONE)
Block(3,12,-9,STONE)
Block(3,12,-8,STONE)
Block(3,12,-7,STONE)
Block(3,12,-6,STONE)
Block(3,12,-5,STONE)
Block(3,12,-4,STONE)
Block(3,12,-3,STONE)
Block(3,12,-2,STONE)
Block(3,12,-1,STONE)
Block(3,12,0,STONE)
Block(3,12,1,STONE)
Block(3,12,2,STONE)
Block(3,12,3,STONE)
Block(3,12,4,STONE)
Block(3,12,5,STONE)
Block(3,12,6,STONE)
Block(3,12,7,STONE)
Block(3,12,8,STONE)
Block(3,12,9,STONE)
Block(3,12,10,STONE)
Block(3,12,11,STONE)
Block(3,12,12,STONE)
Block(3,12,13,STONE)
Block(3,13,-10,STONE)
Block(3,13,-9,STONE)
Block(3,13,-8,STONE)
Block(3,13,-7,STONE)
Block(3,13,-6,STONE)
Block(3,13,-5,STONE)
Block(3,13,-4,STONE)
Block(3,13,-3,STONE)
Block(3,13,-2,STONE)
Block(3,13,-1,STONE)
Block(3,13,0,STONE)
Block(3,13,1,STONE)
Block(3,13,2,STONE)
Block(3,13,3,STONE)
Block(3,13,4,STONE)
Block(3,13,5,STONE)
Block(3,13,6,STONE)
Block(3,13,7,STONE)
Block(3,13,8,STONE)
Block(3,13,9,STONE)
Block(3,13,10,STONE)
Block(3,13,11,STONE)
Block(3,13,12,STONE)
Block(3,13,13,STONE)
Block(3,14,-10,STONE)
Block(3,14,-9,STONE)
Block(3,14,-8,STONE)
Block(3,14,-7,STONE)
Block(3,14,-6,STONE)
Block(3,14,-5,STONE)
Block(3,14,-4,STONE)
Block(3,14,-3,STONE)
Block(3,14,-2,STONE)
Block(3,14,-1,STONE)
Block(3,14,0,STONE)
Block(3,14,1,STONE)
Block(3,14,2,STONE)
Block(3,14,3,STONE)
Block(3,14,4,STONE)
Block(3,14,5,STONE)
Block(3,14,6,STONE)
Block(3,14,7,STONE)
Block(3,14,8,STONE)
Block(3,14,9,STONE)
Block(3,14,10,STONE)
Block(3,14,11,STONE)
Block(3,14,12,STONE)
Block(3,14,13,STONE)
Block(3,15,-10,STONE)
Block(3,15,-9,STONE)
Block(3,15,-8,STONE)
Block(3,15,-7,STONE)
Block(3,15,-6,STONE)
Block(3,15,-5,STONE)
Block(3,15,-4,STONE)
Block(3,15,-3,STONE)
Block(3,15,-2,STONE)
Block(3,15,-1,STONE)
Block(3,15,0,STONE)
Block(3,15,1,STONE)
Block(3,15,2,STONE)
Block(3,15,3,STONE)
Block(3,15,4,STONE)
Block(3,15,5,STONE)
Block(3,15,6,STONE)
Block(3,15,7,STONE)
Block(3,15,8,STONE)
Block(3,15,9,STONE)
Block(3,15,10,STONE)
Block(3,15,11,STONE)
Block(3,15,12,STONE)
Block(3,15,13,STONE)
Block(3,16,-10,STONE)
Block(3,16,-9,STONE)
Block(3,16,-8,STONE)
Block(3,16,-7,STONE)
Block(3,16,-6,STONE)
Block(3,16,-5,STONE)
Block(3,16,-4,STONE)
Block(3,16,-3,STONE)
Block(3,16,-2,STONE)
Block(3,16,-1,STONE)
Block(3,16,0,STONE)
Block(3,16,1,STONE)
Block(3,16,2,STONE)
Block(3,16,3,STONE)
Block(3,16,4,STONE)
Block(3,16,5,STONE)
Block(3,16,6,STONE)
Block(3,16,7,STONE)
Block(3,16,8,STONE)
Block(3,16,9,STONE)
Block(3,16,10,STONE)
Block(3,16,11,STONE)
Block(3,16,12,STONE)
Block(3,16,13,STONE)
Block(3,17,-10,STONE)
Block(3,17,-9,STONE)
Block(3,17,-8,STONE)
Block(3,17,-7,STONE)
Block(3,17,-6,STONE)
Block(3,17,-5,STONE)
Block(3,17,-4,STONE)
Block(3,17,-3,STONE)
Block(3,17,-2,STONE)
Block(3,17,-1,STONE)
Block(3,17,0,STONE)
Block(3,17,1,STONE)
Block(3,17,2,STONE)
Block(3,17,3,STONE)
Block(3,17,4,STONE)
Block(3,17,5,STONE)
Block(3,17,6,STONE)
Block(3,17,7,STONE)
Block(3,17,8,STONE)
Block(3,17,9,STONE)
Block(3,17,10,STONE)
Block(3,17,11,STONE)
Block(3,17,12,STONE)
Block(3,17,13,STONE)
Block(3,18,-10,STONE)
Block(3,18,-9,STONE)
Block(3,18,-8,STONE)
Block(3,18,-7,STONE)
Block(3,18,-6,STONE)
Block(3,18,-5,STONE)
Block(3,18,-4,STONE)
Block(3,18,-3,STONE)
Block(3,18,-2,STONE)
Block(3,18,-1,STONE)
Block(3,18,0,STONE)
Block(3,18,1,STONE)
Block(3,18,2,STONE)
Block(3,18,3,STONE)
Block(3,18,4,STONE)
Block(3,18,5,STONE)
Block(3,18,6,STONE)
Block(3,18,7,STONE)
Block(3,18,8,STONE)
Block(3,18,9,STONE)
Block(3,18,10,STONE)
Block(3,18,11,STONE)
Block(3,18,12,STONE)
Block(3,18,13,STONE)
Block(3,19,-10,STONE)
Block(3,19,-9,STONE)
Block(3,19,-8,STONE)
Block(3,19,-7,STONE)
Block(3,19,-6,STONE)
Block(3,19,-5,STONE)
Block(3,19,-4,STONE)
Block(3,19,-3,STONE)
Block(3,19,-2,STONE)
Block(3,19,-1,STONE)
Block(3,19,0,STONE)
Block(3,19,1,STONE)
Block(3,19,2,STONE)
Block(3,19,3,STONE)
Block(3,19,4,STONE)
Block(3,19,5,STONE)
Block(3,19,6,STONE)
Block(3,19,7,STONE)
Block(3,19,8,STONE)
Block(3,19,9,STONE)
Block(3,19,10,STONE)
Block(3,19,11,STONE)
Block(3,19,12,STONE)
Block(3,19,13,STONE)
Block(3,20,-10,STONE)
Block(3,20,-9,STONE)
Block(3,20,-8,STONE)
Block(3,20,-7,STONE)
Block(3,20,-6,STONE)
Block(3,20,-5,STONE)
Block(3,20,-4,STONE)
Block(3,20,-3,STONE)
Block(3,20,-2,STONE)
Block(3,20,-1,STONE)
Block(3,20,0,STONE)
Block(3,20,1,STONE)
Block(3,20,2,STONE)
Block(3,20,3,STONE)
Block(3,20,4,STONE)
Block(3,20,5,STONE)
Block(3,20,6,STONE)
Block(3,20,7,STONE)
Block(3,20,8,STONE)
Block(3,20,9,STONE)
Block(3,20,10,STONE)
Block(3,20,11,STONE)
Block(3,20,12,STONE)
Block(3,21,-10,STONE)
Block(3,21,-9,STONE)
Block(3,21,-8,STONE)
Block(3,21,-7,STONE)
Block(3,21,-6,STONE)
Block(3,21,-5,STONE)
Block(3,21,-4,STONE)
Block(3,21,-3,STONE)
Block(3,21,-2,STONE)
Block(3,21,-1,STONE)
Block(3,21,0,STONE)
Block(3,21,1,STONE)
Block(3,21,2,STONE)
Block(3,21,3,STONE)
Block(3,21,4,STONE)
Block(3,21,5,STONE)
Block(3,21,6,STONE)
Block(3,21,7,STONE)
Block(3,21,8,STONE)
Block(3,21,9,STONE)
Block(3,21,10,STONE)
Block(3,21,11,STONE)
Block(3,21,12,STONE)
Block(3,22,-10,STONE)
Block(3,22,-9,STONE)
Block(3,22,-8,STONE)
Block(3,22,-7,STONE)
Block(3,22,-6,STONE)
Block(3,22,-5,STONE)
Block(3,22,-4,STONE)
Block(3,22,-3,STONE)
Block(3,22,-2,STONE)
Block(3,22,-1,STONE)
Block(3,22,0,STONE)
Block(3,22,1,STONE)
Block(3,22,2,STONE)
Block(3,22,3,STONE)
Block(3,22,4,STONE)
Block(3,22,5,STONE)
Block(3,22,6,STONE)
Block(3,22,7,STONE)
Block(3,22,8,STONE)
Block(3,22,9,STONE)
Block(3,22,10,STONE)
Block(3,22,11,STONE)
Block(3,22,12,STONE)
Block(3,23,-9,STONE)
Block(3,23,-8,STONE)
Block(3,23,-7,STONE)
Block(3,23,-6,STONE)
Block(3,23,-5,STONE)
Block(3,23,-4,STONE)
Block(3,23,-3,STONE)
Block(3,23,-2,STONE)
Block(3,23,-1,STONE)
Block(3,23,0,STONE)
Block(3,23,1,STONE)
Block(3,23,2,STONE)
Block(3,23,3,STONE)
Block(3,23,4,STONE)
Block(3,23,5,STONE)
Block(3,23,6,STONE)
Block(3,23,7,STONE)
Block(3,23,8,STONE)
Block(3,23,9,STONE)
Block(3,23,10,STONE)
Block(3,23,11,STONE)
Block(3,23,12,STONE)
Block(3,24,-8,STONE)
Block(3,24,-7,STONE)
Block(3,24,-6,STONE)
Block(3,24,-5,STONE)
Block(3,24,-4,STONE)
Block(3,24,-3,STONE)
Block(3,24,-2,STONE)
Block(3,24,-1,STONE)
Block(3,24,0,STONE)
Block(3,24,1,STONE)
Block(3,24,2,STONE)
Block(3,24,3,STONE)
Block(3,24,4,STONE)
Block(3,24,5,STONE)
Block(3,24,6,STONE)
Block(3,24,7,STONE)
Block(3,24,8,STONE)
Block(3,24,9,STONE)
Block(3,24,10,STONE)
Block(3,24,11,STONE)
Block(3,25,-7,STONE)
Block(3,25,-6,STONE)
Block(3,25,-5,STONE)
Block(3,25,-4,STONE)
Block(3,25,-3,STONE)
Block(3,25,-2,STONE)
Block(3,25,-1,STONE)
Block(3,25,0,STONE)
Block(3,25,1,STONE)
Block(3,25,2,STONE)
Block(3,25,3,STONE)
Block(3,25,4,STONE)
Block(3,25,5,STONE)
Block(3,25,6,STONE)
Block(3,25,7,STONE)
Block(3,25,8,STONE)
Block(3,25,9,STONE)
Block(3,26,-6,STONE)
Block(3,26,-5,STONE)
Block(3,26,-4,STONE)
Block(3,26,-3,STONE)
Block(3,26,-2,STONE)
Block(3,26,-1,STONE)
Block(3,26,0,STONE)
Block(3,26,1,STONE)
Block(3,27,-4,STONE)
Block(4,1,-4,STONE)
Block(4,1,-3,STONE)
Block(4,1,-2,STONE)
Block(4,1,-1,STONE)
Block(4,2,-4,STONE)
Block(4,2,-3,STONE)
Block(4,2,-2,STONE)
Block(4,2,-1,STONE)
Block(4,2,0,STONE)
Block(4,2,1,STONE)
Block(4,2,2,STONE)
Block(4,2,3,STONE)
Block(4,2,4,STONE)
Block(4,2,5,STONE)
Block(4,2,6,STONE)
Block(4,2,7,STONE)
Block(4,2,8,STONE)
Block(4,2,9,STONE)
Block(4,3,-5,STONE)
Block(4,3,-4,STONE)
Block(4,3,-3,STONE)
Block(4,3,-2,STONE)
Block(4,3,-1,STONE)
Block(4,3,0,STONE)
Block(4,3,1,STONE)
Block(4,3,2,STONE)
Block(4,3,3,STONE)
Block(4,3,4,STONE)
Block(4,3,5,STONE)
Block(4,3,6,STONE)
Block(4,3,7,STONE)
Block(4,3,8,STONE)
Block(4,3,9,STONE)
Block(4,3,10,STONE)
Block(4,4,-6,STONE)
Block(4,4,-5,STONE)
Block(4,4,-4,STONE)
Block(4,4,-3,STONE)
Block(4,4,-2,STONE)
Block(4,4,-1,STONE)
Block(4,4,0,STONE)
Block(4,4,1,STONE)
Block(4,4,2,STONE)
Block(4,4,3,STONE)
Block(4,4,4,STONE)
Block(4,4,5,STONE)
Block(4,4,6,STONE)
Block(4,4,7,STONE)
Block(4,4,8,STONE)
Block(4,4,9,STONE)
Block(4,4,10,STONE)
Block(4,5,-7,STONE)
Block(4,5,-6,STONE)
Block(4,5,-5,STONE)
Block(4,5,-4,STONE)
Block(4,5,-3,STONE)
Block(4,5,-2,STONE)
Block(4,5,-1,STONE)
Block(4,5,0,STONE)
Block(4,5,1,STONE)
Block(4,5,2,STONE)
Block(4,5,3,STONE)
Block(4,5,4,STONE)
Block(4,5,5,STONE)
Block(4,5,6,STONE)
Block(4,5,7,STONE)
Block(4,5,8,STONE)
Block(4,5,9,STONE)
Block(4,5,10,STONE)
Block(4,6,-8,STONE)
Block(4,6,-7,STONE)
Block(4,6,-6,STONE)
Block(4,6,-5,STONE)
Block(4,6,-4,STONE)
Block(4,6,-3,STONE)
Block(4,6,-2,STONE)
Block(4,6,-1,STONE)
Block(4,6,0,STONE)
Block(4,6,1,STONE)
Block(4,6,2,STONE)
Block(4,6,3,STONE)
Block(4,6,4,STONE)
Block(4,6,5,STONE)
Block(4,6,6,STONE)
Block(4,6,7,STONE)
Block(4,6,8,STONE)
Block(4,6,9,STONE)
Block(4,6,10,STONE)
Block(4,6,11,STONE)
Block(4,7,-9,STONE)
Block(4,7,-8,STONE)
Block(4,7,-7,STONE)
Block(4,7,-6,STONE)
Block(4,7,-5,STONE)
Block(4,7,-4,STONE)
Block(4,7,-3,STONE)
Block(4,7,-2,STONE)
Block(4,7,-1,STONE)
Block(4,7,0,STONE)
Block(4,7,1,STONE)
Block(4,7,2,STONE)
Block(4,7,3,STONE)
Block(4,7,4,STONE)
Block(4,7,5,STONE)
Block(4,7,6,STONE)
Block(4,7,7,STONE)
Block(4,7,8,STONE)
Block(4,7,9,STONE)
Block(4,7,10,STONE)
Block(4,7,11,STONE)
Block(4,8,-10,STONE)
Block(4,8,-9,STONE)
Block(4,8,-8,STONE)
Block(4,8,-7,STONE)
Block(4,8,-6,STONE)
Block(4,8,-5,STONE)
Block(4,8,-4,STONE)
Block(4,8,-3,STONE)
Block(4,8,-2,STONE)
Block(4,8,-1,STONE)
Block(4,8,0,STONE)
Block(4,8,1,STONE)
Block(4,8,2,STONE)
Block(4,8,3,STONE)
Block(4,8,4,STONE)
Block(4,8,5,STONE)
Block(4,8,6,STONE)
Block(4,8,7,STONE)
Block(4,8,8,STONE)
Block(4,8,9,STONE)
Block(4,8,10,STONE)
Block(4,8,11,STONE)
Block(4,9,-10,STONE)
Block(4,9,-9,STONE)
Block(4,9,-8,STONE)
Block(4,9,-7,STONE)
Block(4,9,-6,STONE)
Block(4,9,-5,STONE)
Block(4,9,-4,STONE)
Block(4,9,-3,STONE)
Block(4,9,-2,STONE)
Block(4,9,-1,STONE)
Block(4,9,0,STONE)
Block(4,9,1,STONE)
Block(4,9,2,STONE)
Block(4,9,3,STONE)
Block(4,9,4,STONE)
Block(4,9,5,STONE)
Block(4,9,6,STONE)
Block(4,9,7,STONE)
Block(4,9,8,STONE)
Block(4,9,9,STONE)
Block(4,9,10,STONE)
Block(4,9,11,STONE)
Block(4,10,-10,STONE)
Block(4,10,-9,STONE)
Block(4,10,-8,STONE)
Block(4,10,-7,STONE)
Block(4,10,-6,STONE)
Block(4,10,-5,STONE)
Block(4,10,-4,STONE)
Block(4,10,-3,STONE)
Block(4,10,-2,STONE)
Block(4,10,-1,STONE)
Block(4,10,0,STONE)
Block(4,10,1,STONE)
Block(4,10,2,STONE)
Block(4,10,3,STONE)
Block(4,10,4,STONE)
Block(4,10,5,STONE)
Block(4,10,6,STONE)
Block(4,10,7,STONE)
Block(4,10,8,STONE)
Block(4,10,9,STONE)
Block(4,10,10,STONE)
Block(4,10,11,STONE)
Block(4,10,12,STONE)
Block(4,11,-10,STONE)
Block(4,11,-9,STONE)
Block(4,11,-8,STONE)
Block(4,11,-7,STONE)
Block(4,11,-6,STONE)
Block(4,11,-5,STONE)
Block(4,11,-4,STONE)
Block(4,11,-3,STONE)
Block(4,11,-2,STONE)
Block(4,11,-1,STONE)
Block(4,11,0,STONE)
Block(4,11,1,STONE)
Block(4,11,2,STONE)
Block(4,11,3,STONE)
Block(4,11,4,STONE)
Block(4,11,5,STONE)
Block(4,11,6,STONE)
Block(4,11,7,STONE)
Block(4,11,8,STONE)
Block(4,11,9,STONE)
Block(4,11,10,STONE)
Block(4,11,11,STONE)
Block(4,11,12,STONE)
Block(4,12,-10,STONE)
Block(4,12,-9,STONE)
Block(4,12,-8,STONE)
Block(4,12,-7,STONE)
Block(4,12,-6,STONE)
Block(4,12,-5,STONE)
Block(4,12,-4,STONE)
Block(4,12,-3,STONE)
Block(4,12,-2,STONE)
Block(4,12,-1,STONE)
Block(4,12,0,STONE)
Block(4,12,1,STONE)
Block(4,12,2,STONE)
Block(4,12,3,STONE)
Block(4,12,4,STONE)
Block(4,12,5,STONE)
Block(4,12,6,STONE)
Block(4,12,7,STONE)
Block(4,12,8,STONE)
Block(4,12,9,STONE)
Block(4,12,10,STONE)
Block(4,12,11,STONE)
Block(4,12,12,STONE)
Block(4,12,13,STONE)
Block(4,13,-10,STONE)
Block(4,13,-9,STONE)
Block(4,13,-8,STONE)
Block(4,13,-7,STONE)
Block(4,13,-6,STONE)
Block(4,13,-5,STONE)
Block(4,13,-4,STONE)
Block(4,13,-3,STONE)
Block(4,13,-2,STONE)
Block(4,13,-1,STONE)
Block(4,13,0,STONE)
Block(4,13,1,STONE)
Block(4,13,2,STONE)
Block(4,13,3,STONE)
Block(4,13,4,STONE)
Block(4,13,5,STONE)
Block(4,13,6,STONE)
Block(4,13,7,STONE)
Block(4,13,8,STONE)
Block(4,13,9,STONE)
Block(4,13,10,STONE)
Block(4,13,11,STONE)
Block(4,13,12,STONE)
Block(4,13,13,STONE)
Block(4,14,-10,STONE)
Block(4,14,-9,STONE)
Block(4,14,-8,STONE)
Block(4,14,-7,STONE)
Block(4,14,-6,STONE)
Block(4,14,-5,STONE)
Block(4,14,-4,STONE)
Block(4,14,-3,STONE)
Block(4,14,-2,STONE)
Block(4,14,-1,STONE)
Block(4,14,0,STONE)
Block(4,14,1,STONE)
Block(4,14,2,STONE)
Block(4,14,3,STONE)
Block(4,14,4,STONE)
Block(4,14,5,STONE)
Block(4,14,6,STONE)
Block(4,14,7,STONE)
Block(4,14,8,STONE)
Block(4,14,9,STONE)
Block(4,14,10,STONE)
Block(4,14,11,STONE)
Block(4,14,12,STONE)
Block(4,14,13,STONE)
Block(4,14,14,STONE)
Block(4,15,-11,STONE)
Block(4,15,-10,STONE)
Block(4,15,-9,STONE)
Block(4,15,-8,STONE)
Block(4,15,-7,STONE)
Block(4,15,-6,STONE)
Block(4,15,-5,STONE)
Block(4,15,-4,STONE)
Block(4,15,-3,STONE)
Block(4,15,-2,STONE)
Block(4,15,-1,STONE)
Block(4,15,0,STONE)
Block(4,15,1,STONE)
Block(4,15,2,STONE)
Block(4,15,3,STONE)
Block(4,15,4,STONE)
Block(4,15,5,STONE)
Block(4,15,6,STONE)
Block(4,15,7,STONE)
Block(4,15,8,STONE)
Block(4,15,9,STONE)
Block(4,15,10,STONE)
Block(4,15,11,STONE)
Block(4,15,12,STONE)
Block(4,15,13,STONE)
Block(4,15,14,STONE)
Block(4,16,-11,STONE)
Block(4,16,-10,STONE)
Block(4,16,-9,STONE)
Block(4,16,-8,STONE)
Block(4,16,-7,STONE)
Block(4,16,-6,STONE)
Block(4,16,-5,STONE)
Block(4,16,-4,STONE)
Block(4,16,-3,STONE)
Block(4,16,-2,STONE)
Block(4,16,-1,STONE)
Block(4,16,0,STONE)
Block(4,16,1,STONE)
Block(4,16,2,STONE)
Block(4,16,3,STONE)
Block(4,16,4,STONE)
Block(4,16,5,STONE)
Block(4,16,6,STONE)
Block(4,16,7,STONE)
Block(4,16,8,STONE)
Block(4,16,9,STONE)
Block(4,16,10,STONE)
Block(4,16,11,STONE)
Block(4,16,12,STONE)
Block(4,16,13,STONE)
Block(4,16,14,STONE)
Block(4,17,-11,STONE)
Block(4,17,-10,STONE)
Block(4,17,-9,STONE)
Block(4,17,-8,STONE)
Block(4,17,-7,STONE)
Block(4,17,-6,STONE)
Block(4,17,-5,STONE)
Block(4,17,-4,STONE)
Block(4,17,-3,STONE)
Block(4,17,-2,STONE)
Block(4,17,-1,STONE)
Block(4,17,0,STONE)
Block(4,17,1,STONE)
Block(4,17,2,STONE)
Block(4,17,3,STONE)
Block(4,17,4,STONE)
Block(4,17,5,STONE)
Block(4,17,6,STONE)
Block(4,17,7,STONE)
Block(4,17,8,STONE)
Block(4,17,9,STONE)
Block(4,17,10,STONE)
Block(4,17,11,STONE)
Block(4,17,12,STONE)
Block(4,17,13,STONE)
Block(4,17,14,STONE)
Block(4,18,-11,STONE)
Block(4,18,-10,STONE)
Block(4,18,-9,STONE)
Block(4,18,-8,STONE)
Block(4,18,-7,STONE)
Block(4,18,-6,STONE)
Block(4,18,-5,STONE)
Block(4,18,-4,STONE)
Block(4,18,-3,STONE)
Block(4,18,-2,STONE)
Block(4,18,-1,STONE)
Block(4,18,0,STONE)
Block(4,18,1,STONE)
Block(4,18,2,STONE)
Block(4,18,3,STONE)
Block(4,18,4,STONE)
Block(4,18,5,STONE)
Block(4,18,6,STONE)
Block(4,18,7,STONE)
Block(4,18,8,STONE)
Block(4,18,9,STONE)
Block(4,18,10,STONE)
Block(4,18,11,STONE)
Block(4,18,12,STONE)
Block(4,18,13,STONE)
Block(4,19,-11,STONE)
Block(4,19,-10,STONE)
Block(4,19,-9,STONE)
Block(4,19,-8,STONE)
Block(4,19,-7,STONE)
Block(4,19,-6,STONE)
Block(4,19,-5,STONE)
Block(4,19,-4,STONE)
Block(4,19,-3,STONE)
Block(4,19,-2,STONE)
Block(4,19,-1,STONE)
Block(4,19,0,STONE)
Block(4,19,1,STONE)
Block(4,19,2,STONE)
Block(4,19,3,STONE)
Block(4,19,4,STONE)
Block(4,19,5,STONE)
Block(4,19,6,STONE)
Block(4,19,7,STONE)
Block(4,19,8,STONE)
Block(4,19,9,STONE)
Block(4,19,10,STONE)
Block(4,19,11,STONE)
Block(4,19,12,STONE)
Block(4,19,13,STONE)
Block(4,20,-11,STONE)
Block(4,20,-10,STONE)
Block(4,20,-9,STONE)
Block(4,20,-8,STONE)
Block(4,20,-7,STONE)
Block(4,20,-6,STONE)
Block(4,20,-5,STONE)
Block(4,20,-4,STONE)
Block(4,20,-3,STONE)
Block(4,20,-2,STONE)
Block(4,20,-1,STONE)
Block(4,20,0,STONE)
Block(4,20,1,STONE)
Block(4,20,2,STONE)
Block(4,20,3,STONE)
Block(4,20,4,STONE)
Block(4,20,5,STONE)
Block(4,20,6,STONE)
Block(4,20,7,STONE)
Block(4,20,8,STONE)
Block(4,20,9,STONE)
Block(4,20,10,STONE)
Block(4,20,11,STONE)
Block(4,20,12,STONE)
Block(4,20,13,STONE)
Block(4,21,-10,STONE)
Block(4,21,-9,STONE)
Block(4,21,-8,STONE)
Block(4,21,-7,STONE)
Block(4,21,-6,STONE)
Block(4,21,-5,STONE)
Block(4,21,-4,STONE)
Block(4,21,-3,STONE)
Block(4,21,-2,STONE)
Block(4,21,-1,STONE)
Block(4,21,0,STONE)
Block(4,21,1,STONE)
Block(4,21,2,STONE)
Block(4,21,3,STONE)
Block(4,21,4,STONE)
Block(4,21,5,STONE)
Block(4,21,6,STONE)
Block(4,21,7,STONE)
Block(4,21,8,STONE)
Block(4,21,9,STONE)
Block(4,21,10,STONE)
Block(4,21,11,STONE)
Block(4,21,12,STONE)
Block(4,21,13,STONE)
Block(4,22,-10,STONE)
Block(4,22,-9,STONE)
Block(4,22,-8,STONE)
Block(4,22,-7,STONE)
Block(4,22,-6,STONE)
Block(4,22,-5,STONE)
Block(4,22,-4,STONE)
Block(4,22,-3,STONE)
Block(4,22,-2,STONE)
Block(4,22,-1,STONE)
Block(4,22,0,STONE)
Block(4,22,1,STONE)
Block(4,22,2,STONE)
Block(4,22,3,STONE)
Block(4,22,4,STONE)
Block(4,22,5,STONE)
Block(4,22,6,STONE)
Block(4,22,7,STONE)
Block(4,22,8,STONE)
Block(4,22,9,STONE)
Block(4,22,10,STONE)
Block(4,22,11,STONE)
Block(4,22,12,STONE)
Block(4,22,13,STONE)
Block(4,23,-9,STONE)
Block(4,23,-8,STONE)
Block(4,23,-7,STONE)
Block(4,23,-6,STONE)
Block(4,23,-5,STONE)
Block(4,23,-4,STONE)
Block(4,23,-3,STONE)
Block(4,23,-2,STONE)
Block(4,23,-1,STONE)
Block(4,23,0,STONE)
Block(4,23,1,STONE)
Block(4,23,2,STONE)
Block(4,23,3,STONE)
Block(4,23,4,STONE)
Block(4,23,5,STONE)
Block(4,23,6,STONE)
Block(4,23,7,STONE)
Block(4,23,8,STONE)
Block(4,23,9,STONE)
Block(4,23,10,STONE)
Block(4,23,11,STONE)
Block(4,23,12,STONE)
Block(4,24,-8,STONE)
Block(4,24,-7,STONE)
Block(4,24,-6,STONE)
Block(4,24,-5,STONE)
Block(4,24,-4,STONE)
Block(4,24,-3,STONE)
Block(4,24,-2,STONE)
Block(4,24,-1,STONE)
Block(4,24,0,STONE)
Block(4,24,1,STONE)
Block(4,24,2,STONE)
Block(4,24,3,STONE)
Block(4,24,4,STONE)
Block(4,24,5,STONE)
Block(4,24,6,STONE)
Block(4,24,7,STONE)
Block(4,24,8,STONE)
Block(4,24,9,STONE)
Block(4,24,10,STONE)
Block(4,24,11,STONE)
Block(4,24,12,STONE)
Block(4,25,-7,STONE)
Block(4,25,-6,STONE)
Block(4,25,-5,STONE)
Block(4,25,-4,STONE)
Block(4,25,-3,STONE)
Block(4,25,-2,STONE)
Block(4,25,-1,STONE)
Block(4,25,0,STONE)
Block(4,25,1,STONE)
Block(4,25,2,STONE)
Block(4,25,3,STONE)
Block(4,25,4,STONE)
Block(4,25,5,STONE)
Block(4,25,6,STONE)
Block(4,25,7,STONE)
Block(4,25,8,STONE)
Block(4,25,9,STONE)
Block(4,25,10,STONE)
Block(4,25,11,STONE)
Block(4,26,-5,STONE)
Block(4,26,-4,STONE)
Block(4,26,-3,STONE)
Block(4,26,-2,STONE)
Block(4,26,-1,STONE)
Block(4,26,0,STONE)
Block(5,1,-3,STONE)
Block(5,1,-2,STONE)
Block(5,2,-4,STONE)
Block(5,2,-3,STONE)
Block(5,2,-2,STONE)
Block(5,2,-1,STONE)
Block(5,2,0,STONE)
Block(5,2,1,STONE)
Block(5,2,2,STONE)
Block(5,2,3,STONE)
Block(5,2,4,STONE)
Block(5,2,7,STONE)
Block(5,2,8,STONE)
Block(5,2,9,STONE)
Block(5,3,-5,STONE)
Block(5,3,-4,STONE)
Block(5,3,-3,STONE)
Block(5,3,-2,STONE)
Block(5,3,-1,STONE)
Block(5,3,0,STONE)
Block(5,3,1,STONE)
Block(5,3,2,STONE)
Block(5,3,3,STONE)
Block(5,3,4,STONE)
Block(5,3,5,STONE)
Block(5,3,6,STONE)
Block(5,3,7,STONE)
Block(5,3,8,STONE)
Block(5,3,9,STONE)
Block(5,3,10,STONE)
Block(5,4,-6,STONE)
Block(5,4,-5,STONE)
Block(5,4,-4,STONE)
Block(5,4,-3,STONE)
Block(5,4,-2,STONE)
Block(5,4,-1,STONE)
Block(5,4,0,STONE)
Block(5,4,1,STONE)
Block(5,4,2,STONE)
Block(5,4,3,STONE)
Block(5,4,4,STONE)
Block(5,4,5,STONE)
Block(5,4,6,STONE)
Block(5,4,7,STONE)
Block(5,4,8,STONE)
Block(5,4,9,STONE)
Block(5,4,10,STONE)
Block(5,5,-7,STONE)
Block(5,5,-6,STONE)
Block(5,5,-5,STONE)
Block(5,5,-4,STONE)
Block(5,5,-3,STONE)
Block(5,5,-2,STONE)
Block(5,5,-1,STONE)
Block(5,5,0,STONE)
Block(5,5,1,STONE)
Block(5,5,2,STONE)
Block(5,5,3,STONE)
Block(5,5,4,STONE)
Block(5,5,5,STONE)
Block(5,5,6,STONE)
Block(5,5,7,STONE)
Block(5,5,8,STONE)
Block(5,5,9,STONE)
Block(5,5,10,STONE)
Block(5,6,-8,STONE)
Block(5,6,-7,STONE)
Block(5,6,-6,STONE)
Block(5,6,-5,STONE)
Block(5,6,-4,STONE)
Block(5,6,-3,STONE)
Block(5,6,-2,STONE)
Block(5,6,-1,STONE)
Block(5,6,0,STONE)
Block(5,6,1,STONE)
Block(5,6,2,STONE)
Block(5,6,3,STONE)
Block(5,6,4,STONE)
Block(5,6,5,STONE)
Block(5,6,6,STONE)
Block(5,6,7,STONE)
Block(5,6,8,STONE)
Block(5,6,9,STONE)
Block(5,6,10,STONE)
Block(5,7,-9,STONE)
Block(5,7,-8,STONE)
Block(5,7,-7,STONE)
Block(5,7,-6,STONE)
Block(5,7,-5,STONE)
Block(5,7,-4,STONE)
Block(5,7,-3,STONE)
Block(5,7,-2,STONE)
Block(5,7,-1,STONE)
Block(5,7,0,STONE)
Block(5,7,1,STONE)
Block(5,7,2,STONE)
Block(5,7,3,STONE)
Block(5,7,4,STONE)
Block(5,7,5,STONE)
Block(5,7,6,STONE)
Block(5,7,7,STONE)
Block(5,7,8,STONE)
Block(5,7,9,STONE)
Block(5,7,10,STONE)
Block(5,8,-10,STONE)
Block(5,8,-9,STONE)
Block(5,8,-8,STONE)
Block(5,8,-7,STONE)
Block(5,8,-6,STONE)
Block(5,8,-5,STONE)
Block(5,8,-4,STONE)
Block(5,8,-3,STONE)
Block(5,8,-2,STONE)
Block(5,8,-1,STONE)
Block(5,8,0,STONE)
Block(5,8,1,STONE)
Block(5,8,2,STONE)
Block(5,8,3,STONE)
Block(5,8,4,STONE)
Block(5,8,5,STONE)
Block(5,8,6,STONE)
Block(5,8,7,STONE)
Block(5,8,8,STONE)
Block(5,8,9,STONE)
Block(5,8,10,STONE)
Block(5,8,11,STONE)
Block(5,9,-10,STONE)
Block(5,9,-9,STONE)
Block(5,9,-8,STONE)
Block(5,9,-7,STONE)
Block(5,9,-6,STONE)
Block(5,9,-5,STONE)
Block(5,9,-4,STONE)
Block(5,9,-3,STONE)
Block(5,9,-2,STONE)
Block(5,9,-1,STONE)
Block(5,9,0,STONE)
Block(5,9,1,STONE)
Block(5,9,2,STONE)
Block(5,9,3,STONE)
Block(5,9,4,STONE)
Block(5,9,5,STONE)
Block(5,9,6,STONE)
Block(5,9,7,STONE)
Block(5,9,8,STONE)
Block(5,9,9,STONE)
Block(5,9,10,STONE)
Block(5,9,11,STONE)
Block(5,10,-10,STONE)
Block(5,10,-9,STONE)
Block(5,10,-8,STONE)
Block(5,10,-7,STONE)
Block(5,10,-6,STONE)
Block(5,10,-5,STONE)
Block(5,10,-4,STONE)
Block(5,10,-3,STONE)
Block(5,10,-2,STONE)
Block(5,10,-1,STONE)
Block(5,10,0,STONE)
Block(5,10,1,STONE)
Block(5,10,2,STONE)
Block(5,10,3,STONE)
Block(5,10,4,STONE)
Block(5,10,5,STONE)
Block(5,10,6,STONE)
Block(5,10,7,STONE)
Block(5,10,8,STONE)
Block(5,10,9,STONE)
Block(5,10,10,STONE)
Block(5,10,11,STONE)
Block(5,11,-10,STONE)
Block(5,11,-9,STONE)
Block(5,11,-8,STONE)
Block(5,11,-7,STONE)
Block(5,11,-6,STONE)
Block(5,11,-5,STONE)
Block(5,11,-4,STONE)
Block(5,11,-3,STONE)
Block(5,11,-2,STONE)
Block(5,11,-1,STONE)
Block(5,11,0,STONE)
Block(5,11,1,STONE)
Block(5,11,2,STONE)
Block(5,11,3,STONE)
Block(5,11,4,STONE)
Block(5,11,5,STONE)
Block(5,11,6,STONE)
Block(5,11,7,STONE)
Block(5,11,8,STONE)
Block(5,11,9,STONE)
Block(5,11,10,STONE)
Block(5,11,11,STONE)
Block(5,11,12,STONE)
Block(5,12,-11,STONE)
Block(5,12,-10,STONE)
Block(5,12,-9,STONE)
Block(5,12,-8,STONE)
Block(5,12,-7,STONE)
Block(5,12,-6,STONE)
Block(5,12,-5,STONE)
Block(5,12,-4,STONE)
Block(5,12,-3,STONE)
Block(5,12,-2,STONE)
Block(5,12,-1,STONE)
Block(5,12,0,STONE)
Block(5,12,1,STONE)
Block(5,12,2,STONE)
Block(5,12,3,STONE)
Block(5,12,4,STONE)
Block(5,12,5,STONE)
Block(5,12,6,STONE)
Block(5,12,7,STONE)
Block(5,12,8,STONE)
Block(5,12,9,STONE)
Block(5,12,10,STONE)
Block(5,12,11,STONE)
Block(5,12,12,STONE)
Block(5,13,-11,STONE)
Block(5,13,-10,STONE)
Block(5,13,-9,STONE)
Block(5,13,-8,STONE)
Block(5,13,-7,STONE)
Block(5,13,-6,STONE)
Block(5,13,-5,STONE)
Block(5,13,-4,STONE)
Block(5,13,-3,STONE)
Block(5,13,-2,STONE)
Block(5,13,-1,STONE)
Block(5,13,0,STONE)
Block(5,13,1,STONE)
Block(5,13,2,STONE)
Block(5,13,3,STONE)
Block(5,13,4,STONE)
Block(5,13,5,STONE)
Block(5,13,6,STONE)
Block(5,13,7,STONE)
Block(5,13,8,STONE)
Block(5,13,9,STONE)
Block(5,13,10,STONE)
Block(5,13,11,STONE)
Block(5,13,12,STONE)
Block(5,13,13,STONE)
Block(5,14,-11,STONE)
Block(5,14,-10,STONE)
Block(5,14,-9,STONE)
Block(5,14,-8,STONE)
Block(5,14,-7,STONE)
Block(5,14,-6,STONE)
Block(5,14,-5,STONE)
Block(5,14,-4,STONE)
Block(5,14,-3,STONE)
Block(5,14,-2,STONE)
Block(5,14,-1,STONE)
Block(5,14,0,STONE)
Block(5,14,1,STONE)
Block(5,14,2,STONE)
Block(5,14,3,STONE)
Block(5,14,4,STONE)
Block(5,14,5,STONE)
Block(5,14,6,STONE)
Block(5,14,7,STONE)
Block(5,14,8,STONE)
Block(5,14,9,STONE)
Block(5,14,10,STONE)
Block(5,14,11,STONE)
Block(5,14,12,STONE)
Block(5,14,13,STONE)
Block(5,15,-11,STONE)
Block(5,15,-10,STONE)
Block(5,15,-9,STONE)
Block(5,15,-8,STONE)
Block(5,15,-7,STONE)
Block(5,15,-6,STONE)
Block(5,15,-5,STONE)
Block(5,15,-4,STONE)
Block(5,15,-3,STONE)
Block(5,15,-2,STONE)
Block(5,15,-1,STONE)
Block(5,15,0,STONE)
Block(5,15,1,STONE)
Block(5,15,2,STONE)
Block(5,15,3,STONE)
Block(5,15,4,STONE)
Block(5,15,5,STONE)
Block(5,15,6,STONE)
Block(5,15,7,STONE)
Block(5,15,8,STONE)
Block(5,15,9,STONE)
Block(5,15,10,STONE)
Block(5,15,11,STONE)
Block(5,15,12,STONE)
Block(5,15,13,STONE)
Block(5,15,14,STONE)
Block(5,16,-11,STONE)
Block(5,16,-10,STONE)
Block(5,16,-9,STONE)
Block(5,16,-8,STONE)
Block(5,16,-7,STONE)
Block(5,16,-6,STONE)
Block(5,16,-5,STONE)
Block(5,16,-4,STONE)
Block(5,16,-3,STONE)
Block(5,16,-2,STONE)
Block(5,16,-1,STONE)
Block(5,16,0,STONE)
Block(5,16,1,STONE)
Block(5,16,2,STONE)
Block(5,16,3,STONE)
Block(5,16,4,STONE)
Block(5,16,5,STONE)
Block(5,16,6,STONE)
Block(5,16,7,STONE)
Block(5,16,8,STONE)
Block(5,16,9,STONE)
Block(5,16,10,STONE)
Block(5,16,11,STONE)
Block(5,16,12,STONE)
Block(5,16,13,STONE)
Block(5,16,14,STONE)
Block(5,17,-11,STONE)
Block(5,17,-10,STONE)
Block(5,17,-9,STONE)
Block(5,17,-8,STONE)
Block(5,17,-7,STONE)
Block(5,17,-6,STONE)
Block(5,17,-5,STONE)
Block(5,17,-4,STONE)
Block(5,17,-3,STONE)
Block(5,17,-2,STONE)
Block(5,17,-1,STONE)
Block(5,17,0,STONE)
Block(5,17,1,STONE)
Block(5,17,2,STONE)
Block(5,17,3,STONE)
Block(5,17,4,STONE)
Block(5,17,5,STONE)
Block(5,17,6,STONE)
Block(5,17,7,STONE)
Block(5,17,8,STONE)
Block(5,17,9,STONE)
Block(5,17,10,STONE)
Block(5,17,11,STONE)
Block(5,17,12,STONE)
Block(5,17,13,STONE)
Block(5,17,14,STONE)
Block(5,18,-11,STONE)
Block(5,18,-10,STONE)
Block(5,18,-9,STONE)
Block(5,18,-8,STONE)
Block(5,18,-7,STONE)
Block(5,18,-6,STONE)
Block(5,18,-5,STONE)
Block(5,18,-4,STONE)
Block(5,18,-3,STONE)
Block(5,18,-2,STONE)
Block(5,18,-1,STONE)
Block(5,18,0,STONE)
Block(5,18,1,STONE)
Block(5,18,2,STONE)
Block(5,18,3,STONE)
Block(5,18,4,STONE)
Block(5,18,5,STONE)
Block(5,18,6,STONE)
Block(5,18,7,STONE)
Block(5,18,8,STONE)
Block(5,18,9,STONE)
Block(5,18,10,STONE)
Block(5,18,11,STONE)
Block(5,18,12,STONE)
Block(5,18,13,STONE)
Block(5,18,14,STONE)
Block(5,19,-11,STONE)
Block(5,19,-10,STONE)
Block(5,19,-9,STONE)
Block(5,19,-8,STONE)
Block(5,19,-7,STONE)
Block(5,19,-6,STONE)
Block(5,19,-5,STONE)
Block(5,19,-4,STONE)
Block(5,19,-3,STONE)
Block(5,19,-2,STONE)
Block(5,19,-1,STONE)
Block(5,19,0,STONE)
Block(5,19,1,STONE)
Block(5,19,2,STONE)
Block(5,19,3,STONE)
Block(5,19,4,STONE)
Block(5,19,5,STONE)
Block(5,19,6,STONE)
Block(5,19,7,STONE)
Block(5,19,8,STONE)
Block(5,19,9,STONE)
Block(5,19,10,STONE)
Block(5,19,11,STONE)
Block(5,19,12,STONE)
Block(5,19,13,STONE)
Block(5,19,14,STONE)
Block(5,20,-11,STONE)
Block(5,20,-10,STONE)
Block(5,20,-9,STONE)
Block(5,20,-8,STONE)
Block(5,20,-7,STONE)
Block(5,20,-6,STONE)
Block(5,20,-5,STONE)
Block(5,20,-4,STONE)
Block(5,20,-3,STONE)
Block(5,20,-2,STONE)
Block(5,20,-1,STONE)
Block(5,20,0,STONE)
Block(5,20,1,STONE)
Block(5,20,2,STONE)
Block(5,20,3,STONE)
Block(5,20,4,STONE)
Block(5,20,5,STONE)
Block(5,20,6,STONE)
Block(5,20,7,STONE)
Block(5,20,8,STONE)
Block(5,20,9,STONE)
Block(5,20,10,STONE)
Block(5,20,11,STONE)
Block(5,20,12,STONE)
Block(5,20,13,STONE)
Block(5,20,14,STONE)
Block(5,21,-11,STONE)
Block(5,21,-10,STONE)
Block(5,21,-9,STONE)
Block(5,21,-8,STONE)
Block(5,21,-7,STONE)
Block(5,21,-6,STONE)
Block(5,21,-5,STONE)
Block(5,21,-4,STONE)
Block(5,21,-3,STONE)
Block(5,21,-2,STONE)
Block(5,21,-1,STONE)
Block(5,21,0,STONE)
Block(5,21,1,STONE)
Block(5,21,2,STONE)
Block(5,21,3,STONE)
Block(5,21,4,STONE)
Block(5,21,5,STONE)
Block(5,21,6,STONE)
Block(5,21,7,STONE)
Block(5,21,8,STONE)
Block(5,21,9,STONE)
Block(5,21,10,STONE)
Block(5,21,11,STONE)
Block(5,21,12,STONE)
Block(5,21,13,STONE)
Block(5,22,-10,STONE)
Block(5,22,-9,STONE)
Block(5,22,-8,STONE)
Block(5,22,-7,STONE)
Block(5,22,-6,STONE)
Block(5,22,-5,STONE)
Block(5,22,-4,STONE)
Block(5,22,-3,STONE)
Block(5,22,-2,STONE)
Block(5,22,-1,STONE)
Block(5,22,0,STONE)
Block(5,22,1,STONE)
Block(5,22,2,STONE)
Block(5,22,3,STONE)
Block(5,22,4,STONE)
Block(5,22,5,STONE)
Block(5,22,6,STONE)
Block(5,22,7,STONE)
Block(5,22,8,STONE)
Block(5,22,9,STONE)
Block(5,22,10,STONE)
Block(5,22,11,STONE)
Block(5,22,12,STONE)
Block(5,22,13,STONE)
Block(5,23,-9,STONE)
Block(5,23,-8,STONE)
Block(5,23,-7,STONE)
Block(5,23,-6,STONE)
Block(5,23,-5,STONE)
Block(5,23,-4,STONE)
Block(5,23,-3,STONE)
Block(5,23,-2,STONE)
Block(5,23,-1,STONE)
Block(5,23,0,STONE)
Block(5,23,1,STONE)
Block(5,23,2,STONE)
Block(5,23,3,STONE)
Block(5,23,4,STONE)
Block(5,23,5,STONE)
Block(5,23,6,STONE)
Block(5,23,7,STONE)
Block(5,23,8,STONE)
Block(5,23,9,STONE)
Block(5,23,10,STONE)
Block(5,23,11,STONE)
Block(5,23,12,STONE)
Block(5,23,13,STONE)
Block(5,24,-8,STONE)
Block(5,24,-7,STONE)
Block(5,24,-6,STONE)
Block(5,24,-5,STONE)
Block(5,24,-4,STONE)
Block(5,24,-3,STONE)
Block(5,24,-2,STONE)
Block(5,24,-1,STONE)
Block(5,24,0,STONE)
Block(5,24,1,STONE)
Block(5,24,2,STONE)
Block(5,24,3,STONE)
Block(5,24,4,STONE)
Block(5,24,5,STONE)
Block(5,24,6,STONE)
Block(5,24,7,STONE)
Block(5,24,8,STONE)
Block(5,24,9,STONE)
Block(5,24,10,STONE)
Block(5,24,11,STONE)
Block(5,24,12,STONE)
Block(5,25,-6,STONE)
Block(5,25,-5,STONE)
Block(5,25,-4,STONE)
Block(5,25,-3,STONE)
Block(5,25,-2,STONE)
Block(5,25,-1,STONE)
Block(5,25,0,STONE)
