#######################################################################
# +-----------------------------------------------------------------+ #
# |                            BO3 object                           | #
# +-----------------------------------------------------------------+ #
#######################################################################

# This is the config file of a custom object.
# If you add this object correctly to your BiomeConfigs, it will spawn in the world.

# This is the creator of this BO3 object
Author: BO3 BulkEdit (by LanToaster)

# A short description of this BO3 object
Description: This Object was Created with BO3_BulkEdit

# The BO3 version, don't change this! It can be used by external applications to do a version check.
Version: 3

# The settings mode, WriteAll, WriteWithoutComments or WriteDisable. See WorldConfig.
SettingsMode: WriteDisable


#######################################################################
# +-----------------------------------------------------------------+ #
# |                          Main settings                          | #
# +-----------------------------------------------------------------+ #
#######################################################################

# This needs to be set to true to spawn the object in the Tree and Sapling resources.
Tree: true

# The frequency of the BO3 from 1 to 200. Tries this many times to spawn this BO3 when using the CustomObject(...) resource.
# Ignored by Tree(..), Sapling(..) and CustomStructure(..)
Frequency: 1

# The rarity of the BO3 from 0 to 100. Each spawn attempt has rarity% chance to succeed when using the CustomObject(...) resource.
# Ignored by Tree(..), Sapling(..) and CustomStructure(..)
Rarity: 100.0

# If you set this to true, the BO3 will be placed with a random rotation.
RotateRandomly: true

# The spawn height of the BO3 - randomY, highestBlock or highestSolidBlock.
SpawnHeight: highestSolidBlock
SpawnHeightOffset: -1
# The height limits for the BO3.
MinHeight: 0

MaxHeight: 256

# Objects can have other objects attacthed to it: branches. Branches can also
# have branches attached to it, which can also have branches, etc. This is the
# maximum branch depth for this objects.
MaxBranchDepth: 10

# When spawned with the UseWorld keyword, this BO3 should NOT spawn in the following biomes.
# If you writer.write the BO3 name directly in the BiomeConfigs, this will be ignored.
ExcludedBiomes: All


#######################################################################
# +-----------------------------------------------------------------+ #
# |                      Source block settings                      | #
# +-----------------------------------------------------------------+ #
#######################################################################

# The block(s) the BO3 should spawn in.
SourceBlocks: AIR,GRASS,STONE,SAND,GRAVEL,DIRT,174,SNOW_BLOCK,SNOW,174

# The maximum percentage of the BO3 that can be outside the SourceBlock.
# The BO3 won't be placed on a location with more blocks outside the SourceBlock than this percentage.
MaxPercentageOutsideSourceBlock: 0

# What to do when a block is about to be placed outside the SourceBlock? (dontPlace, placeAnyway)
OutsideSourceBlock: dontPlace


#######################################################################
# +-----------------------------------------------------------------+ #
# |                              Blocks                             | #
# +-----------------------------------------------------------------+ #
#######################################################################

# All the blocks used in the BO3 are listed here. Possible blocks:
# Block(x,y,z,id[.data][,nbtfile.nbt)
# RandomBlock(x,y,z,id[:data][,nbtfile.nbt],chance[,id[:data][,nbtfile.nbt],chance[,...]])
# So RandomBlock(0,0,0,CHEST,chest.nbt,50,CHEST,anotherchest.nbt,100) will spawn a chest at
# the BO3 origin, and give it a 50% chance to have the contents of chest.nbt, or, if that
# fails, a 100% percent chance to have the contents of anotherchest.nbt.
Block(1,0,-2,ICE)
Block(2,0,-2,ICE)
Block(3,0,-2,ICE)
Block(0,0,-1,ICE)
Block(1,0,-1,ICE)
Block(2,0,-1,ICE)
Block(3,0,-1,ICE)
Block(4,0,-1,ICE)
Block(5,0,-1,ICE)
Block(6,0,-1,ICE)
Block(0,0,0,ICE)
Block(1,0,0,ICE)
Block(2,0,0,ICE)
Block(3,0,0,ICE)
Block(4,0,0,ICE)
Block(5,0,0,ICE)
Block(6,0,0,ICE)
Block(7,0,0,ICE)
Block(-2,0,1,ICE)
Block(-1,0,1,ICE)
Block(0,0,1,ICE)
Block(1,0,1,ICE)
Block(2,0,1,ICE)
Block(3,0,1,ICE)
Block(4,0,1,ICE)
Block(5,0,1,ICE)
Block(6,0,1,ICE)
Block(7,0,1,ICE)
Block(0,0,2,ICE)
Block(1,0,2,ICE)
Block(2,0,2,ICE)
Block(3,0,2,ICE)
Block(4,0,2,ICE)
Block(5,0,2,ICE)
Block(6,0,2,ICE)
Block(7,0,2,ICE)
Block(0,0,3,ICE)
Block(1,0,3,ICE)
Block(2,0,3,ICE)
Block(3,0,3,ICE)
Block(4,0,3,ICE)
Block(5,0,3,ICE)
Block(6,0,3,ICE)
Block(0,0,4,ICE)
Block(1,0,4,ICE)
Block(2,0,4,ICE)
Block(3,0,4,ICE)
Block(4,0,4,ICE)
Block(5,0,4,ICE)
Block(6,0,4,ICE)
Block(0,0,5,ICE)
Block(1,0,5,ICE)
Block(2,0,5,ICE)
Block(3,0,5,ICE)
Block(4,0,5,ICE)
Block(5,0,5,ICE)
Block(1,0,6,ICE)
Block(2,0,6,ICE)
Block(3,0,6,ICE)
Block(3,1,-3,ICE)
Block(1,1,-2,ICE)
Block(2,1,-2,ICE)
Block(3,1,-2,ICE)
Block(0,1,-1,ICE)
Block(1,1,-1,ICE)
Block(2,1,-1,ICE)
Block(3,1,-1,ICE)
Block(4,1,-1,ICE)
Block(0,1,0,ICE)
Block(1,1,0,ICE)
Block(2,1,0,ICE)
Block(3,1,0,ICE)
Block(4,1,0,ICE)
Block(5,1,0,ICE)
Block(6,1,0,ICE)
Block(-2,1,1,ICE)
Block(-1,1,1,ICE)
Block(0,1,1,ICE)
Block(1,1,1,ICE)
Block(2,1,1,ICE)
Block(3,1,1,ICE)
Block(4,1,1,ICE)
Block(5,1,1,ICE)
Block(6,1,1,ICE)
Block(7,1,1,ICE)
Block(-1,1,2,ICE)
Block(0,1,2,ICE)
Block(1,1,2,ICE)
Block(2,1,2,ICE)
Block(3,1,2,ICE)
Block(4,1,2,ICE)
Block(5,1,2,ICE)
Block(6,1,2,ICE)
Block(0,1,3,ICE)
Block(1,1,3,ICE)
Block(2,1,3,ICE)
Block(3,1,3,ICE)
Block(4,1,3,ICE)
Block(5,1,3,ICE)
Block(6,1,3,ICE)
Block(1,1,4,ICE)
Block(2,1,4,ICE)
Block(3,1,4,ICE)
Block(4,1,4,ICE)
Block(5,1,4,ICE)
Block(6,1,4,ICE)
Block(1,1,5,ICE)
Block(2,1,5,ICE)
Block(3,1,5,ICE)
Block(4,1,5,ICE)
Block(5,1,5,ICE)
Block(3,1,6,ICE)
Block(3,2,-3,ICE)
Block(1,2,-2,ICE)
Block(2,2,-2,ICE)
Block(3,2,-2,ICE)
Block(4,2,-2,ICE)
Block(1,2,-1,ICE)
Block(2,2,-1,ICE)
Block(3,2,-1,ICE)
Block(4,2,-1,ICE)
Block(5,2,-1,ICE)
Block(-1,2,0,ICE)
Block(0,2,0,ICE)
Block(1,2,0,ICE)
Block(2,2,0,ICE)
Block(3,2,0,ICE)
Block(4,2,0,ICE)
Block(5,2,0,ICE)
Block(6,2,0,ICE)
Block(-1,2,1,ICE)
Block(0,2,1,ICE)
Block(1,2,1,ICE)
Block(2,2,1,ICE)
Block(3,2,1,ICE)
Block(4,2,1,ICE)
Block(5,2,1,ICE)
Block(6,2,1,ICE)
Block(-1,2,2,ICE)
Block(0,2,2,ICE)
Block(1,2,2,ICE)
Block(2,2,2,ICE)
Block(3,2,2,ICE)
Block(4,2,2,ICE)
Block(5,2,2,ICE)
Block(6,2,2,ICE)
Block(0,2,3,ICE)
Block(1,2,3,ICE)
Block(2,2,3,ICE)
Block(3,2,3,ICE)
Block(4,2,3,ICE)
Block(5,2,3,ICE)
Block(1,2,4,ICE)
Block(2,2,4,ICE)
Block(3,2,4,ICE)
Block(4,2,4,ICE)
Block(5,2,4,ICE)
Block(2,2,5,ICE)
Block(3,2,5,ICE)
Block(4,2,5,ICE)
Block(3,2,6,ICE)
Block(2,3,-3,ICE)
Block(3,3,-3,ICE)
Block(2,3,-2,ICE)
Block(3,3,-2,ICE)
Block(4,3,-2,ICE)
Block(1,3,-1,ICE)
Block(2,3,-1,ICE)
Block(3,3,-1,ICE)
Block(4,3,-1,ICE)
Block(5,3,-1,ICE)
Block(-1,3,0,ICE)
Block(0,3,0,ICE)
Block(1,3,0,ICE)
Block(2,3,0,ICE)
Block(3,3,0,ICE)
Block(4,3,0,ICE)
Block(5,3,0,ICE)
Block(6,3,0,ICE)
Block(-1,3,1,ICE)
Block(0,3,1,ICE)
Block(1,3,1,ICE)
Block(2,3,1,ICE)
Block(3,3,1,ICE)
Block(4,3,1,ICE)
Block(5,3,1,ICE)
Block(6,3,1,ICE)
Block(7,3,1,ICE)
Block(-1,3,2,ICE)
Block(0,3,2,ICE)
Block(1,3,2,ICE)
Block(2,3,2,ICE)
Block(3,3,2,ICE)
Block(4,3,2,ICE)
Block(5,3,2,ICE)
Block(-1,3,3,ICE)
Block(0,3,3,ICE)
Block(1,3,3,ICE)
Block(2,3,3,ICE)
Block(3,3,3,ICE)
Block(4,3,3,ICE)
Block(1,3,4,ICE)
Block(2,3,4,ICE)
Block(3,3,4,ICE)
Block(4,3,4,ICE)
Block(5,3,4,ICE)
Block(2,3,5,ICE)
Block(3,3,5,ICE)
Block(4,3,5,ICE)
Block(5,3,5,ICE)
Block(2,3,6,ICE)
Block(3,3,6,ICE)
Block(4,3,6,ICE)
Block(2,4,-3,ICE)
Block(3,4,-3,ICE)
Block(4,4,-3,ICE)
Block(2,4,-2,ICE)
Block(3,4,-2,ICE)
Block(4,4,-2,ICE)
Block(5,4,-2,ICE)
Block(2,4,-1,ICE)
Block(3,4,-1,ICE)
Block(4,4,-1,ICE)
Block(5,4,-1,ICE)
Block(0,4,0,ICE)
Block(1,4,0,ICE)
Block(2,4,0,ICE)
Block(3,4,0,ICE)
Block(4,4,0,ICE)
Block(5,4,0,ICE)
Block(6,4,0,ICE)
Block(-1,4,1,ICE)
Block(0,4,1,ICE)
Block(1,4,1,ICE)
Block(2,4,1,ICE)
Block(3,4,1,ICE)
Block(4,4,1,ICE)
Block(5,4,1,ICE)
Block(6,4,1,ICE)
Block(7,4,1,ICE)
Block(-2,4,2,ICE)
Block(-1,4,2,ICE)
Block(0,4,2,ICE)
Block(1,4,2,ICE)
Block(2,4,2,ICE)
Block(3,4,2,ICE)
Block(4,4,2,ICE)
Block(5,4,2,ICE)
Block(-2,4,3,ICE)
Block(-1,4,3,ICE)
Block(0,4,3,ICE)
Block(1,4,3,ICE)
Block(2,4,3,ICE)
Block(3,4,3,ICE)
Block(-1,4,4,ICE)
Block(1,4,4,ICE)
Block(2,4,4,ICE)
Block(3,4,4,ICE)
Block(4,4,4,ICE)
Block(5,4,4,ICE)
Block(1,4,5,ICE)
Block(2,4,5,ICE)
Block(3,4,5,ICE)
Block(4,4,5,ICE)
Block(5,4,5,ICE)
Block(2,4,6,ICE)
Block(3,4,6,ICE)
Block(4,4,6,ICE)
Block(3,4,7,ICE)
Block(4,5,-4,ICE)
Block(3,5,-3,ICE)
Block(4,5,-3,ICE)
Block(5,5,-3,ICE)
Block(2,5,-2,ICE)
Block(3,5,-2,ICE)
Block(4,5,-2,ICE)
Block(5,5,-2,ICE)
Block(3,5,-1,ICE)
Block(4,5,-1,ICE)
Block(5,5,-1,ICE)
Block(0,5,0,ICE)
Block(2,5,0,ICE)
Block(3,5,0,ICE)
Block(4,5,0,ICE)
Block(5,5,0,ICE)
Block(6,5,0,ICE)
Block(-1,5,1,ICE)
Block(0,5,1,ICE)
Block(1,5,1,ICE)
Block(2,5,1,ICE)
Block(3,5,1,ICE)
Block(4,5,1,ICE)
Block(5,5,1,ICE)
Block(6,5,1,ICE)
Block(7,5,1,ICE)
Block(8,5,1,ICE)
Block(-2,5,2,ICE)
Block(-1,5,2,ICE)
Block(0,5,2,ICE)
Block(1,5,2,ICE)
Block(2,5,2,ICE)
Block(5,5,2,ICE)
Block(6,5,2,ICE)
Block(-3,5,3,ICE)
Block(-2,5,3,ICE)
Block(-1,5,3,ICE)
Block(0,5,3,ICE)
Block(1,5,3,ICE)
Block(2,5,3,ICE)
Block(-2,5,4,ICE)
Block(-1,5,4,ICE)
Block(1,5,4,ICE)
Block(2,5,4,ICE)
Block(3,5,4,ICE)
Block(4,5,4,ICE)
Block(1,5,5,ICE)
Block(2,5,5,ICE)
Block(3,5,5,ICE)
Block(4,5,5,ICE)
Block(5,5,5,ICE)
Block(2,5,6,ICE)
Block(3,5,6,ICE)
Block(4,5,6,ICE)
Block(5,5,6,ICE)
Block(3,5,7,ICE)
Block(4,6,-4,ICE)
Block(5,6,-4,ICE)
Block(3,6,-3,ICE)
Block(4,6,-3,ICE)
Block(5,6,-3,ICE)
Block(3,6,-2,ICE)
Block(4,6,-2,ICE)
Block(5,6,-2,ICE)
Block(4,6,-1,ICE)
Block(4,6,0,ICE)
Block(5,6,0,ICE)
Block(6,6,0,ICE)
Block(7,6,0,ICE)
Block(-2,6,1,ICE)
Block(-1,6,1,ICE)
Block(0,6,1,ICE)
Block(1,6,1,ICE)
Block(5,6,1,ICE)
Block(6,6,1,ICE)
Block(7,6,1,ICE)
Block(8,6,1,ICE)
Block(-2,6,2,ICE)
Block(-1,6,2,ICE)
Block(0,6,2,ICE)
Block(1,6,2,ICE)
Block(5,6,2,ICE)
Block(6,6,2,ICE)
Block(-3,6,3,ICE)
Block(-2,6,3,ICE)
Block(-1,6,3,ICE)
Block(0,6,3,ICE)
Block(-3,6,4,ICE)
Block(-2,6,4,ICE)
Block(-1,6,4,ICE)
Block(0,6,4,ICE)
Block(1,6,4,ICE)
Block(3,6,4,ICE)
Block(1,6,5,ICE)
Block(2,6,5,ICE)
Block(3,6,5,ICE)
Block(4,6,5,ICE)
Block(1,6,6,ICE)
Block(2,6,6,ICE)
Block(3,6,6,ICE)
Block(4,6,6,ICE)
Block(5,6,6,ICE)
Block(2,6,7,ICE)
Block(3,6,7,ICE)
Block(4,6,7,ICE)
Block(4,7,-5,ICE)
Block(5,7,-5,ICE)
Block(3,7,-4,ICE)
Block(4,7,-4,ICE)
Block(5,7,-4,ICE)
Block(6,7,-4,ICE)
Block(3,7,-3,ICE)
Block(4,7,-3,ICE)
Block(5,7,-3,ICE)
Block(4,7,-2,ICE)
Block(5,7,0,ICE)
Block(6,7,0,ICE)
Block(7,7,0,ICE)
Block(5,7,1,ICE)
Block(6,7,1,ICE)
Block(7,7,1,ICE)
Block(8,7,1,ICE)
Block(-3,7,2,ICE)
Block(-2,7,2,ICE)
Block(-1,7,2,ICE)
Block(0,7,2,ICE)
Block(5,7,2,ICE)
Block(6,7,2,ICE)
Block(7,7,2,ICE)
Block(-3,7,3,ICE)
Block(-2,7,3,ICE)
Block(-1,7,3,ICE)
Block(0,7,3,ICE)
Block(-4,7,4,ICE)
Block(-3,7,4,ICE)
Block(-2,7,4,ICE)
Block(-1,7,4,ICE)
Block(3,7,4,ICE)
Block(-3,7,5,ICE)
Block(2,7,5,ICE)
Block(3,7,5,ICE)
Block(4,7,5,ICE)
Block(1,7,6,ICE)
Block(2,7,6,ICE)
Block(3,7,6,ICE)
Block(4,7,6,ICE)
Block(5,7,6,ICE)
Block(2,7,7,ICE)
Block(3,7,7,ICE)
Block(4,7,7,ICE)
Block(3,7,8,ICE)
Block(5,8,-6,ICE)
Block(4,8,-5,ICE)
Block(5,8,-5,ICE)
Block(6,8,-5,ICE)
Block(3,8,-4,ICE)
Block(4,8,-4,ICE)
Block(5,8,-4,ICE)
Block(6,8,-4,ICE)
Block(4,8,-3,ICE)
Block(5,8,-3,ICE)
Block(6,8,0,ICE)
Block(7,8,0,ICE)
Block(8,8,0,ICE)
Block(5,8,1,ICE)
Block(6,8,1,ICE)
Block(7,8,1,ICE)
Block(8,8,1,ICE)
Block(-2,8,2,ICE)
Block(5,8,2,ICE)
Block(6,8,2,ICE)
Block(7,8,2,ICE)
Block(-4,8,3,ICE)
Block(-3,8,3,ICE)
Block(-2,8,3,ICE)
Block(-1,8,3,ICE)
Block(-5,8,4,ICE)
Block(-4,8,4,ICE)
Block(-3,8,4,ICE)
Block(-2,8,4,ICE)
Block(-4,8,5,ICE)
Block(-3,8,5,ICE)
Block(-2,8,5,ICE)
Block(3,8,5,ICE)
Block(2,8,6,ICE)
Block(3,8,6,ICE)
Block(4,8,6,ICE)
Block(2,8,7,ICE)
Block(3,8,7,ICE)
Block(4,8,7,ICE)
Block(3,8,8,ICE)
Block(4,8,8,ICE)
Block(5,9,-7,ICE)
Block(5,9,-6,ICE)
Block(6,9,-6,ICE)
Block(4,9,-5,ICE)
Block(5,9,-5,ICE)
Block(6,9,-5,ICE)
Block(4,9,-4,ICE)
Block(5,9,-4,ICE)
Block(6,9,-4,ICE)
Block(5,9,-3,ICE)
Block(6,9,0,ICE)
Block(7,9,0,ICE)
Block(8,9,0,ICE)
Block(5,9,1,ICE)
Block(6,9,1,ICE)
Block(7,9,1,ICE)
Block(8,9,1,ICE)
Block(9,9,1,ICE)
Block(6,9,2,ICE)
Block(7,9,2,ICE)
Block(8,9,2,ICE)
Block(-5,9,3,ICE)
Block(-4,9,3,ICE)
Block(-3,9,3,ICE)
Block(-2,9,3,ICE)
Block(-5,9,4,ICE)
Block(-4,9,4,ICE)
Block(-3,9,4,ICE)
Block(-2,9,4,ICE)
Block(-6,9,5,ICE)
Block(-5,9,5,ICE)
Block(-4,9,5,ICE)
Block(-3,9,5,ICE)
Block(-5,9,6,ICE)
Block(2,9,6,ICE)
Block(3,9,6,ICE)
Block(4,9,6,ICE)
Block(2,9,7,ICE)
Block(3,9,7,ICE)
Block(4,9,7,ICE)
Block(2,9,8,ICE)
Block(3,9,8,ICE)
Block(4,9,8,ICE)
Block(5,10,-7,ICE)
Block(6,10,-7,ICE)
Block(4,10,-6,ICE)
Block(5,10,-6,ICE)
Block(6,10,-6,ICE)
Block(4,10,-5,ICE)
Block(5,10,-5,ICE)
Block(6,10,-5,ICE)
Block(5,10,-4,ICE)
Block(6,10,0,ICE)
Block(7,10,0,ICE)
Block(8,10,0,ICE)
Block(6,10,1,ICE)
Block(7,10,1,ICE)
Block(8,10,1,ICE)
Block(9,10,1,ICE)
Block(6,10,2,ICE)
Block(7,10,2,ICE)
Block(8,10,2,ICE)
Block(-4,10,3,ICE)
Block(-6,10,4,ICE)
Block(-5,10,4,ICE)
Block(-4,10,4,ICE)
Block(-3,10,4,ICE)
Block(-7,10,5,ICE)
Block(-6,10,5,ICE)
Block(-5,10,5,ICE)
Block(-4,10,5,ICE)
Block(-6,10,6,ICE)
Block(-5,10,6,ICE)
Block(-4,10,6,ICE)
Block(3,10,6,ICE)
Block(2,10,7,ICE)
Block(3,10,7,ICE)
Block(4,10,7,ICE)
Block(3,10,8,ICE)
Block(5,11,-7,ICE)
Block(6,11,-7,ICE)
Block(4,11,-6,ICE)
Block(5,11,-6,ICE)
Block(6,11,-6,ICE)
Block(5,11,-5,ICE)
Block(7,11,0,ICE)
Block(8,11,0,ICE)
Block(6,11,1,ICE)
Block(7,11,1,ICE)
Block(8,11,1,ICE)
Block(9,11,1,ICE)
Block(7,11,2,ICE)
Block(8,11,2,ICE)
Block(-6,11,4,ICE)
Block(-5,11,4,ICE)
Block(-4,11,4,ICE)
Block(-7,11,5,ICE)
Block(-6,11,5,ICE)
Block(-5,11,5,ICE)
Block(-4,11,5,ICE)
Block(-7,11,6,ICE)
Block(-6,11,6,ICE)
Block(-5,11,6,ICE)
Block(3,11,7,ICE)
Block(3,11,8,ICE)
Block(5,12,-8,ICE)
Block(6,12,-8,ICE)
Block(5,12,-7,ICE)
Block(6,12,-7,ICE)
Block(5,12,-6,ICE)
Block(7,12,0,ICE)
Block(8,12,0,ICE)
Block(9,12,0,ICE)
Block(6,12,1,ICE)
Block(7,12,1,ICE)
Block(8,12,1,ICE)
Block(9,12,1,ICE)
Block(7,12,2,ICE)
Block(8,12,2,ICE)
Block(9,12,2,ICE)
Block(-6,12,4,ICE)
Block(-7,12,5,ICE)
Block(-6,12,5,ICE)
Block(-5,12,5,ICE)
Block(-8,12,6,ICE)
Block(-7,12,6,ICE)
Block(-6,12,6,ICE)
Block(3,12,7,ICE)
Block(3,12,8,ICE)
Block(5,13,-8,ICE)
Block(6,13,-8,ICE)
Block(6,13,-7,ICE)
Block(7,13,0,ICE)
Block(8,13,0,ICE)
Block(9,13,0,ICE)
Block(7,13,1,ICE)
Block(8,13,1,ICE)
Block(9,13,1,ICE)
Block(7,13,2,ICE)
Block(8,13,2,ICE)
Block(9,13,2,ICE)
Block(-7,13,5,ICE)
Block(-6,13,5,ICE)
Block(-8,13,6,ICE)
Block(-7,13,6,ICE)
Block(-6,13,6,ICE)
Block(-8,13,7,ICE)
Block(-7,13,7,ICE)
Block(3,13,8,ICE)
Block(6,14,-8,ICE)
Block(8,14,0,ICE)
Block(7,14,1,ICE)
Block(8,14,1,ICE)
Block(9,14,1,ICE)
Block(8,14,2,ICE)
Block(-8,14,6,ICE)
Block(-7,14,6,ICE)
Block(-9,14,7,ICE)
Block(-8,14,7,ICE)
Block(3,14,8,ICE)
Block(6,15,-8,ICE)
Block(8,15,1,ICE)
Block(9,15,1,ICE)
Block(-8,15,6,ICE)
Block(-9,15,7,ICE)
Block(8,16,1,ICE)
Block(9,16,1,ICE)
Block(-9,16,7,ICE)
Block(9,17,1,ICE)
Block(9,18,1,ICE)
Block(9,19,1,ICE)

#######################################################################
# +-----------------------------------------------------------------+ #
# |                            BO3 checks                           | #
# +-----------------------------------------------------------------+ #
#######################################################################

# Require a condition at a certain location in order for the BO3 to be spawned.
# BlockCheck(x,y,z,BlockName[,BlockName[,...]]) - one of the blocks must be at the location
# BlockCheckNot(x,y,z,BlockName[,BlockName[,...]]) - all the blocks must not be at the location
# LightCheck(x,y,z,minLightLevel,maxLightLevel) - light must be between min and max (inclusive)

# You can use "Solid" as a BlockName for matching all solid blocks or "All" to match all blocks that aren't air.

# Examples:
BlockCheck(0,-1,0,GRASS,DIRT,DIRT:2,STONE,SNOW_BLOCK,174,174)
#   BlockCheck(0,-1,0,Solid)       Require any solid block just below the object
#   BlockCheck(0,-1,0,WOOL)        Require any type of wool just below the object
#   BlockCheck(0,-1,0,WOOL:0)      Require white wool just below the object
#   BlockCheckNot(0,-1,0,WOOL:0)   Require that there is no white wool below the object
#   LightCheck(0,0,0,0,1)          Require almost complete darkness just below the object

#######################################################################
# +-----------------------------------------------------------------+ #
# |                             Branches                            | #
# +-----------------------------------------------------------------+ #
#######################################################################

# Branches are objects that will spawn when this object spawns when it is used in
# the CustomStructure resource. Branches can also have branches, making complex
# structures possible. See the wiki for more details.

# Regular Branches spawn each branch with an independent chance of spawning.
# Branch(x,y,z,branchName,rotation,chance[,anotherBranchName,rotation,chance[,...]][IndividualChance])
# branchName - name of the object to spawn.
# rotation - NORTH, SOUTH, EAST or WEST.
# IndividualChance - The chance each branch has to spawn, assumed to be 100 when left blank

# Weighted Branches spawn branches with a dependent chance of spawning.
# WeightedBranch(x,y,z,branchName,rotation,chance[,anotherBranchName,rotation,chance[,...]][MaxChanceOutOf])
# MaxChanceOutOf - The chance all branches have to spawn out of, assumed to be 100 when left blank
