#######################################################################
# +-----------------------------------------------------------------+ #
# |                            BO3 object                           | #
# +-----------------------------------------------------------------+ #
#######################################################################

# This is the config file of a custom object.
# If you add this object correctly to your BiomeConfigs, it will spawn in the world.

# This is the creator of this BO3 object
Author: BO3 BulkEdit (by LanToaster)

# A short description of this BO3 object
Description: This Object was Created with BO3_BulkEdit

# The BO3 version, don't change this! It can be used by external applications to do a version check.
Version: 3

# The settings mode, WriteAll, WriteWithoutComments or WriteDisable. See WorldConfig.
SettingsMode: WriteDisable


#######################################################################
# +-----------------------------------------------------------------+ #
# |                          Main settings                          | #
# +-----------------------------------------------------------------+ #
#######################################################################

# This needs to be set to true to spawn the object in the Tree and Sapling resources.
Tree: true

# The frequency of the BO3 from 1 to 200. Tries this many times to spawn this BO3 when using the CustomObject(...) resource.
# Ignored by Tree(..), Sapling(..) and CustomStructure(..)
Frequency: 200

# The rarity of the BO3 from 0 to 100. Each spawn attempt has rarity% chance to succeed when using the CustomObject(...) resource.
# Ignored by Tree(..), Sapling(..) and CustomStructure(..)
Rarity: 100

# If you set this to true, the BO3 will be placed with a random rotation.
RotateRandomly: True

# The spawn height of the BO3 - randomY, highestBlock or highestSolidBlock.
SpawnHeight: highestSolidBlock

# The height limits for the BO3.
MinHeight: 0

MaxHeight: 70

# Objects can have other objects attacthed to it: branches. Branches can also
# have branches attached to it, which can also have branches, etc. This is the
# maximum branch depth for this objects.
MaxBranchDepth: 10

# When spawned with the UseWorld keyword, this BO3 should NOT spawn in the following biomes.
# If you writer.write the BO3 name directly in the BiomeConfigs, this will be ignored.
ExcludedBiomes: All


#######################################################################
# +-----------------------------------------------------------------+ #
# |                      Source block settings                      | #
# +-----------------------------------------------------------------+ #
#######################################################################

# The block(s) the BO3 should spawn in.
SourceBlocks: AIR, STATIONARY_WATER

# The maximum percentage of the BO3 that can be outside the SourceBlock.
# The BO3 won't be placed on a location with more blocks outside the SourceBlock than this percentage.
MaxPercentageOutsideSourceBlock: 0

# What to do when a block is about to be placed outside the SourceBlock? (dontPlace, placeAnyway)
OutsideSourceBlock: dontPlace


#######################################################################
# +-----------------------------------------------------------------+ #
# |                              Blocks                             | #
# +-----------------------------------------------------------------+ #
#######################################################################

# All the blocks used in the BO3 are listed here. Possible blocks:
# Block(x,y,z,id[.data][,nbtfile.nbt)
# RandomBlock(x,y,z,id[:data][,nbtfile.nbt],chance[,id[:data][,nbtfile.nbt],chance[,...]])
# So RandomBlock(0,0,0,CHEST,chest.nbt,50,CHEST,anotherchest.nbt,100) will spawn a chest at
# the BO3 origin, and give it a 50% chance to have the contents of chest.nbt, or, if that
# fails, a 100% percent chance to have the contents of anotherchest.nbt.
Block(3,0,-2,LOG2:13)
Block(1,0,-1,LOG2:13)
Block(2,0,-1,LOG2:13)
Block(3,0,-1,LOG2:13)
Block(4,0,-1,LOG2:13)
Block(1,0,0,LOG2:13)
Block(2,0,0,LOG2:13)
Block(3,0,0,LOG2:13)
Block(3,1,-2,LOG2:13)
Block(2,1,-1,LOG2:13)
Block(3,1,-1,LOG2:13)
Block(2,1,0,LOG2:13)
Block(3,1,0,LOG2:13)
Block(2,2,-1,LOG2:13)
Block(3,2,-1,LOG2:13)
Block(2,2,0,LOG2:13)
Block(3,2,0,LOG2:13)
Block(2,3,-1,LOG2:13)
Block(3,3,-1,LOG2:13)
Block(2,3,0,LOG2:13)
Block(3,3,0,LOG2:13)
Block(2,4,-1,LOG2:13)
Block(3,4,-1,LOG2:13)
Block(2,4,0,LOG2:13)
Block(3,4,0,LOG2:13)
Block(2,5,-1,LOG2:13)
Block(3,5,-1,LOG2:13)
Block(2,5,0,LOG2:13)
Block(3,5,0,LOG2:13)
Block(8,6,-2,LEAVES2:13)
Block(2,6,-1,LOG2:13)
Block(3,6,-1,LOG2:13)
Block(7,6,-1,LEAVES2:13)
Block(8,6,-1,LEAVES2:13)
Block(9,6,-1,LEAVES2:13)
Block(2,6,0,LOG2:13)
Block(3,6,0,LOG2:13)
Block(8,6,0,LEAVES2:13)
Block(7,7,-3,LEAVES2:13)
Block(8,7,-3,LEAVES2:13)
Block(9,7,-3,LEAVES2:13)
Block(6,7,-2,LEAVES2:13)
Block(7,7,-2,LEAVES2:13)
Block(8,7,-2,LEAVES2:13)
Block(9,7,-2,LEAVES2:13)
Block(10,7,-2,LEAVES2:13)
Block(2,7,-1,LOG2:13)
Block(3,7,-1,LOG2:13)
Block(6,7,-1,LEAVES2:13)
Block(7,7,-1,LEAVES2:13)
Block(8,7,-1,LEAVES2:13)
Block(9,7,-1,LEAVES2:13)
Block(10,7,-1,LEAVES2:13)
Block(2,7,0,LOG2:13)
Block(3,7,0,LOG2:13)
Block(6,7,0,LEAVES2:13)
Block(7,7,0,LEAVES2:13)
Block(8,7,0,LEAVES2:13)
Block(9,7,0,LEAVES2:13)
Block(10,7,0,LEAVES2:13)
Block(7,7,1,LEAVES2:13)
Block(8,7,1,LEAVES2:13)
Block(9,7,1,LEAVES2:13)
Block(7,8,-8,LEAVES2:13)
Block(6,8,-7,LEAVES2:13)
Block(7,8,-7,LEAVES2:13)
Block(8,8,-7,LEAVES2:13)
Block(6,8,-6,LOG2:13)
Block(7,8,-6,LEAVES2:13)
Block(5,8,-5,LOG2:13)
Block(-2,8,-4,LOG2:13)
Block(5,8,-4,LOG2:13)
Block(6,8,-4,LEAVES2:13)
Block(7,8,-4,LEAVES2:13)
Block(8,8,-4,LEAVES2:13)
Block(9,8,-4,LEAVES2:13)
Block(10,8,-4,LEAVES2:13)
Block(-1,8,-3,LOG2:13)
Block(0,8,-3,LOG2:13)
Block(4,8,-3,LOG2:13)
Block(5,8,-3,LEAVES2:13)
Block(6,8,-3,LEAVES2:13)
Block(7,8,-3,LEAVES2:13)
Block(8,8,-3,LEAVES2:13)
Block(9,8,-3,LEAVES2:13)
Block(10,8,-3,LEAVES2:13)
Block(11,8,-3,LEAVES2:13)
Block(0,8,-2,LOG2:13)
Block(1,8,-2,LOG2:13)
Block(3,8,-2,LOG2:13)
Block(5,8,-2,LEAVES2:13)
Block(6,8,-2,LEAVES2:13)
Block(7,8,-2,LEAVES2:13)
Block(8,8,-2,LEAVES2:13)
Block(9,8,-2,LEAVES2:13)
Block(10,8,-2,LEAVES2:13)
Block(11,8,-2,LEAVES2:13)
Block(1,8,-1,LOG2:13)
Block(2,8,-1,LOG2:13)
Block(3,8,-1,LOG2:13)
Block(4,8,-1,LOG2:13)
Block(5,8,-1,LOG2:13)
Block(6,8,-1,LOG2:13)
Block(7,8,-1,LOG2:13)
Block(8,8,-1,LEAVES2:13)
Block(9,8,-1,LEAVES2:13)
Block(10,8,-1,LEAVES2:13)
Block(11,8,-1,LEAVES2:13)
Block(2,8,0,LOG2:13)
Block(3,8,0,LOG2:13)
Block(5,8,0,LEAVES2:13)
Block(6,8,0,LEAVES2:13)
Block(7,8,0,LEAVES2:13)
Block(8,8,0,LEAVES2:13)
Block(9,8,0,LEAVES2:13)
Block(10,8,0,LEAVES2:13)
Block(11,8,0,LEAVES2:13)
Block(5,8,1,LEAVES2:13)
Block(6,8,1,LEAVES2:13)
Block(7,8,1,LEAVES2:13)
Block(8,8,1,LEAVES2:13)
Block(9,8,1,LEAVES2:13)
Block(10,8,1,LEAVES2:13)
Block(11,8,1,LEAVES2:13)
Block(6,8,2,LEAVES2:13)
Block(7,8,2,LEAVES2:13)
Block(8,8,2,LEAVES2:13)
Block(9,8,2,LEAVES2:13)
Block(10,8,2,LEAVES2:13)
Block(7,9,-12,LEAVES2:13)
Block(4,9,-11,LEAVES2:13)
Block(5,9,-11,LEAVES2:13)
Block(6,9,-11,LEAVES2:13)
Block(7,9,-11,LEAVES2:13)
Block(8,9,-11,LEAVES2:13)
Block(9,9,-11,LEAVES2:13)
Block(10,9,-11,LEAVES2:13)
Block(3,9,-10,LEAVES2:13)
Block(4,9,-10,LEAVES2:13)
Block(5,9,-10,LEAVES2:13)
Block(6,9,-10,LEAVES2:13)
Block(7,9,-10,LEAVES2:13)
Block(8,9,-10,LEAVES2:13)
Block(9,9,-10,LEAVES2:13)
Block(10,9,-10,LEAVES2:13)
Block(11,9,-10,LEAVES2:13)
Block(3,9,-9,LEAVES2:13)
Block(4,9,-9,LEAVES2:13)
Block(5,9,-9,LEAVES2:13)
Block(6,9,-9,LEAVES2:13)
Block(7,9,-9,LEAVES2:13)
Block(8,9,-9,LEAVES2:13)
Block(9,9,-9,LEAVES2:13)
Block(10,9,-9,LEAVES2:13)
Block(11,9,-9,LEAVES2:13)
Block(-7,9,-8,LEAVES2:13)
Block(3,9,-8,LEAVES2:13)
Block(4,9,-8,LEAVES2:13)
Block(5,9,-8,LEAVES2:13)
Block(6,9,-8,LEAVES2:13)
Block(7,9,-8,LEAVES2:13)
Block(8,9,-8,LEAVES2:13)
Block(9,9,-8,LEAVES2:13)
Block(10,9,-8,LEAVES2:13)
Block(11,9,-8,LEAVES2:13)
Block(-6,9,-7,LOG2:13)
Block(2,9,-7,LEAVES2:13)
Block(3,9,-7,LEAVES2:13)
Block(4,9,-7,LEAVES2:13)
Block(5,9,-7,LEAVES2:13)
Block(6,9,-7,LEAVES2:13)
Block(7,9,-7,LOG2:13)
Block(8,9,-7,LEAVES2:13)
Block(9,9,-7,LEAVES2:13)
Block(10,9,-7,LEAVES2:13)
Block(11,9,-7,LEAVES2:13)
Block(12,9,-7,LEAVES2:13)
Block(-5,9,-6,LOG2:13)
Block(3,9,-6,LEAVES2:13)
Block(4,9,-6,LEAVES2:13)
Block(5,9,-6,LEAVES2:13)
Block(6,9,-6,LEAVES2:13)
Block(7,9,-6,LEAVES2:13)
Block(8,9,-6,LEAVES2:13)
Block(9,9,-6,LEAVES2:13)
Block(10,9,-6,LEAVES2:13)
Block(11,9,-6,LEAVES2:13)
Block(-4,9,-5,LOG2:13)
Block(-1,9,-5,LOG2:13)
Block(3,9,-5,LEAVES2:13)
Block(4,9,-5,LEAVES2:13)
Block(5,9,-5,LEAVES2:13)
Block(6,9,-5,LEAVES2:13)
Block(7,9,-5,LEAVES2:13)
Block(8,9,-5,LEAVES2:13)
Block(9,9,-5,LEAVES2:13)
Block(10,9,-5,LEAVES2:13)
Block(11,9,-5,LEAVES2:13)
Block(-3,9,-4,LOG2:13)
Block(0,9,-4,LOG2:13)
Block(3,9,-4,LOG2:13)
Block(4,9,-4,LEAVES2:13)
Block(5,9,-4,LEAVES2:13)
Block(6,9,-4,LEAVES2:13)
Block(7,9,-4,LEAVES2:13)
Block(8,9,-4,LEAVES2:13)
Block(9,9,-4,LEAVES2:13)
Block(10,9,-4,LEAVES2:13)
Block(11,9,-4,LEAVES2:13)
Block(-3,9,-3,LOG2:13)
Block(-2,9,-3,LOG2:13)
Block(3,9,-3,LOG2:13)
Block(4,9,-3,LEAVES2:13)
Block(5,9,-3,LEAVES2:13)
Block(6,9,-3,LEAVES2:13)
Block(7,9,-3,LEAVES2:13)
Block(8,9,-3,LEAVES2:13)
Block(9,9,-3,LEAVES2:13)
Block(10,9,-3,LEAVES2:13)
Block(11,9,-3,LEAVES2:13)
Block(-1,9,-2,LOG2:13)
Block(5,9,-2,LOG2:13)
Block(6,9,-2,LEAVES2:13)
Block(7,9,-2,LEAVES2:13)
Block(8,9,-2,LEAVES2:13)
Block(9,9,-2,LEAVES2:13)
Block(10,9,-2,LEAVES2:13)
Block(11,9,-2,LEAVES2:13)
Block(1,9,-1,LOG2:13)
Block(2,9,-1,LOG2:13)
Block(3,9,-1,LOG2:13)
Block(4,9,-1,LEAVES2:13)
Block(5,9,-1,LEAVES2:13)
Block(6,9,-1,LEAVES2:13)
Block(7,9,-1,LEAVES2:13)
Block(8,9,-1,LOG2:13)
Block(9,9,-1,LEAVES2:13)
Block(10,9,-1,LEAVES2:13)
Block(11,9,-1,LEAVES2:13)
Block(12,9,-1,LEAVES2:13)
Block(1,9,0,LOG2:13)
Block(2,9,0,LOG2:13)
Block(3,9,0,LOG2:13)
Block(5,9,0,LEAVES2:13)
Block(6,9,0,LEAVES2:13)
Block(7,9,0,LEAVES2:13)
Block(8,9,0,LEAVES2:13)
Block(9,9,0,LEAVES2:13)
Block(10,9,0,LEAVES2:13)
Block(11,9,0,LEAVES2:13)
Block(1,9,1,LOG2:13)
Block(3,9,1,LOG2:13)
Block(5,9,1,LEAVES2:13)
Block(6,9,1,LEAVES2:13)
Block(7,9,1,LEAVES2:13)
Block(8,9,1,LEAVES2:13)
Block(9,9,1,LEAVES2:13)
Block(10,9,1,LEAVES2:13)
Block(11,9,1,LEAVES2:13)
Block(6,9,2,LEAVES2:13)
Block(7,9,2,LEAVES2:13)
Block(8,9,2,LEAVES2:13)
Block(9,9,2,LEAVES2:13)
Block(10,9,2,LEAVES2:13)
Block(8,9,3,LEAVES2:13)
Block(-7,10,-11,LEAVES2:13)
Block(-9,10,-10,LEAVES2:13)
Block(-8,10,-10,LEAVES2:13)
Block(-7,10,-10,LEAVES2:13)
Block(-6,10,-10,LEAVES2:13)
Block(-5,10,-10,LEAVES2:13)
Block(-9,10,-9,LEAVES2:13)
Block(-8,10,-9,LEAVES2:13)
Block(-7,10,-9,LEAVES2:13)
Block(-6,10,-9,LEAVES2:13)
Block(-5,10,-9,LEAVES2:13)
Block(-10,10,-8,LEAVES2:13)
Block(-9,10,-8,LEAVES2:13)
Block(-8,10,-8,LEAVES2:13)
Block(-7,10,-8,LOG2:13)
Block(-6,10,-8,LEAVES2:13)
Block(-5,10,-8,LEAVES2:13)
Block(-4,10,-8,LEAVES2:13)
Block(7,10,-8,LEAVES2:13)
Block(-9,10,-7,LEAVES2:13)
Block(-8,10,-7,LEAVES2:13)
Block(-7,10,-7,LEAVES2:13)
Block(-6,10,-7,LEAVES2:13)
Block(-5,10,-7,LEAVES2:13)
Block(-2,10,-7,LOG2:13)
Block(6,10,-7,LEAVES2:13)
Block(7,10,-7,LEAVES2:13)
Block(8,10,-7,LEAVES2:13)
Block(-9,10,-6,LEAVES2:13)
Block(-8,10,-6,LEAVES2:13)
Block(-7,10,-6,LEAVES2:13)
Block(-6,10,-6,LEAVES2:13)
Block(-5,10,-6,LEAVES2:13)
Block(-2,10,-6,LOG2:13)
Block(7,10,-6,LEAVES2:13)
Block(-7,10,-5,LEAVES2:13)
Block(-6,10,-5,LOG2:13)
Block(4,10,-5,LOG2:13)
Block(-5,10,-4,LOG2:13)
Block(-4,10,-4,LOG2:13)
Block(6,10,-4,LEAVES2:13)
Block(7,10,-4,LEAVES2:13)
Block(8,10,-4,LEAVES2:13)
Block(9,10,-4,LEAVES2:13)
Block(10,10,-4,LEAVES2:13)
Block(5,10,-3,LEAVES2:13)
Block(6,10,-3,LOG2:13)
Block(7,10,-3,LOG2:13)
Block(8,10,-3,LEAVES2:13)
Block(9,10,-3,LEAVES2:13)
Block(10,10,-3,LEAVES2:13)
Block(11,10,-3,LEAVES2:13)
Block(0,10,-2,LOG2:13)
Block(4,10,-2,LOG2:13)
Block(5,10,-2,LEAVES2:13)
Block(6,10,-2,LEAVES2:13)
Block(7,10,-2,LEAVES2:13)
Block(8,10,-2,LEAVES2:13)
Block(9,10,-2,LEAVES2:13)
Block(10,10,-2,LEAVES2:13)
Block(11,10,-2,LEAVES2:13)
Block(1,10,-1,LOG2:13)
Block(2,10,-1,LOG2:13)
Block(3,10,-1,LOG2:13)
Block(5,10,-1,LEAVES2:13)
Block(6,10,-1,LEAVES2:13)
Block(7,10,-1,LEAVES2:13)
Block(8,10,-1,LEAVES2:13)
Block(9,10,-1,LEAVES2:13)
Block(10,10,-1,LEAVES2:13)
Block(11,10,-1,LEAVES2:13)
Block(0,10,0,LOG2:13)
Block(1,10,0,LOG2:13)
Block(2,10,0,LOG2:13)
Block(3,10,0,LOG2:13)
Block(5,10,0,LEAVES2:13)
Block(6,10,0,LEAVES2:13)
Block(7,10,0,LEAVES2:13)
Block(8,10,0,LEAVES2:13)
Block(9,10,0,LEAVES2:13)
Block(10,10,0,LEAVES2:13)
Block(11,10,0,LEAVES2:13)
Block(-2,10,1,LEAVES2:13)
Block(0,10,1,LOG2:13)
Block(3,10,1,LOG2:13)
Block(4,10,1,LOG2:13)
Block(5,10,1,LEAVES2:13)
Block(6,10,1,LEAVES2:13)
Block(7,10,1,LEAVES2:13)
Block(8,10,1,LEAVES2:13)
Block(9,10,1,LEAVES2:13)
Block(10,10,1,LEAVES2:13)
Block(11,10,1,LEAVES2:13)
Block(-3,10,2,LEAVES2:13)
Block(-2,10,2,LEAVES2:13)
Block(-1,10,2,LEAVES2:13)
Block(6,10,2,LEAVES2:13)
Block(7,10,2,LEAVES2:13)
Block(8,10,2,LEAVES2:13)
Block(9,10,2,LEAVES2:13)
Block(10,10,2,LEAVES2:13)
Block(-2,10,3,LEAVES2:13)
Block(-4,11,-11,LEAVES2:13)
Block(-7,11,-10,LEAVES2:13)
Block(-5,11,-10,LEAVES2:13)
Block(-4,11,-10,LEAVES2:13)
Block(-3,11,-10,LEAVES2:13)
Block(5,11,-10,LEAVES2:13)
Block(-9,11,-9,LEAVES2:13)
Block(-8,11,-9,LEAVES2:13)
Block(-7,11,-9,LEAVES2:13)
Block(-6,11,-9,LEAVES2:13)
Block(-5,11,-9,LEAVES2:13)
Block(-4,11,-9,LOG2:13)
Block(4,11,-9,LEAVES2:13)
Block(5,11,-9,LEAVES2:13)
Block(6,11,-9,LEAVES2:13)
Block(-10,11,-8,LEAVES2:13)
Block(-9,11,-8,LEAVES2:13)
Block(-8,11,-8,LEAVES2:13)
Block(-7,11,-8,LEAVES2:13)
Block(-6,11,-8,LEAVES2:13)
Block(-5,11,-8,LEAVES2:13)
Block(-4,11,-8,LEAVES2:13)
Block(-3,11,-8,LOG2:13)
Block(5,11,-8,LEAVES2:13)
Block(-10,11,-7,LEAVES2:13)
Block(-9,11,-7,LEAVES2:13)
Block(-8,11,-7,LEAVES2:13)
Block(-7,11,-7,LEAVES2:13)
Block(-6,11,-7,LEAVES2:13)
Block(-5,11,-7,LEAVES2:13)
Block(-4,11,-7,LEAVES2:13)
Block(4,11,-7,LOG2:13)
Block(-11,11,-6,LEAVES2:13)
Block(-10,11,-6,LEAVES2:13)
Block(-9,11,-6,LEAVES2:13)
Block(-8,11,-6,LEAVES2:13)
Block(-7,11,-6,LOG2:13)
Block(-6,11,-6,LEAVES2:13)
Block(-5,11,-6,LEAVES2:13)
Block(-4,11,-6,LEAVES2:13)
Block(-3,11,-6,LEAVES2:13)
Block(4,11,-6,LOG2:13)
Block(-10,11,-5,LEAVES2:13)
Block(-9,11,-5,LEAVES2:13)
Block(-8,11,-5,LEAVES2:13)
Block(-7,11,-5,LEAVES2:13)
Block(-6,11,-5,LEAVES2:13)
Block(-5,11,-5,LEAVES2:13)
Block(-4,11,-5,LEAVES2:13)
Block(-10,11,-4,LEAVES2:13)
Block(-9,11,-4,LEAVES2:13)
Block(-8,11,-4,LEAVES2:13)
Block(-7,11,-4,LEAVES2:13)
Block(-6,11,-4,LEAVES2:13)
Block(-5,11,-4,LEAVES2:13)
Block(-4,11,-4,LEAVES2:13)
Block(8,11,-4,LOG2:13)
Block(-9,11,-3,LEAVES2:13)
Block(-8,11,-3,LEAVES2:13)
Block(-7,11,-3,LEAVES2:13)
Block(-6,11,-3,LEAVES2:13)
Block(-5,11,-3,LEAVES2:13)
Block(-1,11,-3,LOG2:13)
Block(4,11,-3,LOG2:13)
Block(7,11,-3,LEAVES2:13)
Block(8,11,-3,LEAVES2:13)
Block(9,11,-3,LEAVES2:13)
Block(-7,11,-2,LEAVES2:13)
Block(1,11,-2,LOG2:13)
Block(3,11,-2,LOG2:13)
Block(6,11,-2,LEAVES2:13)
Block(7,11,-2,LEAVES2:13)
Block(8,11,-2,LEAVES2:13)
Block(9,11,-2,LEAVES2:13)
Block(10,11,-2,LEAVES2:13)
Block(0,11,-1,LOG2:13)
Block(1,11,-1,LOG2:13)
Block(2,11,-1,LOG2:13)
Block(3,11,-1,LOG2:13)
Block(6,11,-1,LEAVES2:13)
Block(7,11,-1,LEAVES2:13)
Block(8,11,-1,LEAVES2:13)
Block(9,11,-1,LEAVES2:13)
Block(10,11,-1,LEAVES2:13)
Block(-3,11,0,LEAVES2:13)
Block(-2,11,0,LEAVES2:13)
Block(-1,11,0,LOG2:13)
Block(1,11,0,LOG2:13)
Block(2,11,0,LOG2:13)
Block(3,11,0,LOG2:13)
Block(4,11,0,LOG2:13)
Block(6,11,0,LEAVES2:13)
Block(7,11,0,LEAVES2:13)
Block(8,11,0,LEAVES2:13)
Block(9,11,0,LEAVES2:13)
Block(10,11,0,LEAVES2:13)
Block(-4,11,1,LEAVES2:13)
Block(-3,11,1,LEAVES2:13)
Block(-2,11,1,LEAVES2:13)
Block(-1,11,1,LEAVES2:13)
Block(0,11,1,LOG2:13)
Block(1,11,1,LOG2:13)
Block(4,11,1,LOG2:13)
Block(7,11,1,LEAVES2:13)
Block(8,11,1,LEAVES2:13)
Block(9,11,1,LEAVES2:13)
Block(-4,11,2,LEAVES2:13)
Block(-3,11,2,LEAVES2:13)
Block(-2,11,2,LEAVES2:13)
Block(-1,11,2,LOG2:13)
Block(0,11,2,LEAVES2:13)
Block(3,11,2,LOG2:13)
Block(-4,11,3,LEAVES2:13)
Block(-3,11,3,LEAVES2:13)
Block(-2,11,3,LEAVES2:13)
Block(-1,11,3,LEAVES2:13)
Block(0,11,3,LEAVES2:13)
Block(-3,11,4,LEAVES2:13)
Block(-2,11,4,LEAVES2:13)
Block(-1,11,4,LEAVES2:13)
Block(-4,12,-14,LEAVES2:13)
Block(-6,12,-13,LEAVES2:13)
Block(-5,12,-13,LEAVES2:13)
Block(-4,12,-13,LEAVES2:13)
Block(-3,12,-13,LEAVES2:13)
Block(-2,12,-13,LEAVES2:13)
Block(-7,12,-12,LEAVES2:13)
Block(-6,12,-12,LEAVES2:13)
Block(-5,12,-12,LEAVES2:13)
Block(-4,12,-12,LEAVES2:13)
Block(-3,12,-12,LEAVES2:13)
Block(-2,12,-12,LEAVES2:13)
Block(-1,12,-12,LEAVES2:13)
Block(4,12,-12,LEAVES2:13)
Block(5,12,-12,LEAVES2:13)
Block(6,12,-12,LEAVES2:13)
Block(-7,12,-11,LEAVES2:13)
Block(-6,12,-11,LEAVES2:13)
Block(-5,12,-11,LEAVES2:13)
Block(-4,12,-11,LEAVES2:13)
Block(-3,12,-11,LEAVES2:13)
Block(-2,12,-11,LEAVES2:13)
Block(-1,12,-11,LEAVES2:13)
Block(3,12,-11,LEAVES2:13)
Block(4,12,-11,LEAVES2:13)
Block(5,12,-11,LEAVES2:13)
Block(6,12,-11,LEAVES2:13)
Block(7,12,-11,LEAVES2:13)
Block(-8,12,-10,LEAVES2:13)
Block(-7,12,-10,LEAVES2:13)
Block(-6,12,-10,LEAVES2:13)
Block(-5,12,-10,LEAVES2:13)
Block(-4,12,-10,LOG2:13)
Block(-3,12,-10,LEAVES2:13)
Block(-2,12,-10,LEAVES2:13)
Block(-1,12,-10,LEAVES2:13)
Block(0,12,-10,LEAVES2:13)
Block(2,12,-10,LEAVES2:13)
Block(3,12,-10,LEAVES2:13)
Block(4,12,-10,LEAVES2:13)
Block(5,12,-10,LEAVES2:13)
Block(6,12,-10,LEAVES2:13)
Block(7,12,-10,LEAVES2:13)
Block(8,12,-10,LEAVES2:13)
Block(-7,12,-9,LEAVES2:13)
Block(-6,12,-9,LEAVES2:13)
Block(-5,12,-9,LEAVES2:13)
Block(-4,12,-9,LEAVES2:13)
Block(-3,12,-9,LEAVES2:13)
Block(-2,12,-9,LEAVES2:13)
Block(-1,12,-9,LEAVES2:13)
Block(2,12,-9,LEAVES2:13)
Block(3,12,-9,LEAVES2:13)
Block(4,12,-9,LEAVES2:13)
Block(5,12,-9,LEAVES2:13)
Block(6,12,-9,LEAVES2:13)
Block(7,12,-9,LEAVES2:13)
Block(8,12,-9,LEAVES2:13)
Block(-7,12,-8,LEAVES2:13)
Block(-6,12,-8,LEAVES2:13)
Block(-5,12,-8,LEAVES2:13)
Block(-4,12,-8,LEAVES2:13)
Block(-3,12,-8,LEAVES2:13)
Block(-2,12,-8,LEAVES2:13)
Block(-1,12,-8,LEAVES2:13)
Block(2,12,-8,LEAVES2:13)
Block(3,12,-8,LEAVES2:13)
Block(4,12,-8,LOG2:13)
Block(5,12,-8,LEAVES2:13)
Block(6,12,-8,LEAVES2:13)
Block(7,12,-8,LEAVES2:13)
Block(8,12,-8,LEAVES2:13)
Block(-7,12,-7,LEAVES2:13)
Block(-6,12,-7,LEAVES2:13)
Block(-5,12,-7,LEAVES2:13)
Block(-4,12,-7,LEAVES2:13)
Block(-3,12,-7,LEAVES2:13)
Block(-2,12,-7,LEAVES2:13)
Block(3,12,-7,LEAVES2:13)
Block(4,12,-7,LEAVES2:13)
Block(5,12,-7,LEAVES2:13)
Block(6,12,-7,LEAVES2:13)
Block(7,12,-7,LEAVES2:13)
Block(10,12,-7,LEAVES2:13)
Block(-8,12,-6,LEAVES2:13)
Block(-7,12,-6,LEAVES2:13)
Block(-6,12,-6,LEAVES2:13)
Block(-4,12,-6,LEAVES2:13)
Block(4,12,-6,LEAVES2:13)
Block(5,12,-6,LEAVES2:13)
Block(6,12,-6,LEAVES2:13)
Block(9,12,-6,LEAVES2:13)
Block(10,12,-6,LEAVES2:13)
Block(11,12,-6,LEAVES2:13)
Block(-7,12,-5,LEAVES2:13)
Block(-3,12,-5,LEAVES2:13)
Block(9,12,-5,LOG2:13)
Block(10,12,-5,LEAVES2:13)
Block(-2,12,-4,LOG2:13)
Block(5,12,-4,LOG2:13)
Block(0,12,-2,LOG2:13)
Block(3,12,-2,LOG2:13)
Block(8,12,-2,LEAVES2:13)
Block(-4,12,-1,LEAVES2:13)
Block(-3,12,-1,LEAVES2:13)
Block(-2,12,-1,LEAVES2:13)
Block(-1,12,-1,LEAVES2:13)
Block(0,12,-1,LOG2:13)
Block(2,12,-1,LOG2:13)
Block(3,12,-1,LOG2:13)
Block(7,12,-1,LEAVES2:13)
Block(8,12,-1,LEAVES2:13)
Block(9,12,-1,LEAVES2:13)
Block(-5,12,0,LEAVES2:13)
Block(-4,12,0,LEAVES2:13)
Block(-3,12,0,LEAVES2:13)
Block(-2,12,0,LOG2:13)
Block(-1,12,0,LEAVES2:13)
Block(0,12,0,LOG2:13)
Block(1,12,0,LEAVES2:13)
Block(2,12,0,LOG2:13)
Block(3,12,0,LOG2:13)
Block(4,12,0,LOG2:13)
Block(8,12,0,LEAVES2:13)
Block(-5,12,1,LEAVES2:13)
Block(-4,12,1,LEAVES2:13)
Block(-3,12,1,LEAVES2:13)
Block(-2,12,1,LEAVES2:13)
Block(-1,12,1,LOG2:13)
Block(0,12,1,LOG2:13)
Block(1,12,1,LEAVES2:13)
Block(5,12,1,LOG2:13)
Block(-5,12,2,LEAVES2:13)
Block(-4,12,2,LEAVES2:13)
Block(-3,12,2,LEAVES2:13)
Block(-2,12,2,LOG2:13)
Block(-1,12,2,LEAVES2:13)
Block(0,12,2,LEAVES2:13)
Block(1,12,2,LEAVES2:13)
Block(3,12,2,LOG2:13)
Block(-5,12,3,LEAVES2:13)
Block(-4,12,3,LEAVES2:13)
Block(-3,12,3,LEAVES2:13)
Block(-2,12,3,LEAVES2:13)
Block(-1,12,3,LEAVES2:13)
Block(0,12,3,LEAVES2:13)
Block(1,12,3,LEAVES2:13)
Block(-5,12,4,LEAVES2:13)
Block(-4,12,4,LEAVES2:13)
Block(-3,12,4,LEAVES2:13)
Block(-2,12,4,LEAVES2:13)
Block(-1,12,4,LEAVES2:13)
Block(0,12,4,LEAVES2:13)
Block(1,12,4,LEAVES2:13)
Block(-4,12,5,LEAVES2:13)
Block(-3,12,5,LEAVES2:13)
Block(-2,12,5,LEAVES2:13)
Block(-1,12,5,LEAVES2:13)
Block(0,12,5,LEAVES2:13)
Block(5,13,-13,LEAVES2:13)
Block(3,13,-12,LEAVES2:13)
Block(4,13,-12,LEAVES2:13)
Block(5,13,-12,LEAVES2:13)
Block(6,13,-12,LEAVES2:13)
Block(7,13,-12,LEAVES2:13)
Block(-4,13,-11,LEAVES2:13)
Block(2,13,-11,LEAVES2:13)
Block(3,13,-11,LEAVES2:13)
Block(4,13,-11,LEAVES2:13)
Block(5,13,-11,LEAVES2:13)
Block(6,13,-11,LEAVES2:13)
Block(7,13,-11,LEAVES2:13)
Block(8,13,-11,LEAVES2:13)
Block(10,13,-11,LEAVES2:13)
Block(-5,13,-10,LEAVES2:13)
Block(-4,13,-10,LEAVES2:13)
Block(-3,13,-10,LEAVES2:13)
Block(2,13,-10,LEAVES2:13)
Block(3,13,-10,LEAVES2:13)
Block(4,13,-10,LEAVES2:13)
Block(5,13,-10,LEAVES2:13)
Block(6,13,-10,LEAVES2:13)
Block(7,13,-10,LEAVES2:13)
Block(8,13,-10,LEAVES2:13)
Block(9,13,-10,LEAVES2:13)
Block(10,13,-10,LEAVES2:13)
Block(11,13,-10,LEAVES2:13)
Block(12,13,-10,LEAVES2:13)
Block(13,13,-10,LEAVES2:13)
Block(-4,13,-9,LEAVES2:13)
Block(1,13,-9,LEAVES2:13)
Block(2,13,-9,LEAVES2:13)
Block(3,13,-9,LEAVES2:13)
Block(4,13,-9,LEAVES2:13)
Block(5,13,-9,LOG2:13)
Block(6,13,-9,LEAVES2:13)
Block(7,13,-9,LEAVES2:13)
Block(8,13,-9,LEAVES2:13)
Block(9,13,-9,LEAVES2:13)
Block(10,13,-9,LEAVES2:13)
Block(11,13,-9,LEAVES2:13)
Block(12,13,-9,LEAVES2:13)
Block(13,13,-9,LEAVES2:13)
Block(14,13,-9,LEAVES2:13)
Block(-3,13,-8,LEAVES2:13)
Block(2,13,-8,LEAVES2:13)
Block(3,13,-8,LEAVES2:13)
Block(4,13,-8,LEAVES2:13)
Block(5,13,-8,LEAVES2:13)
Block(6,13,-8,LEAVES2:13)
Block(7,13,-8,LEAVES2:13)
Block(8,13,-8,LEAVES2:13)
Block(9,13,-8,LEAVES2:13)
Block(10,13,-8,LEAVES2:13)
Block(11,13,-8,LEAVES2:13)
Block(12,13,-8,LEAVES2:13)
Block(13,13,-8,LEAVES2:13)
Block(14,13,-8,LEAVES2:13)
Block(-5,13,-7,LEAVES2:13)
Block(-4,13,-7,LEAVES2:13)
Block(-3,13,-7,LEAVES2:13)
Block(-2,13,-7,LEAVES2:13)
Block(-1,13,-7,LEAVES2:13)
Block(2,13,-7,LEAVES2:13)
Block(3,13,-7,LEAVES2:13)
Block(4,13,-7,LEAVES2:13)
Block(5,13,-7,LEAVES2:13)
Block(6,13,-7,LEAVES2:13)
Block(7,13,-7,LEAVES2:13)
Block(8,13,-7,LEAVES2:13)
Block(9,13,-7,LEAVES2:13)
Block(10,13,-7,LEAVES2:13)
Block(11,13,-7,LEAVES2:13)
Block(12,13,-7,LEAVES2:13)
Block(13,13,-7,LEAVES2:13)
Block(14,13,-7,LEAVES2:13)
Block(-5,13,-6,LEAVES2:13)
Block(-4,13,-6,LEAVES2:13)
Block(-3,13,-6,LEAVES2:13)
Block(-2,13,-6,LEAVES2:13)
Block(-1,13,-6,LEAVES2:13)
Block(3,13,-6,LEAVES2:13)
Block(4,13,-6,LEAVES2:13)
Block(5,13,-6,LEAVES2:13)
Block(6,13,-6,LEAVES2:13)
Block(7,13,-6,LEAVES2:13)
Block(8,13,-6,LEAVES2:13)
Block(9,13,-6,LEAVES2:13)
Block(10,13,-6,LOG2:13)
Block(11,13,-6,LEAVES2:13)
Block(12,13,-6,LEAVES2:13)
Block(13,13,-6,LEAVES2:13)
Block(14,13,-6,LEAVES2:13)
Block(15,13,-6,LEAVES2:13)
Block(-6,13,-5,LEAVES2:13)
Block(-5,13,-5,LEAVES2:13)
Block(-4,13,-5,LEAVES2:13)
Block(-3,13,-5,LOG2:13)
Block(-2,13,-5,LEAVES2:13)
Block(-1,13,-5,LEAVES2:13)
Block(0,13,-5,LEAVES2:13)
Block(5,13,-5,LEAVES2:13)
Block(6,13,-5,LEAVES2:13)
Block(7,13,-5,LEAVES2:13)
Block(8,13,-5,LEAVES2:13)
Block(9,13,-5,LEAVES2:13)
Block(10,13,-5,LEAVES2:13)
Block(11,13,-5,LEAVES2:13)
Block(12,13,-5,LEAVES2:13)
Block(13,13,-5,LEAVES2:13)
Block(14,13,-5,LEAVES2:13)
Block(-5,13,-4,LEAVES2:13)
Block(-4,13,-4,LEAVES2:13)
Block(-3,13,-4,LEAVES2:13)
Block(-2,13,-4,LEAVES2:13)
Block(-1,13,-4,LEAVES2:13)
Block(5,13,-4,LOG2:13)
Block(6,13,-4,LEAVES2:13)
Block(7,13,-4,LEAVES2:13)
Block(8,13,-4,LEAVES2:13)
Block(9,13,-4,LEAVES2:13)
Block(10,13,-4,LEAVES2:13)
Block(11,13,-4,LEAVES2:13)
Block(12,13,-4,LEAVES2:13)
Block(13,13,-4,LEAVES2:13)
Block(14,13,-4,LEAVES2:13)
Block(-5,13,-3,LEAVES2:13)
Block(-4,13,-3,LEAVES2:13)
Block(-3,13,-3,LEAVES2:13)
Block(-2,13,-3,LEAVES2:13)
Block(-1,13,-3,LEAVES2:13)
Block(4,13,-3,LOG2:13)
Block(6,13,-3,LEAVES2:13)
Block(7,13,-3,LEAVES2:13)
Block(8,13,-3,LEAVES2:13)
Block(9,13,-3,LEAVES2:13)
Block(10,13,-3,LEAVES2:13)
Block(11,13,-3,LEAVES2:13)
Block(12,13,-3,LEAVES2:13)
Block(13,13,-3,LEAVES2:13)
Block(14,13,-3,LEAVES2:13)
Block(-3,13,-2,LEAVES2:13)
Block(-2,13,-2,LEAVES2:13)
Block(0,13,-2,LOG2:13)
Block(7,13,-2,LEAVES2:13)
Block(8,13,-2,LEAVES2:13)
Block(9,13,-2,LEAVES2:13)
Block(10,13,-2,LEAVES2:13)
Block(11,13,-2,LEAVES2:13)
Block(12,13,-2,LEAVES2:13)
Block(13,13,-2,LEAVES2:13)
Block(-4,13,-1,LEAVES2:13)
Block(-3,13,-1,LEAVES2:13)
Block(-2,13,-1,LEAVES2:13)
Block(-1,13,-1,LEAVES2:13)
Block(0,13,-1,LOG2:13)
Block(1,13,-1,LOG2:13)
Block(2,13,-1,LOG2:13)
Block(3,13,-1,LOG2:13)
Block(10,13,-1,LEAVES2:13)
Block(-5,13,0,LEAVES2:13)
Block(-4,13,0,LEAVES2:13)
Block(-3,13,0,LOG2:13)
Block(-2,13,0,LEAVES2:13)
Block(-1,13,0,LEAVES2:13)
Block(0,13,0,LOG2:13)
Block(1,13,0,LEAVES2:13)
Block(2,13,0,LOG2:13)
Block(3,13,0,LOG2:13)
Block(5,13,0,LOG2:13)
Block(-5,13,1,LEAVES2:13)
Block(-4,13,1,LEAVES2:13)
Block(-3,13,1,LEAVES2:13)
Block(-2,13,1,LEAVES2:13)
Block(-1,13,1,LOG2:13)
Block(0,13,1,LOG2:13)
Block(1,13,1,LEAVES2:13)
Block(5,13,1,LOG2:13)
Block(-6,13,2,LEAVES2:13)
Block(-5,13,2,LEAVES2:13)
Block(-4,13,2,LEAVES2:13)
Block(-3,13,2,LEAVES2:13)
Block(-2,13,2,LOG2:13)
Block(-1,13,2,LEAVES2:13)
Block(0,13,2,LEAVES2:13)
Block(1,13,2,LEAVES2:13)
Block(2,13,2,LEAVES2:13)
Block(4,13,2,LOG2:13)
Block(-5,13,3,LEAVES2:13)
Block(-4,13,3,LEAVES2:13)
Block(-3,13,3,LEAVES2:13)
Block(-2,13,3,LEAVES2:13)
Block(-1,13,3,LEAVES2:13)
Block(0,13,3,LEAVES2:13)
Block(1,13,3,LEAVES2:13)
Block(-5,13,4,LEAVES2:13)
Block(-4,13,4,LEAVES2:13)
Block(-3,13,4,LEAVES2:13)
Block(-2,13,4,LEAVES2:13)
Block(-1,13,4,LEAVES2:13)
Block(0,13,4,LEAVES2:13)
Block(1,13,4,LEAVES2:13)
Block(-4,13,5,LEAVES2:13)
Block(-3,13,5,LEAVES2:13)
Block(-2,13,5,LEAVES2:13)
Block(-1,13,5,LEAVES2:13)
Block(0,13,5,LEAVES2:13)
Block(-2,13,6,LEAVES2:13)
Block(4,14,-12,LEAVES2:13)
Block(5,14,-12,LEAVES2:13)
Block(6,14,-12,LEAVES2:13)
Block(3,14,-11,LEAVES2:13)
Block(4,14,-11,LEAVES2:13)
Block(5,14,-11,LEAVES2:13)
Block(6,14,-11,LEAVES2:13)
Block(7,14,-11,LEAVES2:13)
Block(2,14,-10,LEAVES2:13)
Block(3,14,-10,LEAVES2:13)
Block(4,14,-10,LEAVES2:13)
Block(5,14,-10,LEAVES2:13)
Block(6,14,-10,LEAVES2:13)
Block(7,14,-10,LEAVES2:13)
Block(8,14,-10,LEAVES2:13)
Block(2,14,-9,LEAVES2:13)
Block(3,14,-9,LEAVES2:13)
Block(4,14,-9,LEAVES2:13)
Block(5,14,-9,LEAVES2:13)
Block(6,14,-9,LEAVES2:13)
Block(7,14,-9,LEAVES2:13)
Block(8,14,-9,LEAVES2:13)
Block(2,14,-8,LEAVES2:13)
Block(3,14,-8,LEAVES2:13)
Block(4,14,-8,LEAVES2:13)
Block(5,14,-8,LEAVES2:13)
Block(6,14,-8,LEAVES2:13)
Block(7,14,-8,LEAVES2:13)
Block(8,14,-8,LEAVES2:13)
Block(3,14,-7,LEAVES2:13)
Block(4,14,-7,LEAVES2:13)
Block(5,14,-7,LEAVES2:13)
Block(6,14,-7,LEAVES2:13)
Block(7,14,-7,LEAVES2:13)
Block(10,14,-7,LEAVES2:13)
Block(4,14,-6,LEAVES2:13)
Block(5,14,-6,LEAVES2:13)
Block(6,14,-6,LEAVES2:13)
Block(9,14,-6,LEAVES2:13)
Block(10,14,-6,LEAVES2:13)
Block(11,14,-6,LEAVES2:13)
Block(-3,14,-5,LEAVES2:13)
Block(6,14,-5,LOG2:13)
Block(10,14,-5,LEAVES2:13)
Block(0,14,-3,LOG2:13)
Block(4,14,-3,LOG2:13)
Block(0,14,-2,LOG2:13)
Block(1,14,-2,LOG2:13)
Block(-4,14,-1,LEAVES2:13)
Block(-3,14,-1,LEAVES2:13)
Block(-2,14,-1,LEAVES2:13)
Block(-1,14,-1,LOG2:13)
Block(0,14,-1,LEAVES2:13)
Block(2,14,-1,LOG2:13)
Block(3,14,-1,LOG2:13)
Block(-5,14,0,LEAVES2:13)
Block(-4,14,0,LOG2:13)
Block(-3,14,0,LEAVES2:13)
Block(-2,14,0,LEAVES2:13)
Block(-1,14,0,LEAVES2:13)
Block(0,14,0,LOG2:13)
Block(1,14,0,LEAVES2:13)
Block(2,14,0,LOG2:13)
Block(3,14,0,LOG2:13)
Block(5,14,0,LOG2:13)
Block(8,14,0,LEAVES2:13)
Block(-5,14,1,LEAVES2:13)
Block(-4,14,1,LEAVES2:13)
Block(-3,14,1,LEAVES2:13)
Block(-2,14,1,LOG2:13)
Block(-1,14,1,LOG2:13)
Block(0,14,1,LEAVES2:13)
Block(1,14,1,LEAVES2:13)
Block(6,14,1,LOG2:13)
Block(7,14,1,LEAVES2:13)
Block(8,14,1,LEAVES2:13)
Block(9,14,1,LEAVES2:13)
Block(-5,14,2,LEAVES2:13)
Block(-4,14,2,LEAVES2:13)
Block(-3,14,2,LEAVES2:13)
Block(-2,14,2,LEAVES2:13)
Block(-1,14,2,LEAVES2:13)
Block(0,14,2,LEAVES2:13)
Block(1,14,2,LEAVES2:13)
Block(8,14,2,LEAVES2:13)
Block(-5,14,3,LEAVES2:13)
Block(-4,14,3,LEAVES2:13)
Block(-3,14,3,LEAVES2:13)
Block(-2,14,3,LEAVES2:13)
Block(-1,14,3,LEAVES2:13)
Block(0,14,3,LEAVES2:13)
Block(1,14,3,LEAVES2:13)
Block(4,14,3,LOG2:13)
Block(-5,14,4,LEAVES2:13)
Block(-4,14,4,LEAVES2:13)
Block(-3,14,4,LEAVES2:13)
Block(-2,14,4,LEAVES2:13)
Block(-1,14,4,LEAVES2:13)
Block(0,14,4,LEAVES2:13)
Block(1,14,4,LEAVES2:13)
Block(-4,14,5,LEAVES2:13)
Block(-3,14,5,LEAVES2:13)
Block(-2,14,5,LEAVES2:13)
Block(-1,14,5,LEAVES2:13)
Block(0,14,5,LEAVES2:13)
Block(5,15,-10,LEAVES2:13)
Block(4,15,-9,LEAVES2:13)
Block(5,15,-9,LEAVES2:13)
Block(6,15,-9,LEAVES2:13)
Block(5,15,-8,LEAVES2:13)
Block(0,15,-6,LEAVES2:13)
Block(6,15,-6,LOG2:13)
Block(-2,15,-5,LEAVES2:13)
Block(-1,15,-5,LEAVES2:13)
Block(0,15,-5,LEAVES2:13)
Block(1,15,-5,LEAVES2:13)
Block(2,15,-5,LEAVES2:13)
Block(-2,15,-4,LEAVES2:13)
Block(-1,15,-4,LEAVES2:13)
Block(0,15,-4,LEAVES2:13)
Block(1,15,-4,LEAVES2:13)
Block(2,15,-4,LEAVES2:13)
Block(4,15,-4,LOG2:13)
Block(-3,15,-3,LEAVES2:13)
Block(-2,15,-3,LEAVES2:13)
Block(-1,15,-3,LEAVES2:13)
Block(0,15,-3,LOG2:13)
Block(1,15,-3,LOG2:13)
Block(2,15,-3,LEAVES2:13)
Block(3,15,-3,LEAVES2:13)
Block(-2,15,-2,LEAVES2:13)
Block(-1,15,-2,LEAVES2:13)
Block(0,15,-2,LEAVES2:13)
Block(1,15,-2,LEAVES2:13)
Block(2,15,-2,LEAVES2:13)
Block(7,15,-2,LEAVES2:13)
Block(8,15,-2,LEAVES2:13)
Block(9,15,-2,LEAVES2:13)
Block(-2,15,-1,LEAVES2:13)
Block(-1,15,-1,LOG2:13)
Block(0,15,-1,LEAVES2:13)
Block(1,15,-1,LEAVES2:13)
Block(2,15,-1,LOG2:13)
Block(3,15,-1,LOG2:13)
Block(6,15,-1,LEAVES2:13)
Block(7,15,-1,LEAVES2:13)
Block(8,15,-1,LEAVES2:13)
Block(9,15,-1,LEAVES2:13)
Block(10,15,-1,LEAVES2:13)
Block(-5,15,0,LOG2:13)
Block(-3,15,0,LEAVES2:13)
Block(-2,15,0,LEAVES2:13)
Block(-1,15,0,LOG2:13)
Block(0,15,0,LEAVES2:13)
Block(2,15,0,LOG2:13)
Block(3,15,0,LOG2:13)
Block(5,15,0,LEAVES2:13)
Block(6,15,0,LOG2:13)
Block(7,15,0,LEAVES2:13)
Block(8,15,0,LEAVES2:13)
Block(9,15,0,LEAVES2:13)
Block(10,15,0,LEAVES2:13)
Block(11,15,0,LEAVES2:13)
Block(-4,15,1,LEAVES2:13)
Block(-3,15,1,LOG2:13)
Block(-2,15,1,LEAVES2:13)
Block(-1,15,1,LOG2:13)
Block(0,15,1,LEAVES2:13)
Block(5,15,1,LEAVES2:13)
Block(6,15,1,LOG2:13)
Block(7,15,1,LEAVES2:13)
Block(8,15,1,LEAVES2:13)
Block(9,15,1,LEAVES2:13)
Block(10,15,1,LEAVES2:13)
Block(11,15,1,LEAVES2:13)
Block(-4,15,2,LEAVES2:13)
Block(-3,15,2,LEAVES2:13)
Block(-2,15,2,LEAVES2:13)
Block(-1,15,2,LEAVES2:13)
Block(0,15,2,LEAVES2:13)
Block(5,15,2,LEAVES2:13)
Block(6,15,2,LEAVES2:13)
Block(7,15,2,LEAVES2:13)
Block(8,15,2,LEAVES2:13)
Block(9,15,2,LEAVES2:13)
Block(10,15,2,LEAVES2:13)
Block(11,15,2,LEAVES2:13)
Block(-4,15,3,LEAVES2:13)
Block(-3,15,3,LEAVES2:13)
Block(-2,15,3,LEAVES2:13)
Block(-1,15,3,LEAVES2:13)
Block(0,15,3,LEAVES2:13)
Block(4,15,3,LOG2:13)
Block(6,15,3,LEAVES2:13)
Block(7,15,3,LEAVES2:13)
Block(8,15,3,LEAVES2:13)
Block(9,15,3,LEAVES2:13)
Block(10,15,3,LEAVES2:13)
Block(-3,15,4,LEAVES2:13)
Block(-2,15,4,LEAVES2:13)
Block(-1,15,4,LEAVES2:13)
Block(7,15,4,LEAVES2:13)
Block(8,15,4,LEAVES2:13)
Block(9,15,4,LEAVES2:13)
Block(7,16,-7,LOG2:13)
Block(4,16,-4,LOG2:13)
Block(-1,16,-3,LOG2:13)
Block(0,16,-3,LEAVES2:13)
Block(1,16,-3,LOG2:13)
Block(6,16,-3,LEAVES2:13)
Block(7,16,-3,LEAVES2:13)
Block(8,16,-3,LEAVES2:13)
Block(9,16,-3,LEAVES2:13)
Block(10,16,-3,LEAVES2:13)
Block(5,16,-2,LEAVES2:13)
Block(6,16,-2,LEAVES2:13)
Block(7,16,-2,LEAVES2:13)
Block(8,16,-2,LEAVES2:13)
Block(9,16,-2,LEAVES2:13)
Block(10,16,-2,LEAVES2:13)
Block(11,16,-2,LEAVES2:13)
Block(-1,16,-1,LOG2:13)
Block(2,16,-1,LOG2:13)
Block(3,16,-1,LOG2:13)
Block(4,16,-1,LEAVES2:13)
Block(5,16,-1,LEAVES2:13)
Block(6,16,-1,LEAVES2:13)
Block(7,16,-1,LEAVES2:13)
Block(8,16,-1,LEAVES2:13)
Block(9,16,-1,LEAVES2:13)
Block(10,16,-1,LEAVES2:13)
Block(11,16,-1,LEAVES2:13)
Block(12,16,-1,LEAVES2:13)
Block(-6,16,0,LOG2:13)
Block(-4,16,0,LEAVES2:13)
Block(-1,16,0,LOG2:13)
Block(2,16,0,LOG2:13)
Block(3,16,0,LOG2:13)
Block(4,16,0,LEAVES2:13)
Block(5,16,0,LEAVES2:13)
Block(6,16,0,LOG2:13)
Block(7,16,0,LEAVES2:13)
Block(8,16,0,LEAVES2:13)
Block(9,16,0,LEAVES2:13)
Block(10,16,0,LEAVES2:13)
Block(11,16,0,LEAVES2:13)
Block(12,16,0,LEAVES2:13)
Block(-5,16,1,LEAVES2:13)
Block(-4,16,1,LEAVES2:13)
Block(-3,16,1,LOG2:13)
Block(-2,16,1,LOG2:13)
Block(4,16,1,LEAVES2:13)
Block(5,16,1,LEAVES2:13)
Block(6,16,1,LEAVES2:13)
Block(7,16,1,LOG2:13)
Block(8,16,1,LEAVES2:13)
Block(9,16,1,LEAVES2:13)
Block(10,16,1,LEAVES2:13)
Block(11,16,1,LEAVES2:13)
Block(12,16,1,LEAVES2:13)
Block(-4,16,2,LEAVES2:13)
Block(-3,16,2,LEAVES2:13)
Block(-2,16,2,LEAVES2:13)
Block(-1,16,2,LEAVES2:13)
Block(4,16,2,LEAVES2:13)
Block(5,16,2,LEAVES2:13)
Block(6,16,2,LEAVES2:13)
Block(7,16,2,LEAVES2:13)
Block(8,16,2,LEAVES2:13)
Block(9,16,2,LEAVES2:13)
Block(10,16,2,LEAVES2:13)
Block(11,16,2,LEAVES2:13)
Block(12,16,2,LEAVES2:13)
Block(-2,16,3,LEAVES2:13)
Block(4,16,3,LEAVES2:13)
Block(5,16,3,LEAVES2:13)
Block(6,16,3,LEAVES2:13)
Block(7,16,3,LEAVES2:13)
Block(8,16,3,LEAVES2:13)
Block(9,16,3,LEAVES2:13)
Block(10,16,3,LEAVES2:13)
Block(11,16,3,LEAVES2:13)
Block(12,16,3,LEAVES2:13)
Block(4,16,4,LOG2:13)
Block(5,16,4,LEAVES2:13)
Block(6,16,4,LEAVES2:13)
Block(7,16,4,LEAVES2:13)
Block(8,16,4,LEAVES2:13)
Block(9,16,4,LEAVES2:13)
Block(10,16,4,LEAVES2:13)
Block(11,16,4,LEAVES2:13)
Block(6,16,5,LEAVES2:13)
Block(7,16,5,LEAVES2:13)
Block(8,16,5,LEAVES2:13)
Block(9,16,5,LEAVES2:13)
Block(10,16,5,LEAVES2:13)
Block(7,17,-7,LOG2:13)
Block(-1,17,-6,LEAVES2:13)
Block(-2,17,-5,LEAVES2:13)
Block(-1,17,-5,LEAVES2:13)
Block(0,17,-5,LEAVES2:13)
Block(4,17,-5,LOG2:13)
Block(-1,17,-4,LOG2:13)
Block(1,17,-4,LOG2:13)
Block(8,17,-4,LEAVES2:13)
Block(5,17,-3,LEAVES2:13)
Block(6,17,-3,LEAVES2:13)
Block(7,17,-3,LEAVES2:13)
Block(8,17,-3,LEAVES2:13)
Block(9,17,-3,LEAVES2:13)
Block(10,17,-3,LEAVES2:13)
Block(11,17,-3,LEAVES2:13)
Block(-6,17,-2,LEAVES2:13)
Block(-5,17,-2,LEAVES2:13)
Block(-4,17,-2,LEAVES2:13)
Block(-3,17,-2,LEAVES2:13)
Block(-2,17,-2,LEAVES2:13)
Block(4,17,-2,LEAVES2:13)
Block(5,17,-2,LEAVES2:13)
Block(6,17,-2,LEAVES2:13)
Block(7,17,-2,LEAVES2:13)
Block(8,17,-2,LEAVES2:13)
Block(9,17,-2,LEAVES2:13)
Block(10,17,-2,LEAVES2:13)
Block(11,17,-2,LEAVES2:13)
Block(12,17,-2,LEAVES2:13)
Block(-7,17,-1,LEAVES2:13)
Block(-6,17,-1,LEAVES2:13)
Block(-5,17,-1,LEAVES2:13)
Block(-4,17,-1,LEAVES2:13)
Block(-3,17,-1,LEAVES2:13)
Block(-2,17,-1,LOG2:13)
Block(-1,17,-1,LEAVES2:13)
Block(2,17,-1,LOG2:13)
Block(3,17,-1,LOG2:13)
Block(4,17,-1,LEAVES2:13)
Block(5,17,-1,LEAVES2:13)
Block(6,17,-1,LEAVES2:13)
Block(7,17,-1,LEAVES2:13)
Block(8,17,-1,LEAVES2:13)
Block(9,17,-1,LEAVES2:13)
Block(10,17,-1,LEAVES2:13)
Block(11,17,-1,LEAVES2:13)
Block(12,17,-1,LEAVES2:13)
Block(-8,17,0,LEAVES2:13)
Block(-7,17,0,LOG2:13)
Block(-6,17,0,LEAVES2:13)
Block(-5,17,0,LEAVES2:13)
Block(-4,17,0,LEAVES2:13)
Block(-3,17,0,LEAVES2:13)
Block(-2,17,0,LEAVES2:13)
Block(-1,17,0,LOG2:13)
Block(2,17,0,LOG2:13)
Block(3,17,0,LOG2:13)
Block(4,17,0,LEAVES2:13)
Block(5,17,0,LEAVES2:13)
Block(6,17,0,LEAVES2:13)
Block(7,17,0,LOG2:13)
Block(8,17,0,LEAVES2:13)
Block(9,17,0,LEAVES2:13)
Block(10,17,0,LEAVES2:13)
Block(11,17,0,LEAVES2:13)
Block(12,17,0,LEAVES2:13)
Block(-7,17,1,LEAVES2:13)
Block(-6,17,1,LEAVES2:13)
Block(-5,17,1,LEAVES2:13)
Block(-4,17,1,LOG2:13)
Block(-3,17,1,LEAVES2:13)
Block(-2,17,1,LEAVES2:13)
Block(-1,17,1,LEAVES2:13)
Block(3,17,1,LEAVES2:13)
Block(4,17,1,LEAVES2:13)
Block(5,17,1,LEAVES2:13)
Block(6,17,1,LEAVES2:13)
Block(7,17,1,LEAVES2:13)
Block(8,17,1,LOG2:13)
Block(9,17,1,LEAVES2:13)
Block(10,17,1,LEAVES2:13)
Block(11,17,1,LEAVES2:13)
Block(12,17,1,LEAVES2:13)
Block(13,17,1,LEAVES2:13)
Block(-7,17,2,LEAVES2:13)
Block(-6,17,2,LEAVES2:13)
Block(-5,17,2,LEAVES2:13)
Block(-4,17,2,LEAVES2:13)
Block(-3,17,2,LOG2:13)
Block(-2,17,2,LEAVES2:13)
Block(-1,17,2,LEAVES2:13)
Block(4,17,2,LEAVES2:13)
Block(5,17,2,LEAVES2:13)
Block(6,17,2,LEAVES2:13)
Block(7,17,2,LEAVES2:13)
Block(8,17,2,LEAVES2:13)
Block(9,17,2,LEAVES2:13)
Block(10,17,2,LEAVES2:13)
Block(11,17,2,LEAVES2:13)
Block(12,17,2,LEAVES2:13)
Block(-7,17,3,LEAVES2:13)
Block(-6,17,3,LEAVES2:13)
Block(-5,17,3,LEAVES2:13)
Block(-4,17,3,LEAVES2:13)
Block(-3,17,3,LEAVES2:13)
Block(-2,17,3,LEAVES2:13)
Block(-1,17,3,LEAVES2:13)
Block(4,17,3,LEAVES2:13)
Block(5,17,3,LEAVES2:13)
Block(6,17,3,LEAVES2:13)
Block(7,17,3,LEAVES2:13)
Block(8,17,3,LEAVES2:13)
Block(9,17,3,LEAVES2:13)
Block(10,17,3,LEAVES2:13)
Block(11,17,3,LEAVES2:13)
Block(12,17,3,LEAVES2:13)
Block(-6,17,4,LEAVES2:13)
Block(-5,17,4,LEAVES2:13)
Block(-4,17,4,LEAVES2:13)
Block(-3,17,4,LEAVES2:13)
Block(-2,17,4,LEAVES2:13)
Block(4,17,4,LOG2:13)
Block(5,17,4,LEAVES2:13)
Block(6,17,4,LEAVES2:13)
Block(7,17,4,LEAVES2:13)
Block(8,17,4,LEAVES2:13)
Block(9,17,4,LEAVES2:13)
Block(10,17,4,LEAVES2:13)
Block(11,17,4,LEAVES2:13)
Block(12,17,4,LEAVES2:13)
Block(5,17,5,LEAVES2:13)
Block(6,17,5,LEAVES2:13)
Block(7,17,5,LEAVES2:13)
Block(8,17,5,LEAVES2:13)
Block(9,17,5,LEAVES2:13)
Block(10,17,5,LEAVES2:13)
Block(11,17,5,LEAVES2:13)
Block(8,17,6,LEAVES2:13)
Block(-3,18,-8,LEAVES2:13)
Block(-2,18,-8,LEAVES2:13)
Block(-1,18,-8,LEAVES2:13)
Block(0,18,-8,LEAVES2:13)
Block(1,18,-8,LEAVES2:13)
Block(8,18,-8,LOG2:13)
Block(-4,18,-7,LEAVES2:13)
Block(-3,18,-7,LEAVES2:13)
Block(-2,18,-7,LEAVES2:13)
Block(-1,18,-7,LEAVES2:13)
Block(0,18,-7,LEAVES2:13)
Block(1,18,-7,LEAVES2:13)
Block(2,18,-7,LEAVES2:13)
Block(-4,18,-6,LEAVES2:13)
Block(-3,18,-6,LEAVES2:13)
Block(-2,18,-6,LEAVES2:13)
Block(-1,18,-6,LEAVES2:13)
Block(0,18,-6,LEAVES2:13)
Block(1,18,-6,LEAVES2:13)
Block(2,18,-6,LEAVES2:13)
Block(-7,18,-5,LEAVES2:13)
Block(-4,18,-5,LEAVES2:13)
Block(-3,18,-5,LEAVES2:13)
Block(-2,18,-5,LEAVES2:13)
Block(-1,18,-5,LEAVES2:13)
Block(0,18,-5,LOG2:13)
Block(1,18,-5,LEAVES2:13)
Block(2,18,-5,LEAVES2:13)
Block(5,18,-5,LOG2:13)
Block(-10,18,-4,LEAVES2:13)
Block(-9,18,-4,LEAVES2:13)
Block(-8,18,-4,LEAVES2:13)
Block(-7,18,-4,LEAVES2:13)
Block(-6,18,-4,LEAVES2:13)
Block(-5,18,-4,LEAVES2:13)
Block(-4,18,-4,LEAVES2:13)
Block(-3,18,-4,LEAVES2:13)
Block(-2,18,-4,LEAVES2:13)
Block(-1,18,-4,LOG2:13)
Block(0,18,-4,LEAVES2:13)
Block(1,18,-4,LEAVES2:13)
Block(2,18,-4,LEAVES2:13)
Block(-11,18,-3,LEAVES2:13)
Block(-10,18,-3,LEAVES2:13)
Block(-9,18,-3,LEAVES2:13)
Block(-8,18,-3,LEAVES2:13)
Block(-7,18,-3,LEAVES2:13)
Block(-6,18,-3,LEAVES2:13)
Block(-5,18,-3,LEAVES2:13)
Block(-4,18,-3,LEAVES2:13)
Block(-3,18,-3,LEAVES2:13)
Block(-2,18,-3,LEAVES2:13)
Block(-1,18,-3,LEAVES2:13)
Block(0,18,-3,LEAVES2:13)
Block(1,18,-3,LEAVES2:13)
Block(2,18,-3,LEAVES2:13)
Block(6,18,-3,LEAVES2:13)
Block(7,18,-3,LEAVES2:13)
Block(8,18,-3,LEAVES2:13)
Block(9,18,-3,LEAVES2:13)
Block(10,18,-3,LEAVES2:13)
Block(-11,18,-2,LEAVES2:13)
Block(-10,18,-2,LEAVES2:13)
Block(-9,18,-2,LEAVES2:13)
Block(-8,18,-2,LEAVES2:13)
Block(-7,18,-2,LEAVES2:13)
Block(-6,18,-2,LEAVES2:13)
Block(-5,18,-2,LEAVES2:13)
Block(-4,18,-2,LEAVES2:13)
Block(-3,18,-2,LEAVES2:13)
Block(-2,18,-2,LEAVES2:13)
Block(-1,18,-2,LEAVES2:13)
Block(0,18,-2,LEAVES2:13)
Block(1,18,-2,LEAVES2:13)
Block(5,18,-2,LEAVES2:13)
Block(6,18,-2,LEAVES2:13)
Block(7,18,-2,LEAVES2:13)
Block(8,18,-2,LEAVES2:13)
Block(9,18,-2,LEAVES2:13)
Block(10,18,-2,LEAVES2:13)
Block(11,18,-2,LEAVES2:13)
Block(-11,18,-1,LEAVES2:13)
Block(-10,18,-1,LEAVES2:13)
Block(-9,18,-1,LEAVES2:13)
Block(-8,18,-1,LEAVES2:13)
Block(-7,18,-1,LEAVES2:13)
Block(-6,18,-1,LEAVES2:13)
Block(-5,18,-1,LEAVES2:13)
Block(-4,18,-1,LEAVES2:13)
Block(-3,18,-1,LEAVES2:13)
Block(-2,18,-1,LOG2:13)
Block(-1,18,-1,LEAVES2:13)
Block(0,18,-1,LEAVES2:13)
Block(2,18,-1,LOG2:13)
Block(3,18,-1,LOG2:13)
Block(4,18,-1,LEAVES2:13)
Block(5,18,-1,LEAVES2:13)
Block(6,18,-1,LEAVES2:13)
Block(7,18,-1,LEAVES2:13)
Block(8,18,-1,LEAVES2:13)
Block(9,18,-1,LEAVES2:13)
Block(10,18,-1,LEAVES2:13)
Block(11,18,-1,LEAVES2:13)
Block(12,18,-1,LEAVES2:13)
Block(-12,18,0,LEAVES2:13)
Block(-11,18,0,LEAVES2:13)
Block(-10,18,0,LEAVES2:13)
Block(-9,18,0,LEAVES2:13)
Block(-8,18,0,LEAVES2:13)
Block(-7,18,0,LOG2:13)
Block(-6,18,0,LEAVES2:13)
Block(-5,18,0,LEAVES2:13)
Block(-4,18,0,LEAVES2:13)
Block(-3,18,0,LEAVES2:13)
Block(-2,18,0,LOG2:13)
Block(-1,18,0,LEAVES2:13)
Block(0,18,0,LEAVES2:13)
Block(2,18,0,LOG2:13)
Block(3,18,0,LOG2:13)
Block(4,18,0,LEAVES2:13)
Block(5,18,0,LEAVES2:13)
Block(6,18,0,LEAVES2:13)
Block(7,18,0,LOG2:13)
Block(8,18,0,LEAVES2:13)
Block(9,18,0,LEAVES2:13)
Block(10,18,0,LEAVES2:13)
Block(11,18,0,LEAVES2:13)
Block(12,18,0,LEAVES2:13)
Block(-11,18,1,LEAVES2:13)
Block(-10,18,1,LEAVES2:13)
Block(-9,18,1,LEAVES2:13)
Block(-8,18,1,LEAVES2:13)
Block(-7,18,1,LEAVES2:13)
Block(-6,18,1,LEAVES2:13)
Block(-5,18,1,LEAVES2:13)
Block(-4,18,1,LOG2:13)
Block(-3,18,1,LEAVES2:13)
Block(-2,18,1,LEAVES2:13)
Block(-1,18,1,LEAVES2:13)
Block(0,18,1,LEAVES2:13)
Block(1,18,1,LEAVES2:13)
Block(2,18,1,LEAVES2:13)
Block(3,18,1,LEAVES2:13)
Block(4,18,1,LEAVES2:13)
Block(5,18,1,LEAVES2:13)
Block(6,18,1,LEAVES2:13)
Block(7,18,1,LEAVES2:13)
Block(8,18,1,LEAVES2:13)
Block(9,18,1,LEAVES2:13)
Block(10,18,1,LEAVES2:13)
Block(11,18,1,LEAVES2:13)
Block(12,18,1,LEAVES2:13)
Block(-11,18,2,LEAVES2:13)
Block(-10,18,2,LEAVES2:13)
Block(-9,18,2,LEAVES2:13)
Block(-8,18,2,LEAVES2:13)
Block(-7,18,2,LEAVES2:13)
Block(-6,18,2,LEAVES2:13)
Block(-5,18,2,LEAVES2:13)
Block(-4,18,2,LEAVES2:13)
Block(-3,18,2,LOG2:13)
Block(-2,18,2,LEAVES2:13)
Block(-1,18,2,LEAVES2:13)
Block(0,18,2,LEAVES2:13)
Block(1,18,2,LEAVES2:13)
Block(2,18,2,LEAVES2:13)
Block(3,18,2,LEAVES2:13)
Block(4,18,2,LEAVES2:13)
Block(5,18,2,LEAVES2:13)
Block(6,18,2,LEAVES2:13)
Block(7,18,2,LEAVES2:13)
Block(8,18,2,LEAVES2:13)
Block(9,18,2,LEAVES2:13)
Block(10,18,2,LEAVES2:13)
Block(11,18,2,LEAVES2:13)
Block(12,18,2,LEAVES2:13)
Block(-11,18,3,LEAVES2:13)
Block(-10,18,3,LEAVES2:13)
Block(-9,18,3,LEAVES2:13)
Block(-8,18,3,LEAVES2:13)
Block(-7,18,3,LEAVES2:13)
Block(-6,18,3,LEAVES2:13)
Block(-5,18,3,LEAVES2:13)
Block(-4,18,3,LEAVES2:13)
Block(-3,18,3,LEAVES2:13)
Block(-2,18,3,LEAVES2:13)
Block(-1,18,3,LEAVES2:13)
Block(0,18,3,LEAVES2:13)
Block(1,18,3,LEAVES2:13)
Block(2,18,3,LEAVES2:13)
Block(3,18,3,LEAVES2:13)
Block(4,18,3,LEAVES2:13)
Block(5,18,3,LEAVES2:13)
Block(6,18,3,LEAVES2:13)
Block(7,18,3,LEAVES2:13)
Block(8,18,3,LEAVES2:13)
Block(9,18,3,LEAVES2:13)
Block(10,18,3,LEAVES2:13)
Block(11,18,3,LEAVES2:13)
Block(12,18,3,LEAVES2:13)
Block(-10,18,4,LEAVES2:13)
Block(-9,18,4,LEAVES2:13)
Block(-8,18,4,LEAVES2:13)
Block(-7,18,4,LEAVES2:13)
Block(-6,18,4,LEAVES2:13)
Block(-5,18,4,LEAVES2:13)
Block(-4,18,4,LEAVES2:13)
Block(-3,18,4,LEAVES2:13)
Block(-2,18,4,LEAVES2:13)
Block(-1,18,4,LEAVES2:13)
Block(0,18,4,LEAVES2:13)
Block(1,18,4,LEAVES2:13)
Block(2,18,4,LEAVES2:13)
Block(3,18,4,LEAVES2:13)
Block(4,18,4,LEAVES2:13)
Block(5,18,4,LOG2:13)
Block(6,18,4,LEAVES2:13)
Block(7,18,4,LEAVES2:13)
Block(8,18,4,LEAVES2:13)
Block(9,18,4,LEAVES2:13)
Block(10,18,4,LEAVES2:13)
Block(11,18,4,LEAVES2:13)
Block(-7,18,5,LEAVES2:13)
Block(-6,18,5,LEAVES2:13)
Block(-5,18,5,LEAVES2:13)
Block(-4,18,5,LEAVES2:13)
Block(-3,18,5,LEAVES2:13)
Block(-2,18,5,LEAVES2:13)
Block(-1,18,5,LEAVES2:13)
Block(1,18,5,LEAVES2:13)
Block(2,18,5,LEAVES2:13)
Block(3,18,5,LEAVES2:13)
Block(4,18,5,LEAVES2:13)
Block(5,18,5,LEAVES2:13)
Block(6,18,5,LEAVES2:13)
Block(7,18,5,LEAVES2:13)
Block(8,18,5,LEAVES2:13)
Block(9,18,5,LEAVES2:13)
Block(10,18,5,LEAVES2:13)
Block(-4,18,6,LEAVES2:13)
Block(1,18,6,LEAVES2:13)
Block(2,18,6,LEAVES2:13)
Block(3,18,6,LEAVES2:13)
Block(4,18,6,LEAVES2:13)
Block(5,18,6,LEAVES2:13)
Block(6,18,6,LEAVES2:13)
Block(7,18,6,LEAVES2:13)
Block(8,18,6,LEAVES2:13)
Block(9,18,6,LEAVES2:13)
Block(1,18,7,LEAVES2:13)
Block(2,18,7,LEAVES2:13)
Block(3,18,7,LEAVES2:13)
Block(4,18,7,LEAVES2:13)
Block(5,18,7,LEAVES2:13)
Block(6,18,7,LEAVES2:13)
Block(7,18,7,LEAVES2:13)
Block(8,18,7,LEAVES2:13)
Block(9,18,7,LEAVES2:13)
Block(2,18,8,LEAVES2:13)
Block(3,18,8,LEAVES2:13)
Block(4,18,8,LEAVES2:13)
Block(5,18,8,LEAVES2:13)
Block(6,18,8,LEAVES2:13)
Block(7,18,8,LEAVES2:13)
Block(8,18,8,LEAVES2:13)
Block(5,18,9,LEAVES2:13)
Block(-1,19,-10,LEAVES2:13)
Block(9,19,-10,LEAVES2:13)
Block(-4,19,-9,LEAVES2:13)
Block(-3,19,-9,LEAVES2:13)
Block(-2,19,-9,LEAVES2:13)
Block(-1,19,-9,LEAVES2:13)
Block(0,19,-9,LEAVES2:13)
Block(1,19,-9,LEAVES2:13)
Block(2,19,-9,LEAVES2:13)
Block(8,19,-9,LOG2:13)
Block(-5,19,-8,LEAVES2:13)
Block(-4,19,-8,LEAVES2:13)
Block(-3,19,-8,LEAVES2:13)
Block(-2,19,-8,LEAVES2:13)
Block(-1,19,-8,LEAVES2:13)
Block(0,19,-8,LEAVES2:13)
Block(1,19,-8,LEAVES2:13)
Block(2,19,-8,LEAVES2:13)
Block(3,19,-8,LEAVES2:13)
Block(-5,19,-7,LEAVES2:13)
Block(-4,19,-7,LEAVES2:13)
Block(-3,19,-7,LEAVES2:13)
Block(-2,19,-7,LEAVES2:13)
Block(-1,19,-7,LEAVES2:13)
Block(0,19,-7,LEAVES2:13)
Block(1,19,-7,LEAVES2:13)
Block(2,19,-7,LEAVES2:13)
Block(3,19,-7,LEAVES2:13)
Block(-5,19,-6,LEAVES2:13)
Block(-4,19,-6,LEAVES2:13)
Block(-3,19,-6,LEAVES2:13)
Block(-2,19,-6,LEAVES2:13)
Block(-1,19,-6,LEAVES2:13)
Block(0,19,-6,LEAVES2:13)
Block(1,19,-6,LEAVES2:13)
Block(2,19,-6,LEAVES2:13)
Block(3,19,-6,LEAVES2:13)
Block(5,19,-6,LOG2:13)
Block(-6,19,-5,LEAVES2:13)
Block(-5,19,-5,LEAVES2:13)
Block(-4,19,-5,LEAVES2:13)
Block(-3,19,-5,LEAVES2:13)
Block(-2,19,-5,LEAVES2:13)
Block(-1,19,-5,LOG2:13)
Block(0,19,-5,LOG2:13)
Block(1,19,-5,LEAVES2:13)
Block(2,19,-5,LEAVES2:13)
Block(3,19,-5,LEAVES2:13)
Block(4,19,-5,LEAVES2:13)
Block(-5,19,-4,LEAVES2:13)
Block(-4,19,-4,LEAVES2:13)
Block(-3,19,-4,LEAVES2:13)
Block(-2,19,-4,LEAVES2:13)
Block(-1,19,-4,LEAVES2:13)
Block(0,19,-4,LEAVES2:13)
Block(1,19,-4,LEAVES2:13)
Block(2,19,-4,LEAVES2:13)
Block(3,19,-4,LEAVES2:13)
Block(-5,19,-3,LEAVES2:13)
Block(-4,19,-3,LEAVES2:13)
Block(-3,19,-3,LEAVES2:13)
Block(-2,19,-3,LEAVES2:13)
Block(-1,19,-3,LEAVES2:13)
Block(0,19,-3,LEAVES2:13)
Block(1,19,-3,LEAVES2:13)
Block(2,19,-3,LEAVES2:13)
Block(3,19,-3,LEAVES2:13)
Block(-6,19,-2,LEAVES2:13)
Block(-5,19,-2,LEAVES2:13)
Block(-4,19,-2,LEAVES2:13)
Block(-3,19,-2,LEAVES2:13)
Block(-2,19,-2,LEAVES2:13)
Block(-1,19,-2,LEAVES2:13)
Block(0,19,-2,LEAVES2:13)
Block(1,19,-2,LEAVES2:13)
Block(2,19,-2,LEAVES2:13)
Block(3,19,-2,LEAVES2:13)
Block(7,19,-2,LEAVES2:13)
Block(8,19,-2,LEAVES2:13)
Block(9,19,-2,LEAVES2:13)
Block(-7,19,-1,LEAVES2:13)
Block(-6,19,-1,LEAVES2:13)
Block(-5,19,-1,LEAVES2:13)
Block(-4,19,-1,LEAVES2:13)
Block(-3,19,-1,LEAVES2:13)
Block(-2,19,-1,LOG2:13)
Block(-1,19,-1,LEAVES2:13)
Block(0,19,-1,LEAVES2:13)
Block(1,19,-1,LEAVES2:13)
Block(2,19,-1,LOG2:13)
Block(3,19,-1,LOG2:13)
Block(6,19,-1,LEAVES2:13)
Block(7,19,-1,LEAVES2:13)
Block(8,19,-1,LEAVES2:13)
Block(9,19,-1,LEAVES2:13)
Block(10,19,-1,LEAVES2:13)
Block(-8,19,0,LEAVES2:13)
Block(-7,19,0,LEAVES2:13)
Block(-6,19,0,LEAVES2:13)
Block(-5,19,0,LEAVES2:13)
Block(-4,19,0,LEAVES2:13)
Block(-3,19,0,LEAVES2:13)
Block(-2,19,0,LOG2:13)
Block(-1,19,0,LEAVES2:13)
Block(0,19,0,LEAVES2:13)
Block(2,19,0,LOG2:13)
Block(3,19,0,LOG2:13)
Block(5,19,0,LEAVES2:13)
Block(6,19,0,LEAVES2:13)
Block(7,19,0,LEAVES2:13)
Block(8,19,0,LOG2:13)
Block(9,19,0,LEAVES2:13)
Block(10,19,0,LEAVES2:13)
Block(11,19,0,LEAVES2:13)
Block(-7,19,1,LEAVES2:13)
Block(-6,19,1,LEAVES2:13)
Block(-5,19,1,LEAVES2:13)
Block(-4,19,1,LEAVES2:13)
Block(-3,19,1,LEAVES2:13)
Block(-2,19,1,LEAVES2:13)
Block(-1,19,1,LEAVES2:13)
Block(0,19,1,LEAVES2:13)
Block(5,19,1,LEAVES2:13)
Block(6,19,1,LEAVES2:13)
Block(7,19,1,LEAVES2:13)
Block(8,19,1,LEAVES2:13)
Block(9,19,1,LEAVES2:13)
Block(10,19,1,LEAVES2:13)
Block(11,19,1,LEAVES2:13)
Block(-7,19,2,LEAVES2:13)
Block(-6,19,2,LEAVES2:13)
Block(-5,19,2,LEAVES2:13)
Block(-4,19,2,LOG2:13)
Block(-3,19,2,LEAVES2:13)
Block(-2,19,2,LEAVES2:13)
Block(-1,19,2,LEAVES2:13)
Block(5,19,2,LEAVES2:13)
Block(6,19,2,LEAVES2:13)
Block(7,19,2,LEAVES2:13)
Block(8,19,2,LEAVES2:13)
Block(9,19,2,LEAVES2:13)
Block(10,19,2,LEAVES2:13)
Block(11,19,2,LEAVES2:13)
Block(-7,19,3,LEAVES2:13)
Block(-6,19,3,LEAVES2:13)
Block(-5,19,3,LEAVES2:13)
Block(-4,19,3,LEAVES2:13)
Block(-3,19,3,LEAVES2:13)
Block(-2,19,3,LEAVES2:13)
Block(-1,19,3,LEAVES2:13)
Block(5,19,3,LEAVES2:13)
Block(6,19,3,LEAVES2:13)
Block(7,19,3,LEAVES2:13)
Block(8,19,3,LEAVES2:13)
Block(9,19,3,LEAVES2:13)
Block(10,19,3,LEAVES2:13)
Block(-6,19,4,LEAVES2:13)
Block(-5,19,4,LEAVES2:13)
Block(-4,19,4,LEAVES2:13)
Block(-3,19,4,LEAVES2:13)
Block(-2,19,4,LEAVES2:13)
Block(4,19,4,LEAVES2:13)
Block(5,19,4,LEAVES2:13)
Block(6,19,4,LEAVES2:13)
Block(7,19,4,LEAVES2:13)
Block(8,19,4,LEAVES2:13)
Block(9,19,4,LEAVES2:13)
Block(5,19,5,LEAVES2:13)
Block(9,20,-13,LEAVES2:13)
Block(7,20,-12,LEAVES2:13)
Block(8,20,-12,LEAVES2:13)
Block(9,20,-12,LEAVES2:13)
Block(10,20,-12,LEAVES2:13)
Block(11,20,-12,LEAVES2:13)
Block(7,20,-11,LEAVES2:13)
Block(8,20,-11,LEAVES2:13)
Block(9,20,-11,LEAVES2:13)
Block(10,20,-11,LEAVES2:13)
Block(11,20,-11,LEAVES2:13)
Block(6,20,-10,LEAVES2:13)
Block(7,20,-10,LEAVES2:13)
Block(8,20,-10,LEAVES2:13)
Block(9,20,-10,LOG2:13)
Block(10,20,-10,LEAVES2:13)
Block(11,20,-10,LEAVES2:13)
Block(12,20,-10,LEAVES2:13)
Block(7,20,-9,LEAVES2:13)
Block(8,20,-9,LEAVES2:13)
Block(9,20,-9,LEAVES2:13)
Block(10,20,-9,LEAVES2:13)
Block(11,20,-9,LEAVES2:13)
Block(-3,20,-8,LEAVES2:13)
Block(-2,20,-8,LEAVES2:13)
Block(-1,20,-8,LEAVES2:13)
Block(0,20,-8,LEAVES2:13)
Block(1,20,-8,LEAVES2:13)
Block(7,20,-8,LEAVES2:13)
Block(8,20,-8,LEAVES2:13)
Block(9,20,-8,LEAVES2:13)
Block(10,20,-8,LEAVES2:13)
Block(11,20,-8,LEAVES2:13)
Block(-4,20,-7,LEAVES2:13)
Block(-3,20,-7,LEAVES2:13)
Block(-2,20,-7,LEAVES2:13)
Block(-1,20,-7,LEAVES2:13)
Block(0,20,-7,LEAVES2:13)
Block(1,20,-7,LEAVES2:13)
Block(2,20,-7,LEAVES2:13)
Block(9,20,-7,LEAVES2:13)
Block(-4,20,-6,LEAVES2:13)
Block(-3,20,-6,LEAVES2:13)
Block(-2,20,-6,LEAVES2:13)
Block(-1,20,-6,LEAVES2:13)
Block(0,20,-6,LOG2:13)
Block(1,20,-6,LEAVES2:13)
Block(2,20,-6,LEAVES2:13)
Block(5,20,-6,LOG2:13)
Block(-4,20,-5,LEAVES2:13)
Block(-3,20,-5,LEAVES2:13)
Block(-2,20,-5,LEAVES2:13)
Block(-1,20,-5,LEAVES2:13)
Block(0,20,-5,LEAVES2:13)
Block(1,20,-5,LEAVES2:13)
Block(2,20,-5,LEAVES2:13)
Block(-4,20,-4,LEAVES2:13)
Block(-3,20,-4,LEAVES2:13)
Block(-2,20,-4,LEAVES2:13)
Block(-1,20,-4,LEAVES2:13)
Block(0,20,-4,LEAVES2:13)
Block(1,20,-4,LEAVES2:13)
Block(2,20,-4,LEAVES2:13)
Block(-4,20,-3,LEAVES2:13)
Block(-3,20,-3,LEAVES2:13)
Block(-2,20,-3,LEAVES2:13)
Block(-1,20,-3,LEAVES2:13)
Block(0,20,-3,LEAVES2:13)
Block(1,20,-3,LEAVES2:13)
Block(2,20,-3,LEAVES2:13)
Block(3,20,-3,LEAVES2:13)
Block(-4,20,-2,LEAVES2:13)
Block(-3,20,-2,LEAVES2:13)
Block(-2,20,-2,LEAVES2:13)
Block(-1,20,-2,LEAVES2:13)
Block(0,20,-2,LEAVES2:13)
Block(1,20,-2,LEAVES2:13)
Block(2,20,-2,LEAVES2:13)
Block(3,20,-2,LEAVES2:13)
Block(4,20,-2,LEAVES2:13)
Block(-6,20,-1,LEAVES2:13)
Block(-5,20,-1,LEAVES2:13)
Block(-4,20,-1,LEAVES2:13)
Block(-3,20,-1,LOG2:13)
Block(-2,20,-1,LEAVES2:13)
Block(-1,20,-1,LEAVES2:13)
Block(0,20,-1,LEAVES2:13)
Block(1,20,-1,LEAVES2:13)
Block(2,20,-1,LOG2:13)
Block(3,20,-1,LOG2:13)
Block(4,20,-1,LEAVES2:13)
Block(-7,20,0,LEAVES2:13)
Block(-6,20,0,LEAVES2:13)
Block(-5,20,0,LEAVES2:13)
Block(-4,20,0,LEAVES2:13)
Block(-3,20,0,LEAVES2:13)
Block(-2,20,0,LOG2:13)
Block(-1,20,0,LEAVES2:13)
Block(0,20,0,LEAVES2:13)
Block(1,20,0,LEAVES2:13)
Block(2,20,0,LOG2:13)
Block(3,20,0,LOG2:13)
Block(4,20,0,LEAVES2:13)
Block(8,20,0,LOG2:13)
Block(-8,20,1,LEAVES2:13)
Block(-7,20,1,LEAVES2:13)
Block(-6,20,1,LEAVES2:13)
Block(-5,20,1,LEAVES2:13)
Block(-4,20,1,LEAVES2:13)
Block(-3,20,1,LEAVES2:13)
Block(-2,20,1,LEAVES2:13)
Block(-1,20,1,LEAVES2:13)
Block(0,20,1,LEAVES2:13)
Block(1,20,1,LEAVES2:13)
Block(2,20,1,LEAVES2:13)
Block(3,20,1,LEAVES2:13)
Block(7,20,1,LEAVES2:13)
Block(8,20,1,LEAVES2:13)
Block(9,20,1,LEAVES2:13)
Block(-8,20,2,LEAVES2:13)
Block(-7,20,2,LEAVES2:13)
Block(-6,20,2,LEAVES2:13)
Block(-5,20,2,LEAVES2:13)
Block(-4,20,2,LOG2:13)
Block(-3,20,2,LEAVES2:13)
Block(-2,20,2,LEAVES2:13)
Block(-1,20,2,LEAVES2:13)
Block(0,20,2,LEAVES2:13)
Block(8,20,2,LEAVES2:13)
Block(-8,20,3,LEAVES2:13)
Block(-7,20,3,LEAVES2:13)
Block(-6,20,3,LEAVES2:13)
Block(-5,20,3,LEAVES2:13)
Block(-4,20,3,LEAVES2:13)
Block(-3,20,3,LEAVES2:13)
Block(-2,20,3,LEAVES2:13)
Block(-7,20,4,LEAVES2:13)
Block(-6,20,4,LEAVES2:13)
Block(-5,20,4,LEAVES2:13)
Block(-4,20,4,LEAVES2:13)
Block(-3,20,4,LEAVES2:13)
Block(-6,20,5,LEAVES2:13)
Block(-5,20,5,LEAVES2:13)
Block(-4,20,5,LEAVES2:13)
Block(9,21,-10,LEAVES2:13)
Block(0,21,-9,LEAVES2:13)
Block(-1,21,-8,LEAVES2:13)
Block(0,21,-8,LEAVES2:13)
Block(1,21,-8,LEAVES2:13)
Block(0,21,-7,LOG2:13)
Block(5,21,-7,LOG2:13)
Block(-1,21,-6,LEAVES2:13)
Block(-2,21,-5,LEAVES2:13)
Block(-1,21,-5,LEAVES2:13)
Block(0,21,-5,LEAVES2:13)
Block(-1,21,-4,LEAVES2:13)
Block(1,21,-4,LEAVES2:13)
Block(2,21,-4,LEAVES2:13)
Block(3,21,-4,LEAVES2:13)
Block(0,21,-3,LEAVES2:13)
Block(1,21,-3,LEAVES2:13)
Block(2,21,-3,LEAVES2:13)
Block(3,21,-3,LEAVES2:13)
Block(4,21,-3,LEAVES2:13)
Block(-7,21,-2,LEAVES2:13)
Block(-6,21,-2,LEAVES2:13)
Block(-5,21,-2,LEAVES2:13)
Block(-4,21,-2,LEAVES2:13)
Block(-3,21,-2,LEAVES2:13)
Block(-2,21,-2,LEAVES2:13)
Block(-1,21,-2,LEAVES2:13)
Block(0,21,-2,LEAVES2:13)
Block(1,21,-2,LEAVES2:13)
Block(2,21,-2,LEAVES2:13)
Block(3,21,-2,LEAVES2:13)
Block(4,21,-2,LEAVES2:13)
Block(5,21,-2,LEAVES2:13)
Block(-8,21,-1,LEAVES2:13)
Block(-7,21,-1,LEAVES2:13)
Block(-6,21,-1,LEAVES2:13)
Block(-5,21,-1,LEAVES2:13)
Block(-4,21,-1,LEAVES2:13)
Block(-3,21,-1,LOG2:13)
Block(-2,21,-1,LEAVES2:13)
Block(-1,21,-1,LEAVES2:13)
Block(0,21,-1,LEAVES2:13)
Block(1,21,-1,LEAVES2:13)
Block(2,21,-1,LOG2:13)
Block(3,21,-1,LOG2:13)
Block(4,21,-1,LEAVES2:13)
Block(5,21,-1,LEAVES2:13)
Block(-9,21,0,LEAVES2:13)
Block(-8,21,0,LEAVES2:13)
Block(-7,21,0,LEAVES2:13)
Block(-6,21,0,LEAVES2:13)
Block(-5,21,0,LEAVES2:13)
Block(-4,21,0,LEAVES2:13)
Block(-3,21,0,LEAVES2:13)
Block(-2,21,0,LEAVES2:13)
Block(-1,21,0,LEAVES2:13)
Block(0,21,0,LEAVES2:13)
Block(1,21,0,LEAVES2:13)
Block(2,21,0,LOG2:13)
Block(3,21,0,LOG2:13)
Block(4,21,0,LEAVES2:13)
Block(5,21,0,LEAVES2:13)
Block(9,21,0,LOG2:13)
Block(-9,21,1,LEAVES2:13)
Block(-8,21,1,LEAVES2:13)
Block(-7,21,1,LEAVES2:13)
Block(-6,21,1,LEAVES2:13)
Block(-5,21,1,LEAVES2:13)
Block(-4,21,1,LEAVES2:13)
Block(-3,21,1,LEAVES2:13)
Block(-2,21,1,LEAVES2:13)
Block(-1,21,1,LEAVES2:13)
Block(0,21,1,LEAVES2:13)
Block(1,21,1,LEAVES2:13)
Block(2,21,1,LEAVES2:13)
Block(3,21,1,LEAVES2:13)
Block(4,21,1,LEAVES2:13)
Block(-9,21,2,LEAVES2:13)
Block(-8,21,2,LEAVES2:13)
Block(-7,21,2,LEAVES2:13)
Block(-6,21,2,LEAVES2:13)
Block(-5,21,2,LOG2:13)
Block(-4,21,2,LEAVES2:13)
Block(-3,21,2,LEAVES2:13)
Block(-2,21,2,LEAVES2:13)
Block(-1,21,2,LEAVES2:13)
Block(1,21,2,LEAVES2:13)
Block(2,21,2,LEAVES2:13)
Block(3,21,2,LEAVES2:13)
Block(-9,21,3,LEAVES2:13)
Block(-8,21,3,LEAVES2:13)
Block(-7,21,3,LEAVES2:13)
Block(-6,21,3,LEAVES2:13)
Block(-5,21,3,LEAVES2:13)
Block(-4,21,3,LEAVES2:13)
Block(-3,21,3,LEAVES2:13)
Block(-2,21,3,LEAVES2:13)
Block(-1,21,3,LEAVES2:13)
Block(-9,21,4,LEAVES2:13)
Block(-8,21,4,LEAVES2:13)
Block(-7,21,4,LEAVES2:13)
Block(-6,21,4,LEAVES2:13)
Block(-5,21,4,LEAVES2:13)
Block(-4,21,4,LEAVES2:13)
Block(-3,21,4,LEAVES2:13)
Block(-2,21,4,LEAVES2:13)
Block(-1,21,4,LEAVES2:13)
Block(-8,21,5,LEAVES2:13)
Block(-7,21,5,LEAVES2:13)
Block(-6,21,5,LEAVES2:13)
Block(-5,21,5,LEAVES2:13)
Block(-4,21,5,LEAVES2:13)
Block(-3,21,5,LEAVES2:13)
Block(-2,21,5,LEAVES2:13)
Block(-7,21,6,LEAVES2:13)
Block(-6,21,6,LEAVES2:13)
Block(-5,21,6,LEAVES2:13)
Block(-4,21,6,LEAVES2:13)
Block(-3,21,6,LEAVES2:13)
Block(0,22,-12,LEAVES2:13)
Block(-2,22,-11,LEAVES2:13)
Block(-1,22,-11,LEAVES2:13)
Block(0,22,-11,LEAVES2:13)
Block(1,22,-11,LEAVES2:13)
Block(2,22,-11,LEAVES2:13)
Block(-3,22,-10,LEAVES2:13)
Block(-2,22,-10,LEAVES2:13)
Block(-1,22,-10,LEAVES2:13)
Block(0,22,-10,LEAVES2:13)
Block(1,22,-10,LEAVES2:13)
Block(2,22,-10,LEAVES2:13)
Block(3,22,-10,LEAVES2:13)
Block(-3,22,-9,LEAVES2:13)
Block(-2,22,-9,LEAVES2:13)
Block(-1,22,-9,LEAVES2:13)
Block(0,22,-9,LEAVES2:13)
Block(1,22,-9,LEAVES2:13)
Block(2,22,-9,LEAVES2:13)
Block(3,22,-9,LEAVES2:13)
Block(-4,22,-8,LEAVES2:13)
Block(-3,22,-8,LEAVES2:13)
Block(-2,22,-8,LEAVES2:13)
Block(-1,22,-8,LEAVES2:13)
Block(0,22,-8,LOG2:13)
Block(1,22,-8,LEAVES2:13)
Block(2,22,-8,LEAVES2:13)
Block(3,22,-8,LEAVES2:13)
Block(4,22,-8,LEAVES2:13)
Block(-3,22,-7,LEAVES2:13)
Block(-2,22,-7,LEAVES2:13)
Block(-1,22,-7,LEAVES2:13)
Block(0,22,-7,LEAVES2:13)
Block(1,22,-7,LEAVES2:13)
Block(2,22,-7,LEAVES2:13)
Block(3,22,-7,LEAVES2:13)
Block(5,22,-7,LOG2:13)
Block(-3,22,-6,LEAVES2:13)
Block(-2,22,-6,LEAVES2:13)
Block(-1,22,-6,LEAVES2:13)
Block(0,22,-6,LEAVES2:13)
Block(1,22,-6,LEAVES2:13)
Block(2,22,-6,LEAVES2:13)
Block(3,22,-6,LEAVES2:13)
Block(-2,22,-5,LEAVES2:13)
Block(-1,22,-5,LEAVES2:13)
Block(0,22,-5,LEAVES2:13)
Block(1,22,-5,LEAVES2:13)
Block(2,22,-5,LEAVES2:13)
Block(3,22,-5,LEAVES2:13)
Block(-3,22,-4,LEAVES2:13)
Block(-1,22,-4,LEAVES2:13)
Block(0,22,-4,LEAVES2:13)
Block(1,22,-4,LEAVES2:13)
Block(2,22,-4,LEAVES2:13)
Block(3,22,-4,LEAVES2:13)
Block(4,22,-4,LEAVES2:13)
Block(5,22,-4,LEAVES2:13)
Block(-5,22,-3,LEAVES2:13)
Block(-4,22,-3,LEAVES2:13)
Block(-3,22,-3,LEAVES2:13)
Block(-2,22,-3,LEAVES2:13)
Block(-1,22,-3,LEAVES2:13)
Block(0,22,-3,LEAVES2:13)
Block(1,22,-3,LEAVES2:13)
Block(2,22,-3,LEAVES2:13)
Block(3,22,-3,LEAVES2:13)
Block(4,22,-3,LEAVES2:13)
Block(5,22,-3,LEAVES2:13)
Block(-8,22,-2,LEAVES2:13)
Block(-7,22,-2,LEAVES2:13)
Block(-6,22,-2,LEAVES2:13)
Block(-5,22,-2,LEAVES2:13)
Block(-4,22,-2,LEAVES2:13)
Block(-3,22,-2,LEAVES2:13)
Block(-2,22,-2,LEAVES2:13)
Block(-1,22,-2,LEAVES2:13)
Block(0,22,-2,LEAVES2:13)
Block(1,22,-2,LEAVES2:13)
Block(2,22,-2,LEAVES2:13)
Block(3,22,-2,LEAVES2:13)
Block(4,22,-2,LEAVES2:13)
Block(5,22,-2,LEAVES2:13)
Block(6,22,-2,LEAVES2:13)
Block(-9,22,-1,LEAVES2:13)
Block(-8,22,-1,LEAVES2:13)
Block(-7,22,-1,LEAVES2:13)
Block(-6,22,-1,LEAVES2:13)
Block(-5,22,-1,LEAVES2:13)
Block(-4,22,-1,LEAVES2:13)
Block(-3,22,-1,LOG2:13)
Block(-2,22,-1,LEAVES2:13)
Block(-1,22,-1,LEAVES2:13)
Block(0,22,-1,LEAVES2:13)
Block(1,22,-1,LEAVES2:13)
Block(2,22,-1,LOG2:13)
Block(3,22,-1,LOG2:13)
Block(4,22,-1,LEAVES2:13)
Block(5,22,-1,LEAVES2:13)
Block(6,22,-1,LEAVES2:13)
Block(-9,22,0,LEAVES2:13)
Block(-8,22,0,LEAVES2:13)
Block(-7,22,0,LEAVES2:13)
Block(-6,22,0,LEAVES2:13)
Block(-5,22,0,LEAVES2:13)
Block(-4,22,0,LEAVES2:13)
Block(-3,22,0,LEAVES2:13)
Block(-2,22,0,LEAVES2:13)
Block(-1,22,0,LEAVES2:13)
Block(0,22,0,LEAVES2:13)
Block(1,22,0,LEAVES2:13)
Block(2,22,0,LOG2:13)
Block(3,22,0,LOG2:13)
Block(4,22,0,LEAVES2:13)
Block(5,22,0,LEAVES2:13)
Block(6,22,0,LEAVES2:13)
Block(9,22,0,LOG2:13)
Block(-9,22,1,LEAVES2:13)
Block(-8,22,1,LEAVES2:13)
Block(-7,22,1,LEAVES2:13)
Block(-6,22,1,LEAVES2:13)
Block(-5,22,1,LEAVES2:13)
Block(-4,22,1,LEAVES2:13)
Block(-3,22,1,LEAVES2:13)
Block(-2,22,1,LEAVES2:13)
Block(-1,22,1,LEAVES2:13)
Block(0,22,1,LEAVES2:13)
Block(1,22,1,LEAVES2:13)
Block(2,22,1,LEAVES2:13)
Block(3,22,1,LEAVES2:13)
Block(4,22,1,LEAVES2:13)
Block(5,22,1,LEAVES2:13)
Block(-10,22,2,LEAVES2:13)
Block(-9,22,2,LEAVES2:13)
Block(-8,22,2,LEAVES2:13)
Block(-7,22,2,LEAVES2:13)
Block(-6,22,2,LEAVES2:13)
Block(-5,22,2,LOG2:13)
Block(-4,22,2,LEAVES2:13)
Block(-3,22,2,LEAVES2:13)
Block(-2,22,2,LEAVES2:13)
Block(-1,22,2,LEAVES2:13)
Block(0,22,2,LEAVES2:13)
Block(1,22,2,LEAVES2:13)
Block(2,22,2,LEAVES2:13)
Block(3,22,2,LEAVES2:13)
Block(4,22,2,LEAVES2:13)
Block(5,22,2,LEAVES2:13)
Block(-9,22,3,LEAVES2:13)
Block(-8,22,3,LEAVES2:13)
Block(-7,22,3,LEAVES2:13)
Block(-6,22,3,LEAVES2:13)
Block(-5,22,3,LEAVES2:13)
Block(-4,22,3,LEAVES2:13)
Block(-3,22,3,LEAVES2:13)
Block(-2,22,3,LEAVES2:13)
Block(-1,22,3,LEAVES2:13)
Block(1,22,3,LEAVES2:13)
Block(2,22,3,LEAVES2:13)
Block(3,22,3,LEAVES2:13)
Block(-9,22,4,LEAVES2:13)
Block(-8,22,4,LEAVES2:13)
Block(-7,22,4,LEAVES2:13)
Block(-6,22,4,LEAVES2:13)
Block(-5,22,4,LEAVES2:13)
Block(-4,22,4,LEAVES2:13)
Block(-3,22,4,LEAVES2:13)
Block(-2,22,4,LEAVES2:13)
Block(-1,22,4,LEAVES2:13)
Block(-9,22,5,LEAVES2:13)
Block(-8,22,5,LEAVES2:13)
Block(-7,22,5,LEAVES2:13)
Block(-6,22,5,LEAVES2:13)
Block(-5,22,5,LEAVES2:13)
Block(-4,22,5,LEAVES2:13)
Block(-3,22,5,LEAVES2:13)
Block(-2,22,5,LEAVES2:13)
Block(-1,22,5,LEAVES2:13)
Block(-8,22,6,LEAVES2:13)
Block(-7,22,6,LEAVES2:13)
Block(-6,22,6,LEAVES2:13)
Block(-5,22,6,LEAVES2:13)
Block(-4,22,6,LEAVES2:13)
Block(-3,22,6,LEAVES2:13)
Block(-2,22,6,LEAVES2:13)
Block(-5,22,7,LEAVES2:13)
Block(0,23,-9,LEAVES2:13)
Block(-1,23,-8,LEAVES2:13)
Block(0,23,-8,LEAVES2:13)
Block(1,23,-8,LEAVES2:13)
Block(6,23,-8,LOG2:13)
Block(0,23,-7,LEAVES2:13)
Block(0,23,-5,LEAVES2:13)
Block(1,23,-5,LEAVES2:13)
Block(2,23,-5,LEAVES2:13)
Block(3,23,-5,LEAVES2:13)
Block(4,23,-5,LEAVES2:13)
Block(-1,23,-4,LEAVES2:13)
Block(0,23,-4,LEAVES2:13)
Block(1,23,-4,LEAVES2:13)
Block(2,23,-4,LEAVES2:13)
Block(3,23,-4,LEAVES2:13)
Block(4,23,-4,LEAVES2:13)
Block(5,23,-4,LEAVES2:13)
Block(-2,23,-3,LEAVES2:13)
Block(-1,23,-3,LEAVES2:13)
Block(0,23,-3,LEAVES2:13)
Block(1,23,-3,LEAVES2:13)
Block(2,23,-3,LEAVES2:13)
Block(3,23,-3,LEAVES2:13)
Block(4,23,-3,LEAVES2:13)
Block(5,23,-3,LEAVES2:13)
Block(6,23,-3,LEAVES2:13)
Block(-7,23,-2,LEAVES2:13)
Block(-6,23,-2,LEAVES2:13)
Block(-5,23,-2,LEAVES2:13)
Block(-4,23,-2,LEAVES2:13)
Block(-3,23,-2,LEAVES2:13)
Block(-2,23,-2,LEAVES2:13)
Block(-1,23,-2,LEAVES2:13)
Block(0,23,-2,LEAVES2:13)
Block(1,23,-2,LEAVES2:13)
Block(2,23,-2,LEAVES2:13)
Block(3,23,-2,LEAVES2:13)
Block(4,23,-2,LEAVES2:13)
Block(5,23,-2,LEAVES2:13)
Block(6,23,-2,LEAVES2:13)
Block(-8,23,-1,LEAVES2:13)
Block(-7,23,-1,LEAVES2:13)
Block(-6,23,-1,LEAVES2:13)
Block(-5,23,-1,LEAVES2:13)
Block(-4,23,-1,LEAVES2:13)
Block(-3,23,-1,LEAVES2:13)
Block(-2,23,-1,LEAVES2:13)
Block(-1,23,-1,LEAVES2:13)
Block(0,23,-1,LEAVES2:13)
Block(1,23,-1,LEAVES2:13)
Block(2,23,-1,LOG2:13)
Block(3,23,-1,LOG2:13)
Block(4,23,-1,LEAVES2:13)
Block(5,23,-1,LEAVES2:13)
Block(6,23,-1,LEAVES2:13)
Block(11,23,-1,LEAVES2:13)
Block(-9,23,0,LEAVES2:13)
Block(-8,23,0,LEAVES2:13)
Block(-7,23,0,LEAVES2:13)
Block(-6,23,0,LEAVES2:13)
Block(-5,23,0,LEAVES2:13)
Block(-4,23,0,LEAVES2:13)
Block(-3,23,0,LEAVES2:13)
Block(-2,23,0,LEAVES2:13)
Block(-1,23,0,LEAVES2:13)
Block(0,23,0,LEAVES2:13)
Block(1,23,0,LEAVES2:13)
Block(2,23,0,LOG2:13)
Block(3,23,0,LOG2:13)
Block(4,23,0,LEAVES2:13)
Block(5,23,0,LEAVES2:13)
Block(6,23,0,LEAVES2:13)
Block(10,23,0,LOG2:13)
Block(11,23,0,LEAVES2:13)
Block(12,23,0,LEAVES2:13)
Block(-9,23,1,LEAVES2:13)
Block(-8,23,1,LEAVES2:13)
Block(-7,23,1,LEAVES2:13)
Block(-6,23,1,LEAVES2:13)
Block(-5,23,1,LEAVES2:13)
Block(-4,23,1,LEAVES2:13)
Block(-3,23,1,LEAVES2:13)
Block(-2,23,1,LEAVES2:13)
Block(-1,23,1,LEAVES2:13)
Block(0,23,1,LEAVES2:13)
Block(1,23,1,LEAVES2:13)
Block(2,23,1,LEAVES2:13)
Block(3,23,1,LEAVES2:13)
Block(4,23,1,LEAVES2:13)
Block(5,23,1,LEAVES2:13)
Block(6,23,1,LEAVES2:13)
Block(11,23,1,LEAVES2:13)
Block(-9,23,2,LEAVES2:13)
Block(-8,23,2,LEAVES2:13)
Block(-7,23,2,LEAVES2:13)
Block(-6,23,2,LEAVES2:13)
Block(-5,23,2,LEAVES2:13)
Block(-4,23,2,LEAVES2:13)
Block(-3,23,2,LEAVES2:13)
Block(-2,23,2,LEAVES2:13)
Block(-1,23,2,LEAVES2:13)
Block(0,23,2,LEAVES2:13)
Block(1,23,2,LEAVES2:13)
Block(2,23,2,LEAVES2:13)
Block(3,23,2,LEAVES2:13)
Block(4,23,2,LEAVES2:13)
Block(5,23,2,LEAVES2:13)
Block(-9,23,3,LEAVES2:13)
Block(-8,23,3,LEAVES2:13)
Block(-7,23,3,LEAVES2:13)
Block(-6,23,3,LEAVES2:13)
Block(-5,23,3,LEAVES2:13)
Block(-4,23,3,LEAVES2:13)
Block(-3,23,3,LEAVES2:13)
Block(-2,23,3,LEAVES2:13)
Block(-1,23,3,LEAVES2:13)
Block(0,23,3,LEAVES2:13)
Block(1,23,3,LEAVES2:13)
Block(2,23,3,LEAVES2:13)
Block(3,23,3,LEAVES2:13)
Block(4,23,3,LEAVES2:13)
Block(-9,23,4,LEAVES2:13)
Block(-8,23,4,LEAVES2:13)
Block(-7,23,4,LEAVES2:13)
Block(-6,23,4,LEAVES2:13)
Block(-5,23,4,LEAVES2:13)
Block(-4,23,4,LEAVES2:13)
Block(-3,23,4,LEAVES2:13)
Block(-2,23,4,LEAVES2:13)
Block(-1,23,4,LEAVES2:13)
Block(-8,23,5,LEAVES2:13)
Block(-7,23,5,LEAVES2:13)
Block(-6,23,5,LEAVES2:13)
Block(-5,23,5,LEAVES2:13)
Block(-4,23,5,LEAVES2:13)
Block(-3,23,5,LEAVES2:13)
Block(-2,23,5,LEAVES2:13)
Block(-7,23,6,LEAVES2:13)
Block(-6,23,6,LEAVES2:13)
Block(-5,23,6,LEAVES2:13)
Block(-4,23,6,LEAVES2:13)
Block(-3,23,6,LEAVES2:13)
Block(6,24,-8,LOG2:13)
Block(2,24,-6,LEAVES2:13)
Block(-1,24,-5,LEAVES2:13)
Block(0,24,-5,LEAVES2:13)
Block(1,24,-5,LEAVES2:13)
Block(2,24,-5,LEAVES2:13)
Block(3,24,-5,LEAVES2:13)
Block(4,24,-5,LEAVES2:13)
Block(5,24,-5,LEAVES2:13)
Block(-2,24,-4,LEAVES2:13)
Block(-1,24,-4,LEAVES2:13)
Block(0,24,-4,LEAVES2:13)
Block(1,24,-4,LEAVES2:13)
Block(2,24,-4,LEAVES2:13)
Block(3,24,-4,LEAVES2:13)
Block(4,24,-4,LEAVES2:13)
Block(5,24,-4,LEAVES2:13)
Block(6,24,-4,LEAVES2:13)
Block(-2,24,-3,LEAVES2:13)
Block(-1,24,-3,LEAVES2:13)
Block(0,24,-3,LEAVES2:13)
Block(1,24,-3,LEAVES2:13)
Block(2,24,-3,LEAVES2:13)
Block(3,24,-3,LEAVES2:13)
Block(4,24,-3,LEAVES2:13)
Block(5,24,-3,LEAVES2:13)
Block(6,24,-3,LEAVES2:13)
Block(9,24,-3,LEAVES2:13)
Block(10,24,-3,LEAVES2:13)
Block(11,24,-3,LEAVES2:13)
Block(12,24,-3,LEAVES2:13)
Block(13,24,-3,LEAVES2:13)
Block(-2,24,-2,LEAVES2:13)
Block(-1,24,-2,LEAVES2:13)
Block(0,24,-2,LEAVES2:13)
Block(1,24,-2,LEAVES2:13)
Block(2,24,-2,LEAVES2:13)
Block(3,24,-2,LEAVES2:13)
Block(4,24,-2,LEAVES2:13)
Block(5,24,-2,LEAVES2:13)
Block(6,24,-2,LEAVES2:13)
Block(8,24,-2,LEAVES2:13)
Block(9,24,-2,LEAVES2:13)
Block(10,24,-2,LEAVES2:13)
Block(11,24,-2,LEAVES2:13)
Block(12,24,-2,LEAVES2:13)
Block(13,24,-2,LEAVES2:13)
Block(14,24,-2,LEAVES2:13)
Block(-6,24,-1,LEAVES2:13)
Block(-5,24,-1,LEAVES2:13)
Block(-4,24,-1,LEAVES2:13)
Block(-3,24,-1,LEAVES2:13)
Block(-2,24,-1,LEAVES2:13)
Block(-1,24,-1,LEAVES2:13)
Block(0,24,-1,LEAVES2:13)
Block(1,24,-1,LEAVES2:13)
Block(2,24,-1,LEAVES2:13)
Block(3,24,-1,LEAVES2:13)
Block(4,24,-1,LEAVES2:13)
Block(5,24,-1,LEAVES2:13)
Block(6,24,-1,LEAVES2:13)
Block(7,24,-1,LEAVES2:13)
Block(8,24,-1,LEAVES2:13)
Block(9,24,-1,LEAVES2:13)
Block(10,24,-1,LEAVES2:13)
Block(11,24,-1,LEAVES2:13)
Block(12,24,-1,LEAVES2:13)
Block(13,24,-1,LEAVES2:13)
Block(14,24,-1,LEAVES2:13)
Block(-7,24,0,LEAVES2:13)
Block(-6,24,0,LEAVES2:13)
Block(-5,24,0,LEAVES2:13)
Block(-4,24,0,LEAVES2:13)
Block(-3,24,0,LEAVES2:13)
Block(-2,24,0,LEAVES2:13)
Block(-1,24,0,LEAVES2:13)
Block(0,24,0,LEAVES2:13)
Block(1,24,0,LEAVES2:13)
Block(2,24,0,LEAVES2:13)
Block(3,24,0,LEAVES2:13)
Block(4,24,0,LEAVES2:13)
Block(5,24,0,LEAVES2:13)
Block(6,24,0,LEAVES2:13)
Block(8,24,0,LEAVES2:13)
Block(9,24,0,LEAVES2:13)
Block(10,24,0,LOG2:13)
Block(11,24,0,LEAVES2:13)
Block(12,24,0,LEAVES2:13)
Block(13,24,0,LEAVES2:13)
Block(14,24,0,LEAVES2:13)
Block(-8,24,1,LEAVES2:13)
Block(-7,24,1,LEAVES2:13)
Block(-6,24,1,LEAVES2:13)
Block(-5,24,1,LEAVES2:13)
Block(-4,24,1,LEAVES2:13)
Block(-3,24,1,LEAVES2:13)
Block(-2,24,1,LEAVES2:13)
Block(-1,24,1,LEAVES2:13)
Block(0,24,1,LEAVES2:13)
Block(1,24,1,LEAVES2:13)
Block(2,24,1,LEAVES2:13)
Block(3,24,1,LEAVES2:13)
Block(4,24,1,LEAVES2:13)
Block(5,24,1,LEAVES2:13)
Block(6,24,1,LEAVES2:13)
Block(8,24,1,LEAVES2:13)
Block(9,24,1,LEAVES2:13)
Block(10,24,1,LEAVES2:13)
Block(11,24,1,LEAVES2:13)
Block(12,24,1,LEAVES2:13)
Block(13,24,1,LEAVES2:13)
Block(14,24,1,LEAVES2:13)
Block(-8,24,2,LEAVES2:13)
Block(-7,24,2,LEAVES2:13)
Block(-6,24,2,LEAVES2:13)
Block(-5,24,2,LEAVES2:13)
Block(-4,24,2,LEAVES2:13)
Block(-3,24,2,LEAVES2:13)
Block(-2,24,2,LEAVES2:13)
Block(-1,24,2,LEAVES2:13)
Block(0,24,2,LEAVES2:13)
Block(1,24,2,LEAVES2:13)
Block(2,24,2,LEAVES2:13)
Block(3,24,2,LEAVES2:13)
Block(4,24,2,LEAVES2:13)
Block(5,24,2,LEAVES2:13)
Block(6,24,2,LEAVES2:13)
Block(8,24,2,LEAVES2:13)
Block(9,24,2,LEAVES2:13)
Block(10,24,2,LEAVES2:13)
Block(11,24,2,LEAVES2:13)
Block(12,24,2,LEAVES2:13)
Block(13,24,2,LEAVES2:13)
Block(14,24,2,LEAVES2:13)
Block(-8,24,3,LEAVES2:13)
Block(-7,24,3,LEAVES2:13)
Block(-6,24,3,LEAVES2:13)
Block(-5,24,3,LEAVES2:13)
Block(-4,24,3,LEAVES2:13)
Block(-3,24,3,LEAVES2:13)
Block(-2,24,3,LEAVES2:13)
Block(-1,24,3,LEAVES2:13)
Block(0,24,3,LEAVES2:13)
Block(1,24,3,LEAVES2:13)
Block(2,24,3,LEAVES2:13)
Block(3,24,3,LEAVES2:13)
Block(4,24,3,LEAVES2:13)
Block(5,24,3,LEAVES2:13)
Block(9,24,3,LEAVES2:13)
Block(10,24,3,LEAVES2:13)
Block(11,24,3,LEAVES2:13)
Block(12,24,3,LEAVES2:13)
Block(13,24,3,LEAVES2:13)
Block(-7,24,4,LEAVES2:13)
Block(-6,24,4,LEAVES2:13)
Block(-5,24,4,LEAVES2:13)
Block(-4,24,4,LEAVES2:13)
Block(-3,24,4,LEAVES2:13)
Block(2,24,4,LEAVES2:13)
Block(-6,24,5,LEAVES2:13)
Block(-5,24,5,LEAVES2:13)
Block(-4,24,5,LEAVES2:13)
Block(7,25,-11,LEAVES2:13)
Block(6,25,-10,LEAVES2:13)
Block(7,25,-10,LEAVES2:13)
Block(8,25,-10,LEAVES2:13)
Block(6,25,-9,LOG2:13)
Block(7,25,-9,LEAVES2:13)
Block(0,25,-5,LEAVES2:13)
Block(1,25,-5,LEAVES2:13)
Block(2,25,-5,LEAVES2:13)
Block(3,25,-5,LEAVES2:13)
Block(4,25,-5,LEAVES2:13)
Block(11,25,-5,LEAVES2:13)
Block(-1,25,-4,LEAVES2:13)
Block(0,25,-4,LEAVES2:13)
Block(1,25,-4,LEAVES2:13)
Block(2,25,-4,LEAVES2:13)
Block(3,25,-4,LEAVES2:13)
Block(4,25,-4,LEAVES2:13)
Block(5,25,-4,LEAVES2:13)
Block(8,25,-4,LEAVES2:13)
Block(9,25,-4,LEAVES2:13)
Block(10,25,-4,LEAVES2:13)
Block(11,25,-4,LEAVES2:13)
Block(12,25,-4,LEAVES2:13)
Block(13,25,-4,LEAVES2:13)
Block(14,25,-4,LEAVES2:13)
Block(-2,25,-3,LEAVES2:13)
Block(-1,25,-3,LEAVES2:13)
Block(0,25,-3,LEAVES2:13)
Block(1,25,-3,LEAVES2:13)
Block(2,25,-3,LEAVES2:13)
Block(3,25,-3,LEAVES2:13)
Block(4,25,-3,LEAVES2:13)
Block(5,25,-3,LEAVES2:13)
Block(6,25,-3,LEAVES2:13)
Block(7,25,-3,LEAVES2:13)
Block(8,25,-3,LEAVES2:13)
Block(9,25,-3,LEAVES2:13)
Block(10,25,-3,LEAVES2:13)
Block(11,25,-3,LEAVES2:13)
Block(12,25,-3,LEAVES2:13)
Block(13,25,-3,LEAVES2:13)
Block(14,25,-3,LEAVES2:13)
Block(15,25,-3,LEAVES2:13)
Block(-2,25,-2,LEAVES2:13)
Block(-1,25,-2,LEAVES2:13)
Block(0,25,-2,LEAVES2:13)
Block(1,25,-2,LEAVES2:13)
Block(2,25,-2,LEAVES2:13)
Block(3,25,-2,LEAVES2:13)
Block(4,25,-2,LEAVES2:13)
Block(5,25,-2,LEAVES2:13)
Block(6,25,-2,LEAVES2:13)
Block(7,25,-2,LEAVES2:13)
Block(8,25,-2,LEAVES2:13)
Block(9,25,-2,LEAVES2:13)
Block(10,25,-2,LEAVES2:13)
Block(11,25,-2,LEAVES2:13)
Block(12,25,-2,LEAVES2:13)
Block(13,25,-2,LEAVES2:13)
Block(14,25,-2,LEAVES2:13)
Block(15,25,-2,LEAVES2:13)
Block(-2,25,-1,LEAVES2:13)
Block(-1,25,-1,LEAVES2:13)
Block(0,25,-1,LEAVES2:13)
Block(1,25,-1,LEAVES2:13)
Block(2,25,-1,LEAVES2:13)
Block(3,25,-1,LEAVES2:13)
Block(4,25,-1,LEAVES2:13)
Block(5,25,-1,LEAVES2:13)
Block(6,25,-1,LEAVES2:13)
Block(7,25,-1,LEAVES2:13)
Block(8,25,-1,LEAVES2:13)
Block(9,25,-1,LEAVES2:13)
Block(10,25,-1,LEAVES2:13)
Block(11,25,-1,LEAVES2:13)
Block(12,25,-1,LEAVES2:13)
Block(13,25,-1,LEAVES2:13)
Block(14,25,-1,LEAVES2:13)
Block(15,25,-1,LEAVES2:13)
Block(-2,25,0,LEAVES2:13)
Block(-1,25,0,LEAVES2:13)
Block(0,25,0,LEAVES2:13)
Block(1,25,0,LEAVES2:13)
Block(2,25,0,LEAVES2:13)
Block(3,25,0,LEAVES2:13)
Block(4,25,0,LEAVES2:13)
Block(5,25,0,LEAVES2:13)
Block(6,25,0,LEAVES2:13)
Block(7,25,0,LEAVES2:13)
Block(8,25,0,LEAVES2:13)
Block(9,25,0,LEAVES2:13)
Block(10,25,0,LEAVES2:13)
Block(11,25,0,LOG2:13)
Block(12,25,0,LEAVES2:13)
Block(13,25,0,LEAVES2:13)
Block(14,25,0,LEAVES2:13)
Block(15,25,0,LEAVES2:13)
Block(16,25,0,LEAVES2:13)
Block(-5,25,1,LEAVES2:13)
Block(-2,25,1,LEAVES2:13)
Block(-1,25,1,LEAVES2:13)
Block(0,25,1,LEAVES2:13)
Block(1,25,1,LEAVES2:13)
Block(2,25,1,LEAVES2:13)
Block(3,25,1,LEAVES2:13)
Block(4,25,1,LEAVES2:13)
Block(5,25,1,LEAVES2:13)
Block(6,25,1,LEAVES2:13)
Block(7,25,1,LEAVES2:13)
Block(8,25,1,LEAVES2:13)
Block(9,25,1,LEAVES2:13)
Block(10,25,1,LEAVES2:13)
Block(11,25,1,LEAVES2:13)
Block(12,25,1,LEAVES2:13)
Block(13,25,1,LEAVES2:13)
Block(14,25,1,LEAVES2:13)
Block(15,25,1,LEAVES2:13)
Block(-6,25,2,LEAVES2:13)
Block(-5,25,2,LEAVES2:13)
Block(-4,25,2,LEAVES2:13)
Block(-1,25,2,LEAVES2:13)
Block(0,25,2,LEAVES2:13)
Block(1,25,2,LEAVES2:13)
Block(2,25,2,LEAVES2:13)
Block(3,25,2,LEAVES2:13)
Block(4,25,2,LEAVES2:13)
Block(5,25,2,LEAVES2:13)
Block(7,25,2,LEAVES2:13)
Block(8,25,2,LEAVES2:13)
Block(9,25,2,LEAVES2:13)
Block(10,25,2,LEAVES2:13)
Block(11,25,2,LEAVES2:13)
Block(12,25,2,LEAVES2:13)
Block(13,25,2,LEAVES2:13)
Block(14,25,2,LEAVES2:13)
Block(15,25,2,LEAVES2:13)
Block(-5,25,3,LEAVES2:13)
Block(0,25,3,LEAVES2:13)
Block(1,25,3,LEAVES2:13)
Block(2,25,3,LEAVES2:13)
Block(3,25,3,LEAVES2:13)
Block(4,25,3,LEAVES2:13)
Block(7,25,3,LEAVES2:13)
Block(8,25,3,LEAVES2:13)
Block(9,25,3,LEAVES2:13)
Block(10,25,3,LEAVES2:13)
Block(11,25,3,LEAVES2:13)
Block(12,25,3,LEAVES2:13)
Block(13,25,3,LEAVES2:13)
Block(14,25,3,LEAVES2:13)
Block(15,25,3,LEAVES2:13)
Block(8,25,4,LEAVES2:13)
Block(9,25,4,LEAVES2:13)
Block(10,25,4,LEAVES2:13)
Block(11,25,4,LEAVES2:13)
Block(12,25,4,LEAVES2:13)
Block(13,25,4,LEAVES2:13)
Block(14,25,4,LEAVES2:13)
Block(11,25,5,LEAVES2:13)
Block(5,26,-13,LEAVES2:13)
Block(6,26,-13,LEAVES2:13)
Block(7,26,-13,LEAVES2:13)
Block(8,26,-13,LEAVES2:13)
Block(9,26,-13,LEAVES2:13)
Block(4,26,-12,LEAVES2:13)
Block(5,26,-12,LEAVES2:13)
Block(6,26,-12,LEAVES2:13)
Block(7,26,-12,LEAVES2:13)
Block(8,26,-12,LEAVES2:13)
Block(9,26,-12,LEAVES2:13)
Block(10,26,-12,LEAVES2:13)
Block(4,26,-11,LEAVES2:13)
Block(5,26,-11,LEAVES2:13)
Block(6,26,-11,LEAVES2:13)
Block(7,26,-11,LEAVES2:13)
Block(8,26,-11,LEAVES2:13)
Block(9,26,-11,LEAVES2:13)
Block(10,26,-11,LEAVES2:13)
Block(4,26,-10,LEAVES2:13)
Block(5,26,-10,LEAVES2:13)
Block(6,26,-10,LEAVES2:13)
Block(7,26,-10,LEAVES2:13)
Block(8,26,-10,LEAVES2:13)
Block(9,26,-10,LEAVES2:13)
Block(10,26,-10,LEAVES2:13)
Block(4,26,-9,LEAVES2:13)
Block(5,26,-9,LEAVES2:13)
Block(6,26,-9,LOG2:13)
Block(7,26,-9,LEAVES2:13)
Block(8,26,-9,LEAVES2:13)
Block(9,26,-9,LEAVES2:13)
Block(10,26,-9,LEAVES2:13)
Block(4,26,-8,LEAVES2:13)
Block(5,26,-8,LEAVES2:13)
Block(6,26,-8,LEAVES2:13)
Block(7,26,-8,LEAVES2:13)
Block(8,26,-8,LEAVES2:13)
Block(9,26,-8,LEAVES2:13)
Block(10,26,-8,LEAVES2:13)
Block(5,26,-7,LEAVES2:13)
Block(6,26,-7,LEAVES2:13)
Block(7,26,-7,LEAVES2:13)
Block(8,26,-7,LEAVES2:13)
Block(9,26,-7,LEAVES2:13)
Block(1,26,-5,LEAVES2:13)
Block(2,26,-5,LEAVES2:13)
Block(3,26,-5,LEAVES2:13)
Block(-1,26,-4,LEAVES2:13)
Block(0,26,-4,LEAVES2:13)
Block(1,26,-4,LEAVES2:13)
Block(2,26,-4,LEAVES2:13)
Block(3,26,-4,LEAVES2:13)
Block(4,26,-4,LEAVES2:13)
Block(5,26,-4,LEAVES2:13)
Block(-1,26,-3,LEAVES2:13)
Block(0,26,-3,LEAVES2:13)
Block(1,26,-3,LEAVES2:13)
Block(2,26,-3,LEAVES2:13)
Block(3,26,-3,LEAVES2:13)
Block(4,26,-3,LEAVES2:13)
Block(5,26,-3,LEAVES2:13)
Block(9,26,-3,LEAVES2:13)
Block(10,26,-3,LEAVES2:13)
Block(11,26,-3,LEAVES2:13)
Block(12,26,-3,LEAVES2:13)
Block(13,26,-3,LEAVES2:13)
Block(-2,26,-2,LEAVES2:13)
Block(-1,26,-2,LEAVES2:13)
Block(0,26,-2,LEAVES2:13)
Block(1,26,-2,LEAVES2:13)
Block(2,26,-2,LEAVES2:13)
Block(3,26,-2,LEAVES2:13)
Block(4,26,-2,LEAVES2:13)
Block(5,26,-2,LEAVES2:13)
Block(6,26,-2,LEAVES2:13)
Block(8,26,-2,LEAVES2:13)
Block(9,26,-2,LEAVES2:13)
Block(10,26,-2,LEAVES2:13)
Block(11,26,-2,LEAVES2:13)
Block(12,26,-2,LEAVES2:13)
Block(13,26,-2,LEAVES2:13)
Block(14,26,-2,LEAVES2:13)
Block(-2,26,-1,LEAVES2:13)
Block(-1,26,-1,LEAVES2:13)
Block(0,26,-1,LEAVES2:13)
Block(1,26,-1,LEAVES2:13)
Block(2,26,-1,LEAVES2:13)
Block(3,26,-1,LEAVES2:13)
Block(4,26,-1,LEAVES2:13)
Block(5,26,-1,LEAVES2:13)
Block(6,26,-1,LEAVES2:13)
Block(8,26,-1,LEAVES2:13)
Block(9,26,-1,LEAVES2:13)
Block(10,26,-1,LEAVES2:13)
Block(11,26,-1,LEAVES2:13)
Block(12,26,-1,LEAVES2:13)
Block(13,26,-1,LEAVES2:13)
Block(14,26,-1,LEAVES2:13)
Block(-2,26,0,LEAVES2:13)
Block(-1,26,0,LEAVES2:13)
Block(0,26,0,LEAVES2:13)
Block(1,26,0,LEAVES2:13)
Block(2,26,0,LEAVES2:13)
Block(3,26,0,LEAVES2:13)
Block(4,26,0,LEAVES2:13)
Block(5,26,0,LEAVES2:13)
Block(6,26,0,LEAVES2:13)
Block(8,26,0,LEAVES2:13)
Block(9,26,0,LEAVES2:13)
Block(10,26,0,LEAVES2:13)
Block(11,26,0,LEAVES2:13)
Block(12,26,0,LEAVES2:13)
Block(13,26,0,LEAVES2:13)
Block(14,26,0,LEAVES2:13)
Block(-1,26,1,LEAVES2:13)
Block(0,26,1,LEAVES2:13)
Block(1,26,1,LEAVES2:13)
Block(2,26,1,LEAVES2:13)
Block(3,26,1,LEAVES2:13)
Block(4,26,1,LEAVES2:13)
Block(5,26,1,LEAVES2:13)
Block(8,26,1,LEAVES2:13)
Block(9,26,1,LEAVES2:13)
Block(10,26,1,LEAVES2:13)
Block(11,26,1,LEAVES2:13)
Block(12,26,1,LEAVES2:13)
Block(13,26,1,LEAVES2:13)
Block(14,26,1,LEAVES2:13)
Block(-1,26,2,LEAVES2:13)
Block(0,26,2,LEAVES2:13)
Block(1,26,2,LEAVES2:13)
Block(2,26,2,LEAVES2:13)
Block(3,26,2,LEAVES2:13)
Block(4,26,2,LEAVES2:13)
Block(5,26,2,LEAVES2:13)
Block(8,26,2,LEAVES2:13)
Block(9,26,2,LEAVES2:13)
Block(10,26,2,LEAVES2:13)
Block(11,26,2,LEAVES2:13)
Block(12,26,2,LEAVES2:13)
Block(13,26,2,LEAVES2:13)
Block(14,26,2,LEAVES2:13)
Block(1,26,3,LEAVES2:13)
Block(2,26,3,LEAVES2:13)
Block(3,26,3,LEAVES2:13)
Block(9,26,3,LEAVES2:13)
Block(10,26,3,LEAVES2:13)
Block(11,26,3,LEAVES2:13)
Block(12,26,3,LEAVES2:13)
Block(13,26,3,LEAVES2:13)
Block(4,27,-14,LEAVES2:13)
Block(5,27,-14,LEAVES2:13)
Block(6,27,-14,LEAVES2:13)
Block(7,27,-14,LEAVES2:13)
Block(8,27,-14,LEAVES2:13)
Block(9,27,-14,LEAVES2:13)
Block(10,27,-14,LEAVES2:13)
Block(3,27,-13,LEAVES2:13)
Block(4,27,-13,LEAVES2:13)
Block(5,27,-13,LEAVES2:13)
Block(6,27,-13,LEAVES2:13)
Block(7,27,-13,LEAVES2:13)
Block(8,27,-13,LEAVES2:13)
Block(9,27,-13,LEAVES2:13)
Block(10,27,-13,LEAVES2:13)
Block(11,27,-13,LEAVES2:13)
Block(3,27,-12,LEAVES2:13)
Block(4,27,-12,LEAVES2:13)
Block(5,27,-12,LEAVES2:13)
Block(6,27,-12,LEAVES2:13)
Block(7,27,-12,LEAVES2:13)
Block(8,27,-12,LEAVES2:13)
Block(9,27,-12,LEAVES2:13)
Block(10,27,-12,LEAVES2:13)
Block(11,27,-12,LEAVES2:13)
Block(3,27,-11,LEAVES2:13)
Block(4,27,-11,LEAVES2:13)
Block(5,27,-11,LEAVES2:13)
Block(6,27,-11,LEAVES2:13)
Block(7,27,-11,LEAVES2:13)
Block(8,27,-11,LEAVES2:13)
Block(9,27,-11,LEAVES2:13)
Block(10,27,-11,LEAVES2:13)
Block(11,27,-11,LEAVES2:13)
Block(2,27,-10,LEAVES2:13)
Block(3,27,-10,LEAVES2:13)
Block(4,27,-10,LEAVES2:13)
Block(5,27,-10,LEAVES2:13)
Block(6,27,-10,LEAVES2:13)
Block(7,27,-10,LOG2:13)
Block(8,27,-10,LEAVES2:13)
Block(9,27,-10,LEAVES2:13)
Block(10,27,-10,LEAVES2:13)
Block(11,27,-10,LEAVES2:13)
Block(12,27,-10,LEAVES2:13)
Block(3,27,-9,LEAVES2:13)
Block(4,27,-9,LEAVES2:13)
Block(5,27,-9,LEAVES2:13)
Block(6,27,-9,LEAVES2:13)
Block(7,27,-9,LEAVES2:13)
Block(8,27,-9,LEAVES2:13)
Block(9,27,-9,LEAVES2:13)
Block(10,27,-9,LEAVES2:13)
Block(11,27,-9,LEAVES2:13)
Block(3,27,-8,LEAVES2:13)
Block(4,27,-8,LEAVES2:13)
Block(5,27,-8,LEAVES2:13)
Block(6,27,-8,LEAVES2:13)
Block(7,27,-8,LEAVES2:13)
Block(8,27,-8,LEAVES2:13)
Block(9,27,-8,LEAVES2:13)
Block(10,27,-8,LEAVES2:13)
Block(11,27,-8,LEAVES2:13)
Block(3,27,-7,LEAVES2:13)
Block(4,27,-7,LEAVES2:13)
Block(5,27,-7,LEAVES2:13)
Block(6,27,-7,LEAVES2:13)
Block(7,27,-7,LEAVES2:13)
Block(8,27,-7,LEAVES2:13)
Block(9,27,-7,LEAVES2:13)
Block(10,27,-7,LEAVES2:13)
Block(11,27,-7,LEAVES2:13)
Block(4,27,-6,LEAVES2:13)
Block(5,27,-6,LEAVES2:13)
Block(6,27,-6,LEAVES2:13)
Block(7,27,-6,LEAVES2:13)
Block(8,27,-6,LEAVES2:13)
Block(9,27,-6,LEAVES2:13)
Block(10,27,-6,LEAVES2:13)
Block(7,27,-5,LEAVES2:13)
Block(1,27,-4,LEAVES2:13)
Block(2,27,-4,LEAVES2:13)
Block(3,27,-4,LEAVES2:13)
Block(0,27,-3,LEAVES2:13)
Block(1,27,-3,LEAVES2:13)
Block(2,27,-3,LEAVES2:13)
Block(3,27,-3,LEAVES2:13)
Block(4,27,-3,LEAVES2:13)
Block(-1,27,-2,LEAVES2:13)
Block(0,27,-2,LEAVES2:13)
Block(1,27,-2,LEAVES2:13)
Block(2,27,-2,LEAVES2:13)
Block(3,27,-2,LEAVES2:13)
Block(4,27,-2,LEAVES2:13)
Block(5,27,-2,LEAVES2:13)
Block(-1,27,-1,LEAVES2:13)
Block(0,27,-1,LEAVES2:13)
Block(1,27,-1,LEAVES2:13)
Block(2,27,-1,LEAVES2:13)
Block(3,27,-1,LEAVES2:13)
Block(4,27,-1,LEAVES2:13)
Block(5,27,-1,LEAVES2:13)
Block(11,27,-1,LEAVES2:13)
Block(-1,27,0,LEAVES2:13)
Block(0,27,0,LEAVES2:13)
Block(1,27,0,LEAVES2:13)
Block(2,27,0,LEAVES2:13)
Block(3,27,0,LEAVES2:13)
Block(4,27,0,LEAVES2:13)
Block(5,27,0,LEAVES2:13)
Block(10,27,0,LEAVES2:13)
Block(11,27,0,LEAVES2:13)
Block(12,27,0,LEAVES2:13)
Block(0,27,1,LEAVES2:13)
Block(1,27,1,LEAVES2:13)
Block(2,27,1,LEAVES2:13)
Block(3,27,1,LEAVES2:13)
Block(4,27,1,LEAVES2:13)
Block(11,27,1,LEAVES2:13)
Block(1,27,2,LEAVES2:13)
Block(2,27,2,LEAVES2:13)
Block(3,27,2,LEAVES2:13)
Block(5,28,-13,LEAVES2:13)
Block(6,28,-13,LEAVES2:13)
Block(7,28,-13,LEAVES2:13)
Block(8,28,-13,LEAVES2:13)
Block(9,28,-13,LEAVES2:13)
Block(4,28,-12,LEAVES2:13)
Block(5,28,-12,LEAVES2:13)
Block(6,28,-12,LEAVES2:13)
Block(7,28,-12,LEAVES2:13)
Block(8,28,-12,LEAVES2:13)
Block(9,28,-12,LEAVES2:13)
Block(10,28,-12,LEAVES2:13)
Block(4,28,-11,LEAVES2:13)
Block(5,28,-11,LEAVES2:13)
Block(6,28,-11,LEAVES2:13)
Block(7,28,-11,LEAVES2:13)
Block(8,28,-11,LEAVES2:13)
Block(9,28,-11,LEAVES2:13)
Block(10,28,-11,LEAVES2:13)
Block(4,28,-10,LEAVES2:13)
Block(5,28,-10,LEAVES2:13)
Block(6,28,-10,LEAVES2:13)
Block(7,28,-10,LEAVES2:13)
Block(8,28,-10,LEAVES2:13)
Block(9,28,-10,LEAVES2:13)
Block(10,28,-10,LEAVES2:13)
Block(4,28,-9,LEAVES2:13)
Block(5,28,-9,LEAVES2:13)
Block(6,28,-9,LEAVES2:13)
Block(7,28,-9,LEAVES2:13)
Block(8,28,-9,LEAVES2:13)
Block(9,28,-9,LEAVES2:13)
Block(10,28,-9,LEAVES2:13)
Block(4,28,-8,LEAVES2:13)
Block(5,28,-8,LEAVES2:13)
Block(6,28,-8,LEAVES2:13)
Block(7,28,-8,LEAVES2:13)
Block(8,28,-8,LEAVES2:13)
Block(9,28,-8,LEAVES2:13)
Block(10,28,-8,LEAVES2:13)
Block(5,28,-7,LEAVES2:13)
Block(6,28,-7,LEAVES2:13)
Block(7,28,-7,LEAVES2:13)
Block(8,28,-7,LEAVES2:13)
Block(9,28,-7,LEAVES2:13)
Block(1,28,-3,LEAVES2:13)
Block(2,28,-3,LEAVES2:13)
Block(3,28,-3,LEAVES2:13)
Block(0,28,-2,LEAVES2:13)
Block(1,28,-2,LEAVES2:13)
Block(2,28,-2,LEAVES2:13)
Block(3,28,-2,LEAVES2:13)
Block(4,28,-2,LEAVES2:13)
Block(0,28,-1,LEAVES2:13)
Block(1,28,-1,LEAVES2:13)
Block(2,28,-1,LEAVES2:13)
Block(3,28,-1,LEAVES2:13)
Block(4,28,-1,LEAVES2:13)
Block(0,28,0,LEAVES2:13)
Block(1,28,0,LEAVES2:13)
Block(2,28,0,LEAVES2:13)
Block(3,28,0,LEAVES2:13)
Block(4,28,0,LEAVES2:13)
Block(1,28,1,LEAVES2:13)
Block(2,28,1,LEAVES2:13)
Block(3,28,1,LEAVES2:13)
Block(7,29,-11,LEAVES2:13)
Block(6,29,-10,LEAVES2:13)
Block(7,29,-10,LEAVES2:13)
Block(8,29,-10,LEAVES2:13)
Block(7,29,-9,LEAVES2:13)
Block(2,29,-2,LEAVES2:13)
Block(1,29,-1,LEAVES2:13)
Block(2,29,-1,LEAVES2:13)
Block(3,29,-1,LEAVES2:13)
Block(2,29,0,LEAVES2:13)

#######################################################################
# +-----------------------------------------------------------------+ #
# |                            BO3 checks                           | #
# +-----------------------------------------------------------------+ #
#######################################################################

# Require a condition at a certain location in order for the BO3 to be spawned.
# BlockCheck(x,y,z,BlockName[,BlockName[,...]]) - one of the blocks must be at the location
# BlockCheckNot(x,y,z,BlockName[,BlockName[,...]]) - all the blocks must not be at the location
# LightCheck(x,y,z,minLightLevel,maxLightLevel) - light must be between min and max (inclusive)

# You can use "Solid" as a BlockName for matching all solid blocks or "All" to match all blocks that aren't air.

# Examples:

#   BlockCheck(0,-1,0,Solid)       Require any solid block just below the object
#   BlockCheck(0,-1,0,WOOL)        Require any type of wool just below the object
#   BlockCheck(0,-1,0,WOOL:0)      Require white wool just below the object
#   BlockCheckNot(0,-1,0,WOOL:0)   Require that there is no white wool below the object
#   LightCheck(0,0,0,0,1)          Require almost complete darkness just below the object

#######################################################################
# +-----------------------------------------------------------------+ #
# |                             Branches                            | #
# +-----------------------------------------------------------------+ #
#######################################################################

# Branches are objects that will spawn when this object spawns when it is used in
# the CustomStructure resource. Branches can also have branches, making complex
# structures possible. See the wiki for more details.

# Regular Branches spawn each branch with an independent chance of spawning.
# Branch(x,y,z,branchName,rotation,chance[,anotherBranchName,rotation,chance[,...]][IndividualChance])
# branchName - name of the object to spawn.
# rotation - NORTH, SOUTH, EAST or WEST.
# IndividualChance - The chance each branch has to spawn, assumed to be 100 when left blank

# Weighted Branches spawn branches with a dependent chance of spawning.
# WeightedBranch(x,y,z,branchName,rotation,chance[,anotherBranchName,rotation,chance[,...]][MaxChanceOutOf])
# MaxChanceOutOf - The chance all branches have to spawn out of, assumed to be 100 when left blank
BlockCheck(0,-1,0,STONE,GRASS,DIRT,SAND,GRAVEL)
