#######################################################################
# +-----------------------------------------------------------------+ #
# |                            BO3 object                           | #
# +-----------------------------------------------------------------+ #
#######################################################################

# This is the config file of a custom object.
# If you add this object correctly to your BiomeConfigs, it will spawn in the world.

# This is the creator of this BO3 object
Author: BO3 BulkEdit (by LanToaster)

# A short description of this BO3 object
Description: This Object was Created with BO3_BulkEdit

# The BO3 version, don't change this! It can be used by external applications to do a version check.
Version: 3

# The settings mode, WriteAll, WriteWithoutComments or WriteDisable. See WorldConfig.
SettingsMode: WriteDisable


#######################################################################
# +-----------------------------------------------------------------+ #
# |                          Main settings                          | #
# +-----------------------------------------------------------------+ #
#######################################################################

# This needs to be set to true to spawn the object in the Tree and Sapling resources.
Tree: true

# The frequency of the BO3 from 1 to 200. Tries this many times to spawn this BO3 when using the CustomObject(...) resource.
# Ignored by Tree(..), Sapling(..) and CustomStructure(..)
Frequency: 1

# The rarity of the BO3 from 0 to 100. Each spawn attempt has rarity% chance to succeed when using the CustomObject(...) resource.
# Ignored by Tree(..), Sapling(..) and CustomStructure(..)
Rarity: 100

# If you set this to true, the BO3 will be placed with a random rotation.
RotateRandomly: True

# The spawn height of the BO3 - randomY, highestBlock or highestSolidBlock.
SpawnHeight: highestSolidBlock
SpawnHeightOffset: -1
# The height limits for the BO3.
MinHeight: 0

MaxHeight: 68

# Objects can have other objects attacthed to it: branches. Branches can also
# have branches attached to it, which can also have branches, etc. This is the
# maximum branch depth for this objects.
MaxBranchDepth: 10

# When spawned with the UseWorld keyword, this BO3 should NOT spawn in the following biomes.
# If you writer.write the BO3 name directly in the BiomeConfigs, this will be ignored.
ExcludedBiomes: All


#######################################################################
# +-----------------------------------------------------------------+ #
# |                      Source block settings                      | #
# +-----------------------------------------------------------------+ #
#######################################################################

# The block(s) the BO3 should spawn in.
SourceBlocks: AIR,GRASS,DIRT,DIRT:2,STONE,SAND,CLAY,GRAVEL,STATIONARY_WATER

# The maximum percentage of the BO3 that can be outside the SourceBlock.
# The BO3 won't be placed on a location with more blocks outside the SourceBlock than this percentage.
MaxPercentageOutsideSourceBlock: 0

# What to do when a block is about to be placed outside the SourceBlock? (dontPlace, placeAnyway)
OutsideSourceBlock: dontPlace


#######################################################################
# +-----------------------------------------------------------------+ #
# |                              Blocks                             | #
# +-----------------------------------------------------------------+ #
#######################################################################

# All the blocks used in the BO3 are listed here. Possible blocks:
# Block(x,y,z,id[.data][,nbtfile.nbt)
# RandomBlock(x,y,z,id[:data][,nbtfile.nbt],chance[,id[:data][,nbtfile.nbt],chance[,...]])
# So RandomBlock(0,0,0,CHEST,chest.nbt,50,CHEST,anotherchest.nbt,100) will spawn a chest at
# the BO3 origin, and give it a 50% chance to have the contents of chest.nbt, or, if that
# fails, a 100% percent chance to have the contents of anotherchest.nbt.
Block(0,0,-3,LOG:3)
Block(1,0,-3,LOG:3)
Block(0,0,-2,LOG:3)
Block(1,0,-2,LOG:3)
Block(1,0,2,VINE:4)
Block(0,0,2,VINE:4)
Block(1,0,1,VINE:4)
Block(1,0,0,TALLGRASS:1)
Block(0,0,0,VINE:4)
Block(-1,0,0,TALLGRASS:1)
Block(-2,0,0,TALLGRASS:1)
Block(3,0,-1,VINE:2)
Block(2,0,-1,RED_FLOWER)
Block(1,0,-1,YELLOW_FLOWER)
Block(0,0,-1,TALLGRASS:1)
Block(-1,0,-1,TALLGRASS:1)
Block(-2,0,-1,VINE:8)
Block(-3,0,-1,YELLOW_FLOWER)
Block(3,0,-2,RED_FLOWER)
Block(2,0,-2,TALLGRASS:1)
Block(-1,0,-2,TALLGRASS:1)
Block(-2,0,-2,TALLGRASS:1)
Block(-3,0,-2,TALLGRASS:1)
Block(-4,0,-2,VINE:8)
Block(3,0,-3,TALLGRASS:1)
Block(2,0,-3,TALLGRASS:1)
Block(-1,0,-3,TALLGRASS:1)
Block(-2,0,-3,TALLGRASS:1)
Block(-3,0,-3,VINE:8)
Block(2,0,-4,TALLGRASS:1)
Block(1,0,-4,TALLGRASS:1)
Block(0,0,-4,TALLGRASS:1)
Block(-1,0,-4,YELLOW_FLOWER)
Block(-2,0,-4,VINE:1)
Block(2,0,-5,VINE:1)
Block(1,0,-5,TALLGRASS:1)
Block(0,0,-5,TALLGRASS:1)
Block(-1,0,-5,VINE:1)
Block(-2,0,-5,TALLGRASS:1)
Block(-3,0,-5,VINE:8)
Block(2,0,-6,VINE:1)
Block(-1,0,-6,TALLGRASS:1)
Block(-1,0,-7,VINE:1)

Block(0,1,-3,LOG:3)
Block(1,1,-3,LOG:3)
Block(0,1,-2,LOG:3)
Block(1,1,-2,LOG:3)
Block(2,1,2,VINE:4)
Block(1,1,2,VINE:4)
Block(0,1,2,VINE:4)
Block(1,1,1,VINE:4)
Block(4,1,0,VINE:2)
Block(2,1,0,VINE:2)
Block(0,1,0,VINE:4)
Block(-1,1,0,VINE:4)
Block(-2,1,0,VINE:4)
Block(5,1,-1,VINE:2)
Block(3,1,-1,VINE:2)
Block(-2,1,-1,VINE:8)
Block(-3,1,-2,VINE:8)
Block(-4,1,-2,VINE:8)
Block(4,1,-3,VINE:2)
Block(-3,1,-3,VINE:8)
Block(-4,1,-3,VINE:8)
Block(3,1,-4,VINE:2)
Block(-2,1,-4,VINE:1)
Block(2,1,-5,VINE:1)
Block(1,1,-5,VINE:1)
Block(-1,1,-5,VINE:1)
Block(-3,1,-5,VINE:8)
Block(2,1,-6,VINE:1)
Block(-2,1,-6,VINE:1)
Block(-1,1,-7,VINE:1)
Block(-1,2,-4,LEAVES)
Block(0,2,-4,LEAVES)
Block(1,2,-4,LEAVES)
Block(2,2,-4,LEAVES)
Block(-2,2,-3,LEAVES)
Block(-1,2,-3,LOG:3)
Block(0,2,-3,LOG:3)
Block(1,2,-3,LOG:3)
Block(2,2,-3,LEAVES)
Block(3,2,-3,LEAVES)
Block(-2,2,-2,LEAVES)
Block(-1,2,-2,LOG:3)
Block(0,2,-2,LOG:3)
Block(1,2,-2,LOG:3)
Block(2,2,-2,LEAVES)
Block(3,2,-2,LEAVES)
Block(-1,2,-1,LEAVES)
Block(0,2,-1,LEAVES)
Block(1,2,-1,LEAVES)
Block(2,2,-1,LEAVES)
Block(1,2,0,LEAVES)
Block(2,2,2,VINE:4)
Block(1,2,2,VINE:4)
Block(0,2,2,VINE:4)
Block(1,2,1,VINE:4)
Block(-1,2,1,VINE:4)
Block(4,2,0,VINE:2)
Block(2,2,0,VINE:2)
Block(0,2,0,VINE:4)
Block(-1,2,0,VINE:4)
Block(-2,2,0,VINE:4)
Block(5,2,-1,VINE:2)
Block(3,2,-1,VINE:2)
Block(-2,2,-1,VINE:8)
Block(-3,2,-1,VINE:4)
Block(4,2,-2,VINE:2)
Block(-3,2,-2,VINE:8)
Block(-4,2,-2,VINE:8)
Block(4,2,-3,VINE:2)
Block(-3,2,-3,VINE:8)
Block(-4,2,-3,VINE:8)
Block(3,2,-4,VINE:2)
Block(-2,2,-4,VINE:1)
Block(-3,2,-4,VINE:8)
Block(3,2,-5,VINE:1)
Block(2,2,-5,VINE:1)
Block(1,2,-5,VINE:1)
Block(-1,2,-5,VINE:1)
Block(-3,2,-5,VINE:8)
Block(2,2,-6,VINE:1)
Block(-2,2,-6,VINE:1)
Block(-1,2,-7,VINE:1)
Block(-1,3,-6,LEAVES)
Block(0,3,-6,LEAVES)
Block(-2,3,-5,LEAVES)
Block(-1,3,-5,LEAVES)
Block(0,3,-5,LEAVES)
Block(1,3,-5,LEAVES)
Block(2,3,-5,LEAVES)
Block(-2,3,-4,LEAVES)
Block(-1,3,-4,LEAVES)
Block(0,3,-4,LEAVES)
Block(1,3,-4,LEAVES)
Block(2,3,-4,LEAVES)
Block(3,3,-4,LEAVES)
Block(-3,3,-3,LEAVES)
Block(-2,3,-3,LEAVES)
Block(-1,3,-3,LOG:3)
Block(0,3,-3,LOG:3)
Block(1,3,-3,LOG:3)
Block(2,3,-3,LEAVES)
Block(3,3,-3,LEAVES)
Block(4,3,-3,LEAVES)
Block(-3,3,-2,LEAVES)
Block(-2,3,-2,LEAVES)
Block(-1,3,-2,LOG:3)
Block(0,3,-2,LOG:3)
Block(1,3,-2,LOG:3)
Block(2,3,-2,LEAVES)
Block(3,3,-2,LEAVES)
Block(4,3,-2,LEAVES)
Block(-2,3,-1,LEAVES)
Block(-1,3,-1,LEAVES)
Block(0,3,-1,LEAVES)
Block(1,3,-1,LEAVES)
Block(2,3,-1,LEAVES)
Block(3,3,-1,LEAVES)
Block(4,3,-1,LEAVES)
Block(-1,3,0,LEAVES)
Block(0,3,0,LEAVES)
Block(1,3,0,LEAVES)
Block(2,3,0,LEAVES)
Block(3,3,0,LEAVES)
Block(0,3,1,LEAVES)
Block(1,3,1,LEAVES)
Block(2,3,1,LEAVES)
Block(2,3,2,VINE:4)
Block(1,3,2,VINE:4)
Block(0,3,2,VINE:4)
Block(3,3,1,VINE:4)
Block(-1,3,1,VINE:4)
Block(4,3,0,VINE:2)
Block(-2,3,0,VINE:4)
Block(5,3,-1,VINE:2)
Block(-3,3,-1,VINE:4)
Block(-4,3,-2,VINE:8)
Block(5,3,-3,VINE:2)
Block(-4,3,-3,VINE:8)
Block(4,3,-4,VINE:1)
Block(-3,3,-4,VINE:8)
Block(3,3,-5,VINE:1)
Block(-3,3,-5,VINE:8)
Block(2,3,-6,VINE:1)
Block(-2,3,-6,VINE:1)
Block(0,3,-7,VINE:1)
Block(-1,3,-7,VINE:1)
Block(-2,4,-5,LEAVES)
Block(-1,4,-5,LEAVES)
Block(0,4,-5,LEAVES)
Block(-3,4,-4,LEAVES)
Block(-2,4,-4,LEAVES)
Block(-1,4,-4,LEAVES)
Block(0,4,-4,LEAVES)
Block(1,4,-4,LEAVES)
Block(-3,4,-3,LEAVES)
Block(-2,4,-3,LOG:3)
Block(-1,4,-3,LOG:3)
Block(0,4,-3,LOG:3)
Block(1,4,-3,LEAVES)
Block(2,4,-3,LEAVES)
Block(-3,4,-2,LEAVES)
Block(-2,4,-2,LOG:3)
Block(-1,4,-2,LOG:3)
Block(0,4,-2,LOG:3)
Block(1,4,-2,LEAVES)
Block(2,4,-2,LEAVES)
Block(-3,4,-1,LEAVES)
Block(-2,4,-1,LEAVES)
Block(-1,4,-1,LEAVES)
Block(0,4,-1,LEAVES)
Block(1,4,-1,LEAVES)
Block(2,4,-1,LEAVES)
Block(-2,4,0,LEAVES)
Block(-1,4,0,LEAVES)
Block(0,4,0,LEAVES)
Block(1,4,0,LEAVES)
Block(-3,4,0,VINE:4)
Block(-4,4,-2,VINE:8)
Block(-2,5,-5,LEAVES)
Block(-3,5,-4,LEAVES)
Block(-2,5,-4,LEAVES)
Block(-1,5,-4,LEAVES)
Block(0,5,-4,LEAVES)
Block(-4,5,-3,LEAVES)
Block(-3,5,-3,LEAVES)
Block(-2,5,-3,LOG:3)
Block(-1,5,-3,LOG:3)
Block(0,5,-3,LOG:3)
Block(1,5,-3,LEAVES)
Block(-3,5,-2,LEAVES)
Block(-2,5,-2,LOG:3)
Block(-1,5,-2,LOG:3)
Block(0,5,-2,LOG:3)
Block(1,5,-2,LEAVES)
Block(-2,5,-1,LEAVES)
Block(-1,5,-1,LEAVES)
Block(0,5,-1,LEAVES)
Block(1,5,-1,LEAVES)
Block(5,5,0,VINE:2)
Block(-3,5,0,VINE:4)
Block(-4,5,-2,VINE:8)
Block(-3,5,-6,VINE:1)
Block(-3,6,-4,LEAVES)
Block(-2,6,-4,LEAVES)
Block(-1,6,-4,LEAVES)
Block(0,6,-4,LEAVES)
Block(-3,6,-3,LEAVES)
Block(-2,6,-3,LOG:3)
Block(-1,6,-3,LOG:3)
Block(0,6,-3,LEAVES)
Block(-3,6,-2,LEAVES)
Block(-2,6,-2,LOG:3)
Block(-1,6,-2,LOG:3)
Block(0,6,-2,LEAVES)
Block(-3,6,-1,LEAVES)
Block(-2,6,-1,LEAVES)
Block(-3,6,2,VINE:4)
Block(5,6,0,VINE:2)
Block(1,6,0,VINE:2)
Block(-3,6,0,VINE:4)
Block(2,6,-1,VINE:2)
Block(-4,6,-1,VINE:8)
Block(-4,6,-2,VINE:8)
Block(-6,6,-2,VINE:8)
Block(5,6,-3,VINE:2)
Block(-4,6,-3,VINE:8)
Block(-4,6,-4,VINE:8)
Block(-2,6,-6,VINE:1)
Block(-3,6,-6,VINE:1)
Block(-2,7,-4,LEAVES)
Block(-1,7,-4,LEAVES)
Block(-3,7,-3,LEAVES)
Block(-2,7,-3,LOG:3)
Block(-1,7,-3,LOG:3)
Block(0,7,-3,LEAVES)
Block(-3,7,-2,LEAVES)
Block(-2,7,-2,LOG:3)
Block(-1,7,-2,LOG:3)
Block(0,7,-2,LEAVES)
Block(1,7,-2,LEAVES)
Block(-3,7,-1,LEAVES)
Block(-2,7,-1,LEAVES)
Block(-1,7,-1,LEAVES)
Block(1,7,3,VINE:4)
Block(0,7,3,VINE:4)
Block(-3,7,2,VINE:4)
Block(5,7,0,VINE:2)
Block(1,7,0,VINE:2)
Block(-3,7,0,VINE:4)
Block(2,7,-1,VINE:2)
Block(-4,7,-1,VINE:8)
Block(-4,7,-2,VINE:8)
Block(-6,7,-2,VINE:8)
Block(5,7,-3,VINE:2)
Block(-4,7,-3,VINE:8)
Block(-4,7,-4,VINE:8)
Block(-2,7,-6,VINE:1)
Block(-3,7,-6,VINE:1)
Block(-2,8,-4,LEAVES)
Block(-1,8,-4,LEAVES)
Block(0,8,-4,LEAVES)
Block(-3,8,-3,LEAVES)
Block(-2,8,-3,LOG:3)
Block(-1,8,-3,LOG:3)
Block(0,8,-3,LOG:3)
Block(1,8,-3,LEAVES)
Block(-3,8,-2,LEAVES)
Block(-2,8,-2,LOG:3)
Block(-1,8,-2,LOG:3)
Block(0,8,-2,LOG:3)
Block(1,8,-2,LEAVES)
Block(2,8,-2,LEAVES)
Block(-3,8,-1,LEAVES)
Block(-2,8,-1,LEAVES)
Block(-1,8,-1,LEAVES)
Block(0,8,-1,LEAVES)
Block(1,8,-1,LEAVES)
Block(0,8,0,LEAVES)
Block(1,8,3,VINE:4)
Block(0,8,3,VINE:4)
Block(-3,8,2,VINE:4)
Block(5,8,0,VINE:2)
Block(1,8,0,VINE:2)
Block(-3,8,0,VINE:4)
Block(5,8,-1,VINE:2)
Block(2,8,-1,VINE:2)
Block(-4,8,-1,VINE:8)
Block(-6,8,-1,VINE:8)
Block(5,8,-2,VINE:2)
Block(-4,8,-2,VINE:8)
Block(-6,8,-2,VINE:8)
Block(5,8,-3,VINE:2)
Block(-4,8,-3,VINE:8)
Block(-6,8,-3,VINE:8)
Block(-4,8,-4,VINE:8)
Block(-6,8,-4,VINE:8)
Block(-4,8,-5,VINE:1)
Block(-2,8,-6,VINE:1)
Block(-3,8,-6,VINE:1)
Block(2,8,-7,VINE:1)
Block(-1,8,-7,VINE:1)
Block(-1,9,-6,LEAVES)
Block(-2,9,-5,LEAVES)
Block(-1,9,-5,LEAVES)
Block(1,9,-5,LEAVES)
Block(-3,9,-4,LEAVES)
Block(-2,9,-4,LEAVES)
Block(-1,9,-4,LEAVES)
Block(0,9,-4,LEAVES)
Block(1,9,-4,LEAVES)
Block(2,9,-4,LEAVES)
Block(-3,9,-3,LEAVES)
Block(-2,9,-3,LOG:3)
Block(-1,9,-3,LOG:3)
Block(0,9,-3,LOG:3)
Block(1,9,-3,LEAVES)
Block(2,9,-3,LEAVES)
Block(-4,9,-2,LEAVES)
Block(-3,9,-2,LEAVES)
Block(-2,9,-2,LOG:3)
Block(-1,9,-2,LOG:3)
Block(0,9,-2,LOG:3)
Block(1,9,-2,LEAVES)
Block(2,9,-2,LEAVES)
Block(3,9,-2,LEAVES)
Block(-4,9,-1,LEAVES)
Block(-3,9,-1,LEAVES)
Block(-2,9,-1,LEAVES)
Block(-1,9,-1,LEAVES)
Block(0,9,-1,LEAVES)
Block(1,9,-1,LEAVES)
Block(2,9,-1,LEAVES)
Block(-3,9,0,LEAVES)
Block(-2,9,0,LEAVES)
Block(-1,9,0,LEAVES)
Block(0,9,0,LEAVES)
Block(1,9,0,LEAVES)
Block(-2,9,1,LEAVES)
Block(1,9,3,VINE:4)
Block(0,9,3,VINE:4)
Block(-3,9,2,VINE:4)
Block(-4,9,1,VINE:4)
Block(5,9,0,VINE:2)
Block(5,9,-1,VINE:2)
Block(-6,9,-1,VINE:8)
Block(5,9,-2,VINE:2)
Block(-6,9,-2,VINE:8)
Block(5,9,-3,VINE:2)
Block(-4,9,-3,VINE:8)
Block(-6,9,-3,VINE:8)
Block(-4,9,-4,VINE:8)
Block(-6,9,-4,VINE:8)
Block(-4,9,-5,VINE:1)
Block(-5,9,-5,VINE:1)
Block(-2,9,-6,VINE:1)
Block(-3,9,-6,VINE:1)
Block(2,9,-7,VINE:1)
Block(0,9,-7,VINE:1)
Block(-1,9,-7,VINE:1)
Block(-1,10,-6,LEAVES)
Block(0,10,-6,LEAVES)
Block(1,10,-6,LEAVES)
Block(2,10,-6,LEAVES)
Block(-3,10,-5,LEAVES)
Block(-2,10,-5,LEAVES)
Block(-1,10,-5,LEAVES)
Block(0,10,-5,LEAVES)
Block(1,10,-5,LEAVES)
Block(2,10,-5,LEAVES)
Block(3,10,-5,LEAVES)
Block(-5,10,-4,LEAVES)
Block(-4,10,-4,LEAVES)
Block(-3,10,-4,LEAVES)
Block(-2,10,-4,LEAVES)
Block(-1,10,-4,LEAVES)
Block(0,10,-4,LEAVES)
Block(1,10,-4,LEAVES)
Block(2,10,-4,LEAVES)
Block(3,10,-4,LEAVES)
Block(-5,10,-3,LEAVES)
Block(-4,10,-3,LEAVES)
Block(-3,10,-3,LEAVES)
Block(-2,10,-3,LEAVES)
Block(-1,10,-3,LOG:3)
Block(0,10,-3,LOG:3)
Block(1,10,-3,LOG:3)
Block(2,10,-3,LEAVES)
Block(3,10,-3,LEAVES)
Block(4,10,-3,LEAVES)
Block(-5,10,-2,LEAVES)
Block(-4,10,-2,LEAVES)
Block(-3,10,-2,LEAVES)
Block(-2,10,-2,LEAVES)
Block(-1,10,-2,LOG:3)
Block(0,10,-2,LOG:3)
Block(1,10,-2,LOG:3)
Block(2,10,-2,LEAVES)
Block(3,10,-2,LEAVES)
Block(4,10,-2,LEAVES)
Block(-5,10,-1,LEAVES)
Block(-4,10,-1,LEAVES)
Block(-3,10,-1,LEAVES)
Block(-2,10,-1,LEAVES)
Block(-1,10,-1,LEAVES)
Block(0,10,-1,LEAVES)
Block(1,10,-1,LEAVES)
Block(2,10,-1,LEAVES)
Block(3,10,-1,LEAVES)
Block(4,10,-1,LEAVES)
Block(-4,10,0,LEAVES)
Block(-3,10,0,LEAVES)
Block(-2,10,0,LEAVES)
Block(-1,10,0,LEAVES)
Block(0,10,0,LEAVES)
Block(1,10,0,LEAVES)
Block(2,10,0,LEAVES)
Block(3,10,0,LEAVES)
Block(4,10,0,LEAVES)
Block(-3,10,1,LEAVES)
Block(-2,10,1,LEAVES)
Block(-1,10,1,LEAVES)
Block(0,10,1,LEAVES)
Block(1,10,1,LEAVES)
Block(2,10,1,LEAVES)
Block(-1,10,2,LEAVES)
Block(0,10,2,LEAVES)
Block(1,10,2,LEAVES)
Block(1,10,3,VINE:4)
Block(0,10,3,VINE:4)
Block(-1,10,3,VINE:4)
Block(-2,10,2,VINE:4)
Block(-3,10,2,VINE:4)
Block(-4,10,1,VINE:4)
Block(5,10,0,VINE:2)
Block(-5,10,0,VINE:4)
Block(5,10,-1,VINE:2)
Block(-6,10,-1,VINE:8)
Block(5,10,-2,VINE:2)
Block(-6,10,-2,VINE:8)
Block(5,10,-3,VINE:2)
Block(-6,10,-3,VINE:8)
Block(-6,10,-4,VINE:8)
Block(-4,10,-5,VINE:1)
Block(-5,10,-5,VINE:1)
Block(-3,10,-6,VINE:1)
Block(2,10,-7,VINE:1)
Block(0,10,-7,VINE:1)
Block(-1,10,-7,VINE:1)
Block(0,11,-5,LEAVES)
Block(1,11,-5,LEAVES)
Block(-2,11,-4,LEAVES)
Block(-1,11,-4,LEAVES)
Block(0,11,-4,LEAVES)
Block(1,11,-4,LEAVES)
Block(2,11,-4,LEAVES)
Block(-3,11,-3,LEAVES)
Block(-2,11,-3,LEAVES)
Block(-1,11,-3,LEAVES)
Block(0,11,-3,LOG:3)
Block(1,11,-3,LOG:3)
Block(2,11,-3,LEAVES)
Block(3,11,-3,LEAVES)
Block(-3,11,-2,LEAVES)
Block(-2,11,-2,LEAVES)
Block(-1,11,-2,LEAVES)
Block(0,11,-2,LOG:3)
Block(1,11,-2,LOG:3)
Block(2,11,-2,LEAVES)
Block(-3,11,-1,LEAVES)
Block(-2,11,-1,LEAVES)
Block(-1,11,-1,LEAVES)
Block(0,11,-1,LEAVES)
Block(1,11,-1,LEAVES)
Block(2,11,-1,LEAVES)
Block(-2,11,0,LEAVES)
Block(-1,11,0,LEAVES)
Block(0,11,0,LEAVES)
Block(1,11,0,LEAVES)
Block(0,11,1,LEAVES)
Block(0,11,2,VINE:4)
Block(2,11,1,VINE:4)
Block(-1,11,1,VINE)
Block(3,11,0,VINE)
Block(-3,11,0,VINE:8)
Block(-4,11,-1,VINE:8)
Block(-1,11,-5,VINE:8)
Block(0,11,-6,VINE:1)
Block(0,12,-4,LEAVES)
Block(1,12,-4,LEAVES)
Block(-1,12,-3,LEAVES)
Block(0,12,-3,LOG:3)
Block(1,12,-3,LOG:3)
Block(2,12,-3,LEAVES)
Block(-2,12,-2,LEAVES)
Block(-1,12,-2,LEAVES)
Block(0,12,-2,LEAVES)
Block(1,12,-2,LOG:3)
Block(2,12,-2,LOG:3)
Block(3,12,-2,LEAVES)
Block(-2,12,-1,LEAVES)
Block(-1,12,-1,LEAVES)
Block(0,12,-1,LEAVES)
Block(1,12,-1,LOG:3)
Block(2,12,-1,LOG:3)
Block(3,12,-1,LEAVES)
Block(-1,12,0,LEAVES)
Block(0,12,0,LEAVES)
Block(1,12,0,LEAVES)
Block(2,12,0,LEAVES)
Block(0,12,1,LEAVES)
Block(-2,12,3,VINE:4)
Block(0,12,2,VINE:4)
Block(2,12,1,VINE:4)
Block(-1,12,1,VINE)
Block(-5,12,1,VINE:8)
Block(3,12,0,VINE)
Block(-2,12,0,VINE:8)
Block(-3,12,0,VINE:8)
Block(-4,12,-1,VINE:8)
Block(1,12,-5,VINE:1)
Block(0,12,-5,VINE:1)
Block(1,13,-4,LEAVES)
Block(0,13,-3,LEAVES)
Block(1,13,-3,LOG:3)
Block(2,13,-3,LEAVES)
Block(-1,13,-2,LEAVES)
Block(0,13,-2,LEAVES)
Block(1,13,-2,LOG:3)
Block(2,13,-2,LOG:3)
Block(3,13,-2,LEAVES)
Block(0,13,-1,LEAVES)
Block(1,13,-1,LOG:3)
Block(2,13,-1,LOG:3)
Block(3,13,-1,LEAVES)
Block(0,13,0,LEAVES)
Block(1,13,0,LEAVES)
Block(2,13,0,LEAVES)
Block(-1,13,3,VINE:8)
Block(-2,13,3,VINE:4)
Block(2,13,1,VINE:4)
Block(-1,13,1,VINE:4)
Block(-5,13,1,VINE:8)
Block(4,13,0,VINE:2)
Block(3,13,0,VINE)
Block(-2,13,0,VINE:8)
Block(-3,13,0,VINE:8)
Block(-2,13,-1,VINE:8)
Block(-4,13,-1,VINE:8)
Block(-5,13,-2,VINE:8)
Block(4,13,-3,VINE:1)
Block(3,13,-4,VINE:1)
Block(0,13,-4,VINE:8)
Block(1,13,-5,VINE:1)
Block(0,13,-5,VINE:1)
Block(5,13,-6,VINE:1)
Block(1,13,-6,VINE:1)
Block(1,14,-3,LEAVES)
Block(2,14,-3,LEAVES)
Block(0,14,-2,LEAVES)
Block(1,14,-2,LOG:3)
Block(2,14,-2,LOG:3)
Block(3,14,-2,LEAVES)
Block(-1,14,-1,LEAVES)
Block(0,14,-1,LOG:3)
Block(1,14,-1,LOG:3)
Block(2,14,-1,LOG:3)
Block(3,14,-1,LEAVES)
Block(-1,14,0,LEAVES)
Block(0,14,0,LOG:3)
Block(1,14,0,LOG:3)
Block(2,14,0,LEAVES)
Block(0,14,1,LEAVES)
Block(1,14,1,LEAVES)
Block(2,14,4,VINE:4)
Block(3,14,3,VINE:4)
Block(-1,14,3,VINE:8)
Block(-2,14,3,VINE:4)
Block(2,14,1,VINE:4)
Block(-1,14,1,VINE:4)
Block(-5,14,1,VINE:8)
Block(4,14,0,VINE:2)
Block(3,14,0,VINE)
Block(-2,14,0,VINE:8)
Block(-3,14,0,VINE:8)
Block(7,14,-1,VINE:2)
Block(-2,14,-1,VINE:8)
Block(-4,14,-1,VINE:8)
Block(5,14,-2,VINE:2)
Block(-5,14,-2,VINE:8)
Block(4,14,-3,VINE:1)
Block(3,14,-4,VINE:1)
Block(0,14,-5,VINE:1)
Block(5,14,-6,VINE:1)
Block(1,14,-6,VINE:1)
Block(-2,14,-6,VINE:1)
Block(2,15,-3,LEAVES)
Block(3,15,-3,LEAVES)
Block(1,15,-2,LEAVES)
Block(2,15,-2,LOG:3)
Block(3,15,-2,LEAVES)
Block(4,15,-2,LEAVES)
Block(-1,15,-1,LEAVES)
Block(0,15,-1,LOG:3)
Block(1,15,-1,LOG:3)
Block(2,15,-1,LOG:3)
Block(3,15,-1,LEAVES)
Block(-1,15,0,LEAVES)
Block(0,15,0,LOG:3)
Block(1,15,0,LOG:3)
Block(2,15,0,LEAVES)
Block(0,15,1,LEAVES)
Block(1,15,1,LEAVES)
Block(2,15,4,VINE:4)
Block(0,15,4,VINE:4)
Block(3,15,3,VINE:4)
Block(1,15,3,VINE:4)
Block(0,15,3,VINE:4)
Block(-1,15,3,VINE:8)
Block(-2,15,3,VINE:4)
Block(4,15,2,VINE:2)
Block(0,15,2,VINE:4)
Block(4,15,1,VINE:2)
Block(2,15,1,VINE:4)
Block(-1,15,1,VINE:4)
Block(-5,15,1,VINE:8)
Block(4,15,0,VINE:2)
Block(3,15,0,VINE:4)
Block(-2,15,0,VINE:8)
Block(-3,15,0,VINE:8)
Block(7,15,-1,VINE:2)
Block(-2,15,-1,VINE:8)
Block(-4,15,-1,VINE:8)
Block(6,15,-2,VINE:2)
Block(5,15,-2,VINE:2)
Block(-5,15,-2,VINE:8)
Block(4,15,-3,VINE:1)
Block(1,15,-3,VINE:1)
Block(7,15,-4,VINE:2)
Block(3,15,-4,VINE:1)
Block(0,15,-5,VINE:1)
Block(5,15,-6,VINE:1)
Block(3,15,-6,VINE:1)
Block(1,15,-6,VINE:1)
Block(-2,15,-6,VINE:1)
Block(4,15,-7,VINE:1)
Block(1,15,-8,VINE:1)
Block(2,16,-3,LEAVES)
Block(3,16,-3,LEAVES)
Block(0,16,-2,LEAVES)
Block(1,16,-2,LEAVES)
Block(2,16,-2,LEAVES)
Block(3,16,-2,LEAVES)
Block(4,16,-2,LEAVES)
Block(-1,16,-1,LEAVES)
Block(0,16,-1,LOG:3)
Block(1,16,-1,LOG:3)
Block(2,16,-1,LOG:3)
Block(3,16,-1,LEAVES)
Block(-1,16,0,LEAVES)
Block(0,16,0,LOG:3)
Block(1,16,0,LOG:3)
Block(2,16,0,LEAVES)
Block(0,16,1,LEAVES)
Block(1,16,1,LEAVES)
Block(2,16,4,VINE:4)
Block(1,16,4,VINE:4)
Block(0,16,4,VINE:4)
Block(3,16,3,VINE:4)
Block(1,16,3,VINE:4)
Block(0,16,3,VINE:4)
Block(-1,16,3,VINE:8)
Block(-2,16,3,VINE:4)
Block(4,16,2,VINE:2)
Block(3,16,2,VINE:4)
Block(-3,16,2,VINE:8)
Block(-4,16,2,VINE:4)
Block(5,16,1,VINE:2)
Block(4,16,1,VINE:2)
Block(-1,16,1,VINE:4)
Block(-5,16,1,VINE:8)
Block(4,16,0,VINE:2)
Block(-3,16,0,VINE:8)
Block(7,16,-1,VINE:2)
Block(-4,16,-1,VINE:8)
Block(7,16,-2,VINE:2)
Block(6,16,-2,VINE:2)
Block(-5,16,-2,VINE:8)
Block(7,16,-3,VINE:2)
Block(4,16,-3,VINE:1)
Block(7,16,-4,VINE:2)
Block(3,16,-4,VINE:1)
Block(2,16,-4,VINE:1)
Block(0,16,-5,VINE:1)
Block(-3,16,-5,VINE:8)
Block(5,16,-6,VINE:1)
Block(3,16,-6,VINE:1)
Block(1,16,-6,VINE:1)
Block(0,16,-6,VINE:1)
Block(-2,16,-6,VINE:1)
Block(4,16,-7,VINE:1)
Block(1,16,-8,VINE:1)
Block(-2,17,-5,LEAVES)
Block(-2,17,-4,LEAVES)
Block(-1,17,-4,LEAVES)
Block(0,17,-4,LEAVES)
Block(-1,17,-3,LEAVES)
Block(0,17,-3,LEAVES)
Block(1,17,-3,LEAVES)
Block(2,17,-3,LEAVES)
Block(3,17,-3,LEAVES)
Block(-2,17,-2,LEAVES)
Block(-1,17,-2,LEAVES)
Block(0,17,-2,LEAVES)
Block(1,17,-2,LEAVES)
Block(2,17,-2,LEAVES)
Block(3,17,-2,LEAVES)
Block(4,17,-2,LEAVES)
Block(5,17,-2,LEAVES)
Block(-3,17,-1,LEAVES)
Block(-2,17,-1,LEAVES)
Block(-1,17,-1,LEAVES)
Block(0,17,-1,LOG:3)
Block(1,17,-1,LOG:3)
Block(2,17,-1,LEAVES)
Block(3,17,-1,LEAVES)
Block(4,17,-1,LEAVES)
Block(-2,17,0,LEAVES)
Block(-1,17,0,LEAVES)
Block(0,17,0,LOG:3)
Block(1,17,0,LOG:3)
Block(2,17,0,LEAVES)
Block(3,17,0,LEAVES)
Block(0,17,1,LEAVES)
Block(1,17,1,LEAVES)
Block(2,17,1,LEAVES)
Block(3,17,1,LEAVES)
Block(0,17,2,LEAVES)
Block(1,17,2,LEAVES)
Block(2,17,4,VINE:4)
Block(1,17,4,VINE:4)
Block(0,17,4,VINE:4)
Block(3,17,3,VINE:4)
Block(1,17,3,VINE:4)
Block(0,17,3,VINE:4)
Block(-1,17,3,VINE:8)
Block(-2,17,3,VINE:4)
Block(4,17,2,VINE:2)
Block(3,17,2,VINE:4)
Block(-3,17,2,VINE)
Block(-4,17,2,VINE:4)
Block(5,17,1,VINE:2)
Block(4,17,1,VINE:2)
Block(-1,17,1,VINE:4)
Block(-5,17,1,VINE:8)
Block(6,17,0,VINE:2)
Block(4,17,0,VINE:2)
Block(-3,17,0,VINE:8)
Block(-5,17,0,VINE:8)
Block(7,17,-1,VINE:2)
Block(-4,17,-1,VINE:8)
Block(-5,17,-1,VINE:8)
Block(7,17,-2,VINE:2)
Block(6,17,-2,VINE:2)
Block(-5,17,-2,VINE:8)
Block(7,17,-3,VINE:2)
Block(4,17,-3,VINE:1)
Block(7,17,-4,VINE:2)
Block(3,17,-4,VINE:1)
Block(0,17,-5,VINE:1)
Block(-3,17,-5,VINE:8)
Block(5,17,-6,VINE:1)
Block(3,17,-6,VINE:1)
Block(2,17,-6,VINE:1)
Block(1,17,-6,VINE:1)
Block(0,17,-6,VINE:1)
Block(-2,17,-6,VINE:1)
Block(4,17,-7,VINE:1)
Block(1,17,-8,VINE:1)
Block(-2,18,-6,LEAVES)
Block(-1,18,-6,LEAVES)
Block(-3,18,-5,LEAVES)
Block(-2,18,-5,LEAVES)
Block(-1,18,-5,LEAVES)
Block(0,18,-5,LEAVES)
Block(1,18,-5,LEAVES)
Block(2,18,-5,LEAVES)
Block(3,18,-5,LEAVES)
Block(4,18,-5,LEAVES)
Block(5,18,-5,LEAVES)
Block(-3,18,-4,LEAVES)
Block(-2,18,-4,LEAVES)
Block(-1,18,-4,LEAVES)
Block(0,18,-4,LEAVES)
Block(1,18,-4,LEAVES)
Block(2,18,-4,LEAVES)
Block(3,18,-4,LEAVES)
Block(4,18,-4,LEAVES)
Block(5,18,-4,LEAVES)
Block(6,18,-4,LEAVES)
Block(-4,18,-3,LEAVES)
Block(-3,18,-3,LEAVES)
Block(-2,18,-3,LEAVES)
Block(-1,18,-3,LEAVES)
Block(0,18,-3,LEAVES)
Block(1,18,-3,LEAVES)
Block(2,18,-3,LEAVES)
Block(3,18,-3,LEAVES)
Block(4,18,-3,LEAVES)
Block(5,18,-3,LEAVES)
Block(6,18,-3,LEAVES)
Block(-4,18,-2,LEAVES)
Block(-3,18,-2,LEAVES)
Block(-2,18,-2,LEAVES)
Block(-1,18,-2,LEAVES)
Block(0,18,-2,LOG:3)
Block(1,18,-2,LEAVES)
Block(2,18,-2,LEAVES)
Block(3,18,-2,LEAVES)
Block(4,18,-2,LEAVES)
Block(5,18,-2,LEAVES)
Block(6,18,-2,LEAVES)
Block(-4,18,-1,LEAVES)
Block(-3,18,-1,LEAVES)
Block(-2,18,-1,LEAVES)
Block(-1,18,-1,LOG:3)
Block(0,18,-1,LOG:3)
Block(1,18,-1,LOG:3)
Block(2,18,-1,LEAVES)
Block(3,18,-1,LEAVES)
Block(4,18,-1,LEAVES)
Block(5,18,-1,LEAVES)
Block(6,18,-1,LEAVES)
Block(-4,18,0,LEAVES)
Block(-3,18,0,LEAVES)
Block(-2,18,0,LEAVES)
Block(-1,18,0,LEAVES)
Block(0,18,0,LOG:3)
Block(1,18,0,LOG:3)
Block(2,18,0,LEAVES)
Block(3,18,0,LEAVES)
Block(4,18,0,LEAVES)
Block(5,18,0,LEAVES)
Block(-4,18,1,LEAVES)
Block(-3,18,1,LEAVES)
Block(-2,18,1,LEAVES)
Block(-1,18,1,LEAVES)
Block(0,18,1,LEAVES)
Block(1,18,1,LEAVES)
Block(2,18,1,LEAVES)
Block(3,18,1,LEAVES)
Block(4,18,1,LEAVES)
Block(-2,18,2,LEAVES)
Block(-1,18,2,LEAVES)
Block(0,18,2,LEAVES)
Block(1,18,2,LEAVES)
Block(2,18,2,LEAVES)
Block(3,18,2,LEAVES)
Block(0,18,3,LEAVES)
Block(1,18,3,LEAVES)
Block(2,18,3,LEAVES)
Block(2,18,4,VINE:4)
Block(1,18,4,VINE:4)
Block(0,18,4,VINE:4)
Block(3,18,3,VINE:4)
Block(-1,18,3,VINE:8)
Block(-2,18,3,VINE:4)
Block(4,18,2,VINE:2)
Block(-3,18,2,VINE)
Block(-4,18,2,VINE:4)
Block(5,18,1,VINE:2)
Block(-5,18,1,VINE:8)
Block(13,18,0,VINE:4)
Block(6,18,0,VINE:2)
Block(-5,18,0,VINE:8)
Block(7,18,-1,VINE:2)
Block(-5,18,-1,VINE:8)
Block(7,18,-2,VINE:2)
Block(-5,18,-2,VINE:8)
Block(7,18,-3,VINE:2)
Block(7,18,-4,VINE:2)
Block(12,18,-5,VINE:1)
Block(11,18,-6,VINE:1)
Block(5,18,-6,VINE:1)
Block(3,18,-6,VINE:1)
Block(2,18,-6,VINE:1)
Block(1,18,-6,VINE:1)
Block(0,18,-6,VINE:1)
Block(6,18,-7,VINE:1)
Block(4,18,-7,VINE:1)
Block(6,18,-8,VINE:1)
Block(5,18,-8,VINE:1)
Block(1,18,-8,VINE:1)
Block(-2,19,-4,LEAVES)
Block(-1,19,-4,LEAVES)
Block(0,19,-4,LEAVES)
Block(1,19,-4,LEAVES)
Block(2,19,-4,LEAVES)
Block(3,19,-4,LEAVES)
Block(4,19,-4,LEAVES)
Block(-3,19,-3,LEAVES)
Block(-2,19,-3,LEAVES)
Block(-1,19,-3,LEAVES)
Block(0,19,-3,LEAVES)
Block(1,19,-3,LEAVES)
Block(2,19,-3,LEAVES)
Block(3,19,-3,LEAVES)
Block(4,19,-3,LEAVES)
Block(-3,19,-2,LEAVES)
Block(-2,19,-2,LEAVES)
Block(-1,19,-2,LOG:3)
Block(0,19,-2,LOG:3)
Block(1,19,-2,LEAVES)
Block(2,19,-2,LEAVES)
Block(3,19,-2,LEAVES)
Block(4,19,-2,LEAVES)
Block(-2,19,-1,LEAVES)
Block(-1,19,-1,LOG:3)
Block(0,19,-1,LOG:3)
Block(1,19,-1,LEAVES)
Block(2,19,-1,LEAVES)
Block(3,19,-1,LEAVES)
Block(4,19,-1,LEAVES)
Block(-3,19,0,LEAVES)
Block(-2,19,0,LEAVES)
Block(-1,19,0,LEAVES)
Block(0,19,0,LEAVES)
Block(1,19,0,LEAVES)
Block(2,19,0,LEAVES)
Block(3,19,0,LEAVES)
Block(-1,19,1,LEAVES)
Block(0,19,1,LEAVES)
Block(1,19,1,LEAVES)
Block(2,19,1,LEAVES)
Block(2,19,2,LEAVES)
Block(4,19,3,VINE:2)
Block(-2,19,2,VINE:4)
Block(-3,19,2,VINE:4)
Block(13,19,0,VINE:4)
Block(5,19,-2,VINE:2)
Block(14,19,-3,VINE:2)
Block(7,19,-4,VINE:2)
Block(12,19,-5,VINE:1)
Block(-2,19,-5,VINE:1)
Block(11,19,-6,VINE:1)
Block(3,19,-6,VINE:1)
Block(-1,19,-6,VINE:1)
Block(8,19,-7,VINE:2)
Block(6,19,-7,VINE:1)
Block(5,19,-7,VINE:1)
Block(4,19,-7,VINE:1)
Block(6,19,-8,VINE:1)
Block(5,19,-8,VINE:1)
Block(1,19,-8,VINE:1)
Block(-1,20,-4,LEAVES)
Block(0,20,-4,LEAVES)
Block(1,20,-4,LEAVES)
Block(2,20,-4,LEAVES)
Block(3,20,-4,LEAVES)
Block(4,20,-4,LEAVES)
Block(-2,20,-3,LEAVES)
Block(-1,20,-3,LEAVES)
Block(0,20,-3,LOG:3)
Block(1,20,-3,LOG:3)
Block(2,20,-3,LOG:3)
Block(3,20,-3,LEAVES)
Block(-2,20,-2,LEAVES)
Block(-1,20,-2,LOG:3)
Block(0,20,-2,LOG:3)
Block(1,20,-2,LOG:3)
Block(2,20,-2,LEAVES)
Block(3,20,-2,LEAVES)
Block(-2,20,-1,LEAVES)
Block(-1,20,-1,LEAVES)
Block(0,20,-1,LEAVES)
Block(1,20,-1,LEAVES)
Block(2,20,-1,LEAVES)
Block(-1,20,0,LEAVES)
Block(0,20,0,LEAVES)
Block(2,20,0,LEAVES)
Block(3,20,4,VINE:4)
Block(4,20,3,VINE:2)
Block(0,20,3,VINE:4)
Block(-2,20,2,VINE:4)
Block(-3,20,2,VINE:4)
Block(-4,20,2,VINE:4)
Block(13,20,0,VINE:4)
Block(14,20,-1,VINE:2)
Block(-4,20,-1,VINE:8)
Block(5,20,-2,VINE:2)
Block(-3,20,-2,VINE:8)
Block(14,20,-3,VINE:2)
Block(5,20,-3,VINE:2)
Block(7,20,-4,VINE:2)
Block(6,20,-4,VINE:2)
Block(-2,20,-4,VINE:1)
Block(13,20,-5,VINE:1)
Block(12,20,-5,VINE:1)
Block(-2,20,-5,VINE:1)
Block(11,20,-6,VINE:1)
Block(8,20,-6,VINE:2)
Block(3,20,-6,VINE:1)
Block(-1,20,-6,VINE:1)
Block(8,20,-7,VINE:2)
Block(6,20,-7,VINE:1)
Block(5,20,-7,VINE:1)
Block(4,20,-7,VINE:1)
Block(1,20,-7,VINE:1)
Block(8,20,-8,VINE:2)
Block(6,20,-8,VINE:1)
Block(5,20,-8,VINE:1)
Block(2,20,-8,VINE:1)
Block(1,20,-8,VINE:1)
Block(-1,20,-8,VINE:1)
Block(-3,20,-8,VINE:2)
Block(3,20,-9,VINE:1)
Block(1,20,-9,VINE:1)
Block(5,20,-10,VINE:1)
Block(4,21,-6,LEAVES)
Block(5,21,-6,LEAVES)
Block(6,21,-6,LEAVES)
Block(-1,21,-5,LEAVES)
Block(3,21,-5,LEAVES)
Block(4,21,-5,LEAVES)
Block(5,21,-5,LEAVES)
Block(-2,21,-4,LEAVES)
Block(-1,21,-4,LOG:3)
Block(0,21,-4,LEAVES)
Block(1,21,-4,LEAVES)
Block(2,21,-4,LEAVES)
Block(3,21,-4,LOG:3)
Block(4,21,-4,LOG:3)
Block(5,21,-4,LEAVES)
Block(-2,21,-3,LEAVES)
Block(-1,21,-3,LOG:3)
Block(0,21,-3,LOG:3)
Block(1,21,-3,LEAVES)
Block(2,21,-3,LOG:3)
Block(3,21,-3,LOG:3)
Block(4,21,-3,LEAVES)
Block(-2,21,-2,LEAVES)
Block(-1,21,-2,LOG:3)
Block(0,21,-2,LOG:3)
Block(1,21,-2,LEAVES)
Block(2,21,-2,LEAVES)
Block(3,21,-2,LEAVES)
Block(-3,21,-1,LEAVES)
Block(-2,21,-1,LEAVES)
Block(-1,21,-1,LEAVES)
Block(0,21,-1,LEAVES)
Block(1,21,-1,LEAVES)
Block(2,21,-1,LEAVES)
Block(-1,21,0,LEAVES)
Block(0,21,0,LEAVES)
Block(6,21,6,VINE:4)
Block(3,21,5,VINE:4)
Block(4,21,4,VINE:4)
Block(3,21,4,VINE:4)
Block(4,21,3,VINE:2)
Block(0,21,3,VINE:4)
Block(7,21,2,VINE:2)
Block(4,21,2,VINE:2)
Block(1,21,2,VINE:4)
Block(-2,21,2,VINE:4)
Block(-3,21,2,VINE:4)
Block(-4,21,2,VINE:4)
Block(13,21,0,VINE:4)
Block(14,21,-1,VINE:2)
Block(-4,21,-1,VINE:8)
Block(-5,21,-1,VINE:8)
Block(5,21,-2,VINE:2)
Block(14,21,-3,VINE:2)
Block(5,21,-3,VINE:2)
Block(13,21,-4,VINE:1)
Block(7,21,-4,VINE:2)
Block(6,21,-4,VINE:2)
Block(13,21,-5,VINE:1)
Block(12,21,-5,VINE:1)
Block(7,21,-5,VINE:2)
Block(-2,21,-5,VINE:1)
Block(11,21,-6,VINE:1)
Block(8,21,-6,VINE:2)
Block(3,21,-6,VINE:1)
Block(-1,21,-6,VINE:1)
Block(8,21,-7,VINE:2)
Block(6,21,-7,VINE:1)
Block(5,21,-7,VINE:1)
Block(4,21,-7,VINE:1)
Block(1,21,-7,VINE:1)
Block(8,21,-8,VINE:2)
Block(6,21,-8,VINE:1)
Block(5,21,-8,VINE:1)
Block(3,21,-8,VINE:1)
Block(2,21,-8,VINE:1)
Block(1,21,-8,VINE:1)
Block(0,21,-8,VINE:1)
Block(-1,21,-8,VINE:1)
Block(-2,21,-8,VINE:1)
Block(-3,21,-8,VINE:2)
Block(6,21,-9,VINE:1)
Block(3,21,-9,VINE:1)
Block(1,21,-9,VINE:1)
Block(-1,21,-9,VINE:1)
Block(5,21,-10,VINE:1)
Block(4,21,-10,VINE:1)
Block(8,21,-11,VINE:1)
Block(5,22,-7,LEAVES)
Block(6,22,-7,LEAVES)
Block(-3,22,-6,LEAVES)
Block(-2,22,-6,LEAVES)
Block(1,22,-6,LEAVES)
Block(4,22,-6,LEAVES)
Block(5,22,-6,LOG:3)
Block(6,22,-6,LEAVES)
Block(-4,22,-5,LEAVES)
Block(-3,22,-5,LOG:3)
Block(-2,22,-5,LOG:3)
Block(-1,22,-5,LEAVES)
Block(1,22,-5,LEAVES)
Block(2,22,-5,LEAVES)
Block(3,22,-5,LEAVES)
Block(4,22,-5,LOG:3)
Block(5,22,-5,LOG:3)
Block(6,22,-5,LEAVES)
Block(-3,22,-4,LEAVES)
Block(-2,22,-4,LOG:3)
Block(-1,22,-4,LOG:3)
Block(0,22,-4,LEAVES)
Block(1,22,-4,LEAVES)
Block(2,22,-4,LEAVES)
Block(3,22,-4,LEAVES)
Block(4,22,-4,LOG:3)
Block(5,22,-4,LEAVES)
Block(-2,22,-3,LEAVES)
Block(-1,22,-3,LOG:3)
Block(0,22,-3,LEAVES)
Block(1,22,-3,LEAVES)
Block(2,22,-3,LEAVES)
Block(3,22,-3,LEAVES)
Block(4,22,-3,LEAVES)
Block(-3,22,-2,LEAVES)
Block(-2,22,-2,LOG:3)
Block(-1,22,-2,LOG:3)
Block(0,22,-2,LOG:3)
Block(1,22,-2,LEAVES)
Block(2,22,-2,LEAVES)
Block(3,22,-2,LEAVES)
Block(4,22,-2,LEAVES)
Block(-3,22,-1,LEAVES)
Block(-2,22,-1,LEAVES)
Block(-1,22,-1,LEAVES)
Block(0,22,-1,LOG:3)
Block(1,22,-1,LEAVES)
Block(2,22,-1,LEAVES)
Block(-2,22,0,LEAVES)
Block(-1,22,0,LEAVES)
Block(0,22,0,LEAVES)
Block(1,22,0,LEAVES)
Block(2,22,0,LEAVES)
Block(0,22,1,LEAVES)
Block(2,22,1,LEAVES)
Block(6,22,6,VINE:4)
Block(3,22,5,VINE:4)
Block(4,22,4,VINE:4)
Block(3,22,4,VINE:4)
Block(4,22,3,VINE:2)
Block(0,22,3,VINE:4)
Block(9,22,2,VINE:4)
Block(7,22,2,VINE:2)
Block(4,22,2,VINE:2)
Block(1,22,2,VINE:4)
Block(-2,22,2,VINE:4)
Block(-3,22,2,VINE:4)
Block(-4,22,2,VINE:4)
Block(13,22,0,VINE:4)
Block(12,22,0,VINE:4)
Block(14,22,-1,VINE:2)
Block(-4,22,-1,VINE:8)
Block(-5,22,-1,VINE:8)
Block(-6,22,-1,VINE:8)
Block(5,22,-2,VINE:2)
Block(14,22,-3,VINE:2)
Block(5,22,-3,VINE:2)
Block(-6,22,-3,VINE:8)
Block(13,22,-4,VINE:1)
Block(7,22,-4,VINE:2)
Block(6,22,-4,VINE:2)
Block(14,22,-5,VINE:1)
Block(13,22,-5,VINE:1)
Block(12,22,-5,VINE:1)
Block(7,22,-5,VINE:2)
Block(11,22,-6,VINE:1)
Block(8,22,-6,VINE:2)
Block(8,22,-7,VINE:2)
Block(4,22,-7,VINE:1)
Block(1,22,-7,VINE:1)
Block(8,22,-8,VINE:2)
Block(6,22,-8,VINE:1)
Block(5,22,-8,VINE:1)
Block(3,22,-8,VINE:1)
Block(2,22,-8,VINE:1)
Block(1,22,-8,VINE:1)
Block(0,22,-8,VINE:1)
Block(-1,22,-8,VINE:1)
Block(-2,22,-8,VINE:1)
Block(-3,22,-8,VINE:2)
Block(-5,22,-8,VINE:8)
Block(9,22,-9,VINE:2)
Block(6,22,-9,VINE:1)
Block(4,22,-9,VINE:1)
Block(3,22,-9,VINE:1)
Block(1,22,-9,VINE:1)
Block(-1,22,-9,VINE:1)
Block(9,22,-10,VINE:2)
Block(5,22,-10,VINE:1)
Block(4,22,-10,VINE:1)
Block(3,22,-10,VINE:1)
Block(2,22,-10,VINE:1)
Block(8,22,-11,VINE:1)
Block(8,22,-12,VINE:1)
Block(6,23,-8,LEAVES)
Block(-4,23,-7,LEAVES)
Block(-3,23,-7,LEAVES)
Block(-2,23,-7,LEAVES)
Block(1,23,-7,LEAVES)
Block(5,23,-7,LEAVES)
Block(6,23,-7,LOG:3)
Block(7,23,-7,LEAVES)
Block(-5,23,-6,LEAVES)
Block(-4,23,-6,LOG:3)
Block(-3,23,-6,LOG:3)
Block(-2,23,-6,LEAVES)
Block(-1,23,-6,LEAVES)
Block(0,23,-6,LEAVES)
Block(1,23,-6,LEAVES)
Block(2,23,-6,LEAVES)
Block(4,23,-6,LEAVES)
Block(5,23,-6,LOG:3)
Block(6,23,-6,LOG:3)
Block(7,23,-6,LEAVES)
Block(-4,23,-5,LEAVES)
Block(-3,23,-5,LOG:3)
Block(-2,23,-5,LEAVES)
Block(-1,23,-5,LEAVES)
Block(0,23,-5,LEAVES)
Block(1,23,-5,LOG:1)
Block(2,23,-5,LEAVES)
Block(3,23,-5,LEAVES)
Block(4,23,-5,LEAVES)
Block(5,23,-5,LEAVES)
Block(6,23,-5,LEAVES)
Block(-4,23,-4,LEAVES)
Block(-3,23,-4,LEAVES)
Block(-2,23,-4,LEAVES)
Block(-1,23,-4,LEAVES)
Block(0,23,-4,LEAVES)
Block(1,23,-4,LEAVES)
Block(2,23,-4,LEAVES)
Block(3,23,-4,LEAVES)
Block(4,23,-4,LOG:3)
Block(5,23,-4,LEAVES)
Block(-5,23,-3,LEAVES)
Block(-4,23,-3,LEAVES)
Block(-3,23,-3,LEAVES)
Block(-2,23,-3,LEAVES)
Block(-1,23,-3,LEAVES)
Block(0,23,-3,LOG:1)
Block(1,23,-3,LEAVES)
Block(2,23,-3,LEAVES)
Block(3,23,-3,LEAVES)
Block(4,23,-3,LEAVES)
Block(5,23,-3,LEAVES)
Block(-4,23,-2,LEAVES)
Block(-3,23,-2,LEAVES)
Block(-2,23,-2,LOG:3)
Block(-1,23,-2,LEAVES)
Block(0,23,-2,LEAVES)
Block(1,23,-2,LEAVES)
Block(2,23,-2,LEAVES)
Block(3,23,-2,LEAVES)
Block(-4,23,-1,LEAVES)
Block(-3,23,-1,LOG:3)
Block(-2,23,-1,LEAVES)
Block(-1,23,-1,LEAVES)
Block(0,23,-1,LOG:3)
Block(1,23,-1,LOG:3)
Block(2,23,-1,LEAVES)
Block(-3,23,0,LEAVES)
Block(-2,23,0,LEAVES)
Block(-1,23,0,LEAVES)
Block(0,23,0,LEAVES)
Block(1,23,0,LOG:3)
Block(2,23,0,LEAVES)
Block(-4,23,1,LEAVES)
Block(-3,23,1,LEAVES)
Block(-2,23,1,LEAVES)
Block(-1,23,1,LEAVES)
Block(0,23,1,LEAVES)
Block(1,23,1,LEAVES)
Block(2,23,1,LOG:3)
Block(3,23,1,LEAVES)
Block(2,23,2,LEAVES)
Block(3,23,2,LEAVES)
Block(6,23,6,VINE:4)
Block(3,23,5,VINE:4)
Block(7,23,4,VINE:2)
Block(4,23,4,VINE:4)
Block(3,23,4,VINE:4)
Block(-2,23,4,VINE:4)
Block(4,23,3,VINE:2)
Block(0,23,3,VINE:4)
Block(9,23,2,VINE:4)
Block(7,23,2,VINE:2)
Block(4,23,2,VINE:2)
Block(1,23,2,VINE:4)
Block(-1,23,2,VINE:4)
Block(-2,23,2,VINE:4)
Block(-3,23,2,VINE:4)
Block(-4,23,2,VINE:4)
Block(-5,23,2,VINE:4)
Block(13,23,0,VINE:4)
Block(12,23,0,VINE:4)
Block(14,23,-1,VINE:2)
Block(13,23,-1,VINE:2)
Block(-5,23,-1,VINE:8)
Block(-6,23,-1,VINE:8)
Block(-7,23,-1,VINE:1)
Block(15,23,-3,VINE:2)
Block(14,23,-3,VINE:2)
Block(-6,23,-3,VINE:8)
Block(13,23,-4,VINE:1)
Block(7,23,-4,VINE:2)
Block(14,23,-5,VINE:1)
Block(13,23,-5,VINE:1)
Block(12,23,-5,VINE:1)
Block(11,23,-6,VINE:1)
Block(8,23,-6,VINE:2)
Block(-6,23,-6,VINE:8)
Block(8,23,-7,VINE:2)
Block(4,23,-7,VINE:1)
Block(8,23,-8,VINE:2)
Block(5,23,-8,VINE:1)
Block(3,23,-8,VINE:1)
Block(2,23,-8,VINE:1)
Block(1,23,-8,VINE:1)
Block(0,23,-8,VINE:1)
Block(-1,23,-8,VINE:1)
Block(-2,23,-8,VINE:1)
Block(-3,23,-8,VINE:2)
Block(-5,23,-8,VINE:8)
Block(9,23,-9,VINE:2)
Block(6,23,-9,VINE:1)
Block(4,23,-9,VINE:1)
Block(3,23,-9,VINE:1)
Block(1,23,-9,VINE:1)
Block(-1,23,-9,VINE:1)
Block(-2,23,-9,VINE:1)
Block(-4,23,-9,VINE:1)
Block(-5,23,-9,VINE:1)
Block(9,23,-10,VINE:2)
Block(5,23,-10,VINE:1)
Block(4,23,-10,VINE:1)
Block(3,23,-10,VINE:1)
Block(2,23,-10,VINE:1)
Block(8,23,-11,VINE:1)
Block(8,23,-12,VINE:1)
Block(-4,24,-8,LEAVES)
Block(6,24,-8,LEAVES)
Block(7,24,-8,LEAVES)
Block(-5,24,-7,LEAVES)
Block(-4,24,-7,LOG:3)
Block(-3,24,-7,LEAVES)
Block(-2,24,-7,LEAVES)
Block(-1,24,-7,LEAVES)
Block(0,24,-7,LEAVES)
Block(1,24,-7,LEAVES)
Block(2,24,-7,LEAVES)
Block(3,24,-7,LEAVES)
Block(5,24,-7,LEAVES)
Block(6,24,-7,LOG:3)
Block(7,24,-7,LEAVES)
Block(-5,24,-6,LEAVES)
Block(-4,24,-6,LOG:3)
Block(-3,24,-6,LEAVES)
Block(-2,24,-6,LEAVES)
Block(-1,24,-6,LEAVES)
Block(0,24,-6,LEAVES)
Block(1,24,-6,LEAVES)
Block(2,24,-6,LOG:1)
Block(3,24,-6,LEAVES)
Block(4,24,-6,LEAVES)
Block(5,24,-6,LEAVES)
Block(6,24,-6,LEAVES)
Block(-4,24,-5,LEAVES)
Block(-3,24,-5,LEAVES)
Block(-2,24,-5,LEAVES)
Block(-1,24,-5,LEAVES)
Block(0,24,-5,LEAVES)
Block(1,24,-5,LEAVES)
Block(2,24,-5,LEAVES)
Block(3,24,-5,LEAVES)
Block(4,24,-5,LEAVES)
Block(5,24,-5,LEAVES)
Block(6,24,-5,LEAVES)
Block(-4,24,-4,LEAVES)
Block(-3,24,-4,LEAVES)
Block(-2,24,-4,LEAVES)
Block(0,24,-4,LOG:3)
Block(1,24,-4,LEAVES)
Block(2,24,-4,LEAVES)
Block(3,24,-4,LEAVES)
Block(4,24,-4,LOG:3)
Block(5,24,-4,LEAVES)
Block(6,24,-4,LEAVES)
Block(-4,24,-3,LEAVES)
Block(-3,24,-3,LEAVES)
Block(-2,24,-3,LEAVES)
Block(-1,24,-3,LEAVES)
Block(0,24,-3,LOG:3)
Block(1,24,-3,LEAVES)
Block(2,24,-3,LEAVES)
Block(3,24,-3,LEAVES)
Block(4,24,-3,LEAVES)
Block(5,24,-3,LOG:3)
Block(6,24,-3,LEAVES)
Block(-4,24,-2,LEAVES)
Block(-3,24,-2,LEAVES)
Block(-2,24,-2,LEAVES)
Block(-1,24,-2,LEAVES)
Block(0,24,-2,LEAVES)
Block(1,24,-2,LEAVES)
Block(2,24,-2,LEAVES)
Block(3,24,-2,LEAVES)
Block(5,24,-2,LEAVES)
Block(6,24,-2,LEAVES)
Block(7,24,-2,LEAVES)
Block(-5,24,-1,LEAVES)
Block(-4,24,-1,LOG:3)
Block(-3,24,-1,LOG:3)
Block(-2,24,-1,LEAVES)
Block(-1,24,-1,LEAVES)
Block(0,24,-1,LEAVES)
Block(1,24,-1,LEAVES)
Block(2,24,-1,LEAVES)
Block(3,24,-1,LEAVES)
Block(-4,24,0,LEAVES)
Block(-3,24,0,LEAVES)
Block(-2,24,0,LEAVES)
Block(-1,24,0,LEAVES)
Block(0,24,0,LEAVES)
Block(1,24,0,LOG:3)
Block(2,24,0,LEAVES)
Block(3,24,0,LEAVES)
Block(-3,24,1,LEAVES)
Block(-2,24,1,LEAVES)
Block(-1,24,1,LEAVES)
Block(0,24,1,LEAVES)
Block(1,24,1,LEAVES)
Block(2,24,1,LOG:3)
Block(3,24,1,LOG:3)
Block(4,24,1,LEAVES)
Block(-1,24,2,LEAVES)
Block(2,24,2,LEAVES)
Block(3,24,2,LOG:3)
Block(4,24,2,LEAVES)
Block(3,24,3,LEAVES)
Block(6,24,6,VINE:4)
Block(6,24,5,VINE:4)
Block(3,24,5,VINE:4)
Block(7,24,4,VINE:2)
Block(4,24,4,VINE:4)
Block(3,24,4,VINE:4)
Block(2,24,4,VINE:4)
Block(-2,24,4,VINE:4)
Block(7,24,3,VINE:2)
Block(4,24,3,VINE:2)
Block(1,24,3,VINE:4)
Block(0,24,3,VINE:4)
Block(-1,24,3,VINE:4)
Block(9,24,2,VINE:4)
Block(7,24,2,VINE:2)
Block(-5,24,2,VINE:4)
Block(11,24,1,VINE:4)
Block(-7,24,1,VINE:8)
Block(13,24,0,VINE:4)
Block(12,24,0,VINE:4)
Block(14,24,-1,VINE:2)
Block(13,24,-1,VINE:2)
Block(-6,24,-1,VINE:8)
Block(-7,24,-1,VINE:1)
Block(-7,24,-2,VINE:8)
Block(15,24,-3,VINE:2)
Block(14,24,-3,VINE:2)
Block(-5,24,-3,VINE:8)
Block(13,24,-4,VINE:1)
Block(7,24,-4,VINE:2)
Block(14,24,-5,VINE:1)
Block(13,24,-5,VINE:1)
Block(12,24,-5,VINE:1)
Block(9,24,-5,VINE:1)
Block(7,24,-5,VINE:2)
Block(11,24,-6,VINE:1)
Block(-6,24,-7,VINE:8)
Block(8,24,-8,VINE:2)
Block(3,24,-8,VINE:1)
Block(2,24,-8,VINE:1)
Block(1,24,-8,VINE:1)
Block(0,24,-8,VINE:1)
Block(-1,24,-8,VINE:1)
Block(-2,24,-8,VINE:1)
Block(-3,24,-8,VINE:2)
Block(-5,24,-8,VINE:8)
Block(-7,24,-8,VINE:8)
Block(9,24,-9,VINE:2)
Block(6,24,-9,VINE:1)
Block(4,24,-9,VINE:1)
Block(3,24,-9,VINE:1)
Block(1,24,-9,VINE:1)
Block(-1,24,-9,VINE:1)
Block(-2,24,-9,VINE:1)
Block(-4,24,-9,VINE:1)
Block(-5,24,-9,VINE:1)
Block(-6,24,-9,VINE:1)
Block(9,24,-10,VINE:2)
Block(5,24,-10,VINE:1)
Block(4,24,-10,VINE:1)
Block(3,24,-10,VINE:1)
Block(2,24,-10,VINE:1)
Block(8,24,-11,VINE:1)
Block(7,24,-11,VINE:1)
Block(0,24,-11,VINE:1)
Block(-1,24,-11,VINE:1)
Block(8,24,-12,VINE:1)
Block(6,24,-12,VINE:1)
Block(8,24,-13,VINE:1)
Block(0,25,-9,LEAVES)
Block(7,25,-9,LEAVES)
Block(-6,25,-8,LEAVES)
Block(-5,25,-8,LEAVES)
Block(-1,25,-8,LEAVES)
Block(0,25,-8,LEAVES)
Block(1,25,-8,LEAVES)
Block(2,25,-8,LEAVES)
Block(3,25,-8,LEAVES)
Block(4,25,-8,LEAVES)
Block(5,25,-8,LEAVES)
Block(6,25,-8,LEAVES)
Block(7,25,-8,LEAVES)
Block(-5,25,-7,LEAVES)
Block(-4,25,-7,LEAVES)
Block(-2,25,-7,LEAVES)
Block(-1,25,-7,LEAVES)
Block(0,25,-7,LEAVES)
Block(1,25,-7,LEAVES)
Block(2,25,-7,LEAVES)
Block(3,25,-7,LOG:1)
Block(4,25,-7,LEAVES)
Block(5,25,-7,LEAVES)
Block(6,25,-7,LEAVES)
Block(7,25,-7,LEAVES)
Block(-4,25,-6,LEAVES)
Block(-3,25,-6,LEAVES)
Block(-2,25,-6,LEAVES)
Block(-1,25,-6,LEAVES)
Block(0,25,-6,LEAVES)
Block(1,25,-6,LEAVES)
Block(2,25,-6,LOG:1)
Block(3,25,-6,LEAVES)
Block(4,25,-6,LEAVES)
Block(5,25,-6,LEAVES)
Block(6,25,-6,LEAVES)
Block(-4,25,-5,LEAVES)
Block(-3,25,-5,LEAVES)
Block(-2,25,-5,LEAVES)
Block(-1,25,-5,LOG:3)
Block(0,25,-5,LEAVES)
Block(1,25,-5,LEAVES)
Block(2,25,-5,LEAVES)
Block(3,25,-5,LEAVES)
Block(4,25,-5,LEAVES)
Block(5,25,-5,LEAVES)
Block(6,25,-5,LEAVES)
Block(-4,25,-4,LEAVES)
Block(-3,25,-4,LEAVES)
Block(-2,25,-4,LEAVES)
Block(-1,25,-4,LOG:3)
Block(0,25,-4,LOG:3)
Block(1,25,-4,LEAVES)
Block(2,25,-4,LEAVES)
Block(3,25,-4,LEAVES)
Block(4,25,-4,LEAVES)
Block(5,25,-4,LEAVES)
Block(6,25,-4,LEAVES)
Block(-4,25,-3,LEAVES)
Block(-3,25,-3,LEAVES)
Block(-2,25,-3,LEAVES)
Block(-1,25,-3,LEAVES)
Block(0,25,-3,LOG:3)
Block(1,25,-3,LEAVES)
Block(2,25,-3,LEAVES)
Block(3,25,-3,LEAVES)
Block(4,25,-3,LEAVES)
Block(5,25,-3,LOG:3)
Block(6,25,-3,LEAVES)
Block(7,25,-3,LEAVES)
Block(8,25,-3,LEAVES)
Block(-4,25,-2,LEAVES)
Block(-3,25,-2,LEAVES)
Block(-2,25,-2,LEAVES)
Block(-1,25,-2,LEAVES)
Block(0,25,-2,LEAVES)
Block(1,25,-2,LEAVES)
Block(2,25,-2,LEAVES)
Block(3,25,-2,LEAVES)
Block(4,25,-2,LEAVES)
Block(5,25,-2,LEAVES)
Block(6,25,-2,LOG:3)
Block(7,25,-2,LEAVES)
Block(8,25,-2,LEAVES)
Block(9,25,-2,LEAVES)
Block(10,25,-2,LEAVES)
Block(-5,25,-1,LEAVES)
Block(-4,25,-1,LOG:3)
Block(-3,25,-1,LEAVES)
Block(-2,25,-1,LEAVES)
Block(-1,25,-1,LEAVES)
Block(0,25,-1,LEAVES)
Block(1,25,-1,LEAVES)
Block(2,25,-1,LEAVES)
Block(3,25,-1,LEAVES)
Block(4,25,-1,LEAVES)
Block(6,25,-1,LEAVES)
Block(7,25,-1,LEAVES)
Block(8,25,-1,LEAVES)
Block(9,25,-1,LEAVES)
Block(-5,25,0,LEAVES)
Block(-4,25,0,LOG:3)
Block(-3,25,0,LEAVES)
Block(-2,25,0,LEAVES)
Block(-1,25,0,LEAVES)
Block(0,25,0,LEAVES)
Block(1,25,0,LEAVES)
Block(2,25,0,LEAVES)
Block(3,25,0,LEAVES)
Block(4,25,0,LEAVES)
Block(7,25,0,LEAVES)
Block(8,25,0,LEAVES)
Block(9,25,0,LEAVES)
Block(-4,25,1,LEAVES)
Block(-3,25,1,LEAVES)
Block(-2,25,1,LEAVES)
Block(-1,25,1,LEAVES)
Block(0,25,1,LEAVES)
Block(1,25,1,LEAVES)
Block(2,25,1,LEAVES)
Block(3,25,1,LEAVES)
Block(4,25,1,LEAVES)
Block(5,25,1,LEAVES)
Block(-2,25,2,LEAVES)
Block(-1,25,2,LEAVES)
Block(0,25,2,LEAVES)
Block(1,25,2,LEAVES)
Block(2,25,2,LEAVES)
Block(3,25,2,LOG:3)
Block(4,25,2,LOG:3)
Block(5,25,2,LEAVES)
Block(-2,25,3,LEAVES)
Block(3,25,3,LEAVES)
Block(4,25,3,LEAVES)
Block(5,25,3,LEAVES)
Block(6,25,6,VINE:4)
Block(6,25,5,VINE:4)
Block(3,25,5,VINE:4)
Block(8,25,4,VINE:2)
Block(7,25,4,VINE:2)
Block(4,25,4,VINE:4)
Block(2,25,4,VINE:4)
Block(-2,25,4,VINE:4)
Block(7,25,3,VINE:2)
Block(1,25,3,VINE:4)
Block(0,25,3,VINE:4)
Block(-1,25,3,VINE:4)
Block(-5,25,3,VINE:4)
Block(-6,25,3,VINE:4)
Block(9,25,2,VINE:4)
Block(8,25,2,VINE:4)
Block(7,25,2,VINE:2)
Block(-5,25,2,VINE:4)
Block(-7,25,2,VINE:8)
Block(-9,25,2,VINE:8)
Block(11,25,1,VINE:4)
Block(-7,25,1,VINE:8)
Block(13,25,0,VINE:4)
Block(12,25,0,VINE:4)
Block(-8,25,0,VINE:8)
Block(14,25,-1,VINE:2)
Block(13,25,-1,VINE:2)
Block(-7,25,-1,VINE:1)
Block(15,25,-2,VINE:2)
Block(-7,25,-2,VINE:8)
Block(15,25,-3,VINE:2)
Block(14,25,-3,VINE:2)
Block(-5,25,-3,VINE:8)
Block(-7,25,-3,VINE:8)
Block(15,25,-4,VINE:2)
Block(13,25,-4,VINE:1)
Block(-7,25,-4,VINE:8)
Block(14,25,-5,VINE:1)
Block(13,25,-5,VINE:1)
Block(12,25,-5,VINE:1)
Block(10,25,-5,VINE:1)
Block(9,25,-5,VINE:1)
Block(7,25,-5,VINE:2)
Block(11,25,-6,VINE:1)
Block(-5,25,-6,VINE:8)
Block(8,25,-8,VINE:2)
Block(-7,25,-8,VINE:8)
Block(9,25,-9,VINE:2)
Block(4,25,-9,VINE:1)
Block(3,25,-9,VINE:1)
Block(1,25,-9,VINE:1)
Block(-1,25,-9,VINE:1)
Block(-2,25,-9,VINE:1)
Block(-5,25,-9,VINE:1)
Block(-6,25,-9,VINE:1)
Block(9,25,-10,VINE:2)
Block(5,25,-10,VINE:1)
Block(4,25,-10,VINE:1)
Block(3,25,-10,VINE:1)
Block(2,25,-10,VINE:1)
Block(0,25,-10,VINE:1)
Block(8,25,-11,VINE:1)
Block(7,25,-11,VINE:1)
Block(1,25,-11,VINE:1)
Block(0,25,-11,VINE:1)
Block(-1,25,-11,VINE:1)
Block(9,25,-12,VINE:2)
Block(8,25,-12,VINE:1)
Block(6,25,-12,VINE:1)
Block(8,25,-13,VINE:1)
Block(7,26,-10,LEAVES)
Block(8,26,-10,LEAVES)
Block(1,26,-9,LEAVES)
Block(2,26,-9,LEAVES)
Block(4,26,-9,LEAVES)
Block(5,26,-9,LEAVES)
Block(6,26,-9,LEAVES)
Block(7,26,-9,LEAVES)
Block(-6,26,-8,LEAVES)
Block(-5,26,-8,LEAVES)
Block(-3,26,-8,LEAVES)
Block(-2,26,-8,LEAVES)
Block(-1,26,-8,LEAVES)
Block(0,26,-8,LEAVES)
Block(1,26,-8,LEAVES)
Block(2,26,-8,LEAVES)
Block(3,26,-8,LEAVES)
Block(4,26,-8,LOG:1)
Block(5,26,-8,LEAVES)
Block(6,26,-8,LEAVES)
Block(7,26,-8,LEAVES)
Block(-5,26,-7,LEAVES)
Block(-4,26,-7,LEAVES)
Block(-3,26,-7,LEAVES)
Block(-2,26,-7,LEAVES)
Block(-1,26,-7,LEAVES)
Block(0,26,-7,LEAVES)
Block(1,26,-7,LEAVES)
Block(2,26,-7,LEAVES)
Block(3,26,-7,LOG:1)
Block(4,26,-7,LEAVES)
Block(5,26,-7,LEAVES)
Block(-5,26,-6,LEAVES)
Block(-4,26,-6,LEAVES)
Block(-3,26,-6,LEAVES)
Block(-2,26,-6,LEAVES)
Block(-1,26,-6,LEAVES)
Block(0,26,-6,LEAVES)
Block(1,26,-6,LEAVES)
Block(2,26,-6,LEAVES)
Block(3,26,-6,LEAVES)
Block(4,26,-6,LEAVES)
Block(5,26,-6,LEAVES)
Block(-5,26,-5,LEAVES)
Block(-4,26,-5,LEAVES)
Block(-3,26,-5,LEAVES)
Block(-2,26,-5,LOG:3)
Block(-1,26,-5,LEAVES)
Block(0,26,-5,LEAVES)
Block(1,26,-5,LEAVES)
Block(2,26,-5,LEAVES)
Block(3,26,-5,LEAVES)
Block(4,26,-5,LEAVES)
Block(5,26,-5,LEAVES)
Block(6,26,-5,LEAVES)
Block(-6,26,-4,LEAVES)
Block(-5,26,-4,LEAVES)
Block(-4,26,-4,LEAVES)
Block(-3,26,-4,LEAVES)
Block(-2,26,-4,LEAVES)
Block(-1,26,-4,LEAVES)
Block(0,26,-4,LEAVES)
Block(1,26,-4,LEAVES)
Block(2,26,-4,LEAVES)
Block(3,26,-4,LEAVES)
Block(4,26,-4,LEAVES)
Block(5,26,-4,LEAVES)
Block(6,26,-4,LEAVES)
Block(7,26,-4,LEAVES)
Block(9,26,-4,LEAVES)
Block(-6,26,-3,LEAVES)
Block(-5,26,-3,LEAVES)
Block(-4,26,-3,LEAVES)
Block(-3,26,-3,LEAVES)
Block(-2,26,-3,LEAVES)
Block(-1,26,-3,LEAVES)
Block(0,26,-3,LEAVES)
Block(1,26,-3,LOG:3)
Block(2,26,-3,LEAVES)
Block(3,26,-3,LEAVES)
Block(4,26,-3,LEAVES)
Block(5,26,-3,LEAVES)
Block(6,26,-3,LEAVES)
Block(7,26,-3,LEAVES)
Block(8,26,-3,LEAVES)
Block(9,26,-3,LEAVES)
Block(10,26,-3,LEAVES)
Block(12,26,-3,LEAVES)
Block(13,26,-3,LEAVES)
Block(-6,26,-2,LEAVES)
Block(-5,26,-2,LEAVES)
Block(-4,26,-2,LEAVES)
Block(-3,26,-2,LEAVES)
Block(-2,26,-2,LEAVES)
Block(-1,26,-2,LEAVES)
Block(0,26,-2,LEAVES)
Block(1,26,-2,LEAVES)
Block(2,26,-2,LOG:3)
Block(3,26,-2,LEAVES)
Block(4,26,-2,LEAVES)
Block(5,26,-2,LEAVES)
Block(6,26,-2,LOG:3)
Block(7,26,-2,LOG:3)
Block(8,26,-2,LOG:1)
Block(9,26,-2,LOG:3)
Block(10,26,-2,LEAVES)
Block(11,26,-2,LEAVES)
Block(-5,26,-1,LEAVES)
Block(-4,26,-1,LEAVES)
Block(-3,26,-1,LEAVES)
Block(-2,26,-1,LEAVES)
Block(-1,26,-1,LEAVES)
Block(0,26,-1,LEAVES)
Block(1,26,-1,LEAVES)
Block(2,26,-1,LEAVES)
Block(3,26,-1,LEAVES)
Block(4,26,-1,LEAVES)
Block(5,26,-1,LEAVES)
Block(6,26,-1,LEAVES)
Block(7,26,-1,LEAVES)
Block(8,26,-1,LEAVES)
Block(9,26,-1,LEAVES)
Block(10,26,-1,LEAVES)
Block(-6,26,0,LEAVES)
Block(-5,26,0,LOG:3)
Block(-4,26,0,LOG:3)
Block(-3,26,0,LEAVES)
Block(-2,26,0,LEAVES)
Block(-1,26,0,LEAVES)
Block(0,26,0,LEAVES)
Block(1,26,0,LEAVES)
Block(2,26,0,LEAVES)
Block(3,26,0,LEAVES)
Block(4,26,0,LEAVES)
Block(5,26,0,LEAVES)
Block(6,26,0,LEAVES)
Block(7,26,0,LEAVES)
Block(8,26,0,LEAVES)
Block(9,26,0,LEAVES)
Block(-6,26,1,LEAVES)
Block(-5,26,1,LEAVES)
Block(-4,26,1,LEAVES)
Block(-3,26,1,LEAVES)
Block(-2,26,1,LEAVES)
Block(-1,26,1,LEAVES)
Block(0,26,1,LEAVES)
Block(1,26,1,LEAVES)
Block(2,26,1,LEAVES)
Block(3,26,1,LEAVES)
Block(4,26,1,LEAVES)
Block(5,26,1,LEAVES)
Block(6,26,1,LEAVES)
Block(7,26,1,LEAVES)
Block(8,26,1,LEAVES)
Block(9,26,1,LEAVES)
Block(-6,26,2,LEAVES)
Block(-3,26,2,LEAVES)
Block(-2,26,2,LEAVES)
Block(-1,26,2,LEAVES)
Block(1,26,2,LEAVES)
Block(2,26,2,LEAVES)
Block(3,26,2,LEAVES)
Block(4,26,2,LEAVES)
Block(5,26,2,LEAVES)
Block(6,26,2,LEAVES)
Block(-1,26,3,LEAVES)
Block(2,26,3,LEAVES)
Block(3,26,3,LEAVES)
Block(4,26,3,LEAVES)
Block(5,26,3,LEAVES)
Block(6,26,3,LEAVES)
Block(3,26,4,LEAVES)
Block(5,26,4,LEAVES)
Block(6,26,4,LEAVES)
Block(7,26,6,VINE:4)
Block(6,26,6,VINE:4)
Block(6,26,5,VINE:4)
Block(5,26,5,VINE:4)
Block(3,26,5,VINE:4)
Block(8,26,4,VINE:2)
Block(7,26,4,VINE:2)
Block(4,26,4,VINE:4)
Block(2,26,4,VINE:4)
Block(7,26,3,VINE:2)
Block(1,26,3,VINE:4)
Block(-2,26,3,VINE:4)
Block(-5,26,3,VINE:4)
Block(-6,26,3,VINE:4)
Block(-8,26,3,VINE:4)
Block(10,26,2,VINE:4)
Block(9,26,2,VINE:4)
Block(8,26,2,VINE:4)
Block(7,26,2,VINE:2)
Block(-4,26,2,VINE:4)
Block(-5,26,2,VINE:4)
Block(-7,26,2,VINE)
Block(-9,26,2,VINE:8)
Block(11,26,1,VINE:4)
Block(-7,26,1,VINE:8)
Block(-9,26,1,VINE:8)
Block(13,26,0,VINE:4)
Block(12,26,0,VINE:4)
Block(-8,26,0,VINE:8)
Block(14,26,-1,VINE:2)
Block(13,26,-1,VINE:2)
Block(-7,26,-1,VINE)
Block(15,26,-2,VINE:2)
Block(-7,26,-2,VINE:8)
Block(15,26,-3,VINE:2)
Block(14,26,-3,VINE:2)
Block(-7,26,-3,VINE:8)
Block(15,26,-4,VINE:2)
Block(13,26,-4,VINE:1)
Block(-7,26,-4,VINE:8)
Block(14,26,-5,VINE:1)
Block(13,26,-5,VINE:1)
Block(12,26,-5,VINE:1)
Block(10,26,-5,VINE:1)
Block(9,26,-5,VINE:1)
Block(8,26,-5,VINE:2)
Block(7,26,-5,VINE:2)
Block(11,26,-6,VINE:1)
Block(6,26,-7,VINE:4)
Block(8,26,-8,VINE:2)
Block(-7,26,-8,VINE:8)
Block(9,26,-9,VINE:2)
Block(0,26,-9,VINE:1)
Block(-1,26,-9,VINE:1)
Block(-2,26,-9,VINE:1)
Block(-3,26,-9,VINE:1)
Block(-5,26,-9,VINE:1)
Block(-6,26,-9,VINE:1)
Block(9,26,-10,VINE:2)
Block(5,26,-10,VINE:1)
Block(4,26,-10,VINE:1)
Block(3,26,-10,VINE:1)
Block(2,26,-10,VINE:1)
Block(-4,26,-10,VINE:1)
Block(-6,26,-10,VINE:1)
Block(9,26,-11,VINE:2)
Block(8,26,-11,VINE:1)
Block(7,26,-11,VINE:1)
Block(1,26,-11,VINE:1)
Block(0,26,-11,VINE:1)
Block(-1,26,-11,VINE:1)
Block(-7,26,-11,VINE:1)
Block(9,26,-12,VINE:2)
Block(8,26,-12,VINE:1)
Block(6,26,-12,VINE:1)
Block(8,26,-13,VINE:1)
Block(7,27,-12,LEAVES)
Block(6,27,-11,LEAVES)
Block(7,27,-11,LEAVES)
Block(8,27,-11,LEAVES)
Block(-1,27,-10,LEAVES)
Block(0,27,-10,LEAVES)
Block(1,27,-10,LEAVES)
Block(4,27,-10,LEAVES)
Block(5,27,-10,LEAVES)
Block(6,27,-10,LEAVES)
Block(7,27,-10,LEAVES)
Block(8,27,-10,LEAVES)
Block(-6,27,-9,LEAVES)
Block(-5,27,-9,LEAVES)
Block(-4,27,-9,LEAVES)
Block(-1,27,-9,LEAVES)
Block(0,27,-9,LEAVES)
Block(1,27,-9,LEAVES)
Block(2,27,-9,LEAVES)
Block(3,27,-9,LEAVES)
Block(4,27,-9,LEAVES)
Block(5,27,-9,LEAVES)
Block(6,27,-9,LEAVES)
Block(7,27,-9,LEAVES)
Block(8,27,-9,LEAVES)
Block(-6,27,-8,LEAVES)
Block(-5,27,-8,LEAVES)
Block(-4,27,-8,LEAVES)
Block(-3,27,-8,LEAVES)
Block(-2,27,-8,LEAVES)
Block(-1,27,-8,LEAVES)
Block(0,27,-8,LEAVES)
Block(1,27,-8,LEAVES)
Block(2,27,-8,LEAVES)
Block(3,27,-8,LEAVES)
Block(4,27,-8,LEAVES)
Block(5,27,-8,LEAVES)
Block(6,27,-8,LEAVES)
Block(7,27,-8,LEAVES)
Block(-5,27,-7,LEAVES)
Block(-4,27,-7,LEAVES)
Block(-3,27,-7,LEAVES)
Block(-2,27,-7,LEAVES)
Block(-1,27,-7,LEAVES)
Block(0,27,-7,LEAVES)
Block(1,27,-7,LEAVES)
Block(2,27,-7,LEAVES)
Block(3,27,-7,LEAVES)
Block(4,27,-7,LEAVES)
Block(5,27,-7,LEAVES)
Block(-4,27,-6,LEAVES)
Block(-3,27,-6,LEAVES)
Block(-2,27,-6,LEAVES)
Block(-1,27,-6,LOG:1)
Block(0,27,-6,LEAVES)
Block(1,27,-6,LEAVES)
Block(2,27,-6,LEAVES)
Block(3,27,-6,LEAVES)
Block(4,27,-6,LEAVES)
Block(5,27,-6,LEAVES)
Block(6,27,-6,LEAVES)
Block(-3,27,-5,LEAVES)
Block(-2,27,-5,LEAVES)
Block(0,27,-5,LEAVES)
Block(1,27,-5,LEAVES)
Block(2,27,-5,LEAVES)
Block(3,27,-5,LEAVES)
Block(4,27,-5,LEAVES)
Block(5,27,-5,LEAVES)
Block(6,27,-5,LEAVES)
Block(7,27,-5,LEAVES)
Block(11,27,-5,LEAVES)
Block(-5,27,-4,LEAVES)
Block(-4,27,-4,LEAVES)
Block(-3,27,-4,LEAVES)
Block(-2,27,-4,LEAVES)
Block(-1,27,-4,LEAVES)
Block(0,27,-4,LEAVES)
Block(1,27,-4,LEAVES)
Block(2,27,-4,LEAVES)
Block(3,27,-4,LEAVES)
Block(4,27,-4,LEAVES)
Block(5,27,-4,LEAVES)
Block(6,27,-4,LEAVES)
Block(7,27,-4,LEAVES)
Block(8,27,-4,LEAVES)
Block(9,27,-4,LEAVES)
Block(10,27,-4,LEAVES)
Block(11,27,-4,LEAVES)
Block(12,27,-4,LEAVES)
Block(13,27,-4,LEAVES)
Block(-6,27,-3,LEAVES)
Block(-5,27,-3,LEAVES)
Block(-4,27,-3,LEAVES)
Block(-3,27,-3,LEAVES)
Block(-2,27,-3,LEAVES)
Block(-1,27,-3,LEAVES)
Block(0,27,-3,LEAVES)
Block(1,27,-3,LEAVES)
Block(2,27,-3,LEAVES)
Block(3,27,-3,LEAVES)
Block(4,27,-3,LEAVES)
Block(5,27,-3,LEAVES)
Block(6,27,-3,LEAVES)
Block(7,27,-3,LEAVES)
Block(8,27,-3,LEAVES)
Block(9,27,-3,LEAVES)
Block(10,27,-3,LEAVES)
Block(11,27,-3,LOG:3)
Block(12,27,-3,LEAVES)
Block(13,27,-3,LEAVES)
Block(-6,27,-2,LEAVES)
Block(-5,27,-2,LEAVES)
Block(-4,27,-2,LEAVES)
Block(-3,27,-2,LEAVES)
Block(-2,27,-2,LEAVES)
Block(-1,27,-2,LEAVES)
Block(0,27,-2,LEAVES)
Block(1,27,-2,LEAVES)
Block(2,27,-2,LEAVES)
Block(3,27,-2,LEAVES)
Block(4,27,-2,LEAVES)
Block(6,27,-2,LEAVES)
Block(7,27,-2,LEAVES)
Block(8,27,-2,LEAVES)
Block(9,27,-2,LEAVES)
Block(10,27,-2,LOG:3)
Block(11,27,-2,LOG:3)
Block(12,27,-2,LEAVES)
Block(13,27,-2,LEAVES)
Block(-6,27,-1,LEAVES)
Block(-5,27,-1,LEAVES)
Block(-4,27,-1,LEAVES)
Block(-3,27,-1,LEAVES)
Block(-2,27,-1,LEAVES)
Block(-1,27,-1,LEAVES)
Block(0,27,-1,LEAVES)
Block(1,27,-1,LEAVES)
Block(2,27,-1,LEAVES)
Block(3,27,-1,LEAVES)
Block(4,27,-1,LEAVES)
Block(5,27,-1,LEAVES)
Block(6,27,-1,LEAVES)
Block(7,27,-1,LEAVES)
Block(8,27,-1,LEAVES)
Block(9,27,-1,LEAVES)
Block(10,27,-1,LEAVES)
Block(11,27,-1,LEAVES)
Block(12,27,-1,LEAVES)
Block(-7,27,0,LEAVES)
Block(-6,27,0,LEAVES)
Block(-5,27,0,LOG:3)
Block(-4,27,0,LEAVES)
Block(-3,27,0,LEAVES)
Block(-2,27,0,LEAVES)
Block(-1,27,0,LEAVES)
Block(0,27,0,LEAVES)
Block(1,27,0,LEAVES)
Block(2,27,0,LEAVES)
Block(3,27,0,LEAVES)
Block(4,27,0,LEAVES)
Block(5,27,0,LEAVES)
Block(6,27,0,LEAVES)
Block(7,27,0,LEAVES)
Block(8,27,0,LEAVES)
Block(9,27,0,LEAVES)
Block(10,27,0,LEAVES)
Block(11,27,0,LEAVES)
Block(-7,27,1,LEAVES)
Block(-6,27,1,LEAVES)
Block(-5,27,1,LEAVES)
Block(-4,27,1,LEAVES)
Block(-2,27,1,LEAVES)
Block(2,27,1,LEAVES)
Block(3,27,1,LEAVES)
Block(4,27,1,LEAVES)
Block(5,27,1,LEAVES)
Block(6,27,1,LEAVES)
Block(10,27,1,LEAVES)
Block(-6,27,2,LEAVES)
Block(-2,27,2,LEAVES)
Block(3,27,2,LEAVES)
Block(4,27,2,LEAVES)
Block(5,27,2,LEAVES)
Block(6,27,2,LEAVES)
Block(4,27,3,LEAVES)
Block(5,27,3,LEAVES)
Block(5,27,4,LEAVES)
Block(6,27,4,LEAVES)
Block(7,27,6,VINE:4)
Block(6,27,6,VINE:4)
Block(8,27,5,VINE:2)
Block(6,27,5,VINE:4)
Block(5,27,5,VINE:4)
Block(8,27,4,VINE:2)
Block(7,27,4,VINE:2)
Block(6,27,3,VINE:4)
Block(-5,27,3,VINE:4)
Block(-6,27,3,VINE:4)
Block(-7,27,3,VINE:4)
Block(-8,27,3,VINE:4)
Block(10,27,2,VINE:4)
Block(7,27,2,VINE:2)
Block(-4,27,2,VINE:4)
Block(-5,27,2,VINE:4)
Block(-7,27,2,VINE:4)
Block(-9,27,2,VINE:8)
Block(11,27,1,VINE:4)
Block(8,27,1,VINE:4)
Block(7,27,1,VINE:2)
Block(-1,27,1,VINE:4)
Block(-8,27,1,VINE:8)
Block(-9,27,1,VINE:8)
Block(13,27,0,VINE:4)
Block(12,27,0,VINE:4)
Block(-8,27,0,VINE:8)
Block(14,27,-1,VINE:2)
Block(13,27,-1,VINE:2)
Block(-7,27,-1,VINE)
Block(15,27,-2,VINE:2)
Block(15,27,-3,VINE:2)
Block(15,27,-4,VINE:2)
Block(14,27,-5,VINE:1)
Block(13,27,-5,VINE:1)
Block(12,27,-5,VINE:1)
Block(10,27,-5,VINE:1)
Block(9,27,-5,VINE:1)
Block(8,27,-5,VINE:2)
Block(11,27,-6,VINE:1)
Block(6,27,-7,VINE:4)
Block(8,27,-8,VINE:2)
Block(-7,27,-8,VINE:8)
Block(9,27,-9,VINE:2)
Block(-2,27,-9,VINE:1)
Block(9,27,-10,VINE:2)
Block(3,27,-10,VINE:1)
Block(-4,27,-10,VINE:1)
Block(-6,27,-10,VINE:1)
Block(9,27,-11,VINE:2)
Block(5,27,-11,VINE:1)
Block(1,27,-11,VINE:1)
Block(0,27,-11,VINE:1)
Block(-1,27,-11,VINE:1)
Block(-5,27,-11,VINE:1)
Block(-6,27,-11,VINE:1)
Block(-7,27,-11,VINE:1)
Block(9,27,-12,VINE:2)
Block(8,27,-12,VINE:1)
Block(6,27,-12,VINE:1)
Block(8,27,-13,VINE:1)
Block(7,27,-13,VINE:1)
Block(8,28,-12,LEAVES)
Block(7,28,-11,LEAVES)
Block(-7,28,-10,LEAVES)
Block(-6,28,-10,LEAVES)
Block(-5,28,-10,LEAVES)
Block(5,28,-10,LEAVES)
Block(6,28,-10,LEAVES)
Block(7,28,-10,LEAVES)
Block(-8,28,-9,LEAVES)
Block(-7,28,-9,LEAVES)
Block(-6,28,-9,LEAVES)
Block(-5,28,-9,LEAVES)
Block(0,28,-9,LEAVES)
Block(4,28,-9,LEAVES)
Block(5,28,-9,LEAVES)
Block(6,28,-9,LEAVES)
Block(-7,28,-8,LEAVES)
Block(-6,28,-8,LEAVES)
Block(-5,28,-8,LEAVES)
Block(-4,28,-8,LEAVES)
Block(-1,28,-8,LEAVES)
Block(0,28,-8,LEAVES)
Block(1,28,-8,LEAVES)
Block(4,28,-8,LEAVES)
Block(-5,28,-7,LEAVES)
Block(-4,28,-7,LEAVES)
Block(1,28,-7,LEAVES)
Block(2,28,-7,LEAVES)
Block(3,28,-7,LEAVES)
Block(4,28,-7,LEAVES)
Block(-3,28,-6,LEAVES)
Block(-2,28,-6,LEAVES)
Block(-1,28,-6,LEAVES)
Block(0,28,-6,LEAVES)
Block(1,28,-6,LEAVES)
Block(2,28,-6,LEAVES)
Block(3,28,-6,LEAVES)
Block(5,28,-6,LEAVES)
Block(6,28,-6,LEAVES)
Block(-1,28,-5,LEAVES)
Block(0,28,-5,LEAVES)
Block(1,28,-5,LEAVES)
Block(2,28,-5,LEAVES)
Block(3,28,-5,LEAVES)
Block(11,28,-5,LEAVES)
Block(-4,28,-4,LEAVES)
Block(-2,28,-4,LEAVES)
Block(-1,28,-4,LEAVES)
Block(0,28,-4,LEAVES)
Block(1,28,-4,LEAVES)
Block(2,28,-4,LEAVES)
Block(3,28,-4,LEAVES)
Block(4,28,-4,LEAVES)
Block(8,28,-4,LEAVES)
Block(11,28,-4,LEAVES)
Block(12,28,-4,LEAVES)
Block(13,28,-4,LEAVES)
Block(14,28,-4,LEAVES)
Block(-5,28,-3,LEAVES)
Block(-4,28,-3,LEAVES)
Block(-3,28,-3,LEAVES)
Block(-2,28,-3,LEAVES)
Block(-1,28,-3,LEAVES)
Block(0,28,-3,LEAVES)
Block(1,28,-3,LEAVES)
Block(2,28,-3,LEAVES)
Block(3,28,-3,LEAVES)
Block(7,28,-3,LEAVES)
Block(10,28,-3,LEAVES)
Block(11,28,-3,LEAVES)
Block(12,28,-3,LEAVES)
Block(13,28,-3,LEAVES)
Block(14,28,-3,LEAVES)
Block(-4,28,-2,LEAVES)
Block(-3,28,-2,LEAVES)
Block(-2,28,-2,LEAVES)
Block(-1,28,-2,LEAVES)
Block(0,28,-2,LEAVES)
Block(1,28,-2,LEAVES)
Block(2,28,-2,LEAVES)
Block(3,28,-2,LEAVES)
Block(6,28,-2,LEAVES)
Block(8,28,-2,LEAVES)
Block(9,28,-2,LEAVES)
Block(10,28,-2,LEAVES)
Block(11,28,-2,LEAVES)
Block(12,28,-2,LEAVES)
Block(13,28,-2,LEAVES)
Block(14,28,-2,LEAVES)
Block(-5,28,-1,LEAVES)
Block(-4,28,-1,LEAVES)
Block(-2,28,-1,LEAVES)
Block(-1,28,-1,LEAVES)
Block(0,28,-1,LEAVES)
Block(2,28,-1,LEAVES)
Block(3,28,-1,LEAVES)
Block(7,28,-1,LEAVES)
Block(9,28,-1,LEAVES)
Block(10,28,-1,LEAVES)
Block(11,28,-1,LEAVES)
Block(13,28,-1,LEAVES)
Block(-7,28,0,LEAVES)
Block(-6,28,0,LEAVES)
Block(-5,28,0,LEAVES)
Block(-4,28,0,LEAVES)
Block(-3,28,0,LEAVES)
Block(5,28,0,LEAVES)
Block(-8,28,1,LEAVES)
Block(-7,28,1,LEAVES)
Block(-6,28,1,LEAVES)
Block(-5,28,1,LEAVES)
Block(-4,28,1,LEAVES)
Block(4,28,1,LEAVES)
Block(5,28,1,LEAVES)
Block(-8,28,2,LEAVES)
Block(-7,28,2,LEAVES)
Block(-6,28,2,LEAVES)
Block(-5,28,2,LEAVES)
Block(4,28,2,LEAVES)
Block(4,28,3,LEAVES)
Block(5,28,3,LEAVES)
Block(5,28,4,LEAVES)
Block(6,28,4,LEAVES)
Block(7,28,4,LEAVES)
Block(6,28,5,LEAVES)
Block(7,28,5,LEAVES)
Block(7,28,6,VINE:4)
Block(6,28,6,VINE:4)
Block(8,28,5,VINE:2)
Block(8,28,4,VINE:2)
Block(-5,28,3,VINE:4)
Block(-6,28,3,VINE:4)
Block(-7,28,3,VINE:4)
Block(-8,28,3,VINE:4)
Block(-4,28,2,VINE:4)
Block(-9,28,2,VINE:8)
Block(-9,28,1,VINE:8)
Block(13,28,0,VINE:4)
Block(11,28,0,VINE:4)
Block(-1,28,0,VINE:4)
Block(-8,28,0,VINE:1)
Block(14,28,-1,VINE:2)
Block(12,28,-1,VINE:2)
Block(8,28,-1,VINE:2)
Block(-7,28,-1,VINE:1)
Block(15,28,-2,VINE:2)
Block(7,28,-2,VINE:2)
Block(15,28,-3,VINE:2)
Block(9,28,-3,VINE:1)
Block(15,28,-4,VINE:2)
Block(10,28,-4,VINE:1)
Block(9,28,-4,VINE:2)
Block(14,28,-5,VINE:1)
Block(13,28,-5,VINE:1)
Block(12,28,-5,VINE:1)
Block(11,28,-6,VINE:1)
Block(-1,28,-7,VINE:1)
Block(0,28,-10,VINE:1)
Block(-8,28,-10,VINE:1)
Block(6,28,-11,VINE:8)
Block(5,28,-11,VINE:1)
Block(-5,28,-11,VINE:1)
Block(-6,28,-11,VINE:1)
Block(-7,28,-11,VINE:1)
Block(9,28,-12,VINE:2)
Block(8,28,-13,VINE:1)
Block(8,29,-12,LEAVES)
Block(7,29,-11,LEAVES)
Block(-7,29,-9,LEAVES)
Block(-6,29,-9,LEAVES)
Block(-4,29,-7,LEAVES)
Block(-2,29,-6,LEAVES)
Block(0,29,-5,LEAVES)
Block(1,29,-5,LEAVES)
Block(12,29,-5,LEAVES)
Block(-1,29,-4,LEAVES)
Block(0,29,-4,LEAVES)
Block(1,29,-4,LEAVES)
Block(2,29,-4,LEAVES)
Block(11,29,-4,LEAVES)
Block(12,29,-4,LEAVES)
Block(13,29,-4,LEAVES)
Block(14,29,-4,LEAVES)
Block(-2,29,-3,LEAVES)
Block(-1,29,-3,LEAVES)
Block(0,29,-3,LEAVES)
Block(1,29,-3,LEAVES)
Block(11,29,-3,LEAVES)
Block(12,29,-3,LEAVES)
Block(13,29,-3,LEAVES)
Block(-2,29,-2,LEAVES)
Block(-1,29,-2,LEAVES)
Block(9,29,-2,LEAVES)
Block(10,29,-2,LEAVES)
Block(11,29,-2,LEAVES)
Block(12,29,-2,LEAVES)
Block(13,29,-2,LEAVES)
Block(11,29,-1,LEAVES)
Block(-8,29,1,LEAVES)
Block(-7,29,1,LEAVES)
Block(-5,29,1,LEAVES)
Block(-7,29,2,LEAVES)
Block(7,29,5,LEAVES)
Block(7,29,6,VINE:4)
Block(-7,29,3,VINE:4)
Block(11,29,0,VINE:4)
Block(12,29,-1,VINE:2)
Block(10,29,-3,VINE:1)
Block(9,29,-3,VINE:1)
Block(15,29,-4,VINE:2)
Block(14,29,-5,VINE:1)
Block(13,29,-5,VINE:1)
Block(9,29,-12,VINE:2)
Block(7,29,-12,VINE:1)
Block(8,29,-13,VINE:1)
Block(0,30,-4,LEAVES)
Block(1,30,-4,LEAVES)
Block(-1,30,-3,LEAVES)
Block(0,30,-3,LEAVES)
Block(11,30,-1,LEAVES)
Block(11,30,0,VINE:4)
Block(12,30,-1,VINE:2)
Block(1,30,-3,VINE:4)
Block(2,30,-4,VINE:2)
Block(1,30,-5,VINE:1)
Block(0,30,-5,VINE:1)

#######################################################################
# +-----------------------------------------------------------------+ #
# |                            BO3 checks                           | #
# +-----------------------------------------------------------------+ #
#######################################################################

# Require a condition at a certain location in order for the BO3 to be spawned.
# BlockCheck(x,y,z,BlockName[,BlockName[,...]]) - one of the blocks must be at the location
# BlockCheckNot(x,y,z,BlockName[,BlockName[,...]]) - all the blocks must not be at the location
# LightCheck(x,y,z,minLightLevel,maxLightLevel) - light must be between min and max (inclusive)

# You can use "Solid" as a BlockName for matching all solid blocks or "All" to match all blocks that aren't air.

# Examples:
BlockCheck(0,-1,0,GRASS,DIRT,DIRT:2,SAND,STONE,CLAY,GRAVEL)
#   BlockCheck(0,-1,0,Solid)       Require any solid block just below the object
#   BlockCheck(0,-1,0,WOOL)        Require any type of wool just below the object
#   BlockCheck(0,-1,0,WOOL:0)      Require white wool just below the object
#   BlockCheckNot(0,-1,0,WOOL:0)   Require that there is no white wool below the object
#   LightCheck(0,0,0,0,1)          Require almost complete darkness just below the object

#######################################################################
# +-----------------------------------------------------------------+ #
# |                             Branches                            | #
# +-----------------------------------------------------------------+ #
#######################################################################

# Branches are objects that will spawn when this object spawns when it is used in
# the CustomStructure resource. Branches can also have branches, making complex
# structures possible. See the wiki for more details.

# Regular Branches spawn each branch with an independent chance of spawning.
# Branch(x,y,z,branchName,rotation,chance[,anotherBranchName,rotation,chance[,...]][IndividualChance])
# branchName - name of the object to spawn.
# rotation - NORTH, SOUTH, EAST or WEST.
# IndividualChance - The chance each branch has to spawn, assumed to be 100 when left blank

# Weighted Branches spawn branches with a dependent chance of spawning.
# WeightedBranch(x,y,z,branchName,rotation,chance[,anotherBranchName,rotation,chance[,...]][MaxChanceOutOf])
# MaxChanceOutOf - The chance all branches have to spawn out of, assumed to be 100 when left blank

