#######################################################################
# +-----------------------------------------------------------------+ #
# |                            BO3 object                           | #
# +-----------------------------------------------------------------+ #
#######################################################################

# The descriptions in this file are accurate only for TerrainControl and OTG.
# For MCW and OTG+ these descriptions are only accurate if the BO3 is used as a CustomObject.
# MCW and OTG+ completely reimplemented CustomStructure, check the MCW/OTG+ documentation for more information.

# This is the config file of a custom object.
# If you add this object correctly to your BiomeConfigs, it will spawn in the world.

# This is the creator of this BO3 object
Author: Unknown

# A short description of this BO3 object
Description: This BO3 was converted from a schematic using OTGEdit. The author and description information of the schematic could not be found. If you know who the author of the schematic is then please add this information.

# The BO3 version, don't change this! It can be used by external applications to do a version check.
Version: 3

# The settings mode, WriteAll, WriteWithoutComments or WriteDisable. See WorldConfig.
SettingsMode: WriteDisable

#######################################################################
# +-----------------------------------------------------------------+ #
# |                          Main settings                          | #
# +-----------------------------------------------------------------+ #
#######################################################################

# This needs to be set to true to spawn the object in the Tree and Sapling resources.
Tree: true

# The frequency of the BO3 from 1 to 200. Tries this many times to spawn this BO3 when using the CustomObject(...) resource.
# Ignored by Tree(..), Sapling(..) and CustomStructure(..)
Frequency: 40

# The rarity of the BO3 from 0 to 100. Each spawn attempt has rarity% chance to succeed when using the CustomObject(...) resource.
# Ignored by Tree(..), Sapling(..) and CustomStructure(..)
Rarity: 100.0

# If you set this to true, the BO3 will be placed with a random rotation.
RotateRandomly: true

# The spawn height of the BO3 - randomY, highestBlock or highestSolidBlock.
SpawnHeight: highestSolidBlock

# The height limits for the BO3.
MinHeight: 0

MaxHeight: 68

# Objects can have other objects attached to it: branches. Branches can also
# have branches attached to it, which can also have branches, etc. This is the
# maximum branch depth for this objects.
MaxBranchDepth: 10

# When spawned with the UseWorld keyword, this BO3 should NOT spawn in the following biomes.
# If you writer.write the BO3 name directly in the BiomeConfigs, this will be ignored.
ExcludedBiomes: All

# To optimise this BO3 for faster loading times you can use Notepad++ to find/replace comments and abbreviate things.
# Notepad++ find/replace with regex:
# Find: ^[#;].* replace to nothing removes all lines starting with # 
# Find: ^\s*$ replace to nothing removes most empty lines 
# Notepad++ find/replace without regex:
# *Warning: This will only work for OTG 1.10.2 v21 / OTG 1.11.2 v6 or higher. B( is not recognised by lower versions.
# Find: Block( replace to B(

#######################################################################
# +-----------------------------------------------------------------+ #
# |                      Source block settings                      | #
# +-----------------------------------------------------------------+ #
#######################################################################

# The block(s) the BO3 should spawn in.
SourceBlocks: AIR

# The maximum percentage of the BO3 that can be outside the SourceBlock.
# The BO3 won't be placed on a location with more blocks outside the SourceBlock than this percentage.
MaxPercentageOutsideSourceBlock: 0

# What to do when a block is about to be placed outside the SourceBlock? (dontPlace, placeAnyway)
OutsideSourceBlock: dontPlace

#######################################################################
# +-----------------------------------------------------------------+ #
# |                              Blocks                             | #
# +-----------------------------------------------------------------+ #
#######################################################################

# All the blocks used in the BO3 are listed here. Possible blocks:
# Block(x,y,z,id[.data][,nbtfile.nbt) or B(x,y,z,id[.data][,nbtfile.nbt)
# RandomBlock(x,y,z,id[:data][,nbtfile.nbt],chance[,id[:data][,nbtfile.nbt],chance[,...]])
# So RandomBlock(0,0,0,CHEST,chest.nbt,50,CHEST,anotherchest.nbt,100) will spawn a chest at
# the BO3 origin, and give it a 50% chance to have the contents of chest.nbt, or, if that
# fails, a 100% percent chance to have the contents of anotherchest.nbt.

Block(-9,15,-2,18:3)
Block(-9,17,-3,18:3)
Block(-9,17,-2,18:3)
Block(-8,13,-3,18:3)
Block(-8,14,-2,18:3)
Block(-8,15,-3,18:3)
Block(-8,15,-2,18:3)
Block(-8,16,-4,18:3)
Block(-8,16,-3,18:3)
Block(-8,16,-2,18:3)
Block(-8,17,-3,18:3)
Block(-8,17,-2,18:3)
Block(-8,22,2,18:3)
Block(-8,24,1,18:3)
Block(-8,24,2,18:3)
Block(-8,25,1,18:3)
Block(-7,13,-3,18:3)
Block(-7,14,-4,18:3)
Block(-7,14,-3,18:3)
Block(-7,15,-5,18:3)
Block(-7,15,-4,18:3)
Block(-7,15,-3,18:3)
Block(-7,15,-1,18:3)
Block(-7,16,-5,18:3)
Block(-7,16,-3,18:3)
Block(-7,16,-2,18:3)
Block(-7,16,1,18:3)
Block(-7,17,-3,18:3)
Block(-7,17,-2,18:3)
Block(-7,17,0,18:3)
Block(-7,22,3,18:3)
Block(-7,23,0,18:3)
Block(-7,23,3,18:3)
Block(-7,24,1,18:3)
Block(-7,25,0,18:3)
Block(-6,13,-3,18:3)
Block(-6,14,-4,18:3)
Block(-6,14,-3,18:3)
Block(-6,14,-2,18:3)
Block(-6,15,-5,18:3)
Block(-6,15,-4,18:3)
Block(-6,15,-3,18:3)
Block(-6,15,-1,18:3)
Block(-6,15,1,18:3)
Block(-6,16,-5,18:3)
Block(-6,16,-4,18:3)
Block(-6,16,-3,18:3)
Block(-6,16,-2,18:3)
Block(-6,16,-1,18:3)
Block(-6,16,5,18:3)
Block(-6,16,6,18:3)
Block(-6,17,-4,18:3)
Block(-6,17,-3,18:3)
Block(-6,17,-2,18:3)
Block(-6,17,6,18:3)
Block(-6,18,-5,18:3)
Block(-6,18,-4,18:3)
Block(-6,18,-1,18:3)
Block(-6,18,2,18:3)
Block(-6,18,3,18:3)
Block(-6,21,1,18:3)
Block(-6,22,0,18:3)
Block(-6,22,2,18:3)
Block(-6,23,2,18:3)
Block(-6,24,-1,18:3)
Block(-6,24,0,18:3)
Block(-6,24,1,18:3)
Block(-6,24,2,18:3)
Block(-6,24,5,18:3)
Block(-6,25,1,18:3)
Block(-6,25,2,18:3)
Block(-6,25,4,18:3)
Block(-5,14,-4,18:3)
Block(-5,14,-3,18:3)
Block(-5,14,-2,18:3)
Block(-5,14,0,18:3)
Block(-5,14,6,18:3)
Block(-5,15,-4,18:3)
Block(-5,15,-3,18:3)
Block(-5,15,-2,18:3)
Block(-5,15,-1,17:7)
Block(-5,15,4,18:3)
Block(-5,16,-4,18:3)
Block(-5,16,-2,17:3)
Block(-5,16,0,18:3)
Block(-5,16,4,18:3)
Block(-5,16,5,18:3)
Block(-5,17,-6,18:3)
Block(-5,17,-4,18:3)
Block(-5,17,-3,18:3)
Block(-5,17,-2,18:3)
Block(-5,17,3,18:3)
Block(-5,17,5,18:3)
Block(-5,18,-4,18:3)
Block(-5,18,-2,18:3)
Block(-5,18,3,18:3)
Block(-5,18,5,18:3)
Block(-5,18,6,18:3)
Block(-5,19,3,18:3)
Block(-5,19,4,18:3)
Block(-5,22,0,18:3)
Block(-5,22,3,18:3)
Block(-5,22,4,18:3)
Block(-5,23,-1,18:3)
Block(-5,23,0,18:3)
Block(-5,23,1,18:3)
Block(-5,23,2,17:7)
Block(-5,23,4,18:3)
Block(-5,23,5,18:3)
Block(-5,24,-1,18:3)
Block(-5,24,1,18:3)
Block(-5,24,2,18:3)
Block(-5,24,3,17:3)
Block(-5,24,4,18:3)
Block(-5,25,1,18:3)
Block(-5,25,3,18:3)
Block(-4,13,0,18:3)
Block(-4,13,1,17:7)
Block(-4,14,0,17:11)
Block(-4,14,1,17:3)
Block(-4,14,6,18:3)
Block(-4,15,-1,17:11)
Block(-4,15,0,17:3)
Block(-4,15,2,18:3)
Block(-4,15,7,18:3)
Block(-4,16,-3,18:3)
Block(-4,16,-1,18:3)
Block(-4,16,0,18:3)
Block(-4,16,2,18:3)
Block(-4,16,3,18:3)
Block(-4,16,4,18:3)
Block(-4,16,5,18:3)
Block(-4,17,-3,18:3)
Block(-4,17,-2,18:3)
Block(-4,17,0,18:3)
Block(-4,17,1,18:3)
Block(-4,17,2,18:3)
Block(-4,17,3,18:3)
Block(-4,17,4,18:3)
Block(-4,17,5,18:3)
Block(-4,18,-2,18:3)
Block(-4,18,1,18:3)
Block(-4,18,3,17:3)
Block(-4,18,6,18:3)
Block(-4,19,2,18:3)
Block(-4,19,3,18:3)
Block(-4,19,4,18:3)
Block(-4,20,2,18:3)
Block(-4,20,4,18:3)
Block(-4,21,3,18:3)
Block(-4,22,1,17:7)
Block(-4,22,3,18:3)
Block(-4,23,0,18:3)
Block(-4,23,1,17:3)
Block(-4,23,2,17:11)
Block(-4,24,-1,18:3)
Block(-4,24,0,18:3)
Block(-4,24,1,18:3)
Block(-4,24,2,18:3)
Block(-4,24,3,18:3)
Block(-4,25,0,18:3)
Block(-4,25,1,18:3)
Block(-4,25,3,18:3)
Block(-3,11,1,17:7)
Block(-3,12,1,17:3)
Block(-3,13,-1,18:3)
Block(-3,13,1,17:3)
Block(-3,13,2,17:11)
Block(-3,14,2,17:3)
Block(-3,15,-7,18:3)
Block(-3,15,-6,18:3)
Block(-3,15,-5,18:3)
Block(-3,15,-4,18:3)
Block(-3,15,0,18:3)
Block(-3,15,2,17:3)
Block(-3,15,3,17:11)
Block(-3,16,-4,18:3)
Block(-3,16,-2,18:3)
Block(-3,16,3,17:3)
Block(-3,16,5,18:3)
Block(-3,17,1,18:3)
Block(-3,17,3,17:3)
Block(-3,17,4,18:3)
Block(-3,17,7,18:3)
Block(-3,18,2,18:3)
Block(-3,18,3,18:3)
Block(-3,18,4,18:3)
Block(-3,18,5,18:3)
Block(-3,19,3,17:3)
Block(-3,20,2,18:3)
Block(-3,20,3,18:3)
Block(-3,22,0,18:3)
Block(-3,22,1,17:7)
Block(-3,23,0,18:3)
Block(-3,23,2,18:3)
Block(-3,23,4,18:3)
Block(-3,23,5,18:3)
Block(-3,23,6,18:3)
Block(-3,24,-1,18:3)
Block(-3,24,0,18:3)
Block(-3,24,2,18:3)
Block(-3,24,3,18:3)
Block(-3,24,6,18:3)
Block(-3,25,0,18:3)
Block(-3,25,4,18:3)
Block(-2,0,0,17:3)
Block(-2,0,1,17:11)
Block(-2,10,0,17:7)
Block(-2,10,1,17:11)
Block(-2,11,1,17:3)
Block(-2,13,-6,18:3)
Block(-2,13,-5,18:3)
Block(-2,14,-7,18:3)
Block(-2,14,0,18:3)
Block(-2,15,-5,18:3)
Block(-2,15,-1,18:3)
Block(-2,15,2,17:7)
Block(-2,16,3,18:3)
Block(-2,16,5,18:3)
Block(-2,17,-6,18:3)
Block(-2,17,-5,18:3)
Block(-2,17,2,18:3)
Block(-2,17,5,18:3)
Block(-2,17,6,18:3)
Block(-2,18,3,18:3)
Block(-2,18,7,18:3)
Block(-2,20,2,17:11)
Block(-2,20,3,17:7)
Block(-2,21,-1,18:3)
Block(-2,21,1,17:11)
Block(-2,21,2,17:3)
Block(-2,21,5,18:3)
Block(-2,22,0,18:3)
Block(-2,22,1,17:3)
Block(-2,22,4,18:3)
Block(-2,22,5,18:3)
Block(-2,23,-1,18:3)
Block(-2,23,0,18:3)
Block(-2,23,2,18:3)
Block(-2,23,6,18:3)
Block(-2,24,-1,18:3)
Block(-2,24,0,18:3)
Block(-2,24,1,18:3)
Block(-2,24,2,18:3)
Block(-2,25,0,18:3)
Block(-2,25,1,18:3)
Block(-2,25,2,18:3)
Block(-1,0,-1,17:3)
Block(-1,0,0,17:3)
Block(-1,0,1,17:3)
Block(-1,1,-1,17:3)
Block(-1,1,0,17:3)
Block(-1,1,1,17:3)
Block(-1,2,0,17:3)
Block(-1,3,0,17:3)
Block(-1,5,0,17:7)
Block(-1,6,0,17:3)
Block(-1,7,-1,17:11)
Block(-1,7,0,17:3)
Block(-1,8,-1,17:3)
Block(-1,9,-1,17:3)
Block(-1,9,0,17:11)
Block(-1,10,0,17:3)
Block(-1,13,-7,18:3)
Block(-1,14,-3,18:3)
Block(-1,15,-8,18:3)
Block(-1,15,-7,18:3)
Block(-1,15,-5,17:3)
Block(-1,15,-4,18:3)
Block(-1,15,2,17:7)
Block(-1,16,-7,18:3)
Block(-1,16,-6,18:3)
Block(-1,16,-5,18:3)
Block(-1,16,-3,18:3)
Block(-1,16,2,17:3)
Block(-1,16,3,18:3)
Block(-1,16,4,18:3)
Block(-1,17,-5,18:3)
Block(-1,17,1,18:3)
Block(-1,17,2,18:3)
Block(-1,17,3,18:3)
Block(-1,17,4,18:3)
Block(-1,17,6,18:3)
Block(-1,17,7,18:3)
Block(-1,18,2,18:3)
Block(-1,18,4,18:3)
Block(-1,18,5,18:3)
Block(-1,18,8,18:3)
Block(-1,20,2,18:3)
Block(-1,20,3,18:3)
Block(-1,21,0,18:3)
Block(-1,22,-7,18:3)
Block(-1,22,-6,18:3)
Block(-1,22,-2,18:3)
Block(-1,22,1,17:7)
Block(-1,22,2,18:3)
Block(-1,23,-6,18:3)
Block(-1,23,-5,18:3)
Block(-1,23,0,17:3)
Block(-1,23,4,18:3)
Block(-1,24,-2,18:3)
Block(-1,24,1,18:3)
Block(-1,24,2,18:3)
Block(-1,25,0,18:3)
Block(0,0,-2,17:3)
Block(0,0,-1,17:11)
Block(0,0,0,17:3)
Block(0,0,1,17:3)
Block(0,0,2,17:3)
Block(0,1,-1,17:11)
Block(0,1,0,17:3)
Block(0,1,1,17:3)
Block(0,2,-1,17:3)
Block(0,2,0,17:3)
Block(0,2,1,17:3)
Block(0,3,-1,17:3)
Block(0,3,0,17:3)
Block(0,3,1,17:3)
Block(0,4,0,17:3)
Block(0,5,0,17:3)
Block(0,7,2,18:3)
Block(0,7,4,18:3)
Block(0,8,3,18:3)
Block(0,9,-1,17:7)
Block(0,10,-1,17:7)
Block(0,11,-1,17:3)
Block(0,12,-1,17:3)
Block(0,13,-7,18:3)
Block(0,13,-4,18:3)
Block(0,14,-8,18:3)
Block(0,14,-4,17:11)
Block(0,14,-3,17:7)
Block(0,15,-6,18:3)
Block(0,15,-5,18:3)
Block(0,15,4,18:3)
Block(0,15,6,18:3)
Block(0,16,-4,18:3)
Block(0,16,2,17:7)
Block(0,16,3,17:7)
Block(0,16,4,18:3)
Block(0,16,8,18:3)
Block(0,17,2,18:3)
Block(0,17,3,18:3)
Block(0,17,4,18:3)
Block(0,17,5,18:3)
Block(0,17,6,18:3)
Block(0,17,7,18:3)
Block(0,18,2,18:3)
Block(0,18,4,18:3)
Block(0,18,6,18:3)
Block(0,19,4,18:3)
Block(0,19,6,18:3)
Block(0,20,-6,18:3)
Block(0,22,-8,18:3)
Block(0,22,-5,18:3)
Block(0,22,-4,18:3)
Block(0,22,0,18:3)
Block(0,23,-7,18:3)
Block(0,23,-6,18:3)
Block(0,23,0,18:3)
Block(0,23,1,18:3)
Block(0,24,-1,18:3)
Block(0,24,0,18:3)
Block(0,25,-1,18:3)
Block(1,0,-1,17:3)
Block(1,0,0,17:3)
Block(1,0,1,17:3)
Block(1,1,0,17:3)
Block(1,2,0,17:3)
Block(1,3,0,17:3)
Block(1,3,1,17:7)
Block(1,4,1,17:3)
Block(1,5,2,17:3)
Block(1,6,2,17:3)
Block(1,8,1,18:3)
Block(1,8,3,18:3)
Block(1,9,3,18:3)
Block(1,12,-1,17:7)
Block(1,13,-3,17:11)
Block(1,13,-2,17:7)
Block(1,13,-1,17:3)
Block(1,14,-8,18:3)
Block(1,14,-4,18:3)
Block(1,14,-3,17:3)
Block(1,15,-5,18:3)
Block(1,15,-4,18:3)
Block(1,15,4,18:3)
Block(1,16,-7,18:3)
Block(1,16,3,17:7)
Block(1,16,4,18:3)
Block(1,16,5,18:3)
Block(1,16,7,18:3)
Block(1,17,-7,18:3)
Block(1,17,-6,18:3)
Block(1,17,-5,18:3)
Block(1,17,2,18:3)
Block(1,17,3,18:3)
Block(1,17,4,17:3)
Block(1,17,6,18:3)
Block(1,17,8,18:3)
Block(1,18,-6,18:3)
Block(1,18,-5,18:3)
Block(1,18,-4,18:3)
Block(1,18,4,18:3)
Block(1,18,5,18:3)
Block(1,18,6,18:3)
Block(1,19,2,18:3)
Block(1,19,4,18:3)
Block(1,19,5,18:3)
Block(1,19,6,18:3)
Block(1,20,-9,18:3)
Block(1,20,-6,18:3)
Block(1,20,3,18:3)
Block(1,20,5,18:3)
Block(1,20,6,18:3)
Block(1,21,-6,18:3)
Block(1,21,-5,18:3)
Block(1,22,-9,18:3)
Block(1,22,-8,18:3)
Block(1,22,-7,18:3)
Block(1,22,-6,17:7)
Block(1,22,-4,18:3)
Block(1,22,0,18:3)
Block(1,23,-8,18:3)
Block(1,23,-7,18:3)
Block(1,23,-6,18:3)
Block(1,23,-5,18:3)
Block(1,24,-9,18:3)
Block(1,24,-7,18:3)
Block(1,24,-6,18:3)
Block(1,25,-5,18:3)
Block(2,6,2,18:3)
Block(2,7,0,18:3)
Block(2,7,1,17:11)
Block(2,7,2,17:3)
Block(2,8,-1,18:3)
Block(2,8,1,18:3)
Block(2,8,2,18:3)
Block(2,8,3,17:3)
Block(2,8,4,18:3)
Block(2,8,5,18:3)
Block(2,9,-2,18:3)
Block(2,9,0,18:3)
Block(2,9,1,18:3)
Block(2,9,2,18:3)
Block(2,9,5,18:3)
Block(2,10,0,18:3)
Block(2,10,2,18:3)
Block(2,10,3,18:3)
Block(2,13,-2,17:11)
Block(2,13,-1,17:7)
Block(2,14,-2,17:3)
Block(2,14,4,18:3)
Block(2,14,5,18:3)
Block(2,15,3,18:3)
Block(2,15,4,18:3)
Block(2,16,-6,18:3)
Block(2,16,2,18:3)
Block(2,16,4,18:3)
Block(2,16,5,18:3)
Block(2,16,7,18:3)
Block(2,17,-8,18:3)
Block(2,17,-5,18:3)
Block(2,17,2,18:3)
Block(2,17,3,18:3)
Block(2,17,4,18:3)
Block(2,17,6,18:3)
Block(2,18,-5,18:3)
Block(2,18,-4,18:3)
Block(2,18,2,18:3)
Block(2,18,4,18:3)
Block(2,18,5,18:3)
Block(2,18,6,18:3)
Block(2,19,-4,18:3)
Block(2,19,4,18:3)
Block(2,20,-6,18:3)
Block(2,21,-9,18:3)
Block(2,21,-8,18:3)
Block(2,21,-6,17:11)
Block(2,21,-5,17:7)
Block(2,22,-9,18:3)
Block(2,22,-8,18:3)
Block(2,22,-7,18:3)
Block(2,22,-6,18:3)
Block(2,22,-5,18:3)
Block(2,23,-9,18:3)
Block(2,23,-8,18:3)
Block(2,23,-7,18:3)
Block(2,23,-6,18:3)
Block(2,23,-5,18:3)
Block(2,24,-8,18:3)
Block(2,24,-7,18:3)
Block(2,24,-6,18:3)
Block(3,7,-1,18:3)
Block(3,7,1,17:7)
Block(3,8,0,17:3)
Block(3,8,1,18:3)
Block(3,8,2,18:3)
Block(3,9,3,18:3)
Block(3,10,0,18:3)
Block(3,10,4,18:3)
Block(3,14,-2,17:7)
Block(3,14,5,18:3)
Block(3,15,-7,18:3)
Block(3,15,-3,17:11)
Block(3,15,-2,17:3)
Block(3,16,-8,18:3)
Block(3,16,4,18:3)
Block(3,16,5,18:3)
Block(3,17,-7,18:3)
Block(3,17,-6,18:3)
Block(3,17,-4,17:11)
Block(3,17,-3,18:3)
Block(3,17,0,18:3)
Block(3,17,1,18:3)
Block(3,17,2,18:3)
Block(3,17,3,18:3)
Block(3,17,4,18:3)
Block(3,17,5,18:3)
Block(3,18,-6,18:3)
Block(3,18,-5,18:3)
Block(3,18,-4,17:3)
Block(3,18,-2,18:3)
Block(3,18,1,18:3)
Block(3,18,4,18:3)
Block(3,19,-6,18:3)
Block(3,19,-4,18:3)
Block(3,19,4,18:3)
Block(3,20,-7,18:3)
Block(3,20,-4,18:3)
Block(3,20,-3,18:3)
Block(3,21,-5,17:7)
Block(3,22,-9,18:3)
Block(3,22,-8,18:3)
Block(3,22,-7,18:3)
Block(3,22,-6,18:3)
Block(3,23,-8,18:3)
Block(3,23,-7,18:3)
Block(3,23,-5,18:3)
Block(3,23,-1,18:3)
Block(3,24,-6,18:3)
Block(3,24,-2,18:3)
Block(3,24,2,18:3)
Block(4,7,2,18:3)
Block(4,8,0,18:3)
Block(4,8,3,18:3)
Block(4,9,-1,18:3)
Block(4,9,3,18:3)
Block(4,9,4,18:3)
Block(4,10,0,18:3)
Block(4,15,-5,18:3)
Block(4,15,-1,17:7)
Block(4,15,0,17:11)
Block(4,15,1,18:3)
Block(4,16,-4,18:3)
Block(4,16,-3,17:3)
Block(4,16,0,17:3)
Block(4,16,1,18:3)
Block(4,16,2,18:3)
Block(4,16,3,18:3)
Block(4,16,5,18:3)
Block(4,17,-5,18:3)
Block(4,17,-3,17:3)
Block(4,17,0,18:3)
Block(4,17,1,18:3)
Block(4,17,2,18:3)
Block(4,17,3,18:3)
Block(4,17,4,18:3)
Block(4,17,5,18:3)
Block(4,18,-6,18:3)
Block(4,18,-5,18:3)
Block(4,18,-3,18:3)
Block(4,18,1,18:3)
Block(4,18,2,18:3)
Block(4,19,-6,17:3)
Block(4,19,-5,17:3)
Block(4,19,-3,18:3)
Block(4,19,1,18:3)
Block(4,20,-5,17:3)
Block(4,20,-4,18:3)
Block(4,21,-5,17:3)
Block(4,22,-9,18:3)
Block(4,22,-7,18:3)
Block(4,22,-5,17:3)
Block(4,22,-4,17:11)
Block(4,23,-3,18:3)
Block(4,23,-2,18:3)
Block(4,23,-1,18:3)
Block(4,24,-2,18:3)
Block(4,24,-1,18:3)
Block(4,24,1,18:3)
Block(4,24,2,18:3)
Block(4,25,-3,18:3)
Block(4,25,-2,18:3)
Block(4,25,-1,18:3)
Block(4,26,2,18:3)
Block(5,8,2,18:3)
Block(5,9,-2,18:3)
Block(5,10,1,18:3)
Block(5,14,3,18:3)
Block(5,14,4,18:3)
Block(5,15,-1,18:3)
Block(5,15,0,18:3)
Block(5,15,1,18:3)
Block(5,15,2,18:3)
Block(5,15,3,18:3)
Block(5,15,4,18:3)
Block(5,16,-5,18:3)
Block(5,16,0,17:7)
Block(5,16,1,18:3)
Block(5,16,2,18:3)
Block(5,16,4,18:3)
Block(5,16,6,18:3)
Block(5,17,-7,18:3)
Block(5,17,-6,18:3)
Block(5,17,-5,18:3)
Block(5,17,-1,18:3)
Block(5,17,0,18:3)
Block(5,17,1,17:3)
Block(5,17,2,18:3)
Block(5,17,3,18:3)
Block(5,17,4,18:3)
Block(5,17,5,18:3)
Block(5,17,6,18:3)
Block(5,18,-7,18:3)
Block(5,18,-6,18:3)
Block(5,18,-5,18:3)
Block(5,18,-4,18:3)
Block(5,18,0,18:3)
Block(5,18,2,18:3)
Block(5,18,3,18:3)
Block(5,18,4,18:3)
Block(5,18,5,18:3)
Block(5,19,-6,18:3)
Block(5,19,-5,18:3)
Block(5,19,1,18:3)
Block(5,19,2,18:3)
Block(5,19,3,18:3)
Block(5,19,4,18:3)
Block(5,20,-5,18:3)
Block(5,20,-4,18:3)
Block(5,22,-4,17:7)
Block(5,23,-4,17:3)
Block(5,23,-3,17:11)
Block(5,23,-1,18:3)
Block(5,23,0,18:3)
Block(5,24,-3,18:3)
Block(5,24,-1,18:3)
Block(5,24,1,18:3)
Block(5,25,-3,18:3)
Block(5,25,0,18:3)
Block(5,25,1,18:3)
Block(5,26,-2,18:3)
Block(5,26,-1,18:3)
Block(5,26,0,18:3)
Block(5,26,1,18:3)
Block(6,8,0,18:3)
Block(6,9,0,18:3)
Block(6,15,1,18:3)
Block(6,15,2,18:3)
Block(6,15,4,18:3)
Block(6,16,-4,18:3)
Block(6,16,0,18:3)
Block(6,16,2,18:3)
Block(6,16,3,18:3)
Block(6,16,4,18:3)
Block(6,17,-1,18:3)
Block(6,17,0,18:3)
Block(6,17,1,18:3)
Block(6,17,2,18:3)
Block(6,17,4,18:3)
Block(6,18,-7,18:3)
Block(6,18,-5,18:3)
Block(6,18,-4,18:3)
Block(6,18,1,18:3)
Block(6,18,2,18:3)
Block(6,18,3,18:3)
Block(6,18,4,18:3)
Block(6,18,5,18:3)
Block(6,19,-5,18:3)
Block(6,19,-4,18:3)
Block(6,19,0,18:3)
Block(6,19,2,18:3)
Block(6,19,3,18:3)
Block(6,20,-5,18:3)
Block(6,21,-4,18:3)
Block(6,22,1,18:3)
Block(6,23,-3,17:7)
Block(6,23,-2,18:3)
Block(6,23,-1,18:3)
Block(6,24,-2,17:3)
Block(6,24,-1,18:3)
Block(6,24,0,18:3)
Block(6,24,1,18:3)
Block(6,24,2,18:3)
Block(6,24,3,18:3)
Block(6,25,-4,18:3)
Block(6,25,-3,18:3)
Block(6,25,-2,18:3)
Block(6,25,-1,18:3)
Block(6,25,0,18:3)
Block(6,25,1,18:3)
Block(6,26,-2,18:3)
Block(6,26,-1,18:3)
Block(7,14,0,18:3)
Block(7,15,2,18:3)
Block(7,15,4,18:3)
Block(7,15,5,18:3)
Block(7,16,0,18:3)
Block(7,16,1,18:3)
Block(7,16,2,18:3)
Block(7,16,3,18:3)
Block(7,17,-6,18:3)
Block(7,17,-5,18:3)
Block(7,17,-4,18:3)
Block(7,17,-2,18:3)
Block(7,17,-1,18:3)
Block(7,17,0,18:3)
Block(7,17,1,18:3)
Block(7,18,-5,18:3)
Block(7,18,0,18:3)
Block(7,18,1,18:3)
Block(7,18,2,18:3)
Block(7,18,3,18:3)
Block(7,19,-6,18:3)
Block(7,19,1,18:3)
Block(7,22,-1,18:3)
Block(7,23,-2,18:3)
Block(7,23,-1,18:3)
Block(7,23,1,18:3)
Block(7,24,-4,18:3)
Block(7,24,-3,18:3)
Block(7,24,-2,18:3)
Block(7,24,-1,18:3)
Block(7,24,0,18:3)
Block(7,25,-3,18:3)
Block(7,25,-2,18:3)
Block(7,25,-1,18:3)
Block(7,25,0,18:3)
Block(7,26,0,18:3)
Block(8,15,-1,18:3)
Block(8,16,0,18:3)
Block(8,16,2,18:3)
Block(8,17,-1,18:3)
Block(8,17,0,18:3)
Block(8,18,-1,18:3)
Block(8,18,0,18:3)
Block(8,22,0,18:3)
Block(8,23,-4,18:3)
Block(8,24,-4,18:3)
Block(8,24,-3,18:3)
Block(8,24,-2,18:3)
Block(8,24,-1,18:3)
Block(8,25,-1,18:3)
Block(8,26,0,18:3)
Block(8,27,-1,18:3)
Block(9,15,3,18:3)
Block(9,23,-2,18:3)
Block(9,24,-2,18:3)
Block(9,24,-1,18:3)
Block(9,24,0,18:3)
Block(9,25,-2,18:3)
Block(9,25,0,18:3)


#######################################################################
# +-----------------------------------------------------------------+ #
# |                             Entities                            | #
# +-----------------------------------------------------------------+ #
#######################################################################

# Entity() spawns an entity instead of a block. The entity is spawned only once when the BO3 is spawned.
# Entities are persistent by default so they don't de-spawn when no player is near, they are only unloaded.
# Usage: Entity(x,y,z,mobName,groupSize,NameTagOrNBTFileName) or Entity(x,y,z,mobName,groupSize)
# Use /tc entities or /otg entities to get a list of entities that can be used as mobName, this includes entities added by other mods.
# NameTagOrNBTFileName can be either a nametag for the mob or an nbt file (such as mymobinfo.nbt or mymobinfo.txt).
# When using a text file you can use the same mob spawning parameters used with the /summon command to equip the
# entity and give it custom attributes etc. You can copy the DATA part of a summon command including surrounding
# curly braces to a .txt file, for instance for: "/summon Skeleton x y z {DATA}"

#######################################################################
# +-----------------------------------------------------------------+ #
# |                            BO3 checks                           | #
# +-----------------------------------------------------------------+ #
#######################################################################

# Require a condition at a certain location in order for the BO3 to be spawned.
# BlockCheck(x,y,z,BlockName[,BlockName[,...]]) - one of the blocks must be at the location
# BlockCheckNot(x,y,z,BlockName[,BlockName[,...]]) - all the blocks must not be at the location
# LightCheck(x,y,z,minLightLevel,maxLightLevel) - light must be between min and max (inclusive)

# You can use "Solid" as a BlockName for matching all solid blocks or "All" to match all blocks that aren't air.

# Examples:
BlockCheck(0,-1,0,GRASS,DIRT,DIRT:2,SAND)
#   BlockCheck(0,-1,0,Solid)       Require any solid block just below the object
#   BlockCheck(0,-1,0,WOOL)        Require any type of wool just below the object
#   BlockCheck(0,-1,0,WOOL:0)      Require white wool just below the object
#   BlockCheckNot(0,-1,0,WOOL:0)   Require that there is no white wool below the object
#   LightCheck(0,0,0,0,1)          Require almost complete darkness just below the object

