#######################################################################
# +-----------------------------------------------------------------+ #
# |                            BO3 object                           | #
# +-----------------------------------------------------------------+ #
#######################################################################

# This is the config file of a custom object.
# If you add this object correctly to your BiomeConfigs, it will spawn in the world.

# This is the creator of this BO3 object
Author: BO3 BulkEdit (by LanToaster)

# A short description of this BO3 object
Description: This Object was Created with BO3_BulkEdit

# The BO3 version, don't change this! It can be used by external applications to do a version check.
Version: 3

# The settings mode, WriteAll, WriteWithoutComments or WriteDisable. See WorldConfig.
SettingsMode: WriteDisable


#######################################################################
# +-----------------------------------------------------------------+ #
# |                          Main settings                          | #
# +-----------------------------------------------------------------+ #
#######################################################################

# This needs to be set to true to spawn the object in the Tree and Sapling resources.
Tree: true

# The frequency of the BO3 from 1 to 200. Tries this many times to spawn this BO3 when using the CustomObject(...) resource.
# Ignored by Tree(..), Sapling(..) and CustomStructure(..)
Frequency: 1

# The rarity of the BO3 from 0 to 100. Each spawn attempt has rarity% chance to succeed when using the CustomObject(...) resource.
# Ignored by Tree(..), Sapling(..) and CustomStructure(..)
Rarity: 100

# If you set this to true, the BO3 will be placed with a random rotation.
RotateRandomly: True

# The spawn height of the BO3 - randomY, highestBlock or highestSolidBlock.
SpawnHeight: highestSolidBlock

# The height limits for the BO3.
MinHeight: 0

MaxHeight: 80

# Objects can have other objects attacthed to it: branches. Branches can also
# have branches attached to it, which can also have branches, etc. This is the
# maximum branch depth for this objects.
MaxBranchDepth: 10

# When spawned with the UseWorld keyword, this BO3 should NOT spawn in the following biomes.
# If you writer.write the BO3 name directly in the BiomeConfigs, this will be ignored.
ExcludedBiomes: All


#######################################################################
# +-----------------------------------------------------------------+ #
# |                      Source block settings                      | #
# +-----------------------------------------------------------------+ #
#######################################################################

# The block(s) the BO3 should spawn in.
SourceBlocks: AIR

# The maximum percentage of the BO3 that can be outside the SourceBlock.
# The BO3 won't be placed on a location with more blocks outside the SourceBlock than this percentage.
MaxPercentageOutsideSourceBlock: 0

# What to do when a block is about to be placed outside the SourceBlock? (dontPlace, placeAnyway)
OutsideSourceBlock: dontPlace


#######################################################################
# +-----------------------------------------------------------------+ #
# |                              Blocks                             | #
# +-----------------------------------------------------------------+ #
#######################################################################

# All the blocks used in the BO3 are listed here. Possible blocks:
# Block(x,y,z,id[.data][,nbtfile.nbt)
# RandomBlock(x,y,z,id[:data][,nbtfile.nbt],chance[,id[:data][,nbtfile.nbt],chance[,...]])
# So RandomBlock(0,0,0,CHEST,chest.nbt,50,CHEST,anotherchest.nbt,100) will spawn a chest at
# the BO3 origin, and give it a 50% chance to have the contents of chest.nbt, or, if that
# fails, a 100% percent chance to have the contents of anotherchest.nbt.
Block(1,0,-1,LOG:13)
Block(-1,0,0,LOG:13)
Block(0,0,0,LOG:13)
Block(1,0,0,LOG:13)
Block(2,0,0,LOG:13)
Block(-2,0,1,LOG:13)
Block(-1,0,1,LOG:13)
Block(0,0,1,LOG:13)
Block(1,0,1,LOG:13)
Block(2,0,1,LOG:13)
Block(3,0,1,LOG:13)
Block(-3,0,2,LOG:13)
Block(-2,0,2,LOG:13)
Block(-1,0,2,LOG:13)
Block(0,0,2,LOG:13)
Block(1,0,2,LOG:13)
Block(2,0,2,LOG:13)
Block(-3,0,3,LOG:13)
Block(-2,0,3,LOG:13)
Block(-1,0,3,LOG:13)
Block(0,0,3,LOG:13)
Block(1,0,3,LOG:13)
Block(2,0,3,LOG:13)
Block(-3,0,4,LOG:13)
Block(-2,0,4,LOG:13)
Block(-1,0,4,LOG:13)
Block(0,0,4,LOG:13)
Block(1,0,4,LOG:13)
Block(-2,0,5,LOG:13)
Block(-1,0,5,LOG:13)
Block(0,0,5,LOG:13)
Block(1,0,5,LOG:13)
Block(-1,0,6,LOG:13)
Block(0,0,6,LOG:13)
Block(1,1,-1,LOG:13)
Block(0,1,0,LOG:13)
Block(1,1,0,LOG:13)
Block(2,1,0,LOG:13)
Block(-2,1,1,LOG:13)
Block(-1,1,1,LOG:13)
Block(0,1,1,LOG:13)
Block(1,1,1,LOG:13)
Block(2,1,1,LOG:13)
Block(3,1,1,LOG:13)
Block(-3,1,2,LOG:13)
Block(-2,1,2,LOG:13)
Block(-1,1,2,LOG:13)
Block(0,1,2,LOG:13)
Block(1,1,2,LOG:13)
Block(2,1,2,LOG:13)
Block(-3,1,3,LOG:13)
Block(-2,1,3,LOG:13)
Block(-1,1,3,LOG:13)
Block(0,1,3,LOG:13)
Block(1,1,3,LOG:13)
Block(2,1,3,LOG:13)
Block(-3,1,4,LOG:13)
Block(-2,1,4,LOG:13)
Block(-1,1,4,LOG:13)
Block(0,1,4,LOG:13)
Block(1,1,4,LOG:13)
Block(-2,1,5,LOG:13)
Block(-1,1,5,LOG:13)
Block(0,1,5,LOG:13)
Block(1,1,5,LOG:13)
Block(-1,1,6,LOG:13)
Block(0,1,6,LOG:13)
Block(1,2,-1,LOG:13)
Block(0,2,0,LOG:13)
Block(1,2,0,LOG:13)
Block(2,2,0,LOG:13)
Block(-2,2,1,LOG:13)
Block(-1,2,1,LOG:13)
Block(0,2,1,LOG:13)
Block(1,2,1,LOG:13)
Block(2,2,1,LOG:13)
Block(3,2,1,LOG:13)
Block(-3,2,2,LOG:13)
Block(-2,2,2,LOG:13)
Block(-1,2,2,LOG:13)
Block(0,2,2,LOG:13)
Block(1,2,2,LOG:13)
Block(2,2,2,LOG:13)
Block(-3,2,3,LOG:13)
Block(-2,2,3,LOG:13)
Block(-1,2,3,LOG:13)
Block(0,2,3,LOG:13)
Block(1,2,3,LOG:13)
Block(2,2,3,LOG:13)
Block(-3,2,4,LOG:13)
Block(-2,2,4,LOG:13)
Block(-1,2,4,LOG:13)
Block(0,2,4,LOG:13)
Block(1,2,4,LOG:13)
Block(-2,2,5,LOG:13)
Block(-1,2,5,LOG:13)
Block(0,2,5,LOG:13)
Block(1,2,5,LOG:13)
Block(-1,2,6,LOG:13)
Block(0,2,6,LOG:13)
Block(1,3,-1,LOG:13)
Block(0,3,0,LOG:13)
Block(1,3,0,LOG:13)
Block(2,3,0,LOG:13)
Block(-2,3,1,LOG:13)
Block(-1,3,1,LOG:13)
Block(0,3,1,LOG:13)
Block(1,3,1,LOG:13)
Block(2,3,1,LOG:13)
Block(3,3,1,LOG:13)
Block(-3,3,2,LOG:13)
Block(-2,3,2,LOG:13)
Block(-1,3,2,LOG:13)
Block(0,3,2,LOG:13)
Block(1,3,2,LOG:13)
Block(2,3,2,LOG:13)
Block(-3,3,3,LOG:13)
Block(-2,3,3,LOG:13)
Block(-1,3,3,LOG:13)
Block(0,3,3,LOG:13)
Block(1,3,3,LOG:13)
Block(2,3,3,LOG:13)
Block(-3,3,4,LOG:13)
Block(-2,3,4,LOG:13)
Block(-1,3,4,LOG:13)
Block(0,3,4,LOG:13)
Block(1,3,4,LOG:13)
Block(-2,3,5,LOG:13)
Block(-1,3,5,LOG:13)
Block(0,3,5,LOG:13)
Block(1,3,5,LOG:13)
Block(-1,3,6,LOG:13)
Block(1,4,-1,LOG:13)
Block(0,4,0,LOG:13)
Block(1,4,0,LOG:13)
Block(2,4,0,LOG:13)
Block(-2,4,1,LOG:13)
Block(-1,4,1,LOG:13)
Block(0,4,1,LOG:13)
Block(1,4,1,LOG:13)
Block(2,4,1,LOG:13)
Block(3,4,1,LOG:13)
Block(-3,4,2,LOG:13)
Block(-2,4,2,LOG:13)
Block(-1,4,2,LOG:13)
Block(0,4,2,LOG:13)
Block(1,4,2,LOG:13)
Block(2,4,2,LOG:13)
Block(-3,4,3,LOG:13)
Block(-2,4,3,LOG:13)
Block(-1,4,3,LOG:13)
Block(0,4,3,LOG:13)
Block(1,4,3,LOG:13)
Block(-3,4,4,LOG:13)
Block(-2,4,4,LOG:13)
Block(-1,4,4,LOG:13)
Block(0,4,4,LOG:13)
Block(1,4,4,LOG:13)
Block(-2,4,5,LOG:13)
Block(-1,4,5,LOG:13)
Block(0,4,5,LOG:13)
Block(1,5,-1,LOG:13)
Block(0,5,0,LOG:13)
Block(1,5,0,LOG:13)
Block(2,5,0,LOG:13)
Block(-2,5,1,LOG:13)
Block(0,5,1,LOG:13)
Block(1,5,1,LOG:13)
Block(2,5,1,LOG:13)
Block(3,5,1,LOG:13)
Block(-3,5,2,LOG:13)
Block(-2,5,2,LOG:13)
Block(-1,5,2,LOG:13)
Block(0,5,2,LOG:13)
Block(1,5,2,LOG:13)
Block(2,5,2,LOG:13)
Block(-3,5,3,LOG:13)
Block(-2,5,3,LOG:13)
Block(-1,5,3,LOG:13)
Block(0,5,3,LOG:13)
Block(1,5,3,LOG:13)
Block(-3,5,4,LOG:13)
Block(-2,5,4,LOG:13)
Block(-1,5,4,LOG:13)
Block(0,5,4,LOG:13)
Block(1,5,4,LOG:13)
Block(-2,5,5,LOG:13)
Block(-1,5,5,LOG:13)
Block(0,5,5,LOG:13)
Block(1,6,-1,LOG:13)
Block(0,6,0,LOG:13)
Block(1,6,0,LOG:13)
Block(2,6,0,LOG:13)
Block(-2,6,1,LOG:13)
Block(0,6,1,LOG:13)
Block(1,6,1,LOG:13)
Block(2,6,1,LOG:13)
Block(3,6,1,LOG:13)
Block(-3,6,2,LOG:13)
Block(-2,6,2,LOG:13)
Block(-1,6,2,LOG:13)
Block(0,6,2,LOG:13)
Block(1,6,2,LOG:13)
Block(2,6,2,LOG:13)
Block(-3,6,3,LOG:13)
Block(-2,6,3,LOG:13)
Block(-1,6,3,LOG:13)
Block(0,6,3,LOG:13)
Block(1,6,3,LOG:13)
Block(-3,6,4,LOG:13)
Block(-2,6,4,LOG:13)
Block(-1,6,4,LOG:13)
Block(0,6,4,LOG:13)
Block(1,6,4,LOG:13)
Block(-2,6,5,LOG:13)
Block(-1,6,5,LOG:13)
Block(0,6,5,LOG:13)
Block(1,7,-1,LOG:13)
Block(0,7,0,LOG:13)
Block(1,7,0,LOG:13)
Block(2,7,0,LOG:13)
Block(-2,7,1,LOG:13)
Block(0,7,1,LOG:13)
Block(1,7,1,LOG:13)
Block(2,7,1,LOG:13)
Block(3,7,1,LOG:13)
Block(-3,7,2,LOG:13)
Block(-2,7,2,LOG:13)
Block(-1,7,2,LOG:13)
Block(0,7,2,LOG:13)
Block(1,7,2,LOG:13)
Block(2,7,2,LOG:13)
Block(-3,7,3,LOG:13)
Block(-2,7,3,LOG:13)
Block(-1,7,3,LOG:13)
Block(0,7,3,LOG:13)
Block(1,7,3,LOG:13)
Block(-3,7,4,LOG:13)
Block(-2,7,4,LOG:13)
Block(-1,7,4,LOG:13)
Block(0,7,4,LOG:13)
Block(1,7,4,LOG:13)
Block(-2,7,5,LOG:13)
Block(-1,7,5,LOG:13)
Block(0,7,5,LOG:13)
Block(1,8,-1,LOG:13)
Block(0,8,0,LOG:13)
Block(1,8,0,LOG:13)
Block(2,8,0,LOG:13)
Block(-2,8,1,LOG:13)
Block(0,8,1,LOG:13)
Block(1,8,1,LOG:13)
Block(2,8,1,LOG:13)
Block(3,8,1,LOG:13)
Block(-3,8,2,LOG:13)
Block(-2,8,2,LOG:13)
Block(-1,8,2,LOG:13)
Block(0,8,2,LOG:13)
Block(1,8,2,LOG:13)
Block(2,8,2,LOG:13)
Block(-3,8,3,LOG:13)
Block(-2,8,3,LOG:13)
Block(-1,8,3,LOG:13)
Block(0,8,3,LOG:13)
Block(1,8,3,LOG:13)
Block(-3,8,4,LOG:13)
Block(-2,8,4,LOG:13)
Block(-1,8,4,LOG:13)
Block(0,8,4,LOG:13)
Block(1,8,4,LOG:13)
Block(-2,8,5,LOG:13)
Block(-1,8,5,LOG:13)
Block(0,8,5,LOG:13)
Block(1,9,-1,LOG:13)
Block(0,9,0,LOG:13)
Block(1,9,0,LOG:13)
Block(2,9,0,LOG:13)
Block(-2,9,1,LOG:13)
Block(0,9,1,LOG:13)
Block(1,9,1,LOG:13)
Block(2,9,1,LOG:13)
Block(3,9,1,LOG:13)
Block(-3,9,2,LOG:13)
Block(-2,9,2,LOG:13)
Block(-1,9,2,LOG:13)
Block(0,9,2,LOG:13)
Block(1,9,2,LOG:13)
Block(2,9,2,LOG:13)
Block(-2,9,3,LOG:13)
Block(-1,9,3,LOG:13)
Block(0,9,3,LOG:13)
Block(1,9,3,LOG:13)
Block(-2,9,4,LOG:13)
Block(-1,9,4,LOG:13)
Block(0,9,4,LOG:13)
Block(1,9,4,LOG:13)
Block(-2,9,5,LOG:13)
Block(-1,9,5,LOG:13)
Block(0,9,5,LOG:13)
Block(1,10,-1,LOG:13)
Block(0,10,0,LOG:13)
Block(1,10,0,LOG:13)
Block(2,10,0,LOG:13)
Block(-2,10,1,LOG:13)
Block(0,10,1,LOG:13)
Block(1,10,1,LOG:13)
Block(2,10,1,LOG:13)
Block(3,10,1,LOG:13)
Block(-3,10,2,LOG:13)
Block(-2,10,2,LOG:13)
Block(-1,10,2,LOG:13)
Block(0,10,2,LOG:13)
Block(1,10,2,LOG:13)
Block(2,10,2,LOG:13)
Block(-2,10,3,LOG:13)
Block(0,10,3,LOG:13)
Block(1,10,3,LOG:13)
Block(-2,10,4,LOG:13)
Block(-1,10,4,LOG:13)
Block(0,10,4,LOG:13)
Block(-2,10,5,LOG:13)
Block(-1,10,5,LOG:13)
Block(0,10,5,LOG:13)
Block(1,11,-1,LOG:13)
Block(0,11,0,LOG:13)
Block(1,11,0,LOG:13)
Block(2,11,0,LOG:13)
Block(-2,11,1,LOG:13)
Block(0,11,1,LOG:13)
Block(1,11,1,LOG:13)
Block(2,11,1,LOG:13)
Block(3,11,1,LOG:13)
Block(-3,11,2,LOG:13)
Block(-2,11,2,LOG:13)
Block(-1,11,2,LOG:13)
Block(0,11,2,LOG:13)
Block(1,11,2,LOG:13)
Block(2,11,2,LOG:13)
Block(-2,11,3,LOG:13)
Block(0,11,3,LOG:13)
Block(1,11,3,LOG:13)
Block(-2,11,4,LOG:13)
Block(-1,11,4,LOG:13)
Block(0,11,4,LOG:13)
Block(-2,11,5,LOG:13)
Block(-1,11,5,LOG:13)
Block(0,11,5,LOG:13)
Block(1,12,-1,LOG:13)
Block(0,12,0,LOG:13)
Block(1,12,0,LOG:13)
Block(2,12,0,LOG:13)
Block(-2,12,1,LOG:13)
Block(0,12,1,LOG:13)
Block(1,12,1,LOG:13)
Block(2,12,1,LOG:13)
Block(3,12,1,LOG:13)
Block(-3,12,2,LOG:13)
Block(-2,12,2,LOG:13)
Block(-1,12,2,LOG:13)
Block(0,12,2,LOG:13)
Block(1,12,2,LOG:13)
Block(2,12,2,LOG:13)
Block(-2,12,3,LOG:13)
Block(0,12,3,LOG:13)
Block(1,12,3,LOG:13)
Block(-2,12,4,LOG:13)
Block(-1,12,4,LOG:13)
Block(0,12,4,LOG:13)
Block(-2,12,5,LOG:13)
Block(-1,12,5,LOG:13)
Block(0,12,5,LOG:13)
Block(1,13,-1,LOG:13)
Block(0,13,0,LOG:13)
Block(1,13,0,LOG:13)
Block(2,13,0,LOG:13)
Block(-2,13,1,LOG:13)
Block(0,13,1,LOG:13)
Block(1,13,1,LOG:13)
Block(2,13,1,LOG:13)
Block(3,13,1,LOG:13)
Block(-3,13,2,LOG:13)
Block(-2,13,2,LOG:13)
Block(-1,13,2,LOG:13)
Block(0,13,2,LOG:13)
Block(1,13,2,LOG:13)
Block(2,13,2,LOG:13)
Block(-2,13,3,LOG:13)
Block(0,13,3,LOG:13)
Block(1,13,3,LOG:13)
Block(-2,13,4,LOG:13)
Block(-1,13,4,LOG:13)
Block(0,13,4,LOG:13)
Block(-1,13,5,LOG:13)
Block(0,13,5,LOG:13)
Block(1,14,-1,LOG:13)
Block(0,14,0,LOG:13)
Block(1,14,0,LOG:13)
Block(2,14,0,LOG:13)
Block(-2,14,1,LOG:13)
Block(0,14,1,LOG:13)
Block(1,14,1,LOG:13)
Block(2,14,1,LOG:13)
Block(3,14,1,LOG:13)
Block(-2,14,2,LOG:13)
Block(-1,14,2,LOG:13)
Block(0,14,2,LOG:13)
Block(1,14,2,LOG:13)
Block(2,14,2,LOG:13)
Block(-2,14,3,LOG:13)
Block(0,14,3,LOG:13)
Block(1,14,3,LOG:13)
Block(-2,14,4,LOG:13)
Block(-1,14,4,LOG:13)
Block(0,14,4,LOG:13)
Block(-1,14,5,LOG:13)
Block(0,14,5,LOG:13)
Block(0,15,0,LOG:13)
Block(1,15,0,LOG:13)
Block(2,15,0,LOG:13)
Block(-2,15,1,LOG:13)
Block(0,15,1,LOG:13)
Block(1,15,1,LOG:13)
Block(2,15,1,LOG:13)
Block(-2,15,2,LOG:13)
Block(-1,15,2,LOG:13)
Block(0,15,2,LOG:13)
Block(1,15,2,LOG:13)
Block(2,15,2,LOG:13)
Block(-2,15,3,LOG:13)
Block(0,15,3,LOG:13)
Block(1,15,3,LOG:13)
Block(-2,15,4,LOG:13)
Block(-1,15,4,LOG:13)
Block(0,15,4,LOG:13)
Block(-1,15,5,LOG:13)
Block(0,16,0,LOG:13)
Block(1,16,0,LOG:13)
Block(2,16,0,LOG:13)
Block(-2,16,1,LOG:13)
Block(0,16,1,LOG:13)
Block(1,16,1,LOG:13)
Block(2,16,1,LOG:13)
Block(-2,16,2,LOG:13)
Block(-1,16,2,LOG:13)
Block(0,16,2,LOG:13)
Block(1,16,2,LOG:13)
Block(2,16,2,LOG:13)
Block(-2,16,3,LOG:13)
Block(0,16,3,LOG:13)
Block(1,16,3,LOG:13)
Block(-2,16,4,LOG:13)
Block(-1,16,4,LOG:13)
Block(0,16,4,LOG:13)
Block(0,17,0,LOG:13)
Block(1,17,0,LOG:13)
Block(2,17,0,LOG:13)
Block(-2,17,1,LOG:13)
Block(0,17,1,LOG:13)
Block(1,17,1,LOG:13)
Block(2,17,1,LOG:13)
Block(-2,17,2,LOG:13)
Block(-1,17,2,LOG:13)
Block(0,17,2,LOG:13)
Block(1,17,2,LOG:13)
Block(2,17,2,LOG:13)
Block(-2,17,3,LOG:13)
Block(0,17,3,LOG:13)
Block(1,17,3,LOG:13)
Block(-2,17,4,LOG:13)
Block(-1,17,4,LOG:13)
Block(0,17,4,LOG:13)
Block(0,18,0,LOG:13)
Block(1,18,0,LOG:13)
Block(-2,18,1,LOG:13)
Block(0,18,1,LOG:13)
Block(1,18,1,LOG:13)
Block(2,18,1,LOG:13)
Block(-2,18,2,LOG:13)
Block(-1,18,2,LOG:13)
Block(0,18,2,LOG:13)
Block(1,18,2,LOG:13)
Block(2,18,2,LOG:13)
Block(-2,18,3,LOG:13)
Block(0,18,3,LOG:13)
Block(1,18,3,LOG:13)
Block(-2,18,4,LOG:13)
Block(-1,18,4,LOG:13)
Block(0,18,4,LOG:13)
Block(0,19,0,LOG:13)
Block(1,19,0,LOG:13)
Block(-2,19,1,LOG:13)
Block(0,19,1,LOG:13)
Block(1,19,1,LOG:13)
Block(2,19,1,LOG:13)
Block(-2,19,2,LOG:13)
Block(-1,19,2,LOG:13)
Block(0,19,2,LOG:13)
Block(1,19,2,LOG:13)
Block(2,19,2,LOG:13)
Block(-2,19,3,LOG:13)
Block(0,19,3,LOG:13)
Block(1,19,3,LOG:13)
Block(-2,19,4,LOG:13)
Block(-1,19,4,LOG:13)
Block(0,19,4,LOG:13)
Block(0,20,0,LOG:13)
Block(1,20,0,LOG:13)
Block(-2,20,1,LOG:13)
Block(0,20,1,LOG:13)
Block(1,20,1,LOG:13)
Block(2,20,1,LOG:13)
Block(-2,20,2,LOG:13)
Block(-1,20,2,LOG:13)
Block(0,20,2,LOG:13)
Block(1,20,2,LOG:13)
Block(2,20,2,LOG:13)
Block(-2,20,3,LOG:13)
Block(1,20,3,LOG:13)
Block(-2,20,4,LOG:13)
Block(-1,20,4,LOG:13)
Block(0,20,4,LOG:13)
Block(0,21,0,LOG:13)
Block(1,21,0,LOG:13)
Block(-2,21,1,LOG:13)
Block(0,21,1,LOG:13)
Block(1,21,1,LOG:13)
Block(2,21,1,LOG:13)
Block(-2,21,2,LOG:13)
Block(-1,21,2,LOG:13)
Block(0,21,2,LOG:13)
Block(1,21,2,LOG:13)
Block(2,21,2,LOG:13)
Block(-3,21,3,LOG:13)
Block(-2,21,3,LOG:13)
Block(1,21,3,LOG:13)
Block(-2,21,4,LOG:13)
Block(-1,21,4,LOG:13)
Block(0,21,4,LOG:13)
Block(0,22,0,LOG:13)
Block(1,22,0,LOG:13)
Block(-2,22,1,LOG:13)
Block(0,22,1,LOG:13)
Block(1,22,1,LOG:13)
Block(2,22,1,LOG:13)
Block(-2,22,2,LOG:13)
Block(-1,22,2,LOG:13)
Block(0,22,2,LOG:13)
Block(1,22,2,LOG:13)
Block(2,22,2,LOG:13)
Block(-3,22,3,LOG:13)
Block(-2,22,3,LOG:13)
Block(1,22,3,LOG:13)
Block(-2,22,4,LOG:13)
Block(-1,22,4,LOG:13)
Block(0,22,4,LOG:13)
Block(-4,23,0,LEAVES:13)
Block(0,23,0,LOG:13)
Block(1,23,0,LOG:13)
Block(-4,23,1,LEAVES:13)
Block(-2,23,1,LOG:13)
Block(0,23,1,LOG:13)
Block(1,23,1,LOG:13)
Block(2,23,1,LOG:13)
Block(-5,23,2,LEAVES:13)
Block(-4,23,2,LOG:13)
Block(-2,23,2,LOG:13)
Block(-1,23,2,LOG:13)
Block(0,23,2,LOG:13)
Block(1,23,2,LOG:13)
Block(2,23,2,LOG:13)
Block(-2,23,3,LOG:13)
Block(1,23,3,LOG:13)
Block(-2,23,4,LOG:13)
Block(-1,23,4,LOG:13)
Block(0,23,4,LOG:13)
Block(0,23,5,LOG:13)
Block(1,23,5,LEAVES:13)
Block(4,24,-2,LEAVES:13)
Block(2,24,-1,LOG:13)
Block(0,24,0,LOG:13)
Block(1,24,0,LOG:13)
Block(2,24,0,LOG:13)
Block(-5,24,1,LEAVES:13)
Block(-2,24,1,LOG:13)
Block(0,24,1,LOG:13)
Block(1,24,1,LOG:13)
Block(2,24,1,LOG:13)
Block(-6,24,2,LEAVES:13)
Block(-5,24,2,LEAVES:13)
Block(-4,24,2,LOG:13)
Block(-2,24,2,LOG:13)
Block(-1,24,2,LOG:13)
Block(0,24,2,LOG:13)
Block(1,24,2,LOG:13)
Block(2,24,2,LOG:13)
Block(5,24,2,LEAVES:13)
Block(-3,24,3,LEAVES:13)
Block(-2,24,3,LOG:13)
Block(1,24,3,LOG:13)
Block(-2,24,4,LOG:13)
Block(-1,24,4,LOG:13)
Block(0,24,4,LOG:13)
Block(0,24,5,LEAVES:13)
Block(0,24,6,LOG:13)
Block(-2,24,8,LEAVES:13)
Block(1,24,8,LEAVES:13)
Block(-2,24,11,LEAVES:13)
Block(2,25,-4,LEAVES:13)
Block(5,25,-4,LEAVES:13)
Block(6,25,-4,LEAVES:13)
Block(3,25,-2,LOG:13)
Block(3,25,-1,LOG:13)
Block(-5,25,0,LEAVES:13)
Block(0,25,0,LOG:13)
Block(1,25,0,LOG:13)
Block(-6,25,1,LEAVES:13)
Block(-5,25,1,LEAVES:13)
Block(-3,25,1,LEAVES:13)
Block(-2,25,1,LOG:13)
Block(0,25,1,LOG:13)
Block(1,25,1,LOG:13)
Block(2,25,1,LOG:13)
Block(-4,25,2,LOG:13)
Block(-2,25,2,LOG:13)
Block(-1,25,2,LOG:13)
Block(0,25,2,LOG:13)
Block(1,25,2,LOG:13)
Block(2,25,2,LOG:13)
Block(3,25,2,LOG:13)
Block(4,25,2,LOG:13)
Block(7,25,2,LEAVES:13)
Block(-4,25,3,LEAVES:13)
Block(-2,25,3,LOG:13)
Block(-1,25,3,LOG:13)
Block(0,25,3,LOG:13)
Block(1,25,3,LOG:13)
Block(-2,25,4,LOG:13)
Block(-1,25,4,LOG:13)
Block(0,25,4,LOG:13)
Block(5,25,4,LEAVES:13)
Block(-2,25,6,LEAVES:13)
Block(-1,25,6,LEAVES:13)
Block(0,25,6,LEAVES:13)
Block(1,25,6,LEAVES:13)
Block(-3,25,7,LEAVES:13)
Block(0,25,7,LOG:13)
Block(1,25,7,LOG:13)
Block(2,25,7,LEAVES:13)
Block(-2,25,8,LEAVES:13)
Block(-1,25,8,LOG:13)
Block(1,25,8,LOG:13)
Block(3,25,8,LEAVES:13)
Block(-1,25,9,LOG:13)
Block(1,25,9,LEAVES:13)
Block(-2,25,10,LOG:13)
Block(1,25,10,LEAVES:13)
Block(-3,25,11,LEAVES:13)
Block(4,25,11,LEAVES:13)
Block(4,26,-5,LEAVES:13)
Block(2,26,-4,LEAVES:13)
Block(4,26,-4,LEAVES:13)
Block(5,26,-4,LEAVES:13)
Block(6,26,-4,LEAVES:13)
Block(4,26,-3,LOG:13)
Block(6,26,-3,LEAVES:13)
Block(3,26,-2,LEAVES:13)
Block(-5,26,-1,LEAVES:13)
Block(-3,26,0,LEAVES:13)
Block(0,26,0,LOG:13)
Block(1,26,0,LOG:13)
Block(-7,26,1,LEAVES:13)
Block(-5,26,1,LOG:13)
Block(-3,26,1,LEAVES:13)
Block(-2,26,1,LOG:13)
Block(0,26,1,LOG:13)
Block(1,26,1,LOG:13)
Block(2,26,1,LOG:13)
Block(6,26,1,LEAVES:13)
Block(-7,26,2,LEAVES:13)
Block(-4,26,2,LEAVES:13)
Block(-3,26,2,LEAVES:13)
Block(-2,26,2,LOG:13)
Block(-1,26,2,LOG:13)
Block(0,26,2,LOG:13)
Block(1,26,2,LOG:13)
Block(2,26,2,LOG:13)
Block(7,26,2,LEAVES:13)
Block(-2,26,3,LOG:13)
Block(-1,26,3,LOG:13)
Block(0,26,3,LOG:13)
Block(1,26,3,LOG:13)
Block(4,26,3,LEAVES:13)
Block(5,26,3,LOG:13)
Block(6,26,3,LOG:13)
Block(-1,26,4,LOG:13)
Block(0,26,4,LOG:13)
Block(8,26,4,LEAVES:13)
Block(-3,26,7,LEAVES:13)
Block(-1,26,7,LEAVES:13)
Block(1,26,7,LEAVES:13)
Block(-1,26,8,LEAVES:13)
Block(1,26,8,LEAVES:13)
Block(2,26,8,LEAVES:13)
Block(3,26,8,LEAVES:13)
Block(-3,26,9,LEAVES:13)
Block(0,26,9,LEAVES:13)
Block(2,26,9,LOG:13)
Block(3,26,9,LEAVES:13)
Block(-3,26,10,LEAVES:13)
Block(-1,26,10,LEAVES:13)
Block(2,26,10,LEAVES:13)
Block(3,26,10,LOG:13)
Block(1,26,11,LEAVES:13)
Block(2,26,11,LEAVES:13)
Block(4,26,11,LEAVES:13)
Block(3,27,-3,LEAVES:13)
Block(5,27,-3,LEAVES:13)
Block(-4,27,0,LEAVES:13)
Block(0,27,0,LOG:13)
Block(1,27,0,LOG:13)
Block(-2,27,1,LOG:13)
Block(0,27,1,LOG:13)
Block(1,27,1,LOG:13)
Block(2,27,1,LOG:13)
Block(-7,27,2,LEAVES:13)
Block(-3,27,2,LEAVES:13)
Block(-2,27,2,LOG:13)
Block(-1,27,2,LOG:13)
Block(0,27,2,LOG:13)
Block(1,27,2,LOG:13)
Block(2,27,2,LOG:13)
Block(8,27,2,LEAVES:13)
Block(-2,27,3,LOG:13)
Block(-1,27,3,LOG:13)
Block(0,27,3,LOG:13)
Block(1,27,3,LOG:13)
Block(5,27,3,LEAVES:13)
Block(7,27,3,LEAVES:13)
Block(-1,27,4,LOG:13)
Block(0,27,4,LOG:13)
Block(-1,27,7,LEAVES:13)
Block(-1,27,9,LEAVES:13)
Block(1,27,9,LEAVES:13)
Block(2,27,9,LEAVES:13)
Block(3,27,10,LEAVES:13)
Block(4,28,-3,LEAVES:13)
Block(-3,28,-2,LEAVES:13)
Block(-4,28,-1,LEAVES:13)
Block(-2,28,-1,LEAVES:13)
Block(0,28,0,LOG:13)
Block(1,28,0,LOG:13)
Block(0,28,1,LOG:13)
Block(1,28,1,LOG:13)
Block(2,28,1,LOG:13)
Block(-2,28,2,LOG:13)
Block(-1,28,2,LOG:13)
Block(0,28,2,LOG:13)
Block(1,28,2,LOG:13)
Block(2,28,2,LOG:13)
Block(-1,28,3,LOG:13)
Block(0,28,3,LOG:13)
Block(1,28,3,LOG:13)
Block(6,28,3,LEAVES:13)
Block(-1,28,4,LOG:13)
Block(0,28,4,LOG:13)
Block(-2,29,-1,LEAVES:13)
Block(-2,29,0,LOG:13)
Block(0,29,0,LOG:13)
Block(1,29,0,LOG:13)
Block(-1,29,1,LOG:13)
Block(0,29,1,LOG:13)
Block(1,29,1,LOG:13)
Block(-2,29,2,LOG:13)
Block(-1,29,2,LOG:13)
Block(0,29,2,LOG:13)
Block(1,29,2,LOG:13)
Block(2,29,2,LOG:13)
Block(-1,29,3,LOG:13)
Block(0,29,3,LOG:13)
Block(1,29,3,LOG:13)
Block(-1,29,4,LOG:13)
Block(0,29,4,LOG:13)
Block(1,29,4,LOG:13)
Block(1,29,5,LOG:13)
Block(1,29,6,LOG:13)
Block(1,29,8,LEAVES:13)
Block(2,29,8,LEAVES:13)
Block(2,29,9,LEAVES:13)
Block(-4,30,-3,LEAVES:13)
Block(-4,30,-1,LOG:13)
Block(-3,30,-1,LOG:13)
Block(-1,30,-1,LEAVES:13)
Block(-5,30,0,LEAVES:13)
Block(0,30,0,LOG:13)
Block(1,30,0,LOG:13)
Block(0,30,1,LOG:13)
Block(1,30,1,LOG:13)
Block(-2,30,2,LOG:13)
Block(-1,30,2,LOG:13)
Block(0,30,2,LOG:13)
Block(1,30,2,LOG:13)
Block(2,30,2,LOG:13)
Block(-1,30,3,LOG:13)
Block(0,30,3,LOG:13)
Block(1,30,3,LOG:13)
Block(-1,30,4,LOG:13)
Block(0,30,4,LOG:13)
Block(0,30,6,LOG:13)
Block(1,30,7,LEAVES:13)
Block(2,30,7,LOG:13)
Block(3,30,8,LOG:13)
Block(2,30,9,LEAVES:13)
Block(5,30,9,LEAVES:13)
Block(3,30,10,LEAVES:13)
Block(-7,31,-4,LEAVES:13)
Block(-5,31,-2,LOG:13)
Block(1,31,-2,LEAVES:13)
Block(-6,31,-1,LEAVES:13)
Block(-5,31,-1,LEAVES:13)
Block(-1,31,-1,LEAVES:13)
Block(0,31,0,LOG:13)
Block(1,31,0,LOG:13)
Block(-3,31,1,LEAVES:13)
Block(0,31,1,LOG:13)
Block(1,31,1,LOG:13)
Block(-2,31,2,LOG:13)
Block(-1,31,2,LOG:13)
Block(0,31,2,LOG:13)
Block(1,31,2,LOG:13)
Block(2,31,2,LOG:13)
Block(-1,31,3,LOG:13)
Block(0,31,3,LOG:13)
Block(1,31,3,LOG:13)
Block(-1,31,4,LOG:13)
Block(0,31,4,LOG:13)
Block(3,31,8,LEAVES:13)
Block(4,31,9,LEAVES:13)
Block(4,32,-6,LEAVES:13)
Block(5,32,-4,LEAVES:13)
Block(-6,32,-3,LOG:13)
Block(-4,32,-3,LEAVES:13)
Block(-7,32,-2,LEAVES:13)
Block(-6,32,-2,LEAVES:13)
Block(1,32,-2,LEAVES:13)
Block(2,32,-2,LOG:13)
Block(-6,32,-1,LEAVES:13)
Block(0,32,-1,LEAVES:13)
Block(1,32,-1,LOG:13)
Block(0,32,0,LOG:13)
Block(1,32,0,LOG:13)
Block(0,32,1,LOG:13)
Block(1,32,1,LOG:13)
Block(-2,32,2,LOG:13)
Block(-1,32,2,LOG:13)
Block(0,32,2,LOG:13)
Block(1,32,2,LOG:13)
Block(2,32,2,LOG:13)
Block(-1,32,3,LOG:13)
Block(0,32,3,LOG:13)
Block(3,32,3,LEAVES:13)
Block(-1,32,4,LOG:13)
Block(0,32,4,LOG:13)
Block(3,33,-6,LEAVES:13)
Block(4,33,-5,LEAVES:13)
Block(5,33,-5,LEAVES:13)
Block(6,33,-5,LEAVES:13)
Block(-7,33,-4,LEAVES:13)
Block(4,33,-4,LOG:13)
Block(-6,33,-3,LEAVES:13)
Block(2,33,-3,LEAVES:13)
Block(3,33,-3,LOG:13)
Block(5,33,-3,LEAVES:13)
Block(-10,33,-2,LEAVES:13)
Block(2,33,-2,LEAVES:13)
Block(1,33,-1,LEAVES:13)
Block(-6,33,0,LEAVES:13)
Block(-4,33,0,LEAVES:13)
Block(0,33,0,LOG:13)
Block(1,33,0,LOG:13)
Block(-7,33,1,LEAVES:13)
Block(-4,33,1,LEAVES:13)
Block(0,33,1,LOG:13)
Block(1,33,1,LOG:13)
Block(-2,33,2,LOG:13)
Block(-1,33,2,LOG:13)
Block(0,33,2,LOG:13)
Block(1,33,2,LOG:13)
Block(2,33,2,LOG:13)
Block(5,33,2,LEAVES:13)
Block(-1,33,3,LOG:13)
Block(0,33,3,LOG:13)
Block(3,33,3,LEAVES:13)
Block(5,33,3,LEAVES:13)
Block(-1,33,4,LOG:13)
Block(0,33,4,LOG:13)
Block(3,33,4,LEAVES:13)
Block(5,33,4,LEAVES:13)
Block(6,33,4,LEAVES:13)
Block(3,33,5,LEAVES:13)
Block(4,33,5,LEAVES:13)
Block(5,34,-7,LEAVES:13)
Block(5,34,-6,LEAVES:13)
Block(3,34,-5,LEAVES:13)
Block(4,34,-5,LEAVES:13)
Block(3,34,-4,LEAVES:13)
Block(-7,34,-3,LEAVES:13)
Block(2,34,-3,LEAVES:13)
Block(4,34,-3,LEAVES:13)
Block(-10,34,-2,LEAVES:13)
Block(-9,34,-1,LEAVES:13)
Block(-8,34,-1,LEAVES:13)
Block(-6,34,-1,LEAVES:13)
Block(-13,34,0,LEAVES:13)
Block(-12,34,0,LEAVES:13)
Block(-11,34,0,LOG:13)
Block(-10,34,0,LOG:13)
Block(-9,34,0,LOG:13)
Block(-8,34,0,LEAVES:13)
Block(-5,34,0,LEAVES:13)
Block(0,34,0,LOG:13)
Block(1,34,0,LOG:13)
Block(-10,34,1,LEAVES:13)
Block(-9,34,1,LEAVES:13)
Block(-5,34,1,LEAVES:13)
Block(-4,34,1,LEAVES:13)
Block(-3,34,1,LEAVES:13)
Block(0,34,1,LOG:13)
Block(1,34,1,LOG:13)
Block(3,34,1,LEAVES:13)
Block(4,34,1,LEAVES:13)
Block(-2,34,2,LOG:13)
Block(-1,34,2,LOG:13)
Block(0,34,2,LOG:13)
Block(1,34,2,LOG:13)
Block(2,34,2,LOG:13)
Block(3,34,2,LEAVES:13)
Block(4,34,2,LEAVES:13)
Block(6,34,2,LEAVES:13)
Block(-5,34,3,LEAVES:13)
Block(-1,34,3,LOG:13)
Block(0,34,3,LOG:13)
Block(2,34,3,LEAVES:13)
Block(3,34,3,LOG:13)
Block(4,34,3,LOG:13)
Block(5,34,3,LEAVES:13)
Block(-1,34,4,LOG:13)
Block(0,34,4,LOG:13)
Block(3,34,4,LEAVES:13)
Block(5,34,4,LEAVES:13)
Block(3,34,5,LEAVES:13)
Block(4,35,-7,LEAVES:13)
Block(6,35,-7,LEAVES:13)
Block(3,35,-6,LEAVES:13)
Block(4,35,-5,LEAVES:13)
Block(3,35,-4,LEAVES:13)
Block(4,35,-4,LEAVES:13)
Block(5,35,-4,LEAVES:13)
Block(-12,35,-1,LEAVES:13)
Block(-11,35,0,LEAVES:13)
Block(-6,35,0,LEAVES:13)
Block(0,35,0,LOG:13)
Block(1,35,0,LOG:13)
Block(-8,35,1,LOG:13)
Block(-7,35,1,LOG:13)
Block(-6,35,1,LOG:13)
Block(-5,35,1,LOG:13)
Block(-4,35,1,LEAVES:13)
Block(-3,35,1,LEAVES:13)
Block(-2,35,1,LEAVES:13)
Block(-1,35,1,LOG:13)
Block(0,35,1,LOG:13)
Block(1,35,1,LOG:13)
Block(-9,35,2,LEAVES:13)
Block(-8,35,2,LEAVES:13)
Block(-7,35,2,LEAVES:13)
Block(-6,35,2,LEAVES:13)
Block(-4,35,2,LOG:13)
Block(-3,35,2,LOG:13)
Block(-2,35,2,LOG:13)
Block(-1,35,2,LOG:13)
Block(0,35,2,LOG:13)
Block(1,35,2,LOG:13)
Block(2,35,2,LOG:13)
Block(-8,35,3,LEAVES:13)
Block(-6,35,3,LEAVES:13)
Block(-5,35,3,LEAVES:13)
Block(-1,35,3,LOG:13)
Block(0,35,3,LOG:13)
Block(2,35,3,LEAVES:13)
Block(3,35,3,LEAVES:13)
Block(4,35,3,LEAVES:13)
Block(5,35,3,LEAVES:13)
Block(-1,35,4,LOG:13)
Block(0,35,4,LOG:13)
Block(3,35,4,LEAVES:13)
Block(5,35,4,LOG:13)
Block(4,35,6,LEAVES:13)
Block(11,35,8,LEAVES:13)
Block(0,36,-11,LEAVES:13)
Block(0,36,-10,LEAVES:13)
Block(5,36,-7,LOG:13)
Block(6,36,-7,LEAVES:13)
Block(4,36,-6,LEAVES:13)
Block(2,36,-5,LEAVES:13)
Block(3,36,-5,LEAVES:13)
Block(4,36,-5,LEAVES:13)
Block(4,36,-4,LEAVES:13)
Block(5,36,-3,LEAVES:13)
Block(4,36,-2,LEAVES:13)
Block(5,36,-2,LEAVES:13)
Block(-10,36,-1,LEAVES:13)
Block(-6,36,-1,LEAVES:13)
Block(-2,36,-1,LOG:13)
Block(-9,36,0,LEAVES:13)
Block(-2,36,0,LOG:13)
Block(0,36,0,LOG:13)
Block(-8,36,1,LEAVES:13)
Block(-7,36,1,LEAVES:13)
Block(-5,36,1,LEAVES:13)
Block(-3,36,1,LEAVES:13)
Block(-1,36,1,LEAVES:13)
Block(0,36,1,LOG:13)
Block(1,36,1,LOG:13)
Block(-6,36,2,LEAVES:13)
Block(-5,36,2,LEAVES:13)
Block(-2,36,2,LOG:13)
Block(-1,36,2,LOG:13)
Block(0,36,2,LOG:13)
Block(1,36,2,LOG:13)
Block(2,36,2,LOG:13)
Block(-4,36,3,LEAVES:13)
Block(-2,36,3,LOG:13)
Block(-1,36,3,LOG:13)
Block(0,36,3,LOG:13)
Block(2,36,3,LEAVES:13)
Block(5,36,3,LEAVES:13)
Block(10,36,3,LEAVES:13)
Block(-1,36,4,LOG:13)
Block(0,36,4,LOG:13)
Block(6,36,4,LEAVES:13)
Block(5,36,5,LEAVES:13)
Block(7,36,5,LEAVES:13)
Block(5,36,6,LEAVES:13)
Block(6,36,6,LEAVES:13)
Block(12,36,6,LEAVES:13)
Block(6,36,7,LEAVES:13)
Block(9,36,7,LEAVES:13)
Block(6,36,8,LEAVES:13)
Block(8,36,8,LEAVES:13)
Block(9,36,8,LEAVES:13)
Block(13,36,8,LEAVES:13)
Block(12,36,9,LEAVES:13)
Block(9,36,10,LEAVES:13)
Block(12,36,12,LEAVES:13)
Block(-1,37,-13,LEAVES:13)
Block(0,37,-11,LEAVES:13)
Block(2,37,-11,LEAVES:13)
Block(0,37,-10,LEAVES:13)
Block(1,37,-9,LEAVES:13)
Block(5,37,-9,LEAVES:13)
Block(-1,37,-8,LEAVES:13)
Block(1,37,-8,LEAVES:13)
Block(5,37,-8,LEAVES:13)
Block(0,37,-7,LEAVES:13)
Block(3,37,-7,LEAVES:13)
Block(4,37,-7,LEAVES:13)
Block(5,37,-7,LEAVES:13)
Block(3,37,-6,LEAVES:13)
Block(4,37,-6,LOG:13)
Block(5,37,-6,LEAVES:13)
Block(4,37,-5,LOG:13)
Block(5,37,-5,LEAVES:13)
Block(2,37,-4,LEAVES:13)
Block(3,37,-4,LEAVES:13)
Block(4,37,-4,LOG:13)
Block(3,37,-3,LEAVES:13)
Block(5,37,-3,LEAVES:13)
Block(-1,37,-2,LOG:13)
Block(4,37,-2,LEAVES:13)
Block(-5,37,0,LEAVES:13)
Block(0,37,0,LOG:13)
Block(11,37,0,LEAVES:13)
Block(-7,37,1,LEAVES:13)
Block(-6,37,1,LEAVES:13)
Block(-5,37,1,LEAVES:13)
Block(-4,37,1,LEAVES:13)
Block(0,37,1,LOG:13)
Block(1,37,1,LOG:13)
Block(8,37,1,LEAVES:13)
Block(-2,37,2,LOG:13)
Block(-1,37,2,LOG:13)
Block(0,37,2,LOG:13)
Block(1,37,2,LOG:13)
Block(2,37,2,LOG:13)
Block(-13,37,3,LEAVES:13)
Block(-11,37,3,LEAVES:13)
Block(-10,37,3,LEAVES:13)
Block(-4,37,3,LOG:13)
Block(-3,37,3,LOG:13)
Block(-2,37,3,LEAVES:13)
Block(-1,37,3,LOG:13)
Block(0,37,3,LOG:13)
Block(5,37,3,LEAVES:13)
Block(6,37,3,LEAVES:13)
Block(11,37,3,LEAVES:13)
Block(-12,37,4,LEAVES:13)
Block(-11,37,4,LEAVES:13)
Block(-10,37,4,LEAVES:13)
Block(-7,37,4,LEAVES:13)
Block(-3,37,4,LEAVES:13)
Block(-1,37,4,LOG:13)
Block(0,37,4,LOG:13)
Block(5,37,4,LEAVES:13)
Block(12,37,4,LEAVES:13)
Block(0,37,5,LOG:13)
Block(6,37,6,LEAVES:13)
Block(9,37,6,LEAVES:13)
Block(5,37,7,LEAVES:13)
Block(9,37,7,LEAVES:13)
Block(11,37,7,LEAVES:13)
Block(1,37,8,LEAVES:13)
Block(7,37,8,LEAVES:13)
Block(8,37,8,LEAVES:13)
Block(9,37,8,LEAVES:13)
Block(10,37,8,LOG:13)
Block(11,37,8,LOG:13)
Block(12,37,8,LOG:13)
Block(9,37,9,LOG:13)
Block(-6,37,10,LEAVES:13)
Block(-5,37,10,LEAVES:13)
Block(9,37,10,LEAVES:13)
Block(10,37,10,LOG:13)
Block(11,37,10,LEAVES:13)
Block(13,37,10,LEAVES:13)
Block(-4,37,11,LEAVES:13)
Block(9,37,11,LEAVES:13)
Block(10,37,11,LEAVES:13)
Block(11,37,11,LOG:13)
Block(-5,37,12,LEAVES:13)
Block(4,37,12,LEAVES:13)
Block(-5,37,14,LEAVES:13)
Block(-4,37,14,LEAVES:13)
Block(0,38,-13,LEAVES:13)
Block(0,38,-12,LOG:13)
Block(0,38,-11,LOG:13)
Block(2,38,-11,LEAVES:13)
Block(-1,38,-10,LEAVES:13)
Block(0,38,-10,LOG:13)
Block(-1,38,-9,LEAVES:13)
Block(0,38,-9,LEAVES:13)
Block(0,38,-8,LEAVES:13)
Block(0,38,-7,LEAVES:13)
Block(0,38,-6,LEAVES:13)
Block(2,38,-6,LEAVES:13)
Block(4,38,-6,LEAVES:13)
Block(0,38,-5,LEAVES:13)
Block(0,38,-4,LOG:13)
Block(3,38,-4,LEAVES:13)
Block(4,38,-4,LEAVES:13)
Block(-1,38,-3,LOG:13)
Block(3,38,-3,LOG:13)
Block(4,38,-3,LEAVES:13)
Block(5,38,-3,LEAVES:13)
Block(0,38,-2,LEAVES:13)
Block(3,38,-2,LOG:13)
Block(2,38,-1,LOG:13)
Block(0,38,0,LOG:13)
Block(2,38,0,LOG:13)
Block(5,38,0,LEAVES:13)
Block(8,38,0,LEAVES:13)
Block(11,38,0,LEAVES:13)
Block(-12,38,1,LEAVES:13)
Block(-11,38,1,LEAVES:13)
Block(-1,38,1,LEAVES:13)
Block(0,38,1,LOG:13)
Block(1,38,1,LOG:13)
Block(6,38,1,LEAVES:13)
Block(9,38,1,LEAVES:13)
Block(-12,38,2,LEAVES:13)
Block(-11,38,2,LEAVES:13)
Block(-2,38,2,LOG:13)
Block(-1,38,2,LOG:13)
Block(0,38,2,LOG:13)
Block(1,38,2,LOG:13)
Block(2,38,2,LOG:13)
Block(9,38,2,LOG:13)
Block(10,38,2,LOG:13)
Block(11,38,2,LOG:13)
Block(12,38,2,LOG:13)
Block(-14,38,3,LEAVES:13)
Block(-13,38,3,LEAVES:13)
Block(-12,38,3,LEAVES:13)
Block(-7,38,3,LEAVES:13)
Block(-1,38,3,LOG:13)
Block(0,38,3,LOG:13)
Block(5,38,3,LEAVES:13)
Block(-12,38,4,LEAVES:13)
Block(-11,38,4,LEAVES:13)
Block(-6,38,4,LOG:13)
Block(-5,38,4,LOG:13)
Block(-1,38,4,LOG:13)
Block(0,38,4,LOG:13)
Block(6,38,4,LEAVES:13)
Block(7,38,4,LEAVES:13)
Block(8,38,4,LEAVES:13)
Block(-9,38,5,LEAVES:13)
Block(-7,38,5,LEAVES:13)
Block(-2,38,5,LEAVES:13)
Block(-7,38,6,LEAVES:13)
Block(-1,38,6,LOG:13)
Block(6,38,6,LOG:13)
Block(7,38,6,LEAVES:13)
Block(12,38,6,LEAVES:13)
Block(-2,38,7,LEAVES:13)
Block(-1,38,7,LOG:13)
Block(0,38,7,LEAVES:13)
Block(1,38,7,LEAVES:13)
Block(7,38,7,LOG:13)
Block(8,38,7,LOG:13)
Block(9,38,7,LEAVES:13)
Block(-1,38,8,LEAVES:13)
Block(0,38,8,LEAVES:13)
Block(8,38,8,LOG:13)
Block(9,38,8,LOG:13)
Block(10,38,8,LEAVES:13)
Block(12,38,8,LEAVES:13)
Block(13,38,8,LEAVES:13)
Block(0,38,9,LEAVES:13)
Block(1,38,9,LEAVES:13)
Block(-3,38,10,LEAVES:13)
Block(2,38,10,LEAVES:13)
Block(3,38,10,LEAVES:13)
Block(11,38,10,LEAVES:13)
Block(13,38,10,LEAVES:13)
Block(-5,38,11,LEAVES:13)
Block(3,38,11,LEAVES:13)
Block(-7,38,12,LEAVES:13)
Block(-4,38,12,LEAVES:13)
Block(4,38,12,LEAVES:13)
Block(10,38,12,LEAVES:13)
Block(-3,38,13,LEAVES:13)
Block(1,38,13,LEAVES:13)
Block(3,38,13,LEAVES:13)
Block(-5,38,14,LEAVES:13)
Block(-5,38,15,LEAVES:13)
Block(-2,39,-12,LEAVES:13)
Block(0,39,-12,LEAVES:13)
Block(-1,39,-11,LEAVES:13)
Block(1,39,-11,LEAVES:13)
Block(-2,39,-10,LEAVES:13)
Block(-1,39,-10,LEAVES:13)
Block(0,39,-10,LEAVES:13)
Block(1,39,-10,LEAVES:13)
Block(0,39,-9,LOG:13)
Block(-1,39,-8,LEAVES:13)
Block(0,39,-8,LOG:13)
Block(1,39,-8,LEAVES:13)
Block(-2,39,-7,LEAVES:13)
Block(0,39,-7,LOG:13)
Block(1,39,-7,LEAVES:13)
Block(-1,39,-6,LEAVES:13)
Block(0,39,-6,LEAVES:13)
Block(1,39,-6,LEAVES:13)
Block(2,39,-6,LEAVES:13)
Block(-2,39,-5,LEAVES:13)
Block(-1,39,-5,LEAVES:13)
Block(1,39,-5,LEAVES:13)
Block(3,39,-5,LEAVES:13)
Block(5,39,-5,LEAVES:13)
Block(-2,39,-4,LEAVES:13)
Block(0,39,-4,LEAVES:13)
Block(5,39,-4,LEAVES:13)
Block(1,39,-3,LEAVES:13)
Block(3,39,-3,LEAVES:13)
Block(4,39,-3,LEAVES:13)
Block(0,39,-2,LEAVES:13)
Block(2,39,-2,LEAVES:13)
Block(3,39,-2,LEAVES:13)
Block(-1,39,-1,LEAVES:13)
Block(-1,39,0,LEAVES:13)
Block(0,39,0,LOG:13)
Block(8,39,0,LEAVES:13)
Block(-2,39,1,LEAVES:13)
Block(-1,39,1,LEAVES:13)
Block(0,39,1,LOG:13)
Block(1,39,1,LOG:13)
Block(7,39,1,LEAVES:13)
Block(8,39,1,LEAVES:13)
Block(10,39,1,LEAVES:13)
Block(-13,39,2,LEAVES:13)
Block(-10,39,2,LEAVES:13)
Block(-3,39,2,LEAVES:13)
Block(-2,39,2,LOG:13)
Block(-1,39,2,LOG:13)
Block(0,39,2,LOG:13)
Block(1,39,2,LOG:13)
Block(2,39,2,LOG:13)
Block(3,39,2,LEAVES:13)
Block(5,39,2,LOG:13)
Block(6,39,2,LOG:13)
Block(7,39,2,LOG:13)
Block(8,39,2,LOG:13)
Block(10,39,2,LEAVES:13)
Block(11,39,2,LEAVES:13)
Block(-12,39,3,LOG:13)
Block(-11,39,3,LOG:13)
Block(-10,39,3,LOG:13)
Block(-9,39,3,LOG:13)
Block(-1,39,3,LOG:13)
Block(0,39,3,LOG:13)
Block(1,39,3,LOG:13)
Block(2,39,3,LOG:13)
Block(5,39,3,LEAVES:13)
Block(8,39,3,LEAVES:13)
Block(-13,39,4,LEAVES:13)
Block(-12,39,4,LEAVES:13)
Block(-9,39,4,LEAVES:13)
Block(-8,39,4,LEAVES:13)
Block(-1,39,4,LOG:13)
Block(0,39,4,LOG:13)
Block(4,39,4,LOG:13)
Block(9,39,4,LEAVES:13)
Block(12,39,4,LEAVES:13)
Block(-11,39,5,LEAVES:13)
Block(-9,39,5,LEAVES:13)
Block(-7,39,5,LOG:13)
Block(-5,39,5,LEAVES:13)
Block(5,39,5,LOG:13)
Block(-5,39,6,LEAVES:13)
Block(-1,39,6,LEAVES:13)
Block(-7,39,7,LEAVES:13)
Block(8,39,7,LEAVES:13)
Block(10,39,7,LEAVES:13)
Block(11,39,7,LEAVES:13)
Block(7,39,8,LEAVES:13)
Block(11,39,8,LEAVES:13)
Block(-5,39,9,LEAVES:13)
Block(-2,39,9,LEAVES:13)
Block(0,39,9,LEAVES:13)
Block(1,39,9,LEAVES:13)
Block(2,39,9,LEAVES:13)
Block(9,39,9,LEAVES:13)
Block(11,39,9,LEAVES:13)
Block(-7,39,10,LEAVES:13)
Block(-6,39,10,LEAVES:13)
Block(-5,39,10,LOG:13)
Block(-3,39,10,LEAVES:13)
Block(0,39,10,LEAVES:13)
Block(2,39,10,LEAVES:13)
Block(3,39,10,LEAVES:13)
Block(10,39,10,LEAVES:13)
Block(-5,39,11,LOG:13)
Block(-4,39,11,LEAVES:13)
Block(-3,39,11,LEAVES:13)
Block(0,39,11,LEAVES:13)
Block(3,39,11,LEAVES:13)
Block(4,39,11,LEAVES:13)
Block(-5,39,12,LOG:13)
Block(-3,39,12,LEAVES:13)
Block(2,39,12,LEAVES:13)
Block(3,39,12,LOG:13)
Block(11,39,12,LEAVES:13)
Block(-7,39,13,LEAVES:13)
Block(-5,39,13,LOG:13)
Block(2,39,13,LEAVES:13)
Block(3,39,13,LOG:13)
Block(4,39,13,LEAVES:13)
Block(-7,39,14,LEAVES:13)
Block(-6,39,14,LEAVES:13)
Block(-5,39,14,LOG:13)
Block(-3,39,14,LEAVES:13)
Block(1,39,14,LEAVES:13)
Block(3,39,14,LOG:13)
Block(-5,39,15,LEAVES:13)
Block(3,39,15,LEAVES:13)
Block(-6,39,16,LEAVES:13)
Block(-1,40,-11,LEAVES:13)
Block(0,40,-11,LEAVES:13)
Block(0,40,-8,LEAVES:13)
Block(2,40,-8,LEAVES:13)
Block(-2,40,-6,LEAVES:13)
Block(0,40,-6,LOG:13)
Block(1,40,-6,LEAVES:13)
Block(2,40,-6,LEAVES:13)
Block(-2,40,-5,LEAVES:13)
Block(0,40,-5,LOG:13)
Block(1,40,-5,LEAVES:13)
Block(-2,40,-4,LEAVES:13)
Block(0,40,-4,LOG:13)
Block(4,40,-4,LEAVES:13)
Block(-1,40,-3,LEAVES:13)
Block(0,40,-3,LOG:13)
Block(3,40,-3,LEAVES:13)
Block(5,40,-3,LEAVES:13)
Block(-1,40,-2,LEAVES:13)
Block(0,40,-2,LOG:13)
Block(1,40,-2,LEAVES:13)
Block(3,40,-2,LOG:13)
Block(-1,40,-1,LEAVES:13)
Block(0,40,-1,LOG:13)
Block(2,40,-1,LOG:13)
Block(5,40,-1,LEAVES:13)
Block(-5,40,0,LEAVES:13)
Block(-2,40,0,LEAVES:13)
Block(-1,40,0,LEAVES:13)
Block(0,40,0,LOG:13)
Block(1,40,0,LOG:13)
Block(8,40,0,LEAVES:13)
Block(-2,40,1,LEAVES:13)
Block(-1,40,1,LEAVES:13)
Block(0,40,1,LOG:13)
Block(1,40,1,LOG:13)
Block(6,40,1,LEAVES:13)
Block(10,40,1,LEAVES:13)
Block(11,40,1,LEAVES:13)
Block(-8,40,2,LOG:13)
Block(-7,40,2,LOG:13)
Block(-6,40,2,LOG:13)
Block(-5,40,2,LOG:13)
Block(-4,40,2,LOG:13)
Block(-3,40,2,LOG:13)
Block(-2,40,2,LOG:13)
Block(-1,40,2,LOG:13)
Block(0,40,2,LOG:13)
Block(1,40,2,LOG:13)
Block(2,40,2,LOG:13)
Block(3,40,2,LOG:13)
Block(4,40,2,LOG:13)
Block(5,40,2,LEAVES:13)
Block(11,40,2,LEAVES:13)
Block(-14,40,3,LEAVES:13)
Block(-12,40,3,LEAVES:13)
Block(-11,40,3,LEAVES:13)
Block(-9,40,3,LEAVES:13)
Block(-7,40,3,LEAVES:13)
Block(-2,40,3,LEAVES:13)
Block(-1,40,3,LOG:13)
Block(0,40,3,LOG:13)
Block(1,40,3,LOG:13)
Block(2,40,3,LOG:13)
Block(3,40,3,LOG:13)
Block(4,40,3,LOG:13)
Block(9,40,3,LEAVES:13)
Block(10,40,3,LEAVES:13)
Block(-2,40,4,LOG:13)
Block(1,40,4,LOG:13)
Block(-9,40,5,LEAVES:13)
Block(-2,40,5,LOG:13)
Block(1,40,5,LOG:13)
Block(-7,40,6,LEAVES:13)
Block(-3,40,6,LOG:13)
Block(-2,40,6,LEAVES:13)
Block(1,40,6,LOG:13)
Block(7,40,6,LEAVES:13)
Block(8,40,6,LEAVES:13)
Block(-8,40,7,LEAVES:13)
Block(-3,40,7,LOG:13)
Block(1,40,7,LOG:13)
Block(2,40,7,LEAVES:13)
Block(9,40,7,LEAVES:13)
Block(-4,40,8,LOG:13)
Block(1,40,8,LEAVES:13)
Block(2,40,8,LOG:13)
Block(3,40,8,LEAVES:13)
Block(-5,40,9,LEAVES:13)
Block(-4,40,9,LOG:13)
Block(0,40,9,LEAVES:13)
Block(1,40,9,LEAVES:13)
Block(2,40,9,LOG:13)
Block(-3,40,10,LEAVES:13)
Block(1,40,10,LEAVES:13)
Block(2,40,10,LOG:13)
Block(4,40,10,LEAVES:13)
Block(-4,40,11,LEAVES:13)
Block(2,40,11,LOG:13)
Block(-6,40,12,LEAVES:13)
Block(2,40,12,LEAVES:13)
Block(-6,40,13,LEAVES:13)
Block(-5,40,13,LEAVES:13)
Block(2,40,13,LEAVES:13)
Block(4,40,13,LEAVES:13)
Block(-7,40,14,LEAVES:13)
Block(-4,40,14,LEAVES:13)
Block(-3,40,14,LEAVES:13)
Block(-4,40,15,LEAVES:13)
Block(-5,40,16,LEAVES:13)
Block(1,41,-8,LEAVES:13)
Block(0,41,-7,LEAVES:13)
Block(-2,41,-6,LEAVES:13)
Block(-1,41,-6,LEAVES:13)
Block(0,41,-6,LEAVES:13)
Block(0,41,-5,LEAVES:13)
Block(-2,41,-4,LEAVES:13)
Block(-2,41,-3,LEAVES:13)
Block(1,41,-3,LEAVES:13)
Block(3,41,-3,LEAVES:13)
Block(-1,41,-2,LEAVES:13)
Block(2,41,-2,LEAVES:13)
Block(4,41,-2,LEAVES:13)
Block(-5,41,-1,LEAVES:13)
Block(-5,41,0,LOG:13)
Block(-1,41,0,LEAVES:13)
Block(0,41,0,LOG:13)
Block(-5,41,1,LEAVES:13)
Block(-4,41,1,LOG:13)
Block(-3,41,1,LOG:13)
Block(-2,41,1,LEAVES:13)
Block(-1,41,1,LEAVES:13)
Block(0,41,1,LOG:13)
Block(1,41,1,LOG:13)
Block(6,41,1,LEAVES:13)
Block(8,41,1,LEAVES:13)
Block(-12,41,2,LEAVES:13)
Block(-6,41,2,LEAVES:13)
Block(-2,41,2,LOG:13)
Block(-1,41,2,LOG:13)
Block(0,41,2,LOG:13)
Block(1,41,2,LOG:13)
Block(2,41,2,LOG:13)
Block(7,41,2,LEAVES:13)
Block(8,41,2,LEAVES:13)
Block(-12,41,3,LEAVES:13)
Block(-11,41,3,LEAVES:13)
Block(-4,41,3,LEAVES:13)
Block(-1,41,3,LOG:13)
Block(0,41,3,LOG:13)
Block(6,41,3,LEAVES:13)
Block(9,41,3,LEAVES:13)
Block(-7,41,5,LEAVES:13)
Block(-2,41,5,LEAVES:13)
Block(-8,41,6,LEAVES:13)
Block(1,41,8,LEAVES:13)
Block(2,41,8,LEAVES:13)
Block(4,41,8,LEAVES:13)
Block(2,41,9,LEAVES:13)
Block(4,41,9,LEAVES:13)
Block(-4,41,10,LEAVES:13)
Block(-3,41,10,LEAVES:13)
Block(-6,41,12,LEAVES:13)
Block(-5,41,12,LEAVES:13)
Block(-4,41,12,LEAVES:13)
Block(4,41,12,LEAVES:13)
Block(-6,41,13,LEAVES:13)
Block(-5,41,13,LEAVES:13)
Block(2,41,13,LEAVES:13)
Block(-5,41,14,LEAVES:13)
Block(-4,41,14,LEAVES:13)
Block(3,41,14,LEAVES:13)
Block(0,42,-4,LEAVES:13)
Block(0,42,-3,LEAVES:13)
Block(1,42,-2,LEAVES:13)
Block(-1,42,-1,LEAVES:13)
Block(3,42,-1,LEAVES:13)
Block(0,42,0,LOG:13)
Block(0,42,1,LOG:13)
Block(1,42,1,LOG:13)
Block(-4,42,2,LEAVES:13)
Block(-1,42,2,LOG:13)
Block(0,42,2,LOG:13)
Block(1,42,2,LOG:13)
Block(2,42,2,LOG:13)
Block(4,42,2,LEAVES:13)
Block(-4,42,3,LEAVES:13)
Block(-3,42,3,LOG:13)
Block(-1,42,3,LOG:13)
Block(0,42,3,LOG:13)
Block(5,42,3,LEAVES:13)
Block(-4,42,4,LEAVES:13)
Block(0,42,4,LOG:13)
Block(-3,42,5,LEAVES:13)
Block(0,42,5,LOG:13)
Block(-1,42,7,LEAVES:13)
Block(4,42,7,LEAVES:13)
Block(-2,42,8,LEAVES:13)
Block(6,42,8,LEAVES:13)
Block(-2,42,9,LEAVES:13)
Block(0,42,9,LEAVES:13)
Block(2,42,10,LEAVES:13)
Block(-3,42,11,LEAVES:13)
Block(-1,42,11,LEAVES:13)
Block(2,42,11,LEAVES:13)
Block(3,42,11,LEAVES:13)
Block(-4,43,-6,LEAVES:13)
Block(-3,43,-6,LEAVES:13)
Block(-1,43,-2,LEAVES:13)
Block(1,43,-2,LEAVES:13)
Block(1,43,-1,LEAVES:13)
Block(-5,43,0,LEAVES:13)
Block(0,43,0,LOG:13)
Block(-6,43,1,LEAVES:13)
Block(-4,43,1,LEAVES:13)
Block(0,43,1,LOG:13)
Block(1,43,1,LOG:13)
Block(4,43,1,LEAVES:13)
Block(-1,43,2,LOG:13)
Block(0,43,2,LOG:13)
Block(1,43,2,LOG:13)
Block(2,43,2,LOG:13)
Block(3,43,2,LOG:13)
Block(-5,43,3,LEAVES:13)
Block(-2,43,3,LEAVES:13)
Block(-1,43,3,LOG:13)
Block(0,43,3,LOG:13)
Block(1,43,3,LOG:13)
Block(5,43,3,LEAVES:13)
Block(-4,43,4,LOG:13)
Block(0,43,4,LEAVES:13)
Block(1,43,4,LOG:13)
Block(5,43,4,LEAVES:13)
Block(6,43,4,LEAVES:13)
Block(-4,43,5,LEAVES:13)
Block(-1,43,5,LOG:13)
Block(0,43,5,LEAVES:13)
Block(1,43,5,LEAVES:13)
Block(2,43,5,LOG:13)
Block(-3,43,6,LEAVES:13)
Block(-1,43,6,LOG:13)
Block(3,43,6,LOG:13)
Block(-2,43,7,LEAVES:13)
Block(-1,43,7,LOG:13)
Block(5,43,7,LEAVES:13)
Block(-4,43,8,LEAVES:13)
Block(-2,43,8,LEAVES:13)
Block(4,43,8,LEAVES:13)
Block(5,43,8,LEAVES:13)
Block(6,43,8,LEAVES:13)
Block(-3,43,9,LEAVES:13)
Block(-2,43,9,LOG:13)
Block(-1,43,9,LEAVES:13)
Block(0,43,9,LEAVES:13)
Block(3,43,9,LEAVES:13)
Block(5,43,9,LEAVES:13)
Block(6,43,9,LEAVES:13)
Block(7,43,9,LEAVES:13)
Block(-3,43,10,LEAVES:13)
Block(6,43,10,LEAVES:13)
Block(-3,43,11,LEAVES:13)
Block(-2,43,11,LEAVES:13)
Block(-4,44,-8,LEAVES:13)
Block(-3,44,-8,LEAVES:13)
Block(-6,44,-6,LEAVES:13)
Block(-2,44,-6,LEAVES:13)
Block(-5,44,-5,LEAVES:13)
Block(-3,44,-5,LEAVES:13)
Block(-2,44,-5,LEAVES:13)
Block(-1,44,-4,LEAVES:13)
Block(-2,44,-3,LOG:13)
Block(-2,44,-2,LOG:13)
Block(-2,44,-1,LOG:13)
Block(-1,44,-1,LOG:13)
Block(1,44,-1,LEAVES:13)
Block(-3,44,0,LEAVES:13)
Block(-1,44,0,LOG:13)
Block(-2,44,1,LEAVES:13)
Block(-1,44,1,LOG:13)
Block(0,44,1,LOG:13)
Block(1,44,1,LOG:13)
Block(-1,44,2,LOG:13)
Block(0,44,2,LOG:13)
Block(1,44,2,LOG:13)
Block(3,44,2,LEAVES:13)
Block(-6,44,3,LEAVES:13)
Block(-5,44,3,LEAVES:13)
Block(-3,44,3,LEAVES:13)
Block(0,44,3,LOG:13)
Block(3,44,3,LEAVES:13)
Block(4,44,3,LOG:13)
Block(5,44,3,LOG:13)
Block(6,44,3,LEAVES:13)
Block(7,44,3,LEAVES:13)
Block(-2,44,4,LEAVES:13)
Block(5,44,4,LEAVES:13)
Block(6,44,4,LEAVES:13)
Block(7,44,4,LEAVES:13)
Block(-5,44,5,LEAVES:13)
Block(5,44,5,LEAVES:13)
Block(7,44,5,LEAVES:13)
Block(-5,44,6,LEAVES:13)
Block(-3,44,6,LEAVES:13)
Block(-2,44,6,LEAVES:13)
Block(-1,44,6,LEAVES:13)
Block(0,44,6,LEAVES:13)
Block(-3,44,7,LEAVES:13)
Block(4,44,7,LOG:13)
Block(-3,44,8,LEAVES:13)
Block(-2,44,8,LOG:13)
Block(-1,44,8,LEAVES:13)
Block(0,44,8,LEAVES:13)
Block(3,44,8,LEAVES:13)
Block(4,44,8,LEAVES:13)
Block(5,44,8,LOG:13)
Block(0,44,9,LEAVES:13)
Block(5,44,9,LEAVES:13)
Block(6,44,9,LOG:13)
Block(8,44,9,LEAVES:13)
Block(-2,44,10,LEAVES:13)
Block(-1,44,10,LEAVES:13)
Block(5,44,10,LEAVES:13)
Block(6,44,10,LEAVES:13)
Block(-4,45,-8,LEAVES:13)
Block(-5,45,-7,LEAVES:13)
Block(-3,45,-7,LEAVES:13)
Block(-4,45,-6,LOG:13)
Block(-2,45,-6,LEAVES:13)
Block(-1,45,-6,LEAVES:13)
Block(-4,45,-5,LEAVES:13)
Block(-3,45,-5,LOG:13)
Block(-2,45,-5,LEAVES:13)
Block(-1,45,-5,LEAVES:13)
Block(1,45,-5,LEAVES:13)
Block(-3,45,-4,LOG:13)
Block(-2,45,-4,LEAVES:13)
Block(-1,45,-4,LEAVES:13)
Block(-3,45,-3,LEAVES:13)
Block(-1,45,-3,LEAVES:13)
Block(0,45,-3,LEAVES:13)
Block(-1,45,-2,LEAVES:13)
Block(-2,45,-1,LEAVES:13)
Block(-3,45,0,LEAVES:13)
Block(0,45,1,LOG:13)
Block(-1,45,2,LOG:13)
Block(0,45,2,LOG:13)
Block(1,45,2,LOG:13)
Block(-5,45,3,LEAVES:13)
Block(0,45,3,LOG:13)
Block(3,45,4,LEAVES:13)
Block(5,45,4,LEAVES:13)
Block(6,45,4,LOG:13)
Block(4,45,5,LEAVES:13)
Block(6,45,6,LEAVES:13)
Block(7,45,6,LEAVES:13)
Block(-1,45,7,LEAVES:13)
Block(5,45,7,LEAVES:13)
Block(6,45,7,LEAVES:13)
Block(-2,45,8,LEAVES:13)
Block(4,45,8,LEAVES:13)
Block(-3,45,9,LEAVES:13)
Block(-2,45,9,LEAVES:13)
Block(4,45,9,LEAVES:13)
Block(6,45,9,LEAVES:13)
Block(-1,45,10,LEAVES:13)
Block(5,45,10,LEAVES:13)
Block(6,45,10,LEAVES:13)
Block(-5,46,-7,LEAVES:13)
Block(-3,46,-7,LEAVES:13)
Block(-3,46,-6,LEAVES:13)
Block(-2,46,-6,LEAVES:13)
Block(-4,46,-5,LEAVES:13)
Block(-3,46,-5,LEAVES:13)
Block(-1,46,-5,LEAVES:13)
Block(-5,46,-4,LEAVES:13)
Block(-4,46,-4,LEAVES:13)
Block(-1,46,-2,LEAVES:13)
Block(-1,46,-1,LEAVES:13)
Block(0,46,1,LOG:13)
Block(-1,46,2,LOG:13)
Block(0,46,2,LOG:13)
Block(1,46,2,LOG:13)
Block(6,46,2,LEAVES:13)
Block(0,46,3,LOG:13)
Block(4,46,3,LEAVES:13)
Block(5,46,3,LEAVES:13)
Block(4,46,4,LEAVES:13)
Block(5,46,4,LEAVES:13)
Block(3,46,5,LEAVES:13)
Block(6,46,5,LEAVES:13)
Block(2,46,6,LEAVES:13)
Block(4,46,7,LEAVES:13)
Block(5,46,7,LEAVES:13)
Block(6,46,7,LEAVES:13)
Block(5,46,8,LEAVES:13)
Block(-2,46,9,LEAVES:13)
Block(4,46,10,LEAVES:13)
Block(5,46,10,LEAVES:13)
Block(-5,47,-6,LEAVES:13)
Block(-3,47,-6,LEAVES:13)
Block(-2,47,-5,LEAVES:13)
Block(-1,47,-4,LEAVES:13)
Block(-4,47,-3,LEAVES:13)
Block(2,47,-2,LEAVES:13)
Block(3,47,-2,LEAVES:13)
Block(-1,47,-1,LOG:13)
Block(0,47,-1,LOG:13)
Block(2,47,-1,LEAVES:13)
Block(0,47,0,LOG:13)
Block(0,47,1,LOG:13)
Block(-1,47,2,LOG:13)
Block(0,47,2,LOG:13)
Block(1,47,2,LOG:13)
Block(0,47,3,LOG:13)
Block(1,47,3,LOG:13)
Block(2,47,4,LOG:13)
Block(5,47,9,LEAVES:13)
Block(6,47,9,LEAVES:13)
Block(0,48,-7,LEAVES:13)
Block(0,48,-6,LEAVES:13)
Block(1,48,-6,LEAVES:13)
Block(-3,48,-5,LEAVES:13)
Block(1,48,-5,LEAVES:13)
Block(-1,48,-3,LEAVES:13)
Block(1,48,-3,LOG:13)
Block(2,48,-3,LEAVES:13)
Block(-2,48,-2,LOG:13)
Block(1,48,-2,LOG:13)
Block(2,48,-2,LOG:13)
Block(5,48,-2,LEAVES:13)
Block(-3,48,-1,LEAVES:13)
Block(1,48,-1,LEAVES:13)
Block(5,48,-1,LEAVES:13)
Block(4,48,0,LEAVES:13)
Block(5,48,0,LEAVES:13)
Block(0,48,1,LOG:13)
Block(4,48,1,LEAVES:13)
Block(-1,48,2,LOG:13)
Block(0,48,2,LOG:13)
Block(1,48,2,LOG:13)
Block(0,48,3,LOG:13)
Block(3,48,5,LOG:13)
Block(5,48,5,LEAVES:13)
Block(1,48,6,LEAVES:13)
Block(2,48,6,LEAVES:13)
Block(3,48,6,LOG:13)
Block(5,48,6,LEAVES:13)
Block(3,48,8,LEAVES:13)
Block(1,49,-8,LEAVES:13)
Block(2,49,-8,LEAVES:13)
Block(2,49,-7,LEAVES:13)
Block(1,49,-6,LEAVES:13)
Block(-2,49,-5,LEAVES:13)
Block(1,49,-5,LOG:13)
Block(2,49,-5,LEAVES:13)
Block(0,49,-4,LEAVES:13)
Block(1,49,-4,LOG:13)
Block(4,49,-4,LEAVES:13)
Block(-3,49,-3,LOG:13)
Block(-2,49,-3,LEAVES:13)
Block(3,49,-3,LOG:13)
Block(4,49,-3,LOG:13)
Block(-2,49,-2,LEAVES:13)
Block(-3,49,-1,LEAVES:13)
Block(3,49,-1,LOG:13)
Block(1,49,0,LEAVES:13)
Block(0,49,1,LOG:13)
Block(-2,49,2,LOG:13)
Block(-1,49,2,LOG:13)
Block(0,49,2,LOG:13)
Block(1,49,2,LOG:13)
Block(0,49,3,LOG:13)
Block(0,49,4,LOG:13)
Block(0,49,5,LOG:13)
Block(5,49,5,LEAVES:13)
Block(3,49,6,LEAVES:13)
Block(4,49,6,LEAVES:13)
Block(-2,49,7,LEAVES:13)
Block(5,49,7,LEAVES:13)
Block(3,49,8,LEAVES:13)
Block(4,49,8,LEAVES:13)
Block(2,50,-9,LEAVES:13)
Block(-1,50,-8,LEAVES:13)
Block(0,50,-8,LEAVES:13)
Block(1,50,-8,LEAVES:13)
Block(3,50,-8,LEAVES:13)
Block(0,50,-7,LEAVES:13)
Block(1,50,-7,LOG:13)
Block(3,50,-7,LEAVES:13)
Block(-1,50,-6,LEAVES:13)
Block(1,50,-6,LOG:13)
Block(3,50,-6,LEAVES:13)
Block(1,50,-5,LEAVES:13)
Block(-3,50,-4,LEAVES:13)
Block(5,50,-4,LEAVES:13)
Block(4,50,-3,LEAVES:13)
Block(5,50,-3,LOG:13)
Block(6,50,-3,LEAVES:13)
Block(1,50,-2,LEAVES:13)
Block(4,50,-2,LEAVES:13)
Block(7,50,-2,LEAVES:13)
Block(-4,50,-1,LEAVES:13)
Block(2,50,-1,LEAVES:13)
Block(4,50,-1,LEAVES:13)
Block(5,50,-1,LEAVES:13)
Block(-6,50,0,LEAVES:13)
Block(0,50,1,LOG:13)
Block(-3,50,2,LOG:13)
Block(-1,50,2,LOG:13)
Block(0,50,2,LOG:13)
Block(1,50,2,LOG:13)
Block(0,50,3,LOG:13)
Block(5,50,3,LEAVES:13)
Block(-4,50,5,LEAVES:13)
Block(2,50,5,LEAVES:13)
Block(4,50,5,LEAVES:13)
Block(-3,50,6,LEAVES:13)
Block(-1,50,6,LEAVES:13)
Block(0,50,6,LOG:13)
Block(-6,50,7,LEAVES:13)
Block(0,50,7,LOG:13)
Block(-3,50,8,LEAVES:13)
Block(0,50,8,LEAVES:13)
Block(1,50,8,LEAVES:13)
Block(-3,50,9,LEAVES:13)
Block(-2,50,9,LEAVES:13)
Block(-1,50,9,LEAVES:13)
Block(-1,50,10,LEAVES:13)
Block(1,51,-8,LEAVES:13)
Block(0,51,-7,LEAVES:13)
Block(0,51,-6,LEAVES:13)
Block(2,51,-6,LEAVES:13)
Block(4,51,-5,LEAVES:13)
Block(-3,51,-4,LEAVES:13)
Block(2,51,-4,LEAVES:13)
Block(5,51,-3,LEAVES:13)
Block(3,51,-2,LEAVES:13)
Block(-5,51,1,LOG:13)
Block(-4,51,1,LOG:13)
Block(0,51,1,LOG:13)
Block(-1,51,2,LOG:13)
Block(0,51,2,LOG:13)
Block(1,51,2,LOG:13)
Block(-1,51,3,LOG:13)
Block(0,51,3,LOG:13)
Block(3,51,3,LEAVES:13)
Block(-8,51,4,LEAVES:13)
Block(-2,51,4,LOG:13)
Block(4,51,4,LEAVES:13)
Block(6,51,4,LEAVES:13)
Block(-4,51,5,LEAVES:13)
Block(-2,51,5,LOG:13)
Block(-5,51,6,LEAVES:13)
Block(-3,51,6,LOG:13)
Block(5,51,6,LEAVES:13)
Block(-4,51,7,LOG:13)
Block(-1,51,7,LEAVES:13)
Block(-2,51,8,LEAVES:13)
Block(-1,51,8,LOG:13)
Block(-1,51,10,LEAVES:13)
Block(0,52,-6,LEAVES:13)
Block(-6,52,-2,LEAVES:13)
Block(-3,52,-2,LEAVES:13)
Block(-2,52,-2,LEAVES:13)
Block(-2,52,-1,LEAVES:13)
Block(-1,52,-1,LEAVES:13)
Block(-6,52,0,LOG:13)
Block(0,52,1,LOG:13)
Block(-6,52,2,LOG:13)
Block(-1,52,2,LOG:13)
Block(0,52,2,LOG:13)
Block(1,52,2,LOG:13)
Block(5,52,2,LEAVES:13)
Block(-10,52,3,LEAVES:13)
Block(0,52,3,LOG:13)
Block(6,52,3,LEAVES:13)
Block(4,52,4,LOG:13)
Block(5,52,4,LOG:13)
Block(7,52,4,LEAVES:13)
Block(-9,52,5,LEAVES:13)
Block(-8,52,5,LEAVES:13)
Block(-8,52,6,LEAVES:13)
Block(-6,52,6,LEAVES:13)
Block(4,52,6,LEAVES:13)
Block(5,52,6,LEAVES:13)
Block(6,52,6,LEAVES:13)
Block(-5,52,7,LEAVES:13)
Block(-4,52,7,LEAVES:13)
Block(0,52,7,LEAVES:13)
Block(-3,52,8,LEAVES:13)
Block(-2,52,8,LEAVES:13)
Block(-1,52,8,LEAVES:13)
Block(-3,52,9,LEAVES:13)
Block(1,52,9,LEAVES:13)
Block(-1,52,10,LEAVES:13)
Block(-6,53,-2,LEAVES:13)
Block(-6,53,-1,LEAVES:13)
Block(-6,53,0,LEAVES:13)
Block(-1,53,0,LOG:13)
Block(-1,53,1,LOG:13)
Block(0,53,1,LOG:13)
Block(-9,53,2,LEAVES:13)
Block(-5,53,2,LEAVES:13)
Block(-1,53,2,LOG:13)
Block(0,53,2,LOG:13)
Block(1,53,2,LOG:13)
Block(-7,53,3,LOG:13)
Block(2,53,3,LOG:13)
Block(3,53,3,LOG:13)
Block(6,53,3,LEAVES:13)
Block(-8,53,4,LOG:13)
Block(-7,53,4,LEAVES:13)
Block(6,53,4,LEAVES:13)
Block(7,53,4,LEAVES:13)
Block(4,53,5,LEAVES:13)
Block(6,53,5,LEAVES:13)
Block(-4,53,6,LEAVES:13)
Block(-3,53,8,LEAVES:13)
Block(-2,53,8,LEAVES:13)
Block(-3,54,-3,LEAVES:13)
Block(-2,54,-3,LEAVES:13)
Block(-4,54,-2,LEAVES:13)
Block(-5,54,-1,LEAVES:13)
Block(-2,54,-1,LOG:13)
Block(-1,54,0,LEAVES:13)
Block(-5,54,1,LEAVES:13)
Block(0,54,1,LOG:13)
Block(1,54,1,LOG:13)
Block(-2,54,2,LEAVES:13)
Block(-1,54,2,LOG:13)
Block(0,54,2,LOG:13)
Block(1,54,2,LOG:13)
Block(-9,54,3,LEAVES:13)
Block(0,54,3,LEAVES:13)
Block(-7,54,4,LEAVES:13)
Block(-2,54,4,LEAVES:13)
Block(4,54,4,LEAVES:13)
Block(5,54,4,LEAVES:13)
Block(6,54,4,LEAVES:13)
Block(-5,55,-2,LEAVES:13)
Block(-3,55,-2,LOG:13)
Block(-4,55,-1,LEAVES:13)
Block(-4,55,0,LEAVES:13)
Block(2,55,0,LOG:13)
Block(0,55,1,LOG:13)
Block(-1,55,2,LOG:13)
Block(0,55,2,LOG:13)
Block(1,55,2,LOG:13)
Block(2,55,2,LEAVES:13)
Block(-8,55,3,LEAVES:13)
Block(0,55,3,LOG:13)
Block(1,55,3,LEAVES:13)
Block(-2,55,4,LEAVES:13)
Block(-7,55,5,LEAVES:13)
Block(1,55,5,LEAVES:13)
Block(-3,56,-3,LEAVES:13)
Block(-5,56,-2,LEAVES:13)
Block(-3,56,-2,LOG:13)
Block(-2,56,-2,LEAVES:13)
Block(-2,56,-1,LEAVES:13)
Block(-4,56,0,LEAVES:13)
Block(2,56,0,LOG:13)
Block(3,56,0,LEAVES:13)
Block(0,56,1,LOG:13)
Block(3,56,1,LEAVES:13)
Block(-1,56,2,LEAVES:13)
Block(0,56,2,LOG:13)
Block(1,56,2,LOG:13)
Block(2,56,3,LEAVES:13)
Block(-1,56,4,LOG:13)
Block(1,56,5,LEAVES:13)
Block(-4,57,-4,LEAVES:13)
Block(-4,57,-3,LEAVES:13)
Block(1,57,-3,LEAVES:13)
Block(2,57,-2,LEAVES:13)
Block(2,57,-1,LOG:13)
Block(3,57,-1,LOG:13)
Block(0,57,1,LOG:13)
Block(0,57,2,LOG:13)
Block(1,57,2,LOG:13)
Block(2,57,2,LEAVES:13)
Block(-1,57,3,LEAVES:13)
Block(1,57,3,LEAVES:13)
Block(0,57,4,LEAVES:13)
Block(2,58,-3,LEAVES:13)
Block(-3,58,-2,LEAVES:13)
Block(1,58,-2,LEAVES:13)
Block(3,58,-2,LEAVES:13)
Block(2,58,-1,LOG:13)
Block(3,58,0,LEAVES:13)
Block(4,58,0,LOG:13)
Block(5,58,1,LEAVES:13)
Block(0,58,2,LOG:13)
Block(-2,58,4,LEAVES:13)
Block(-1,58,5,LEAVES:13)
Block(1,59,-4,LEAVES:13)
Block(2,59,-4,LEAVES:13)
Block(1,59,-3,LEAVES:13)
Block(3,59,-3,LEAVES:13)
Block(0,59,-2,LEAVES:13)
Block(1,59,-2,LOG:13)
Block(2,59,-2,LEAVES:13)
Block(2,59,-1,LEAVES:13)
Block(3,59,-1,LEAVES:13)
Block(4,59,-1,LEAVES:13)
Block(-1,59,0,LEAVES:13)
Block(2,59,0,LEAVES:13)
Block(3,59,0,LEAVES:13)
Block(4,59,0,LOG:13)
Block(6,59,0,LEAVES:13)
Block(-1,59,1,LEAVES:13)
Block(3,59,1,LEAVES:13)
Block(4,59,1,LEAVES:13)
Block(-3,59,2,LEAVES:13)
Block(0,59,2,LOG:13)
Block(4,59,2,LEAVES:13)
Block(5,59,2,LEAVES:13)
Block(-2,59,3,LEAVES:13)
Block(-1,59,3,LOG:13)
Block(1,59,3,LEAVES:13)
Block(0,60,-4,LEAVES:13)
Block(2,60,-4,LEAVES:13)
Block(1,60,-3,LEAVES:13)
Block(-1,60,-2,LEAVES:13)
Block(1,60,-2,LOG:13)
Block(2,60,-2,LEAVES:13)
Block(3,60,-2,LEAVES:13)
Block(-2,60,-1,LEAVES:13)
Block(-1,60,-1,LEAVES:13)
Block(0,60,-1,LEAVES:13)
Block(1,60,-1,LEAVES:13)
Block(2,60,-1,LEAVES:13)
Block(5,60,-1,LOG:13)
Block(-3,60,0,LEAVES:13)
Block(1,60,0,LEAVES:13)
Block(4,60,0,LEAVES:13)
Block(-1,60,1,LOG:13)
Block(4,60,1,LEAVES:13)
Block(6,60,1,LEAVES:13)
Block(-2,60,2,LEAVES:13)
Block(0,60,2,LOG:13)
Block(-3,60,3,LEAVES:13)
Block(-2,60,3,LEAVES:13)
Block(0,60,3,LEAVES:13)
Block(-2,60,4,LOG:13)
Block(1,61,-4,LEAVES:13)
Block(0,61,-2,LEAVES:13)
Block(1,61,-2,LEAVES:13)
Block(2,61,-2,LEAVES:13)
Block(5,61,-2,LEAVES:13)
Block(2,61,-1,LEAVES:13)
Block(4,61,-1,LEAVES:13)
Block(5,61,-1,LOG:13)
Block(-2,61,0,LOG:13)
Block(1,61,0,LEAVES:13)
Block(5,61,0,LEAVES:13)
Block(-1,61,1,LEAVES:13)
Block(4,61,1,LEAVES:13)
Block(0,61,2,LOG:13)
Block(1,61,2,LEAVES:13)
Block(-2,61,3,LEAVES:13)
Block(-1,61,3,LEAVES:13)
Block(-1,61,4,LEAVES:13)
Block(1,62,-2,LEAVES:13)
Block(1,62,-1,LEAVES:13)
Block(3,62,-1,LEAVES:13)
Block(5,62,-1,LEAVES:13)
Block(-1,62,1,LEAVES:13)
Block(1,62,1,LEAVES:13)
Block(0,62,2,LOG:13)
Block(3,62,2,LEAVES:13)
Block(1,62,5,LEAVES:13)
Block(2,62,5,LEAVES:13)
Block(-2,63,0,LEAVES:13)
Block(2,63,1,LEAVES:13)
Block(0,63,2,LOG:13)
Block(1,63,3,LOG:13)
Block(3,63,3,LEAVES:13)
Block(-1,63,4,LEAVES:13)
Block(3,63,4,LEAVES:13)
Block(1,63,5,LEAVES:13)
Block(-2,64,0,LEAVES:13)
Block(0,64,2,LOG:13)
Block(1,64,3,LEAVES:13)
Block(2,64,4,LOG:13)
Block(0,64,5,LEAVES:13)
Block(-1,65,0,LEAVES:13)
Block(-2,65,1,LEAVES:13)
Block(-1,65,1,LOG:13)
Block(0,65,2,LOG:13)
Block(1,65,3,LEAVES:13)
Block(2,65,4,LEAVES:13)
Block(-1,66,0,LEAVES:13)
Block(1,66,1,LEAVES:13)
Block(0,66,2,LOG:13)
Block(-1,66,3,LEAVES:13)
Block(-1,67,1,LEAVES:13)
Block(1,67,1,LEAVES:13)
Block(0,67,2,LOG:13)
Block(-1,67,3,LEAVES:13)
Block(0,68,1,LEAVES:13)
Block(-1,68,2,LEAVES:13)
Block(0,68,2,LEAVES:13)
Block(1,68,2,LEAVES:13)
Block(0,68,3,LEAVES:13)
Block(0,69,2,LEAVES:13)
Block(1,69,2,LEAVES:13)
Block(0,70,2,LEAVES:13)
Block(1,70,2,LEAVES:13)
Block(0,71,2,LEAVES:13)
Block(0,72,2,LEAVES:5)

#######################################################################
# +-----------------------------------------------------------------+ #
# |                            BO3 checks                           | #
# +-----------------------------------------------------------------+ #
#######################################################################

# Require a condition at a certain location in order for the BO3 to be spawned.
# BlockCheck(x,y,z,BlockName[,BlockName[,...]]) - one of the blocks must be at the location
# BlockCheckNot(x,y,z,BlockName[,BlockName[,...]]) - all the blocks must not be at the location
# LightCheck(x,y,z,minLightLevel,maxLightLevel) - light must be between min and max (inclusive)

# You can use "Solid" as a BlockName for matching all solid blocks or "All" to match all blocks that aren't air.

# Examples:
BlockCheck(0,-1,0,GRASS,DIRT,DIRT:2,DIRT:1,SAND)
#   BlockCheck(0,-1,0,Solid)       Require any solid block just below the object
#   BlockCheck(0,-1,0,WOOL)        Require any type of wool just below the object
#   BlockCheck(0,-1,0,WOOL:0)      Require white wool just below the object
#   BlockCheckNot(0,-1,0,WOOL:0)   Require that there is no white wool below the object
#   LightCheck(0,0,0,0,1)          Require almost complete darkness just below the object

#######################################################################
# +-----------------------------------------------------------------+ #
# |                             Branches                            | #
# +-----------------------------------------------------------------+ #
#######################################################################

# Branches are objects that will spawn when this object spawns when it is used in
# the CustomStructure resource. Branches can also have branches, making complex
# structures possible. See the wiki for more details.

# Regular Branches spawn each branch with an independent chance of spawning.
# Branch(x,y,z,branchName,rotation,chance[,anotherBranchName,rotation,chance[,...]][IndividualChance])
# branchName - name of the object to spawn.
# rotation - NORTH, SOUTH, EAST or WEST.
# IndividualChance - The chance each branch has to spawn, assumed to be 100 when left blank

# Weighted Branches spawn branches with a dependent chance of spawning.
# WeightedBranch(x,y,z,branchName,rotation,chance[,anotherBranchName,rotation,chance[,...]][MaxChanceOutOf])
# MaxChanceOutOf - The chance all branches have to spawn out of, assumed to be 100 when left blank

