#######################################################################
# +-----------------------------------------------------------------+ #
# |                            BO3 object                           | #
# +-----------------------------------------------------------------+ #
#######################################################################

# This is the config file of a custom object.
# If you add this object correctly to your BiomeConfigs, it will spawn in the world.

# This is the creator of this BO3 object
Author: BO3 BulkEdit (by LanToaster)

# A short description of this BO3 object
Description: This Object was Created with BO3_BulkEdit

# The BO3 version, don't change this! It can be used by external applications to do a version check.
Version: 3

# The settings mode, WriteAll, WriteWithoutComments or WriteDisable. See WorldConfig.
SettingsMode: WriteDisable


#######################################################################
# +-----------------------------------------------------------------+ #
# |                          Main settings                          | #
# +-----------------------------------------------------------------+ #
#######################################################################

# This needs to be set to true to spawn the object in the Tree and Sapling resources.
Tree: true

# The frequency of the BO3 from 1 to 200. Tries this many times to spawn this BO3 when using the CustomObject(...) resource.
# Ignored by Tree(..), Sapling(..) and CustomStructure(..)
Frequency: 1

# The rarity of the BO3 from 0 to 100. Each spawn attempt has rarity% chance to succeed when using the CustomObject(...) resource.
# Ignored by Tree(..), Sapling(..) and CustomStructure(..)
Rarity: 100

# If you set this to true, the BO3 will be placed with a random rotation.
RotateRandomly: True

# The spawn height of the BO3 - randomY, highestBlock or highestSolidBlock.
SpawnHeight: highestSolidBlock

# The height limits for the BO3.
MinHeight: 0

MaxHeight: 200

# Objects can have other objects attacthed to it: branches. Branches can also
# have branches attached to it, which can also have branches, etc. This is the
# maximum branch depth for this objects.
MaxBranchDepth: 10

# When spawned with the UseWorld keyword, this BO3 should NOT spawn in the following biomes.
# If you writer.write the BO3 name directly in the BiomeConfigs, this will be ignored.
ExcludedBiomes: All


#######################################################################
# +-----------------------------------------------------------------+ #
# |                      Source block settings                      | #
# +-----------------------------------------------------------------+ #
#######################################################################

# The block(s) the BO3 should spawn in.
SourceBlocks: AIR

# The maximum percentage of the BO3 that can be outside the SourceBlock.
# The BO3 won't be placed on a location with more blocks outside the SourceBlock than this percentage.
MaxPercentageOutsideSourceBlock: 0

# What to do when a block is about to be placed outside the SourceBlock? (dontPlace, placeAnyway)
OutsideSourceBlock: dontPlace


#######################################################################
# +-----------------------------------------------------------------+ #
# |                              Blocks                             | #
# +-----------------------------------------------------------------+ #
#######################################################################

# All the blocks used in the BO3 are listed here. Possible blocks:
# Block(x,y,z,id[.data][,nbtfile.nbt)
# RandomBlock(x,y,z,id[:data][,nbtfile.nbt],chance[,id[:data][,nbtfile.nbt],chance[,...]])
# So RandomBlock(0,0,0,CHEST,chest.nbt,50,CHEST,anotherchest.nbt,100) will spawn a chest at
# the BO3 origin, and give it a 50% chance to have the contents of chest.nbt, or, if that
# fails, a 100% percent chance to have the contents of anotherchest.nbt.
Block(-3,0,1,LOG:1)
Block(-2,0,1,LOG:1)
Block(-3,0,2,LOG:1)
Block(-2,0,2,LOG:1)
Block(-3,1,1,LOG:1)
Block(-2,1,1,LOG:1)
Block(-3,1,2,LOG:1)
Block(-2,1,2,LOG:1)
Block(-3,2,1,LOG:1)
Block(-2,2,1,LOG:1)
Block(-3,2,2,LOG:1)
Block(-2,2,2,LOG:1)
Block(-3,3,1,LOG:1)
Block(-2,3,1,LOG:1)
Block(-3,3,2,LOG:1)
Block(-2,3,2,LOG:1)
Block(-3,4,1,LOG:1)
Block(-2,4,1,LOG:1)
Block(-3,4,2,LOG:1)
Block(-2,4,2,LOG:1)
Block(-3,5,1,LOG:1)
Block(-2,5,1,LOG:1)
Block(-3,5,2,LOG:1)
Block(-2,5,2,LOG:1)
Block(-3,6,1,LOG:1)
Block(-2,6,1,LOG:1)
Block(-3,6,2,LOG:1)
Block(-2,6,2,LOG:1)
Block(-3,7,1,LOG:1)
Block(-2,7,1,LOG:1)
Block(-3,7,2,LOG:1)
Block(-2,7,2,LOG:1)
Block(-3,8,1,LOG:1)
Block(-2,8,1,LOG:1)
Block(-3,8,2,LOG:1)
Block(-2,8,2,LOG:1)
Block(-3,9,1,LOG:1)
Block(-2,9,1,LOG:1)
Block(-3,9,2,LOG:1)
Block(-2,9,2,LOG:1)
Block(-3,10,1,LOG:1)
Block(-2,10,1,LOG:1)
Block(-3,10,2,LOG:1)
Block(-2,10,2,LOG:1)
Block(-7,11,-1,LEAVES:1)
Block(-4,11,-1,LEAVES:1)
Block(-9,11,0,LEAVES:1)
Block(-8,11,0,LEAVES:1)
Block(-7,11,0,LEAVES:1)
Block(-6,11,0,LEAVES:1)
Block(-10,11,1,LEAVES:1)
Block(-4,11,1,LEAVES:1)
Block(-3,11,1,LOG:1)
Block(-2,11,1,LOG:1)
Block(-9,11,2,LEAVES:1)
Block(-8,11,2,LEAVES:1)
Block(-7,11,2,LEAVES:1)
Block(-4,11,2,LOG:1)
Block(-3,11,2,LOG:1)
Block(-2,11,2,LOG:1)
Block(-8,11,3,LEAVES:1)
Block(-6,11,3,LOG:1)
Block(-5,11,3,LOG:1)
Block(-4,11,3,LEAVES:1)
Block(-3,11,3,LEAVES:1)
Block(-6,11,4,LEAVES:1)
Block(-3,11,5,LEAVES:1)
Block(-2,11,5,LEAVES:1)
Block(-6,11,6,LEAVES:1)
Block(-4,11,6,LEAVES:1)
Block(-4,11,7,LEAVES:1)
Block(-6,12,-9,LEAVES:1)
Block(-5,12,-9,LEAVES:1)
Block(-4,12,-9,LEAVES:1)
Block(-3,12,-9,LEAVES:1)
Block(-5,12,-8,LEAVES:1)
Block(-2,12,-8,LEAVES:1)
Block(-7,12,-7,LEAVES:1)
Block(-6,12,-7,LEAVES:1)
Block(-4,12,-7,LEAVES:1)
Block(-2,12,-7,LEAVES:1)
Block(0,12,-7,LEAVES:1)
Block(1,12,-7,LEAVES:1)
Block(-6,12,-6,LEAVES:1)
Block(-5,12,-6,LEAVES:1)
Block(-4,12,-6,LEAVES:1)
Block(-1,12,-6,LEAVES:1)
Block(-6,12,-5,LEAVES:1)
Block(-5,12,-5,LOG:1)
Block(-4,12,-5,LEAVES:1)
Block(-3,12,-5,LEAVES:1)
Block(-2,12,-5,LEAVES:1)
Block(1,12,-5,LEAVES:1)
Block(-8,12,-4,LEAVES:1)
Block(-7,12,-4,LEAVES:1)
Block(-5,12,-4,LOG:1)
Block(-3,12,-4,LEAVES:1)
Block(-1,12,-4,LEAVES:1)
Block(3,12,-4,LEAVES:1)
Block(-9,12,-3,LEAVES:1)
Block(-5,12,-3,LEAVES:1)
Block(-4,12,-3,LOG:1)
Block(-3,12,-3,LEAVES:1)
Block(-2,12,-3,LEAVES:1)
Block(-1,12,-3,LOG:1)
Block(0,12,-3,LEAVES:1)
Block(1,12,-3,LEAVES:1)
Block(3,12,-3,LEAVES:1)
Block(-6,12,-2,LEAVES:1)
Block(-5,12,-2,LEAVES:1)
Block(-4,12,-2,LOG:1)
Block(-2,12,-2,LOG:1)
Block(-1,12,-2,LEAVES:1)
Block(1,12,-2,LEAVES:1)
Block(3,12,-2,LEAVES:1)
Block(-7,12,-1,LEAVES:1)
Block(-6,12,-1,LEAVES:1)
Block(-5,12,-1,LEAVES:1)
Block(-4,12,-1,LEAVES:1)
Block(-3,12,-1,LOG:1)
Block(-2,12,-1,LEAVES:1)
Block(-1,12,-1,LEAVES:1)
Block(3,12,-1,LEAVES:1)
Block(-3,12,0,LOG:1)
Block(-1,12,0,LEAVES:1)
Block(-3,12,1,LOG:1)
Block(-2,12,1,LOG:1)
Block(-1,12,1,LEAVES:1)
Block(-3,12,2,LOG:1)
Block(-2,12,2,LOG:1)
Block(-1,13,-3,LEAVES:1)
Block(-2,13,-2,LEAVES:1)
Block(-1,13,-2,LEAVES:1)
Block(-5,13,-1,LEAVES:1)
Block(0,13,-1,LEAVES:1)
Block(1,13,-1,LEAVES:1)
Block(-5,13,0,LEAVES:1)
Block(-4,13,0,LEAVES:1)
Block(-3,13,0,LEAVES:1)
Block(-7,13,1,LEAVES:1)
Block(-5,13,1,LEAVES:1)
Block(-4,13,1,LEAVES:1)
Block(-3,13,1,LOG:1)
Block(-2,13,1,LOG:1)
Block(0,13,1,LEAVES:1)
Block(-5,13,2,LEAVES:1)
Block(-3,13,2,LOG:1)
Block(-2,13,2,LOG:1)
Block(-6,13,3,LEAVES:1)
Block(-3,13,3,LEAVES:1)
Block(-1,13,4,LEAVES:1)
Block(-3,14,1,LOG:1)
Block(-2,14,1,LOG:1)
Block(-3,14,2,LOG:1)
Block(-2,14,2,LOG:1)
Block(-7,15,-4,LEAVES:1)
Block(0,15,-4,LEAVES:1)
Block(1,15,-4,LEAVES:1)
Block(-7,15,-3,LEAVES:1)
Block(-6,15,-3,LEAVES:1)
Block(-5,15,-3,LEAVES:1)
Block(1,15,-3,LEAVES:1)
Block(2,15,-3,LEAVES:1)
Block(3,15,-3,LEAVES:1)
Block(4,15,-3,LEAVES:1)
Block(-6,15,-2,LEAVES:1)
Block(-5,15,-2,LEAVES:1)
Block(-2,15,-2,LEAVES:1)
Block(0,15,-2,LEAVES:1)
Block(3,15,-2,LEAVES:1)
Block(-5,15,-1,LEAVES:1)
Block(-2,15,-1,LEAVES:1)
Block(5,15,-1,LEAVES:1)
Block(-9,15,0,LEAVES:1)
Block(-8,15,0,LEAVES:1)
Block(-5,15,0,LOG:1)
Block(-4,15,0,LEAVES:1)
Block(-3,15,0,LEAVES:1)
Block(-2,15,0,LEAVES:1)
Block(-1,15,0,LEAVES:1)
Block(1,15,0,LOG:1)
Block(2,15,0,LEAVES:1)
Block(3,15,0,LEAVES:1)
Block(4,15,0,LEAVES:1)
Block(5,15,0,LEAVES:1)
Block(-7,15,1,LEAVES:1)
Block(-4,15,1,LOG:1)
Block(-3,15,1,LOG:1)
Block(-2,15,1,LOG:1)
Block(-1,15,1,LOG:1)
Block(0,15,1,LOG:1)
Block(1,15,1,LEAVES:1)
Block(2,15,1,LEAVES:1)
Block(3,15,1,LEAVES:1)
Block(-8,15,2,LEAVES:1)
Block(-3,15,2,LOG:1)
Block(-2,15,2,LOG:1)
Block(0,15,2,LEAVES:1)
Block(1,15,2,LEAVES:1)
Block(2,15,2,LEAVES:1)
Block(3,15,2,LEAVES:1)
Block(5,15,2,LEAVES:1)
Block(-6,15,3,LEAVES:1)
Block(-4,15,3,LEAVES:1)
Block(-2,15,3,LEAVES:1)
Block(0,15,3,LEAVES:1)
Block(2,15,3,LEAVES:1)
Block(4,15,3,LEAVES:1)
Block(-6,15,4,LEAVES:1)
Block(-3,15,4,LEAVES:1)
Block(-1,15,4,LEAVES:1)
Block(-5,16,-3,LEAVES:1)
Block(-3,16,-3,LEAVES:1)
Block(-2,16,-3,LEAVES:1)
Block(-4,16,-2,LEAVES:1)
Block(0,16,-2,LEAVES:1)
Block(-5,16,-1,LEAVES:1)
Block(-4,16,0,LEAVES:1)
Block(-7,16,1,LEAVES:1)
Block(-6,16,1,LEAVES:1)
Block(-5,16,1,LEAVES:1)
Block(-4,16,1,LEAVES:1)
Block(-3,16,1,LOG:1)
Block(-2,16,1,LOG:1)
Block(-1,16,1,LEAVES:1)
Block(0,16,1,LEAVES:1)
Block(1,16,1,LEAVES:1)
Block(-3,16,2,LOG:1)
Block(-2,16,2,LOG:1)
Block(-7,16,3,LEAVES:1)
Block(-3,16,3,LEAVES:1)
Block(-6,16,4,LEAVES:1)
Block(-3,16,4,LEAVES:1)
Block(0,16,4,LEAVES:1)
Block(-3,16,5,LEAVES:1)
Block(-2,16,5,LEAVES:1)
Block(-1,16,5,LEAVES:1)
Block(-3,17,1,LOG:1)
Block(-2,17,1,LEAVES:1)
Block(-1,17,1,LEAVES:1)
Block(1,17,1,LEAVES:1)
Block(-3,17,2,LOG:1)
Block(-2,17,2,LOG:1)
Block(-4,17,3,LEAVES:1)
Block(-2,17,3,LOG:1)
Block(-1,17,3,LEAVES:1)
Block(2,17,3,LEAVES:1)
Block(-5,17,4,LEAVES:1)
Block(-2,17,4,LOG:1)
Block(-1,17,4,LEAVES:1)
Block(2,17,4,LEAVES:1)
Block(-6,17,5,LEAVES:1)
Block(-5,17,5,LEAVES:1)
Block(-1,17,5,LOG:1)
Block(0,17,5,LOG:1)
Block(2,17,5,LEAVES:1)
Block(-5,17,6,LEAVES:1)
Block(-3,17,6,LEAVES:1)
Block(-1,17,6,LOG:1)
Block(1,17,6,LOG:1)
Block(2,17,6,LEAVES:1)
Block(3,17,6,LEAVES:1)
Block(4,17,6,LEAVES:1)
Block(5,17,6,LEAVES:1)
Block(-7,17,7,LEAVES:1)
Block(-3,17,7,LEAVES:1)
Block(-2,17,7,LOG:1)
Block(0,17,7,LEAVES:1)
Block(1,17,7,LEAVES:1)
Block(2,17,7,LOG:1)
Block(3,17,7,LEAVES:1)
Block(4,17,7,LEAVES:1)
Block(5,17,7,LEAVES:1)
Block(-4,17,8,LEAVES:1)
Block(-3,17,8,LOG:1)
Block(-1,17,8,LEAVES:1)
Block(0,17,8,LEAVES:1)
Block(2,17,8,LEAVES:1)
Block(-7,17,9,LEAVES:1)
Block(-1,17,9,LEAVES:1)
Block(1,17,9,LEAVES:1)
Block(2,17,9,LEAVES:1)
Block(-7,17,10,LEAVES:1)
Block(-5,17,10,LEAVES:1)
Block(-3,17,10,LEAVES:1)
Block(0,17,10,LEAVES:1)
Block(1,17,10,LEAVES:1)
Block(-4,17,11,LEAVES:1)
Block(0,17,11,LEAVES:1)
Block(2,17,11,LEAVES:1)
Block(3,17,11,LEAVES:1)
Block(-2,17,12,LEAVES:1)
Block(-1,17,12,LEAVES:1)
Block(-6,18,-3,LEAVES:1)
Block(-4,18,-3,LEAVES:1)
Block(-7,18,-2,LEAVES:1)
Block(-5,18,-2,LEAVES:1)
Block(-4,18,-2,LEAVES:1)
Block(-7,18,-1,LEAVES:1)
Block(-6,18,-1,LEAVES:1)
Block(-5,18,-1,LEAVES:1)
Block(-10,18,0,LEAVES:1)
Block(-7,18,0,LEAVES:1)
Block(-6,18,0,LOG:1)
Block(-4,18,0,LEAVES:1)
Block(-3,18,0,LEAVES:1)
Block(-10,18,1,LEAVES:1)
Block(-6,18,1,LEAVES:1)
Block(-5,18,1,LOG:1)
Block(-4,18,1,LOG:1)
Block(-3,18,1,LOG:1)
Block(-10,18,2,LEAVES:1)
Block(-5,18,2,LEAVES:1)
Block(-4,18,2,LEAVES:1)
Block(-3,18,2,LOG:1)
Block(-2,18,2,LOG:1)
Block(-3,19,-2,LEAVES:1)
Block(-7,19,-1,LEAVES:1)
Block(-6,19,-1,LEAVES:1)
Block(-2,19,-1,LEAVES:1)
Block(-1,19,-1,LEAVES:1)
Block(-6,19,0,LEAVES:1)
Block(-5,19,0,LEAVES:1)
Block(-3,19,0,LEAVES:1)
Block(-2,19,0,LEAVES:1)
Block(-3,19,1,LOG:1)
Block(1,19,1,LEAVES:1)
Block(-4,19,2,LEAVES:1)
Block(-3,19,2,LOG:1)
Block(-2,19,2,LOG:1)
Block(1,19,2,LEAVES:1)
Block(-7,19,3,LEAVES:1)
Block(-5,19,3,LEAVES:1)
Block(-3,19,3,LEAVES:1)
Block(-1,19,3,LEAVES:1)
Block(-4,19,4,LEAVES:1)
Block(-5,19,5,LEAVES:1)
Block(-3,19,5,LEAVES:1)
Block(-1,19,5,LEAVES:1)
Block(-3,20,1,LOG:1)
Block(-3,20,2,LOG:1)
Block(-2,20,2,LOG:1)
Block(-1,21,-5,LEAVES:1)
Block(1,21,-5,LEAVES:1)
Block(-2,21,-4,LEAVES:1)
Block(-1,21,-4,LEAVES:1)
Block(0,21,-4,LEAVES:1)
Block(-4,21,-3,LEAVES:1)
Block(3,21,-3,LEAVES:1)
Block(-7,21,-2,LEAVES:1)
Block(-5,21,-2,LEAVES:1)
Block(-4,21,-2,LEAVES:1)
Block(-3,21,-2,LEAVES:1)
Block(-1,21,-2,LEAVES:1)
Block(0,21,-2,LEAVES:1)
Block(-5,21,-1,LEAVES:1)
Block(-4,21,-1,LEAVES:1)
Block(-2,21,-1,LEAVES:1)
Block(-1,21,-1,LEAVES:1)
Block(2,21,-1,LEAVES:1)
Block(-11,21,0,LEAVES:1)
Block(-9,21,0,LEAVES:1)
Block(-7,21,0,LEAVES:1)
Block(-6,21,0,LEAVES:1)
Block(-4,21,0,LEAVES:1)
Block(-2,21,0,LEAVES:1)
Block(0,21,0,LEAVES:1)
Block(-10,21,1,LEAVES:1)
Block(-6,21,1,LEAVES:1)
Block(-5,21,1,LEAVES:1)
Block(-4,21,1,LEAVES:1)
Block(-3,21,1,LOG:1)
Block(-2,21,1,LEAVES:1)
Block(-1,21,1,LEAVES:1)
Block(0,21,1,LEAVES:1)
Block(1,21,1,LEAVES:1)
Block(2,21,1,LEAVES:1)
Block(3,21,1,LEAVES:1)
Block(-11,21,2,LEAVES:1)
Block(-10,21,2,LEAVES:1)
Block(-9,21,2,LEAVES:1)
Block(-8,21,2,LEAVES:1)
Block(-7,21,2,LEAVES:1)
Block(-5,21,2,LEAVES:1)
Block(-3,21,2,LOG:1)
Block(-2,21,2,LOG:1)
Block(1,21,2,LEAVES:1)
Block(-11,21,3,LEAVES:1)
Block(-7,21,3,LEAVES:1)
Block(-5,21,3,LEAVES:1)
Block(-3,21,3,LEAVES:1)
Block(-2,21,3,LEAVES:1)
Block(-1,21,3,LEAVES:1)
Block(-5,21,4,LEAVES:1)
Block(-3,21,4,LEAVES:1)
Block(-6,21,5,LEAVES:1)
Block(-3,21,5,LEAVES:1)
Block(-2,21,5,LEAVES:1)
Block(0,21,5,LEAVES:1)
Block(1,21,5,LEAVES:1)
Block(2,21,5,LEAVES:1)
Block(4,21,5,LEAVES:1)
Block(-5,21,6,LEAVES:1)
Block(-2,21,6,LEAVES:1)
Block(4,21,6,LEAVES:1)
Block(-2,21,7,LEAVES:1)
Block(3,21,7,LEAVES:1)
Block(4,21,7,LEAVES:1)
Block(-2,21,8,LEAVES:1)
Block(0,21,8,LEAVES:1)
Block(1,21,8,LEAVES:1)
Block(3,21,8,LEAVES:1)
Block(0,21,9,LEAVES:1)
Block(-1,22,-3,LEAVES:1)
Block(0,22,-2,LEAVES:1)
Block(-4,22,-1,LEAVES:1)
Block(0,22,-1,LEAVES:1)
Block(-7,22,1,LEAVES:1)
Block(-5,22,1,LEAVES:1)
Block(-3,22,1,LOG:1)
Block(-1,22,1,LEAVES:1)
Block(-4,22,2,LEAVES:1)
Block(-3,22,2,LOG:1)
Block(-2,22,2,LOG:1)
Block(0,22,2,LEAVES:1)
Block(-3,22,3,LEAVES:1)
Block(1,22,3,LEAVES:1)
Block(-3,22,4,LEAVES:1)
Block(0,22,4,LEAVES:1)
Block(-5,22,5,LEAVES:1)
Block(-4,22,5,LEAVES:1)
Block(-3,22,5,LEAVES:1)
Block(2,23,-4,LEAVES:1)
Block(2,23,-3,LEAVES:1)
Block(5,23,-3,LEAVES:1)
Block(-1,23,-2,LEAVES:1)
Block(0,23,-2,LEAVES:1)
Block(3,23,-2,LEAVES:1)
Block(-2,23,-1,LEAVES:1)
Block(-1,23,-1,LEAVES:1)
Block(1,23,-1,LEAVES:1)
Block(4,23,-1,LEAVES:1)
Block(5,23,-1,LEAVES:1)
Block(6,23,-1,LEAVES:1)
Block(-2,23,0,LEAVES:1)
Block(-1,23,0,LEAVES:1)
Block(0,23,0,LEAVES:1)
Block(1,23,0,LEAVES:1)
Block(2,23,0,LOG:1)
Block(5,23,0,LEAVES:1)
Block(6,23,0,LEAVES:1)
Block(-3,23,1,LOG:1)
Block(-2,23,1,LEAVES:1)
Block(-1,23,1,LEAVES:1)
Block(0,23,1,LOG:1)
Block(1,23,1,LOG:1)
Block(2,23,1,LEAVES:1)
Block(5,23,1,LEAVES:1)
Block(-3,23,2,LOG:1)
Block(-2,23,2,LOG:1)
Block(-1,23,2,LOG:1)
Block(0,23,2,LEAVES:1)
Block(1,23,2,LEAVES:1)
Block(2,23,2,LEAVES:1)
Block(3,23,2,LEAVES:1)
Block(6,23,2,LEAVES:1)
Block(2,23,3,LEAVES:1)
Block(3,23,3,LEAVES:1)
Block(-2,23,4,LEAVES:1)
Block(2,23,4,LEAVES:1)
Block(1,23,5,LEAVES:1)
Block(2,23,5,LEAVES:1)
Block(-3,24,-2,LEAVES:1)
Block(-1,24,-2,LEAVES:1)
Block(1,24,-2,LEAVES:1)
Block(-3,24,-1,LEAVES:1)
Block(-1,24,-1,LEAVES:1)
Block(0,24,-1,LEAVES:1)
Block(-3,24,0,LEAVES:1)
Block(2,24,0,LEAVES:1)
Block(3,24,0,LEAVES:1)
Block(-6,24,1,LEAVES:1)
Block(-4,24,1,LEAVES:1)
Block(-3,24,1,LOG:1)
Block(-2,24,1,LEAVES:1)
Block(-1,24,1,LEAVES:1)
Block(1,24,1,LEAVES:1)
Block(-4,24,2,LEAVES:1)
Block(-3,24,2,LOG:1)
Block(-2,24,2,LOG:1)
Block(-1,24,2,LEAVES:1)
Block(1,24,2,LEAVES:1)
Block(3,24,2,LEAVES:1)
Block(5,24,2,LEAVES:1)
Block(-7,24,3,LEAVES:1)
Block(-6,24,3,LEAVES:1)
Block(-3,24,3,LEAVES:1)
Block(-2,24,3,LEAVES:1)
Block(-1,24,3,LEAVES:1)
Block(1,24,3,LEAVES:1)
Block(-6,24,4,LEAVES:1)
Block(-5,24,4,LEAVES:1)
Block(-3,24,4,LEAVES:1)
Block(-2,24,4,LEAVES:1)
Block(-1,24,4,LEAVES:1)
Block(1,24,4,LEAVES:1)
Block(2,24,4,LEAVES:1)
Block(3,24,4,LEAVES:1)
Block(-3,24,5,LEAVES:1)
Block(-2,24,5,LEAVES:1)
Block(1,24,5,LEAVES:1)
Block(2,24,5,LEAVES:1)
Block(-2,24,6,LEAVES:1)
Block(-1,24,6,LEAVES:1)
Block(2,24,6,LEAVES:1)
Block(-2,24,7,LEAVES:1)
Block(-3,24,8,LEAVES:1)
Block(-3,25,1,LOG:1)
Block(-3,25,2,LOG:1)
Block(-2,25,2,LOG:1)
Block(-3,26,1,LOG:1)
Block(-3,26,2,LOG:1)
Block(-2,26,2,LOG:1)
Block(0,26,2,LEAVES:1)
Block(2,26,2,LEAVES:1)
Block(-2,26,3,LOG:1)
Block(-1,26,3,LEAVES:1)
Block(0,26,3,LEAVES:1)
Block(2,26,3,LEAVES:1)
Block(-4,26,4,LEAVES:1)
Block(-2,26,4,LOG:1)
Block(3,26,4,LEAVES:1)
Block(4,26,4,LEAVES:1)
Block(-4,26,5,LEAVES:1)
Block(-1,26,5,LOG:1)
Block(0,26,5,LEAVES:1)
Block(1,26,5,LEAVES:1)
Block(2,26,5,LEAVES:1)
Block(4,26,5,LEAVES:1)
Block(-2,26,6,LEAVES:1)
Block(-1,26,6,LEAVES:1)
Block(0,26,6,LOG:1)
Block(2,26,6,LEAVES:1)
Block(3,26,6,LEAVES:1)
Block(4,26,6,LEAVES:1)
Block(-4,26,8,LEAVES:1)
Block(-1,26,8,LEAVES:1)
Block(1,26,8,LEAVES:1)
Block(0,26,9,LEAVES:1)
Block(3,26,9,LEAVES:1)
Block(-1,27,-7,LEAVES:1)
Block(1,27,-7,LEAVES:1)
Block(-4,27,-6,LEAVES:1)
Block(-1,27,-6,LEAVES:1)
Block(-5,27,-5,LEAVES:1)
Block(-1,27,-5,LEAVES:1)
Block(2,27,-5,LEAVES:1)
Block(3,27,-5,LEAVES:1)
Block(-9,27,-4,LEAVES:1)
Block(-7,27,-4,LEAVES:1)
Block(-5,27,-4,LEAVES:1)
Block(-3,27,-4,LEAVES:1)
Block(0,27,-4,LEAVES:1)
Block(3,27,-4,LEAVES:1)
Block(-8,27,-3,LEAVES:1)
Block(-4,27,-3,LEAVES:1)
Block(-3,27,-3,LEAVES:1)
Block(-2,27,-3,LEAVES:1)
Block(-1,27,-3,LOG:1)
Block(3,27,-3,LEAVES:1)
Block(-11,27,-2,LEAVES:1)
Block(-10,27,-2,LEAVES:1)
Block(-9,27,-2,LEAVES:1)
Block(-6,27,-2,LEAVES:1)
Block(-4,27,-2,LEAVES:1)
Block(-3,27,-2,LEAVES:1)
Block(-2,27,-2,LOG:1)
Block(-9,27,-1,LEAVES:1)
Block(-7,27,-1,LEAVES:1)
Block(-3,27,-1,LOG:1)
Block(-1,27,-1,LEAVES:1)
Block(-10,27,0,LEAVES:1)
Block(-9,27,0,LEAVES:1)
Block(-7,27,0,LOG:1)
Block(-6,27,0,LEAVES:1)
Block(-3,27,0,LOG:1)
Block(-1,27,0,LEAVES:1)
Block(-11,27,1,LEAVES:1)
Block(-7,27,1,LEAVES:1)
Block(-6,27,1,LOG:1)
Block(-5,27,1,LEAVES:1)
Block(-3,27,1,LOG:1)
Block(0,27,1,LEAVES:1)
Block(-11,27,2,LEAVES:1)
Block(-5,27,2,LOG:1)
Block(-4,27,2,LOG:1)
Block(-3,27,2,LOG:1)
Block(-9,27,3,LEAVES:1)
Block(-8,27,3,LEAVES:1)
Block(-9,27,4,LEAVES:1)
Block(-7,27,4,LEAVES:1)
Block(-6,27,4,LEAVES:1)
Block(-5,27,4,LEAVES:1)
Block(-4,28,-6,LEAVES:1)
Block(-7,28,-4,LEAVES:1)
Block(-7,28,-3,LEAVES:1)
Block(-3,28,-3,LEAVES:1)
Block(-2,28,-3,LEAVES:1)
Block(0,28,-3,LEAVES:1)
Block(-7,28,-2,LEAVES:1)
Block(-6,28,-2,LEAVES:1)
Block(-4,28,-2,LEAVES:1)
Block(-3,28,-2,LEAVES:1)
Block(-1,28,-2,LEAVES:1)
Block(1,28,-2,LEAVES:1)
Block(-7,28,-1,LEAVES:1)
Block(-3,28,-1,LEAVES:1)
Block(-2,28,-1,LEAVES:1)
Block(0,28,-1,LEAVES:1)
Block(-7,28,0,LEAVES:1)
Block(-6,28,0,LEAVES:1)
Block(-5,28,0,LEAVES:1)
Block(-2,28,0,LEAVES:1)
Block(-1,28,0,LEAVES:1)
Block(0,28,0,LEAVES:1)
Block(-5,28,1,LEAVES:1)
Block(-3,28,1,LOG:1)
Block(-1,28,1,LEAVES:1)
Block(-5,28,2,LEAVES:1)
Block(-4,28,2,LEAVES:1)
Block(-3,28,2,LOG:1)
Block(-1,28,2,LEAVES:1)
Block(-3,28,3,LEAVES:1)
Block(-2,28,3,LEAVES:1)
Block(0,28,3,LEAVES:1)
Block(1,28,3,LEAVES:1)
Block(-5,28,4,LEAVES:1)
Block(-3,28,4,LEAVES:1)
Block(-5,28,5,LEAVES:1)
Block(-4,28,6,LEAVES:1)
Block(-3,29,1,LOG:1)
Block(-3,29,2,LOG:1)
Block(-8,30,-4,LEAVES:1)
Block(-6,30,-4,LEAVES:1)
Block(-5,30,-4,LEAVES:1)
Block(-4,30,-3,LEAVES:1)
Block(-9,30,-2,LEAVES:1)
Block(-8,30,-2,LEAVES:1)
Block(-6,30,-2,LEAVES:1)
Block(-8,30,-1,LEAVES:1)
Block(-6,30,-1,LEAVES:1)
Block(-5,30,-1,LEAVES:1)
Block(-6,30,0,LOG:1)
Block(-7,30,1,LEAVES:1)
Block(-5,30,1,LOG:1)
Block(-4,30,1,LOG:1)
Block(-3,30,1,LOG:1)
Block(-6,30,2,LEAVES:1)
Block(-3,30,2,LOG:1)
Block(-6,30,3,LEAVES:1)
Block(-5,30,3,LEAVES:1)
Block(-7,30,4,LEAVES:1)
Block(-6,30,4,LEAVES:1)
Block(-2,31,-2,LEAVES:1)
Block(-5,31,-1,LEAVES:1)
Block(-4,31,-1,LEAVES:1)
Block(-3,31,-1,LEAVES:1)
Block(-2,31,-1,LEAVES:1)
Block(-1,31,-1,LEAVES:1)
Block(-2,31,0,LEAVES:1)
Block(-4,31,1,LEAVES:1)
Block(-3,31,1,LOG:1)
Block(-2,31,1,LEAVES:1)
Block(-1,31,1,LEAVES:1)
Block(-6,31,2,LEAVES:1)
Block(-3,31,2,LOG:1)
Block(-2,31,2,LEAVES:1)
Block(-2,31,3,LEAVES:1)
Block(1,31,3,LEAVES:1)
Block(-4,31,4,LEAVES:1)
Block(-2,31,4,LEAVES:1)
Block(-2,31,5,LEAVES:1)
Block(-4,31,6,LEAVES:1)
Block(-1,31,6,LEAVES:1)
Block(-1,32,-3,LEAVES:1)
Block(-5,32,-2,LEAVES:1)
Block(0,32,-2,LEAVES:1)
Block(-5,32,-1,LEAVES:1)
Block(-2,32,-1,LEAVES:1)
Block(-1,32,-1,LEAVES:1)
Block(1,32,-1,LEAVES:1)
Block(2,32,-1,LEAVES:1)
Block(-6,32,0,LEAVES:1)
Block(-4,32,0,LEAVES:1)
Block(-1,32,0,LEAVES:1)
Block(0,32,0,LOG:1)
Block(2,32,0,LEAVES:1)
Block(-5,32,1,LEAVES:1)
Block(-3,32,1,LOG:1)
Block(-2,32,1,LOG:1)
Block(-1,32,1,LOG:1)
Block(0,32,1,LEAVES:1)
Block(-6,32,2,LEAVES:1)
Block(-5,32,2,LEAVES:1)
Block(-3,32,2,LOG:1)
Block(-2,32,2,LEAVES:1)
Block(-1,32,2,LEAVES:1)
Block(1,32,2,LEAVES:1)
Block(2,32,2,LEAVES:1)
Block(-1,32,3,LEAVES:1)
Block(0,32,3,LEAVES:1)
Block(-5,32,4,LEAVES:1)
Block(-3,32,4,LEAVES:1)
Block(-2,32,4,LEAVES:1)
Block(-4,32,5,LEAVES:1)
Block(-1,32,5,LEAVES:1)
Block(0,32,5,LEAVES:1)
Block(-3,33,1,LOG:1)
Block(-3,33,2,LOG:1)
Block(-5,34,-3,LEAVES:1)
Block(-4,34,-3,LEAVES:1)
Block(-3,34,-3,LEAVES:1)
Block(-3,34,-2,LEAVES:1)
Block(-4,34,-1,LEAVES:1)
Block(-2,34,-1,LEAVES:1)
Block(0,34,-1,LEAVES:1)
Block(1,34,-1,LEAVES:1)
Block(-6,34,0,LEAVES:1)
Block(-1,34,0,LEAVES:1)
Block(1,34,0,LEAVES:1)
Block(-5,34,1,LEAVES:1)
Block(-4,34,1,LEAVES:1)
Block(-3,34,1,LOG:1)
Block(-2,34,1,LEAVES:1)
Block(-4,34,2,LEAVES:1)
Block(-3,34,2,LOG:1)
Block(0,34,2,LEAVES:1)
Block(-6,34,3,LEAVES:1)
Block(-5,34,3,LEAVES:1)
Block(-3,34,3,LEAVES:1)
Block(-2,34,3,LEAVES:1)
Block(-5,34,4,LEAVES:1)
Block(-1,34,4,LEAVES:1)
Block(-1,35,0,LEAVES:1)
Block(-4,35,1,LEAVES:1)
Block(-3,35,1,LOG:1)
Block(-2,35,1,LEAVES:1)
Block(-7,35,2,LEAVES:1)
Block(-3,35,2,LOG:1)
Block(-1,35,2,LEAVES:1)
Block(1,35,2,LEAVES:1)
Block(-3,35,3,LOG:1)
Block(-4,35,4,LEAVES:1)
Block(-3,35,4,LOG:1)
Block(-2,35,4,LEAVES:1)
Block(0,35,4,LEAVES:1)
Block(-6,35,5,LEAVES:1)
Block(0,35,5,LEAVES:1)
Block(-1,35,6,LEAVES:1)
Block(1,35,6,LEAVES:1)
Block(-3,35,7,LEAVES:1)
Block(-1,35,7,LEAVES:1)
Block(0,35,7,LEAVES:1)
Block(-1,35,8,LEAVES:1)
Block(-3,36,1,LOG:1)
Block(-4,37,-3,LEAVES:1)
Block(-2,37,-3,LEAVES:1)
Block(-5,37,-2,LEAVES:1)
Block(-1,37,-2,LEAVES:1)
Block(-6,37,-1,LEAVES:1)
Block(-3,37,-1,LEAVES:1)
Block(0,37,-1,LEAVES:1)
Block(-7,37,0,LEAVES:1)
Block(-1,37,0,LEAVES:1)
Block(0,37,0,LEAVES:1)
Block(-5,37,1,LEAVES:1)
Block(-4,37,1,LEAVES:1)
Block(-3,37,1,LOG:1)
Block(-2,37,1,LEAVES:1)
Block(0,37,1,LEAVES:1)
Block(1,37,1,LEAVES:1)
Block(-5,37,2,LEAVES:1)
Block(-3,37,2,LEAVES:1)
Block(1,37,2,LEAVES:1)
Block(-3,37,3,LEAVES:1)
Block(-1,37,3,LEAVES:1)
Block(-4,37,4,LEAVES:1)
Block(-2,37,4,LEAVES:1)
Block(-2,37,5,LEAVES:1)
Block(-5,38,-3,LEAVES:1)
Block(-4,38,-3,LEAVES:1)
Block(-7,38,-2,LEAVES:1)
Block(-6,38,-2,LEAVES:1)
Block(-2,38,-2,LEAVES:1)
Block(-8,38,-1,LEAVES:1)
Block(-6,38,-1,LEAVES:1)
Block(-9,38,0,LEAVES:1)
Block(-8,38,0,LEAVES:1)
Block(-6,38,0,LEAVES:1)
Block(-5,38,0,LEAVES:1)
Block(-7,38,1,LEAVES:1)
Block(-6,38,1,LOG:1)
Block(-5,38,1,LOG:1)
Block(-4,38,1,LOG:1)
Block(-3,38,1,LOG:1)
Block(-1,38,1,LEAVES:1)
Block(-9,38,2,LEAVES:1)
Block(-7,38,2,LEAVES:1)
Block(-5,38,2,LEAVES:1)
Block(-4,38,2,LEAVES:1)
Block(-1,38,2,LEAVES:1)
Block(-2,38,3,LEAVES:1)
Block(-7,38,4,LEAVES:1)
Block(-6,38,4,LEAVES:1)
Block(-5,38,4,LEAVES:1)
Block(-2,38,4,LEAVES:1)
Block(-3,39,1,LOG:1)
Block(-4,40,-4,LEAVES:1)
Block(-2,40,-4,LEAVES:1)
Block(-1,40,-4,LEAVES:1)
Block(-5,40,-3,LEAVES:1)
Block(-6,40,-2,LEAVES:1)
Block(-1,40,-1,LOG:1)
Block(-3,40,0,LEAVES:1)
Block(-2,40,0,LOG:1)
Block(0,40,0,LEAVES:1)
Block(-6,40,1,LEAVES:1)
Block(-3,40,1,LOG:1)
Block(-2,40,1,LEAVES:1)
Block(-1,40,1,LEAVES:1)
Block(0,40,1,LEAVES:1)
Block(2,40,1,LEAVES:1)
Block(-2,40,2,LEAVES:1)
Block(0,40,2,LEAVES:1)
Block(-1,40,3,LEAVES:1)
Block(-3,41,1,LOG:1)
Block(-4,42,-3,LEAVES:1)
Block(-3,42,-3,LEAVES:1)
Block(-6,42,-2,LEAVES:1)
Block(-4,42,-2,LEAVES:1)
Block(-1,42,-2,LEAVES:1)
Block(-6,42,-1,LEAVES:1)
Block(-5,42,-1,LEAVES:1)
Block(-3,42,-1,LEAVES:1)
Block(-6,42,0,LEAVES:1)
Block(-3,42,0,LEAVES:1)
Block(-2,42,0,LEAVES:1)
Block(1,42,0,LEAVES:1)
Block(-6,42,1,LEAVES:1)
Block(-4,42,1,LEAVES:1)
Block(-3,42,1,LOG:1)
Block(-2,42,1,LEAVES:1)
Block(0,42,1,LEAVES:1)
Block(-5,42,2,LEAVES:1)
Block(-4,42,2,LEAVES:1)
Block(-1,42,2,LEAVES:1)
Block(-7,42,3,LEAVES:1)
Block(1,42,3,LEAVES:1)
Block(-5,42,4,LEAVES:1)
Block(-4,42,4,LEAVES:1)
Block(0,42,4,LEAVES:1)
Block(-3,42,5,LEAVES:1)
Block(-1,42,5,LEAVES:1)
Block(-4,43,-2,LEAVES:1)
Block(-3,43,-2,LEAVES:1)
Block(-3,43,-1,LEAVES:1)
Block(-1,43,-1,LEAVES:1)
Block(-3,43,0,LEAVES:1)
Block(-2,43,0,LEAVES:1)
Block(-5,43,1,LEAVES:1)
Block(-3,43,1,LOG:1)
Block(-1,43,1,LEAVES:1)
Block(-6,43,2,LEAVES:1)
Block(-1,43,2,LEAVES:1)
Block(-5,43,3,LEAVES:1)
Block(-3,43,3,LEAVES:1)
Block(-1,43,3,LEAVES:1)
Block(-3,43,4,LEAVES:1)
Block(-4,44,-2,LEAVES:1)
Block(-2,44,-2,LEAVES:1)
Block(-4,44,0,LEAVES:1)
Block(0,44,0,LEAVES:1)
Block(-3,44,1,LOG:1)
Block(-3,44,3,LEAVES:1)
Block(-3,44,4,LEAVES:1)
Block(-3,45,1,LOG:1)
Block(-5,46,0,LEAVES:1)
Block(-3,46,0,LEAVES:1)
Block(-4,46,1,LEAVES:1)
Block(-3,46,1,LOG:1)
Block(-2,46,1,LEAVES:1)
Block(-1,46,2,LEAVES:1)
Block(-3,47,0,LEAVES:1)
Block(-3,47,1,LOG:1)
Block(-1,47,1,LEAVES:1)
Block(-4,47,3,LEAVES:1)
Block(-3,47,3,LEAVES:1)
Block(-2,47,3,LEAVES:1)
Block(-3,48,1,LOG:1)
Block(-5,49,0,LEAVES:1)
Block(-4,49,0,LEAVES:1)
Block(-5,49,1,LEAVES:1)
Block(-3,49,1,LOG:1)
Block(-1,49,1,LEAVES:1)
Block(-4,49,2,LEAVES:1)
Block(-3,49,3,LEAVES:1)
Block(-4,50,-1,LEAVES:1)
Block(-3,50,-1,LEAVES:1)
Block(-1,50,0,LEAVES:1)
Block(-3,50,1,LOG:1)
Block(-5,50,2,LEAVES:1)
Block(-2,50,3,LEAVES:1)
Block(-3,51,1,LOG:1)
Block(-3,52,0,LEAVES:1)
Block(-2,52,0,LEAVES:1)
Block(-3,52,1,LOG:1)
Block(-3,52,2,LEAVES:1)
Block(-3,53,1,LOG:1)
Block(-2,53,1,LEAVES:1)
Block(-4,53,2,LEAVES:1)
Block(-4,54,1,LEAVES:1)
Block(-3,54,1,LOG:1)
Block(-4,54,2,LEAVES:1)

#######################################################################
# +-----------------------------------------------------------------+ #
# |                            BO3 checks                           | #
# +-----------------------------------------------------------------+ #
#######################################################################

# Require a condition at a certain location in order for the BO3 to be spawned.
# BlockCheck(x,y,z,BlockName[,BlockName[,...]]) - one of the blocks must be at the location
# BlockCheckNot(x,y,z,BlockName[,BlockName[,...]]) - all the blocks must not be at the location
# LightCheck(x,y,z,minLightLevel,maxLightLevel) - light must be between min and max (inclusive)

# You can use "Solid" as a BlockName for matching all solid blocks or "All" to match all blocks that aren't air.

# Examples:
BlockCheck(0,-1,0,GRASS,DIRT,DIRT:2,SAND,DIRT:1)
#   BlockCheck(0,-1,0,Solid)       Require any solid block just below the object
#   BlockCheck(0,-1,0,WOOL)        Require any type of wool just below the object
#   BlockCheck(0,-1,0,WOOL:0)      Require white wool just below the object
#   BlockCheckNot(0,-1,0,WOOL:0)   Require that there is no white wool below the object
#   LightCheck(0,0,0,0,1)          Require almost complete darkness just below the object

#######################################################################
# +-----------------------------------------------------------------+ #
# |                             Branches                            | #
# +-----------------------------------------------------------------+ #
#######################################################################

# Branches are objects that will spawn when this object spawns when it is used in
# the CustomStructure resource. Branches can also have branches, making complex
# structures possible. See the wiki for more details.

# Regular Branches spawn each branch with an independent chance of spawning.
# Branch(x,y,z,branchName,rotation,chance[,anotherBranchName,rotation,chance[,...]][IndividualChance])
# branchName - name of the object to spawn.
# rotation - NORTH, SOUTH, EAST or WEST.
# IndividualChance - The chance each branch has to spawn, assumed to be 100 when left blank

# Weighted Branches spawn branches with a dependent chance of spawning.
# WeightedBranch(x,y,z,branchName,rotation,chance[,anotherBranchName,rotation,chance[,...]][MaxChanceOutOf])
# MaxChanceOutOf - The chance all branches have to spawn out of, assumed to be 100 when left blank

