#######################################################################
# +-----------------------------------------------------------------+ #
# |                            BO3 object                           | #
# +-----------------------------------------------------------------+ #
#######################################################################

# This is the config file of a custom object.
# If you add this object correctly to your BiomeConfigs, it will spawn in the world.

# This is the creator of this BO3 object
Author: BO3 BulkEdit (by LanToaster)

# A short description of this BO3 object
Description: This Object was Created with BO3_BulkEdit

# The BO3 version, don't change this! It can be used by external applications to do a version check.
Version: 3

# The settings mode, WriteAll, WriteWithoutComments or WriteDisable. See WorldConfig.
SettingsMode: WriteDisable


#######################################################################
# +-----------------------------------------------------------------+ #
# |                          Main settings                          | #
# +-----------------------------------------------------------------+ #
#######################################################################

# This needs to be set to true to spawn the object in the Tree and Sapling resources.
Tree: true

# The frequency of the BO3 from 1 to 200. Tries this many times to spawn this BO3 when using the CustomObject(...) resource.
# Ignored by Tree(..), Sapling(..) and CustomStructure(..)
Frequency: 1

# The rarity of the BO3 from 0 to 100. Each spawn attempt has rarity% chance to succeed when using the CustomObject(...) resource.
# Ignored by Tree(..), Sapling(..) and CustomStructure(..)
Rarity: 100.0

# If you set this to true, the BO3 will be placed with a random rotation.
RotateRandomly: true

# The spawn height of the BO3 - randomY, highestBlock or highestSolidBlock.
SpawnHeight: highestSolidBlock
SpawnHeightOffset: -4
# The height limits for the BO3.
MinHeight: 0

MaxHeight: 75

# Objects can have other objects attacthed to it: branches. Branches can also
# have branches attached to it, which can also have branches, etc. This is the
# maximum branch depth for this objects.
MaxBranchDepth: 10

# When spawned with the UseWorld keyword, this BO3 should NOT spawn in the following biomes.
# If you writer.write the BO3 name directly in the BiomeConfigs, this will be ignored.
ExcludedBiomes: All


#######################################################################
# +-----------------------------------------------------------------+ #
# |                      Source block settings                      | #
# +-----------------------------------------------------------------+ #
#######################################################################

# The block(s) the BO3 should spawn in.
SourceBlocks: AIR,GRASS,DIRT,DIRT:1,STONE,DIRT:2

# The maximum percentage of the BO3 that can be outside the SourceBlock.
# The BO3 won't be placed on a location with more blocks outside the SourceBlock than this percentage.
MaxPercentageOutsideSourceBlock: 0

# What to do when a block is about to be placed outside the SourceBlock? (dontPlace, placeAnyway)
OutsideSourceBlock: dontPlace


#######################################################################
# +-----------------------------------------------------------------+ #
# |                              Blocks                             | #
# +-----------------------------------------------------------------+ #
#######################################################################

# All the blocks used in the BO3 are listed here. Possible blocks:
# Block(x,y,z,id[.data][,nbtfile.nbt)
# RandomBlock(x,y,z,id[:data][,nbtfile.nbt],chance[,id[:data][,nbtfile.nbt],chance[,...]])
# So RandomBlock(0,0,0,CHEST,chest.nbt,50,CHEST,anotherchest.nbt,100) will spawn a chest at
# the BO3 origin, and give it a 50% chance to have the contents of chest.nbt, or, if that
# fails, a 100% percent chance to have the contents of anotherchest.nbt.
Block(0,0,-5,LOG:15)
Block(-4,0,-4,LOG:15)
Block(3,0,-3,LOG:15)
Block(0,0,-2,LOG:15)
Block(3,0,0,LOG:15)
Block(-2,0,1,LOG:15)
Block(-2,0,2,LOG:15)
Block(0,0,2,LOG:15)
Block(0,0,3,LOG:15)
Block(4,0,3,LOG:15)
Block(0,1,-5,LOG:15)
Block(-4,1,-4,LOG:15)
Block(-3,1,-3,LOG:15)
Block(3,1,-3,LOG:15)
Block(0,1,-2,LOG:15)
Block(0,1,-1,LOG:15)
Block(-2,1,0,LOG:15)
Block(2,1,0,LOG:15)
Block(3,1,0,LOG:15)
Block(-2,1,1,LOG:15)
Block(-2,1,2,LOG:15)
Block(0,1,2,LOG:15)
Block(4,1,2,LOG:15)
Block(0,1,3,LOG:15)
Block(4,1,3,LOG:15)
Block(0,2,-5,LOG:15)
Block(-4,2,-4,LOG:15)
Block(0,2,-4,LOG:15)
Block(-3,2,-3,LOG:15)
Block(2,2,-3,LOG:15)
Block(3,2,-3,LOG:15)
Block(0,2,-1,LOG:15)
Block(-2,2,0,LOG:15)
Block(2,2,0,LOG:15)
Block(3,2,0,LOG:15)
Block(-2,2,1,LOG:15)
Block(0,2,1,LOG:15)
Block(0,2,2,LOG:15)
Block(3,2,2,LOG:15)
Block(4,2,2,LOG:15)
Block(0,3,-5,LOG:15)
Block(0,3,-4,LOG:15)
Block(1,3,-4,LOG:15)
Block(-3,3,-3,LOG:15)
Block(2,3,-3,LOG:15)
Block(-3,3,-2,LOG:15)
Block(0,3,-1,LOG:15)
Block(1,3,-1,LOG:15)
Block(-2,3,0,LOG:15)
Block(-1,3,0,LOG:15)
Block(1,3,0,LOG:15)
Block(3,3,0,LOG:15)
Block(-1,3,1,LOG:15)
Block(0,3,1,LOG:15)
Block(3,3,1,LOG:15)
Block(0,3,2,LOG:15)
Block(3,3,2,LOG:15)
Block(0,4,-4,LOG:15)
Block(1,4,-4,LOG:15)
Block(1,4,-3,LOG:15)
Block(2,4,-3,LOG:15)
Block(-3,4,-2,LOG:15)
Block(-2,4,-2,LOG:15)
Block(1,4,-1,LOG:15)
Block(-1,4,0,LOG:15)
Block(1,4,0,LOG:15)
Block(2,4,0,LOG:15)
Block(0,4,1,LOG:15)
Block(1,4,1,LOG:15)
Block(3,4,1,LOG:15)
Block(1,5,-4,LOG:15)
Block(1,5,-3,LOG:15)
Block(-2,5,-2,LOG:15)
Block(-1,5,-2,LOG:15)
Block(1,5,-1,LOG:15)
Block(2,5,-1,LOG:15)
Block(-1,5,0,LOG:15)
Block(1,5,0,LOG:15)
Block(2,5,0,LOG:15)
Block(0,5,1,LOG:15)
Block(1,5,1,LOG:15)
Block(1,6,-3,LOG:15)
Block(-2,6,-2,LOG:15)
Block(-1,6,-2,LOG:15)
Block(0,6,-2,LOG:15)
Block(1,6,-2,LOG:15)
Block(-1,6,-1,LOG:15)
Block(1,6,-1,LOG:15)
Block(2,6,-1,LOG:15)
Block(-1,6,0,LOG:15)
Block(0,6,0,LOG:15)
Block(1,6,0,LOG:15)
Block(2,6,0,LOG:15)
Block(0,6,1,LOG:15)
Block(0,7,-2,LOG:15)
Block(1,7,-2,LOG:15)
Block(-1,7,-1,LOG:15)
Block(0,7,-1,LOG:15)
Block(1,7,-1,LOG:15)
Block(2,7,-1,LOG:15)
Block(0,7,0,LOG:15)
Block(1,7,0,LOG:15)
Block(2,7,0,LOG:15)
Block(0,7,1,LOG:15)
Block(1,8,-2,LOG:15)
Block(-1,8,-1,LOG:15)
Block(0,8,-1,LOG:15)
Block(1,8,-1,LOG:15)
Block(2,8,-1,LOG:15)
Block(0,8,0,LOG:15)
Block(1,8,0,LOG:15)
Block(0,9,-1,LOG:15)
Block(1,9,-1,LOG:15)
Block(2,9,-1,LOG:15)
Block(0,9,0,LOG:15)
Block(1,9,0,LOG:15)
Block(0,10,-1,LOG:15)
Block(1,10,-1,LOG:15)
Block(2,10,-1,LOG:15)
Block(0,10,0,LOG:15)
Block(1,10,0,LOG:15)
Block(0,11,-1,LOG:15)
Block(1,11,-1,LOG:15)
Block(2,11,-1,LOG:15)
Block(0,11,0,LOG:15)
Block(1,11,0,LOG:15)
Block(2,11,0,LOG:15)
Block(-1,11,3,LEAVES:15)
Block(2,11,3,LEAVES:7)
Block(0,12,-1,LOG:15)
Block(1,12,-1,LOG:15)
Block(0,12,0,LOG:15)
Block(1,12,0,LOG:15)
Block(2,12,0,LOG:15)
Block(0,12,1,LEAVES:7)
Block(2,12,1,LOG:15)
Block(-1,12,2,LEAVES:15)
Block(0,12,2,LEAVES:15)
Block(1,12,2,LOG:15)
Block(2,12,2,LOG:15)
Block(3,12,2,LEAVES:7)
Block(0,12,3,LEAVES:15)
Block(2,12,3,LOG:15)
Block(3,12,3,LOG:15)
Block(4,12,3,LOG:15)
Block(5,12,3,LEAVES:7)
Block(3,12,4,LEAVES:15)
Block(4,12,4,LEAVES:15)
Block(6,12,4,LEAVES:7)
Block(-1,12,5,LEAVES:7)
Block(1,12,5,LEAVES:7)
Block(3,12,5,LEAVES:7)
Block(5,12,6,LEAVES:7)
Block(3,12,7,LEAVES:15)
Block(0,13,-2,COCOA:0)
Block(0,13,-1,LOG:15)
Block(1,13,-1,LOG:15)
Block(1,13,0,LOG:15)
Block(2,13,0,LOG:15)
Block(2,13,1,LEAVES:15)
Block(0,13,2,LEAVES:15)
Block(1,13,2,LEAVES:15)
Block(2,13,2,LEAVES:15)
Block(3,13,2,LEAVES:7)
Block(0,13,3,LEAVES:15)
Block(1,13,3,LEAVES:15)
Block(2,13,3,LOG:15)
Block(3,13,3,LEAVES:15)
Block(4,13,3,LEAVES:15)
Block(5,13,3,LEAVES:15)
Block(6,13,3,LEAVES:15)
Block(0,13,4,LEAVES:15)
Block(1,13,4,LEAVES:7)
Block(2,13,4,LOG:15)
Block(3,13,4,LEAVES:15)
Block(5,13,4,LOG:15)
Block(6,13,4,LEAVES:15)
Block(7,13,4,LEAVES:7)
Block(-1,13,5,LEAVES:15)
Block(0,13,5,LEAVES:15)
Block(1,13,5,LOG:15)
Block(2,13,5,LEAVES:15)
Block(3,13,5,LEAVES:7)
Block(4,13,5,LEAVES:7)
Block(5,13,5,LEAVES:15)
Block(6,13,5,LEAVES:7)
Block(1,13,6,LEAVES:7)
Block(2,13,6,LEAVES:15)
Block(3,13,6,LEAVES:15)
Block(5,13,6,LEAVES:7)
Block(-1,13,7,LEAVES:15)
Block(2,13,7,LEAVES:15)
Block(1,13,8,LEAVES:7)
Block(-1,13,9,LEAVES:15)
Block(-1,14,-1,COCOA:11)
Block(0,14,-1,LOG:15)
Block(1,14,-1,LOG:15)
Block(1,14,0,LOG:15)
Block(2,14,0,LOG:15)
Block(2,14,2,LEAVES:7)
Block(1,14,3,LEAVES:7)
Block(2,14,3,LEAVES:15)
Block(3,14,3,LEAVES:7)
Block(2,14,4,LEAVES:7)
Block(4,14,4,LEAVES:7)
Block(5,14,4,LEAVES:15)
Block(6,14,4,LEAVES:15)
Block(0,14,5,LEAVES:15)
Block(1,14,5,LEAVES:7)
Block(2,14,5,LEAVES:15)
Block(3,14,5,LEAVES:7)
Block(5,14,5,LEAVES:7)
Block(-1,14,6,LEAVES:15)
Block(0,14,6,LOG:15)
Block(1,14,6,LEAVES:7)
Block(2,14,6,LEAVES:15)
Block(-2,14,7,LEAVES:15)
Block(-1,14,7,LEAVES:15)
Block(0,14,7,LEAVES:15)
Block(1,14,7,LEAVES:15)
Block(-1,14,8,LEAVES:15)
Block(0,14,8,LEAVES:15)
Block(1,14,8,LEAVES:15)
Block(0,14,9,LEAVES:15)
Block(3,15,-5,LEAVES:7)
Block(1,15,-3,LOG:15)
Block(5,15,-3,LEAVES:15)
Block(1,15,-2,LOG:15)
Block(2,15,-2,LOG:15)
Block(0,15,-1,LOG:15)
Block(1,15,-1,LOG:15)
Block(3,15,-1,LEAVES:7)
Block(6,15,-1,LEAVES:15)
Block(1,15,0,LOG:15)
Block(2,15,0,LOG:15)
Block(6,15,1,LEAVES:15)
Block(2,15,3,LEAVES:7)
Block(5,15,4,LEAVES:15)
Block(0,15,5,LEAVES:15)
Block(2,15,5,LEAVES:7)
Block(0,15,6,LEAVES:15)
Block(-1,15,7,LEAVES:15)
Block(0,15,7,LEAVES:15)
Block(0,15,8,LEAVES:15)
Block(0,16,-8,LEAVES:15)
Block(1,16,-7,LEAVES:15)
Block(-1,16,-6,LEAVES:7)
Block(3,16,-6,LEAVES:15)
Block(5,16,-6,LEAVES:15)
Block(-2,16,-5,LEAVES:7)
Block(1,16,-5,LEAVES:7)
Block(3,16,-5,LEAVES:7)
Block(4,16,-5,LEAVES:15)
Block(7,16,-5,LEAVES:15)
Block(-1,16,-4,LEAVES:7)
Block(1,16,-4,LOG:15)
Block(2,16,-4,LEAVES:7)
Block(3,16,-4,LEAVES:15)
Block(4,16,-4,LEAVES:15)
Block(5,16,-4,LEAVES:15)
Block(6,16,-4,LEAVES:15)
Block(-3,16,-3,LEAVES:15)
Block(1,16,-3,LOG:15)
Block(2,16,-3,LEAVES:7)
Block(3,16,-3,LOG:15)
Block(4,16,-3,LEAVES:15)
Block(8,16,-3,LEAVES:15)
Block(-1,16,-2,LEAVES:15)
Block(2,16,-2,LOG:15)
Block(3,16,-2,LOG:15)
Block(4,16,-2,LEAVES:15)
Block(5,16,-2,LEAVES:15)
Block(0,16,-1,LOG:15)
Block(1,16,-1,LOG:15)
Block(3,16,-1,LEAVES:7)
Block(4,16,-1,LOG:15)
Block(5,16,-1,LEAVES:15)
Block(6,16,-1,LEAVES:15)
Block(1,16,0,LOG:15)
Block(2,16,0,LOG:15)
Block(4,16,0,LEAVES:7)
Block(5,16,0,LEAVES:15)
Block(2,16,1,LEAVES:15)
Block(5,16,1,LEAVES:15)
Block(6,16,2,LEAVES:15)
Block(4,16,3,LEAVES:7)
Block(0,16,6,LEAVES:15)
Block(4,17,-10,LEAVES:15)
Block(2,17,-9,LEAVES:7)
Block(1,17,-8,LEAVES:15)
Block(3,17,-8,LEAVES:7)
Block(5,17,-8,LEAVES:7)
Block(0,17,-7,LEAVES:15)
Block(1,17,-7,LEAVES:15)
Block(4,17,-7,LEAVES:15)
Block(-1,17,-6,LEAVES:7)
Block(0,17,-6,LEAVES:15)
Block(1,17,-6,LEAVES:15)
Block(2,17,-6,LEAVES:7)
Block(3,17,-6,LOG:15)
Block(4,17,-6,LEAVES:15)
Block(5,17,-6,LEAVES:15)
Block(6,17,-6,LEAVES:15)
Block(-2,17,-5,LEAVES:7)
Block(-1,17,-5,LEAVES:7)
Block(0,17,-5,LEAVES:7)
Block(1,17,-5,LOG:15)
Block(2,17,-5,LOG:15)
Block(3,17,-5,LEAVES:15)
Block(5,17,-5,LEAVES:15)
Block(6,17,-5,LEAVES:15)
Block(7,17,-5,LEAVES:15)
Block(-3,17,-4,LEAVES:15)
Block(-2,17,-4,LEAVES:15)
Block(-1,17,-4,LOG:15)
Block(1,17,-4,LEAVES:7)
Block(2,17,-4,LEAVES:15)
Block(3,17,-4,LEAVES:7)
Block(4,17,-4,LEAVES:15)
Block(5,17,-4,LOG:15)
Block(6,17,-4,LEAVES:15)
Block(7,17,-4,LEAVES:15)
Block(8,17,-4,LEAVES:15)
Block(-2,17,-3,LEAVES:15)
Block(-1,17,-3,LEAVES:15)
Block(0,17,-3,LOG:15)
Block(1,17,-3,LEAVES:7)
Block(2,17,-3,LEAVES:7)
Block(3,17,-3,LEAVES:15)
Block(4,17,-3,LOG:15)
Block(5,17,-3,LEAVES:15)
Block(6,17,-3,LEAVES:15)
Block(7,17,-3,LEAVES:15)
Block(-8,17,-2,LEAVES:15)
Block(-1,17,-2,LEAVES:15)
Block(0,17,-2,LEAVES:15)
Block(3,17,-2,LEAVES:7)
Block(-4,17,-1,LEAVES:15)
Block(-2,17,-1,LEAVES:15)
Block(1,17,-1,LOG:15)
Block(4,17,-1,LEAVES:7)
Block(5,17,-1,LEAVES:15)
Block(-4,17,0,LEAVES:15)
Block(-2,17,0,LOG:15)
Block(-1,17,0,LOG:15)
Block(0,17,0,LOG:15)
Block(1,17,0,LOG:15)
Block(2,17,0,LEAVES:15)
Block(3,17,0,LEAVES:15)
Block(4,17,0,LOG:15)
Block(5,17,0,LEAVES:15)
Block(-1,17,1,LEAVES:7)
Block(3,17,1,LEAVES:15)
Block(4,17,1,LOG:15)
Block(5,17,1,LEAVES:15)
Block(6,17,1,LEAVES:15)
Block(-3,17,2,LEAVES:7)
Block(3,17,2,LEAVES:15)
Block(4,17,2,LEAVES:15)
Block(5,17,2,LEAVES:15)
Block(-2,17,3,LEAVES:7)
Block(4,17,3,LEAVES:15)
Block(-4,17,4,LEAVES:15)
Block(3,18,-10,LEAVES:15)
Block(2,18,-9,LEAVES:7)
Block(3,18,-9,LEAVES:15)
Block(4,18,-9,LEAVES:15)
Block(2,18,-8,LEAVES:7)
Block(3,18,-8,LEAVES:15)
Block(4,18,-8,LEAVES:15)
Block(5,18,-8,LEAVES:15)
Block(1,18,-7,LEAVES:15)
Block(2,18,-7,LEAVES:7)
Block(3,18,-7,LOG:15)
Block(4,18,-7,LEAVES:15)
Block(0,18,-6,LEAVES:7)
Block(1,18,-6,LEAVES:15)
Block(2,18,-6,LEAVES:7)
Block(3,18,-6,LEAVES:15)
Block(4,18,-6,LEAVES:15)
Block(-8,18,-5,LEAVES:15)
Block(-1,18,-5,LEAVES:7)
Block(1,18,-5,LEAVES:7)
Block(2,18,-5,LEAVES:15)
Block(3,18,-5,LEAVES:15)
Block(6,18,-5,LEAVES:15)
Block(-6,18,-4,LEAVES:7)
Block(-2,18,-4,LEAVES:15)
Block(-1,18,-4,LEAVES:15)
Block(0,18,-4,LEAVES:7)
Block(2,18,-4,LEAVES:7)
Block(3,18,-4,LEAVES:15)
Block(4,18,-4,LEAVES:7)
Block(5,18,-4,LEAVES:15)
Block(6,18,-4,LEAVES:15)
Block(7,18,-4,LEAVES:15)
Block(-8,18,-3,LEAVES:15)
Block(-7,18,-3,LEAVES:7)
Block(-5,18,-3,LEAVES:7)
Block(-4,18,-3,LEAVES:7)
Block(-1,18,-3,LEAVES:15)
Block(0,18,-3,LEAVES:7)
Block(1,18,-3,LEAVES:7)
Block(3,18,-3,LEAVES:7)
Block(4,18,-3,LEAVES:15)
Block(-9,18,-2,LEAVES:15)
Block(-6,18,-2,LEAVES:7)
Block(-3,18,-2,LEAVES:15)
Block(-2,18,-2,LEAVES:15)
Block(-7,18,-1,LEAVES:15)
Block(-5,18,-1,LEAVES:15)
Block(-4,18,-1,LOG:15)
Block(-3,18,-1,LOG:15)
Block(-2,18,-1,LEAVES:15)
Block(-1,18,-1,LEAVES:15)
Block(1,18,-1,LOG:15)
Block(-8,18,0,LEAVES:15)
Block(-3,18,0,LOG:15)
Block(-2,18,0,LOG:15)
Block(-1,18,0,LEAVES:15)
Block(0,18,0,LEAVES:7)
Block(1,18,0,LOG:15)
Block(2,18,0,LOG:15)
Block(3,18,0,LEAVES:15)
Block(4,18,0,LEAVES:15)
Block(-7,18,1,LEAVES:15)
Block(-4,18,1,LEAVES:15)
Block(-3,18,1,LOG:15)
Block(-2,18,1,LEAVES:7)
Block(-1,18,1,LEAVES:7)
Block(4,18,1,LEAVES:7)
Block(5,18,1,LEAVES:15)
Block(-3,18,2,LEAVES:15)
Block(-2,18,2,LEAVES:15)
Block(-1,18,2,LEAVES:7)
Block(4,18,2,LEAVES:15)
Block(-6,18,3,LEAVES:7)
Block(-4,18,3,LEAVES:15)
Block(-3,18,3,LEAVES:15)
Block(-2,18,3,LEAVES:7)
Block(-3,18,4,LEAVES:15)
Block(-4,18,5,LEAVES:15)
Block(3,19,-9,LEAVES:15)
Block(3,19,-8,LEAVES:7)
Block(4,19,-8,LEAVES:15)
Block(2,19,-7,LEAVES:7)
Block(3,19,-7,LEAVES:15)
Block(1,19,-6,LEAVES:7)
Block(3,19,-6,LEAVES:7)
Block(-7,19,-5,LEAVES:15)
Block(2,19,-5,LEAVES:7)
Block(-8,19,-4,LEAVES:15)
Block(-7,19,-4,LEAVES:15)
Block(-6,19,-4,LEAVES:15)
Block(-3,19,-4,LEAVES:15)
Block(-1,19,-4,LEAVES:7)
Block(5,19,-4,LEAVES:7)
Block(-9,19,-3,LEAVES:15)
Block(-8,19,-3,LEAVES:15)
Block(-7,19,-3,LOG:15)
Block(-6,19,-3,LEAVES:7)
Block(-5,19,-3,LEAVES:7)
Block(-4,19,-3,LEAVES:7)
Block(-3,19,-3,LEAVES:15)
Block(-2,19,-3,LEAVES:15)
Block(-8,19,-2,LEAVES:15)
Block(-7,19,-2,LEAVES:15)
Block(-6,19,-2,LEAVES:7)
Block(-5,19,-2,LEAVES:15)
Block(-4,19,-2,LEAVES:7)
Block(-3,19,-2,LOG:15)
Block(-2,19,-2,LEAVES:15)
Block(-8,19,-1,LEAVES:15)
Block(-7,19,-1,LEAVES:15)
Block(-6,19,-1,LEAVES:15)
Block(-5,19,-1,LOG:15)
Block(-4,19,-1,LEAVES:15)
Block(-3,19,-1,LEAVES:15)
Block(-2,19,-1,LEAVES:15)
Block(1,19,-1,LOG:15)
Block(-7,19,0,LEAVES:15)
Block(-6,19,0,LEAVES:15)
Block(-5,19,0,LEAVES:15)
Block(-4,19,0,LEAVES:15)
Block(-3,19,0,LEAVES:15)
Block(-2,19,0,LEAVES:7)
Block(-1,19,0,LEAVES:7)
Block(1,19,0,LOG:15)
Block(2,19,0,LOG:15)
Block(4,19,0,LEAVES:7)
Block(-6,19,1,LEAVES:15)
Block(-4,19,1,LEAVES:15)
Block(-3,19,1,LEAVES:15)
Block(-7,19,2,LEAVES:15)
Block(-5,19,2,LEAVES:7)
Block(-4,19,2,LOG:15)
Block(-3,19,2,LEAVES:15)
Block(-2,19,2,LEAVES:7)
Block(-7,19,3,LEAVES:7)
Block(-6,19,3,LEAVES:15)
Block(-5,19,3,LOG:15)
Block(-4,19,3,LEAVES:15)
Block(-3,19,3,LEAVES:15)
Block(-6,19,4,LEAVES:7)
Block(-5,19,4,LEAVES:15)
Block(-4,19,4,LEAVES:15)
Block(-5,19,5,LEAVES:15)
Block(3,20,-7,LEAVES:7)
Block(-7,20,-4,LEAVES:15)
Block(-8,20,-3,LEAVES:15)
Block(-7,20,-3,LEAVES:7)
Block(-3,20,-3,LEAVES:15)
Block(-6,20,-2,LOG:15)
Block(-5,20,-2,LEAVES:7)
Block(-3,20,-2,LEAVES:7)
Block(-7,20,-1,LEAVES:15)
Block(-6,20,-1,LEAVES:15)
Block(-5,20,-1,LEAVES:7)
Block(-4,20,-1,LEAVES:7)
Block(1,20,-1,LOG:15)
Block(-6,20,0,LEAVES:15)
Block(-3,20,0,LEAVES:7)
Block(1,20,0,LOG:15)
Block(2,20,0,LOG:15)
Block(-4,20,1,LEAVES:7)
Block(-6,20,2,LEAVES:15)
Block(-5,20,2,LEAVES:7)
Block(-4,20,2,LEAVES:15)
Block(-6,20,3,LEAVES:7)
Block(-5,20,3,LEAVES:7)
Block(-5,20,4,LEAVES:15)
Block(-6,21,-2,LEAVES:7)
Block(-6,21,-1,LEAVES:7)
Block(1,21,-1,LOG:15)
Block(2,21,-1,COCOA:1)
Block(1,21,0,LOG:15)
Block(2,21,0,LOG:15)
Block(2,21,1,COCOA:6)
Block(-4,21,2,LEAVES:7)
Block(3,22,-6,LEAVES:15)
Block(0,22,-4,LEAVES:15)
Block(3,22,-4,LEAVES:15)
Block(1,22,-2,LEAVES:7)
Block(1,22,-1,LOG:15)
Block(1,22,0,LOG:15)
Block(2,22,0,LOG:15)
Block(1,22,1,COCOA:10)
Block(6,23,-8,LEAVES:15)
Block(5,23,-7,LEAVES:15)
Block(3,23,-6,LEAVES:15)
Block(7,23,-6,LEAVES:7)
Block(2,23,-5,LEAVES:15)
Block(3,23,-5,LEAVES:15)
Block(4,23,-5,LEAVES:7)
Block(1,23,-4,LEAVES:15)
Block(2,23,-4,LEAVES:15)
Block(3,23,-4,LOG:15)
Block(6,23,-4,LEAVES:15)
Block(0,23,-3,LEAVES:15)
Block(1,23,-3,LEAVES:15)
Block(2,23,-3,LOG:15)
Block(3,23,-3,LEAVES:7)
Block(1,23,-2,LEAVES:7)
Block(2,23,-2,LOG:15)
Block(4,23,-2,LEAVES:7)
Block(1,23,-1,LOG:15)
Block(2,23,-1,LOG:15)
Block(1,23,0,LOG:15)
Block(2,23,0,LOG:15)
Block(-2,23,2,LEAVES:15)
Block(1,23,2,LEAVES:7)
Block(5,24,-8,LEAVES:15)
Block(4,24,-7,LEAVES:7)
Block(5,24,-7,LEAVES:15)
Block(6,24,-7,LEAVES:15)
Block(4,24,-6,LEAVES:7)
Block(5,24,-6,LEAVES:15)
Block(6,24,-6,LEAVES:15)
Block(7,24,-6,LEAVES:7)
Block(3,24,-5,LEAVES:7)
Block(4,24,-5,LEAVES:7)
Block(5,24,-5,LOG:15)
Block(6,24,-5,LEAVES:15)
Block(3,24,-4,LEAVES:7)
Block(4,24,-4,LOG:15)
Block(5,24,-4,LEAVES:15)
Block(1,24,-3,LEAVES:15)
Block(2,24,-3,LEAVES:7)
Block(3,24,-3,LEAVES:7)
Block(4,24,-3,LEAVES:15)
Block(5,24,-3,LEAVES:15)
Block(4,24,-2,LEAVES:7)
Block(1,24,-1,LOG:15)
Block(2,24,-1,LOG:15)
Block(3,24,-1,COCOA:9)
Block(-1,24,0,LEAVES:7)
Block(1,24,0,LOG:15)
Block(2,24,0,LOG:15)
Block(3,24,0,COCOA:5)
Block(-2,24,1,LEAVES:15)
Block(-1,24,1,LEAVES:15)
Block(0,24,1,LOG:15)
Block(1,24,1,LOG:15)
Block(2,24,1,LEAVES:7)
Block(-1,24,2,LEAVES:15)
Block(1,24,2,LOG:15)
Block(2,24,2,LOG:15)
Block(3,24,2,LOG:15)
Block(4,24,2,LEAVES:7)
Block(2,24,3,LEAVES:15)
Block(3,24,3,LEAVES:15)
Block(5,24,3,LEAVES:7)
Block(-2,24,4,LEAVES:7)
Block(0,24,4,LEAVES:7)
Block(2,24,4,LEAVES:7)
Block(4,24,5,LEAVES:7)
Block(2,24,6,LEAVES:15)
Block(5,25,-7,LEAVES:15)
Block(5,25,-6,LEAVES:7)
Block(6,25,-6,LEAVES:7)
Block(4,25,-5,LEAVES:7)
Block(5,25,-5,LEAVES:15)
Block(4,25,-3,LEAVES:7)
Block(1,25,-1,LOG:15)
Block(2,25,-1,LOG:15)
Block(1,25,0,LEAVES:15)
Block(2,25,0,LOG:15)
Block(3,25,0,COCOA:5)
Block(-1,25,1,LEAVES:15)
Block(0,25,1,LEAVES:15)
Block(1,25,1,LEAVES:15)
Block(2,25,1,LEAVES:7)
Block(-1,25,2,LEAVES:15)
Block(0,25,2,LEAVES:15)
Block(1,25,2,LOG:15)
Block(2,25,2,LEAVES:15)
Block(3,25,2,LEAVES:15)
Block(4,25,2,LEAVES:15)
Block(5,25,2,LEAVES:15)
Block(-1,25,3,LEAVES:15)
Block(0,25,3,LEAVES:7)
Block(1,25,3,LOG:15)
Block(2,25,3,LEAVES:15)
Block(4,25,3,LOG:15)
Block(5,25,3,LEAVES:15)
Block(6,25,3,LEAVES:7)
Block(-2,25,4,LEAVES:15)
Block(-1,25,4,LEAVES:15)
Block(0,25,4,LOG:15)
Block(1,25,4,LEAVES:15)
Block(2,25,4,LEAVES:7)
Block(3,25,4,LEAVES:7)
Block(4,25,4,LEAVES:15)
Block(5,25,4,LEAVES:7)
Block(0,25,5,LEAVES:7)
Block(1,25,5,LEAVES:15)
Block(2,25,5,LEAVES:15)
Block(4,25,5,LEAVES:7)
Block(-2,25,6,LEAVES:15)
Block(1,25,6,LEAVES:15)
Block(0,25,7,LEAVES:7)
Block(-2,25,8,LEAVES:15)
Block(5,26,-5,LEAVES:7)
Block(1,26,-2,COCOA:8)
Block(1,26,-1,LOG:15)
Block(2,26,-1,LOG:15)
Block(2,26,0,LOG:15)
Block(1,26,1,LEAVES:7)
Block(0,26,2,LEAVES:7)
Block(1,26,2,LEAVES:15)
Block(2,26,2,LEAVES:7)
Block(1,26,3,LEAVES:7)
Block(3,26,3,LEAVES:7)
Block(4,26,3,LEAVES:15)
Block(5,26,3,LEAVES:15)
Block(-1,26,4,LEAVES:15)
Block(0,26,4,LEAVES:7)
Block(1,26,4,LEAVES:15)
Block(2,26,4,LEAVES:7)
Block(4,26,4,LEAVES:7)
Block(-2,26,5,LEAVES:15)
Block(-1,26,5,LOG:15)
Block(0,26,5,LEAVES:7)
Block(1,26,5,LEAVES:15)
Block(-3,26,6,LEAVES:15)
Block(-2,26,6,LEAVES:15)
Block(-1,26,6,LEAVES:15)
Block(0,26,6,LEAVES:15)
Block(-2,26,7,LEAVES:15)
Block(-1,26,7,LEAVES:15)
Block(0,26,7,LEAVES:15)
Block(-1,26,8,LEAVES:15)
Block(1,27,-1,LOG:15)
Block(2,27,-1,LOG:15)
Block(3,27,-1,LOG:15)
Block(4,27,-1,COCOA:9)
Block(2,27,0,LOG:15)
Block(3,27,0,LEAVES:7)
Block(1,27,2,LEAVES:7)
Block(4,27,3,LEAVES:15)
Block(-1,27,4,LEAVES:15)
Block(1,27,4,LEAVES:7)
Block(-1,27,5,LEAVES:15)
Block(-2,27,6,LEAVES:15)
Block(-1,27,6,LEAVES:15)
Block(-1,27,7,LEAVES:15)
Block(5,28,-5,LEAVES:15)
Block(7,28,-4,LEAVES:15)
Block(3,28,-3,LEAVES:7)
Block(5,28,-3,LEAVES:7)
Block(-4,28,-2,LEAVES:15)
Block(-2,28,-2,LEAVES:15)
Block(1,28,-2,COCOA:4)
Block(2,28,-2,LEAVES:7)
Block(3,28,-2,LEAVES:15)
Block(4,28,-2,LEAVES:7)
Block(6,28,-2,LEAVES:15)
Block(8,28,-2,LEAVES:15)
Block(1,28,-1,LOG:15)
Block(2,28,-1,LOG:15)
Block(3,28,-1,LOG:15)
Block(4,28,-1,LOG:15)
Block(5,28,-1,COCOA:9)
Block(0,28,0,LEAVES:7)
Block(2,28,0,LOG:15)
Block(4,28,0,LOG:15)
Block(5,28,0,LEAVES:15)
Block(6,28,0,LEAVES:7)
Block(-2,28,1,LEAVES:15)
Block(4,28,2,LEAVES:7)
Block(6,28,2,LEAVES:7)
Block(6,28,4,LEAVES:15)
Block(-1,28,5,LEAVES:15)
Block(-4,29,-6,LEAVES:7)
Block(-6,29,-5,LEAVES:15)
Block(-2,29,-5,LEAVES:15)
Block(6,29,-5,LEAVES:15)
Block(-5,29,-4,LEAVES:15)
Block(5,29,-4,LEAVES:15)
Block(6,29,-4,LEAVES:15)
Block(7,29,-4,LEAVES:15)
Block(-3,29,-3,LEAVES:7)
Block(0,29,-3,LEAVES:7)
Block(4,29,-3,LEAVES:7)
Block(5,29,-3,LEAVES:15)
Block(6,29,-3,LOG:15)
Block(7,29,-3,LEAVES:15)
Block(8,29,-3,LEAVES:15)
Block(-4,29,-2,LEAVES:15)
Block(-3,29,-2,LEAVES:15)
Block(-2,29,-2,LOG:15)
Block(-1,29,-2,LEAVES:7)
Block(3,29,-2,LEAVES:7)
Block(4,29,-2,LEAVES:7)
Block(5,29,-2,LOG:15)
Block(7,29,-2,LEAVES:15)
Block(-3,29,-1,LEAVES:15)
Block(-2,29,-1,LEAVES:15)
Block(-1,29,-1,LOG:15)
Block(0,29,-1,LOG:15)
Block(1,29,-1,LOG:15)
Block(2,29,-1,LOG:15)
Block(3,29,-1,LEAVES:7)
Block(4,29,-1,LEAVES:7)
Block(5,29,-1,LEAVES:15)
Block(-2,29,0,LEAVES:15)
Block(-1,29,0,LEAVES:15)
Block(0,29,0,LEAVES:7)
Block(2,29,0,LOG:15)
Block(3,29,0,LEAVES:7)
Block(4,29,0,LEAVES:15)
Block(5,29,0,LEAVES:7)
Block(-1,29,1,LEAVES:15)
Block(4,29,1,LEAVES:7)
Block(5,29,1,LOG:15)
Block(6,29,1,LEAVES:7)
Block(4,29,2,LEAVES:7)
Block(5,29,2,LEAVES:15)
Block(6,29,2,LEAVES:15)
Block(7,29,2,LEAVES:15)
Block(4,29,3,LEAVES:7)
Block(5,29,3,LEAVES:15)
Block(6,29,3,LEAVES:15)
Block(5,29,4,LEAVES:15)
Block(-4,30,-6,LEAVES:7)
Block(-5,30,-5,LEAVES:15)
Block(-4,30,-5,LEAVES:15)
Block(-3,30,-5,LEAVES:15)
Block(-6,30,-4,LEAVES:15)
Block(-5,30,-4,LEAVES:15)
Block(-4,30,-4,LEAVES:15)
Block(-3,30,-4,LOG:15)
Block(-2,30,-4,LEAVES:15)
Block(-1,30,-4,LEAVES:15)
Block(6,30,-4,LEAVES:15)
Block(-5,30,-3,LEAVES:7)
Block(-4,30,-3,LEAVES:7)
Block(-3,30,-3,LEAVES:7)
Block(-2,30,-3,LOG:15)
Block(-1,30,-3,LEAVES:15)
Block(0,30,-3,LEAVES:7)
Block(5,30,-3,LEAVES:15)
Block(6,30,-3,LEAVES:15)
Block(7,30,-3,LEAVES:15)
Block(-3,30,-2,LEAVES:7)
Block(-2,30,-2,LEAVES:7)
Block(-1,30,-2,LEAVES:7)
Block(4,30,-2,LEAVES:7)
Block(5,30,-2,LEAVES:15)
Block(6,30,-2,LEAVES:15)
Block(-1,30,-1,LEAVES:7)
Block(1,30,-1,LOG:15)
Block(2,30,-1,LOG:15)
Block(5,30,-1,LEAVES:15)
Block(-1,30,0,LEAVES:15)
Block(2,30,0,LOG:15)
Block(4,30,0,LEAVES:7)
Block(5,30,1,LEAVES:7)
Block(5,30,2,LEAVES:15)
Block(6,30,2,LEAVES:15)
Block(5,30,3,LEAVES:15)
Block(-4,31,-5,LEAVES:7)
Block(-5,31,-4,LEAVES:15)
Block(-4,31,-4,LEAVES:7)
Block(-3,31,-4,LEAVES:15)
Block(-3,31,-3,LEAVES:7)
Block(-1,31,-3,LEAVES:7)
Block(5,31,-2,LEAVES:7)
Block(1,31,-1,LOG:15)
Block(2,31,-1,LOG:15)
Block(2,31,0,LOG:15)
Block(5,31,2,LEAVES:15)
Block(-3,32,-4,LEAVES:7)
Block(0,32,-1,COCOA:11)
Block(1,32,-1,LOG:15)
Block(2,32,-1,LOG:15)
Block(1,32,0,COCOA:6)
Block(2,32,0,LOG:15)
Block(2,33,-2,COCOA:8)
Block(1,33,-1,LOG:15)
Block(2,33,-1,LOG:15)
Block(2,33,0,LOG:15)
Block(2,34,-3,LEAVES:7)
Block(5,34,-3,LEAVES:15)
Block(2,34,-1,LOG:15)
Block(2,34,0,LOG:15)
Block(1,35,-7,LEAVES:15)
Block(-1,35,-6,LEAVES:7)
Block(1,35,-5,LEAVES:7)
Block(3,35,-5,LEAVES:7)
Block(5,35,-5,LEAVES:7)
Block(-2,35,-4,LEAVES:7)
Block(0,35,-4,LEAVES:15)
Block(1,35,-4,LEAVES:15)
Block(-1,35,-3,LEAVES:7)
Block(0,35,-3,LOG:15)
Block(1,35,-3,LOG:15)
Block(2,35,-3,LOG:15)
Block(4,35,-3,LEAVES:15)
Block(1,35,-2,LEAVES:7)
Block(2,35,-2,LOG:15)
Block(3,35,-2,LOG:15)
Block(4,35,-2,LEAVES:15)
Block(5,35,-2,LEAVES:15)
Block(2,35,-1,LOG:15)
Block(4,35,-1,LEAVES:7)
Block(1,35,0,COCOA:11)
Block(2,35,0,LOG:15)
Block(5,36,-9,LEAVES:15)
Block(3,36,-8,LEAVES:7)
Block(2,36,-7,LEAVES:15)
Block(5,36,-7,LEAVES:15)
Block(-1,36,-6,LEAVES:7)
Block(1,36,-6,LEAVES:15)
Block(2,36,-6,LEAVES:15)
Block(3,36,-6,LEAVES:7)
Block(-2,36,-5,LEAVES:7)
Block(-1,36,-5,LEAVES:15)
Block(0,36,-5,LEAVES:7)
Block(1,36,-5,LEAVES:7)
Block(2,36,-5,LEAVES:15)
Block(3,36,-5,LOG:15)
Block(4,36,-5,LEAVES:15)
Block(5,36,-5,LEAVES:15)
Block(-3,36,-4,LEAVES:7)
Block(-2,36,-4,LEAVES:15)
Block(-1,36,-4,LOG:15)
Block(1,36,-4,LEAVES:15)
Block(2,36,-4,LOG:15)
Block(3,36,-4,LEAVES:7)
Block(4,36,-4,LEAVES:15)
Block(-2,36,-3,LEAVES:15)
Block(-1,36,-3,LEAVES:15)
Block(0,36,-3,LEAVES:15)
Block(1,36,-3,LEAVES:15)
Block(2,36,-3,LOG:15)
Block(3,36,-3,LEAVES:15)
Block(4,36,-3,LEAVES:15)
Block(1,36,-2,LEAVES:7)
Block(2,36,-2,LEAVES:15)
Block(3,36,-2,LEAVES:15)
Block(4,36,-2,LEAVES:15)
Block(2,36,-1,LEAVES:15)
Block(2,36,0,LOG:15)
Block(4,37,-9,LEAVES:15)
Block(3,37,-8,LEAVES:15)
Block(4,37,-8,LEAVES:15)
Block(5,37,-8,LEAVES:15)
Block(3,37,-7,LEAVES:15)
Block(4,37,-7,LEAVES:15)
Block(5,37,-7,LEAVES:15)
Block(6,37,-7,LEAVES:15)
Block(2,37,-6,LEAVES:15)
Block(3,37,-6,LEAVES:7)
Block(4,37,-6,LOG:15)
Block(5,37,-6,LEAVES:15)
Block(-1,37,-5,LEAVES:7)
Block(1,37,-5,LEAVES:7)
Block(2,37,-5,LEAVES:15)
Block(3,37,-5,LEAVES:7)
Block(4,37,-5,LEAVES:15)
Block(-2,37,-4,LEAVES:15)
Block(-1,37,-4,LEAVES:15)
Block(0,37,-4,LEAVES:7)
Block(2,37,-4,LEAVES:7)
Block(1,37,-3,LEAVES:7)
Block(2,37,-3,LEAVES:15)
Block(3,37,-3,LEAVES:7)
Block(2,37,-2,LEAVES:7)
Block(2,37,0,LOG:15)
Block(3,37,0,COCOA:9)
Block(4,38,-8,LEAVES:15)
Block(4,38,-7,LEAVES:15)
Block(5,38,-7,LEAVES:15)
Block(4,38,-6,LEAVES:15)
Block(2,38,-5,LEAVES:7)
Block(4,38,-5,LEAVES:15)
Block(-1,38,-4,LEAVES:15)
Block(2,38,-3,LEAVES:7)
Block(2,38,-1,COCOA:0)
Block(2,38,0,LOG:15)
Block(2,38,1,COCOA:6)
Block(3,38,4,LEAVES:7)
Block(1,38,5,LEAVES:15)
Block(3,38,6,LEAVES:7)
Block(4,39,-6,LEAVES:15)
Block(2,39,-1,COCOA:4)
Block(2,39,0,LOG:15)
Block(2,39,1,LOG:15)
Block(2,39,2,LOG:15)
Block(3,39,2,LEAVES:15)
Block(-2,39,3,LEAVES:7)
Block(0,39,3,LEAVES:7)
Block(2,39,3,LOG:15)
Block(4,39,3,LEAVES:15)
Block(1,39,4,LEAVES:15)
Block(3,39,4,LOG:15)
Block(5,39,4,LEAVES:15)
Block(-1,39,5,LEAVES:15)
Block(2,39,5,LEAVES:15)
Block(3,39,5,LEAVES:15)
Block(4,39,5,LEAVES:15)
Block(1,39,6,LEAVES:15)
Block(3,39,6,LEAVES:15)
Block(7,39,6,LEAVES:7)
Block(5,39,7,LEAVES:7)
Block(4,39,8,LEAVES:7)
Block(6,39,9,LEAVES:15)
Block(1,40,0,COCOA:11)
Block(2,40,0,LOG:15)
Block(1,40,1,LEAVES:7)
Block(2,40,1,LEAVES:7)
Block(-1,40,2,LEAVES:7)
Block(0,40,2,LEAVES:7)
Block(1,40,2,LOG:15)
Block(2,40,2,LEAVES:15)
Block(3,40,2,LEAVES:15)
Block(-2,40,3,LEAVES:15)
Block(-1,40,3,LEAVES:15)
Block(0,40,3,LOG:15)
Block(1,40,3,LEAVES:7)
Block(2,40,3,LEAVES:7)
Block(3,40,3,LEAVES:15)
Block(-1,40,4,LEAVES:15)
Block(0,40,4,LEAVES:15)
Block(1,40,4,LEAVES:15)
Block(2,40,4,LEAVES:15)
Block(3,40,4,LEAVES:15)
Block(4,40,4,LEAVES:15)
Block(-1,40,5,LEAVES:15)
Block(0,40,5,LEAVES:15)
Block(1,40,5,LEAVES:15)
Block(3,40,5,LEAVES:15)
Block(4,40,5,LOG:15)
Block(5,40,5,LEAVES:15)
Block(6,40,5,LEAVES:15)
Block(0,40,6,LEAVES:15)
Block(4,40,6,LEAVES:7)
Block(5,40,6,LOG:15)
Block(6,40,6,LEAVES:15)
Block(7,40,6,LEAVES:7)
Block(4,40,7,LEAVES:7)
Block(5,40,7,LEAVES:15)
Block(6,40,7,LEAVES:7)
Block(4,40,8,LEAVES:7)
Block(5,40,8,LEAVES:15)
Block(6,40,8,LEAVES:15)
Block(5,40,9,LEAVES:15)
Block(2,41,0,LOG:15)
Block(3,41,0,COCOA:9)
Block(1,41,2,LEAVES:7)
Block(-1,41,3,LEAVES:7)
Block(0,41,3,LEAVES:7)
Block(-1,41,4,LEAVES:7)
Block(0,41,4,LEAVES:15)
Block(3,41,4,LEAVES:15)
Block(4,41,4,LEAVES:15)
Block(0,41,5,LEAVES:15)
Block(4,41,5,LEAVES:15)
Block(5,41,5,LEAVES:15)
Block(4,41,6,LEAVES:7)
Block(5,41,6,LEAVES:7)
Block(6,41,6,LEAVES:7)
Block(4,41,7,LEAVES:7)
Block(5,41,7,LEAVES:15)
Block(6,41,7,LEAVES:7)
Block(5,41,8,LEAVES:15)
Block(3,42,-1,LEAVES:7)
Block(1,42,0,COCOA:11)
Block(2,42,0,LOG:15)
Block(2,42,1,LEAVES:7)
Block(5,42,1,LEAVES:15)
Block(0,42,4,LEAVES:7)
Block(4,42,5,LEAVES:7)
Block(3,43,-3,LEAVES:7)
Block(5,43,-3,LEAVES:7)
Block(3,43,-2,LEAVES:15)
Block(6,43,-2,LEAVES:7)
Block(3,43,-1,LOG:15)
Block(4,43,-1,LEAVES:7)
Block(1,43,0,LEAVES:7)
Block(2,43,0,LOG:15)
Block(3,43,0,LOG:15)
Block(4,43,0,LEAVES:15)
Block(5,43,0,LEAVES:15)
Block(7,43,0,LEAVES:15)
Block(3,43,1,LEAVES:7)
Block(4,43,1,LEAVES:15)
Block(2,43,2,LEAVES:7)
Block(3,43,3,LEAVES:7)
Block(4,44,-3,LEAVES:7)
Block(5,44,-3,LEAVES:7)
Block(0,44,-2,LEAVES:7)
Block(2,44,-2,LEAVES:7)
Block(3,44,-2,LEAVES:7)
Block(4,44,-2,LEAVES:7)
Block(5,44,-2,LEAVES:15)
Block(6,44,-2,LEAVES:7)
Block(-1,44,-1,LEAVES:7)
Block(2,44,-1,LEAVES:15)
Block(3,44,-1,LEAVES:7)
Block(4,44,-1,LOG:15)
Block(5,44,-1,LEAVES:15)
Block(6,44,-1,LEAVES:15)
Block(7,44,-1,LEAVES:15)
Block(1,44,0,LEAVES:7)
Block(2,44,0,LOG:15)
Block(4,44,0,LEAVES:15)
Block(5,44,0,LEAVES:15)
Block(6,44,0,LEAVES:15)
Block(0,44,1,LEAVES:15)
Block(1,44,1,LEAVES:15)
Block(2,44,1,LOG:15)
Block(3,44,1,LEAVES:15)
Block(1,44,2,LEAVES:15)
Block(2,44,2,LEAVES:15)
Block(3,44,2,LEAVES:15)
Block(1,44,3,LEAVES:15)
Block(2,44,3,LEAVES:15)
Block(3,44,3,LEAVES:7)
Block(4,44,3,LEAVES:7)
Block(2,44,4,LEAVES:7)
Block(0,45,-2,LEAVES:7)
Block(1,45,-2,LEAVES:7)
Block(4,45,-2,LEAVES:7)
Block(5,45,-2,LEAVES:7)
Block(-1,45,-1,LEAVES:15)
Block(0,45,-1,LEAVES:15)
Block(1,45,-1,LOG:15)
Block(2,45,-1,LEAVES:7)
Block(4,45,-1,LEAVES:7)
Block(5,45,-1,LEAVES:15)
Block(6,45,-1,LEAVES:15)
Block(0,45,0,LEAVES:7)
Block(1,45,0,LEAVES:7)
Block(2,45,0,LOG:15)
Block(3,45,0,LEAVES:15)
Block(5,45,0,LEAVES:7)
Block(1,45,1,LEAVES:7)
Block(1,45,2,LEAVES:15)
Block(2,45,2,LEAVES:15)
Block(3,45,2,LEAVES:15)
Block(2,45,3,LEAVES:15)
Block(0,46,-1,LEAVES:7)
Block(1,46,-1,LEAVES:7)
Block(2,46,-1,LEAVES:7)
Block(5,46,-1,LEAVES:7)
Block(1,46,0,LEAVES:7)
Block(2,46,0,LEAVES:15)
Block(3,46,0,LEAVES:15)
Block(2,46,1,LEAVES:15)
Block(2,46,2,LEAVES:15)
Block(2,47,0,LEAVES:7)

#######################################################################
# +-----------------------------------------------------------------+ #
# |                            BO3 checks                           | #
# +-----------------------------------------------------------------+ #
#######################################################################

# Require a condition at a certain location in order for the BO3 to be spawned.
# BlockCheck(x,y,z,BlockName[,BlockName[,...]]) - one of the blocks must be at the location
# BlockCheckNot(x,y,z,BlockName[,BlockName[,...]]) - all the blocks must not be at the location
# LightCheck(x,y,z,minLightLevel,maxLightLevel) - light must be between min and max (inclusive)

# You can use "Solid" as a BlockName for matching all solid blocks or "All" to match all blocks that aren't air.

# Examples:
BlockCheck(0,-1,0,GRASS,DIRT,DIRT:2,STONE)
#   BlockCheck(0,-1,0,Solid)       Require any solid block just below the object
#   BlockCheck(0,-1,0,WOOL)        Require any type of wool just below the object
#   BlockCheck(0,-1,0,WOOL:0)      Require white wool just below the object
#   BlockCheckNot(0,-1,0,WOOL:0)   Require that there is no white wool below the object
#   LightCheck(0,0,0,0,1)          Require almost complete darkness just below the object

#######################################################################
# +-----------------------------------------------------------------+ #
# |                             Branches                            | #
# +-----------------------------------------------------------------+ #
#######################################################################

# Branches are objects that will spawn when this object spawns when it is used in
# the CustomStructure resource. Branches can also have branches, making complex
# structures possible. See the wiki for more details.

# Regular Branches spawn each branch with an independent chance of spawning.
# Branch(x,y,z,branchName,rotation,chance[,anotherBranchName,rotation,chance[,...]][IndividualChance])
# branchName - name of the object to spawn.
# rotation - NORTH, SOUTH, EAST or WEST.
# IndividualChance - The chance each branch has to spawn, assumed to be 100 when left blank

# Weighted Branches spawn branches with a dependent chance of spawning.
# WeightedBranch(x,y,z,branchName,rotation,chance[,anotherBranchName,rotation,chance[,...]][MaxChanceOutOf])
# MaxChanceOutOf - The chance all branches have to spawn out of, assumed to be 100 when left blank
