#######################################################################
# +-----------------------------------------------------------------+ #
# |                            BO3 object                           | #
# +-----------------------------------------------------------------+ #
#######################################################################

# This is the config file of a custom object.
# If you add this object correctly to your BiomeConfigs, it will spawn in the world.

# This is the creator of this BO3 object
Author: BO3 BulkEdit (by LanToaster)

# A short description of this BO3 object
Description: This Object was Created with BO3_BulkEdit

# The BO3 version, don't change this! It can be used by external applications to do a version check.
Version: 3

# The settings mode, WriteAll, WriteWithoutComments or WriteDisable. See WorldConfig.
SettingsMode: WriteDisable


#######################################################################
# +-----------------------------------------------------------------+ #
# |                          Main settings                          | #
# +-----------------------------------------------------------------+ #
#######################################################################

# This needs to be set to true to spawn the object in the Tree and Sapling resources.
Tree: true

# The frequency of the BO3 from 1 to 200. Tries this many times to spawn this BO3 when using the CustomObject(...) resource.
# Ignored by Tree(..), Sapling(..) and CustomStructure(..)
Frequency: 1

# The rarity of the BO3 from 0 to 100. Each spawn attempt has rarity% chance to succeed when using the CustomObject(...) resource.
# Ignored by Tree(..), Sapling(..) and CustomStructure(..)
Rarity: 100.0

# If you set this to true, the BO3 will be placed with a random rotation.
RotateRandomly: true

# The spawn height of the BO3 - randomY, highestBlock or highestSolidBlock.
SpawnHeight: highestSolidBlock
SpawnHeightOffset: -1
# The height limits for the BO3.
MinHeight: 0

MaxHeight: 75

# Objects can have other objects attacthed to it: branches. Branches can also
# have branches attached to it, which can also have branches, etc. This is the
# maximum branch depth for this objects.
MaxBranchDepth: 10

# When spawned with the UseWorld keyword, this BO3 should NOT spawn in the following biomes.
# If you writer.write the BO3 name directly in the BiomeConfigs, this will be ignored.
ExcludedBiomes: All


#######################################################################
# +-----------------------------------------------------------------+ #
# |                      Source block settings                      | #
# +-----------------------------------------------------------------+ #
#######################################################################

# The block(s) the BO3 should spawn in.
SourceBlocks: AIR,GRASS,DIRT,DIRT:1,STONE,DIRT:2,STATIONARY_WATER,CLAY,SAND,SAND:1,GRAVEL

# The maximum percentage of the BO3 that can be outside the SourceBlock.
# The BO3 won't be placed on a location with more blocks outside the SourceBlock than this percentage.
MaxPercentageOutsideSourceBlock: 0

# What to do when a block is about to be placed outside the SourceBlock? (dontPlace, placeAnyway)
OutsideSourceBlock: dontPlace


#######################################################################
# +-----------------------------------------------------------------+ #
# |                              Blocks                             | #
# +-----------------------------------------------------------------+ #
#######################################################################

# All the blocks used in the BO3 are listed here. Possible blocks:
# Block(x,y,z,id[.data][,nbtfile.nbt)
# RandomBlock(x,y,z,id[:data][,nbtfile.nbt],chance[,id[:data][,nbtfile.nbt],chance[,...]])
# So RandomBlock(0,0,0,CHEST,chest.nbt,50,CHEST,anotherchest.nbt,100) will spawn a chest at
# the BO3 origin, and give it a 50% chance to have the contents of chest.nbt, or, if that
# fails, a 100% percent chance to have the contents of anotherchest.nbt.
Block(-2,0,-6,LOG:15)
Block(-6,0,-5,LOG:15)
Block(-6,0,-4,LOG:15)
Block(-1,0,-4,LOG:15)
Block(0,0,-4,LOG:15)
Block(-4,0,-2,LOG:15)
Block(-7,0,0,LOG:15)
Block(1,0,0,LOG:15)
Block(-1,0,1,LOG:15)
Block(-6,0,2,LOG:15)
Block(-2,0,2,LOG:15)
Block(-4,0,3,LOG:15)
Block(-2,1,-6,LOG:15)
Block(-2,1,-5,LOG:15)
Block(-6,1,-4,LOG:15)
Block(-1,1,-4,LOG:15)
Block(0,1,-4,LOG:15)
Block(-4,1,-2,LOG:15)
Block(1,1,-1,LOG:15)
Block(-7,1,0,LOG:15)
Block(-6,1,0,LOG:15)
Block(1,1,0,LOG:15)
Block(-2,1,1,LOG:15)
Block(-1,1,1,LOG:15)
Block(-6,1,2,LOG:15)
Block(-5,1,2,LOG:15)
Block(-3,2,-5,LOG:15)
Block(-2,2,-5,LOG:15)
Block(-6,2,-4,LOG:15)
Block(-1,2,-4,LOG:15)
Block(-6,2,-3,LOG:15)
Block(-4,2,-3,LOG:15)
Block(-1,2,-3,LOG:15)
Block(-4,2,-2,LOG:15)
Block(0,2,-2,LOG:15)
Block(0,2,-1,LOG:15)
Block(1,2,-1,LOG:15)
Block(-6,2,0,LOG:15)
Block(-2,2,0,LOG:15)
Block(-5,2,1,LOG:15)
Block(-2,2,1,LOG:15)
Block(-5,2,2,LOG:15)
Block(-3,3,-5,LOG:15)
Block(-1,3,-4,LOG:15)
Block(-6,3,-3,LOG:15)
Block(-5,3,-3,LOG:15)
Block(-4,3,-3,LOG:15)
Block(-1,3,-3,LOG:15)
Block(-1,3,-2,LOG:15)
Block(0,3,-2,LOG:15)
Block(-4,3,-1,LOG:15)
Block(-6,3,0,LOG:15)
Block(-5,3,0,LOG:15)
Block(-2,3,0,LOG:15)
Block(-5,3,1,LOG:15)
Block(-3,4,-5,LOG:15)
Block(-3,4,-4,LOG:15)
Block(-5,4,-3,LOG:15)
Block(-1,4,-3,LOG:15)
Block(-2,4,-2,LOG:15)
Block(-1,4,-2,LOG:15)
Block(-4,4,-1,LOG:15)
Block(-3,4,-1,LOG:15)
Block(-2,4,-1,LOG:15)
Block(-6,4,0,LOG:15)
Block(-5,4,0,LOG:15)
Block(-4,4,0,LOG:15)
Block(-2,4,0,LOG:15)
Block(-3,5,-4,LOG:15)
Block(-5,5,-3,LOG:15)
Block(-2,5,-3,LOG:15)
Block(-1,5,-3,LOG:15)
Block(-5,5,-2,LOG:15)
Block(-3,5,-2,LOG:15)
Block(-2,5,-2,LOG:15)
Block(-1,5,-2,LOG:15)
Block(-4,5,-1,LOG:15)
Block(-3,5,-1,LOG:15)
Block(-2,5,-1,LOG:15)
Block(-5,5,0,LOG:15)
Block(-4,5,0,LOG:15)
Block(-2,5,0,LOG:15)
Block(-3,6,-4,LOG:15)
Block(-3,6,-3,LOG:15)
Block(-2,6,-3,LOG:15)
Block(-1,6,-3,LOG:15)
Block(-5,6,-2,LOG:15)
Block(-4,6,-2,LOG:15)
Block(-3,6,-2,LOG:15)
Block(-2,6,-2,LOG:15)
Block(-1,6,-2,LOG:15)
Block(-4,6,-1,LOG:15)
Block(-3,6,-1,LOG:15)
Block(-2,6,-1,LOG:15)
Block(-4,6,0,LOG:15)
Block(-2,6,0,LOG:15)
Block(-3,7,-3,LOG:15)
Block(-2,7,-3,LOG:15)
Block(-5,7,-2,LOG:15)
Block(-4,7,-2,LOG:15)
Block(-3,7,-2,LOG:15)
Block(-2,7,-2,LOG:15)
Block(-1,7,-2,LOG:15)
Block(-4,7,-1,LOG:15)
Block(-3,7,-1,LOG:15)
Block(-2,7,-1,LOG:15)
Block(-4,7,0,LOG:15)
Block(-2,7,0,LOG:15)
Block(-3,8,-3,LOG:15)
Block(-2,8,-3,LOG:15)
Block(-4,8,-2,LOG:15)
Block(-3,8,-2,LOG:15)
Block(-2,8,-2,LOG:15)
Block(-1,8,-2,LOG:15)
Block(-4,8,-1,LOG:15)
Block(-3,8,-1,LOG:15)
Block(-2,8,-1,LOG:15)
Block(-3,9,-3,LOG:15)
Block(-2,9,-3,LOG:15)
Block(-4,9,-2,LOG:15)
Block(-3,9,-2,LOG:15)
Block(-2,9,-2,LOG:15)
Block(-1,9,-2,LOG:15)
Block(-4,9,-1,LOG:15)
Block(-3,9,-1,LOG:15)
Block(-2,9,-1,LOG:15)
Block(-3,10,-3,LOG:15)
Block(-2,10,-3,LOG:15)
Block(-4,10,-2,LOG:15)
Block(-3,10,-2,LOG:15)
Block(-2,10,-2,LOG:15)
Block(-1,10,-2,LOG:15)
Block(-4,10,-1,LOG:15)
Block(-3,10,-1,LOG:15)
Block(-2,10,-1,LOG:15)
Block(-3,11,-3,LOG:15)
Block(-4,11,-2,LOG:15)
Block(-3,11,-2,LOG:15)
Block(-2,11,-2,LOG:15)
Block(-1,11,-2,LOG:15)
Block(-3,11,-1,LOG:15)
Block(-2,11,-1,LOG:15)
Block(-3,12,-3,LOG:15)
Block(-4,12,-2,LOG:15)
Block(-3,12,-2,LOG:15)
Block(-2,12,-2,LOG:15)
Block(-1,12,-2,LOG:15)
Block(-3,12,-1,LOG:15)
Block(-2,12,-1,LOG:15)
Block(-3,13,-3,LOG:15)
Block(-4,13,-2,LOG:15)
Block(-3,13,-2,LOG:15)
Block(-2,13,-2,LOG:15)
Block(-1,13,-2,LOG:15)
Block(-3,13,-1,LOG:15)
Block(-2,13,-1,LOG:15)
Block(-3,14,-3,LOG:15)
Block(-4,14,-2,LOG:15)
Block(-3,14,-2,LOG:15)
Block(-2,14,-2,LOG:15)
Block(-1,14,-2,LOG:15)
Block(-3,14,-1,LOG:15)
Block(-2,14,-1,LOG:15)
Block(6,15,-10,LEAVES:15)
Block(-6,15,-5,LEAVES:7)
Block(-6,15,-4,LEAVES:15)
Block(-5,15,-4,LEAVES:7)
Block(-8,15,-3,LEAVES:7)
Block(-6,15,-3,LOG:15)
Block(-3,15,-3,LOG:15)
Block(0,15,-3,LOG:15)
Block(-6,15,-2,LOG:15)
Block(-5,15,-2,LOG:15)
Block(-4,15,-2,LOG:15)
Block(-3,15,-2,LOG:15)
Block(-2,15,-2,LOG:15)
Block(-1,15,-2,LOG:15)
Block(0,15,-2,LOG:15)
Block(3,15,-2,LOG:15)
Block(4,15,-2,LOG:15)
Block(-3,15,-1,LOG:15)
Block(-2,15,-1,LOG:15)
Block(5,15,-1,LOG:15)
Block(1,15,0,LEAVES:15)
Block(3,15,1,LEAVES:7)
Block(6,16,-13,LEAVES:15)
Block(4,16,-12,LEAVES:7)
Block(-2,16,-11,LEAVES:15)
Block(3,16,-11,LEAVES:15)
Block(6,16,-11,LEAVES:15)
Block(0,16,-10,LEAVES:15)
Block(5,16,-10,LEAVES:15)
Block(4,16,-9,LEAVES:7)
Block(7,16,-9,LEAVES:15)
Block(-2,16,-8,LEAVES:15)
Block(-11,16,-7,LEAVES:7)
Block(-9,16,-7,LEAVES:7)
Block(-12,16,-6,LEAVES:15)
Block(-10,16,-6,LEAVES:7)
Block(0,16,-6,LEAVES:7)
Block(3,16,-6,LOG:15)
Block(-13,16,-5,LEAVES:15)
Block(-8,16,-5,LEAVES:7)
Block(-7,16,-5,LEAVES:7)
Block(2,16,-5,LOG:15)
Block(4,16,-5,LOG:15)
Block(-9,16,-4,LEAVES:7)
Block(-7,16,-4,LOG:15)
Block(-6,16,-4,LEAVES:7)
Block(-1,16,-4,LEAVES:15)
Block(1,16,-4,LEAVES:7)
Block(2,16,-4,LOG:15)
Block(3,16,-4,LOG:15)
Block(4,16,-4,LEAVES:15)
Block(7,16,-4,LEAVES:15)
Block(-11,16,-3,LEAVES:7)
Block(-10,16,-3,LEAVES:7)
Block(-8,16,-3,LOG:15)
Block(-7,16,-3,LOG:15)
Block(-6,16,-3,LOG:15)
Block(-5,16,-3,LEAVES:15)
Block(-3,16,-3,LOG:15)
Block(0,16,-3,LOG:15)
Block(1,16,-3,LOG:15)
Block(2,16,-3,LOG:15)
Block(6,16,-3,LEAVES:15)
Block(12,16,-3,LEAVES:15)
Block(-9,16,-2,LOG:15)
Block(-8,16,-2,LEAVES:7)
Block(-6,16,-2,LEAVES:7)
Block(-4,16,-2,LOG:15)
Block(-3,16,-2,LOG:15)
Block(-2,16,-2,LOG:15)
Block(0,16,-2,LEAVES:7)
Block(3,16,-2,LOG:15)
Block(4,16,-2,LOG:15)
Block(8,16,-2,LEAVES:15)
Block(9,16,-2,LEAVES:15)
Block(11,16,-2,LEAVES:15)
Block(-10,16,-1,LEAVES:7)
Block(-3,16,-1,LOG:15)
Block(-2,16,-1,LOG:15)
Block(4,16,-1,LOG:15)
Block(6,16,-1,LEAVES:7)
Block(-3,16,0,LOG:15)
Block(3,16,0,LOG:15)
Block(4,16,0,LOG:15)
Block(7,16,0,LEAVES:7)
Block(8,16,0,LOG:15)
Block(9,16,0,LOG:15)
Block(0,16,1,LEAVES:15)
Block(2,16,1,LEAVES:15)
Block(3,16,1,LOG:15)
Block(4,16,1,LEAVES:7)
Block(10,16,1,LEAVES:15)
Block(6,16,2,LEAVES:15)
Block(13,16,2,LEAVES:15)
Block(9,16,3,LEAVES:15)
Block(11,16,3,LEAVES:15)
Block(5,17,-13,LEAVES:15)
Block(-2,17,-12,LEAVES:15)
Block(4,17,-12,LEAVES:15)
Block(5,17,-12,LEAVES:15)
Block(6,17,-12,LEAVES:15)
Block(-1,17,-11,LEAVES:15)
Block(4,17,-11,LEAVES:15)
Block(5,17,-11,LEAVES:15)
Block(6,17,-11,LEAVES:15)
Block(-3,17,-10,LEAVES:15)
Block(1,17,-10,LEAVES:15)
Block(4,17,-10,LEAVES:15)
Block(5,17,-10,LOG:15)
Block(6,17,-10,LEAVES:15)
Block(7,17,-10,LEAVES:15)
Block(-2,17,-9,LEAVES:15)
Block(0,17,-9,LEAVES:15)
Block(1,17,-9,LEAVES:15)
Block(2,17,-9,LEAVES:7)
Block(3,17,-9,LEAVES:7)
Block(4,17,-9,LOG:15)
Block(5,17,-9,LEAVES:15)
Block(6,17,-9,LEAVES:15)
Block(-11,17,-8,LEAVES:7)
Block(-1,17,-8,LEAVES:15)
Block(1,17,-8,LOG:15)
Block(2,17,-8,LEAVES:7)
Block(3,17,-8,LOG:15)
Block(6,17,-8,LEAVES:15)
Block(-12,17,-7,LEAVES:7)
Block(-11,17,-7,LEAVES:15)
Block(-10,17,-7,LEAVES:7)
Block(-9,17,-7,LEAVES:7)
Block(2,17,-7,LOG:15)
Block(3,17,-7,LOG:15)
Block(5,17,-7,LEAVES:7)
Block(-13,17,-6,LEAVES:15)
Block(-12,17,-6,LEAVES:15)
Block(-11,17,-6,LEAVES:15)
Block(-10,17,-6,LOG:15)
Block(-9,17,-6,LOG:15)
Block(-8,17,-6,LEAVES:7)
Block(0,17,-6,LEAVES:7)
Block(1,17,-6,LEAVES:7)
Block(3,17,-6,LEAVES:7)
Block(6,17,-6,LEAVES:7)
Block(7,17,-6,LOG:15)
Block(-12,17,-5,LEAVES:15)
Block(-11,17,-5,LEAVES:7)
Block(-10,17,-5,LEAVES:7)
Block(-9,17,-5,LEAVES:15)
Block(-8,17,-5,LOG:15)
Block(-1,17,-5,LEAVES:15)
Block(0,17,-5,LEAVES:15)
Block(1,17,-5,LEAVES:15)
Block(2,17,-5,LEAVES:7)
Block(4,17,-5,LOG:15)
Block(5,17,-5,LOG:15)
Block(6,17,-5,LOG:15)
Block(-13,17,-4,LEAVES:15)
Block(-10,17,-4,LEAVES:7)
Block(-9,17,-4,LEAVES:7)
Block(-8,17,-4,LOG:15)
Block(-7,17,-4,LEAVES:15)
Block(-6,17,-4,LEAVES:7)
Block(0,17,-4,LEAVES:15)
Block(1,17,-4,LEAVES:15)
Block(2,17,-4,LOG:15)
Block(3,17,-4,LOG:15)
Block(4,17,-4,LOG:15)
Block(6,17,-4,LEAVES:15)
Block(-11,17,-3,LEAVES:7)
Block(-10,17,-3,LEAVES:15)
Block(-9,17,-3,LEAVES:15)
Block(-8,17,-3,LEAVES:15)
Block(-7,17,-3,LEAVES:15)
Block(-6,17,-3,LEAVES:15)
Block(-3,17,-3,LOG:15)
Block(1,17,-3,LEAVES:7)
Block(2,17,-3,LEAVES:15)
Block(3,17,-3,LEAVES:7)
Block(4,17,-3,LEAVES:15)
Block(5,17,-3,LEAVES:15)
Block(6,17,-3,LEAVES:15)
Block(7,17,-3,LEAVES:15)
Block(11,17,-3,LEAVES:15)
Block(14,17,-3,LEAVES:15)
Block(-14,17,-2,LEAVES:7)
Block(-12,17,-2,LEAVES:7)
Block(-11,17,-2,LOG:15)
Block(-9,17,-2,LOG:15)
Block(-8,17,-2,LEAVES:15)
Block(-7,17,-2,LEAVES:15)
Block(-4,17,-2,LOG:15)
Block(-3,17,-2,LOG:15)
Block(-2,17,-2,LOG:15)
Block(1,17,-2,LEAVES:7)
Block(2,17,-2,LEAVES:15)
Block(3,17,-2,LEAVES:7)
Block(4,17,-2,LEAVES:15)
Block(5,17,-2,LEAVES:15)
Block(6,17,-2,LEAVES:15)
Block(7,17,-2,LEAVES:15)
Block(8,17,-2,LEAVES:15)
Block(10,17,-2,LEAVES:15)
Block(11,17,-2,LEAVES:15)
Block(12,17,-2,LEAVES:15)
Block(-11,17,-1,LEAVES:7)
Block(-10,17,-1,LOG:15)
Block(-9,17,-1,LEAVES:7)
Block(-8,17,-1,LEAVES:15)
Block(-3,17,-1,LOG:15)
Block(-2,17,-1,LOG:15)
Block(1,17,-1,LEAVES:15)
Block(2,17,-1,LEAVES:15)
Block(4,17,-1,LEAVES:15)
Block(5,17,-1,LOG:15)
Block(6,17,-1,LOG:15)
Block(7,17,-1,LEAVES:7)
Block(8,17,-1,LEAVES:15)
Block(10,17,-1,LEAVES:15)
Block(11,17,-1,LOG:15)
Block(13,17,-1,LEAVES:15)
Block(15,17,-1,LEAVES:7)
Block(-14,17,0,LEAVES:15)
Block(-9,17,0,LEAVES:7)
Block(-3,17,0,LOG:15)
Block(-2,17,0,LOG:15)
Block(0,17,0,LEAVES:15)
Block(1,17,0,LEAVES:15)
Block(2,17,0,LOG:15)
Block(3,17,0,LEAVES:7)
Block(4,17,0,LEAVES:15)
Block(5,17,0,LEAVES:15)
Block(6,17,0,LEAVES:7)
Block(7,17,0,LOG:15)
Block(9,17,0,LEAVES:15)
Block(10,17,0,LOG:15)
Block(11,17,0,LEAVES:7)
Block(-12,17,1,LEAVES:15)
Block(-10,17,1,LEAVES:15)
Block(-3,17,1,LOG:15)
Block(0,17,1,LEAVES:15)
Block(1,17,1,LEAVES:15)
Block(2,17,1,LEAVES:15)
Block(3,17,1,LEAVES:7)
Block(5,17,1,LEAVES:15)
Block(6,17,1,LEAVES:15)
Block(7,17,1,LEAVES:15)
Block(8,17,1,LEAVES:15)
Block(9,17,1,LEAVES:15)
Block(10,17,1,LOG:15)
Block(11,17,1,LEAVES:15)
Block(12,17,1,LEAVES:15)
Block(13,17,1,LEAVES:15)
Block(-13,17,2,LEAVES:15)
Block(-10,17,2,LEAVES:15)
Block(-3,17,2,LOG:15)
Block(2,17,2,LEAVES:7)
Block(3,17,2,LOG:15)
Block(4,17,2,LEAVES:7)
Block(7,17,2,LEAVES:15)
Block(8,17,2,LEAVES:15)
Block(9,17,2,LEAVES:15)
Block(10,17,2,LEAVES:15)
Block(11,17,2,LOG:15)
Block(12,17,2,LEAVES:15)
Block(13,17,2,LEAVES:15)
Block(-11,17,3,LEAVES:15)
Block(0,17,3,LEAVES:15)
Block(3,17,3,LOG:15)
Block(5,17,3,LEAVES:15)
Block(10,17,3,LEAVES:15)
Block(11,17,3,LEAVES:15)
Block(12,17,3,LEAVES:15)
Block(2,17,4,LEAVES:7)
Block(0,17,5,LEAVES:7)
Block(5,17,5,LEAVES:15)
Block(6,17,6,LEAVES:15)
Block(1,17,7,LEAVES:7)
Block(-1,18,-12,LEAVES:15)
Block(5,18,-12,LEAVES:15)
Block(-2,18,-11,LEAVES:15)
Block(-1,18,-11,LEAVES:15)
Block(5,18,-11,LEAVES:7)
Block(-2,18,-10,LEAVES:15)
Block(-1,18,-10,LEAVES:15)
Block(0,18,-10,LEAVES:15)
Block(4,18,-10,LEAVES:15)
Block(5,18,-10,LEAVES:15)
Block(6,18,-10,LEAVES:15)
Block(9,18,-10,LEAVES:15)
Block(12,18,-10,LEAVES:15)
Block(-3,18,-9,LEAVES:15)
Block(-2,18,-9,LEAVES:15)
Block(-1,18,-9,LOG:15)
Block(0,18,-9,LEAVES:15)
Block(1,18,-9,LEAVES:15)
Block(4,18,-9,LEAVES:7)
Block(11,18,-9,LEAVES:15)
Block(-2,18,-8,LEAVES:15)
Block(-1,18,-8,LEAVES:15)
Block(0,18,-8,LOG:15)
Block(1,18,-8,LEAVES:7)
Block(2,18,-8,LEAVES:7)
Block(5,18,-8,LEAVES:7)
Block(6,18,-8,LEAVES:15)
Block(8,18,-8,LOG:15)
Block(9,18,-8,LOG:15)
Block(13,18,-8,LEAVES:15)
Block(-11,18,-7,LEAVES:7)
Block(-10,18,-7,LEAVES:7)
Block(0,18,-7,LEAVES:7)
Block(1,18,-7,LEAVES:7)
Block(2,18,-7,LEAVES:15)
Block(3,18,-7,LEAVES:7)
Block(4,18,-7,LEAVES:7)
Block(5,18,-7,LEAVES:15)
Block(6,18,-7,LEAVES:15)
Block(7,18,-7,LOG:15)
Block(8,18,-7,LOG:15)
Block(11,18,-7,LEAVES:7)
Block(-12,18,-6,LEAVES:15)
Block(-11,18,-6,LEAVES:7)
Block(-10,18,-6,LEAVES:15)
Block(-9,18,-6,LEAVES:7)
Block(1,18,-6,LEAVES:7)
Block(4,18,-6,LEAVES:7)
Block(5,18,-6,LEAVES:15)
Block(6,18,-6,LEAVES:7)
Block(7,18,-6,LOG:15)
Block(8,18,-6,LEAVES:7)
Block(9,18,-6,LEAVES:7)
Block(12,18,-6,LEAVES:7)
Block(-9,18,-5,LEAVES:7)
Block(-8,18,-5,LEAVES:7)
Block(0,18,-5,LEAVES:15)
Block(1,18,-5,LEAVES:15)
Block(3,18,-5,LEAVES:7)
Block(4,18,-5,LEAVES:7)
Block(5,18,-5,LEAVES:15)
Block(6,18,-5,LOG:15)
Block(7,18,-5,LEAVES:7)
Block(-13,18,-4,LEAVES:15)
Block(-12,18,-4,LEAVES:15)
Block(-9,18,-4,LEAVES:7)
Block(-8,18,-4,LEAVES:7)
Block(-7,18,-4,LEAVES:7)
Block(2,18,-4,LEAVES:7)
Block(3,18,-4,LEAVES:7)
Block(4,18,-4,LEAVES:7)
Block(5,18,-4,LEAVES:7)
Block(6,18,-4,LEAVES:7)
Block(7,18,-4,LOG:15)
Block(8,18,-4,LEAVES:7)
Block(11,18,-4,LEAVES:15)
Block(-14,18,-3,LEAVES:7)
Block(-13,18,-3,LEAVES:15)
Block(-12,18,-3,LEAVES:7)
Block(-10,18,-3,LEAVES:7)
Block(-9,18,-3,LEAVES:15)
Block(-7,18,-3,LEAVES:7)
Block(-3,18,-3,LOG:15)
Block(1,18,-3,LEAVES:7)
Block(2,18,-3,LEAVES:15)
Block(3,18,-3,LEAVES:7)
Block(6,18,-3,LEAVES:15)
Block(8,18,-3,LOG:15)
Block(13,18,-3,LEAVES:15)
Block(-15,18,-2,LEAVES:7)
Block(-14,18,-2,LEAVES:15)
Block(-13,18,-2,LEAVES:15)
Block(-12,18,-2,LOG:15)
Block(-11,18,-2,LEAVES:7)
Block(-9,18,-2,LEAVES:15)
Block(-8,18,-2,LEAVES:15)
Block(-4,18,-2,LOG:15)
Block(-3,18,-2,LOG:15)
Block(-2,18,-2,LOG:15)
Block(2,18,-2,LEAVES:7)
Block(4,18,-2,LEAVES:15)
Block(6,18,-2,LEAVES:15)
Block(7,18,-2,LEAVES:7)
Block(8,18,-2,LEAVES:15)
Block(11,18,-2,LEAVES:15)
Block(12,18,-2,LEAVES:15)
Block(13,18,-2,LEAVES:15)
Block(14,18,-2,LEAVES:15)
Block(-14,18,-1,LEAVES:15)
Block(-13,18,-1,LEAVES:15)
Block(-12,18,-1,LEAVES:7)
Block(-10,18,-1,LEAVES:7)
Block(-8,18,-1,LEAVES:7)
Block(-3,18,-1,LOG:15)
Block(-2,18,-1,LOG:15)
Block(5,18,-1,LEAVES:7)
Block(6,18,-1,LEAVES:15)
Block(7,18,-1,LEAVES:7)
Block(8,18,-1,LEAVES:15)
Block(9,18,-1,LEAVES:15)
Block(10,18,-1,LEAVES:15)
Block(11,18,-1,LEAVES:15)
Block(12,18,-1,LOG:15)
Block(13,18,-1,LEAVES:15)
Block(14,18,-1,LEAVES:15)
Block(15,18,-1,LEAVES:15)
Block(-13,18,0,LEAVES:15)
Block(-12,18,0,LEAVES:7)
Block(-11,18,0,LEAVES:7)
Block(-10,18,0,LOG:15)
Block(-9,18,0,LEAVES:15)
Block(-8,18,0,LEAVES:15)
Block(-7,18,0,LEAVES:15)
Block(-5,18,0,LEAVES:7)
Block(-4,18,0,LOG:15)
Block(-3,18,0,LOG:15)
Block(1,18,0,LEAVES:7)
Block(2,18,0,LEAVES:15)
Block(3,18,0,LEAVES:7)
Block(5,18,0,LEAVES:7)
Block(6,18,0,LEAVES:7)
Block(7,18,0,LEAVES:7)
Block(8,18,0,LOG:15)
Block(9,18,0,LEAVES:15)
Block(10,18,0,LEAVES:15)
Block(11,18,0,LEAVES:15)
Block(12,18,0,LEAVES:15)
Block(13,18,0,LEAVES:15)
Block(14,18,0,LEAVES:15)
Block(-13,18,1,LEAVES:15)
Block(-12,18,1,LEAVES:15)
Block(-11,18,1,LOG:15)
Block(-10,18,1,LEAVES:15)
Block(-9,18,1,LEAVES:15)
Block(-8,18,1,LEAVES:15)
Block(-6,18,1,LEAVES:15)
Block(-3,18,1,LEAVES:15)
Block(2,18,1,LEAVES:7)
Block(7,18,1,LEAVES:15)
Block(8,18,1,LEAVES:15)
Block(9,18,1,LEAVES:15)
Block(10,18,1,LEAVES:15)
Block(-12,18,2,LEAVES:15)
Block(-11,18,2,LEAVES:15)
Block(-10,18,2,LEAVES:15)
Block(-9,18,2,LEAVES:15)
Block(-3,18,2,LOG:15)
Block(2,18,2,LEAVES:15)
Block(9,18,2,LEAVES:15)
Block(11,18,2,LEAVES:15)
Block(12,18,2,LEAVES:15)
Block(-11,18,3,LEAVES:15)
Block(-5,18,3,LEAVES:15)
Block(-4,18,3,LOG:15)
Block(-3,18,3,LOG:15)
Block(1,18,3,LEAVES:15)
Block(2,18,3,LEAVES:15)
Block(3,18,3,LEAVES:15)
Block(10,18,3,LEAVES:15)
Block(11,18,3,LEAVES:15)
Block(-5,18,4,LOG:15)
Block(-4,18,4,LOG:15)
Block(0,18,4,LEAVES:15)
Block(1,18,4,LEAVES:15)
Block(2,18,4,LOG:15)
Block(3,18,4,LOG:15)
Block(4,18,4,LEAVES:15)
Block(5,18,4,LEAVES:15)
Block(-5,18,5,LOG:15)
Block(0,18,5,LEAVES:15)
Block(1,18,5,LOG:15)
Block(2,18,5,LEAVES:7)
Block(4,18,5,LOG:15)
Block(5,18,5,LEAVES:15)
Block(6,18,5,LEAVES:15)
Block(-5,18,6,LEAVES:15)
Block(0,18,6,LEAVES:7)
Block(1,18,6,LEAVES:15)
Block(2,18,6,LEAVES:15)
Block(5,18,6,LEAVES:15)
Block(1,18,7,LEAVES:15)
Block(2,18,7,LEAVES:15)
Block(4,18,7,LEAVES:15)
Block(6,18,8,LEAVES:15)
Block(4,18,9,LEAVES:7)
Block(-1,19,-11,LEAVES:15)
Block(-1,19,-10,LEAVES:7)
Block(5,19,-10,LEAVES:7)
Block(11,19,-10,LEAVES:15)
Block(-2,19,-9,LEAVES:15)
Block(-1,19,-9,LEAVES:15)
Block(0,19,-9,LEAVES:7)
Block(9,19,-9,LEAVES:15)
Block(10,19,-9,LEAVES:15)
Block(11,19,-9,LEAVES:15)
Block(12,19,-9,LEAVES:15)
Block(-1,19,-8,LEAVES:7)
Block(0,19,-8,LEAVES:7)
Block(7,19,-8,LEAVES:7)
Block(8,19,-8,LEAVES:7)
Block(9,19,-8,LEAVES:15)
Block(10,19,-8,LEAVES:15)
Block(11,19,-8,LEAVES:15)
Block(12,19,-8,LEAVES:15)
Block(13,19,-8,LEAVES:15)
Block(2,19,-7,LEAVES:7)
Block(5,19,-7,LEAVES:7)
Block(6,19,-7,LEAVES:7)
Block(7,19,-7,LEAVES:15)
Block(8,19,-7,LEAVES:7)
Block(9,19,-7,LEAVES:7)
Block(10,19,-7,LOG:15)
Block(11,19,-7,LOG:15)
Block(12,19,-7,LEAVES:7)
Block(13,19,-7,LEAVES:15)
Block(15,19,-7,LEAVES:7)
Block(4,19,-6,LEAVES:7)
Block(5,19,-6,LEAVES:15)
Block(7,19,-6,LEAVES:7)
Block(9,19,-6,LEAVES:7)
Block(10,19,-6,LEAVES:15)
Block(11,19,-6,LEAVES:7)
Block(12,19,-6,LOG:15)
Block(16,19,-6,LEAVES:7)
Block(1,19,-5,LEAVES:7)
Block(5,19,-5,LEAVES:7)
Block(6,19,-5,LEAVES:7)
Block(10,19,-5,LEAVES:15)
Block(11,19,-5,LEAVES:15)
Block(12,19,-5,LEAVES:15)
Block(14,19,-5,LEAVES:15)
Block(-8,19,-4,LEAVES:7)
Block(7,19,-4,LEAVES:7)
Block(9,19,-4,LEAVES:7)
Block(10,19,-4,LEAVES:7)
Block(12,19,-4,LEAVES:15)
Block(13,19,-4,LEAVES:15)
Block(-12,19,-3,LEAVES:7)
Block(-9,19,-3,LEAVES:7)
Block(-3,19,-3,LOG:15)
Block(2,19,-3,LEAVES:7)
Block(8,19,-3,LEAVES:7)
Block(9,19,-3,LOG:15)
Block(10,19,-3,LEAVES:15)
Block(11,19,-3,LEAVES:7)
Block(-14,19,-2,LEAVES:7)
Block(-13,19,-2,LEAVES:7)
Block(-12,19,-2,LEAVES:15)
Block(-11,19,-2,LEAVES:7)
Block(-4,19,-2,LOG:15)
Block(-3,19,-2,LOG:15)
Block(-2,19,-2,LOG:15)
Block(9,19,-2,LEAVES:7)
Block(10,19,-2,LEAVES:7)
Block(13,19,-2,LEAVES:15)
Block(-10,19,-1,LEAVES:7)
Block(-3,19,-1,LOG:15)
Block(-2,19,-1,LOG:15)
Block(6,19,-1,LEAVES:7)
Block(8,19,-1,LEAVES:7)
Block(11,19,-1,LEAVES:15)
Block(12,19,-1,LEAVES:15)
Block(13,19,-1,LEAVES:15)
Block(14,19,-1,LEAVES:15)
Block(-10,19,0,LEAVES:15)
Block(-9,19,0,LEAVES:15)
Block(-8,19,0,LEAVES:15)
Block(-5,19,0,LEAVES:7)
Block(-4,19,0,LOG:15)
Block(2,19,0,LEAVES:7)
Block(7,19,0,LEAVES:7)
Block(8,19,0,LEAVES:15)
Block(9,19,0,LEAVES:15)
Block(10,19,0,LEAVES:7)
Block(12,19,0,LEAVES:15)
Block(-12,19,1,LEAVES:15)
Block(-11,19,1,LEAVES:7)
Block(-9,19,1,LEAVES:15)
Block(-5,19,1,LOG:15)
Block(-4,19,1,LEAVES:15)
Block(-3,19,1,LEAVES:15)
Block(9,19,1,LEAVES:15)
Block(-11,19,2,LEAVES:15)
Block(-7,19,2,LEAVES:15)
Block(-5,19,2,LEAVES:15)
Block(-4,19,2,LEAVES:15)
Block(-3,19,2,LEAVES:15)
Block(-8,19,3,LEAVES:7)
Block(-6,19,3,LEAVES:15)
Block(-4,19,3,LEAVES:7)
Block(-3,19,3,LEAVES:15)
Block(2,19,3,LEAVES:15)
Block(-7,19,4,LEAVES:15)
Block(-6,19,4,LEAVES:15)
Block(-5,19,4,LEAVES:15)
Block(0,19,4,LEAVES:15)
Block(2,19,4,LEAVES:7)
Block(3,19,4,LEAVES:15)
Block(4,19,4,LEAVES:15)
Block(-5,19,5,LOG:15)
Block(-3,19,5,LEAVES:15)
Block(0,19,5,LEAVES:7)
Block(1,19,5,LEAVES:7)
Block(3,19,5,LEAVES:7)
Block(4,19,5,LEAVES:15)
Block(5,19,5,LEAVES:15)
Block(-5,19,6,LOG:15)
Block(1,19,6,LEAVES:15)
Block(3,19,6,LEAVES:15)
Block(4,19,6,LOG:15)
Block(5,19,6,LEAVES:15)
Block(-6,19,7,LEAVES:15)
Block(-5,19,7,LOG:15)
Block(-4,19,7,LEAVES:15)
Block(-3,19,7,LEAVES:15)
Block(-1,19,7,LEAVES:15)
Block(3,19,7,LEAVES:15)
Block(4,19,7,LEAVES:15)
Block(5,19,7,LEAVES:15)
Block(6,19,7,LEAVES:15)
Block(-5,19,8,LOG:15)
Block(-4,19,8,LEAVES:15)
Block(3,19,8,LEAVES:15)
Block(4,19,8,LEAVES:15)
Block(5,19,8,LEAVES:15)
Block(-5,19,9,LEAVES:15)
Block(-2,19,9,LEAVES:15)
Block(4,19,9,LEAVES:15)
Block(-4,19,10,LEAVES:15)
Block(-1,20,-9,LEAVES:7)
Block(11,20,-9,LEAVES:15)
Block(9,20,-8,LEAVES:15)
Block(11,20,-8,LEAVES:15)
Block(12,20,-8,LEAVES:7)
Block(13,20,-8,LEAVES:15)
Block(7,20,-7,LEAVES:7)
Block(10,20,-7,LEAVES:7)
Block(11,20,-7,LEAVES:15)
Block(12,20,-7,LEAVES:7)
Block(13,20,-7,LEAVES:15)
Block(14,20,-7,LEAVES:15)
Block(15,20,-7,LEAVES:15)
Block(5,20,-6,LEAVES:7)
Block(10,20,-6,LEAVES:7)
Block(11,20,-6,LEAVES:7)
Block(12,20,-6,LEAVES:7)
Block(13,20,-6,LOG:15)
Block(14,20,-6,LEAVES:15)
Block(15,20,-6,LEAVES:15)
Block(16,20,-6,LEAVES:15)
Block(12,20,-5,LEAVES:15)
Block(13,20,-5,LEAVES:15)
Block(14,20,-5,LEAVES:15)
Block(15,20,-5,LEAVES:15)
Block(9,20,-4,LEAVES:7)
Block(14,20,-4,LEAVES:15)
Block(-3,20,-3,LOG:15)
Block(9,20,-3,LEAVES:15)
Block(10,20,-3,LEAVES:7)
Block(-12,20,-2,LEAVES:7)
Block(-4,20,-2,LOG:15)
Block(-3,20,-2,LOG:15)
Block(-2,20,-2,LOG:15)
Block(-3,20,-1,LOG:15)
Block(12,20,-1,LEAVES:15)
Block(-10,20,0,LEAVES:7)
Block(-6,20,0,LEAVES:15)
Block(-4,20,0,LEAVES:15)
Block(8,20,0,LEAVES:7)
Block(-8,20,1,LEAVES:7)
Block(-7,20,1,LEAVES:15)
Block(-6,20,1,LOG:15)
Block(-5,20,1,LEAVES:15)
Block(-4,20,1,LEAVES:15)
Block(-3,20,1,LEAVES:7)
Block(-9,20,2,LEAVES:15)
Block(-8,20,2,LEAVES:15)
Block(-7,20,2,LOG:15)
Block(-6,20,2,LEAVES:15)
Block(-4,20,2,LEAVES:7)
Block(-8,20,3,LEAVES:15)
Block(-7,20,3,LEAVES:15)
Block(-6,20,3,LEAVES:7)
Block(-3,20,3,LEAVES:15)
Block(-1,20,3,LEAVES:15)
Block(1,20,3,LEAVES:15)
Block(-7,20,4,LEAVES:15)
Block(-6,20,4,LEAVES:15)
Block(-5,20,4,LEAVES:15)
Block(-4,20,4,LEAVES:15)
Block(-3,20,4,LEAVES:15)
Block(-6,20,5,LEAVES:15)
Block(-5,20,5,LEAVES:15)
Block(-4,20,5,LEAVES:15)
Block(-3,20,5,LOG:15)
Block(-2,20,5,LEAVES:15)
Block(0,20,5,LEAVES:7)
Block(4,20,5,LEAVES:7)
Block(-7,20,6,LEAVES:15)
Block(-6,20,6,LEAVES:15)
Block(-5,20,6,LOG:15)
Block(-4,20,6,LOG:15)
Block(-3,20,6,LEAVES:15)
Block(-2,20,6,LEAVES:15)
Block(-1,20,6,LEAVES:15)
Block(3,20,6,LEAVES:15)
Block(4,20,6,LEAVES:15)
Block(-6,20,7,LEAVES:15)
Block(-5,20,7,LEAVES:15)
Block(-4,20,7,LEAVES:15)
Block(-3,20,7,LEAVES:15)
Block(-2,20,7,LEAVES:15)
Block(4,20,7,LEAVES:7)
Block(5,20,7,LEAVES:15)
Block(-5,20,8,LEAVES:15)
Block(-3,20,8,LEAVES:15)
Block(4,20,8,LEAVES:15)
Block(-5,20,9,LEAVES:15)
Block(-4,20,9,LOG:15)
Block(-3,20,9,LEAVES:15)
Block(-2,20,9,LEAVES:15)
Block(-5,20,10,LEAVES:15)
Block(-4,20,10,LEAVES:15)
Block(-3,20,10,LEAVES:15)
Block(-4,20,11,LEAVES:7)
Block(11,21,-7,LEAVES:7)
Block(13,21,-7,LEAVES:7)
Block(12,21,-6,LEAVES:7)
Block(13,21,-6,LEAVES:15)
Block(14,21,-6,LEAVES:15)
Block(15,21,-6,LEAVES:7)
Block(14,21,-5,LEAVES:15)
Block(-3,21,-3,LOG:15)
Block(9,21,-3,LEAVES:7)
Block(-4,21,-2,LOG:15)
Block(-3,21,-2,LOG:15)
Block(-2,21,-2,LOG:15)
Block(-3,21,-1,LOG:15)
Block(-7,21,1,LEAVES:7)
Block(-6,21,1,LEAVES:7)
Block(-4,21,1,LEAVES:7)
Block(-8,21,2,LEAVES:15)
Block(-7,21,2,LEAVES:15)
Block(-6,21,2,LEAVES:15)
Block(-1,21,2,LEAVES:15)
Block(-8,21,3,LEAVES:7)
Block(-7,21,3,LEAVES:15)
Block(-2,21,3,LEAVES:15)
Block(-1,21,3,LEAVES:15)
Block(0,21,3,LEAVES:15)
Block(-3,21,4,LEAVES:15)
Block(-2,21,4,LOG:15)
Block(-1,21,4,LEAVES:15)
Block(0,21,4,LEAVES:15)
Block(1,21,4,LEAVES:15)
Block(-5,21,5,LEAVES:15)
Block(-3,21,5,LEAVES:15)
Block(-2,21,5,LEAVES:15)
Block(-1,21,5,LEAVES:15)
Block(0,21,5,LEAVES:15)
Block(-6,21,6,LEAVES:15)
Block(-5,21,6,LEAVES:15)
Block(-4,21,6,LEAVES:15)
Block(-3,21,6,LEAVES:15)
Block(-2,21,6,LEAVES:15)
Block(4,21,6,LEAVES:7)
Block(-5,21,7,LEAVES:15)
Block(-3,21,7,LEAVES:15)
Block(-4,21,8,LEAVES:15)
Block(-4,21,9,LEAVES:15)
Block(-3,21,9,LEAVES:15)
Block(-4,21,10,LEAVES:15)
Block(13,22,-6,LEAVES:7)
Block(-3,22,-3,LOG:15)
Block(-4,22,-2,LOG:15)
Block(-3,22,-2,LOG:15)
Block(-2,22,-2,LOG:15)
Block(-3,22,-1,LOG:15)
Block(-7,22,2,LEAVES:15)
Block(-1,22,3,LEAVES:15)
Block(-3,22,4,LEAVES:15)
Block(-2,22,4,LEAVES:15)
Block(-1,22,4,LEAVES:15)
Block(0,22,4,LEAVES:15)
Block(-5,22,6,LEAVES:15)
Block(-3,22,6,LEAVES:15)
Block(-4,22,9,LEAVES:15)
Block(-4,23,-3,LOG:15)
Block(-3,23,-3,LOG:15)
Block(-4,23,-2,LOG:15)
Block(-3,23,-2,LOG:15)
Block(-2,23,-2,LOG:15)
Block(-3,23,-1,LOG:15)
Block(-2,23,4,LEAVES:15)
Block(-8,24,-8,LEAVES:15)
Block(-10,24,-5,LEAVES:15)
Block(-7,24,-5,LEAVES:7)
Block(-3,24,-5,LOG:15)
Block(-9,24,-4,LEAVES:15)
Block(-5,24,-4,LOG:15)
Block(-4,24,-4,LOG:15)
Block(-3,24,-4,LOG:15)
Block(-10,24,-3,LEAVES:15)
Block(-7,24,-3,LEAVES:15)
Block(-3,24,-3,LOG:15)
Block(-9,24,-2,LEAVES:15)
Block(-5,24,-2,LEAVES:7)
Block(-4,24,-2,LOG:15)
Block(-3,24,-2,LOG:15)
Block(-2,24,-2,LOG:15)
Block(-3,24,-1,LOG:15)
Block(-9,25,-9,LEAVES:15)
Block(-8,25,-9,LEAVES:15)
Block(-11,25,-8,LEAVES:15)
Block(-9,25,-7,LEAVES:15)
Block(-7,25,-7,LEAVES:15)
Block(-2,25,-7,LOG:15)
Block(-10,25,-6,LEAVES:7)
Block(-7,25,-6,LOG:15)
Block(-3,25,-6,LOG:15)
Block(-2,25,-6,LOG:15)
Block(-9,25,-5,LEAVES:15)
Block(-8,25,-5,LEAVES:15)
Block(-7,25,-5,LEAVES:15)
Block(-6,25,-5,LOG:15)
Block(-5,25,-5,LEAVES:7)
Block(-3,25,-5,LOG:15)
Block(-10,25,-4,LEAVES:15)
Block(-9,25,-4,LEAVES:15)
Block(-8,25,-4,LEAVES:15)
Block(-7,25,-4,LOG:15)
Block(-6,25,-4,LOG:15)
Block(-5,25,-4,LEAVES:15)
Block(-4,25,-4,LEAVES:7)
Block(-9,25,-3,LEAVES:15)
Block(-8,25,-3,LEAVES:15)
Block(-6,25,-3,LEAVES:15)
Block(-5,25,-3,LEAVES:15)
Block(-4,25,-3,LEAVES:7)
Block(-3,25,-3,LOG:15)
Block(-10,25,-2,LEAVES:15)
Block(-5,25,-2,LEAVES:7)
Block(-4,25,-2,LOG:15)
Block(-3,25,-2,LOG:15)
Block(-2,25,-2,LOG:15)
Block(-8,25,-1,LEAVES:15)
Block(-3,25,-1,LOG:15)
Block(-9,25,0,LEAVES:15)
Block(-1,26,-12,LEAVES:15)
Block(-2,26,-11,LEAVES:15)
Block(-6,26,-10,LEAVES:7)
Block(-4,26,-10,LEAVES:15)
Block(0,26,-10,LEAVES:7)
Block(-8,26,-9,LEAVES:15)
Block(-5,26,-9,LEAVES:15)
Block(-2,26,-9,LEAVES:7)
Block(1,26,-9,LEAVES:7)
Block(-10,26,-8,LEAVES:15)
Block(-9,26,-8,LEAVES:15)
Block(-8,26,-8,LEAVES:15)
Block(-7,26,-8,LEAVES:15)
Block(-2,26,-8,LOG:15)
Block(0,26,-8,LEAVES:7)
Block(-11,26,-7,LEAVES:15)
Block(-10,26,-7,LEAVES:15)
Block(-9,26,-7,LOG:15)
Block(-8,26,-7,LEAVES:15)
Block(-7,26,-7,LEAVES:15)
Block(-5,26,-7,LEAVES:15)
Block(-3,26,-7,LEAVES:7)
Block(-2,26,-7,LOG:15)
Block(2,26,-7,LEAVES:15)
Block(-10,26,-6,LEAVES:15)
Block(-9,26,-6,LEAVES:15)
Block(-8,26,-6,LOG:15)
Block(-7,26,-6,LEAVES:7)
Block(0,26,-6,LEAVES:15)
Block(-8,26,-5,LEAVES:7)
Block(-5,26,-5,LEAVES:7)
Block(-9,26,-4,LEAVES:15)
Block(-8,26,-4,LEAVES:15)
Block(-7,26,-4,LEAVES:15)
Block(-6,26,-4,LEAVES:15)
Block(-5,26,-4,LEAVES:15)
Block(-4,26,-4,LEAVES:7)
Block(-9,26,-3,LEAVES:15)
Block(-8,26,-3,LEAVES:15)
Block(-7,26,-3,LOG:15)
Block(-5,26,-3,LEAVES:7)
Block(-3,26,-3,LOG:15)
Block(-10,26,-2,LEAVES:15)
Block(-9,26,-2,LEAVES:15)
Block(-8,26,-2,LOG:15)
Block(-7,26,-2,LEAVES:15)
Block(-3,26,-2,LOG:15)
Block(-2,26,-2,LOG:15)
Block(-9,26,-1,LEAVES:15)
Block(-8,26,-1,LEAVES:15)
Block(-7,26,-1,LEAVES:7)
Block(-3,26,-1,LOG:15)
Block(-8,26,0,LEAVES:15)
Block(-5,27,-14,LEAVES:15)
Block(-3,27,-13,LEAVES:7)
Block(-6,27,-12,LEAVES:7)
Block(-4,27,-12,LEAVES:7)
Block(-2,27,-12,LEAVES:15)
Block(-5,27,-11,LEAVES:15)
Block(-2,27,-11,LEAVES:15)
Block(-1,27,-11,LEAVES:15)
Block(-6,27,-10,LEAVES:15)
Block(-5,27,-10,LEAVES:15)
Block(-4,27,-10,LOG:15)
Block(-3,27,-10,LEAVES:7)
Block(-2,27,-10,LEAVES:15)
Block(-1,27,-10,LEAVES:15)
Block(0,27,-10,LEAVES:7)
Block(-4,27,-9,LEAVES:15)
Block(-3,27,-9,LOG:15)
Block(-2,27,-9,LOG:15)
Block(-1,27,-9,LEAVES:7)
Block(0,27,-9,LEAVES:7)
Block(1,27,-9,LEAVES:7)
Block(-9,27,-8,LEAVES:15)
Block(-8,27,-8,LEAVES:15)
Block(-5,27,-8,LEAVES:15)
Block(-4,27,-8,LEAVES:15)
Block(-3,27,-8,LEAVES:15)
Block(-2,27,-8,LEAVES:7)
Block(0,27,-8,LOG:15)
Block(1,27,-8,LEAVES:15)
Block(2,27,-8,LEAVES:15)
Block(-10,27,-7,LEAVES:15)
Block(-9,27,-7,LEAVES:15)
Block(-8,27,-7,LEAVES:7)
Block(-4,27,-7,LEAVES:15)
Block(-3,27,-7,LEAVES:7)
Block(-2,27,-7,LEAVES:7)
Block(-1,27,-7,LOG:15)
Block(0,27,-7,LEAVES:15)
Block(1,27,-7,LEAVES:15)
Block(-8,27,-6,LEAVES:7)
Block(-1,27,-6,LEAVES:15)
Block(-8,27,-4,LEAVES:7)
Block(-5,27,-4,LEAVES:7)
Block(-8,27,-3,LEAVES:7)
Block(-3,27,-3,LOG:15)
Block(-9,27,-2,LEAVES:7)
Block(-8,27,-2,LEAVES:15)
Block(-7,27,-2,LEAVES:7)
Block(-3,27,-2,LOG:15)
Block(-2,27,-2,LOG:15)
Block(-8,27,-1,LEAVES:15)
Block(-3,27,-1,LOG:15)
Block(-4,28,-14,LEAVES:15)
Block(-5,28,-13,LEAVES:15)
Block(-4,28,-13,LEAVES:15)
Block(-3,28,-13,LEAVES:7)
Block(-6,28,-12,LEAVES:15)
Block(-5,28,-12,LEAVES:15)
Block(-4,28,-12,LEAVES:15)
Block(-3,28,-12,LEAVES:7)
Block(-5,28,-11,LEAVES:15)
Block(-4,28,-11,LOG:15)
Block(-3,28,-11,LEAVES:7)
Block(-2,28,-11,LEAVES:15)
Block(-5,28,-10,LEAVES:15)
Block(-4,28,-10,LEAVES:15)
Block(-3,28,-10,LEAVES:7)
Block(-2,28,-10,LEAVES:15)
Block(-1,28,-10,LEAVES:7)
Block(-4,28,-9,LEAVES:15)
Block(-3,28,-9,LEAVES:15)
Block(-2,28,-9,LEAVES:7)
Block(0,28,-9,LEAVES:7)
Block(-4,28,-8,LEAVES:15)
Block(-3,28,-8,LEAVES:7)
Block(-1,28,-8,LEAVES:7)
Block(0,28,-8,LEAVES:15)
Block(1,28,-8,LEAVES:15)
Block(-9,28,-7,LEAVES:15)
Block(-2,28,-7,LEAVES:7)
Block(-1,28,-7,LEAVES:7)
Block(0,28,-7,LEAVES:15)
Block(2,28,-5,LEAVES:15)
Block(-9,28,-2,LEAVES:15)
Block(-8,28,-2,LEAVES:7)
Block(-3,28,-2,LOG:15)
Block(-2,28,-2,LOG:15)
Block(2,28,-2,LEAVES:7)
Block(-3,28,-1,LOG:15)
Block(-2,28,-1,LOG:15)
Block(-11,28,0,LEAVES:15)
Block(-2,28,0,LOG:15)
Block(-4,29,-13,LEAVES:15)
Block(-5,29,-12,LEAVES:15)
Block(-4,29,-12,LEAVES:7)
Block(-4,29,-11,LEAVES:15)
Block(-3,29,-11,LEAVES:7)
Block(-4,29,-10,LEAVES:7)
Block(-2,29,-10,LEAVES:7)
Block(-3,29,-9,LEAVES:7)
Block(0,29,-8,LEAVES:7)
Block(1,29,-5,LEAVES:15)
Block(4,29,-5,LEAVES:7)
Block(0,29,-4,LEAVES:7)
Block(1,29,-4,LEAVES:15)
Block(2,29,-4,LEAVES:15)
Block(1,29,-3,LOG:15)
Block(4,29,-3,LEAVES:7)
Block(-12,29,-2,LEAVES:15)
Block(-10,29,-2,LEAVES:15)
Block(-3,29,-2,LOG:15)
Block(-2,29,-2,LOG:15)
Block(0,29,-2,LOG:15)
Block(1,29,-2,LOG:15)
Block(2,29,-2,LOG:15)
Block(-11,29,-1,LEAVES:15)
Block(-9,29,-1,LEAVES:15)
Block(-7,29,-1,LEAVES:15)
Block(-3,29,-1,LOG:15)
Block(-2,29,-1,LOG:15)
Block(1,29,-1,LEAVES:7)
Block(2,29,-1,LOG:15)
Block(3,29,-1,LEAVES:15)
Block(4,29,-1,LEAVES:7)
Block(6,29,-1,LEAVES:15)
Block(-10,29,0,LEAVES:15)
Block(-8,29,0,LEAVES:7)
Block(-3,29,0,LOG:15)
Block(-2,29,0,LOG:15)
Block(2,29,0,LOG:15)
Block(3,29,0,LEAVES:15)
Block(-11,29,1,LEAVES:15)
Block(-9,29,1,LEAVES:15)
Block(-3,29,1,LOG:15)
Block(-2,29,1,LOG:15)
Block(2,29,1,LEAVES:7)
Block(5,29,1,LEAVES:7)
Block(-7,29,2,LEAVES:15)
Block(-3,29,2,LOG:15)
Block(3,29,2,LEAVES:7)
Block(-7,29,3,LEAVES:15)
Block(-7,29,4,LOG:15)
Block(-6,29,4,LOG:15)
Block(-4,30,-11,LEAVES:7)
Block(4,30,-5,LEAVES:15)
Block(6,30,-5,LEAVES:15)
Block(8,30,-5,LEAVES:15)
Block(1,30,-4,LEAVES:15)
Block(2,30,-4,LEAVES:15)
Block(3,30,-4,LEAVES:15)
Block(4,30,-4,LEAVES:15)
Block(-10,30,-3,LEAVES:15)
Block(1,30,-3,LEAVES:15)
Block(2,30,-3,LEAVES:15)
Block(3,30,-3,LEAVES:7)
Block(4,30,-3,LOG:15)
Block(5,30,-3,LEAVES:7)
Block(7,30,-3,LEAVES:7)
Block(-11,30,-2,LEAVES:15)
Block(-10,30,-2,LEAVES:15)
Block(-8,30,-2,LEAVES:15)
Block(-3,30,-2,LOG:15)
Block(-2,30,-2,LOG:15)
Block(0,30,-2,LEAVES:15)
Block(1,30,-2,LEAVES:15)
Block(2,30,-2,LOG:15)
Block(3,30,-2,LOG:15)
Block(4,30,-2,LEAVES:15)
Block(5,30,-2,LEAVES:15)
Block(6,30,-2,LEAVES:15)
Block(-11,30,-1,LEAVES:15)
Block(-10,30,-1,LEAVES:15)
Block(-9,30,-1,LEAVES:15)
Block(-8,30,-1,LEAVES:15)
Block(-7,30,-1,LEAVES:15)
Block(-3,30,-1,LOG:15)
Block(1,30,-1,LEAVES:7)
Block(2,30,-1,LEAVES:15)
Block(3,30,-1,LEAVES:15)
Block(4,30,-1,LEAVES:7)
Block(5,30,-1,LEAVES:15)
Block(-11,30,0,LEAVES:15)
Block(-10,30,0,LOG:15)
Block(-9,30,0,LEAVES:15)
Block(-8,30,0,LEAVES:15)
Block(-7,30,0,LEAVES:15)
Block(-6,30,0,LEAVES:7)
Block(2,30,0,LEAVES:15)
Block(4,30,0,LEAVES:7)
Block(-10,30,1,LEAVES:15)
Block(-9,30,1,LOG:15)
Block(-3,30,1,LOG:15)
Block(2,30,1,LEAVES:15)
Block(3,30,1,LOG:15)
Block(4,30,1,LEAVES:15)
Block(5,30,1,LEAVES:7)
Block(-9,30,2,LEAVES:15)
Block(-8,30,2,LOG:15)
Block(-6,30,2,LEAVES:15)
Block(-3,30,2,LOG:15)
Block(2,30,2,LEAVES:15)
Block(3,30,2,LEAVES:15)
Block(4,30,2,LEAVES:7)
Block(-14,30,3,LEAVES:15)
Block(-7,30,3,LEAVES:15)
Block(-6,30,3,LOG:15)
Block(-4,30,3,LOG:15)
Block(-3,30,3,LOG:15)
Block(3,30,3,LEAVES:7)
Block(-6,30,4,LOG:15)
Block(-5,30,4,LOG:15)
Block(-14,30,5,LEAVES:15)
Block(-11,30,5,LEAVES:7)
Block(-8,30,5,LOG:15)
Block(-6,30,5,LEAVES:15)
Block(-10,30,6,LOG:15)
Block(-9,30,6,LOG:15)
Block(-13,30,7,LEAVES:15)
Block(-9,30,7,LOG:15)
Block(-11,30,9,LEAVES:7)
Block(-9,30,10,LEAVES:7)
Block(-5,30,10,LEAVES:7)
Block(-3,30,11,LEAVES:15)
Block(6,31,-6,LEAVES:15)
Block(5,31,-5,LEAVES:15)
Block(6,31,-5,LEAVES:15)
Block(7,31,-5,LEAVES:15)
Block(4,31,-4,LEAVES:15)
Block(5,31,-4,LOG:15)
Block(6,31,-4,LEAVES:15)
Block(7,31,-4,LEAVES:15)
Block(8,31,-4,LEAVES:15)
Block(2,31,-3,LEAVES:7)
Block(4,31,-3,LEAVES:7)
Block(5,31,-3,LEAVES:7)
Block(6,31,-3,LEAVES:15)
Block(7,31,-3,LEAVES:15)
Block(-10,31,-2,LEAVES:15)
Block(-3,31,-2,LOG:15)
Block(-2,31,-2,LOG:15)
Block(1,31,-2,LEAVES:7)
Block(2,31,-2,LEAVES:15)
Block(3,31,-2,LEAVES:7)
Block(4,31,-2,LEAVES:15)
Block(5,31,-2,LEAVES:15)
Block(-10,31,-1,LEAVES:7)
Block(-8,31,-1,LEAVES:7)
Block(-3,31,-1,LOG:15)
Block(2,31,-1,LEAVES:7)
Block(4,31,-1,LEAVES:7)
Block(-10,31,0,LEAVES:15)
Block(-9,31,0,LEAVES:7)
Block(-8,31,0,LEAVES:15)
Block(-7,31,0,LEAVES:7)
Block(-6,31,0,LEAVES:7)
Block(3,31,0,LEAVES:7)
Block(-12,31,1,LEAVES:15)
Block(-9,31,1,LEAVES:7)
Block(-8,31,1,LEAVES:7)
Block(3,31,1,LEAVES:15)
Block(4,31,1,LEAVES:7)
Block(-14,31,2,LEAVES:15)
Block(-9,31,2,LEAVES:15)
Block(-8,31,2,LOG:15)
Block(-7,31,2,LEAVES:15)
Block(3,31,2,LEAVES:15)
Block(-13,31,3,LEAVES:15)
Block(-10,31,3,LEAVES:15)
Block(-9,31,3,LEAVES:7)
Block(-7,31,3,LOG:15)
Block(-5,31,3,LEAVES:15)
Block(-4,31,3,LOG:15)
Block(-13,31,4,LEAVES:15)
Block(-12,31,4,LEAVES:7)
Block(-6,31,4,LEAVES:15)
Block(-5,31,4,LOG:15)
Block(-4,31,4,LOG:15)
Block(-14,31,5,LEAVES:15)
Block(-13,31,5,LEAVES:15)
Block(-12,31,5,LOG:15)
Block(-11,31,5,LEAVES:7)
Block(-9,31,5,LEAVES:7)
Block(-8,31,5,LEAVES:15)
Block(-5,31,5,LEAVES:15)
Block(-4,31,5,LOG:15)
Block(-3,31,5,LEAVES:15)
Block(-13,31,6,LEAVES:15)
Block(-12,31,6,LEAVES:15)
Block(-11,31,6,LOG:15)
Block(-10,31,6,LOG:15)
Block(-9,31,6,LEAVES:7)
Block(-8,31,6,LEAVES:7)
Block(-3,31,6,LEAVES:15)
Block(-16,31,7,LEAVES:15)
Block(-12,31,7,LEAVES:15)
Block(-11,31,7,LOG:15)
Block(-10,31,7,LEAVES:7)
Block(-9,31,7,LEAVES:7)
Block(-6,31,7,LEAVES:7)
Block(-14,31,8,LEAVES:15)
Block(-13,31,8,LEAVES:15)
Block(-12,31,8,LEAVES:15)
Block(-11,31,8,LEAVES:15)
Block(-10,31,8,LEAVES:7)
Block(-9,31,8,LEAVES:7)
Block(-8,31,8,LOG:15)
Block(-5,31,8,LOG:15)
Block(-15,31,9,LEAVES:15)
Block(-11,31,9,LEAVES:7)
Block(-10,31,9,LEAVES:7)
Block(-9,31,9,LOG:15)
Block(-8,31,9,LEAVES:7)
Block(-7,31,9,LEAVES:7)
Block(-4,31,9,LOG:15)
Block(-13,31,10,LEAVES:15)
Block(-9,31,10,LEAVES:7)
Block(-5,31,10,LEAVES:7)
Block(-4,31,10,LOG:15)
Block(-3,31,10,LEAVES:15)
Block(-4,31,11,LEAVES:15)
Block(-9,31,12,LEAVES:7)
Block(-7,31,13,LEAVES:15)
Block(-4,31,13,LEAVES:15)
Block(-5,31,15,LEAVES:15)
Block(6,32,-5,LEAVES:15)
Block(4,32,-4,LEAVES:15)
Block(5,32,-4,LEAVES:15)
Block(6,32,-4,LEAVES:15)
Block(7,32,-4,LEAVES:15)
Block(-3,32,-2,LOG:15)
Block(-2,32,-2,LOG:15)
Block(2,32,-2,LEAVES:7)
Block(4,32,-2,LEAVES:7)
Block(-3,32,-1,LOG:15)
Block(-8,32,0,LEAVES:7)
Block(-12,32,1,LEAVES:15)
Block(-4,32,1,LEAVES:15)
Block(3,32,1,LEAVES:15)
Block(-13,32,2,LEAVES:15)
Block(-12,32,2,LEAVES:15)
Block(-11,32,2,LEAVES:15)
Block(-9,32,2,LEAVES:7)
Block(-8,32,2,LEAVES:7)
Block(-5,32,2,LEAVES:15)
Block(-4,32,2,LEAVES:15)
Block(-3,32,2,LEAVES:15)
Block(1,32,2,LEAVES:15)
Block(-14,32,3,LEAVES:15)
Block(-13,32,3,LEAVES:15)
Block(-12,32,3,LOG:15)
Block(-11,32,3,LEAVES:15)
Block(-5,32,3,LEAVES:15)
Block(-4,32,3,LEAVES:15)
Block(-3,32,3,LEAVES:15)
Block(-1,32,3,LEAVES:15)
Block(-13,32,4,LEAVES:15)
Block(-12,32,4,LOG:15)
Block(-11,32,4,LEAVES:15)
Block(-10,32,4,LEAVES:15)
Block(-6,32,4,LEAVES:15)
Block(-4,32,4,LEAVES:15)
Block(0,32,4,LEAVES:15)
Block(-13,32,5,LEAVES:15)
Block(-12,32,5,LEAVES:7)
Block(-8,32,5,LEAVES:7)
Block(-4,32,5,LOG:15)
Block(-2,32,5,LEAVES:15)
Block(-11,32,6,LEAVES:7)
Block(-10,32,6,LEAVES:7)
Block(-8,32,6,LEAVES:7)
Block(-7,32,6,LEAVES:15)
Block(-6,32,6,LEAVES:15)
Block(-5,32,6,LOG:15)
Block(-4,32,6,LOG:15)
Block(-3,32,6,LOG:15)
Block(-2,32,6,LOG:15)
Block(-1,32,6,LOG:15)
Block(1,32,6,LEAVES:15)
Block(-15,32,7,LEAVES:15)
Block(-14,32,7,LEAVES:15)
Block(-13,32,7,LEAVES:15)
Block(-12,32,7,LOG:15)
Block(-11,32,7,LEAVES:15)
Block(-7,32,7,LEAVES:7)
Block(-6,32,7,LEAVES:7)
Block(-5,32,7,LOG:15)
Block(-1,32,7,LEAVES:15)
Block(1,32,7,LEAVES:15)
Block(-16,32,8,LEAVES:15)
Block(-15,32,8,LEAVES:15)
Block(-14,32,8,LEAVES:15)
Block(-13,32,8,LOG:15)
Block(-12,32,8,LEAVES:15)
Block(-11,32,8,LEAVES:15)
Block(-9,32,8,LEAVES:15)
Block(-8,32,8,LEAVES:15)
Block(-6,32,8,LOG:15)
Block(-5,32,8,LOG:15)
Block(-3,32,8,LEAVES:7)
Block(-2,32,8,LEAVES:15)
Block(5,32,8,LEAVES:15)
Block(-15,32,9,LEAVES:15)
Block(-14,32,9,LEAVES:15)
Block(-13,32,9,LEAVES:15)
Block(-9,32,9,LEAVES:7)
Block(-8,32,9,LEAVES:7)
Block(-7,32,9,LEAVES:15)
Block(-6,32,9,LOG:15)
Block(-5,32,9,LEAVES:7)
Block(-4,32,9,LEAVES:7)
Block(-3,32,9,LEAVES:15)
Block(-14,32,10,LEAVES:15)
Block(-6,32,10,LEAVES:7)
Block(-10,32,11,LEAVES:7)
Block(-8,32,11,LEAVES:7)
Block(-7,32,11,LEAVES:7)
Block(-9,32,12,LEAVES:7)
Block(-7,32,12,LOG:15)
Block(-9,32,13,LEAVES:15)
Block(-7,32,13,LEAVES:15)
Block(-6,32,13,LOG:15)
Block(-5,32,13,LEAVES:15)
Block(-7,32,14,LEAVES:15)
Block(-6,32,14,LEAVES:15)
Block(-5,32,14,LEAVES:15)
Block(-6,32,15,LEAVES:15)
Block(5,33,-4,LEAVES:15)
Block(-3,33,-2,LOG:15)
Block(-2,33,-2,LOG:15)
Block(-3,33,-1,LOG:15)
Block(1,33,1,LEAVES:15)
Block(-12,33,2,LEAVES:15)
Block(-7,33,2,LEAVES:15)
Block(-4,33,2,LEAVES:15)
Block(0,33,2,LEAVES:15)
Block(-13,33,3,LEAVES:15)
Block(-12,33,3,LEAVES:7)
Block(-8,33,3,LEAVES:15)
Block(-7,33,3,LEAVES:15)
Block(-6,33,3,LEAVES:15)
Block(-4,33,3,LEAVES:15)
Block(-3,33,3,LEAVES:15)
Block(-1,33,3,LEAVES:15)
Block(0,33,3,LEAVES:15)
Block(1,33,3,LEAVES:15)
Block(3,33,3,LEAVES:7)
Block(-12,33,4,LEAVES:15)
Block(-11,33,4,LEAVES:15)
Block(-9,33,4,LEAVES:15)
Block(-8,33,4,LEAVES:15)
Block(-7,33,4,LOG:15)
Block(-6,33,4,LOG:15)
Block(-5,33,4,LEAVES:15)
Block(-2,33,4,LEAVES:15)
Block(-1,33,4,LEAVES:15)
Block(0,33,4,LEAVES:15)
Block(-8,33,5,LEAVES:7)
Block(-7,33,5,LEAVES:7)
Block(-6,33,5,LEAVES:15)
Block(-5,33,5,LOG:15)
Block(-4,33,5,LEAVES:15)
Block(-2,33,5,LEAVES:15)
Block(-1,33,5,LEAVES:15)
Block(0,33,5,LOG:15)
Block(1,33,5,LEAVES:15)
Block(4,33,5,LEAVES:15)
Block(-7,33,6,LEAVES:7)
Block(-6,33,6,LEAVES:15)
Block(-5,33,6,LEAVES:15)
Block(-2,33,6,LEAVES:15)
Block(-1,33,6,LOG:15)
Block(0,33,6,LOG:15)
Block(5,33,6,LEAVES:15)
Block(-12,33,7,LEAVES:15)
Block(-11,33,7,LEAVES:7)
Block(-6,33,7,LEAVES:7)
Block(-5,33,7,LEAVES:7)
Block(-2,33,7,LEAVES:15)
Block(-1,33,7,LEAVES:15)
Block(0,33,7,LOG:15)
Block(1,33,7,LOG:15)
Block(2,33,7,LEAVES:15)
Block(4,33,7,LEAVES:15)
Block(-15,33,8,LEAVES:15)
Block(-14,33,8,LEAVES:15)
Block(-13,33,8,LEAVES:15)
Block(-12,33,8,LEAVES:7)
Block(-8,33,8,LEAVES:7)
Block(-1,33,8,LEAVES:15)
Block(0,33,8,LEAVES:15)
Block(3,33,8,LEAVES:7)
Block(6,33,8,LEAVES:15)
Block(-14,33,9,LEAVES:15)
Block(-7,33,9,LEAVES:7)
Block(-6,33,9,LOG:15)
Block(-3,33,9,LEAVES:15)
Block(1,33,9,LEAVES:7)
Block(2,33,9,LEAVES:7)
Block(4,33,9,LEAVES:7)
Block(5,33,9,LEAVES:15)
Block(-10,33,10,LEAVES:15)
Block(-9,33,10,LEAVES:15)
Block(-7,33,10,LOG:15)
Block(-6,33,10,LOG:15)
Block(-1,33,10,LEAVES:15)
Block(3,33,10,LEAVES:7)
Block(-11,33,11,LEAVES:7)
Block(-10,33,11,LEAVES:7)
Block(-9,33,11,LEAVES:15)
Block(-8,33,11,LOG:15)
Block(-7,33,11,LOG:15)
Block(-6,33,11,LEAVES:7)
Block(-5,33,11,LEAVES:7)
Block(-2,33,11,LEAVES:15)
Block(5,33,11,LEAVES:15)
Block(-10,33,12,LEAVES:7)
Block(-9,33,12,LOG:15)
Block(-8,33,12,LEAVES:7)
Block(-7,33,12,LEAVES:15)
Block(-6,33,12,LEAVES:7)
Block(-12,33,13,LEAVES:15)
Block(-9,33,13,LEAVES:15)
Block(-8,33,13,LEAVES:15)
Block(-7,33,13,LEAVES:15)
Block(-6,33,13,LEAVES:7)
Block(-2,33,13,LEAVES:15)
Block(-10,33,14,LEAVES:15)
Block(-9,33,14,LEAVES:15)
Block(-6,33,14,LEAVES:15)
Block(-3,34,-3,LOG:15)
Block(-3,34,-2,LOG:15)
Block(-2,34,-2,LOG:15)
Block(-3,34,-1,LOG:15)
Block(2,34,1,LEAVES:15)
Block(1,34,2,LEAVES:15)
Block(2,34,2,LEAVES:15)
Block(3,34,2,LEAVES:7)
Block(-7,34,3,LEAVES:15)
Block(-6,34,3,LEAVES:15)
Block(-4,34,3,LEAVES:15)
Block(0,34,3,LEAVES:15)
Block(1,34,3,LEAVES:15)
Block(2,34,3,LOG:15)
Block(3,34,3,LEAVES:15)
Block(4,34,3,LEAVES:7)
Block(-12,34,4,LEAVES:7)
Block(-8,34,4,LEAVES:7)
Block(-7,34,4,LEAVES:15)
Block(-6,34,4,LEAVES:15)
Block(-5,34,4,LEAVES:15)
Block(-1,34,4,LEAVES:15)
Block(0,34,4,LEAVES:15)
Block(1,34,4,LOG:15)
Block(2,34,4,LEAVES:15)
Block(4,34,4,LEAVES:15)
Block(-6,34,5,LEAVES:15)
Block(0,34,5,LEAVES:15)
Block(1,34,5,LEAVES:15)
Block(3,34,5,LEAVES:15)
Block(-6,34,6,LEAVES:15)
Block(-5,34,6,LEAVES:15)
Block(-3,34,6,LEAVES:15)
Block(-2,34,6,LEAVES:15)
Block(-1,34,6,LEAVES:15)
Block(0,34,6,LEAVES:15)
Block(1,34,6,LEAVES:15)
Block(2,34,6,LEAVES:15)
Block(3,34,6,LEAVES:15)
Block(4,34,6,LEAVES:15)
Block(-5,34,7,LEAVES:7)
Block(-1,34,7,LEAVES:15)
Block(0,34,7,LEAVES:15)
Block(1,34,7,LEAVES:15)
Block(2,34,7,LOG:15)
Block(3,34,7,LEAVES:15)
Block(4,34,7,LEAVES:15)
Block(5,34,7,LEAVES:15)
Block(-13,34,8,LEAVES:7)
Block(-6,34,8,LEAVES:7)
Block(-5,34,8,LEAVES:15)
Block(-4,34,8,LEAVES:15)
Block(-3,34,8,LEAVES:15)
Block(-2,34,8,LEAVES:15)
Block(-1,34,8,LEAVES:15)
Block(0,34,8,LOG:15)
Block(1,34,8,LEAVES:7)
Block(2,34,8,LEAVES:15)
Block(3,34,8,LEAVES:7)
Block(4,34,8,LEAVES:15)
Block(5,34,8,LEAVES:15)
Block(-6,34,9,LEAVES:7)
Block(-5,34,9,LOG:15)
Block(-4,34,9,LEAVES:15)
Block(-1,34,9,LEAVES:15)
Block(0,34,9,LEAVES:15)
Block(1,34,9,LEAVES:7)
Block(2,34,9,LEAVES:7)
Block(3,34,9,LEAVES:7)
Block(4,34,9,LOG:15)
Block(5,34,9,LEAVES:15)
Block(6,34,9,LEAVES:15)
Block(-9,34,10,LEAVES:15)
Block(-7,34,10,LEAVES:7)
Block(-6,34,10,LOG:15)
Block(-5,34,10,LOG:15)
Block(-4,34,10,LEAVES:15)
Block(-3,34,10,LEAVES:15)
Block(0,34,10,LEAVES:15)
Block(3,34,10,LEAVES:15)
Block(4,34,10,LEAVES:15)
Block(5,34,10,LEAVES:15)
Block(-11,34,11,LEAVES:7)
Block(-10,34,11,LEAVES:7)
Block(-9,34,11,LEAVES:15)
Block(-8,34,11,LEAVES:7)
Block(-7,34,11,LEAVES:7)
Block(-5,34,11,LEAVES:7)
Block(-4,34,11,LOG:15)
Block(-3,34,11,LEAVES:15)
Block(-2,34,11,LEAVES:15)
Block(4,34,11,LEAVES:15)
Block(-12,34,12,LEAVES:15)
Block(-11,34,12,LEAVES:15)
Block(-10,34,12,LOG:15)
Block(-9,34,12,LEAVES:7)
Block(-7,34,12,LEAVES:7)
Block(-4,34,12,LEAVES:7)
Block(-3,34,12,LEAVES:15)
Block(-11,34,13,LEAVES:15)
Block(-10,34,13,LEAVES:15)
Block(-9,34,13,LEAVES:15)
Block(-6,34,13,LEAVES:15)
Block(-3,34,13,LEAVES:15)
Block(-2,34,14,LEAVES:15)
Block(-4,34,15,LEAVES:7)
Block(-11,35,-7,LEAVES:15)
Block(-13,35,-3,LEAVES:15)
Block(-4,35,-3,LOG:15)
Block(-3,35,-3,LOG:15)
Block(-3,35,-2,LOG:15)
Block(-2,35,-2,LOG:15)
Block(-10,35,-1,LEAVES:7)
Block(-3,35,-1,LOG:15)
Block(2,35,2,LEAVES:15)
Block(2,35,3,LEAVES:7)
Block(3,35,3,LEAVES:7)
Block(-6,35,4,LEAVES:7)
Block(1,35,4,LEAVES:15)
Block(2,35,4,LEAVES:7)
Block(3,35,4,LEAVES:15)
Block(1,35,5,LEAVES:7)
Block(-2,35,6,LEAVES:15)
Block(0,35,6,LEAVES:7)
Block(3,35,6,LEAVES:15)
Block(-3,35,7,LEAVES:15)
Block(-2,35,7,LEAVES:15)
Block(-1,35,7,LEAVES:15)
Block(1,35,7,LEAVES:7)
Block(2,35,7,LEAVES:7)
Block(3,35,7,LEAVES:15)
Block(4,35,7,LEAVES:15)
Block(-5,35,8,LEAVES:7)
Block(-4,35,8,LEAVES:15)
Block(-3,35,8,LOG:15)
Block(-2,35,8,LEAVES:15)
Block(-1,35,8,LEAVES:15)
Block(0,35,8,LEAVES:15)
Block(2,35,8,LEAVES:7)
Block(3,35,8,LOG:15)
Block(-5,35,9,LEAVES:15)
Block(-4,35,9,LOG:15)
Block(-3,35,9,LEAVES:15)
Block(-2,35,9,LEAVES:15)
Block(-1,35,9,LEAVES:15)
Block(0,35,9,LEAVES:15)
Block(4,35,9,LEAVES:7)
Block(5,35,9,LEAVES:15)
Block(-5,35,10,LEAVES:7)
Block(4,35,10,LEAVES:15)
Block(-9,35,11,LEAVES:7)
Block(-4,35,11,LEAVES:7)
Block(-3,35,11,LEAVES:15)
Block(-11,35,12,LEAVES:15)
Block(-10,35,12,LEAVES:7)
Block(-6,35,12,LEAVES:15)
Block(-5,35,12,LEAVES:15)
Block(-4,35,12,LOG:15)
Block(-3,35,12,LEAVES:15)
Block(-5,35,13,LEAVES:15)
Block(-4,35,13,LOG:15)
Block(-3,35,13,LEAVES:15)
Block(-2,35,13,LEAVES:15)
Block(-5,35,14,LEAVES:15)
Block(-4,35,14,LEAVES:15)
Block(-3,35,14,LEAVES:15)
Block(-4,35,15,LEAVES:15)
Block(-10,36,-9,LEAVES:15)
Block(-11,36,-8,LEAVES:15)
Block(-9,36,-8,LEAVES:15)
Block(-13,36,-6,LEAVES:7)
Block(-11,36,-6,LEAVES:15)
Block(-12,36,-5,LEAVES:7)
Block(-8,36,-5,LOG:15)
Block(-6,36,-5,LEAVES:7)
Block(-8,36,-4,LOG:15)
Block(-7,36,-4,LOG:15)
Block(-6,36,-4,LOG:15)
Block(-3,36,-4,LOG:15)
Block(-14,36,-3,LEAVES:15)
Block(-12,36,-3,LEAVES:15)
Block(-8,36,-3,LEAVES:7)
Block(-6,36,-3,LOG:15)
Block(-5,36,-3,LOG:15)
Block(-4,36,-3,LOG:15)
Block(-3,36,-3,LOG:15)
Block(-7,36,-2,LOG:15)
Block(-3,36,-2,LOG:15)
Block(-13,36,-1,LEAVES:15)
Block(-11,36,-1,LEAVES:15)
Block(-10,36,-1,LEAVES:15)
Block(-3,36,-1,LOG:15)
Block(-9,36,0,LEAVES:7)
Block(-8,36,1,LEAVES:7)
Block(-9,36,2,LEAVES:15)
Block(1,36,4,LEAVES:7)
Block(-2,36,7,LEAVES:15)
Block(3,36,7,LEAVES:7)
Block(-4,36,8,LEAVES:7)
Block(-3,36,8,LEAVES:15)
Block(-2,36,8,LEAVES:15)
Block(-1,36,8,LEAVES:15)
Block(3,36,8,LEAVES:7)
Block(-5,36,9,LEAVES:7)
Block(-4,36,9,LEAVES:15)
Block(-5,36,12,LEAVES:15)
Block(-4,36,12,LEAVES:15)
Block(-4,36,13,LEAVES:7)
Block(-3,36,13,LEAVES:15)
Block(-4,36,14,LEAVES:15)
Block(-3,37,-14,LEAVES:15)
Block(-9,37,-10,LEAVES:15)
Block(-2,37,-10,LEAVES:15)
Block(-1,37,-10,LEAVES:15)
Block(3,37,-10,LEAVES:15)
Block(-11,37,-9,LEAVES:15)
Block(1,37,-9,LEAVES:7)
Block(-12,37,-8,LEAVES:7)
Block(-7,37,-8,LEAVES:15)
Block(-2,37,-8,LEAVES:15)
Block(-1,37,-8,LOG:15)
Block(2,37,-8,LEAVES:7)
Block(-12,37,-7,LEAVES:15)
Block(-11,37,-7,LEAVES:15)
Block(-10,37,-7,LEAVES:15)
Block(-9,37,-7,LEAVES:15)
Block(-5,37,-7,LEAVES:7)
Block(-3,37,-7,LEAVES:15)
Block(-1,37,-7,LOG:15)
Block(0,37,-7,LEAVES:7)
Block(-13,37,-6,LEAVES:15)
Block(-12,37,-6,LEAVES:15)
Block(-11,37,-6,LEAVES:15)
Block(-10,37,-6,LOG:15)
Block(-9,37,-6,LOG:15)
Block(-8,37,-6,LEAVES:15)
Block(-7,37,-6,LEAVES:7)
Block(-5,37,-6,LEAVES:7)
Block(-2,37,-6,LOG:15)
Block(-1,37,-6,LOG:15)
Block(-12,37,-5,LEAVES:15)
Block(-11,37,-5,LEAVES:7)
Block(-10,37,-5,LEAVES:7)
Block(-9,37,-5,LOG:15)
Block(-8,37,-5,LOG:15)
Block(-7,37,-5,LEAVES:15)
Block(-2,37,-5,LOG:15)
Block(-13,37,-4,LEAVES:15)
Block(-12,37,-4,LEAVES:15)
Block(-11,37,-4,LOG:15)
Block(-10,37,-4,LOG:15)
Block(-9,37,-4,LEAVES:7)
Block(-8,37,-4,LEAVES:15)
Block(-7,37,-4,LEAVES:15)
Block(-3,37,-4,LOG:15)
Block(-2,37,-4,LOG:15)
Block(-14,37,-3,LEAVES:15)
Block(-13,37,-3,LEAVES:15)
Block(-12,37,-3,LOG:15)
Block(-11,37,-3,LEAVES:7)
Block(-10,37,-3,LEAVES:15)
Block(-9,37,-3,LEAVES:7)
Block(-6,37,-3,LEAVES:7)
Block(-13,37,-2,LEAVES:15)
Block(-12,37,-2,LEAVES:15)
Block(-11,37,-2,LEAVES:15)
Block(-10,37,-2,LEAVES:15)
Block(-9,37,-2,LEAVES:7)
Block(-7,37,-2,LEAVES:7)
Block(-3,37,-2,LOG:15)
Block(-2,37,-2,LEAVES:7)
Block(-12,37,-1,LEAVES:15)
Block(-10,37,-1,LEAVES:15)
Block(-9,37,-1,LEAVES:7)
Block(-8,37,-1,LEAVES:7)
Block(-7,37,-1,LOG:15)
Block(-6,37,-1,LEAVES:7)
Block(-3,37,-1,LOG:15)
Block(-10,37,0,LEAVES:15)
Block(-9,37,0,LEAVES:15)
Block(-8,37,0,LOG:15)
Block(-7,37,0,LEAVES:7)
Block(-9,37,1,LEAVES:15)
Block(-8,37,1,LEAVES:15)
Block(-7,37,1,LEAVES:7)
Block(-8,37,2,LEAVES:15)
Block(0,37,5,LEAVES:7)
Block(-1,37,7,LEAVES:7)
Block(-3,37,8,LEAVES:7)
Block(-4,37,12,LEAVES:7)
Block(-3,38,-15,LEAVES:15)
Block(-6,38,-14,LEAVES:15)
Block(-4,38,-14,LEAVES:15)
Block(-1,38,-14,LEAVES:15)
Block(-4,38,-13,LEAVES:7)
Block(-2,38,-13,LEAVES:15)
Block(0,38,-13,LEAVES:15)
Block(-5,38,-12,LEAVES:7)
Block(-3,38,-12,LEAVES:7)
Block(2,38,-12,LEAVES:7)
Block(-4,38,-11,LEAVES:7)
Block(-2,38,-11,LEAVES:15)
Block(-10,38,-10,LEAVES:15)
Block(-4,38,-10,LEAVES:7)
Block(-2,38,-10,LOG:15)
Block(0,38,-10,LEAVES:15)
Block(2,38,-10,LEAVES:15)
Block(4,38,-10,LEAVES:15)
Block(-11,38,-9,LEAVES:15)
Block(-10,38,-9,LEAVES:15)
Block(-9,38,-9,LEAVES:15)
Block(-3,38,-9,LEAVES:15)
Block(-2,38,-9,LOG:15)
Block(-1,38,-9,LOG:15)
Block(0,38,-9,LOG:15)
Block(1,38,-9,LEAVES:15)
Block(2,38,-9,LEAVES:15)
Block(3,38,-9,LEAVES:15)
Block(-12,38,-8,LEAVES:7)
Block(-11,38,-8,LEAVES:15)
Block(-10,38,-8,LOG:15)
Block(-9,38,-8,LEAVES:15)
Block(-5,38,-8,LEAVES:15)
Block(-3,38,-8,LEAVES:15)
Block(-2,38,-8,LEAVES:15)
Block(-1,38,-8,LOG:15)
Block(0,38,-8,LEAVES:7)
Block(1,38,-8,LEAVES:15)
Block(2,38,-8,LEAVES:7)
Block(-11,38,-7,LEAVES:15)
Block(-10,38,-7,LOG:15)
Block(-9,38,-7,LEAVES:15)
Block(-7,38,-7,LEAVES:15)
Block(-6,38,-7,LEAVES:15)
Block(-2,38,-7,LEAVES:15)
Block(-1,38,-7,LEAVES:15)
Block(0,38,-7,LEAVES:7)
Block(1,38,-7,LEAVES:7)
Block(-12,38,-6,LEAVES:7)
Block(-11,38,-6,LEAVES:15)
Block(-10,38,-6,LEAVES:7)
Block(-5,38,-6,LEAVES:7)
Block(-3,38,-6,LEAVES:7)
Block(-2,38,-6,LEAVES:7)
Block(-1,38,-6,LEAVES:7)
Block(-11,38,-5,LEAVES:15)
Block(-9,38,-5,LEAVES:15)
Block(-6,38,-5,LEAVES:15)
Block(-5,38,-5,LOG:15)
Block(-4,38,-5,LEAVES:7)
Block(-3,38,-5,LEAVES:15)
Block(-2,38,-5,LEAVES:15)
Block(-1,38,-5,LEAVES:7)
Block(-11,38,-4,LEAVES:7)
Block(-10,38,-4,LEAVES:15)
Block(-9,38,-4,LEAVES:7)
Block(-4,38,-4,LOG:15)
Block(-3,38,-4,LEAVES:7)
Block(-2,38,-4,LEAVES:7)
Block(-13,38,-3,LEAVES:7)
Block(-12,38,-3,LEAVES:7)
Block(-10,38,-3,LEAVES:15)
Block(-5,38,-3,LEAVES:7)
Block(-4,38,-3,LEAVES:15)
Block(-3,38,-3,LEAVES:7)
Block(-12,38,-2,LEAVES:15)
Block(-10,38,-2,LEAVES:15)
Block(-4,38,-2,LEAVES:7)
Block(-3,38,-2,LOG:15)
Block(-1,38,-2,LEAVES:7)
Block(-8,38,-1,LEAVES:7)
Block(-7,38,-1,LEAVES:7)
Block(-3,38,-1,LOG:15)
Block(1,38,-1,LEAVES:15)
Block(-9,38,0,LEAVES:7)
Block(-8,38,0,LEAVES:15)
Block(-7,38,0,LEAVES:7)
Block(-1,38,0,LEAVES:7)
Block(-8,38,1,LEAVES:15)
Block(-4,38,2,LEAVES:7)
Block(-2,38,2,LEAVES:7)
Block(-2,38,4,LOG:15)
Block(-1,38,4,LEAVES:7)
Block(0,38,4,LEAVES:7)
Block(-6,38,5,LEAVES:15)
Block(-2,38,5,LEAVES:7)
Block(-1,38,5,LOG:15)
Block(0,38,5,LEAVES:15)
Block(1,38,5,LEAVES:7)
Block(-2,38,6,LEAVES:7)
Block(-1,38,6,LEAVES:15)
Block(0,38,6,LEAVES:7)
Block(-1,38,7,LEAVES:15)
Block(-4,39,-15,LEAVES:15)
Block(-5,39,-14,LEAVES:15)
Block(-4,39,-14,LEAVES:15)
Block(-3,39,-14,LEAVES:15)
Block(-2,39,-14,LEAVES:15)
Block(-6,39,-13,LEAVES:15)
Block(-5,39,-13,LEAVES:15)
Block(-4,39,-13,LOG:15)
Block(-3,39,-13,LEAVES:15)
Block(-2,39,-13,LEAVES:15)
Block(-1,39,-13,LEAVES:15)
Block(1,39,-13,LEAVES:15)
Block(2,39,-13,LEAVES:7)
Block(-5,39,-12,LEAVES:15)
Block(-4,39,-12,LEAVES:7)
Block(-3,39,-12,LEAVES:7)
Block(-2,39,-12,LEAVES:15)
Block(-1,39,-12,LEAVES:15)
Block(0,39,-12,LEAVES:15)
Block(2,39,-12,LEAVES:15)
Block(3,39,-12,LEAVES:7)
Block(-4,39,-11,LEAVES:7)
Block(-3,39,-11,LEAVES:15)
Block(-2,39,-11,LOG:15)
Block(-1,39,-11,LEAVES:15)
Block(1,39,-11,LEAVES:7)
Block(2,39,-11,LOG:15)
Block(3,39,-11,LEAVES:15)
Block(4,39,-11,LEAVES:15)
Block(-4,39,-10,LEAVES:7)
Block(-3,39,-10,LEAVES:7)
Block(-2,39,-10,LEAVES:15)
Block(-1,39,-10,LEAVES:15)
Block(0,39,-10,LEAVES:15)
Block(1,39,-10,LOG:15)
Block(2,39,-10,LEAVES:15)
Block(3,39,-10,LEAVES:15)
Block(-10,39,-9,LEAVES:15)
Block(-5,39,-9,LEAVES:15)
Block(-4,39,-9,LEAVES:15)
Block(-3,39,-9,LOG:15)
Block(-2,39,-9,LEAVES:15)
Block(-1,39,-9,LEAVES:15)
Block(0,39,-9,LEAVES:15)
Block(1,39,-9,LEAVES:15)
Block(2,39,-9,LEAVES:15)
Block(-11,39,-8,LEAVES:7)
Block(-10,39,-8,LEAVES:7)
Block(-7,39,-8,LEAVES:15)
Block(-4,39,-8,LEAVES:15)
Block(-3,39,-8,LEAVES:15)
Block(-2,39,-8,LEAVES:15)
Block(-1,39,-8,LEAVES:7)
Block(1,39,-8,LEAVES:7)
Block(-10,39,-7,LEAVES:15)
Block(-9,39,-7,LEAVES:15)
Block(-8,39,-7,LEAVES:15)
Block(-7,39,-7,LEAVES:15)
Block(-6,39,-7,LEAVES:15)
Block(-1,39,-7,LEAVES:7)
Block(-11,39,-6,LEAVES:15)
Block(-10,39,-6,LEAVES:7)
Block(-9,39,-6,LEAVES:15)
Block(-8,39,-6,LEAVES:15)
Block(-7,39,-6,LOG:15)
Block(-6,39,-6,LEAVES:15)
Block(-9,39,-5,LEAVES:15)
Block(-8,39,-5,LEAVES:15)
Block(-6,39,-5,LOG:15)
Block(-5,39,-5,LEAVES:7)
Block(-3,39,-5,LEAVES:7)
Block(-2,39,-5,LEAVES:15)
Block(-1,39,-5,LEAVES:7)
Block(-10,39,-4,LEAVES:15)
Block(-7,39,-4,LEAVES:15)
Block(-6,39,-4,LEAVES:15)
Block(-5,39,-4,LEAVES:7)
Block(-4,39,-4,LEAVES:7)
Block(-2,39,-4,LEAVES:7)
Block(-6,39,-3,LEAVES:7)
Block(-4,39,-3,LEAVES:7)
Block(-4,39,-2,LEAVES:7)
Block(-3,39,-2,LOG:15)
Block(-1,39,-2,LEAVES:7)
Block(-3,39,-1,LOG:15)
Block(-2,39,-1,LEAVES:7)
Block(-1,39,-1,LEAVES:15)
Block(0,39,-1,LEAVES:15)
Block(-8,39,0,LEAVES:7)
Block(-4,39,0,LEAVES:7)
Block(-3,39,0,LOG:15)
Block(-2,39,0,LOG:15)
Block(-1,39,0,LEAVES:15)
Block(0,39,0,LEAVES:15)
Block(-4,39,1,LEAVES:7)
Block(-3,39,1,LEAVES:7)
Block(-2,39,1,LOG:15)
Block(-1,39,1,LEAVES:7)
Block(-5,39,2,LEAVES:7)
Block(-4,39,2,LEAVES:15)
Block(-3,39,2,LOG:15)
Block(-2,39,2,LEAVES:7)
Block(-1,39,2,LEAVES:7)
Block(1,39,2,LEAVES:15)
Block(-2,39,3,LOG:15)
Block(-1,39,3,LEAVES:15)
Block(0,39,3,LEAVES:15)
Block(-7,39,4,LEAVES:15)
Block(-5,39,4,LEAVES:15)
Block(-4,39,4,LEAVES:7)
Block(-2,39,4,LEAVES:7)
Block(-1,39,4,LEAVES:7)
Block(-8,39,5,LEAVES:15)
Block(-2,39,5,LEAVES:7)
Block(-1,39,5,LEAVES:15)
Block(0,39,5,LEAVES:7)
Block(-6,39,6,LEAVES:15)
Block(-1,39,6,LEAVES:7)
Block(-4,40,-14,LEAVES:15)
Block(-5,40,-13,LEAVES:15)
Block(-4,40,-13,LEAVES:7)
Block(-2,40,-13,LEAVES:15)
Block(-3,40,-12,LOG:15)
Block(-2,40,-12,LEAVES:15)
Block(-1,40,-12,LEAVES:15)
Block(1,40,-12,LEAVES:15)
Block(2,40,-12,LEAVES:7)
Block(-3,40,-11,LEAVES:7)
Block(-2,40,-11,LEAVES:7)
Block(1,40,-11,LEAVES:7)
Block(2,40,-11,LEAVES:7)
Block(3,40,-11,LEAVES:15)
Block(-2,40,-10,LEAVES:7)
Block(0,40,-10,LEAVES:7)
Block(1,40,-10,LEAVES:15)
Block(-4,40,-9,LEAVES:15)
Block(-3,40,-9,LEAVES:7)
Block(-1,40,-9,LEAVES:7)
Block(-7,40,-7,LEAVES:7)
Block(-9,40,-6,LEAVES:15)
Block(-8,40,-6,LEAVES:15)
Block(-7,40,-6,LEAVES:15)
Block(-8,40,-5,LEAVES:15)
Block(-6,40,-5,LEAVES:15)
Block(-2,40,-5,LEAVES:7)
Block(-6,40,-4,LEAVES:15)
Block(-3,40,-2,LOG:15)
Block(-4,40,-1,LEAVES:7)
Block(-3,40,-1,LOG:15)
Block(-1,40,-1,LEAVES:7)
Block(-3,40,0,LEAVES:7)
Block(-2,40,0,LEAVES:7)
Block(-1,40,0,LEAVES:15)
Block(0,40,0,LEAVES:15)
Block(-2,40,1,LEAVES:7)
Block(-1,40,1,LOG:15)
Block(0,40,1,LEAVES:15)
Block(2,40,1,LEAVES:15)
Block(-4,40,2,LEAVES:7)
Block(-3,40,2,LEAVES:7)
Block(-2,40,2,LEAVES:7)
Block(0,40,2,LOG:15)
Block(-7,40,3,LEAVES:15)
Block(-6,40,3,LEAVES:15)
Block(-5,40,3,LEAVES:15)
Block(-4,40,3,LOG:15)
Block(-3,40,3,LOG:15)
Block(-2,40,3,LEAVES:7)
Block(-1,40,3,LEAVES:7)
Block(0,40,3,LEAVES:15)
Block(1,40,3,LEAVES:15)
Block(3,40,3,LEAVES:15)
Block(-8,40,4,LEAVES:15)
Block(-7,40,4,LEAVES:15)
Block(-6,40,4,LEAVES:15)
Block(-5,40,4,LOG:15)
Block(-4,40,4,LEAVES:7)
Block(-3,40,4,LEAVES:15)
Block(-7,40,5,LEAVES:15)
Block(-6,40,5,LEAVES:15)
Block(-5,40,5,LEAVES:15)
Block(-4,40,5,LEAVES:7)
Block(-3,40,5,LEAVES:15)
Block(-2,40,5,LEAVES:15)
Block(-1,40,5,LEAVES:7)
Block(-6,40,6,LEAVES:15)
Block(-3,40,6,LEAVES:15)
Block(-3,41,-12,LEAVES:7)
Block(-2,41,-12,LEAVES:7)
Block(1,41,-10,LEAVES:7)
Block(-8,41,-6,LEAVES:15)
Block(-3,41,-2,LOG:15)
Block(-3,41,-1,LOG:15)
Block(-1,41,0,LEAVES:15)
Block(-1,41,1,LEAVES:7)
Block(1,41,1,LEAVES:15)
Block(2,41,1,LEAVES:15)
Block(0,41,2,LEAVES:15)
Block(1,41,2,LOG:15)
Block(2,41,2,LEAVES:15)
Block(3,41,2,LEAVES:15)
Block(1,41,3,LEAVES:15)
Block(2,41,3,LEAVES:15)
Block(-7,41,4,LEAVES:15)
Block(-6,41,4,LEAVES:15)
Block(-5,41,4,LEAVES:7)
Block(-3,41,4,LEAVES:7)
Block(1,41,4,LEAVES:7)
Block(-6,41,5,LEAVES:7)
Block(-3,41,5,LEAVES:15)
Block(-4,42,-2,LOG:15)
Block(-3,42,-2,LOG:15)
Block(-4,42,-1,LOG:15)
Block(-3,42,-1,LOG:15)
Block(1,42,2,LEAVES:7)
Block(2,42,2,LEAVES:15)
Block(1,42,3,LEAVES:7)
Block(-6,42,4,LEAVES:7)
Block(-4,43,-2,LOG:15)
Block(-3,43,-2,LOG:15)
Block(-3,43,-1,LOG:15)
Block(-6,43,6,LEAVES:15)
Block(5,44,-4,LEAVES:15)
Block(-4,44,-3,LOG:15)
Block(-4,44,-2,LOG:15)
Block(-3,44,-2,LOG:15)
Block(-6,44,-1,LEAVES:15)
Block(-3,44,-1,LOG:15)
Block(-5,44,1,LEAVES:15)
Block(-3,44,2,LOG:15)
Block(-2,44,2,LOG:15)
Block(-3,44,3,LOG:15)
Block(-5,44,4,LEAVES:7)
Block(-4,44,4,LOG:15)
Block(-8,44,5,LEAVES:15)
Block(-7,44,6,LEAVES:7)
Block(-2,44,6,LEAVES:15)
Block(-7,44,7,LEAVES:15)
Block(-5,44,7,LEAVES:15)
Block(-7,45,-11,LEAVES:15)
Block(-2,45,-10,LEAVES:15)
Block(-8,45,-9,LEAVES:15)
Block(-3,45,-9,LEAVES:15)
Block(-6,45,-8,LEAVES:15)
Block(-8,45,-7,LEAVES:15)
Block(-5,45,-7,LOG:15)
Block(-3,45,-7,LEAVES:15)
Block(-5,45,-6,LOG:15)
Block(-3,45,-6,LEAVES:15)
Block(-5,45,-5,LEAVES:7)
Block(-1,45,-5,LEAVES:15)
Block(4,45,-5,LEAVES:15)
Block(-7,45,-4,LEAVES:15)
Block(-4,45,-4,LEAVES:7)
Block(-2,45,-4,LEAVES:15)
Block(6,45,-4,LEAVES:15)
Block(8,45,-4,LEAVES:15)
Block(5,45,-3,LEAVES:15)
Block(-6,45,-2,LEAVES:7)
Block(-5,45,-2,LOG:15)
Block(-4,45,-2,LOG:15)
Block(-3,45,-2,LOG:15)
Block(-1,45,-2,LEAVES:15)
Block(0,45,-2,LOG:15)
Block(4,45,-2,LEAVES:7)
Block(7,45,-2,LEAVES:7)
Block(-6,45,-1,LOG:15)
Block(-5,45,-1,LOG:15)
Block(-3,45,-1,LOG:15)
Block(-1,45,-1,LOG:15)
Block(1,45,-1,LOG:15)
Block(6,45,-1,LEAVES:15)
Block(-6,45,0,LEAVES:15)
Block(-2,45,0,LOG:15)
Block(-1,45,0,LOG:15)
Block(0,45,0,LOG:15)
Block(-2,45,1,LOG:15)
Block(-1,45,1,LEAVES:15)
Block(-6,45,2,LEAVES:15)
Block(-3,45,2,LEAVES:15)
Block(-2,45,2,LOG:15)
Block(1,45,2,LEAVES:15)
Block(5,45,2,LEAVES:15)
Block(-4,45,3,LEAVES:7)
Block(-3,45,3,LEAVES:7)
Block(-1,45,3,LEAVES:15)
Block(-6,45,4,LEAVES:7)
Block(-5,45,4,LEAVES:7)
Block(-4,45,4,LEAVES:15)
Block(3,45,4,LEAVES:15)
Block(6,45,4,LEAVES:15)
Block(-7,45,5,LEAVES:15)
Block(-6,45,5,LEAVES:15)
Block(-5,45,5,LEAVES:15)
Block(-4,45,5,LOG:15)
Block(0,45,5,LEAVES:7)
Block(1,45,5,LEAVES:15)
Block(-8,45,6,LEAVES:15)
Block(-7,45,6,LEAVES:15)
Block(-6,45,6,LEAVES:15)
Block(-5,45,6,LOG:15)
Block(-1,45,6,LEAVES:7)
Block(-7,45,7,LEAVES:15)
Block(-6,45,7,LEAVES:15)
Block(-5,45,7,LEAVES:15)
Block(-2,45,7,LEAVES:15)
Block(0,45,7,LEAVES:7)
Block(-6,45,8,LEAVES:7)
Block(-3,45,8,LEAVES:15)
Block(-2,45,8,LEAVES:15)
Block(-4,45,9,LEAVES:15)
Block(0,45,9,LEAVES:15)
Block(-4,46,-13,LEAVES:7)
Block(-2,46,-12,LEAVES:15)
Block(-7,46,-11,LEAVES:15)
Block(-6,46,-11,LEAVES:15)
Block(-4,46,-11,LEAVES:15)
Block(-8,46,-10,LEAVES:15)
Block(-7,46,-10,LEAVES:15)
Block(-6,46,-10,LEAVES:15)
Block(-3,46,-10,LEAVES:15)
Block(-8,46,-9,LEAVES:15)
Block(-7,46,-9,LOG:15)
Block(-6,46,-9,LEAVES:15)
Block(-5,46,-9,LEAVES:7)
Block(-4,46,-9,LOG:15)
Block(-3,46,-9,LEAVES:15)
Block(-2,46,-9,LEAVES:15)
Block(-8,46,-8,LEAVES:15)
Block(-7,46,-8,LEAVES:15)
Block(-6,46,-8,LOG:15)
Block(-5,46,-8,LOG:15)
Block(-4,46,-8,LEAVES:15)
Block(-3,46,-8,LEAVES:15)
Block(-7,46,-7,LEAVES:15)
Block(-6,46,-7,LEAVES:15)
Block(-5,46,-7,LEAVES:15)
Block(-7,46,-6,LEAVES:15)
Block(-6,46,-6,LEAVES:15)
Block(-4,46,-6,LEAVES:15)
Block(-3,46,-6,LEAVES:15)
Block(-7,46,-5,LEAVES:15)
Block(-6,46,-5,LEAVES:15)
Block(-5,46,-5,LOG:15)
Block(-4,46,-5,LEAVES:7)
Block(-3,46,-5,LEAVES:15)
Block(-2,46,-5,LEAVES:15)
Block(1,46,-5,LOG:15)
Block(5,46,-5,LEAVES:15)
Block(-11,46,-4,LEAVES:15)
Block(-6,46,-4,LEAVES:15)
Block(-5,46,-4,LEAVES:7)
Block(-4,46,-4,LOG:15)
Block(-3,46,-4,LEAVES:15)
Block(-2,46,-4,LEAVES:15)
Block(-1,46,-4,LEAVES:15)
Block(0,46,-4,LOG:15)
Block(1,46,-4,LEAVES:7)
Block(3,46,-4,LEAVES:15)
Block(4,46,-4,LEAVES:15)
Block(5,46,-4,LEAVES:15)
Block(6,46,-4,LEAVES:15)
Block(7,46,-4,LEAVES:15)
Block(-10,46,-3,LEAVES:15)
Block(-8,46,-3,LEAVES:15)
Block(-6,46,-3,LEAVES:15)
Block(-5,46,-3,LEAVES:15)
Block(-4,46,-3,LOG:15)
Block(-3,46,-3,LEAVES:15)
Block(-2,46,-3,LEAVES:15)
Block(0,46,-3,LOG:15)
Block(2,46,-3,LEAVES:7)
Block(4,46,-3,LEAVES:15)
Block(5,46,-3,LOG:15)
Block(6,46,-3,LEAVES:15)
Block(7,46,-3,LEAVES:15)
Block(8,46,-3,LEAVES:15)
Block(-7,46,-2,LEAVES:7)
Block(-5,46,-2,LEAVES:15)
Block(-4,46,-2,LEAVES:15)
Block(-3,46,-2,LEAVES:15)
Block(-2,46,-2,LEAVES:15)
Block(-1,46,-2,LOG:15)
Block(0,46,-2,LOG:15)
Block(4,46,-2,LOG:15)
Block(5,46,-2,LEAVES:15)
Block(6,46,-2,LEAVES:15)
Block(7,46,-2,LEAVES:15)
Block(-8,46,-1,LOG:15)
Block(-7,46,-1,LOG:15)
Block(-6,46,-1,LEAVES:15)
Block(-5,46,-1,LEAVES:15)
Block(-3,46,-1,LEAVES:15)
Block(-2,46,-1,LEAVES:15)
Block(-1,46,-1,LOG:15)
Block(1,46,-1,LEAVES:15)
Block(2,46,-1,LOG:15)
Block(3,46,-1,LOG:15)
Block(4,46,-1,LEAVES:7)
Block(-9,46,0,LEAVES:7)
Block(-7,46,0,LEAVES:15)
Block(-6,46,0,LEAVES:15)
Block(-5,46,0,LOG:15)
Block(-4,46,0,LEAVES:15)
Block(-3,46,0,LEAVES:15)
Block(-2,46,0,LEAVES:15)
Block(-1,46,0,LOG:15)
Block(0,46,0,LEAVES:15)
Block(2,46,0,LOG:15)
Block(3,46,0,LEAVES:7)
Block(4,46,0,LEAVES:7)
Block(-12,46,1,LEAVES:7)
Block(-6,46,1,LEAVES:15)
Block(-5,46,1,LEAVES:15)
Block(-4,46,1,LEAVES:15)
Block(-3,46,1,LEAVES:15)
Block(-2,46,1,LEAVES:15)
Block(-1,46,1,LEAVES:15)
Block(0,46,1,LEAVES:15)
Block(1,46,1,LEAVES:15)
Block(3,46,1,LOG:15)
Block(4,46,1,LEAVES:15)
Block(5,46,1,LEAVES:15)
Block(-10,46,2,LEAVES:7)
Block(-8,46,2,LEAVES:15)
Block(-6,46,2,LEAVES:15)
Block(-5,46,2,LEAVES:15)
Block(-1,46,2,LEAVES:15)
Block(0,46,2,LEAVES:15)
Block(1,46,2,LEAVES:15)
Block(4,46,2,LEAVES:15)
Block(0,46,3,LEAVES:15)
Block(3,46,3,LEAVES:15)
Block(6,46,3,LEAVES:15)
Block(-4,46,4,LEAVES:7)
Block(4,46,4,LEAVES:15)
Block(7,46,4,LEAVES:15)
Block(-6,46,5,LEAVES:7)
Block(-4,46,5,LEAVES:15)
Block(-3,46,5,LOG:15)
Block(-2,46,5,LEAVES:15)
Block(-1,46,5,LEAVES:15)
Block(0,46,5,LEAVES:15)
Block(5,46,5,LEAVES:15)
Block(-7,46,6,LEAVES:15)
Block(-6,46,6,LEAVES:7)
Block(-5,46,6,LEAVES:7)
Block(-4,46,6,LEAVES:15)
Block(-2,46,6,LOG:15)
Block(-1,46,6,LOG:15)
Block(0,46,6,LEAVES:15)
Block(1,46,6,LEAVES:15)
Block(-6,46,7,LEAVES:7)
Block(-5,46,7,LOG:15)
Block(-4,46,7,LEAVES:15)
Block(-3,46,7,LEAVES:15)
Block(-2,46,7,LEAVES:15)
Block(-1,46,7,LEAVES:15)
Block(0,46,7,LEAVES:15)
Block(-6,46,8,LEAVES:15)
Block(-5,46,8,LEAVES:15)
Block(-4,46,8,LEAVES:15)
Block(-2,46,8,LEAVES:15)
Block(-1,46,8,LEAVES:15)
Block(0,46,8,LEAVES:15)
Block(-5,46,9,LEAVES:15)
Block(-1,46,9,LEAVES:15)
Block(-4,47,-13,LEAVES:15)
Block(-5,47,-12,LEAVES:15)
Block(-4,47,-12,LEAVES:15)
Block(-3,47,-12,LEAVES:15)
Block(-5,47,-11,LEAVES:15)
Block(-4,47,-11,LEAVES:15)
Block(-3,47,-11,LEAVES:15)
Block(-2,47,-11,LEAVES:15)
Block(3,47,-11,LEAVES:15)
Block(-7,47,-10,LEAVES:15)
Block(-5,47,-10,LEAVES:15)
Block(-4,47,-10,LOG:15)
Block(-3,47,-10,LEAVES:15)
Block(1,47,-10,LEAVES:7)
Block(5,47,-10,LEAVES:15)
Block(-8,47,-9,LEAVES:15)
Block(-7,47,-9,LEAVES:15)
Block(-5,47,-9,LEAVES:15)
Block(-4,47,-9,LEAVES:15)
Block(-3,47,-9,LEAVES:15)
Block(-1,47,-9,LEAVES:15)
Block(2,47,-9,LEAVES:7)
Block(4,47,-9,LEAVES:15)
Block(-8,47,-8,LEAVES:15)
Block(-6,47,-8,LEAVES:15)
Block(-5,47,-8,LEAVES:15)
Block(-4,47,-8,LEAVES:15)
Block(-7,47,-7,LEAVES:15)
Block(-6,47,-7,LEAVES:15)
Block(-5,47,-7,LEAVES:15)
Block(-4,47,-7,LEAVES:15)
Block(1,47,-7,LEAVES:7)
Block(3,47,-7,LOG:15)
Block(5,47,-7,LEAVES:15)
Block(-6,47,-6,LEAVES:15)
Block(-5,47,-6,LOG:15)
Block(-4,47,-6,LEAVES:15)
Block(-3,47,-6,LEAVES:15)
Block(-2,47,-6,LOG:15)
Block(-1,47,-6,LEAVES:7)
Block(1,47,-6,LEAVES:7)
Block(2,47,-6,LOG:15)
Block(3,47,-6,LOG:15)
Block(-6,47,-5,LEAVES:15)
Block(-5,47,-5,LEAVES:7)
Block(-4,47,-5,LEAVES:7)
Block(-3,47,-5,LEAVES:7)
Block(-1,47,-5,LOG:15)
Block(0,47,-5,LEAVES:7)
Block(1,47,-5,LOG:15)
Block(2,47,-5,LOG:15)
Block(-13,47,-4,LEAVES:15)
Block(-10,47,-4,LEAVES:15)
Block(-5,47,-4,LEAVES:7)
Block(-4,47,-4,LEAVES:15)
Block(-3,47,-4,LEAVES:15)
Block(-2,47,-4,LEAVES:15)
Block(-1,47,-4,LEAVES:7)
Block(0,47,-4,LOG:15)
Block(1,47,-4,LEAVES:7)
Block(2,47,-4,LEAVES:15)
Block(3,47,-4,LEAVES:15)
Block(5,47,-4,LEAVES:15)
Block(-11,47,-3,LEAVES:15)
Block(-10,47,-3,LEAVES:15)
Block(-9,47,-3,LEAVES:15)
Block(-5,47,-3,LEAVES:7)
Block(-4,47,-3,LEAVES:7)
Block(-1,47,-3,LEAVES:7)
Block(0,47,-3,LEAVES:15)
Block(1,47,-3,LEAVES:15)
Block(2,47,-3,LEAVES:15)
Block(3,47,-3,LEAVES:7)
Block(5,47,-3,LEAVES:15)
Block(6,47,-3,LEAVES:7)
Block(7,47,-3,LEAVES:15)
Block(-14,47,-2,LEAVES:7)
Block(-12,47,-2,LEAVES:15)
Block(-10,47,-2,LOG:15)
Block(-9,47,-2,LEAVES:15)
Block(-3,47,-2,LEAVES:15)
Block(-1,47,-2,LEAVES:7)
Block(0,47,-2,LEAVES:7)
Block(1,47,-2,LEAVES:7)
Block(2,47,-2,LEAVES:7)
Block(4,47,-2,LEAVES:7)
Block(5,47,-2,LEAVES:15)
Block(-9,47,-1,LOG:15)
Block(-8,47,-1,LEAVES:15)
Block(-5,47,-1,LEAVES:15)
Block(-2,47,-1,LEAVES:15)
Block(-1,47,-1,LEAVES:15)
Block(0,47,-1,LEAVES:15)
Block(2,47,-1,LEAVES:7)
Block(-12,47,0,LEAVES:15)
Block(-11,47,0,LEAVES:15)
Block(-10,47,0,LEAVES:7)
Block(-9,47,0,LOG:15)
Block(-8,47,0,LEAVES:15)
Block(-7,47,0,LEAVES:15)
Block(-6,47,0,LEAVES:15)
Block(-5,47,0,LEAVES:15)
Block(-3,47,0,LEAVES:15)
Block(-2,47,0,LEAVES:15)
Block(-1,47,0,LEAVES:15)
Block(2,47,0,LEAVES:15)
Block(3,47,0,LEAVES:7)
Block(-12,47,1,LEAVES:15)
Block(-11,47,1,LEAVES:15)
Block(-10,47,1,LOG:15)
Block(-9,47,1,LEAVES:15)
Block(-8,47,1,LEAVES:15)
Block(-5,47,1,LEAVES:15)
Block(-2,47,1,LEAVES:15)
Block(0,47,1,LEAVES:15)
Block(1,47,1,LEAVES:15)
Block(2,47,1,LEAVES:7)
Block(3,47,1,LEAVES:7)
Block(4,47,1,LEAVES:15)
Block(-11,47,2,LEAVES:7)
Block(-10,47,2,LEAVES:15)
Block(-9,47,2,LEAVES:15)
Block(0,47,2,LEAVES:15)
Block(2,47,2,LEAVES:7)
Block(3,47,2,LOG:15)
Block(4,47,2,LEAVES:15)
Block(5,47,2,LEAVES:15)
Block(3,47,3,LEAVES:15)
Block(4,47,3,LOG:15)
Block(5,47,3,LEAVES:15)
Block(6,47,3,LEAVES:15)
Block(7,47,3,LEAVES:15)
Block(3,47,4,LEAVES:15)
Block(4,47,4,LEAVES:15)
Block(5,47,4,LEAVES:15)
Block(6,47,4,LEAVES:15)
Block(-3,47,5,LEAVES:7)
Block(4,47,5,LEAVES:15)
Block(-2,47,6,LEAVES:15)
Block(-1,47,6,LEAVES:15)
Block(0,47,6,LEAVES:15)
Block(-5,47,7,LEAVES:7)
Block(-4,47,7,LEAVES:15)
Block(-1,47,7,LEAVES:15)
Block(0,47,7,LEAVES:7)
Block(-5,47,8,LEAVES:15)
Block(-1,47,8,LEAVES:15)
Block(1,48,-14,LEAVES:7)
Block(2,48,-13,LEAVES:7)
Block(-4,48,-12,LEAVES:15)
Block(0,48,-12,LEAVES:15)
Block(-4,48,-11,LEAVES:15)
Block(-3,48,-11,LEAVES:15)
Block(-1,48,-11,LEAVES:15)
Block(2,48,-11,LEAVES:15)
Block(3,48,-11,LEAVES:15)
Block(-5,48,-10,LEAVES:15)
Block(-4,48,-10,LEAVES:15)
Block(-1,48,-10,LEAVES:15)
Block(0,48,-10,LEAVES:15)
Block(1,48,-10,LOG:15)
Block(2,48,-10,LEAVES:7)
Block(3,48,-10,LEAVES:15)
Block(4,48,-10,LEAVES:15)
Block(-4,48,-9,LEAVES:15)
Block(-2,48,-9,LEAVES:7)
Block(0,48,-9,LEAVES:15)
Block(1,48,-9,LEAVES:7)
Block(2,48,-9,LOG:15)
Block(3,48,-9,LEAVES:15)
Block(4,48,-9,LEAVES:15)
Block(5,48,-9,LEAVES:15)
Block(-5,48,-8,LEAVES:7)
Block(-3,48,-8,LEAVES:7)
Block(-2,48,-8,LEAVES:15)
Block(-1,48,-8,LEAVES:7)
Block(0,48,-8,LEAVES:15)
Block(1,48,-8,LEAVES:15)
Block(2,48,-8,LOG:15)
Block(3,48,-8,LEAVES:15)
Block(4,48,-8,LEAVES:15)
Block(-6,48,-7,LEAVES:15)
Block(-5,48,-7,LEAVES:15)
Block(-3,48,-7,LEAVES:7)
Block(-2,48,-7,LOG:15)
Block(-1,48,-7,LEAVES:7)
Block(1,48,-7,LEAVES:7)
Block(2,48,-7,LEAVES:7)
Block(3,48,-7,LEAVES:15)
Block(4,48,-7,LEAVES:15)
Block(-5,48,-6,LEAVES:15)
Block(-4,48,-6,LEAVES:7)
Block(-2,48,-6,LEAVES:7)
Block(2,48,-6,LEAVES:7)
Block(3,48,-6,LEAVES:7)
Block(-5,48,-5,LEAVES:7)
Block(-1,48,-5,LEAVES:7)
Block(1,48,-5,LEAVES:7)
Block(2,48,-5,LEAVES:15)
Block(3,48,-5,LEAVES:7)
Block(-12,48,-4,LEAVES:15)
Block(-4,48,-4,LEAVES:7)
Block(0,48,-4,LEAVES:7)
Block(2,48,-4,LEAVES:7)
Block(-13,48,-3,LEAVES:15)
Block(-12,48,-3,LEAVES:15)
Block(-11,48,-3,LEAVES:15)
Block(-10,48,-3,LEAVES:15)
Block(0,48,-3,LEAVES:7)
Block(1,48,-3,LEAVES:15)
Block(2,48,-3,LEAVES:7)
Block(5,48,-3,LEAVES:7)
Block(-14,48,-2,LEAVES:15)
Block(-13,48,-2,LEAVES:15)
Block(-12,48,-2,LEAVES:15)
Block(-11,48,-2,LOG:15)
Block(-10,48,-2,LEAVES:15)
Block(-9,48,-2,LEAVES:15)
Block(-3,48,-2,LOG:15)
Block(1,48,-2,LEAVES:7)
Block(-13,48,-1,LEAVES:15)
Block(-12,48,-1,LEAVES:15)
Block(-11,48,-1,LEAVES:15)
Block(-10,48,-1,LEAVES:7)
Block(-9,48,-1,LEAVES:15)
Block(-9,48,0,LEAVES:7)
Block(-8,48,0,LEAVES:15)
Block(-5,48,0,LEAVES:7)
Block(-2,48,0,LEAVES:7)
Block(2,48,0,LEAVES:7)
Block(-11,48,1,LEAVES:15)
Block(-10,48,1,LEAVES:7)
Block(0,48,1,LEAVES:15)
Block(-10,48,2,LEAVES:7)
Block(-9,48,2,LEAVES:15)
Block(-2,48,2,LEAVES:7)
Block(1,48,2,LEAVES:15)
Block(3,48,2,LEAVES:7)
Block(4,48,2,LEAVES:7)
Block(3,48,3,LEAVES:7)
Block(4,48,3,LEAVES:15)
Block(5,48,3,LEAVES:7)
Block(6,48,3,LEAVES:15)
Block(-2,48,4,LEAVES:15)
Block(4,48,4,LEAVES:15)
Block(-1,48,7,LEAVES:7)
Block(1,49,-14,LEAVES:15)
Block(0,49,-13,LEAVES:15)
Block(1,49,-13,LEAVES:15)
Block(2,49,-13,LEAVES:15)
Block(-1,49,-12,LEAVES:15)
Block(0,49,-12,LEAVES:15)
Block(1,49,-12,LEAVES:15)
Block(2,49,-12,LEAVES:15)
Block(0,49,-11,LEAVES:15)
Block(1,49,-11,LOG:15)
Block(2,49,-11,LEAVES:15)
Block(3,49,-11,LEAVES:15)
Block(-4,49,-10,LEAVES:15)
Block(0,49,-10,LEAVES:15)
Block(1,49,-10,LEAVES:7)
Block(2,49,-10,LEAVES:7)
Block(3,49,-10,LEAVES:7)
Block(1,49,-9,LEAVES:7)
Block(2,49,-9,LEAVES:15)
Block(3,49,-9,LEAVES:15)
Block(4,49,-9,LEAVES:15)
Block(-2,49,-8,LEAVES:7)
Block(1,49,-8,LEAVES:7)
Block(2,49,-8,LEAVES:7)
Block(-2,49,-7,LEAVES:15)
Block(-1,49,-7,LEAVES:7)
Block(3,49,-7,LEAVES:15)
Block(-5,49,-6,LEAVES:7)
Block(2,49,-5,LEAVES:7)
Block(-12,49,-3,LEAVES:15)
Block(1,49,-3,LEAVES:7)
Block(-13,49,-2,LEAVES:15)
Block(-12,49,-2,LEAVES:7)
Block(-11,49,-2,LEAVES:15)
Block(-10,49,-2,LEAVES:7)
Block(-3,49,-2,LOG:15)
Block(-11,49,-1,LEAVES:15)
Block(-3,49,-1,LOG:15)
Block(-2,49,-1,LEAVES:7)
Block(-3,49,0,LOG:15)
Block(-2,49,0,LEAVES:15)
Block(-1,49,0,LEAVES:7)
Block(-2,49,1,LOG:15)
Block(1,49,1,LEAVES:15)
Block(2,49,1,LEAVES:15)
Block(-4,49,2,LEAVES:7)
Block(-2,49,2,LOG:15)
Block(-1,49,2,LEAVES:7)
Block(-2,49,3,LEAVES:15)
Block(0,49,3,LEAVES:15)
Block(4,49,3,LEAVES:7)
Block(-5,49,4,LEAVES:15)
Block(-3,49,5,LEAVES:15)
Block(-4,49,6,LEAVES:15)
Block(1,50,-13,LEAVES:7)
Block(0,50,-12,LEAVES:15)
Block(1,50,-12,LEAVES:15)
Block(1,50,-11,LEAVES:15)
Block(2,50,-11,LEAVES:7)
Block(1,50,-10,LEAVES:7)
Block(2,50,-9,LEAVES:7)
Block(-2,50,-7,LEAVES:7)
Block(-3,50,-3,LEAVES:7)
Block(-11,50,-2,LEAVES:7)
Block(-4,50,-2,LOG:15)
Block(-3,50,-2,LOG:15)
Block(-1,50,-2,LEAVES:15)
Block(-3,50,-1,LEAVES:7)
Block(-3,50,0,LEAVES:15)
Block(-2,50,0,LEAVES:15)
Block(-1,50,0,LEAVES:15)
Block(0,50,0,LEAVES:7)
Block(1,50,0,LEAVES:7)
Block(-2,50,1,LEAVES:15)
Block(-1,50,1,LOG:15)
Block(0,50,1,LEAVES:15)
Block(1,50,1,LEAVES:15)
Block(2,50,1,LEAVES:15)
Block(-4,50,2,LEAVES:7)
Block(-3,50,2,LEAVES:7)
Block(-2,50,2,LEAVES:15)
Block(-1,50,2,LEAVES:15)
Block(0,50,2,LEAVES:15)
Block(1,50,2,LEAVES:15)
Block(-5,50,3,LEAVES:15)
Block(-4,50,3,LEAVES:15)
Block(-3,50,3,LOG:15)
Block(-2,50,3,LEAVES:15)
Block(-1,50,3,LEAVES:15)
Block(-4,50,4,LEAVES:15)
Block(-3,50,4,LEAVES:15)
Block(-2,50,4,LEAVES:15)
Block(-4,50,5,LEAVES:15)
Block(-3,50,5,LEAVES:15)
Block(-2,50,5,LEAVES:15)
Block(-3,50,6,LEAVES:15)
Block(1,51,-11,LEAVES:7)
Block(-2,51,-6,LOG:15)
Block(-3,51,-5,LEAVES:15)
Block(-2,51,-5,LOG:15)
Block(-4,51,-4,LEAVES:15)
Block(-2,51,-4,LOG:15)
Block(0,51,-4,LEAVES:7)
Block(2,51,-4,LEAVES:7)
Block(-5,51,-3,LEAVES:15)
Block(-3,51,-3,LOG:15)
Block(-1,51,-3,LEAVES:15)
Block(-4,51,-2,LEAVES:15)
Block(-3,51,-2,LOG:15)
Block(-2,51,-2,LEAVES:15)
Block(1,51,-2,LEAVES:15)
Block(-7,51,-1,LEAVES:7)
Block(-3,51,-1,LEAVES:15)
Block(-1,51,-1,LEAVES:15)
Block(-5,51,0,LEAVES:7)
Block(0,51,0,LEAVES:7)
Block(-4,51,1,LEAVES:7)
Block(-1,51,1,LEAVES:7)
Block(0,51,1,LEAVES:15)
Block(1,51,1,LEAVES:15)
Block(-6,51,2,LEAVES:15)
Block(-1,51,2,LEAVES:15)
Block(0,51,2,LEAVES:15)
Block(-4,51,3,LEAVES:15)
Block(-3,51,3,LEAVES:15)
Block(-2,51,3,LEAVES:7)
Block(-4,51,4,LEAVES:15)
Block(-3,51,4,LEAVES:7)
Block(-3,51,5,LEAVES:15)
Block(-2,52,-6,LEAVES:7)
Block(-1,52,-6,LEAVES:7)
Block(-3,52,-5,LEAVES:15)
Block(-2,52,-5,LEAVES:15)
Block(-1,52,-5,LOG:15)
Block(0,52,-5,LEAVES:7)
Block(1,52,-5,LEAVES:7)
Block(-3,52,-4,LEAVES:15)
Block(-2,52,-4,LEAVES:7)
Block(-1,52,-4,LEAVES:7)
Block(0,52,-4,LOG:15)
Block(1,52,-4,LEAVES:15)
Block(2,52,-4,LEAVES:15)
Block(-4,52,-3,LEAVES:15)
Block(-3,52,-3,LEAVES:15)
Block(-2,52,-3,LEAVES:15)
Block(-1,52,-3,LEAVES:15)
Block(0,52,-3,LEAVES:15)
Block(1,52,-3,LEAVES:15)
Block(-6,52,-2,LEAVES:15)
Block(-5,52,-2,LEAVES:15)
Block(-4,52,-2,LOG:15)
Block(-3,52,-2,LEAVES:15)
Block(-1,52,-2,LEAVES:15)
Block(0,52,-2,LEAVES:15)
Block(1,52,-2,LEAVES:15)
Block(-7,52,-1,LEAVES:7)
Block(-6,52,-1,LEAVES:15)
Block(-5,52,-1,LOG:15)
Block(-4,52,-1,LEAVES:7)
Block(0,52,-1,LEAVES:15)
Block(-6,52,0,LEAVES:7)
Block(-5,52,0,LEAVES:15)
Block(-4,52,0,LEAVES:7)
Block(-6,52,1,LEAVES:15)
Block(-5,52,1,LEAVES:15)
Block(-4,52,1,LEAVES:7)
Block(0,52,1,LEAVES:7)
Block(-5,52,2,LEAVES:15)
Block(-3,52,3,LEAVES:7)
Block(-1,53,-5,LEAVES:7)
Block(0,53,-4,LEAVES:7)
Block(1,53,-4,LEAVES:7)
Block(-4,53,-3,LEAVES:15)
Block(-3,53,-3,LEAVES:15)
Block(0,53,-3,LEAVES:15)
Block(1,53,-3,LEAVES:7)
Block(-5,53,-2,LEAVES:15)
Block(-4,53,-2,LEAVES:15)
Block(0,53,-2,LEAVES:15)
Block(-6,53,-1,LEAVES:7)
Block(-5,53,-1,LEAVES:7)
Block(-4,53,-1,LEAVES:7)
Block(-6,53,0,LEAVES:7)
Block(-5,53,0,LEAVES:15)
Block(-4,53,0,LEAVES:7)
Block(-5,53,1,LEAVES:15)
Block(0,54,-3,LEAVES:7)
Block(-4,54,-2,LEAVES:7)

#######################################################################
# +-----------------------------------------------------------------+ #
# |                            BO3 checks                           | #
# +-----------------------------------------------------------------+ #
#######################################################################

# Require a condition at a certain location in order for the BO3 to be spawned.
# BlockCheck(x,y,z,BlockName[,BlockName[,...]]) - one of the blocks must be at the location
# BlockCheckNot(x,y,z,BlockName[,BlockName[,...]]) - all the blocks must not be at the location
# LightCheck(x,y,z,minLightLevel,maxLightLevel) - light must be between min and max (inclusive)

# You can use "Solid" as a BlockName for matching all solid blocks or "All" to match all blocks that aren't air.

# Examples:
BlockCheck(0,-1,0,GRASS,DIRT,DIRT:2,STONE,CLAY,SAND:1,GRAVEL,SAND)
#   BlockCheck(0,-1,0,Solid)       Require any solid block just below the object
#   BlockCheck(0,-1,0,WOOL)        Require any type of wool just below the object
#   BlockCheck(0,-1,0,WOOL:0)      Require white wool just below the object
#   BlockCheckNot(0,-1,0,WOOL:0)   Require that there is no white wool below the object
#   LightCheck(0,0,0,0,1)          Require almost complete darkness just below the object

#######################################################################
# +-----------------------------------------------------------------+ #
# |                             Branches                            | #
# +-----------------------------------------------------------------+ #
#######################################################################

# Branches are objects that will spawn when this object spawns when it is used in
# the CustomStructure resource. Branches can also have branches, making complex
# structures possible. See the wiki for more details.

# Regular Branches spawn each branch with an independent chance of spawning.
# Branch(x,y,z,branchName,rotation,chance[,anotherBranchName,rotation,chance[,...]][IndividualChance])
# branchName - name of the object to spawn.
# rotation - NORTH, SOUTH, EAST or WEST.
# IndividualChance - The chance each branch has to spawn, assumed to be 100 when left blank

# Weighted Branches spawn branches with a dependent chance of spawning.
# WeightedBranch(x,y,z,branchName,rotation,chance[,anotherBranchName,rotation,chance[,...]][MaxChanceOutOf])
# MaxChanceOutOf - The chance all branches have to spawn out of, assumed to be 100 when left blank
