#######################################################################
# +-----------------------------------------------------------------+ #
# |                            BO3 object                           | #
# +-----------------------------------------------------------------+ #
#######################################################################

# This is the config file of a custom object.
# If you add this object correctly to your BiomeConfigs, it will spawn in the world.

# This is the creator of this BO3 object
Author: BO3 BulkEdit (by LanToaster)

# A short description of this BO3 object
Description: This Object was Created with BO3_BulkEdit

# The BO3 version, don't change this! It can be used by external applications to do a version check.
Version: 3

# The settings mode, WriteAll, WriteWithoutComments or WriteDisable. See WorldConfig.
SettingsMode: WriteDisable


#######################################################################
# +-----------------------------------------------------------------+ #
# |                          Main settings                          | #
# +-----------------------------------------------------------------+ #
#######################################################################

# This needs to be set to true to spawn the object in the Tree and Sapling resources.
Tree: true

# The frequency of the BO3 from 1 to 200. Tries this many times to spawn this BO3 when using the CustomObject(...) resource.
# Ignored by Tree(..), Sapling(..) and CustomStructure(..)
Frequency: 1

# The rarity of the BO3 from 0 to 100. Each spawn attempt has rarity% chance to succeed when using the CustomObject(...) resource.
# Ignored by Tree(..), Sapling(..) and CustomStructure(..)
Rarity: 100

# If you set this to true, the BO3 will be placed with a random rotation.
RotateRandomly: True

# The spawn height of the BO3 - randomY, highestBlock or highestSolidBlock.
SpawnHeight: highestSolidBlock
SpawnHeightOffset: -1
# The height limits for the BO3.
MinHeight: 59

MaxHeight: 200

# Objects can have other objects attacthed to it: branches. Branches can also
# have branches attached to it, which can also have branches, etc. This is the
# maximum branch depth for this objects.
MaxBranchDepth: 10

# When spawned with the UseWorld keyword, this BO3 should NOT spawn in the following biomes.
# If you writer.write the BO3 name directly in the BiomeConfigs, this will be ignored.
ExcludedBiomes: All


#######################################################################
# +-----------------------------------------------------------------+ #
# |                      Source block settings                      | #
# +-----------------------------------------------------------------+ #
#######################################################################

# The block(s) the BO3 should spawn in.
SourceBlocks: AIR, STATIONARY_WATER, FLOWING_WATER

# The maximum percentage of the BO3 that can be outside the SourceBlock.
# The BO3 won't be placed on a location with more blocks outside the SourceBlock than this percentage.
MaxPercentageOutsideSourceBlock: 10

# What to do when a block is about to be placed outside the SourceBlock? (dontPlace, placeAnyway)
OutsideSourceBlock: dontPlace


#######################################################################
# +-----------------------------------------------------------------+ #
# |                              Blocks                             | #
# +-----------------------------------------------------------------+ #
#######################################################################

# All the blocks used in the BO3 are listed here. Possible blocks:
# Block(x,y,z,id[.data][,nbtfile.nbt)
# RandomBlock(x,y,z,id[:data][,nbtfile.nbt],chance[,id[:data][,nbtfile.nbt],chance[,...]])
# So RandomBlock(0,0,0,CHEST,chest.nbt,50,CHEST,anotherchest.nbt,100) will spawn a chest at
# the BO3 origin, and give it a 50% chance to have the contents of chest.nbt, or, if that
# fails, a 100% percent chance to have the contents of anotherchest.nbt.

Block(1,0,-3,LOG:12)
Block(0,0,-2,LOG:12)
Block(1,0,-2,LOG:12)
Block(2,0,-2,LOG:12)
Block(-1,0,-1,LOG:12)
Block(0,0,-1,LOG:12)
Block(1,0,-1,LOG:12)
Block(2,0,-1,LOG:12)
Block(3,0,-1,LOG:12)
Block(0,0,0,LOG:12)
Block(1,0,0,LOG:12)
Block(2,0,0,LOG:12)
Block(1,0,1,LOG:12)
Block(1,1,-2,LOG:12)
Block(2,1,-2,LOG:12)
Block(0,1,-1,LOG:12)
Block(1,1,-1,LOG:12)
Block(2,1,-1,LOG:12)
Block(0,1,0,LOG:12)
Block(1,1,0,LOG:12)
Block(1,2,-2,LOG:12)
Block(0,2,-1,LOG:12)
Block(1,2,-1,LOG:12)
Block(1,2,0,LOG:12)
Block(1,3,-1,LOG:12)
Block(1,4,-1,LOG:12)
Block(1,5,-1,LOG:12)
Block(1,6,-1,LOG:12)
Block(1,7,-1,LOG:12)
Block(1,8,-1,LOG:12)
Block(1,9,-1,LOG:12)
Block(1,10,-1,LOG:12)
Block(1,11,-1,LOG:12)
Block(1,12,-1,LOG:12)
Block(1,13,-1,LOG:12)
Block(1,14,-1,LOG:12)
Block(1,15,-1,LOG:12)
Block(9,16,-2,LEAVES:12)
Block(10,16,-2,LEAVES:12)
Block(1,16,-1,LOG:12)
Block(2,16,-1,LOG:12)
Block(9,16,-1,LEAVES:12)
Block(9,16,0,LOG:12)
Block(10,16,0,LOG:12)
Block(8,17,-4,LEAVES:12)
Block(9,17,-4,LEAVES:12)
Block(8,17,-3,LEAVES:12)
Block(11,17,-3,LEAVES:12)
Block(8,17,-2,LEAVES:12)
Block(1,17,-1,LOG:12)
Block(3,17,-1,LOG:12)
Block(7,17,-1,LOG:12)
Block(8,17,-1,LOG:12)
Block(9,17,-1,LEAVES:12)
Block(6,17,2,LEAVES:12)
Block(7,17,2,LEAVES:12)
Block(7,17,3,LEAVES:12)
Block(8,17,3,LEAVES:12)
Block(4,18,-4,LEAVES:4)
Block(10,18,-4,LEAVES:12)
Block(4,18,-3,LEAVES:4)
Block(8,18,-3,LEAVES:12)
Block(9,18,-3,LEAVES:12)
Block(11,18,-3,LEAVES:12)
Block(0,18,-2,LOG:12)
Block(3,18,-2,LEAVES:4)
Block(4,18,-2,LEAVES:4)
Block(7,18,-2,LEAVES:12)
Block(8,18,-2,LEAVES:12)
Block(9,18,-2,LOG:12)
Block(10,18,-2,LEAVES:12)
Block(11,18,-2,LEAVES:12)
Block(4,18,-1,LOG:12)
Block(5,18,-1,LOG:12)
Block(6,18,-1,LOG:12)
Block(9,18,-1,LEAVES:12)
Block(5,18,0,LOG:12)
Block(8,18,0,LEAVES:12)
Block(9,18,0,LEAVES:12)
Block(10,18,0,LEAVES:12)
Block(5,18,1,LEAVES:12)
Block(8,18,1,LEAVES:12)
Block(5,18,2,LEAVES:12)
Block(6,18,2,LEAVES:12)
Block(7,18,2,LEAVES:12)
Block(8,18,2,LEAVES:12)
Block(7,18,3,LEAVES:12)
Block(7,18,4,LEAVES:12)
Block(8,18,4,LEAVES:12)
Block(2,19,-4,LEAVES:4)
Block(4,19,-4,LEAVES:4)
Block(10,19,-4,LEAVES:12)
Block(2,19,-3,LEAVES:4)
Block(5,19,-3,LEAVES:4)
Block(10,19,-3,LEAVES:12)
Block(0,19,-2,LOG:12)
Block(4,19,-2,LEAVES:4)
Block(5,19,-2,LOG:12)
Block(9,19,-2,LEAVES:12)
Block(5,19,-1,LEAVES:4)
Block(7,19,-1,LEAVES:12)
Block(10,19,-1,LEAVES:12)
Block(9,19,0,LEAVES:12)
Block(6,19,1,LOG:12)
Block(7,19,1,LEAVES:12)
Block(5,19,2,LEAVES:12)
Block(6,19,2,LEAVES:12)
Block(7,19,2,LOG:12)
Block(8,19,2,LEAVES:12)
Block(6,19,3,LEAVES:12)
Block(7,19,3,LEAVES:12)
Block(7,19,4,LEAVES:12)
Block(8,19,4,LEAVES:12)
Block(5,20,-5,LEAVES:4)
Block(4,20,-4,LEAVES:4)
Block(2,20,-3,LEAVES:4)
Block(3,20,-3,LEAVES:4)
Block(4,20,-3,LOG:12)
Block(5,20,-3,LEAVES:4)
Block(9,20,-3,LEAVES:12)
Block(10,20,-3,LEAVES:12)
Block(0,20,-2,LOG:12)
Block(6,20,-2,LEAVES:4)
Block(9,20,-2,LEAVES:12)
Block(10,20,-2,LEAVES:12)
Block(3,20,-1,LEAVES:4)
Block(4,20,-1,LEAVES:4)
Block(8,20,0,LEAVES:12)
Block(5,20,2,LEAVES:12)
Block(7,20,2,LEAVES:12)
Block(9,20,2,LEAVES:12)
Block(5,20,3,LEAVES:12)
Block(6,20,3,LEAVES:12)
Block(7,20,4,LEAVES:12)
Block(8,20,4,LEAVES:12)
Block(4,21,-5,LEAVES:4)
Block(5,21,-5,LEAVES:4)
Block(4,21,-4,LEAVES:4)
Block(4,21,-3,LEAVES:4)
Block(5,21,-3,LEAVES:4)
Block(0,21,-2,LOG:12)
Block(4,21,-2,LEAVES:4)
Block(6,21,-2,LEAVES:4)
Block(1,21,-1,LOG:12)
Block(6,21,1,LEAVES:12)
Block(7,21,1,LEAVES:12)
Block(7,21,2,LEAVES:12)
Block(7,21,3,LEAVES:12)
Block(3,22,-4,LEAVES:4)
Block(-1,22,-3,LOG:12)
Block(4,22,-3,LEAVES:4)
Block(5,22,-3,LEAVES:4)
Block(-1,22,-2,LEAVES:12)
Block(-1,22,-1,LOG:12)
Block(-2,22,0,LEAVES:12)
Block(2,22,0,LOG:12)
Block(-2,23,-4,LOG:12)
Block(-2,23,-3,LEAVES:12)
Block(-2,23,-2,LEAVES:12)
Block(-1,23,-1,LOG:12)
Block(0,23,-1,LEAVES:12)
Block(-3,23,0,LEAVES:12)
Block(0,23,0,LEAVES:12)
Block(3,23,0,LOG:12)
Block(-1,23,1,LEAVES:12)
Block(0,23,1,LEAVES:12)
Block(7,23,1,LEAVES:12)
Block(7,23,2,LEAVES:12)
Block(8,23,2,LEAVES:12)
Block(6,23,3,LEAVES:12)
Block(-4,24,-5,LOG:12)
Block(-3,24,-5,LOG:12)
Block(-6,24,-4,LEAVES:4)
Block(-5,24,-3,LEAVES:12)
Block(-4,24,-3,LEAVES:12)
Block(-2,24,-3,LEAVES:12)
Block(-1,24,-3,LEAVES:12)
Block(0,24,-3,LEAVES:12)
Block(-2,24,-2,LEAVES:12)
Block(-1,24,-2,LEAVES:12)
Block(-2,24,-1,LEAVES:12)
Block(-1,24,-1,LOG:12)
Block(0,24,-1,LEAVES:12)
Block(-2,24,0,LEAVES:12)
Block(-1,24,0,LEAVES:12)
Block(-1,24,1,LEAVES:12)
Block(3,24,1,LOG:12)
Block(5,24,1,LEAVES:12)
Block(6,24,1,LEAVES:12)
Block(7,24,1,LEAVES:12)
Block(6,24,2,LEAVES:12)
Block(7,24,2,LEAVES:12)
Block(6,24,3,LEAVES:4)
Block(9,24,3,LEAVES:4)
Block(7,24,4,LEAVES:4)
Block(8,24,4,LEAVES:4)
Block(-1,25,-8,LEAVES:12)
Block(-1,25,-7,LEAVES:12)
Block(0,25,-7,LEAVES:12)
Block(-3,25,-6,LOG:12)
Block(-2,25,-6,LEAVES:12)
Block(-1,25,-6,LEAVES:12)
Block(-4,25,-5,LEAVES:12)
Block(3,25,-5,LEAVES:12)
Block(-5,25,-4,LOG:12)
Block(3,25,-4,LEAVES:12)
Block(-6,25,-3,LEAVES:4)
Block(-4,25,-3,LEAVES:12)
Block(-2,25,-3,LEAVES:12)
Block(3,25,-3,LEAVES:12)
Block(-6,25,-2,LEAVES:4)
Block(-5,25,-2,LEAVES:12)
Block(-3,25,-2,LEAVES:12)
Block(-1,25,-2,LEAVES:12)
Block(0,25,-2,LEAVES:12)
Block(-6,25,-1,LEAVES:4)
Block(-4,25,-1,LEAVES:12)
Block(-3,25,-1,LEAVES:12)
Block(-1,25,-1,LEAVES:12)
Block(0,25,-1,LEAVES:12)
Block(1,25,-1,LEAVES:12)
Block(-3,25,0,LEAVES:12)
Block(-2,25,0,LOG:12)
Block(-1,25,0,LEAVES:12)
Block(0,25,0,LEAVES:12)
Block(6,25,0,LEAVES:12)
Block(7,25,0,LEAVES:12)
Block(8,25,0,LEAVES:4)
Block(-2,25,1,LEAVES:12)
Block(-1,25,1,LEAVES:12)
Block(1,25,1,LEAVES:12)
Block(4,25,1,LOG:12)
Block(5,25,1,LOG:12)
Block(7,25,1,LEAVES:4)
Block(9,25,1,LEAVES:4)
Block(-1,25,2,LEAVES:12)
Block(2,25,2,LOG:12)
Block(3,25,2,LEAVES:12)
Block(4,25,2,LEAVES:12)
Block(5,25,2,LEAVES:12)
Block(7,25,2,LOG:12)
Block(9,25,2,LEAVES:4)
Block(0,25,3,LEAVES:12)
Block(2,25,3,LEAVES:12)
Block(3,25,3,LEAVES:12)
Block(4,25,3,LEAVES:12)
Block(5,25,3,LEAVES:12)
Block(6,25,3,LEAVES:4)
Block(7,25,3,LEAVES:4)
Block(6,25,4,LEAVES:4)
Block(7,25,4,LEAVES:4)
Block(-1,26,-9,LEAVES:4)
Block(-2,26,-8,LEAVES:12)
Block(-2,26,-7,LOG:12)
Block(-1,26,-7,LEAVES:12)
Block(-3,26,-6,LEAVES:12)
Block(-1,26,-6,LEAVES:12)
Block(0,26,-6,LEAVES:12)
Block(2,26,-6,LEAVES:12)
Block(-5,26,-5,LEAVES:12)
Block(3,26,-5,LEAVES:12)
Block(5,26,-5,LEAVES:12)
Block(-5,26,-4,LEAVES:12)
Block(-4,26,-4,LEAVES:12)
Block(1,26,-4,LEAVES:12)
Block(2,26,-4,LEAVES:12)
Block(3,26,-4,LEAVES:12)
Block(-6,26,-3,LEAVES:4)
Block(-5,26,-3,LOG:12)
Block(-4,26,-3,LEAVES:12)
Block(-3,26,-3,LEAVES:12)
Block(5,26,-3,LEAVES:12)
Block(-5,26,-2,LEAVES:12)
Block(-3,26,-2,LEAVES:12)
Block(3,26,-2,LEAVES:12)
Block(-4,26,-1,LEAVES:12)
Block(-3,26,-1,LEAVES:12)
Block(-2,26,-1,LEAVES:12)
Block(7,26,-1,LEAVES:12)
Block(-5,26,0,LEAVES:12)
Block(-4,26,0,LEAVES:12)
Block(-2,26,0,LOG:12)
Block(1,26,0,LEAVES:12)
Block(5,26,0,LEAVES:12)
Block(6,26,0,LEAVES:12)
Block(8,26,0,LEAVES:4)
Block(9,26,0,LEAVES:4)
Block(-3,26,1,LEAVES:12)
Block(0,26,1,LEAVES:12)
Block(1,26,1,LEAVES:12)
Block(5,26,1,LEAVES:12)
Block(6,26,1,LOG:12)
Block(7,26,1,LEAVES:4)
Block(8,26,1,LEAVES:4)
Block(-1,26,2,LEAVES:12)
Block(1,26,2,LEAVES:12)
Block(2,26,2,LOG:12)
Block(5,26,2,LEAVES:12)
Block(6,26,2,LEAVES:4)
Block(7,26,2,LEAVES:4)
Block(8,26,2,LEAVES:4)
Block(9,26,2,LEAVES:4)
Block(-1,26,3,LEAVES:12)
Block(0,26,3,LEAVES:12)
Block(2,26,3,LEAVES:12)
Block(3,26,3,LEAVES:12)
Block(5,26,3,LEAVES:12)
Block(7,26,3,LEAVES:4)
Block(3,26,4,LEAVES:4)
Block(8,26,4,LEAVES:4)
Block(2,26,5,LEAVES:4)
Block(-1,27,-9,LEAVES:4)
Block(-2,27,-8,LEAVES:12)
Block(0,27,-8,LEAVES:12)
Block(1,27,-8,LEAVES:12)
Block(-3,27,-7,LEAVES:12)
Block(-2,27,-7,LEAVES:12)
Block(-1,27,-7,LOG:12)
Block(0,27,-7,LEAVES:12)
Block(-1,27,-6,LEAVES:12)
Block(0,27,-6,LEAVES:12)
Block(1,27,-6,LEAVES:12)
Block(3,27,-6,LEAVES:12)
Block(4,27,-6,LEAVES:12)
Block(-4,27,-5,LEAVES:4)
Block(-2,27,-5,LEAVES:12)
Block(-1,27,-5,LEAVES:12)
Block(1,27,-5,LEAVES:4)
Block(2,27,-5,LEAVES:12)
Block(5,27,-5,LEAVES:12)
Block(-7,27,-4,LEAVES:4)
Block(-5,27,-4,LEAVES:4)
Block(0,27,-4,LEAVES:4)
Block(1,27,-4,LEAVES:12)
Block(3,27,-4,LEAVES:4)
Block(5,27,-4,LEAVES:12)
Block(-7,27,-3,LEAVES:4)
Block(-1,27,-3,LEAVES:4)
Block(0,27,-3,LEAVES:4)
Block(4,27,-3,LEAVES:12)
Block(-6,27,-2,LEAVES:4)
Block(-4,27,-2,LEAVES:4)
Block(-3,27,-2,LEAVES:12)
Block(0,27,-2,LEAVES:4)
Block(2,27,-2,LEAVES:12)
Block(7,27,-2,LEAVES:12)
Block(8,27,-2,LEAVES:4)
Block(-5,27,-1,LEAVES:4)
Block(-3,27,-1,LEAVES:12)
Block(6,27,-1,LEAVES:12)
Block(7,27,-1,LEAVES:12)
Block(8,27,-1,LEAVES:4)
Block(9,27,-1,LEAVES:4)
Block(-5,27,0,LEAVES:4)
Block(-4,27,0,LEAVES:4)
Block(-3,27,0,LOG:12)
Block(-2,27,0,LEAVES:12)
Block(-1,27,0,LEAVES:12)
Block(1,27,0,LEAVES:12)
Block(5,27,0,LEAVES:12)
Block(6,27,0,LEAVES:12)
Block(7,27,0,LOG:12)
Block(-5,27,1,LEAVES:4)
Block(-3,27,1,LEAVES:12)
Block(-2,27,1,LEAVES:12)
Block(-1,27,1,LOG:12)
Block(0,27,1,LEAVES:12)
Block(1,27,1,LEAVES:12)
Block(3,27,1,LEAVES:12)
Block(4,27,1,LEAVES:12)
Block(9,27,1,LEAVES:4)
Block(-4,27,2,LEAVES:4)
Block(-3,27,2,LEAVES:12)
Block(-2,27,2,LEAVES:12)
Block(0,27,2,LEAVES:12)
Block(1,27,2,LOG:12)
Block(2,27,2,LEAVES:12)
Block(3,27,2,LEAVES:12)
Block(6,27,2,LEAVES:4)
Block(7,27,2,LEAVES:4)
Block(-1,27,3,LEAVES:12)
Block(1,27,3,LEAVES:12)
Block(3,27,3,LOG:12)
Block(4,27,3,LEAVES:12)
Block(5,27,3,LEAVES:12)
Block(7,27,3,LEAVES:4)
Block(1,27,4,LEAVES:4)
Block(2,27,4,LEAVES:4)
Block(3,27,4,LEAVES:4)
Block(4,27,4,LEAVES:4)
Block(5,27,4,LEAVES:4)
Block(3,27,5,LEAVES:4)
Block(0,28,-9,LEAVES:4)
Block(-3,28,-8,LEAVES:12)
Block(-2,28,-7,LEAVES:12)
Block(-2,28,-6,LEAVES:12)
Block(1,28,-6,LEAVES:4)
Block(3,28,-6,LEAVES:12)
Block(-1,28,-5,LEAVES:4)
Block(1,28,-5,LEAVES:12)
Block(-6,28,-4,LEAVES:4)
Block(-5,28,-4,LEAVES:4)
Block(-4,28,-4,LEAVES:4)
Block(0,28,-4,LEAVES:4)
Block(1,28,-4,LEAVES:12)
Block(2,28,-4,LEAVES:4)
Block(3,28,-4,LEAVES:12)
Block(4,28,-4,LEAVES:12)
Block(-5,28,-3,LEAVES:4)
Block(-4,28,-3,LEAVES:4)
Block(3,28,-3,LEAVES:12)
Block(4,28,-3,LEAVES:12)
Block(5,28,-3,LEAVES:12)
Block(-4,28,-2,LEAVES:4)
Block(-3,28,-2,LEAVES:12)
Block(0,28,-2,LEAVES:4)
Block(6,28,-2,LEAVES:12)
Block(-5,28,-1,LEAVES:4)
Block(-4,28,-1,LEAVES:4)
Block(-3,28,-1,LEAVES:12)
Block(-2,28,-1,LEAVES:12)
Block(5,28,-1,LEAVES:12)
Block(9,28,-1,LEAVES:4)
Block(-5,28,0,LEAVES:4)
Block(-4,28,0,LOG:12)
Block(-3,28,0,LEAVES:12)
Block(-2,28,0,LEAVES:12)
Block(1,28,0,LEAVES:12)
Block(5,28,0,LEAVES:12)
Block(7,28,0,LEAVES:12)
Block(-6,28,1,LEAVES:4)
Block(-5,28,1,LEAVES:4)
Block(-4,28,1,LEAVES:4)
Block(-3,28,1,LEAVES:12)
Block(0,28,1,LEAVES:12)
Block(8,28,1,LEAVES:4)
Block(-4,28,2,LEAVES:4)
Block(-3,28,2,LEAVES:12)
Block(-1,28,2,LEAVES:12)
Block(1,28,2,LEAVES:12)
Block(2,28,2,LEAVES:12)
Block(4,28,2,LEAVES:12)
Block(5,28,2,LEAVES:12)
Block(-2,28,3,LEAVES:12)
Block(1,28,3,LEAVES:12)
Block(2,28,3,LEAVES:12)
Block(3,28,3,LEAVES:12)
Block(1,28,4,LEAVES:4)
Block(2,28,4,LEAVES:4)
Block(5,28,4,LEAVES:4)
Block(3,28,5,LEAVES:4)
Block(-2,29,-7,LEAVES:12)
Block(-1,29,-7,LEAVES:12)
Block(0,29,-7,LEAVES:12)
Block(-1,29,-6,LEAVES:12)
Block(0,29,-5,LEAVES:4)
Block(4,29,-5,LEAVES:12)
Block(1,29,-4,LEAVES:4)
Block(2,29,-4,LEAVES:12)
Block(3,29,-4,LEAVES:12)
Block(1,29,-3,LEAVES:4)
Block(2,29,-3,LEAVES:12)
Block(4,29,-3,LEAVES:12)
Block(1,29,-2,LEAVES:4)
Block(2,29,-2,LEAVES:4)
Block(6,29,-1,LEAVES:12)
Block(7,29,-1,LEAVES:12)
Block(-5,29,0,LEAVES:4)
Block(-4,29,0,LEAVES:4)
Block(-1,29,0,LEAVES:12)
Block(6,29,0,LEAVES:12)
Block(7,29,0,LEAVES:12)
Block(8,29,0,LEAVES:4)
Block(-6,29,1,LEAVES:4)
Block(-2,29,1,LEAVES:12)
Block(-1,29,1,LEAVES:12)
Block(0,29,1,LEAVES:12)
Block(1,29,1,LEAVES:12)
Block(2,29,1,LEAVES:12)
Block(6,29,1,LEAVES:4)
Block(7,29,1,LEAVES:4)
Block(1,29,2,LEAVES:12)
Block(4,29,2,LEAVES:12)
Block(1,29,3,LEAVES:12)
Block(3,29,3,LEAVES:12)
Block(3,29,4,LEAVES:4)
Block(0,30,-5,LEAVES:4)
Block(1,30,-5,LEAVES:4)
Block(1,30,-4,LEAVES:4)
Block(2,30,-4,LEAVES:4)
Block(1,30,-3,LEAVES:4)
Block(-4,30,-1,LEAVES:4)
Block(-4,30,0,LEAVES:4)
Block(-3,30,0,LEAVES:12)

#######################################################################
# +-----------------------------------------------------------------+ #
# |                            BO3 checks                           | #
# +-----------------------------------------------------------------+ #
#######################################################################

# Require a condition at a certain location in order for the BO3 to be spawned.
# BlockCheck(x,y,z,BlockName[,BlockName[,...]]) - one of the blocks must be at the location
# BlockCheckNot(x,y,z,BlockName[,BlockName[,...]]) - all the blocks must not be at the location
# LightCheck(x,y,z,minLightLevel,maxLightLevel) - light must be between min and max (inclusive)

# You can use "Solid" as a BlockName for matching all solid blocks or "All" to match all blocks that aren't air.

# Examples:
BlockCheck(0,-1,0,GRASS,DIRT,DIRT:2,SAND,CLAY)
#   BlockCheck(0,-1,0,Solid)       Require any solid block just below the object
#   BlockCheck(0,-1,0,WOOL)        Require any type of wool just below the object
#   BlockCheck(0,-1,0,WOOL:0)      Require white wool just below the object
#   BlockCheckNot(0,-1,0,WOOL:0)   Require that there is no white wool below the object
#   LightCheck(0,0,0,0,1)          Require almost complete darkness just below the object

#######################################################################
# +-----------------------------------------------------------------+ #
# |                             Branches                            | #
# +-----------------------------------------------------------------+ #
#######################################################################

# Branches are objects that will spawn when this object spawns when it is used in
# the CustomStructure resource. Branches can also have branches, making complex
# structures possible. See the wiki for more details.

# Regular Branches spawn each branch with an independent chance of spawning.
# Branch(x,y,z,branchName,rotation,chance[,anotherBranchName,rotation,chance[,...]][IndividualChance])
# branchName - name of the object to spawn.
# rotation - NORTH, SOUTH, EAST or WEST.
# IndividualChance - The chance each branch has to spawn, assumed to be 100 when left blank

# Weighted Branches spawn branches with a dependent chance of spawning.
# WeightedBranch(x,y,z,branchName,rotation,chance[,anotherBranchName,rotation,chance[,...]][MaxChanceOutOf])
# MaxChanceOutOf - The chance all branches have to spawn out of, assumed to be 100 when left blank

