#######################################################################
# +-----------------------------------------------------------------+ #
# |                            BO3 object                           | #
# +-----------------------------------------------------------------+ #
#######################################################################

# This is the config file of a custom object.
# If you add this object correctly to your BiomeConfigs, it will spawn in the world.

# This is the creator of this BO3 object
Author: BO3 BulkEdit (by LanToaster)

# A short description of this BO3 object
Description: This Object was Created with BO3_BulkEdit

# The BO3 version, don't change this! It can be used by external applications to do a version check.
Version: 3

# The settings mode, WriteAll, WriteWithoutComments or WriteDisable. See WorldConfig.
SettingsMode: WriteDisable


#######################################################################
# +-----------------------------------------------------------------+ #
# |                          Main settings                          | #
# +-----------------------------------------------------------------+ #
#######################################################################

# This needs to be set to true to spawn the object in the Tree and Sapling resources.
Tree: true

# The frequency of the BO3 from 1 to 200. Tries this many times to spawn this BO3 when using the CustomObject(...) resource.
# Ignored by Tree(..), Sapling(..) and CustomStructure(..)
Frequency: 1

# The rarity of the BO3 from 0 to 100. Each spawn attempt has rarity% chance to succeed when using the CustomObject(...) resource.
# Ignored by Tree(..), Sapling(..) and CustomStructure(..)
Rarity: 100.0

# If you set this to true, the BO3 will be placed with a random rotation.
RotateRandomly: true

# The spawn height of the BO3 - randomY, highestBlock or highestSolidBlock.
SpawnHeight: highestSolidBlock
SpawnHeightOffset: -8
# The height limits for the BO3.
MinHeight: 0

MaxHeight: 256

# Objects can have other objects attacthed to it: branches. Branches can also
# have branches attached to it, which can also have branches, etc. This is the
# maximum branch depth for this objects.
MaxBranchDepth: 10

# When spawned with the UseWorld keyword, this BO3 should NOT spawn in the following biomes.
# If you writer.write the BO3 name directly in the BiomeConfigs, this will be ignored.
ExcludedBiomes: All


#######################################################################
# +-----------------------------------------------------------------+ #
# |                      Source block settings                      | #
# +-----------------------------------------------------------------+ #
#######################################################################

# The block(s) the BO3 should spawn in.
SourceBlocks: AIR,GRASS,DIRT,STONE,SAND,GRAVEL,CLAY,STATIONARY_WATER,FLOWING_WATER,LEAVES:0,252:8,251:8

# The maximum percentage of the BO3 that can be outside the SourceBlock.
# The BO3 won't be placed on a location with more blocks outside the SourceBlock than this percentage.
MaxPercentageOutsideSourceBlock: 0

# What to do when a block is about to be placed outside the SourceBlock? (dontPlace, placeAnyway)
OutsideSourceBlock: dontPlace


#######################################################################
# +-----------------------------------------------------------------+ #
# |                              Blocks                             | #
# +-----------------------------------------------------------------+ #
#######################################################################

# All the blocks used in the BO3 are listed here. Possible blocks:
# Block(x,y,z,id[.data][,nbtfile.nbt)
# RandomBlock(x,y,z,id[:data][,nbtfile.nbt],chance[,id[:data][,nbtfile.nbt],chance[,...]])
# So RandomBlock(0,0,0,CHEST,chest.nbt,50,CHEST,anotherchest.nbt,100) will spawn a chest at
# the BO3 origin, and give it a 50% chance to have the contents of chest.nbt, or, if that
# fails, a 100% percent chance to have the contents of anotherchest.nbt.
Block(-1,1,-4,STONE)
Block(0,1,-4,STONE)
Block(-1,1,-3,STONE:5)
Block(0,1,-3,STONE)
Block(2,1,-3,LEAVES:0)
Block(3,1,-3,LEAVES:0)
Block(-2,1,-2,LEAVES:0)
Block(-1,1,-2,LEAVES:0)
Block(0,1,-2,MOSSY_COBBLESTONE)
Block(2,1,-2,LEAVES:0)
Block(5,1,-2,LEAVES:12)
Block(2,1,-1,LEAVES:0)
Block(3,1,-1,LEAVES:0)
Block(4,1,-1,LEAVES:12)
Block(2,1,0,LEAVES:0)
Block(0,1,1,LEAVES:0)
Block(1,1,1,LEAVES:0)
Block(2,1,1,LEAVES:0)
Block(0,1,2,LEAVES:0)
Block(2,1,2,LEAVES:0)
Block(0,1,3,LEAVES:0)
Block(3,1,3,LEAVES:12)
Block(0,2,-7,MOSSY_COBBLESTONE)
Block(1,2,-7,STONE)
Block(2,2,-7,MOSSY_COBBLESTONE)
Block(0,2,-6,STONE)
Block(1,2,-6,STONE)
Block(2,2,-6,STONE)
Block(3,2,-6,STONE)
Block(-1,2,-5,STONE)
Block(0,2,-5,STONE:5)
Block(1,2,-5,STONE:5)
Block(2,2,-5,STONE:5)
Block(3,2,-5,STONE)
Block(4,2,-5,STONE)
Block(-2,2,-4,STONE)
Block(-1,2,-4,GRAVEL:0)
Block(0,2,-4,STONE:5)
Block(1,2,-4,STONE:5)
Block(2,2,-4,STONE)
Block(3,2,-4,STONE)
Block(4,2,-4,STONE)
Block(-3,2,-3,LEAVES:0)
Block(-2,2,-3,STONE)
Block(-1,2,-3,STONE:5)
Block(0,2,-3,STONE:5)
Block(1,2,-3,STONE:5)
Block(2,2,-3,STONE:5)
Block(3,2,-3,MOSSY_COBBLESTONE)
Block(4,2,-3,MOSSY_COBBLESTONE)
Block(5,2,-3,STONE)
Block(6,2,-3,LEAVES:0)
Block(-3,2,-2,MOSSY_COBBLESTONE)
Block(-2,2,-2,STONE)
Block(-1,2,-2,STONE)
Block(0,2,-2,MOSSY_COBBLESTONE)
Block(1,2,-2,GRAVEL:0)
Block(2,2,-2,STONE)
Block(3,2,-2,STONE)
Block(4,2,-2,STONE)
Block(5,2,-2,MOSSY_COBBLESTONE)
Block(-3,2,-1,MOSSY_COBBLESTONE)
Block(-2,2,-1,MOSSY_COBBLESTONE)
Block(-1,2,-1,MOSSY_COBBLESTONE)
Block(0,2,-1,STONE)
Block(1,2,-1,STONE)
Block(2,2,-1,STONE)
Block(3,2,-1,STONE)
Block(4,2,-1,STONE)
Block(5,2,-1,STONE)
Block(6,2,-1,MOSSY_COBBLESTONE)
Block(-3,2,0,STONE)
Block(-2,2,0,STONE)
Block(-1,2,0,STONE)
Block(0,2,0,STONE)
Block(1,2,0,STONE)
Block(2,2,0,STONE)
Block(3,2,0,STONE)
Block(4,2,0,STONE)
Block(5,2,0,STONE)
Block(6,2,0,STONE)
Block(-2,2,1,STONE)
Block(-1,2,1,STONE)
Block(0,2,1,STONE)
Block(1,2,1,STONE)
Block(2,2,1,STONE)
Block(3,2,1,STONE)
Block(4,2,1,MOSSY_COBBLESTONE)
Block(5,2,1,STONE)
Block(-1,2,2,STONE)
Block(0,2,2,STONE)
Block(1,2,2,STONE)
Block(2,2,2,STONE)
Block(3,2,2,STONE)
Block(4,2,2,STONE)
Block(-1,2,3,STONE)
Block(0,2,3,STONE)
Block(1,2,3,MOSSY_COBBLESTONE)
Block(2,2,3,STONE)
Block(3,2,3,STONE)
Block(4,2,3,LEAVES:12)
Block(0,2,4,STONE)
Block(1,2,4,STONE)
Block(2,2,4,STONE)
Block(0,2,5,STONE)
Block(1,2,5,STONE)
Block(0,3,-8,STONE)
Block(1,3,-8,MOSSY_COBBLESTONE)
Block(2,3,-8,STONE)
Block(-1,3,-7,MOSSY_COBBLESTONE)
Block(0,3,-7,STONE)
Block(1,3,-7,STONE)
Block(2,3,-7,MOSSY_COBBLESTONE)
Block(-1,3,-6,STONE)
Block(0,3,-6,STONE)
Block(1,3,-6,STONE)
Block(2,3,-6,STONE)
Block(3,3,-6,STONE)
Block(-1,3,-5,STONE)
Block(0,3,-5,STONE:5)
Block(1,3,-5,STONE:5)
Block(2,3,-5,STONE:5)
Block(3,3,-5,STONE)
Block(4,3,-5,STONE)
Block(-3,3,-4,LEAVES:12)
Block(-2,3,-4,MOSSY_COBBLESTONE)
Block(-1,3,-4,STONE)
Block(0,3,-4,STONE:5)
Block(1,3,-4,STONE:5)
Block(2,3,-4,STONE)
Block(3,3,-4,STONE)
Block(4,3,-4,STONE)
Block(5,3,-4,MOSSY_COBBLESTONE)
Block(-3,3,-3,STONE)
Block(-2,3,-3,STONE)
Block(-1,3,-3,STONE:5)
Block(0,3,-3,STONE:5)
Block(1,3,-3,STONE:5)
Block(2,3,-3,STONE:5)
Block(3,3,-3,MOSSY_COBBLESTONE)
Block(4,3,-3,MOSSY_COBBLESTONE)
Block(5,3,-3,STONE)
Block(-3,3,-2,MOSSY_COBBLESTONE)
Block(-2,3,-2,STONE)
Block(-1,3,-2,STONE)
Block(0,3,-2,MOSSY_COBBLESTONE)
Block(1,3,-2,GRAVEL:0)
Block(2,3,-2,STONE)
Block(3,3,-2,STONE)
Block(4,3,-2,STONE)
Block(5,3,-2,MOSSY_COBBLESTONE)
Block(6,3,-2,STONE)
Block(-3,3,-1,STONE)
Block(-2,3,-1,MOSSY_COBBLESTONE)
Block(-1,3,-1,MOSSY_COBBLESTONE)
Block(0,3,-1,STONE)
Block(1,3,-1,STONE)
Block(2,3,-1,STONE)
Block(3,3,-1,STONE)
Block(4,3,-1,STONE)
Block(5,3,-1,STONE)
Block(6,3,-1,STONE)
Block(7,3,-1,STONE)
Block(-3,3,0,STONE)
Block(-2,3,0,STONE)
Block(-1,3,0,STONE)
Block(0,3,0,STONE)
Block(1,3,0,STONE)
Block(2,3,0,STONE)
Block(3,3,0,STONE)
Block(4,3,0,STONE)
Block(5,3,0,STONE)
Block(6,3,0,STONE)
Block(-3,3,1,STONE)
Block(-2,3,1,STONE)
Block(-1,3,1,STONE)
Block(0,3,1,STONE)
Block(1,3,1,STONE)
Block(2,3,1,STONE)
Block(3,3,1,STONE)
Block(4,3,1,STONE)
Block(5,3,1,STONE)
Block(-2,3,2,STONE)
Block(-1,3,2,STONE)
Block(0,3,2,STONE)
Block(1,3,2,STONE)
Block(2,3,2,STONE)
Block(3,3,2,STONE)
Block(4,3,2,STONE)
Block(-2,3,3,STONE)
Block(-1,3,3,STONE)
Block(0,3,3,STONE)
Block(1,3,3,MOSSY_COBBLESTONE)
Block(2,3,3,STONE)
Block(3,3,3,STONE)
Block(4,3,3,LEAVES:0)
Block(-1,3,4,STONE)
Block(0,3,4,STONE)
Block(1,3,4,MOSSY_COBBLESTONE)
Block(2,3,4,STONE)
Block(-1,3,5,LEAVES:0)
Block(0,3,5,MOSSY_COBBLESTONE)
Block(1,3,5,MOSSY_COBBLESTONE)
Block(-1,4,-8,STONE)
Block(0,4,-8,STONE)
Block(1,4,-8,STONE)
Block(2,4,-8,STONE)
Block(-1,4,-7,STONE)
Block(0,4,-7,STONE)
Block(1,4,-7,STONE)
Block(2,4,-7,MOSSY_COBBLESTONE)
Block(3,4,-7,STONE)
Block(-1,4,-6,STONE)
Block(0,4,-6,STONE)
Block(1,4,-6,STONE)
Block(2,4,-6,STONE)
Block(3,4,-6,MOSSY_COBBLESTONE)
Block(4,4,-6,STONE)
Block(-1,4,-5,STONE)
Block(0,4,-5,STONE:5)
Block(1,4,-5,STONE:5)
Block(2,4,-5,STONE:5)
Block(3,4,-5,STONE)
Block(4,4,-5,STONE)
Block(5,4,-5,STONE)
Block(-3,4,-4,LEAVES:12)
Block(-2,4,-4,MOSSY_COBBLESTONE)
Block(-1,4,-4,STONE)
Block(0,4,-4,STONE:5)
Block(1,4,-4,STONE:5)
Block(2,4,-4,STONE)
Block(3,4,-4,STONE)
Block(4,4,-4,STONE)
Block(5,4,-4,MOSSY_COBBLESTONE)
Block(-4,4,-3,STONE)
Block(-3,4,-3,STONE)
Block(-2,4,-3,STONE)
Block(-1,4,-3,STONE:5)
Block(0,4,-3,STONE:5)
Block(1,4,-3,STONE:5)
Block(2,4,-3,STONE:5)
Block(3,4,-3,MOSSY_COBBLESTONE)
Block(4,4,-3,MOSSY_COBBLESTONE)
Block(5,4,-3,MOSSY_COBBLESTONE)
Block(6,4,-3,MOSSY_COBBLESTONE)
Block(-4,4,-2,MOSSY_COBBLESTONE)
Block(-3,4,-2,STONE)
Block(-2,4,-2,STONE)
Block(-1,4,-2,STONE)
Block(0,4,-2,MOSSY_COBBLESTONE)
Block(1,4,-2,GRAVEL:0)
Block(2,4,-2,STONE)
Block(3,4,-2,STONE)
Block(4,4,-2,STONE)
Block(5,4,-2,MOSSY_COBBLESTONE)
Block(6,4,-2,MOSSY_COBBLESTONE)
Block(7,4,-2,MOSSY_COBBLESTONE)
Block(-4,4,-1,STONE:5)
Block(-3,4,-1,STONE)
Block(-2,4,-1,MOSSY_COBBLESTONE)
Block(-1,4,-1,MOSSY_COBBLESTONE)
Block(0,4,-1,STONE)
Block(1,4,-1,STONE)
Block(2,4,-1,STONE)
Block(3,4,-1,STONE)
Block(4,4,-1,STONE)
Block(5,4,-1,STONE)
Block(6,4,-1,MOSSY_COBBLESTONE)
Block(7,4,-1,STONE:5)
Block(-3,4,0,STONE)
Block(-2,4,0,STONE)
Block(-1,4,0,STONE)
Block(0,4,0,STONE)
Block(1,4,0,STONE)
Block(2,4,0,STONE)
Block(3,4,0,STONE)
Block(4,4,0,STONE)
Block(5,4,0,MOSSY_COBBLESTONE)
Block(6,4,0,STONE)
Block(-3,4,1,MOSSY_COBBLESTONE)
Block(-2,4,1,STONE)
Block(-1,4,1,STONE)
Block(0,4,1,STONE)
Block(1,4,1,STONE)
Block(2,4,1,STONE)
Block(3,4,1,STONE)
Block(4,4,1,STONE)
Block(5,4,1,MOSSY_COBBLESTONE)
Block(-3,4,2,STONE)
Block(-2,4,2,STONE)
Block(-1,4,2,STONE)
Block(0,4,2,STONE)
Block(1,4,2,STONE)
Block(2,4,2,STONE)
Block(3,4,2,STONE)
Block(4,4,2,STONE)
Block(-2,4,3,STONE)
Block(-1,4,3,STONE)
Block(0,4,3,STONE)
Block(1,4,3,MOSSY_COBBLESTONE)
Block(2,4,3,STONE)
Block(3,4,3,MOSSY_COBBLESTONE)
Block(4,4,3,STONE)
Block(-2,4,4,STONE)
Block(-1,4,4,STONE)
Block(0,4,4,STONE)
Block(1,4,4,STONE)
Block(2,4,4,MOSSY_COBBLESTONE)
Block(3,4,4,STONE)
Block(-2,4,5,LEAVES:0)
Block(-1,4,5,STONE)
Block(0,4,5,STONE)
Block(1,4,5,STONE)
Block(0,4,6,STONE)
Block(-1,5,-8,MOSSY_COBBLESTONE)
Block(0,5,-8,STONE)
Block(1,5,-8,STONE)
Block(2,5,-8,MOSSY_COBBLESTONE)
Block(-1,5,-7,STONE)
Block(0,5,-7,STONE)
Block(1,5,-7,STONE)
Block(2,5,-7,MOSSY_COBBLESTONE)
Block(3,5,-7,STONE)
Block(-1,5,-6,STONE)
Block(0,5,-6,STONE)
Block(1,5,-6,STONE)
Block(2,5,-6,STONE)
Block(3,5,-6,MOSSY_COBBLESTONE)
Block(4,5,-6,STONE)
Block(-2,5,-5,LEAVES:0)
Block(-1,5,-5,STONE)
Block(0,5,-5,STONE:5)
Block(1,5,-5,STONE:5)
Block(2,5,-5,STONE:5)
Block(3,5,-5,STONE)
Block(4,5,-5,STONE)
Block(5,5,-5,STONE)
Block(-3,5,-4,LEAVES:12)
Block(-2,5,-4,STONE)
Block(-1,5,-4,STONE:5)
Block(0,5,-4,STONE:5)
Block(1,5,-4,STONE:5)
Block(2,5,-4,STONE)
Block(3,5,-4,STONE)
Block(4,5,-4,STONE)
Block(5,5,-4,STONE)
Block(6,5,-4,STONE)
Block(-4,5,-3,STONE)
Block(-3,5,-3,STONE)
Block(-2,5,-3,STONE)
Block(-1,5,-3,STONE:5)
Block(0,5,-3,STONE:5)
Block(1,5,-3,STONE:5)
Block(2,5,-3,STONE:5)
Block(3,5,-3,MOSSY_COBBLESTONE)
Block(4,5,-3,MOSSY_COBBLESTONE)
Block(5,5,-3,STONE)
Block(6,5,-3,MOSSY_COBBLESTONE)
Block(7,5,-3,STONE)
Block(-4,5,-2,MOSSY_COBBLESTONE)
Block(-3,5,-2,STONE)
Block(-2,5,-2,STONE)
Block(-1,5,-2,STONE)
Block(0,5,-2,MOSSY_COBBLESTONE)
Block(1,5,-2,GRAVEL:0)
Block(2,5,-2,STONE)
Block(3,5,-2,STONE)
Block(4,5,-2,STONE)
Block(5,5,-2,MOSSY_COBBLESTONE)
Block(6,5,-2,MOSSY_COBBLESTONE)
Block(7,5,-2,MOSSY_COBBLESTONE)
Block(-4,5,-1,STONE)
Block(-3,5,-1,STONE)
Block(-2,5,-1,STONE)
Block(-1,5,-1,MOSSY_COBBLESTONE)
Block(0,5,-1,STONE)
Block(1,5,-1,STONE)
Block(2,5,-1,STONE)
Block(3,5,-1,STONE)
Block(4,5,-1,STONE)
Block(5,5,-1,STONE)
Block(6,5,-1,MOSSY_COBBLESTONE)
Block(7,5,-1,STONE)
Block(-4,5,0,STONE)
Block(-3,5,0,STONE)
Block(-2,5,0,STONE)
Block(-1,5,0,STONE)
Block(0,5,0,STONE)
Block(1,5,0,STONE)
Block(2,5,0,STONE)
Block(3,5,0,STONE)
Block(4,5,0,STONE)
Block(5,5,0,STONE)
Block(6,5,0,MOSSY_COBBLESTONE)
Block(7,5,0,STONE)
Block(-4,5,1,MOSSY_COBBLESTONE)
Block(-3,5,1,STONE)
Block(-2,5,1,STONE)
Block(-1,5,1,STONE)
Block(0,5,1,STONE)
Block(1,5,1,STONE)
Block(2,5,1,STONE)
Block(3,5,1,STONE)
Block(4,5,1,STONE)
Block(5,5,1,STONE)
Block(6,5,1,MOSSY_COBBLESTONE)
Block(-3,5,2,STONE)
Block(-2,5,2,STONE)
Block(-1,5,2,STONE:5)
Block(0,5,2,STONE)
Block(1,5,2,STONE)
Block(2,5,2,STONE)
Block(3,5,2,STONE)
Block(4,5,2,STONE)
Block(5,5,2,STONE)
Block(-3,5,3,STONE)
Block(-2,5,3,STONE)
Block(-1,5,3,STONE:5)
Block(0,5,3,STONE)
Block(1,5,3,MOSSY_COBBLESTONE)
Block(2,5,3,STONE)
Block(3,5,3,MOSSY_COBBLESTONE)
Block(4,5,3,STONE)
Block(-3,5,4,STONE)
Block(-2,5,4,STONE)
Block(-1,5,4,STONE:5)
Block(0,5,4,STONE)
Block(1,5,4,STONE)
Block(2,5,4,MOSSY_COBBLESTONE)
Block(3,5,4,STONE)
Block(4,5,4,LEAVES:0)
Block(-3,5,5,LEAVES:0)
Block(-2,5,5,STONE)
Block(-1,5,5,STONE:5)
Block(0,5,5,STONE)
Block(1,5,5,STONE)
Block(2,5,5,STONE)
Block(-2,5,6,LEAVES:0)
Block(-1,5,6,STONE:5)
Block(0,5,6,STONE)
Block(0,6,-8,MOSSY_COBBLESTONE)
Block(1,6,-8,STONE)
Block(2,6,-8,MOSSY_COBBLESTONE)
Block(3,6,-8,MOSSY_COBBLESTONE)
Block(-1,6,-7,STONE)
Block(0,6,-7,STONE)
Block(1,6,-7,STONE)
Block(2,6,-7,MOSSY_COBBLESTONE)
Block(3,6,-7,MOSSY_COBBLESTONE)
Block(4,6,-7,STONE)
Block(-1,6,-6,STONE)
Block(0,6,-6,STONE)
Block(1,6,-6,STONE)
Block(2,6,-6,MOSSY_COBBLESTONE)
Block(3,6,-6,MOSSY_COBBLESTONE)
Block(4,6,-6,MOSSY_COBBLESTONE)
Block(5,6,-6,STONE)
Block(-3,6,-5,LEAVES:12)
Block(-2,6,-5,STONE)
Block(-1,6,-5,MOSSY_COBBLESTONE)
Block(0,6,-5,STONE)
Block(1,6,-5,STONE:5)
Block(2,6,-5,STONE:5)
Block(3,6,-5,STONE)
Block(4,6,-5,MOSSY_COBBLESTONE)
Block(5,6,-5,STONE)
Block(-3,6,-4,STONE)
Block(-2,6,-4,STONE)
Block(-1,6,-4,MOSSY_COBBLESTONE)
Block(0,6,-4,STONE:5)
Block(1,6,-4,STONE:5)
Block(2,6,-4,STONE)
Block(3,6,-4,STONE)
Block(4,6,-4,STONE)
Block(5,6,-4,STONE)
Block(6,6,-4,STONE)
Block(7,6,-4,LEAVES:0)
Block(-5,6,-3,LEAVES:12)
Block(-4,6,-3,STONE)
Block(-3,6,-3,STONE)
Block(-2,6,-3,STONE)
Block(-1,6,-3,MOSSY_COBBLESTONE)
Block(0,6,-3,STONE:5)
Block(1,6,-3,STONE:5)
Block(2,6,-3,STONE:5)
Block(3,6,-3,MOSSY_COBBLESTONE)
Block(4,6,-3,MOSSY_COBBLESTONE)
Block(5,6,-3,STONE)
Block(6,6,-3,MOSSY_COBBLESTONE)
Block(7,6,-3,STONE)
Block(-4,6,-2,STONE)
Block(-3,6,-2,STONE)
Block(-2,6,-2,STONE)
Block(-1,6,-2,MOSSY_COBBLESTONE)
Block(0,6,-2,MOSSY_COBBLESTONE)
Block(1,6,-2,GRAVEL:0)
Block(2,6,-2,STONE)
Block(3,6,-2,STONE)
Block(4,6,-2,STONE)
Block(5,6,-2,MOSSY_COBBLESTONE)
Block(6,6,-2,MOSSY_COBBLESTONE)
Block(7,6,-2,MOSSY_COBBLESTONE)
Block(8,6,-2,STONE)
Block(-4,6,-1,MOSSY_COBBLESTONE)
Block(-3,6,-1,STONE)
Block(-2,6,-1,STONE)
Block(-1,6,-1,MOSSY_COBBLESTONE)
Block(0,6,-1,STONE)
Block(1,6,-1,STONE)
Block(2,6,-1,STONE)
Block(3,6,-1,STONE)
Block(4,6,-1,STONE)
Block(5,6,-1,STONE)
Block(6,6,-1,MOSSY_COBBLESTONE)
Block(7,6,-1,MOSSY_COBBLESTONE)
Block(-4,6,0,STONE)
Block(-3,6,0,STONE)
Block(-2,6,0,STONE)
Block(-1,6,0,MOSSY_COBBLESTONE)
Block(0,6,0,STONE)
Block(1,6,0,STONE)
Block(2,6,0,STONE)
Block(3,6,0,STONE)
Block(4,6,0,STONE)
Block(5,6,0,STONE)
Block(6,6,0,MOSSY_COBBLESTONE)
Block(7,6,0,STONE)
Block(-4,6,1,GRAVEL:0)
Block(-3,6,1,STONE)
Block(-2,6,1,STONE)
Block(-1,6,1,MOSSY_COBBLESTONE)
Block(0,6,1,STONE)
Block(1,6,1,STONE)
Block(2,6,1,STONE)
Block(3,6,1,STONE)
Block(4,6,1,MOSSY_COBBLESTONE)
Block(5,6,1,STONE)
Block(6,6,1,GRAVEL:0)
Block(-4,6,2,MOSSY_COBBLESTONE)
Block(-3,6,2,STONE)
Block(-2,6,2,STONE)
Block(-1,6,2,MOSSY_COBBLESTONE)
Block(0,6,2,STONE)
Block(1,6,2,STONE)
Block(2,6,2,STONE)
Block(3,6,2,STONE)
Block(4,6,2,MOSSY_COBBLESTONE)
Block(5,6,2,STONE)
Block(6,6,2,MOSSY_COBBLESTONE)
Block(-3,6,3,STONE)
Block(-2,6,3,STONE)
Block(-1,6,3,MOSSY_COBBLESTONE)
Block(0,6,3,STONE)
Block(1,6,3,STONE)
Block(2,6,3,MOSSY_COBBLESTONE)
Block(3,6,3,MOSSY_COBBLESTONE)
Block(4,6,3,MOSSY_COBBLESTONE)
Block(5,6,3,STONE)
Block(-3,6,4,STONE)
Block(-2,6,4,STONE)
Block(-1,6,4,MOSSY_COBBLESTONE)
Block(0,6,4,STONE)
Block(1,6,4,STONE)
Block(2,6,4,MOSSY_COBBLESTONE)
Block(3,6,4,MOSSY_COBBLESTONE)
Block(4,6,4,STONE)
Block(-4,6,5,LEAVES:0)
Block(-3,6,5,MOSSY_COBBLESTONE)
Block(-2,6,5,STONE)
Block(-1,6,5,MOSSY_COBBLESTONE)
Block(0,6,5,STONE)
Block(1,6,5,STONE)
Block(2,6,5,MOSSY_COBBLESTONE)
Block(3,6,5,LEAVES:0)
Block(-2,6,6,STONE)
Block(-1,6,6,MOSSY_COBBLESTONE)
Block(0,6,6,MOSSY_COBBLESTONE)
Block(2,7,-9,MOSSY_COBBLESTONE)
Block(0,7,-8,MOSSY_COBBLESTONE)
Block(1,7,-8,STONE)
Block(2,7,-8,MOSSY_COBBLESTONE)
Block(3,7,-8,MOSSY_COBBLESTONE)
Block(-1,7,-7,STONE)
Block(0,7,-7,STONE)
Block(1,7,-7,STONE)
Block(2,7,-7,MOSSY_COBBLESTONE)
Block(3,7,-7,MOSSY_COBBLESTONE)
Block(4,7,-7,STONE)
Block(-2,7,-6,STONE)
Block(-1,7,-6,STONE)
Block(0,7,-6,STONE)
Block(1,7,-6,STONE)
Block(2,7,-6,MOSSY_COBBLESTONE)
Block(3,7,-6,MOSSY_COBBLESTONE)
Block(4,7,-6,MOSSY_COBBLESTONE)
Block(5,7,-6,STONE)
Block(-2,7,-5,STONE)
Block(-1,7,-5,STONE)
Block(0,7,-5,STONE)
Block(1,7,-5,STONE)
Block(2,7,-5,MOSSY_COBBLESTONE)
Block(3,7,-5,MOSSY_COBBLESTONE)
Block(4,7,-5,MOSSY_COBBLESTONE)
Block(5,7,-5,STONE)
Block(6,7,-5,LEAVES:0)
Block(-3,7,-4,STONE)
Block(-2,7,-4,STONE)
Block(-1,7,-4,STONE)
Block(0,7,-4,STONE)
Block(1,7,-4,STONE)
Block(2,7,-4,STONE)
Block(3,7,-4,STONE)
Block(4,7,-4,STONE)
Block(5,7,-4,MOSSY_COBBLESTONE)
Block(6,7,-4,STONE)
Block(-4,7,-3,STONE)
Block(-3,7,-3,STONE)
Block(-2,7,-3,STONE)
Block(-1,7,-3,STONE)
Block(0,7,-3,STONE)
Block(1,7,-3,STONE:5)
Block(2,7,-3,STONE:5)
Block(3,7,-3,MOSSY_COBBLESTONE)
Block(4,7,-3,MOSSY_COBBLESTONE)
Block(5,7,-3,MOSSY_COBBLESTONE)
Block(6,7,-3,MOSSY_COBBLESTONE)
Block(7,7,-3,STONE)
Block(-6,7,-2,LEAVES:0)
Block(-5,7,-2,STONE)
Block(-4,7,-2,STONE)
Block(-3,7,-2,STONE)
Block(-2,7,-2,STONE)
Block(-1,7,-2,STONE)
Block(0,7,-2,MOSSY_COBBLESTONE)
Block(1,7,-2,GRAVEL:0)
Block(2,7,-2,STONE)
Block(3,7,-2,STONE)
Block(4,7,-2,STONE)
Block(5,7,-2,MOSSY_COBBLESTONE)
Block(6,7,-2,MOSSY_COBBLESTONE)
Block(7,7,-2,MOSSY_COBBLESTONE)
Block(8,7,-2,STONE)
Block(-5,7,-1,STONE)
Block(-4,7,-1,STONE)
Block(-3,7,-1,STONE)
Block(-2,7,-1,STONE)
Block(-1,7,-1,STONE)
Block(0,7,-1,STONE)
Block(1,7,-1,STONE)
Block(2,7,-1,STONE)
Block(3,7,-1,STONE)
Block(4,7,-1,STONE)
Block(5,7,-1,STONE)
Block(6,7,-1,MOSSY_COBBLESTONE)
Block(7,7,-1,STONE)
Block(-5,7,0,STONE)
Block(-4,7,0,STONE)
Block(-3,7,0,STONE)
Block(-2,7,0,STONE)
Block(-1,7,0,STONE)
Block(0,7,0,STONE)
Block(1,7,0,STONE)
Block(2,7,0,STONE)
Block(3,7,0,STONE)
Block(4,7,0,STONE)
Block(5,7,0,MOSSY_COBBLESTONE)
Block(6,7,0,MOSSY_COBBLESTONE)
Block(7,7,0,STONE)
Block(-4,7,1,STONE)
Block(-3,7,1,STONE)
Block(-2,7,1,STONE)
Block(-1,7,1,STONE)
Block(0,7,1,STONE)
Block(1,7,1,STONE)
Block(2,7,1,STONE)
Block(3,7,1,STONE)
Block(4,7,1,MOSSY_COBBLESTONE)
Block(5,7,1,MOSSY_COBBLESTONE)
Block(6,7,1,MOSSY_COBBLESTONE)
Block(7,7,1,STONE)
Block(-4,7,2,STONE)
Block(-3,7,2,STONE)
Block(-2,7,2,STONE)
Block(-1,7,2,STONE)
Block(0,7,2,STONE)
Block(1,7,2,STONE)
Block(2,7,2,MOSSY_COBBLESTONE)
Block(3,7,2,MOSSY_COBBLESTONE)
Block(4,7,2,MOSSY_COBBLESTONE)
Block(5,7,2,MOSSY_COBBLESTONE)
Block(6,7,2,STONE)
Block(-4,7,3,STONE)
Block(-3,7,3,STONE)
Block(-2,7,3,STONE)
Block(-1,7,3,STONE)
Block(0,7,3,STONE)
Block(1,7,3,STONE)
Block(2,7,3,MOSSY_COBBLESTONE)
Block(3,7,3,MOSSY_COBBLESTONE)
Block(4,7,3,MOSSY_COBBLESTONE)
Block(5,7,3,MOSSY_COBBLESTONE)
Block(6,7,3,STONE)
Block(-4,7,4,STONE)
Block(-3,7,4,STONE)
Block(-2,7,4,STONE)
Block(-1,7,4,STONE)
Block(0,7,4,STONE)
Block(1,7,4,STONE)
Block(2,7,4,MOSSY_COBBLESTONE)
Block(3,7,4,MOSSY_COBBLESTONE)
Block(4,7,4,STONE)
Block(-4,7,5,LEAVES:0)
Block(-3,7,5,MOSSY_COBBLESTONE)
Block(-2,7,5,STONE)
Block(-1,7,5,STONE)
Block(0,7,5,STONE)
Block(1,7,5,STONE)
Block(2,7,5,MOSSY_COBBLESTONE)
Block(3,7,5,LEAVES:0)
Block(-3,7,6,MOSSY_COBBLESTONE)
Block(-2,7,6,STONE)
Block(-1,7,6,STONE)
Block(0,7,6,STONE)
Block(1,7,6,MOSSY_COBBLESTONE)
Block(2,7,6,LEAVES:0)
Block(-1,7,7,STONE)
Block(1,8,-9,STONE)
Block(2,8,-9,STONE)
Block(0,8,-8,STONE)
Block(1,8,-8,STONE)
Block(2,8,-8,MOSSY_COBBLESTONE)
Block(3,8,-8,STONE)
Block(-1,8,-7,STONE)
Block(0,8,-7,MOSSY_COBBLESTONE)
Block(1,8,-7,STONE)
Block(2,8,-7,MOSSY_COBBLESTONE)
Block(3,8,-7,STONE)
Block(4,8,-7,STONE)
Block(5,8,-7,LEAVES:0)
Block(-2,8,-6,STONE)
Block(-1,8,-6,STONE)
Block(0,8,-6,MOSSY_COBBLESTONE)
Block(1,8,-6,STONE)
Block(2,8,-6,MOSSY_COBBLESTONE)
Block(3,8,-6,STONE)
Block(4,8,-6,STONE)
Block(5,8,-6,STONE)
Block(6,8,-6,LEAVES:0)
Block(-2,8,-5,STONE)
Block(-1,8,-5,STONE)
Block(0,8,-5,MOSSY_COBBLESTONE)
Block(1,8,-5,STONE)
Block(2,8,-5,MOSSY_COBBLESTONE)
Block(3,8,-5,STONE)
Block(4,8,-5,STONE)
Block(5,8,-5,STONE)
Block(6,8,-5,STONE)
Block(-3,8,-4,STONE)
Block(-2,8,-4,STONE)
Block(-1,8,-4,STONE)
Block(0,8,-4,MOSSY_COBBLESTONE)
Block(1,8,-4,STONE)
Block(2,8,-4,MOSSY_COBBLESTONE)
Block(3,8,-4,STONE)
Block(4,8,-4,STONE)
Block(5,8,-4,STONE)
Block(6,8,-4,STONE)
Block(-4,8,-3,STONE)
Block(-3,8,-3,STONE)
Block(-2,8,-3,STONE)
Block(-1,8,-3,STONE)
Block(0,8,-3,MOSSY_COBBLESTONE)
Block(1,8,-3,STONE)
Block(2,8,-3,MOSSY_COBBLESTONE)
Block(3,8,-3,STONE)
Block(4,8,-3,STONE)
Block(5,8,-3,STONE)
Block(6,8,-3,STONE)
Block(7,8,-3,STONE)
Block(-5,8,-2,STONE)
Block(-4,8,-2,STONE)
Block(-3,8,-2,STONE)
Block(-2,8,-2,STONE)
Block(-1,8,-2,STONE)
Block(0,8,-2,MOSSY_COBBLESTONE)
Block(1,8,-2,STONE)
Block(2,8,-2,MOSSY_COBBLESTONE)
Block(3,8,-2,STONE)
Block(4,8,-2,STONE)
Block(5,8,-2,STONE)
Block(6,8,-2,STONE)
Block(7,8,-2,MOSSY_COBBLESTONE)
Block(8,8,-2,STONE)
Block(-6,8,-1,LEAVES:0)
Block(-5,8,-1,STONE)
Block(-4,8,-1,STONE)
Block(-3,8,-1,STONE)
Block(-2,8,-1,STONE)
Block(-1,8,-1,STONE)
Block(0,8,-1,MOSSY_COBBLESTONE)
Block(1,8,-1,STONE)
Block(2,8,-1,MOSSY_COBBLESTONE)
Block(3,8,-1,STONE)
Block(4,8,-1,STONE)
Block(5,8,-1,STONE)
Block(6,8,-1,STONE)
Block(7,8,-1,STONE)
Block(-5,8,0,MOSSY_COBBLESTONE)
Block(-4,8,0,STONE)
Block(-3,8,0,STONE)
Block(-2,8,0,STONE)
Block(-1,8,0,STONE)
Block(0,8,0,MOSSY_COBBLESTONE)
Block(1,8,0,STONE)
Block(2,8,0,MOSSY_COBBLESTONE)
Block(3,8,0,STONE)
Block(4,8,0,STONE)
Block(5,8,0,STONE)
Block(6,8,0,STONE)
Block(7,8,0,MOSSY_COBBLESTONE)
Block(-5,8,1,STONE)
Block(-4,8,1,STONE)
Block(-3,8,1,STONE)
Block(-2,8,1,STONE)
Block(-1,8,1,STONE)
Block(0,8,1,MOSSY_COBBLESTONE)
Block(1,8,1,STONE)
Block(2,8,1,MOSSY_COBBLESTONE)
Block(3,8,1,STONE)
Block(4,8,1,STONE)
Block(5,8,1,STONE)
Block(6,8,1,STONE)
Block(7,8,1,STONE)
Block(-5,8,2,STONE)
Block(-4,8,2,STONE)
Block(-3,8,2,STONE)
Block(-2,8,2,STONE)
Block(-1,8,2,STONE)
Block(0,8,2,MOSSY_COBBLESTONE)
Block(1,8,2,STONE)
Block(2,8,2,MOSSY_COBBLESTONE)
Block(3,8,2,STONE)
Block(4,8,2,STONE)
Block(5,8,2,STONE)
Block(6,8,2,STONE)
Block(-4,8,3,STONE)
Block(-3,8,3,STONE)
Block(-2,8,3,STONE)
Block(-1,8,3,STONE)
Block(0,8,3,MOSSY_COBBLESTONE)
Block(1,8,3,STONE)
Block(2,8,3,MOSSY_COBBLESTONE)
Block(3,8,3,STONE)
Block(4,8,3,STONE)
Block(5,8,3,STONE)
Block(-4,8,4,STONE)
Block(-3,8,4,STONE)
Block(-2,8,4,STONE)
Block(-1,8,4,STONE)
Block(0,8,4,MOSSY_COBBLESTONE)
Block(1,8,4,STONE)
Block(2,8,4,MOSSY_COBBLESTONE)
Block(3,8,4,STONE)
Block(4,8,4,STONE)
Block(-5,8,5,LEAVES:12)
Block(-4,8,5,STONE)
Block(-3,8,5,STONE)
Block(-2,8,5,STONE)
Block(-1,8,5,STONE)
Block(0,8,5,MOSSY_COBBLESTONE)
Block(1,8,5,STONE)
Block(2,8,5,MOSSY_COBBLESTONE)
Block(3,8,5,STONE)
Block(-3,8,6,MOSSY_COBBLESTONE)
Block(-2,8,6,STONE)
Block(-1,8,6,STONE)
Block(0,8,6,MOSSY_COBBLESTONE)
Block(1,8,6,MOSSY_COBBLESTONE)
Block(2,8,6,LEAVES:12)
Block(-2,8,7,STONE)
Block(-1,8,7,STONE)
Block(1,9,-9,STONE)
Block(2,9,-9,STONE)
Block(0,9,-8,MOSSY_COBBLESTONE)
Block(1,9,-8,STONE)
Block(2,9,-8,STONE)
Block(3,9,-8,MOSSY_COBBLESTONE)
Block(4,9,-8,LEAVES:12)
Block(-1,9,-7,MOSSY_COBBLESTONE)
Block(0,9,-7,STONE)
Block(1,9,-7,STONE)
Block(2,9,-7,STONE)
Block(3,9,-7,MOSSY_COBBLESTONE)
Block(4,9,-7,STONE)
Block(5,9,-7,MOSSY_COBBLESTONE)
Block(-1,9,-6,STONE)
Block(0,9,-6,STONE)
Block(1,9,-6,STONE)
Block(2,9,-6,STONE)
Block(3,9,-6,MOSSY_COBBLESTONE)
Block(4,9,-6,STONE)
Block(5,9,-6,STONE)
Block(-2,9,-5,STONE)
Block(-1,9,-5,STONE)
Block(0,9,-5,STONE)
Block(1,9,-5,STONE)
Block(2,9,-5,STONE)
Block(3,9,-5,MOSSY_COBBLESTONE)
Block(4,9,-5,STONE)
Block(5,9,-5,STONE)
Block(6,9,-5,STONE)
Block(-3,9,-4,STONE)
Block(-2,9,-4,STONE)
Block(-1,9,-4,STONE)
Block(0,9,-4,STONE)
Block(1,9,-4,STONE)
Block(2,9,-4,STONE)
Block(3,9,-4,MOSSY_COBBLESTONE)
Block(4,9,-4,STONE)
Block(5,9,-4,STONE)
Block(6,9,-4,MOSSY_COBBLESTONE)
Block(7,9,-4,STONE)
Block(-4,9,-3,STONE)
Block(-3,9,-3,STONE)
Block(-2,9,-3,STONE)
Block(-1,9,-3,STONE)
Block(0,9,-3,STONE)
Block(1,9,-3,STONE)
Block(2,9,-3,STONE)
Block(3,9,-3,MOSSY_COBBLESTONE)
Block(4,9,-3,STONE)
Block(5,9,-3,STONE)
Block(6,9,-3,MOSSY_COBBLESTONE)
Block(7,9,-3,STONE)
Block(-5,9,-2,STONE)
Block(-4,9,-2,STONE)
Block(-3,9,-2,STONE)
Block(-2,9,-2,STONE)
Block(-1,9,-2,STONE)
Block(0,9,-2,STONE)
Block(1,9,-2,STONE)
Block(2,9,-2,STONE)
Block(3,9,-2,MOSSY_COBBLESTONE)
Block(4,9,-2,STONE)
Block(5,9,-2,STONE)
Block(6,9,-2,MOSSY_COBBLESTONE)
Block(7,9,-2,STONE)
Block(8,9,-2,STONE)
Block(-6,9,-1,LEAVES:0)
Block(-5,9,-1,MOSSY_COBBLESTONE)
Block(-4,9,-1,STONE)
Block(-3,9,-1,STONE)
Block(-2,9,-1,STONE)
Block(-1,9,-1,STONE)
Block(0,9,-1,STONE)
Block(1,9,-1,STONE)
Block(2,9,-1,STONE)
Block(3,9,-1,MOSSY_COBBLESTONE)
Block(4,9,-1,STONE)
Block(5,9,-1,STONE)
Block(6,9,-1,MOSSY_COBBLESTONE)
Block(7,9,-1,MOSSY_COBBLESTONE)
Block(-5,9,0,STONE:5)
Block(-4,9,0,STONE)
Block(-3,9,0,STONE)
Block(-2,9,0,STONE)
Block(-1,9,0,STONE)
Block(0,9,0,STONE)
Block(1,9,0,STONE)
Block(2,9,0,STONE)
Block(3,9,0,MOSSY_COBBLESTONE)
Block(4,9,0,STONE)
Block(5,9,0,STONE)
Block(6,9,0,MOSSY_COBBLESTONE)
Block(7,9,0,STONE:5)
Block(-5,9,1,STONE)
Block(-4,9,1,STONE)
Block(-3,9,1,STONE)
Block(-2,9,1,STONE)
Block(-1,9,1,STONE)
Block(0,9,1,STONE)
Block(1,9,1,STONE)
Block(2,9,1,STONE)
Block(3,9,1,MOSSY_COBBLESTONE)
Block(4,9,1,STONE)
Block(5,9,1,STONE)
Block(6,9,1,STONE)
Block(7,9,1,LEAVES:0)
Block(-5,9,2,MOSSY_COBBLESTONE)
Block(-4,9,2,STONE)
Block(-3,9,2,STONE)
Block(-2,9,2,STONE)
Block(-1,9,2,STONE)
Block(0,9,2,STONE)
Block(1,9,2,STONE)
Block(2,9,2,STONE)
Block(3,9,2,MOSSY_COBBLESTONE)
Block(4,9,2,STONE)
Block(5,9,2,STONE)
Block(6,9,2,MOSSY_COBBLESTONE)
Block(-5,9,3,STONE)
Block(-4,9,3,STONE)
Block(-3,9,3,STONE)
Block(-2,9,3,STONE)
Block(-1,9,3,STONE)
Block(0,9,3,STONE)
Block(1,9,3,STONE)
Block(2,9,3,STONE)
Block(3,9,3,MOSSY_COBBLESTONE)
Block(4,9,3,STONE)
Block(5,9,3,STONE)
Block(-5,9,4,LEAVES:12)
Block(-4,9,4,STONE)
Block(-3,9,4,STONE)
Block(-2,9,4,STONE)
Block(-1,9,4,STONE)
Block(0,9,4,STONE)
Block(1,9,4,STONE)
Block(2,9,4,STONE)
Block(3,9,4,MOSSY_COBBLESTONE)
Block(4,9,4,STONE)
Block(-4,9,5,MOSSY_COBBLESTONE)
Block(-3,9,5,STONE)
Block(-2,9,5,STONE)
Block(-1,9,5,STONE)
Block(0,9,5,STONE)
Block(1,9,5,STONE)
Block(2,9,5,MOSSY_COBBLESTONE)
Block(-4,9,6,MOSSY_COBBLESTONE)
Block(-3,9,6,STONE)
Block(-2,9,6,STONE)
Block(-1,9,6,STONE)
Block(0,9,6,STONE)
Block(1,9,6,MOSSY_COBBLESTONE)
Block(2,9,6,LEAVES:0)
Block(-3,9,7,MOSSY_COBBLESTONE)
Block(-2,9,7,STONE)
Block(-1,9,7,STONE)
Block(0,9,7,STONE)
Block(1,9,7,LEAVES:12)
Block(1,10,-9,STONE)
Block(2,10,-9,STONE)
Block(0,10,-8,STONE)
Block(1,10,-8,MOSSY_COBBLESTONE)
Block(2,10,-8,STONE)
Block(3,10,-8,STONE)
Block(4,10,-8,LEAVES:12)
Block(-1,10,-7,STONE)
Block(0,10,-7,STONE)
Block(1,10,-7,MOSSY_COBBLESTONE)
Block(2,10,-7,STONE)
Block(3,10,-7,MOSSY_COBBLESTONE)
Block(4,10,-7,MOSSY_COBBLESTONE)
Block(5,10,-7,STONE)
Block(-1,10,-6,STONE)
Block(0,10,-6,STONE)
Block(1,10,-6,MOSSY_COBBLESTONE)
Block(2,10,-6,STONE)
Block(3,10,-6,MOSSY_COBBLESTONE)
Block(4,10,-6,MOSSY_COBBLESTONE)
Block(5,10,-6,MOSSY_COBBLESTONE)
Block(6,10,-6,STONE)
Block(-2,10,-5,WOOL:13)
Block(-1,10,-5,STONE)
Block(0,10,-5,STONE)
Block(1,10,-5,MOSSY_COBBLESTONE)
Block(2,10,-5,STONE)
Block(3,10,-5,MOSSY_COBBLESTONE)
Block(4,10,-5,MOSSY_COBBLESTONE)
Block(5,10,-5,MOSSY_COBBLESTONE)
Block(6,10,-5,WOOL:13)
Block(-3,10,-4,STONE)
Block(-2,10,-4,STONE)
Block(-1,10,-4,STONE)
Block(0,10,-4,STONE)
Block(1,10,-4,MOSSY_COBBLESTONE)
Block(2,10,-4,STONE)
Block(3,10,-4,MOSSY_COBBLESTONE)
Block(4,10,-4,MOSSY_COBBLESTONE)
Block(5,10,-4,MOSSY_COBBLESTONE)
Block(6,10,-4,STONE)
Block(7,10,-4,STONE)
Block(-4,10,-3,STONE)
Block(-3,10,-3,STONE)
Block(-2,10,-3,STONE)
Block(-1,10,-3,STONE)
Block(0,10,-3,STONE)
Block(1,10,-3,MOSSY_COBBLESTONE)
Block(2,10,-3,STONE)
Block(3,10,-3,MOSSY_COBBLESTONE)
Block(4,10,-3,MOSSY_COBBLESTONE)
Block(5,10,-3,MOSSY_COBBLESTONE)
Block(6,10,-3,STONE)
Block(7,10,-3,STONE)
Block(-5,10,-2,MOSSY_COBBLESTONE)
Block(-4,10,-2,STONE)
Block(-3,10,-2,STONE)
Block(-2,10,-2,STONE)
Block(-1,10,-2,STONE)
Block(0,10,-2,STONE)
Block(1,10,-2,MOSSY_COBBLESTONE)
Block(2,10,-2,STONE)
Block(3,10,-2,MOSSY_COBBLESTONE)
Block(4,10,-2,MOSSY_COBBLESTONE)
Block(5,10,-2,MOSSY_COBBLESTONE)
Block(6,10,-2,STONE)
Block(7,10,-2,MOSSY_COBBLESTONE)
Block(8,10,-2,MOSSY_COBBLESTONE)
Block(-5,10,-1,STONE)
Block(-4,10,-1,STONE)
Block(-3,10,-1,STONE)
Block(-2,10,-1,STONE)
Block(-1,10,-1,STONE)
Block(0,10,-1,STONE)
Block(1,10,-1,MOSSY_COBBLESTONE)
Block(2,10,-1,STONE)
Block(3,10,-1,MOSSY_COBBLESTONE)
Block(4,10,-1,MOSSY_COBBLESTONE)
Block(5,10,-1,MOSSY_COBBLESTONE)
Block(6,10,-1,STONE)
Block(7,10,-1,STONE)
Block(-6,10,0,LEAVES:0)
Block(-5,10,0,STONE)
Block(-4,10,0,STONE)
Block(-3,10,0,STONE)
Block(-2,10,0,STONE)
Block(-1,10,0,STONE)
Block(0,10,0,STONE)
Block(1,10,0,MOSSY_COBBLESTONE)
Block(2,10,0,STONE)
Block(3,10,0,MOSSY_COBBLESTONE)
Block(4,10,0,MOSSY_COBBLESTONE)
Block(5,10,0,MOSSY_COBBLESTONE)
Block(6,10,0,STONE)
Block(7,10,0,STONE)
Block(-6,10,1,STONE)
Block(-5,10,1,STONE)
Block(-4,10,1,STONE)
Block(-3,10,1,STONE)
Block(-2,10,1,STONE)
Block(-1,10,1,STONE)
Block(0,10,1,STONE)
Block(1,10,1,MOSSY_COBBLESTONE)
Block(2,10,1,STONE)
Block(3,10,1,MOSSY_COBBLESTONE)
Block(4,10,1,MOSSY_COBBLESTONE)
Block(5,10,1,MOSSY_COBBLESTONE)
Block(6,10,1,STONE)
Block(-5,10,2,STONE)
Block(-4,10,2,STONE)
Block(-3,10,2,STONE)
Block(-2,10,2,STONE)
Block(-1,10,2,STONE)
Block(0,10,2,STONE)
Block(1,10,2,MOSSY_COBBLESTONE)
Block(2,10,2,STONE)
Block(3,10,2,MOSSY_COBBLESTONE)
Block(4,10,2,MOSSY_COBBLESTONE)
Block(5,10,2,STONE)
Block(6,10,2,LEAVES:0)
Block(-5,10,3,MOSSY_COBBLESTONE)
Block(-4,10,3,STONE)
Block(-3,10,3,STONE)
Block(-2,10,3,STONE)
Block(-1,10,3,STONE)
Block(0,10,3,STONE)
Block(1,10,3,MOSSY_COBBLESTONE)
Block(2,10,3,STONE)
Block(3,10,3,MOSSY_COBBLESTONE)
Block(4,10,3,MOSSY_COBBLESTONE)
Block(-6,10,4,LEAVES:12)
Block(-5,10,4,MOSSY_COBBLESTONE)
Block(-4,10,4,STONE)
Block(-3,10,4,STONE)
Block(-2,10,4,STONE)
Block(-1,10,4,STONE)
Block(0,10,4,STONE)
Block(1,10,4,MOSSY_COBBLESTONE)
Block(2,10,4,STONE)
Block(3,10,4,MOSSY_COBBLESTONE)
Block(4,10,4,MOSSY_COBBLESTONE)
Block(-5,10,5,STONE)
Block(-4,10,5,STONE)
Block(-3,10,5,STONE)
Block(-2,10,5,STONE)
Block(-1,10,5,STONE)
Block(0,10,5,STONE)
Block(1,10,5,MOSSY_COBBLESTONE)
Block(2,10,5,STONE)
Block(-4,10,6,STONE)
Block(-3,10,6,STONE)
Block(-2,10,6,STONE)
Block(-1,10,6,STONE)
Block(0,10,6,STONE)
Block(1,10,6,STONE)
Block(-3,10,7,MOSSY_COBBLESTONE)
Block(-2,10,7,STONE)
Block(-1,10,7,MOSSY_COBBLESTONE)
Block(0,10,7,LEAVES:0)
Block(1,11,-9,STONE)
Block(2,11,-9,STONE)
Block(3,11,-9,LEAVES:0)
Block(0,11,-8,MOSSY_COBBLESTONE)
Block(1,11,-8,STONE)
Block(2,11,-8,MOSSY_COBBLESTONE)
Block(3,11,-8,STONE)
Block(4,11,-8,MOSSY_COBBLESTONE)
Block(-1,11,-7,MOSSY_COBBLESTONE)
Block(0,11,-7,STONE)
Block(1,11,-7,STONE)
Block(2,11,-7,MOSSY_COBBLESTONE)
Block(3,11,-7,STONE)
Block(4,11,-7,STONE)
Block(5,11,-7,MOSSY_COBBLESTONE)
Block(-1,11,-6,STONE)
Block(0,11,-6,STONE)
Block(1,11,-6,STONE)
Block(2,11,-6,MOSSY_COBBLESTONE)
Block(3,11,-6,STONE)
Block(4,11,-6,STONE)
Block(5,11,-6,STONE)
Block(-2,11,-5,STONE)
Block(-1,11,-5,STONE)
Block(0,11,-5,STONE)
Block(1,11,-5,STONE)
Block(2,11,-5,MOSSY_COBBLESTONE)
Block(3,11,-5,STONE)
Block(4,11,-5,STONE)
Block(5,11,-5,MOSSY_COBBLESTONE)
Block(6,11,-5,STONE)
Block(-3,11,-4,STONE)
Block(-2,11,-4,STONE)
Block(-1,11,-4,STONE)
Block(0,11,-4,STONE)
Block(1,11,-4,STONE)
Block(2,11,-4,MOSSY_COBBLESTONE)
Block(3,11,-4,STONE)
Block(4,11,-4,STONE)
Block(5,11,-4,MOSSY_COBBLESTONE)
Block(6,11,-4,MOSSY_COBBLESTONE)
Block(7,11,-4,STONE)
Block(-4,11,-3,STONE)
Block(-3,11,-3,STONE)
Block(-2,11,-3,STONE)
Block(-1,11,-3,STONE)
Block(0,11,-3,STONE)
Block(1,11,-3,STONE)
Block(2,11,-3,MOSSY_COBBLESTONE)
Block(3,11,-3,STONE)
Block(4,11,-3,STONE)
Block(5,11,-3,MOSSY_COBBLESTONE)
Block(6,11,-3,MOSSY_COBBLESTONE)
Block(7,11,-3,STONE)
Block(-5,11,-2,MOSSY_COBBLESTONE)
Block(-4,11,-2,STONE)
Block(-3,11,-2,STONE)
Block(-2,11,-2,STONE)
Block(-1,11,-2,STONE)
Block(0,11,-2,STONE)
Block(1,11,-2,STONE)
Block(2,11,-2,MOSSY_COBBLESTONE)
Block(3,11,-2,STONE)
Block(4,11,-2,STONE)
Block(5,11,-2,MOSSY_COBBLESTONE)
Block(6,11,-2,MOSSY_COBBLESTONE)
Block(7,11,-2,MOSSY_COBBLESTONE)
Block(8,11,-2,MOSSY_COBBLESTONE)
Block(-6,11,-1,MOSSY_COBBLESTONE)
Block(-5,11,-1,STONE)
Block(-4,11,-1,STONE)
Block(-3,11,-1,STONE)
Block(-2,11,-1,STONE)
Block(-1,11,-1,STONE)
Block(0,11,-1,STONE)
Block(1,11,-1,STONE)
Block(2,11,-1,MOSSY_COBBLESTONE)
Block(3,11,-1,STONE)
Block(4,11,-1,STONE)
Block(5,11,-1,MOSSY_COBBLESTONE)
Block(6,11,-1,MOSSY_COBBLESTONE)
Block(7,11,-1,MOSSY_COBBLESTONE)
Block(-6,11,0,STONE)
Block(-5,11,0,STONE)
Block(-4,11,0,STONE)
Block(-3,11,0,STONE)
Block(-2,11,0,STONE)
Block(-1,11,0,STONE)
Block(0,11,0,STONE)
Block(1,11,0,STONE)
Block(2,11,0,MOSSY_COBBLESTONE)
Block(3,11,0,STONE)
Block(4,11,0,STONE)
Block(5,11,0,MOSSY_COBBLESTONE)
Block(6,11,0,STONE)
Block(-7,11,1,LEAVES:0)
Block(-6,11,1,STONE)
Block(-5,11,1,STONE)
Block(-4,11,1,STONE)
Block(-3,11,1,STONE)
Block(-2,11,1,STONE)
Block(-1,11,1,STONE)
Block(0,11,1,STONE)
Block(1,11,1,STONE)
Block(2,11,1,MOSSY_COBBLESTONE)
Block(3,11,1,STONE)
Block(4,11,1,STONE)
Block(5,11,1,STONE)
Block(-6,11,2,STONE)
Block(-5,11,2,STONE)
Block(-4,11,2,STONE)
Block(-3,11,2,STONE)
Block(-2,11,2,STONE)
Block(-1,11,2,STONE)
Block(0,11,2,STONE)
Block(1,11,2,STONE)
Block(2,11,2,MOSSY_COBBLESTONE)
Block(3,11,2,STONE)
Block(4,11,2,STONE)
Block(5,11,2,STONE)
Block(6,11,2,LEAVES:0)
Block(-6,11,3,MOSSY_COBBLESTONE)
Block(-5,11,3,STONE)
Block(-4,11,3,STONE)
Block(-3,11,3,STONE)
Block(-2,11,3,STONE)
Block(-1,11,3,STONE)
Block(0,11,3,STONE)
Block(1,11,3,STONE)
Block(2,11,3,MOSSY_COBBLESTONE)
Block(3,11,3,STONE)
Block(4,11,3,MOSSY_COBBLESTONE)
Block(-6,11,4,LEAVES:0)
Block(-5,11,4,MOSSY_COBBLESTONE)
Block(-4,11,4,STONE)
Block(-3,11,4,STONE)
Block(-2,11,4,STONE)
Block(-1,11,4,STONE)
Block(0,11,4,STONE)
Block(1,11,4,STONE)
Block(2,11,4,MOSSY_COBBLESTONE)
Block(3,11,4,MOSSY_COBBLESTONE)
Block(-5,11,5,STONE)
Block(-4,11,5,STONE)
Block(-3,11,5,STONE)
Block(-2,11,5,STONE)
Block(-1,11,5,STONE)
Block(0,11,5,STONE)
Block(1,11,5,STONE)
Block(2,11,5,STONE)
Block(-4,11,6,MOSSY_COBBLESTONE)
Block(-3,11,6,STONE)
Block(-2,11,6,STONE)
Block(-1,11,6,STONE)
Block(0,11,6,STONE)
Block(1,11,6,MOSSY_COBBLESTONE)
Block(-4,11,7,STONE)
Block(-3,11,7,STONE)
Block(-2,11,7,STONE)
Block(-1,11,7,STONE)
Block(0,11,7,LEAVES:0)
Block(1,12,-9,STONE)
Block(2,12,-9,STONE)
Block(3,12,-9,LEAVES:0)
Block(0,12,-8,MOSSY_COBBLESTONE)
Block(1,12,-8,STONE)
Block(2,12,-8,STONE:5)
Block(3,12,-8,MOSSY_COBBLESTONE)
Block(4,12,-8,MOSSY_COBBLESTONE)
Block(-1,12,-7,MOSSY_COBBLESTONE)
Block(0,12,-7,STONE)
Block(1,12,-7,STONE)
Block(2,12,-7,STONE:5)
Block(3,12,-7,MOSSY_COBBLESTONE)
Block(4,12,-7,MOSSY_COBBLESTONE)
Block(-1,12,-6,STONE)
Block(0,12,-6,STONE)
Block(1,12,-6,STONE)
Block(2,12,-6,STONE:5)
Block(3,12,-6,MOSSY_COBBLESTONE)
Block(4,12,-6,STONE)
Block(5,12,-6,STONE)
Block(-2,12,-5,STONE)
Block(-1,12,-5,STONE)
Block(0,12,-5,STONE)
Block(1,12,-5,STONE)
Block(2,12,-5,STONE:5)
Block(3,12,-5,MOSSY_COBBLESTONE)
Block(4,12,-5,STONE)
Block(5,12,-5,STONE)
Block(-3,12,-4,STONE)
Block(-2,12,-4,STONE)
Block(-1,12,-4,STONE)
Block(0,12,-4,STONE)
Block(1,12,-4,STONE)
Block(2,12,-4,STONE:5)
Block(3,12,-4,MOSSY_COBBLESTONE)
Block(4,12,-4,STONE)
Block(5,12,-4,MOSSY_COBBLESTONE)
Block(6,12,-4,MOSSY_COBBLESTONE)
Block(-4,12,-3,LEAVES:0)
Block(-3,12,-3,STONE)
Block(-2,12,-3,STONE)
Block(-1,12,-3,STONE)
Block(0,12,-3,STONE)
Block(1,12,-3,STONE)
Block(2,12,-3,STONE:5)
Block(3,12,-3,MOSSY_COBBLESTONE)
Block(4,12,-3,STONE)
Block(5,12,-3,MOSSY_COBBLESTONE)
Block(6,12,-3,MOSSY_COBBLESTONE)
Block(7,12,-3,STONE)
Block(-5,12,-2,STONE)
Block(-4,12,-2,MOSSY_COBBLESTONE)
Block(-3,12,-2,STONE)
Block(-2,12,-2,STONE)
Block(-1,12,-2,STONE)
Block(0,12,-2,STONE)
Block(1,12,-2,STONE)
Block(2,12,-2,STONE:5)
Block(3,12,-2,MOSSY_COBBLESTONE)
Block(4,12,-2,STONE)
Block(5,12,-2,MOSSY_COBBLESTONE)
Block(6,12,-2,MOSSY_COBBLESTONE)
Block(7,12,-2,STONE)
Block(-6,12,-1,STONE)
Block(-5,12,-1,MOSSY_COBBLESTONE)
Block(-4,12,-1,MOSSY_COBBLESTONE)
Block(-3,12,-1,STONE)
Block(-2,12,-1,STONE)
Block(-1,12,-1,STONE)
Block(0,12,-1,STONE)
Block(1,12,-1,STONE)
Block(2,12,-1,STONE:5)
Block(3,12,-1,MOSSY_COBBLESTONE)
Block(4,12,-1,STONE)
Block(5,12,-1,MOSSY_COBBLESTONE)
Block(6,12,-1,MOSSY_COBBLESTONE)
Block(7,12,-1,STONE)
Block(-6,12,0,MOSSY_COBBLESTONE)
Block(-5,12,0,MOSSY_COBBLESTONE)
Block(-4,12,0,MOSSY_COBBLESTONE)
Block(-3,12,0,STONE)
Block(-2,12,0,STONE)
Block(-1,12,0,STONE)
Block(0,12,0,STONE)
Block(1,12,0,STONE)
Block(2,12,0,STONE:5)
Block(3,12,0,MOSSY_COBBLESTONE)
Block(4,12,0,STONE)
Block(5,12,0,MOSSY_COBBLESTONE)
Block(6,12,0,MOSSY_COBBLESTONE)
Block(-6,12,1,STONE)
Block(-5,12,1,MOSSY_COBBLESTONE)
Block(-4,12,1,MOSSY_COBBLESTONE)
Block(-3,12,1,STONE)
Block(-2,12,1,STONE)
Block(-1,12,1,STONE)
Block(0,12,1,STONE)
Block(1,12,1,STONE)
Block(2,12,1,STONE:5)
Block(3,12,1,MOSSY_COBBLESTONE)
Block(4,12,1,STONE)
Block(5,12,1,STONE)
Block(-7,12,2,LEAVES:0)
Block(-6,12,2,STONE)
Block(-5,12,2,MOSSY_COBBLESTONE)
Block(-4,12,2,MOSSY_COBBLESTONE)
Block(-3,12,2,STONE)
Block(-2,12,2,STONE)
Block(-1,12,2,STONE)
Block(0,12,2,STONE)
Block(1,12,2,STONE)
Block(2,12,2,STONE:5)
Block(3,12,2,MOSSY_COBBLESTONE)
Block(4,12,2,STONE)
Block(5,12,2,LEAVES:0)
Block(-6,12,3,STONE)
Block(-5,12,3,MOSSY_COBBLESTONE)
Block(-4,12,3,MOSSY_COBBLESTONE)
Block(-3,12,3,STONE)
Block(-2,12,3,STONE)
Block(-1,12,3,STONE)
Block(0,12,3,STONE)
Block(1,12,3,STONE)
Block(2,12,3,STONE:5)
Block(3,12,3,MOSSY_COBBLESTONE)
Block(4,12,3,STONE)
Block(-5,12,4,STONE)
Block(-4,12,4,MOSSY_COBBLESTONE)
Block(-3,12,4,STONE)
Block(-2,12,4,STONE)
Block(-1,12,4,STONE)
Block(0,12,4,STONE)
Block(1,12,4,STONE)
Block(2,12,4,STONE:5)
Block(3,12,4,STONE)
Block(-5,12,5,STONE)
Block(-4,12,5,MOSSY_COBBLESTONE)
Block(-3,12,5,STONE)
Block(-2,12,5,STONE)
Block(-1,12,5,STONE)
Block(0,12,5,STONE)
Block(1,12,5,STONE)
Block(2,12,5,STONE)
Block(-5,12,6,STONE)
Block(-4,12,6,MOSSY_COBBLESTONE)
Block(-3,12,6,STONE)
Block(-2,12,6,STONE)
Block(-1,12,6,STONE)
Block(0,12,6,STONE)
Block(1,12,6,STONE)
Block(-4,12,7,STONE)
Block(-3,12,7,STONE)
Block(-2,12,7,STONE)
Block(-1,12,7,STONE)
Block(0,12,7,LEAVES:0)
Block(-2,12,8,STONE)
Block(1,13,-9,STONE)
Block(2,13,-9,STONE)
Block(3,13,-9,LEAVES:0)
Block(0,13,-8,STONE)
Block(1,13,-8,STONE)
Block(2,13,-8,STONE)
Block(3,13,-8,STONE)
Block(-1,13,-7,STONE)
Block(0,13,-7,STONE)
Block(1,13,-7,STONE)
Block(2,13,-7,STONE)
Block(3,13,-7,MOSSY_COBBLESTONE)
Block(4,13,-7,STONE)
Block(-1,13,-6,STONE)
Block(0,13,-6,STONE)
Block(1,13,-6,STONE)
Block(2,13,-6,STONE)
Block(3,13,-6,MOSSY_COBBLESTONE)
Block(4,13,-6,STONE)
Block(-2,13,-5,STONE)
Block(-1,13,-5,STONE)
Block(0,13,-5,STONE)
Block(1,13,-5,STONE)
Block(2,13,-5,STONE)
Block(3,13,-5,MOSSY_COBBLESTONE)
Block(4,13,-5,STONE)
Block(5,13,-5,STONE)
Block(-3,13,-4,STONE)
Block(-2,13,-4,STONE)
Block(-1,13,-4,STONE)
Block(0,13,-4,STONE)
Block(1,13,-4,STONE)
Block(2,13,-4,STONE)
Block(3,13,-4,MOSSY_COBBLESTONE)
Block(4,13,-4,STONE)
Block(5,13,-4,STONE)
Block(-4,13,-3,LEAVES:0)
Block(-3,13,-3,STONE)
Block(-2,13,-3,STONE)
Block(-1,13,-3,STONE)
Block(0,13,-3,STONE)
Block(1,13,-3,STONE)
Block(2,13,-3,STONE)
Block(3,13,-3,MOSSY_COBBLESTONE)
Block(4,13,-3,STONE)
Block(5,13,-3,MOSSY_COBBLESTONE)
Block(6,13,-3,STONE)
Block(-4,13,-2,STONE:5)
Block(-3,13,-2,MOSSY_COBBLESTONE)
Block(-2,13,-2,STONE)
Block(-1,13,-2,STONE)
Block(0,13,-2,STONE)
Block(1,13,-2,STONE)
Block(2,13,-2,STONE)
Block(3,13,-2,MOSSY_COBBLESTONE)
Block(4,13,-2,STONE)
Block(5,13,-2,MOSSY_COBBLESTONE)
Block(6,13,-2,STONE:5)
Block(7,13,-2,LEAVES:0)
Block(-6,13,-1,STONE)
Block(-5,13,-1,STONE)
Block(-4,13,-1,MOSSY_COBBLESTONE)
Block(-3,13,-1,MOSSY_COBBLESTONE)
Block(-2,13,-1,STONE)
Block(-1,13,-1,STONE)
Block(0,13,-1,STONE)
Block(1,13,-1,STONE)
Block(2,13,-1,STONE)
Block(3,13,-1,MOSSY_COBBLESTONE)
Block(4,13,-1,STONE)
Block(5,13,-1,MOSSY_COBBLESTONE)
Block(6,13,-1,MOSSY_COBBLESTONE)
Block(7,13,-1,STONE)
Block(-6,13,0,STONE)
Block(-5,13,0,STONE)
Block(-4,13,0,MOSSY_COBBLESTONE)
Block(-3,13,0,MOSSY_COBBLESTONE)
Block(-2,13,0,STONE)
Block(-1,13,0,STONE)
Block(0,13,0,STONE)
Block(1,13,0,STONE)
Block(2,13,0,STONE)
Block(3,13,0,MOSSY_COBBLESTONE)
Block(4,13,0,STONE)
Block(5,13,0,MOSSY_COBBLESTONE)
Block(6,13,0,STONE)
Block(-6,13,1,STONE)
Block(-5,13,1,STONE)
Block(-4,13,1,MOSSY_COBBLESTONE)
Block(-3,13,1,MOSSY_COBBLESTONE)
Block(-2,13,1,STONE)
Block(-1,13,1,STONE)
Block(0,13,1,STONE)
Block(1,13,1,STONE)
Block(2,13,1,STONE)
Block(3,13,1,MOSSY_COBBLESTONE)
Block(4,13,1,STONE)
Block(5,13,1,STONE)
Block(-7,13,2,LEAVES:0)
Block(-6,13,2,STONE)
Block(-5,13,2,STONE)
Block(-4,13,2,MOSSY_COBBLESTONE)
Block(-3,13,2,MOSSY_COBBLESTONE)
Block(-2,13,2,STONE)
Block(-1,13,2,STONE)
Block(0,13,2,STONE)
Block(1,13,2,STONE)
Block(2,13,2,STONE)
Block(3,13,2,MOSSY_COBBLESTONE)
Block(4,13,2,STONE)
Block(-6,13,3,STONE)
Block(-5,13,3,STONE)
Block(-4,13,3,MOSSY_COBBLESTONE)
Block(-3,13,3,MOSSY_COBBLESTONE)
Block(-2,13,3,STONE)
Block(-1,13,3,STONE)
Block(0,13,3,STONE)
Block(1,13,3,STONE)
Block(2,13,3,STONE)
Block(3,13,3,STONE)
Block(4,13,3,LEAVES:12)
Block(-6,13,4,STONE)
Block(-5,13,4,STONE)
Block(-4,13,4,MOSSY_COBBLESTONE)
Block(-3,13,4,MOSSY_COBBLESTONE)
Block(-2,13,4,STONE)
Block(-1,13,4,STONE)
Block(0,13,4,STONE)
Block(1,13,4,STONE)
Block(2,13,4,STONE)
Block(3,13,4,STONE)
Block(-5,13,5,STONE)
Block(-4,13,5,MOSSY_COBBLESTONE)
Block(-3,13,5,MOSSY_COBBLESTONE)
Block(-2,13,5,STONE)
Block(-1,13,5,STONE)
Block(0,13,5,STONE)
Block(1,13,5,STONE)
Block(2,13,5,STONE)
Block(-5,13,6,MOSSY_COBBLESTONE)
Block(-4,13,6,MOSSY_COBBLESTONE)
Block(-3,13,6,MOSSY_COBBLESTONE)
Block(-2,13,6,STONE)
Block(-1,13,6,STONE)
Block(0,13,6,MOSSY_COBBLESTONE)
Block(-4,13,7,MOSSY_COBBLESTONE)
Block(-3,13,7,MOSSY_COBBLESTONE)
Block(-2,13,7,STONE)
Block(-1,13,7,MOSSY_COBBLESTONE)
Block(-1,13,8,LEAVES:0)
Block(1,14,-9,STONE)
Block(2,14,-9,LEAVES:0)
Block(0,14,-8,STONE)
Block(1,14,-8,STONE)
Block(2,14,-8,MOSSY_COBBLESTONE)
Block(3,14,-8,STONE)
Block(-1,14,-7,MOSSY_COBBLESTONE)
Block(0,14,-7,STONE)
Block(1,14,-7,STONE)
Block(2,14,-7,MOSSY_COBBLESTONE)
Block(3,14,-7,MOSSY_COBBLESTONE)
Block(-1,14,-6,STONE)
Block(0,14,-6,STONE)
Block(1,14,-6,STONE)
Block(2,14,-6,MOSSY_COBBLESTONE)
Block(3,14,-6,STONE)
Block(-3,14,-5,LEAVES:0)
Block(-2,14,-5,STONE)
Block(-1,14,-5,STONE)
Block(0,14,-5,STONE)
Block(1,14,-5,STONE)
Block(2,14,-5,MOSSY_COBBLESTONE)
Block(3,14,-5,STONE)
Block(4,14,-5,STONE)
Block(-4,14,-4,LEAVES:0)
Block(-3,14,-4,STONE)
Block(-2,14,-4,STONE)
Block(-1,14,-4,STONE)
Block(0,14,-4,STONE)
Block(1,14,-4,STONE)
Block(2,14,-4,MOSSY_COBBLESTONE)
Block(3,14,-4,STONE)
Block(4,14,-4,STONE)
Block(5,14,-4,STONE)
Block(-3,14,-3,STONE)
Block(-2,14,-3,STONE)
Block(-1,14,-3,STONE)
Block(0,14,-3,STONE)
Block(1,14,-3,STONE)
Block(2,14,-3,MOSSY_COBBLESTONE)
Block(3,14,-3,STONE)
Block(4,14,-3,STONE)
Block(5,14,-3,STONE)
Block(6,14,-3,LEAVES:0)
Block(-4,14,-2,STONE)
Block(-3,14,-2,STONE)
Block(-2,14,-2,STONE)
Block(-1,14,-2,STONE)
Block(0,14,-2,STONE)
Block(1,14,-2,STONE)
Block(2,14,-2,MOSSY_COBBLESTONE)
Block(3,14,-2,STONE)
Block(4,14,-2,STONE)
Block(5,14,-2,STONE)
Block(6,14,-2,STONE)
Block(-5,14,-1,MOSSY_COBBLESTONE)
Block(-4,14,-1,STONE)
Block(-3,14,-1,STONE)
Block(-2,14,-1,STONE)
Block(-1,14,-1,STONE)
Block(0,14,-1,STONE)
Block(1,14,-1,STONE)
Block(2,14,-1,MOSSY_COBBLESTONE)
Block(3,14,-1,STONE)
Block(4,14,-1,STONE)
Block(5,14,-1,STONE)
Block(6,14,-1,MOSSY_COBBLESTONE)
Block(-6,14,0,STONE)
Block(-5,14,0,STONE)
Block(-4,14,0,STONE)
Block(-3,14,0,STONE)
Block(-2,14,0,STONE)
Block(-1,14,0,STONE)
Block(0,14,0,STONE)
Block(1,14,0,STONE)
Block(2,14,0,MOSSY_COBBLESTONE)
Block(3,14,0,STONE)
Block(4,14,0,STONE)
Block(5,14,0,STONE)
Block(6,14,0,STONE)
Block(-7,14,1,LEAVES:0)
Block(-6,14,1,STONE)
Block(-5,14,1,STONE)
Block(-4,14,1,STONE)
Block(-3,14,1,STONE)
Block(-2,14,1,STONE)
Block(-1,14,1,STONE)
Block(0,14,1,STONE)
Block(1,14,1,STONE)
Block(2,14,1,MOSSY_COBBLESTONE)
Block(3,14,1,STONE)
Block(4,14,1,STONE)
Block(5,14,1,STONE)
Block(-6,14,2,MOSSY_COBBLESTONE)
Block(-5,14,2,STONE)
Block(-4,14,2,STONE)
Block(-3,14,2,STONE)
Block(-2,14,2,STONE)
Block(-1,14,2,STONE)
Block(0,14,2,STONE)
Block(1,14,2,STONE)
Block(2,14,2,MOSSY_COBBLESTONE)
Block(3,14,2,STONE)
Block(4,14,2,MOSSY_COBBLESTONE)
Block(-6,14,3,MOSSY_COBBLESTONE)
Block(-5,14,3,STONE)
Block(-4,14,3,STONE)
Block(-3,14,3,STONE)
Block(-2,14,3,STONE)
Block(-1,14,3,STONE)
Block(0,14,3,STONE)
Block(1,14,3,STONE)
Block(2,14,3,MOSSY_COBBLESTONE)
Block(3,14,3,MOSSY_COBBLESTONE)
Block(-6,14,4,STONE)
Block(-5,14,4,STONE)
Block(-4,14,4,STONE)
Block(-3,14,4,STONE)
Block(-2,14,4,STONE)
Block(-1,14,4,STONE)
Block(0,14,4,STONE)
Block(1,14,4,STONE)
Block(2,14,4,STONE)
Block(3,14,4,LEAVES:0)
Block(-5,14,5,STONE)
Block(-4,14,5,STONE)
Block(-3,14,5,STONE)
Block(-2,14,5,STONE)
Block(-1,14,5,STONE)
Block(0,14,5,STONE)
Block(1,14,5,STONE)
Block(2,14,5,STONE)
Block(-5,14,6,STONE)
Block(-4,14,6,STONE)
Block(-3,14,6,STONE)
Block(-2,14,6,STONE)
Block(-1,14,6,STONE)
Block(0,14,6,STONE)
Block(-4,14,7,STONE)
Block(-3,14,7,STONE)
Block(-2,14,7,STONE)
Block(-1,14,7,STONE)
Block(-2,14,8,LEAVES:0)
Block(0,15,-8,STONE)
Block(1,15,-8,STONE)
Block(2,15,-8,STONE)
Block(-1,15,-7,STONE)
Block(0,15,-7,STONE)
Block(1,15,-7,STONE)
Block(2,15,-7,STONE)
Block(3,15,-7,STONE)
Block(-2,15,-6,LEAVES:0)
Block(-1,15,-6,STONE)
Block(0,15,-6,STONE)
Block(1,15,-6,STONE)
Block(2,15,-6,STONE)
Block(3,15,-6,STONE)
Block(-3,15,-5,LEAVES:0)
Block(-2,15,-5,STONE)
Block(-1,15,-5,STONE)
Block(0,15,-5,STONE)
Block(1,15,-5,STONE)
Block(2,15,-5,STONE)
Block(3,15,-5,STONE)
Block(-3,15,-4,STONE)
Block(-2,15,-4,MOSSY_COBBLESTONE)
Block(-1,15,-4,STONE)
Block(0,15,-4,STONE)
Block(1,15,-4,STONE)
Block(2,15,-4,STONE)
Block(3,15,-4,STONE)
Block(4,15,-4,STONE)
Block(-3,15,-3,STONE)
Block(-2,15,-3,MOSSY_COBBLESTONE)
Block(-1,15,-3,STONE)
Block(0,15,-3,STONE)
Block(1,15,-3,STONE)
Block(2,15,-3,STONE)
Block(3,15,-3,STONE)
Block(4,15,-3,STONE)
Block(5,15,-3,LEAVES:0)
Block(-4,15,-2,STONE)
Block(-3,15,-2,STONE)
Block(-2,15,-2,MOSSY_COBBLESTONE)
Block(-1,15,-2,STONE)
Block(0,15,-2,STONE)
Block(1,15,-2,STONE)
Block(2,15,-2,STONE)
Block(3,15,-2,STONE)
Block(4,15,-2,STONE)
Block(5,15,-2,STONE)
Block(-5,15,-1,STONE)
Block(-4,15,-1,STONE)
Block(-3,15,-1,STONE)
Block(-2,15,-1,MOSSY_COBBLESTONE)
Block(-1,15,-1,STONE)
Block(0,15,-1,STONE)
Block(1,15,-1,STONE)
Block(2,15,-1,STONE)
Block(3,15,-1,STONE)
Block(4,15,-1,STONE)
Block(5,15,-1,STONE)
Block(6,15,-1,STONE)
Block(-7,15,0,LEAVES:0)
Block(-6,15,0,STONE)
Block(-5,15,0,STONE)
Block(-4,15,0,STONE)
Block(-3,15,0,STONE)
Block(-2,15,0,MOSSY_COBBLESTONE)
Block(-1,15,0,STONE)
Block(0,15,0,STONE)
Block(1,15,0,STONE)
Block(2,15,0,STONE)
Block(3,15,0,STONE)
Block(4,15,0,STONE)
Block(5,15,0,STONE)
Block(-7,15,1,LEAVES:0)
Block(-6,15,1,STONE)
Block(-5,15,1,STONE)
Block(-4,15,1,STONE)
Block(-3,15,1,STONE)
Block(-2,15,1,MOSSY_COBBLESTONE)
Block(-1,15,1,STONE)
Block(0,15,1,STONE)
Block(1,15,1,STONE)
Block(2,15,1,STONE)
Block(3,15,1,STONE)
Block(4,15,1,STONE)
Block(5,15,1,STONE)
Block(-6,15,2,STONE)
Block(-5,15,2,STONE)
Block(-4,15,2,STONE)
Block(-3,15,2,STONE)
Block(-2,15,2,MOSSY_COBBLESTONE)
Block(-1,15,2,STONE)
Block(0,15,2,STONE)
Block(1,15,2,STONE)
Block(2,15,2,STONE)
Block(3,15,2,STONE)
Block(4,15,2,STONE)
Block(-6,15,3,MOSSY_COBBLESTONE)
Block(-5,15,3,STONE)
Block(-4,15,3,STONE)
Block(-3,15,3,STONE)
Block(-2,15,3,MOSSY_COBBLESTONE)
Block(-1,15,3,STONE)
Block(0,15,3,STONE)
Block(1,15,3,STONE)
Block(2,15,3,STONE)
Block(3,15,3,MOSSY_COBBLESTONE)
Block(-6,15,4,STONE)
Block(-5,15,4,STONE)
Block(-4,15,4,STONE)
Block(-3,15,4,STONE)
Block(-2,15,4,MOSSY_COBBLESTONE)
Block(-1,15,4,STONE)
Block(0,15,4,STONE)
Block(1,15,4,STONE)
Block(2,15,4,STONE)
Block(-5,15,5,MOSSY_COBBLESTONE)
Block(-4,15,5,STONE)
Block(-3,15,5,STONE)
Block(-2,15,5,MOSSY_COBBLESTONE)
Block(-1,15,5,STONE)
Block(0,15,5,STONE)
Block(1,15,5,MOSSY_COBBLESTONE)
Block(2,15,5,LEAVES:12)
Block(-5,15,6,STONE)
Block(-4,15,6,STONE)
Block(-3,15,6,STONE)
Block(-2,15,6,MOSSY_COBBLESTONE)
Block(-1,15,6,STONE)
Block(0,15,6,STONE)
Block(-4,15,7,STONE)
Block(-3,15,7,STONE)
Block(-2,15,7,MOSSY_COBBLESTONE)
Block(-1,15,7,STONE)
Block(0,16,-8,STONE)
Block(1,16,-8,STONE)
Block(2,16,-8,STONE)
Block(-1,16,-7,STONE)
Block(0,16,-7,STONE)
Block(1,16,-7,STONE)
Block(2,16,-7,STONE)
Block(3,16,-7,STONE)
Block(-2,16,-6,LEAVES:0)
Block(-1,16,-6,STONE)
Block(0,16,-6,STONE)
Block(1,16,-6,STONE)
Block(2,16,-6,STONE)
Block(3,16,-6,STONE)
Block(-2,16,-5,STONE)
Block(-1,16,-5,STONE)
Block(0,16,-5,STONE)
Block(1,16,-5,STONE)
Block(2,16,-5,STONE)
Block(3,16,-5,STONE)
Block(-3,16,-4,STONE)
Block(-2,16,-4,STONE)
Block(-1,16,-4,STONE)
Block(0,16,-4,STONE)
Block(1,16,-4,STONE)
Block(2,16,-4,STONE)
Block(3,16,-4,STONE)
Block(4,16,-4,LEAVES:0)
Block(-3,16,-3,STONE)
Block(-2,16,-3,STONE)
Block(-1,16,-3,STONE)
Block(0,16,-3,STONE)
Block(1,16,-3,STONE)
Block(2,16,-3,STONE)
Block(3,16,-3,STONE)
Block(4,16,-3,STONE)
Block(-4,16,-2,STONE)
Block(-3,16,-2,STONE)
Block(-2,16,-2,STONE)
Block(-1,16,-2,STONE)
Block(0,16,-2,STONE)
Block(1,16,-2,STONE)
Block(2,16,-2,STONE)
Block(3,16,-2,STONE)
Block(4,16,-2,STONE)
Block(-6,16,-1,LEAVES:0)
Block(-5,16,-1,STONE)
Block(-4,16,-1,STONE)
Block(-3,16,-1,STONE)
Block(-2,16,-1,STONE)
Block(-1,16,-1,STONE)
Block(0,16,-1,STONE)
Block(1,16,-1,STONE)
Block(2,16,-1,STONE)
Block(3,16,-1,STONE)
Block(4,16,-1,STONE)
Block(5,16,-1,STONE)
Block(-6,16,0,STONE)
Block(-5,16,0,STONE)
Block(-4,16,0,STONE)
Block(-3,16,0,STONE)
Block(-2,16,0,STONE)
Block(-1,16,0,STONE)
Block(0,16,0,STONE)
Block(1,16,0,STONE)
Block(2,16,0,STONE)
Block(3,16,0,STONE)
Block(4,16,0,STONE)
Block(5,16,0,STONE)
Block(-6,16,1,MOSSY_COBBLESTONE)
Block(-5,16,1,STONE)
Block(-4,16,1,STONE)
Block(-3,16,1,STONE)
Block(-2,16,1,STONE)
Block(-1,16,1,STONE)
Block(0,16,1,STONE)
Block(1,16,1,STONE)
Block(2,16,1,STONE)
Block(3,16,1,STONE)
Block(4,16,1,STONE)
Block(5,16,1,MOSSY_COBBLESTONE)
Block(-7,16,2,MOSSY_COBBLESTONE)
Block(-6,16,2,STONE)
Block(-5,16,2,STONE)
Block(-4,16,2,STONE)
Block(-3,16,2,STONE)
Block(-2,16,2,STONE)
Block(-1,16,2,STONE)
Block(0,16,2,STONE)
Block(1,16,2,STONE)
Block(2,16,2,STONE)
Block(3,16,2,STONE)
Block(4,16,2,MOSSY_COBBLESTONE)
Block(-6,16,3,MOSSY_COBBLESTONE)
Block(-5,16,3,STONE)
Block(-4,16,3,STONE)
Block(-3,16,3,STONE)
Block(-2,16,3,STONE)
Block(-1,16,3,STONE)
Block(0,16,3,STONE)
Block(1,16,3,STONE)
Block(2,16,3,STONE)
Block(3,16,3,MOSSY_COBBLESTONE)
Block(-6,16,4,MOSSY_COBBLESTONE)
Block(-5,16,4,STONE)
Block(-4,16,4,STONE)
Block(-3,16,4,STONE)
Block(-2,16,4,STONE)
Block(-1,16,4,STONE)
Block(0,16,4,STONE)
Block(1,16,4,STONE)
Block(2,16,4,MOSSY_COBBLESTONE)
Block(-5,16,5,MOSSY_COBBLESTONE)
Block(-4,16,5,STONE)
Block(-3,16,5,STONE)
Block(-2,16,5,STONE)
Block(-1,16,5,STONE)
Block(0,16,5,STONE)
Block(1,16,5,MOSSY_COBBLESTONE)
Block(-5,16,6,STONE)
Block(-4,16,6,STONE)
Block(-3,16,6,STONE)
Block(-2,16,6,STONE)
Block(-1,16,6,STONE)
Block(0,16,6,STONE)
Block(-3,16,7,STONE)
Block(-2,16,7,STONE)
Block(-1,16,7,STONE)
Block(0,17,-8,STONE)
Block(1,17,-8,STONE:5)
Block(-1,17,-7,STONE)
Block(0,17,-7,STONE)
Block(1,17,-7,STONE:5)
Block(2,17,-7,STONE)
Block(-2,17,-6,LEAVES:0)
Block(-1,17,-6,STONE)
Block(0,17,-6,STONE)
Block(1,17,-6,STONE:5)
Block(2,17,-6,STONE)
Block(-2,17,-5,STONE)
Block(-1,17,-5,STONE)
Block(0,17,-5,STONE)
Block(1,17,-5,STONE:5)
Block(2,17,-5,STONE)
Block(-3,17,-4,STONE)
Block(-2,17,-4,MOSSY_COBBLESTONE)
Block(-1,17,-4,STONE)
Block(0,17,-4,STONE)
Block(1,17,-4,STONE:5)
Block(2,17,-4,STONE)
Block(3,17,-4,LEAVES:0)
Block(-4,17,-3,LEAVES:0)
Block(-3,17,-3,STONE)
Block(-2,17,-3,MOSSY_COBBLESTONE)
Block(-1,17,-3,STONE)
Block(0,17,-3,STONE)
Block(1,17,-3,STONE:5)
Block(2,17,-3,STONE)
Block(3,17,-3,STONE)
Block(-5,17,-2,LEAVES:0)
Block(-4,17,-2,STONE)
Block(-3,17,-2,STONE:5)
Block(-2,17,-2,MOSSY_COBBLESTONE)
Block(-1,17,-2,STONE)
Block(0,17,-2,STONE)
Block(1,17,-2,STONE:5)
Block(2,17,-2,STONE)
Block(3,17,-2,STONE)
Block(-5,17,-1,STONE)
Block(-4,17,-1,STONE)
Block(-3,17,-1,STONE:5)
Block(-2,17,-1,MOSSY_COBBLESTONE)
Block(-1,17,-1,STONE)
Block(0,17,-1,STONE)
Block(1,17,-1,STONE:5)
Block(2,17,-1,STONE)
Block(3,17,-1,STONE:5)
Block(4,17,-1,STONE)
Block(-5,17,0,STONE)
Block(-4,17,0,STONE)
Block(-3,17,0,STONE:5)
Block(-2,17,0,MOSSY_COBBLESTONE)
Block(-1,17,0,STONE)
Block(0,17,0,STONE)
Block(1,17,0,STONE:5)
Block(2,17,0,STONE)
Block(3,17,0,STONE:5)
Block(4,17,0,STONE)
Block(-6,17,1,MOSSY_COBBLESTONE)
Block(-5,17,1,MOSSY_COBBLESTONE)
Block(-4,17,1,STONE)
Block(-3,17,1,STONE:5)
Block(-2,17,1,MOSSY_COBBLESTONE)
Block(-1,17,1,STONE)
Block(0,17,1,STONE)
Block(1,17,1,STONE:5)
Block(2,17,1,STONE)
Block(3,17,1,STONE:5)
Block(4,17,1,MOSSY_COBBLESTONE)
Block(-7,17,2,MOSSY_COBBLESTONE)
Block(-6,17,2,STONE)
Block(-5,17,2,MOSSY_COBBLESTONE)
Block(-4,17,2,STONE)
Block(-3,17,2,STONE:5)
Block(-2,17,2,MOSSY_COBBLESTONE)
Block(-1,17,2,STONE)
Block(0,17,2,STONE)
Block(1,17,2,STONE:5)
Block(2,17,2,STONE)
Block(3,17,2,STONE:5)
Block(4,17,2,MOSSY_COBBLESTONE)
Block(-7,17,3,MOSSY_COBBLESTONE)
Block(-6,17,3,STONE)
Block(-5,17,3,MOSSY_COBBLESTONE)
Block(-4,17,3,STONE)
Block(-3,17,3,STONE:5)
Block(-2,17,3,MOSSY_COBBLESTONE)
Block(-1,17,3,STONE)
Block(0,17,3,STONE)
Block(1,17,3,STONE:5)
Block(2,17,3,STONE)
Block(3,17,3,MOSSY_COBBLESTONE)
Block(-6,17,4,MOSSY_COBBLESTONE)
Block(-5,17,4,MOSSY_COBBLESTONE)
Block(-4,17,4,STONE)
Block(-3,17,4,STONE:5)
Block(-2,17,4,MOSSY_COBBLESTONE)
Block(-1,17,4,STONE)
Block(0,17,4,STONE)
Block(1,17,4,STONE:5)
Block(2,17,4,MOSSY_COBBLESTONE)
Block(-5,17,5,MOSSY_COBBLESTONE)
Block(-4,17,5,STONE)
Block(-3,17,5,STONE:5)
Block(-2,17,5,MOSSY_COBBLESTONE)
Block(-1,17,5,STONE)
Block(0,17,5,STONE)
Block(1,17,5,MOSSY_COBBLESTONE)
Block(-4,17,6,MOSSY_COBBLESTONE)
Block(-3,17,6,STONE:5)
Block(-2,17,6,MOSSY_COBBLESTONE)
Block(-1,17,6,MOSSY_COBBLESTONE)
Block(-3,17,7,STONE)
Block(-2,17,7,MOSSY_COBBLESTONE)
Block(0,18,-8,STONE)
Block(-2,18,-7,LEAVES:0)
Block(-1,18,-7,STONE)
Block(0,18,-7,MOSSY_COBBLESTONE)
Block(1,18,-7,MOSSY_COBBLESTONE)
Block(2,18,-7,STONE)
Block(-1,18,-6,STONE)
Block(0,18,-6,MOSSY_COBBLESTONE)
Block(1,18,-6,MOSSY_COBBLESTONE)
Block(2,18,-6,STONE)
Block(-2,18,-5,STONE)
Block(-1,18,-5,MOSSY_COBBLESTONE)
Block(0,18,-5,MOSSY_COBBLESTONE)
Block(1,18,-5,MOSSY_COBBLESTONE)
Block(2,18,-5,STONE)
Block(3,18,-5,LEAVES:0)
Block(-3,18,-4,STONE)
Block(-2,18,-4,MOSSY_COBBLESTONE)
Block(-1,18,-4,MOSSY_COBBLESTONE)
Block(0,18,-4,MOSSY_COBBLESTONE)
Block(1,18,-4,MOSSY_COBBLESTONE)
Block(2,18,-4,STONE)
Block(-4,18,-3,LEAVES:12)
Block(-3,18,-3,STONE)
Block(-2,18,-3,MOSSY_COBBLESTONE)
Block(-1,18,-3,MOSSY_COBBLESTONE)
Block(0,18,-3,MOSSY_COBBLESTONE)
Block(1,18,-3,MOSSY_COBBLESTONE)
Block(2,18,-3,STONE)
Block(3,18,-3,LEAVES:0)
Block(-4,18,-2,STONE)
Block(-3,18,-2,STONE)
Block(-2,18,-2,MOSSY_COBBLESTONE)
Block(-1,18,-2,MOSSY_COBBLESTONE)
Block(0,18,-2,MOSSY_COBBLESTONE)
Block(1,18,-2,MOSSY_COBBLESTONE)
Block(2,18,-2,STONE)
Block(3,18,-2,LEAVES:0)
Block(-5,18,-1,STONE)
Block(-4,18,-1,STONE)
Block(-3,18,-1,STONE)
Block(-2,18,-1,MOSSY_COBBLESTONE)
Block(-1,18,-1,MOSSY_COBBLESTONE)
Block(0,18,-1,MOSSY_COBBLESTONE)
Block(1,18,-1,MOSSY_COBBLESTONE)
Block(2,18,-1,MOSSY_COBBLESTONE)
Block(3,18,-1,STONE)
Block(-5,18,0,MOSSY_COBBLESTONE)
Block(-4,18,0,STONE)
Block(-3,18,0,STONE)
Block(-2,18,0,MOSSY_COBBLESTONE)
Block(-1,18,0,MOSSY_COBBLESTONE)
Block(0,18,0,MOSSY_COBBLESTONE)
Block(1,18,0,MOSSY_COBBLESTONE)
Block(2,18,0,MOSSY_COBBLESTONE)
Block(3,18,0,MOSSY_COBBLESTONE)
Block(-6,18,1,STONE)
Block(-5,18,1,MOSSY_COBBLESTONE)
Block(-4,18,1,STONE)
Block(-3,18,1,STONE)
Block(-2,18,1,MOSSY_COBBLESTONE)
Block(-1,18,1,MOSSY_COBBLESTONE)
Block(0,18,1,MOSSY_COBBLESTONE)
Block(1,18,1,MOSSY_COBBLESTONE)
Block(2,18,1,MOSSY_COBBLESTONE)
Block(3,18,1,STONE)
Block(4,18,1,STONE)
Block(-7,18,2,MOSSY_COBBLESTONE)
Block(-6,18,2,MOSSY_COBBLESTONE)
Block(-5,18,2,MOSSY_COBBLESTONE)
Block(-4,18,2,STONE)
Block(-3,18,2,STONE)
Block(-2,18,2,MOSSY_COBBLESTONE)
Block(-1,18,2,MOSSY_COBBLESTONE)
Block(0,18,2,MOSSY_COBBLESTONE)
Block(1,18,2,MOSSY_COBBLESTONE)
Block(2,18,2,MOSSY_COBBLESTONE)
Block(3,18,2,STONE)
Block(4,18,2,MOSSY_COBBLESTONE)
Block(-7,18,3,MOSSY_COBBLESTONE)
Block(-6,18,3,MOSSY_COBBLESTONE)
Block(-5,18,3,MOSSY_COBBLESTONE)
Block(-4,18,3,STONE)
Block(-3,18,3,STONE)
Block(-2,18,3,MOSSY_COBBLESTONE)
Block(-1,18,3,MOSSY_COBBLESTONE)
Block(0,18,3,MOSSY_COBBLESTONE)
Block(1,18,3,MOSSY_COBBLESTONE)
Block(2,18,3,MOSSY_COBBLESTONE)
Block(3,18,3,MOSSY_COBBLESTONE)
Block(-6,18,4,MOSSY_COBBLESTONE)
Block(-5,18,4,MOSSY_COBBLESTONE)
Block(-4,18,4,STONE)
Block(-3,18,4,STONE)
Block(-2,18,4,MOSSY_COBBLESTONE)
Block(-1,18,4,MOSSY_COBBLESTONE)
Block(0,18,4,MOSSY_COBBLESTONE)
Block(1,18,4,MOSSY_COBBLESTONE)
Block(-5,18,5,STONE)
Block(-4,18,5,STONE)
Block(-3,18,5,STONE)
Block(-2,18,5,MOSSY_COBBLESTONE)
Block(-1,18,5,MOSSY_COBBLESTONE)
Block(0,18,5,MOSSY_COBBLESTONE)
Block(-4,18,6,STONE)
Block(-3,18,6,STONE)
Block(-2,18,6,MOSSY_COBBLESTONE)
Block(-1,18,6,STONE)
Block(-3,18,7,STONE)
Block(-1,19,-7,LEAVES:0)
Block(0,19,-7,STONE)
Block(1,19,-7,LEAVES:0)
Block(-1,19,-6,STONE)
Block(0,19,-6,STONE)
Block(1,19,-6,STONE)
Block(2,19,-6,LEAVES:0)
Block(-2,19,-5,MOSSY_COBBLESTONE)
Block(-1,19,-5,MOSSY_COBBLESTONE)
Block(0,19,-5,STONE)
Block(1,19,-5,MOSSY_COBBLESTONE)
Block(2,19,-5,LEAVES:0)
Block(-4,19,-4,LEAVES:12)
Block(-3,19,-4,STONE)
Block(-2,19,-4,STONE)
Block(-1,19,-4,MOSSY_COBBLESTONE)
Block(0,19,-4,STONE)
Block(1,19,-4,MOSSY_COBBLESTONE)
Block(2,19,-4,STONE)
Block(-3,19,-3,STONE)
Block(-2,19,-3,STONE)
Block(-1,19,-3,MOSSY_COBBLESTONE)
Block(0,19,-3,STONE)
Block(1,19,-3,MOSSY_COBBLESTONE)
Block(2,19,-3,STONE)
Block(-4,19,-2,STONE)
Block(-3,19,-2,MOSSY_COBBLESTONE)
Block(-2,19,-2,STONE)
Block(-1,19,-2,MOSSY_COBBLESTONE)
Block(0,19,-2,STONE)
Block(1,19,-2,MOSSY_COBBLESTONE)
Block(2,19,-2,STONE)
Block(-5,19,-1,STONE)
Block(-4,19,-1,MOSSY_COBBLESTONE)
Block(-3,19,-1,MOSSY_COBBLESTONE)
Block(-2,19,-1,STONE)
Block(-1,19,-1,MOSSY_COBBLESTONE)
Block(0,19,-1,STONE)
Block(1,19,-1,MOSSY_COBBLESTONE)
Block(2,19,-1,STONE)
Block(3,19,-1,LEAVES:0)
Block(-5,19,0,MOSSY_COBBLESTONE)
Block(-4,19,0,MOSSY_COBBLESTONE)
Block(-3,19,0,MOSSY_COBBLESTONE)
Block(-2,19,0,STONE)
Block(-1,19,0,MOSSY_COBBLESTONE)
Block(0,19,0,STONE)
Block(1,19,0,MOSSY_COBBLESTONE)
Block(2,19,0,STONE)
Block(3,19,0,MOSSY_COBBLESTONE)
Block(-6,19,1,STONE)
Block(-5,19,1,STONE)
Block(-4,19,1,MOSSY_COBBLESTONE)
Block(-3,19,1,MOSSY_COBBLESTONE)
Block(-2,19,1,STONE)
Block(-1,19,1,MOSSY_COBBLESTONE)
Block(0,19,1,STONE)
Block(1,19,1,MOSSY_COBBLESTONE)
Block(2,19,1,STONE)
Block(3,19,1,STONE)
Block(-7,19,2,MOSSY_COBBLESTONE)
Block(-6,19,2,STONE)
Block(-5,19,2,STONE)
Block(-4,19,2,MOSSY_COBBLESTONE)
Block(-3,19,2,MOSSY_COBBLESTONE)
Block(-2,19,2,STONE)
Block(-1,19,2,MOSSY_COBBLESTONE)
Block(0,19,2,STONE)
Block(1,19,2,MOSSY_COBBLESTONE)
Block(2,19,2,STONE)
Block(3,19,2,MOSSY_COBBLESTONE)
Block(-6,19,3,STONE)
Block(-5,19,3,STONE)
Block(-4,19,3,MOSSY_COBBLESTONE)
Block(-3,19,3,MOSSY_COBBLESTONE)
Block(-2,19,3,STONE)
Block(-1,19,3,MOSSY_COBBLESTONE)
Block(0,19,3,STONE)
Block(1,19,3,MOSSY_COBBLESTONE)
Block(-6,19,4,STONE)
Block(-5,19,4,STONE)
Block(-4,19,4,MOSSY_COBBLESTONE)
Block(-3,19,4,MOSSY_COBBLESTONE)
Block(-2,19,4,STONE)
Block(-1,19,4,MOSSY_COBBLESTONE)
Block(0,19,4,STONE)
Block(-5,19,5,STONE)
Block(-4,19,5,MOSSY_COBBLESTONE)
Block(-3,19,5,MOSSY_COBBLESTONE)
Block(-2,19,5,STONE)
Block(-1,19,5,MOSSY_COBBLESTONE)
Block(-4,19,6,STONE)
Block(-3,19,6,MOSSY_COBBLESTONE)
Block(-2,19,6,STONE)
Block(0,20,-7,LEAVES:0)
Block(-1,20,-6,STONE)
Block(0,20,-6,STONE)
Block(1,20,-6,STONE)
Block(-2,20,-5,STONE)
Block(-1,20,-5,STONE)
Block(0,20,-5,STONE)
Block(1,20,-5,STONE)
Block(-3,20,-4,STONE)
Block(-2,20,-4,STONE)
Block(-1,20,-4,STONE)
Block(0,20,-4,STONE)
Block(1,20,-4,STONE)
Block(-3,20,-3,STONE)
Block(-2,20,-3,STONE)
Block(-1,20,-3,STONE)
Block(0,20,-3,STONE)
Block(1,20,-3,STONE)
Block(-4,20,-2,STONE)
Block(-3,20,-2,STONE)
Block(-2,20,-2,STONE)
Block(-1,20,-2,STONE)
Block(0,20,-2,STONE)
Block(1,20,-2,STONE)
Block(-5,20,-1,STONE)
Block(-4,20,-1,MOSSY_COBBLESTONE)
Block(-3,20,-1,STONE)
Block(-2,20,-1,STONE)
Block(-1,20,-1,STONE)
Block(0,20,-1,STONE)
Block(1,20,-1,STONE)
Block(2,20,-1,LEAVES:0)
Block(-5,20,0,STONE)
Block(-4,20,0,MOSSY_COBBLESTONE)
Block(-3,20,0,STONE)
Block(-2,20,0,STONE)
Block(-1,20,0,STONE)
Block(0,20,0,STONE)
Block(1,20,0,STONE)
Block(2,20,0,STONE)
Block(-6,20,1,STONE)
Block(-5,20,1,STONE)
Block(-4,20,1,MOSSY_COBBLESTONE)
Block(-3,20,1,STONE)
Block(-2,20,1,STONE)
Block(-1,20,1,STONE)
Block(0,20,1,STONE)
Block(1,20,1,STONE)
Block(2,20,1,STONE)
Block(-7,20,2,STONE)
Block(-6,20,2,STONE)
Block(-5,20,2,STONE)
Block(-4,20,2,MOSSY_COBBLESTONE)
Block(-3,20,2,STONE)
Block(-2,20,2,STONE)
Block(-1,20,2,STONE)
Block(0,20,2,STONE)
Block(1,20,2,STONE)
Block(-6,20,3,STONE)
Block(-5,20,3,STONE)
Block(-4,20,3,MOSSY_COBBLESTONE)
Block(-3,20,3,STONE)
Block(-2,20,3,STONE)
Block(-1,20,3,STONE)
Block(-5,20,4,STONE)
Block(-4,20,4,MOSSY_COBBLESTONE)
Block(-3,20,4,STONE)
Block(-2,20,4,STONE)
Block(-4,20,5,MOSSY_COBBLESTONE)
Block(-3,20,5,STONE)
Block(-1,21,-6,MOSSY_COBBLESTONE)
Block(0,21,-6,MOSSY_COBBLESTONE)
Block(-1,21,-5,STONE:5)
Block(0,21,-5,STONE:5)
Block(-2,21,-4,MOSSY_COBBLESTONE)
Block(-1,21,-4,STONE)
Block(0,21,-4,MOSSY_COBBLESTONE)
Block(-3,21,-3,STONE)
Block(-2,21,-3,STONE)
Block(-1,21,-3,STONE)
Block(0,21,-3,STONE)
Block(-4,21,-2,STONE)
Block(-3,21,-2,STONE)
Block(-2,21,-2,STONE)
Block(-1,21,-2,MOSSY_COBBLESTONE)
Block(0,21,-2,STONE)
Block(1,21,-2,STONE)
Block(-5,21,-1,MOSSY_COBBLESTONE)
Block(-4,21,-1,MOSSY_COBBLESTONE)
Block(-3,21,-1,STONE)
Block(-2,21,-1,STONE)
Block(-1,21,-1,MOSSY_COBBLESTONE)
Block(0,21,-1,STONE)
Block(1,21,-1,MOSSY_COBBLESTONE)
Block(-5,21,0,MOSSY_COBBLESTONE)
Block(-4,21,0,MOSSY_COBBLESTONE)
Block(-3,21,0,STONE)
Block(-2,21,0,STONE)
Block(-1,21,0,STONE)
Block(0,21,0,STONE)
Block(1,21,0,STONE)
Block(2,21,0,LEAVES:0)
Block(-6,21,1,STONE)
Block(-5,21,1,STONE)
Block(-4,21,1,MOSSY_COBBLESTONE)
Block(-3,21,1,STONE)
Block(-2,21,1,STONE)
Block(-1,21,1,STONE)
Block(0,21,1,STONE)
Block(-6,21,2,STONE)
Block(-5,21,2,STONE)
Block(-4,21,2,STONE)
Block(-3,21,2,STONE)
Block(-2,21,2,STONE)
Block(-1,21,2,STONE)
Block(-5,21,3,STONE)
Block(-4,21,3,STONE)
Block(-3,21,3,MOSSY_COBBLESTONE)
Block(-2,21,3,STONE)
Block(-4,21,4,STONE)
Block(-3,21,4,STONE)
Block(-1,22,-5,MOSSY_COBBLESTONE)
Block(-2,22,-4,MOSSY_COBBLESTONE)
Block(-1,22,-4,STONE)
Block(0,22,-4,MOSSY_COBBLESTONE)
Block(-3,22,-3,STONE)
Block(-2,22,-3,STONE)
Block(-1,22,-3,STONE:5)
Block(0,22,-3,STONE)
Block(-4,22,-2,STONE)
Block(-3,22,-2,STONE)
Block(-2,22,-2,STONE)
Block(-1,22,-2,STONE)
Block(0,22,-2,MOSSY_COBBLESTONE)
Block(-5,22,-1,MOSSY_COBBLESTONE)
Block(-4,22,-1,MOSSY_COBBLESTONE)
Block(-3,22,-1,STONE)
Block(-2,22,-1,MOSSY_COBBLESTONE)
Block(-1,22,-1,MOSSY_COBBLESTONE)
Block(0,22,-1,LEAVES:0)
Block(-5,22,0,STONE)
Block(-4,22,0,MOSSY_COBBLESTONE)
Block(-3,22,0,STONE)
Block(1,22,0,LEAVES:0)
Block(-5,22,1,STONE)
Block(-4,22,1,STONE)
Block(-1,23,-5,MOSSY_COBBLESTONE)
Block(-2,23,-4,MOSSY_COBBLESTONE)

#######################################################################
# +-----------------------------------------------------------------+ #
# |                            BO3 checks                           | #
# +-----------------------------------------------------------------+ #
#######################################################################

# Require a condition at a certain location in order for the BO3 to be spawned.
# BlockCheck(x,y,z,BlockName[,BlockName[,...]]) - one of the blocks must be at the location
# BlockCheckNot(x,y,z,BlockName[,BlockName[,...]]) - all the blocks must not be at the location
# LightCheck(x,y,z,minLightLevel,maxLightLevel) - light must be between min and max (inclusive)

# You can use "Solid" as a BlockName for matching all solid blocks or "All" to match all blocks that aren't air.

# Examples:
BlockCheck(0,-1,0,GRASS,DIRT,DIRT:2,SAND,CLAY,GRAVEL,STONE,252:8,251:8)

#   BlockCheck(0,-1,0,Solid)       Require any solid block just below the object
#   BlockCheck(0,-1,0,WOOL)        Require any type of wool just below the object
#   BlockCheck(0,-1,0,WOOL:0)      Require white wool just below the object
#   BlockCheckNot(0,-1,0,WOOL:0)   Require that there is no white wool below the object
#   LightCheck(0,0,0,0,1)          Require almost complete darkness just below the object

#######################################################################
# +-----------------------------------------------------------------+ #
# |                             Branches                            | #
# +-----------------------------------------------------------------+ #
#######################################################################

# Branches are objects that will spawn when this object spawns when it is used in
# the CustomStructure resource. Branches can also have branches, making complex
# structures possible. See the wiki for more details.

# Regular Branches spawn each branch with an independent chance of spawning.
# Branch(x,y,z,branchName,rotation,chance[,anotherBranchName,rotation,chance[,...]][IndividualChance])
# branchName - name of the object to spawn.
# rotation - NORTH, SOUTH, EAST or WEST.
# IndividualChance - The chance each branch has to spawn, assumed to be 100 when left blank

# Weighted Branches spawn branches with a dependent chance of spawning.
# WeightedBranch(x,y,z,branchName,rotation,chance[,anotherBranchName,rotation,chance[,...]][MaxChanceOutOf])
# MaxChanceOutOf - The chance all branches have to spawn out of, assumed to be 100 when left blank
