#######################################################################
# +-----------------------------------------------------------------+ #
# |                            BO3 object                           | #
# +-----------------------------------------------------------------+ #
#######################################################################

# This is the config file of a custom object.
# If you add this object correctly to your BiomeConfigs, it will spawn in the world.

# This is the creator of this BO3 object
Author: BO3 BulkEdit (by LanToaster)

# A short description of this BO3 object
Description: This Object was Created with BO3_BulkEdit

# The BO3 version, don't change this! It can be used by external applications to do a version check.
Version: 3

# The settings mode, WriteAll, WriteWithoutComments or WriteDisable. See WorldConfig.
SettingsMode: WriteDisable


#######################################################################
# +-----------------------------------------------------------------+ #
# |                          Main settings                          | #
# +-----------------------------------------------------------------+ #
#######################################################################

# This needs to be set to true to spawn the object in the Tree and Sapling resources.
Tree: true

# The frequency of the BO3 from 1 to 200. Tries this many times to spawn this BO3 when using the CustomObject(...) resource.
# Ignored by Tree(..), Sapling(..) and CustomStructure(..)
Frequency: 1

# The rarity of the BO3 from 0 to 100. Each spawn attempt has rarity% chance to succeed when using the CustomObject(...) resource.
# Ignored by Tree(..), Sapling(..) and CustomStructure(..)
Rarity: 100.0

# If you set this to true, the BO3 will be placed with a random rotation.
RotateRandomly: false

# The spawn height of the BO3 - randomY, highestBlock or highestSolidBlock.
SpawnHeight: highestSolidBlock
SpawnHeightOffset: -2
# The height limits for the BO3.
MinHeight: 0

MaxHeight: 75

# Objects can have other objects attacthed to it: branches. Branches can also
# have branches attached to it, which can also have branches, etc. This is the
# maximum branch depth for this objects.
MaxBranchDepth: 10

# When spawned with the UseWorld keyword, this BO3 should NOT spawn in the following biomes.
# If you writer.write the BO3 name directly in the BiomeConfigs, this will be ignored.
ExcludedBiomes: All


#######################################################################
# +-----------------------------------------------------------------+ #
# |                      Source block settings                      | #
# +-----------------------------------------------------------------+ #
#######################################################################

# The block(s) the BO3 should spawn in.
SourceBlocks: AIR,GRASS,DIRT,DIRT:2,CLAY

# The maximum percentage of the BO3 that can be outside the SourceBlock.
# The BO3 won't be placed on a location with more blocks outside the SourceBlock than this percentage.
MaxPercentageOutsideSourceBlock: 0

# What to do when a block is about to be placed outside the SourceBlock? (dontPlace, placeAnyway)
OutsideSourceBlock: dontPlace


#######################################################################
# +-----------------------------------------------------------------+ #
# |                              Blocks                             | #
# +-----------------------------------------------------------------+ #
#######################################################################

# All the blocks used in the BO3 are listed here. Possible blocks:
# Block(x,y,z,id[.data][,nbtfile.nbt)
# RandomBlock(x,y,z,id[:data][,nbtfile.nbt],chance[,id[:data][,nbtfile.nbt],chance[,...]])
# So RandomBlock(0,0,0,CHEST,chest.nbt,50,CHEST,anotherchest.nbt,100) will spawn a chest at
# the BO3 origin, and give it a 50% chance to have the contents of chest.nbt, or, if that
# fails, a 100% percent chance to have the contents of anotherchest.nbt.
Block(-4,0,-6,GRASS:0)
Block(-3,0,-6,GRASS:0)
Block(-2,0,-6,GRASS:0)
Block(-1,0,-6,GRASS:0)
Block(0,0,-6,GRASS:0)
Block(-5,0,-5,GRASS:0)
Block(-4,0,-5,GRASS:0)
Block(-3,0,-5,GRASS:0)
Block(-2,0,-5,GRASS:0)
Block(-1,0,-5,DIRT:0)
Block(0,0,-5,GRASS:0)
Block(1,0,-5,GRASS:0)
Block(2,0,-5,GRASS:0)
Block(3,0,-5,GRASS:0)
Block(-5,0,-4,GRASS:0)
Block(-4,0,-4,GRASS:0)
Block(-3,0,-4,GRASS:0)
Block(-2,0,-4,GRASS:0)
Block(-1,0,-4,GRASS:0)
Block(0,0,-4,DIRT:0)
Block(1,0,-4,GRASS:0)
Block(2,0,-4,GRASS:0)
Block(3,0,-4,GRASS:0)
Block(-5,0,-3,GRASS:0)
Block(-4,0,-3,GRASS:0)
Block(-3,0,-3,GRASS:0)
Block(-2,0,-3,GRASS:0)
Block(-1,0,-3,GRASS:0)
Block(0,0,-3,DIRT:0)
Block(1,0,-3,DIRT:0)
Block(2,0,-3,GRASS:0)
Block(3,0,-3,GRASS:0)
Block(4,0,-3,GRASS:0)
Block(-5,0,-2,GRASS:0)
Block(-4,0,-2,GRASS:0)
Block(-3,0,-2,GRASS:0)
Block(-2,0,-2,DIRT:0)
Block(-1,0,-2,DIRT:0)
Block(0,0,-2,DIRT:0)
Block(1,0,-2,DIRT:0)
Block(2,0,-2,DIRT:0)
Block(3,0,-2,DIRT:0)
Block(4,0,-2,DIRT:0)
Block(-5,0,-1,GRASS:0)
Block(-4,0,-1,GRASS:0)
Block(-3,0,-1,GRASS:0)
Block(-2,0,-1,DIRT:0)
Block(-1,0,-1,DIRT:0)
Block(0,0,-1,DIRT:0)
Block(1,0,-1,DIRT:0)
Block(2,0,-1,DIRT:0)
Block(3,0,-1,DIRT:0)
Block(4,0,-1,GRASS:0)
Block(-5,0,0,GRASS:0)
Block(-4,0,0,GRASS:0)
Block(-3,0,0,DIRT:0)
Block(-2,0,0,DIRT:0)
Block(-1,0,0,DIRT:0)
Block(0,0,0,DIRT:0)
Block(1,0,0,DIRT:0)
Block(2,0,0,DIRT:0)
Block(3,0,0,GRASS:0)
Block(4,0,0,GRASS:0)
Block(-5,0,1,GRASS:0)
Block(-4,0,1,GRASS:0)
Block(-3,0,1,GRASS:0)
Block(-2,0,1,GRASS:0)
Block(-1,0,1,DIRT:0)
Block(0,0,1,DIRT:0)
Block(1,0,1,DIRT:0)
Block(2,0,1,GRASS:0)
Block(3,0,1,GRASS:0)
Block(4,0,1,GRASS:0)
Block(-5,0,2,GRASS:0)
Block(-4,0,2,GRASS:0)
Block(-3,0,2,GRASS:0)
Block(-2,0,2,GRASS:0)
Block(-1,0,2,GRASS:0)
Block(0,0,2,DIRT:0)
Block(1,0,2,GRASS:0)
Block(2,0,2,GRASS:0)
Block(3,0,2,GRASS:0)
Block(4,0,2,GRASS:0)
Block(-5,0,3,GRASS:0)
Block(-4,0,3,GRASS:0)
Block(-3,0,3,GRASS:0)
Block(-2,0,3,GRASS:0)
Block(-1,0,3,GRASS:0)
Block(0,0,3,GRASS:0)
Block(1,0,3,DIRT:0)
Block(2,0,3,GRASS:0)
Block(3,0,3,GRASS:0)
Block(4,0,3,GRASS:0)
Block(-1,1,-5,LOG:8)
Block(-1,1,-4,LEAVES:12)
Block(0,1,-4,LOG:0)
Block(1,1,-4,LEAVES:12)
Block(2,1,-4,LEAVES:12)
Block(-2,1,-3,LEAVES:12)
Block(-1,1,-3,LEAVES:12)
Block(0,1,-3,LOG:0)
Block(1,1,-3,LOG:0)
Block(2,1,-3,LEAVES:12)
Block(-2,1,-2,LOG:0)
Block(-1,1,-2,LOG:0)
Block(0,1,-2,LOG:0)
Block(1,1,-2,LOG:0)
Block(2,1,-2,LOG:0)
Block(3,1,-2,LOG:4)
Block(4,1,-2,LOG:4)
Block(-3,1,-1,LEAVES:12)
Block(-2,1,-1,LOG:0)
Block(-1,1,-1,LOG:0)
Block(0,1,-1,LOG:0)
Block(1,1,-1,LOG:0)
Block(2,1,-1,LOG:0)
Block(3,1,-1,LOG:0)
Block(-4,1,0,LEAVES:12)
Block(-3,1,0,LOG:0)
Block(-2,1,0,LOG:0)
Block(-1,1,0,LOG:0)
Block(0,1,0,LOG:0)
Block(1,1,0,LOG:0)
Block(2,1,0,LOG:0)
Block(3,1,0,LEAVES:12)
Block(-3,1,1,LEAVES:12)
Block(-2,1,1,LEAVES:12)
Block(-1,1,1,LOG:0)
Block(0,1,1,LOG:0)
Block(1,1,1,LOG:0)
Block(2,1,1,LEAVES:12)
Block(0,1,2,LOG:0)
Block(1,1,2,LEAVES:12)
Block(1,1,3,LOG:8)
Block(-1,2,-4,LEAVES:12)
Block(0,2,-4,LOG:0)
Block(-1,2,-3,LOG:0)
Block(0,2,-3,LOG:0)
Block(1,2,-3,LOG:0)
Block(2,2,-3,LEAVES:12)
Block(-2,2,-2,LOG:0)
Block(-1,2,-2,LOG:0)
Block(0,2,-2,LOG:0)
Block(1,2,-2,LOG:0)
Block(2,2,-2,LOG:0)
Block(3,2,-2,LEAVES:12)
Block(-2,2,-1,LOG:0)
Block(-1,2,-1,LOG:0)
Block(0,2,-1,LOG:0)
Block(1,2,-1,LOG:0)
Block(2,2,-1,LOG:0)
Block(3,2,-1,LOG:0)
Block(-3,2,0,LOG:0)
Block(-2,2,0,LOG:0)
Block(-1,2,0,LOG:0)
Block(0,2,0,LOG:0)
Block(1,2,0,LOG:0)
Block(2,2,0,LOG:0)
Block(-2,2,1,LEAVES:12)
Block(-1,2,1,LOG:0)
Block(0,2,1,LOG:0)
Block(1,2,1,LOG:0)
Block(2,2,1,LEAVES:12)
Block(0,2,2,LOG:0)
Block(-1,3,-3,LOG:0)
Block(0,3,-3,LOG:0)
Block(1,3,-3,LOG:0)
Block(-2,3,-2,LEAVES:12)
Block(-1,3,-2,LOG:0)
Block(0,3,-2,LOG:0)
Block(1,3,-2,LOG:0)
Block(2,3,-2,LOG:0)
Block(-2,3,-1,LOG:0)
Block(-1,3,-1,LOG:0)
Block(0,3,-1,LOG:0)
Block(1,3,-1,LOG:0)
Block(2,3,-1,LOG:0)
Block(3,3,-1,LOG:0)
Block(-3,3,0,LOG:0)
Block(-2,3,0,LOG:0)
Block(-1,3,0,LOG:0)
Block(0,3,0,LOG:0)
Block(1,3,0,LOG:0)
Block(2,3,0,LOG:0)
Block(-1,3,1,LOG:0)
Block(0,3,1,LOG:0)
Block(1,3,1,LOG:0)
Block(0,3,2,LEAVES:12)
Block(1,3,2,LEAVES:12)
Block(-1,4,-3,LOG:0)
Block(0,4,-3,LOG:0)
Block(1,4,-3,LEAVES:4)
Block(-1,4,-2,LOG:0)
Block(0,4,-2,LOG:0)
Block(1,4,-2,LOG:0)
Block(2,4,-2,LOG:0)
Block(-2,4,-1,LOG:0)
Block(-1,4,-1,LOG:0)
Block(0,4,-1,LOG:0)
Block(1,4,-1,LOG:0)
Block(2,4,-1,LOG:0)
Block(3,4,-1,LEAVES:12)
Block(-3,4,0,LEAVES:12)
Block(-2,4,0,LOG:0)
Block(-1,4,0,LOG:0)
Block(0,4,0,LOG:0)
Block(1,4,0,LOG:0)
Block(2,4,0,LOG:0)
Block(-1,4,1,LEAVES:12)
Block(0,4,1,LOG:0)
Block(1,4,1,LOG:0)
Block(0,4,2,LEAVES:12)
Block(-1,5,-3,LOG:0)
Block(0,5,-3,LOG:0)
Block(-1,5,-2,LOG:0)
Block(0,5,-2,LOG:0)
Block(1,5,-2,LOG:0)
Block(2,5,-2,LOG:0)
Block(-2,5,-1,LOG:0)
Block(-1,5,-1,LOG:0)
Block(0,5,-1,LOG:0)
Block(1,5,-1,LOG:0)
Block(2,5,-1,LOG:0)
Block(-2,5,0,LOG:0)
Block(-1,5,0,LOG:0)
Block(0,5,0,LOG:0)
Block(1,5,0,LEAVES:12)
Block(2,5,0,LEAVES:12)
Block(0,5,1,LOG:0)
Block(1,5,1,LOG:0)
Block(0,5,2,LEAVES:12)
Block(1,5,2,LEAVES:12)
Block(-1,6,-3,LOG:0)
Block(0,6,-3,LEAVES:12)
Block(-1,6,-2,LOG:0)
Block(0,6,-2,LOG:0)
Block(1,6,-2,LOG:0)
Block(2,6,-2,LOG:0)
Block(3,6,-2,LEAVES:12)
Block(-2,6,-1,LOG:0)
Block(-1,6,-1,LOG:0)
Block(0,6,-1,LOG:0)
Block(1,6,-1,LOG:0)
Block(2,6,-1,LOG:0)
Block(3,6,-1,LEAVES:12)
Block(4,6,-1,LEAVES:12)
Block(-2,6,0,LOG:0)
Block(-1,6,0,LOG:0)
Block(0,6,0,LOG:0)
Block(1,6,0,LOG:0)
Block(0,6,1,LOG:0)
Block(1,6,1,LOG:0)
Block(1,6,2,LEAVES:12)
Block(-1,7,-3,LOG:0)
Block(-1,7,-2,LOG:0)
Block(0,7,-2,LOG:0)
Block(1,7,-2,LOG:0)
Block(2,7,-2,LOG:0)
Block(-2,7,-1,LOG:0)
Block(-1,7,-1,LOG:0)
Block(0,7,-1,LOG:0)
Block(1,7,-1,LOG:0)
Block(2,7,-1,LOG:0)
Block(3,7,-1,LEAVES:12)
Block(-2,7,0,LOG:0)
Block(-1,7,0,LOG:0)
Block(0,7,0,LOG:0)
Block(1,7,0,LOG:0)
Block(0,7,1,LOG:0)
Block(1,7,1,LOG:0)
Block(-1,8,-3,LOG:0)
Block(-1,8,-2,LOG:0)
Block(0,8,-2,LOG:0)
Block(1,8,-2,LOG:0)
Block(2,8,-2,LOG:0)
Block(-2,8,-1,LOG:0)
Block(-1,8,-1,LOG:0)
Block(0,8,-1,LOG:0)
Block(1,8,-1,LOG:0)
Block(2,8,-1,LOG:0)
Block(-2,8,0,LEAVES:12)
Block(-1,8,0,LOG:0)
Block(0,8,0,LOG:0)
Block(1,8,0,LOG:0)
Block(0,8,1,LOG:0)
Block(1,9,-3,LEAVES:4)
Block(-1,9,-2,LOG:0)
Block(0,9,-2,LOG:0)
Block(1,9,-2,LOG:0)
Block(2,9,-2,LOG:0)
Block(-2,9,-1,LOG:0)
Block(-1,9,-1,LOG:0)
Block(0,9,-1,LOG:0)
Block(1,9,-1,LOG:0)
Block(2,9,-1,LOG:0)
Block(-1,9,0,LOG:0)
Block(0,9,0,LOG:0)
Block(1,9,0,LOG:0)
Block(0,9,1,LOG:0)
Block(1,10,-3,LEAVES:12)
Block(-1,10,-2,LOG:0)
Block(0,10,-2,LOG:0)
Block(1,10,-2,LEAVES:12)
Block(2,10,-2,LEAVES:12)
Block(-2,10,-1,LOG:0)
Block(-1,10,-1,LOG:0)
Block(0,10,-1,LOG:0)
Block(1,10,-1,LOG:0)
Block(2,10,-1,LOG:0)
Block(-1,10,0,LOG:0)
Block(0,10,0,LOG:0)
Block(1,10,0,LOG:0)
Block(0,10,1,LOG:0)
Block(1,11,-3,LEAVES:4)
Block(-1,11,-2,LOG:0)
Block(0,11,-2,LOG:0)
Block(1,11,-2,LOG:0)
Block(-2,11,-1,LOG:0)
Block(-1,11,-1,LOG:0)
Block(0,11,-1,LOG:0)
Block(1,11,-1,LOG:0)
Block(2,11,-1,LOG:0)
Block(-1,11,0,LOG:0)
Block(0,11,0,LOG:0)
Block(1,11,0,LOG:0)
Block(2,11,0,LEAVES:12)
Block(0,11,1,LOG:0)
Block(0,11,2,LEAVES:12)
Block(-1,12,-2,LOG:0)
Block(0,12,-2,LOG:0)
Block(1,12,-2,LOG:0)
Block(-2,12,-1,LOG:0)
Block(-1,12,-1,LOG:0)
Block(0,12,-1,LOG:0)
Block(1,12,-1,LOG:0)
Block(2,12,-1,LOG:0)
Block(-1,12,0,LOG:0)
Block(0,12,0,LOG:0)
Block(1,12,0,LOG:0)
Block(2,12,0,LEAVES:12)
Block(0,12,1,LOG:0)
Block(1,12,1,LEAVES:12)
Block(1,12,2,LEAVES:12)
Block(-1,13,-2,LOG:12)
Block(0,13,-2,LOG:12)
Block(1,13,-2,LOG:12)
Block(-2,13,-1,LOG:12)
Block(-1,13,-1,LOG:12)
Block(0,13,-1,LOG:12)
Block(1,13,-1,LOG:12)
Block(2,13,-1,LOG:12)
Block(-1,13,0,LOG:12)
Block(0,13,0,LOG:12)
Block(1,13,0,LOG:12)
Block(2,13,0,LEAVES:12)
Block(0,13,1,LOG:12)
Block(1,13,1,LEAVES:12)
Block(2,13,1,LEAVES:12)
Block(0,13,2,LEAVES:12)
Block(1,13,2,LEAVES:12)
Block(2,13,2,LEAVES:12)
Block(-1,14,-2,LOG:12)
Block(0,14,-2,LOG:12)
Block(1,14,-2,LOG:12)
Block(-2,14,-1,LOG:12)
Block(-1,14,-1,LOG:12)
Block(0,14,-1,LOG:12)
Block(1,14,-1,LOG:12)
Block(2,14,-1,LOG:12)
Block(-1,14,0,LOG:12)
Block(0,14,0,LOG:12)
Block(1,14,0,LOG:12)
Block(2,14,0,LEAVES:12)
Block(0,14,1,LOG:12)
Block(1,14,1,LEAVES:12)
Block(2,14,2,LEAVES:12)
Block(-1,15,-2,LOG:12)
Block(0,15,-2,LOG:12)
Block(1,15,-2,LOG:12)
Block(-2,15,-1,LOG:12)
Block(-1,15,-1,LOG:12)
Block(0,15,-1,LOG:12)
Block(1,15,-1,LOG:12)
Block(2,15,-1,LOG:12)
Block(-1,15,0,LOG:12)
Block(0,15,0,LOG:12)
Block(1,15,0,LOG:12)
Block(2,15,0,LEAVES:12)
Block(-1,15,1,LEAVES:12)
Block(0,15,1,LOG:12)
Block(1,15,1,LEAVES:12)
Block(0,15,2,LEAVES:12)
Block(1,15,2,LEAVES:12)
Block(-1,16,-2,LOG:12)
Block(0,16,-2,LOG:12)
Block(1,16,-2,LOG:12)
Block(-2,16,-1,LOG:12)
Block(-1,16,-1,LOG:12)
Block(0,16,-1,LOG:12)
Block(1,16,-1,LOG:12)
Block(2,16,-1,LOG:12)
Block(-1,16,0,LOG:12)
Block(0,16,0,LOG:12)
Block(1,16,0,LOG:12)
Block(0,16,1,LOG:12)
Block(1,16,1,LEAVES:12)
Block(-1,17,-2,LOG:12)
Block(0,17,-2,LOG:12)
Block(1,17,-2,LOG:12)
Block(-2,17,-1,LOG:12)
Block(-1,17,-1,LOG:12)
Block(0,17,-1,LOG:12)
Block(1,17,-1,LOG:12)
Block(2,17,-1,LOG:12)
Block(-1,17,0,LOG:12)
Block(0,17,0,LOG:12)
Block(1,17,0,LOG:12)
Block(2,17,0,LEAVES:12)
Block(-1,17,1,LEAVES:12)
Block(0,17,1,LOG:12)
Block(-1,18,-3,LEAVES:12)
Block(-2,18,-2,LEAVES:12)
Block(-1,18,-2,LOG:12)
Block(0,18,-2,LOG:12)
Block(1,18,-2,LOG:12)
Block(-2,18,-1,LOG:12)
Block(-1,18,-1,LOG:12)
Block(0,18,-1,LOG:12)
Block(1,18,-1,LOG:12)
Block(2,18,-1,LOG:12)
Block(-1,18,0,LOG:12)
Block(0,18,0,LOG:12)
Block(1,18,0,LOG:12)
Block(0,18,1,LOG:12)
Block(-6,19,-4,LEAVES:12)
Block(-4,19,-4,LEAVES:12)
Block(-5,19,-3,LEAVES:12)
Block(-4,19,-3,LEAVES:12)
Block(-3,19,-3,LEAVES:12)
Block(-1,19,-3,LEAVES:12)
Block(0,19,-3,LEAVES:12)
Block(-4,19,-2,LEAVES:12)
Block(-3,19,-2,LEAVES:12)
Block(-1,19,-2,LOG:12)
Block(0,19,-2,LOG:12)
Block(1,19,-2,LOG:12)
Block(-2,19,-1,LOG:12)
Block(-1,19,-1,LOG:12)
Block(0,19,-1,LOG:12)
Block(1,19,-1,LOG:12)
Block(2,19,-1,LOG:12)
Block(4,19,-1,LEAVES:12)
Block(5,19,-1,LEAVES:12)
Block(-1,19,0,LOG:12)
Block(0,19,0,LOG:12)
Block(1,19,0,LOG:12)
Block(-1,19,1,LOG:12)
Block(0,19,1,LOG:12)
Block(-1,19,2,LEAVES:12)
Block(-1,19,3,LEAVES:12)
Block(0,19,3,LEAVES:12)
Block(-3,19,4,LEAVES:12)
Block(-2,19,4,LEAVES:12)
Block(-1,19,4,LEAVES:12)
Block(-2,19,5,LEAVES:12)
Block(-6,20,-9,LEAVES:12)
Block(1,20,-9,LEAVES:12)
Block(1,20,-8,LEAVES:12)
Block(3,20,-8,LEAVES:12)
Block(-6,20,-7,LEAVES:12)
Block(1,20,-7,LEAVES:12)
Block(-7,20,-6,LEAVES:12)
Block(-6,20,-6,LEAVES:12)
Block(-5,20,-6,LEAVES:12)
Block(2,20,-6,LEAVES:12)
Block(-6,20,-5,LEAVES:12)
Block(-5,20,-5,LEAVES:12)
Block(-4,20,-5,LEAVES:12)
Block(0,20,-5,LEAVES:12)
Block(1,20,-5,LEAVES:12)
Block(2,20,-5,LEAVES:12)
Block(3,20,-5,LEAVES:12)
Block(-5,20,-4,LOG:12)
Block(-4,20,-4,LOG:12)
Block(-3,20,-4,LEAVES:12)
Block(-1,20,-4,LEAVES:12)
Block(0,20,-4,LEAVES:12)
Block(1,20,-4,LEAVES:12)
Block(2,20,-4,LEAVES:12)
Block(-5,20,-3,LEAVES:12)
Block(-4,20,-3,LOG:12)
Block(-3,20,-3,LEAVES:12)
Block(0,20,-3,LEAVES:12)
Block(-5,20,-2,LEAVES:12)
Block(-4,20,-2,LOG:12)
Block(-3,20,-2,LOG:12)
Block(-2,20,-2,LEAVES:12)
Block(-1,20,-2,LOG:12)
Block(0,20,-2,LOG:12)
Block(1,20,-2,LEAVES:12)
Block(-6,20,-1,LEAVES:12)
Block(-5,20,-1,LEAVES:12)
Block(-3,20,-1,LOG:12)
Block(-2,20,-1,LOG:12)
Block(-1,20,-1,LOG:12)
Block(0,20,-1,LOG:12)
Block(1,20,-1,LOG:12)
Block(2,20,-1,LOG:12)
Block(3,20,-1,LEAVES:12)
Block(-2,20,0,LOG:12)
Block(-1,20,0,LOG:12)
Block(0,20,0,LOG:12)
Block(1,20,0,LOG:12)
Block(2,20,0,LOG:12)
Block(3,20,0,LEAVES:12)
Block(4,20,0,LEAVES:12)
Block(7,20,0,LEAVES:12)
Block(-1,20,1,LOG:12)
Block(0,20,1,LOG:12)
Block(1,20,1,LEAVES:12)
Block(-1,20,2,LOG:12)
Block(0,20,2,LEAVES:12)
Block(-2,20,3,LEAVES:12)
Block(-1,20,3,LOG:12)
Block(0,20,3,LEAVES:12)
Block(-3,20,4,LEAVES:12)
Block(-2,20,4,LOG:12)
Block(-1,20,4,LOG:12)
Block(0,20,4,LEAVES:12)
Block(-5,20,5,LEAVES:12)
Block(-4,20,5,LEAVES:12)
Block(-3,20,5,LEAVES:12)
Block(-2,20,5,LOG:12)
Block(-1,20,5,LEAVES:12)
Block(-6,20,6,LEAVES:12)
Block(-5,20,6,LEAVES:12)
Block(-3,20,6,LEAVES:12)
Block(-2,20,6,LEAVES:12)
Block(-1,20,6,LEAVES:12)
Block(-3,20,7,LEAVES:12)
Block(-7,21,-9,LEAVES:12)
Block(-4,21,-9,LEAVES:12)
Block(-6,21,-8,LEAVES:12)
Block(-4,21,-8,LEAVES:12)
Block(-2,21,-8,LEAVES:12)
Block(1,21,-8,LEAVES:12)
Block(2,21,-8,LEAVES:12)
Block(4,21,-8,LEAVES:12)
Block(-7,21,-7,LEAVES:12)
Block(-6,21,-7,LEAVES:12)
Block(-5,21,-7,LEAVES:12)
Block(-2,21,-7,LEAVES:12)
Block(1,21,-7,LEAVES:12)
Block(2,21,-7,LOG:12)
Block(3,21,-7,LEAVES:12)
Block(-8,21,-6,LEAVES:4)
Block(-7,21,-6,LEAVES:4)
Block(-6,21,-6,LOG:12)
Block(-5,21,-6,LOG:12)
Block(-4,21,-6,LEAVES:12)
Block(-1,21,-6,LEAVES:12)
Block(1,21,-6,LEAVES:12)
Block(2,21,-6,LOG:12)
Block(3,21,-6,LEAVES:12)
Block(6,21,-6,LEAVES:12)
Block(7,21,-6,LEAVES:4)
Block(-7,21,-5,LEAVES:12)
Block(-6,21,-5,LEAVES:12)
Block(-5,21,-5,LOG:12)
Block(-1,21,-5,LEAVES:12)
Block(0,21,-5,LEAVES:12)
Block(1,21,-5,LOG:12)
Block(2,21,-5,LOG:12)
Block(3,21,-5,LEAVES:12)
Block(4,21,-5,LEAVES:12)
Block(5,21,-5,LEAVES:12)
Block(-6,21,-4,LEAVES:12)
Block(-5,21,-4,LOG:12)
Block(-4,21,-4,LEAVES:12)
Block(-1,21,-4,LEAVES:12)
Block(0,21,-4,LOG:12)
Block(1,21,-4,LOG:12)
Block(2,21,-4,LEAVES:12)
Block(3,21,-4,LEAVES:12)
Block(-7,21,-3,LEAVES:12)
Block(-6,21,-3,LEAVES:12)
Block(-5,21,-3,LEAVES:12)
Block(-4,21,-3,LEAVES:12)
Block(-3,21,-3,LEAVES:12)
Block(-1,21,-3,LEAVES:12)
Block(0,21,-3,LOG:12)
Block(1,21,-3,LEAVES:12)
Block(2,21,-3,LEAVES:12)
Block(6,21,-3,LEAVES:12)
Block(-5,21,-2,LEAVES:12)
Block(-4,21,-2,LEAVES:12)
Block(-3,21,-2,LEAVES:12)
Block(-1,21,-2,LOG:12)
Block(0,21,-2,LOG:12)
Block(6,21,-2,LEAVES:12)
Block(-4,21,-1,LEAVES:12)
Block(-2,21,-1,LOG:12)
Block(-1,21,-1,LOG:12)
Block(0,21,-1,LOG:12)
Block(1,21,-1,LOG:12)
Block(-2,21,0,LOG:12)
Block(-1,21,0,LOG:12)
Block(0,21,0,LOG:12)
Block(1,21,0,LOG:12)
Block(2,21,0,LOG:12)
Block(3,21,0,LEAVES:12)
Block(4,21,0,LEAVES:12)
Block(5,21,0,LEAVES:12)
Block(6,21,0,LEAVES:12)
Block(-1,21,1,LOG:12)
Block(0,21,1,LOG:12)
Block(1,21,1,LOG:12)
Block(3,21,1,LEAVES:12)
Block(4,21,1,LEAVES:12)
Block(1,21,2,LEAVES:12)
Block(5,21,2,LEAVES:12)
Block(-4,21,3,LEAVES:12)
Block(-3,21,3,LEAVES:12)
Block(-2,21,3,LEAVES:12)
Block(0,21,3,LEAVES:12)
Block(5,21,3,LEAVES:12)
Block(-5,21,4,LEAVES:12)
Block(-2,21,4,LEAVES:12)
Block(-1,21,4,LEAVES:12)
Block(-3,21,5,LEAVES:12)
Block(-2,21,5,LEAVES:12)
Block(-4,21,6,LEAVES:12)
Block(-3,21,6,LEAVES:12)
Block(-2,21,6,LOG:12)
Block(-1,21,6,LEAVES:12)
Block(2,21,6,LEAVES:12)
Block(-4,21,7,LEAVES:12)
Block(-2,21,7,LEAVES:12)
Block(0,22,-8,LEAVES:12)
Block(2,22,-8,LEAVES:12)
Block(-6,22,-7,LEAVES:12)
Block(1,22,-7,LEAVES:12)
Block(2,22,-7,LOG:12)
Block(3,22,-7,LEAVES:12)
Block(4,22,-7,LEAVES:12)
Block(6,22,-7,LEAVES:12)
Block(-6,22,-6,LEAVES:12)
Block(-5,22,-6,LEAVES:12)
Block(2,22,-6,LEAVES:12)
Block(3,22,-6,LEAVES:12)
Block(5,22,-6,LEAVES:12)
Block(-6,22,-5,LEAVES:12)
Block(-5,22,-5,LEAVES:12)
Block(-4,22,-5,LEAVES:12)
Block(1,22,-5,LEAVES:12)
Block(2,22,-5,LEAVES:12)
Block(3,22,-5,LEAVES:12)
Block(4,22,-5,LEAVES:4)
Block(5,22,-5,LEAVES:4)
Block(-6,22,-4,LEAVES:12)
Block(-5,22,-4,LEAVES:12)
Block(-4,22,-4,LEAVES:12)
Block(-2,22,-4,LEAVES:12)
Block(0,22,-4,LEAVES:12)
Block(1,22,-4,LEAVES:12)
Block(2,22,-4,LEAVES:12)
Block(7,22,-4,LEAVES:12)
Block(-5,22,-3,LEAVES:12)
Block(-4,22,-3,LEAVES:12)
Block(-2,22,-3,LEAVES:12)
Block(0,22,-3,LEAVES:12)
Block(6,22,-3,LEAVES:4)
Block(7,22,-3,LEAVES:12)
Block(-4,22,-2,LEAVES:12)
Block(-2,22,-2,LEAVES:12)
Block(0,22,-2,LOG:12)
Block(1,22,-2,LEAVES:12)
Block(6,22,-2,LEAVES:12)
Block(-3,22,-1,LEAVES:12)
Block(-1,22,-1,LOG:12)
Block(0,22,-1,LOG:12)
Block(1,22,-1,LOG:12)
Block(2,22,-1,LEAVES:12)
Block(4,22,-1,LEAVES:12)
Block(6,22,-1,LEAVES:12)
Block(7,22,-1,LEAVES:4)
Block(-7,22,0,LEAVES:12)
Block(-5,22,0,LEAVES:12)
Block(-4,22,0,LEAVES:12)
Block(-3,22,0,LEAVES:12)
Block(-2,22,0,LOG:12)
Block(-1,22,0,LOG:12)
Block(0,22,0,LOG:12)
Block(1,22,0,LOG:12)
Block(2,22,0,LOG:12)
Block(3,22,0,LOG:12)
Block(4,22,0,LOG:12)
Block(5,22,0,LEAVES:12)
Block(6,22,0,LEAVES:12)
Block(-6,22,1,LEAVES:12)
Block(-5,22,1,LEAVES:12)
Block(-4,22,1,LEAVES:12)
Block(-3,22,1,LEAVES:12)
Block(-2,22,1,LOG:12)
Block(-1,22,1,LOG:12)
Block(0,22,1,LOG:12)
Block(1,22,1,LOG:12)
Block(2,22,1,LEAVES:12)
Block(3,22,1,LEAVES:12)
Block(4,22,1,LOG:12)
Block(5,22,1,LEAVES:4)
Block(-5,22,2,LEAVES:12)
Block(-1,22,2,LEAVES:12)
Block(4,22,2,LEAVES:12)
Block(5,22,2,LEAVES:12)
Block(6,22,2,LEAVES:12)
Block(-2,22,3,LEAVES:12)
Block(-3,22,4,LEAVES:12)
Block(-2,22,4,LEAVES:12)
Block(-3,22,5,LEAVES:12)
Block(-3,22,6,LEAVES:12)
Block(2,22,6,LEAVES:12)
Block(-2,22,7,LEAVES:12)
Block(-1,22,7,LEAVES:12)
Block(2,22,7,LEAVES:12)
Block(-2,22,8,LEAVES:12)
Block(-3,23,-9,LEAVES:12)
Block(-3,23,-8,LEAVES:12)
Block(3,23,-8,LEAVES:12)
Block(-4,23,-7,LEAVES:12)
Block(2,23,-7,LEAVES:12)
Block(3,23,-7,LEAVES:12)
Block(-6,23,-6,LEAVES:12)
Block(-4,23,-6,LEAVES:12)
Block(3,23,-6,LEAVES:12)
Block(0,23,-5,LEAVES:12)
Block(2,23,-5,LEAVES:12)
Block(-7,23,-4,LEAVES:12)
Block(-6,23,-4,LEAVES:12)
Block(0,23,-4,LEAVES:12)
Block(-5,23,-3,LEAVES:12)
Block(-1,23,-3,LEAVES:12)
Block(1,23,-3,LEAVES:12)
Block(-1,23,-2,LEAVES:4)
Block(0,23,-2,LOG:12)
Block(4,23,-2,LEAVES:12)
Block(-4,23,-1,LEAVES:12)
Block(-3,23,-1,LEAVES:12)
Block(-2,23,-1,LEAVES:12)
Block(-1,23,-1,LOG:12)
Block(0,23,-1,LOG:12)
Block(1,23,-1,LOG:12)
Block(3,23,-1,LEAVES:12)
Block(-6,23,0,LEAVES:12)
Block(-5,23,0,LEAVES:12)
Block(-4,23,0,LEAVES:12)
Block(-3,23,0,LOG:12)
Block(-2,23,0,LOG:12)
Block(-1,23,0,LOG:12)
Block(0,23,0,LOG:12)
Block(1,23,0,LOG:12)
Block(2,23,0,LOG:12)
Block(3,23,0,LEAVES:12)
Block(4,23,0,LEAVES:12)
Block(5,23,0,LEAVES:12)
Block(-6,23,1,LEAVES:12)
Block(-5,23,1,LOG:12)
Block(-4,23,1,LOG:12)
Block(-3,23,1,LOG:12)
Block(-2,23,1,LEAVES:12)
Block(-1,23,1,LOG:12)
Block(0,23,1,LOG:12)
Block(1,23,1,LOG:12)
Block(3,23,1,LEAVES:12)
Block(5,23,1,LEAVES:12)
Block(6,23,1,LEAVES:12)
Block(-8,23,2,LEAVES:12)
Block(-7,23,2,LEAVES:12)
Block(-6,23,2,LEAVES:12)
Block(-5,23,2,LOG:12)
Block(-4,23,2,LEAVES:12)
Block(0,23,2,LEAVES:12)
Block(3,23,2,LEAVES:12)
Block(4,23,2,LEAVES:12)
Block(5,23,2,LEAVES:12)
Block(6,23,2,LEAVES:12)
Block(7,23,2,LEAVES:12)
Block(-6,23,3,LEAVES:12)
Block(-5,23,3,LEAVES:12)
Block(-1,23,3,LEAVES:12)
Block(0,23,3,LEAVES:12)
Block(5,23,3,LEAVES:12)
Block(-2,23,4,LEAVES:12)
Block(0,23,4,LEAVES:12)
Block(1,23,4,LEAVES:12)
Block(6,23,4,LEAVES:12)
Block(7,23,4,LEAVES:12)
Block(-4,23,5,LEAVES:12)
Block(-3,23,5,LEAVES:12)
Block(-2,23,5,LEAVES:12)
Block(0,23,5,LEAVES:12)
Block(1,23,5,LEAVES:12)
Block(-6,23,6,LEAVES:12)
Block(-5,23,6,LEAVES:12)
Block(-2,23,6,LEAVES:12)
Block(1,23,6,LEAVES:12)
Block(2,23,6,LOG:12)
Block(3,23,6,LEAVES:12)
Block(1,23,7,LEAVES:12)
Block(2,23,7,LEAVES:12)
Block(4,23,7,LEAVES:12)
Block(2,23,8,LEAVES:12)
Block(-5,24,-8,LEAVES:12)
Block(-5,24,-7,LEAVES:12)
Block(0,24,-6,LEAVES:12)
Block(5,24,-5,LEAVES:12)
Block(6,24,-5,LEAVES:12)
Block(-7,24,-4,LEAVES:12)
Block(4,24,-4,LEAVES:12)
Block(5,24,-4,LEAVES:12)
Block(3,24,-3,LEAVES:12)
Block(4,24,-3,LEAVES:12)
Block(1,24,-2,LEAVES:12)
Block(2,24,-2,LEAVES:12)
Block(-3,24,-1,LEAVES:12)
Block(-1,24,-1,LOG:12)
Block(0,24,-1,LOG:12)
Block(1,24,-1,LOG:12)
Block(5,24,-1,LEAVES:12)
Block(6,24,-1,LEAVES:12)
Block(7,24,-1,LEAVES:12)
Block(-7,24,0,LEAVES:12)
Block(-5,24,0,LEAVES:12)
Block(-4,24,0,LEAVES:12)
Block(-3,24,0,LEAVES:12)
Block(-2,24,0,LOG:12)
Block(-1,24,0,LOG:12)
Block(0,24,0,LOG:12)
Block(1,24,0,LOG:12)
Block(3,24,0,LEAVES:12)
Block(4,24,0,LEAVES:12)
Block(5,24,0,LEAVES:12)
Block(-6,24,1,LEAVES:12)
Block(-5,24,1,LEAVES:12)
Block(-4,24,1,LEAVES:12)
Block(-1,24,1,LOG:12)
Block(0,24,1,LOG:12)
Block(1,24,1,LOG:12)
Block(2,24,1,LEAVES:12)
Block(3,24,1,LEAVES:12)
Block(4,24,1,LEAVES:12)
Block(6,24,1,LEAVES:12)
Block(-7,24,2,LEAVES:12)
Block(-6,24,2,LEAVES:12)
Block(-5,24,2,LEAVES:12)
Block(-4,24,2,LEAVES:12)
Block(-3,24,2,LEAVES:12)
Block(-1,24,2,LEAVES:12)
Block(0,24,2,LOG:12)
Block(1,24,2,LEAVES:12)
Block(3,24,2,LEAVES:12)
Block(-6,24,3,LEAVES:12)
Block(-5,24,3,LEAVES:12)
Block(-1,24,3,LEAVES:12)
Block(0,24,3,LOG:12)
Block(1,24,3,LEAVES:12)
Block(-7,24,4,LEAVES:12)
Block(-6,24,4,LEAVES:12)
Block(-1,24,4,LEAVES:12)
Block(0,24,4,LOG:12)
Block(1,24,4,LOG:12)
Block(2,24,4,LEAVES:12)
Block(-2,24,5,LEAVES:12)
Block(0,24,5,LEAVES:12)
Block(1,24,5,LOG:12)
Block(2,24,5,LEAVES:12)
Block(3,24,5,LEAVES:12)
Block(0,24,6,LEAVES:12)
Block(1,24,6,LOG:12)
Block(2,24,6,LOG:12)
Block(3,24,6,LEAVES:12)
Block(4,24,6,LEAVES:12)
Block(1,24,7,LEAVES:12)
Block(2,24,7,LEAVES:12)
Block(3,24,7,LEAVES:12)
Block(4,24,7,LEAVES:12)
Block(5,24,7,LEAVES:12)
Block(2,24,8,LEAVES:12)
Block(1,24,9,LEAVES:12)
Block(-2,25,-8,LEAVES:12)
Block(0,25,-5,LEAVES:12)
Block(3,25,-5,LEAVES:12)
Block(0,25,-4,LEAVES:12)
Block(3,25,-4,LEAVES:12)
Block(-4,25,-3,LEAVES:12)
Block(-3,25,-3,LEAVES:12)
Block(1,25,-3,LEAVES:12)
Block(2,25,-3,LEAVES:12)
Block(3,25,-3,LOG:12)
Block(4,25,-3,LEAVES:12)
Block(5,25,-3,LEAVES:12)
Block(0,25,-2,LEAVES:4)
Block(1,25,-2,LOG:12)
Block(2,25,-2,LOG:12)
Block(3,25,-2,LOG:12)
Block(4,25,-2,LEAVES:12)
Block(-2,25,-1,LOG:12)
Block(-1,25,-1,LOG:12)
Block(0,25,-1,LOG:12)
Block(1,25,-1,LOG:12)
Block(2,25,-1,LEAVES:12)
Block(3,25,-1,LEAVES:12)
Block(-3,25,0,LEAVES:12)
Block(-2,25,0,LOG:12)
Block(-1,25,0,LOG:12)
Block(0,25,0,LOG:12)
Block(1,25,0,LOG:12)
Block(-4,25,1,LEAVES:12)
Block(-3,25,1,LEAVES:12)
Block(-1,25,1,LOG:12)
Block(0,25,1,LOG:12)
Block(1,25,1,LOG:12)
Block(2,25,1,LEAVES:12)
Block(-5,25,2,LEAVES:12)
Block(-2,25,2,LEAVES:12)
Block(0,25,2,LEAVES:12)
Block(0,25,3,LEAVES:12)
Block(1,25,3,LEAVES:12)
Block(2,25,3,LEAVES:12)
Block(0,25,4,LEAVES:12)
Block(1,25,4,LEAVES:12)
Block(1,25,5,LEAVES:12)
Block(2,25,5,LEAVES:12)
Block(4,25,5,LEAVES:12)
Block(5,25,5,LEAVES:12)
Block(1,25,6,LEAVES:12)
Block(2,25,6,LEAVES:12)
Block(-3,25,7,LEAVES:12)
Block(2,25,7,LEAVES:12)
Block(3,25,7,LEAVES:12)
Block(-6,26,-8,LEAVES:12)
Block(-2,26,-7,LEAVES:12)
Block(-6,26,-6,LEAVES:12)
Block(-2,26,-6,LEAVES:12)
Block(2,26,-6,LEAVES:12)
Block(-3,26,-5,LEAVES:12)
Block(2,26,-5,LEAVES:12)
Block(-6,26,-4,LEAVES:12)
Block(-3,26,-4,LEAVES:12)
Block(-1,26,-4,LEAVES:12)
Block(0,26,-3,LEAVES:12)
Block(2,26,-3,LEAVES:12)
Block(3,26,-3,LEAVES:12)
Block(-3,26,-2,LEAVES:12)
Block(-2,26,-2,LEAVES:12)
Block(0,26,-2,LOG:12)
Block(1,26,-2,LEAVES:12)
Block(2,26,-2,LEAVES:12)
Block(3,26,-2,LEAVES:12)
Block(-2,26,-1,LOG:12)
Block(-1,26,-1,LOG:12)
Block(0,26,-1,LOG:12)
Block(1,26,-1,LOG:12)
Block(3,26,-1,LEAVES:12)
Block(-2,26,0,LOG:12)
Block(-1,26,0,LOG:12)
Block(0,26,0,LOG:12)
Block(1,26,0,LOG:12)
Block(4,26,0,LEAVES:12)
Block(-2,26,1,LEAVES:12)
Block(-1,26,1,LOG:12)
Block(0,26,1,LOG:12)
Block(1,26,1,LOG:12)
Block(3,26,1,LEAVES:12)
Block(4,26,1,LEAVES:12)
Block(5,26,1,LEAVES:12)
Block(6,26,1,LEAVES:12)
Block(6,26,2,LEAVES:12)
Block(7,26,2,LEAVES:12)
Block(3,26,3,LEAVES:12)
Block(4,26,3,LEAVES:12)
Block(-3,26,4,LEAVES:12)
Block(-4,26,5,LEAVES:12)
Block(-3,26,5,LEAVES:12)
Block(-5,26,6,LEAVES:12)
Block(-4,26,6,LEAVES:12)
Block(-2,26,6,LEAVES:12)
Block(-4,26,7,LEAVES:4)
Block(4,27,-9,LEAVES:12)
Block(5,27,-9,LEAVES:12)
Block(-5,27,-8,LEAVES:12)
Block(4,27,-8,LEAVES:12)
Block(7,27,-8,LEAVES:12)
Block(-4,27,-7,LEAVES:12)
Block(-6,27,-6,LEAVES:12)
Block(-5,27,-6,LEAVES:12)
Block(6,27,-6,LEAVES:12)
Block(7,27,-6,LEAVES:12)
Block(-7,27,-5,LEAVES:12)
Block(-6,27,-5,LEAVES:12)
Block(-5,27,-5,LEAVES:12)
Block(-4,27,-5,LEAVES:12)
Block(4,27,-5,LEAVES:12)
Block(5,27,-5,LEAVES:12)
Block(6,27,-5,LEAVES:12)
Block(-5,27,-4,LEAVES:12)
Block(-4,27,-4,LEAVES:12)
Block(-4,27,-3,LEAVES:12)
Block(-3,27,-3,LEAVES:12)
Block(7,27,-3,LEAVES:12)
Block(-1,27,-2,LEAVES:4)
Block(0,27,-2,LOG:12)
Block(5,27,-2,LEAVES:12)
Block(-7,27,-1,LEAVES:12)
Block(-6,27,-1,LEAVES:12)
Block(-2,27,-1,LOG:12)
Block(-1,27,-1,LOG:12)
Block(0,27,-1,LOG:12)
Block(1,27,-1,LOG:12)
Block(2,27,-1,LEAVES:12)
Block(3,27,-1,LEAVES:12)
Block(5,27,-1,LEAVES:12)
Block(6,27,-1,LEAVES:12)
Block(-2,27,0,LEAVES:12)
Block(-1,27,0,LOG:12)
Block(0,27,0,LOG:12)
Block(1,27,0,LOG:12)
Block(3,27,0,LOG:12)
Block(4,27,0,LEAVES:12)
Block(-5,27,1,LEAVES:12)
Block(-1,27,1,LOG:12)
Block(0,27,1,LOG:12)
Block(3,27,1,LOG:12)
Block(4,27,1,LOG:12)
Block(5,27,1,LEAVES:12)
Block(0,27,2,LEAVES:4)
Block(3,27,2,LEAVES:12)
Block(-3,27,3,LEAVES:12)
Block(-1,27,3,LEAVES:12)
Block(0,27,3,LEAVES:12)
Block(-4,27,4,LEAVES:12)
Block(-3,27,4,LOG:12)
Block(-2,27,4,LOG:12)
Block(-1,27,4,LOG:12)
Block(0,27,4,LEAVES:12)
Block(-5,27,5,LEAVES:12)
Block(-4,27,5,LOG:12)
Block(-3,27,5,LOG:12)
Block(-2,27,5,LEAVES:12)
Block(1,27,5,LEAVES:12)
Block(-6,27,6,LEAVES:12)
Block(-5,27,6,LEAVES:12)
Block(-4,27,6,LOG:12)
Block(-3,27,6,LEAVES:12)
Block(1,27,6,LEAVES:12)
Block(-5,27,7,LEAVES:4)
Block(-4,27,7,LEAVES:4)
Block(2,27,7,LEAVES:12)
Block(-4,27,8,LEAVES:4)
Block(-7,28,-8,LEAVES:12)
Block(-4,28,-8,LEAVES:12)
Block(-1,28,-8,LEAVES:12)
Block(3,28,-8,LEAVES:12)
Block(-6,28,-7,LEAVES:12)
Block(-5,28,-7,LEAVES:4)
Block(-4,28,-7,LEAVES:12)
Block(-1,28,-7,LEAVES:12)
Block(3,28,-7,LEAVES:12)
Block(6,28,-7,LEAVES:12)
Block(-6,28,-6,LEAVES:12)
Block(-5,28,-6,LOG:12)
Block(-4,28,-6,LEAVES:12)
Block(-2,28,-6,LEAVES:12)
Block(4,28,-6,LEAVES:12)
Block(5,28,-6,LEAVES:12)
Block(-6,28,-5,LEAVES:12)
Block(-5,28,-5,LOG:12)
Block(-4,28,-5,LOG:12)
Block(-3,28,-5,LEAVES:12)
Block(0,28,-5,LEAVES:12)
Block(3,28,-5,LEAVES:12)
Block(4,28,-5,LOG:12)
Block(5,28,-5,LEAVES:4)
Block(6,28,-5,LEAVES:12)
Block(8,28,-5,LEAVES:12)
Block(-6,28,-4,LEAVES:12)
Block(-5,28,-4,LEAVES:12)
Block(-4,28,-4,LOG:12)
Block(-3,28,-4,LEAVES:12)
Block(-1,28,-4,LEAVES:12)
Block(0,28,-4,LEAVES:4)
Block(2,28,-4,LEAVES:12)
Block(3,28,-4,LEAVES:12)
Block(4,28,-4,LEAVES:12)
Block(5,28,-4,LEAVES:12)
Block(6,28,-4,LEAVES:12)
Block(7,28,-4,LEAVES:12)
Block(-5,28,-3,LEAVES:12)
Block(-4,28,-3,LOG:12)
Block(-3,28,-3,LEAVES:12)
Block(-2,28,-3,LEAVES:12)
Block(1,28,-3,LEAVES:12)
Block(2,28,-3,LEAVES:12)
Block(4,28,-3,LEAVES:12)
Block(-6,28,-2,LEAVES:4)
Block(-5,28,-2,LEAVES:4)
Block(-4,28,-2,LEAVES:4)
Block(-3,28,-2,LEAVES:4)
Block(-2,28,-2,LEAVES:4)
Block(-1,28,-2,LOG:12)
Block(0,28,-2,LOG:12)
Block(1,28,-2,LOG:12)
Block(2,28,-2,LEAVES:12)
Block(4,28,-2,LEAVES:12)
Block(-4,28,-1,LEAVES:4)
Block(-2,28,-1,LOG:12)
Block(-1,28,-1,LOG:12)
Block(0,28,-1,LOG:12)
Block(1,28,-1,LOG:12)
Block(2,28,-1,LEAVES:12)
Block(3,28,-1,LEAVES:12)
Block(6,28,-1,LEAVES:12)
Block(7,28,-1,LEAVES:12)
Block(8,28,-1,LEAVES:12)
Block(-4,28,0,LEAVES:12)
Block(-2,28,0,LEAVES:12)
Block(-1,28,0,LOG:12)
Block(0,28,0,LOG:12)
Block(1,28,0,LOG:12)
Block(2,28,0,LOG:12)
Block(3,28,0,LOG:12)
Block(4,28,0,LEAVES:12)
Block(5,28,0,LEAVES:12)
Block(-1,28,1,LEAVES:4)
Block(0,28,1,LOG:12)
Block(3,28,1,LEAVES:12)
Block(4,28,1,LEAVES:12)
Block(-1,28,2,LEAVES:4)
Block(0,28,2,LOG:12)
Block(1,28,2,LEAVES:4)
Block(-4,28,3,LEAVES:12)
Block(-2,28,3,LEAVES:12)
Block(-1,28,3,LOG:12)
Block(0,28,3,LOG:12)
Block(1,28,3,LEAVES:4)
Block(2,28,3,LEAVES:12)
Block(7,28,3,LEAVES:12)
Block(-4,28,4,LEAVES:12)
Block(-3,28,4,LEAVES:12)
Block(-2,28,4,LEAVES:12)
Block(-1,28,4,LOG:12)
Block(0,28,4,LEAVES:4)
Block(1,28,4,LEAVES:4)
Block(3,28,4,LEAVES:12)
Block(-4,28,5,LEAVES:12)
Block(-3,28,5,LEAVES:12)
Block(-2,28,5,LEAVES:12)
Block(-1,28,5,LEAVES:12)
Block(0,28,5,LEAVES:12)
Block(-5,28,6,LEAVES:12)
Block(-4,28,6,LEAVES:12)
Block(-3,28,6,LEAVES:12)
Block(-4,28,7,LEAVES:12)
Block(-3,29,-9,LEAVES:12)
Block(-2,29,-9,LEAVES:12)
Block(-3,29,-8,LEAVES:12)
Block(-5,29,-7,LEAVES:12)
Block(-4,29,-7,LEAVES:12)
Block(-6,29,-6,LEAVES:12)
Block(-5,29,-6,LEAVES:12)
Block(2,29,-6,LEAVES:12)
Block(4,29,-6,LEAVES:12)
Block(6,29,-6,LEAVES:12)
Block(-7,29,-5,LEAVES:12)
Block(-6,29,-5,LEAVES:12)
Block(-5,29,-5,LEAVES:12)
Block(-4,29,-5,LEAVES:12)
Block(2,29,-5,LEAVES:12)
Block(3,29,-5,LEAVES:12)
Block(4,29,-5,LOG:12)
Block(5,29,-5,LEAVES:12)
Block(-5,29,-4,LEAVES:12)
Block(-4,29,-4,LEAVES:12)
Block(-3,29,-4,LEAVES:12)
Block(-2,29,-4,LEAVES:12)
Block(1,29,-4,LEAVES:12)
Block(2,29,-4,LOG:12)
Block(3,29,-4,LOG:12)
Block(4,29,-4,LOG:12)
Block(5,29,-4,LEAVES:12)
Block(6,29,-4,LEAVES:12)
Block(-6,29,-3,LEAVES:12)
Block(-5,29,-3,LEAVES:12)
Block(-4,29,-3,LOG:12)
Block(-3,29,-3,LOG:12)
Block(-2,29,-3,LOG:12)
Block(0,29,-3,LEAVES:4)
Block(1,29,-3,LOG:12)
Block(2,29,-3,LOG:12)
Block(3,29,-3,LEAVES:12)
Block(4,29,-3,LEAVES:12)
Block(5,29,-3,LEAVES:12)
Block(-7,29,-2,LEAVES:12)
Block(-4,29,-2,LEAVES:12)
Block(-3,29,-2,LEAVES:12)
Block(-2,29,-2,LOG:12)
Block(-1,29,-2,LOG:12)
Block(0,29,-2,LOG:12)
Block(1,29,-2,LOG:12)
Block(2,29,-2,LEAVES:12)
Block(3,29,-2,LEAVES:12)
Block(-5,29,-1,LEAVES:12)
Block(-2,29,-1,LOG:12)
Block(-1,29,-1,LOG:12)
Block(0,29,-1,LOG:12)
Block(1,29,-1,LOG:12)
Block(-1,29,0,LOG:12)
Block(0,29,0,LOG:12)
Block(2,29,0,LEAVES:12)
Block(3,29,0,LEAVES:12)
Block(-1,29,1,LEAVES:4)
Block(0,29,1,LOG:12)
Block(0,29,2,LEAVES:4)
Block(6,29,2,LEAVES:12)
Block(-6,29,3,LEAVES:12)
Block(-5,29,3,LEAVES:12)
Block(-1,29,3,LEAVES:4)
Block(0,29,3,LEAVES:4)
Block(1,29,3,LEAVES:4)
Block(5,29,3,LEAVES:12)
Block(6,29,3,LEAVES:12)
Block(-4,29,4,LEAVES:12)
Block(-2,29,4,LEAVES:12)
Block(-1,29,4,LEAVES:4)
Block(0,29,4,LEAVES:4)
Block(6,29,4,LEAVES:12)
Block(-5,29,5,LEAVES:12)
Block(-4,29,5,LEAVES:12)
Block(-3,29,5,LEAVES:12)
Block(-1,29,5,LEAVES:12)
Block(0,29,5,LEAVES:12)
Block(-6,29,6,LEAVES:12)
Block(-5,29,6,LEAVES:12)
Block(-1,29,6,LEAVES:4)
Block(-6,29,7,LEAVES:12)
Block(-3,29,7,LEAVES:12)
Block(0,29,7,LEAVES:12)
Block(-3,30,-7,LEAVES:12)
Block(-4,30,-6,LEAVES:12)
Block(-5,30,-5,LEAVES:12)
Block(-4,30,-5,LEAVES:12)
Block(3,30,-5,LEAVES:12)
Block(4,30,-5,LEAVES:12)
Block(-4,30,-4,LEAVES:12)
Block(-3,30,-4,LEAVES:12)
Block(0,30,-4,LEAVES:12)
Block(2,30,-4,LEAVES:12)
Block(3,30,-4,LEAVES:12)
Block(4,30,-4,LEAVES:12)
Block(5,30,-4,LEAVES:12)
Block(-4,30,-3,LEAVES:12)
Block(-3,30,-3,LEAVES:12)
Block(-2,30,-3,LEAVES:12)
Block(-1,30,-3,LEAVES:12)
Block(0,30,-3,LEAVES:4)
Block(1,30,-3,LEAVES:12)
Block(2,30,-3,LEAVES:12)
Block(3,30,-3,LEAVES:12)
Block(-3,30,-2,LEAVES:12)
Block(-1,30,-2,LOG:12)
Block(0,30,-2,LOG:12)
Block(1,30,-2,LOG:12)
Block(5,30,-2,LEAVES:12)
Block(6,30,-2,LEAVES:12)
Block(-2,30,-1,LOG:12)
Block(-1,30,-1,LOG:12)
Block(0,30,-1,LOG:12)
Block(1,30,-1,LOG:12)
Block(-5,30,0,LEAVES:12)
Block(-4,30,0,LEAVES:12)
Block(-2,30,0,LOG:12)
Block(-1,30,0,LOG:12)
Block(0,30,0,LOG:12)
Block(2,30,0,LEAVES:12)
Block(7,30,0,LEAVES:12)
Block(-7,30,1,LEAVES:12)
Block(-6,30,1,LEAVES:12)
Block(-2,30,1,LEAVES:12)
Block(-1,30,1,LOG:12)
Block(0,30,1,LOG:12)
Block(1,30,1,LEAVES:4)
Block(2,30,1,LEAVES:12)
Block(3,30,1,LEAVES:12)
Block(4,30,1,LEAVES:12)
Block(5,30,1,LEAVES:12)
Block(6,30,1,LEAVES:12)
Block(-1,30,2,LEAVES:4)
Block(3,30,2,LEAVES:12)
Block(4,30,2,LOG:12)
Block(5,30,2,LOG:12)
Block(6,30,2,LOG:12)
Block(7,30,2,LEAVES:12)
Block(4,30,3,LEAVES:12)
Block(5,30,3,LEAVES:12)
Block(6,30,3,LEAVES:12)
Block(7,30,3,LEAVES:12)
Block(1,30,4,LEAVES:4)
Block(5,30,4,LEAVES:12)
Block(7,30,4,LEAVES:4)
Block(1,30,5,LEAVES:4)
Block(2,30,5,LEAVES:12)
Block(7,30,5,LEAVES:4)
Block(2,30,6,LEAVES:12)
Block(-1,31,-9,LEAVES:12)
Block(0,31,-9,LEAVES:12)
Block(-1,31,-8,LEAVES:12)
Block(-3,31,-3,LEAVES:12)
Block(-1,31,-3,LOG:12)
Block(0,31,-3,LEAVES:4)
Block(-7,31,-2,LEAVES:12)
Block(-4,31,-2,LEAVES:12)
Block(-3,31,-2,LEAVES:12)
Block(-2,31,-2,LEAVES:12)
Block(-1,31,-2,LOG:12)
Block(0,31,-2,LOG:12)
Block(1,31,-2,LOG:12)
Block(-7,31,-1,LEAVES:12)
Block(-6,31,-1,LEAVES:12)
Block(-5,31,-1,LEAVES:12)
Block(-4,31,-1,LOG:12)
Block(-3,31,-1,LOG:12)
Block(-2,31,-1,LOG:12)
Block(-1,31,-1,LOG:12)
Block(0,31,-1,LOG:12)
Block(1,31,-1,LOG:12)
Block(2,31,-1,LEAVES:12)
Block(-6,31,0,LEAVES:12)
Block(-5,31,0,LOG:12)
Block(-4,31,0,LOG:12)
Block(-2,31,0,LOG:12)
Block(-1,31,0,LOG:12)
Block(0,31,0,LOG:12)
Block(1,31,0,LOG:12)
Block(2,31,0,LOG:12)
Block(3,31,0,LEAVES:12)
Block(4,31,0,LEAVES:12)
Block(-5,31,1,LEAVES:12)
Block(-4,31,1,LEAVES:12)
Block(-1,31,1,LOG:12)
Block(0,31,1,LEAVES:4)
Block(1,31,1,LEAVES:4)
Block(2,31,1,LOG:12)
Block(3,31,1,LOG:12)
Block(4,31,1,LOG:12)
Block(5,31,1,LEAVES:12)
Block(7,31,1,LEAVES:12)
Block(2,31,2,LEAVES:12)
Block(3,31,2,LEAVES:12)
Block(4,31,2,LOG:12)
Block(5,31,2,LEAVES:12)
Block(6,31,2,LEAVES:12)
Block(3,31,3,LEAVES:12)
Block(4,31,3,LEAVES:12)
Block(5,31,3,LEAVES:12)
Block(-6,31,4,LEAVES:12)
Block(-5,31,4,LEAVES:12)
Block(-6,31,5,LEAVES:12)
Block(-5,31,5,LEAVES:12)
Block(-6,31,6,LEAVES:12)
Block(-2,32,-9,LEAVES:12)
Block(-1,32,-9,LEAVES:12)
Block(-2,32,-8,LEAVES:12)
Block(-1,32,-8,LEAVES:12)
Block(3,32,-8,LEAVES:12)
Block(-3,32,-7,LEAVES:12)
Block(-2,32,-7,LEAVES:12)
Block(-1,32,-7,LEAVES:12)
Block(2,32,-7,LEAVES:12)
Block(6,32,-7,LEAVES:12)
Block(-2,32,-6,LEAVES:12)
Block(1,32,-6,LEAVES:12)
Block(5,32,-6,LEAVES:12)
Block(6,32,-6,LEAVES:12)
Block(4,32,-5,LEAVES:12)
Block(5,32,-5,LEAVES:12)
Block(6,32,-5,LEAVES:12)
Block(-1,32,-4,LEAVES:12)
Block(5,32,-4,LEAVES:12)
Block(-5,32,-3,LEAVES:12)
Block(-2,32,-3,LEAVES:12)
Block(-1,32,-3,LOG:12)
Block(5,32,-3,LEAVES:12)
Block(6,32,-3,LEAVES:12)
Block(7,32,-3,LEAVES:12)
Block(-4,32,-2,LEAVES:12)
Block(-1,32,-2,LOG:12)
Block(0,32,-2,LOG:12)
Block(-4,32,-1,LEAVES:12)
Block(-3,32,-1,LEAVES:12)
Block(-2,32,-1,LOG:12)
Block(-1,32,-1,LOG:12)
Block(0,32,-1,LOG:12)
Block(1,32,-1,LOG:12)
Block(5,32,-1,LEAVES:12)
Block(-5,32,0,LEAVES:12)
Block(-4,32,0,LEAVES:12)
Block(-2,32,0,LOG:12)
Block(-1,32,0,LOG:12)
Block(0,32,0,LOG:12)
Block(2,32,0,LEAVES:12)
Block(3,32,0,LEAVES:12)
Block(5,32,0,LEAVES:12)
Block(-2,32,1,LEAVES:12)
Block(-1,32,1,LEAVES:4)
Block(2,32,1,LEAVES:12)
Block(3,32,1,LEAVES:12)
Block(4,32,1,LEAVES:12)
Block(-4,32,2,LEAVES:12)
Block(-2,32,2,LEAVES:12)
Block(3,32,2,LEAVES:12)
Block(4,32,2,LEAVES:12)
Block(5,32,2,LEAVES:12)
Block(-5,32,3,LEAVES:12)
Block(-4,32,3,LEAVES:12)
Block(-1,32,3,LEAVES:4)
Block(4,32,3,LEAVES:12)
Block(-6,32,4,LEAVES:12)
Block(-5,32,4,LOG:12)
Block(0,32,4,LEAVES:4)
Block(4,32,4,LEAVES:12)
Block(-5,32,5,LEAVES:12)
Block(-3,32,5,LEAVES:12)
Block(5,32,5,LEAVES:12)
Block(-7,32,6,LEAVES:12)
Block(-6,32,6,LEAVES:12)
Block(-5,32,6,LEAVES:12)
Block(-3,32,6,LEAVES:12)
Block(-2,32,6,LEAVES:12)
Block(-6,32,7,LEAVES:12)
Block(-5,32,7,LEAVES:12)
Block(-2,32,7,LEAVES:12)
Block(-3,33,-10,LEAVES:12)
Block(-1,33,-10,LEAVES:4)
Block(2,33,-10,LEAVES:12)
Block(-2,33,-9,LEAVES:12)
Block(-1,33,-9,LEAVES:12)
Block(0,33,-9,LEAVES:12)
Block(1,33,-9,LEAVES:12)
Block(-5,33,-8,LEAVES:12)
Block(-3,33,-8,LEAVES:12)
Block(-2,33,-8,LOG:12)
Block(-1,33,-8,LEAVES:4)
Block(6,33,-8,LEAVES:12)
Block(-4,33,-7,LEAVES:12)
Block(-3,33,-7,LEAVES:12)
Block(-2,33,-7,LOG:12)
Block(-1,33,-7,LEAVES:12)
Block(0,33,-7,LEAVES:12)
Block(5,33,-7,LEAVES:12)
Block(6,33,-7,LEAVES:12)
Block(7,33,-7,LEAVES:12)
Block(-4,33,-6,LEAVES:12)
Block(-3,33,-6,LEAVES:12)
Block(-2,33,-6,LOG:12)
Block(-1,33,-6,LEAVES:12)
Block(0,33,-6,LEAVES:12)
Block(1,33,-6,LEAVES:12)
Block(4,33,-6,LEAVES:12)
Block(5,33,-6,LEAVES:12)
Block(-3,33,-5,LEAVES:12)
Block(-2,33,-5,LOG:12)
Block(-1,33,-5,LOG:12)
Block(0,33,-5,LEAVES:12)
Block(4,33,-5,LOG:12)
Block(5,33,-5,LOG:12)
Block(6,33,-5,LEAVES:12)
Block(7,33,-5,LEAVES:12)
Block(3,33,-4,LEAVES:12)
Block(4,33,-4,LOG:12)
Block(5,33,-4,LEAVES:12)
Block(6,33,-4,LEAVES:12)
Block(-6,33,-3,LEAVES:12)
Block(-1,33,-3,LOG:12)
Block(0,33,-3,LOG:12)
Block(2,33,-3,LEAVES:12)
Block(3,33,-3,LOG:12)
Block(4,33,-3,LOG:12)
Block(-7,33,-2,LEAVES:12)
Block(-2,33,-2,LOG:12)
Block(-1,33,-2,LOG:12)
Block(0,33,-2,LOG:12)
Block(3,33,-2,LEAVES:12)
Block(-2,33,-1,LOG:12)
Block(-1,33,-1,LOG:12)
Block(0,33,-1,LOG:12)
Block(-3,33,0,LEAVES:12)
Block(-2,33,0,LOG:12)
Block(-1,33,0,LOG:12)
Block(0,33,0,LOG:12)
Block(-5,33,1,LEAVES:12)
Block(-4,33,1,LOG:12)
Block(-3,33,1,LOG:12)
Block(-2,33,1,LOG:12)
Block(-1,33,1,LEAVES:4)
Block(0,33,1,LEAVES:4)
Block(3,33,1,LEAVES:12)
Block(-5,33,2,LOG:12)
Block(-4,33,2,LOG:12)
Block(-3,33,2,LEAVES:12)
Block(-2,33,2,LEAVES:12)
Block(-1,33,2,LEAVES:4)
Block(-6,33,3,LEAVES:12)
Block(-5,33,3,LOG:12)
Block(-4,33,3,LEAVES:12)
Block(-3,33,3,LEAVES:12)
Block(-7,33,4,LEAVES:12)
Block(-6,33,4,LEAVES:12)
Block(-5,33,4,LOG:12)
Block(-4,33,4,LEAVES:12)
Block(-3,33,4,LEAVES:12)
Block(-6,33,5,LEAVES:12)
Block(-5,33,5,LEAVES:12)
Block(-4,33,5,LEAVES:12)
Block(-6,33,6,LEAVES:12)
Block(-1,34,-9,LEAVES:12)
Block(-2,34,-8,LEAVES:12)
Block(-1,34,-8,LEAVES:12)
Block(-3,34,-7,LEAVES:12)
Block(-2,34,-7,LEAVES:12)
Block(-1,34,-7,LEAVES:12)
Block(0,34,-7,LEAVES:12)
Block(-6,34,-6,LEAVES:12)
Block(-5,34,-6,LEAVES:12)
Block(-3,34,-6,LEAVES:12)
Block(-2,34,-6,LEAVES:12)
Block(0,34,-6,LEAVES:12)
Block(5,34,-6,LEAVES:12)
Block(6,34,-6,LEAVES:12)
Block(-2,34,-5,LEAVES:12)
Block(-1,34,-5,LOG:12)
Block(0,34,-5,LEAVES:12)
Block(4,34,-5,LEAVES:12)
Block(5,34,-5,LEAVES:12)
Block(6,34,-5,LEAVES:12)
Block(-7,34,-4,LEAVES:4)
Block(-6,34,-4,LEAVES:4)
Block(-2,34,-4,LEAVES:12)
Block(-1,34,-4,LOG:12)
Block(0,34,-4,LEAVES:12)
Block(2,34,-4,LEAVES:12)
Block(3,34,-4,LEAVES:12)
Block(4,34,-4,LEAVES:12)
Block(5,34,-4,LEAVES:12)
Block(7,34,-4,LEAVES:12)
Block(-6,34,-3,LEAVES:4)
Block(-5,34,-3,LOG:12)
Block(-3,34,-3,LEAVES:12)
Block(-1,34,-3,LOG:12)
Block(0,34,-3,LOG:12)
Block(2,34,-3,LEAVES:12)
Block(3,34,-3,LOG:12)
Block(4,34,-3,LEAVES:12)
Block(-8,34,-2,LEAVES:4)
Block(-7,34,-2,LEAVES:12)
Block(-5,34,-2,LOG:12)
Block(-4,34,-2,LEAVES:12)
Block(-3,34,-2,LEAVES:12)
Block(-2,34,-2,LOG:12)
Block(-1,34,-2,LOG:12)
Block(0,34,-2,LOG:12)
Block(1,34,-2,LOG:12)
Block(2,34,-2,LOG:12)
Block(3,34,-2,LOG:12)
Block(4,34,-2,LEAVES:12)
Block(-7,34,-1,LEAVES:12)
Block(-5,34,-1,LEAVES:12)
Block(-3,34,-1,LEAVES:12)
Block(-2,34,-1,LOG:12)
Block(-1,34,-1,LOG:12)
Block(0,34,-1,LOG:12)
Block(1,34,-1,LEAVES:4)
Block(4,34,-1,LEAVES:12)
Block(5,34,-1,LEAVES:12)
Block(-2,34,0,LEAVES:12)
Block(-1,34,0,LOG:12)
Block(0,34,0,LOG:12)
Block(-4,34,1,LEAVES:12)
Block(-3,34,1,LEAVES:12)
Block(-2,34,1,LEAVES:12)
Block(-1,34,1,LEAVES:4)
Block(-5,34,2,LEAVES:12)
Block(-4,34,2,LEAVES:12)
Block(-3,34,2,LEAVES:12)
Block(-2,34,2,LEAVES:12)
Block(-5,34,3,LEAVES:12)
Block(-4,34,3,LEAVES:12)
Block(-3,34,3,LEAVES:12)
Block(-6,34,4,LEAVES:12)
Block(-5,34,4,LEAVES:12)
Block(-4,34,4,LEAVES:12)
Block(-5,34,5,LEAVES:12)
Block(-3,35,-9,LEAVES:12)
Block(2,35,-9,LEAVES:12)
Block(-3,35,-8,LEAVES:12)
Block(1,35,-8,LEAVES:12)
Block(-2,35,-7,LEAVES:12)
Block(0,35,-7,LEAVES:12)
Block(1,35,-7,LEAVES:12)
Block(-2,35,-6,LEAVES:12)
Block(-1,35,-6,LEAVES:12)
Block(5,35,-6,LEAVES:12)
Block(-2,35,-5,LEAVES:12)
Block(-1,35,-5,LEAVES:12)
Block(0,35,-5,LEAVES:12)
Block(2,35,-5,LEAVES:12)
Block(-1,35,-4,LEAVES:12)
Block(3,35,-4,LEAVES:12)
Block(-6,35,-3,LEAVES:4)
Block(-5,35,-3,LEAVES:12)
Block(-4,35,-3,LEAVES:12)
Block(-3,35,-3,LEAVES:12)
Block(-2,35,-3,LEAVES:12)
Block(0,35,-3,LOG:12)
Block(3,35,-3,LEAVES:12)
Block(4,35,-3,LEAVES:12)
Block(-6,35,-2,LEAVES:12)
Block(-5,35,-2,LOG:12)
Block(-4,35,-2,LOG:12)
Block(-3,35,-2,LOG:12)
Block(-2,35,-2,LOG:12)
Block(-1,35,-2,LOG:12)
Block(0,35,-2,LOG:12)
Block(1,35,-2,LOG:12)
Block(3,35,-2,LEAVES:12)
Block(-6,35,-1,LEAVES:12)
Block(-5,35,-1,LEAVES:12)
Block(-4,35,-1,LEAVES:12)
Block(-3,35,-1,LEAVES:12)
Block(-2,35,-1,LOG:12)
Block(-1,35,-1,LOG:12)
Block(0,35,-1,LOG:12)
Block(-6,35,0,LEAVES:12)
Block(-2,35,0,LEAVES:12)
Block(-1,35,0,LOG:12)
Block(0,35,0,LEAVES:4)
Block(1,35,0,LEAVES:4)
Block(2,35,0,LEAVES:4)
Block(-7,35,1,LEAVES:12)
Block(1,35,1,LEAVES:4)
Block(2,35,1,LEAVES:4)
Block(3,35,1,LEAVES:4)
Block(-3,35,2,LEAVES:12)
Block(0,35,2,LEAVES:4)
Block(2,35,2,LEAVES:4)
Block(0,35,3,LEAVES:4)
Block(-1,35,4,LEAVES:4)
Block(2,35,4,LEAVES:4)
Block(-6,35,5,LEAVES:12)
Block(2,35,5,LEAVES:4)
Block(-5,36,-5,LEAVES:12)
Block(-4,36,-4,LEAVES:12)
Block(0,36,-4,LEAVES:12)
Block(-4,36,-3,LEAVES:12)
Block(-3,36,-3,LEAVES:12)
Block(-2,36,-3,LEAVES:12)
Block(0,36,-3,LOG:12)
Block(2,36,-3,LEAVES:12)
Block(-6,36,-2,LEAVES:12)
Block(-5,36,-2,LEAVES:12)
Block(-4,36,-2,LEAVES:12)
Block(-3,36,-2,LEAVES:12)
Block(-2,36,-2,LOG:12)
Block(-1,36,-2,LOG:12)
Block(0,36,-2,LOG:12)
Block(1,36,-2,LOG:12)
Block(-5,36,-1,LEAVES:12)
Block(-4,36,-1,LEAVES:12)
Block(-3,36,-1,LEAVES:12)
Block(-2,36,-1,LOG:12)
Block(-1,36,-1,LOG:12)
Block(0,36,-1,LOG:12)
Block(1,36,-1,LOG:12)
Block(2,36,-1,LEAVES:12)
Block(-1,36,0,LOG:12)
Block(0,36,0,LEAVES:4)
Block(1,36,0,LOG:12)
Block(3,36,0,LEAVES:4)
Block(4,36,0,LEAVES:4)
Block(-1,36,1,LEAVES:4)
Block(0,36,1,LEAVES:4)
Block(1,36,1,LOG:12)
Block(2,36,1,LOG:12)
Block(3,36,1,LEAVES:4)
Block(1,36,2,LEAVES:4)
Block(2,36,2,LEAVES:4)
Block(3,36,2,LEAVES:4)
Block(4,36,2,LEAVES:4)
Block(3,36,3,LEAVES:4)
Block(3,36,4,LEAVES:4)
Block(-5,37,-3,LEAVES:12)
Block(-1,37,-3,LEAVES:4)
Block(0,37,-3,LOG:12)
Block(-4,37,-2,LEAVES:12)
Block(-3,37,-2,LEAVES:12)
Block(-2,37,-2,LOG:12)
Block(-1,37,-2,LOG:12)
Block(0,37,-2,LOG:12)
Block(1,37,-2,LOG:12)
Block(-1,37,-1,LOG:12)
Block(0,37,-1,LOG:12)
Block(4,37,-1,LEAVES:12)
Block(5,37,-1,LEAVES:12)
Block(-5,37,0,LEAVES:12)
Block(-4,37,0,LEAVES:12)
Block(-1,37,0,LOG:12)
Block(1,37,0,LEAVES:4)
Block(2,37,0,LEAVES:4)
Block(-6,37,1,LEAVES:12)
Block(-5,37,1,LEAVES:12)
Block(2,37,1,LEAVES:4)
Block(3,37,1,LEAVES:4)
Block(4,37,2,LEAVES:4)
Block(5,37,3,LEAVES:4)
Block(-5,37,4,LEAVES:4)
Block(-4,37,4,LEAVES:4)
Block(4,38,-7,LEAVES:4)
Block(2,38,-6,LEAVES:4)
Block(4,38,-6,LEAVES:4)
Block(-3,38,-5,LEAVES:12)
Block(1,38,-5,LEAVES:4)
Block(2,38,-5,LEAVES:4)
Block(3,38,-5,LEAVES:4)
Block(-3,38,-4,LEAVES:12)
Block(-2,38,-4,LEAVES:12)
Block(1,38,-4,LEAVES:4)
Block(2,38,-4,LEAVES:4)
Block(3,38,-4,LEAVES:4)
Block(4,38,-4,LEAVES:4)
Block(5,38,-4,LEAVES:4)
Block(-2,38,-3,LEAVES:12)
Block(0,38,-3,LOG:12)
Block(2,38,-3,LEAVES:4)
Block(-2,38,-2,LOG:12)
Block(-1,38,-2,LOG:12)
Block(0,38,-2,LOG:12)
Block(1,38,-2,LOG:12)
Block(-2,38,-1,LEAVES:12)
Block(-1,38,-1,LOG:12)
Block(0,38,-1,LOG:12)
Block(-3,38,0,LEAVES:12)
Block(-1,38,0,LEAVES:4)
Block(0,38,0,LEAVES:4)
Block(-4,38,1,LEAVES:12)
Block(-2,38,1,LEAVES:12)
Block(-3,38,2,LEAVES:4)
Block(-1,38,2,LEAVES:4)
Block(2,38,2,LEAVES:4)
Block(-4,38,3,LEAVES:4)
Block(-3,38,3,LEAVES:4)
Block(-1,38,3,LEAVES:4)
Block(2,39,-8,LEAVES:4)
Block(2,39,-7,LEAVES:4)
Block(1,39,-6,LEAVES:4)
Block(2,39,-6,LEAVES:4)
Block(3,39,-6,LEAVES:4)
Block(-1,39,-5,LEAVES:4)
Block(1,39,-5,LEAVES:4)
Block(2,39,-5,LOG:12)
Block(0,39,-4,LEAVES:4)
Block(1,39,-4,LOG:12)
Block(2,39,-4,LOG:12)
Block(3,39,-4,LEAVES:4)
Block(-2,39,-3,LEAVES:4)
Block(1,39,-3,LOG:12)
Block(2,39,-3,LEAVES:4)
Block(3,39,-3,LEAVES:4)
Block(4,39,-3,LEAVES:4)
Block(-2,39,-2,LOG:12)
Block(-1,39,-2,LOG:12)
Block(0,39,-2,LOG:12)
Block(1,39,-2,LOG:12)
Block(3,39,-2,LEAVES:4)
Block(-3,39,-1,LEAVES:4)
Block(-2,39,-1,LEAVES:4)
Block(-1,39,-1,LOG:12)
Block(0,39,-1,LOG:12)
Block(1,39,-1,LEAVES:4)
Block(4,39,-1,LEAVES:4)
Block(-4,39,0,LEAVES:4)
Block(-3,39,0,LEAVES:4)
Block(-2,39,0,LOG:12)
Block(-1,39,0,LOG:12)
Block(0,39,0,LEAVES:4)
Block(1,39,0,LEAVES:4)
Block(2,39,0,LEAVES:4)
Block(-5,39,1,LEAVES:4)
Block(-4,39,1,LEAVES:4)
Block(-3,39,1,LOG:12)
Block(-2,39,1,LOG:12)
Block(-1,39,1,LEAVES:4)
Block(3,39,1,LEAVES:4)
Block(-4,39,2,LEAVES:4)
Block(-3,39,2,LEAVES:4)
Block(-2,39,2,LEAVES:4)
Block(2,40,-6,LEAVES:4)
Block(1,40,-5,LEAVES:4)
Block(2,40,-5,LEAVES:4)
Block(1,40,-4,LEAVES:4)
Block(2,40,-4,LEAVES:4)
Block(3,40,-4,LEAVES:4)
Block(-5,40,-3,LEAVES:4)
Block(-4,40,-3,LEAVES:4)
Block(-1,40,-3,LEAVES:4)
Block(2,40,-3,LEAVES:4)
Block(-4,40,-2,LEAVES:4)
Block(-2,40,-2,LEAVES:4)
Block(-1,40,-2,LOG:12)
Block(0,40,-2,LOG:12)
Block(1,40,-2,LOG:12)
Block(-3,40,-1,LEAVES:4)
Block(-1,40,-1,LOG:12)
Block(1,40,-1,LEAVES:4)
Block(-6,40,0,LEAVES:4)
Block(-5,40,0,LEAVES:4)
Block(-3,40,0,LEAVES:4)
Block(-2,40,0,LEAVES:4)
Block(-1,40,0,LEAVES:4)
Block(-4,40,1,LEAVES:4)
Block(-3,40,1,LEAVES:4)
Block(-2,40,1,LEAVES:4)
Block(1,40,1,LEAVES:4)
Block(-3,40,2,LEAVES:4)
Block(4,41,-7,LEAVES:4)
Block(-1,41,-6,LEAVES:4)
Block(3,41,-6,LEAVES:4)
Block(4,41,-6,LEAVES:4)
Block(-1,41,-5,LEAVES:4)
Block(3,41,-5,LEAVES:4)
Block(2,41,-4,LEAVES:4)
Block(-1,41,-3,LEAVES:4)
Block(0,41,-3,LEAVES:4)
Block(-1,41,-2,LOG:12)
Block(0,41,-2,LOG:12)
Block(1,41,-2,LEAVES:4)
Block(2,41,-2,LEAVES:4)
Block(3,41,-2,LEAVES:4)
Block(-2,41,-1,LEAVES:4)
Block(-1,41,-1,LOG:12)
Block(0,41,-1,LEAVES:4)
Block(3,41,-1,LEAVES:4)
Block(4,41,-1,LEAVES:4)
Block(-3,41,0,LEAVES:4)
Block(-1,41,0,LEAVES:4)
Block(-4,41,1,LEAVES:4)
Block(-2,41,2,LEAVES:4)
Block(-4,42,-5,LEAVES:4)
Block(-1,42,-5,LEAVES:4)
Block(0,42,-5,LEAVES:4)
Block(-5,42,-4,LEAVES:4)
Block(-4,42,-4,LEAVES:4)
Block(0,42,-4,LEAVES:4)
Block(-4,42,-3,LEAVES:4)
Block(-1,42,-3,LEAVES:4)
Block(0,42,-3,LOG:12)
Block(1,42,-3,LEAVES:4)
Block(-2,42,-2,LEAVES:4)
Block(-1,42,-2,LOG:12)
Block(0,42,-2,LOG:12)
Block(0,42,-1,LEAVES:4)
Block(-2,42,0,LEAVES:4)
Block(-1,42,0,LEAVES:4)
Block(0,42,0,LEAVES:4)
Block(1,42,0,LEAVES:4)
Block(-2,42,1,LEAVES:4)
Block(2,42,1,LEAVES:4)
Block(3,42,1,LEAVES:4)
Block(3,42,2,LEAVES:4)
Block(4,42,2,LEAVES:4)
Block(0,42,3,LEAVES:4)
Block(0,42,4,LEAVES:4)
Block(0,43,-6,LEAVES:4)
Block(0,43,-5,LEAVES:4)
Block(2,43,-5,LEAVES:4)
Block(0,43,-4,LEAVES:4)
Block(1,43,-4,LEAVES:4)
Block(2,43,-4,LEAVES:4)
Block(3,43,-4,LEAVES:4)
Block(-4,43,-3,LEAVES:4)
Block(-3,43,-3,LEAVES:4)
Block(0,43,-3,LEAVES:4)
Block(-4,43,-2,LEAVES:4)
Block(-3,43,-2,LEAVES:4)
Block(-2,43,-2,LEAVES:4)
Block(-1,43,-2,LOG:12)
Block(0,43,-2,LOG:12)
Block(1,43,-2,LEAVES:4)
Block(-1,43,-1,LEAVES:4)
Block(0,43,-1,LOG:12)
Block(1,43,-1,LEAVES:4)
Block(-1,43,0,LEAVES:4)
Block(0,43,0,LOG:12)
Block(1,43,0,LOG:12)
Block(2,43,0,LEAVES:4)
Block(0,43,1,LEAVES:4)
Block(1,43,1,LEAVES:4)
Block(2,43,1,LEAVES:4)
Block(1,43,2,LEAVES:4)
Block(1,43,3,LEAVES:4)
Block(-3,44,-5,LEAVES:12)
Block(-2,44,-4,LEAVES:12)
Block(1,44,-4,LEAVES:4)
Block(-2,44,-3,LEAVES:4)
Block(-1,44,-3,LEAVES:4)
Block(-1,44,-2,LEAVES:4)
Block(0,44,-2,LOG:12)
Block(-4,44,-1,LEAVES:12)
Block(-3,44,-1,LEAVES:4)
Block(-1,44,-1,LEAVES:4)
Block(0,44,-1,LEAVES:4)
Block(0,44,0,LEAVES:4)
Block(1,44,0,LEAVES:4)
Block(-2,44,1,LEAVES:4)
Block(-1,44,1,LEAVES:4)
Block(-1,44,2,LEAVES:4)
Block(-1,45,-5,LEAVES:12)
Block(-1,45,-4,LEAVES:12)
Block(0,45,-4,LEAVES:4)
Block(-5,45,-3,LEAVES:4)
Block(-4,45,-3,LEAVES:4)
Block(-2,45,-3,LEAVES:4)
Block(0,45,-3,LEAVES:4)
Block(2,45,-3,LEAVES:4)
Block(-4,45,-2,LEAVES:12)
Block(0,45,-2,LOG:12)
Block(1,45,-2,LEAVES:4)
Block(-4,45,-1,LEAVES:12)
Block(-2,45,-1,LEAVES:4)
Block(0,45,-1,LEAVES:4)
Block(-2,45,0,LEAVES:4)
Block(1,45,1,LEAVES:4)
Block(-2,46,-4,LEAVES:4)
Block(-1,46,-4,LEAVES:4)
Block(-3,46,-3,LEAVES:4)
Block(-2,46,-3,LEAVES:4)
Block(0,46,-3,LEAVES:4)
Block(1,46,-3,LEAVES:4)
Block(-1,46,-2,LOG:12)
Block(0,46,-2,LOG:12)
Block(1,46,-2,LEAVES:4)
Block(-3,46,-1,LEAVES:4)
Block(-2,46,-1,LEAVES:4)
Block(-1,46,-1,LEAVES:4)
Block(1,46,-1,LEAVES:4)
Block(-3,46,0,LEAVES:4)
Block(-2,46,0,LEAVES:4)
Block(0,46,0,LEAVES:4)
Block(1,46,0,LEAVES:4)
Block(2,46,0,LEAVES:4)
Block(-1,47,-4,LEAVES:4)
Block(-1,47,-3,LEAVES:4)
Block(-4,47,-2,LEAVES:4)
Block(-3,47,-2,LEAVES:4)
Block(-2,47,-2,LEAVES:4)
Block(-1,47,-2,LOG:12)
Block(0,47,-2,LEAVES:4)
Block(-2,47,-1,LEAVES:4)
Block(-1,47,-1,LEAVES:4)
Block(0,47,0,LEAVES:4)
Block(0,47,1,LEAVES:4)
Block(0,48,-4,LEAVES:12)
Block(-2,48,-3,LEAVES:12)
Block(-1,48,-3,LEAVES:12)
Block(-2,48,-2,LEAVES:4)
Block(-1,48,-2,LOG:12)
Block(0,48,-2,LEAVES:4)
Block(1,48,-2,LEAVES:4)
Block(-3,48,-1,LEAVES:4)
Block(0,48,-1,LEAVES:4)
Block(1,48,-1,LEAVES:4)
Block(-2,48,0,LEAVES:4)
Block(-1,48,0,LEAVES:4)
Block(-2,49,-3,LEAVES:4)
Block(0,49,-3,LEAVES:12)
Block(-2,49,-2,LEAVES:12)
Block(-1,49,-2,LOG:12)
Block(0,49,-2,LEAVES:4)
Block(-2,49,-1,LEAVES:4)
Block(-1,49,-1,LEAVES:4)
Block(0,49,-1,LEAVES:4)
Block(-1,50,-3,LEAVES:12)
Block(-2,50,-2,LEAVES:4)
Block(-1,50,-2,LEAVES:12)
Block(0,50,-2,LEAVES:12)
Block(-1,50,-1,LEAVES:4)
Block(-1,51,-2,LEAVES:12)

#######################################################################
# +-----------------------------------------------------------------+ #
# |                            BO3 checks                           | #
# +-----------------------------------------------------------------+ #
#######################################################################

# Require a condition at a certain location in order for the BO3 to be spawned.
# BlockCheck(x,y,z,BlockName[,BlockName[,...]]) - one of the blocks must be at the location
# BlockCheckNot(x,y,z,BlockName[,BlockName[,...]]) - all the blocks must not be at the location
# LightCheck(x,y,z,minLightLevel,maxLightLevel) - light must be between min and max (inclusive)

# You can use "Solid" as a BlockName for matching all solid blocks or "All" to match all blocks that aren't air.

# Examples:
BlockCheck(0,-1,0,GRASS,DIRT,DIRT:2,STONE,CLAY)
#   BlockCheck(0,-1,0,Solid)       Require any solid block just below the object
#   BlockCheck(0,-1,0,WOOL)        Require any type of wool just below the object
#   BlockCheck(0,-1,0,WOOL:0)      Require white wool just below the object
#   BlockCheckNot(0,-1,0,WOOL:0)   Require that there is no white wool below the object
#   LightCheck(0,0,0,0,1)          Require almost complete darkness just below the object

#######################################################################
# +-----------------------------------------------------------------+ #
# |                             Branches                            | #
# +-----------------------------------------------------------------+ #
#######################################################################

# Branches are objects that will spawn when this object spawns when it is used in
# the CustomStructure resource. Branches can also have branches, making complex
# structures possible. See the wiki for more details.

# Regular Branches spawn each branch with an independent chance of spawning.
# Branch(x,y,z,branchName,rotation,chance[,anotherBranchName,rotation,chance[,...]][IndividualChance])
# branchName - name of the object to spawn.
# rotation - NORTH, SOUTH, EAST or WEST.
# IndividualChance - The chance each branch has to spawn, assumed to be 100 when left blank

# Weighted Branches spawn branches with a dependent chance of spawning.
# WeightedBranch(x,y,z,branchName,rotation,chance[,anotherBranchName,rotation,chance[,...]][MaxChanceOutOf])
# MaxChanceOutOf - The chance all branches have to spawn out of, assumed to be 100 when left blank
