#######################################################################
# +-----------------------------------------------------------------+ #
# |                            BO3 object                           | #
# +-----------------------------------------------------------------+ #
#######################################################################

# The descriptions in this file are accurate only for TerrainControl and OTG.
# For MCW and OTG+ these descriptions are only accurate if the BO3 is used as a CustomObject.
# MCW and OTG+ completely reimplemented CustomStructure, check the MCW/OTG+ documentation for more information.

# This is the config file of a custom object.
# If you add this object correctly to your BiomeConfigs, it will spawn in the world.

# This is the creator of this BO3 object
Author: Unknown

# A short description of this BO3 object
Description: This BO3 was converted from a schematic using OTGEdit. The author and description information of the schematic could not be found. If you know who the author of the schematic is then please add this information.

# The BO3 version, don't change this! It can be used by external applications to do a version check.
Version: 3

# The settings mode, WriteAll, WriteWithoutComments or WriteDisable. See WorldConfig.
SettingsMode: WriteDisable

#######################################################################
# +-----------------------------------------------------------------+ #
# |                          Main settings                          | #
# +-----------------------------------------------------------------+ #
#######################################################################

# This needs to be set to true to spawn the object in the Tree and Sapling resources.
Tree: true

# The frequency of the BO3 from 1 to 200. Tries this many times to spawn this BO3 when using the CustomObject(...) resource.
# Ignored by Tree(..), Sapling(..) and CustomStructure(..)
Frequency: 40

# The rarity of the BO3 from 0 to 100. Each spawn attempt has rarity% chance to succeed when using the CustomObject(...) resource.
# Ignored by Tree(..), Sapling(..) and CustomStructure(..)
Rarity: 100.0

# If you set this to true, the BO3 will be placed with a random rotation.
RotateRandomly: true

# The spawn height of the BO3 - randomY, highestBlock or highestSolidBlock.
SpawnHeight: highestSolidBlock

# The height limits for the BO3.
MinHeight: 0

MaxHeight: 256

# Objects can have other objects attached to it: branches. Branches can also
# have branches attached to it, which can also have branches, etc. This is the
# maximum branch depth for this objects.
MaxBranchDepth: 10

# When spawned with the UseWorld keyword, this BO3 should NOT spawn in the following biomes.
# If you writer.write the BO3 name directly in the BiomeConfigs, this will be ignored.
ExcludedBiomes: All

# To optimise this BO3 for faster loading times you can use Notepad++ to find/replace comments and abbreviate things.
# Notepad++ find/replace with regex:
# Find: ^[#;].* replace to nothing removes all lines starting with # 
# Find: ^\s*$ replace to nothing removes most empty lines 
# Notepad++ find/replace without regex:
# *Warning: This will only work for OTG 1.10.2 v21 / OTG 1.11.2 v6 or higher. B( is not recognised by lower versions.
# Find: Block( replace to B(

#######################################################################
# +-----------------------------------------------------------------+ #
# |                      Source block settings                      | #
# +-----------------------------------------------------------------+ #
#######################################################################

# The block(s) the BO3 should spawn in.
SourceBlocks: AIR

# The maximum percentage of the BO3 that can be outside the SourceBlock.
# The BO3 won't be placed on a location with more blocks outside the SourceBlock than this percentage.
MaxPercentageOutsideSourceBlock: 0

# What to do when a block is about to be placed outside the SourceBlock? (dontPlace, placeAnyway)
OutsideSourceBlock: dontPlace

#######################################################################
# +-----------------------------------------------------------------+ #
# |                              Blocks                             | #
# +-----------------------------------------------------------------+ #
#######################################################################

# All the blocks used in the BO3 are listed here. Possible blocks:
# Block(x,y,z,id[.data][,nbtfile.nbt) or B(x,y,z,id[.data][,nbtfile.nbt)
# RandomBlock(x,y,z,id[:data][,nbtfile.nbt],chance[,id[:data][,nbtfile.nbt],chance[,...]])
# So RandomBlock(0,0,0,CHEST,chest.nbt,50,CHEST,anotherchest.nbt,100) will spawn a chest at
# the BO3 origin, and give it a 50% chance to have the contents of chest.nbt, or, if that
# fails, a 100% percent chance to have the contents of anotherchest.nbt.

Block(-17,9,13,LEAVES:12)
Block(-17,10,12,LEAVES:12)
Block(-17,10,13,LEAVES:12)
Block(-17,11,8,LEAVES:12)
Block(-16,7,10,LEAVES:12)
Block(-16,10,12,LEAVES:12)
Block(-16,11,8,LEAVES:12)
Block(-16,11,9,LEAVES:12)
Block(-16,14,10,LEAVES:12)
Block(-16,14,12,LEAVES:12)
Block(-16,15,10,LEAVES:12)
Block(-15,6,11,LEAVES:12)
Block(-15,7,11,LEAVES:12)
Block(-15,8,13,LEAVES:12)
Block(-15,9,5,LEAVES:12)
Block(-15,9,7,LEAVES:12)
Block(-15,10,4,LEAVES:12)
Block(-15,10,5,LEAVES:12)
Block(-15,10,9,LEAVES:12)
Block(-15,10,10,LEAVES:12)
Block(-15,10,12,LEAVES:12)
Block(-15,11,0,LEAVES:12)
Block(-15,11,9,LEAVES:12)
Block(-15,11,11,LEAVES:12)
Block(-15,11,12,LEAVES:12)
Block(-15,13,13,LEAVES:12)
Block(-15,13,15,LEAVES:12)
Block(-15,13,16,LEAVES:12)
Block(-15,14,10,LEAVES:12)
Block(-15,14,11,LEAVES:12)
Block(-14,6,13,LEAVES:12)
Block(-14,7,2,LEAVES:12)
Block(-14,7,7,LEAVES:12)
Block(-14,7,11,LEAVES:12)
Block(-14,7,12,LEAVES:12)
Block(-14,8,7,LEAVES:12)
Block(-14,8,8,LEAVES:12)
Block(-14,8,12,LEAVES:12)
Block(-14,8,15,LEAVES:12)
Block(-14,9,12,LEAVES:12)
Block(-14,10,4,LEAVES:12)
Block(-14,10,10,LEAVES:12)
Block(-14,11,0,LEAVES:12)
Block(-14,11,1,LEAVES:12)
Block(-14,11,11,LEAVES:12)
Block(-14,12,14,LEAVES:12)
Block(-14,12,15,LEAVES:12)
Block(-14,13,7,LEAVES:12)
Block(-14,13,8,LEAVES:12)
Block(-14,13,11,LEAVES:12)
Block(-14,13,15,LEAVES:12)
Block(-14,14,2,LEAVES:12)
Block(-14,14,4,LEAVES:12)
Block(-14,14,11,LEAVES:12)
Block(-14,14,15,LEAVES:12)
Block(-14,15,2,LEAVES:12)
Block(-14,15,11,LEAVES:12)
Block(-13,6,3,LEAVES:12)
Block(-13,7,3,LEAVES:12)
Block(-13,8,5,LEAVES:12)
Block(-13,8,8,LEAVES:12)
Block(-13,8,14,LEAVES:12)
Block(-13,8,15,LEAVES:12)
Block(-13,9,-1,LEAVES:12)
Block(-13,9,8,LEAVES:12)
Block(-13,9,12,LEAVES:12)
Block(-13,9,13,LEAVES:12)
Block(-13,9,14,LEAVES:12)
Block(-13,10,1,LEAVES:12)
Block(-13,10,2,LEAVES:12)
Block(-13,10,4,LEAVES:12)
Block(-13,10,10,LEAVES:12)
Block(-13,10,12,LEAVES:12)
Block(-13,11,1,LEAVES:12)
Block(-13,11,3,LEAVES:12)
Block(-13,11,4,LEAVES:12)
Block(-13,11,11,LEAVES:12)
Block(-13,12,9,LEAVES:12)
Block(-13,12,10,LEAVES:12)
Block(-13,12,11,LEAVES:12)
Block(-13,12,13,LEAVES:12)
Block(-13,12,14,LEAVES:12)
Block(-13,12,20,LEAVES:12)
Block(-13,13,5,LEAVES:12)
Block(-13,13,7,LEAVES:12)
Block(-13,13,8,LEAVES:12)
Block(-13,13,9,LEAVES:12)
Block(-13,13,11,LEAVES:12)
Block(-13,13,16,LEAVES:12)
Block(-13,13,19,LEAVES:12)
Block(-13,13,20,LEAVES:12)
Block(-13,14,2,LEAVES:12)
Block(-13,14,3,LEAVES:12)
Block(-13,14,9,LEAVES:12)
Block(-13,14,15,LEAVES:12)
Block(-12,6,5,LEAVES:12)
Block(-12,6,23,LEAVES:12)
Block(-12,7,-1,LEAVES:12)
Block(-12,7,3,LEAVES:12)
Block(-12,7,4,LEAVES:12)
Block(-12,7,10,LEAVES:12)
Block(-12,7,22,LEAVES:12)
Block(-12,7,23,LEAVES:12)
Block(-12,8,-1,LEAVES:12)
Block(-12,8,0,LEAVES:12)
Block(-12,8,4,LEAVES:12)
Block(-12,8,7,LEAVES:12)
Block(-12,8,9,LEAVES:12)
Block(-12,8,15,LEAVES:12)
Block(-12,8,16,LEAVES:12)
Block(-12,8,18,LEAVES:12)
Block(-12,9,4,LEAVES:12)
Block(-12,9,8,LEAVES:12)
Block(-12,9,9,LEAVES:12)
Block(-12,10,2,LEAVES:12)
Block(-12,10,9,LEAVES:12)
Block(-12,10,10,LEAVES:12)
Block(-12,10,11,LEAVES:12)
Block(-12,10,12,LEAVES:12)
Block(-12,10,17,LEAVES:12)
Block(-12,11,3,LEAVES:12)
Block(-12,11,11,LOG:12)
Block(-12,11,12,LEAVES:12)
Block(-12,11,13,LEAVES:12)
Block(-12,12,6,LEAVES:12)
Block(-12,12,7,LEAVES:12)
Block(-12,12,11,LEAVES:12)
Block(-12,12,13,LEAVES:12)
Block(-12,13,-1,LEAVES:12)
Block(-12,13,0,LEAVES:12)
Block(-12,13,3,LEAVES:12)
Block(-12,13,7,LEAVES:12)
Block(-12,13,11,LEAVES:12)
Block(-12,13,12,LEAVES:12)
Block(-12,13,19,LEAVES:12)
Block(-12,14,3,LEAVES:12)
Block(-12,14,7,LEAVES:12)
Block(-12,14,12,LEAVES:12)
Block(-12,14,15,LEAVES:12)
Block(-12,14,16,LEAVES:12)
Block(-12,15,3,LEAVES:12)
Block(-12,15,11,LEAVES:12)
Block(-12,17,17,LEAVES:12)
Block(-12,17,19,LEAVES:12)
Block(-12,18,17,LEAVES:12)
Block(-11,4,20,LEAVES:12)
Block(-11,7,13,LEAVES:12)
Block(-11,7,22,LEAVES:12)
Block(-11,8,0,LEAVES:12)
Block(-11,8,6,LEAVES:12)
Block(-11,8,7,LEAVES:12)
Block(-11,8,11,LEAVES:12)
Block(-11,8,13,LEAVES:12)
Block(-11,8,18,LEAVES:12)
Block(-11,8,19,LEAVES:12)
Block(-11,9,0,LEAVES:12)
Block(-11,9,4,LEAVES:12)
Block(-11,9,5,LEAVES:12)
Block(-11,9,6,LEAVES:12)
Block(-11,9,11,LEAVES:12)
Block(-11,9,13,LEAVES:12)
Block(-11,9,15,LEAVES:12)
Block(-11,9,18,LEAVES:12)
Block(-11,10,2,LEAVES:12)
Block(-11,10,4,LEAVES:12)
Block(-11,10,9,LEAVES:12)
Block(-11,10,11,LEAVES:12)
Block(-11,10,12,LEAVES:12)
Block(-11,10,13,LEAVES:12)
Block(-11,10,15,LEAVES:12)
Block(-11,10,18,LEAVES:12)
Block(-11,11,3,LEAVES:12)
Block(-11,11,7,LEAVES:12)
Block(-11,11,9,LEAVES:12)
Block(-11,11,11,LOG:12)
Block(-11,11,12,LEAVES:12)
Block(-11,11,16,LEAVES:12)
Block(-11,11,20,LEAVES:12)
Block(-11,11,22,LEAVES:12)
Block(-11,12,1,LEAVES:12)
Block(-11,12,2,LEAVES:12)
Block(-11,12,3,LEAVES:12)
Block(-11,12,5,LEAVES:12)
Block(-11,12,6,LEAVES:12)
Block(-11,12,11,LOG:12)
Block(-11,12,14,LEAVES:12)
Block(-11,12,20,LEAVES:12)
Block(-11,13,0,LEAVES:12)
Block(-11,13,1,LEAVES:12)
Block(-11,13,3,LEAVES:12)
Block(-11,13,8,LEAVES:12)
Block(-11,13,16,LEAVES:12)
Block(-11,13,17,LEAVES:12)
Block(-11,13,19,LEAVES:12)
Block(-11,14,1,LEAVES:12)
Block(-11,14,12,LEAVES:12)
Block(-11,14,13,LEAVES:12)
Block(-11,14,16,LEAVES:12)
Block(-11,14,18,LEAVES:12)
Block(-11,14,19,LEAVES:12)
Block(-11,15,13,LEAVES:12)
Block(-11,15,14,LEAVES:12)
Block(-11,16,13,LEAVES:12)
Block(-11,16,20,LEAVES:12)
Block(-11,16,22,LEAVES:12)
Block(-11,16,23,LEAVES:12)
Block(-11,17,17,LEAVES:12)
Block(-11,17,18,LEAVES:12)
Block(-10,3,21,LEAVES:12)
Block(-10,4,21,LEAVES:12)
Block(-10,5,23,LEAVES:12)
Block(-10,6,17,LEAVES:12)
Block(-10,7,2,LEAVES:12)
Block(-10,7,10,LEAVES:12)
Block(-10,7,19,LEAVES:12)
Block(-10,7,20,LEAVES:12)
Block(-10,7,22,LEAVES:12)
Block(-10,8,1,LEAVES:12)
Block(-10,8,7,LEAVES:12)
Block(-10,8,8,LEAVES:12)
Block(-10,8,14,LEAVES:12)
Block(-10,8,19,LEAVES:12)
Block(-10,8,21,LEAVES:12)
Block(-10,8,22,LEAVES:12)
Block(-10,9,0,LEAVES:12)
Block(-10,9,1,LEAVES:12)
Block(-10,9,11,LEAVES:12)
Block(-10,9,13,LEAVES:12)
Block(-10,9,14,LEAVES:12)
Block(-10,9,20,LEAVES:12)
Block(-10,10,1,LEAVES:12)
Block(-10,10,2,LEAVES:12)
Block(-10,10,3,LEAVES:12)
Block(-10,10,4,LEAVES:12)
Block(-10,10,14,LEAVES:12)
Block(-10,10,18,LEAVES:12)
Block(-10,10,19,LEAVES:12)
Block(-10,10,23,LEAVES:12)
Block(-10,10,25,LEAVES:12)
Block(-10,10,26,LEAVES:12)
Block(-10,11,2,LOG:12)
Block(-10,11,3,LOG:12)
Block(-10,11,4,LOG:12)
Block(-10,11,5,LEAVES:12)
Block(-10,11,8,LEAVES:12)
Block(-10,11,9,LEAVES:12)
Block(-10,11,12,LEAVES:12)
Block(-10,11,13,LEAVES:12)
Block(-10,11,14,LEAVES:12)
Block(-10,11,15,LEAVES:12)
Block(-10,11,19,LEAVES:12)
Block(-10,11,20,LEAVES:12)
Block(-10,11,21,LEAVES:12)
Block(-10,11,22,LEAVES:12)
Block(-10,12,3,LEAVES:12)
Block(-10,12,4,LOG:12)
Block(-10,12,5,LEAVES:12)
Block(-10,12,10,LOG:12)
Block(-10,12,11,LOG:12)
Block(-10,12,13,LEAVES:12)
Block(-10,12,19,LEAVES:12)
Block(-10,13,3,LEAVES:12)
Block(-10,13,4,LEAVES:12)
Block(-10,13,8,LEAVES:12)
Block(-10,13,10,LOG:12)
Block(-10,13,11,LEAVES:12)
Block(-10,13,17,LEAVES:12)
Block(-10,14,4,LEAVES:12)
Block(-10,14,10,LOG:12)
Block(-10,14,18,LEAVES:12)
Block(-10,15,3,LEAVES:12)
Block(-10,15,21,LEAVES:12)
Block(-10,15,22,LEAVES:12)
Block(-10,16,14,LEAVES:12)
Block(-10,16,15,LEAVES:12)
Block(-10,16,18,LEAVES:12)
Block(-10,16,22,LEAVES:12)
Block(-10,17,18,LEAVES:12)
Block(-10,17,22,LEAVES:12)
Block(-10,18,4,LEAVES:12)
Block(-10,18,18,LEAVES:12)
Block(-10,19,3,LEAVES:12)
Block(-10,19,4,LEAVES:12)
Block(-10,20,-1,LEAVES:12)
Block(-9,3,23,LEAVES:12)
Block(-9,4,17,LEAVES:12)
Block(-9,4,21,LEAVES:12)
Block(-9,4,22,LEAVES:12)
Block(-9,5,17,LEAVES:12)
Block(-9,5,18,LEAVES:12)
Block(-9,5,22,LEAVES:12)
Block(-9,5,25,LEAVES:12)
Block(-9,6,22,LEAVES:12)
Block(-9,7,5,LEAVES:12)
Block(-9,7,14,LEAVES:12)
Block(-9,7,20,LEAVES:12)
Block(-9,8,3,LEAVES:12)
Block(-9,8,5,LEAVES:12)
Block(-9,8,10,LEAVES:12)
Block(-9,8,11,LEAVES:12)
Block(-9,8,14,LEAVES:12)
Block(-9,8,21,LEAVES:12)
Block(-9,9,3,LEAVES:12)
Block(-9,9,5,LEAVES:12)
Block(-9,9,7,LEAVES:12)
Block(-9,9,11,LEAVES:12)
Block(-9,9,24,LEAVES:12)
Block(-9,9,25,LEAVES:12)
Block(-9,10,1,LEAVES:12)
Block(-9,10,3,LEAVES:12)
Block(-9,10,4,LEAVES:12)
Block(-9,10,5,LEAVES:12)
Block(-9,10,7,LEAVES:12)
Block(-9,10,11,LEAVES:12)
Block(-9,10,17,LEAVES:12)
Block(-9,10,18,LEAVES:12)
Block(-9,10,21,LEAVES:12)
Block(-9,10,25,LEAVES:12)
Block(-9,11,-1,LEAVES:12)
Block(-9,11,1,LEAVES:12)
Block(-9,11,3,LEAVES:12)
Block(-9,11,4,LEAVES:12)
Block(-9,11,7,LEAVES:12)
Block(-9,11,8,LEAVES:12)
Block(-9,11,15,LEAVES:12)
Block(-9,11,21,LEAVES:12)
Block(-9,11,22,LEAVES:12)
Block(-9,11,25,LEAVES:12)
Block(-9,12,3,LEAVES:12)
Block(-9,12,4,LOG:12)
Block(-9,12,5,LOG:12)
Block(-9,12,13,LEAVES:12)
Block(-9,12,14,LEAVES:12)
Block(-9,12,15,LEAVES:12)
Block(-9,12,19,LEAVES:12)
Block(-9,12,20,LEAVES:12)
Block(-9,12,21,LEAVES:12)
Block(-9,13,5,LOG:12)
Block(-9,13,6,LOG:12)
Block(-9,13,9,LEAVES:12)
Block(-9,13,10,LEAVES:12)
Block(-9,13,14,LEAVES:12)
Block(-9,13,17,LEAVES:12)
Block(-9,13,19,LEAVES:12)
Block(-9,14,4,LEAVES:12)
Block(-9,14,5,LEAVES:12)
Block(-9,14,9,LOG:12)
Block(-9,14,10,LOG:12)
Block(-9,14,12,LEAVES:12)
Block(-9,14,18,LEAVES:12)
Block(-9,15,5,LEAVES:12)
Block(-9,15,6,LEAVES:12)
Block(-9,15,9,LOG:12)
Block(-9,15,16,LEAVES:12)
Block(-9,15,17,LEAVES:12)
Block(-9,15,18,LEAVES:12)
Block(-9,15,20,LEAVES:12)
Block(-9,15,21,LEAVES:12)
Block(-9,16,1,LEAVES:12)
Block(-9,16,5,LEAVES:12)
Block(-9,16,15,LEAVES:12)
Block(-9,16,16,LEAVES:12)
Block(-9,16,18,LEAVES:12)
Block(-9,16,23,LEAVES:12)
Block(-9,17,16,LEAVES:12)
Block(-9,19,3,LEAVES:12)
Block(-9,20,-1,LEAVES:12)
Block(-9,20,0,LEAVES:12)
Block(-9,23,1,LEAVES:12)
Block(-9,23,3,LEAVES:12)
Block(-9,24,1,LEAVES:12)
Block(-8,5,18,LEAVES:12)
Block(-8,5,24,LEAVES:12)
Block(-8,5,25,LEAVES:12)
Block(-8,6,18,LEAVES:12)
Block(-8,6,22,LEAVES:12)
Block(-8,6,23,LEAVES:12)
Block(-8,6,24,LEAVES:12)
Block(-8,7,2,LEAVES:12)
Block(-8,7,9,LEAVES:12)
Block(-8,7,10,LEAVES:12)
Block(-8,7,20,LEAVES:12)
Block(-8,7,22,LEAVES:12)
Block(-8,8,6,LEAVES:12)
Block(-8,8,10,LEAVES:12)
Block(-8,8,21,LEAVES:12)
Block(-8,9,3,LEAVES:12)
Block(-8,9,5,LEAVES:12)
Block(-8,9,6,LEAVES:12)
Block(-8,9,19,LEAVES:12)
Block(-8,9,20,LEAVES:12)
Block(-8,9,21,LEAVES:12)
Block(-8,9,23,LEAVES:12)
Block(-8,9,24,LEAVES:12)
Block(-8,10,10,LEAVES:12)
Block(-8,10,11,LEAVES:12)
Block(-8,10,17,LEAVES:12)
Block(-8,10,18,LEAVES:12)
Block(-8,10,19,LEAVES:12)
Block(-8,10,21,LEAVES:12)
Block(-8,10,26,LEAVES:12)
Block(-8,11,0,LEAVES:12)
Block(-8,11,1,LEAVES:12)
Block(-8,11,4,LEAVES:12)
Block(-8,11,5,LEAVES:12)
Block(-8,11,11,LEAVES:12)
Block(-8,11,16,LEAVES:12)
Block(-8,11,19,LEAVES:12)
Block(-8,11,22,LEAVES:12)
Block(-8,11,23,LEAVES:12)
Block(-8,12,3,LEAVES:12)
Block(-8,12,5,LEAVES:12)
Block(-8,12,14,LEAVES:12)
Block(-8,12,15,LEAVES:12)
Block(-8,12,16,LEAVES:12)
Block(-8,13,0,LEAVES:12)
Block(-8,13,2,LEAVES:12)
Block(-8,13,3,LEAVES:12)
Block(-8,13,6,LOG:12)
Block(-8,13,9,LEAVES:12)
Block(-8,13,16,LEAVES:12)
Block(-8,13,17,LEAVES:12)
Block(-8,13,18,LOG:12)
Block(-8,13,19,LOG:12)
Block(-8,14,6,LOG:12)
Block(-8,14,7,LOG:12)
Block(-8,14,9,LEAVES:12)
Block(-8,14,18,LOG:12)
Block(-8,14,19,LEAVES:12)
Block(-8,14,20,LEAVES:12)
Block(-8,15,2,LEAVES:12)
Block(-8,15,9,LOG:12)
Block(-8,15,18,LEAVES:12)
Block(-8,15,20,LEAVES:12)
Block(-8,16,2,LEAVES:12)
Block(-8,16,18,LEAVES:12)
Block(-8,16,19,LEAVES:12)
Block(-8,17,4,LEAVES:12)
Block(-8,17,19,LEAVES:12)
Block(-8,18,-2,LEAVES:12)
Block(-8,18,18,LEAVES:12)
Block(-8,19,0,LEAVES:12)
Block(-8,19,1,LEAVES:12)
Block(-8,19,3,LEAVES:12)
Block(-8,20,0,LEAVES:12)
Block(-8,20,2,LEAVES:12)
Block(-8,20,3,LEAVES:12)
Block(-8,22,4,LEAVES:12)
Block(-8,22,6,LEAVES:12)
Block(-8,22,7,LEAVES:12)
Block(-8,23,1,LEAVES:12)
Block(-8,23,2,LEAVES:12)
Block(-7,4,20,LEAVES:12)
Block(-7,5,19,LEAVES:12)
Block(-7,5,25,LEAVES:12)
Block(-7,5,26,LEAVES:12)
Block(-7,6,18,LEAVES:12)
Block(-7,6,19,LEAVES:12)
Block(-7,7,1,LEAVES:12)
Block(-7,7,6,LEAVES:12)
Block(-7,7,9,LEAVES:12)
Block(-7,7,19,LEAVES:12)
Block(-7,7,20,LEAVES:12)
Block(-7,7,21,LEAVES:12)
Block(-7,7,22,LEAVES:12)
Block(-7,8,0,LEAVES:12)
Block(-7,8,1,LEAVES:12)
Block(-7,8,2,LEAVES:12)
Block(-7,8,3,LEAVES:12)
Block(-7,8,6,LEAVES:12)
Block(-7,8,19,LOG:12)
Block(-7,8,20,LOG:12)
Block(-7,8,21,LOG:12)
Block(-7,8,22,LEAVES:12)
Block(-7,8,23,LEAVES:12)
Block(-7,9,-4,LEAVES:12)
Block(-7,9,3,LEAVES:12)
Block(-7,9,12,LEAVES:12)
Block(-7,9,21,LEAVES:12)
Block(-7,9,23,LEAVES:12)
Block(-7,10,3,LEAVES:12)
Block(-7,10,11,LEAVES:12)
Block(-7,10,12,LEAVES:12)
Block(-7,10,20,LEAVES:12)
Block(-7,10,21,LEAVES:12)
Block(-7,10,22,LEAVES:12)
Block(-7,11,-1,LEAVES:12)
Block(-7,11,0,LEAVES:12)
Block(-7,11,18,LEAVES:12)
Block(-7,11,20,LEAVES:12)
Block(-7,11,22,LEAVES:12)
Block(-7,12,5,LEAVES:12)
Block(-7,12,6,LEAVES:12)
Block(-7,12,7,LEAVES:12)
Block(-7,12,18,LEAVES:12)
Block(-7,12,20,LEAVES:12)
Block(-7,12,21,LEAVES:12)
Block(-7,12,22,LEAVES:12)
Block(-7,13,1,LEAVES:12)
Block(-7,13,2,LEAVES:12)
Block(-7,13,6,LEAVES:12)
Block(-7,13,16,LEAVES:12)
Block(-7,13,18,LEAVES:12)
Block(-7,13,19,LEAVES:12)
Block(-7,13,20,LEAVES:12)
Block(-7,13,22,LEAVES:12)
Block(-7,14,4,LEAVES:12)
Block(-7,14,7,LOG:12)
Block(-7,14,14,LEAVES:12)
Block(-7,14,16,LEAVES:12)
Block(-7,14,17,LOG:12)
Block(-7,14,18,LOG:12)
Block(-7,14,19,LEAVES:12)
Block(-7,14,23,LEAVES:12)
Block(-7,15,4,LEAVES:12)
Block(-7,15,7,LOG:12)
Block(-7,15,8,LOG:12)
Block(-7,15,9,LOG:12)
Block(-7,15,17,LOG:12)
Block(-7,15,18,LEAVES:12)
Block(-7,16,-2,LEAVES:12)
Block(-7,16,2,LEAVES:12)
Block(-7,16,3,LEAVES:12)
Block(-7,17,-2,LEAVES:12)
Block(-7,17,-1,LEAVES:12)
Block(-7,17,3,LEAVES:12)
Block(-7,17,6,LEAVES:12)
Block(-7,17,19,LEAVES:12)
Block(-7,17,20,LEAVES:12)
Block(-7,18,3,LEAVES:12)
Block(-7,18,20,LEAVES:12)
Block(-7,18,21,LEAVES:12)
Block(-7,19,1,LEAVES:12)
Block(-7,19,20,LEAVES:12)
Block(-7,20,2,LEAVES:12)
Block(-7,21,5,LEAVES:12)
Block(-7,21,6,LEAVES:12)
Block(-7,22,-2,LEAVES:12)
Block(-7,22,-1,LEAVES:12)
Block(-7,22,2,LEAVES:12)
Block(-7,22,6,LEAVES:12)
Block(-7,23,2,LEAVES:12)
Block(-7,23,6,LEAVES:12)
Block(-7,24,2,LEAVES:12)
Block(-6,4,23,LEAVES:12)
Block(-6,5,-2,LEAVES:12)
Block(-6,5,21,LEAVES:12)
Block(-6,5,23,LEAVES:12)
Block(-6,6,21,LEAVES:12)
Block(-6,6,23,LEAVES:12)
Block(-6,6,25,LEAVES:12)
Block(-6,7,1,LEAVES:12)
Block(-6,7,2,LEAVES:12)
Block(-6,7,19,LEAVES:12)
Block(-6,7,21,LEAVES:12)
Block(-6,7,22,LEAVES:12)
Block(-6,7,23,LEAVES:12)
Block(-6,7,25,LEAVES:12)
Block(-6,8,0,LEAVES:12)
Block(-6,8,2,LEAVES:12)
Block(-6,8,17,LEAVES:12)
Block(-6,8,19,LOG:12)
Block(-6,8,21,LEAVES:12)
Block(-6,8,22,LEAVES:12)
Block(-6,8,26,LEAVES:12)
Block(-6,9,-4,LEAVES:12)
Block(-6,9,-3,LEAVES:12)
Block(-6,9,12,LEAVES:12)
Block(-6,9,18,LOG:12)
Block(-6,9,19,LOG:12)
Block(-6,9,21,LEAVES:12)
Block(-6,10,2,LEAVES:12)
Block(-6,10,3,LEAVES:12)
Block(-6,10,17,LEAVES:12)
Block(-6,11,3,LEAVES:12)
Block(-6,11,21,LEAVES:12)
Block(-6,11,22,LEAVES:12)
Block(-6,11,23,LEAVES:12)
Block(-6,12,-2,LEAVES:12)
Block(-6,12,0,LEAVES:12)
Block(-6,12,6,LEAVES:12)
Block(-6,12,18,LEAVES:12)
Block(-6,12,20,LEAVES:12)
Block(-6,12,21,LEAVES:12)
Block(-6,12,23,LEAVES:12)
Block(-6,12,24,LEAVES:12)
Block(-6,13,-2,LEAVES:12)
Block(-6,13,1,LEAVES:12)
Block(-6,13,23,LEAVES:12)
Block(-6,14,1,LEAVES:12)
Block(-6,14,15,LEAVES:12)
Block(-6,14,16,LEAVES:12)
Block(-6,14,19,LEAVES:12)
Block(-6,14,20,LEAVES:12)
Block(-6,15,8,LOG:12)
Block(-6,15,17,LOG:12)
Block(-6,15,18,LEAVES:12)
Block(-6,15,20,LEAVES:12)
Block(-6,16,15,LEAVES:12)
Block(-6,16,17,LEAVES:12)
Block(-6,16,18,LEAVES:12)
Block(-6,17,-1,LEAVES:12)
Block(-6,17,5,LEAVES:12)
Block(-6,17,6,LEAVES:12)
Block(-6,18,-1,LEAVES:12)
Block(-6,18,3,LEAVES:12)
Block(-6,18,4,LEAVES:12)
Block(-6,18,5,LEAVES:12)
Block(-6,19,1,LEAVES:12)
Block(-6,19,3,LEAVES:12)
Block(-6,20,2,LOG:12)
Block(-6,21,0,LEAVES:12)
Block(-6,21,1,LEAVES:12)
Block(-6,21,2,LEAVES:12)
Block(-6,21,4,LEAVES:12)
Block(-6,21,5,LEAVES:12)
Block(-6,22,-1,LEAVES:12)
Block(-6,22,0,LEAVES:12)
Block(-6,22,2,LEAVES:12)
Block(-6,22,7,LEAVES:12)
Block(-6,23,0,LEAVES:12)
Block(-5,4,-1,LEAVES:12)
Block(-5,4,20,LEAVES:12)
Block(-5,5,-1,LEAVES:12)
Block(-5,5,24,LEAVES:12)
Block(-5,6,1,LEAVES:12)
Block(-5,6,21,LEAVES:12)
Block(-5,6,23,LEAVES:12)
Block(-5,6,24,LEAVES:12)
Block(-5,7,-5,LEAVES:12)
Block(-5,7,1,LEAVES:12)
Block(-5,8,-3,LEAVES:12)
Block(-5,8,-2,LEAVES:12)
Block(-5,8,0,LEAVES:12)
Block(-5,8,18,LEAVES:12)
Block(-5,8,19,LEAVES:12)
Block(-5,8,22,LEAVES:12)
Block(-5,8,23,LEAVES:12)
Block(-5,9,-3,LEAVES:12)
Block(-5,9,-1,LEAVES:12)
Block(-5,9,0,LEAVES:12)
Block(-5,9,4,LEAVES:12)
Block(-5,9,18,LOG:12)
Block(-5,9,21,LEAVES:12)
Block(-5,9,23,LEAVES:12)
Block(-5,9,25,LEAVES:12)
Block(-5,10,3,LEAVES:12)
Block(-5,10,4,LEAVES:12)
Block(-5,10,18,LEAVES:12)
Block(-5,10,20,LEAVES:12)
Block(-5,10,21,LEAVES:12)
Block(-5,10,24,LEAVES:12)
Block(-5,10,25,LEAVES:12)
Block(-5,11,1,LEAVES:12)
Block(-5,11,3,LEAVES:12)
Block(-5,11,4,LEAVES:12)
Block(-5,11,17,LEAVES:12)
Block(-5,11,18,LEAVES:12)
Block(-5,11,20,LEAVES:12)
Block(-5,11,21,LEAVES:12)
Block(-5,12,-2,LEAVES:12)
Block(-5,12,-1,LEAVES:12)
Block(-5,12,18,LEAVES:12)
Block(-5,13,18,LEAVES:12)
Block(-5,14,9,LOG:12)
Block(-5,14,14,LEAVES:12)
Block(-5,14,15,LEAVES:12)
Block(-5,15,8,LOG:12)
Block(-5,15,9,LOG:12)
Block(-5,15,16,LOG:12)
Block(-5,15,17,LOG:12)
Block(-5,15,20,LEAVES:12)
Block(-5,15,21,LEAVES:12)
Block(-5,15,22,LEAVES:12)
Block(-5,16,1,LEAVES:12)
Block(-5,16,16,LEAVES:12)
Block(-5,16,17,LEAVES:12)
Block(-5,16,21,LEAVES:12)
Block(-5,17,0,LEAVES:12)
Block(-5,17,6,LEAVES:12)
Block(-5,17,7,LEAVES:12)
Block(-5,17,19,LEAVES:12)
Block(-5,18,-1,LEAVES:12)
Block(-5,18,0,LEAVES:12)
Block(-5,19,0,LEAVES:12)
Block(-5,19,1,LEAVES:12)
Block(-5,19,2,LEAVES:12)
Block(-5,19,3,LOG:12)
Block(-5,20,2,LOG:12)
Block(-5,20,3,LOG:12)
Block(-5,20,4,LEAVES:12)
Block(-5,21,2,LEAVES:12)
Block(-5,21,4,LEAVES:12)
Block(-5,22,2,LEAVES:12)
Block(-5,22,3,LEAVES:12)
Block(-5,23,3,LEAVES:12)
Block(-5,24,2,LEAVES:12)
Block(-4,0,10,LOG:12)
Block(-4,1,10,LOG:12)
Block(-4,2,10,LOG:12)
Block(-4,3,10,LOG:12)
Block(-4,4,1,LEAVES:12)
Block(-4,4,10,LOG:12)
Block(-4,4,24,LEAVES:12)
Block(-4,5,-5,LEAVES:12)
Block(-4,5,-1,LEAVES:12)
Block(-4,5,0,LEAVES:12)
Block(-4,5,20,LEAVES:12)
Block(-4,5,21,LEAVES:12)
Block(-4,5,24,LEAVES:12)
Block(-4,6,-5,LEAVES:12)
Block(-4,6,-4,LEAVES:12)
Block(-4,6,0,LEAVES:12)
Block(-4,6,3,LEAVES:12)
Block(-4,6,21,LEAVES:12)
Block(-4,7,0,LEAVES:12)
Block(-4,7,21,LEAVES:12)
Block(-4,7,22,LEAVES:12)
Block(-4,8,-2,LEAVES:12)
Block(-4,8,17,LEAVES:12)
Block(-4,8,18,LEAVES:12)
Block(-4,9,-1,LEAVES:12)
Block(-4,9,4,LEAVES:12)
Block(-4,9,18,LOG:12)
Block(-4,9,23,LEAVES:12)
Block(-4,9,24,LEAVES:12)
Block(-4,9,25,LEAVES:12)
Block(-4,10,2,LEAVES:12)
Block(-4,10,3,LEAVES:12)
Block(-4,10,16,LEAVES:12)
Block(-4,10,17,LOG:12)
Block(-4,10,18,LOG:12)
Block(-4,10,19,LEAVES:12)
Block(-4,10,20,LEAVES:12)
Block(-4,10,24,LEAVES:12)
Block(-4,11,-5,LEAVES:12)
Block(-4,11,-4,LEAVES:12)
Block(-4,11,-1,LEAVES:12)
Block(-4,11,3,LEAVES:12)
Block(-4,11,17,LEAVES:12)
Block(-4,11,20,LEAVES:12)
Block(-4,11,21,LEAVES:12)
Block(-4,11,22,LEAVES:12)
Block(-4,12,-1,LEAVES:12)
Block(-4,12,3,LEAVES:12)
Block(-4,13,-1,LEAVES:12)
Block(-4,13,17,LEAVES:12)
Block(-4,13,18,LEAVES:12)
Block(-4,14,9,LOG:12)
Block(-4,14,16,LOG:12)
Block(-4,14,18,LEAVES:12)
Block(-4,14,22,LEAVES:12)
Block(-4,14,24,LEAVES:12)
Block(-4,15,16,LOG:12)
Block(-4,15,21,LEAVES:12)
Block(-4,15,22,LEAVES:12)
Block(-4,16,4,LEAVES:12)
Block(-4,16,16,LEAVES:12)
Block(-4,17,2,LEAVES:12)
Block(-4,17,4,LEAVES:12)
Block(-4,17,16,LEAVES:12)
Block(-4,18,2,LEAVES:12)
Block(-4,18,4,LEAVES:12)
Block(-4,18,6,LEAVES:12)
Block(-4,19,0,LEAVES:12)
Block(-4,19,2,LEAVES:12)
Block(-4,19,3,LOG:12)
Block(-4,19,4,LEAVES:12)
Block(-4,19,6,LEAVES:12)
Block(-4,20,-2,LEAVES:12)
Block(-4,20,0,LEAVES:12)
Block(-4,20,2,LEAVES:12)
Block(-4,20,3,LEAVES:12)
Block(-4,20,7,LEAVES:12)
Block(-4,20,16,LEAVES:12)
Block(-4,21,2,LEAVES:12)
Block(-4,21,15,LEAVES:12)
Block(-4,21,16,LEAVES:12)
Block(-4,22,11,LEAVES:12)
Block(-4,23,3,LEAVES:12)
Block(-4,23,4,LEAVES:12)
Block(-4,24,4,LEAVES:12)
Block(-4,24,5,LEAVES:12)
Block(-4,25,4,LEAVES:12)
Block(-3,0,9,LOG:12)
Block(-3,0,10,LOG:12)
Block(-3,0,11,LOG:12)
Block(-3,1,9,LOG:12)
Block(-3,1,10,LOG:12)
Block(-3,1,11,LOG:12)
Block(-3,2,9,LOG:12)
Block(-3,2,10,LOG:12)
Block(-3,2,11,LOG:12)
Block(-3,3,10,LOG:12)
Block(-3,3,11,LOG:12)
Block(-3,4,10,LOG:12)
Block(-3,4,11,LOG:12)
Block(-3,4,19,LEAVES:12)
Block(-3,4,20,LEAVES:12)
Block(-3,5,10,LOG:12)
Block(-3,5,20,LEAVES:12)
Block(-3,6,-4,LEAVES:12)
Block(-3,6,2,LEAVES:12)
Block(-3,6,3,LEAVES:12)
Block(-3,6,10,LOG:12)
Block(-3,6,23,LEAVES:12)
Block(-3,7,-4,LEAVES:12)
Block(-3,7,0,LEAVES:12)
Block(-3,7,1,LEAVES:12)
Block(-3,7,2,LEAVES:12)
Block(-3,7,10,LOG:12)
Block(-3,7,20,LEAVES:12)
Block(-3,7,21,LEAVES:12)
Block(-3,7,23,LEAVES:12)
Block(-3,8,-2,LEAVES:12)
Block(-3,8,0,LEAVES:12)
Block(-3,8,21,LEAVES:12)
Block(-3,8,25,LEAVES:12)
Block(-3,9,-1,LEAVES:12)
Block(-3,9,19,LEAVES:12)
Block(-3,9,24,LEAVES:12)
Block(-3,10,-3,LEAVES:12)
Block(-3,10,-2,LEAVES:12)
Block(-3,10,-1,LOG:12)
Block(-3,10,0,LOG:12)
Block(-3,10,1,LEAVES:12)
Block(-3,10,2,LEAVES:12)
Block(-3,10,16,LEAVES:12)
Block(-3,10,17,LOG:12)
Block(-3,10,19,LEAVES:12)
Block(-3,10,21,LEAVES:12)
Block(-3,10,22,LEAVES:12)
Block(-3,10,24,LEAVES:12)
Block(-3,11,-4,LEAVES:12)
Block(-3,11,-3,LEAVES:12)
Block(-3,11,-1,LEAVES:12)
Block(-3,11,0,LOG:12)
Block(-3,11,4,LEAVES:12)
Block(-3,11,19,LEAVES:12)
Block(-3,11,21,LEAVES:12)
Block(-3,11,23,LEAVES:12)
Block(-3,11,24,LEAVES:12)
Block(-3,12,-3,LEAVES:12)
Block(-3,12,0,LOG:12)
Block(-3,12,1,LOG:12)
Block(-3,12,19,LEAVES:12)
Block(-3,13,1,LOG:12)
Block(-3,13,2,LOG:12)
Block(-3,13,3,LOG:12)
Block(-3,13,9,LOG:12)
Block(-3,13,18,LEAVES:12)
Block(-3,13,19,LEAVES:12)
Block(-3,13,25,LEAVES:12)
Block(-3,13,27,LEAVES:12)
Block(-3,13,28,LEAVES:12)
Block(-3,14,9,LOG:12)
Block(-3,14,10,LOG:12)
Block(-3,14,15,LOG:12)
Block(-3,14,16,LOG:12)
Block(-3,14,22,LEAVES:12)
Block(-3,14,23,LEAVES:12)
Block(-3,15,10,LOG:12)
Block(-3,16,1,LEAVES:12)
Block(-3,16,10,LOG:12)
Block(-3,17,5,LEAVES:12)
Block(-3,17,10,LOG:12)
Block(-3,17,11,LOG:12)
Block(-3,18,2,LEAVES:12)
Block(-3,18,4,LOG:12)
Block(-3,18,5,LEAVES:12)
Block(-3,18,13,LEAVES:12)
Block(-3,19,3,LOG:12)
Block(-3,19,4,LOG:12)
Block(-3,20,-1,LEAVES:12)
Block(-3,20,0,LEAVES:12)
Block(-3,20,3,LEAVES:12)
Block(-3,20,4,LEAVES:12)
Block(-3,21,2,LEAVES:12)
Block(-3,21,4,LEAVES:12)
Block(-3,21,15,LEAVES:12)
Block(-3,22,-1,LEAVES:12)
Block(-3,22,1,LEAVES:12)
Block(-3,22,2,LEAVES:12)
Block(-3,22,11,LEAVES:12)
Block(-3,22,12,LEAVES:12)
Block(-3,25,13,LEAVES:12)
Block(-3,25,15,LEAVES:12)
Block(-3,26,13,LEAVES:12)
Block(-2,0,10,LOG:12)
Block(-2,0,11,LOG:12)
Block(-2,1,10,LOG:12)
Block(-2,2,10,LOG:12)
Block(-2,3,10,LOG:12)
Block(-2,4,10,LOG:12)
Block(-2,4,11,LOG:12)
Block(-2,4,19,LEAVES:12)
Block(-2,5,-2,LEAVES:12)
Block(-2,5,10,LOG:12)
Block(-2,5,11,LOG:12)
Block(-2,6,-3,LEAVES:12)
Block(-2,6,3,LEAVES:12)
Block(-2,6,4,LEAVES:12)
Block(-2,6,10,LOG:12)
Block(-2,6,11,LOG:12)
Block(-2,6,22,LEAVES:12)
Block(-2,6,25,LEAVES:12)
Block(-2,7,-4,LEAVES:12)
Block(-2,7,-3,LEAVES:12)
Block(-2,7,9,LOG:12)
Block(-2,7,10,LOG:12)
Block(-2,7,11,LOG:12)
Block(-2,7,19,LEAVES:12)
Block(-2,7,21,LEAVES:12)
Block(-2,7,22,LEAVES:12)
Block(-2,7,23,LEAVES:12)
Block(-2,7,24,LEAVES:12)
Block(-2,8,-3,LEAVES:12)
Block(-2,8,-2,LEAVES:12)
Block(-2,8,-1,LOG:12)
Block(-2,8,0,LEAVES:12)
Block(-2,8,9,LOG:12)
Block(-2,8,10,LOG:12)
Block(-2,8,19,LEAVES:12)
Block(-2,8,20,LEAVES:12)
Block(-2,8,24,LEAVES:12)
Block(-2,8,27,LEAVES:12)
Block(-2,9,-1,LOG:12)
Block(-2,9,0,LEAVES:12)
Block(-2,9,1,LEAVES:12)
Block(-2,9,8,LOG:12)
Block(-2,9,9,LOG:12)
Block(-2,9,10,LOG:12)
Block(-2,9,24,LEAVES:12)
Block(-2,10,-1,LOG:12)
Block(-2,10,1,LEAVES:12)
Block(-2,10,8,LOG:12)
Block(-2,10,9,LOG:12)
Block(-2,10,17,LOG:12)
Block(-2,10,22,LEAVES:12)
Block(-2,11,-1,LEAVES:12)
Block(-2,11,0,LEAVES:12)
Block(-2,11,7,LOG:12)
Block(-2,11,8,LOG:12)
Block(-2,11,9,LOG:12)
Block(-2,11,16,LOG:12)
Block(-2,11,17,LOG:12)
Block(-2,11,23,LEAVES:12)
Block(-2,12,0,LEAVES:12)
Block(-2,12,7,LOG:12)
Block(-2,12,9,LOG:12)
Block(-2,12,19,LEAVES:12)
Block(-2,12,26,LEAVES:12)
Block(-2,12,27,LEAVES:12)
Block(-2,13,-1,LEAVES:12)
Block(-2,13,3,LOG:12)
Block(-2,13,4,LOG:12)
Block(-2,13,5,LOG:12)
Block(-2,13,7,LOG:12)
Block(-2,13,9,LOG:12)
Block(-2,13,15,LOG:12)
Block(-2,13,19,LEAVES:12)
Block(-2,13,20,LEAVES:12)
Block(-2,13,23,LEAVES:12)
Block(-2,13,27,LEAVES:12)
Block(-2,14,15,LOG:12)
Block(-2,14,23,LEAVES:12)
Block(-2,14,27,LEAVES:12)
Block(-2,15,23,LEAVES:12)
Block(-2,16,5,LEAVES:12)
Block(-2,17,1,LEAVES:12)
Block(-2,17,2,LEAVES:12)
Block(-2,17,4,LOG:12)
Block(-2,17,5,LOG:12)
Block(-2,17,11,LOG:12)
Block(-2,17,14,LEAVES:12)
Block(-2,18,2,LEAVES:12)
Block(-2,18,4,LOG:12)
Block(-2,18,11,LOG:12)
Block(-2,18,12,LOG:12)
Block(-2,18,14,LEAVES:12)
Block(-2,19,2,LEAVES:12)
Block(-2,19,16,LEAVES:12)
Block(-2,20,-2,LEAVES:12)
Block(-2,20,-1,LEAVES:12)
Block(-2,20,10,LEAVES:12)
Block(-2,21,4,LEAVES:12)
Block(-2,21,5,LEAVES:12)
Block(-2,21,6,LEAVES:12)
Block(-2,21,12,LEAVES:12)
Block(-2,21,13,LEAVES:12)
Block(-2,21,15,LEAVES:12)
Block(-2,22,0,LEAVES:12)
Block(-2,22,1,LEAVES:12)
Block(-2,22,5,LEAVES:12)
Block(-2,22,12,LEAVES:12)
Block(-2,22,14,LEAVES:12)
Block(-2,22,15,LEAVES:12)
Block(-2,23,3,LEAVES:12)
Block(-2,24,16,LEAVES:12)
Block(-2,24,18,LEAVES:12)
Block(-2,24,19,LEAVES:12)
Block(-2,25,13,LEAVES:12)
Block(-2,25,14,LEAVES:12)
Block(-1,5,1,LEAVES:12)
Block(-1,6,-1,LEAVES:12)
Block(-1,6,1,LEAVES:12)
Block(-1,6,9,LOG:12)
Block(-1,6,10,LOG:12)
Block(-1,6,22,LEAVES:12)
Block(-1,7,-1,LEAVES:12)
Block(-1,7,1,LEAVES:12)
Block(-1,7,3,LEAVES:12)
Block(-1,7,9,LOG:12)
Block(-1,7,10,LOG:12)
Block(-1,8,-3,LEAVES:12)
Block(-1,8,-1,LEAVES:12)
Block(-1,8,0,LEAVES:12)
Block(-1,8,1,LEAVES:12)
Block(-1,8,3,LEAVES:12)
Block(-1,8,9,LOG:12)
Block(-1,8,10,LOG:12)
Block(-1,8,20,LEAVES:12)
Block(-1,8,26,LEAVES:12)
Block(-1,8,27,LEAVES:12)
Block(-1,9,-5,LEAVES:12)
Block(-1,9,-3,LEAVES:12)
Block(-1,9,-1,LEAVES:12)
Block(-1,9,0,LEAVES:12)
Block(-1,9,4,LEAVES:12)
Block(-1,9,8,LOG:12)
Block(-1,9,9,LOG:12)
Block(-1,9,10,LOG:12)
Block(-1,9,20,LEAVES:12)
Block(-1,9,24,LEAVES:12)
Block(-1,9,25,LEAVES:12)
Block(-1,9,26,LEAVES:12)
Block(-1,10,-1,LEAVES:12)
Block(-1,10,10,LOG:12)
Block(-1,10,22,LEAVES:12)
Block(-1,10,24,LEAVES:12)
Block(-1,11,15,LOG:12)
Block(-1,11,16,LOG:12)
Block(-1,11,22,LOG:12)
Block(-1,11,23,LEAVES:12)
Block(-1,12,0,LEAVES:12)
Block(-1,12,1,LEAVES:12)
Block(-1,12,14,LOG:12)
Block(-1,12,15,LOG:12)
Block(-1,12,20,LOG:12)
Block(-1,12,21,LOG:12)
Block(-1,12,22,LOG:12)
Block(-1,12,23,LEAVES:12)
Block(-1,12,25,LEAVES:12)
Block(-1,12,26,LEAVES:12)
Block(-1,13,1,LEAVES:12)
Block(-1,13,2,LEAVES:12)
Block(-1,13,5,LOG:12)
Block(-1,13,6,LOG:12)
Block(-1,13,7,LOG:12)
Block(-1,13,15,LOG:12)
Block(-1,13,16,LOG:12)
Block(-1,13,17,LOG:12)
Block(-1,13,19,LOG:12)
Block(-1,13,20,LOG:12)
Block(-1,13,21,LEAVES:12)
Block(-1,13,22,LEAVES:12)
Block(-1,13,23,LEAVES:12)
Block(-1,13,28,LEAVES:12)
Block(-1,14,1,LEAVES:12)
Block(-1,14,6,LOG:12)
Block(-1,14,21,LEAVES:12)
Block(-1,14,22,LEAVES:12)
Block(-1,15,5,LOG:12)
Block(-1,15,6,LOG:12)
Block(-1,15,17,LEAVES:12)
Block(-1,16,0,LEAVES:12)
Block(-1,16,1,LEAVES:12)
Block(-1,16,5,LOG:12)
Block(-1,17,1,LEAVES:12)
Block(-1,17,5,LOG:12)
Block(-1,17,16,LEAVES:12)
Block(-1,18,10,LEAVES:12)
Block(-1,18,12,LOG:12)
Block(-1,18,14,LEAVES:12)
Block(-1,18,15,LEAVES:12)
Block(-1,19,1,LEAVES:12)
Block(-1,19,2,LEAVES:12)
Block(-1,19,10,LEAVES:12)
Block(-1,19,11,LEAVES:12)
Block(-1,19,15,LEAVES:12)
Block(-1,19,18,LEAVES:12)
Block(-1,20,2,LEAVES:12)
Block(-1,20,15,LEAVES:12)
Block(-1,21,5,LEAVES:12)
Block(-1,21,13,LEAVES:12)
Block(-1,22,0,LEAVES:12)
Block(-1,22,14,LEAVES:12)
Block(-1,23,0,LEAVES:12)
Block(-1,23,17,LEAVES:12)
Block(-1,23,18,LEAVES:12)
Block(-1,24,10,LEAVES:12)
Block(-1,24,11,LEAVES:12)
Block(-1,24,14,LEAVES:12)
Block(-1,24,18,LEAVES:12)
Block(-1,25,14,LEAVES:12)
Block(-1,25,18,LEAVES:12)
Block(-1,26,14,LEAVES:12)
Block(0,5,-2,LEAVES:12)
Block(0,6,2,LEAVES:12)
Block(0,6,3,LEAVES:12)
Block(0,7,-1,LEAVES:12)
Block(0,7,1,LEAVES:12)
Block(0,7,2,LEAVES:12)
Block(0,7,3,LEAVES:12)
Block(0,7,22,LEAVES:12)
Block(0,8,-2,LEAVES:12)
Block(0,8,21,LEAVES:12)
Block(0,8,27,LEAVES:12)
Block(0,8,28,LEAVES:12)
Block(0,9,-4,LEAVES:12)
Block(0,9,-3,LEAVES:12)
Block(0,9,0,LEAVES:12)
Block(0,9,1,LEAVES:12)
Block(0,9,20,LEAVES:12)
Block(0,9,21,LEAVES:12)
Block(0,10,-1,LEAVES:12)
Block(0,10,1,LEAVES:12)
Block(0,10,10,LOG:12)
Block(0,10,21,LEAVES:12)
Block(0,10,22,LEAVES:12)
Block(0,10,23,LEAVES:12)
Block(0,10,24,LEAVES:12)
Block(0,11,-4,LEAVES:12)
Block(0,11,-2,LEAVES:12)
Block(0,11,-1,LEAVES:12)
Block(0,11,10,LOG:12)
Block(0,11,11,LOG:12)
Block(0,11,19,LEAVES:12)
Block(0,11,22,LOG:12)
Block(0,11,23,LOG:12)
Block(0,11,24,LOG:12)
Block(0,11,25,LEAVES:12)
Block(0,12,13,LOG:12)
Block(0,12,14,LOG:12)
Block(0,12,23,LEAVES:12)
Block(0,12,25,LEAVES:12)
Block(0,13,17,LOG:12)
Block(0,13,18,LOG:12)
Block(0,13,19,LOG:12)
Block(0,13,23,LEAVES:12)
Block(0,13,24,LEAVES:12)
Block(0,14,6,LOG:12)
Block(0,14,18,LOG:12)
Block(0,14,21,LEAVES:12)
Block(0,14,24,LEAVES:12)
Block(0,15,17,LEAVES:12)
Block(0,15,18,LEAVES:12)
Block(0,15,23,LEAVES:12)
Block(0,16,0,LEAVES:12)
Block(0,17,5,LOG:12)
Block(0,17,7,LEAVES:12)
Block(0,18,3,LEAVES:12)
Block(0,18,5,LOG:12)
Block(0,18,6,LEAVES:12)
Block(0,18,7,LEAVES:12)
Block(0,18,12,LOG:12)
Block(0,18,19,LEAVES:12)
Block(0,18,21,LEAVES:12)
Block(0,19,2,LEAVES:12)
Block(0,19,3,LEAVES:12)
Block(0,19,11,LEAVES:12)
Block(0,19,12,LOG:12)
Block(0,19,13,LOG:12)
Block(0,19,17,LEAVES:12)
Block(0,19,18,LEAVES:12)
Block(0,19,19,LEAVES:12)
Block(0,20,11,LEAVES:12)
Block(0,20,13,LOG:12)
Block(0,20,15,LEAVES:12)
Block(0,20,16,LEAVES:12)
Block(0,20,17,LEAVES:12)
Block(0,21,13,LOG:12)
Block(0,21,14,LOG:12)
Block(0,21,15,LEAVES:12)
Block(0,22,14,LEAVES:12)
Block(0,23,12,LEAVES:12)
Block(0,23,13,LEAVES:12)
Block(0,23,14,LEAVES:12)
Block(0,23,16,LEAVES:12)
Block(0,23,17,LEAVES:12)
Block(0,24,11,LEAVES:12)
Block(0,24,12,LEAVES:12)
Block(0,24,14,LEAVES:12)
Block(0,24,19,LEAVES:12)
Block(0,25,12,LEAVES:12)
Block(1,4,0,LEAVES:12)
Block(1,5,2,LEAVES:12)
Block(1,6,-2,LEAVES:12)
Block(1,6,-1,LEAVES:12)
Block(1,6,2,LEAVES:12)
Block(1,7,-1,LEAVES:12)
Block(1,7,2,LEAVES:12)
Block(1,7,25,LEAVES:12)
Block(1,8,-2,LEAVES:12)
Block(1,8,-1,LEAVES:12)
Block(1,8,23,LEAVES:12)
Block(1,8,25,LEAVES:12)
Block(1,9,-5,LEAVES:12)
Block(1,9,-4,LEAVES:12)
Block(1,9,23,LEAVES:12)
Block(1,9,25,LEAVES:12)
Block(1,9,27,LEAVES:12)
Block(1,10,1,LEAVES:12)
Block(1,10,2,LEAVES:12)
Block(1,10,3,LEAVES:12)
Block(1,10,20,LEAVES:12)
Block(1,10,21,LEAVES:12)
Block(1,10,23,LEAVES:12)
Block(1,10,24,LEAVES:12)
Block(1,10,25,LEAVES:12)
Block(1,10,27,LEAVES:12)
Block(1,11,-3,LEAVES:12)
Block(1,11,-2,LEAVES:12)
Block(1,11,0,LEAVES:12)
Block(1,11,2,LEAVES:12)
Block(1,11,11,LOG:12)
Block(1,11,19,LEAVES:12)
Block(1,11,20,LEAVES:12)
Block(1,11,21,LEAVES:12)
Block(1,11,23,LEAVES:12)
Block(1,11,24,LEAVES:12)
Block(1,11,28,LEAVES:12)
Block(1,12,0,LEAVES:12)
Block(1,12,11,LOG:12)
Block(1,12,12,LOG:12)
Block(1,12,13,LOG:12)
Block(1,12,22,LEAVES:12)
Block(1,12,23,LEAVES:12)
Block(1,13,16,LEAVES:12)
Block(1,14,6,LOG:12)
Block(1,14,18,LOG:12)
Block(1,14,19,LOG:12)
Block(1,14,21,LEAVES:12)
Block(1,14,24,LEAVES:12)
Block(1,14,25,LEAVES:12)
Block(1,15,4,LEAVES:12)
Block(1,15,18,LEAVES:12)
Block(1,15,20,LEAVES:12)
Block(1,15,21,LEAVES:12)
Block(1,15,25,LEAVES:12)
Block(1,15,26,LEAVES:12)
Block(1,16,25,LEAVES:12)
Block(1,17,22,LEAVES:12)
Block(1,17,24,LEAVES:12)
Block(1,17,25,LEAVES:12)
Block(1,18,3,LEAVES:12)
Block(1,18,5,LOG:12)
Block(1,18,6,LEAVES:12)
Block(1,18,13,LEAVES:12)
Block(1,18,19,LEAVES:12)
Block(1,18,20,LEAVES:12)
Block(1,19,2,LEAVES:12)
Block(1,19,3,LEAVES:12)
Block(1,19,12,LEAVES:12)
Block(1,19,18,LEAVES:12)
Block(1,19,19,LEAVES:12)
Block(1,20,11,LEAVES:12)
Block(1,20,12,LEAVES:12)
Block(1,21,12,LEAVES:12)
Block(1,21,13,LEAVES:12)
Block(1,21,14,LOG:12)
Block(1,21,15,LEAVES:12)
Block(1,22,4,LEAVES:12)
Block(1,22,6,LEAVES:12)
Block(1,22,14,LOG:12)
Block(1,22,15,LEAVES:12)
Block(1,22,16,LEAVES:12)
Block(1,23,4,LEAVES:12)
Block(1,23,14,LEAVES:12)
Block(1,23,16,LEAVES:12)
Block(1,24,14,LEAVES:12)
Block(1,24,15,LEAVES:12)
Block(1,25,15,LEAVES:12)
Block(1,26,14,LEAVES:12)
Block(2,3,1,LEAVES:12)
Block(2,4,1,LEAVES:12)
Block(2,5,-3,LEAVES:12)
Block(2,5,-2,LEAVES:12)
Block(2,5,3,LEAVES:12)
Block(2,6,-3,LEAVES:12)
Block(2,6,-2,LEAVES:12)
Block(2,7,-1,LEAVES:12)
Block(2,7,0,LEAVES:12)
Block(2,7,2,LEAVES:12)
Block(2,7,22,LEAVES:12)
Block(2,8,-2,LEAVES:12)
Block(2,8,-1,LEAVES:12)
Block(2,8,1,LEAVES:12)
Block(2,8,2,LEAVES:12)
Block(2,8,26,LEAVES:12)
Block(2,9,-1,LEAVES:12)
Block(2,9,23,LEAVES:12)
Block(2,9,25,LEAVES:12)
Block(2,9,26,LEAVES:12)
Block(2,10,2,LEAVES:12)
Block(2,10,3,LEAVES:12)
Block(2,10,5,LEAVES:12)
Block(2,10,6,LEAVES:12)
Block(2,10,22,LEAVES:12)
Block(2,11,-3,LEAVES:12)
Block(2,11,0,LEAVES:12)
Block(2,11,1,LEAVES:12)
Block(2,11,14,LOG:12)
Block(2,11,16,LEAVES:12)
Block(2,11,20,LEAVES:12)
Block(2,11,21,LEAVES:12)
Block(2,11,24,LEAVES:12)
Block(2,11,25,LEAVES:12)
Block(2,12,-3,LEAVES:12)
Block(2,12,11,LOG:12)
Block(2,12,13,LOG:12)
Block(2,12,14,LOG:12)
Block(2,12,15,LEAVES:12)
Block(2,12,16,LEAVES:12)
Block(2,12,17,LEAVES:12)
Block(2,12,21,LEAVES:12)
Block(2,12,23,LEAVES:12)
Block(2,12,24,LEAVES:12)
Block(2,12,25,LEAVES:12)
Block(2,13,11,LOG:12)
Block(2,13,14,LEAVES:12)
Block(2,13,15,LEAVES:12)
Block(2,13,20,LEAVES:12)
Block(2,13,21,LEAVES:12)
Block(2,13,22,LEAVES:12)
Block(2,13,23,LEAVES:12)
Block(2,14,5,LEAVES:12)
Block(2,14,6,LOG:12)
Block(2,14,10,LEAVES:12)
Block(2,14,19,LOG:12)
Block(2,14,20,LOG:12)
Block(2,15,5,LEAVES:12)
Block(2,15,20,LEAVES:12)
Block(2,16,7,LEAVES:12)
Block(2,16,23,LEAVES:12)
Block(2,16,24,LEAVES:12)
Block(2,17,1,LEAVES:12)
Block(2,17,16,LEAVES:12)
Block(2,17,17,LEAVES:12)
Block(2,17,20,LEAVES:12)
Block(2,17,24,LEAVES:12)
Block(2,18,3,LEAVES:12)
Block(2,18,4,LEAVES:12)
Block(2,18,5,LOG:12)
Block(2,18,6,LOG:12)
Block(2,18,16,LEAVES:12)
Block(2,18,20,LEAVES:12)
Block(2,18,24,LEAVES:12)
Block(2,19,3,LEAVES:12)
Block(2,19,5,LEAVES:12)
Block(2,19,6,LOG:12)
Block(2,19,14,LEAVES:12)
Block(2,19,16,LEAVES:12)
Block(2,19,20,LEAVES:12)
Block(2,20,14,LEAVES:12)
Block(2,20,16,LEAVES:12)
Block(2,20,18,LEAVES:12)
Block(2,21,7,LEAVES:12)
Block(2,21,9,LEAVES:12)
Block(2,21,10,LEAVES:12)
Block(2,21,12,LEAVES:12)
Block(2,21,14,LEAVES:12)
Block(2,21,15,LEAVES:12)
Block(2,21,16,LEAVES:12)
Block(2,21,18,LEAVES:12)
Block(2,22,4,LEAVES:12)
Block(2,22,5,LEAVES:12)
Block(2,22,10,LEAVES:12)
Block(2,22,12,LEAVES:12)
Block(2,22,14,LEAVES:12)
Block(2,22,15,LEAVES:12)
Block(2,22,19,LEAVES:12)
Block(2,23,14,LEAVES:12)
Block(2,25,15,LEAVES:12)
Block(2,25,16,LEAVES:12)
Block(2,26,16,LEAVES:12)
Block(2,26,17,LEAVES:12)
Block(2,27,16,LEAVES:12)
Block(3,3,3,LEAVES:12)
Block(3,4,-3,LEAVES:12)
Block(3,4,1,LEAVES:12)
Block(3,4,2,LEAVES:12)
Block(3,5,-3,LEAVES:12)
Block(3,5,-2,LEAVES:12)
Block(3,5,2,LEAVES:12)
Block(3,5,5,LEAVES:12)
Block(3,6,2,LEAVES:12)
Block(3,7,0,LEAVES:12)
Block(3,7,26,LEAVES:12)
Block(3,8,-1,LEAVES:12)
Block(3,8,0,LEAVES:12)
Block(3,8,1,LEAVES:12)
Block(3,8,22,LEAVES:12)
Block(3,8,23,LEAVES:12)
Block(3,8,26,LEAVES:12)
Block(3,9,4,LEAVES:12)
Block(3,9,5,LEAVES:12)
Block(3,9,23,LEAVES:12)
Block(3,10,-3,LEAVES:12)
Block(3,10,-2,LEAVES:12)
Block(3,10,1,LEAVES:12)
Block(3,10,5,LEAVES:12)
Block(3,10,12,LEAVES:12)
Block(3,10,15,LOG:12)
Block(3,10,23,LEAVES:12)
Block(3,11,1,LEAVES:12)
Block(3,11,5,LEAVES:12)
Block(3,11,14,LOG:12)
Block(3,11,15,LOG:12)
Block(3,11,19,LEAVES:12)
Block(3,11,20,LEAVES:12)
Block(3,12,1,LEAVES:12)
Block(3,12,3,LOG:12)
Block(3,12,17,LEAVES:12)
Block(3,12,23,LEAVES:12)
Block(3,12,24,LEAVES:12)
Block(3,12,25,LEAVES:12)
Block(3,12,26,LEAVES:12)
Block(3,12,27,LEAVES:12)
Block(3,13,3,LOG:12)
Block(3,13,4,LOG:12)
Block(3,13,5,LOG:12)
Block(3,13,11,LOG:12)
Block(3,13,14,LEAVES:12)
Block(3,13,17,LEAVES:12)
Block(3,13,21,LEAVES:12)
Block(3,13,22,LEAVES:12)
Block(3,13,23,LEAVES:12)
Block(3,13,26,LEAVES:12)
Block(3,14,5,LOG:12)
Block(3,14,6,LOG:12)
Block(3,14,7,LEAVES:12)
Block(3,14,10,LEAVES:12)
Block(3,14,11,LOG:12)
Block(3,14,19,LEAVES:12)
Block(3,14,20,LOG:12)
Block(3,14,21,LEAVES:12)
Block(3,14,24,LEAVES:12)
Block(3,15,1,LEAVES:12)
Block(3,15,5,LEAVES:12)
Block(3,15,6,LEAVES:12)
Block(3,15,20,LOG:12)
Block(3,16,1,LEAVES:12)
Block(3,16,2,LEAVES:12)
Block(3,16,6,LEAVES:12)
Block(3,16,9,LEAVES:12)
Block(3,16,18,LEAVES:12)
Block(3,16,19,LEAVES:12)
Block(3,16,20,LEAVES:12)
Block(3,16,22,LEAVES:12)
Block(3,16,23,LEAVES:12)
Block(3,17,6,LEAVES:12)
Block(3,17,12,LEAVES:12)
Block(3,17,14,LEAVES:12)
Block(3,17,17,LEAVES:12)
Block(3,17,18,LEAVES:12)
Block(3,17,20,LEAVES:12)
Block(3,17,25,LEAVES:12)
Block(3,18,4,LEAVES:12)
Block(3,18,12,LEAVES:12)
Block(3,18,13,LEAVES:12)
Block(3,18,18,LEAVES:12)
Block(3,19,5,LEAVES:12)
Block(3,19,6,LOG:12)
Block(3,19,17,LEAVES:12)
Block(3,20,8,LEAVES:12)
Block(3,20,9,LEAVES:12)
Block(3,20,14,LEAVES:12)
Block(3,20,16,LEAVES:12)
Block(3,20,17,LEAVES:12)
Block(3,21,1,LEAVES:12)
Block(3,21,2,LEAVES:12)
Block(3,21,5,LEAVES:12)
Block(3,21,9,LEAVES:12)
Block(3,22,5,LEAVES:12)
Block(3,22,9,LEAVES:12)
Block(3,22,11,LEAVES:12)
Block(3,22,12,LEAVES:12)
Block(3,22,15,LEAVES:12)
Block(3,22,16,LEAVES:12)
Block(3,23,5,LEAVES:12)
Block(3,23,14,LEAVES:12)
Block(3,23,16,LEAVES:12)
Block(3,24,11,LEAVES:12)
Block(3,24,13,LEAVES:12)
Block(3,24,14,LEAVES:12)
Block(4,5,-2,LEAVES:12)
Block(4,5,4,LEAVES:12)
Block(4,5,5,LEAVES:12)
Block(4,6,-2,LEAVES:12)
Block(4,6,2,LEAVES:12)
Block(4,6,3,LEAVES:12)
Block(4,6,4,LEAVES:12)
Block(4,7,0,LEAVES:12)
Block(4,7,2,LEAVES:12)
Block(4,7,21,LEAVES:12)
Block(4,7,22,LEAVES:12)
Block(4,8,1,LEAVES:12)
Block(4,8,22,LEAVES:12)
Block(4,9,-1,LEAVES:12)
Block(4,9,0,LEAVES:12)
Block(4,9,1,LEAVES:12)
Block(4,9,3,LEAVES:12)
Block(4,9,4,LEAVES:12)
Block(4,9,13,LEAVES:12)
Block(4,10,-2,LEAVES:12)
Block(4,10,-1,LEAVES:12)
Block(4,10,1,LOG:12)
Block(4,10,2,LOG:12)
Block(4,10,6,LEAVES:12)
Block(4,10,13,LEAVES:12)
Block(4,10,15,LOG:12)
Block(4,10,22,LEAVES:12)
Block(4,10,23,LEAVES:12)
Block(4,11,-1,LEAVES:12)
Block(4,11,2,LOG:12)
Block(4,11,15,LEAVES:12)
Block(4,11,19,LEAVES:12)
Block(4,11,23,LEAVES:12)
Block(4,12,2,LOG:12)
Block(4,12,3,LOG:12)
Block(4,12,9,LEAVES:12)
Block(4,12,18,LEAVES:12)
Block(4,12,24,LEAVES:12)
Block(4,12,25,LEAVES:12)
Block(4,12,26,LEAVES:12)
Block(4,13,5,LOG:12)
Block(4,13,11,LEAVES:12)
Block(4,13,12,LEAVES:12)
Block(4,13,14,LEAVES:12)
Block(4,13,17,LEAVES:12)
Block(4,13,18,LEAVES:12)
Block(4,13,21,LEAVES:12)
Block(4,14,11,LOG:12)
Block(4,14,12,LOG:12)
Block(4,14,13,LEAVES:12)
Block(4,14,14,LEAVES:12)
Block(4,14,18,LEAVES:12)
Block(4,14,19,LEAVES:12)
Block(4,14,20,LEAVES:12)
Block(4,14,21,LEAVES:12)
Block(4,15,20,LOG:12)
Block(4,15,21,LEAVES:12)
Block(4,15,22,LEAVES:12)
Block(4,16,2,LEAVES:12)
Block(4,16,8,LEAVES:12)
Block(4,16,9,LEAVES:12)
Block(4,16,15,LEAVES:12)
Block(4,16,17,LEAVES:12)
Block(4,16,18,LEAVES:12)
Block(4,16,20,LEAVES:12)
Block(4,16,22,LEAVES:12)
Block(4,17,2,LEAVES:12)
Block(4,17,6,LEAVES:12)
Block(4,17,7,LEAVES:12)
Block(4,17,8,LEAVES:12)
Block(4,17,12,LEAVES:12)
Block(4,17,13,LEAVES:12)
Block(4,17,20,LEAVES:12)
Block(4,17,21,LEAVES:12)
Block(4,18,4,LEAVES:12)
Block(4,18,6,LEAVES:12)
Block(4,18,17,LEAVES:12)
Block(4,18,21,LEAVES:12)
Block(4,19,5,LOG:12)
Block(4,19,6,LOG:12)
Block(4,19,13,LEAVES:12)
Block(4,19,14,LEAVES:12)
Block(4,19,17,LEAVES:12)
Block(4,19,20,LEAVES:12)
Block(4,20,3,LEAVES:12)
Block(4,20,4,LEAVES:12)
Block(4,20,5,LEAVES:12)
Block(4,20,7,LEAVES:12)
Block(4,20,8,LEAVES:12)
Block(4,20,14,LEAVES:12)
Block(4,21,2,LEAVES:12)
Block(4,21,3,LEAVES:12)
Block(4,21,5,LEAVES:12)
Block(4,21,10,LEAVES:12)
Block(4,21,14,LEAVES:12)
Block(4,22,3,LEAVES:12)
Block(4,22,10,LEAVES:12)
Block(4,22,11,LEAVES:12)
Block(4,23,16,LEAVES:12)
Block(4,23,17,LEAVES:12)
Block(4,23,18,LEAVES:12)
Block(4,24,12,LEAVES:12)
Block(4,24,13,LEAVES:12)
Block(4,24,17,LEAVES:12)
Block(4,25,15,LEAVES:12)
Block(5,4,0,LEAVES:12)
Block(5,5,-1,LEAVES:12)
Block(5,5,5,LEAVES:12)
Block(5,5,6,LEAVES:12)
Block(5,6,-2,LEAVES:12)
Block(5,6,-1,LEAVES:12)
Block(5,7,-1,LEAVES:12)
Block(5,7,0,LEAVES:12)
Block(5,7,1,LEAVES:12)
Block(5,7,2,LEAVES:12)
Block(5,7,21,LEAVES:12)
Block(5,8,1,LOG:12)
Block(5,8,2,LEAVES:12)
Block(5,8,3,LEAVES:12)
Block(5,9,1,LOG:12)
Block(5,9,3,LEAVES:12)
Block(5,9,15,LOG:12)
Block(5,9,16,LOG:12)
Block(5,9,24,LEAVES:12)
Block(5,10,1,LOG:12)
Block(5,10,2,LEAVES:12)
Block(5,10,9,LEAVES:12)
Block(5,10,13,LEAVES:12)
Block(5,10,14,LEAVES:12)
Block(5,10,15,LOG:12)
Block(5,10,23,LEAVES:12)
Block(5,10,24,LEAVES:12)
Block(5,11,2,LEAVES:12)
Block(5,11,9,LEAVES:12)
Block(5,11,10,LEAVES:12)
Block(5,11,14,LEAVES:12)
Block(5,11,17,LEAVES:12)
Block(5,11,22,LEAVES:12)
Block(5,12,1,LEAVES:12)
Block(5,12,14,LEAVES:12)
Block(5,12,20,LEAVES:12)
Block(5,12,22,LEAVES:12)
Block(5,13,5,LOG:12)
Block(5,13,12,LEAVES:12)
Block(5,13,20,LEAVES:12)
Block(5,13,22,LEAVES:12)
Block(5,13,24,LEAVES:12)
Block(5,14,12,LOG:12)
Block(5,14,13,LOG:12)
Block(5,14,18,LEAVES:12)
Block(5,14,20,LEAVES:12)
Block(5,14,21,LEAVES:12)
Block(5,14,22,LEAVES:12)
Block(5,14,24,LEAVES:12)
Block(5,15,4,LEAVES:12)
Block(5,15,16,LEAVES:12)
Block(5,15,17,LEAVES:12)
Block(5,15,18,LEAVES:12)
Block(5,15,20,LEAVES:12)
Block(5,15,21,LEAVES:12)
Block(5,15,25,LEAVES:12)
Block(5,16,3,LEAVES:12)
Block(5,16,9,LEAVES:12)
Block(5,16,10,LEAVES:12)
Block(5,16,13,LEAVES:12)
Block(5,16,17,LEAVES:12)
Block(5,16,20,LEAVES:12)
Block(5,17,2,LEAVES:12)
Block(5,17,3,LEAVES:12)
Block(5,17,13,LEAVES:12)
Block(5,17,17,LEAVES:12)
Block(5,18,3,LEAVES:12)
Block(5,18,4,LEAVES:12)
Block(5,18,5,LEAVES:12)
Block(5,18,6,LEAVES:12)
Block(5,18,12,LEAVES:12)
Block(5,18,13,LEAVES:12)
Block(5,18,21,LEAVES:12)
Block(5,18,22,LEAVES:12)
Block(5,19,5,LOG:12)
Block(5,19,6,LEAVES:12)
Block(5,19,7,LEAVES:12)
Block(5,19,13,LEAVES:12)
Block(5,19,22,LEAVES:12)
Block(5,19,23,LEAVES:12)
Block(5,20,5,LEAVES:12)
Block(5,20,7,LEAVES:12)
Block(5,20,22,LEAVES:12)
Block(5,21,5,LEAVES:12)
Block(5,21,6,LEAVES:12)
Block(5,21,13,LEAVES:12)
Block(5,21,14,LEAVES:12)
Block(5,22,6,LEAVES:12)
Block(5,22,14,LEAVES:12)
Block(5,23,5,LEAVES:12)
Block(5,23,17,LEAVES:12)
Block(5,24,12,LEAVES:12)
Block(5,25,12,LEAVES:12)
Block(6,4,3,LEAVES:12)
Block(6,5,1,LEAVES:12)
Block(6,5,3,LEAVES:12)
Block(6,6,1,LEAVES:12)
Block(6,6,3,LEAVES:12)
Block(6,6,5,LEAVES:12)
Block(6,7,-1,LEAVES:12)
Block(6,7,1,LEAVES:12)
Block(6,7,2,LEAVES:12)
Block(6,7,3,LEAVES:12)
Block(6,7,5,LEAVES:12)
Block(6,8,-3,LEAVES:12)
Block(6,8,-1,LEAVES:12)
Block(6,8,1,LEAVES:12)
Block(6,8,2,LEAVES:12)
Block(6,8,6,LEAVES:12)
Block(6,8,16,LOG:12)
Block(6,9,1,LEAVES:12)
Block(6,9,16,LOG:12)
Block(6,9,24,LEAVES:12)
Block(6,11,2,LEAVES:12)
Block(6,11,3,LEAVES:12)
Block(6,11,10,LEAVES:12)
Block(6,11,16,LEAVES:12)
Block(6,11,17,LEAVES:12)
Block(6,11,19,LEAVES:12)
Block(6,12,3,LEAVES:12)
Block(6,12,4,LEAVES:12)
Block(6,12,5,LOG:12)
Block(6,12,10,LEAVES:12)
Block(6,12,14,LEAVES:12)
Block(6,12,15,LEAVES:12)
Block(6,12,16,LEAVES:12)
Block(6,12,23,LEAVES:12)
Block(6,13,3,LEAVES:12)
Block(6,13,5,LOG:12)
Block(6,13,12,LEAVES:12)
Block(6,13,14,LEAVES:12)
Block(6,13,20,LEAVES:12)
Block(6,13,22,LEAVES:12)
Block(6,13,23,LEAVES:12)
Block(6,14,13,LOG:12)
Block(6,15,7,LEAVES:12)
Block(6,15,11,LEAVES:12)
Block(6,15,12,LEAVES:12)
Block(6,15,13,LEAVES:12)
Block(6,15,15,LEAVES:12)
Block(6,15,16,LEAVES:12)
Block(6,15,17,LEAVES:12)
Block(6,15,18,LEAVES:12)
Block(6,15,21,LEAVES:12)
Block(6,15,22,LEAVES:12)
Block(6,16,5,LEAVES:12)
Block(6,16,7,LEAVES:12)
Block(6,16,10,LEAVES:12)
Block(6,16,11,LEAVES:12)
Block(6,16,13,LEAVES:12)
Block(6,16,18,LEAVES:12)
Block(6,16,20,LEAVES:12)
Block(6,16,22,LEAVES:12)
Block(6,17,5,LEAVES:12)
Block(6,17,7,LEAVES:12)
Block(6,17,9,LEAVES:12)
Block(6,17,11,LEAVES:12)
Block(6,17,17,LEAVES:12)
Block(6,17,19,LEAVES:12)
Block(6,17,20,LEAVES:12)
Block(6,18,3,LEAVES:12)
Block(6,18,5,LEAVES:12)
Block(6,18,6,LEAVES:12)
Block(6,18,7,LEAVES:12)
Block(6,18,9,LEAVES:12)
Block(6,18,12,LEAVES:12)
Block(6,19,1,LEAVES:12)
Block(6,19,3,LEAVES:12)
Block(6,19,5,LEAVES:12)
Block(6,19,6,LEAVES:12)
Block(6,19,10,LEAVES:12)
Block(6,20,5,LEAVES:12)
Block(6,20,15,LEAVES:12)
Block(6,21,14,LEAVES:12)
Block(6,21,15,LEAVES:12)
Block(6,22,6,LEAVES:12)
Block(6,22,7,LEAVES:12)
Block(6,23,7,LEAVES:12)
Block(6,23,8,LEAVES:12)
Block(6,24,7,LEAVES:12)
Block(7,4,0,LEAVES:12)
Block(7,5,4,LEAVES:12)
Block(7,6,1,LEAVES:12)
Block(7,6,3,LEAVES:12)
Block(7,6,4,LEAVES:12)
Block(7,8,-2,LEAVES:12)
Block(7,8,-1,LEAVES:12)
Block(7,8,2,LEAVES:12)
Block(7,8,3,LEAVES:12)
Block(7,8,9,LEAVES:12)
Block(7,9,1,LEAVES:12)
Block(7,9,3,LEAVES:12)
Block(7,9,8,LEAVES:12)
Block(7,9,9,LEAVES:12)
Block(7,10,-2,LEAVES:12)
Block(7,10,0,LEAVES:12)
Block(7,10,1,LEAVES:12)
Block(7,10,4,LEAVES:12)
Block(7,10,12,LEAVES:12)
Block(7,11,11,LEAVES:12)
Block(7,11,17,LEAVES:12)
Block(7,11,18,LEAVES:12)
Block(7,11,23,LEAVES:12)
Block(7,12,5,LOG:12)
Block(7,12,10,LEAVES:12)
Block(7,12,11,LEAVES:12)
Block(7,12,19,LEAVES:12)
Block(7,12,20,LEAVES:12)
Block(7,12,23,LEAVES:12)
Block(7,13,11,LEAVES:12)
Block(7,13,12,LEAVES:12)
Block(7,13,13,LOG:12)
Block(7,13,14,LEAVES:12)
Block(7,13,20,LEAVES:12)
Block(7,14,13,LOG:12)
Block(7,14,14,LEAVES:12)
Block(7,14,15,LEAVES:12)
Block(7,14,20,LEAVES:12)
Block(7,15,4,LEAVES:12)
Block(7,15,13,LEAVES:12)
Block(7,15,15,LEAVES:12)
Block(7,15,16,LEAVES:12)
Block(7,15,17,LEAVES:12)
Block(7,16,8,LEAVES:12)
Block(7,16,13,LEAVES:12)
Block(7,16,14,LEAVES:12)
Block(7,16,22,LEAVES:12)
Block(7,16,23,LEAVES:12)
Block(7,16,24,LEAVES:12)
Block(7,17,5,LEAVES:12)
Block(7,17,7,LEAVES:12)
Block(7,17,8,LEAVES:12)
Block(7,17,14,LEAVES:12)
Block(7,17,18,LEAVES:12)
Block(7,17,19,LEAVES:12)
Block(7,17,23,LEAVES:12)
Block(7,18,13,LEAVES:12)
Block(7,18,21,LEAVES:12)
Block(7,19,2,LEAVES:12)
Block(7,19,3,LEAVES:12)
Block(7,19,6,LEAVES:12)
Block(7,19,7,LEAVES:12)
Block(7,20,5,LEAVES:12)
Block(7,20,7,LEAVES:12)
Block(7,20,15,LEAVES:12)
Block(7,21,2,LEAVES:12)
Block(7,21,4,LEAVES:12)
Block(7,21,5,LEAVES:12)
Block(8,4,4,LEAVES:12)
Block(8,5,0,LEAVES:12)
Block(8,5,1,LEAVES:12)
Block(8,5,4,LEAVES:12)
Block(8,6,1,LEAVES:12)
Block(8,6,6,LEAVES:12)
Block(8,7,1,LEAVES:12)
Block(8,8,-3,LEAVES:12)
Block(8,8,-2,LEAVES:12)
Block(8,9,3,LEAVES:12)
Block(8,9,4,LEAVES:12)
Block(8,9,5,LEAVES:12)
Block(8,9,8,LEAVES:12)
Block(8,10,-1,LEAVES:12)
Block(8,10,0,LEAVES:12)
Block(8,10,4,LEAVES:12)
Block(8,10,5,LEAVES:12)
Block(8,10,15,LEAVES:12)
Block(8,11,2,LEAVES:12)
Block(8,11,6,LOG:12)
Block(8,11,13,LEAVES:12)
Block(8,11,15,LEAVES:12)
Block(8,11,18,LEAVES:12)
Block(8,11,19,LEAVES:12)
Block(8,12,5,LOG:12)
Block(8,12,6,LOG:12)
Block(8,12,13,LEAVES:12)
Block(8,12,15,LEAVES:12)
Block(8,12,17,LEAVES:12)
Block(8,12,19,LEAVES:12)
Block(8,13,6,LEAVES:12)
Block(8,13,8,LEAVES:12)
Block(8,13,11,LEAVES:12)
Block(8,13,13,LOG:12)
Block(8,13,14,LEAVES:12)
Block(8,13,15,LEAVES:12)
Block(8,13,17,LEAVES:12)
Block(8,14,6,LEAVES:12)
Block(8,14,9,LEAVES:12)
Block(8,14,11,LEAVES:12)
Block(8,14,13,LEAVES:12)
Block(8,14,14,LEAVES:12)
Block(8,14,18,LEAVES:12)
Block(8,14,19,LEAVES:12)
Block(8,14,20,LEAVES:12)
Block(8,15,8,LEAVES:12)
Block(8,15,13,LEAVES:12)
Block(8,15,20,LEAVES:12)
Block(8,16,4,LEAVES:12)
Block(8,16,5,LEAVES:12)
Block(8,16,8,LEAVES:12)
Block(8,16,23,LEAVES:12)
Block(8,17,5,LEAVES:12)
Block(8,17,14,LEAVES:12)
Block(8,17,15,LEAVES:12)
Block(8,17,18,LEAVES:12)
Block(8,18,5,LEAVES:12)
Block(8,18,15,LEAVES:12)
Block(8,18,16,LEAVES:12)
Block(8,18,18,LEAVES:12)
Block(8,19,1,LEAVES:12)
Block(8,19,2,LEAVES:12)
Block(8,19,15,LEAVES:12)
Block(8,20,7,LEAVES:12)
Block(8,20,8,LEAVES:12)
Block(8,20,9,LEAVES:12)
Block(8,21,3,LEAVES:12)
Block(8,21,4,LEAVES:12)
Block(8,21,8,LEAVES:12)
Block(8,22,6,LEAVES:12)
Block(9,4,-1,LEAVES:12)
Block(9,4,0,LEAVES:12)
Block(9,5,0,LEAVES:12)
Block(9,5,7,LEAVES:12)
Block(9,6,7,LEAVES:12)
Block(9,7,0,LEAVES:12)
Block(9,7,1,LEAVES:12)
Block(9,7,9,LEAVES:12)
Block(9,8,1,LEAVES:12)
Block(9,8,3,LEAVES:12)
Block(9,9,4,LEAVES:12)
Block(9,9,5,LEAVES:12)
Block(9,9,6,LEAVES:12)
Block(9,9,8,LEAVES:12)
Block(9,10,-1,LEAVES:12)
Block(9,10,5,LEAVES:12)
Block(9,10,7,LEAVES:12)
Block(9,10,8,LEAVES:12)
Block(9,10,12,LEAVES:12)
Block(9,11,-1,LEAVES:12)
Block(9,11,6,LOG:12)
Block(9,11,7,LOG:12)
Block(9,11,16,LEAVES:12)
Block(9,11,18,LEAVES:12)
Block(9,12,9,LEAVES:12)
Block(9,12,11,LEAVES:12)
Block(9,12,12,LEAVES:12)
Block(9,12,13,LEAVES:12)
Block(9,12,15,LEAVES:12)
Block(9,12,16,LEAVES:12)
Block(9,13,6,LEAVES:12)
Block(9,13,7,LEAVES:12)
Block(9,13,13,LOG:12)
Block(9,13,21,LEAVES:12)
Block(9,14,10,LEAVES:12)
Block(9,14,11,LEAVES:12)
Block(9,14,14,LEAVES:12)
Block(9,14,15,LEAVES:12)
Block(9,14,20,LEAVES:12)
Block(9,14,21,LEAVES:12)
Block(9,15,3,LEAVES:12)
Block(9,15,4,LEAVES:12)
Block(9,15,13,LEAVES:12)
Block(9,15,15,LEAVES:12)
Block(9,16,4,LEAVES:12)
Block(9,16,10,LEAVES:12)
Block(9,16,12,LEAVES:12)
Block(9,16,13,LEAVES:12)
Block(9,18,4,LEAVES:12)
Block(9,18,5,LEAVES:12)
Block(9,19,5,LEAVES:12)
Block(9,20,8,LEAVES:12)
Block(9,21,3,LEAVES:12)
Block(9,22,3,LEAVES:12)
Block(10,4,-1,LEAVES:12)
Block(10,5,9,LEAVES:12)
Block(10,6,2,LEAVES:12)
Block(10,6,3,LEAVES:12)
Block(10,6,7,LEAVES:12)
Block(10,6,8,LEAVES:12)
Block(10,7,1,LEAVES:12)
Block(10,7,2,LEAVES:12)
Block(10,7,3,LEAVES:12)
Block(10,7,4,LEAVES:12)
Block(10,7,8,LEAVES:12)
Block(10,7,11,LEAVES:12)
Block(10,8,8,LEAVES:12)
Block(10,9,6,LEAVES:12)
Block(10,10,7,LOG:12)
Block(10,10,16,LEAVES:12)
Block(10,11,7,LOG:12)
Block(10,11,10,LEAVES:12)
Block(10,11,11,LEAVES:12)
Block(10,11,12,LEAVES:12)
Block(10,11,13,LEAVES:12)
Block(10,11,16,LEAVES:12)
Block(10,12,3,LEAVES:12)
Block(10,12,4,LEAVES:12)
Block(10,12,7,LEAVES:12)
Block(10,12,11,LEAVES:12)
Block(10,12,13,LEAVES:12)
Block(10,13,7,LEAVES:12)
Block(10,13,11,LEAVES:12)
Block(10,13,13,LEAVES:12)
Block(10,13,21,LEAVES:12)
Block(10,14,7,LEAVES:12)
Block(10,14,9,LEAVES:12)
Block(10,14,10,LEAVES:12)
Block(10,15,3,LEAVES:12)
Block(10,15,15,LEAVES:12)
Block(10,15,16,LEAVES:12)
Block(10,15,17,LEAVES:12)
Block(10,16,11,LEAVES:12)
Block(10,16,12,LEAVES:12)
Block(10,16,16,LEAVES:12)
Block(10,17,6,LEAVES:12)
Block(10,17,14,LEAVES:12)
Block(10,18,5,LEAVES:12)
Block(10,18,6,LEAVES:12)
Block(11,6,2,LEAVES:12)
Block(11,7,4,LEAVES:12)
Block(11,7,10,LEAVES:12)
Block(11,7,11,LEAVES:12)
Block(11,8,4,LEAVES:12)
Block(11,8,8,LEAVES:12)
Block(11,8,9,LEAVES:12)
Block(11,8,10,LEAVES:12)
Block(11,9,6,LEAVES:12)
Block(11,9,8,LEAVES:12)
Block(11,10,7,LOG:12)
Block(11,10,11,LEAVES:12)
Block(11,10,12,LEAVES:12)
Block(11,11,5,LEAVES:12)
Block(11,11,6,LEAVES:12)
Block(11,11,7,LEAVES:12)
Block(11,11,9,LEAVES:12)
Block(11,11,10,LEAVES:12)
Block(11,11,12,LEAVES:12)
Block(11,12,4,LEAVES:12)
Block(11,12,5,LEAVES:12)
Block(11,12,7,LEAVES:12)
Block(11,12,12,LEAVES:12)
Block(11,13,5,LEAVES:12)
Block(11,13,12,LEAVES:12)
Block(11,13,13,LEAVES:12)
Block(11,14,13,LEAVES:12)
Block(11,15,16,LEAVES:12)
Block(11,16,11,LEAVES:12)
Block(11,17,6,LEAVES:12)
Block(11,17,11,LEAVES:12)
Block(12,6,6,LEAVES:12)
Block(12,7,5,LEAVES:12)
Block(12,7,11,LEAVES:12)
Block(12,7,12,LEAVES:12)
Block(12,8,4,LEAVES:12)
Block(12,8,5,LEAVES:12)
Block(12,9,5,LEAVES:12)
Block(12,9,6,LEAVES:12)
Block(12,9,7,LEAVES:12)
Block(12,9,8,LEAVES:12)
Block(12,10,7,LOG:12)
Block(12,10,8,LEAVES:12)
Block(12,10,9,LEAVES:12)
Block(12,10,11,LEAVES:12)
Block(12,11,7,LEAVES:12)
Block(12,11,9,LEAVES:12)
Block(12,12,7,LEAVES:12)
Block(12,12,8,LEAVES:12)
Block(12,12,14,LEAVES:12)
Block(12,13,8,LEAVES:12)
Block(12,13,13,LEAVES:12)
Block(12,13,14,LEAVES:12)
Block(12,14,7,LEAVES:12)
Block(13,6,9,LEAVES:12)
Block(13,7,7,LEAVES:12)
Block(13,7,9,LEAVES:12)
Block(13,8,7,LEAVES:12)
Block(13,8,9,LEAVES:12)
Block(13,8,11,LEAVES:12)
Block(13,9,5,LEAVES:12)
Block(13,9,7,LEAVES:12)
Block(13,9,8,LEAVES:12)
Block(13,9,9,LEAVES:12)
Block(13,9,11,LEAVES:12)
Block(13,10,3,LEAVES:12)
Block(13,10,5,LEAVES:12)
Block(13,10,7,LEAVES:12)
Block(13,10,8,LEAVES:12)
Block(13,10,12,LEAVES:12)
Block(13,11,7,LEAVES:12)
Block(13,12,14,LEAVES:12)
Block(13,13,8,LEAVES:12)
Block(13,13,9,LEAVES:12)
Block(13,14,9,LEAVES:12)
Block(13,14,10,LEAVES:12)
Block(13,15,9,LEAVES:12)
Block(14,6,6,LEAVES:12)
Block(14,7,10,LEAVES:12)
Block(14,8,7,LEAVES:12)
Block(14,8,9,LEAVES:12)
Block(14,8,10,LEAVES:12)
Block(14,10,4,LEAVES:12)
Block(14,10,5,LEAVES:12)
Block(14,10,8,LEAVES:12)
Block(14,10,9,LEAVES:12)
Block(14,11,7,LEAVES:12)
Block(14,11,9,LEAVES:12)
Block(14,12,4,LEAVES:12)
Block(14,12,6,LEAVES:12)
Block(14,12,7,LEAVES:12)
Block(15,6,10,LEAVES:12)
Block(15,7,6,LEAVES:12)
Block(15,7,7,LEAVES:12)
Block(15,7,10,LEAVES:12)
Block(15,8,7,LEAVES:12)
Block(15,9,7,LEAVES:12)
Block(15,10,3,LEAVES:12)
Block(15,10,4,LEAVES:12)
Block(15,11,9,LEAVES:12)
Block(15,11,10,LEAVES:12)
Block(15,11,11,LEAVES:12)
Block(15,12,5,LEAVES:12)
Block(15,12,6,LEAVES:12)
Block(15,12,10,LEAVES:12)
Block(15,13,8,LEAVES:12)
Block(16,6,5,LEAVES:12)
Block(16,6,6,LEAVES:12)
Block(16,7,6,LEAVES:12)
Block(16,9,6,LEAVES:12)
Block(16,9,7,LEAVES:12)
Block(16,10,7,LEAVES:12)
Block(16,11,10,LEAVES:12)
Block(16,12,5,LEAVES:12)
Block(16,13,5,LEAVES:12)
Block(17,6,5,LEAVES:12)
Block(17,8,8,LEAVES:12)
Block(17,9,7,LEAVES:12)
Block(17,9,8,LEAVES:12)
Block(18,8,8,LEAVES:12)


#######################################################################
# +-----------------------------------------------------------------+ #
# |                             Entities                            | #
# +-----------------------------------------------------------------+ #
#######################################################################

# Entity() spawns an entity instead of a block. The entity is spawned only once when the BO3 is spawned.
# Entities are persistent by default so they don't de-spawn when no player is near, they are only unloaded.
# Usage: Entity(x,y,z,mobName,groupSize,NameTagOrNBTFileName) or Entity(x,y,z,mobName,groupSize)
# Use /tc entities or /otg entities to get a list of entities that can be used as mobName, this includes entities added by other mods.
# NameTagOrNBTFileName can be either a nametag for the mob or an nbt file (such as mymobinfo.nbt or mymobinfo.txt).
# When using a text file you can use the same mob spawning parameters used with the /summon command to equip the
# entity and give it custom attributes etc. You can copy the DATA part of a summon command including surrounding
# curly braces to a .txt file, for instance for: "/summon Skeleton x y z {DATA}"

#######################################################################
# +-----------------------------------------------------------------+ #
# |                            BO3 checks                           | #
# +-----------------------------------------------------------------+ #
#######################################################################

# Require a condition at a certain location in order for the BO3 to be spawned.
# BlockCheck(x,y,z,BlockName[,BlockName[,...]]) - one of the blocks must be at the location
# BlockCheckNot(x,y,z,BlockName[,BlockName[,...]]) - all the blocks must not be at the location
# LightCheck(x,y,z,minLightLevel,maxLightLevel) - light must be between min and max (inclusive)

# You can use "Solid" as a BlockName for matching all solid blocks or "All" to match all blocks that aren't air.

# Examples:
BlockCheck(0,-1,0,GRASS,DIRT,DIRT:2,SAND)
#   BlockCheck(0,-1,0,Solid)       Require any solid block just below the object
#   BlockCheck(0,-1,0,WOOL)        Require any type of wool just below the object
#   BlockCheck(0,-1,0,WOOL:0)      Require white wool just below the object
#   BlockCheckNot(0,-1,0,WOOL:0)   Require that there is no white wool below the object
#   LightCheck(0,0,0,0,1)          Require almost complete darkness just below the object

