#######################################################################
# +-----------------------------------------------------------------+ #
# |                            BO3 object                           | #
# +-----------------------------------------------------------------+ #
#######################################################################

# The descriptions in this file are accurate only for TerrainControl and OTG.
# For MCW and OTG+ these descriptions are only accurate if the BO3 is used as a CustomObject.
# MCW and OTG+ completely reimplemented CustomStructure, check the MCW/OTG+ documentation for more information.

# This is the config file of a custom object.
# If you add this object correctly to your BiomeConfigs, it will spawn in the world.

# This is the creator of this BO3 object
Author: Unknown

# A short description of this BO3 object
Description: This BO3 was converted from a schematic using OTGEdit. The author and description information of the schematic could not be found. If you know who the author of the schematic is then please add this information.

# The BO3 version, don't change this! It can be used by external applications to do a version check.
Version: 3

# The settings mode, WriteAll, WriteWithoutComments or WriteDisable. See WorldConfig.
SettingsMode: WriteDisable

#######################################################################
# +-----------------------------------------------------------------+ #
# |                          Main settings                          | #
# +-----------------------------------------------------------------+ #
#######################################################################

# This needs to be set to true to spawn the object in the Tree and Sapling resources.
Tree: true

# The frequency of the BO3 from 1 to 200. Tries this many times to spawn this BO3 when using the CustomObject(...) resource.
# Ignored by Tree(..), Sapling(..) and CustomStructure(..)
Frequency: 40

# The rarity of the BO3 from 0 to 100. Each spawn attempt has rarity% chance to succeed when using the CustomObject(...) resource.
# Ignored by Tree(..), Sapling(..) and CustomStructure(..)
Rarity: 100.0

# If you set this to true, the BO3 will be placed with a random rotation.
RotateRandomly: true

# The spawn height of the BO3 - randomY, highestBlock or highestSolidBlock.
SpawnHeight: highestSolidBlock

# The height limits for the BO3.
MinHeight: 0

MaxHeight: 256

# Objects can have other objects attached to it: branches. Branches can also
# have branches attached to it, which can also have branches, etc. This is the
# maximum branch depth for this objects.
MaxBranchDepth: 10

# When spawned with the UseWorld keyword, this BO3 should NOT spawn in the following biomes.
# If you writer.write the BO3 name directly in the BiomeConfigs, this will be ignored.
ExcludedBiomes: All

# To optimise this BO3 for faster loading times you can use Notepad++ to find/replace comments and abbreviate things.
# Notepad++ find/replace with regex:
# Find: ^[#;].* replace to nothing removes all lines starting with # 
# Find: ^\s*$ replace to nothing removes most empty lines 
# Notepad++ find/replace without regex:
# *Warning: This will only work for OTG 1.10.2 v21 / OTG 1.11.2 v6 or higher. B( is not recognised by lower versions.
# Find: Block( replace to B(

#######################################################################
# +-----------------------------------------------------------------+ #
# |                      Source block settings                      | #
# +-----------------------------------------------------------------+ #
#######################################################################

# The block(s) the BO3 should spawn in.
SourceBlocks: AIR

# The maximum percentage of the BO3 that can be outside the SourceBlock.
# The BO3 won't be placed on a location with more blocks outside the SourceBlock than this percentage.
MaxPercentageOutsideSourceBlock: 0

# What to do when a block is about to be placed outside the SourceBlock? (dontPlace, placeAnyway)
OutsideSourceBlock: dontPlace

#######################################################################
# +-----------------------------------------------------------------+ #
# |                              Blocks                             | #
# +-----------------------------------------------------------------+ #
#######################################################################

# All the blocks used in the BO3 are listed here. Possible blocks:
# Block(x,y,z,id[.data][,nbtfile.nbt) or B(x,y,z,id[.data][,nbtfile.nbt)
# RandomBlock(x,y,z,id[:data][,nbtfile.nbt],chance[,id[:data][,nbtfile.nbt],chance[,...]])
# So RandomBlock(0,0,0,CHEST,chest.nbt,50,CHEST,anotherchest.nbt,100) will spawn a chest at
# the BO3 origin, and give it a 50% chance to have the contents of chest.nbt, or, if that
# fails, a 100% percent chance to have the contents of anotherchest.nbt.

Block(-15,8,2,LEAVES:12)
Block(-15,9,1,LEAVES:12)
Block(-15,9,2,LEAVES:12)
Block(-15,10,-3,LEAVES:12)
Block(-14,6,-1,LEAVES:12)
Block(-14,9,1,LEAVES:12)
Block(-14,10,-3,LEAVES:12)
Block(-14,10,-2,LEAVES:12)
Block(-14,13,-1,LEAVES:12)
Block(-14,13,1,LEAVES:12)
Block(-14,13,14,LEAVES:12)
Block(-14,14,-1,LEAVES:12)
Block(-14,14,13,LEAVES:12)
Block(-14,14,14,LEAVES:12)
Block(-14,15,9,LEAVES:12)
Block(-13,5,0,LEAVES:12)
Block(-13,6,0,LEAVES:12)
Block(-13,7,2,LEAVES:12)
Block(-13,8,-4,LEAVES:12)
Block(-13,9,-2,LEAVES:12)
Block(-13,9,-1,LEAVES:12)
Block(-13,9,1,LEAVES:12)
Block(-13,10,-2,LEAVES:12)
Block(-13,10,0,LEAVES:12)
Block(-13,10,1,LEAVES:12)
Block(-13,11,11,LEAVES:12)
Block(-13,12,2,LEAVES:12)
Block(-13,12,4,LEAVES:12)
Block(-13,12,5,LEAVES:12)
Block(-13,13,-1,LEAVES:12)
Block(-13,13,0,LEAVES:12)
Block(-13,14,13,LEAVES:12)
Block(-13,15,9,LEAVES:12)
Block(-13,15,10,LEAVES:12)
Block(-13,18,11,LEAVES:12)
Block(-13,18,13,LEAVES:12)
Block(-13,19,11,LEAVES:12)
Block(-12,5,2,LEAVES:12)
Block(-12,6,-4,LEAVES:12)
Block(-12,6,0,LEAVES:12)
Block(-12,6,1,LEAVES:12)
Block(-12,7,-4,LEAVES:12)
Block(-12,7,-3,LEAVES:12)
Block(-12,7,1,LEAVES:12)
Block(-12,7,4,LEAVES:12)
Block(-12,8,1,LEAVES:12)
Block(-12,9,-1,LEAVES:12)
Block(-12,10,0,LEAVES:12)
Block(-12,10,12,LEAVES:12)
Block(-12,11,3,LEAVES:12)
Block(-12,11,4,LEAVES:12)
Block(-12,11,12,LEAVES:12)
Block(-12,12,-4,LEAVES:12)
Block(-12,12,-3,LEAVES:12)
Block(-12,12,0,LEAVES:12)
Block(-12,12,4,LEAVES:12)
Block(-12,12,14,LEAVES:12)
Block(-12,13,0,LEAVES:12)
Block(-12,13,4,LEAVES:12)
Block(-12,13,8,LEAVES:12)
Block(-12,14,0,LEAVES:12)
Block(-12,14,10,LEAVES:12)
Block(-12,14,11,LEAVES:12)
Block(-12,14,13,LEAVES:12)
Block(-12,15,10,LEAVES:12)
Block(-12,15,12,LEAVES:12)
Block(-12,15,13,LEAVES:12)
Block(-12,17,14,LEAVES:12)
Block(-12,17,16,LEAVES:12)
Block(-12,17,17,LEAVES:12)
Block(-12,18,11,LEAVES:12)
Block(-12,18,12,LEAVES:12)
Block(-11,7,-3,LEAVES:12)
Block(-11,7,3,LEAVES:12)
Block(-11,7,4,LEAVES:12)
Block(-11,8,-3,LEAVES:12)
Block(-11,8,1,LEAVES:12)
Block(-11,8,2,LEAVES:12)
Block(-11,8,3,LEAVES:12)
Block(-11,9,-1,LEAVES:12)
Block(-11,9,1,LEAVES:12)
Block(-11,10,0,LEAVES:12)
Block(-11,10,14,LEAVES:12)
Block(-11,11,-2,LEAVES:12)
Block(-11,11,-1,LEAVES:12)
Block(-11,11,0,LEAVES:12)
Block(-11,11,2,LEAVES:12)
Block(-11,11,3,LEAVES:12)
Block(-11,11,8,LEAVES:12)
Block(-11,11,12,LEAVES:12)
Block(-11,11,13,LEAVES:12)
Block(-11,12,-3,LEAVES:12)
Block(-11,12,-2,LEAVES:12)
Block(-11,12,0,LEAVES:12)
Block(-11,12,5,LEAVES:12)
Block(-11,12,8,LEAVES:12)
Block(-11,12,9,LEAVES:12)
Block(-11,12,13,LEAVES:12)
Block(-11,12,16,LEAVES:12)
Block(-11,13,-2,LEAVES:12)
Block(-11,13,13,LEAVES:12)
Block(-11,14,11,LEAVES:12)
Block(-11,15,12,LEAVES:12)
Block(-11,16,15,LEAVES:12)
Block(-11,16,16,LEAVES:12)
Block(-11,17,8,LEAVES:12)
Block(-11,17,9,LEAVES:12)
Block(-11,17,12,LEAVES:12)
Block(-11,17,16,LEAVES:12)
Block(-11,18,12,LEAVES:12)
Block(-11,18,16,LEAVES:12)
Block(-11,19,12,LEAVES:12)
Block(-10,6,-1,LEAVES:12)
Block(-10,7,-2,LEAVES:12)
Block(-10,7,4,LEAVES:12)
Block(-10,7,5,LEAVES:12)
Block(-10,8,-3,LEAVES:12)
Block(-10,8,-2,LEAVES:12)
Block(-10,9,-2,LEAVES:12)
Block(-10,9,-1,LEAVES:12)
Block(-10,9,0,LEAVES:12)
Block(-10,9,1,LEAVES:12)
Block(-10,10,0,LOG:12)
Block(-10,10,1,LEAVES:12)
Block(-10,10,2,LEAVES:12)
Block(-10,11,0,LEAVES:12)
Block(-10,11,2,LEAVES:12)
Block(-10,12,0,LEAVES:12)
Block(-10,12,1,LEAVES:12)
Block(-10,12,9,LEAVES:12)
Block(-10,12,15,LEAVES:12)
Block(-10,12,16,LEAVES:12)
Block(-10,13,1,LEAVES:12)
Block(-10,13,9,LEAVES:12)
Block(-10,13,13,LEAVES:12)
Block(-10,13,14,LEAVES:12)
Block(-10,13,15,LEAVES:12)
Block(-10,14,0,LEAVES:12)
Block(-10,14,11,LEAVES:12)
Block(-10,14,13,LEAVES:12)
Block(-10,15,12,LEAVES:12)
Block(-10,16,10,LEAVES:12)
Block(-10,16,11,LEAVES:12)
Block(-10,16,12,LEAVES:12)
Block(-10,16,14,LEAVES:12)
Block(-10,16,15,LEAVES:12)
Block(-10,17,9,LEAVES:12)
Block(-10,17,10,LEAVES:12)
Block(-10,17,12,LEAVES:12)
Block(-10,17,17,LEAVES:12)
Block(-10,18,10,LEAVES:12)
Block(-9,6,2,LEAVES:12)
Block(-9,7,0,LEAVES:12)
Block(-9,7,2,LEAVES:12)
Block(-9,8,0,LEAVES:12)
Block(-9,8,2,LEAVES:12)
Block(-9,8,4,LEAVES:12)
Block(-9,9,-2,LEAVES:12)
Block(-9,9,0,LEAVES:12)
Block(-9,9,1,LEAVES:12)
Block(-9,9,2,LEAVES:12)
Block(-9,9,4,LEAVES:12)
Block(-9,10,-4,LEAVES:12)
Block(-9,10,-2,LEAVES:12)
Block(-9,10,0,LOG:12)
Block(-9,10,1,LEAVES:12)
Block(-9,10,5,LEAVES:12)
Block(-9,11,0,LEAVES:12)
Block(-9,11,11,LEAVES:12)
Block(-9,12,10,LEAVES:12)
Block(-9,12,16,LEAVES:12)
Block(-9,12,17,LEAVES:12)
Block(-9,13,1,LEAVES:12)
Block(-9,13,2,LEAVES:12)
Block(-9,13,9,LEAVES:12)
Block(-9,13,10,LEAVES:12)
Block(-9,14,2,LEAVES:12)
Block(-9,14,3,LEAVES:12)
Block(-9,14,10,LEAVES:12)
Block(-9,14,11,LEAVES:12)
Block(-9,14,12,LEAVES:12)
Block(-9,14,13,LEAVES:12)
Block(-9,15,2,LEAVES:12)
Block(-9,15,10,LOG:12)
Block(-9,15,11,LOG:12)
Block(-9,15,12,LOG:12)
Block(-9,15,13,LEAVES:12)
Block(-9,15,14,LEAVES:12)
Block(-9,16,12,LEAVES:12)
Block(-9,16,14,LEAVES:12)
Block(-9,17,12,LEAVES:12)
Block(-9,17,13,LEAVES:12)
Block(-9,18,4,LEAVES:12)
Block(-9,18,13,LEAVES:12)
Block(-9,19,3,LEAVES:12)
Block(-9,19,4,LEAVES:12)
Block(-9,19,12,LEAVES:12)
Block(-9,20,-1,LEAVES:12)
Block(-8,6,-1,LEAVES:12)
Block(-8,7,3,LEAVES:12)
Block(-8,8,-3,LEAVES:12)
Block(-8,8,0,LEAVES:12)
Block(-8,8,2,LEAVES:12)
Block(-8,8,3,LEAVES:12)
Block(-8,9,-4,LEAVES:12)
Block(-8,9,-3,LEAVES:12)
Block(-8,10,-8,LEAVES:12)
Block(-8,10,-3,LEAVES:12)
Block(-8,10,-2,LEAVES:12)
Block(-8,10,0,LOG:12)
Block(-8,10,1,LOG:12)
Block(-8,10,2,LEAVES:12)
Block(-8,11,0,LEAVES:12)
Block(-8,11,2,LEAVES:12)
Block(-8,11,14,LEAVES:12)
Block(-8,12,-3,LEAVES:12)
Block(-8,12,-1,LEAVES:12)
Block(-8,12,0,LEAVES:12)
Block(-8,12,12,LEAVES:12)
Block(-8,12,14,LEAVES:12)
Block(-8,13,12,LEAVES:12)
Block(-8,13,14,LEAVES:12)
Block(-8,13,16,LEAVES:12)
Block(-8,14,9,LOG:12)
Block(-8,14,10,LOG:12)
Block(-8,14,12,LEAVES:12)
Block(-8,14,13,LEAVES:12)
Block(-8,14,14,LEAVES:12)
Block(-8,14,16,LEAVES:12)
Block(-8,15,8,LEAVES:12)
Block(-8,15,10,LOG:12)
Block(-8,15,12,LEAVES:12)
Block(-8,15,13,LEAVES:12)
Block(-8,15,17,LEAVES:12)
Block(-8,16,1,LEAVES:12)
Block(-8,16,12,LEAVES:12)
Block(-8,18,13,LEAVES:12)
Block(-8,18,14,LEAVES:12)
Block(-8,19,3,LEAVES:12)
Block(-8,19,13,LEAVES:12)
Block(-8,19,14,LEAVES:12)
Block(-8,19,15,LEAVES:12)
Block(-8,20,-1,LEAVES:12)
Block(-8,20,0,LEAVES:12)
Block(-8,20,12,LEAVES:12)
Block(-8,20,13,LEAVES:12)
Block(-8,20,14,LEAVES:12)
Block(-8,21,8,LEAVES:12)
Block(-8,23,1,LEAVES:12)
Block(-8,23,3,LEAVES:12)
Block(-8,24,1,LEAVES:12)
Block(-7,6,-6,LEAVES:12)
Block(-7,6,3,LEAVES:12)
Block(-7,7,-1,LEAVES:12)
Block(-7,7,0,LEAVES:12)
Block(-7,7,3,LEAVES:12)
Block(-7,8,0,LEAVES:12)
Block(-7,9,-4,LEAVES:12)
Block(-7,9,0,LEAVES:12)
Block(-7,10,-8,LEAVES:12)
Block(-7,10,-7,LEAVES:12)
Block(-7,10,-4,LEAVES:12)
Block(-7,10,-3,LEAVES:12)
Block(-7,10,1,LOG:12)
Block(-7,10,2,LOG:12)
Block(-7,11,2,LOG:12)
Block(-7,11,3,LOG:12)
Block(-7,11,4,LOG:12)
Block(-7,11,11,LEAVES:12)
Block(-7,12,-2,LEAVES:12)
Block(-7,12,-1,LEAVES:12)
Block(-7,12,3,LEAVES:12)
Block(-7,12,15,LEAVES:12)
Block(-7,13,-6,LEAVES:12)
Block(-7,13,-4,LEAVES:12)
Block(-7,13,1,LEAVES:12)
Block(-7,13,7,LOG:12)
Block(-7,13,8,LOG:12)
Block(-7,13,12,LEAVES:12)
Block(-7,13,14,LEAVES:12)
Block(-7,13,15,LEAVES:12)
Block(-7,14,-6,LEAVES:12)
Block(-7,14,8,LOG:12)
Block(-7,14,9,LOG:12)
Block(-7,15,2,LEAVES:12)
Block(-7,15,9,LEAVES:12)
Block(-7,15,10,LEAVES:12)
Block(-7,15,13,LEAVES:12)
Block(-7,15,14,LEAVES:12)
Block(-7,16,2,LEAVES:12)
Block(-7,16,12,LEAVES:12)
Block(-7,16,14,LEAVES:12)
Block(-7,17,4,LEAVES:12)
Block(-7,17,9,LEAVES:12)
Block(-7,17,10,LEAVES:12)
Block(-7,17,11,LEAVES:12)
Block(-7,17,12,LEAVES:12)
Block(-7,18,-2,LEAVES:12)
Block(-7,19,0,LEAVES:12)
Block(-7,19,1,LEAVES:12)
Block(-7,19,3,LEAVES:12)
Block(-7,20,0,LEAVES:12)
Block(-7,20,2,LEAVES:12)
Block(-7,20,3,LEAVES:12)
Block(-7,20,12,LEAVES:12)
Block(-7,21,8,LEAVES:12)
Block(-7,21,9,LEAVES:12)
Block(-7,22,4,LEAVES:12)
Block(-7,22,6,LEAVES:12)
Block(-7,22,7,LEAVES:12)
Block(-7,23,1,LEAVES:12)
Block(-7,23,2,LEAVES:12)
Block(-7,24,10,LEAVES:12)
Block(-7,24,12,LEAVES:12)
Block(-7,25,10,LEAVES:12)
Block(-6,5,-5,LEAVES:12)
Block(-6,6,-5,LEAVES:12)
Block(-6,6,-2,LEAVES:12)
Block(-6,6,-1,LEAVES:12)
Block(-6,7,-3,LEAVES:12)
Block(-6,7,-1,LEAVES:12)
Block(-6,8,-9,LEAVES:12)
Block(-6,9,-7,LEAVES:12)
Block(-6,9,-6,LEAVES:12)
Block(-6,9,-4,LEAVES:12)
Block(-6,9,-1,LEAVES:12)
Block(-6,9,0,LEAVES:12)
Block(-6,10,-7,LEAVES:12)
Block(-6,10,-5,LEAVES:12)
Block(-6,10,-4,LEAVES:12)
Block(-6,10,0,LEAVES:12)
Block(-6,11,3,LEAVES:12)
Block(-6,11,4,LOG:12)
Block(-6,11,15,LEAVES:12)
Block(-6,12,-3,LEAVES:12)
Block(-6,12,-2,LEAVES:12)
Block(-6,12,-1,LEAVES:12)
Block(-6,12,0,LEAVES:12)
Block(-6,12,4,LOG:12)
Block(-6,12,5,LOG:12)
Block(-6,12,11,LEAVES:12)
Block(-6,12,12,LEAVES:12)
Block(-6,12,15,LEAVES:12)
Block(-6,12,18,LEAVES:12)
Block(-6,13,-6,LEAVES:12)
Block(-6,13,-5,LEAVES:12)
Block(-6,13,-2,LEAVES:12)
Block(-6,13,7,LOG:12)
Block(-6,13,12,LEAVES:12)
Block(-6,13,17,LEAVES:12)
Block(-6,13,18,LEAVES:12)
Block(-6,14,12,LEAVES:12)
Block(-6,14,13,LEAVES:12)
Block(-6,15,4,LEAVES:12)
Block(-6,15,8,LEAVES:12)
Block(-6,15,9,LEAVES:12)
Block(-6,16,-2,LEAVES:12)
Block(-6,16,2,LEAVES:12)
Block(-6,16,3,LEAVES:12)
Block(-6,16,11,LEAVES:12)
Block(-6,16,14,LEAVES:12)
Block(-6,16,15,LEAVES:12)
Block(-6,16,16,LEAVES:12)
Block(-6,17,-2,LEAVES:12)
Block(-6,17,-1,LEAVES:12)
Block(-6,17,3,LEAVES:12)
Block(-6,17,6,LEAVES:12)
Block(-6,17,10,LEAVES:12)
Block(-6,17,11,LEAVES:12)
Block(-6,17,15,LEAVES:12)
Block(-6,18,3,LEAVES:12)
Block(-6,18,13,LEAVES:12)
Block(-6,19,1,LEAVES:12)
Block(-6,19,7,LEAVES:12)
Block(-6,20,2,LEAVES:12)
Block(-6,20,9,LEAVES:12)
Block(-6,20,10,LEAVES:12)
Block(-6,20,12,LEAVES:12)
Block(-6,21,5,LEAVES:12)
Block(-6,21,6,LEAVES:12)
Block(-6,21,9,LEAVES:12)
Block(-6,21,11,LEAVES:12)
Block(-6,21,12,LEAVES:12)
Block(-6,22,-2,LEAVES:12)
Block(-6,22,-1,LEAVES:12)
Block(-6,22,2,LEAVES:12)
Block(-6,22,6,LEAVES:12)
Block(-6,23,2,LEAVES:12)
Block(-6,23,6,LEAVES:12)
Block(-6,23,13,LEAVES:12)
Block(-6,23,15,LEAVES:12)
Block(-6,23,16,LEAVES:12)
Block(-6,24,2,LEAVES:12)
Block(-6,24,10,LEAVES:12)
Block(-6,24,11,LEAVES:12)
Block(-5,5,-3,LEAVES:12)
Block(-5,6,-9,LEAVES:12)
Block(-5,6,-5,LEAVES:12)
Block(-5,6,-4,LEAVES:12)
Block(-5,6,-2,LEAVES:12)
Block(-5,7,-9,LEAVES:12)
Block(-5,7,-8,LEAVES:12)
Block(-5,7,-4,LEAVES:12)
Block(-5,7,-1,LEAVES:12)
Block(-5,8,-4,LEAVES:12)
Block(-5,8,1,LEAVES:12)
Block(-5,9,-6,LEAVES:12)
Block(-5,9,0,LEAVES:12)
Block(-5,9,1,LEAVES:12)
Block(-5,10,-5,LEAVES:12)
Block(-5,10,15,LEAVES:12)
Block(-5,11,-2,LEAVES:12)
Block(-5,11,-1,LEAVES:12)
Block(-5,11,10,LEAVES:12)
Block(-5,11,11,LEAVES:12)
Block(-5,12,-9,LEAVES:12)
Block(-5,12,-8,LEAVES:12)
Block(-5,12,-5,LEAVES:12)
Block(-5,12,-1,LEAVES:12)
Block(-5,12,5,LOG:12)
Block(-5,12,6,LOG:12)
Block(-5,12,11,LEAVES:12)
Block(-5,13,-5,LEAVES:12)
Block(-5,13,-1,LEAVES:12)
Block(-5,13,6,LOG:12)
Block(-5,13,7,LOG:12)
Block(-5,13,17,LEAVES:12)
Block(-5,14,-5,LEAVES:12)
Block(-5,14,11,LEAVES:12)
Block(-5,14,12,LEAVES:12)
Block(-5,14,13,LEAVES:12)
Block(-5,14,14,LEAVES:12)
Block(-5,15,12,LEAVES:12)
Block(-5,16,13,LEAVES:12)
Block(-5,16,15,LEAVES:12)
Block(-5,17,-1,LEAVES:12)
Block(-5,17,5,LEAVES:12)
Block(-5,17,6,LEAVES:12)
Block(-5,17,7,LEAVES:12)
Block(-5,17,10,LEAVES:12)
Block(-5,17,11,LEAVES:12)
Block(-5,17,12,LEAVES:12)
Block(-5,17,15,LEAVES:12)
Block(-5,17,17,LEAVES:12)
Block(-5,18,-1,LEAVES:12)
Block(-5,18,3,LEAVES:12)
Block(-5,18,4,LEAVES:12)
Block(-5,18,5,LEAVES:12)
Block(-5,18,7,LEAVES:12)
Block(-5,18,8,LEAVES:12)
Block(-5,18,10,LEAVES:12)
Block(-5,18,12,LEAVES:12)
Block(-5,18,15,LEAVES:12)
Block(-5,19,1,LEAVES:12)
Block(-5,19,3,LEAVES:12)
Block(-5,19,12,LEAVES:12)
Block(-5,20,2,LOG:12)
Block(-5,20,10,LEAVES:12)
Block(-5,21,0,LEAVES:12)
Block(-5,21,1,LEAVES:12)
Block(-5,21,2,LEAVES:12)
Block(-5,21,4,LEAVES:12)
Block(-5,21,5,LEAVES:12)
Block(-5,21,11,LEAVES:12)
Block(-5,22,-1,LEAVES:12)
Block(-5,22,0,LEAVES:12)
Block(-5,22,2,LEAVES:12)
Block(-5,22,7,LEAVES:12)
Block(-5,22,14,LEAVES:12)
Block(-5,22,15,LEAVES:12)
Block(-5,23,0,LEAVES:12)
Block(-5,23,7,LEAVES:12)
Block(-5,23,8,LEAVES:12)
Block(-5,23,11,LEAVES:12)
Block(-5,23,15,LEAVES:12)
Block(-5,24,11,LEAVES:12)
Block(-5,24,15,LEAVES:12)
Block(-5,25,11,LEAVES:12)
Block(-4,7,-8,LEAVES:12)
Block(-4,7,-2,LEAVES:12)
Block(-4,7,-1,LEAVES:12)
Block(-4,8,-8,LEAVES:12)
Block(-4,8,-4,LEAVES:12)
Block(-4,8,-3,LEAVES:12)
Block(-4,8,-2,LEAVES:12)
Block(-4,8,1,LEAVES:12)
Block(-4,9,-6,LEAVES:12)
Block(-4,9,-4,LEAVES:12)
Block(-4,9,16,LEAVES:12)
Block(-4,10,-5,LEAVES:12)
Block(-4,10,16,LEAVES:12)
Block(-4,11,-7,LEAVES:12)
Block(-4,11,-6,LEAVES:12)
Block(-4,11,-5,LEAVES:12)
Block(-4,11,-3,LEAVES:12)
Block(-4,11,-2,LEAVES:12)
Block(-4,11,10,LEAVES:12)
Block(-4,11,18,LEAVES:12)
Block(-4,12,-8,LEAVES:12)
Block(-4,12,-7,LEAVES:12)
Block(-4,12,-5,LEAVES:12)
Block(-4,12,0,LEAVES:12)
Block(-4,12,12,LEAVES:12)
Block(-4,13,-7,LEAVES:12)
Block(-4,13,6,LOG:12)
Block(-4,13,13,LEAVES:12)
Block(-4,13,14,LEAVES:12)
Block(-4,13,15,LEAVES:12)
Block(-4,13,17,LEAVES:12)
Block(-4,14,12,LEAVES:12)
Block(-4,14,13,LEAVES:12)
Block(-4,14,14,LEAVES:12)
Block(-4,14,16,LEAVES:12)
Block(-4,14,17,LEAVES:12)
Block(-4,16,1,LEAVES:12)
Block(-4,16,18,LEAVES:12)
Block(-4,16,20,LEAVES:12)
Block(-4,16,21,LEAVES:12)
Block(-4,17,0,LEAVES:12)
Block(-4,17,6,LEAVES:12)
Block(-4,17,7,LEAVES:12)
Block(-4,17,15,LEAVES:12)
Block(-4,17,16,LEAVES:12)
Block(-4,18,-1,LEAVES:12)
Block(-4,18,0,LEAVES:12)
Block(-4,18,8,LEAVES:12)
Block(-4,18,14,LEAVES:12)
Block(-4,18,15,LEAVES:12)
Block(-4,19,0,LEAVES:12)
Block(-4,19,1,LEAVES:12)
Block(-4,19,2,LEAVES:12)
Block(-4,19,3,LEAVES:12)
Block(-4,19,8,LEAVES:12)
Block(-4,19,12,LEAVES:12)
Block(-4,19,13,LEAVES:12)
Block(-4,19,14,LEAVES:12)
Block(-4,20,2,LOG:12)
Block(-4,20,3,LOG:12)
Block(-4,20,4,LEAVES:12)
Block(-4,20,10,LEAVES:12)
Block(-4,20,12,LEAVES:12)
Block(-4,21,2,LEAVES:12)
Block(-4,21,4,LEAVES:12)
Block(-4,21,11,LEAVES:12)
Block(-4,22,2,LEAVES:12)
Block(-4,22,3,LEAVES:12)
Block(-4,22,9,LEAVES:12)
Block(-4,22,10,LEAVES:12)
Block(-4,22,11,LEAVES:12)
Block(-4,22,13,LEAVES:12)
Block(-4,22,14,LEAVES:12)
Block(-4,23,3,LEAVES:12)
Block(-4,23,8,LEAVES:12)
Block(-4,23,9,LEAVES:12)
Block(-4,23,11,LEAVES:12)
Block(-4,23,16,LEAVES:12)
Block(-4,24,2,LEAVES:12)
Block(-4,24,9,LEAVES:12)
Block(-3,6,-6,LEAVES:12)
Block(-3,7,-7,LEAVES:12)
Block(-3,7,-1,LEAVES:12)
Block(-3,7,0,LEAVES:12)
Block(-3,8,-8,LEAVES:12)
Block(-3,8,-7,LEAVES:12)
Block(-3,9,-7,LEAVES:12)
Block(-3,9,-6,LEAVES:12)
Block(-3,9,-5,LEAVES:12)
Block(-3,9,-4,LEAVES:12)
Block(-3,9,18,LEAVES:12)
Block(-3,10,-5,LOG:12)
Block(-3,10,-4,LOG:12)
Block(-3,10,-3,LEAVES:12)
Block(-3,10,12,LEAVES:12)
Block(-3,10,16,LEAVES:12)
Block(-3,10,17,LEAVES:12)
Block(-3,11,-5,LEAVES:12)
Block(-3,11,-3,LEAVES:12)
Block(-3,11,12,LEAVES:12)
Block(-3,11,13,LEAVES:12)
Block(-3,11,17,LEAVES:12)
Block(-3,11,20,LEAVES:12)
Block(-3,12,-5,LEAVES:12)
Block(-3,12,-4,LEAVES:12)
Block(-3,12,17,LEAVES:12)
Block(-3,13,-4,LEAVES:12)
Block(-3,13,6,LOG:12)
Block(-3,13,13,LEAVES:12)
Block(-3,13,15,LEAVES:12)
Block(-3,14,-5,LEAVES:12)
Block(-3,14,16,LEAVES:12)
Block(-3,15,19,LEAVES:12)
Block(-3,15,20,LEAVES:12)
Block(-3,16,4,LEAVES:12)
Block(-3,16,12,LEAVES:12)
Block(-3,16,13,LEAVES:12)
Block(-3,16,16,LEAVES:12)
Block(-3,16,20,LEAVES:12)
Block(-3,17,2,LEAVES:12)
Block(-3,17,4,LEAVES:12)
Block(-3,17,10,LEAVES:12)
Block(-3,17,16,LEAVES:12)
Block(-3,17,20,LEAVES:12)
Block(-3,18,2,LEAVES:12)
Block(-3,18,4,LEAVES:12)
Block(-3,18,6,LEAVES:12)
Block(-3,18,9,LEAVES:12)
Block(-3,18,15,LEAVES:12)
Block(-3,18,16,LEAVES:12)
Block(-3,19,0,LEAVES:12)
Block(-3,19,2,LEAVES:12)
Block(-3,19,3,LEAVES:12)
Block(-3,19,4,LEAVES:12)
Block(-3,19,6,LEAVES:12)
Block(-3,19,8,LEAVES:12)
Block(-3,19,9,LEAVES:12)
Block(-3,19,11,LOG:12)
Block(-3,20,-2,LEAVES:12)
Block(-3,20,0,LEAVES:12)
Block(-3,20,2,LEAVES:12)
Block(-3,20,3,LOG:12)
Block(-3,20,7,LEAVES:12)
Block(-3,20,9,LEAVES:12)
Block(-3,20,10,LEAVES:12)
Block(-3,20,11,LOG:12)
Block(-3,20,12,LEAVES:12)
Block(-3,21,2,LEAVES:12)
Block(-3,21,11,LOG:12)
Block(-3,21,12,LEAVES:12)
Block(-3,21,13,LEAVES:12)
Block(-3,22,11,LEAVES:12)
Block(-3,22,13,LEAVES:12)
Block(-3,23,3,LEAVES:12)
Block(-3,23,4,LEAVES:12)
Block(-3,23,11,LEAVES:12)
Block(-3,23,12,LEAVES:12)
Block(-3,24,4,LEAVES:12)
Block(-3,24,5,LEAVES:12)
Block(-3,24,12,LEAVES:12)
Block(-3,25,4,LEAVES:12)
Block(-3,25,11,LEAVES:12)
Block(-2,6,-3,LEAVES:12)
Block(-2,7,-5,LEAVES:12)
Block(-2,7,-3,LEAVES:12)
Block(-2,8,-5,LEAVES:12)
Block(-2,8,-3,LEAVES:12)
Block(-2,8,-1,LEAVES:12)
Block(-2,9,-7,LEAVES:12)
Block(-2,9,-5,LEAVES:12)
Block(-2,9,-4,LEAVES:12)
Block(-2,9,-3,LEAVES:12)
Block(-2,9,-1,LEAVES:12)
Block(-2,10,-9,LEAVES:12)
Block(-2,10,-7,LEAVES:12)
Block(-2,10,-5,LEAVES:12)
Block(-2,10,-4,LOG:12)
Block(-2,10,-3,LOG:12)
Block(-2,10,0,LEAVES:12)
Block(-2,11,-5,LEAVES:12)
Block(-2,11,13,LEAVES:12)
Block(-2,11,19,LEAVES:12)
Block(-2,11,20,LEAVES:12)
Block(-2,12,5,LOG:12)
Block(-2,12,13,LEAVES:12)
Block(-2,12,17,LEAVES:12)
Block(-2,12,18,LEAVES:12)
Block(-2,12,19,LEAVES:12)
Block(-2,13,-4,LEAVES:12)
Block(-2,13,-3,LEAVES:12)
Block(-2,13,5,LOG:12)
Block(-2,13,6,LOG:12)
Block(-2,13,15,LEAVES:12)
Block(-2,13,17,LEAVES:12)
Block(-2,14,-3,LEAVES:12)
Block(-2,14,-2,LEAVES:12)
Block(-2,14,16,LEAVES:12)
Block(-2,15,-3,LEAVES:12)
Block(-2,15,14,LEAVES:12)
Block(-2,15,15,LEAVES:12)
Block(-2,15,16,LEAVES:12)
Block(-2,15,18,LEAVES:12)
Block(-2,15,19,LEAVES:12)
Block(-2,16,1,LEAVES:12)
Block(-2,16,10,LOG:12)
Block(-2,16,13,LEAVES:12)
Block(-2,16,14,LEAVES:12)
Block(-2,16,16,LEAVES:12)
Block(-2,16,21,LEAVES:12)
Block(-2,17,5,LEAVES:12)
Block(-2,17,10,LOG:12)
Block(-2,17,11,LOG:12)
Block(-2,17,13,LEAVES:12)
Block(-2,17,14,LEAVES:12)
Block(-2,18,2,LEAVES:12)
Block(-2,18,4,LEAVES:12)
Block(-2,18,5,LEAVES:12)
Block(-2,18,11,LOG:12)
Block(-2,18,13,LEAVES:12)
Block(-2,19,4,LOG:12)
Block(-2,19,11,LOG:12)
Block(-2,19,13,LEAVES:12)
Block(-2,19,15,LEAVES:12)
Block(-2,20,-1,LEAVES:12)
Block(-2,20,0,LEAVES:12)
Block(-2,20,3,LOG:12)
Block(-2,20,4,LOG:12)
Block(-2,20,9,LEAVES:12)
Block(-2,20,11,LEAVES:12)
Block(-2,20,12,LEAVES:12)
Block(-2,20,13,LEAVES:12)
Block(-2,20,15,LEAVES:12)
Block(-2,21,2,LEAVES:12)
Block(-2,21,4,LEAVES:12)
Block(-2,21,7,LEAVES:12)
Block(-2,21,9,LEAVES:12)
Block(-2,21,11,LEAVES:12)
Block(-2,21,12,LEAVES:12)
Block(-2,21,16,LEAVES:12)
Block(-2,22,-1,LEAVES:12)
Block(-2,22,1,LEAVES:12)
Block(-2,22,2,LEAVES:12)
Block(-2,22,11,LEAVES:12)
Block(-2,24,12,LEAVES:12)
Block(-2,24,13,LEAVES:12)
Block(-2,25,13,LEAVES:12)
Block(-2,25,14,LEAVES:12)
Block(-2,26,13,LEAVES:12)
Block(-1,6,-6,LEAVES:12)
Block(-1,7,-2,LEAVES:12)
Block(-1,8,-5,LEAVES:12)
Block(-1,8,-3,LEAVES:12)
Block(-1,8,-2,LEAVES:12)
Block(-1,10,-8,LEAVES:12)
Block(-1,10,-7,LEAVES:12)
Block(-1,10,-4,LEAVES:12)
Block(-1,10,-3,LOG:12)
Block(-1,10,15,LEAVES:12)
Block(-1,11,-5,LEAVES:12)
Block(-1,11,-3,LOG:12)
Block(-1,11,5,LOG:12)
Block(-1,11,14,LEAVES:12)
Block(-1,11,20,LEAVES:12)
Block(-1,11,21,LEAVES:12)
Block(-1,12,-8,LEAVES:12)
Block(-1,12,-6,LEAVES:12)
Block(-1,12,-5,LEAVES:12)
Block(-1,12,5,LOG:12)
Block(-1,12,6,LOG:12)
Block(-1,12,13,LEAVES:12)
Block(-1,12,14,LEAVES:12)
Block(-1,13,5,LOG:12)
Block(-1,13,14,LEAVES:12)
Block(-1,13,15,LEAVES:12)
Block(-1,13,16,LEAVES:12)
Block(-1,13,17,LEAVES:12)
Block(-1,14,15,LOG:12)
Block(-1,14,16,LOG:12)
Block(-1,14,17,LEAVES:12)
Block(-1,14,18,LEAVES:12)
Block(-1,15,9,LOG:12)
Block(-1,15,10,LOG:12)
Block(-1,15,16,LEAVES:12)
Block(-1,15,18,LEAVES:12)
Block(-1,16,0,LEAVES:12)
Block(-1,16,5,LEAVES:12)
Block(-1,16,10,LOG:12)
Block(-1,16,16,LEAVES:12)
Block(-1,16,17,LEAVES:12)
Block(-1,17,-1,LEAVES:12)
Block(-1,17,0,LEAVES:12)
Block(-1,17,1,LEAVES:12)
Block(-1,17,2,LEAVES:12)
Block(-1,17,5,LEAVES:12)
Block(-1,17,10,LEAVES:12)
Block(-1,17,17,LEAVES:12)
Block(-1,18,-5,LEAVES:12)
Block(-1,18,2,LEAVES:12)
Block(-1,18,14,LEAVES:12)
Block(-1,18,16,LEAVES:12)
Block(-1,19,2,LEAVES:12)
Block(-1,19,4,LOG:12)
Block(-1,19,5,LOG:12)
Block(-1,19,11,LEAVES:12)
Block(-1,19,13,LEAVES:12)
Block(-1,19,14,LEAVES:12)
Block(-1,20,-2,LEAVES:12)
Block(-1,20,-1,LEAVES:12)
Block(-1,21,4,LEAVES:12)
Block(-1,21,5,LEAVES:12)
Block(-1,21,6,LEAVES:12)
Block(-1,21,8,LEAVES:12)
Block(-1,21,9,LEAVES:12)
Block(-1,21,12,LEAVES:12)
Block(-1,21,13,LEAVES:12)
Block(-1,22,0,LEAVES:12)
Block(-1,22,1,LEAVES:12)
Block(-1,22,5,LEAVES:12)
Block(-1,22,11,LEAVES:12)
Block(-1,22,13,LEAVES:12)
Block(-1,23,3,LEAVES:12)
Block(-1,23,8,LEAVES:12)
Block(-1,23,10,LEAVES:12)
Block(-1,23,11,LEAVES:12)
Block(0,0,3,LOG:12)
Block(0,0,4,LOG:12)
Block(0,1,4,LOG:12)
Block(0,2,4,LOG:12)
Block(0,5,5,LOG:12)
Block(0,6,-2,LEAVES:12)
Block(0,6,4,LOG:12)
Block(0,6,5,LOG:12)
Block(0,7,-6,LEAVES:12)
Block(0,7,-5,LEAVES:12)
Block(0,7,-2,LEAVES:12)
Block(0,7,4,LOG:12)
Block(0,7,5,LOG:12)
Block(0,8,-5,LEAVES:12)
Block(0,8,5,LOG:12)
Block(0,9,-5,LEAVES:12)
Block(0,10,-9,LEAVES:12)
Block(0,10,-8,LEAVES:12)
Block(0,10,5,LOG:12)
Block(0,10,18,LEAVES:12)
Block(0,11,-3,LOG:12)
Block(0,11,-2,LOG:12)
Block(0,11,-1,LEAVES:12)
Block(0,11,5,LOG:12)
Block(0,11,6,LOG:12)
Block(0,11,16,LEAVES:12)
Block(0,11,18,LEAVES:12)
Block(0,12,-7,LEAVES:12)
Block(0,12,-6,LEAVES:12)
Block(0,12,-2,LOG:12)
Block(0,12,5,LOG:12)
Block(0,12,16,LEAVES:12)
Block(0,12,18,LEAVES:12)
Block(0,12,20,LEAVES:12)
Block(0,13,-4,LEAVES:12)
Block(0,13,14,LEAVES:12)
Block(0,13,16,LEAVES:12)
Block(0,13,17,LEAVES:12)
Block(0,13,18,LEAVES:12)
Block(0,13,20,LEAVES:12)
Block(0,14,-3,LEAVES:12)
Block(0,14,12,LEAVES:12)
Block(0,14,13,LOG:12)
Block(0,14,14,LOG:12)
Block(0,14,15,LOG:12)
Block(0,14,16,LEAVES:12)
Block(0,14,17,LEAVES:12)
Block(0,14,21,LEAVES:12)
Block(0,15,9,LOG:12)
Block(0,15,16,LEAVES:12)
Block(0,16,0,LEAVES:12)
Block(0,16,1,LEAVES:12)
Block(0,16,2,LOG:12)
Block(0,16,3,LOG:12)
Block(0,17,-1,LEAVES:12)
Block(0,17,0,LOG:12)
Block(0,17,1,LOG:12)
Block(0,17,2,LOG:12)
Block(0,17,14,LEAVES:12)
Block(0,17,17,LEAVES:12)
Block(0,17,18,LEAVES:12)
Block(0,18,-5,LEAVES:12)
Block(0,18,-4,LEAVES:12)
Block(0,18,5,LOG:12)
Block(0,18,10,LEAVES:12)
Block(0,18,11,LEAVES:12)
Block(0,18,14,LEAVES:12)
Block(0,18,18,LEAVES:12)
Block(0,18,19,LEAVES:12)
Block(0,19,1,LEAVES:12)
Block(0,19,2,LEAVES:12)
Block(0,19,5,LOG:12)
Block(0,19,11,LEAVES:12)
Block(0,19,18,LEAVES:12)
Block(0,20,2,LEAVES:12)
Block(0,20,11,LEAVES:12)
Block(0,21,-3,LEAVES:12)
Block(0,21,-1,LEAVES:12)
Block(0,21,5,LEAVES:12)
Block(0,21,7,LEAVES:12)
Block(0,21,8,LEAVES:12)
Block(0,22,-3,LEAVES:12)
Block(0,22,0,LEAVES:12)
Block(0,22,13,LEAVES:12)
Block(0,22,14,LEAVES:12)
Block(0,22,15,LEAVES:12)
Block(0,23,0,LEAVES:12)
Block(0,23,9,LEAVES:12)
Block(0,23,10,LEAVES:12)
Block(0,23,14,LEAVES:12)
Block(0,24,12,LEAVES:12)
Block(1,0,3,LOG:12)
Block(1,0,4,LOG:12)
Block(1,0,5,LOG:12)
Block(1,1,3,LOG:12)
Block(1,1,5,LOG:12)
Block(1,2,3,LOG:12)
Block(1,2,4,LOG:12)
Block(1,2,5,LOG:12)
Block(1,3,3,LOG:12)
Block(1,3,4,LOG:12)
Block(1,3,5,LOG:12)
Block(1,4,3,LOG:12)
Block(1,4,4,LOG:12)
Block(1,4,5,LOG:12)
Block(1,5,3,LOG:12)
Block(1,5,4,LOG:12)
Block(1,5,5,LOG:12)
Block(1,6,-7,LEAVES:12)
Block(1,6,-6,LEAVES:12)
Block(1,6,4,LOG:12)
Block(1,6,5,LOG:12)
Block(1,7,-6,LEAVES:12)
Block(1,7,4,LOG:12)
Block(1,7,5,LOG:12)
Block(1,8,4,LOG:12)
Block(1,8,5,LOG:12)
Block(1,9,-6,LEAVES:12)
Block(1,9,-5,LEAVES:12)
Block(1,9,4,LOG:12)
Block(1,9,5,LOG:12)
Block(1,10,-5,LEAVES:12)
Block(1,10,4,LOG:12)
Block(1,10,5,LOG:12)
Block(1,10,15,LEAVES:12)
Block(1,11,-2,LEAVES:12)
Block(1,11,5,LOG:12)
Block(1,11,19,LEAVES:12)
Block(1,12,-7,LEAVES:12)
Block(1,12,-2,LOG:12)
Block(1,12,-1,LOG:12)
Block(1,12,0,LOG:12)
Block(1,12,16,LEAVES:12)
Block(1,12,18,LEAVES:12)
Block(1,12,19,LEAVES:12)
Block(1,13,-7,LEAVES:12)
Block(1,13,-2,LEAVES:12)
Block(1,13,0,LOG:12)
Block(1,14,-2,LEAVES:12)
Block(1,14,4,LOG:12)
Block(1,14,8,LOG:12)
Block(1,14,13,LOG:12)
Block(1,14,14,LEAVES:12)
Block(1,14,17,LEAVES:12)
Block(1,14,18,LEAVES:12)
Block(1,15,0,LEAVES:12)
Block(1,15,4,LOG:12)
Block(1,15,8,LOG:12)
Block(1,15,9,LOG:12)
Block(1,15,16,LEAVES:12)
Block(1,15,18,LEAVES:12)
Block(1,16,-6,LEAVES:12)
Block(1,16,0,LEAVES:12)
Block(1,16,3,LOG:12)
Block(1,16,4,LOG:12)
Block(1,16,5,LOG:12)
Block(1,16,13,LEAVES:12)
Block(1,16,15,LEAVES:12)
Block(1,16,16,LEAVES:12)
Block(1,17,-4,LEAVES:12)
Block(1,17,-3,LEAVES:12)
Block(1,17,-1,LEAVES:12)
Block(1,17,0,LOG:12)
Block(1,17,5,LOG:12)
Block(1,17,9,LEAVES:12)
Block(1,17,10,LEAVES:12)
Block(1,18,-4,LEAVES:12)
Block(1,18,-2,LEAVES:12)
Block(1,18,-1,LOG:12)
Block(1,18,0,LOG:12)
Block(1,18,3,LEAVES:12)
Block(1,18,5,LOG:12)
Block(1,18,10,LEAVES:12)
Block(1,19,2,LEAVES:12)
Block(1,19,3,LEAVES:12)
Block(1,20,0,LEAVES:12)
Block(1,20,2,LEAVES:12)
Block(1,20,3,LEAVES:12)
Block(1,20,7,LEAVES:12)
Block(1,20,10,LEAVES:12)
Block(1,20,11,LEAVES:12)
Block(1,21,-3,LEAVES:12)
Block(1,21,-2,LEAVES:12)
Block(1,21,6,LEAVES:12)
Block(1,21,7,LEAVES:12)
Block(1,21,11,LEAVES:12)
Block(1,22,2,LEAVES:12)
Block(1,22,14,LEAVES:12)
Block(1,23,9,LEAVES:12)
Block(1,24,9,LEAVES:12)
Block(2,0,3,LOG:12)
Block(2,0,4,LOG:12)
Block(2,0,5,LOG:12)
Block(2,1,3,LOG:12)
Block(2,1,4,LOG:12)
Block(2,2,3,LOG:12)
Block(2,2,4,LOG:12)
Block(2,3,3,LOG:12)
Block(2,3,4,LOG:12)
Block(2,4,4,LOG:12)
Block(2,5,4,LOG:12)
Block(2,6,-7,LEAVES:12)
Block(2,8,-4,LEAVES:12)
Block(2,8,5,LOG:12)
Block(2,9,-5,LEAVES:12)
Block(2,9,-4,LEAVES:12)
Block(2,9,5,LOG:12)
Block(2,9,17,LEAVES:12)
Block(2,10,5,LOG:12)
Block(2,10,16,LEAVES:12)
Block(2,10,17,LEAVES:12)
Block(2,10,19,LEAVES:12)
Block(2,11,4,LOG:12)
Block(2,11,5,LOG:12)
Block(2,11,12,LEAVES:12)
Block(2,11,15,LEAVES:12)
Block(2,11,16,LEAVES:12)
Block(2,11,19,LEAVES:12)
Block(2,12,4,LOG:12)
Block(2,12,5,LOG:12)
Block(2,12,6,LOG:12)
Block(2,12,16,LEAVES:12)
Block(2,13,0,LOG:12)
Block(2,13,1,LOG:12)
Block(2,13,2,LOG:12)
Block(2,13,3,LOG:12)
Block(2,13,4,LOG:12)
Block(2,13,5,LOG:12)
Block(2,13,6,LOG:12)
Block(2,13,7,LOG:12)
Block(2,13,16,LEAVES:12)
Block(2,14,-6,LEAVES:12)
Block(2,14,-2,LEAVES:12)
Block(2,14,-1,LEAVES:12)
Block(2,14,4,LOG:12)
Block(2,14,5,LOG:12)
Block(2,14,7,LOG:12)
Block(2,14,8,LOG:12)
Block(2,14,12,LOG:12)
Block(2,14,13,LOG:12)
Block(2,15,-6,LEAVES:12)
Block(2,15,-5,LEAVES:12)
Block(2,15,-1,LEAVES:12)
Block(2,15,2,LEAVES:12)
Block(2,15,7,LOG:12)
Block(2,15,18,LEAVES:12)
Block(2,15,19,LEAVES:12)
Block(2,15,20,LEAVES:12)
Block(2,16,-1,LEAVES:12)
Block(2,16,14,LEAVES:12)
Block(2,16,15,LEAVES:12)
Block(2,16,19,LEAVES:12)
Block(2,17,-3,LEAVES:12)
Block(2,17,9,LEAVES:12)
Block(2,17,16,LEAVES:12)
Block(2,17,17,LEAVES:12)
Block(2,18,-2,LEAVES:12)
Block(2,18,-1,LOG:12)
Block(2,18,3,LEAVES:12)
Block(2,18,4,LEAVES:12)
Block(2,18,15,LEAVES:12)
Block(2,18,16,LEAVES:12)
Block(2,19,1,LEAVES:12)
Block(2,19,2,LEAVES:12)
Block(2,19,11,LEAVES:12)
Block(2,19,12,LEAVES:12)
Block(2,20,-6,LEAVES:12)
Block(2,20,-5,LEAVES:12)
Block(2,20,-2,LEAVES:12)
Block(2,20,2,LEAVES:12)
Block(2,20,11,LEAVES:12)
Block(2,20,12,LEAVES:12)
Block(2,21,-2,LEAVES:12)
Block(2,21,2,LEAVES:12)
Block(2,21,6,LEAVES:12)
Block(2,22,-2,LEAVES:12)
Block(2,22,2,LEAVES:12)
Block(2,22,3,LEAVES:12)
Block(2,25,4,LEAVES:12)
Block(2,25,6,LEAVES:12)
Block(2,26,4,LEAVES:12)
Block(3,7,14,LEAVES:12)
Block(3,8,-4,LEAVES:12)
Block(3,10,5,LOG:12)
Block(3,10,14,LEAVES:12)
Block(3,10,15,LEAVES:12)
Block(3,10,16,LEAVES:12)
Block(3,11,5,LOG:12)
Block(3,11,6,LOG:12)
Block(3,11,12,LEAVES:12)
Block(3,11,13,LEAVES:12)
Block(3,11,15,LEAVES:12)
Block(3,13,2,LOG:12)
Block(3,13,3,LOG:12)
Block(3,13,12,LOG:12)
Block(3,13,15,LEAVES:12)
Block(3,13,16,LEAVES:12)
Block(3,14,2,LOG:12)
Block(3,14,12,LOG:12)
Block(3,14,14,LEAVES:12)
Block(3,14,16,LEAVES:12)
Block(3,15,-5,LEAVES:12)
Block(3,15,1,LEAVES:12)
Block(3,15,2,LEAVES:12)
Block(3,15,7,LOG:12)
Block(3,15,13,LEAVES:12)
Block(3,15,14,LEAVES:12)
Block(3,15,19,LEAVES:12)
Block(3,16,-5,LEAVES:12)
Block(3,16,-1,LEAVES:12)
Block(3,16,0,LEAVES:12)
Block(3,16,1,LEAVES:12)
Block(3,16,7,LOG:12)
Block(3,16,8,LOG:12)
Block(3,16,14,LEAVES:12)
Block(3,17,-3,LEAVES:12)
Block(3,17,-1,LEAVES:12)
Block(3,17,5,LEAVES:12)
Block(3,17,14,LEAVES:12)
Block(3,18,-2,LOG:12)
Block(3,18,-1,LOG:12)
Block(3,18,5,LEAVES:12)
Block(3,18,15,LEAVES:12)
Block(3,19,-4,LEAVES:12)
Block(3,19,-3,LEAVES:12)
Block(3,19,-2,LEAVES:12)
Block(3,19,0,LEAVES:12)
Block(3,19,1,LEAVES:12)
Block(3,19,7,LEAVES:12)
Block(3,19,11,LEAVES:12)
Block(3,19,12,LEAVES:12)
Block(3,20,-5,LEAVES:12)
Block(3,20,-4,LEAVES:12)
Block(3,20,-2,LEAVES:12)
Block(3,20,1,LEAVES:12)
Block(3,20,3,LEAVES:12)
Block(3,21,-4,LEAVES:12)
Block(3,21,3,LEAVES:12)
Block(3,21,4,LEAVES:12)
Block(3,21,6,LEAVES:12)
Block(3,22,3,LEAVES:12)
Block(3,22,5,LEAVES:12)
Block(3,22,6,LEAVES:12)
Block(3,22,13,LEAVES:12)
Block(3,22,15,LEAVES:12)
Block(3,23,13,LEAVES:12)
Block(3,24,7,LEAVES:12)
Block(3,24,9,LEAVES:12)
Block(3,24,10,LEAVES:12)
Block(3,25,4,LEAVES:12)
Block(3,25,5,LEAVES:12)
Block(4,6,15,LEAVES:12)
Block(4,7,15,LEAVES:12)
Block(4,8,17,LEAVES:12)
Block(4,9,11,LEAVES:12)
Block(4,10,13,LEAVES:12)
Block(4,10,14,LEAVES:12)
Block(4,10,16,LEAVES:12)
Block(4,11,6,LOG:12)
Block(4,11,7,LOG:12)
Block(4,11,13,LEAVES:12)
Block(4,11,15,LEAVES:12)
Block(4,11,16,LEAVES:12)
Block(4,12,7,LOG:12)
Block(4,12,17,LEAVES:12)
Block(4,13,11,LOG:12)
Block(4,13,12,LOG:12)
Block(4,13,16,LEAVES:12)
Block(4,13,17,LEAVES:12)
Block(4,13,19,LEAVES:12)
Block(4,13,20,LEAVES:12)
Block(4,14,-3,LEAVES:12)
Block(4,14,1,LOG:12)
Block(4,14,2,LOG:12)
Block(4,14,14,LEAVES:12)
Block(4,14,15,LEAVES:12)
Block(4,15,-4,LEAVES:12)
Block(4,15,2,LEAVES:12)
Block(4,15,3,LEAVES:12)
Block(4,15,14,LEAVES:12)
Block(4,16,-5,LEAVES:12)
Block(4,16,-4,LEAVES:12)
Block(4,16,8,LOG:12)
Block(4,16,16,LEAVES:12)
Block(4,17,-4,LEAVES:12)
Block(4,17,-3,LEAVES:12)
Block(4,17,-2,LEAVES:12)
Block(4,17,-1,LEAVES:12)
Block(4,17,7,LOG:12)
Block(4,17,8,LOG:12)
Block(4,17,9,LOG:12)
Block(4,17,10,LEAVES:12)
Block(4,18,-2,LOG:12)
Block(4,18,-1,LEAVES:12)
Block(4,18,0,LEAVES:12)
Block(4,18,1,LEAVES:12)
Block(4,18,5,LEAVES:12)
Block(4,18,6,LEAVES:12)
Block(4,18,7,LOG:12)
Block(4,18,12,LEAVES:12)
Block(4,18,13,LEAVES:12)
Block(4,18,15,LEAVES:12)
Block(4,19,-2,LEAVES:12)
Block(4,19,0,LEAVES:12)
Block(4,19,1,LEAVES:12)
Block(4,19,2,LEAVES:12)
Block(4,19,6,LEAVES:12)
Block(4,19,7,LOG:12)
Block(4,19,9,LEAVES:12)
Block(4,19,12,LEAVES:12)
Block(4,19,14,LEAVES:12)
Block(4,19,15,LEAVES:12)
Block(4,20,-2,LEAVES:12)
Block(4,20,-1,LEAVES:12)
Block(4,20,6,LEAVES:12)
Block(4,21,-1,LEAVES:12)
Block(4,21,4,LEAVES:12)
Block(4,21,16,LEAVES:12)
Block(4,21,18,LEAVES:12)
Block(4,21,19,LEAVES:12)
Block(4,22,-2,LEAVES:12)
Block(4,22,5,LEAVES:12)
Block(4,22,13,LEAVES:12)
Block(4,22,14,LEAVES:12)
Block(4,23,8,LEAVES:12)
Block(4,23,9,LEAVES:12)
Block(4,24,1,LEAVES:12)
Block(4,24,2,LEAVES:12)
Block(4,24,5,LEAVES:12)
Block(4,24,9,LEAVES:12)
Block(4,25,5,LEAVES:12)
Block(4,25,9,LEAVES:12)
Block(4,26,5,LEAVES:12)
Block(5,6,17,LEAVES:12)
Block(5,7,11,LEAVES:12)
Block(5,7,15,LEAVES:12)
Block(5,7,16,LEAVES:12)
Block(5,8,11,LEAVES:12)
Block(5,8,12,LEAVES:12)
Block(5,8,16,LEAVES:12)
Block(5,8,19,LEAVES:12)
Block(5,9,16,LEAVES:12)
Block(5,10,14,LEAVES:12)
Block(5,11,7,LOG:12)
Block(5,11,15,LEAVES:12)
Block(5,12,7,LOG:12)
Block(5,12,8,LOG:12)
Block(5,12,9,LOG:12)
Block(5,12,11,LOG:12)
Block(5,12,12,LOG:12)
Block(5,12,17,LEAVES:12)
Block(5,12,18,LEAVES:12)
Block(5,12,19,LEAVES:12)
Block(5,13,9,LOG:12)
Block(5,13,10,LOG:12)
Block(5,13,11,LOG:12)
Block(5,13,12,LEAVES:12)
Block(5,13,15,LEAVES:12)
Block(5,13,19,LEAVES:12)
Block(5,14,0,LEAVES:12)
Block(5,14,1,LOG:12)
Block(5,14,15,LEAVES:12)
Block(5,14,16,LEAVES:12)
Block(5,14,19,LEAVES:12)
Block(5,15,-2,LEAVES:12)
Block(5,15,0,LEAVES:12)
Block(5,15,10,LEAVES:12)
Block(5,15,14,LEAVES:12)
Block(5,15,15,LEAVES:12)
Block(5,16,-2,LEAVES:12)
Block(5,16,0,LEAVES:12)
Block(5,16,2,LEAVES:12)
Block(5,16,10,LEAVES:12)
Block(5,16,11,LEAVES:12)
Block(5,16,15,LEAVES:12)
Block(5,16,18,LEAVES:12)
Block(5,17,-4,LEAVES:12)
Block(5,17,-2,LEAVES:12)
Block(5,17,-1,LEAVES:12)
Block(5,17,0,LEAVES:12)
Block(5,17,2,LEAVES:12)
Block(5,17,9,LOG:12)
Block(5,17,15,LEAVES:12)
Block(5,18,-6,LEAVES:12)
Block(5,18,-4,LEAVES:12)
Block(5,18,-2,LOG:12)
Block(5,18,-1,LEAVES:12)
Block(5,18,3,LEAVES:12)
Block(5,18,13,LEAVES:12)
Block(5,19,-2,LEAVES:12)
Block(5,19,2,LEAVES:12)
Block(5,19,6,LOG:12)
Block(5,19,7,LOG:12)
Block(5,19,8,LEAVES:12)
Block(5,19,9,LEAVES:12)
Block(5,19,14,LEAVES:12)
Block(5,20,2,LEAVES:12)
Block(5,20,6,LOG:12)
Block(5,20,7,LEAVES:12)
Block(5,20,8,LEAVES:12)
Block(5,20,17,LEAVES:12)
Block(5,20,18,LEAVES:12)
Block(5,21,-1,LEAVES:12)
Block(5,21,0,LEAVES:12)
Block(5,21,4,LEAVES:12)
Block(5,21,6,LEAVES:12)
Block(5,21,10,LEAVES:12)
Block(5,21,11,LEAVES:12)
Block(5,21,14,LEAVES:12)
Block(5,21,18,LEAVES:12)
Block(5,22,0,LEAVES:12)
Block(5,22,1,LEAVES:12)
Block(5,22,5,LEAVES:12)
Block(5,22,14,LEAVES:12)
Block(5,22,18,LEAVES:12)
Block(5,23,0,LEAVES:12)
Block(5,23,3,LEAVES:12)
Block(5,23,4,LEAVES:12)
Block(5,23,5,LEAVES:12)
Block(5,23,7,LEAVES:12)
Block(5,23,8,LEAVES:12)
Block(5,23,14,LEAVES:12)
Block(5,24,2,LEAVES:12)
Block(5,24,3,LEAVES:12)
Block(5,24,5,LEAVES:12)
Block(5,24,10,LEAVES:12)
Block(5,25,3,LEAVES:12)
Block(6,7,2,LEAVES:12)
Block(6,8,1,LEAVES:12)
Block(6,8,2,LEAVES:12)
Block(6,8,12,LEAVES:12)
Block(6,8,18,LEAVES:12)
Block(6,8,19,LEAVES:12)
Block(6,9,-3,LEAVES:12)
Block(6,9,12,LEAVES:12)
Block(6,9,16,LEAVES:12)
Block(6,9,17,LEAVES:12)
Block(6,9,18,LEAVES:12)
Block(6,10,14,LEAVES:12)
Block(6,10,16,LEAVES:12)
Block(6,11,7,LOG:12)
Block(6,11,13,LOG:12)
Block(6,11,14,LOG:12)
Block(6,11,15,LEAVES:12)
Block(6,12,6,LOG:12)
Block(6,12,7,LOG:12)
Block(6,12,12,LOG:12)
Block(6,12,13,LOG:12)
Block(6,12,14,LEAVES:12)
Block(6,12,15,LEAVES:12)
Block(6,12,17,LEAVES:12)
Block(6,12,18,LEAVES:12)
Block(6,13,12,LEAVES:12)
Block(6,13,13,LEAVES:12)
Block(6,13,15,LEAVES:12)
Block(6,13,20,LEAVES:12)
Block(6,14,-3,LEAVES:12)
Block(6,14,1,LOG:12)
Block(6,14,2,LEAVES:12)
Block(6,14,13,LEAVES:12)
Block(6,15,0,LOG:12)
Block(6,15,1,LOG:12)
Block(6,15,2,LEAVES:12)
Block(6,16,-3,LEAVES:12)
Block(6,16,-2,LEAVES:12)
Block(6,16,0,LEAVES:12)
Block(6,16,1,LEAVES:12)
Block(6,16,11,LEAVES:12)
Block(6,16,17,LEAVES:12)
Block(6,16,18,LEAVES:12)
Block(6,17,9,LOG:12)
Block(6,17,11,LEAVES:12)
Block(6,17,15,LEAVES:12)
Block(6,17,16,LEAVES:12)
Block(6,17,17,LEAVES:12)
Block(6,18,-5,LEAVES:12)
Block(6,18,-4,LEAVES:12)
Block(6,18,-1,LEAVES:12)
Block(6,18,0,LEAVES:12)
Block(6,18,4,LEAVES:12)
Block(6,18,9,LOG:12)
Block(6,18,10,LOG:12)
Block(6,18,13,LEAVES:12)
Block(6,18,15,LEAVES:12)
Block(6,19,-2,LEAVES:12)
Block(6,19,0,LEAVES:12)
Block(6,19,3,LEAVES:12)
Block(6,19,9,LEAVES:12)
Block(6,19,10,LEAVES:12)
Block(6,19,14,LEAVES:12)
Block(6,20,-5,LEAVES:12)
Block(6,20,-3,LEAVES:12)
Block(6,20,-2,LEAVES:12)
Block(6,20,2,LEAVES:12)
Block(6,20,3,LEAVES:12)
Block(6,20,5,LOG:12)
Block(6,20,6,LOG:12)
Block(6,20,12,LEAVES:12)
Block(6,20,13,LEAVES:12)
Block(6,20,14,LEAVES:12)
Block(6,20,16,LEAVES:12)
Block(6,20,17,LEAVES:12)
Block(6,21,3,LEAVES:12)
Block(6,21,4,LEAVES:12)
Block(6,21,5,LOG:12)
Block(6,21,6,LEAVES:12)
Block(6,21,11,LEAVES:12)
Block(6,21,12,LEAVES:12)
Block(6,21,14,LEAVES:12)
Block(6,21,19,LEAVES:12)
Block(6,22,5,LOG:12)
Block(6,22,6,LEAVES:12)
Block(6,22,7,LEAVES:12)
Block(6,22,12,LEAVES:12)
Block(6,23,5,LEAVES:12)
Block(6,23,7,LEAVES:12)
Block(6,24,5,LEAVES:12)
Block(6,24,6,LEAVES:12)
Block(6,25,6,LEAVES:12)
Block(6,26,5,LEAVES:12)
Block(7,5,-1,LEAVES:12)
Block(7,7,14,LEAVES:12)
Block(7,8,1,LEAVES:12)
Block(7,8,13,LEAVES:12)
Block(7,8,19,LEAVES:12)
Block(7,8,20,LEAVES:12)
Block(7,9,-3,LEAVES:12)
Block(7,9,-2,LEAVES:12)
Block(7,9,12,LEAVES:12)
Block(7,9,13,LEAVES:12)
Block(7,10,13,LEAVES:12)
Block(7,10,14,LEAVES:12)
Block(7,10,15,LEAVES:12)
Block(7,10,16,LEAVES:12)
Block(7,11,14,LOG:12)
Block(7,11,15,LOG:12)
Block(7,11,16,LEAVES:12)
Block(7,11,17,LEAVES:12)
Block(7,12,-1,LEAVES:12)
Block(7,12,1,LEAVES:12)
Block(7,12,5,LOG:12)
Block(7,12,6,LOG:12)
Block(7,12,7,LOG:12)
Block(7,12,15,LEAVES:12)
Block(7,12,17,LEAVES:12)
Block(7,13,-1,LEAVES:12)
Block(7,13,7,LOG:12)
Block(7,13,15,LEAVES:12)
Block(7,13,16,LEAVES:12)
Block(7,14,1,LEAVES:12)
Block(7,14,16,LEAVES:12)
Block(7,15,-3,LEAVES:12)
Block(7,15,-2,LEAVES:12)
Block(7,15,0,LOG:12)
Block(7,15,1,LEAVES:12)
Block(7,15,13,LEAVES:12)
Block(7,15,15,LEAVES:12)
Block(7,16,-3,LEAVES:12)
Block(7,16,-2,LEAVES:12)
Block(7,16,12,LEAVES:12)
Block(7,16,18,LEAVES:12)
Block(7,16,19,LEAVES:12)
Block(7,17,-2,LEAVES:12)
Block(7,17,11,LEAVES:12)
Block(7,17,12,LEAVES:12)
Block(7,18,-6,LEAVES:12)
Block(7,18,-5,LEAVES:12)
Block(7,18,7,LEAVES:12)
Block(7,18,10,LOG:12)
Block(7,18,11,LOG:12)
Block(7,18,12,LEAVES:12)
Block(7,18,13,LEAVES:12)
Block(7,18,14,LEAVES:12)
Block(7,18,15,LEAVES:12)
Block(7,19,-1,LEAVES:12)
Block(7,19,0,LEAVES:12)
Block(7,19,1,LEAVES:12)
Block(7,19,2,LEAVES:12)
Block(7,19,5,LEAVES:12)
Block(7,19,7,LEAVES:12)
Block(7,19,11,LOG:12)
Block(7,19,12,LOG:12)
Block(7,19,13,LOG:12)
Block(7,19,14,LOG:12)
Block(7,19,15,LEAVES:12)
Block(7,19,16,LEAVES:12)
Block(7,20,-4,LEAVES:12)
Block(7,20,-3,LEAVES:12)
Block(7,20,-1,LEAVES:12)
Block(7,20,1,LEAVES:12)
Block(7,20,5,LEAVES:12)
Block(7,20,7,LEAVES:12)
Block(7,20,9,LEAVES:12)
Block(7,20,14,LEAVES:12)
Block(7,20,16,LEAVES:12)
Block(7,21,-1,LEAVES:12)
Block(7,21,3,LEAVES:12)
Block(7,21,5,LEAVES:12)
Block(7,21,6,LEAVES:12)
Block(7,21,7,LEAVES:12)
Block(7,21,9,LEAVES:12)
Block(7,21,14,LEAVES:12)
Block(7,21,15,LEAVES:12)
Block(7,22,1,LEAVES:12)
Block(7,22,3,LEAVES:12)
Block(7,22,5,LEAVES:12)
Block(7,22,6,LEAVES:12)
Block(7,22,10,LEAVES:12)
Block(7,22,15,LEAVES:12)
Block(7,23,5,LEAVES:12)
Block(7,23,14,LEAVES:12)
Block(7,25,6,LEAVES:12)
Block(7,25,7,LEAVES:12)
Block(7,26,7,LEAVES:12)
Block(7,26,8,LEAVES:12)
Block(7,27,7,LEAVES:12)
Block(8,4,0,LEAVES:12)
Block(8,5,0,LEAVES:12)
Block(8,6,2,LEAVES:12)
Block(8,7,-4,LEAVES:12)
Block(8,7,17,LEAVES:12)
Block(8,8,-2,LEAVES:12)
Block(8,8,-1,LEAVES:12)
Block(8,8,1,LEAVES:12)
Block(8,8,15,LEAVES:12)
Block(8,8,17,LEAVES:12)
Block(8,9,-2,LEAVES:12)
Block(8,9,0,LEAVES:12)
Block(8,9,1,LEAVES:12)
Block(8,9,15,LEAVES:12)
Block(8,9,17,LEAVES:12)
Block(8,9,19,LEAVES:12)
Block(8,10,13,LEAVES:12)
Block(8,10,15,LEAVES:12)
Block(8,10,16,LEAVES:12)
Block(8,10,17,LEAVES:12)
Block(8,10,19,LEAVES:12)
Block(8,11,0,LEAVES:12)
Block(8,11,2,LEAVES:12)
Block(8,11,3,LOG:12)
Block(8,11,4,LOG:12)
Block(8,11,5,LOG:12)
Block(8,11,11,LEAVES:12)
Block(8,11,13,LEAVES:12)
Block(8,11,15,LEAVES:12)
Block(8,11,16,LEAVES:12)
Block(8,11,20,LEAVES:12)
Block(8,12,-1,LEAVES:12)
Block(8,12,0,LEAVES:12)
Block(8,12,5,LOG:12)
Block(8,12,15,LEAVES:12)
Block(8,13,2,LEAVES:12)
Block(8,13,7,LOG:12)
Block(8,13,8,LOG:12)
Block(8,13,13,LEAVES:12)
Block(8,14,-4,LEAVES:12)
Block(8,14,-3,LEAVES:12)
Block(8,14,7,LOG:12)
Block(8,14,8,LOG:12)
Block(8,14,12,LEAVES:12)
Block(8,14,13,LEAVES:12)
Block(8,14,16,LEAVES:12)
Block(8,14,17,LEAVES:12)
Block(8,15,-3,LEAVES:12)
Block(8,15,-2,LEAVES:12)
Block(8,15,-1,LEAVES:12)
Block(8,15,0,LOG:12)
Block(8,15,1,LEAVES:12)
Block(8,15,8,LEAVES:12)
Block(8,15,16,LEAVES:12)
Block(8,15,17,LEAVES:12)
Block(8,15,18,LEAVES:12)
Block(8,16,-2,LEAVES:12)
Block(8,16,0,LEAVES:12)
Block(8,16,1,LEAVES:12)
Block(8,16,14,LEAVES:12)
Block(8,16,16,LEAVES:12)
Block(8,16,17,LEAVES:12)
Block(8,17,-3,LEAVES:12)
Block(8,17,-2,LEAVES:12)
Block(8,17,14,LEAVES:12)
Block(8,17,16,LEAVES:12)
Block(8,17,18,LEAVES:12)
Block(8,18,-2,LEAVES:12)
Block(8,18,2,LEAVES:12)
Block(8,18,4,LEAVES:12)
Block(8,18,5,LEAVES:12)
Block(8,18,12,LEAVES:12)
Block(8,18,14,LEAVES:12)
Block(8,18,15,LEAVES:12)
Block(8,18,16,LEAVES:12)
Block(8,18,18,LEAVES:12)
Block(8,19,-1,LEAVES:12)
Block(8,19,0,LEAVES:12)
Block(8,19,1,LEAVES:12)
Block(8,19,8,LEAVES:12)
Block(8,19,10,LEAVES:12)
Block(8,19,12,LEAVES:12)
Block(8,19,14,LEAVES:12)
Block(8,19,15,LEAVES:12)
Block(8,19,19,LEAVES:12)
Block(8,20,-4,LEAVES:12)
Block(8,20,5,LEAVES:12)
Block(8,20,7,LEAVES:12)
Block(8,20,8,LEAVES:12)
Block(8,20,14,LEAVES:12)
Block(8,21,-4,LEAVES:12)
Block(8,22,2,LEAVES:12)
Block(8,22,3,LEAVES:12)
Block(8,22,6,LEAVES:12)
Block(8,22,7,LEAVES:12)
Block(8,22,15,LEAVES:12)
Block(8,22,16,LEAVES:12)
Block(8,23,5,LEAVES:12)
Block(8,23,7,LEAVES:12)
Block(8,23,16,LEAVES:12)
Block(8,23,17,LEAVES:12)
Block(8,24,2,LEAVES:12)
Block(8,24,4,LEAVES:12)
Block(8,24,5,LEAVES:12)
Block(8,24,16,LEAVES:12)
Block(9,4,2,LEAVES:12)
Block(9,5,-4,LEAVES:12)
Block(9,5,0,LEAVES:12)
Block(9,5,1,LEAVES:12)
Block(9,6,-4,LEAVES:12)
Block(9,6,-3,LEAVES:12)
Block(9,6,1,LEAVES:12)
Block(9,6,4,LEAVES:12)
Block(9,7,1,LEAVES:12)
Block(9,7,14,LEAVES:12)
Block(9,8,-1,LEAVES:12)
Block(9,8,18,LEAVES:12)
Block(9,9,0,LEAVES:12)
Block(9,9,15,LEAVES:12)
Block(9,9,17,LEAVES:12)
Block(9,9,18,LEAVES:12)
Block(9,10,2,LOG:12)
Block(9,10,3,LOG:12)
Block(9,10,4,LEAVES:12)
Block(9,11,-4,LEAVES:12)
Block(9,11,-3,LEAVES:12)
Block(9,11,0,LEAVES:12)
Block(9,11,2,LEAVES:12)
Block(9,11,3,LOG:12)
Block(9,11,4,LEAVES:12)
Block(9,11,10,LEAVES:12)
Block(9,11,12,LEAVES:12)
Block(9,11,13,LEAVES:12)
Block(9,11,16,LEAVES:12)
Block(9,11,17,LEAVES:12)
Block(9,12,-4,LEAVES:12)
Block(9,12,0,LEAVES:12)
Block(9,12,1,LEAVES:12)
Block(9,12,4,LEAVES:12)
Block(9,12,15,LEAVES:12)
Block(9,12,17,LEAVES:12)
Block(9,13,-4,LEAVES:12)
Block(9,13,-3,LEAVES:12)
Block(9,13,0,LEAVES:12)
Block(9,13,1,LEAVES:12)
Block(9,13,4,LEAVES:12)
Block(9,13,12,LEAVES:12)
Block(9,13,14,LEAVES:12)
Block(9,13,15,LEAVES:12)
Block(9,14,-4,LEAVES:12)
Block(9,14,1,LEAVES:12)
Block(9,14,8,LOG:12)
Block(9,14,9,LOG:12)
Block(9,14,10,LOG:12)
Block(9,14,12,LEAVES:12)
Block(9,15,-1,LEAVES:12)
Block(9,15,0,LOG:12)
Block(9,15,8,LEAVES:12)
Block(9,15,9,LEAVES:12)
Block(9,15,13,LEAVES:12)
Block(9,16,-1,LEAVES:12)
Block(9,16,0,LOG:12)
Block(9,16,17,LEAVES:12)
Block(9,17,-2,LEAVES:12)
Block(9,17,-1,LEAVES:12)
Block(9,17,3,LEAVES:12)
Block(9,17,4,LEAVES:12)
Block(9,17,14,LEAVES:12)
Block(9,17,16,LEAVES:12)
Block(9,17,17,LEAVES:12)
Block(9,18,-4,LEAVES:12)
Block(9,18,-3,LEAVES:12)
Block(9,18,0,LEAVES:12)
Block(9,18,4,LEAVES:12)
Block(9,18,8,LEAVES:12)
Block(9,18,10,LEAVES:12)
Block(9,18,12,LEAVES:12)
Block(9,19,0,LEAVES:12)
Block(9,19,4,LEAVES:12)
Block(9,19,5,LEAVES:12)
Block(9,19,8,LEAVES:12)
Block(9,19,10,LEAVES:12)
Block(9,19,11,LEAVES:12)
Block(9,19,12,LEAVES:12)
Block(9,19,15,LEAVES:12)
Block(9,19,16,LEAVES:12)
Block(9,20,0,LEAVES:12)
Block(9,20,5,LEAVES:12)
Block(9,20,14,LEAVES:12)
Block(9,20,16,LEAVES:12)
Block(9,21,5,LEAVES:12)
Block(9,21,11,LEAVES:12)
Block(9,21,13,LEAVES:12)
Block(9,21,14,LEAVES:12)
Block(9,22,1,LEAVES:12)
Block(9,22,2,LEAVES:12)
Block(9,23,7,LEAVES:12)
Block(9,23,8,LEAVES:12)
Block(9,23,9,LEAVES:12)
Block(9,24,3,LEAVES:12)
Block(9,24,4,LEAVES:12)
Block(9,24,8,LEAVES:12)
Block(9,25,6,LEAVES:12)
Block(10,6,-3,LEAVES:12)
Block(10,6,3,LEAVES:12)
Block(10,6,4,LEAVES:12)
Block(10,7,-3,LEAVES:12)
Block(10,7,1,LEAVES:12)
Block(10,7,2,LEAVES:12)
Block(10,7,3,LEAVES:12)
Block(10,7,18,LEAVES:12)
Block(10,8,-1,LEAVES:12)
Block(10,8,1,LEAVES:12)
Block(10,8,14,LEAVES:12)
Block(10,8,15,LEAVES:12)
Block(10,8,18,LEAVES:12)
Block(10,9,0,LEAVES:12)
Block(10,9,1,LOG:12)
Block(10,9,15,LEAVES:12)
Block(10,10,-2,LEAVES:12)
Block(10,10,-1,LEAVES:12)
Block(10,10,0,LEAVES:12)
Block(10,10,1,LOG:12)
Block(10,10,2,LOG:12)
Block(10,10,3,LEAVES:12)
Block(10,10,11,LEAVES:12)
Block(10,10,15,LEAVES:12)
Block(10,11,-3,LEAVES:12)
Block(10,11,-2,LEAVES:12)
Block(10,11,0,LEAVES:12)
Block(10,11,5,LEAVES:12)
Block(10,11,11,LEAVES:12)
Block(10,11,12,LEAVES:12)
Block(10,12,-2,LEAVES:12)
Block(10,12,13,LEAVES:12)
Block(10,12,17,LEAVES:12)
Block(10,12,18,LEAVES:12)
Block(10,12,19,LEAVES:12)
Block(10,13,-3,LEAVES:12)
Block(10,13,3,LEAVES:12)
Block(10,13,4,LEAVES:12)
Block(10,13,7,LEAVES:12)
Block(10,13,13,LEAVES:12)
Block(10,13,14,LEAVES:12)
Block(10,13,18,LEAVES:12)
Block(10,14,-3,LEAVES:12)
Block(10,14,1,LEAVES:12)
Block(10,14,2,LEAVES:12)
Block(10,14,3,LEAVES:12)
Block(10,14,9,LEAVES:12)
Block(10,14,10,LOG:12)
Block(10,14,12,LEAVES:12)
Block(10,14,16,LEAVES:12)
Block(10,15,-1,LEAVES:12)
Block(10,15,1,LEAVES:12)
Block(10,15,9,LEAVES:12)
Block(10,15,10,LOG:12)
Block(10,15,11,LOG:12)
Block(10,15,12,LEAVES:12)
Block(10,15,17,LEAVES:12)
Block(10,16,-1,LEAVES:12)
Block(10,16,0,LOG:12)
Block(10,16,13,LEAVES:12)
Block(10,16,14,LEAVES:12)
Block(10,16,17,LEAVES:12)
Block(10,17,-2,LEAVES:12)
Block(10,17,-1,LEAVES:12)
Block(10,17,0,LEAVES:12)
Block(10,17,2,LEAVES:12)
Block(10,17,3,LEAVES:12)
Block(10,17,13,LEAVES:12)
Block(10,17,14,LEAVES:12)
Block(10,17,15,LEAVES:12)
Block(10,17,16,LEAVES:12)
Block(10,18,-3,LEAVES:12)
Block(10,18,-2,LEAVES:12)
Block(10,18,0,LEAVES:12)
Block(10,18,3,LEAVES:12)
Block(10,18,4,LEAVES:12)
Block(10,18,5,LEAVES:12)
Block(10,18,10,LEAVES:12)
Block(10,18,11,LEAVES:12)
Block(10,18,14,LEAVES:12)
Block(10,19,-2,LEAVES:12)
Block(10,19,4,LEAVES:12)
Block(10,19,10,LEAVES:12)
Block(10,19,11,LEAVES:12)
Block(10,20,16,LEAVES:12)
Block(10,20,17,LEAVES:12)
Block(10,20,18,LEAVES:12)
Block(10,21,4,LEAVES:12)
Block(10,21,5,LEAVES:12)
Block(10,21,12,LEAVES:12)
Block(10,21,13,LEAVES:12)
Block(10,21,17,LEAVES:12)
Block(10,22,5,LEAVES:12)
Block(10,22,15,LEAVES:12)
Block(10,23,8,LEAVES:12)
Block(10,24,3,LEAVES:12)
Block(10,25,3,LEAVES:12)
Block(11,5,-1,LEAVES:12)
Block(11,6,-2,LEAVES:12)
Block(11,6,4,LEAVES:12)
Block(11,6,5,LEAVES:12)
Block(11,7,-3,LEAVES:12)
Block(11,7,-2,LEAVES:12)
Block(11,7,13,LEAVES:12)
Block(11,7,14,LEAVES:12)
Block(11,8,-2,LEAVES:12)
Block(11,8,-1,LEAVES:12)
Block(11,8,0,LEAVES:12)
Block(11,8,1,LEAVES:12)
Block(11,8,14,LEAVES:12)
Block(11,9,0,LOG:12)
Block(11,9,1,LOG:12)
Block(11,9,2,LEAVES:12)
Block(11,10,0,LEAVES:12)
Block(11,10,2,LEAVES:12)
Block(11,10,13,LEAVES:12)
Block(11,10,14,LEAVES:12)
Block(11,10,15,LEAVES:12)
Block(11,11,0,LEAVES:12)
Block(11,11,1,LEAVES:12)
Block(11,11,7,LEAVES:12)
Block(11,11,11,LEAVES:12)
Block(11,11,12,LEAVES:12)
Block(11,11,15,LEAVES:12)
Block(11,12,-1,LEAVES:12)
Block(11,12,1,LEAVES:12)
Block(11,12,7,LEAVES:12)
Block(11,12,8,LEAVES:12)
Block(11,12,12,LEAVES:12)
Block(11,12,15,LEAVES:12)
Block(11,12,18,LEAVES:12)
Block(11,13,-2,LEAVES:12)
Block(11,13,0,LEAVES:12)
Block(11,13,4,LEAVES:12)
Block(11,13,5,LEAVES:12)
Block(11,13,12,LEAVES:12)
Block(11,13,13,LEAVES:12)
Block(11,14,-3,LEAVES:12)
Block(11,14,-2,LEAVES:12)
Block(11,14,10,LEAVES:12)
Block(11,14,13,LEAVES:12)
Block(11,15,-2,LEAVES:12)
Block(11,15,-1,LEAVES:12)
Block(11,15,0,LEAVES:12)
Block(11,15,1,LEAVES:12)
Block(11,15,11,LOG:12)
Block(11,15,12,LEAVES:12)
Block(11,15,13,LEAVES:12)
Block(11,16,0,LOG:12)
Block(11,16,1,LEAVES:12)
Block(11,16,2,LEAVES:12)
Block(11,16,13,LEAVES:12)
Block(11,16,14,LEAVES:12)
Block(11,16,15,LEAVES:12)
Block(11,17,0,LEAVES:12)
Block(11,17,2,LEAVES:12)
Block(11,17,7,LEAVES:12)
Block(11,17,8,LEAVES:12)
Block(11,17,11,LEAVES:12)
Block(11,17,15,LEAVES:12)
Block(11,18,0,LEAVES:12)
Block(11,18,1,LEAVES:12)
Block(11,18,3,LEAVES:12)
Block(11,18,11,LEAVES:12)
Block(11,18,13,LEAVES:12)
Block(11,18,14,LEAVES:12)
Block(11,18,15,LEAVES:12)
Block(11,19,1,LEAVES:12)
Block(11,19,11,LEAVES:12)
Block(11,19,14,LEAVES:12)
Block(11,20,0,LEAVES:12)
Block(11,20,6,LEAVES:12)
Block(11,20,17,LEAVES:12)
Block(11,21,5,LEAVES:12)
Block(11,21,6,LEAVES:12)
Block(11,21,12,LEAVES:12)
Block(11,22,12,LEAVES:12)
Block(12,5,2,LEAVES:12)
Block(12,6,0,LEAVES:12)
Block(12,6,2,LEAVES:12)
Block(12,7,0,LEAVES:12)
Block(12,7,2,LEAVES:12)
Block(12,7,4,LEAVES:12)
Block(12,7,13,LEAVES:12)
Block(12,8,-2,LEAVES:12)
Block(12,8,0,LEAVES:12)
Block(12,8,1,LEAVES:12)
Block(12,8,2,LEAVES:12)
Block(12,8,4,LEAVES:12)
Block(12,9,-4,LEAVES:12)
Block(12,9,-2,LEAVES:12)
Block(12,9,0,LOG:12)
Block(12,9,1,LEAVES:12)
Block(12,9,5,LEAVES:12)
Block(12,9,16,LEAVES:12)
Block(12,10,0,LEAVES:12)
Block(12,10,15,LEAVES:12)
Block(12,10,16,LEAVES:12)
Block(12,12,1,LEAVES:12)
Block(12,12,2,LEAVES:12)
Block(12,12,8,LEAVES:12)
Block(12,12,14,LEAVES:12)
Block(12,12,15,LEAVES:12)
Block(12,13,0,LEAVES:12)
Block(12,13,2,LEAVES:12)
Block(12,13,3,LEAVES:12)
Block(12,13,8,LEAVES:12)
Block(12,13,12,LEAVES:12)
Block(12,13,13,LEAVES:12)
Block(12,13,14,LEAVES:12)
Block(12,14,0,LEAVES:12)
Block(12,14,2,LEAVES:12)
Block(12,14,4,LEAVES:12)
Block(12,14,10,LEAVES:12)
Block(12,14,12,LEAVES:12)
Block(12,15,-2,LEAVES:12)
Block(12,15,0,LEAVES:12)
Block(12,15,1,LEAVES:12)
Block(12,15,2,LEAVES:12)
Block(12,15,4,LEAVES:12)
Block(12,15,11,LOG:12)
Block(12,15,12,LEAVES:12)
Block(12,16,-4,LEAVES:12)
Block(12,16,-2,LEAVES:12)
Block(12,16,0,LEAVES:12)
Block(12,16,1,LEAVES:12)
Block(12,16,5,LEAVES:12)
Block(12,16,9,LEAVES:12)
Block(12,16,10,LEAVES:12)
Block(12,16,11,LEAVES:12)
Block(12,16,13,LEAVES:12)
Block(12,16,14,LEAVES:12)
Block(12,17,0,LEAVES:12)
Block(12,17,8,LEAVES:12)
Block(12,17,9,LEAVES:12)
Block(12,17,11,LEAVES:12)
Block(12,17,15,LEAVES:12)
Block(12,17,16,LEAVES:12)
Block(12,18,9,LEAVES:12)
Block(12,18,14,LEAVES:12)
Block(12,18,15,LEAVES:12)
Block(12,19,1,LEAVES:12)
Block(12,19,2,LEAVES:12)
Block(12,20,2,LEAVES:12)
Block(12,20,3,LEAVES:12)
Block(12,20,6,LEAVES:12)
Block(12,21,2,LEAVES:12)
Block(13,5,-1,LEAVES:12)
Block(13,6,3,LEAVES:12)
Block(13,7,0,LEAVES:12)
Block(13,7,2,LEAVES:12)
Block(13,7,3,LEAVES:12)
Block(13,9,-3,LEAVES:12)
Block(13,9,-2,LEAVES:12)
Block(13,9,1,LEAVES:12)
Block(13,9,2,LEAVES:12)
Block(13,9,16,LEAVES:12)
Block(13,10,0,LEAVES:12)
Block(13,10,2,LEAVES:12)
Block(13,11,-3,LEAVES:12)
Block(13,11,-1,LEAVES:12)
Block(13,11,0,LEAVES:12)
Block(13,11,10,LEAVES:12)
Block(13,12,-1,LEAVES:12)
Block(13,12,9,LEAVES:12)
Block(13,12,15,LEAVES:12)
Block(13,12,16,LEAVES:12)
Block(13,13,3,LEAVES:12)
Block(13,13,8,LEAVES:12)
Block(13,13,9,LEAVES:12)
Block(13,14,0,LEAVES:12)
Block(13,14,2,LEAVES:12)
Block(13,14,3,LEAVES:12)
Block(13,14,9,LEAVES:12)
Block(13,14,10,LEAVES:12)
Block(13,14,11,LEAVES:12)
Block(13,14,12,LEAVES:12)
Block(13,15,11,LOG:12)
Block(13,15,12,LEAVES:12)
Block(13,15,13,LEAVES:12)
Block(13,16,-3,LEAVES:12)
Block(13,16,-2,LEAVES:12)
Block(13,16,1,LEAVES:12)
Block(13,16,2,LEAVES:12)
Block(13,16,11,LEAVES:12)
Block(13,16,13,LEAVES:12)
Block(13,17,0,LEAVES:12)
Block(13,17,2,LEAVES:12)
Block(13,17,11,LEAVES:12)
Block(13,17,12,LEAVES:12)
Block(13,17,15,LEAVES:12)
Block(13,18,-3,LEAVES:12)
Block(13,18,-1,LEAVES:12)
Block(13,18,0,LEAVES:12)
Block(13,18,12,LEAVES:12)
Block(13,19,11,LEAVES:12)
Block(14,5,3,LEAVES:12)
Block(14,6,-1,LEAVES:12)
Block(14,6,0,LEAVES:12)
Block(14,6,3,LEAVES:12)
Block(14,7,0,LEAVES:12)
Block(14,8,0,LEAVES:12)
Block(14,9,-4,LEAVES:12)
Block(14,9,-3,LEAVES:12)
Block(14,10,2,LEAVES:12)
Block(14,10,3,LEAVES:12)
Block(14,10,4,LEAVES:12)
Block(14,11,-2,LEAVES:12)
Block(14,11,-1,LEAVES:12)
Block(14,11,3,LEAVES:12)
Block(14,11,13,LEAVES:12)
Block(14,12,1,LEAVES:12)
Block(14,12,3,LEAVES:12)
Block(14,12,11,LEAVES:12)
Block(14,12,13,LEAVES:12)
Block(14,13,-1,LEAVES:12)
Block(14,13,0,LEAVES:12)
Block(14,13,3,LEAVES:12)
Block(14,13,11,LEAVES:12)
Block(14,13,13,LEAVES:12)
Block(14,13,15,LEAVES:12)
Block(14,14,0,LEAVES:12)
Block(14,14,9,LEAVES:12)
Block(14,14,11,LEAVES:12)
Block(14,14,12,LEAVES:12)
Block(14,14,13,LEAVES:12)
Block(14,14,15,LEAVES:12)
Block(14,15,0,LEAVES:12)
Block(14,15,7,LEAVES:12)
Block(14,15,9,LEAVES:12)
Block(14,15,11,LEAVES:12)
Block(14,15,12,LEAVES:12)
Block(14,15,16,LEAVES:12)
Block(14,16,-4,LEAVES:12)
Block(14,16,-3,LEAVES:12)
Block(14,16,11,LEAVES:12)
Block(14,17,2,LEAVES:12)
Block(14,17,3,LEAVES:12)
Block(14,17,4,LEAVES:12)
Block(14,18,-2,LEAVES:12)
Block(14,18,-1,LEAVES:12)
Block(14,18,3,LEAVES:12)
Block(14,18,12,LEAVES:12)
Block(14,18,13,LEAVES:12)
Block(14,19,1,LEAVES:12)
Block(14,19,13,LEAVES:12)
Block(14,19,14,LEAVES:12)
Block(14,20,13,LEAVES:12)
Block(15,5,-2,LEAVES:12)
Block(15,5,-1,LEAVES:12)
Block(15,6,-1,LEAVES:12)
Block(15,8,-1,LEAVES:12)
Block(15,8,0,LEAVES:12)
Block(15,9,0,LEAVES:12)
Block(15,10,3,LEAVES:12)
Block(15,11,-2,LEAVES:12)
Block(15,11,10,LEAVES:12)
Block(15,12,-2,LEAVES:12)
Block(15,12,-1,LEAVES:12)
Block(15,12,14,LEAVES:12)
Block(15,13,-1,LEAVES:12)
Block(15,13,11,LEAVES:12)
Block(15,13,13,LEAVES:12)
Block(15,13,14,LEAVES:12)
Block(15,15,-1,LEAVES:12)
Block(15,15,0,LEAVES:12)
Block(15,15,8,LEAVES:12)
Block(15,15,9,LEAVES:12)
Block(15,15,12,LEAVES:12)
Block(15,15,13,LEAVES:12)
Block(15,16,0,LEAVES:12)
Block(15,16,11,LEAVES:12)
Block(15,16,13,LEAVES:12)
Block(15,17,3,LEAVES:12)
Block(15,17,8,LEAVES:12)
Block(15,17,10,LEAVES:12)
Block(15,17,11,LEAVES:12)
Block(15,18,-2,LEAVES:12)
Block(15,19,-2,LEAVES:12)
Block(16,5,-2,LEAVES:12)
Block(16,7,1,LEAVES:12)
Block(16,8,0,LEAVES:12)
Block(16,8,1,LEAVES:12)
Block(16,11,14,LEAVES:12)
Block(16,12,-2,LEAVES:12)
Block(16,12,10,LEAVES:12)
Block(16,12,11,LEAVES:12)
Block(16,12,14,LEAVES:12)
Block(16,13,11,LEAVES:12)
Block(16,14,1,LEAVES:12)
Block(16,14,11,LEAVES:12)
Block(16,15,0,LEAVES:12)
Block(16,15,1,LEAVES:12)
Block(16,15,7,LEAVES:12)
Block(16,15,8,LEAVES:12)
Block(16,16,13,LEAVES:12)
Block(16,16,14,LEAVES:12)
Block(16,16,15,LEAVES:12)
Block(16,17,9,LEAVES:12)
Block(16,17,10,LEAVES:12)
Block(16,17,14,LEAVES:12)
Block(16,18,12,LEAVES:12)
Block(17,7,1,LEAVES:12)
Block(17,11,9,LEAVES:12)
Block(17,11,10,LEAVES:12)
Block(17,12,10,LEAVES:12)
Block(17,14,1,LEAVES:12)
Block(17,14,10,LEAVES:12)
Block(17,14,11,LEAVES:12)
Block(17,15,11,LEAVES:12)
Block(17,16,14,LEAVES:12)
Block(17,17,9,LEAVES:12)
Block(17,18,9,LEAVES:12)
Block(18,11,9,LEAVES:12)
Block(18,13,12,LEAVES:12)
Block(18,14,11,LEAVES:12)
Block(18,14,12,LEAVES:12)
Block(19,13,12,LEAVES:12)


#######################################################################
# +-----------------------------------------------------------------+ #
# |                             Entities                            | #
# +-----------------------------------------------------------------+ #
#######################################################################

# Entity() spawns an entity instead of a block. The entity is spawned only once when the BO3 is spawned.
# Entities are persistent by default so they don't de-spawn when no player is near, they are only unloaded.
# Usage: Entity(x,y,z,mobName,groupSize,NameTagOrNBTFileName) or Entity(x,y,z,mobName,groupSize)
# Use /tc entities or /otg entities to get a list of entities that can be used as mobName, this includes entities added by other mods.
# NameTagOrNBTFileName can be either a nametag for the mob or an nbt file (such as mymobinfo.nbt or mymobinfo.txt).
# When using a text file you can use the same mob spawning parameters used with the /summon command to equip the
# entity and give it custom attributes etc. You can copy the DATA part of a summon command including surrounding
# curly braces to a .txt file, for instance for: "/summon Skeleton x y z {DATA}"

#######################################################################
# +-----------------------------------------------------------------+ #
# |                            BO3 checks                           | #
# +-----------------------------------------------------------------+ #
#######################################################################

# Require a condition at a certain location in order for the BO3 to be spawned.
# BlockCheck(x,y,z,BlockName[,BlockName[,...]]) - one of the blocks must be at the location
# BlockCheckNot(x,y,z,BlockName[,BlockName[,...]]) - all the blocks must not be at the location
# LightCheck(x,y,z,minLightLevel,maxLightLevel) - light must be between min and max (inclusive)

# You can use "Solid" as a BlockName for matching all solid blocks or "All" to match all blocks that aren't air.

# Examples:
BlockCheck(0,-1,0,GRASS,DIRT,DIRT:2,SAND)
#   BlockCheck(0,-1,0,Solid)       Require any solid block just below the object
#   BlockCheck(0,-1,0,WOOL)        Require any type of wool just below the object
#   BlockCheck(0,-1,0,WOOL:0)      Require white wool just below the object
#   BlockCheckNot(0,-1,0,WOOL:0)   Require that there is no white wool below the object
#   LightCheck(0,0,0,0,1)          Require almost complete darkness just below the object

