#######################################################################
# +-----------------------------------------------------------------+ #
# |                            BO3 object                           | #
# +-----------------------------------------------------------------+ #
#######################################################################

# The descriptions in this file are accurate only for TerrainControl and OTG.
# For MCW and OTG+ these descriptions are only accurate if the BO3 is used as a CustomObject.
# MCW and OTG+ completely reimplemented CustomStructure, check the MCW/OTG+ documentation for more information.

# This is the config file of a custom object.
# If you add this object correctly to your BiomeConfigs, it will spawn in the world.

# This is the creator of this BO3 object
Author: Unknown

# A short description of this BO3 object
Description: This BO3 was converted from a schematic using OTGEdit. The author and description information of the schematic could not be found. If you know who the author of the schematic is then please add this information.

# The BO3 version, don't change this! It can be used by external applications to do a version check.
Version: 3

# The settings mode, WriteAll, WriteWithoutComments or WriteDisable. See WorldConfig.
SettingsMode: WriteDisable

#######################################################################
# +-----------------------------------------------------------------+ #
# |                          Main settings                          | #
# +-----------------------------------------------------------------+ #
#######################################################################

# This needs to be set to true to spawn the object in the Tree and Sapling resources.
Tree: true

# The frequency of the BO3 from 1 to 200. Tries this many times to spawn this BO3 when using the CustomObject(...) resource.
# Ignored by Tree(..), Sapling(..) and CustomStructure(..)
Frequency: 40

# The rarity of the BO3 from 0 to 100. Each spawn attempt has rarity% chance to succeed when using the CustomObject(...) resource.
# Ignored by Tree(..), Sapling(..) and CustomStructure(..)
Rarity: 100.0

# If you set this to true, the BO3 will be placed with a random rotation.
RotateRandomly: true

# The spawn height of the BO3 - randomY, highestBlock or highestSolidBlock.
SpawnHeight: highestSolidBlock
SpawnHeightOffset: -2
# The height limits for the BO3.
MinHeight: 0

MaxHeight: 69

# Objects can have other objects attached to it: branches. Branches can also
# have branches attached to it, which can also have branches, etc. This is the
# maximum branch depth for this objects.
MaxBranchDepth: 10

# When spawned with the UseWorld keyword, this BO3 should NOT spawn in the following biomes.
# If you writer.write the BO3 name directly in the BiomeConfigs, this will be ignored.
ExcludedBiomes: All

# To optimise this BO3 for faster loading times you can use Notepad++ to find/replace comments and abbreviate things.
# Notepad++ find/replace with regex:
# Find: ^[#;].* replace to nothing removes all lines starting with # 
# Find: ^\s*$ replace to nothing removes most empty lines 
# Notepad++ find/replace without regex:
# *Warning: This will only work for OTG 1.10.2 v21 / OTG 1.11.2 v6 or higher. B( is not recognised by lower versions.
# Find: Block( replace to B(

#######################################################################
# +-----------------------------------------------------------------+ #
# |                      Source block settings                      | #
# +-----------------------------------------------------------------+ #
#######################################################################

# The block(s) the BO3 should spawn in.
SourceBlocks: AIR,GRASS,DIRT

# The maximum percentage of the BO3 that can be outside the SourceBlock.
# The BO3 won't be placed on a location with more blocks outside the SourceBlock than this percentage.
MaxPercentageOutsideSourceBlock: 0

# What to do when a block is about to be placed outside the SourceBlock? (dontPlace, placeAnyway)
OutsideSourceBlock: dontPlace

#######################################################################
# +-----------------------------------------------------------------+ #
# |                              Blocks                             | #
# +-----------------------------------------------------------------+ #
#######################################################################

# All the blocks used in the BO3 are listed here. Possible blocks:
# Block(x,y,z,id[.data][,nbtfile.nbt) or B(x,y,z,id[.data][,nbtfile.nbt)
# RandomBlock(x,y,z,id[:data][,nbtfile.nbt],chance[,id[:data][,nbtfile.nbt],chance[,...]])
# So RandomBlock(0,0,0,CHEST,chest.nbt,50,CHEST,anotherchest.nbt,100) will spawn a chest at
# the BO3 origin, and give it a 50% chance to have the contents of chest.nbt, or, if that
# fails, a 100% percent chance to have the contents of anotherchest.nbt.

Block(-3,28,7,LEAVES:15)
Block(-3,29,7,LEAVES:15)
Block(-3,29,8,LEAVES:15)
Block(-2,25,19,LEAVES:15)
Block(-2,25,20,LEAVES:15)
Block(-2,29,7,LEAVES:15)
Block(-2,29,8,LEAVES:15)
Block(-2,29,9,LEAVES:15)
Block(-2,30,8,LEAVES:15)
Block(-2,36,16,LEAVES:15)
Block(-1,25,18,LEAVES:15)
Block(-1,25,19,LEAVES:15)
Block(-1,25,20,LEAVES:15)
Block(-1,29,22,LEAVES:15)
Block(-1,30,8,LEAVES:15)
Block(-1,30,9,LEAVES:15)
Block(-1,30,10,LEAVES:15)
Block(-1,35,16,LEAVES:15)
Block(-1,36,15,LEAVES:15)
Block(-1,36,16,LEAVES:15)
Block(-1,36,17,LEAVES:15)
Block(0,25,18,LEAVES:15)
Block(0,25,19,LEAVES:15)
Block(0,26,17,LEAVES:15)
Block(0,29,10,LEAVES:15)
Block(0,29,11,LEAVES:15)
Block(0,29,22,LEAVES:15)
Block(0,29,23,LEAVES:15)
Block(0,30,8,LEAVES:15)
Block(0,30,9,LEAVES:15)
Block(0,30,10,LEAVES:15)
Block(0,30,21,LEAVES:15)
Block(0,35,15,LEAVES:15)
Block(0,35,16,LEAVES:15)
Block(0,35,17,LEAVES:15)
Block(1,25,18,LEAVES:15)
Block(1,26,16,LEAVES:15)
Block(1,26,17,LEAVES:15)
Block(1,26,18,LEAVES:15)
Block(1,29,10,LEAVES:15)
Block(1,29,11,LEAVES:15)
Block(1,29,12,LEAVES:15)
Block(1,29,23,LEAVES:15)
Block(1,30,9,LEAVES:15)
Block(1,30,10,LEAVES:15)
Block(1,30,19,LEAVES:15)
Block(1,30,20,LEAVES:15)
Block(1,30,21,LEAVES:15)
Block(1,30,22,LEAVES:15)
Block(1,34,15,LEAVES:15)
Block(1,35,14,LEAVES:15)
Block(1,35,15,LEAVES:15)
Block(1,35,16,LEAVES:15)
Block(2,26,3,LEAVES:15)
Block(2,26,4,LEAVES:15)
Block(2,26,15,LEAVES:15)
Block(2,26,16,LEAVES:15)
Block(2,26,17,LEAVES:15)
Block(2,26,18,LEAVES:15)
Block(2,27,5,LEAVES:15)
Block(2,27,6,LEAVES:15)
Block(2,28,12,LEAVES:15)
Block(2,28,13,LEAVES:15)
Block(2,29,10,LEAVES:15)
Block(2,29,11,LEAVES:15)
Block(2,29,12,LEAVES:15)
Block(2,29,19,LEAVES:15)
Block(2,30,18,LEAVES:15)
Block(2,30,19,LEAVES:15)
Block(2,30,20,LEAVES:15)
Block(2,30,21,LEAVES:15)
Block(2,33,14,LEAVES:15)
Block(2,34,14,LEAVES:15)
Block(2,34,15,LEAVES:15)
Block(2,34,16,LEAVES:15)
Block(2,35,9,LEAVES:15)
Block(2,35,14,LEAVES:15)
Block(2,36,7,LEAVES:15)
Block(2,36,8,LEAVES:15)
Block(3,25,15,LEAVES:15)
Block(3,25,16,LEAVES:15)
Block(3,26,2,LEAVES:15)
Block(3,26,3,LEAVES:15)
Block(3,26,4,LEAVES:15)
Block(3,26,15,LEAVES:15)
Block(3,26,16,LEAVES:15)
Block(3,26,17,LEAVES:15)
Block(3,27,4,LEAVES:15)
Block(3,27,5,LEAVES:15)
Block(3,27,6,LEAVES:15)
Block(3,27,7,LEAVES:15)
Block(3,27,8,LEAVES:15)
Block(3,27,12,LEAVES:15)
Block(3,28,12,LEAVES:15)
Block(3,29,11,LEAVES:15)
Block(3,29,17,LEAVES:15)
Block(3,29,18,LEAVES:15)
Block(3,30,18,LEAVES:15)
Block(3,30,19,LEAVES:15)
Block(3,30,20,LEAVES:15)
Block(3,32,14,LEAVES:15)
Block(3,32,15,LEAVES:15)
Block(3,33,14,LEAVES:15)
Block(3,33,15,LEAVES:15)
Block(3,34,10,LEAVES:15)
Block(3,35,9,LEAVES:15)
Block(3,36,7,LEAVES:15)
Block(3,36,8,LEAVES:15)
Block(3,36,9,LEAVES:15)
Block(4,24,12,LEAVES:15)
Block(4,24,14,LEAVES:15)
Block(4,25,14,LEAVES:15)
Block(4,25,15,LEAVES:15)
Block(4,26,3,LEAVES:15)
Block(4,26,4,LEAVES:15)
Block(4,26,13,LEAVES:15)
Block(4,27,4,LEAVES:15)
Block(4,27,5,LEAVES:15)
Block(4,27,6,LEAVES:15)
Block(4,27,7,LEAVES:15)
Block(4,27,8,LEAVES:15)
Block(4,27,9,LEAVES:15)
Block(4,27,13,LEAVES:15)
Block(4,27,15,LEAVES:15)
Block(4,28,12,LEAVES:15)
Block(4,28,15,LEAVES:15)
Block(4,28,16,LEAVES:15)
Block(4,29,14,LEAVES:15)
Block(4,29,16,LEAVES:15)
Block(4,29,17,LEAVES:15)
Block(4,30,14,LEAVES:15)
Block(4,30,19,LEAVES:15)
Block(4,31,12,LEAVES:15)
Block(4,31,14,LEAVES:15)
Block(4,31,15,LEAVES:15)
Block(4,32,12,LEAVES:15)
Block(4,32,14,LEAVES:15)
Block(4,33,10,LEAVES:15)
Block(4,33,11,LEAVES:15)
Block(4,34,10,LEAVES:15)
Block(4,35,8,LEAVES:15)
Block(4,35,9,LEAVES:15)
Block(4,35,10,LEAVES:15)
Block(5,0,13,162:12)
Block(5,0,14,162:12)
Block(5,1,13,162:12)
Block(5,1,14,162:12)
Block(5,2,13,162:12)
Block(5,2,14,162:12)
Block(5,3,13,162:12)
Block(5,3,14,162:12)
Block(5,4,13,162:12)
Block(5,4,14,162:12)
Block(5,5,13,162:12)
Block(5,6,13,162:12)
Block(5,7,13,162:12)
Block(5,8,13,162:12)
Block(5,9,13,162:12)
Block(5,10,13,162:12)
Block(5,22,12,LEAVES:15)
Block(5,22,13,LEAVES:15)
Block(5,23,12,LEAVES:15)
Block(5,23,13,LEAVES:15)
Block(5,23,14,LEAVES:15)
Block(5,24,11,LEAVES:15)
Block(5,24,12,LEAVES:15)
Block(5,24,14,LEAVES:15)
Block(5,24,15,LEAVES:15)
Block(5,25,11,LEAVES:15)
Block(5,25,12,LEAVES:15)
Block(5,25,13,LEAVES:15)
Block(5,25,14,LEAVES:15)
Block(5,26,10,LEAVES:15)
Block(5,26,11,LEAVES:15)
Block(5,26,13,LEAVES:15)
Block(5,26,14,LEAVES:15)
Block(5,26,17,LEAVES:15)
Block(5,27,6,LEAVES:15)
Block(5,27,7,LEAVES:15)
Block(5,27,8,LEAVES:15)
Block(5,27,9,LEAVES:15)
Block(5,27,10,LEAVES:15)
Block(5,27,14,LEAVES:15)
Block(5,27,15,LEAVES:15)
Block(5,27,19,LEAVES:15)
Block(5,27,20,LEAVES:15)
Block(5,28,13,LEAVES:15)
Block(5,28,14,LEAVES:15)
Block(5,29,12,LEAVES:15)
Block(5,29,14,LEAVES:15)
Block(5,30,12,LEAVES:15)
Block(5,31,11,LEAVES:15)
Block(5,31,12,LEAVES:15)
Block(5,32,11,LEAVES:15)
Block(5,33,10,LEAVES:15)
Block(5,33,11,LEAVES:15)
Block(5,34,10,LEAVES:15)
Block(6,0,12,162:12)
Block(6,0,13,162:12)
Block(6,0,14,162:12)
Block(6,1,12,162:12)
Block(6,1,13,162:12)
Block(6,1,14,162:12)
Block(6,2,12,162:12)
Block(6,2,13,162:12)
Block(6,2,14,162:12)
Block(6,3,12,162:12)
Block(6,3,13,162:12)
Block(6,3,14,162:12)
Block(6,4,12,162:12)
Block(6,4,13,162:12)
Block(6,4,14,162:12)
Block(6,5,12,162:12)
Block(6,5,13,162:12)
Block(6,5,14,162:12)
Block(6,6,12,162:12)
Block(6,6,13,162:12)
Block(6,6,14,162:12)
Block(6,7,12,162:12)
Block(6,7,13,162:12)
Block(6,7,14,162:12)
Block(6,8,13,162:12)
Block(6,8,14,162:12)
Block(6,9,13,162:12)
Block(6,9,14,162:12)
Block(6,10,13,162:12)
Block(6,10,14,162:12)
Block(6,11,13,162:12)
Block(6,11,14,162:12)
Block(6,12,13,162:12)
Block(6,12,14,162:12)
Block(6,13,13,162:12)
Block(6,13,14,162:12)
Block(6,14,13,162:12)
Block(6,15,13,162:12)
Block(6,16,13,162:12)
Block(6,17,13,162:12)
Block(6,18,13,162:12)
Block(6,19,13,162:12)
Block(6,20,13,162:12)
Block(6,21,12,LEAVES:15)
Block(6,21,13,162:12)
Block(6,21,14,LEAVES:15)
Block(6,22,12,LEAVES:15)
Block(6,22,13,162:12)
Block(6,22,14,LEAVES:15)
Block(6,23,12,LEAVES:15)
Block(6,23,13,162:12)
Block(6,23,14,LEAVES:15)
Block(6,24,11,LEAVES:15)
Block(6,24,12,LEAVES:15)
Block(6,24,13,LEAVES:15)
Block(6,24,14,LEAVES:15)
Block(6,25,12,LEAVES:15)
Block(6,25,13,LEAVES:15)
Block(6,25,14,LEAVES:15)
Block(6,25,15,LEAVES:15)
Block(6,26,12,LEAVES:15)
Block(6,26,13,LEAVES:15)
Block(6,26,14,LEAVES:15)
Block(6,26,15,LEAVES:15)
Block(6,26,16,LEAVES:15)
Block(6,26,17,LEAVES:15)
Block(6,26,22,LEAVES:15)
Block(6,27,8,LEAVES:15)
Block(6,27,9,LEAVES:15)
Block(6,27,12,LEAVES:15)
Block(6,27,14,LEAVES:15)
Block(6,27,15,LEAVES:15)
Block(6,27,17,LEAVES:15)
Block(6,27,18,LEAVES:15)
Block(6,27,19,LEAVES:15)
Block(6,27,20,LEAVES:15)
Block(6,27,21,LEAVES:15)
Block(6,28,12,LEAVES:15)
Block(6,28,15,LEAVES:15)
Block(6,29,12,LEAVES:15)
Block(6,29,15,LEAVES:15)
Block(6,30,11,LEAVES:15)
Block(6,31,11,LEAVES:15)
Block(6,32,11,LEAVES:15)
Block(7,0,12,162:12)
Block(7,0,13,162:12)
Block(7,1,12,162:12)
Block(7,1,13,162:12)
Block(7,2,13,162:12)
Block(7,3,13,162:12)
Block(7,4,13,162:12)
Block(7,5,13,162:12)
Block(7,6,13,162:12)
Block(7,22,13,LEAVES:15)
Block(7,23,13,LEAVES:15)
Block(7,23,14,LEAVES:15)
Block(7,24,12,LEAVES:15)
Block(7,24,13,LEAVES:15)
Block(7,24,14,LEAVES:15)
Block(7,25,12,LEAVES:15)
Block(7,25,13,LEAVES:15)
Block(7,25,14,LEAVES:15)
Block(7,25,15,LEAVES:15)
Block(7,25,23,LEAVES:15)
Block(7,26,12,LEAVES:15)
Block(7,26,14,LEAVES:15)
Block(7,26,15,LEAVES:15)
Block(7,26,21,LEAVES:15)
Block(7,26,22,LEAVES:15)
Block(7,27,11,LEAVES:15)
Block(7,27,12,LEAVES:15)
Block(7,27,14,LEAVES:15)
Block(7,27,18,LEAVES:15)
Block(7,27,20,LEAVES:15)
Block(7,27,21,LEAVES:15)
Block(7,28,11,LEAVES:15)
Block(7,28,14,LEAVES:15)
Block(7,28,15,LEAVES:15)
Block(7,29,14,LEAVES:15)
Block(7,29,15,LEAVES:15)
Block(7,30,15,LEAVES:15)
Block(7,30,16,LEAVES:15)
Block(7,31,15,LEAVES:15)
Block(8,24,13,LEAVES:15)
Block(8,25,11,LEAVES:15)
Block(8,25,14,LEAVES:15)
Block(8,25,23,LEAVES:15)
Block(8,26,11,LEAVES:15)
Block(8,26,14,LEAVES:15)
Block(8,26,22,LEAVES:15)
Block(8,26,23,LEAVES:15)
Block(8,27,12,LEAVES:15)
Block(8,27,14,LEAVES:15)
Block(8,28,11,LEAVES:15)
Block(8,28,12,LEAVES:15)
Block(8,28,14,LEAVES:15)
Block(8,29,10,LEAVES:15)
Block(8,29,11,LEAVES:15)
Block(8,29,15,LEAVES:15)
Block(8,30,10,LEAVES:15)
Block(8,30,15,LEAVES:15)
Block(8,31,15,LEAVES:15)
Block(8,31,16,LEAVES:15)
Block(8,32,15,LEAVES:15)
Block(8,32,16,LEAVES:15)
Block(8,32,17,LEAVES:15)
Block(9,26,10,LEAVES:15)
Block(9,26,13,LEAVES:15)
Block(9,26,14,LEAVES:15)
Block(9,27,15,LEAVES:15)
Block(9,29,11,LEAVES:15)
Block(9,30,9,LEAVES:15)
Block(9,30,10,LEAVES:15)
Block(9,30,11,LEAVES:15)
Block(9,30,15,LEAVES:15)
Block(9,31,9,LEAVES:15)
Block(9,31,10,LEAVES:15)
Block(9,31,15,LEAVES:15)
Block(9,32,16,LEAVES:15)
Block(9,33,16,LEAVES:15)
Block(9,33,17,LEAVES:15)
Block(10,26,9,LEAVES:15)
Block(10,26,10,LEAVES:15)
Block(10,26,14,LEAVES:15)
Block(10,27,14,LEAVES:15)
Block(10,27,15,LEAVES:15)
Block(10,28,16,LEAVES:15)
Block(10,30,10,LEAVES:15)
Block(10,31,8,LEAVES:15)
Block(10,31,9,LEAVES:15)
Block(10,33,16,LEAVES:15)
Block(10,33,17,LEAVES:15)
Block(10,33,18,LEAVES:15)
Block(11,25,8,LEAVES:15)
Block(11,25,9,LEAVES:15)
Block(11,26,9,LEAVES:15)
Block(11,26,10,LEAVES:15)
Block(11,27,14,LEAVES:15)
Block(11,27,15,LEAVES:15)
Block(11,28,15,LEAVES:15)
Block(11,28,16,LEAVES:15)
Block(11,28,17,LEAVES:15)
Block(11,31,7,LEAVES:15)
Block(11,31,8,LEAVES:15)
Block(11,31,9,LEAVES:15)
Block(11,33,17,LEAVES:15)
Block(12,25,7,LEAVES:15)
Block(12,25,8,LEAVES:15)
Block(12,25,9,LEAVES:15)
Block(12,25,10,LEAVES:15)
Block(12,28,15,LEAVES:15)
Block(12,28,16,LEAVES:15)
Block(12,28,17,LEAVES:15)
Block(12,30,6,LEAVES:15)
Block(12,30,7,LEAVES:15)
Block(12,31,7,LEAVES:15)
Block(12,31,8,LEAVES:15)
Block(13,24,6,LEAVES:15)
Block(13,24,7,LEAVES:15)
Block(13,25,7,LEAVES:15)
Block(13,25,8,LEAVES:15)
Block(13,25,9,LEAVES:15)
Block(13,27,17,LEAVES:15)
Block(13,27,18,LEAVES:15)
Block(13,28,16,LEAVES:15)
Block(13,28,17,LEAVES:15)
Block(13,28,18,LEAVES:15)
Block(13,30,6,LEAVES:15)
Block(13,30,7,LEAVES:15)
Block(14,24,5,LEAVES:15)
Block(14,24,6,LEAVES:15)
Block(14,24,7,LEAVES:15)
Block(14,24,8,LEAVES:15)
Block(14,25,7,LEAVES:15)
Block(14,27,18,LEAVES:15)
Block(14,27,19,LEAVES:15)
Block(14,28,17,LEAVES:15)
Block(15,24,6,LEAVES:15)
Block(15,24,7,LEAVES:15)
Block(15,27,18,LEAVES:15)


#######################################################################
# +-----------------------------------------------------------------+ #
# |                             Entities                            | #
# +-----------------------------------------------------------------+ #
#######################################################################

# Entity() spawns an entity instead of a block. The entity is spawned only once when the BO3 is spawned.
# Entities are persistent by default so they don't de-spawn when no player is near, they are only unloaded.
# Usage: Entity(x,y,z,mobName,groupSize,NameTagOrNBTFileName) or Entity(x,y,z,mobName,groupSize)
# Use /tc entities or /otg entities to get a list of entities that can be used as mobName, this includes entities added by other mods.
# NameTagOrNBTFileName can be either a nametag for the mob or an nbt file (such as mymobinfo.nbt or mymobinfo.txt).
# When using a text file you can use the same mob spawning parameters used with the /summon command to equip the
# entity and give it custom attributes etc. You can copy the DATA part of a summon command including surrounding
# curly braces to a .txt file, for instance for: "/summon Skeleton x y z {DATA}"

#######################################################################
# +-----------------------------------------------------------------+ #
# |                            BO3 checks                           | #
# +-----------------------------------------------------------------+ #
#######################################################################

# Require a condition at a certain location in order for the BO3 to be spawned.
# BlockCheck(x,y,z,BlockName[,BlockName[,...]]) - one of the blocks must be at the location
# BlockCheckNot(x,y,z,BlockName[,BlockName[,...]]) - all the blocks must not be at the location
# LightCheck(x,y,z,minLightLevel,maxLightLevel) - light must be between min and max (inclusive)

# You can use "Solid" as a BlockName for matching all solid blocks or "All" to match all blocks that aren't air.

# Examples:
BlockCheck(0,-1,0,GRASS,DIRT,DIRT:2,SAND,STONE)
#   BlockCheck(0,-1,0,Solid)       Require any solid block just below the object
#   BlockCheck(0,-1,0,WOOL)        Require any type of wool just below the object
#   BlockCheck(0,-1,0,WOOL:0)      Require white wool just below the object
#   BlockCheckNot(0,-1,0,WOOL:0)   Require that there is no white wool below the object
#   LightCheck(0,0,0,0,1)          Require almost complete darkness just below the object

