s#######################################################################
# +-----------------------------------------------------------------+ #
# |                            BO3 object                           | #
# +-----------------------------------------------------------------+ #
#######################################################################

# This is the config file of a custom object.
# If you add this object correctly to your BiomeConfigs, it will spawn in the world.

# This is the creator of this BO3 object
Author: BO3 BulkEdit (by LanToaster)

# A short description of this BO3 object
Description: This Object was Created with BO3_BulkEdit

# The BO3 version, don't change this! It can be used by external applications to do a version check.
Version: 3

# The settings mode, WriteAll, WriteWithoutComments or WriteDisable. See WorldConfig.
SettingsMode: WriteDisable


#######################################################################
# +-----------------------------------------------------------------+ #
# |                          Main settings                          | #
# +-----------------------------------------------------------------+ #
#######################################################################

# This needs to be set to true to spawn the object in the Tree and Sapling resources.
Tree: true

# The frequency of the BO3 from 1 to 200. Tries this many times to spawn this BO3 when using the CustomObject(...) resource.
# Ignored by Tree(..), Sapling(..) and CustomStructure(..)
Frequency: 1

# The rarity of the BO3 from 0 to 100. Each spawn attempt has rarity% chance to succeed when using the CustomObject(...) resource.
# Ignored by Tree(..), Sapling(..) and CustomStructure(..)
Rarity: 100.0

# If you set this to true, the BO3 will be placed with a random rotation.
RotateRandomly: true

# The spawn height of the BO3 - randomY, highestBlock or highestSolidBlock.
SpawnHeight: highestSolidBlock

# The height limits for the BO3.
MinHeight: 0

MaxHeight: 68

# Objects can have other objects attacthed to it: branches. Branches can also
# have branches attached to it, which can also have branches, etc. This is the
# maximum branch depth for this objects.
MaxBranchDepth: 10

# When spawned with the UseWorld keyword, this BO3 should NOT spawn in the following biomes.
# If you writer.write the BO3 name directly in the BiomeConfigs, this will be ignored.
ExcludedBiomes: All


#######################################################################
# +-----------------------------------------------------------------+ #
# |                      Source block settings                      | #
# +-----------------------------------------------------------------+ #
#######################################################################

# The block(s) the BO3 should spawn in.
SourceBlocks: AIR

# The maximum percentage of the BO3 that can be outside the SourceBlock.
# The BO3 won't be placed on a location with more blocks outside the SourceBlock than this percentage.
MaxPercentageOutsideSourceBlock: 0

# What to do when a block is about to be placed outside the SourceBlock? (dontPlace, placeAnyway)
OutsideSourceBlock: dontPlace


#######################################################################
# +-----------------------------------------------------------------+ #
# |                              Blocks                             | #
# +-----------------------------------------------------------------+ #
#######################################################################

# All the blocks used in the BO3 are listed here. Possible blocks:
# Block(x,y,z,id[.data][,nbtfile.nbt)
# RandomBlock(x,y,z,id[:data][,nbtfile.nbt],chance[,id[:data][,nbtfile.nbt],chance[,...]])
# So RandomBlock(0,0,0,CHEST,chest.nbt,50,CHEST,anotherchest.nbt,100) will spawn a chest at
# the BO3 origin, and give it a 50% chance to have the contents of chest.nbt, or, if that
# fails, a 100% percent chance to have the contents of anotherchest.nbt.
Block(3,0,-1,LOG2:12)
Block(4,0,-1,LOG2:12)
Block(4,0,0,LOG2:12)
Block(0,0,1,LOG2:12)
Block(1,0,1,LOG2:12)
Block(3,0,2,LOG2:12)
Block(3,1,-1,LOG2:12)
Block(4,1,-1,LOG2:12)
Block(4,1,0,LOG2:12)
Block(0,1,1,LOG2:12)
Block(1,1,1,LOG2:12)
Block(3,1,2,LOG2:12)
Block(3,2,-1,LOG2:12)
Block(4,2,-1,LOG2:12)
Block(4,2,0,LOG2:12)
Block(0,2,1,LOG2:12)
Block(1,2,1,LOG2:12)
Block(3,2,2,LOG2:12)
Block(3,3,-1,LOG2:12)
Block(4,3,-1,LOG2:12)
Block(4,3,0,LOG2:12)
Block(0,3,1,LOG2:12)
Block(1,3,1,LOG2:12)
Block(3,3,2,LOG2:12)
Block(3,4,-2,LOG2:12)
Block(3,4,-1,LOG2:12)
Block(4,4,-1,LOG2:12)
Block(4,4,0,LOG2:12)
Block(0,4,1,LOG2:12)
Block(1,4,1,LOG2:12)
Block(3,4,2,LOG2:12)
Block(3,5,-2,LOG2:12)
Block(4,5,-1,LOG2:12)
Block(5,5,-1,LOG2:12)
Block(4,5,0,LOG2:12)
Block(0,5,1,LOG2:12)
Block(1,5,1,LOG2:12)
Block(3,5,2,LOG2:12)
Block(4,5,2,LOG2:12)
Block(3,6,-2,LOG2:12)
Block(5,6,-1,LOG2:12)
Block(3,6,0,LOG2:12)
Block(4,6,0,LOG2:12)
Block(0,6,1,LOG2:12)
Block(1,6,1,LOG2:12)
Block(1,6,2,LOG2:12)
Block(4,6,2,LOG2:12)
Block(3,7,-2,LOG2:12)
Block(5,7,-1,LOG2:12)
Block(3,7,0,LOG2:12)
Block(0,7,1,LOG2:12)
Block(1,7,2,LOG2:12)
Block(4,7,2,LOG2:12)
Block(2,8,-3,LOG2:12)
Block(3,8,-3,LOG2:12)
Block(3,8,-2,LOG2:12)
Block(5,8,-2,LOG2:12)
Block(5,8,-1,LOG2:12)
Block(3,8,0,LOG2:12)
Block(-1,8,1,LOG2:12)
Block(0,8,1,LOG2:12)
Block(1,8,2,LOG2:12)
Block(4,8,2,LOG2:12)
Block(2,9,-3,LOG2:12)
Block(5,9,-2,LOG2:12)
Block(3,9,0,LOG2:12)
Block(-1,9,1,LOG2:12)
Block(1,9,2,LOG2:12)
Block(4,9,2,LOG2:12)
Block(1,9,3,LOG2:12)
Block(4,9,3,LOG2:12)
Block(5,9,3,LOG2:12)
Block(2,10,-4,LOG2:12)
Block(2,10,-3,LOG2:12)
Block(5,10,-2,LOG2:12)
Block(6,10,-2,LOG2:12)
Block(2,10,0,LOG2:12)
Block(3,10,0,LOG2:12)
Block(-1,10,1,LOG2:12)
Block(1,10,3,LOG2:12)
Block(5,10,3,LOG2:12)
Block(3,11,-11,LEAVES:12)
Block(2,11,-5,LEAVES:12)
Block(2,11,-4,LOG2:12)
Block(6,11,-2,LOG2:12)
Block(2,11,0,LOG2:12)
Block(-1,11,1,LOG2:12)
Block(1,11,3,LOG2:12)
Block(5,11,3,LOG2:12)
Block(3,12,-11,LEAVES:12)
Block(2,12,-10,LEAVES:12)
Block(3,12,-10,LEAVES:12)
Block(13,12,-8,LEAVES:12)
Block(-5,12,-6,LEAVES:12)
Block(-4,12,-6,LEAVES:12)
Block(2,12,-6,LEAVES:12)
Block(1,12,-5,LOG2:12)
Block(2,12,-5,LOG2:12)
Block(2,12,-4,LOG2:12)
Block(6,12,-3,LOG2:12)
Block(7,12,-3,LOG2:12)
Block(6,12,-2,LOG2:12)
Block(12,12,-2,LEAVES:12)
Block(2,12,0,LOG2:12)
Block(-2,12,1,LOG2:12)
Block(-1,12,1,LOG2:12)
Block(1,12,3,LOG2:12)
Block(5,12,3,LOG2:12)
Block(5,12,4,LOG2:12)
Block(6,12,4,LOG2:12)
Block(-4,13,-12,LEAVES:12)
Block(-4,13,-11,LEAVES:12)
Block(-3,13,-11,LEAVES:12)
Block(2,13,-10,LEAVES:12)
Block(13,13,-8,LEAVES:12)
Block(-4,13,-7,LEAVES:12)
Block(-3,13,-7,LEAVES:12)
Block(1,13,-7,LEAVES:12)
Block(12,13,-7,LEAVES:12)
Block(13,13,-7,LEAVES:12)
Block(-4,13,-6,LEAVES:12)
Block(1,13,-6,LOG2:12)
Block(2,13,-6,LEAVES:12)
Block(1,13,-5,LOG2:12)
Block(8,13,-4,LOG2:12)
Block(5,13,-3,LEAVES:12)
Block(6,13,-3,LEAVES:12)
Block(7,13,-3,LOG2:12)
Block(8,13,-3,LOG2:12)
Block(12,13,-3,LEAVES:12)
Block(12,13,-2,LEAVES:12)
Block(2,13,-1,LOG2:12)
Block(-2,13,0,LOG2:12)
Block(2,13,0,LOG2:12)
Block(-2,13,1,LOG2:12)
Block(0,13,3,LOG2:12)
Block(1,13,3,LOG2:12)
Block(6,13,4,LOG2:12)
Block(-3,14,-11,LEAVES:12)
Block(-2,14,-11,LEAVES:12)
Block(-2,14,-10,LEAVES:12)
Block(2,14,-10,LEAVES:12)
Block(1,14,-9,LEAVES:12)
Block(2,14,-9,LEAVES:12)
Block(6,14,-9,LEAVES:12)
Block(-2,14,-8,LEAVES:12)
Block(0,14,-8,LEAVES:12)
Block(6,14,-8,LEAVES:12)
Block(7,14,-8,LEAVES:12)
Block(-3,14,-7,LEAVES:12)
Block(-2,14,-7,LEAVES:12)
Block(0,14,-7,LOG2:12)
Block(1,14,-7,LEAVES:12)
Block(12,14,-7,LEAVES:12)
Block(0,14,-6,LOG2:12)
Block(1,14,-6,LOG2:12)
Block(-3,14,-5,LEAVES:12)
Block(6,14,-4,LEAVES:12)
Block(7,14,-4,LEAVES:12)
Block(8,14,-4,LOG2:12)
Block(9,14,-4,LOG2:12)
Block(11,14,-4,LEAVES:12)
Block(6,14,-3,LEAVES:12)
Block(11,14,-3,LEAVES:12)
Block(12,14,-3,LEAVES:12)
Block(2,14,-1,LOG2:12)
Block(-2,14,0,LOG2:12)
Block(-4,14,1,LEAVES:12)
Block(0,14,3,LOG2:12)
Block(6,14,4,LOG2:12)
Block(-2,15,-10,LEAVES:12)
Block(-1,15,-10,LEAVES:12)
Block(0,15,-10,LEAVES:12)
Block(-1,15,-9,LEAVES:12)
Block(0,15,-9,LEAVES:12)
Block(1,15,-9,LEAVES:12)
Block(-2,15,-8,LEAVES:12)
Block(-1,15,-8,LEAVES:12)
Block(0,15,-8,LOG2:12)
Block(1,15,-8,LEAVES:12)
Block(2,15,-8,LEAVES:12)
Block(7,15,-8,LEAVES:12)
Block(8,15,-8,LEAVES:12)
Block(0,15,-7,LOG2:12)
Block(8,15,-7,LEAVES:12)
Block(12,15,-7,LEAVES:12)
Block(0,15,-6,LEAVES:12)
Block(11,15,-6,LEAVES:12)
Block(12,15,-6,LEAVES:12)
Block(-3,15,-5,LEAVES:12)
Block(8,15,-5,LEAVES:12)
Block(9,15,-5,LOG2:12)
Block(10,15,-5,LOG2:12)
Block(-4,15,-4,LEAVES:12)
Block(-3,15,-4,LEAVES:12)
Block(7,15,-4,LEAVES:12)
Block(8,15,-4,LEAVES:12)
Block(9,15,-4,LOG2:12)
Block(10,15,-4,LEAVES:12)
Block(11,15,-4,LEAVES:12)
Block(2,15,-1,LOG2:12)
Block(-11,15,0,LEAVES:12)
Block(-10,15,0,LEAVES:12)
Block(-4,15,0,LEAVES:12)
Block(-3,15,0,LOG2:12)
Block(-2,15,0,LOG2:12)
Block(-4,15,1,LEAVES:12)
Block(0,15,3,LOG2:12)
Block(6,15,4,LOG2:12)
Block(1,16,-11,LEAVES:12)
Block(0,16,-10,LEAVES:12)
Block(1,16,-10,LEAVES:12)
Block(-4,16,-9,LEAVES:12)
Block(-3,16,-9,LEAVES:12)
Block(-2,16,-9,LEAVES:12)
Block(-1,16,-9,LEAVES:12)
Block(0,16,-9,LEAVES:12)
Block(-1,16,-8,LEAVES:12)
Block(0,16,-8,LEAVES:12)
Block(2,16,-8,LEAVES:12)
Block(3,16,-8,LEAVES:12)
Block(-1,16,-7,LEAVES:12)
Block(3,16,-7,LEAVES:12)
Block(4,16,-7,LEAVES:12)
Block(8,16,-7,LEAVES:12)
Block(9,16,-7,LEAVES:12)
Block(10,16,-7,LEAVES:12)
Block(-10,16,-6,LEAVES:12)
Block(0,16,-6,LEAVES:12)
Block(9,16,-6,LEAVES:12)
Block(10,16,-6,LEAVES:12)
Block(11,16,-6,LEAVES:12)
Block(-10,16,-5,LEAVES:12)
Block(-9,16,-5,LEAVES:12)
Block(0,16,-5,LEAVES:12)
Block(8,16,-5,LEAVES:12)
Block(9,16,-5,LEAVES:12)
Block(10,16,-5,LOG2:12)
Block(11,16,-5,LEAVES:12)
Block(12,16,-5,LEAVES:12)
Block(-4,16,-4,LEAVES:12)
Block(0,16,-4,LEAVES:12)
Block(1,16,-4,LEAVES:12)
Block(10,16,-4,LEAVES:12)
Block(10,16,-3,LEAVES:12)
Block(-10,16,-1,LEAVES:12)
Block(-9,16,-1,LEAVES:12)
Block(-5,16,-1,LEAVES:12)
Block(2,16,-1,LOG2:12)
Block(-10,16,0,LEAVES:12)
Block(-5,16,0,LEAVES:12)
Block(-4,16,0,LOG2:12)
Block(-3,16,0,LOG2:12)
Block(10,16,1,LEAVES:12)
Block(-1,16,3,LOG2:12)
Block(0,16,3,LOG2:12)
Block(-1,16,4,LOG2:12)
Block(6,16,4,LOG2:12)
Block(7,16,4,LOG2:12)
Block(9,16,7,LEAVES:12)
Block(3,17,-13,LEAVES:12)
Block(2,17,-12,LEAVES:12)
Block(1,17,-11,LEAVES:12)
Block(2,17,-11,LEAVES:12)
Block(-2,17,-10,LEAVES:12)
Block(-1,17,-10,LEAVES:12)
Block(-6,17,-9,LEAVES:12)
Block(-5,17,-9,LEAVES:12)
Block(-4,17,-9,LEAVES:12)
Block(-1,17,-9,LEAVES:12)
Block(0,17,-9,LEAVES:12)
Block(11,17,-8,LEAVES:12)
Block(-2,17,-7,LEAVES:12)
Block(-1,17,-7,LEAVES:12)
Block(4,17,-7,LEAVES:12)
Block(5,17,-7,LEAVES:12)
Block(10,17,-7,LEAVES:12)
Block(11,17,-7,LEAVES:12)
Block(6,17,-6,LEAVES:12)
Block(7,17,-6,LEAVES:12)
Block(8,17,-6,LEAVES:12)
Block(9,17,-6,LEAVES:12)
Block(10,17,-6,LEAVES:12)
Block(-9,17,-5,LEAVES:12)
Block(-8,17,-5,LEAVES:12)
Block(9,17,-5,LEAVES:12)
Block(10,17,-5,LEAVES:12)
Block(12,17,-5,LEAVES:12)
Block(13,17,-5,LEAVES:12)
Block(-8,17,-4,LEAVES:12)
Block(-4,17,-4,LEAVES:12)
Block(9,17,-4,LEAVES:12)
Block(13,17,-4,LEAVES:12)
Block(14,17,-4,LEAVES:12)
Block(-5,17,-3,LEAVES:12)
Block(-4,17,-3,LEAVES:12)
Block(10,17,-3,LEAVES:12)
Block(-8,17,-2,LEAVES:12)
Block(-6,17,-2,LEAVES:12)
Block(3,17,-2,LOG2:12)
Block(10,17,-2,LEAVES:12)
Block(-9,17,-1,LEAVES:12)
Block(-8,17,-1,LEAVES:12)
Block(-6,17,-1,LEAVES:12)
Block(-5,17,-1,LOG2:12)
Block(-4,17,-1,LOG2:12)
Block(2,17,-1,LOG2:12)
Block(3,17,-1,LOG2:12)
Block(10,17,-1,LEAVES:12)
Block(11,17,-1,LEAVES:12)
Block(-4,17,0,LOG2:12)
Block(10,17,1,LEAVES:12)
Block(0,17,2,LEAVES:12)
Block(9,17,2,LEAVES:12)
Block(10,17,2,LEAVES:12)
Block(-1,17,4,LOG2:12)
Block(7,17,4,LOG2:12)
Block(2,17,6,LEAVES:12)
Block(3,17,6,LEAVES:12)
Block(9,17,6,LEAVES:12)
Block(9,17,7,LEAVES:12)
Block(-1,17,8,LEAVES:12)
Block(2,18,-12,LEAVES:12)
Block(-3,18,-11,LEAVES:12)
Block(-2,18,-11,LEAVES:12)
Block(-2,18,-10,LEAVES:12)
Block(0,18,-9,LEAVES:12)
Block(1,18,-9,LEAVES:12)
Block(12,18,-9,LEAVES:12)
Block(11,18,-8,LEAVES:12)
Block(12,18,-8,LEAVES:12)
Block(-3,18,-7,LEAVES:12)
Block(-2,18,-7,LEAVES:12)
Block(8,18,-7,LEAVES:12)
Block(9,18,-7,LEAVES:12)
Block(-3,18,-6,LEAVES:12)
Block(4,18,-6,LEAVES:12)
Block(5,18,-6,LEAVES:12)
Block(6,18,-6,LEAVES:12)
Block(9,18,-6,LEAVES:12)
Block(10,18,-6,LEAVES:12)
Block(-8,18,-4,LEAVES:12)
Block(-7,18,-4,LEAVES:12)
Block(-6,18,-4,LEAVES:12)
Block(8,18,-4,LEAVES:12)
Block(9,18,-4,LEAVES:12)
Block(14,18,-4,LEAVES:12)
Block(15,18,-4,LEAVES:12)
Block(-7,18,-3,LEAVES:12)
Block(-6,18,-3,LEAVES:12)
Block(-5,18,-3,LEAVES:12)
Block(-8,18,-2,LEAVES:12)
Block(-7,18,-2,LEAVES:12)
Block(-6,18,-2,LOG2:12)
Block(-5,18,-2,LOG2:12)
Block(-4,18,-2,LEAVES:12)
Block(3,18,-2,LOG2:12)
Block(-6,18,-1,LEAVES:12)
Block(-5,18,-1,LOG2:12)
Block(-6,18,0,LEAVES:12)
Block(3,18,0,LEAVES:12)
Block(3,18,1,LEAVES:12)
Block(4,18,1,LEAVES:12)
Block(0,18,2,LEAVES:12)
Block(9,18,2,LEAVES:12)
Block(-1,18,3,LEAVES:12)
Block(0,18,3,LEAVES:12)
Block(-2,18,4,LOG2:12)
Block(-1,18,4,LOG2:12)
Block(7,18,4,LOG2:12)
Block(3,18,5,LEAVES:12)
Block(4,18,5,LEAVES:12)
Block(8,18,5,LEAVES:12)
Block(3,18,6,LEAVES:12)
Block(8,18,6,LEAVES:12)
Block(9,18,6,LEAVES:12)
Block(-8,18,7,LEAVES:12)
Block(-7,18,7,LEAVES:12)
Block(-1,18,7,LEAVES:12)
Block(-1,18,8,LEAVES:12)
Block(-3,19,-12,LEAVES:12)
Block(2,19,-12,LEAVES:12)
Block(3,19,-12,LEAVES:12)
Block(-3,19,-11,LEAVES:12)
Block(1,19,-9,LEAVES:12)
Block(12,19,-9,LEAVES:12)
Block(1,19,-8,LEAVES:12)
Block(7,19,-8,LEAVES:12)
Block(8,19,-8,LEAVES:12)
Block(8,19,-7,LEAVES:12)
Block(-4,19,-6,LEAVES:12)
Block(-3,19,-6,LEAVES:12)
Block(6,19,-6,LEAVES:12)
Block(10,19,-6,LEAVES:12)
Block(11,19,-6,LEAVES:12)
Block(-5,19,-5,LEAVES:12)
Block(-6,19,-4,LEAVES:12)
Block(-5,19,-4,LEAVES:12)
Block(7,19,-4,LEAVES:12)
Block(8,19,-4,LEAVES:12)
Block(-10,19,-3,LEAVES:12)
Block(-9,19,-3,LEAVES:12)
Block(-8,19,-3,LEAVES:12)
Block(-7,19,-3,LEAVES:12)
Block(-6,19,-3,LEAVES:12)
Block(7,19,-3,LEAVES:12)
Block(-7,19,-2,LEAVES:12)
Block(-6,19,-2,LEAVES:12)
Block(-4,19,-2,LEAVES:12)
Block(-3,19,-2,LEAVES:12)
Block(3,19,-2,LOG2:12)
Block(-7,19,-1,LEAVES:12)
Block(-3,19,-1,LEAVES:12)
Block(-2,19,-1,LEAVES:12)
Block(-6,19,0,LEAVES:12)
Block(5,19,0,LEAVES:12)
Block(-7,19,1,LEAVES:12)
Block(-6,19,1,LEAVES:12)
Block(4,19,1,LEAVES:12)
Block(5,19,1,LEAVES:12)
Block(-7,19,2,LEAVES:12)
Block(-6,19,2,LEAVES:12)
Block(-5,19,2,LEAVES:12)
Block(5,19,2,LEAVES:12)
Block(9,19,2,LEAVES:12)
Block(-1,19,3,LEAVES:12)
Block(8,19,3,LEAVES:12)
Block(9,19,3,LEAVES:12)
Block(-2,19,4,LOG2:12)
Block(5,19,4,LEAVES:12)
Block(7,19,4,LOG2:12)
Block(-2,19,5,LOG2:12)
Block(4,19,5,LEAVES:12)
Block(5,19,5,LEAVES:12)
Block(7,19,5,LEAVES:12)
Block(8,19,5,LEAVES:12)
Block(-7,19,6,LEAVES:12)
Block(-6,19,6,LEAVES:12)
Block(-2,19,6,LEAVES:12)
Block(-7,19,7,LEAVES:12)
Block(-2,19,7,LEAVES:12)
Block(-1,19,7,LEAVES:12)
Block(13,20,-10,LEAVES:12)
Block(7,20,-9,LEAVES:12)
Block(12,20,-9,LEAVES:12)
Block(13,20,-9,LEAVES:12)
Block(1,20,-8,LEAVES:12)
Block(2,20,-8,LEAVES:12)
Block(7,20,-8,LEAVES:12)
Block(-4,20,-6,LEAVES:12)
Block(6,20,-6,LEAVES:12)
Block(11,20,-6,LEAVES:12)
Block(-5,20,-5,LEAVES:12)
Block(-4,20,-5,LEAVES:12)
Block(5,20,-5,LEAVES:12)
Block(6,20,-5,LEAVES:12)
Block(11,20,-5,LEAVES:12)
Block(-8,20,-4,LEAVES:12)
Block(-7,20,-4,LEAVES:12)
Block(-12,20,-3,LEAVES:12)
Block(-11,20,-3,LEAVES:12)
Block(-10,20,-3,LEAVES:12)
Block(-7,20,-3,LEAVES:12)
Block(-6,20,-3,LEAVES:12)
Block(6,20,-3,LEAVES:12)
Block(7,20,-3,LEAVES:12)
Block(3,20,-2,LOG2:12)
Block(-8,20,-1,LEAVES:12)
Block(-7,20,-1,LEAVES:12)
Block(-2,20,-1,LEAVES:12)
Block(-1,20,-1,LEAVES:12)
Block(5,20,-1,LEAVES:12)
Block(5,20,0,LEAVES:12)
Block(-6,20,2,LEAVES:12)
Block(-5,20,2,LEAVES:12)
Block(5,20,2,LEAVES:12)
Block(6,20,2,LEAVES:12)
Block(7,20,2,LEAVES:12)
Block(-5,20,3,LEAVES:12)
Block(-1,20,3,LEAVES:12)
Block(6,20,3,LEAVES:12)
Block(7,20,3,LEAVES:12)
Block(8,20,3,LEAVES:12)
Block(-2,20,4,LEAVES:12)
Block(-1,20,4,LEAVES:12)
Block(5,20,4,LEAVES:12)
Block(6,20,4,LEAVES:12)
Block(7,20,4,LOG2:12)
Block(8,20,4,LEAVES:12)
Block(9,20,4,LEAVES:12)
Block(-5,20,5,LEAVES:12)
Block(-3,20,5,LOG2:12)
Block(-2,20,5,LOG2:12)
Block(7,20,5,LEAVES:12)
Block(-6,20,6,LEAVES:12)
Block(-5,20,6,LEAVES:12)
Block(-3,20,6,LEAVES:12)
Block(-2,20,6,LEAVES:12)
Block(7,20,6,LEAVES:12)
Block(2,21,-8,LEAVES:12)
Block(-1,21,-7,LEAVES:12)
Block(-4,21,-6,LEAVES:12)
Block(-1,21,-6,LEAVES:12)
Block(0,21,-6,LEAVES:12)
Block(-9,21,-5,LEAVES:12)
Block(-8,21,-5,LEAVES:12)
Block(5,21,-5,LEAVES:12)
Block(11,21,-5,LEAVES:12)
Block(12,21,-5,LEAVES:12)
Block(-8,21,-4,LEAVES:12)
Block(-6,21,-3,LEAVES:12)
Block(-5,21,-3,LEAVES:12)
Block(3,21,-3,LOG2:12)
Block(6,21,-3,LEAVES:12)
Block(-1,21,-2,LEAVES:12)
Block(0,21,-2,LEAVES:12)
Block(3,21,-2,LOG2:12)
Block(4,21,-2,LEAVES:12)
Block(-9,21,-1,LEAVES:12)
Block(-8,21,-1,LEAVES:12)
Block(-1,21,-1,LEAVES:12)
Block(4,21,-1,LEAVES:12)
Block(5,21,-1,LEAVES:12)
Block(-9,21,0,LEAVES:12)
Block(8,21,1,LEAVES:12)
Block(7,21,2,LEAVES:12)
Block(8,21,2,LEAVES:12)
Block(-5,21,3,LEAVES:12)
Block(-4,21,3,LEAVES:12)
Block(-3,21,3,LEAVES:12)
Block(3,21,3,LEAVES:12)
Block(4,21,3,LEAVES:12)
Block(5,21,3,LEAVES:12)
Block(6,21,3,LEAVES:12)
Block(7,21,3,LEAVES:12)
Block(-4,21,4,LEAVES:12)
Block(-3,21,4,LEAVES:12)
Block(-2,21,4,LEAVES:12)
Block(6,21,4,LEAVES:12)
Block(7,21,4,LEAVES:12)
Block(9,21,4,LEAVES:12)
Block(10,21,4,LEAVES:12)
Block(-5,21,5,LEAVES:12)
Block(-4,21,5,LEAVES:12)
Block(-3,21,5,LOG2:12)
Block(-2,21,5,LEAVES:12)
Block(-1,21,5,LEAVES:12)
Block(6,21,5,LEAVES:12)
Block(10,21,5,LEAVES:12)
Block(11,21,5,LEAVES:12)
Block(-3,21,6,LEAVES:12)
Block(7,21,6,LEAVES:12)
Block(-3,21,7,LEAVES:12)
Block(7,21,7,LEAVES:12)
Block(7,21,8,LEAVES:12)
Block(8,21,8,LEAVES:12)
Block(-3,22,-7,LEAVES:12)
Block(-9,22,-6,LEAVES:12)
Block(-4,22,-6,LEAVES:12)
Block(-3,22,-6,LEAVES:12)
Block(0,22,-6,LEAVES:12)
Block(1,22,-6,LEAVES:12)
Block(-9,22,-5,LEAVES:12)
Block(1,22,-5,LEAVES:12)
Block(5,22,-5,LEAVES:12)
Block(12,22,-5,LEAVES:12)
Block(4,22,-4,LEAVES:12)
Block(5,22,-4,LEAVES:12)
Block(-5,22,-3,LEAVES:12)
Block(1,22,-3,LEAVES:12)
Block(3,22,-3,LOG2:12)
Block(-5,22,-2,LEAVES:12)
Block(0,22,-2,LEAVES:12)
Block(1,22,-2,LEAVES:12)
Block(3,22,-2,LEAVES:12)
Block(4,22,-2,LEAVES:12)
Block(-10,22,0,LEAVES:12)
Block(-9,22,0,LEAVES:12)
Block(9,22,0,LEAVES:12)
Block(8,22,1,LEAVES:12)
Block(9,22,1,LEAVES:12)
Block(-2,22,2,LEAVES:12)
Block(5,22,2,LEAVES:12)
Block(6,22,2,LEAVES:12)
Block(-3,22,3,LEAVES:12)
Block(-2,22,3,LEAVES:12)
Block(1,22,3,LEAVES:12)
Block(2,22,3,LEAVES:12)
Block(3,22,3,LEAVES:12)
Block(6,22,3,LEAVES:12)
Block(7,22,3,LEAVES:12)
Block(-7,22,4,LEAVES:12)
Block(-6,22,4,LEAVES:12)
Block(-5,22,4,LEAVES:12)
Block(-4,22,4,LEAVES:12)
Block(-3,22,4,LEAVES:12)
Block(-4,22,5,LEAVES:12)
Block(-3,22,5,LEAVES:12)
Block(-1,22,5,LEAVES:12)
Block(0,22,5,LEAVES:12)
Block(5,22,5,LEAVES:12)
Block(6,22,5,LEAVES:12)
Block(11,22,5,LEAVES:12)
Block(12,22,5,LEAVES:12)
Block(-4,22,6,LEAVES:12)
Block(0,22,6,LEAVES:12)
Block(1,22,6,LEAVES:12)
Block(-3,22,7,LEAVES:12)
Block(-3,22,8,LEAVES:12)
Block(-3,22,9,LEAVES:12)
Block(-2,22,9,LEAVES:12)
Block(1,23,-5,LEAVES:12)
Block(2,23,-5,LEAVES:12)
Block(3,23,-5,LEAVES:12)
Block(2,23,-4,LEAVES:12)
Block(3,23,-4,LEAVES:12)
Block(4,23,-4,LEAVES:12)
Block(1,23,-3,LEAVES:12)
Block(2,23,-3,LEAVES:12)
Block(3,23,-3,LOG2:12)
Block(4,23,-3,LEAVES:12)
Block(5,23,-3,LEAVES:12)
Block(-5,23,-2,LEAVES:12)
Block(-4,23,-2,LEAVES:12)
Block(3,23,-2,LEAVES:12)
Block(3,23,-1,LEAVES:12)
Block(-10,23,0,LEAVES:12)
Block(9,23,0,LEAVES:12)
Block(-1,23,1,LEAVES:12)
Block(4,23,1,LEAVES:12)
Block(5,23,1,LEAVES:12)
Block(-2,23,2,LEAVES:12)
Block(-1,23,2,LEAVES:12)
Block(5,23,2,LEAVES:12)
Block(-5,23,3,LEAVES:12)
Block(-4,23,3,LEAVES:12)
Block(7,23,3,LEAVES:12)
Block(8,23,3,LEAVES:12)
Block(-9,23,4,LEAVES:12)
Block(-8,23,4,LEAVES:12)
Block(-7,23,4,LEAVES:12)
Block(-4,23,4,LEAVES:12)
Block(-3,23,4,LEAVES:12)
Block(4,23,5,LEAVES:12)
Block(5,23,5,LEAVES:12)
Block(-5,23,6,LEAVES:12)
Block(-4,23,6,LEAVES:12)
Block(1,23,6,LEAVES:12)
Block(2,23,6,LEAVES:12)
Block(4,23,6,LEAVES:12)
Block(4,24,-6,LEAVES:12)
Block(3,24,-5,LEAVES:12)
Block(4,24,-5,LEAVES:12)
Block(-1,24,-4,LEAVES:12)
Block(0,24,-4,LEAVES:12)
Block(1,24,-4,LEAVES:12)
Block(2,24,-4,LEAVES:12)
Block(3,24,-4,LEAVES:12)
Block(2,24,-3,LEAVES:12)
Block(3,24,-3,LEAVES:12)
Block(5,24,-3,LEAVES:12)
Block(6,24,-3,LEAVES:12)
Block(-4,24,-2,LEAVES:12)
Block(2,24,-2,LEAVES:12)
Block(6,24,-2,LEAVES:12)
Block(7,24,-2,LEAVES:12)
Block(3,24,-1,LEAVES:12)
Block(10,24,-1,LEAVES:12)
Block(3,24,0,LEAVES:12)
Block(4,24,0,LEAVES:12)
Block(9,24,0,LEAVES:12)
Block(10,24,0,LEAVES:12)
Block(-1,24,1,LEAVES:12)
Block(3,24,1,LEAVES:12)
Block(4,24,1,LEAVES:12)
Block(-6,24,2,LEAVES:12)
Block(-5,24,2,LEAVES:12)
Block(-5,24,3,LEAVES:12)
Block(8,24,3,LEAVES:12)
Block(-3,24,4,LEAVES:12)
Block(-2,24,4,LEAVES:12)
Block(8,24,4,LEAVES:12)
Block(-6,24,6,LEAVES:12)
Block(-5,24,6,LEAVES:12)
Block(3,24,6,LEAVES:12)
Block(4,24,6,LEAVES:12)
Block(-6,24,7,LEAVES:12)
Block(5,25,-7,LEAVES:12)
Block(4,25,-6,LEAVES:12)
Block(5,25,-6,LEAVES:12)
Block(1,25,-5,LEAVES:12)
Block(2,25,-5,LEAVES:12)
Block(-3,25,-4,LEAVES:12)
Block(-2,25,-4,LEAVES:12)
Block(-1,25,-4,LEAVES:12)
Block(2,25,-4,LEAVES:12)
Block(3,25,-4,LEAVES:12)
Block(1,25,-2,LEAVES:12)
Block(2,25,-2,LEAVES:12)
Block(7,25,-2,LEAVES:12)
Block(8,25,-2,LEAVES:12)
Block(0,25,0,LEAVES:12)
Block(-6,25,1,LEAVES:12)
Block(-1,25,1,LEAVES:12)
Block(0,25,1,LEAVES:12)
Block(-6,25,2,LEAVES:12)
Block(-2,25,4,LEAVES:12)
Block(8,25,4,LEAVES:12)
Block(9,25,4,LEAVES:12)
Block(-2,25,5,LEAVES:12)
Block(3,25,6,LEAVES:12)
Block(-7,25,7,LEAVES:12)
Block(-6,25,7,LEAVES:12)
Block(5,26,-7,LEAVES:12)
Block(0,26,-6,LEAVES:12)
Block(1,26,-6,LEAVES:12)
Block(1,26,-5,LEAVES:12)
Block(3,26,-4,LEAVES:12)
Block(4,26,-4,LEAVES:12)
Block(0,26,-2,LEAVES:12)
Block(1,26,-2,LEAVES:12)
Block(0,26,-1,LEAVES:12)
Block(9,26,4,LEAVES:12)
Block(-2,26,5,LEAVES:12)
Block(-1,26,5,LEAVES:12)
Block(-7,26,7,LEAVES:12)
Block(6,27,-8,LEAVES:12)
Block(0,27,-7,LEAVES:12)
Block(5,27,-7,LEAVES:12)
Block(6,27,-7,LEAVES:12)
Block(0,27,-6,LEAVES:12)
Block(4,27,-4,LEAVES:12)
Block(4,27,-3,LEAVES:12)
Block(-1,27,-1,LEAVES:12)
Block(0,27,-1,LEAVES:12)
Block(-1,27,5,LEAVES:12)
Block(4,28,-3,LEAVES:12)
Block(5,28,-3,LEAVES:12)
Block(-1,28,-1,LEAVES:12)
Block(5,29,-3,LEAVES:12)

#######################################################################
# +-----------------------------------------------------------------+ #
# |                            BO3 checks                           | #
# +-----------------------------------------------------------------+ #
#######################################################################

# Require a condition at a certain location in order for the BO3 to be spawned.
# BlockCheck(x,y,z,BlockName[,BlockName[,...]]) - one of the blocks must be at the location
# BlockCheckNot(x,y,z,BlockName[,BlockName[,...]]) - all the blocks must not be at the location
# LightCheck(x,y,z,minLightLevel,maxLightLevel) - light must be between min and max (inclusive)

# You can use "Solid" as a BlockName for matching all solid blocks or "All" to match all blocks that aren't air.

# Examples:
BlockCheck(0,-1,0,GRASS,DIRT,DIRT:2,SAND)
#   BlockCheck(0,-1,0,Solid)       Require any solid block just below the object
#   BlockCheck(0,-1,0,WOOL)        Require any type of wool just below the object
#   BlockCheck(0,-1,0,WOOL:0)      Require white wool just below the object
#   BlockCheckNot(0,-1,0,WOOL:0)   Require that there is no white wool below the object
#   LightCheck(0,0,0,0,1)          Require almost complete darkness just below the object

#######################################################################
# +-----------------------------------------------------------------+ #
# |                             Branches                            | #
# +-----------------------------------------------------------------+ #
#######################################################################

# Branches are objects that will spawn when this object spawns when it is used in
# the CustomStructure resource. Branches can also have branches, making complex
# structures possible. See the wiki for more details.

# Regular Branches spawn each branch with an independent chance of spawning.
# Branch(x,y,z,branchName,rotation,chance[,anotherBranchName,rotation,chance[,...]][IndividualChance])
# branchName - name of the object to spawn.
# rotation - NORTH, SOUTH, EAST or WEST.
# IndividualChance - The chance each branch has to spawn, assumed to be 100 when left blank

# Weighted Branches spawn branches with a dependent chance of spawning.
# WeightedBranch(x,y,z,branchName,rotation,chance[,anotherBranchName,rotation,chance[,...]][MaxChanceOutOf])
# MaxChanceOutOf - The chance all branches have to spawn out of, assumed to be 100 when left blank
