#######################################################################
# +-----------------------------------------------------------------+ #
# |                            BO3 object                           | #
# +-----------------------------------------------------------------+ #
#######################################################################

# The descriptions in this file are accurate only for TerrainControl and OTG.
# For MCW and OTG+ these descriptions are only accurate if the BO3 is used as a CustomObject.
# MCW and OTG+ completely reimplemented CustomStructure, check the MCW/OTG+ documentation for more information.

# This is the config file of a custom object.
# If you add this object correctly to your BiomeConfigs, it will spawn in the world.

# This is the creator of this BO3 object
Author: Unknown

# A short description of this BO3 object
Description: This BO3 was converted from a schematic using OTGEdit. The author and description information of the schematic could not be found. If you know who the author of the schematic is then please add this information.

# The BO3 version, don't change this! It can be used by external applications to do a version check.
Version: 3

# The settings mode, WriteAll, WriteWithoutComments or WriteDisable. See WorldConfig.
SettingsMode: WriteDisable

#######################################################################
# +-----------------------------------------------------------------+ #
# |                          Main settings                          | #
# +-----------------------------------------------------------------+ #
#######################################################################

# This needs to be set to true to spawn the object in the Tree and Sapling resources.
Tree: true

# The frequency of the BO3 from 1 to 200. Tries this many times to spawn this BO3 when using the CustomObject(...) resource.
# Ignored by Tree(..), Sapling(..) and CustomStructure(..)
Frequency: 40

# The rarity of the BO3 from 0 to 100. Each spawn attempt has rarity% chance to succeed when using the CustomObject(...) resource.
# Ignored by Tree(..), Sapling(..) and CustomStructure(..)
Rarity: 100.0

# If you set this to true, the BO3 will be placed with a random rotation.
RotateRandomly: true

# The spawn height of the BO3 - randomY, highestBlock or highestSolidBlock.
SpawnHeight: highestSolidBlock
SpawnHeightOffset: -2
# The height limits for the BO3.
MinHeight: 0

MaxHeight: 69

# Objects can have other objects attached to it: branches. Branches can also
# have branches attached to it, which can also have branches, etc. This is the
# maximum branch depth for this objects.
MaxBranchDepth: 10

# When spawned with the UseWorld keyword, this BO3 should NOT spawn in the following biomes.
# If you writer.write the BO3 name directly in the BiomeConfigs, this will be ignored.
ExcludedBiomes: All

# To optimise this BO3 for faster loading times you can use Notepad++ to find/replace comments and abbreviate things.
# Notepad++ find/replace with regex:
# Find: ^[#;].* replace to nothing removes all lines starting with # 
# Find: ^\s*$ replace to nothing removes most empty lines 
# Notepad++ find/replace without regex:
# *Warning: This will only work for OTG 1.10.2 v21 / OTG 1.11.2 v6 or higher. B( is not recognised by lower versions.
# Find: Block( replace to B(

#######################################################################
# +-----------------------------------------------------------------+ #
# |                      Source block settings                      | #
# +-----------------------------------------------------------------+ #
#######################################################################

# The block(s) the BO3 should spawn in.
SourceBlocks: AIR,GRASS,DIRT

# The maximum percentage of the BO3 that can be outside the SourceBlock.
# The BO3 won't be placed on a location with more blocks outside the SourceBlock than this percentage.
MaxPercentageOutsideSourceBlock: 0

# What to do when a block is about to be placed outside the SourceBlock? (dontPlace, placeAnyway)
OutsideSourceBlock: dontPlace

#######################################################################
# +-----------------------------------------------------------------+ #
# |                              Blocks                             | #
# +-----------------------------------------------------------------+ #
#######################################################################

# All the blocks used in the BO3 are listed here. Possible blocks:
# Block(x,y,z,id[.data][,nbtfile.nbt) or B(x,y,z,id[.data][,nbtfile.nbt)
# RandomBlock(x,y,z,id[:data][,nbtfile.nbt],chance[,id[:data][,nbtfile.nbt],chance[,...]])
# So RandomBlock(0,0,0,CHEST,chest.nbt,50,CHEST,anotherchest.nbt,100) will spawn a chest at
# the BO3 origin, and give it a 50% chance to have the contents of chest.nbt, or, if that
# fails, a 100% percent chance to have the contents of anotherchest.nbt.

Block(-13,28,6,LEAVES:15)
Block(-13,28,7,LEAVES:15)
Block(-13,28,8,LEAVES:15)
Block(-13,33,7,LEAVES:15)
Block(-13,33,8,LEAVES:15)
Block(-13,33,9,LEAVES:15)
Block(-12,28,7,LEAVES:15)
Block(-12,28,8,LEAVES:15)
Block(-12,29,5,LEAVES:15)
Block(-12,29,6,LEAVES:15)
Block(-12,30,17,LEAVES:15)
Block(-12,31,16,LEAVES:15)
Block(-12,32,0,LEAVES:15)
Block(-12,33,9,LEAVES:15)
Block(-12,34,7,LEAVES:15)
Block(-12,34,8,LEAVES:15)
Block(-11,29,5,LEAVES:15)
Block(-11,29,6,LEAVES:15)
Block(-11,29,7,LEAVES:15)
Block(-11,31,14,LEAVES:15)
Block(-11,31,15,LEAVES:15)
Block(-11,31,16,LEAVES:15)
Block(-11,31,17,LEAVES:15)
Block(-11,32,-1,LEAVES:15)
Block(-11,32,0,LEAVES:15)
Block(-11,32,1,LEAVES:15)
Block(-11,34,6,LEAVES:15)
Block(-11,34,7,LEAVES:15)
Block(-11,34,8,LEAVES:15)
Block(-10,29,6,LEAVES:15)
Block(-10,31,13,LEAVES:15)
Block(-10,31,15,LEAVES:15)
Block(-10,31,16,LEAVES:15)
Block(-10,32,-1,LEAVES:15)
Block(-10,32,0,LEAVES:15)
Block(-10,32,1,LEAVES:15)
Block(-10,32,14,LEAVES:15)
Block(-10,34,6,LEAVES:15)
Block(-10,34,7,LEAVES:15)
Block(-10,34,8,LEAVES:15)
Block(-9,28,6,LEAVES:15)
Block(-9,29,6,LEAVES:15)
Block(-9,31,12,LEAVES:15)
Block(-9,31,16,LEAVES:15)
Block(-9,32,-1,LEAVES:15)
Block(-9,32,0,LEAVES:15)
Block(-9,32,1,LEAVES:15)
Block(-9,32,2,LEAVES:15)
Block(-9,32,13,LEAVES:15)
Block(-9,32,14,LEAVES:15)
Block(-9,32,15,LEAVES:15)
Block(-9,33,6,LEAVES:15)
Block(-9,34,7,LEAVES:15)
Block(-8,28,6,LEAVES:15)
Block(-8,31,15,LEAVES:15)
Block(-8,32,0,LEAVES:15)
Block(-8,32,1,LEAVES:15)
Block(-8,32,2,LEAVES:15)
Block(-8,32,12,LEAVES:15)
Block(-8,32,13,LEAVES:15)
Block(-8,32,14,LEAVES:15)
Block(-8,33,6,LEAVES:15)
Block(-8,41,3,LEAVES:15)
Block(-8,42,2,LEAVES:15)
Block(-7,27,6,LEAVES:15)
Block(-7,28,6,LEAVES:15)
Block(-7,31,14,LEAVES:15)
Block(-7,32,1,LEAVES:15)
Block(-7,32,2,LEAVES:15)
Block(-7,32,6,LEAVES:15)
Block(-7,32,12,LEAVES:15)
Block(-7,32,13,LEAVES:15)
Block(-7,40,4,LEAVES:15)
Block(-7,41,2,LEAVES:15)
Block(-7,41,3,LEAVES:15)
Block(-6,26,7,LEAVES:15)
Block(-6,27,6,LEAVES:15)
Block(-6,27,7,LEAVES:15)
Block(-6,31,2,LEAVES:15)
Block(-6,31,6,LEAVES:15)
Block(-6,32,11,LEAVES:15)
Block(-6,38,5,LEAVES:15)
Block(-6,39,4,LEAVES:15)
Block(-6,39,5,LEAVES:15)
Block(-6,40,3,LEAVES:15)
Block(-6,40,4,LEAVES:15)
Block(-5,25,7,LEAVES:15)
Block(-5,26,7,LEAVES:15)
Block(-5,27,20,LEAVES:15)
Block(-5,28,18,LEAVES:15)
Block(-5,28,19,LEAVES:15)
Block(-5,29,17,LEAVES:15)
Block(-5,30,3,LEAVES:15)
Block(-5,30,7,LEAVES:15)
Block(-5,31,2,LEAVES:15)
Block(-5,31,6,LEAVES:15)
Block(-5,31,10,LEAVES:15)
Block(-5,35,6,LEAVES:15)
Block(-5,36,5,LEAVES:15)
Block(-5,36,6,LEAVES:15)
Block(-5,37,4,LEAVES:15)
Block(-5,37,5,LEAVES:15)
Block(-5,38,4,LEAVES:15)
Block(-5,38,5,LEAVES:15)
Block(-5,39,3,LEAVES:15)
Block(-4,24,7,LEAVES:15)
Block(-4,25,7,LEAVES:15)
Block(-4,26,21,LEAVES:15)
Block(-4,27,20,LEAVES:15)
Block(-4,28,5,LEAVES:15)
Block(-4,28,9,LEAVES:15)
Block(-4,28,19,LEAVES:15)
Block(-4,29,4,LEAVES:15)
Block(-4,29,7,LEAVES:15)
Block(-4,29,9,LEAVES:15)
Block(-4,29,15,LEAVES:15)
Block(-4,29,16,LEAVES:15)
Block(-4,29,17,LEAVES:15)
Block(-4,29,18,LEAVES:15)
Block(-4,30,3,LEAVES:15)
Block(-4,30,7,LEAVES:15)
Block(-4,30,9,LEAVES:15)
Block(-4,32,6,LEAVES:15)
Block(-4,33,6,LEAVES:15)
Block(-4,34,6,LEAVES:15)
Block(-3,0,6,162:12)
Block(-3,0,7,162:12)
Block(-3,0,8,162:12)
Block(-3,1,6,162:12)
Block(-3,1,7,162:12)
Block(-3,1,8,162:12)
Block(-3,2,7,162:12)
Block(-3,2,8,162:12)
Block(-3,3,7,162:12)
Block(-3,4,7,162:12)
Block(-3,5,7,162:12)
Block(-3,6,7,162:12)
Block(-3,7,7,162:12)
Block(-3,8,7,162:12)
Block(-3,9,7,162:12)
Block(-3,21,7,LEAVES:15)
Block(-3,22,7,LEAVES:15)
Block(-3,23,6,LEAVES:15)
Block(-3,23,7,LEAVES:15)
Block(-3,23,8,LEAVES:15)
Block(-3,24,7,LEAVES:15)
Block(-3,24,8,LEAVES:15)
Block(-3,25,6,LEAVES:15)
Block(-3,25,8,LEAVES:15)
Block(-3,26,6,LEAVES:15)
Block(-3,26,7,LEAVES:15)
Block(-3,26,8,LEAVES:15)
Block(-3,27,5,LEAVES:15)
Block(-3,27,8,LEAVES:15)
Block(-3,27,19,LEAVES:15)
Block(-3,28,5,LEAVES:15)
Block(-3,28,7,LEAVES:15)
Block(-3,28,18,LEAVES:15)
Block(-3,29,6,LEAVES:15)
Block(-3,29,7,LEAVES:15)
Block(-3,29,16,LEAVES:15)
Block(-3,29,17,LEAVES:15)
Block(-3,30,6,LEAVES:15)
Block(-3,30,12,LEAVES:15)
Block(-3,30,13,LEAVES:15)
Block(-3,30,14,LEAVES:15)
Block(-3,31,6,LEAVES:15)
Block(-3,32,6,LEAVES:15)
Block(-2,0,6,162:12)
Block(-2,0,7,162:12)
Block(-2,0,8,162:12)
Block(-2,1,6,162:12)
Block(-2,1,7,162:12)
Block(-2,1,8,162:12)
Block(-2,2,6,162:12)
Block(-2,2,7,162:12)
Block(-2,2,8,162:12)
Block(-2,3,6,162:12)
Block(-2,3,7,162:12)
Block(-2,3,8,162:12)
Block(-2,4,6,162:12)
Block(-2,4,7,162:12)
Block(-2,4,8,162:12)
Block(-2,5,6,162:12)
Block(-2,5,7,162:12)
Block(-2,5,8,162:12)
Block(-2,6,6,162:12)
Block(-2,6,7,162:12)
Block(-2,6,8,162:12)
Block(-2,7,6,162:12)
Block(-2,7,7,162:12)
Block(-2,7,8,162:12)
Block(-2,8,6,162:12)
Block(-2,8,7,162:12)
Block(-2,8,8,162:12)
Block(-2,9,6,162:12)
Block(-2,9,7,162:12)
Block(-2,9,8,162:12)
Block(-2,10,6,162:12)
Block(-2,10,7,162:12)
Block(-2,10,8,162:12)
Block(-2,11,6,162:12)
Block(-2,11,7,162:12)
Block(-2,11,8,162:12)
Block(-2,12,6,162:12)
Block(-2,12,7,162:12)
Block(-2,12,8,162:12)
Block(-2,13,6,162:12)
Block(-2,13,7,162:12)
Block(-2,13,8,162:12)
Block(-2,14,7,162:12)
Block(-2,14,8,162:12)
Block(-2,15,7,162:12)
Block(-2,15,8,162:12)
Block(-2,16,7,162:12)
Block(-2,16,8,162:12)
Block(-2,17,7,162:12)
Block(-2,18,7,162:12)
Block(-2,19,7,162:12)
Block(-2,20,7,162:12)
Block(-2,21,6,LEAVES:15)
Block(-2,21,7,162:12)
Block(-2,22,6,LEAVES:15)
Block(-2,22,7,162:12)
Block(-2,22,8,LEAVES:15)
Block(-2,23,6,LEAVES:15)
Block(-2,23,7,LEAVES:15)
Block(-2,23,8,LEAVES:15)
Block(-2,24,5,LEAVES:15)
Block(-2,24,6,LEAVES:15)
Block(-2,24,7,LEAVES:15)
Block(-2,24,8,LEAVES:15)
Block(-2,25,3,LEAVES:15)
Block(-2,25,4,LEAVES:15)
Block(-2,25,5,LEAVES:15)
Block(-2,25,6,LEAVES:15)
Block(-2,25,7,LEAVES:15)
Block(-2,25,8,LEAVES:15)
Block(-2,25,9,LEAVES:15)
Block(-2,26,7,LEAVES:15)
Block(-2,26,8,LEAVES:15)
Block(-2,27,7,LEAVES:15)
Block(-2,28,4,LEAVES:15)
Block(-2,28,7,LEAVES:15)
Block(-2,28,8,LEAVES:15)
Block(-2,28,9,LEAVES:15)
Block(-2,29,4,LEAVES:15)
Block(-2,29,7,LEAVES:15)
Block(-2,29,10,LEAVES:15)
Block(-2,29,11,LEAVES:15)
Block(-2,30,4,LEAVES:15)
Block(-2,31,3,LEAVES:15)
Block(-2,32,3,LEAVES:15)
Block(-2,34,-1,LEAVES:15)
Block(-2,34,0,LEAVES:15)
Block(-2,35,-2,LEAVES:15)
Block(-1,0,6,162:12)
Block(-1,0,7,162:12)
Block(-1,0,8,162:12)
Block(-1,1,6,162:12)
Block(-1,1,7,162:12)
Block(-1,1,8,162:12)
Block(-1,2,6,162:12)
Block(-1,2,7,162:12)
Block(-1,3,7,162:12)
Block(-1,4,7,162:12)
Block(-1,5,7,162:12)
Block(-1,6,7,162:12)
Block(-1,7,7,162:12)
Block(-1,8,7,162:12)
Block(-1,9,7,162:12)
Block(-1,10,7,162:12)
Block(-1,11,7,162:12)
Block(-1,12,7,162:12)
Block(-1,13,7,162:12)
Block(-1,22,6,LEAVES:15)
Block(-1,22,7,LEAVES:15)
Block(-1,23,6,LEAVES:15)
Block(-1,23,7,LEAVES:15)
Block(-1,23,8,LEAVES:15)
Block(-1,24,7,LEAVES:15)
Block(-1,25,7,LEAVES:15)
Block(-1,25,8,LEAVES:15)
Block(-1,25,9,LEAVES:15)
Block(-1,26,2,LEAVES:15)
Block(-1,26,3,LEAVES:15)
Block(-1,26,6,LEAVES:15)
Block(-1,26,7,LEAVES:15)
Block(-1,26,9,LEAVES:15)
Block(-1,26,10,LEAVES:15)
Block(-1,27,5,LEAVES:15)
Block(-1,27,6,LEAVES:15)
Block(-1,28,5,LEAVES:15)
Block(-1,29,7,LEAVES:15)
Block(-1,30,7,LEAVES:15)
Block(-1,31,7,LEAVES:15)
Block(-1,31,8,LEAVES:15)
Block(-1,33,2,LEAVES:15)
Block(-1,34,-5,LEAVES:15)
Block(-1,34,0,LEAVES:15)
Block(-1,34,1,LEAVES:15)
Block(-1,34,9,LEAVES:15)
Block(-1,35,-4,LEAVES:15)
Block(-1,35,-3,LEAVES:15)
Block(-1,35,-2,LEAVES:15)
Block(-1,35,-1,LEAVES:15)
Block(-1,35,9,LEAVES:15)
Block(0,25,7,LEAVES:15)
Block(0,26,7,LEAVES:15)
Block(0,26,10,LEAVES:15)
Block(0,27,-2,LEAVES:15)
Block(0,27,-1,LEAVES:15)
Block(0,27,0,LEAVES:15)
Block(0,27,1,LEAVES:15)
Block(0,27,6,LEAVES:15)
Block(0,27,10,LEAVES:15)
Block(0,27,11,LEAVES:15)
Block(0,27,12,LEAVES:15)
Block(0,28,5,LEAVES:15)
Block(0,28,6,LEAVES:15)
Block(0,28,12,LEAVES:15)
Block(0,29,5,LEAVES:15)
Block(0,29,7,LEAVES:15)
Block(0,31,8,LEAVES:15)
Block(0,32,8,LEAVES:15)
Block(0,33,8,LEAVES:15)
Block(0,34,-6,LEAVES:15)
Block(0,34,-1,LEAVES:15)
Block(0,34,0,LEAVES:15)
Block(0,34,8,LEAVES:15)
Block(0,35,-5,LEAVES:15)
Block(0,35,-4,LEAVES:15)
Block(0,35,-3,LEAVES:15)
Block(0,35,-2,LEAVES:15)
Block(0,35,8,LEAVES:15)
Block(0,36,8,LEAVES:15)
Block(0,36,9,LEAVES:15)
Block(0,37,9,LEAVES:15)
Block(0,38,10,LEAVES:15)
Block(1,26,-5,LEAVES:15)
Block(1,26,7,LEAVES:15)
Block(1,27,-4,LEAVES:15)
Block(1,27,-3,LEAVES:15)
Block(1,27,-2,LEAVES:15)
Block(1,27,-1,LEAVES:15)
Block(1,27,7,LEAVES:15)
Block(1,28,12,LEAVES:15)
Block(1,28,13,LEAVES:15)
Block(1,28,14,LEAVES:15)
Block(1,28,15,LEAVES:15)
Block(1,29,4,LEAVES:15)
Block(1,29,5,LEAVES:15)
Block(1,29,7,LEAVES:15)
Block(1,29,16,LEAVES:15)
Block(1,29,17,LEAVES:15)
Block(1,30,4,LEAVES:15)
Block(1,30,7,LEAVES:15)
Block(1,34,-6,LEAVES:15)
Block(1,34,-5,LEAVES:15)
Block(1,34,7,LEAVES:15)
Block(1,35,-4,LEAVES:15)
Block(1,35,-3,LEAVES:15)
Block(1,35,7,LEAVES:15)
Block(1,36,8,LEAVES:15)
Block(1,37,9,LEAVES:15)
Block(1,38,9,LEAVES:15)
Block(1,39,10,LEAVES:15)
Block(1,40,10,LEAVES:15)
Block(2,25,-7,LEAVES:15)
Block(2,26,-6,LEAVES:15)
Block(2,27,-5,LEAVES:15)
Block(2,27,-4,LEAVES:15)
Block(2,27,-3,LEAVES:15)
Block(2,27,-2,LEAVES:15)
Block(2,27,7,LEAVES:15)
Block(2,28,7,LEAVES:15)
Block(2,28,14,LEAVES:15)
Block(2,28,19,LEAVES:15)
Block(2,29,15,LEAVES:15)
Block(2,29,16,LEAVES:15)
Block(2,29,17,LEAVES:15)
Block(2,29,18,LEAVES:15)
Block(2,30,3,LEAVES:15)
Block(2,30,4,LEAVES:15)
Block(2,30,7,LEAVES:15)
Block(2,31,7,LEAVES:15)
Block(2,31,8,LEAVES:15)
Block(2,37,8,LEAVES:15)
Block(2,38,8,LEAVES:15)
Block(2,39,9,LEAVES:15)
Block(2,39,10,LEAVES:15)
Block(2,40,9,LEAVES:15)
Block(2,40,10,LEAVES:15)
Block(2,41,10,LEAVES:15)
Block(3,25,-8,LEAVES:15)
Block(3,26,-7,LEAVES:15)
Block(3,26,-6,LEAVES:15)
Block(3,27,-5,LEAVES:15)
Block(3,27,-4,LEAVES:15)
Block(3,28,7,LEAVES:15)
Block(3,28,8,LEAVES:15)
Block(3,28,18,LEAVES:15)
Block(3,28,19,LEAVES:15)
Block(3,29,15,LEAVES:15)
Block(3,29,16,LEAVES:15)
Block(3,29,17,LEAVES:15)
Block(3,30,3,LEAVES:15)
Block(3,31,8,LEAVES:15)
Block(3,32,8,LEAVES:15)
Block(3,32,9,LEAVES:15)
Block(4,27,20,LEAVES:15)
Block(4,28,8,LEAVES:15)
Block(4,28,18,LEAVES:15)
Block(4,28,19,LEAVES:15)
Block(4,31,1,LEAVES:15)
Block(4,31,2,LEAVES:15)
Block(4,31,11,LEAVES:15)
Block(4,32,9,LEAVES:15)
Block(4,32,10,LEAVES:15)
Block(5,28,8,LEAVES:15)
Block(5,29,8,LEAVES:15)
Block(5,31,1,LEAVES:15)
Block(5,31,2,LEAVES:15)
Block(5,31,12,LEAVES:15)
Block(5,32,10,LEAVES:15)
Block(5,32,11,LEAVES:15)
Block(6,29,8,LEAVES:15)
Block(6,29,9,LEAVES:15)
Block(6,31,2,LEAVES:15)
Block(6,31,13,LEAVES:15)
Block(6,32,0,LEAVES:15)
Block(6,32,1,LEAVES:15)
Block(6,32,10,LEAVES:15)
Block(6,32,11,LEAVES:15)
Block(6,32,12,LEAVES:15)
Block(7,29,7,LEAVES:15)
Block(7,29,8,LEAVES:15)
Block(7,29,9,LEAVES:15)
Block(7,31,2,LEAVES:15)
Block(7,31,14,LEAVES:15)
Block(7,32,0,LEAVES:15)
Block(7,32,1,LEAVES:15)
Block(7,32,11,LEAVES:15)
Block(7,32,12,LEAVES:15)
Block(7,32,13,LEAVES:15)
Block(8,29,7,LEAVES:15)
Block(8,29,8,LEAVES:15)
Block(8,29,9,LEAVES:15)
Block(8,31,1,LEAVES:15)
Block(8,31,13,LEAVES:15)
Block(8,31,14,LEAVES:15)
Block(8,32,-1,LEAVES:15)
Block(8,32,0,LEAVES:15)
Block(8,32,12,LEAVES:15)
Block(9,29,8,LEAVES:15)
Block(9,29,9,LEAVES:15)
Block(9,29,10,LEAVES:15)
Block(9,30,15,LEAVES:15)
Block(9,31,1,LEAVES:15)
Block(9,31,13,LEAVES:15)
Block(9,31,14,LEAVES:15)
Block(9,32,-1,LEAVES:15)
Block(9,32,0,LEAVES:15)
Block(10,28,8,LEAVES:15)
Block(10,28,9,LEAVES:15)
Block(10,28,10,LEAVES:15)
Block(10,29,9,LEAVES:15)
Block(10,31,-1,LEAVES:15)
Block(10,31,0,LEAVES:15)
Block(11,28,8,LEAVES:15)
Block(11,28,9,LEAVES:15)
Block(11,28,10,LEAVES:15)
Block(12,27,8,LEAVES:15)
Block(12,27,9,LEAVES:15)
Block(12,27,10,LEAVES:15)
Block(12,28,9,LEAVES:15)
Block(13,26,9,LEAVES:15)
Block(13,27,10,LEAVES:15)


#######################################################################
# +-----------------------------------------------------------------+ #
# |                             Entities                            | #
# +-----------------------------------------------------------------+ #
#######################################################################

# Entity() spawns an entity instead of a block. The entity is spawned only once when the BO3 is spawned.
# Entities are persistent by default so they don't de-spawn when no player is near, they are only unloaded.
# Usage: Entity(x,y,z,mobName,groupSize,NameTagOrNBTFileName) or Entity(x,y,z,mobName,groupSize)
# Use /tc entities or /otg entities to get a list of entities that can be used as mobName, this includes entities added by other mods.
# NameTagOrNBTFileName can be either a nametag for the mob or an nbt file (such as mymobinfo.nbt or mymobinfo.txt).
# When using a text file you can use the same mob spawning parameters used with the /summon command to equip the
# entity and give it custom attributes etc. You can copy the DATA part of a summon command including surrounding
# curly braces to a .txt file, for instance for: "/summon Skeleton x y z {DATA}"

#######################################################################
# +-----------------------------------------------------------------+ #
# |                            BO3 checks                           | #
# +-----------------------------------------------------------------+ #
#######################################################################

# Require a condition at a certain location in order for the BO3 to be spawned.
# BlockCheck(x,y,z,BlockName[,BlockName[,...]]) - one of the blocks must be at the location
# BlockCheckNot(x,y,z,BlockName[,BlockName[,...]]) - all the blocks must not be at the location
# LightCheck(x,y,z,minLightLevel,maxLightLevel) - light must be between min and max (inclusive)

# You can use "Solid" as a BlockName for matching all solid blocks or "All" to match all blocks that aren't air.

# Examples:
BlockCheck(0,-1,0,GRASS,DIRT,DIRT:2,SAND,STONE)
#   BlockCheck(0,-1,0,Solid)       Require any solid block just below the object
#   BlockCheck(0,-1,0,WOOL)        Require any type of wool just below the object
#   BlockCheck(0,-1,0,WOOL:0)      Require white wool just below the object
#   BlockCheckNot(0,-1,0,WOOL:0)   Require that there is no white wool below the object
#   LightCheck(0,0,0,0,1)          Require almost complete darkness just below the object

