#######################################################################
# +-----------------------------------------------------------------+ #
# |                            BO3 object                           | #
# +-----------------------------------------------------------------+ #
#######################################################################

# The descriptions in this file are accurate only for TerrainControl and OTG.
# For MCW and OTG+ these descriptions are only accurate if the BO3 is used as a CustomObject.
# MCW and OTG+ completely reimplemented CustomStructure, check the MCW/OTG+ documentation for more information.

# This is the config file of a custom object.
# If you add this object correctly to your BiomeConfigs, it will spawn in the world.

# This is the creator of this BO3 object
Author: Unknown

# A short description of this BO3 object
Description: This BO3 was converted from a schematic using OTGEdit. The author and description information of the schematic could not be found. If you know who the author of the schematic is then please add this information.

# The BO3 version, don't change this! It can be used by external applications to do a version check.
Version: 3

# The settings mode, WriteAll, WriteWithoutComments or WriteDisable. See WorldConfig.
SettingsMode: WriteDisable

#######################################################################
# +-----------------------------------------------------------------+ #
# |                          Main settings                          | #
# +-----------------------------------------------------------------+ #
#######################################################################

# This needs to be set to true to spawn the object in the Tree and Sapling resources.
Tree: true

# The frequency of the BO3 from 1 to 200. Tries this many times to spawn this BO3 when using the CustomObject(...) resource.
# Ignored by Tree(..), Sapling(..) and CustomStructure(..)
Frequency: 40

# The rarity of the BO3 from 0 to 100. Each spawn attempt has rarity% chance to succeed when using the CustomObject(...) resource.
# Ignored by Tree(..), Sapling(..) and CustomStructure(..)
Rarity: 100.0

# If you set this to true, the BO3 will be placed with a random rotation.
RotateRandomly: true

# The spawn height of the BO3 - randomY, highestBlock or highestSolidBlock.
SpawnHeight: highestSolidBlock
SpawnHeightOffset: -2
# The height limits for the BO3.
MinHeight: 0

MaxHeight: 69

# Objects can have other objects attached to it: branches. Branches can also
# have branches attached to it, which can also have branches, etc. This is the
# maximum branch depth for this objects.
MaxBranchDepth: 10

# When spawned with the UseWorld keyword, this BO3 should NOT spawn in the following biomes.
# If you writer.write the BO3 name directly in the BiomeConfigs, this will be ignored.
ExcludedBiomes: All

# To optimise this BO3 for faster loading times you can use Notepad++ to find/replace comments and abbreviate things.
# Notepad++ find/replace with regex:
# Find: ^[#;].* replace to nothing removes all lines starting with # 
# Find: ^\s*$ replace to nothing removes most empty lines 
# Notepad++ find/replace without regex:
# *Warning: This will only work for OTG 1.10.2 v21 / OTG 1.11.2 v6 or higher. B( is not recognised by lower versions.
# Find: Block( replace to B(

#######################################################################
# +-----------------------------------------------------------------+ #
# |                      Source block settings                      | #
# +-----------------------------------------------------------------+ #
#######################################################################

# The block(s) the BO3 should spawn in.
SourceBlocks: AIR,GRASS,DIRT

# The maximum percentage of the BO3 that can be outside the SourceBlock.
# The BO3 won't be placed on a location with more blocks outside the SourceBlock than this percentage.
MaxPercentageOutsideSourceBlock: 0

# What to do when a block is about to be placed outside the SourceBlock? (dontPlace, placeAnyway)
OutsideSourceBlock: dontPlace

#######################################################################
# +-----------------------------------------------------------------+ #
# |                              Blocks                             | #
# +-----------------------------------------------------------------+ #
#######################################################################

# All the blocks used in the BO3 are listed here. Possible blocks:
# Block(x,y,z,id[.data][,nbtfile.nbt) or B(x,y,z,id[.data][,nbtfile.nbt)
# RandomBlock(x,y,z,id[:data][,nbtfile.nbt],chance[,id[:data][,nbtfile.nbt],chance[,...]])
# So RandomBlock(0,0,0,CHEST,chest.nbt,50,CHEST,anotherchest.nbt,100) will spawn a chest at
# the BO3 origin, and give it a 50% chance to have the contents of chest.nbt, or, if that
# fails, a 100% percent chance to have the contents of anotherchest.nbt.

Block(-7,29,0,LEAVES:15)
Block(-7,29,1,LEAVES:15)
Block(-6,27,9,LEAVES:15)
Block(-6,27,10,LEAVES:15)
Block(-6,29,0,LEAVES:15)
Block(-6,29,1,LEAVES:15)
Block(-6,30,1,LEAVES:15)
Block(-6,30,2,LEAVES:15)
Block(-5,26,-1,LEAVES:15)
Block(-5,27,8,LEAVES:15)
Block(-5,27,9,LEAVES:15)
Block(-5,27,10,LEAVES:15)
Block(-5,30,1,LEAVES:15)
Block(-5,30,2,LEAVES:15)
Block(-5,30,3,LEAVES:15)
Block(-5,34,9,LEAVES:15)
Block(-4,23,14,LEAVES:15)
Block(-4,24,13,LEAVES:15)
Block(-4,26,-2,LEAVES:15)
Block(-4,26,-1,LEAVES:15)
Block(-4,26,0,LEAVES:15)
Block(-4,27,9,LEAVES:15)
Block(-4,27,10,LEAVES:15)
Block(-4,28,7,LEAVES:15)
Block(-4,28,8,LEAVES:15)
Block(-4,28,9,LEAVES:15)
Block(-4,30,1,LEAVES:15)
Block(-4,30,2,LEAVES:15)
Block(-4,31,2,LEAVES:15)
Block(-4,31,3,LEAVES:15)
Block(-4,34,8,LEAVES:15)
Block(-4,34,9,LEAVES:15)
Block(-4,34,10,LEAVES:15)
Block(-3,23,14,LEAVES:15)
Block(-3,24,13,LEAVES:15)
Block(-3,24,14,LEAVES:15)
Block(-3,25,12,LEAVES:15)
Block(-3,26,-1,LEAVES:15)
Block(-3,26,0,LEAVES:15)
Block(-3,27,-1,LEAVES:15)
Block(-3,27,0,LEAVES:15)
Block(-3,27,1,LEAVES:15)
Block(-3,28,7,LEAVES:15)
Block(-3,28,8,LEAVES:15)
Block(-3,28,9,LEAVES:15)
Block(-3,31,1,LEAVES:15)
Block(-3,31,2,LEAVES:15)
Block(-3,31,3,LEAVES:15)
Block(-3,34,8,LEAVES:15)
Block(-3,34,9,LEAVES:15)
Block(-3,34,10,LEAVES:15)
Block(-2,24,13,LEAVES:15)
Block(-2,24,14,LEAVES:15)
Block(-2,25,11,LEAVES:15)
Block(-2,25,12,LEAVES:15)
Block(-2,25,13,LEAVES:15)
Block(-2,27,-1,LEAVES:15)
Block(-2,27,0,LEAVES:15)
Block(-2,28,0,LEAVES:15)
Block(-2,28,1,LEAVES:15)
Block(-2,28,2,LEAVES:15)
Block(-2,28,6,LEAVES:15)
Block(-2,28,7,LEAVES:15)
Block(-2,28,8,LEAVES:15)
Block(-2,28,9,LEAVES:15)
Block(-2,28,14,LEAVES:15)
Block(-2,28,15,LEAVES:15)
Block(-2,29,13,LEAVES:15)
Block(-2,31,2,LEAVES:15)
Block(-2,31,3,LEAVES:15)
Block(-2,31,4,LEAVES:15)
Block(-2,32,-3,LEAVES:15)
Block(-2,32,-2,LEAVES:15)
Block(-2,32,-1,LEAVES:15)
Block(-2,33,8,LEAVES:15)
Block(-2,33,9,LEAVES:15)
Block(-2,33,10,LEAVES:15)
Block(-2,34,9,LEAVES:15)
Block(-2,38,3,LEAVES:15)
Block(-2,38,4,LEAVES:15)
Block(-1,25,12,LEAVES:15)
Block(-1,25,13,LEAVES:15)
Block(-1,26,11,LEAVES:15)
Block(-1,26,12,LEAVES:15)
Block(-1,28,0,LEAVES:15)
Block(-1,28,1,LEAVES:15)
Block(-1,28,2,LEAVES:15)
Block(-1,28,3,LEAVES:15)
Block(-1,28,6,LEAVES:15)
Block(-1,28,7,LEAVES:15)
Block(-1,28,8,LEAVES:15)
Block(-1,28,14,LEAVES:15)
Block(-1,28,15,LEAVES:15)
Block(-1,29,13,LEAVES:15)
Block(-1,29,14,LEAVES:15)
Block(-1,30,11,LEAVES:15)
Block(-1,30,12,LEAVES:15)
Block(-1,31,2,LEAVES:15)
Block(-1,31,3,LEAVES:15)
Block(-1,31,4,LEAVES:15)
Block(-1,32,-3,LEAVES:15)
Block(-1,32,-2,LEAVES:15)
Block(-1,32,-1,LEAVES:15)
Block(-1,33,-1,LEAVES:15)
Block(-1,33,0,LEAVES:15)
Block(-1,33,7,LEAVES:15)
Block(-1,33,8,LEAVES:15)
Block(-1,33,9,LEAVES:15)
Block(-1,37,4,LEAVES:15)
Block(-1,37,5,LEAVES:15)
Block(-1,38,3,LEAVES:15)
Block(-1,38,4,LEAVES:15)
Block(0,24,-3,LEAVES:15)
Block(0,24,-2,LEAVES:15)
Block(0,25,-2,LEAVES:15)
Block(0,25,-1,LEAVES:15)
Block(0,25,0,LEAVES:15)
Block(0,26,10,LEAVES:15)
Block(0,26,11,LEAVES:15)
Block(0,26,12,LEAVES:15)
Block(0,27,4,LEAVES:15)
Block(0,27,7,LEAVES:15)
Block(0,28,1,LEAVES:15)
Block(0,28,2,LEAVES:15)
Block(0,28,3,LEAVES:15)
Block(0,28,7,LEAVES:15)
Block(0,29,12,LEAVES:15)
Block(0,29,13,LEAVES:15)
Block(0,29,14,LEAVES:15)
Block(0,30,10,LEAVES:15)
Block(0,30,11,LEAVES:15)
Block(0,30,12,LEAVES:15)
Block(0,31,3,LEAVES:15)
Block(0,31,4,LEAVES:15)
Block(0,32,6,LEAVES:15)
Block(0,32,7,LEAVES:15)
Block(0,32,8,LEAVES:15)
Block(0,32,9,LEAVES:15)
Block(0,33,-2,LEAVES:15)
Block(0,33,-1,LEAVES:15)
Block(0,33,0,LEAVES:15)
Block(0,33,1,LEAVES:15)
Block(0,33,2,LEAVES:15)
Block(0,33,8,LEAVES:15)
Block(0,35,6,LEAVES:15)
Block(0,36,5,LEAVES:15)
Block(0,36,6,LEAVES:15)
Block(0,37,3,LEAVES:15)
Block(0,37,4,LEAVES:15)
Block(0,37,5,LEAVES:15)
Block(1,24,-3,LEAVES:15)
Block(1,25,-2,LEAVES:15)
Block(1,25,-1,LEAVES:15)
Block(1,25,0,LEAVES:15)
Block(1,26,1,LEAVES:15)
Block(1,26,10,LEAVES:15)
Block(1,26,11,LEAVES:15)
Block(1,27,4,LEAVES:15)
Block(1,27,6,LEAVES:15)
Block(1,27,7,LEAVES:15)
Block(1,27,9,LEAVES:15)
Block(1,27,10,LEAVES:15)
Block(1,28,2,LEAVES:15)
Block(1,28,3,LEAVES:15)
Block(1,28,4,LEAVES:15)
Block(1,29,13,LEAVES:15)
Block(1,30,4,LEAVES:15)
Block(1,30,10,LEAVES:15)
Block(1,30,11,LEAVES:15)
Block(1,30,12,LEAVES:15)
Block(1,31,4,LEAVES:15)
Block(1,31,6,LEAVES:15)
Block(1,31,7,LEAVES:15)
Block(1,31,8,LEAVES:15)
Block(1,32,7,LEAVES:15)
Block(1,33,-1,LEAVES:15)
Block(1,33,0,LEAVES:15)
Block(1,33,1,LEAVES:15)
Block(1,33,2,LEAVES:15)
Block(1,33,3,LEAVES:15)
Block(1,34,7,LEAVES:15)
Block(1,35,5,LEAVES:15)
Block(1,35,6,LEAVES:15)
Block(1,36,4,LEAVES:15)
Block(1,36,5,LEAVES:15)
Block(2,25,-2,LEAVES:15)
Block(2,25,-1,LEAVES:15)
Block(2,25,0,LEAVES:15)
Block(2,26,0,LEAVES:15)
Block(2,26,1,LEAVES:15)
Block(2,26,2,LEAVES:15)
Block(2,26,5,LEAVES:15)
Block(2,26,6,LEAVES:15)
Block(2,27,4,LEAVES:15)
Block(2,27,5,LEAVES:15)
Block(2,27,6,LEAVES:15)
Block(2,27,8,LEAVES:15)
Block(2,27,9,LEAVES:15)
Block(2,29,5,LEAVES:15)
Block(2,29,8,LEAVES:15)
Block(2,29,9,LEAVES:15)
Block(2,30,4,LEAVES:15)
Block(2,30,5,LEAVES:15)
Block(2,30,6,LEAVES:15)
Block(2,30,7,LEAVES:15)
Block(2,30,9,LEAVES:15)
Block(2,30,10,LEAVES:15)
Block(2,30,11,LEAVES:15)
Block(2,31,7,LEAVES:15)
Block(2,32,3,LEAVES:15)
Block(2,33,1,LEAVES:15)
Block(2,33,2,LEAVES:15)
Block(2,33,3,LEAVES:15)
Block(2,33,6,LEAVES:15)
Block(2,34,6,LEAVES:15)
Block(2,35,5,LEAVES:15)
Block(3,0,6,162:12)
Block(3,1,6,162:12)
Block(3,2,6,162:12)
Block(3,3,6,162:12)
Block(3,4,6,162:12)
Block(3,5,6,162:12)
Block(3,6,6,162:12)
Block(3,7,6,162:12)
Block(3,8,6,162:12)
Block(3,9,6,162:12)
Block(3,10,6,162:12)
Block(3,24,6,LEAVES:15)
Block(3,25,5,LEAVES:15)
Block(3,25,6,LEAVES:15)
Block(3,26,0,LEAVES:15)
Block(3,26,1,LEAVES:15)
Block(3,26,2,LEAVES:15)
Block(3,26,3,LEAVES:15)
Block(3,26,5,LEAVES:15)
Block(3,26,6,LEAVES:15)
Block(3,26,7,LEAVES:15)
Block(3,27,7,LEAVES:15)
Block(3,27,8,LEAVES:15)
Block(3,27,9,LEAVES:15)
Block(3,28,5,LEAVES:15)
Block(3,28,6,LEAVES:15)
Block(3,28,7,LEAVES:15)
Block(3,28,8,LEAVES:15)
Block(3,29,5,LEAVES:15)
Block(3,29,6,LEAVES:15)
Block(3,29,8,LEAVES:15)
Block(3,30,6,LEAVES:15)
Block(3,31,4,LEAVES:15)
Block(3,31,6,LEAVES:15)
Block(3,32,3,LEAVES:15)
Block(3,32,4,LEAVES:15)
Block(3,32,6,LEAVES:15)
Block(3,33,6,LEAVES:15)
Block(4,0,5,162:12)
Block(4,0,6,162:12)
Block(4,0,7,162:12)
Block(4,1,5,162:12)
Block(4,1,6,162:12)
Block(4,1,7,162:12)
Block(4,2,5,162:12)
Block(4,2,6,162:12)
Block(4,2,7,162:12)
Block(4,3,5,162:12)
Block(4,3,6,162:12)
Block(4,3,7,162:12)
Block(4,4,5,162:12)
Block(4,4,6,162:12)
Block(4,4,7,162:12)
Block(4,5,5,162:12)
Block(4,5,6,162:12)
Block(4,5,7,162:12)
Block(4,6,5,162:12)
Block(4,6,6,162:12)
Block(4,6,7,162:12)
Block(4,7,5,162:12)
Block(4,7,6,162:12)
Block(4,7,7,162:12)
Block(4,8,5,162:12)
Block(4,8,6,162:12)
Block(4,9,5,162:12)
Block(4,9,6,162:12)
Block(4,10,5,162:12)
Block(4,10,6,162:12)
Block(4,11,5,162:12)
Block(4,11,6,162:12)
Block(4,12,5,162:12)
Block(4,12,6,162:12)
Block(4,13,5,162:12)
Block(4,13,6,162:12)
Block(4,14,5,162:12)
Block(4,14,6,162:12)
Block(4,15,5,162:12)
Block(4,15,6,162:12)
Block(4,16,5,162:12)
Block(4,16,6,162:12)
Block(4,17,5,162:12)
Block(4,17,6,162:12)
Block(4,18,5,162:12)
Block(4,18,6,162:12)
Block(4,19,5,162:12)
Block(4,19,6,162:12)
Block(4,20,6,162:12)
Block(4,21,6,162:12)
Block(4,22,6,162:12)
Block(4,23,6,162:12)
Block(4,24,5,LEAVES:15)
Block(4,24,6,162:12)
Block(4,24,7,LEAVES:15)
Block(4,25,5,LEAVES:15)
Block(4,25,6,162:12)
Block(4,25,7,LEAVES:15)
Block(4,26,3,LEAVES:15)
Block(4,26,4,LEAVES:15)
Block(4,26,5,LEAVES:15)
Block(4,26,6,162:12)
Block(4,26,7,LEAVES:15)
Block(4,26,8,LEAVES:15)
Block(4,27,4,LEAVES:15)
Block(4,27,5,LEAVES:15)
Block(4,27,6,LEAVES:15)
Block(4,27,7,LEAVES:15)
Block(4,27,8,LEAVES:15)
Block(4,27,9,LEAVES:15)
Block(4,27,10,LEAVES:15)
Block(4,27,11,LEAVES:15)
Block(4,28,1,LEAVES:15)
Block(4,28,4,LEAVES:15)
Block(4,28,5,LEAVES:15)
Block(4,28,6,LEAVES:15)
Block(4,28,7,LEAVES:15)
Block(4,29,5,LEAVES:15)
Block(4,29,6,LEAVES:15)
Block(4,29,7,LEAVES:15)
Block(4,29,8,LEAVES:15)
Block(4,30,4,LEAVES:15)
Block(4,30,5,LEAVES:15)
Block(4,30,6,LEAVES:15)
Block(4,30,8,LEAVES:15)
Block(4,31,4,LEAVES:15)
Block(4,31,6,LEAVES:15)
Block(4,31,9,LEAVES:15)
Block(4,32,6,LEAVES:15)
Block(4,32,7,LEAVES:15)
Block(4,32,10,LEAVES:15)
Block(5,0,6,162:12)
Block(5,1,6,162:12)
Block(5,2,6,162:12)
Block(5,3,6,162:12)
Block(5,4,6,162:12)
Block(5,5,6,162:12)
Block(5,6,6,162:12)
Block(5,7,6,162:12)
Block(5,8,6,162:12)
Block(5,9,6,162:12)
Block(5,10,6,162:12)
Block(5,11,6,162:12)
Block(5,12,6,162:12)
Block(5,13,6,162:12)
Block(5,14,6,162:12)
Block(5,23,6,LEAVES:15)
Block(5,24,6,LEAVES:15)
Block(5,25,6,LEAVES:15)
Block(5,25,7,LEAVES:15)
Block(5,26,-2,LEAVES:15)
Block(5,26,6,LEAVES:15)
Block(5,26,7,LEAVES:15)
Block(5,26,13,LEAVES:15)
Block(5,26,14,LEAVES:15)
Block(5,27,-1,LEAVES:15)
Block(5,27,6,LEAVES:15)
Block(5,27,7,LEAVES:15)
Block(5,27,9,LEAVES:15)
Block(5,27,10,LEAVES:15)
Block(5,27,11,LEAVES:15)
Block(5,27,12,LEAVES:15)
Block(5,28,0,LEAVES:15)
Block(5,28,1,LEAVES:15)
Block(5,28,2,LEAVES:15)
Block(5,28,3,LEAVES:15)
Block(5,28,4,LEAVES:15)
Block(5,28,5,LEAVES:15)
Block(5,29,5,LEAVES:15)
Block(5,30,5,LEAVES:15)
Block(5,30,9,LEAVES:15)
Block(5,31,9,LEAVES:15)
Block(5,32,7,LEAVES:15)
Block(5,32,9,LEAVES:15)
Block(5,32,10,LEAVES:15)
Block(5,33,7,LEAVES:15)
Block(5,33,11,LEAVES:15)
Block(5,34,7,LEAVES:15)
Block(5,34,8,LEAVES:15)
Block(5,35,8,LEAVES:15)
Block(6,25,-3,LEAVES:15)
Block(6,26,-2,LEAVES:15)
Block(6,26,7,LEAVES:15)
Block(6,26,12,LEAVES:15)
Block(6,26,13,LEAVES:15)
Block(6,26,14,LEAVES:15)
Block(6,26,15,LEAVES:15)
Block(6,27,-2,LEAVES:15)
Block(6,27,-1,LEAVES:15)
Block(6,27,0,LEAVES:15)
Block(6,27,5,LEAVES:15)
Block(6,27,6,LEAVES:15)
Block(6,27,10,LEAVES:15)
Block(6,27,11,LEAVES:15)
Block(6,27,12,LEAVES:15)
Block(6,28,0,LEAVES:15)
Block(6,28,1,LEAVES:15)
Block(6,28,2,LEAVES:15)
Block(6,28,5,LEAVES:15)
Block(6,28,6,LEAVES:15)
Block(6,29,4,LEAVES:15)
Block(6,29,5,LEAVES:15)
Block(6,29,7,LEAVES:15)
Block(6,30,5,LEAVES:15)
Block(6,31,5,LEAVES:15)
Block(6,32,4,LEAVES:15)
Block(6,32,5,LEAVES:15)
Block(6,32,9,LEAVES:15)
Block(6,32,10,LEAVES:15)
Block(6,33,7,LEAVES:15)
Block(6,33,10,LEAVES:15)
Block(6,33,11,LEAVES:15)
Block(6,33,12,LEAVES:15)
Block(6,33,13,LEAVES:15)
Block(6,34,7,LEAVES:15)
Block(6,35,7,LEAVES:15)
Block(6,35,8,LEAVES:15)
Block(6,36,8,LEAVES:15)
Block(6,36,9,LEAVES:15)
Block(6,37,8,LEAVES:15)
Block(6,37,9,LEAVES:15)
Block(7,25,-4,LEAVES:15)
Block(7,25,-3,LEAVES:15)
Block(7,25,14,LEAVES:15)
Block(7,25,15,LEAVES:15)
Block(7,26,-3,LEAVES:15)
Block(7,26,-2,LEAVES:15)
Block(7,26,7,LEAVES:15)
Block(7,26,12,LEAVES:15)
Block(7,26,13,LEAVES:15)
Block(7,26,14,LEAVES:15)
Block(7,27,-1,LEAVES:15)
Block(7,27,0,LEAVES:15)
Block(7,27,5,LEAVES:15)
Block(7,27,7,LEAVES:15)
Block(7,27,8,LEAVES:15)
Block(7,28,1,LEAVES:15)
Block(7,28,5,LEAVES:15)
Block(7,28,6,LEAVES:15)
Block(7,29,4,LEAVES:15)
Block(7,29,6,LEAVES:15)
Block(7,30,3,LEAVES:15)
Block(7,30,4,LEAVES:15)
Block(7,30,7,LEAVES:15)
Block(7,30,8,LEAVES:15)
Block(7,32,4,LEAVES:15)
Block(7,33,3,LEAVES:15)
Block(7,33,4,LEAVES:15)
Block(7,33,10,LEAVES:15)
Block(7,33,11,LEAVES:15)
Block(7,33,12,LEAVES:15)
Block(7,33,13,LEAVES:15)
Block(7,34,2,LEAVES:15)
Block(7,34,3,LEAVES:15)
Block(7,34,14,LEAVES:15)
Block(7,36,8,LEAVES:15)
Block(7,37,8,LEAVES:15)
Block(7,38,8,LEAVES:15)
Block(7,38,9,LEAVES:15)
Block(8,25,-3,LEAVES:15)
Block(8,25,14,LEAVES:15)
Block(8,25,15,LEAVES:15)
Block(8,26,-2,LEAVES:15)
Block(8,27,5,LEAVES:15)
Block(8,27,8,LEAVES:15)
Block(8,28,5,LEAVES:15)
Block(8,28,8,LEAVES:15)
Block(8,29,6,LEAVES:15)
Block(8,29,7,LEAVES:15)
Block(8,30,2,LEAVES:15)
Block(8,30,3,LEAVES:15)
Block(8,30,6,LEAVES:15)
Block(8,30,7,LEAVES:15)
Block(8,30,8,LEAVES:15)
Block(8,31,7,LEAVES:15)
Block(8,31,8,LEAVES:15)
Block(8,33,11,LEAVES:15)
Block(8,33,12,LEAVES:15)
Block(8,33,13,LEAVES:15)
Block(8,34,2,LEAVES:15)
Block(8,34,3,LEAVES:15)
Block(8,34,13,LEAVES:15)
Block(8,34,14,LEAVES:15)
Block(8,34,15,LEAVES:15)
Block(8,35,1,LEAVES:15)
Block(8,35,2,LEAVES:15)
Block(8,37,8,LEAVES:15)
Block(8,38,9,LEAVES:15)
Block(9,28,5,LEAVES:15)
Block(9,28,8,LEAVES:15)
Block(9,28,9,LEAVES:15)
Block(9,30,2,LEAVES:15)
Block(9,30,3,LEAVES:15)
Block(9,31,1,LEAVES:15)
Block(9,31,2,LEAVES:15)
Block(9,31,6,LEAVES:15)
Block(9,31,7,LEAVES:15)
Block(9,32,7,LEAVES:15)
Block(9,32,8,LEAVES:15)
Block(9,33,13,LEAVES:15)
Block(9,34,14,LEAVES:15)
Block(9,35,0,LEAVES:15)
Block(9,35,1,LEAVES:15)
Block(9,35,2,LEAVES:15)
Block(9,35,3,LEAVES:15)
Block(10,28,3,LEAVES:15)
Block(10,28,4,LEAVES:15)
Block(10,28,5,LEAVES:15)
Block(10,28,9,LEAVES:15)
Block(10,28,10,LEAVES:15)
Block(10,28,11,LEAVES:15)
Block(10,31,0,LEAVES:15)
Block(10,31,1,LEAVES:15)
Block(10,31,2,LEAVES:15)
Block(10,32,7,LEAVES:15)
Block(10,32,8,LEAVES:15)
Block(10,32,9,LEAVES:15)
Block(10,35,-1,LEAVES:15)
Block(10,35,0,LEAVES:15)
Block(10,35,1,LEAVES:15)
Block(10,35,2,LEAVES:15)
Block(11,28,3,LEAVES:15)
Block(11,28,4,LEAVES:15)
Block(11,28,5,LEAVES:15)
Block(11,28,9,LEAVES:15)
Block(11,28,10,LEAVES:15)
Block(11,28,11,LEAVES:15)
Block(11,31,0,LEAVES:15)
Block(11,31,1,LEAVES:15)
Block(11,31,2,LEAVES:15)
Block(11,32,7,LEAVES:15)
Block(11,32,8,LEAVES:15)
Block(11,33,8,LEAVES:15)
Block(11,33,9,LEAVES:15)
Block(11,34,-2,LEAVES:15)
Block(11,34,-1,LEAVES:15)
Block(11,35,-1,LEAVES:15)
Block(11,35,0,LEAVES:15)
Block(11,35,1,LEAVES:15)
Block(12,27,2,LEAVES:15)
Block(12,27,3,LEAVES:15)
Block(12,27,5,LEAVES:15)
Block(12,28,3,LEAVES:15)
Block(12,28,4,LEAVES:15)
Block(12,28,9,LEAVES:15)
Block(12,28,10,LEAVES:15)
Block(12,28,11,LEAVES:15)
Block(12,28,12,LEAVES:15)
Block(12,30,-1,LEAVES:15)
Block(12,30,0,LEAVES:15)
Block(12,31,0,LEAVES:15)
Block(12,31,1,LEAVES:15)
Block(12,33,8,LEAVES:15)
Block(12,33,9,LEAVES:15)
Block(12,33,10,LEAVES:15)
Block(12,34,-2,LEAVES:15)
Block(12,34,-1,LEAVES:15)
Block(12,34,0,LEAVES:15)
Block(13,27,2,LEAVES:15)
Block(13,27,3,LEAVES:15)
Block(13,27,4,LEAVES:15)
Block(13,27,11,LEAVES:15)
Block(13,28,10,LEAVES:15)
Block(13,28,11,LEAVES:15)
Block(13,28,12,LEAVES:15)
Block(13,30,0,LEAVES:15)
Block(13,33,9,LEAVES:15)
Block(13,33,10,LEAVES:15)
Block(13,34,-2,LEAVES:15)
Block(13,34,-1,LEAVES:15)
Block(14,27,2,LEAVES:15)
Block(14,27,3,LEAVES:15)
Block(14,27,4,LEAVES:15)
Block(14,27,10,LEAVES:15)
Block(14,27,11,LEAVES:15)
Block(14,27,12,LEAVES:15)
Block(15,26,3,LEAVES:15)
Block(15,27,11,LEAVES:15)


#######################################################################
# +-----------------------------------------------------------------+ #
# |                             Entities                            | #
# +-----------------------------------------------------------------+ #
#######################################################################

# Entity() spawns an entity instead of a block. The entity is spawned only once when the BO3 is spawned.
# Entities are persistent by default so they don't de-spawn when no player is near, they are only unloaded.
# Usage: Entity(x,y,z,mobName,groupSize,NameTagOrNBTFileName) or Entity(x,y,z,mobName,groupSize)
# Use /tc entities or /otg entities to get a list of entities that can be used as mobName, this includes entities added by other mods.
# NameTagOrNBTFileName can be either a nametag for the mob or an nbt file (such as mymobinfo.nbt or mymobinfo.txt).
# When using a text file you can use the same mob spawning parameters used with the /summon command to equip the
# entity and give it custom attributes etc. You can copy the DATA part of a summon command including surrounding
# curly braces to a .txt file, for instance for: "/summon Skeleton x y z {DATA}"

#######################################################################
# +-----------------------------------------------------------------+ #
# |                            BO3 checks                           | #
# +-----------------------------------------------------------------+ #
#######################################################################

# Require a condition at a certain location in order for the BO3 to be spawned.
# BlockCheck(x,y,z,BlockName[,BlockName[,...]]) - one of the blocks must be at the location
# BlockCheckNot(x,y,z,BlockName[,BlockName[,...]]) - all the blocks must not be at the location
# LightCheck(x,y,z,minLightLevel,maxLightLevel) - light must be between min and max (inclusive)

# You can use "Solid" as a BlockName for matching all solid blocks or "All" to match all blocks that aren't air.

# Examples:
BlockCheck(0,-1,0,GRASS,DIRT,DIRT:2,SAND,STONE)
#   BlockCheck(0,-1,0,Solid)       Require any solid block just below the object
#   BlockCheck(0,-1,0,WOOL)        Require any type of wool just below the object
#   BlockCheck(0,-1,0,WOOL:0)      Require white wool just below the object
#   BlockCheckNot(0,-1,0,WOOL:0)   Require that there is no white wool below the object
#   LightCheck(0,0,0,0,1)          Require almost complete darkness just below the object

