#######################################################################
# +-----------------------------------------------------------------+ #
# |                            BO3 object                           | #
# +-----------------------------------------------------------------+ #
#######################################################################

# This is the config file of a custom object.
# If you add this object correctly to your BiomeConfigs, it will spawn in the world.

# This is the creator of this BO3 object
Author: BO3 BulkEdit (by LanToaster)

# A short description of this BO3 object
Description: This Object was Created with BO3_BulkEdit

# The BO3 version, don't change this! It can be used by external applications to do a version check.
Version: 3

# The settings mode, WriteAll, WriteWithoutComments or WriteDisable. See WorldConfig.
SettingsMode: WriteDisable


#######################################################################
# +-----------------------------------------------------------------+ #
# |                          Main settings                          | #
# +-----------------------------------------------------------------+ #
#######################################################################

# This needs to be set to true to spawn the object in the Tree and Sapling resources.
Tree: true

# The frequency of the BO3 from 1 to 200. Tries this many times to spawn this BO3 when using the CustomObject(...) resource.
# Ignored by Tree(..), Sapling(..) and CustomStructure(..)
Frequency: 200

# The rarity of the BO3 from 0 to 100. Each spawn attempt has rarity% chance to succeed when using the CustomObject(...) resource.
# Ignored by Tree(..), Sapling(..) and CustomStructure(..)
Rarity: 100

# If you set this to true, the BO3 will be placed with a random rotation.
RotateRandomly: True

# The spawn height of the BO3 - randomY, highestBlock or highestSolidBlock.
SpawnHeight: highestSolidBlock
SpawnHeightOffset: -1
# The height limits for the BO3.
MinHeight: 58

MaxHeight: 70

# Objects can have other objects attacthed to it: branches. Branches can also
# have branches attached to it, which can also have branches, etc. This is the
# maximum branch depth for this objects.
MaxBranchDepth: 10

# When spawned with the UseWorld keyword, this BO3 should NOT spawn in the following biomes.
# If you writer.write the BO3 name directly in the BiomeConfigs, this will be ignored.
ExcludedBiomes: All


#######################################################################
# +-----------------------------------------------------------------+ #
# |                      Source block settings                      | #
# +-----------------------------------------------------------------+ #
#######################################################################

# The block(s) the BO3 should spawn in.
SourceBlocks: AIR,GRASS,DIRT,SAND,CLAY,GRAVEL,STONE

# The maximum percentage of the BO3 that can be outside the SourceBlock.
# The BO3 won't be placed on a location with more blocks outside the SourceBlock than this percentage.
MaxPercentageOutsideSourceBlock: 5

# What to do when a block is about to be placed outside the SourceBlock? (dontPlace, placeAnyway)
OutsideSourceBlock: placeAnyway


#######################################################################
# +-----------------------------------------------------------------+ #
# |                              Blocks                             | #
# +-----------------------------------------------------------------+ #
#######################################################################

# All the blocks used in the BO3 are listed here. Possible blocks:
# Block(x,y,z,id[.data][,nbtfile.nbt)
# RandomBlock(x,y,z,id[:data][,nbtfile.nbt],chance[,id[:data][,nbtfile.nbt],chance[,...]])
# So RandomBlock(0,0,0,CHEST,chest.nbt,50,CHEST,anotherchest.nbt,100) will spawn a chest at
# the BO3 origin, and give it a 50% chance to have the contents of chest.nbt, or, if that
# fails, a 100% percent chance to have the contents of anotherchest.nbt.
Block(0,0,-2,LOG:15)
Block(-1,0,-1,LOG:15)
Block(-2,0,0,LOG:15)
Block(-3,0,1,LOG:15)
Block(-5,0,2,LOG:15)
Block(-4,0,2,LOG:15)
Block(-3,0,2,LOG:15)
Block(-2,0,2,LOG:15)
Block(-6,0,3,LOG:15)
Block(-3,0,3,LOG:15)
Block(-1,0,3,LOG:15)
Block(-3,0,4,LOG:15)
Block(0,0,4,LOG:15)
Block(-4,0,5,LOG:15)
Block(-4,0,6,LOG:15)
Block(-2,1,0,LOG:15)
Block(-3,1,1,LOG:15)
Block(-2,1,1,LOG:15)
Block(-4,1,2,LOG:15)
Block(-3,1,2,LOG:15)
Block(-2,1,2,LOG:15)
Block(-3,1,3,LOG:15)
Block(-3,1,4,VINE:4)
Block(-3,2,1,LOG:15)
Block(-2,2,1,LOG:15)
Block(-4,2,2,LOG:15)
Block(-3,2,2,LOG:15)
Block(-2,2,2,LOG:15)
Block(-3,2,3,LOG:15)
Block(-3,2,4,VINE:4)
Block(-2,2,3,VINE:4)
Block(-4,2,3,VINE:8)
Block(-3,3,1,LOG:15)
Block(-3,3,2,LOG:15)
Block(-2,3,2,LOG:15)
Block(-3,3,3,LOG:15)
Block(-2,3,3,VINE:4)
Block(-1,3,2,VINE:2)
Block(-3,4,1,LOG:15)
Block(-3,4,2,LOG:15)
Block(-2,4,2,LOG:15)
Block(-2,4,3,VINE:4)
Block(-3,5,2,LOG:15)
Block(-2,5,2,LOG:15)
Block(-2,5,3,VINE:4)
Block(-1,5,2,VINE:2)
Block(-4,5,2,VINE:8)
Block(-3,6,2,LOG:15)
Block(-2,6,2,LOG:15)
Block(-3,6,3,VINE:4)
Block(-4,6,2,VINE:8)
Block(-3,7,2,LOG:15)
Block(-3,7,3,VINE:4)
Block(-3,7,1,VINE:1)
Block(-3,8,2,LOG:15)
Block(-3,8,3,VINE:4)
Block(-4,8,2,VINE:8)
Block(-3,8,1,VINE:1)
Block(-3,9,2,LOG:15)
Block(-3,9,3,VINE:4)
Block(-3,9,1,VINE:1)
Block(-3,10,2,LOG:15)
Block(-3,10,3,VINE:4)
Block(-4,10,2,VINE:8)
Block(-3,10,1,VINE:1)
Block(-3,11,2,LOG:15)
Block(-3,11,3,VINE:4)
Block(-3,12,2,LOG:15)
Block(-3,12,3,VINE:4)
Block(-2,12,2,VINE:2)
Block(-3,12,1,VINE:1)
Block(-3,13,2,LOG:15)
Block(-3,13,1,VINE:1)
Block(-3,14,2,LOG:15)
Block(-4,14,2,VINE:8)
Block(-3,14,1,VINE:1)
Block(-3,15,2,LOG:15)
Block(-4,15,2,VINE:8)
Block(-3,15,1,VINE:1)
Block(-3,16,2,LOG:15)
Block(-4,16,2,VINE:8)
Block(-3,16,1,VINE:1)
Block(-3,17,2,LOG:15)
Block(-4,17,2,VINE:8)
Block(-3,18,2,LOG:15)
Block(-3,19,2,LOG:15)
Block(-4,19,2,VINE:8)
Block(-2,20,0,LEAVES:7)
Block(-2,20,1,LOG:15)
Block(-1,20,1,LOG:15)
Block(0,20,1,LOG:15)
Block(-3,20,2,LOG:15)
Block(-4,20,2,VINE:8)
Block(-6,20,2,VINE:8)
Block(0,20,0,VINE:1)
Block(-1,20,0,VINE:1)
Block(-5,21,-7,LEAVES:7)
Block(-3,21,-1,LEAVES:7)
Block(-2,21,-1,LEAVES:7)
Block(-3,21,0,LEAVES:7)
Block(-2,21,0,LEAVES:7)
Block(-1,21,0,LOG:15)
Block(-3,21,1,LEAVES:7)
Block(-2,21,1,LEAVES:7)
Block(-1,21,1,LEAVES:7)
Block(1,21,1,LOG:15)
Block(-5,21,2,LOG:15)
Block(-4,21,2,LOG:15)
Block(-3,21,2,LOG:15)
Block(-2,21,2,LEAVES:7)
Block(-6,21,2,VINE:8)
Block(0,21,1,VINE:8)
Block(-6,22,-8,LEAVES:7)
Block(-5,22,-8,LEAVES:7)
Block(-4,22,-8,LEAVES:7)
Block(-6,22,-7,LEAVES:7)
Block(-5,22,-7,LEAVES:7)
Block(-4,22,-7,LEAVES:7)
Block(-6,22,-6,LEAVES:7)
Block(-5,22,-6,LEAVES:7)
Block(-4,22,-6,LEAVES:7)
Block(-3,22,-1,LEAVES:7)
Block(-2,22,-1,LEAVES:7)
Block(-1,22,-1,LEAVES:7)
Block(0,22,-1,LOG:15)
Block(-4,22,0,LEAVES:7)
Block(-3,22,0,LEAVES:7)
Block(-2,22,0,LEAVES:7)
Block(-1,22,0,LEAVES:7)
Block(0,22,0,LEAVES:7)
Block(-3,22,1,LEAVES:7)
Block(-2,22,1,LEAVES:7)
Block(-1,22,1,LEAVES:7)
Block(2,22,1,LOG:15)
Block(-6,22,2,LOG:15)
Block(-3,22,2,LEAVES:7)
Block(-2,22,2,LEAVES:7)
Block(-1,22,2,LEAVES:7)
Block(0,22,2,LEAVES:7)
Block(3,22,2,LOG:15)
Block(-2,22,3,LEAVES:7)
Block(-7,22,3,VINE:4)
Block(-3,22,-2,VINE:1)
Block(-5,22,-9,VINE:1)
Block(-5,23,-9,LEAVES:7)
Block(-6,23,-8,LEAVES:7)
Block(-5,23,-8,LEAVES:7)
Block(-4,23,-8,LEAVES:7)
Block(-7,23,-7,LEAVES:7)
Block(-6,23,-7,LEAVES:7)
Block(-5,23,-7,LEAVES:7)
Block(-4,23,-7,LEAVES:7)
Block(-3,23,-7,LEAVES:7)
Block(-6,23,-6,LEAVES:7)
Block(-5,23,-6,LEAVES:7)
Block(-4,23,-6,LEAVES:7)
Block(-5,23,-5,LEAVES:7)
Block(1,23,-2,LOG:15)
Block(-3,23,-1,LEAVES:7)
Block(-2,23,-1,LEAVES:7)
Block(-1,23,-1,LEAVES:7)
Block(-3,23,0,LEAVES:7)
Block(-2,23,0,LEAVES:7)
Block(-1,23,0,LEAVES:7)
Block(-3,23,1,LEAVES:7)
Block(-2,23,1,LEAVES:7)
Block(-1,23,1,LEAVES:7)
Block(0,23,1,LEAVES:7)
Block(3,23,1,LOG:15)
Block(-7,23,2,LOG:15)
Block(-3,23,2,LOG:15)
Block(-2,23,2,LEAVES:7)
Block(-1,23,2,LEAVES:7)
Block(0,23,2,LEAVES:7)
Block(1,23,2,LEAVES:7)
Block(0,23,3,LEAVES:7)
Block(3,23,3,LOG:15)
Block(-1,23,4,LOG:15)
Block(-3,23,11,LEAVES:7)
Block(0,23,11,LEAVES:7)
Block(-7,23,3,VINE:4)
Block(-6,23,2,VINE:2)
Block(0,23,-2,VINE:8)
Block(-3,23,-2,VINE:1)
Block(1,23,-3,VINE:1)
Block(-5,23,-10,VINE:1)
Block(-6,24,-9,LEAVES:7)
Block(-5,24,-9,LEAVES:7)
Block(-4,24,-9,LEAVES:7)
Block(-6,24,-8,LEAVES:7)
Block(-5,24,-8,LEAVES:7)
Block(-4,24,-8,LEAVES:7)
Block(0,24,-8,LEAVES:7)
Block(1,24,-8,LEAVES:7)
Block(2,24,-8,LEAVES:7)
Block(-6,24,-7,LEAVES:7)
Block(-5,24,-7,LEAVES:7)
Block(-4,24,-7,LEAVES:7)
Block(-1,24,-7,LEAVES:7)
Block(0,24,-7,LEAVES:7)
Block(1,24,-7,LEAVES:7)
Block(2,24,-7,LEAVES:7)
Block(3,24,-7,LEAVES:7)
Block(-6,24,-6,LEAVES:7)
Block(-5,24,-6,LEAVES:7)
Block(-4,24,-6,LEAVES:7)
Block(6,24,-5,LEAVES:7)
Block(2,24,-4,LOG:15)
Block(2,24,-3,LOG:15)
Block(-3,24,-1,LOG:15)
Block(4,24,-1,LOG:15)
Block(-11,24,0,LEAVES:7)
Block(-2,24,0,LEAVES:7)
Block(4,24,0,LOG:15)
Block(-4,24,1,LOG:15)
Block(4,24,1,LOG:15)
Block(-10,24,2,LEAVES:7)
Block(-9,24,2,LOG:15)
Block(-8,24,2,LOG:15)
Block(-3,24,2,LOG:15)
Block(0,24,2,LEAVES:7)
Block(-4,24,3,LOG:15)
Block(4,24,4,LOG:15)
Block(0,24,5,LOG:15)
Block(-10,24,6,LEAVES:7)
Block(-4,24,10,LEAVES:7)
Block(-3,24,10,LEAVES:7)
Block(-2,24,10,LEAVES:7)
Block(-1,24,10,LEAVES:7)
Block(0,24,10,LEAVES:7)
Block(1,24,10,LEAVES:7)
Block(-4,24,11,LEAVES:7)
Block(-3,24,11,LEAVES:7)
Block(-2,24,11,LEAVES:7)
Block(-1,24,11,LEAVES:7)
Block(0,24,11,LEAVES:7)
Block(1,24,11,LEAVES:7)
Block(-4,24,12,LEAVES:7)
Block(-3,24,12,LEAVES:7)
Block(-2,24,12,LEAVES:7)
Block(-1,24,12,LEAVES:7)
Block(0,24,12,LEAVES:7)
Block(1,24,12,LEAVES:7)
Block(-1,24,13,VINE:4)
Block(-3,24,-2,VINE:1)
Block(0,24,13,VINE:4)
Block(-5,25,-10,LEAVES:7)
Block(-6,25,-9,LEAVES:7)
Block(-5,25,-9,LEAVES:7)
Block(-4,25,-9,LEAVES:7)
Block(0,25,-9,LEAVES:7)
Block(1,25,-9,LEAVES:7)
Block(2,25,-9,LEAVES:7)
Block(-7,25,-8,LEAVES:7)
Block(-6,25,-8,LEAVES:7)
Block(-5,25,-8,LEAVES:7)
Block(-4,25,-8,LEAVES:7)
Block(-3,25,-8,LEAVES:7)
Block(-1,25,-8,LEAVES:7)
Block(0,25,-8,LEAVES:7)
Block(1,25,-8,LEAVES:7)
Block(2,25,-8,LEAVES:7)
Block(3,25,-8,LEAVES:7)
Block(-8,25,-7,LEAVES:7)
Block(-6,25,-7,LEAVES:7)
Block(-5,25,-7,LEAVES:7)
Block(-4,25,-7,LEAVES:7)
Block(-3,25,-7,LEAVES:7)
Block(-2,25,-7,LEAVES:7)
Block(-1,25,-7,LEAVES:7)
Block(0,25,-7,LEAVES:7)
Block(1,25,-7,LEAVES:7)
Block(2,25,-7,LEAVES:7)
Block(3,25,-7,LEAVES:7)
Block(4,25,-7,LEAVES:7)
Block(-5,25,-6,LEAVES:7)
Block(-1,25,-6,LEAVES:7)
Block(2,25,-6,LEAVES:7)
Block(3,25,-6,LEAVES:7)
Block(4,25,-6,LEAVES:7)
Block(5,25,-6,LEAVES:7)
Block(6,25,-6,LEAVES:7)
Block(-9,25,-5,LEAVES:7)
Block(3,25,-5,LEAVES:7)
Block(5,25,-5,LEAVES:7)
Block(6,25,-5,LEAVES:7)
Block(7,25,-5,LEAVES:7)
Block(2,25,-4,LOG:15)
Block(5,25,-4,LEAVES:7)
Block(6,25,-4,LEAVES:7)
Block(7,25,-4,LEAVES:7)
Block(-10,25,-3,LEAVES:7)
Block(5,25,-3,LOG:15)
Block(6,25,-3,LEAVES:7)
Block(-3,25,-2,LOG:15)
Block(4,25,-2,LOG:15)
Block(7,25,-2,LEAVES:7)
Block(-11,25,-1,LEAVES:7)
Block(-10,25,-1,LEAVES:7)
Block(-6,25,-1,LOG:15)
Block(-12,25,0,LEAVES:7)
Block(-11,25,0,LEAVES:7)
Block(-10,25,0,LEAVES:7)
Block(-5,25,0,LOG:15)
Block(-12,25,1,LEAVES:7)
Block(-11,25,1,LEAVES:7)
Block(-10,25,1,LEAVES:7)
Block(-9,25,1,LEAVES:7)
Block(5,25,1,LOG:15)
Block(-11,25,2,LEAVES:7)
Block(-10,25,2,LOG:15)
Block(-3,25,2,LOG:15)
Block(8,25,2,LEAVES:7)
Block(-11,25,3,LEAVES:7)
Block(-10,25,3,LEAVES:7)
Block(-10,25,4,LEAVES:7)
Block(-5,25,4,LOG:15)
Block(-11,25,5,LEAVES:7)
Block(-10,25,5,LEAVES:7)
Block(-9,25,5,LEAVES:7)
Block(5,25,5,LOG:15)
Block(-11,25,6,LEAVES:7)
Block(-10,25,6,LEAVES:7)
Block(-9,25,6,LEAVES:7)
Block(1,25,6,LOG:15)
Block(6,25,6,LEAVES:7)
Block(-11,25,7,LEAVES:7)
Block(-10,25,7,LEAVES:7)
Block(-9,25,7,LEAVES:7)
Block(1,25,7,LOG:15)
Block(-9,25,8,LEAVES:7)
Block(2,25,8,LOG:15)
Block(-3,25,9,LEAVES:7)
Block(-1,25,9,LEAVES:7)
Block(0,25,9,LEAVES:7)
Block(3,25,9,LEAVES:7)
Block(-4,25,10,LEAVES:7)
Block(-3,25,10,LEAVES:7)
Block(-2,25,10,LEAVES:7)
Block(-1,25,10,LEAVES:7)
Block(0,25,10,LEAVES:7)
Block(1,25,10,LEAVES:7)
Block(-5,25,11,LEAVES:7)
Block(-4,25,11,LEAVES:7)
Block(-3,25,11,LEAVES:7)
Block(-2,25,11,LEAVES:7)
Block(-1,25,11,LEAVES:7)
Block(0,25,11,LEAVES:7)
Block(1,25,11,LEAVES:7)
Block(2,25,11,LEAVES:7)
Block(-4,25,12,LEAVES:7)
Block(-3,25,12,LEAVES:7)
Block(-2,25,12,LEAVES:7)
Block(-1,25,12,LEAVES:7)
Block(0,25,12,LEAVES:7)
Block(1,25,12,LEAVES:7)
Block(-3,25,13,LEAVES:7)
Block(0,25,13,LEAVES:7)
Block(2,25,12,VINE:4)
Block(-5,25,12,VINE:4)
Block(4,25,10,VINE:2)
Block(7,25,6,VINE)
Block(7,25,5,VINE)
Block(-4,25,-2,VINE:8)
Block(-3,25,-3,VINE:1)
Block(7,25,-6,VINE:1)
Block(-7,25,-6,VINE)
Block(-6,26,-9,LEAVES:7)
Block(-5,26,-9,LEAVES:7)
Block(-4,26,-9,LEAVES:7)
Block(-1,26,-9,LEAVES:7)
Block(0,26,-9,LEAVES:7)
Block(1,26,-9,LEAVES:7)
Block(2,26,-9,LEAVES:7)
Block(3,26,-9,LEAVES:7)
Block(4,26,-9,LEAVES:7)
Block(-9,26,-8,LEAVES:7)
Block(-8,26,-8,LEAVES:7)
Block(-7,26,-8,LEAVES:7)
Block(-6,26,-8,LEAVES:7)
Block(-5,26,-8,LEAVES:7)
Block(-4,26,-8,LEAVES:7)
Block(-3,26,-8,LEAVES:7)
Block(-2,26,-8,LEAVES:7)
Block(-1,26,-8,LEAVES:7)
Block(0,26,-8,LEAVES:7)
Block(1,26,-8,LEAVES:7)
Block(2,26,-8,LEAVES:7)
Block(3,26,-8,LEAVES:7)
Block(4,26,-8,LEAVES:7)
Block(-9,26,-7,LEAVES:7)
Block(-8,26,-7,LEAVES:7)
Block(-7,26,-7,LEAVES:7)
Block(-6,26,-7,LEAVES:7)
Block(-5,26,-7,LEAVES:7)
Block(-4,26,-7,LEAVES:7)
Block(-3,26,-7,LEAVES:7)
Block(-2,26,-7,LEAVES:7)
Block(-1,26,-7,LEAVES:7)
Block(0,26,-7,LEAVES:7)
Block(1,26,-7,LEAVES:7)
Block(2,26,-7,LEAVES:7)
Block(3,26,-7,LEAVES:7)
Block(4,26,-7,LEAVES:7)
Block(-10,26,-6,LEAVES:7)
Block(-9,26,-6,LEAVES:7)
Block(-8,26,-6,LEAVES:7)
Block(-7,26,-6,LEAVES:7)
Block(2,26,-6,LEAVES:7)
Block(3,26,-6,LEAVES:7)
Block(4,26,-6,LEAVES:7)
Block(5,26,-6,LEAVES:7)
Block(-10,26,-5,LEAVES:7)
Block(-9,26,-5,LEAVES:7)
Block(-8,26,-5,LEAVES:7)
Block(2,26,-5,LEAVES:7)
Block(3,26,-5,LEAVES:7)
Block(4,26,-5,LEAVES:7)
Block(5,26,-5,LEAVES:7)
Block(6,26,-5,LEAVES:7)
Block(-11,26,-4,LEAVES:7)
Block(-10,26,-4,LEAVES:7)
Block(-9,26,-4,LEAVES:7)
Block(-8,26,-4,LEAVES:7)
Block(2,26,-4,LOG:15)
Block(5,26,-4,LEAVES:7)
Block(6,26,-4,LEAVES:7)
Block(7,26,-4,LEAVES:7)
Block(-11,26,-3,LEAVES:7)
Block(-10,26,-3,LEAVES:7)
Block(-9,26,-3,LEAVES:7)
Block(-3,26,-3,LOG:15)
Block(5,26,-3,LEAVES:7)
Block(6,26,-3,LEAVES:7)
Block(7,26,-3,LEAVES:7)
Block(-11,26,-2,LEAVES:7)
Block(-10,26,-2,LEAVES:7)
Block(-9,26,-2,LEAVES:7)
Block(-7,26,-2,LOG:15)
Block(5,26,-2,LEAVES:7)
Block(6,26,-2,LEAVES:7)
Block(7,26,-2,LEAVES:7)
Block(-10,26,-1,LEAVES:7)
Block(-6,26,-1,LOG:15)
Block(6,26,-1,LEAVES:7)
Block(7,26,-1,LEAVES:7)
Block(8,26,-1,LEAVES:7)
Block(-11,26,0,LEAVES:7)
Block(-10,26,0,LEAVES:7)
Block(-9,26,0,LEAVES:7)
Block(1,26,0,LEAVES:7)
Block(2,26,0,LEAVES:7)
Block(7,26,0,LEAVES:7)
Block(8,26,0,LEAVES:7)
Block(9,26,0,LEAVES:7)
Block(-12,26,1,LEAVES:7)
Block(-11,26,1,LEAVES:7)
Block(-10,26,1,LEAVES:7)
Block(-9,26,1,LEAVES:7)
Block(-4,26,1,LEAVES:7)
Block(1,26,1,LEAVES:7)
Block(6,26,1,LOG:15)
Block(7,26,1,LEAVES:7)
Block(8,26,1,LEAVES:7)
Block(9,26,1,LEAVES:7)
Block(-12,26,2,LEAVES:7)
Block(-11,26,2,LEAVES:7)
Block(-10,26,2,LEAVES:7)
Block(-9,26,2,LEAVES:7)
Block(-8,26,2,LEAVES:7)
Block(-3,26,2,LOG:15)
Block(1,26,2,LEAVES:7)
Block(7,26,2,LEAVES:7)
Block(8,26,2,LEAVES:7)
Block(9,26,2,LEAVES:7)
Block(-11,26,3,LEAVES:7)
Block(-10,26,3,LOG:15)
Block(6,26,3,LEAVES:7)
Block(7,26,3,LEAVES:7)
Block(8,26,3,LEAVES:7)
Block(-11,26,4,LEAVES:7)
Block(-10,26,4,LEAVES:7)
Block(7,26,4,LEAVES:7)
Block(-11,26,5,LEAVES:7)
Block(-10,26,5,LEAVES:7)
Block(-9,26,5,LEAVES:7)
Block(-6,26,5,LOG:15)
Block(5,26,5,LEAVES:7)
Block(6,26,5,LEAVES:7)
Block(7,26,5,LEAVES:7)
Block(-12,26,6,LEAVES:7)
Block(-11,26,6,LEAVES:7)
Block(-10,26,6,LEAVES:7)
Block(-9,26,6,LEAVES:7)
Block(-8,26,6,LEAVES:7)
Block(-6,26,6,LOG:15)
Block(5,26,6,LEAVES:7)
Block(6,26,6,LEAVES:7)
Block(7,26,6,LEAVES:7)
Block(-11,26,7,LEAVES:7)
Block(-10,26,7,LEAVES:7)
Block(-9,26,7,LEAVES:7)
Block(-8,26,7,LEAVES:7)
Block(3,26,7,LEAVES:7)
Block(4,26,7,LEAVES:7)
Block(5,26,7,LEAVES:7)
Block(6,26,7,LEAVES:7)
Block(-10,26,8,LEAVES:7)
Block(-9,26,8,LEAVES:7)
Block(-8,26,8,LEAVES:7)
Block(-7,26,8,LEAVES:7)
Block(-2,26,8,LEAVES:7)
Block(-1,26,8,LEAVES:7)
Block(0,26,8,LEAVES:7)
Block(2,26,8,LEAVES:7)
Block(3,26,8,LEAVES:7)
Block(4,26,8,LEAVES:7)
Block(5,26,8,LEAVES:7)
Block(-10,26,9,LEAVES:7)
Block(-9,26,9,LEAVES:7)
Block(-8,26,9,LEAVES:7)
Block(-7,26,9,LEAVES:7)
Block(-2,26,9,LEAVES:7)
Block(-1,26,9,LEAVES:7)
Block(0,26,9,LEAVES:7)
Block(1,26,9,LEAVES:7)
Block(2,26,9,LEAVES:7)
Block(3,26,9,LEAVES:7)
Block(4,26,9,LEAVES:7)
Block(-7,26,10,LEAVES:7)
Block(-5,26,10,LEAVES:7)
Block(-4,26,10,LEAVES:7)
Block(-3,26,10,LEAVES:7)
Block(-2,26,10,LEAVES:7)
Block(-1,26,10,LEAVES:7)
Block(0,26,10,LEAVES:7)
Block(1,26,10,LEAVES:7)
Block(2,26,10,LEAVES:7)
Block(3,26,10,LEAVES:7)
Block(-5,26,11,LEAVES:7)
Block(-4,26,11,LEAVES:7)
Block(-3,26,11,LEAVES:7)
Block(-2,26,11,LEAVES:7)
Block(-1,26,11,LEAVES:7)
Block(0,26,11,LEAVES:7)
Block(1,26,11,LEAVES:7)
Block(-4,26,12,LEAVES:7)
Block(-3,26,12,LEAVES:7)
Block(-2,26,12,LEAVES:7)
Block(-1,26,12,LEAVES:7)
Block(0,26,12,LEAVES:7)
Block(1,26,12,LEAVES:7)
Block(4,26,10,VINE:2)
Block(5,26,9,VINE:2)
Block(-12,26,4,VINE:8)
Block(9,26,3,VINE:2)
Block(-12,26,3,VINE:8)
Block(-4,26,-5,VINE:8)
Block(5,26,-8,VINE:8)
Block(4,26,-10,VINE:1)
Block(3,26,-10,VINE:1)
Block(-8,27,-9,LEAVES:7)
Block(-7,27,-9,LEAVES:7)
Block(-6,27,-9,LEAVES:7)
Block(-5,27,-9,LEAVES:7)
Block(-4,27,-9,LEAVES:7)
Block(-3,27,-9,LEAVES:7)
Block(-2,27,-9,LEAVES:7)
Block(2,27,-9,LEAVES:7)
Block(3,27,-9,LEAVES:7)
Block(-9,27,-8,LEAVES:7)
Block(-8,27,-8,LEAVES:7)
Block(-7,27,-8,LEAVES:7)
Block(-5,27,-8,LEAVES:7)
Block(-4,27,-8,LEAVES:7)
Block(-3,27,-8,LEAVES:7)
Block(-2,27,-8,LEAVES:7)
Block(-1,27,-8,LEAVES:7)
Block(0,27,-8,LEAVES:7)
Block(1,27,-8,LEAVES:7)
Block(2,27,-8,LEAVES:7)
Block(4,27,-8,LEAVES:7)
Block(6,27,-8,LEAVES:7)
Block(-10,27,-7,LEAVES:7)
Block(-9,27,-7,LEAVES:7)
Block(-8,27,-7,LEAVES:7)
Block(-7,27,-7,LEAVES:7)
Block(-6,27,-7,LEAVES:7)
Block(-4,27,-7,LEAVES:7)
Block(-3,27,-7,LEAVES:7)
Block(-2,27,-7,LEAVES:7)
Block(-1,27,-7,LEAVES:7)
Block(0,27,-7,LOG:15)
Block(1,27,-7,LOG:15)
Block(2,27,-7,LOG:15)
Block(3,27,-7,LEAVES:7)
Block(4,27,-7,LEAVES:7)
Block(5,27,-7,LEAVES:7)
Block(6,27,-7,LEAVES:7)
Block(7,27,-7,LEAVES:7)
Block(-10,27,-6,LEAVES:7)
Block(-9,27,-6,LEAVES:7)
Block(-8,27,-6,LEAVES:7)
Block(-7,27,-6,LEAVES:7)
Block(-3,27,-6,LEAVES:7)
Block(-1,27,-6,LOG:15)
Block(1,27,-6,LEAVES:7)
Block(2,27,-6,LEAVES:7)
Block(3,27,-6,LEAVES:7)
Block(4,27,-6,LEAVES:7)
Block(5,27,-6,LEAVES:7)
Block(-11,27,-5,LEAVES:7)
Block(-10,27,-5,LEAVES:7)
Block(-9,27,-5,LEAVES:7)
Block(-8,27,-5,LEAVES:7)
Block(-7,27,-5,LEAVES:7)
Block(-3,27,-5,LOG:15)
Block(-2,27,-5,LOG:15)
Block(2,27,-5,LOG:15)
Block(3,27,-5,LEAVES:7)
Block(4,27,-5,LEAVES:7)
Block(5,27,-5,LEAVES:7)
Block(6,27,-5,LEAVES:7)
Block(7,27,-5,LEAVES:7)
Block(-11,27,-4,LEAVES:7)
Block(-10,27,-4,LEAVES:7)
Block(-9,27,-4,LEAVES:7)
Block(-8,27,-4,LEAVES:7)
Block(-3,27,-4,LOG:15)
Block(2,27,-4,LEAVES:7)
Block(3,27,-4,LEAVES:7)
Block(5,27,-4,LEAVES:7)
Block(6,27,-4,LEAVES:7)
Block(-12,27,-3,LEAVES:7)
Block(-11,27,-3,LEAVES:7)
Block(-10,27,-3,LEAVES:7)
Block(-9,27,-3,LEAVES:7)
Block(-8,27,-3,LEAVES:7)
Block(2,27,-3,LOG:15)
Block(4,27,-3,LEAVES:7)
Block(5,27,-3,LEAVES:7)
Block(6,27,-3,LEAVES:7)
Block(7,27,-3,LEAVES:7)
Block(-11,27,-2,LEAVES:7)
Block(-10,27,-2,LEAVES:7)
Block(-9,27,-2,LEAVES:7)
Block(-8,27,-2,LOG:15)
Block(5,27,-2,LEAVES:7)
Block(6,27,-2,LEAVES:7)
Block(-10,27,-1,LEAVES:7)
Block(2,27,-1,LEAVES:7)
Block(5,27,-1,LEAVES:7)
Block(6,27,-1,LEAVES:7)
Block(7,27,-1,LEAVES:7)
Block(-10,27,0,LEAVES:7)
Block(-4,27,0,LEAVES:7)
Block(-3,27,0,LOG:15)
Block(1,27,0,LEAVES:7)
Block(2,27,0,LEAVES:7)
Block(3,27,0,LEAVES:7)
Block(6,27,0,LEAVES:7)
Block(7,27,0,LEAVES:7)
Block(8,27,0,LEAVES:7)
Block(10,27,0,LEAVES:7)
Block(-11,27,1,LEAVES:7)
Block(-10,27,1,LEAVES:7)
Block(-9,27,1,LEAVES:7)
Block(-5,27,1,LEAVES:7)
Block(-4,27,1,LEAVES:7)
Block(-3,27,1,LEAVES:7)
Block(0,27,1,LEAVES:7)
Block(1,27,1,LEAVES:7)
Block(2,27,1,LEAVES:7)
Block(6,27,1,LEAVES:7)
Block(7,27,1,LEAVES:7)
Block(8,27,1,LEAVES:7)
Block(9,27,1,LEAVES:7)
Block(-11,27,2,LEAVES:7)
Block(-10,27,2,LEAVES:7)
Block(-9,27,2,LEAVES:7)
Block(-8,27,2,LEAVES:7)
Block(-4,27,2,LEAVES:7)
Block(-3,27,2,LOG:15)
Block(-2,27,2,LOG:15)
Block(1,27,2,LEAVES:7)
Block(2,27,2,LEAVES:7)
Block(6,27,2,LEAVES:7)
Block(7,27,2,LEAVES:7)
Block(8,27,2,LEAVES:7)
Block(-11,27,3,LEAVES:7)
Block(-10,27,3,LEAVES:7)
Block(-9,27,3,LEAVES:7)
Block(-3,27,3,LEAVES:7)
Block(1,27,3,LEAVES:7)
Block(6,27,3,LEAVES:7)
Block(7,27,3,LEAVES:7)
Block(-10,27,4,LEAVES:7)
Block(-9,27,4,LOG:15)
Block(-7,27,4,LEAVES:7)
Block(2,27,4,LEAVES:7)
Block(6,27,4,LEAVES:7)
Block(-11,27,5,LEAVES:7)
Block(-10,27,5,LEAVES:7)
Block(-9,27,5,LEAVES:7)
Block(-8,27,5,LEAVES:7)
Block(0,27,5,LEAVES:7)
Block(4,27,5,LEAVES:7)
Block(5,27,5,LEAVES:7)
Block(6,27,5,LEAVES:7)
Block(7,27,5,LEAVES:7)
Block(-11,27,6,LEAVES:7)
Block(-10,27,6,LEAVES:7)
Block(-9,27,6,LEAVES:7)
Block(-7,27,6,LOG:15)
Block(-6,27,6,LEAVES:7)
Block(2,27,6,LEAVES:7)
Block(4,27,6,LEAVES:7)
Block(5,27,6,LEAVES:7)
Block(6,27,6,LEAVES:7)
Block(-11,27,7,LEAVES:7)
Block(-10,27,7,LEAVES:7)
Block(-9,27,7,LEAVES:7)
Block(-8,27,7,LEAVES:7)
Block(-7,27,7,LEAVES:7)
Block(-6,27,7,LOG:15)
Block(-5,27,7,LEAVES:7)
Block(-4,27,7,LEAVES:7)
Block(-1,27,7,LEAVES:7)
Block(1,27,7,LEAVES:7)
Block(2,27,7,LEAVES:7)
Block(3,27,7,LEAVES:7)
Block(5,27,7,LEAVES:7)
Block(-11,27,8,LEAVES:7)
Block(-10,27,8,LEAVES:7)
Block(-9,27,8,LEAVES:7)
Block(-8,27,8,LEAVES:7)
Block(-7,27,8,LEAVES:7)
Block(-6,27,8,LOG:15)
Block(-5,27,8,LEAVES:7)
Block(-2,27,8,LEAVES:7)
Block(-1,27,8,LEAVES:7)
Block(0,27,8,LEAVES:7)
Block(1,27,8,LEAVES:7)
Block(2,27,8,LEAVES:7)
Block(3,27,8,LEAVES:7)
Block(4,27,8,LEAVES:7)
Block(-10,27,9,LEAVES:7)
Block(-9,27,9,LEAVES:7)
Block(-8,27,9,LEAVES:7)
Block(-7,27,9,LEAVES:7)
Block(-6,27,9,LEAVES:7)
Block(-5,27,9,LOG:15)
Block(-3,27,9,LEAVES:7)
Block(-2,27,9,LEAVES:7)
Block(-1,27,9,LEAVES:7)
Block(0,27,9,LEAVES:7)
Block(1,27,9,LEAVES:7)
Block(2,27,9,LEAVES:7)
Block(3,27,9,LEAVES:7)
Block(-9,27,10,LEAVES:7)
Block(-8,27,10,LEAVES:7)
Block(-7,27,10,LEAVES:7)
Block(-6,27,10,LEAVES:7)
Block(-5,27,10,LEAVES:7)
Block(-4,27,10,LEAVES:7)
Block(-3,27,10,LEAVES:7)
Block(-2,27,10,LEAVES:7)
Block(-1,27,10,LEAVES:7)
Block(0,27,10,LEAVES:7)
Block(2,27,10,LEAVES:7)
Block(-7,27,11,LEAVES:7)
Block(-6,27,11,LEAVES:7)
Block(-5,27,11,LEAVES:7)
Block(-4,27,11,LEAVES:7)
Block(-3,27,11,LEAVES:7)
Block(-2,27,11,LEAVES:7)
Block(-1,27,11,LEAVES:7)
Block(0,27,11,LEAVES:7)
Block(-6,27,12,LEAVES:7)
Block(-5,27,12,LEAVES:7)
Block(-4,27,12,LEAVES:7)
Block(-3,27,12,LEAVES:7)
Block(-2,27,12,LEAVES:7)
Block(-1,27,12,LEAVES:7)
Block(-12,27,3,VINE:8)
Block(-12,27,2,VINE:8)
Block(-4,27,-4,VINE:8)
Block(8,27,-5,VINE:2)
Block(-4,27,-5,VINE:8)
Block(7,27,-8,VINE:1)
Block(5,27,-8,VINE:8)
Block(4,27,-9,VINE:2)
Block(1,27,-9,VINE:1)
Block(3,27,-10,VINE:1)
Block(2,27,-10,VINE:1)
Block(-7,28,-10,LEAVES:7)
Block(-6,28,-10,LEAVES:7)
Block(-5,28,-10,LEAVES:7)
Block(-4,28,-10,LEAVES:7)
Block(-3,28,-10,LEAVES:7)
Block(-8,28,-9,LEAVES:7)
Block(-7,28,-9,LEAVES:7)
Block(-6,28,-9,LEAVES:7)
Block(-5,28,-9,LEAVES:7)
Block(-4,28,-9,LEAVES:7)
Block(-3,28,-9,LEAVES:7)
Block(-2,28,-9,LEAVES:7)
Block(3,28,-9,LEAVES:7)
Block(-9,28,-8,LEAVES:7)
Block(-8,28,-8,LEAVES:7)
Block(-7,28,-8,LEAVES:7)
Block(-6,28,-8,LEAVES:7)
Block(-4,28,-8,LEAVES:7)
Block(-3,28,-8,LEAVES:7)
Block(-2,28,-8,LEAVES:7)
Block(-1,28,-8,LEAVES:7)
Block(0,28,-8,LEAVES:7)
Block(1,28,-8,LEAVES:7)
Block(2,28,-8,LEAVES:7)
Block(3,28,-8,LEAVES:7)
Block(4,28,-8,LEAVES:7)
Block(-9,28,-7,LEAVES:7)
Block(-8,28,-7,LEAVES:7)
Block(-7,28,-7,LEAVES:7)
Block(-6,28,-7,LOG:15)
Block(-4,28,-7,LEAVES:7)
Block(-3,28,-7,LEAVES:7)
Block(-2,28,-7,LEAVES:7)
Block(-1,28,-7,LEAVES:7)
Block(0,28,-7,LEAVES:7)
Block(1,28,-7,LEAVES:7)
Block(2,28,-7,LEAVES:7)
Block(3,28,-7,LEAVES:7)
Block(4,28,-7,LEAVES:7)
Block(5,28,-7,LEAVES:7)
Block(-10,28,-6,LEAVES:7)
Block(-9,28,-6,LEAVES:7)
Block(-8,28,-6,LEAVES:7)
Block(-7,28,-6,LEAVES:7)
Block(-5,28,-6,LOG:15)
Block(-4,28,-6,LOG:15)
Block(1,28,-6,LOG:15)
Block(2,28,-6,LEAVES:7)
Block(3,28,-6,LEAVES:7)
Block(4,28,-6,LEAVES:7)
Block(-10,28,-5,LEAVES:7)
Block(-9,28,-5,LEAVES:7)
Block(-8,28,-5,LEAVES:7)
Block(-6,28,-5,LEAVES:7)
Block(-3,28,-5,LOG:15)
Block(2,28,-5,LEAVES:7)
Block(3,28,-5,LEAVES:7)
Block(-11,28,-4,LEAVES:7)
Block(-10,28,-4,LEAVES:7)
Block(-9,28,-4,LEAVES:7)
Block(-8,28,-4,LEAVES:7)
Block(-7,28,-4,LEAVES:7)
Block(2,28,-4,LEAVES:7)
Block(5,28,-4,LEAVES:7)
Block(-11,28,-3,LEAVES:7)
Block(-10,28,-3,LEAVES:7)
Block(-9,28,-3,LEAVES:7)
Block(-8,28,-3,LEAVES:7)
Block(-7,28,-3,LEAVES:7)
Block(2,28,-3,LOG:15)
Block(5,28,-3,LEAVES:7)
Block(6,28,-3,LEAVES:7)
Block(-11,28,-2,LEAVES:7)
Block(-10,28,-2,LEAVES:7)
Block(-9,28,-2,LEAVES:7)
Block(-8,28,-2,LEAVES:7)
Block(-7,28,-2,LEAVES:7)
Block(-6,28,-2,LEAVES:7)
Block(4,28,-2,LEAVES:7)
Block(5,28,-2,LEAVES:7)
Block(-10,28,-1,LEAVES:7)
Block(-9,28,-1,LEAVES:7)
Block(-7,28,-1,LEAVES:7)
Block(-6,28,-1,LEAVES:7)
Block(-3,28,-1,LOG:15)
Block(3,28,-1,LEAVES:7)
Block(6,28,-1,LEAVES:7)
Block(-9,28,0,LEAVES:7)
Block(-6,28,0,LEAVES:7)
Block(1,28,0,LEAVES:7)
Block(2,28,0,LEAVES:7)
Block(3,28,0,LEAVES:7)
Block(4,28,0,LEAVES:7)
Block(5,28,0,LEAVES:7)
Block(6,28,0,LEAVES:7)
Block(7,28,0,LEAVES:7)
Block(-10,28,1,LEAVES:7)
Block(-9,28,1,LEAVES:7)
Block(-4,28,1,LEAVES:7)
Block(0,28,1,LEAVES:7)
Block(1,28,1,LEAVES:7)
Block(2,28,1,LEAVES:7)
Block(3,28,1,LEAVES:7)
Block(6,28,1,LEAVES:7)
Block(7,28,1,LEAVES:7)
Block(8,28,1,LEAVES:7)
Block(-11,28,2,LEAVES:7)
Block(-10,28,2,LEAVES:7)
Block(-9,28,2,LEAVES:7)
Block(-8,28,2,LEAVES:7)
Block(-5,28,2,LEAVES:7)
Block(-4,28,2,LEAVES:7)
Block(-3,28,2,LEAVES:7)
Block(-1,28,2,LOG:15)
Block(0,28,2,LEAVES:7)
Block(1,28,2,LEAVES:7)
Block(2,28,2,LEAVES:7)
Block(3,28,2,LEAVES:7)
Block(7,28,2,LEAVES:7)
Block(-10,28,3,LEAVES:7)
Block(-9,28,3,LEAVES:7)
Block(-8,28,3,LEAVES:7)
Block(-7,28,3,LEAVES:7)
Block(-4,28,3,LEAVES:7)
Block(-3,28,3,LEAVES:7)
Block(-2,28,3,LEAVES:7)
Block(-1,28,3,LOG:15)
Block(0,28,3,LEAVES:7)
Block(1,28,3,LEAVES:7)
Block(2,28,3,LEAVES:7)
Block(3,28,3,LEAVES:7)
Block(6,28,3,LEAVES:7)
Block(-8,28,4,LEAVES:7)
Block(-7,28,4,LEAVES:7)
Block(-3,28,4,LEAVES:7)
Block(-2,28,4,LEAVES:7)
Block(-1,28,4,LOG:15)
Block(0,28,4,LEAVES:7)
Block(1,28,4,LEAVES:7)
Block(2,28,4,LEAVES:7)
Block(3,28,4,LEAVES:7)
Block(5,28,4,LEAVES:7)
Block(6,28,4,LEAVES:7)
Block(-9,28,5,LEAVES:7)
Block(-8,28,5,LEAVES:7)
Block(-7,28,5,LEAVES:7)
Block(-6,28,5,LEAVES:7)
Block(-5,28,5,LEAVES:7)
Block(0,28,5,LEAVES:7)
Block(1,28,5,LEAVES:7)
Block(2,28,5,LEAVES:7)
Block(4,28,5,LEAVES:7)
Block(5,28,5,LEAVES:7)
Block(6,28,5,LEAVES:7)
Block(-10,28,6,LEAVES:7)
Block(-7,28,6,LEAVES:7)
Block(-6,28,6,LEAVES:7)
Block(-5,28,6,LEAVES:7)
Block(-4,28,6,LEAVES:7)
Block(5,28,6,LEAVES:7)
Block(-10,28,7,LEAVES:7)
Block(-9,28,7,LEAVES:7)
Block(-8,28,7,LEAVES:7)
Block(-7,28,7,LEAVES:7)
Block(-6,28,7,LEAVES:7)
Block(-5,28,7,LEAVES:7)
Block(2,28,7,LEAVES:7)
Block(-10,28,8,LEAVES:7)
Block(-9,28,8,LEAVES:7)
Block(-8,28,8,LEAVES:7)
Block(-7,28,8,LEAVES:7)
Block(-6,28,8,LEAVES:7)
Block(-5,28,8,LEAVES:7)
Block(-2,28,8,LEAVES:7)
Block(-1,28,8,LEAVES:7)
Block(0,28,8,LEAVES:7)
Block(1,28,8,LEAVES:7)
Block(2,28,8,LEAVES:7)
Block(3,28,8,LEAVES:7)
Block(-10,28,9,LEAVES:7)
Block(-9,28,9,LEAVES:7)
Block(-8,28,9,LEAVES:7)
Block(-7,28,9,LEAVES:7)
Block(-6,28,9,LEAVES:7)
Block(-5,28,9,LEAVES:7)
Block(-4,28,9,LEAVES:7)
Block(-2,28,9,LEAVES:7)
Block(-1,28,9,LEAVES:7)
Block(0,28,9,LEAVES:7)
Block(2,28,9,LEAVES:7)
Block(3,28,9,LEAVES:7)
Block(-7,28,10,LEAVES:7)
Block(-6,28,10,LEAVES:7)
Block(-5,28,10,LEAVES:7)
Block(-4,28,10,LEAVES:7)
Block(-3,28,10,LEAVES:7)
Block(-2,28,10,LEAVES:7)
Block(-1,28,10,LEAVES:7)
Block(0,28,10,LEAVES:7)
Block(-6,28,11,LEAVES:7)
Block(-5,28,11,LEAVES:7)
Block(-4,28,11,LEAVES:7)
Block(-3,28,11,LEAVES:7)
Block(-2,28,11,LEAVES:7)
Block(-1,28,11,LEAVES:7)
Block(0,28,11,LEAVES:7)
Block(-5,28,12,LEAVES:7)
Block(-3,28,12,LEAVES:7)
Block(-2,28,12,LEAVES:7)
Block(-1,28,12,LEAVES:7)
Block(-2,28,13,LEAVES:7)
Block(-8,28,-10,VINE:8)
Block(-6,28,-11,VINE:1)
Block(-7,29,-9,LEAVES:7)
Block(-6,29,-9,LEAVES:7)
Block(-5,29,-9,LEAVES:7)
Block(-4,29,-9,LEAVES:7)
Block(-7,29,-8,LEAVES:7)
Block(-6,29,-8,LEAVES:7)
Block(-5,29,-8,LEAVES:7)
Block(-4,29,-8,LEAVES:7)
Block(-3,29,-8,LEAVES:7)
Block(-2,29,-8,LEAVES:7)
Block(-9,29,-7,LEAVES:7)
Block(-8,29,-7,LEAVES:7)
Block(-7,29,-7,LEAVES:7)
Block(-6,29,-7,LEAVES:7)
Block(-1,29,-7,LEAVES:7)
Block(0,29,-7,LEAVES:7)
Block(1,29,-7,LEAVES:7)
Block(2,29,-7,LEAVES:7)
Block(3,29,-7,LEAVES:7)
Block(4,29,-7,LEAVES:7)
Block(-8,29,-6,LEAVES:7)
Block(-7,29,-6,LEAVES:7)
Block(-6,29,-6,LEAVES:7)
Block(-4,29,-6,LEAVES:7)
Block(3,29,-6,LEAVES:7)
Block(6,29,-6,LEAVES:7)
Block(-9,29,-5,LEAVES:7)
Block(-7,29,-5,LEAVES:7)
Block(-6,29,-5,LEAVES:7)
Block(-5,29,-5,LEAVES:7)
Block(-3,29,-5,LEAVES:7)
Block(6,29,-5,LEAVES:7)
Block(7,29,-5,LEAVES:7)
Block(-8,29,-4,LEAVES:7)
Block(-7,29,-4,LEAVES:7)
Block(-6,29,-4,LEAVES:7)
Block(2,29,-4,LEAVES:7)
Block(3,29,-4,LEAVES:7)
Block(4,29,-4,LEAVES:7)
Block(7,29,-4,LEAVES:7)
Block(-10,29,-3,LEAVES:7)
Block(-9,29,-3,LEAVES:7)
Block(-8,29,-3,LEAVES:7)
Block(-7,29,-3,LEAVES:7)
Block(-6,29,-3,LEAVES:7)
Block(-5,29,-3,LEAVES:7)
Block(-1,29,-3,LEAVES:7)
Block(2,29,-3,LEAVES:7)
Block(3,29,-3,LEAVES:7)
Block(4,29,-3,LEAVES:7)
Block(5,29,-3,LEAVES:7)
Block(-10,29,-2,LEAVES:7)
Block(-9,29,-2,LEAVES:7)
Block(-8,29,-2,LEAVES:7)
Block(-7,29,-2,LEAVES:7)
Block(-6,29,-2,LEAVES:7)
Block(-5,29,-2,LOG:15)
Block(-4,29,-2,LOG:15)
Block(-3,29,-2,LOG:15)
Block(1,29,-2,LOG:15)
Block(2,29,-2,LEAVES:7)
Block(3,29,-2,LEAVES:7)
Block(4,29,-2,LEAVES:7)
Block(5,29,-2,LEAVES:7)
Block(-9,29,-1,LEAVES:7)
Block(-8,29,-1,LEAVES:7)
Block(-7,29,-1,LEAVES:7)
Block(-6,29,-1,LEAVES:7)
Block(-5,29,-1,LEAVES:7)
Block(1,29,-1,LEAVES:7)
Block(2,29,-1,LEAVES:7)
Block(3,29,-1,LEAVES:7)
Block(4,29,-1,LEAVES:7)
Block(6,29,-1,LEAVES:7)
Block(-8,29,0,LEAVES:7)
Block(-7,29,0,LEAVES:7)
Block(-6,29,0,LEAVES:7)
Block(1,29,0,LOG:15)
Block(3,29,0,LEAVES:7)
Block(6,29,0,LEAVES:7)
Block(7,29,0,LEAVES:7)
Block(-8,29,1,LEAVES:7)
Block(-5,29,1,LEAVES:7)
Block(1,29,1,LEAVES:7)
Block(2,29,1,LEAVES:7)
Block(5,29,1,LEAVES:7)
Block(6,29,1,LEAVES:7)
Block(7,29,1,LEAVES:7)
Block(-10,29,2,LEAVES:7)
Block(-9,29,2,LEAVES:7)
Block(-6,29,2,LEAVES:7)
Block(-4,29,2,LEAVES:7)
Block(-3,29,2,LOG:15)
Block(-2,29,2,LEAVES:7)
Block(0,29,2,LEAVES:7)
Block(1,29,2,LEAVES:7)
Block(2,29,2,LEAVES:7)
Block(6,29,2,LEAVES:7)
Block(-10,29,3,LEAVES:7)
Block(-9,29,3,LEAVES:7)
Block(-8,29,3,LEAVES:7)
Block(-3,29,3,LEAVES:7)
Block(-2,29,3,LEAVES:7)
Block(-1,29,3,LEAVES:7)
Block(0,29,3,LEAVES:7)
Block(1,29,3,LEAVES:7)
Block(2,29,3,LEAVES:7)
Block(-7,29,4,LEAVES:7)
Block(-2,29,4,LEAVES:7)
Block(-1,29,4,LEAVES:7)
Block(0,29,4,LEAVES:7)
Block(1,29,4,LEAVES:7)
Block(2,29,4,LEAVES:7)
Block(4,29,4,LEAVES:7)
Block(6,29,4,LEAVES:7)
Block(-7,29,5,LEAVES:7)
Block(-6,29,5,LEAVES:7)
Block(-3,29,5,LEAVES:7)
Block(-2,29,5,LEAVES:7)
Block(-1,29,5,LOG:15)
Block(1,29,5,LEAVES:7)
Block(5,29,5,LEAVES:7)
Block(6,29,5,LEAVES:7)
Block(-9,29,6,LEAVES:7)
Block(-8,29,6,LEAVES:7)
Block(-7,29,6,LEAVES:7)
Block(-6,29,6,LEAVES:7)
Block(-5,29,6,LEAVES:7)
Block(-7,29,7,LEAVES:7)
Block(-6,29,7,LEAVES:7)
Block(2,29,7,LEAVES:7)
Block(-9,29,8,LEAVES:7)
Block(-7,29,8,LEAVES:7)
Block(-4,29,8,LEAVES:7)
Block(-3,29,8,LEAVES:7)
Block(-2,29,8,LEAVES:7)
Block(2,29,8,LEAVES:7)
Block(-7,29,9,LEAVES:7)
Block(-6,29,9,LEAVES:7)
Block(-3,29,9,LEAVES:7)
Block(-1,29,9,LEAVES:7)
Block(-6,29,10,LEAVES:7)
Block(-5,29,10,LEAVES:7)
Block(-4,29,10,LEAVES:7)
Block(-3,29,10,LEAVES:7)
Block(-2,29,10,LEAVES:7)
Block(-1,29,10,LEAVES:7)
Block(-5,29,11,LEAVES:7)
Block(-3,29,11,LEAVES:7)
Block(-2,29,11,LEAVES:7)
Block(-1,29,11,LEAVES:7)
Block(-3,29,12,LEAVES:7)
Block(-2,29,12,LEAVES:7)
Block(-1,29,12,LEAVES:7)
Block(-5,29,-4,VINE)
Block(-8,29,-9,VINE:8)
Block(-7,30,-8,LEAVES:7)
Block(-6,30,-8,LEAVES:7)
Block(-5,30,-8,LEAVES:7)
Block(-4,30,-8,LEAVES:7)
Block(-3,30,-8,LEAVES:7)
Block(-8,30,-7,LEAVES:7)
Block(-7,30,-7,LEAVES:7)
Block(-1,30,-7,LEAVES:7)
Block(0,30,-7,LEAVES:7)
Block(1,30,-7,LEAVES:7)
Block(-7,30,-6,LEAVES:7)
Block(-3,30,-6,LEAVES:7)
Block(0,30,-6,LEAVES:7)
Block(-6,30,-5,LEAVES:7)
Block(-4,30,-5,LEAVES:7)
Block(-3,30,-5,LEAVES:7)
Block(-2,30,-5,LEAVES:7)
Block(-1,30,-5,LEAVES:7)
Block(2,30,-5,LEAVES:7)
Block(-6,30,-4,LEAVES:7)
Block(-5,30,-4,LEAVES:7)
Block(-3,30,-4,LEAVES:7)
Block(-2,30,-4,LEAVES:7)
Block(-1,30,-4,LEAVES:7)
Block(2,30,-4,LEAVES:7)
Block(3,30,-4,LEAVES:7)
Block(4,30,-4,LEAVES:7)
Block(5,30,-4,LEAVES:7)
Block(-8,30,-3,LEAVES:7)
Block(-7,30,-3,LEAVES:7)
Block(-6,30,-3,LEAVES:7)
Block(-5,30,-3,LEAVES:7)
Block(-2,30,-3,LEAVES:7)
Block(-1,30,-3,LEAVES:7)
Block(0,30,-3,LEAVES:7)
Block(1,30,-3,LEAVES:7)
Block(2,30,-3,LEAVES:7)
Block(3,30,-3,LEAVES:7)
Block(4,30,-3,LEAVES:7)
Block(-9,30,-2,LEAVES:7)
Block(-8,30,-2,LEAVES:7)
Block(-7,30,-2,LEAVES:7)
Block(-6,30,-2,LEAVES:7)
Block(-4,30,-2,LEAVES:7)
Block(-3,30,-2,LOG:15)
Block(0,30,-2,LEAVES:7)
Block(1,30,-2,LEAVES:7)
Block(2,30,-2,LEAVES:7)
Block(3,30,-2,LEAVES:7)
Block(4,30,-2,LEAVES:7)
Block(-8,30,-1,LEAVES:7)
Block(-7,30,-1,LEAVES:7)
Block(-6,30,-1,LEAVES:7)
Block(0,30,-1,LEAVES:7)
Block(1,30,-1,LEAVES:7)
Block(2,30,-1,LEAVES:7)
Block(3,30,-1,LEAVES:7)
Block(6,30,-1,LEAVES:7)
Block(-8,30,0,LEAVES:7)
Block(-7,30,0,LEAVES:7)
Block(-6,30,0,LEAVES:7)
Block(-5,30,0,LEAVES:7)
Block(-4,30,0,LEAVES:7)
Block(0,30,0,LEAVES:7)
Block(1,30,0,LEAVES:7)
Block(2,30,0,LEAVES:7)
Block(3,30,0,LEAVES:7)
Block(4,30,0,LEAVES:7)
Block(5,30,0,LEAVES:7)
Block(6,30,0,LEAVES:7)
Block(-9,30,1,LEAVES:7)
Block(-8,30,1,LEAVES:7)
Block(-7,30,1,LEAVES:7)
Block(-6,30,1,LEAVES:7)
Block(-5,30,1,LEAVES:7)
Block(-4,30,1,LEAVES:7)
Block(1,30,1,LEAVES:7)
Block(3,30,1,LEAVES:7)
Block(6,30,1,LEAVES:7)
Block(-8,30,2,LEAVES:7)
Block(-7,30,2,LEAVES:7)
Block(-6,30,2,LEAVES:7)
Block(-5,30,2,LEAVES:7)
Block(-4,30,2,LEAVES:7)
Block(-3,30,2,LOG:15)
Block(-1,30,2,LEAVES:7)
Block(0,30,2,LEAVES:7)
Block(1,30,2,LEAVES:7)
Block(2,30,2,LEAVES:7)
Block(3,30,2,LEAVES:7)
Block(4,30,2,LEAVES:7)
Block(5,30,2,LEAVES:7)
Block(-9,30,3,LEAVES:7)
Block(-6,30,3,LEAVES:7)
Block(-5,30,3,LEAVES:7)
Block(-2,30,3,LEAVES:7)
Block(-1,30,3,LEAVES:7)
Block(0,30,3,LEAVES:7)
Block(1,30,3,LEAVES:7)
Block(4,30,3,LEAVES:7)
Block(-5,30,4,LEAVES:7)
Block(-3,30,4,LEAVES:7)
Block(-2,30,4,LEAVES:7)
Block(1,30,4,LEAVES:7)
Block(-7,30,5,LEAVES:7)
Block(-8,30,6,LEAVES:7)
Block(-7,30,6,LEAVES:7)
Block(-6,30,6,LEAVES:7)
Block(-1,30,6,LEAVES:7)
Block(-7,30,7,LEAVES:7)
Block(-2,30,7,LEAVES:7)
Block(-1,30,7,LEAVES:7)
Block(3,30,7,LEAVES:7)
Block(1,30,8,LEAVES:7)
Block(2,30,8,LEAVES:7)
Block(-2,30,11,LEAVES:7)
Block(-6,31,-8,LEAVES:7)
Block(-7,31,-7,LEAVES:7)
Block(-3,31,-7,LEAVES:7)
Block(-4,31,-6,LEAVES:7)
Block(-3,31,-6,LEAVES:7)
Block(-2,31,-6,LEAVES:7)
Block(0,31,-6,LEAVES:7)
Block(-5,31,-5,LEAVES:7)
Block(-4,31,-5,LEAVES:7)
Block(-3,31,-5,LEAVES:7)
Block(-2,31,-5,LEAVES:7)
Block(-1,31,-5,LEAVES:7)
Block(0,31,-5,LEAVES:7)
Block(-6,31,-4,LEAVES:7)
Block(-5,31,-4,LEAVES:7)
Block(-4,31,-4,LEAVES:7)
Block(-3,31,-4,LEAVES:7)
Block(-2,31,-4,LEAVES:7)
Block(-1,31,-4,LEAVES:7)
Block(0,31,-4,LEAVES:7)
Block(1,31,-4,LEAVES:7)
Block(2,31,-4,LEAVES:7)
Block(-7,31,-3,LEAVES:7)
Block(-6,31,-3,LEAVES:7)
Block(-5,31,-3,LEAVES:7)
Block(-4,31,-3,LEAVES:7)
Block(-3,31,-3,LOG:15)
Block(-2,31,-3,LEAVES:7)
Block(-1,31,-3,LEAVES:7)
Block(0,31,-3,LEAVES:7)
Block(1,31,-3,LEAVES:7)
Block(2,31,-3,LEAVES:7)
Block(3,31,-3,LEAVES:7)
Block(-7,31,-2,LEAVES:7)
Block(-6,31,-2,LEAVES:7)
Block(-5,31,-2,LEAVES:7)
Block(-4,31,-2,LEAVES:7)
Block(-3,31,-2,LEAVES:7)
Block(-1,31,-2,LEAVES:7)
Block(0,31,-2,LEAVES:7)
Block(1,31,-2,LEAVES:7)
Block(2,31,-2,LEAVES:7)
Block(3,31,-2,LEAVES:7)
Block(-8,31,-1,LEAVES:7)
Block(-7,31,-1,LEAVES:7)
Block(-4,31,-1,LEAVES:7)
Block(-3,31,-1,LEAVES:7)
Block(-2,31,-1,LEAVES:7)
Block(-1,31,-1,LEAVES:7)
Block(0,31,-1,LEAVES:7)
Block(1,31,-1,LEAVES:7)
Block(2,31,-1,LEAVES:7)
Block(5,31,-1,LEAVES:7)
Block(-9,31,0,LEAVES:7)
Block(-8,31,0,LEAVES:7)
Block(-7,31,0,LEAVES:7)
Block(-4,31,0,LEAVES:7)
Block(-3,31,0,LEAVES:7)
Block(-2,31,0,LEAVES:7)
Block(-1,31,0,LEAVES:7)
Block(0,31,0,LEAVES:7)
Block(1,31,0,LEAVES:7)
Block(2,31,0,LEAVES:7)
Block(3,31,0,LEAVES:7)
Block(4,31,0,LEAVES:7)
Block(5,31,0,LEAVES:7)
Block(-10,31,1,LEAVES:7)
Block(-9,31,1,LEAVES:7)
Block(-8,31,1,LEAVES:7)
Block(-6,31,1,LEAVES:7)
Block(-5,31,1,LEAVES:7)
Block(-4,31,1,LEAVES:7)
Block(-3,31,1,LEAVES:7)
Block(-2,31,1,LEAVES:7)
Block(-1,31,1,LEAVES:7)
Block(0,31,1,LEAVES:7)
Block(1,31,1,LEAVES:7)
Block(2,31,1,LEAVES:7)
Block(-8,31,2,LEAVES:7)
Block(-7,31,2,LEAVES:7)
Block(-6,31,2,LEAVES:7)
Block(-5,31,2,LEAVES:7)
Block(-4,31,2,LEAVES:7)
Block(-3,31,2,LEAVES:7)
Block(-2,31,2,LEAVES:7)
Block(-1,31,2,LEAVES:7)
Block(1,31,2,LEAVES:7)
Block(-8,31,3,LEAVES:7)
Block(-6,31,3,LEAVES:7)
Block(-5,31,3,LEAVES:7)
Block(-4,31,3,LEAVES:7)
Block(-3,31,3,LEAVES:7)
Block(-2,31,3,LEAVES:7)
Block(-1,31,3,LEAVES:7)
Block(-4,31,4,LEAVES:7)
Block(-3,31,4,LEAVES:7)
Block(-2,31,4,LEAVES:7)
Block(-4,31,5,LEAVES:7)
Block(-3,31,5,LEAVES:7)
Block(-7,31,6,LEAVES:7)
Block(-5,31,6,LEAVES:7)
Block(-4,31,6,LEAVES:7)
Block(-3,31,6,LEAVES:7)
Block(-2,31,6,LEAVES:7)
Block(-1,31,6,LEAVES:7)
Block(0,31,6,LEAVES:7)
Block(2,31,7,LEAVES:7)
Block(-3,32,-6,LEAVES:7)
Block(-4,32,-5,LEAVES:7)
Block(-3,32,-5,LEAVES:7)
Block(-2,32,-5,LEAVES:7)
Block(-5,32,-4,LEAVES:7)
Block(-4,32,-4,LEAVES:7)
Block(-3,32,-4,LEAVES:7)
Block(-2,32,-4,LEAVES:7)
Block(-1,32,-4,LEAVES:7)
Block(-7,32,-3,LEAVES:7)
Block(-6,32,-3,LEAVES:7)
Block(-5,32,-3,LEAVES:7)
Block(-4,32,-3,LEAVES:7)
Block(-3,32,-3,LEAVES:7)
Block(-2,32,-3,LEAVES:7)
Block(-1,32,-3,LEAVES:7)
Block(0,32,-3,LEAVES:7)
Block(-8,32,-2,LEAVES:7)
Block(-7,32,-2,LEAVES:7)
Block(-5,32,-2,LEAVES:7)
Block(-4,32,-2,LEAVES:7)
Block(-3,32,-2,LEAVES:7)
Block(-2,32,-2,LEAVES:7)
Block(-1,32,-2,LEAVES:7)
Block(-9,32,-1,LEAVES:7)
Block(-8,32,-1,LEAVES:7)
Block(-7,32,-1,LEAVES:7)
Block(-6,32,-1,LEAVES:7)
Block(-4,32,-1,LEAVES:7)
Block(-3,32,-1,LEAVES:7)
Block(-2,32,-1,LEAVES:7)
Block(1,32,-1,LEAVES:7)
Block(-10,32,0,LEAVES:7)
Block(-9,32,0,LEAVES:7)
Block(-8,32,0,LEAVES:7)
Block(-7,32,0,LEAVES:7)
Block(-3,32,0,LEAVES:7)
Block(0,32,0,LEAVES:7)
Block(1,32,0,LEAVES:7)
Block(2,32,0,LEAVES:7)
Block(-11,32,1,LEAVES:7)
Block(-10,32,1,LEAVES:7)
Block(-9,32,1,LEAVES:7)
Block(-8,32,1,LEAVES:7)
Block(-7,32,1,LOG:15)
Block(-4,32,1,LEAVES:7)
Block(-3,32,1,LEAVES:7)
Block(-2,32,1,LEAVES:7)
Block(1,32,1,LEAVES:7)
Block(-9,32,2,LEAVES:7)
Block(-8,32,2,LEAVES:7)
Block(-6,32,2,LEAVES:7)
Block(-5,32,2,LEAVES:7)
Block(-4,32,2,LEAVES:7)
Block(-3,32,2,LEAVES:7)
Block(-2,32,2,LEAVES:7)
Block(-1,32,2,LEAVES:7)
Block(-5,32,3,LEAVES:7)
Block(-4,32,3,LEAVES:7)
Block(-3,32,3,LEAVES:7)
Block(-2,32,3,LEAVES:7)
Block(-4,32,4,LEAVES:7)
Block(-3,32,4,LEAVES:7)
Block(-3,32,6,LEAVES:7)
Block(-3,33,-5,LEAVES:7)
Block(-4,33,-4,LEAVES:7)
Block(-3,33,-4,LEAVES:7)
Block(-2,33,-4,LEAVES:7)
Block(-5,33,-3,LEAVES:7)
Block(-4,33,-3,LEAVES:7)
Block(-3,33,-3,LEAVES:7)
Block(-2,33,-3,LEAVES:7)
Block(-1,33,-3,LEAVES:7)
Block(-7,33,-2,LEAVES:7)
Block(-4,33,-2,LEAVES:7)
Block(-3,33,-2,LEAVES:7)
Block(-2,33,-2,LEAVES:7)
Block(-8,33,-1,LEAVES:7)
Block(-7,33,-1,LEAVES:7)
Block(-3,33,-1,LEAVES:7)
Block(-9,33,0,LEAVES:7)
Block(-8,33,0,LEAVES:7)
Block(-7,33,0,LEAVES:7)
Block(1,33,0,LEAVES:7)
Block(-9,33,1,LEAVES:7)
Block(-8,33,1,LEAVES:7)
Block(-7,33,1,LEAVES:7)
Block(-5,33,1,LEAVES:7)
Block(-4,33,1,LEAVES:7)
Block(-3,33,1,LEAVES:7)
Block(-6,33,2,LEAVES:7)
Block(-5,33,2,LEAVES:7)
Block(-4,33,2,LEAVES:7)
Block(-3,33,2,LEAVES:7)
Block(-2,33,2,LEAVES:7)
Block(-3,33,3,LEAVES:7)
Block(-3,33,4,LEAVES:7)
Block(-3,34,-4,LEAVES:7)
Block(-4,34,-3,LEAVES:7)
Block(-3,34,-3,LEAVES:7)
Block(-2,34,-3,LEAVES:7)
Block(-3,34,-2,LEAVES:7)
Block(-7,34,-1,LEAVES:7)
Block(-6,34,-1,LEAVES:7)
Block(-7,34,0,LEAVES:7)
Block(-6,34,0,LEAVES:7)
Block(-7,34,2,LEAVES:7)
Block(-6,34,2,LEAVES:7)
Block(-3,34,2,LEAVES:7)
Block(-3,34,3,LEAVES:7)
Block(-3,35,-3,LEAVES:7)

#######################################################################
# +-----------------------------------------------------------------+ #
# |                            BO3 checks                           | #
# +-----------------------------------------------------------------+ #
#######################################################################

# Require a condition at a certain location in order for the BO3 to be spawned.
# BlockCheck(x,y,z,BlockName[,BlockName[,...]]) - one of the blocks must be at the location
# BlockCheckNot(x,y,z,BlockName[,BlockName[,...]]) - all the blocks must not be at the location
# LightCheck(x,y,z,minLightLevel,maxLightLevel) - light must be between min and max (inclusive)

# You can use "Solid" as a BlockName for matching all solid blocks or "All" to match all blocks that aren't air.

# Examples:
BlockCheck(0,-1,0,GRASS,DIRT,DIRT:2,SAND,STONE,CLAY,GRAVEL)
#   BlockCheck(0,-1,0,Solid)       Require any solid block just below the object
#   BlockCheck(0,-1,0,WOOL)        Require any type of wool just below the object
#   BlockCheck(0,-1,0,WOOL:0)      Require white wool just below the object
#   BlockCheckNot(0,-1,0,WOOL:0)   Require that there is no white wool below the object
#   LightCheck(0,0,0,0,1)          Require almost complete darkness just below the object

#######################################################################
# +-----------------------------------------------------------------+ #
# |                             Branches                            | #
# +-----------------------------------------------------------------+ #
#######################################################################

# Branches are objects that will spawn when this object spawns when it is used in
# the CustomStructure resource. Branches can also have branches, making complex
# structures possible. See the wiki for more details.

# Regular Branches spawn each branch with an independent chance of spawning.
# Branch(x,y,z,branchName,rotation,chance[,anotherBranchName,rotation,chance[,...]][IndividualChance])
# branchName - name of the object to spawn.
# rotation - NORTH, SOUTH, EAST or WEST.
# IndividualChance - The chance each branch has to spawn, assumed to be 100 when left blank

# Weighted Branches spawn branches with a dependent chance of spawning.
# WeightedBranch(x,y,z,branchName,rotation,chance[,anotherBranchName,rotation,chance[,...]][MaxChanceOutOf])
# MaxChanceOutOf - The chance all branches have to spawn out of, assumed to be 100 when left blank

