#######################################################################
# +-----------------------------------------------------------------+ #
# |                            BO3 object                           | #
# +-----------------------------------------------------------------+ #
#######################################################################

# This is the config file of a custom object.
# If you add this object correctly to your BiomeConfigs, it will spawn in the world.

# This is the creator of this BO3 object
Author: BO3 BulkEdit (by LanToaster)

# A short description of this BO3 object
Description: This Object was Created with BO3_BulkEdit

# The BO3 version, don't change this! It can be used by external applications to do a version check.
Version: 3

# The settings mode, WriteAll, WriteWithoutComments or WriteDisable. See WorldConfig.
SettingsMode: WriteDisable


#######################################################################
# +-----------------------------------------------------------------+ #
# |                          Main settings                          | #
# +-----------------------------------------------------------------+ #
#######################################################################

# This needs to be set to true to spawn the object in the Tree and Sapling resources.
Tree: true

# The frequency of the BO3 from 1 to 200. Tries this many times to spawn this BO3 when using the CustomObject(...) resource.
# Ignored by Tree(..), Sapling(..) and CustomStructure(..)
Frequency: 1

# The rarity of the BO3 from 0 to 100. Each spawn attempt has rarity% chance to succeed when using the CustomObject(...) resource.
# Ignored by Tree(..), Sapling(..) and CustomStructure(..)
Rarity: 100.0

# If you set this to true, the BO3 will be placed with a random rotation.
RotateRandomly: true

# The spawn height of the BO3 - randomY, highestBlock or highestSolidBlock.
SpawnHeight: highestSolidBlock
SpawnHeightOffset: -1
# The height limits for the BO3.
MinHeight: 0

MaxHeight: 256

# Objects can have other objects attacthed to it: branches. Branches can also
# have branches attached to it, which can also have branches, etc. This is the
# maximum branch depth for this objects.
MaxBranchDepth: 10

# When spawned with the UseWorld keyword, this BO3 should NOT spawn in the following biomes.
# If you writer.write the BO3 name directly in the BiomeConfigs, this will be ignored.
ExcludedBiomes: All


#######################################################################
# +-----------------------------------------------------------------+ #
# |                      Source block settings                      | #
# +-----------------------------------------------------------------+ #
#######################################################################

# The block(s) the BO3 should spawn in.
SourceBlocks: AIR,GRASS,DIRT,STONE,SAND,GRAVEL,CLAY

# The maximum percentage of the BO3 that can be outside the SourceBlock.
# The BO3 won't be placed on a location with more blocks outside the SourceBlock than this percentage.
MaxPercentageOutsideSourceBlock: 0

# What to do when a block is about to be placed outside the SourceBlock? (dontPlace, placeAnyway)
OutsideSourceBlock: dontplace


#######################################################################
# +-----------------------------------------------------------------+ #
# |                              Blocks                             | #
# +-----------------------------------------------------------------+ #
#######################################################################

# All the blocks used in the BO3 are listed here. Possible blocks:
# Block(x,y,z,id[.data][,nbtfile.nbt)
# RandomBlock(x,y,z,id[:data][,nbtfile.nbt],chance[,id[:data][,nbtfile.nbt],chance[,...]])
# So RandomBlock(0,0,0,CHEST,chest.nbt,50,CHEST,anotherchest.nbt,100) will spawn a chest at
# the BO3 origin, and give it a 50% chance to have the contents of chest.nbt, or, if that
# fails, a 100% percent chance to have the contents of anotherchest.nbt.
Block(-6,0,-2,LOG:15)
Block(-5,0,-2,LOG:15)
Block(-5,0,-1,LOG:15)
Block(-4,0,-1,LOG:15)
Block(-4,0,0,LOG:15)
Block(-3,0,0,LOG:15)
Block(-2,0,0,LOG:15)
Block(-3,0,1,LOG:15)
Block(-2,0,1,LOG:15)
Block(-4,0,2,LOG:15)
Block(-2,0,2,LOG:15)
Block(-5,0,3,LOG:15)
Block(-4,0,3,LOG:15)
Block(-5,0,4,LOG:15)
Block(2,1,-10,LEAVES:12)
Block(-9,1,-5,LEAVES:12)
Block(-4,1,0,LOG:15)
Block(-3,1,0,LOG:15)
Block(-3,1,1,LOG:15)
Block(-2,1,1,LOG:15)
Block(-4,1,2,LOG:15)
Block(-3,1,2,LOG:15)
Block(-2,1,2,LOG:15)
Block(-4,1,3,LOG:15)
Block(2,1,8,LEAVES:12)
Block(2,2,-10,LEAVES:12)
Block(-9,2,-5,LEAVES:12)
Block(7,2,-3,LEAVES:12)
Block(-3,2,0,LOG:15)
Block(-3,2,1,LOG:15)
Block(-2,2,1,LOG:15)
Block(8,2,1,LEAVES:12)
Block(2,2,8,LEAVES:12)
Block(-7,3,-11,LEAVES:12)
Block(-2,3,-10,LEAVES:12)
Block(2,3,-10,LEAVES:12)
Block(7,3,-10,LEAVES:12)
Block(-9,3,-5,LEAVES:12)
Block(7,3,-3,LEAVES:12)
Block(-7,3,-1,LEAVES:12)
Block(-2,3,-1,LOG:15)
Block(-3,3,0,LOG:15)
Block(-2,3,0,LOG:15)
Block(-3,3,1,LOG:15)
Block(-2,3,1,LOG:15)
Block(-1,3,1,LOG:15)
Block(8,3,1,LEAVES:12)
Block(-1,3,5,LEAVES:12)
Block(4,3,7,LEAVES:12)
Block(2,3,8,LEAVES:12)
Block(-7,4,-11,LEAVES:12)
Block(-5,4,-11,LEAVES:12)
Block(-2,4,-10,LEAVES:12)
Block(2,4,-10,LEAVES:12)
Block(7,4,-10,LEAVES:12)
Block(-9,4,-8,LEAVES:12)
Block(-9,4,-5,LEAVES:12)
Block(7,4,-3,LEAVES:12)
Block(-7,4,-1,LEAVES:12)
Block(-2,4,-1,LOG:15)
Block(-2,4,0,LOG:15)
Block(-1,4,0,LOG:15)
Block(-9,4,1,LEAVES:12)
Block(-2,4,1,LOG:15)
Block(8,4,1,LEAVES:12)
Block(5,4,4,LEAVES:12)
Block(-1,4,5,LEAVES:12)
Block(4,4,7,LEAVES:12)
Block(2,4,8,LEAVES:12)
Block(-7,5,-11,LEAVES:12)
Block(-5,5,-11,LEAVES:12)
Block(-2,5,-10,LEAVES:12)
Block(2,5,-10,LEAVES:12)
Block(7,5,-10,LEAVES:12)
Block(-9,5,-8,LEAVES:12)
Block(-9,5,-5,LEAVES:12)
Block(7,5,-3,LEAVES:12)
Block(-7,5,-1,LEAVES:12)
Block(-2,5,-1,LOG:15)
Block(-1,5,-1,LOG:15)
Block(-2,5,0,LOG:15)
Block(-1,5,0,LOG:15)
Block(0,5,0,LOG:15)
Block(-9,5,1,LEAVES:12)
Block(-1,5,1,LOG:15)
Block(8,5,1,LEAVES:12)
Block(9,5,1,LEAVES:12)
Block(5,5,4,LEAVES:12)
Block(0,5,5,LEAVES:12)
Block(4,5,7,LEAVES:12)
Block(2,5,8,LEAVES:12)
Block(3,5,8,LEAVES:12)
Block(-7,6,-11,LEAVES:12)
Block(-5,6,-11,LEAVES:12)
Block(-2,6,-10,LEAVES:12)
Block(2,6,-10,LEAVES:12)
Block(7,6,-10,LEAVES:12)
Block(-9,6,-8,LEAVES:12)
Block(-9,6,-6,LEAVES:12)
Block(-9,6,-5,LOG:15)
Block(-8,6,-5,LEAVES:12)
Block(-5,6,-4,LEAVES:12)
Block(6,6,-3,LEAVES:12)
Block(7,6,-3,LEAVES:12)
Block(-1,6,-2,LOG:15)
Block(0,6,-2,LOG:15)
Block(-7,6,-1,LEAVES:12)
Block(-1,6,-1,LOG:15)
Block(0,6,-1,LOG:15)
Block(-2,6,0,LOG:15)
Block(-1,6,0,LOG:15)
Block(0,6,0,LOG:15)
Block(-9,6,1,LEAVES:12)
Block(0,6,1,LOG:15)
Block(8,6,1,LOG:15)
Block(9,6,1,LEAVES:12)
Block(8,6,2,LEAVES:12)
Block(5,6,4,LEAVES:12)
Block(0,6,5,LEAVES:12)
Block(4,6,7,LEAVES:12)
Block(1,6,8,LEAVES:12)
Block(2,6,8,LOG:15)
Block(3,6,8,LEAVES:12)
Block(2,6,9,LEAVES:12)
Block(-7,7,-12,LEAVES:12)
Block(-8,7,-11,LEAVES:12)
Block(-7,7,-11,LOG:15)
Block(-5,7,-11,LEAVES:12)
Block(-2,7,-11,LEAVES:12)
Block(2,7,-11,LEAVES:12)
Block(-7,7,-10,LEAVES:12)
Block(-2,7,-10,LOG:15)
Block(-1,7,-10,LEAVES:12)
Block(1,7,-10,LEAVES:12)
Block(2,7,-10,LOG:15)
Block(3,7,-10,LEAVES:12)
Block(7,7,-10,LEAVES:12)
Block(-9,7,-8,LEAVES:12)
Block(-9,7,-6,LEAVES:12)
Block(-10,7,-5,LEAVES:12)
Block(-9,7,-5,LOG:15)
Block(-8,7,-5,LEAVES:12)
Block(-9,7,-4,LEAVES:12)
Block(-5,7,-4,LEAVES:12)
Block(6,7,-4,LEAVES:12)
Block(6,7,-3,LEAVES:12)
Block(7,7,-3,LOG:15)
Block(8,7,-3,LEAVES:12)
Block(-1,7,-2,LOG:15)
Block(0,7,-2,LOG:15)
Block(-8,7,-1,LEAVES:12)
Block(-7,7,-1,LEAVES:12)
Block(0,7,-1,LOG:15)
Block(8,7,-1,LEAVES:12)
Block(-1,7,0,LOG:15)
Block(0,7,0,LOG:15)
Block(8,7,0,LEAVES:12)
Block(9,7,0,LEAVES:12)
Block(-9,7,1,LEAVES:12)
Block(0,7,1,LOG:15)
Block(8,7,1,LOG:15)
Block(9,7,1,LEAVES:12)
Block(8,7,2,LEAVES:12)
Block(5,7,4,LEAVES:12)
Block(0,7,5,LEAVES:12)
Block(2,7,7,LEAVES:12)
Block(4,7,7,LEAVES:12)
Block(1,7,8,LEAVES:12)
Block(2,7,8,LOG:15)
Block(3,7,8,LEAVES:12)
Block(0,7,9,LEAVES:12)
Block(1,7,9,LEAVES:12)
Block(2,7,9,LEAVES:12)
Block(-7,8,-12,LEAVES:12)
Block(-8,8,-11,LEAVES:12)
Block(-7,8,-11,LOG:15)
Block(-6,8,-11,LEAVES:12)
Block(-5,8,-11,LEAVES:12)
Block(-3,8,-11,LEAVES:12)
Block(3,8,-11,LEAVES:12)
Block(-7,8,-10,LEAVES:12)
Block(-6,8,-10,LEAVES:12)
Block(-2,8,-10,LOG:15)
Block(-1,8,-10,LEAVES:12)
Block(1,8,-10,LEAVES:12)
Block(2,8,-10,LOG:15)
Block(3,8,-10,LEAVES:12)
Block(6,8,-10,LEAVES:12)
Block(7,8,-10,LEAVES:12)
Block(8,8,-10,LEAVES:12)
Block(-2,8,-9,LEAVES:12)
Block(1,8,-9,LEAVES:12)
Block(2,8,-9,LEAVES:12)
Block(3,8,-9,LEAVES:12)
Block(-9,8,-8,LEAVES:12)
Block(-9,8,-6,LEAVES:12)
Block(-8,8,-6,LEAVES:12)
Block(-10,8,-5,LEAVES:12)
Block(-9,8,-5,LOG:15)
Block(-8,8,-5,LEAVES:12)
Block(-10,8,-4,LEAVES:12)
Block(7,8,-4,LEAVES:12)
Block(-5,8,-3,LEAVES:12)
Block(-1,8,-3,LOG:15)
Block(0,8,-3,LOG:15)
Block(6,8,-3,LEAVES:12)
Block(7,8,-3,LOG:15)
Block(8,8,-3,LEAVES:12)
Block(-7,8,-2,LEAVES:12)
Block(-1,8,-2,LOG:15)
Block(0,8,-2,LOG:15)
Block(-8,8,-1,LEAVES:12)
Block(-7,8,-1,LOG:15)
Block(-6,8,-1,LEAVES:12)
Block(-8,8,0,LEAVES:12)
Block(-7,8,0,LEAVES:12)
Block(-1,8,0,LOG:15)
Block(0,8,0,LOG:15)
Block(9,8,0,LEAVES:12)
Block(-9,8,1,LEAVES:12)
Block(-1,8,1,LOG:15)
Block(0,8,1,LOG:15)
Block(7,8,1,LEAVES:12)
Block(8,8,1,LOG:15)
Block(9,8,1,LEAVES:12)
Block(0,8,2,LOG:15)
Block(8,8,2,LEAVES:12)
Block(4,8,3,LEAVES:12)
Block(5,8,3,LEAVES:12)
Block(5,8,4,LEAVES:12)
Block(0,8,5,LEAVES:12)
Block(0,8,7,LEAVES:12)
Block(1,8,7,LEAVES:12)
Block(2,8,7,LOG:15)
Block(3,8,7,LEAVES:12)
Block(4,8,7,LEAVES:12)
Block(1,8,8,LEAVES:12)
Block(2,8,8,LOG:15)
Block(-7,9,-12,LEAVES:12)
Block(-8,9,-11,LEAVES:12)
Block(-7,9,-11,LOG:15)
Block(-3,9,-11,LEAVES:12)
Block(-2,9,-11,LEAVES:12)
Block(2,9,-11,LEAVES:12)
Block(3,9,-11,LEAVES:12)
Block(7,9,-11,LEAVES:12)
Block(8,9,-11,LEAVES:12)
Block(-7,9,-10,LEAVES:12)
Block(-6,9,-10,LEAVES:12)
Block(-3,9,-10,LEAVES:12)
Block(-2,9,-10,LOG:15)
Block(-1,9,-10,LEAVES:12)
Block(1,9,-10,LEAVES:12)
Block(2,9,-10,LOG:15)
Block(3,9,-10,LEAVES:12)
Block(6,9,-10,LEAVES:12)
Block(7,9,-10,LOG:15)
Block(8,9,-10,LEAVES:12)
Block(-7,9,-9,LEAVES:12)
Block(-3,9,-9,LEAVES:12)
Block(-2,9,-9,LEAVES:12)
Block(2,9,-9,LEAVES:12)
Block(3,9,-9,LEAVES:12)
Block(7,9,-9,LEAVES:12)
Block(8,9,-9,LEAVES:12)
Block(-9,9,-8,LEAVES:12)
Block(-9,9,-6,LEAVES:12)
Block(-8,9,-6,LEAVES:12)
Block(-10,9,-5,LEAVES:12)
Block(-9,9,-5,LOG:15)
Block(-8,9,-5,LEAVES:12)
Block(-9,9,-4,LEAVES:12)
Block(-8,9,-4,LEAVES:12)
Block(7,9,-4,LEAVES:12)
Block(-5,9,-3,LEAVES:12)
Block(-1,9,-3,LOG:15)
Block(0,9,-3,LOG:15)
Block(6,9,-3,LEAVES:12)
Block(7,9,-3,LOG:15)
Block(8,9,-3,LEAVES:12)
Block(-1,9,-2,LOG:15)
Block(0,9,-2,LOG:15)
Block(7,9,-2,LEAVES:12)
Block(-8,9,-1,LEAVES:12)
Block(-7,9,-1,LOG:15)
Block(-8,9,0,LEAVES:12)
Block(-7,9,0,LEAVES:12)
Block(7,9,0,LEAVES:12)
Block(8,9,0,LEAVES:12)
Block(-9,9,1,LEAVES:12)
Block(-8,9,1,LEAVES:12)
Block(0,9,1,LOG:15)
Block(1,9,1,LOG:15)
Block(7,9,1,LOG:15)
Block(8,9,1,LOG:15)
Block(9,9,1,LEAVES:12)
Block(1,9,2,LOG:15)
Block(6,9,2,LEAVES:12)
Block(7,9,2,LEAVES:12)
Block(8,9,2,LEAVES:12)
Block(4,9,3,LEAVES:12)
Block(5,9,3,LEAVES:12)
Block(0,9,5,LEAVES:12)
Block(1,9,7,LEAVES:12)
Block(2,9,7,LOG:15)
Block(3,9,7,LEAVES:12)
Block(1,9,8,LEAVES:12)
Block(2,9,8,LEAVES:12)
Block(3,9,8,LEAVES:12)
Block(-4,9,12,LEAVES:12)
Block(-3,9,12,LEAVES:12)
Block(-8,10,-12,LEAVES:12)
Block(-7,10,-12,LEAVES:12)
Block(-6,10,-12,LEAVES:12)
Block(-8,10,-11,LEAVES:12)
Block(-7,10,-11,LEAVES:12)
Block(-6,10,-11,LEAVES:12)
Block(-2,10,-11,LEAVES:12)
Block(7,10,-11,LEAVES:12)
Block(-8,10,-10,LEAVES:12)
Block(-7,10,-10,LOG:15)
Block(-6,10,-10,LEAVES:12)
Block(-3,10,-10,LEAVES:12)
Block(-2,10,-10,LOG:15)
Block(-1,10,-10,LEAVES:12)
Block(2,10,-10,LEAVES:12)
Block(3,10,-10,LOG:15)
Block(4,10,-10,LEAVES:12)
Block(6,10,-10,LEAVES:12)
Block(7,10,-10,LOG:15)
Block(8,10,-10,LEAVES:12)
Block(-7,10,-9,LEAVES:12)
Block(-2,10,-9,LEAVES:12)
Block(3,10,-9,LEAVES:12)
Block(7,10,-9,LEAVES:12)
Block(-9,10,-8,LEAVES:12)
Block(-9,10,-6,LEAVES:12)
Block(-8,10,-6,LEAVES:12)
Block(-10,10,-5,LEAVES:12)
Block(-9,10,-5,LEAVES:12)
Block(-8,10,-5,LOG:15)
Block(-7,10,-5,LEAVES:12)
Block(-8,10,-4,LEAVES:12)
Block(-7,10,-4,LEAVES:12)
Block(-1,10,-4,LOG:15)
Block(0,10,-4,LOG:15)
Block(7,10,-4,LEAVES:12)
Block(-5,10,-3,LEAVES:12)
Block(-1,10,-3,LOG:15)
Block(0,10,-3,LOG:15)
Block(7,10,-3,LOG:15)
Block(8,10,-3,LEAVES:12)
Block(-6,10,-2,LEAVES:12)
Block(-5,10,-2,LEAVES:12)
Block(-1,10,-2,LOG:15)
Block(7,10,-2,LEAVES:12)
Block(-8,10,-1,LEAVES:12)
Block(-7,10,-1,LOG:15)
Block(-6,10,-1,LOG:15)
Block(-8,10,0,LEAVES:12)
Block(-7,10,0,LEAVES:12)
Block(-8,10,1,LEAVES:12)
Block(-7,10,1,LEAVES:12)
Block(-6,10,1,LEAVES:12)
Block(1,10,1,LOG:15)
Block(6,10,1,LOG:15)
Block(7,10,1,LOG:15)
Block(8,10,1,LEAVES:12)
Block(1,10,2,LOG:15)
Block(5,10,2,LOG:15)
Block(6,10,2,LOG:15)
Block(4,10,3,LEAVES:12)
Block(5,10,3,LEAVES:12)
Block(0,10,5,LEAVES:12)
Block(1,10,5,LEAVES:12)
Block(2,10,5,LEAVES:12)
Block(3,10,5,LEAVES:12)
Block(0,10,6,LEAVES:12)
Block(1,10,6,LEAVES:12)
Block(2,10,6,LOG:15)
Block(1,10,7,LEAVES:12)
Block(2,10,7,LOG:15)
Block(3,10,7,LEAVES:12)
Block(2,10,8,LEAVES:12)
Block(-7,11,-11,LEAVES:12)
Block(-2,11,-11,LEAVES:12)
Block(3,11,-11,LEAVES:12)
Block(-8,11,-10,LEAVES:12)
Block(-7,11,-10,LOG:15)
Block(-6,11,-10,LEAVES:12)
Block(-2,11,-10,LOG:15)
Block(3,11,-10,LOG:15)
Block(4,11,-10,LEAVES:12)
Block(6,11,-10,LEAVES:12)
Block(7,11,-10,LOG:15)
Block(-7,11,-9,LEAVES:12)
Block(-2,11,-9,LOG:15)
Block(2,11,-9,LEAVES:12)
Block(3,11,-9,LEAVES:12)
Block(7,11,-9,LEAVES:12)
Block(8,11,-9,LEAVES:12)
Block(-9,11,-8,LEAVES:12)
Block(-8,11,-8,LEAVES:12)
Block(-8,11,-6,LEAVES:12)
Block(-10,11,-5,LEAVES:12)
Block(-8,11,-5,LOG:15)
Block(-7,11,-5,LEAVES:12)
Block(-3,11,-4,LEAVES:12)
Block(-2,11,-4,LOG:15)
Block(-1,11,-4,LOG:15)
Block(0,11,-4,LOG:15)
Block(1,11,-4,LEAVES:12)
Block(7,11,-4,LEAVES:12)
Block(8,11,-4,LEAVES:12)
Block(-5,11,-3,LEAVES:12)
Block(-3,11,-3,LEAVES:12)
Block(-2,11,-3,LEAVES:12)
Block(6,11,-3,LEAVES:12)
Block(7,11,-3,LOG:15)
Block(-7,11,-2,LEAVES:12)
Block(-6,11,-2,LOG:15)
Block(-5,11,-2,LOG:15)
Block(-4,11,-2,LEAVES:12)
Block(-3,11,-2,LEAVES:12)
Block(-7,11,-1,LEAVES:12)
Block(-6,11,-1,LOG:15)
Block(-5,11,-1,LEAVES:12)
Block(-8,11,0,LEAVES:12)
Block(-7,11,0,LEAVES:12)
Block(-6,11,0,LEAVES:12)
Block(1,11,1,LOG:15)
Block(2,11,1,LOG:15)
Block(3,11,1,LEAVES:12)
Block(5,11,1,LEAVES:12)
Block(6,11,1,LEAVES:12)
Block(7,11,1,LEAVES:12)
Block(1,11,2,LOG:15)
Block(4,11,2,LEAVES:12)
Block(5,11,2,LOG:15)
Block(6,11,2,LOG:15)
Block(7,11,2,LEAVES:12)
Block(1,11,3,LEAVES:12)
Block(2,11,3,LEAVES:12)
Block(3,11,3,LEAVES:12)
Block(4,11,3,LOG:15)
Block(5,11,3,LOG:15)
Block(6,11,3,LEAVES:12)
Block(7,11,3,LEAVES:12)
Block(1,11,4,LEAVES:12)
Block(4,11,4,LEAVES:12)
Block(0,11,5,LEAVES:12)
Block(1,11,5,LEAVES:12)
Block(2,11,5,LOG:15)
Block(1,11,6,LEAVES:12)
Block(2,11,6,LOG:15)
Block(3,11,6,LEAVES:12)
Block(2,11,7,LEAVES:12)
Block(-7,12,-10,LEAVES:12)
Block(-3,12,-10,LEAVES:12)
Block(-2,12,-10,LEAVES:12)
Block(3,12,-10,LOG:15)
Block(7,12,-10,LOG:15)
Block(8,12,-10,LEAVES:12)
Block(-8,12,-9,LEAVES:12)
Block(-7,12,-9,LOG:15)
Block(-6,12,-9,LEAVES:12)
Block(-2,12,-9,LOG:15)
Block(2,12,-9,LEAVES:12)
Block(3,12,-9,LOG:15)
Block(4,12,-9,LEAVES:12)
Block(6,12,-9,LEAVES:12)
Block(7,12,-9,LOG:15)
Block(8,12,-9,LEAVES:12)
Block(-8,12,-8,LEAVES:12)
Block(-7,12,-8,LEAVES:12)
Block(-6,12,-8,LEAVES:12)
Block(7,12,-8,LEAVES:12)
Block(-8,12,-6,LEAVES:12)
Block(-9,12,-5,LEAVES:12)
Block(-8,12,-5,LOG:15)
Block(-3,12,-5,LEAVES:12)
Block(-2,12,-5,LOG:15)
Block(0,12,-5,LOG:15)
Block(2,12,-5,LEAVES:12)
Block(7,12,-5,LEAVES:12)
Block(-8,12,-4,LEAVES:12)
Block(-4,12,-4,LEAVES:12)
Block(-3,12,-4,LEAVES:12)
Block(-2,12,-4,LOG:15)
Block(-1,12,-4,LOG:15)
Block(0,12,-4,LOG:15)
Block(1,12,-4,LOG:15)
Block(7,12,-4,LEAVES:12)
Block(-5,12,-3,LEAVES:12)
Block(-3,12,-3,LOG:15)
Block(-2,12,-3,LOG:15)
Block(-1,12,-3,LEAVES:12)
Block(7,12,-3,LOG:15)
Block(8,12,-3,LEAVES:12)
Block(-7,12,-2,LEAVES:12)
Block(-5,12,-2,LOG:15)
Block(-4,12,-2,LOG:15)
Block(-3,12,-2,LOG:15)
Block(-2,12,-2,LEAVES:12)
Block(7,12,-2,LEAVES:12)
Block(-6,12,-1,LEAVES:12)
Block(-5,12,-1,LEAVES:12)
Block(-4,12,-1,LEAVES:12)
Block(-6,12,0,LEAVES:12)
Block(2,12,0,LEAVES:12)
Block(1,12,1,LEAVES:12)
Block(2,12,1,LOG:15)
Block(3,12,1,LEAVES:12)
Block(6,12,1,LEAVES:12)
Block(0,12,2,LEAVES:12)
Block(1,12,2,LOG:15)
Block(2,12,2,LOG:15)
Block(3,12,2,LOG:15)
Block(4,12,2,LEAVES:12)
Block(5,12,2,LEAVES:12)
Block(7,12,2,LEAVES:12)
Block(1,12,3,LEAVES:12)
Block(2,12,3,LOG:15)
Block(3,12,3,LOG:15)
Block(4,12,3,LOG:15)
Block(5,12,3,LEAVES:12)
Block(6,12,3,LEAVES:12)
Block(7,12,3,LEAVES:12)
Block(1,12,4,LEAVES:12)
Block(2,12,4,LOG:15)
Block(3,12,4,LOG:15)
Block(4,12,4,LEAVES:12)
Block(5,12,4,LEAVES:12)
Block(2,12,5,LOG:15)
Block(1,12,6,LEAVES:12)
Block(2,12,6,LEAVES:12)
Block(-8,13,-11,LEAVES:12)
Block(-2,13,-11,LEAVES:12)
Block(2,13,-11,LEAVES:12)
Block(3,13,-11,LEAVES:12)
Block(7,13,-11,LEAVES:12)
Block(8,13,-11,LEAVES:12)
Block(-8,13,-10,LEAVES:12)
Block(-7,13,-10,LEAVES:12)
Block(-3,13,-10,LEAVES:12)
Block(-2,13,-10,LEAVES:12)
Block(-1,13,-10,LEAVES:12)
Block(2,13,-10,LEAVES:12)
Block(3,13,-10,LEAVES:12)
Block(4,13,-10,LEAVES:12)
Block(6,13,-10,LEAVES:12)
Block(7,13,-10,LEAVES:12)
Block(8,13,-10,LEAVES:12)
Block(-8,13,-9,LEAVES:12)
Block(-7,13,-9,LOG:15)
Block(-6,13,-9,LOG:15)
Block(-4,13,-9,LEAVES:12)
Block(-2,13,-9,LOG:15)
Block(2,13,-9,LEAVES:12)
Block(3,13,-9,LOG:15)
Block(6,13,-9,LOG:15)
Block(7,13,-9,LOG:15)
Block(8,13,-9,LEAVES:12)
Block(-7,13,-8,LEAVES:12)
Block(-6,13,-8,LOG:15)
Block(-3,13,-8,LOG:15)
Block(-2,13,-8,LOG:15)
Block(3,13,-8,LEAVES:12)
Block(4,13,-8,LEAVES:12)
Block(5,13,-8,LEAVES:12)
Block(6,13,-8,LEAVES:12)
Block(7,13,-8,LEAVES:12)
Block(8,13,-8,LEAVES:12)
Block(-7,13,-7,LEAVES:12)
Block(-6,13,-7,LOG:15)
Block(-5,13,-7,LOG:15)
Block(-3,13,-7,LOG:15)
Block(4,13,-7,LEAVES:12)
Block(5,13,-7,LEAVES:12)
Block(-8,13,-6,LEAVES:12)
Block(-7,13,-6,LEAVES:12)
Block(-6,13,-6,LEAVES:12)
Block(-5,13,-6,LEAVES:12)
Block(-4,13,-6,LEAVES:12)
Block(2,13,-6,LEAVES:12)
Block(4,13,-6,LEAVES:12)
Block(5,13,-6,LEAVES:12)
Block(-9,13,-5,LEAVES:12)
Block(-8,13,-5,LOG:15)
Block(-7,13,-5,LOG:15)
Block(-5,13,-5,LEAVES:12)
Block(-3,13,-5,LOG:15)
Block(-2,13,-5,LOG:15)
Block(0,13,-5,LEAVES:12)
Block(1,13,-5,LOG:15)
Block(2,13,-5,LEAVES:12)
Block(3,13,-5,LEAVES:12)
Block(7,13,-5,LEAVES:12)
Block(-4,13,-4,LEAVES:12)
Block(-3,13,-4,LEAVES:12)
Block(-2,13,-4,LEAVES:12)
Block(0,13,-4,LEAVES:12)
Block(1,13,-4,LOG:15)
Block(6,13,-4,LEAVES:12)
Block(7,13,-4,LOG:15)
Block(8,13,-4,LEAVES:12)
Block(-4,13,-3,LEAVES:12)
Block(-3,13,-3,LEAVES:12)
Block(-2,13,-3,LEAVES:12)
Block(-1,13,-3,LEAVES:12)
Block(7,13,-3,LOG:15)
Block(8,13,-3,LEAVES:12)
Block(-4,13,-2,LEAVES:12)
Block(-3,13,-2,LEAVES:12)
Block(6,13,-2,LEAVES:12)
Block(7,13,-2,LEAVES:12)
Block(8,13,-2,LEAVES:12)
Block(-5,13,-1,LEAVES:12)
Block(-4,13,-1,LEAVES:12)
Block(2,13,0,LEAVES:12)
Block(3,13,1,LEAVES:12)
Block(1,13,2,LEAVES:12)
Block(2,13,2,LEAVES:12)
Block(3,13,2,LEAVES:12)
Block(5,13,2,LEAVES:12)
Block(6,13,2,LEAVES:12)
Block(1,13,3,LEAVES:12)
Block(2,13,3,LEAVES:12)
Block(3,13,3,LEAVES:12)
Block(4,13,3,LEAVES:12)
Block(5,13,3,LEAVES:12)
Block(2,13,4,LEAVES:12)
Block(4,13,4,LEAVES:12)
Block(5,13,4,LEAVES:12)
Block(1,13,5,LEAVES:12)
Block(2,13,5,LEAVES:12)
Block(3,13,5,LEAVES:12)
Block(-8,14,-11,LEAVES:12)
Block(-7,14,-10,LEAVES:12)
Block(-3,14,-10,LEAVES:12)
Block(-2,14,-10,LEAVES:12)
Block(2,14,-10,LEAVES:12)
Block(4,14,-10,LEAVES:12)
Block(6,14,-10,LEAVES:12)
Block(7,14,-10,LEAVES:12)
Block(-7,14,-9,LEAVES:12)
Block(-6,14,-9,LEAVES:12)
Block(-4,14,-9,LEAVES:12)
Block(-3,14,-9,LEAVES:12)
Block(3,14,-9,LOG:15)
Block(4,14,-9,LOG:15)
Block(5,14,-9,LEAVES:12)
Block(6,14,-9,LOG:15)
Block(-6,14,-8,LEAVES:12)
Block(-5,14,-8,LEAVES:12)
Block(-4,14,-8,LEAVES:12)
Block(-3,14,-8,LEAVES:12)
Block(-2,14,-8,LEAVES:12)
Block(4,14,-8,LOG:15)
Block(5,14,-8,LOG:15)
Block(6,14,-8,LOG:15)
Block(7,14,-8,LEAVES:12)
Block(-7,14,-7,LEAVES:12)
Block(-6,14,-7,LEAVES:12)
Block(-5,14,-7,LOG:15)
Block(-4,14,-7,LOG:15)
Block(-3,14,-7,LOG:15)
Block(4,14,-7,LOG:15)
Block(5,14,-7,LOG:15)
Block(6,14,-7,LOG:15)
Block(-8,14,-6,LEAVES:12)
Block(-7,14,-6,LOG:15)
Block(-6,14,-6,LOG:15)
Block(-5,14,-6,LOG:15)
Block(-4,14,-6,LOG:15)
Block(-3,14,-6,LOG:15)
Block(-2,14,-6,LEAVES:12)
Block(0,14,-6,LEAVES:12)
Block(2,14,-6,LOG:15)
Block(4,14,-6,LEAVES:12)
Block(6,14,-6,LEAVES:12)
Block(7,14,-6,LEAVES:12)
Block(-9,14,-5,LEAVES:12)
Block(-8,14,-5,LEAVES:12)
Block(-7,14,-5,LOG:15)
Block(-6,14,-5,LEAVES:12)
Block(-5,14,-5,LEAVES:12)
Block(-4,14,-5,LOG:15)
Block(-3,14,-5,LOG:15)
Block(-2,14,-5,LOG:15)
Block(-1,14,-5,LEAVES:12)
Block(0,14,-5,LEAVES:12)
Block(1,14,-5,LOG:15)
Block(2,14,-5,LOG:15)
Block(3,14,-5,LEAVES:12)
Block(4,14,-5,LEAVES:12)
Block(6,14,-5,LOG:15)
Block(7,14,-5,LEAVES:12)
Block(8,14,-5,LEAVES:12)
Block(-9,14,-4,LEAVES:12)
Block(-8,14,-4,LEAVES:12)
Block(-7,14,-4,LEAVES:12)
Block(-3,14,-4,LEAVES:12)
Block(-2,14,-4,LEAVES:12)
Block(0,14,-4,LEAVES:12)
Block(1,14,-4,LOG:15)
Block(6,14,-4,LOG:15)
Block(7,14,-4,LOG:15)
Block(-4,14,-3,LEAVES:12)
Block(1,14,-3,LEAVES:12)
Block(7,14,-3,LEAVES:12)
Block(8,14,-3,LEAVES:12)
Block(-3,14,-2,LEAVES:12)
Block(2,14,2,LEAVES:12)
Block(1,14,3,LEAVES:12)
Block(2,14,3,LEAVES:12)
Block(2,14,4,LEAVES:12)
Block(-3,15,-9,LEAVES:12)
Block(3,15,-9,LEAVES:12)
Block(4,15,-9,LEAVES:12)
Block(5,15,-9,LEAVES:12)
Block(6,15,-9,LEAVES:12)
Block(-4,15,-8,LEAVES:12)
Block(4,15,-8,LEAVES:12)
Block(5,15,-8,LEAVES:12)
Block(-6,15,-7,LEAVES:12)
Block(-5,15,-7,LEAVES:12)
Block(-3,15,-7,LEAVES:12)
Block(3,15,-7,LEAVES:12)
Block(4,15,-7,LOG:15)
Block(5,15,-7,LOG:15)
Block(6,15,-7,LEAVES:12)
Block(7,15,-7,LEAVES:12)
Block(-7,15,-6,LEAVES:12)
Block(-6,15,-6,LEAVES:12)
Block(-5,15,-6,LEAVES:12)
Block(-4,15,-6,LEAVES:12)
Block(-3,15,-6,LEAVES:12)
Block(-2,15,-6,LEAVES:12)
Block(1,15,-6,LEAVES:12)
Block(2,15,-6,LOG:15)
Block(3,15,-6,LOG:15)
Block(4,15,-6,LOG:15)
Block(5,15,-6,LOG:15)
Block(6,15,-6,LOG:15)
Block(-7,15,-5,LEAVES:12)
Block(-5,15,-5,LEAVES:12)
Block(-4,15,-5,LEAVES:12)
Block(-3,15,-5,LEAVES:12)
Block(-2,15,-5,LEAVES:12)
Block(1,15,-5,LEAVES:12)
Block(2,15,-5,LOG:15)
Block(3,15,-5,LOG:15)
Block(4,15,-5,LEAVES:12)
Block(5,15,-5,LEAVES:12)
Block(6,15,-5,LOG:15)
Block(7,15,-5,LEAVES:12)
Block(-5,15,-4,LEAVES:12)
Block(-3,15,-4,LEAVES:12)
Block(1,15,-4,LEAVES:12)
Block(2,15,-4,LEAVES:12)
Block(7,15,-3,LEAVES:12)
Block(5,16,-9,LEAVES:12)
Block(4,16,-8,LEAVES:12)
Block(5,16,-8,LEAVES:12)
Block(3,16,-7,LEAVES:12)
Block(4,16,-7,LEAVES:12)
Block(5,16,-7,LEAVES:12)
Block(6,16,-7,LEAVES:12)
Block(2,16,-6,LEAVES:12)
Block(3,16,-6,LEAVES:12)
Block(4,16,-6,LEAVES:12)
Block(5,16,-6,LEAVES:12)
Block(6,16,-6,LEAVES:12)
Block(7,16,-6,LEAVES:12)
Block(2,16,-5,LEAVES:12)
Block(3,16,-5,LEAVES:12)
Block(6,16,-4,LEAVES:12)

#######################################################################
# +-----------------------------------------------------------------+ #
# |                            BO3 checks                           | #
# +-----------------------------------------------------------------+ #
#######################################################################

# Require a condition at a certain location in order for the BO3 to be spawned.
# BlockCheck(x,y,z,BlockName[,BlockName[,...]]) - one of the blocks must be at the location
# BlockCheckNot(x,y,z,BlockName[,BlockName[,...]]) - all the blocks must not be at the location
# LightCheck(x,y,z,minLightLevel,maxLightLevel) - light must be between min and max (inclusive)

# You can use "Solid" as a BlockName for matching all solid blocks or "All" to match all blocks that aren't air.

# Examples:
BlockCheck(0,-1,0,GRASS,DIRT,DIRT:2,SAND)
#   BlockCheck(0,-1,0,Solid)       Require any solid block just below the object
#   BlockCheck(0,-1,0,WOOL)        Require any type of wool just below the object
#   BlockCheck(0,-1,0,WOOL:0)      Require white wool just below the object
#   BlockCheckNot(0,-1,0,WOOL:0)   Require that there is no white wool below the object
#   LightCheck(0,0,0,0,1)          Require almost complete darkness just below the object

#######################################################################
# +-----------------------------------------------------------------+ #
# |                             Branches                            | #
# +-----------------------------------------------------------------+ #
#######################################################################

# Branches are objects that will spawn when this object spawns when it is used in
# the CustomStructure resource. Branches can also have branches, making complex
# structures possible. See the wiki for more details.

# Regular Branches spawn each branch with an independent chance of spawning.
# Branch(x,y,z,branchName,rotation,chance[,anotherBranchName,rotation,chance[,...]][IndividualChance])
# branchName - name of the object to spawn.
# rotation - NORTH, SOUTH, EAST or WEST.
# IndividualChance - The chance each branch has to spawn, assumed to be 100 when left blank

# Weighted Branches spawn branches with a dependent chance of spawning.
# WeightedBranch(x,y,z,branchName,rotation,chance[,anotherBranchName,rotation,chance[,...]][MaxChanceOutOf])
# MaxChanceOutOf - The chance all branches have to spawn out of, assumed to be 100 when left blank
