#######################################################################
# +-----------------------------------------------------------------+ #
# |                            BO3 object                           | #
# +-----------------------------------------------------------------+ #
#######################################################################

# The descriptions in this file are accurate only for TerrainControl and OTG.
# For MCW and OTG+ these descriptions are only accurate if the BO3 is used as a CustomObject.
# MCW and OTG+ completely reimplemented CustomStructure, check the MCW/OTG+ documentation for more information.

# This is the config file of a custom object.
# If you add this object correctly to your BiomeConfigs, it will spawn in the world.

# This is the creator of this BO3 object
Author: Unknown

# A short description of this BO3 object
Description: This BO3 was converted from a schematic using OTGEdit. The author and description information of the schematic could not be found. If you know who the author of the schematic is then please add this information.

# The BO3 version, don't change this! It can be used by external applications to do a version check.
Version: 3

# The settings mode, WriteAll, WriteWithoutComments or WriteDisable. See WorldConfig.
SettingsMode: WriteDisable

#######################################################################
# +-----------------------------------------------------------------+ #
# |                          Main settings                          | #
# +-----------------------------------------------------------------+ #
#######################################################################

# This needs to be set to true to spawn the object in the Tree and Sapling resources.
Tree: true

# The frequency of the BO3 from 1 to 200. Tries this many times to spawn this BO3 when using the CustomObject(...) resource.
# Ignored by Tree(..), Sapling(..) and CustomStructure(..)
Frequency: 40

# The rarity of the BO3 from 0 to 100. Each spawn attempt has rarity% chance to succeed when using the CustomObject(...) resource.
# Ignored by Tree(..), Sapling(..) and CustomStructure(..)
Rarity: 100.0

# If you set this to true, the BO3 will be placed with a random rotation.
RotateRandomly: true

# The spawn height of the BO3 - randomY, highestBlock or highestSolidBlock.
SpawnHeight: highestSolidBlock
SpawnHeightOffset: -1
# The height limits for the BO3.
MinHeight: 0

MaxHeight: 256

# Objects can have other objects attached to it: branches. Branches can also
# have branches attached to it, which can also have branches, etc. This is the
# maximum branch depth for this objects.
MaxBranchDepth: 10

# When spawned with the UseWorld keyword, this BO3 should NOT spawn in the following biomes.
# If you writer.write the BO3 name directly in the BiomeConfigs, this will be ignored.
ExcludedBiomes: All

# To optimise this BO3 for faster loading times you can use Notepad++ to find/replace comments and abbreviate things.
# Notepad++ find/replace with regex:
# Find: ^[#;].* replace to nothing removes all lines starting with # 
# Find: ^\s*$ replace to nothing removes most empty lines 
# Notepad++ find/replace without regex:
# *Warning: This will only work for OTG 1.10.2 v21 / OTG 1.11.2 v6 or higher. B( is not recognised by lower versions.
# Find: Block( replace to B(

#######################################################################
# +-----------------------------------------------------------------+ #
# |                      Source block settings                      | #
# +-----------------------------------------------------------------+ #
#######################################################################

# The block(s) the BO3 should spawn in.
SourceBlocks: AIR,GRASS,DIRT

# The maximum percentage of the BO3 that can be outside the SourceBlock.
# The BO3 won't be placed on a location with more blocks outside the SourceBlock than this percentage.
MaxPercentageOutsideSourceBlock: 5

# What to do when a block is about to be placed outside the SourceBlock? (dontPlace, placeAnyway)
OutsideSourceBlock: placeAnyway

#######################################################################
# +-----------------------------------------------------------------+ #
# |                              Blocks                             | #
# +-----------------------------------------------------------------+ #
#######################################################################

# All the blocks used in the BO3 are listed here. Possible blocks:
# Block(x,y,z,id[.data][,nbtfile.nbt) or B(x,y,z,id[.data][,nbtfile.nbt)
# RandomBlock(x,y,z,id[:data][,nbtfile.nbt],chance[,id[:data][,nbtfile.nbt],chance[,...]])
# So RandomBlock(0,0,0,CHEST,chest.nbt,50,CHEST,anotherchest.nbt,100) will spawn a chest at
# the BO3 origin, and give it a 50% chance to have the contents of chest.nbt, or, if that
# fails, a 100% percent chance to have the contents of anotherchest.nbt.

Block(-18,16,-1,LEAVES2:13)
Block(-18,16,0,LEAVES2:13)
Block(-17,15,-2,LEAVES2:13)
Block(-17,15,0,LEAVES2:13)
Block(-17,16,-1,LEAVES2:13)
Block(-17,16,0,LEAVES2:13)
Block(-17,16,1,LEAVES2:13)
Block(-17,17,-1,LEAVES2:13)
Block(-17,17,0,LEAVES2:13)
Block(-17,17,4,LEAVES2:13)
Block(-16,14,-10,LEAVES2:13)
Block(-16,14,-8,LEAVES2:13)
Block(-16,14,0,LEAVES2:13)
Block(-16,15,-9,LEAVES2:13)
Block(-16,15,-1,LEAVES2:13)
Block(-16,15,2,LEAVES2:13)
Block(-16,16,-1,LEAVES2:13)
Block(-16,16,0,LOG2:13)
Block(-16,16,1,LEAVES2:13)
Block(-16,16,4,LEAVES2:13)
Block(-16,17,0,LEAVES2:13)
Block(-16,17,2,LEAVES2:13)
Block(-16,17,3,LEAVES2:13)
Block(-16,17,6,LEAVES2:13)
Block(-16,18,0,LEAVES2:13)
Block(-16,18,4,LEAVES2:13)
Block(-16,18,5,LEAVES2:13)
Block(-15,14,-9,LEAVES2:13)
Block(-15,14,-6,LEAVES2:13)
Block(-15,14,-3,LEAVES2:13)
Block(-15,15,-10,LEAVES2:13)
Block(-15,15,-9,LEAVES2:13)
Block(-15,15,-8,LEAVES2:13)
Block(-15,15,-7,LEAVES2:13)
Block(-15,15,-2,LEAVES2:13)
Block(-15,15,0,LEAVES2:13)
Block(-15,15,1,LEAVES2:13)
Block(-15,16,-9,LEAVES2:13)
Block(-15,16,-3,LEAVES2:13)
Block(-15,16,0,LEAVES2:13)
Block(-15,16,1,LOG2:13)
Block(-15,16,2,LEAVES2:13)
Block(-15,17,1,LEAVES2:13)
Block(-15,17,2,LEAVES2:13)
Block(-15,17,3,LOG2:13)
Block(-15,17,4,LEAVES2:13)
Block(-15,17,5,LEAVES2:13)
Block(-15,18,2,LEAVES2:13)
Block(-15,18,3,LEAVES2:13)
Block(-15,18,4,LOG2:13)
Block(-15,18,5,LEAVES2:13)
Block(-15,18,6,LEAVES2:13)
Block(-15,19,4,LEAVES2:13)
Block(-15,19,5,LEAVES2:13)
Block(-15,28,-13,LEAVES2:13)
Block(-14,12,-9,LEAVES2:13)
Block(-14,13,-6,LEAVES2:13)
Block(-14,14,-9,LEAVES2:13)
Block(-14,14,-8,LEAVES2:13)
Block(-14,14,-4,LEAVES2:13)
Block(-14,14,-2,LEAVES2:13)
Block(-14,14,5,LEAVES2:13)
Block(-14,15,-10,LEAVES2:13)
Block(-14,15,-9,LEAVES2:13)
Block(-14,15,-8,LOG2:13)
Block(-14,15,-7,LEAVES2:13)
Block(-14,15,-6,LEAVES2:13)
Block(-14,15,-3,LEAVES2:13)
Block(-14,15,-2,LEAVES2:13)
Block(-14,15,-1,LEAVES2:13)
Block(-14,15,0,LEAVES2:13)
Block(-14,16,-9,LEAVES2:13)
Block(-14,16,-8,LEAVES2:13)
Block(-14,16,-7,LEAVES2:13)
Block(-14,16,-2,LEAVES2:13)
Block(-14,16,-1,LEAVES2:13)
Block(-14,16,0,LEAVES2:13)
Block(-14,16,1,LOG2:13)
Block(-14,17,0,LEAVES2:13)
Block(-14,17,1,LEAVES2:13)
Block(-14,17,2,LOG2:13)
Block(-14,17,3,LEAVES2:13)
Block(-14,18,2,LEAVES2:13)
Block(-14,18,4,LEAVES2:13)
Block(-14,18,5,LEAVES2:13)
Block(-14,19,4,LEAVES2:13)
Block(-14,21,-8,LEAVES2:13)
Block(-14,29,-14,LEAVES2:13)
Block(-14,29,-13,LEAVES2:13)
Block(-14,30,-12,LEAVES2:13)
Block(-13,13,-8,LEAVES2:13)
Block(-13,13,-2,LEAVES2:13)
Block(-13,14,-10,LEAVES2:13)
Block(-13,14,-7,LEAVES2:13)
Block(-13,14,-6,LEAVES2:13)
Block(-13,14,-5,LEAVES2:13)
Block(-13,14,-3,LEAVES2:13)
Block(-13,14,-2,LEAVES2:13)
Block(-13,14,-1,LEAVES2:13)
Block(-13,14,2,LEAVES2:13)
Block(-13,14,6,LEAVES2:13)
Block(-13,15,-9,LEAVES2:13)
Block(-13,15,-8,LEAVES2:13)
Block(-13,15,-7,LOG2:13)
Block(-13,15,-6,LEAVES2:13)
Block(-13,15,-4,LEAVES2:13)
Block(-13,15,-3,LEAVES2:13)
Block(-13,15,-2,LEAVES2:13)
Block(-13,15,-1,LEAVES2:13)
Block(-13,15,1,LEAVES2:13)
Block(-13,15,2,LOG2:13)
Block(-13,15,3,LEAVES2:13)
Block(-13,15,4,LEAVES2:13)
Block(-13,15,5,LEAVES2:13)
Block(-13,15,6,LEAVES2:13)
Block(-13,16,-11,LEAVES2:13)
Block(-13,16,-10,LEAVES2:13)
Block(-13,16,-7,LEAVES2:13)
Block(-13,16,-3,LEAVES2:13)
Block(-13,16,-2,LEAVES2:13)
Block(-13,16,0,LEAVES2:13)
Block(-13,16,1,LEAVES2:13)
Block(-13,16,2,LEAVES2:13)
Block(-13,17,1,LEAVES2:13)
Block(-13,17,2,LEAVES2:13)
Block(-13,17,3,LEAVES2:13)
Block(-13,18,1,LEAVES2:13)
Block(-13,18,2,LEAVES2:13)
Block(-13,18,3,LEAVES2:13)
Block(-13,19,2,LEAVES2:13)
Block(-13,20,-10,LEAVES2:13)
Block(-13,20,-8,LEAVES2:13)
Block(-13,20,-6,LEAVES2:13)
Block(-13,21,-9,LEAVES2:13)
Block(-13,21,-8,LEAVES2:13)
Block(-13,21,-7,LEAVES2:13)
Block(-13,22,-8,LEAVES2:13)
Block(-13,27,-14,LEAVES2:13)
Block(-13,28,-15,LEAVES2:13)
Block(-13,28,-13,LEAVES2:13)
Block(-13,29,-14,LEAVES2:13)
Block(-13,29,-13,LEAVES2:13)
Block(-13,29,-12,LEAVES2:13)
Block(-13,30,-15,LEAVES2:13)
Block(-13,30,-14,LEAVES2:13)
Block(-13,30,-13,LEAVES2:13)
Block(-12,13,5,LEAVES2:13)
Block(-12,14,-8,LEAVES2:13)
Block(-12,14,-7,LOG2:13)
Block(-12,14,-6,LEAVES2:13)
Block(-12,14,-2,LEAVES2:13)
Block(-12,14,3,LEAVES2:13)
Block(-12,14,4,LOG2:13)
Block(-12,14,5,LEAVES2:13)
Block(-12,14,6,LEAVES2:13)
Block(-12,15,-13,LEAVES2:13)
Block(-12,15,-11,LEAVES2:13)
Block(-12,15,-7,LEAVES2:13)
Block(-12,15,-6,LEAVES2:13)
Block(-12,15,-3,LEAVES2:13)
Block(-12,15,-2,LOG2:13)
Block(-12,15,-1,LEAVES2:13)
Block(-12,15,0,LEAVES2:13)
Block(-12,15,2,LOG2:13)
Block(-12,15,4,LEAVES2:13)
Block(-12,15,5,LOG2:13)
Block(-12,15,6,LEAVES2:13)
Block(-12,15,7,LEAVES2:13)
Block(-12,16,-12,LEAVES2:13)
Block(-12,16,-11,LEAVES2:13)
Block(-12,16,-10,LEAVES2:13)
Block(-12,16,-8,LEAVES2:13)
Block(-12,16,-7,LEAVES2:13)
Block(-12,16,-2,LEAVES2:13)
Block(-12,16,-1,LEAVES2:13)
Block(-12,16,2,LEAVES2:13)
Block(-12,16,5,LEAVES2:13)
Block(-12,16,7,LEAVES2:13)
Block(-12,17,-13,LEAVES2:13)
Block(-12,17,-12,LEAVES2:13)
Block(-12,17,-11,LEAVES2:13)
Block(-12,17,-9,LEAVES2:13)
Block(-12,17,1,LEAVES2:13)
Block(-12,17,2,LEAVES2:13)
Block(-12,17,3,LEAVES2:13)
Block(-12,18,2,LEAVES2:13)
Block(-12,19,-9,LEAVES2:13)
Block(-12,20,-8,LEAVES2:13)
Block(-12,21,-9,LEAVES2:13)
Block(-12,21,-8,LOG2:13)
Block(-12,21,-7,LEAVES2:13)
Block(-12,22,-8,LEAVES2:13)
Block(-12,28,-14,LEAVES2:13)
Block(-12,28,-13,LEAVES2:13)
Block(-12,28,-11,LEAVES2:13)
Block(-12,29,-15,LEAVES2:13)
Block(-12,29,-14,LEAVES2:13)
Block(-12,29,-13,LEAVES2:13)
Block(-12,29,-12,LEAVES2:13)
Block(-12,30,-14,LEAVES2:13)
Block(-12,30,-13,LEAVES2:13)
Block(-12,30,-12,LEAVES2:13)
Block(-12,31,-13,LEAVES2:13)
Block(-11,13,-9,LEAVES2:13)
Block(-11,14,-12,LEAVES2:13)
Block(-11,14,-8,LEAVES2:13)
Block(-11,14,-6,LOG2:13)
Block(-11,14,-1,LEAVES2:13)
Block(-11,14,2,LOG2:13)
Block(-11,14,3,LOG2:13)
Block(-11,15,-11,LEAVES2:13)
Block(-11,15,-10,LEAVES2:13)
Block(-11,15,-7,LEAVES2:13)
Block(-11,15,-6,LEAVES2:13)
Block(-11,15,-5,LEAVES2:13)
Block(-11,15,-2,LEAVES2:13)
Block(-11,15,-1,LOG2:13)
Block(-11,15,0,LEAVES2:13)
Block(-11,15,2,LEAVES2:13)
Block(-11,15,5,LEAVES2:13)
Block(-11,15,6,LEAVES2:13)
Block(-11,16,-13,LEAVES2:13)
Block(-11,16,-12,LEAVES2:13)
Block(-11,16,-11,LOG2:13)
Block(-11,16,-10,LEAVES2:13)
Block(-11,16,-9,LEAVES2:13)
Block(-11,16,-6,LEAVES2:13)
Block(-11,16,-1,LEAVES2:13)
Block(-11,16,0,LEAVES2:13)
Block(-11,16,4,LEAVES2:13)
Block(-11,16,5,LEAVES2:13)
Block(-11,16,8,LEAVES2:13)
Block(-11,17,-14,LEAVES2:13)
Block(-11,17,-13,LEAVES2:13)
Block(-11,17,-12,LOG2:13)
Block(-11,17,-11,LEAVES2:13)
Block(-11,17,-1,LEAVES2:13)
Block(-11,17,2,LEAVES2:13)
Block(-11,17,6,LEAVES2:13)
Block(-11,17,7,LEAVES2:13)
Block(-11,18,-13,LEAVES2:13)
Block(-11,18,-12,LEAVES2:13)
Block(-11,18,-8,LEAVES2:13)
Block(-11,19,-11,LEAVES2:13)
Block(-11,19,-8,LEAVES2:13)
Block(-11,20,-9,LEAVES2:13)
Block(-11,20,-8,LOG2:13)
Block(-11,20,-7,LEAVES2:13)
Block(-11,21,-8,LEAVES2:13)
Block(-11,26,-11,LEAVES2:13)
Block(-11,27,-13,LEAVES2:13)
Block(-11,27,-10,LEAVES2:13)
Block(-11,28,-15,LEAVES2:13)
Block(-11,28,-12,LEAVES2:13)
Block(-11,28,-9,LEAVES2:13)
Block(-11,29,-14,LEAVES2:13)
Block(-11,29,-13,LOG2:13)
Block(-11,29,-12,LEAVES2:13)
Block(-11,29,-11,LEAVES2:13)
Block(-11,30,-13,LEAVES2:13)
Block(-10,0,3,LOG2:13)
Block(-10,1,3,LOG2:13)
Block(-10,13,1,LOG2:13)
Block(-10,14,-10,LEAVES2:13)
Block(-10,14,-6,LEAVES2:13)
Block(-10,14,-5,LOG2:13)
Block(-10,14,-2,LEAVES2:13)
Block(-10,14,-1,LOG2:13)
Block(-10,14,3,LEAVES2:13)
Block(-10,15,-11,LEAVES2:13)
Block(-10,15,-10,LOG2:13)
Block(-10,15,-9,LEAVES2:13)
Block(-10,15,-8,LEAVES2:13)
Block(-10,15,-7,LOG2:13)
Block(-10,15,-6,LEAVES2:13)
Block(-10,15,-1,LEAVES2:13)
Block(-10,15,0,LEAVES2:13)
Block(-10,15,7,LEAVES2:13)
Block(-10,15,9,LEAVES2:13)
Block(-10,16,-15,LEAVES2:13)
Block(-10,16,-13,LEAVES2:13)
Block(-10,16,-11,LEAVES2:13)
Block(-10,16,-10,LEAVES2:13)
Block(-10,16,-7,LEAVES2:13)
Block(-10,16,-1,LEAVES2:13)
Block(-10,16,5,LEAVES2:13)
Block(-10,16,6,LEAVES2:13)
Block(-10,16,8,LEAVES2:13)
Block(-10,17,-14,LEAVES2:13)
Block(-10,17,-13,LEAVES2:13)
Block(-10,17,-12,LEAVES2:13)
Block(-10,17,-9,LEAVES2:13)
Block(-10,17,6,LEAVES2:13)
Block(-10,17,7,LOG2:13)
Block(-10,17,8,LEAVES2:13)
Block(-10,18,-13,LEAVES2:13)
Block(-10,18,5,LEAVES2:13)
Block(-10,18,7,LEAVES2:13)
Block(-10,19,-9,LEAVES2:13)
Block(-10,19,-7,LEAVES2:13)
Block(-10,20,-12,LEAVES2:13)
Block(-10,20,-11,LEAVES2:13)
Block(-10,20,-9,LEAVES2:13)
Block(-10,20,-8,LOG2:13)
Block(-10,20,-7,LEAVES2:13)
Block(-10,20,-6,LEAVES2:13)
Block(-10,21,-15,LEAVES2:13)
Block(-10,21,-10,LEAVES2:13)
Block(-10,21,-8,LEAVES2:13)
Block(-10,21,-7,LEAVES2:13)
Block(-10,22,-13,LEAVES2:13)
Block(-10,25,-9,LEAVES2:13)
Block(-10,26,-12,LEAVES2:13)
Block(-10,26,-10,LEAVES2:13)
Block(-10,27,-15,LEAVES2:13)
Block(-10,27,-13,LEAVES2:13)
Block(-10,27,-12,LEAVES2:13)
Block(-10,27,-11,LEAVES2:13)
Block(-10,27,-10,LEAVES2:13)
Block(-10,27,-9,LEAVES2:13)
Block(-10,28,-14,LEAVES2:13)
Block(-10,28,-13,LEAVES2:13)
Block(-10,28,-12,LOG2:13)
Block(-10,28,-11,LEAVES2:13)
Block(-10,28,-10,LEAVES2:13)
Block(-10,29,-13,LEAVES2:13)
Block(-10,29,-12,LEAVES2:13)
Block(-9,0,0,LOG2:13)
Block(-9,0,2,LOG2:13)
Block(-9,0,3,LOG2:13)
Block(-9,0,5,LOG2:13)
Block(-9,0,7,LOG2:13)
Block(-9,0,8,LOG2:13)
Block(-9,1,0,LOG2:13)
Block(-9,1,2,LOG2:13)
Block(-9,1,3,LOG2:13)
Block(-9,1,5,LOG2:13)
Block(-9,1,7,LOG2:13)
Block(-9,1,8,LOG2:13)
Block(-9,2,0,LOG2:13)
Block(-9,2,2,LOG2:13)
Block(-9,2,3,LOG2:13)
Block(-9,2,7,LOG2:13)
Block(-9,3,2,LOG2:13)
Block(-9,13,1,LOG2:13)
Block(-9,14,-9,LEAVES2:13)
Block(-9,14,0,LOG2:13)
Block(-9,14,1,LEAVES2:13)
Block(-9,14,7,LEAVES2:13)
Block(-9,15,-13,LEAVES2:13)
Block(-9,15,-10,LEAVES2:13)
Block(-9,15,-9,LOG2:13)
Block(-9,15,-8,LOG2:13)
Block(-9,15,-7,LEAVES2:13)
Block(-9,15,-5,LOG2:13)
Block(-9,15,6,LEAVES2:13)
Block(-9,16,-12,LEAVES2:13)
Block(-9,16,-9,LEAVES2:13)
Block(-9,16,-8,LEAVES2:13)
Block(-9,16,-4,LEAVES2:13)
Block(-9,16,4,LEAVES2:13)
Block(-9,16,5,LOG2:13)
Block(-9,16,6,LOG2:13)
Block(-9,16,7,LEAVES2:13)
Block(-9,16,8,LEAVES2:13)
Block(-9,17,-14,LEAVES2:13)
Block(-9,17,-13,LEAVES2:13)
Block(-9,17,5,LEAVES2:13)
Block(-9,17,6,LEAVES2:13)
Block(-9,17,7,LEAVES2:13)
Block(-9,19,-10,LEAVES2:13)
Block(-9,19,-8,LEAVES2:13)
Block(-9,19,-7,LOG2:13)
Block(-9,19,-6,LEAVES2:13)
Block(-9,20,-10,LEAVES2:13)
Block(-9,20,-9,LEAVES2:13)
Block(-9,20,-8,LEAVES2:13)
Block(-9,20,-7,LEAVES2:13)
Block(-9,21,-13,LEAVES2:13)
Block(-9,21,-11,LEAVES2:13)
Block(-9,21,-10,LEAVES2:13)
Block(-9,21,-9,LEAVES2:13)
Block(-9,22,-15,LEAVES2:13)
Block(-9,22,-14,LEAVES2:13)
Block(-9,22,-13,LEAVES2:13)
Block(-9,22,-12,LEAVES2:13)
Block(-9,22,-10,LEAVES2:13)
Block(-9,23,-14,LEAVES2:13)
Block(-9,23,-13,LEAVES2:13)
Block(-9,25,-3,LEAVES2:13)
Block(-9,26,-12,LEAVES2:13)
Block(-9,26,-11,LEAVES2:13)
Block(-9,26,-10,LEAVES2:13)
Block(-9,26,-9,LEAVES2:13)
Block(-9,26,-2,LEAVES2:13)
Block(-9,27,-12,LEAVES2:13)
Block(-9,27,-11,LEAVES2:13)
Block(-9,27,-10,LEAVES2:13)
Block(-9,27,-9,LEAVES2:13)
Block(-9,27,-8,LEAVES2:13)
Block(-9,28,-13,LEAVES2:13)
Block(-9,28,-12,LOG2:13)
Block(-9,28,-11,LEAVES2:13)
Block(-9,28,-10,LEAVES2:13)
Block(-9,28,-9,LEAVES2:13)
Block(-9,29,-13,LEAVES2:13)
Block(-9,29,-12,LEAVES2:13)
Block(-9,29,-10,LEAVES2:13)
Block(-8,0,-1,LOG2:13)
Block(-8,0,2,LOG2:13)
Block(-8,0,3,LOG2:13)
Block(-8,0,4,LOG2:13)
Block(-8,0,5,LOG2:13)
Block(-8,0,7,LOG2:13)
Block(-8,1,-1,LOG2:13)
Block(-8,1,2,LOG2:13)
Block(-8,1,3,LOG2:13)
Block(-8,1,4,LOG2:13)
Block(-8,1,5,LOG2:13)
Block(-8,1,7,LOG2:13)
Block(-8,2,0,LOG2:13)
Block(-8,2,3,LOG2:13)
Block(-8,2,4,LOG2:13)
Block(-8,2,5,LOG2:13)
Block(-8,2,7,LOG2:13)
Block(-8,3,0,LOG2:13)
Block(-8,3,3,LOG2:13)
Block(-8,3,4,LOG2:13)
Block(-8,3,5,LOG2:13)
Block(-8,3,7,LOG2:13)
Block(-8,4,3,LOG2:13)
Block(-8,4,4,LOG2:13)
Block(-8,5,3,LOG2:13)
Block(-8,12,1,LOG2:13)
Block(-8,13,1,LOG2:13)
Block(-8,13,2,LOG2:13)
Block(-8,14,-8,LEAVES2:13)
Block(-8,14,0,LEAVES2:13)
Block(-8,14,2,LEAVES2:13)
Block(-8,14,3,LOG2:13)
Block(-8,14,6,LEAVES2:13)
Block(-8,15,-11,LEAVES2:13)
Block(-8,15,-9,LEAVES2:13)
Block(-8,15,-8,LEAVES2:13)
Block(-8,15,-4,LOG2:13)
Block(-8,15,-3,LEAVES2:13)
Block(-8,15,4,LOG2:13)
Block(-8,16,-10,LEAVES2:13)
Block(-8,16,-9,LOG2:13)
Block(-8,16,-8,LEAVES2:13)
Block(-8,16,-5,LEAVES2:13)
Block(-8,16,-4,LEAVES2:13)
Block(-8,16,-3,LEAVES2:13)
Block(-8,16,4,LEAVES2:13)
Block(-8,16,6,LEAVES2:13)
Block(-8,17,-9,LEAVES2:13)
Block(-8,17,-4,LEAVES2:13)
Block(-8,17,7,LEAVES2:13)
Block(-8,19,-11,LEAVES2:13)
Block(-8,19,-6,LOG2:13)
Block(-8,19,-5,LEAVES2:13)
Block(-8,20,-15,LEAVES2:13)
Block(-8,20,-13,LEAVES2:13)
Block(-8,20,-10,LEAVES2:13)
Block(-8,20,-7,LEAVES2:13)
Block(-8,20,-6,LEAVES2:13)
Block(-8,21,-16,LEAVES2:13)
Block(-8,21,-14,LEAVES2:13)
Block(-8,21,-13,LEAVES2:13)
Block(-8,21,-12,LEAVES2:13)
Block(-8,21,-11,LOG2:13)
Block(-8,21,-10,LEAVES2:13)
Block(-8,21,-9,LEAVES2:13)
Block(-8,22,-15,LEAVES2:13)
Block(-8,22,-14,LEAVES2:13)
Block(-8,22,-13,LOG2:13)
Block(-8,22,-12,LOG2:13)
Block(-8,22,-11,LEAVES2:13)
Block(-8,22,-10,LEAVES2:13)
Block(-8,23,-15,LEAVES2:13)
Block(-8,23,-14,LEAVES2:13)
Block(-8,23,-13,LEAVES2:13)
Block(-8,23,-12,LEAVES2:13)
Block(-8,24,-14,LEAVES2:13)
Block(-8,24,-6,LEAVES2:13)
Block(-8,24,-1,LEAVES2:13)
Block(-8,24,1,LEAVES2:13)
Block(-8,25,-10,LEAVES2:13)
Block(-8,25,-2,LEAVES2:13)
Block(-8,25,2,LEAVES2:13)
Block(-8,26,-10,LEAVES2:13)
Block(-8,26,-5,LEAVES2:13)
Block(-8,26,-3,LEAVES2:13)
Block(-8,26,-2,LEAVES2:13)
Block(-8,26,-1,LEAVES2:13)
Block(-8,27,-15,LEAVES2:13)
Block(-8,27,-13,LEAVES2:13)
Block(-8,27,-12,LOG2:13)
Block(-8,27,-11,LEAVES2:13)
Block(-8,27,-10,LEAVES2:13)
Block(-8,27,-9,LEAVES2:13)
Block(-8,27,-2,LEAVES2:13)
Block(-8,28,-14,LEAVES2:13)
Block(-8,28,-13,LEAVES2:13)
Block(-8,28,-12,LEAVES2:13)
Block(-8,28,-10,LEAVES2:13)
Block(-8,29,-15,LEAVES2:13)
Block(-8,30,-13,LEAVES2:13)
Block(-8,31,7,LEAVES2:13)
Block(-8,32,8,LEAVES2:13)
Block(-7,0,2,LOG2:13)
Block(-7,0,3,LOG2:13)
Block(-7,0,4,LOG2:13)
Block(-7,0,5,LOG2:13)
Block(-7,0,6,LOG2:13)
Block(-7,0,7,LOG2:13)
Block(-7,0,8,LOG2:13)
Block(-7,1,2,LOG2:13)
Block(-7,1,3,LOG2:13)
Block(-7,1,4,LOG2:13)
Block(-7,1,5,LOG2:13)
Block(-7,1,6,LOG2:13)
Block(-7,1,7,LOG2:13)
Block(-7,1,8,LOG2:13)
Block(-7,2,1,LOG2:13)
Block(-7,2,2,LOG2:13)
Block(-7,2,3,LOG2:13)
Block(-7,2,4,LOG2:13)
Block(-7,2,5,LOG2:13)
Block(-7,2,7,LOG2:13)
Block(-7,2,8,LOG2:13)
Block(-7,3,1,LOG2:13)
Block(-7,3,2,LOG2:13)
Block(-7,3,3,LOG2:13)
Block(-7,3,4,LOG2:13)
Block(-7,3,5,LOG2:13)
Block(-7,3,7,LOG2:13)
Block(-7,3,8,LOG2:13)
Block(-7,4,1,LOG2:13)
Block(-7,4,2,LOG2:13)
Block(-7,4,4,LOG2:13)
Block(-7,4,5,LOG2:13)
Block(-7,4,7,LOG2:13)
Block(-7,5,2,LOG2:13)
Block(-7,5,4,LOG2:13)
Block(-7,6,2,LOG2:13)
Block(-7,6,3,LOG2:13)
Block(-7,6,4,LOG2:13)
Block(-7,7,3,LOG2:13)
Block(-7,7,4,LOG2:13)
Block(-7,8,3,LOG2:13)
Block(-7,11,2,LOG2:13)
Block(-7,12,2,LOG2:13)
Block(-7,13,-9,LEAVES2:13)
Block(-7,13,6,LEAVES2:13)
Block(-7,14,4,LOG2:13)
Block(-7,15,-10,LEAVES2:13)
Block(-7,15,-9,LEAVES2:13)
Block(-7,15,-7,LEAVES2:13)
Block(-7,15,-4,LEAVES2:13)
Block(-7,15,5,LEAVES2:13)
Block(-7,15,6,LEAVES2:13)
Block(-7,15,7,LEAVES2:13)
Block(-7,16,-10,LEAVES2:13)
Block(-7,16,-9,LEAVES2:13)
Block(-7,16,-8,LEAVES2:13)
Block(-7,16,-4,LOG2:13)
Block(-7,16,6,LEAVES2:13)
Block(-7,16,7,LEAVES2:13)
Block(-7,17,-9,LEAVES2:13)
Block(-7,17,-5,LEAVES2:13)
Block(-7,17,-4,LEAVES2:13)
Block(-7,17,-2,LEAVES2:13)
Block(-7,18,-6,LOG2:13)
Block(-7,18,-4,LEAVES2:13)
Block(-7,18,-3,LEAVES2:13)
Block(-7,19,-14,LEAVES2:13)
Block(-7,19,-7,LEAVES2:13)
Block(-7,19,-6,LEAVES2:13)
Block(-7,20,-11,LEAVES2:13)
Block(-7,20,-10,LEAVES2:13)
Block(-7,20,-8,LEAVES2:13)
Block(-7,20,-7,LEAVES2:13)
Block(-7,21,-14,LEAVES2:13)
Block(-7,21,-12,LEAVES2:13)
Block(-7,21,-11,LEAVES2:13)
Block(-7,21,-10,LOG2:13)
Block(-7,21,-9,LEAVES2:13)
Block(-7,22,-15,LEAVES2:13)
Block(-7,22,-14,LEAVES2:13)
Block(-7,22,-13,LEAVES2:13)
Block(-7,22,-12,LEAVES2:13)
Block(-7,22,-10,LEAVES2:13)
Block(-7,23,-14,LEAVES2:13)
Block(-7,23,3,LEAVES2:13)
Block(-7,24,-3,LEAVES2:13)
Block(-7,24,2,LEAVES2:13)
Block(-7,25,-8,LEAVES2:13)
Block(-7,25,-5,LEAVES2:13)
Block(-7,25,-4,LEAVES2:13)
Block(-7,25,-2,LEAVES2:13)
Block(-7,25,0,LEAVES2:13)
Block(-7,25,1,LEAVES2:13)
Block(-7,25,2,LEAVES2:13)
Block(-7,25,3,LEAVES2:13)
Block(-7,26,-11,LOG2:13)
Block(-7,26,-10,LEAVES2:13)
Block(-7,26,-9,LEAVES2:13)
Block(-7,26,-6,LEAVES2:13)
Block(-7,26,-5,LEAVES2:13)
Block(-7,26,-4,LEAVES2:13)
Block(-7,26,-3,LEAVES2:13)
Block(-7,26,-2,LOG2:13)
Block(-7,26,-1,LEAVES2:13)
Block(-7,26,0,LEAVES2:13)
Block(-7,26,2,LEAVES2:13)
Block(-7,27,-13,LEAVES2:13)
Block(-7,27,-12,LEAVES2:13)
Block(-7,27,-11,LOG2:13)
Block(-7,27,-10,LEAVES2:13)
Block(-7,27,-9,LEAVES2:13)
Block(-7,27,-5,LEAVES2:13)
Block(-7,27,-3,LEAVES2:13)
Block(-7,27,-2,LEAVES2:13)
Block(-7,28,-14,LEAVES2:13)
Block(-7,28,-13,LEAVES2:13)
Block(-7,28,-12,LEAVES2:13)
Block(-7,28,-11,LEAVES2:13)
Block(-7,29,-13,LEAVES2:13)
Block(-7,29,-12,LEAVES2:13)
Block(-7,31,4,LEAVES2:13)
Block(-7,31,8,LEAVES2:13)
Block(-7,32,7,LEAVES2:13)
Block(-7,32,8,LEAVES2:13)
Block(-7,32,9,LEAVES2:13)
Block(-7,33,6,LEAVES2:13)
Block(-7,33,8,LEAVES2:13)
Block(-6,0,0,LOG2:13)
Block(-6,0,2,LOG2:13)
Block(-6,0,3,LOG2:13)
Block(-6,0,4,LOG2:13)
Block(-6,0,5,LOG2:13)
Block(-6,0,6,LOG2:13)
Block(-6,0,7,LOG2:13)
Block(-6,0,9,LOG2:13)
Block(-6,1,0,LOG2:13)
Block(-6,1,4,LOG2:13)
Block(-6,1,5,LOG2:13)
Block(-6,1,6,LOG2:13)
Block(-6,1,7,LOG2:13)
Block(-6,1,9,LOG2:13)
Block(-6,2,4,LOG2:13)
Block(-6,2,5,LOG2:13)
Block(-6,2,6,LOG2:13)
Block(-6,2,7,LOG2:13)
Block(-6,2,9,LOG2:13)
Block(-6,3,3,LOG2:13)
Block(-6,3,4,LOG2:13)
Block(-6,3,5,LOG2:13)
Block(-6,3,6,LOG2:13)
Block(-6,3,7,LOG2:13)
Block(-6,4,2,LOG2:13)
Block(-6,4,3,LOG2:13)
Block(-6,4,4,LOG2:13)
Block(-6,4,5,LOG2:13)
Block(-6,4,6,LOG2:13)
Block(-6,5,3,LOG2:13)
Block(-6,5,4,LOG2:13)
Block(-6,5,5,LOG2:13)
Block(-6,5,6,LOG2:13)
Block(-6,6,2,LOG2:13)
Block(-6,6,3,LOG2:13)
Block(-6,6,4,LOG2:13)
Block(-6,6,5,LOG2:13)
Block(-6,7,2,LOG2:13)
Block(-6,7,3,LOG2:13)
Block(-6,7,4,LOG2:13)
Block(-6,8,3,LOG2:13)
Block(-6,8,4,LOG2:13)
Block(-6,9,2,LOG2:13)
Block(-6,9,3,LOG2:13)
Block(-6,10,2,LOG2:13)
Block(-6,10,3,LOG2:13)
Block(-6,11,2,LOG2:13)
Block(-6,14,6,LEAVES2:13)
Block(-6,14,7,LEAVES2:13)
Block(-6,15,4,LEAVES2:13)
Block(-6,15,5,LOG2:13)
Block(-6,15,6,LEAVES2:13)
Block(-6,15,7,LEAVES2:13)
Block(-6,15,8,LEAVES2:13)
Block(-6,16,-9,LEAVES2:13)
Block(-6,16,-4,LOG2:13)
Block(-6,16,-3,LEAVES2:13)
Block(-6,16,5,LEAVES2:13)
Block(-6,16,6,LEAVES2:13)
Block(-6,16,7,LEAVES2:13)
Block(-6,17,-6,LOG2:13)
Block(-6,17,-5,LOG2:13)
Block(-6,17,-4,LOG2:13)
Block(-6,17,-3,LEAVES2:13)
Block(-6,17,6,LEAVES2:13)
Block(-6,18,-7,LOG2:13)
Block(-6,18,-6,LOG2:13)
Block(-6,18,-5,LEAVES2:13)
Block(-6,18,-4,LEAVES2:13)
Block(-6,18,-3,LEAVES2:13)
Block(-6,18,-2,LEAVES2:13)
Block(-6,19,-8,LOG2:13)
Block(-6,19,-7,LOG2:13)
Block(-6,19,-6,LEAVES2:13)
Block(-6,19,-4,LEAVES2:13)
Block(-6,19,-3,LEAVES2:13)
Block(-6,20,-12,LEAVES2:13)
Block(-6,20,-11,LEAVES2:13)
Block(-6,20,-9,LOG2:13)
Block(-6,20,-8,LOG2:13)
Block(-6,20,-7,LEAVES2:13)
Block(-6,20,-6,LEAVES2:13)
Block(-6,21,-15,LEAVES2:13)
Block(-6,21,-13,LEAVES2:13)
Block(-6,21,-10,LEAVES2:13)
Block(-6,21,-8,LEAVES2:13)
Block(-6,21,-7,LEAVES2:13)
Block(-6,22,-14,LEAVES2:13)
Block(-6,22,-12,LEAVES2:13)
Block(-6,24,-5,LEAVES2:13)
Block(-6,24,1,LEAVES2:13)
Block(-6,24,2,LEAVES2:13)
Block(-6,24,4,LEAVES2:13)
Block(-6,25,-9,LEAVES2:13)
Block(-6,25,-6,LEAVES2:13)
Block(-6,25,-5,LEAVES2:13)
Block(-6,25,-4,LOG2:13)
Block(-6,25,-3,LEAVES2:13)
Block(-6,25,-2,LEAVES2:13)
Block(-6,25,-1,LEAVES2:13)
Block(-6,25,0,LEAVES2:13)
Block(-6,25,1,LEAVES2:13)
Block(-6,25,2,LEAVES2:13)
Block(-6,25,3,LEAVES2:13)
Block(-6,25,5,LEAVES2:13)
Block(-6,26,-10,LOG2:13)
Block(-6,26,-9,LEAVES2:13)
Block(-6,26,-8,LEAVES2:13)
Block(-6,26,-6,LEAVES2:13)
Block(-6,26,-5,LEAVES2:13)
Block(-6,26,-4,LEAVES2:13)
Block(-6,26,-3,LOG2:13)
Block(-6,26,-2,LEAVES2:13)
Block(-6,26,-1,LEAVES2:13)
Block(-6,26,1,LEAVES2:13)
Block(-6,26,2,LEAVES2:13)
Block(-6,26,3,LEAVES2:13)
Block(-6,27,-10,LEAVES2:13)
Block(-6,27,-9,LEAVES2:13)
Block(-6,27,-8,LEAVES2:13)
Block(-6,27,-5,LEAVES2:13)
Block(-6,27,-3,LEAVES2:13)
Block(-6,27,-2,LEAVES2:13)
Block(-6,27,-1,LEAVES2:13)
Block(-6,28,-15,LEAVES2:13)
Block(-6,28,-13,LEAVES2:13)
Block(-6,28,-12,LOG2:13)
Block(-6,28,-11,LEAVES2:13)
Block(-6,28,-9,LEAVES2:13)
Block(-6,28,-2,LEAVES2:13)
Block(-6,28,11,LEAVES2:13)
Block(-6,29,-14,LEAVES2:13)
Block(-6,29,-12,LEAVES2:13)
Block(-6,30,4,LEAVES2:13)
Block(-6,31,3,LEAVES2:13)
Block(-6,31,4,LEAVES2:13)
Block(-6,31,5,LEAVES2:13)
Block(-6,31,8,LEAVES2:13)
Block(-6,32,2,LEAVES2:13)
Block(-6,32,4,LEAVES2:13)
Block(-6,32,6,LEAVES2:13)
Block(-6,32,7,LEAVES2:13)
Block(-6,32,8,LEAVES2:13)
Block(-6,32,9,LEAVES2:13)
Block(-6,33,7,LEAVES2:13)
Block(-6,33,8,LEAVES2:13)
Block(-6,33,9,LEAVES2:13)
Block(-6,34,8,LEAVES2:13)
Block(-5,0,1,LOG2:13)
Block(-5,0,2,LOG2:13)
Block(-5,0,3,LOG2:13)
Block(-5,0,4,LOG2:13)
Block(-5,0,5,LOG2:13)
Block(-5,1,3,LOG2:13)
Block(-5,1,5,LOG2:13)
Block(-5,2,2,LOG2:13)
Block(-5,2,3,LOG2:13)
Block(-5,2,5,LOG2:13)
Block(-5,3,1,LOG2:13)
Block(-5,3,2,LOG2:13)
Block(-5,3,3,LOG2:13)
Block(-5,3,4,LOG2:13)
Block(-5,3,5,LOG2:13)
Block(-5,4,2,LOG2:13)
Block(-5,4,4,LOG2:13)
Block(-5,4,5,LOG2:13)
Block(-5,5,2,LOG2:13)
Block(-5,5,4,LOG2:13)
Block(-5,5,5,LOG2:13)
Block(-5,6,2,LOG2:13)
Block(-5,6,3,LOG2:13)
Block(-5,6,4,LOG2:13)
Block(-5,6,5,LOG2:13)
Block(-5,7,2,LOG2:13)
Block(-5,7,3,LOG2:13)
Block(-5,7,4,LOG2:13)
Block(-5,8,1,LOG2:13)
Block(-5,8,2,LOG2:13)
Block(-5,8,3,LOG2:13)
Block(-5,8,4,LOG2:13)
Block(-5,9,1,LOG2:13)
Block(-5,9,2,LOG2:13)
Block(-5,9,3,LOG2:13)
Block(-5,9,4,LOG2:13)
Block(-5,10,1,LOG2:13)
Block(-5,10,2,LOG2:13)
Block(-5,10,3,LOG2:13)
Block(-5,11,1,LOG2:13)
Block(-5,11,2,LOG2:13)
Block(-5,11,3,LOG2:13)
Block(-5,12,1,LOG2:13)
Block(-5,13,6,LEAVES2:13)
Block(-5,14,-1,LOG2:13)
Block(-5,14,5,LEAVES2:13)
Block(-5,14,6,LEAVES2:13)
Block(-5,14,8,LEAVES2:13)
Block(-5,15,-3,LOG2:13)
Block(-5,15,-2,LOG2:13)
Block(-5,15,4,LEAVES2:13)
Block(-5,15,5,LOG2:13)
Block(-5,15,6,LEAVES2:13)
Block(-5,15,7,LEAVES2:13)
Block(-5,16,-4,LOG2:13)
Block(-5,16,-3,LOG2:13)
Block(-5,16,-2,LEAVES2:13)
Block(-5,16,4,LEAVES2:13)
Block(-5,16,5,LEAVES2:13)
Block(-5,16,6,LEAVES2:13)
Block(-5,17,-6,LEAVES2:13)
Block(-5,17,-5,LOG2:13)
Block(-5,17,-4,LEAVES2:13)
Block(-5,17,-3,LEAVES2:13)
Block(-5,18,-7,LEAVES2:13)
Block(-5,18,-5,LEAVES2:13)
Block(-5,18,-4,LEAVES2:13)
Block(-5,18,-3,LEAVES2:13)
Block(-5,18,2,LEAVES2:13)
Block(-5,18,4,LEAVES2:13)
Block(-5,19,-10,LEAVES2:13)
Block(-5,20,-9,LOG2:13)
Block(-5,20,-8,LEAVES2:13)
Block(-5,20,-7,LEAVES2:13)
Block(-5,21,-13,LEAVES2:13)
Block(-5,21,-11,LEAVES2:13)
Block(-5,21,-10,LEAVES2:13)
Block(-5,21,-9,LOG2:13)
Block(-5,23,-13,LEAVES2:13)
Block(-5,23,-12,LEAVES2:13)
Block(-5,23,2,LEAVES2:13)
Block(-5,24,-12,LEAVES2:13)
Block(-5,24,-3,LEAVES2:13)
Block(-5,24,-1,LEAVES2:13)
Block(-5,24,1,LEAVES2:13)
Block(-5,24,2,LEAVES2:13)
Block(-5,24,3,LEAVES2:13)
Block(-5,25,-9,LOG2:13)
Block(-5,25,-8,LOG2:13)
Block(-5,25,-7,LEAVES2:13)
Block(-5,25,-6,LEAVES2:13)
Block(-5,25,-5,LOG2:13)
Block(-5,25,-4,LEAVES2:13)
Block(-5,25,1,LEAVES2:13)
Block(-5,25,2,LEAVES2:13)
Block(-5,25,3,LEAVES2:13)
Block(-5,25,4,LEAVES2:13)
Block(-5,25,6,LEAVES2:13)
Block(-5,26,-9,LOG2:13)
Block(-5,26,-8,LEAVES2:13)
Block(-5,26,-5,LEAVES2:13)
Block(-5,26,-3,LEAVES2:13)
Block(-5,26,-2,LEAVES2:13)
Block(-5,26,-1,LEAVES2:13)
Block(-5,26,2,LEAVES2:13)
Block(-5,26,3,LEAVES2:13)
Block(-5,27,-9,LEAVES2:13)
Block(-5,27,-2,LEAVES2:13)
Block(-5,27,11,LEAVES2:13)
Block(-5,28,-14,LEAVES2:13)
Block(-5,28,-13,LOG2:13)
Block(-5,28,-12,LEAVES2:13)
Block(-5,29,-17,LEAVES2:13)
Block(-5,29,-15,LEAVES2:13)
Block(-5,29,-14,LOG2:13)
Block(-5,29,-13,LEAVES2:13)
Block(-5,29,-11,LEAVES2:13)
Block(-5,30,-16,LEAVES2:13)
Block(-5,30,-15,LEAVES2:13)
Block(-5,30,-14,LEAVES2:13)
Block(-5,30,6,LEAVES2:13)
Block(-5,30,8,LEAVES2:13)
Block(-5,31,3,LEAVES2:13)
Block(-5,31,4,LEAVES2:13)
Block(-5,31,5,LEAVES2:13)
Block(-5,31,6,LEAVES2:13)
Block(-5,31,7,LEAVES2:13)
Block(-5,32,3,LEAVES2:13)
Block(-5,32,4,LEAVES2:13)
Block(-5,32,5,LEAVES2:13)
Block(-5,32,6,LEAVES2:13)
Block(-5,32,7,LEAVES2:13)
Block(-5,32,8,LOG2:13)
Block(-5,32,10,LEAVES2:13)
Block(-5,33,4,LEAVES2:13)
Block(-5,33,7,LEAVES2:13)
Block(-5,33,8,LEAVES2:13)
Block(-5,33,9,LEAVES2:13)
Block(-4,0,0,LOG2:13)
Block(-4,0,2,LOG2:13)
Block(-4,0,3,LOG2:13)
Block(-4,0,5,LOG2:13)
Block(-4,0,6,LOG2:13)
Block(-4,1,0,LOG2:13)
Block(-4,1,2,LOG2:13)
Block(-4,1,3,LOG2:13)
Block(-4,2,0,LOG2:13)
Block(-4,2,2,LOG2:13)
Block(-4,2,3,LOG2:13)
Block(-4,3,2,LOG2:13)
Block(-4,3,3,LOG2:13)
Block(-4,3,5,LOG2:13)
Block(-4,3,6,LOG2:13)
Block(-4,4,3,LOG2:13)
Block(-4,4,5,LOG2:13)
Block(-4,4,6,LOG2:13)
Block(-4,5,3,LOG2:13)
Block(-4,5,4,LOG2:13)
Block(-4,6,2,LOG2:13)
Block(-4,6,3,LOG2:13)
Block(-4,7,2,LOG2:13)
Block(-4,7,3,LOG2:13)
Block(-4,8,2,LOG2:13)
Block(-4,8,3,LOG2:13)
Block(-4,8,4,LOG2:13)
Block(-4,9,1,LOG2:13)
Block(-4,9,2,LOG2:13)
Block(-4,9,3,LOG2:13)
Block(-4,10,0,LOG2:13)
Block(-4,10,1,LOG2:13)
Block(-4,10,2,LOG2:13)
Block(-4,10,3,LOG2:13)
Block(-4,11,0,LOG2:13)
Block(-4,11,1,LOG2:13)
Block(-4,11,2,LOG2:13)
Block(-4,12,0,LOG2:13)
Block(-4,12,1,LOG2:13)
Block(-4,12,2,LOG2:13)
Block(-4,13,-1,LOG2:13)
Block(-4,13,0,LOG2:13)
Block(-4,14,-2,LOG2:13)
Block(-4,14,-1,LOG2:13)
Block(-4,14,5,LEAVES2:13)
Block(-4,15,-2,LOG2:13)
Block(-4,15,5,LEAVES2:13)
Block(-4,15,6,LEAVES2:13)
Block(-4,15,8,LEAVES2:13)
Block(-4,15,9,LEAVES2:13)
Block(-4,16,-4,LEAVES2:13)
Block(-4,16,-3,LOG2:13)
Block(-4,16,4,LEAVES2:13)
Block(-4,16,5,LEAVES2:13)
Block(-4,16,6,LOG2:13)
Block(-4,16,7,LEAVES2:13)
Block(-4,16,10,LEAVES2:13)
Block(-4,17,-5,LEAVES2:13)
Block(-4,17,2,LEAVES2:13)
Block(-4,17,4,LEAVES2:13)
Block(-4,17,6,LEAVES2:13)
Block(-4,17,11,LEAVES2:13)
Block(-4,18,3,LEAVES2:13)
Block(-4,19,-2,LEAVES2:13)
Block(-4,19,3,LEAVES2:13)
Block(-4,19,4,LEAVES2:13)
Block(-4,20,-11,LEAVES2:13)
Block(-4,21,-12,LEAVES2:13)
Block(-4,21,-11,LEAVES2:13)
Block(-4,21,-10,LOG2:13)
Block(-4,21,8,LEAVES2:13)
Block(-4,22,-12,LEAVES2:13)
Block(-4,22,-11,LEAVES2:13)
Block(-4,22,-10,LEAVES2:13)
Block(-4,22,-9,LEAVES2:13)
Block(-4,22,7,LEAVES2:13)
Block(-4,23,-14,LEAVES2:13)
Block(-4,23,-11,LEAVES2:13)
Block(-4,23,-7,LOG2:13)
Block(-4,24,-8,LOG2:13)
Block(-4,24,-7,LOG2:13)
Block(-4,24,-6,LOG2:13)
Block(-4,24,-4,LEAVES2:13)
Block(-4,24,1,LEAVES2:13)
Block(-4,24,2,LEAVES2:13)
Block(-4,24,4,LEAVES2:13)
Block(-4,24,6,LEAVES2:13)
Block(-4,25,-8,LOG2:13)
Block(-4,25,-7,LEAVES2:13)
Block(-4,25,-5,LEAVES2:13)
Block(-4,25,-4,LEAVES2:13)
Block(-4,25,-2,LEAVES2:13)
Block(-4,25,0,LEAVES2:13)
Block(-4,25,1,LEAVES2:13)
Block(-4,25,2,LOG2:13)
Block(-4,25,3,LEAVES2:13)
Block(-4,25,4,LEAVES2:13)
Block(-4,25,5,LEAVES2:13)
Block(-4,26,-10,LOG2:13)
Block(-4,26,-9,LEAVES2:13)
Block(-4,26,-4,LEAVES2:13)
Block(-4,26,1,LEAVES2:13)
Block(-4,26,2,LEAVES2:13)
Block(-4,26,3,LEAVES2:13)
Block(-4,26,4,LEAVES2:13)
Block(-4,27,-10,LOG2:13)
Block(-4,27,3,LEAVES2:13)
Block(-4,27,9,LEAVES2:13)
Block(-4,27,12,LEAVES2:13)
Block(-4,28,-17,LEAVES2:13)
Block(-4,28,-13,LEAVES2:13)
Block(-4,28,-12,LEAVES2:13)
Block(-4,28,11,LEAVES2:13)
Block(-4,29,-16,LEAVES2:13)
Block(-4,29,-15,LEAVES2:13)
Block(-4,29,-14,LEAVES2:13)
Block(-4,29,-13,LEAVES2:13)
Block(-4,29,-12,LEAVES2:13)
Block(-4,30,-17,LEAVES2:13)
Block(-4,30,-16,LEAVES2:13)
Block(-4,30,-15,LOG2:13)
Block(-4,30,-14,LEAVES2:13)
Block(-4,30,1,LEAVES2:13)
Block(-4,30,3,LEAVES2:13)
Block(-4,30,4,LEAVES2:13)
Block(-4,30,10,LEAVES2:13)
Block(-4,31,-16,LEAVES2:13)
Block(-4,31,-15,LEAVES2:13)
Block(-4,31,3,LEAVES2:13)
Block(-4,31,4,LOG2:13)
Block(-4,31,5,LEAVES2:13)
Block(-4,31,8,LEAVES2:13)
Block(-4,31,9,LEAVES2:13)
Block(-4,32,4,LEAVES2:13)
Block(-4,32,5,LEAVES2:13)
Block(-4,32,7,LEAVES2:13)
Block(-4,32,8,LOG2:13)
Block(-4,32,9,LEAVES2:13)
Block(-4,33,8,LEAVES2:13)
Block(-3,0,3,LOG2:13)
Block(-3,0,5,LOG2:13)
Block(-3,0,6,LOG2:13)
Block(-3,0,7,LOG2:13)
Block(-3,1,3,LOG2:13)
Block(-3,1,5,LOG2:13)
Block(-3,1,7,LOG2:13)
Block(-3,2,3,LOG2:13)
Block(-3,2,5,LOG2:13)
Block(-3,2,7,LOG2:13)
Block(-3,3,3,LOG2:13)
Block(-3,3,6,LOG2:13)
Block(-3,9,2,LOG2:13)
Block(-3,10,1,LOG2:13)
Block(-3,10,2,LOG2:13)
Block(-3,11,0,LOG2:13)
Block(-3,11,1,LOG2:13)
Block(-3,11,2,LOG2:13)
Block(-3,12,-1,LOG2:13)
Block(-3,12,0,LOG2:13)
Block(-3,12,1,LOG2:13)
Block(-3,13,-1,LOG2:13)
Block(-3,13,0,LOG2:13)
Block(-3,13,1,LOG2:13)
Block(-3,14,-1,LOG2:13)
Block(-3,14,0,LOG2:13)
Block(-3,14,8,LEAVES2:13)
Block(-3,15,6,LEAVES2:13)
Block(-3,15,7,LEAVES2:13)
Block(-3,16,5,LEAVES2:13)
Block(-3,16,6,LEAVES2:13)
Block(-3,16,7,LEAVES2:13)
Block(-3,16,8,LEAVES2:13)
Block(-3,16,11,LEAVES2:13)
Block(-3,16,13,LEAVES2:13)
Block(-3,17,1,LEAVES2:13)
Block(-3,17,3,LEAVES2:13)
Block(-3,17,5,LEAVES2:13)
Block(-3,17,6,LEAVES2:13)
Block(-3,17,7,LEAVES2:13)
Block(-3,17,10,LEAVES2:13)
Block(-3,17,11,LEAVES2:13)
Block(-3,17,12,LEAVES2:13)
Block(-3,18,-3,LEAVES2:13)
Block(-3,18,0,LEAVES2:13)
Block(-3,18,1,LEAVES2:13)
Block(-3,18,2,LEAVES2:13)
Block(-3,18,3,LEAVES2:13)
Block(-3,18,4,LEAVES2:13)
Block(-3,18,11,LEAVES2:13)
Block(-3,19,-2,LEAVES2:13)
Block(-3,19,-1,LEAVES2:13)
Block(-3,19,2,LEAVES2:13)
Block(-3,19,3,LEAVES2:13)
Block(-3,19,4,LEAVES2:13)
Block(-3,20,-2,LEAVES2:13)
Block(-3,20,0,LEAVES2:13)
Block(-3,20,3,LEAVES2:13)
Block(-3,21,-15,LEAVES2:13)
Block(-3,21,-13,LEAVES2:13)
Block(-3,21,-11,LEAVES2:13)
Block(-3,21,-10,LEAVES2:13)
Block(-3,21,6,LEAVES2:13)
Block(-3,22,-14,LEAVES2:13)
Block(-3,22,-12,LEAVES2:13)
Block(-3,22,-11,LOG2:13)
Block(-3,22,-10,LEAVES2:13)
Block(-3,22,-7,LOG2:13)
Block(-3,22,6,LEAVES2:13)
Block(-3,22,7,LEAVES2:13)
Block(-3,22,8,LEAVES2:13)
Block(-3,23,-15,LEAVES2:13)
Block(-3,23,-14,LEAVES2:13)
Block(-3,23,-13,LEAVES2:13)
Block(-3,23,-12,LEAVES2:13)
Block(-3,23,-11,LEAVES2:13)
Block(-3,23,-10,LEAVES2:13)
Block(-3,23,-7,LOG2:13)
Block(-3,23,0,LEAVES2:13)
Block(-3,23,4,LEAVES2:13)
Block(-3,23,7,LEAVES2:13)
Block(-3,23,9,LEAVES2:13)
Block(-3,24,-14,LEAVES2:13)
Block(-3,24,-11,LEAVES2:13)
Block(-3,24,-2,LEAVES2:13)
Block(-3,24,-1,LEAVES2:13)
Block(-3,24,4,LEAVES2:13)
Block(-3,25,-3,LEAVES2:13)
Block(-3,25,0,LEAVES2:13)
Block(-3,25,1,LOG2:13)
Block(-3,25,2,LEAVES2:13)
Block(-3,25,3,LEAVES2:13)
Block(-3,25,4,LEAVES2:13)
Block(-3,25,5,LEAVES2:13)
Block(-3,26,1,LEAVES2:13)
Block(-3,26,3,LEAVES2:13)
Block(-3,26,4,LEAVES2:13)
Block(-3,26,9,LEAVES2:13)
Block(-3,26,13,LEAVES2:13)
Block(-3,27,-11,LOG2:13)
Block(-3,27,11,LEAVES2:13)
Block(-3,28,-13,LEAVES2:13)
Block(-3,28,0,LEAVES2:13)
Block(-3,28,10,LEAVES2:13)
Block(-3,28,11,LEAVES2:13)
Block(-3,28,12,LEAVES2:13)
Block(-3,29,-15,LEAVES2:13)
Block(-3,29,-8,LEAVES2:13)
Block(-3,29,1,LEAVES2:13)
Block(-3,29,3,LEAVES2:13)
Block(-3,29,5,LEAVES2:13)
Block(-3,29,11,LEAVES2:13)
Block(-3,30,-16,LEAVES2:13)
Block(-3,30,-15,LEAVES2:13)
Block(-3,30,-14,LEAVES2:13)
Block(-3,30,-2,LEAVES2:13)
Block(-3,30,0,LEAVES2:13)
Block(-3,30,1,LEAVES2:13)
Block(-3,30,2,LEAVES2:13)
Block(-3,30,4,LEAVES2:13)
Block(-3,30,5,LEAVES2:13)
Block(-3,30,8,LEAVES2:13)
Block(-3,30,9,LEAVES2:13)
Block(-3,31,-13,LEAVES2:13)
Block(-3,31,1,LEAVES2:13)
Block(-3,31,3,LEAVES2:13)
Block(-3,31,4,LOG2:13)
Block(-3,31,5,LEAVES2:13)
Block(-3,31,6,LEAVES2:13)
Block(-3,31,7,LEAVES2:13)
Block(-3,31,8,LOG2:13)
Block(-3,31,9,LEAVES2:13)
Block(-3,31,10,LEAVES2:13)
Block(-3,32,4,LEAVES2:13)
Block(-3,32,5,LEAVES2:13)
Block(-3,32,7,LEAVES2:13)
Block(-3,32,8,LEAVES2:13)
Block(-3,32,9,LEAVES2:13)
Block(-3,32,10,LEAVES2:13)
Block(-3,33,9,LEAVES2:13)
Block(-2,0,5,LOG2:13)
Block(-2,11,1,LOG2:13)
Block(-2,12,0,LOG2:13)
Block(-2,12,1,LOG2:13)
Block(-2,13,-1,LOG2:13)
Block(-2,13,0,LOG2:13)
Block(-2,13,1,LOG2:13)
Block(-2,14,-2,LOG2:13)
Block(-2,14,-1,LOG2:13)
Block(-2,14,0,LOG2:13)
Block(-2,14,1,LOG2:13)
Block(-2,15,-1,LOG2:13)
Block(-2,15,0,LOG2:13)
Block(-2,15,4,LEAVES2:13)
Block(-2,15,6,LEAVES2:13)
Block(-2,15,9,LEAVES2:13)
Block(-2,15,12,LEAVES2:13)
Block(-2,16,5,LEAVES2:13)
Block(-2,16,6,LEAVES2:13)
Block(-2,16,7,LEAVES2:13)
Block(-2,16,10,LEAVES2:13)
Block(-2,16,12,LEAVES2:13)
Block(-2,17,-2,LEAVES2:13)
Block(-2,17,3,LEAVES2:13)
Block(-2,17,4,LEAVES2:13)
Block(-2,17,6,LEAVES2:13)
Block(-2,17,9,LEAVES2:13)
Block(-2,17,10,LOG2:13)
Block(-2,17,11,LEAVES2:13)
Block(-2,17,12,LEAVES2:13)
Block(-2,17,13,LEAVES2:13)
Block(-2,18,-2,LEAVES2:13)
Block(-2,18,2,LEAVES2:13)
Block(-2,18,3,LEAVES2:13)
Block(-2,18,4,LEAVES2:13)
Block(-2,18,5,LEAVES2:13)
Block(-2,18,10,LEAVES2:13)
Block(-2,18,11,LEAVES2:13)
Block(-2,18,12,LEAVES2:13)
Block(-2,19,-3,LEAVES2:13)
Block(-2,19,-2,LEAVES2:13)
Block(-2,19,-1,LEAVES2:13)
Block(-2,19,0,LEAVES2:13)
Block(-2,19,3,LEAVES2:13)
Block(-2,19,4,LEAVES2:13)
Block(-2,20,-10,LEAVES2:13)
Block(-2,20,-3,LEAVES2:13)
Block(-2,20,-2,LEAVES2:13)
Block(-2,20,-1,LEAVES2:13)
Block(-2,21,-2,LEAVES2:13)
Block(-2,21,7,LEAVES2:13)
Block(-2,21,9,LEAVES2:13)
Block(-2,22,-15,LEAVES2:13)
Block(-2,22,-14,LEAVES2:13)
Block(-2,22,-12,LOG2:13)
Block(-2,22,-11,LEAVES2:13)
Block(-2,22,-10,LEAVES2:13)
Block(-2,22,-7,LOG2:13)
Block(-2,22,-6,LOG2:13)
Block(-2,22,6,LEAVES2:13)
Block(-2,22,7,LEAVES2:13)
Block(-2,22,8,LEAVES2:13)
Block(-2,22,12,LEAVES2:13)
Block(-2,23,-16,LEAVES2:13)
Block(-2,23,-15,LEAVES2:13)
Block(-2,23,-14,LEAVES2:13)
Block(-2,23,-13,LOG2:13)
Block(-2,23,-12,LEAVES2:13)
Block(-2,23,-11,LEAVES2:13)
Block(-2,23,-7,LOG2:13)
Block(-2,23,-4,LEAVES2:13)
Block(-2,23,-2,LEAVES2:13)
Block(-2,23,7,LEAVES2:13)
Block(-2,23,8,LEAVES2:13)
Block(-2,23,13,LEAVES2:13)
Block(-2,24,-15,LEAVES2:13)
Block(-2,24,-14,LEAVES2:13)
Block(-2,24,-13,LEAVES2:13)
Block(-2,24,-3,LEAVES2:13)
Block(-2,24,-2,LEAVES2:13)
Block(-2,24,-1,LEAVES2:13)
Block(-2,24,0,LOG2:13)
Block(-2,24,2,LEAVES2:13)
Block(-2,24,3,LEAVES2:13)
Block(-2,24,5,LEAVES2:13)
Block(-2,24,7,LEAVES2:13)
Block(-2,25,-2,LEAVES2:13)
Block(-2,25,1,LEAVES2:13)
Block(-2,25,4,LEAVES2:13)
Block(-2,26,-13,LEAVES2:13)
Block(-2,26,11,LEAVES2:13)
Block(-2,26,12,LEAVES2:13)
Block(-2,27,-15,LEAVES2:13)
Block(-2,27,-12,LEAVES2:13)
Block(-2,27,8,LEAVES2:13)
Block(-2,27,9,LEAVES2:13)
Block(-2,27,10,LEAVES2:13)
Block(-2,27,12,LEAVES2:13)
Block(-2,28,-14,LEAVES2:13)
Block(-2,28,-12,LOG2:13)
Block(-2,28,-10,LOG2:13)
Block(-2,28,1,LEAVES2:13)
Block(-2,28,9,LEAVES2:13)
Block(-2,28,10,LOG2:13)
Block(-2,28,11,LEAVES2:13)
Block(-2,28,12,LEAVES2:13)
Block(-2,28,13,LEAVES2:13)
Block(-2,29,-16,LEAVES2:13)
Block(-2,29,-15,LEAVES2:13)
Block(-2,29,-14,LEAVES2:13)
Block(-2,29,-13,LEAVES2:13)
Block(-2,29,-12,LEAVES2:13)
Block(-2,29,-10,LEAVES2:13)
Block(-2,29,0,LEAVES2:13)
Block(-2,29,1,LEAVES2:13)
Block(-2,29,2,LEAVES2:13)
Block(-2,29,10,LEAVES2:13)
Block(-2,29,11,LEAVES2:13)
Block(-2,29,12,LEAVES2:13)
Block(-2,30,-15,LEAVES2:13)
Block(-2,30,-9,LEAVES2:13)
Block(-2,30,-8,LEAVES2:13)
Block(-2,30,-1,LEAVES2:13)
Block(-2,30,0,LOG2:13)
Block(-2,30,1,LEAVES2:13)
Block(-2,30,2,LEAVES2:13)
Block(-2,30,4,LOG2:13)
Block(-2,30,5,LEAVES2:13)
Block(-2,30,6,LEAVES2:13)
Block(-2,30,13,LEAVES2:13)
Block(-2,31,-9,LEAVES2:13)
Block(-2,31,0,LEAVES2:13)
Block(-2,31,1,LEAVES2:13)
Block(-2,31,5,LEAVES2:13)
Block(-2,31,6,LEAVES2:13)
Block(-2,31,7,LOG2:13)
Block(-2,31,8,LEAVES2:13)
Block(-2,31,9,LEAVES2:13)
Block(-2,32,6,LEAVES2:13)
Block(-2,32,7,LEAVES2:13)
Block(-2,32,9,LEAVES2:13)
Block(-1,12,1,LOG2:13)
Block(-1,13,0,LOG2:13)
Block(-1,13,1,LOG2:13)
Block(-1,14,-1,LOG2:13)
Block(-1,14,0,LOG2:13)
Block(-1,14,1,LOG2:13)
Block(-1,15,-2,LOG2:13)
Block(-1,15,-1,LOG2:13)
Block(-1,15,0,LOG2:13)
Block(-1,15,1,LOG2:13)
Block(-1,16,-1,LOG2:13)
Block(-1,16,0,LOG2:13)
Block(-1,16,1,LOG2:13)
Block(-1,16,5,LEAVES2:13)
Block(-1,16,6,LEAVES2:13)
Block(-1,16,8,LEAVES2:13)
Block(-1,16,9,LEAVES2:13)
Block(-1,16,10,LOG2:13)
Block(-1,16,11,LEAVES2:13)
Block(-1,17,1,LOG2:13)
Block(-1,17,2,LOG2:13)
Block(-1,17,3,LEAVES2:13)
Block(-1,17,9,LEAVES2:13)
Block(-1,17,10,LEAVES2:13)
Block(-1,17,11,LEAVES2:13)
Block(-1,17,12,LEAVES2:13)
Block(-1,18,-4,LEAVES2:13)
Block(-1,18,-2,LEAVES2:13)
Block(-1,18,1,LEAVES2:13)
Block(-1,18,2,LOG2:13)
Block(-1,18,3,LEAVES2:13)
Block(-1,18,4,LEAVES2:13)
Block(-1,18,7,LEAVES2:13)
Block(-1,18,10,LEAVES2:13)
Block(-1,19,-3,LEAVES2:13)
Block(-1,19,-2,LEAVES2:13)
Block(-1,19,-1,LEAVES2:13)
Block(-1,19,2,LEAVES2:13)
Block(-1,19,3,LEAVES2:13)
Block(-1,20,-4,LEAVES2:13)
Block(-1,20,-3,LEAVES2:13)
Block(-1,20,-2,LEAVES2:13)
Block(-1,20,1,LEAVES2:13)
Block(-1,20,3,LEAVES2:13)
Block(-1,20,6,LEAVES2:13)
Block(-1,21,-11,LEAVES2:13)
Block(-1,21,-6,LOG2:13)
Block(-1,21,-5,LOG2:13)
Block(-1,21,5,LEAVES2:13)
Block(-1,21,7,LEAVES2:13)
Block(-1,21,8,LEAVES2:13)
Block(-1,21,11,LEAVES2:13)
Block(-1,22,-16,LEAVES2:13)
Block(-1,22,-14,LEAVES2:13)
Block(-1,22,-12,LEAVES2:13)
Block(-1,22,-6,LOG2:13)
Block(-1,22,6,LEAVES2:13)
Block(-1,22,7,LOG2:13)
Block(-1,22,8,LEAVES2:13)
Block(-1,22,9,LEAVES2:13)
Block(-1,22,13,LEAVES2:13)
Block(-1,22,15,LEAVES2:13)
Block(-1,23,-15,LEAVES2:13)
Block(-1,23,-14,LEAVES2:13)
Block(-1,23,-13,LEAVES2:13)
Block(-1,23,-8,LOG2:13)
Block(-1,23,7,LEAVES2:13)
Block(-1,23,8,LEAVES2:13)
Block(-1,23,12,LEAVES2:13)
Block(-1,23,13,LEAVES2:13)
Block(-1,23,14,LEAVES2:13)
Block(-1,24,-4,LEAVES2:13)
Block(-1,24,-3,LEAVES2:13)
Block(-1,24,-2,LEAVES2:13)
Block(-1,24,-1,LOG2:13)
Block(-1,24,0,LEAVES2:13)
Block(-1,24,2,LEAVES2:13)
Block(-1,24,3,LEAVES2:13)
Block(-1,24,4,LEAVES2:13)
Block(-1,24,6,LEAVES2:13)
Block(-1,24,13,LEAVES2:13)
Block(-1,25,-3,LEAVES2:13)
Block(-1,25,-2,LEAVES2:13)
Block(-1,25,-1,LEAVES2:13)
Block(-1,25,1,LEAVES2:13)
Block(-1,25,3,LEAVES2:13)
Block(-1,25,6,LEAVES2:13)
Block(-1,26,-12,LEAVES2:13)
Block(-1,26,-2,LEAVES2:13)
Block(-1,27,9,LOG2:13)
Block(-1,27,10,LEAVES2:13)
Block(-1,27,13,LEAVES2:13)
Block(-1,28,-16,LEAVES2:13)
Block(-1,28,-15,LEAVES2:13)
Block(-1,28,-13,LEAVES2:13)
Block(-1,28,-12,LEAVES2:13)
Block(-1,28,-10,LEAVES2:13)
Block(-1,28,7,LEAVES2:13)
Block(-1,28,8,LEAVES2:13)
Block(-1,28,9,LEAVES2:13)
Block(-1,28,10,LEAVES2:13)
Block(-1,28,11,LEAVES2:13)
Block(-1,28,12,LEAVES2:13)
Block(-1,29,-17,LEAVES2:13)
Block(-1,29,-16,LEAVES2:13)
Block(-1,29,-15,LEAVES2:13)
Block(-1,29,-14,LOG2:13)
Block(-1,29,-13,LOG2:13)
Block(-1,29,-12,LEAVES2:13)
Block(-1,29,-11,LEAVES2:13)
Block(-1,29,-10,LOG2:13)
Block(-1,29,-9,LEAVES2:13)
Block(-1,29,-8,LEAVES2:13)
Block(-1,29,-1,LEAVES2:13)
Block(-1,29,0,LEAVES2:13)
Block(-1,29,1,LOG2:13)
Block(-1,29,2,LEAVES2:13)
Block(-1,29,11,LEAVES2:13)
Block(-1,30,-16,LEAVES2:13)
Block(-1,30,-15,LEAVES2:13)
Block(-1,30,-14,LEAVES2:13)
Block(-1,30,-13,LEAVES2:13)
Block(-1,30,-12,LEAVES2:13)
Block(-1,30,-10,LEAVES2:13)
Block(-1,30,-9,LOG2:13)
Block(-1,30,-8,LEAVES2:13)
Block(-1,30,-7,LEAVES2:13)
Block(-1,30,-6,LEAVES2:13)
Block(-1,30,0,LEAVES2:13)
Block(-1,30,1,LEAVES2:13)
Block(-1,30,5,LOG2:13)
Block(-1,31,-15,LEAVES2:13)
Block(-1,31,-11,LEAVES2:13)
Block(-1,31,-10,LEAVES2:13)
Block(-1,31,-9,LEAVES2:13)
Block(-1,31,-8,LEAVES2:13)
Block(-1,31,5,LEAVES2:13)
Block(-1,31,6,LOG2:13)
Block(-1,31,7,LEAVES2:13)
Block(-1,32,-9,LEAVES2:13)
Block(-1,32,6,LEAVES2:13)
Block(0,14,-1,LOG2:13)
Block(0,14,1,LOG2:13)
Block(0,14,11,LEAVES2:13)
Block(0,15,-2,LOG2:13)
Block(0,15,-1,LOG2:13)
Block(0,15,0,LOG2:13)
Block(0,15,1,LOG2:13)
Block(0,15,8,LEAVES2:13)
Block(0,15,9,LEAVES2:13)
Block(0,16,-3,LOG2:13)
Block(0,16,-2,LOG2:13)
Block(0,16,-1,LOG2:13)
Block(0,16,0,LOG2:13)
Block(0,16,7,LEAVES2:13)
Block(0,16,8,LEAVES2:13)
Block(0,16,9,LOG2:13)
Block(0,16,10,LEAVES2:13)
Block(0,16,11,LEAVES2:13)
Block(0,17,-2,LOG2:13)
Block(0,17,-1,LOG2:13)
Block(0,17,9,LEAVES2:13)
Block(0,17,10,LEAVES2:13)
Block(0,17,13,LEAVES2:13)
Block(0,18,-3,LEAVES2:13)
Block(0,18,-2,LEAVES2:13)
Block(0,18,-1,LEAVES2:13)
Block(0,18,3,LOG2:13)
Block(0,18,4,LEAVES2:13)
Block(0,18,5,LEAVES2:13)
Block(0,19,-4,LOG2:13)
Block(0,19,-3,LEAVES2:13)
Block(0,19,-2,LEAVES2:13)
Block(0,19,-1,LEAVES2:13)
Block(0,19,0,LEAVES2:13)
Block(0,19,2,LEAVES2:13)
Block(0,19,3,LOG2:13)
Block(0,19,4,LEAVES2:13)
Block(0,20,-5,LOG2:13)
Block(0,20,-2,LEAVES2:13)
Block(0,20,-1,LEAVES2:13)
Block(0,20,2,LEAVES2:13)
Block(0,20,3,LEAVES2:13)
Block(0,20,4,LEAVES2:13)
Block(0,21,-14,LEAVES2:13)
Block(0,21,-6,LOG2:13)
Block(0,21,-5,LOG2:13)
Block(0,21,3,LEAVES2:13)
Block(0,21,6,LEAVES2:13)
Block(0,21,10,LEAVES2:13)
Block(0,21,14,LEAVES2:13)
Block(0,22,5,LEAVES2:13)
Block(0,22,6,LEAVES2:13)
Block(0,22,7,LOG2:13)
Block(0,22,8,LEAVES2:13)
Block(0,22,11,LEAVES2:13)
Block(0,22,13,LEAVES2:13)
Block(0,22,14,LEAVES2:13)
Block(0,23,0,LOG2:13)
Block(0,23,6,LEAVES2:13)
Block(0,23,7,LEAVES2:13)
Block(0,23,10,LEAVES2:13)
Block(0,23,11,LEAVES2:13)
Block(0,23,12,LOG2:13)
Block(0,23,13,LEAVES2:13)
Block(0,23,14,LEAVES2:13)
Block(0,23,15,LEAVES2:13)
Block(0,24,-9,LOG2:13)
Block(0,24,-3,LEAVES2:13)
Block(0,24,-2,LOG2:13)
Block(0,24,-1,LEAVES2:13)
Block(0,24,0,LEAVES2:13)
Block(0,24,2,LEAVES2:13)
Block(0,24,3,LOG2:13)
Block(0,24,4,LOG2:13)
Block(0,24,5,LEAVES2:13)
Block(0,24,12,LEAVES2:13)
Block(0,24,13,LEAVES2:13)
Block(0,24,14,LEAVES2:13)
Block(0,25,-13,LEAVES2:13)
Block(0,25,-11,LEAVES2:13)
Block(0,25,-8,LOG2:13)
Block(0,25,-2,LEAVES2:13)
Block(0,25,3,LEAVES2:13)
Block(0,25,4,LEAVES2:13)
Block(0,25,5,LEAVES2:13)
Block(0,25,6,LEAVES2:13)
Block(0,25,7,LEAVES2:13)
Block(0,26,-8,LEAVES2:13)
Block(0,26,-7,LEAVES2:13)
Block(0,26,6,LEAVES2:13)
Block(0,26,7,LEAVES2:13)
Block(0,27,-14,LEAVES2:13)
Block(0,27,-6,LEAVES2:13)
Block(0,27,-4,LEAVES2:13)
Block(0,28,-15,LEAVES2:13)
Block(0,28,-13,LEAVES2:13)
Block(0,28,-8,LEAVES2:13)
Block(0,28,7,LOG2:13)
Block(0,28,8,LOG2:13)
Block(0,28,9,LEAVES2:13)
Block(0,28,12,LEAVES2:13)
Block(0,29,-16,LEAVES2:13)
Block(0,29,-15,LEAVES2:13)
Block(0,29,-14,LEAVES2:13)
Block(0,29,-13,LEAVES2:13)
Block(0,29,-12,LEAVES2:13)
Block(0,29,-10,LEAVES2:13)
Block(0,29,-7,LEAVES2:13)
Block(0,29,-6,LEAVES2:13)
Block(0,29,1,LEAVES2:13)
Block(0,29,2,LOG2:13)
Block(0,29,6,LOG2:13)
Block(0,29,7,LEAVES2:13)
Block(0,29,8,LEAVES2:13)
Block(0,29,10,LEAVES2:13)
Block(0,30,-15,LEAVES2:13)
Block(0,30,-13,LEAVES2:13)
Block(0,30,-11,LEAVES2:13)
Block(0,30,-9,LEAVES2:13)
Block(0,30,-8,LOG2:13)
Block(0,30,-7,LEAVES2:13)
Block(0,30,-6,LEAVES2:13)
Block(0,30,-5,LEAVES2:13)
Block(0,30,2,LEAVES2:13)
Block(0,30,5,LOG2:13)
Block(0,30,6,LEAVES2:13)
Block(0,30,7,LEAVES2:13)
Block(0,31,-9,LEAVES2:13)
Block(0,31,-8,LEAVES2:13)
Block(0,31,-7,LEAVES2:13)
Block(0,31,-6,LEAVES2:13)
Block(1,14,1,LOG2:13)
Block(1,14,2,LOG2:13)
Block(1,15,-1,LOG2:13)
Block(1,15,1,LOG2:13)
Block(1,15,2,LOG2:13)
Block(1,15,8,LOG2:13)
Block(1,15,9,LEAVES2:13)
Block(1,15,11,LEAVES2:13)
Block(1,16,-2,LOG2:13)
Block(1,16,-1,LOG2:13)
Block(1,16,0,LOG2:13)
Block(1,16,7,LEAVES2:13)
Block(1,16,8,LEAVES2:13)
Block(1,16,9,LEAVES2:13)
Block(1,16,13,LEAVES2:13)
Block(1,17,-3,LOG2:13)
Block(1,17,-2,LOG2:13)
Block(1,17,-1,LOG2:13)
Block(1,17,0,LOG2:13)
Block(1,17,3,LEAVES2:13)
Block(1,17,5,LEAVES2:13)
Block(1,17,6,LEAVES2:13)
Block(1,17,8,LEAVES2:13)
Block(1,17,12,LEAVES2:13)
Block(1,17,13,LEAVES2:13)
Block(1,17,14,LEAVES2:13)
Block(1,18,-3,LOG2:13)
Block(1,18,-2,LOG2:13)
Block(1,18,-1,LOG2:13)
Block(1,18,13,LEAVES2:13)
Block(1,19,-4,LOG2:13)
Block(1,19,-3,LOG2:13)
Block(1,19,-2,LOG2:13)
Block(1,19,-1,LEAVES2:13)
Block(1,19,3,LOG2:13)
Block(1,19,4,LOG2:13)
Block(1,20,-5,LOG2:13)
Block(1,20,-4,LOG2:13)
Block(1,20,2,LEAVES2:13)
Block(1,20,3,LEAVES2:13)
Block(1,21,-8,LEAVES2:13)
Block(1,21,4,LEAVES2:13)
Block(1,21,7,LEAVES2:13)
Block(1,21,8,LOG2:13)
Block(1,21,11,LEAVES2:13)
Block(1,22,-7,LEAVES2:13)
Block(1,22,6,LEAVES2:13)
Block(1,22,7,LEAVES2:13)
Block(1,22,8,LEAVES2:13)
Block(1,22,10,LEAVES2:13)
Block(1,22,11,LOG2:13)
Block(1,22,12,LEAVES2:13)
Block(1,23,-7,LEAVES2:13)
Block(1,23,1,LOG2:13)
Block(1,23,2,LOG2:13)
Block(1,23,3,LEAVES2:13)
Block(1,23,11,LEAVES2:13)
Block(1,23,12,LEAVES2:13)
Block(1,23,13,LEAVES2:13)
Block(1,23,14,LEAVES2:13)
Block(1,24,-13,LEAVES2:13)
Block(1,24,-11,LEAVES2:13)
Block(1,24,-10,LOG2:13)
Block(1,24,2,LEAVES2:13)
Block(1,24,4,LEAVES2:13)
Block(1,25,-14,LEAVES2:13)
Block(1,25,-12,LEAVES2:13)
Block(1,25,-11,LOG2:13)
Block(1,25,-10,LEAVES2:13)
Block(1,25,-3,LOG2:13)
Block(1,25,4,LEAVES2:13)
Block(1,25,5,LOG2:13)
Block(1,25,6,LEAVES2:13)
Block(1,25,7,LEAVES2:13)
Block(1,25,8,LEAVES2:13)
Block(1,26,-15,LEAVES2:13)
Block(1,26,-13,LEAVES2:13)
Block(1,26,-12,LEAVES2:13)
Block(1,26,-11,LEAVES2:13)
Block(1,26,-8,LEAVES2:13)
Block(1,26,-7,LOG2:13)
Block(1,26,-6,LEAVES2:13)
Block(1,26,-3,LEAVES2:13)
Block(1,26,5,LEAVES2:13)
Block(1,26,6,LEAVES2:13)
Block(1,26,7,LEAVES2:13)
Block(1,27,-7,LEAVES2:13)
Block(1,27,-6,LEAVES2:13)
Block(1,27,-5,LEAVES2:13)
Block(1,27,-2,LEAVES2:13)
Block(1,27,7,LEAVES2:13)
Block(1,27,12,LEAVES2:13)
Block(1,28,-14,LEAVES2:13)
Block(1,28,-6,LEAVES2:13)
Block(1,28,-4,LEAVES2:13)
Block(1,28,-3,LEAVES2:13)
Block(1,28,2,LEAVES2:13)
Block(1,28,3,LOG2:13)
Block(1,28,6,LEAVES2:13)
Block(1,28,7,LEAVES2:13)
Block(1,28,8,LEAVES2:13)
Block(1,28,11,LEAVES2:13)
Block(1,29,-15,LEAVES2:13)
Block(1,29,-14,LEAVES2:13)
Block(1,29,-13,LEAVES2:13)
Block(1,29,-9,LEAVES2:13)
Block(1,29,-8,LEAVES2:13)
Block(1,29,3,LEAVES2:13)
Block(1,29,5,LOG2:13)
Block(1,29,7,LEAVES2:13)
Block(1,30,-16,LEAVES2:13)
Block(1,30,-10,LEAVES2:13)
Block(1,30,-9,LEAVES2:13)
Block(1,30,-8,LEAVES2:13)
Block(1,30,-7,LEAVES2:13)
Block(1,30,-6,LEAVES2:13)
Block(1,30,5,LEAVES2:13)
Block(1,31,-8,LEAVES2:13)
Block(2,14,2,LOG2:13)
Block(2,14,7,LEAVES2:13)
Block(2,14,11,LEAVES2:13)
Block(2,15,2,LOG2:13)
Block(2,15,3,LOG2:13)
Block(2,15,7,LOG2:13)
Block(2,15,8,LEAVES2:13)
Block(2,15,10,LEAVES2:13)
Block(2,15,11,LEAVES2:13)
Block(2,15,13,LEAVES2:13)
Block(2,16,-1,LOG2:13)
Block(2,16,2,LOG2:13)
Block(2,16,6,LEAVES2:13)
Block(2,16,8,LEAVES2:13)
Block(2,16,9,LEAVES2:13)
Block(2,16,11,LEAVES2:13)
Block(2,16,12,LEAVES2:13)
Block(2,16,14,LEAVES2:13)
Block(2,17,-2,LOG2:13)
Block(2,17,-1,LOG2:13)
Block(2,17,1,LEAVES2:13)
Block(2,17,3,LEAVES2:13)
Block(2,17,12,LEAVES2:13)
Block(2,17,13,LOG2:13)
Block(2,17,14,LEAVES2:13)
Block(2,18,-3,LOG2:13)
Block(2,18,-2,LOG2:13)
Block(2,18,-1,LOG2:13)
Block(2,18,3,LEAVES2:13)
Block(2,18,13,LEAVES2:13)
Block(2,19,-4,LOG2:13)
Block(2,19,-3,LOG2:13)
Block(2,19,-2,LOG2:13)
Block(2,19,1,LEAVES2:13)
Block(2,19,4,LOG2:13)
Block(2,19,5,LEAVES2:13)
Block(2,20,-3,LOG2:13)
Block(2,20,3,LEAVES2:13)
Block(2,20,4,LOG2:13)
Block(2,20,5,LEAVES2:13)
Block(2,21,4,LEAVES2:13)
Block(2,21,8,LEAVES2:13)
Block(2,21,9,LOG2:13)
Block(2,21,11,LEAVES2:13)
Block(2,21,13,LEAVES2:13)
Block(2,22,-9,LEAVES2:13)
Block(2,22,0,LOG2:13)
Block(2,22,9,LEAVES2:13)
Block(2,22,10,LOG2:13)
Block(2,22,11,LEAVES2:13)
Block(2,22,12,LEAVES2:13)
Block(2,23,-8,LEAVES2:13)
Block(2,23,-7,LEAVES2:13)
Block(2,23,-6,LEAVES2:13)
Block(2,23,0,LOG2:13)
Block(2,23,2,LEAVES2:13)
Block(2,23,10,LEAVES2:13)
Block(2,23,11,LEAVES2:13)
Block(2,23,13,LEAVES2:13)
Block(2,24,-11,LEAVES2:13)
Block(2,24,-10,LOG2:13)
Block(2,24,-9,LEAVES2:13)
Block(2,24,-7,LEAVES2:13)
Block(2,24,3,LEAVES2:13)
Block(2,24,11,LEAVES2:13)
Block(2,25,-12,LEAVES2:13)
Block(2,25,-11,LEAVES2:13)
Block(2,25,-10,LEAVES2:13)
Block(2,25,-9,LEAVES2:13)
Block(2,25,-8,LEAVES2:13)
Block(2,25,-3,LOG2:13)
Block(2,25,-2,LEAVES2:13)
Block(2,25,5,LEAVES2:13)
Block(2,25,6,LEAVES2:13)
Block(2,25,7,LEAVES2:13)
Block(2,26,-14,LEAVES2:13)
Block(2,26,-13,LOG2:13)
Block(2,26,-12,LOG2:13)
Block(2,26,-11,LEAVES2:13)
Block(2,26,-10,LEAVES2:13)
Block(2,26,-7,LEAVES2:13)
Block(2,26,-5,LEAVES2:13)
Block(2,26,-3,LEAVES2:13)
Block(2,26,-1,LEAVES2:13)
Block(2,26,6,LEAVES2:13)
Block(2,27,-16,LEAVES2:13)
Block(2,27,-15,LEAVES2:13)
Block(2,27,-14,LEAVES2:13)
Block(2,27,-13,LEAVES2:13)
Block(2,27,-12,LEAVES2:13)
Block(2,27,-11,LEAVES2:13)
Block(2,27,-6,LOG2:13)
Block(2,27,-5,LOG2:13)
Block(2,27,-4,LEAVES2:13)
Block(2,27,-3,LEAVES2:13)
Block(2,27,3,LOG2:13)
Block(2,27,7,LEAVES2:13)
Block(2,27,9,LEAVES2:13)
Block(2,27,11,LEAVES2:13)
Block(2,27,13,LEAVES2:13)
Block(2,28,-6,LEAVES2:13)
Block(2,28,-5,LEAVES2:13)
Block(2,28,-4,LOG2:13)
Block(2,28,-3,LEAVES2:13)
Block(2,28,-2,LEAVES2:13)
Block(2,28,1,LEAVES2:13)
Block(2,28,2,LEAVES2:13)
Block(2,28,3,LOG2:13)
Block(2,28,4,LOG2:13)
Block(2,28,7,LEAVES2:13)
Block(2,28,10,LEAVES2:13)
Block(2,28,11,LEAVES2:13)
Block(2,28,12,LEAVES2:13)
Block(2,29,-14,LEAVES2:13)
Block(2,29,-7,LEAVES2:13)
Block(2,29,-4,LEAVES2:13)
Block(2,29,-3,LEAVES2:13)
Block(2,29,-2,LEAVES2:13)
Block(2,29,1,LEAVES2:13)
Block(2,29,2,LEAVES2:13)
Block(2,29,3,LEAVES2:13)
Block(2,29,4,LOG2:13)
Block(2,29,8,LEAVES2:13)
Block(2,29,11,LEAVES2:13)
Block(2,30,-8,LEAVES2:13)
Block(2,30,2,LEAVES2:13)
Block(2,30,4,LEAVES2:13)
Block(3,13,8,LEAVES2:13)
Block(3,14,7,LOG2:13)
Block(3,15,3,LOG2:13)
Block(3,15,6,LOG2:13)
Block(3,15,7,LOG2:13)
Block(3,15,9,LEAVES2:13)
Block(3,15,11,LEAVES2:13)
Block(3,16,2,LOG2:13)
Block(3,16,3,LOG2:13)
Block(3,16,6,LOG2:13)
Block(3,16,7,LEAVES2:13)
Block(3,16,8,LEAVES2:13)
Block(3,16,9,LEAVES2:13)
Block(3,16,10,LEAVES2:13)
Block(3,16,11,LEAVES2:13)
Block(3,16,12,LOG2:13)
Block(3,16,13,LEAVES2:13)
Block(3,17,-1,LOG2:13)
Block(3,17,1,LEAVES2:13)
Block(3,17,2,LEAVES2:13)
Block(3,17,3,LOG2:13)
Block(3,17,4,LEAVES2:13)
Block(3,17,6,LEAVES2:13)
Block(3,17,9,LEAVES2:13)
Block(3,17,11,LEAVES2:13)
Block(3,17,12,LEAVES2:13)
Block(3,17,13,LEAVES2:13)
Block(3,17,15,LEAVES2:13)
Block(3,18,-2,LOG2:13)
Block(3,18,-1,LOG2:13)
Block(3,18,2,LEAVES2:13)
Block(3,18,3,LEAVES2:13)
Block(3,18,4,LEAVES2:13)
Block(3,18,12,LEAVES2:13)
Block(3,19,-3,LOG2:13)
Block(3,19,-2,LOG2:13)
Block(3,19,-1,LOG2:13)
Block(3,19,3,LEAVES2:13)
Block(3,20,-2,LOG2:13)
Block(3,20,-1,LOG2:13)
Block(3,20,0,LOG2:13)
Block(3,20,2,LEAVES2:13)
Block(3,20,3,LEAVES2:13)
Block(3,20,4,LOG2:13)
Block(3,20,5,LOG2:13)
Block(3,20,6,LEAVES2:13)
Block(3,20,7,LEAVES2:13)
Block(3,20,9,LOG2:13)
Block(3,21,-1,LOG2:13)
Block(3,21,0,LOG2:13)
Block(3,21,3,LEAVES2:13)
Block(3,21,4,LEAVES2:13)
Block(3,21,5,LEAVES2:13)
Block(3,21,6,LEAVES2:13)
Block(3,21,8,LEAVES2:13)
Block(3,21,9,LEAVES2:13)
Block(3,22,-7,LEAVES2:13)
Block(3,22,-6,LEAVES2:13)
Block(3,22,0,LOG2:13)
Block(3,22,4,LEAVES2:13)
Block(3,22,9,LEAVES2:13)
Block(3,22,10,LEAVES2:13)
Block(3,22,11,LEAVES2:13)
Block(3,23,-8,LEAVES2:13)
Block(3,23,-7,LEAVES2:13)
Block(3,23,-6,LEAVES2:13)
Block(3,23,-5,LEAVES2:13)
Block(3,24,-12,LEAVES2:13)
Block(3,24,-10,LEAVES2:13)
Block(3,24,-7,LEAVES2:13)
Block(3,24,-6,LEAVES2:13)
Block(3,25,-16,LEAVES2:13)
Block(3,25,-13,LEAVES2:13)
Block(3,25,-11,LEAVES2:13)
Block(3,25,-10,LOG2:13)
Block(3,25,-9,LEAVES2:13)
Block(3,25,-4,LEAVES2:13)
Block(3,25,6,LEAVES2:13)
Block(3,26,-16,LEAVES2:13)
Block(3,26,-15,LEAVES2:13)
Block(3,26,-14,LEAVES2:13)
Block(3,26,-13,LEAVES2:13)
Block(3,26,-12,LEAVES2:13)
Block(3,26,-11,LEAVES2:13)
Block(3,26,-10,LEAVES2:13)
Block(3,26,-3,LEAVES2:13)
Block(3,26,-2,LOG2:13)
Block(3,26,-1,LEAVES2:13)
Block(3,26,0,LEAVES2:13)
Block(3,26,3,LOG2:13)
Block(3,26,12,LEAVES2:13)
Block(3,27,-17,LEAVES2:13)
Block(3,27,-16,LEAVES2:13)
Block(3,27,-15,LEAVES2:13)
Block(3,27,-14,LOG2:13)
Block(3,27,-11,LEAVES2:13)
Block(3,27,-7,LEAVES2:13)
Block(3,27,-6,LEAVES2:13)
Block(3,27,-5,LEAVES2:13)
Block(3,27,-2,LEAVES2:13)
Block(3,27,2,LOG2:13)
Block(3,27,3,LOG2:13)
Block(3,27,4,LOG2:13)
Block(3,27,9,LEAVES2:13)
Block(3,27,10,LEAVES2:13)
Block(3,27,11,LEAVES2:13)
Block(3,28,-16,LEAVES2:13)
Block(3,28,-15,LEAVES2:13)
Block(3,28,-14,LEAVES2:13)
Block(3,28,-4,LEAVES2:13)
Block(3,28,-3,LEAVES2:13)
Block(3,28,1,LEAVES2:13)
Block(3,28,2,LEAVES2:13)
Block(3,28,3,LOG2:13)
Block(3,28,6,LEAVES2:13)
Block(3,28,7,LEAVES2:13)
Block(3,28,9,LEAVES2:13)
Block(3,28,10,LOG2:13)
Block(3,28,11,LEAVES2:13)
Block(3,28,12,LEAVES2:13)
Block(3,28,13,LEAVES2:13)
Block(3,29,-5,LEAVES2:13)
Block(3,29,-3,LEAVES2:13)
Block(3,29,-2,LEAVES2:13)
Block(3,29,-1,LEAVES2:13)
Block(3,29,0,LEAVES2:13)
Block(3,29,1,LEAVES2:13)
Block(3,29,2,LEAVES2:13)
Block(3,29,3,LEAVES2:13)
Block(3,29,10,LEAVES2:13)
Block(3,29,11,LEAVES2:13)
Block(3,29,12,LEAVES2:13)
Block(3,30,-2,LEAVES2:13)
Block(3,30,0,LOG2:13)
Block(3,30,1,LEAVES2:13)
Block(3,30,2,LEAVES2:13)
Block(3,30,4,LOG2:13)
Block(3,30,5,LEAVES2:13)
Block(3,31,2,LEAVES2:13)
Block(3,31,4,LEAVES2:13)
Block(4,14,8,LOG2:13)
Block(4,14,9,LEAVES2:13)
Block(4,14,13,LEAVES2:13)
Block(4,15,8,LEAVES2:13)
Block(4,15,9,LEAVES2:13)
Block(4,15,10,LEAVES2:13)
Block(4,15,12,LEAVES2:13)
Block(4,16,3,LOG2:13)
Block(4,16,4,LOG2:13)
Block(4,16,5,LOG2:13)
Block(4,16,8,LEAVES2:13)
Block(4,16,9,LEAVES2:13)
Block(4,16,10,LOG2:13)
Block(4,16,11,LOG2:13)
Block(4,16,12,LEAVES2:13)
Block(4,16,13,LEAVES2:13)
Block(4,16,14,LEAVES2:13)
Block(4,17,2,LEAVES2:13)
Block(4,17,3,LEAVES2:13)
Block(4,17,4,LOG2:13)
Block(4,17,8,LEAVES2:13)
Block(4,17,9,LEAVES2:13)
Block(4,17,10,LEAVES2:13)
Block(4,17,11,LEAVES2:13)
Block(4,17,12,LEAVES2:13)
Block(4,18,-2,LOG2:13)
Block(4,18,3,LEAVES2:13)
Block(4,18,4,LEAVES2:13)
Block(4,18,9,LEAVES2:13)
Block(4,19,-2,LOG2:13)
Block(4,19,-1,LOG2:13)
Block(4,20,-2,LOG2:13)
Block(4,20,-1,LOG2:13)
Block(4,20,0,LEAVES2:13)
Block(4,20,3,LEAVES2:13)
Block(4,20,4,LEAVES2:13)
Block(4,20,5,LEAVES2:13)
Block(4,20,6,LEAVES2:13)
Block(4,20,7,LEAVES2:13)
Block(4,20,8,LEAVES2:13)
Block(4,20,9,LOG2:13)
Block(4,20,11,LEAVES2:13)
Block(4,21,-1,LOG2:13)
Block(4,21,0,LOG2:13)
Block(4,21,4,LEAVES2:13)
Block(4,21,5,LEAVES2:13)
Block(4,21,7,LEAVES2:13)
Block(4,21,8,LEAVES2:13)
Block(4,21,9,LEAVES2:13)
Block(4,21,10,LOG2:13)
Block(4,21,11,LEAVES2:13)
Block(4,21,13,LEAVES2:13)
Block(4,22,-8,LEAVES2:13)
Block(4,22,-1,LOG2:13)
Block(4,22,0,LOG2:13)
Block(4,22,1,LOG2:13)
Block(4,22,8,LEAVES2:13)
Block(4,22,10,LEAVES2:13)
Block(4,22,12,LEAVES2:13)
Block(4,23,-9,LEAVES2:13)
Block(4,23,-8,LEAVES2:13)
Block(4,23,-7,LOG2:13)
Block(4,23,-6,LEAVES2:13)
Block(4,23,0,LOG2:13)
Block(4,23,1,LOG2:13)
Block(4,23,9,LEAVES2:13)
Block(4,23,11,LEAVES2:13)
Block(4,24,-9,LEAVES2:13)
Block(4,24,-7,LEAVES2:13)
Block(4,24,1,LOG2:13)
Block(4,24,2,LOG2:13)
Block(4,25,-14,LEAVES2:13)
Block(4,25,-10,LEAVES2:13)
Block(4,25,-9,LOG2:13)
Block(4,25,-8,LEAVES2:13)
Block(4,25,-2,LEAVES2:13)
Block(4,25,2,LOG2:13)
Block(4,25,3,LOG2:13)
Block(4,26,-17,LEAVES2:13)
Block(4,26,-15,LEAVES2:13)
Block(4,26,-11,LEAVES2:13)
Block(4,26,-9,LEAVES2:13)
Block(4,26,-8,LEAVES2:13)
Block(4,26,-5,LEAVES2:13)
Block(4,26,-3,LEAVES2:13)
Block(4,26,-2,LOG2:13)
Block(4,26,-1,LEAVES2:13)
Block(4,26,2,LOG2:13)
Block(4,26,3,LOG2:13)
Block(4,26,11,LEAVES2:13)
Block(4,27,-16,LEAVES2:13)
Block(4,27,-15,LEAVES2:13)
Block(4,27,-14,LEAVES2:13)
Block(4,27,-4,LEAVES2:13)
Block(4,27,-2,LEAVES2:13)
Block(4,27,0,LEAVES2:13)
Block(4,27,3,LOG2:13)
Block(4,27,7,LEAVES2:13)
Block(4,27,8,LEAVES2:13)
Block(4,27,9,LOG2:13)
Block(4,27,10,LEAVES2:13)
Block(4,27,12,LEAVES2:13)
Block(4,28,-15,LEAVES2:13)
Block(4,28,-6,LEAVES2:13)
Block(4,28,2,LEAVES2:13)
Block(4,28,5,LEAVES2:13)
Block(4,28,6,LEAVES2:13)
Block(4,28,7,LEAVES2:13)
Block(4,28,8,LEAVES2:13)
Block(4,28,9,LEAVES2:13)
Block(4,28,10,LEAVES2:13)
Block(4,28,11,LEAVES2:13)
Block(4,28,12,LEAVES2:13)
Block(4,29,-3,LEAVES2:13)
Block(4,29,-2,LEAVES2:13)
Block(4,29,-1,LOG2:13)
Block(4,29,1,LEAVES2:13)
Block(4,29,2,LEAVES2:13)
Block(4,29,6,LEAVES2:13)
Block(4,29,7,LEAVES2:13)
Block(4,30,-3,LEAVES2:13)
Block(4,30,-2,LEAVES2:13)
Block(4,30,-1,LEAVES2:13)
Block(4,30,2,LEAVES2:13)
Block(4,30,3,LEAVES2:13)
Block(4,30,4,LEAVES2:13)
Block(4,30,5,LOG2:13)
Block(4,30,6,LEAVES2:13)
Block(4,30,8,LEAVES2:13)
Block(4,31,-2,LEAVES2:13)
Block(4,31,5,LEAVES2:13)
Block(4,31,6,LEAVES2:13)
Block(5,13,8,LOG2:13)
Block(5,13,14,LEAVES2:13)
Block(5,14,-1,LEAVES2:13)
Block(5,14,8,LOG2:13)
Block(5,15,0,LEAVES2:13)
Block(5,15,8,LEAVES2:13)
Block(5,15,9,LOG2:13)
Block(5,15,12,LEAVES2:13)
Block(5,15,14,LEAVES2:13)
Block(5,15,15,LEAVES2:13)
Block(5,16,0,LEAVES2:13)
Block(5,16,9,LEAVES2:13)
Block(5,16,10,LEAVES2:13)
Block(5,16,11,LEAVES2:13)
Block(5,16,12,LEAVES2:13)
Block(5,16,13,LEAVES2:13)
Block(5,17,1,LEAVES2:13)
Block(5,17,2,LOG2:13)
Block(5,17,4,LOG2:13)
Block(5,17,5,LOG2:13)
Block(5,17,10,LEAVES2:13)
Block(5,17,12,LEAVES2:13)
Block(5,18,2,LEAVES2:13)
Block(5,18,5,LOG2:13)
Block(5,19,-2,LOG2:13)
Block(5,19,-1,LOG2:13)
Block(5,19,5,LEAVES2:13)
Block(5,19,8,LOG2:13)
Block(5,20,-2,LOG2:13)
Block(5,20,-1,LOG2:13)
Block(5,20,4,LEAVES2:13)
Block(5,20,7,LEAVES2:13)
Block(5,20,8,LOG2:13)
Block(5,20,9,LEAVES2:13)
Block(5,21,-9,LEAVES2:13)
Block(5,21,-7,LEAVES2:13)
Block(5,21,-2,LOG2:13)
Block(5,21,-1,LOG2:13)
Block(5,21,8,LEAVES2:13)
Block(5,21,9,LEAVES2:13)
Block(5,21,10,LEAVES2:13)
Block(5,21,11,LOG2:13)
Block(5,21,12,LEAVES2:13)
Block(5,22,-8,LEAVES2:13)
Block(5,22,-7,LEAVES2:13)
Block(5,22,-6,LEAVES2:13)
Block(5,22,10,LEAVES2:13)
Block(5,22,11,LEAVES2:13)
Block(5,22,12,LEAVES2:13)
Block(5,22,13,LEAVES2:13)
Block(5,23,-10,LEAVES2:13)
Block(5,23,-8,LEAVES2:13)
Block(5,23,-7,LOG2:13)
Block(5,23,-6,LEAVES2:13)
Block(5,23,-5,LEAVES2:13)
Block(5,23,1,LOG2:13)
Block(5,23,2,LOG2:13)
Block(5,23,12,LEAVES2:13)
Block(5,24,-7,LEAVES2:13)
Block(5,24,-6,LEAVES2:13)
Block(5,24,1,LOG2:13)
Block(5,24,2,LOG2:13)
Block(5,25,-11,LEAVES2:13)
Block(5,25,-9,LEAVES2:13)
Block(5,25,-3,LEAVES2:13)
Block(5,25,-2,LEAVES2:13)
Block(5,25,2,LOG2:13)
Block(5,25,4,LOG2:13)
Block(5,26,-16,LEAVES2:13)
Block(5,26,-9,LEAVES2:13)
Block(5,26,-8,LOG2:13)
Block(5,26,-7,LEAVES2:13)
Block(5,26,-4,LEAVES2:13)
Block(5,26,-3,LEAVES2:13)
Block(5,26,-2,LEAVES2:13)
Block(5,26,-1,LEAVES2:13)
Block(5,26,4,LOG2:13)
Block(5,26,7,LEAVES2:13)
Block(5,26,9,LEAVES2:13)
Block(5,27,-15,LEAVES2:13)
Block(5,27,-8,LEAVES2:13)
Block(5,27,-5,LEAVES2:13)
Block(5,27,-4,LEAVES2:13)
Block(5,27,-3,LEAVES2:13)
Block(5,27,-2,LEAVES2:13)
Block(5,27,7,LOG2:13)
Block(5,27,8,LOG2:13)
Block(5,27,9,LEAVES2:13)
Block(5,27,10,LEAVES2:13)
Block(5,28,-4,LEAVES2:13)
Block(5,28,-2,LEAVES2:13)
Block(5,28,-1,LOG2:13)
Block(5,28,6,LEAVES2:13)
Block(5,28,7,LEAVES2:13)
Block(5,28,8,LEAVES2:13)
Block(5,28,9,LEAVES2:13)
Block(5,29,-6,LEAVES2:13)
Block(5,29,-2,LEAVES2:13)
Block(5,29,-1,LEAVES2:13)
Block(5,29,7,LEAVES2:13)
Block(5,29,11,LEAVES2:13)
Block(5,30,-5,LEAVES2:13)
Block(5,30,-2,LEAVES2:13)
Block(5,30,3,LEAVES2:13)
Block(5,30,5,LEAVES2:13)
Block(5,31,5,LEAVES2:13)
Block(5,31,6,LOG2:13)
Block(5,31,7,LEAVES2:13)
Block(5,32,6,LEAVES2:13)
Block(6,13,8,LEAVES2:13)
Block(6,13,9,LOG2:13)
Block(6,14,6,LEAVES2:13)
Block(6,14,7,LOG2:13)
Block(6,14,8,LEAVES2:13)
Block(6,14,9,LEAVES2:13)
Block(6,14,12,LEAVES2:13)
Block(6,14,13,LEAVES2:13)
Block(6,14,14,LEAVES2:13)
Block(6,14,15,LEAVES2:13)
Block(6,15,-3,LEAVES2:13)
Block(6,15,-1,LEAVES2:13)
Block(6,15,0,LEAVES2:13)
Block(6,15,7,LOG2:13)
Block(6,15,8,LEAVES2:13)
Block(6,15,9,LEAVES2:13)
Block(6,15,14,LOG2:13)
Block(6,15,15,LEAVES2:13)
Block(6,15,16,LEAVES2:13)
Block(6,16,-1,LEAVES2:13)
Block(6,16,0,LOG2:13)
Block(6,16,7,LEAVES2:13)
Block(6,16,8,LEAVES2:13)
Block(6,16,10,LEAVES2:13)
Block(6,16,12,LEAVES2:13)
Block(6,16,14,LEAVES2:13)
Block(6,16,15,LEAVES2:13)
Block(6,17,-2,LEAVES2:13)
Block(6,17,0,LEAVES2:13)
Block(6,17,1,LOG2:13)
Block(6,17,2,LEAVES2:13)
Block(6,17,5,LOG2:13)
Block(6,17,6,LOG2:13)
Block(6,18,1,LEAVES2:13)
Block(6,18,6,LOG2:13)
Block(6,18,7,LOG2:13)
Block(6,19,-2,LOG2:13)
Block(6,19,1,LEAVES2:13)
Block(6,19,3,LEAVES2:13)
Block(6,19,7,LOG2:13)
Block(6,20,-3,LOG2:13)
Block(6,20,-2,LOG2:13)
Block(6,20,-1,LOG2:13)
Block(6,20,0,LOG2:13)
Block(6,20,8,LEAVES2:13)
Block(6,20,13,LEAVES2:13)
Block(6,21,-3,LOG2:13)
Block(6,21,-1,LOG2:13)
Block(6,21,10,LEAVES2:13)
Block(6,21,11,LEAVES2:13)
Block(6,21,13,LEAVES2:13)
Block(6,21,14,LEAVES2:13)
Block(6,22,-7,LEAVES2:13)
Block(6,22,-6,LOG2:13)
Block(6,22,-5,LEAVES2:13)
Block(6,22,9,LEAVES2:13)
Block(6,22,11,LEAVES2:13)
Block(6,22,12,LOG2:13)
Block(6,22,13,LEAVES2:13)
Block(6,23,-7,LEAVES2:13)
Block(6,23,-6,LEAVES2:13)
Block(6,23,12,LEAVES2:13)
Block(6,23,13,LEAVES2:13)
Block(6,24,-9,LEAVES2:13)
Block(6,25,-10,LEAVES2:13)
Block(6,25,-8,LEAVES2:13)
Block(6,25,-2,LEAVES2:13)
Block(6,25,6,LEAVES2:13)
Block(6,26,-9,LEAVES2:13)
Block(6,26,-8,LEAVES2:13)
Block(6,26,-7,LEAVES2:13)
Block(6,26,-3,LEAVES2:13)
Block(6,26,-2,LEAVES2:13)
Block(6,26,-1,LEAVES2:13)
Block(6,26,1,LOG2:13)
Block(6,26,5,LOG2:13)
Block(6,26,6,LOG2:13)
Block(6,26,7,LEAVES2:13)
Block(6,26,9,LEAVES2:13)
Block(6,26,10,LEAVES2:13)
Block(6,27,-9,LEAVES2:13)
Block(6,27,-8,LEAVES2:13)
Block(6,27,-7,LEAVES2:13)
Block(6,27,-2,LEAVES2:13)
Block(6,27,1,LOG2:13)
Block(6,27,8,LEAVES2:13)
Block(6,27,9,LEAVES2:13)
Block(6,27,10,LEAVES2:13)
Block(6,27,11,LEAVES2:13)
Block(6,28,-8,LEAVES2:13)
Block(6,28,-5,LEAVES2:13)
Block(6,28,-1,LOG2:13)
Block(6,28,6,LEAVES2:13)
Block(6,28,7,LOG2:13)
Block(6,28,8,LEAVES2:13)
Block(6,28,9,LEAVES2:13)
Block(6,28,10,LEAVES2:13)
Block(6,29,-3,LEAVES2:13)
Block(6,29,-2,LOG2:13)
Block(6,29,-1,LEAVES2:13)
Block(6,29,7,LEAVES2:13)
Block(6,29,8,LEAVES2:13)
Block(6,29,9,LEAVES2:13)
Block(6,30,-6,LEAVES2:13)
Block(6,30,-5,LEAVES2:13)
Block(6,30,-4,LEAVES2:13)
Block(6,30,-2,LEAVES2:13)
Block(6,31,4,LEAVES2:13)
Block(6,31,5,LEAVES2:13)
Block(6,31,6,LOG2:13)
Block(6,31,7,LEAVES2:13)
Block(6,32,5,LEAVES2:13)
Block(6,32,6,LEAVES2:13)
Block(6,32,8,LEAVES2:13)
Block(7,13,6,LEAVES2:13)
Block(7,13,10,LOG2:13)
Block(7,13,11,LOG2:13)
Block(7,13,13,LEAVES2:13)
Block(7,14,7,LEAVES2:13)
Block(7,14,8,LEAVES2:13)
Block(7,14,10,LEAVES2:13)
Block(7,14,12,LOG2:13)
Block(7,14,13,LOG2:13)
Block(7,14,14,LEAVES2:13)
Block(7,15,-2,LEAVES2:13)
Block(7,15,0,LEAVES2:13)
Block(7,15,5,LEAVES2:13)
Block(7,15,6,LOG2:13)
Block(7,15,7,LEAVES2:13)
Block(7,15,8,LEAVES2:13)
Block(7,15,9,LEAVES2:13)
Block(7,15,10,LEAVES2:13)
Block(7,15,12,LEAVES2:13)
Block(7,15,13,LEAVES2:13)
Block(7,15,14,LEAVES2:13)
Block(7,15,15,LEAVES2:13)
Block(7,16,-3,LEAVES2:13)
Block(7,16,-2,LEAVES2:13)
Block(7,16,-1,LOG2:13)
Block(7,16,0,LEAVES2:13)
Block(7,16,4,LEAVES2:13)
Block(7,16,5,LEAVES2:13)
Block(7,16,7,LEAVES2:13)
Block(7,16,8,LEAVES2:13)
Block(7,16,9,LEAVES2:13)
Block(7,17,-2,LEAVES2:13)
Block(7,17,-1,LEAVES2:13)
Block(7,17,8,LEAVES2:13)
Block(7,18,-2,LEAVES2:13)
Block(7,18,0,LEAVES2:13)
Block(7,18,1,LOG2:13)
Block(7,18,2,LEAVES2:13)
Block(7,18,6,LOG2:13)
Block(7,18,7,LOG2:13)
Block(7,19,0,LEAVES2:13)
Block(7,19,1,LEAVES2:13)
Block(7,19,2,LEAVES2:13)
Block(7,19,7,LOG2:13)
Block(7,19,8,LOG2:13)
Block(7,20,-5,LEAVES2:13)
Block(7,20,-1,LOG2:13)
Block(7,20,1,LEAVES2:13)
Block(7,20,2,LEAVES2:13)
Block(7,20,7,LEAVES2:13)
Block(7,21,-6,LEAVES2:13)
Block(7,21,-5,LEAVES2:13)
Block(7,21,-4,LOG2:13)
Block(7,21,-1,LOG2:13)
Block(7,21,0,LOG2:13)
Block(7,21,10,LEAVES2:13)
Block(7,21,13,LEAVES2:13)
Block(7,22,-8,LEAVES2:13)
Block(7,22,-6,LEAVES2:13)
Block(7,22,-5,LOG2:13)
Block(7,22,-4,LOG2:13)
Block(7,22,-1,LOG2:13)
Block(7,22,0,LOG2:13)
Block(7,22,8,LEAVES2:13)
Block(7,22,10,LEAVES2:13)
Block(7,22,12,LEAVES2:13)
Block(7,23,10,LEAVES2:13)
Block(7,25,-8,LEAVES2:13)
Block(7,26,-9,LEAVES2:13)
Block(7,26,-8,LEAVES2:13)
Block(7,26,-7,LEAVES2:13)
Block(7,26,-2,LEAVES2:13)
Block(7,26,3,LEAVES2:13)
Block(7,26,4,LEAVES2:13)
Block(7,26,6,LEAVES2:13)
Block(7,27,-8,LEAVES2:13)
Block(7,27,0,LOG2:13)
Block(7,27,5,LEAVES2:13)
Block(7,27,9,LEAVES2:13)
Block(7,27,10,LEAVES2:13)
Block(7,28,0,LOG2:13)
Block(7,28,7,LEAVES2:13)
Block(7,28,8,LOG2:13)
Block(7,28,9,LEAVES2:13)
Block(7,29,-6,LEAVES2:13)
Block(7,29,-5,LEAVES2:13)
Block(7,29,-4,LEAVES2:13)
Block(7,29,-3,LOG2:13)
Block(7,29,-2,LEAVES2:13)
Block(7,29,0,LEAVES2:13)
Block(7,29,8,LEAVES2:13)
Block(7,29,9,LEAVES2:13)
Block(7,30,-7,LEAVES2:13)
Block(7,30,-6,LEAVES2:13)
Block(7,30,-5,LEAVES2:13)
Block(7,30,-4,LOG2:13)
Block(7,30,4,LEAVES2:13)
Block(7,30,6,LEAVES2:13)
Block(7,30,9,LEAVES2:13)
Block(7,31,-6,LEAVES2:13)
Block(7,31,-5,LEAVES2:13)
Block(7,31,-4,LEAVES2:13)
Block(7,31,5,LEAVES2:13)
Block(7,31,6,LEAVES2:13)
Block(7,31,7,LEAVES2:13)
Block(7,31,8,LEAVES2:13)
Block(7,32,5,LEAVES2:13)
Block(7,32,6,LEAVES2:13)
Block(7,32,7,LEAVES2:13)
Block(7,33,6,LEAVES2:13)
Block(8,13,10,LEAVES2:13)
Block(8,13,11,LEAVES2:13)
Block(8,13,12,LEAVES2:13)
Block(8,13,13,LEAVES2:13)
Block(8,14,0,LEAVES2:13)
Block(8,14,5,LEAVES2:13)
Block(8,14,7,LEAVES2:13)
Block(8,14,10,LOG2:13)
Block(8,14,11,LEAVES2:13)
Block(8,14,12,LEAVES2:13)
Block(8,14,13,LEAVES2:13)
Block(8,14,14,LEAVES2:13)
Block(8,14,15,LEAVES2:13)
Block(8,15,-3,LEAVES2:13)
Block(8,15,-1,LEAVES2:13)
Block(8,15,0,LEAVES2:13)
Block(8,15,1,LEAVES2:13)
Block(8,15,4,LEAVES2:13)
Block(8,15,5,LEAVES2:13)
Block(8,15,6,LEAVES2:13)
Block(8,15,8,LEAVES2:13)
Block(8,15,9,LEAVES2:13)
Block(8,15,10,LEAVES2:13)
Block(8,15,11,LEAVES2:13)
Block(8,15,12,LEAVES2:13)
Block(8,15,13,LEAVES2:13)
Block(8,16,-2,LEAVES2:13)
Block(8,16,-1,LEAVES2:13)
Block(8,16,0,LEAVES2:13)
Block(8,16,3,LEAVES2:13)
Block(8,16,4,LEAVES2:13)
Block(8,16,5,LOG2:13)
Block(8,16,7,LEAVES2:13)
Block(8,16,8,LEAVES2:13)
Block(8,16,12,LEAVES2:13)
Block(8,17,-4,LEAVES2:13)
Block(8,17,-3,LEAVES2:13)
Block(8,17,-2,LOG2:13)
Block(8,17,-1,LEAVES2:13)
Block(8,17,0,LEAVES2:13)
Block(8,17,4,LEAVES2:13)
Block(8,17,5,LEAVES2:13)
Block(8,18,-3,LEAVES2:13)
Block(8,18,-2,LEAVES2:13)
Block(8,18,-1,LEAVES2:13)
Block(8,18,1,LEAVES2:13)
Block(8,18,2,LOG2:13)
Block(8,18,3,LEAVES2:13)
Block(8,19,1,LEAVES2:13)
Block(8,19,2,LEAVES2:13)
Block(8,19,8,LOG2:13)
Block(8,20,8,LOG2:13)
Block(8,20,9,LOG2:13)
Block(8,20,10,LEAVES2:13)
Block(8,21,-5,LEAVES2:13)
Block(8,21,0,LOG2:13)
Block(8,21,9,LOG2:13)
Block(8,21,10,LOG2:13)
Block(8,21,11,LEAVES2:13)
Block(8,22,-5,LEAVES2:13)
Block(8,22,-1,LOG2:13)
Block(8,22,0,LOG2:13)
Block(8,22,1,LOG2:13)
Block(8,22,9,LEAVES2:13)
Block(8,22,10,LOG2:13)
Block(8,22,11,LEAVES2:13)
Block(8,22,14,LEAVES2:13)
Block(8,23,-9,LEAVES2:13)
Block(8,23,-4,LOG2:13)
Block(8,23,10,LEAVES2:13)
Block(8,23,11,LEAVES2:13)
Block(8,23,12,LEAVES2:13)
Block(8,23,13,LEAVES2:13)
Block(8,24,-7,LEAVES2:13)
Block(8,24,-6,LEAVES2:13)
Block(8,24,-4,LEAVES2:13)
Block(8,24,12,LEAVES2:13)
Block(8,25,-9,LEAVES2:13)
Block(8,25,-8,LEAVES2:13)
Block(8,25,-7,LEAVES2:13)
Block(8,26,-8,LEAVES2:13)
Block(8,26,2,LEAVES2:13)
Block(8,26,3,LEAVES2:13)
Block(8,26,4,LOG2:13)
Block(8,26,7,LEAVES2:13)
Block(8,27,4,LEAVES2:13)
Block(8,27,5,LOG2:13)
Block(8,27,6,LEAVES2:13)
Block(8,28,-6,LEAVES2:13)
Block(8,28,-3,LEAVES2:13)
Block(8,28,-2,LEAVES2:13)
Block(8,28,0,LEAVES2:13)
Block(8,28,5,LEAVES2:13)
Block(8,28,8,LEAVES2:13)
Block(8,28,10,LEAVES2:13)
Block(8,29,-5,LEAVES2:13)
Block(8,29,-3,LEAVES2:13)
Block(8,29,7,LEAVES2:13)
Block(8,29,8,LOG2:13)
Block(8,29,9,LEAVES2:13)
Block(8,30,-6,LEAVES2:13)
Block(8,30,-5,LEAVES2:13)
Block(8,30,-4,LEAVES2:13)
Block(8,30,8,LEAVES2:13)
Block(8,31,-5,LEAVES2:13)
Block(8,31,5,LEAVES2:13)
Block(8,31,6,LEAVES2:13)
Block(8,31,7,LEAVES2:13)
Block(8,32,6,LEAVES2:13)
Block(9,12,10,LEAVES2:13)
Block(9,13,12,LEAVES2:13)
Block(9,13,14,LEAVES2:13)
Block(9,14,-1,LEAVES2:13)
Block(9,14,8,LEAVES2:13)
Block(9,14,10,LEAVES2:13)
Block(9,14,11,LEAVES2:13)
Block(9,14,12,LEAVES2:13)
Block(9,14,13,LEAVES2:13)
Block(9,15,0,LEAVES2:13)
Block(9,15,3,LEAVES2:13)
Block(9,15,5,LEAVES2:13)
Block(9,15,7,LEAVES2:13)
Block(9,15,9,LEAVES2:13)
Block(9,15,10,LOG2:13)
Block(9,15,11,LEAVES2:13)
Block(9,15,12,LEAVES2:13)
Block(9,15,14,LEAVES2:13)
Block(9,16,-4,LEAVES2:13)
Block(9,16,-3,LEAVES2:13)
Block(9,16,-2,LEAVES2:13)
Block(9,16,-1,LEAVES2:13)
Block(9,16,0,LEAVES2:13)
Block(9,16,1,LEAVES2:13)
Block(9,16,4,LEAVES2:13)
Block(9,16,5,LEAVES2:13)
Block(9,16,6,LEAVES2:13)
Block(9,16,10,LEAVES2:13)
Block(9,17,-5,LEAVES2:13)
Block(9,17,-4,LEAVES2:13)
Block(9,17,-3,LOG2:13)
Block(9,17,-2,LEAVES2:13)
Block(9,17,-1,LEAVES2:13)
Block(9,17,0,LEAVES2:13)
Block(9,17,5,LEAVES2:13)
Block(9,18,-4,LEAVES2:13)
Block(9,18,-3,LEAVES2:13)
Block(9,18,-2,LEAVES2:13)
Block(9,18,3,LEAVES2:13)
Block(9,19,-3,LEAVES2:13)
Block(9,19,0,LEAVES2:13)
Block(9,19,1,LEAVES2:13)
Block(9,19,2,LOG2:13)
Block(9,19,3,LEAVES2:13)
Block(9,20,-8,LEAVES2:13)
Block(9,20,1,LEAVES2:13)
Block(9,20,2,LEAVES2:13)
Block(9,20,7,LOG2:13)
Block(9,20,9,LEAVES2:13)
Block(9,21,-7,LEAVES2:13)
Block(9,21,-1,LOG2:13)
Block(9,21,8,LEAVES2:13)
Block(9,21,9,LEAVES2:13)
Block(9,21,10,LOG2:13)
Block(9,22,-6,LEAVES2:13)
Block(9,22,0,LOG2:13)
Block(9,22,1,LOG2:13)
Block(9,22,7,LEAVES2:13)
Block(9,22,8,LEAVES2:13)
Block(9,22,9,LEAVES2:13)
Block(9,22,10,LOG2:13)
Block(9,22,11,LOG2:13)
Block(9,22,12,LEAVES2:13)
Block(9,22,13,LEAVES2:13)
Block(9,23,-8,LEAVES2:13)
Block(9,23,-7,LEAVES2:13)
Block(9,23,-6,LEAVES2:13)
Block(9,23,-5,LOG2:13)
Block(9,23,-4,LEAVES2:13)
Block(9,23,1,LOG2:13)
Block(9,23,2,LOG2:13)
Block(9,23,8,LEAVES2:13)
Block(9,23,9,LEAVES2:13)
Block(9,23,10,LEAVES2:13)
Block(9,23,11,LOG2:13)
Block(9,23,12,LEAVES2:13)
Block(9,23,13,LEAVES2:13)
Block(9,23,14,LEAVES2:13)
Block(9,24,-11,LEAVES2:13)
Block(9,24,-9,LEAVES2:13)
Block(9,24,-8,LEAVES2:13)
Block(9,24,-7,LOG2:13)
Block(9,24,-6,LOG2:13)
Block(9,24,-5,LEAVES2:13)
Block(9,24,-3,LOG2:13)
Block(9,24,11,LEAVES2:13)
Block(9,24,12,LEAVES2:13)
Block(9,24,13,LEAVES2:13)
Block(9,25,-10,LEAVES2:13)
Block(9,25,-9,LEAVES2:13)
Block(9,25,-8,LOG2:13)
Block(9,25,-7,LEAVES2:13)
Block(9,25,-6,LEAVES2:13)
Block(9,25,4,LOG2:13)
Block(9,25,12,LEAVES2:13)
Block(9,26,-9,LEAVES2:13)
Block(9,26,-8,LEAVES2:13)
Block(9,26,3,LEAVES2:13)
Block(9,26,4,LEAVES2:13)
Block(9,26,5,LEAVES2:13)
Block(9,27,-1,LEAVES2:13)
Block(9,27,3,LEAVES2:13)
Block(9,27,4,LEAVES2:13)
Block(9,27,5,LEAVES2:13)
Block(9,28,-4,LEAVES2:13)
Block(9,28,-3,LEAVES2:13)
Block(9,28,-2,LOG2:13)
Block(9,28,-1,LEAVES2:13)
Block(9,28,4,LEAVES2:13)
Block(9,29,-7,LEAVES2:13)
Block(9,29,-3,LEAVES2:13)
Block(9,29,-2,LEAVES2:13)
Block(9,29,-1,LEAVES2:13)
Block(9,29,7,LEAVES2:13)
Block(9,29,8,LEAVES2:13)
Block(9,29,9,LOG2:13)
Block(9,29,10,LEAVES2:13)
Block(9,29,11,LEAVES2:13)
Block(9,30,-6,LEAVES2:13)
Block(9,30,-5,LEAVES2:13)
Block(9,30,5,LEAVES2:13)
Block(9,30,9,LEAVES2:13)
Block(9,31,6,LEAVES2:13)
Block(9,32,7,LEAVES2:13)
Block(10,13,8,LEAVES2:13)
Block(10,14,5,LEAVES2:13)
Block(10,14,9,LEAVES2:13)
Block(10,14,12,LEAVES2:13)
Block(10,15,-4,LEAVES2:13)
Block(10,15,-2,LEAVES2:13)
Block(10,15,6,LEAVES2:13)
Block(10,15,8,LEAVES2:13)
Block(10,15,9,LOG2:13)
Block(10,15,10,LEAVES2:13)
Block(10,16,-1,LEAVES2:13)
Block(10,16,0,LEAVES2:13)
Block(10,16,4,LEAVES2:13)
Block(10,16,5,LEAVES2:13)
Block(10,16,9,LEAVES2:13)
Block(10,17,-4,LEAVES2:13)
Block(10,17,-3,LEAVES2:13)
Block(10,17,3,LEAVES2:13)
Block(10,18,-3,LEAVES2:13)
Block(10,18,0,LEAVES2:13)
Block(10,18,2,LEAVES2:13)
Block(10,18,4,LEAVES2:13)
Block(10,19,1,LEAVES2:13)
Block(10,19,2,LOG2:13)
Block(10,19,3,LEAVES2:13)
Block(10,20,-7,LEAVES2:13)
Block(10,20,2,LEAVES2:13)
Block(10,21,-8,LEAVES2:13)
Block(10,21,-7,LEAVES2:13)
Block(10,21,-6,LEAVES2:13)
Block(10,21,-5,LEAVES2:13)
Block(10,21,-1,LOG2:13)
Block(10,21,5,LOG2:13)
Block(10,21,6,LOG2:13)
Block(10,21,8,LEAVES2:13)
Block(10,21,9,LEAVES2:13)
Block(10,21,10,LEAVES2:13)
Block(10,21,11,LEAVES2:13)
Block(10,22,6,LEAVES2:13)
Block(10,22,8,LEAVES2:13)
Block(10,22,9,LEAVES2:13)
Block(10,22,10,LEAVES2:13)
Block(10,22,11,LEAVES2:13)
Block(10,22,12,LEAVES2:13)
Block(10,23,-6,LEAVES2:13)
Block(10,23,-5,LEAVES2:13)
Block(10,23,2,LOG2:13)
Block(10,23,10,LEAVES2:13)
Block(10,23,11,LEAVES2:13)
Block(10,23,12,LEAVES2:13)
Block(10,23,13,LEAVES2:13)
Block(10,24,-10,LEAVES2:13)
Block(10,24,-8,LEAVES2:13)
Block(10,24,-6,LEAVES2:13)
Block(10,24,-3,LOG2:13)
Block(10,24,2,LOG2:13)
Block(10,24,11,LEAVES2:13)
Block(10,24,12,LEAVES2:13)
Block(10,25,-9,LEAVES2:13)
Block(10,25,-8,LEAVES2:13)
Block(10,25,-7,LEAVES2:13)
Block(10,25,2,LEAVES2:13)
Block(10,25,3,LOG2:13)
Block(10,26,-9,LEAVES2:13)
Block(10,26,-8,LEAVES2:13)
Block(10,26,-7,LEAVES2:13)
Block(10,26,1,LEAVES2:13)
Block(10,26,3,LEAVES2:13)
Block(10,26,4,LEAVES2:13)
Block(10,26,6,LEAVES2:13)
Block(10,27,-8,LEAVES2:13)
Block(10,27,-2,LEAVES2:13)
Block(10,27,-1,LOG2:13)
Block(10,27,0,LEAVES2:13)
Block(10,27,3,LEAVES2:13)
Block(10,27,4,LEAVES2:13)
Block(10,27,5,LEAVES2:13)
Block(10,28,-3,LEAVES2:13)
Block(10,28,-2,LEAVES2:13)
Block(10,28,-1,LEAVES2:13)
Block(10,28,4,LEAVES2:13)
Block(10,28,9,LEAVES2:13)
Block(10,28,11,LEAVES2:13)
Block(10,29,-6,LEAVES2:13)
Block(10,29,8,LEAVES2:13)
Block(10,29,9,LEAVES2:13)
Block(10,29,10,LEAVES2:13)
Block(10,30,9,LEAVES2:13)
Block(11,12,9,LEAVES2:13)
Block(11,14,7,LEAVES2:13)
Block(11,14,9,LEAVES2:13)
Block(11,14,10,LEAVES2:13)
Block(11,15,8,LEAVES2:13)
Block(11,15,9,LOG2:13)
Block(11,15,10,LEAVES2:13)
Block(11,15,11,LEAVES2:13)
Block(11,16,-3,LEAVES2:13)
Block(11,16,9,LEAVES2:13)
Block(11,16,10,LEAVES2:13)
Block(11,17,1,LEAVES2:13)
Block(11,18,2,LEAVES2:13)
Block(11,19,-9,LEAVES2:13)
Block(11,19,1,LEAVES2:13)
Block(11,19,2,LEAVES2:13)
Block(11,19,3,LEAVES2:13)
Block(11,20,-8,LEAVES2:13)
Block(11,20,-6,LEAVES2:13)
Block(11,20,-4,LEAVES2:13)
Block(11,20,-2,LOG2:13)
Block(11,20,2,LEAVES2:13)
Block(11,20,4,LEAVES2:13)
Block(11,21,-9,LEAVES2:13)
Block(11,21,-8,LEAVES2:13)
Block(11,21,-7,LEAVES2:13)
Block(11,21,-6,LOG2:13)
Block(11,21,-5,LEAVES2:13)
Block(11,21,3,LEAVES2:13)
Block(11,21,4,LOG2:13)
Block(11,21,5,LEAVES2:13)
Block(11,21,6,LEAVES2:13)
Block(11,21,9,LEAVES2:13)
Block(11,21,11,LEAVES2:13)
Block(11,21,13,LEAVES2:13)
Block(11,22,-8,LEAVES2:13)
Block(11,22,-7,LEAVES2:13)
Block(11,22,-6,LEAVES2:13)
Block(11,22,-5,LEAVES2:13)
Block(11,22,5,LEAVES2:13)
Block(11,22,6,LOG2:13)
Block(11,22,7,LEAVES2:13)
Block(11,22,10,LEAVES2:13)
Block(11,22,11,LEAVES2:13)
Block(11,22,12,LEAVES2:13)
Block(11,23,-9,LEAVES2:13)
Block(11,23,6,LEAVES2:13)
Block(11,23,9,LEAVES2:13)
Block(11,23,11,LEAVES2:13)
Block(11,24,-8,LEAVES2:13)
Block(11,24,2,LOG2:13)
Block(11,24,8,LEAVES2:13)
Block(11,25,-9,LEAVES2:13)
Block(11,25,-8,LEAVES2:13)
Block(11,25,-7,LEAVES2:13)
Block(11,25,-4,LEAVES2:13)
Block(11,25,-3,LOG2:13)
Block(11,25,2,LOG2:13)
Block(11,25,3,LEAVES2:13)
Block(11,25,5,LEAVES2:13)
Block(11,26,-8,LEAVES2:13)
Block(11,26,-6,LEAVES2:13)
Block(11,26,2,LEAVES2:13)
Block(11,27,-3,LEAVES2:13)
Block(11,27,-2,LEAVES2:13)
Block(11,27,-1,LEAVES2:13)
Block(11,27,0,LOG2:13)
Block(11,27,1,LEAVES2:13)
Block(11,27,4,LEAVES2:13)
Block(11,28,-2,LEAVES2:13)
Block(11,28,-1,LEAVES2:13)
Block(11,28,0,LEAVES2:13)
Block(11,28,10,LEAVES2:13)
Block(11,29,-1,LEAVES2:13)
Block(11,29,9,LEAVES2:13)
Block(12,13,10,LEAVES2:13)
Block(12,14,8,LEAVES2:13)
Block(12,14,9,LEAVES2:13)
Block(12,15,7,LEAVES2:13)
Block(12,15,8,LEAVES2:13)
Block(12,15,9,LEAVES2:13)
Block(12,15,10,LEAVES2:13)
Block(12,16,8,LEAVES2:13)
Block(12,16,9,LEAVES2:13)
Block(12,16,10,LEAVES2:13)
Block(12,17,9,LEAVES2:13)
Block(12,18,3,LEAVES2:13)
Block(12,19,-4,LEAVES2:13)
Block(12,19,2,LEAVES2:13)
Block(12,20,-8,LEAVES2:13)
Block(12,20,-5,LEAVES2:13)
Block(12,20,-4,LOG2:13)
Block(12,20,-3,LOG2:13)
Block(12,20,3,LEAVES2:13)
Block(12,20,4,LEAVES2:13)
Block(12,20,6,LEAVES2:13)
Block(12,20,11,LEAVES2:13)
Block(12,21,-8,LEAVES2:13)
Block(12,21,-7,LEAVES2:13)
Block(12,21,-6,LEAVES2:13)
Block(12,21,-5,LOG2:13)
Block(12,21,-4,LEAVES2:13)
Block(12,21,-3,LEAVES2:13)
Block(12,21,2,LEAVES2:13)
Block(12,21,3,LOG2:13)
Block(12,21,4,LEAVES2:13)
Block(12,21,5,LEAVES2:13)
Block(12,21,6,LEAVES2:13)
Block(12,21,7,LEAVES2:13)
Block(12,21,10,LEAVES2:13)
Block(12,22,-6,LEAVES2:13)
Block(12,22,-5,LEAVES2:13)
Block(12,22,-4,LEAVES2:13)
Block(12,22,3,LEAVES2:13)
Block(12,22,4,LEAVES2:13)
Block(12,22,5,LEAVES2:13)
Block(12,22,6,LEAVES2:13)
Block(12,22,7,LOG2:13)
Block(12,22,8,LEAVES2:13)
Block(12,22,11,LEAVES2:13)
Block(12,23,-5,LEAVES2:13)
Block(12,23,5,LEAVES2:13)
Block(12,23,6,LEAVES2:13)
Block(12,23,7,LEAVES2:13)
Block(12,23,8,LEAVES2:13)
Block(12,23,9,LEAVES2:13)
Block(12,23,10,LEAVES2:13)
Block(12,23,12,LEAVES2:13)
Block(12,24,-3,LEAVES2:13)
Block(12,24,6,LEAVES2:13)
Block(12,25,-8,LEAVES2:13)
Block(12,25,-6,LEAVES2:13)
Block(12,25,-5,LEAVES2:13)
Block(12,25,-4,LOG2:13)
Block(12,25,-3,LEAVES2:13)
Block(12,25,-2,LEAVES2:13)
Block(12,25,1,LOG2:13)
Block(12,25,3,LOG2:13)
Block(12,26,-5,LEAVES2:13)
Block(12,26,-4,LEAVES2:13)
Block(12,26,0,LOG2:13)
Block(12,26,1,LEAVES2:13)
Block(12,26,4,LEAVES2:13)
Block(12,27,-1,LEAVES2:13)
Block(12,27,0,LEAVES2:13)
Block(12,28,-1,LEAVES2:13)
Block(13,14,7,LEAVES2:13)
Block(13,15,8,LEAVES2:13)
Block(13,15,9,LEAVES2:13)
Block(13,16,9,LEAVES2:13)
Block(13,18,-5,LEAVES2:13)
Block(13,20,-7,LEAVES2:13)
Block(13,20,-4,LEAVES2:13)
Block(13,20,-3,LOG2:13)
Block(13,20,-2,LEAVES2:13)
Block(13,21,-6,LEAVES2:13)
Block(13,21,-5,LEAVES2:13)
Block(13,21,4,LEAVES2:13)
Block(13,21,6,LEAVES2:13)
Block(13,22,-5,LEAVES2:13)
Block(13,22,-4,LEAVES2:13)
Block(13,22,-2,LEAVES2:13)
Block(13,22,1,LEAVES2:13)
Block(13,22,2,LEAVES2:13)
Block(13,22,3,LOG2:13)
Block(13,22,5,LEAVES2:13)
Block(13,22,6,LEAVES2:13)
Block(13,22,7,LEAVES2:13)
Block(13,22,9,LEAVES2:13)
Block(13,22,10,LEAVES2:13)
Block(13,22,12,LEAVES2:13)
Block(13,23,3,LEAVES2:13)
Block(13,23,6,LEAVES2:13)
Block(13,23,7,LEAVES2:13)
Block(13,23,8,LOG2:13)
Block(13,23,9,LOG2:13)
Block(13,23,10,LEAVES2:13)
Block(13,23,11,LEAVES2:13)
Block(13,24,8,LEAVES2:13)
Block(13,24,9,LEAVES2:13)
Block(13,24,10,LEAVES2:13)
Block(13,25,-7,LEAVES2:13)
Block(13,25,-5,LEAVES2:13)
Block(13,25,1,LEAVES2:13)
Block(13,25,3,LEAVES2:13)
Block(13,25,4,LOG2:13)
Block(13,25,5,LEAVES2:13)
Block(13,26,-8,LEAVES2:13)
Block(13,26,-6,LEAVES2:13)
Block(13,26,-5,LOG2:13)
Block(13,26,-4,LEAVES2:13)
Block(13,26,-3,LEAVES2:13)
Block(13,26,-2,LEAVES2:13)
Block(13,26,-1,LOG2:13)
Block(13,26,0,LEAVES2:13)
Block(13,26,4,LOG2:13)
Block(13,26,5,LEAVES2:13)
Block(13,27,-5,LEAVES2:13)
Block(13,27,-1,LEAVES2:13)
Block(13,27,0,LEAVES2:13)
Block(13,27,4,LEAVES2:13)
Block(14,20,-5,LEAVES2:13)
Block(14,20,-3,LEAVES2:13)
Block(14,20,3,LEAVES2:13)
Block(14,21,-5,LEAVES2:13)
Block(14,21,-3,LEAVES2:13)
Block(14,21,-2,LOG2:13)
Block(14,21,-1,LEAVES2:13)
Block(14,21,1,LEAVES2:13)
Block(14,21,2,LEAVES2:13)
Block(14,21,10,LEAVES2:13)
Block(14,22,-3,LEAVES2:13)
Block(14,22,-2,LEAVES2:13)
Block(14,22,-1,LEAVES2:13)
Block(14,22,0,LEAVES2:13)
Block(14,22,1,LEAVES2:13)
Block(14,22,2,LOG2:13)
Block(14,22,3,LEAVES2:13)
Block(14,22,6,LEAVES2:13)
Block(14,22,9,LEAVES2:13)
Block(14,23,-2,LEAVES2:13)
Block(14,23,1,LEAVES2:13)
Block(14,23,2,LEAVES2:13)
Block(14,23,3,LEAVES2:13)
Block(14,23,4,LEAVES2:13)
Block(14,23,7,LEAVES2:13)
Block(14,23,8,LEAVES2:13)
Block(14,23,9,LEAVES2:13)
Block(14,23,10,LEAVES2:13)
Block(14,24,3,LEAVES2:13)
Block(14,24,9,LEAVES2:13)
Block(14,25,-6,LEAVES2:13)
Block(14,25,-3,LEAVES2:13)
Block(14,25,-1,LEAVES2:13)
Block(14,25,4,LEAVES2:13)
Block(14,26,-7,LEAVES2:13)
Block(14,26,-6,LEAVES2:13)
Block(14,26,-5,LEAVES2:13)
Block(14,26,-4,LEAVES2:13)
Block(14,26,-1,LEAVES2:13)
Block(14,26,0,LEAVES2:13)
Block(14,26,1,LEAVES2:13)
Block(14,26,4,LEAVES2:13)
Block(14,26,5,LOG2:13)
Block(14,26,6,LEAVES2:13)
Block(14,27,-6,LEAVES2:13)
Block(14,27,-5,LEAVES2:13)
Block(14,27,-2,LEAVES2:13)
Block(14,27,-1,LOG2:13)
Block(14,27,0,LEAVES2:13)
Block(14,27,5,LEAVES2:13)
Block(14,28,-1,LEAVES2:13)
Block(15,21,-2,LEAVES2:13)
Block(15,21,-1,LEAVES2:13)
Block(15,21,0,LEAVES2:13)
Block(15,21,2,LEAVES2:13)
Block(15,22,-3,LEAVES2:13)
Block(15,22,-2,LOG2:13)
Block(15,22,-1,LEAVES2:13)
Block(15,22,1,LEAVES2:13)
Block(15,22,2,LEAVES2:13)
Block(15,22,3,LEAVES2:13)
Block(15,22,4,LEAVES2:13)
Block(15,22,7,LEAVES2:13)
Block(15,22,8,LEAVES2:13)
Block(15,23,-2,LEAVES2:13)
Block(15,23,2,LEAVES2:13)
Block(15,23,3,LEAVES2:13)
Block(15,23,9,LEAVES2:13)
Block(15,24,4,LEAVES2:13)
Block(15,25,-7,LEAVES2:13)
Block(15,25,-6,LEAVES2:13)
Block(15,25,-5,LEAVES2:13)
Block(15,25,7,LEAVES2:13)
Block(15,26,-6,LEAVES2:13)
Block(15,26,-5,LEAVES2:13)
Block(15,26,-4,LEAVES2:13)
Block(15,26,-2,LEAVES2:13)
Block(15,26,-1,LEAVES2:13)
Block(15,26,0,LEAVES2:13)
Block(15,26,4,LEAVES2:13)
Block(15,26,5,LEAVES2:13)
Block(15,26,6,LEAVES2:13)
Block(15,26,8,LEAVES2:13)
Block(15,27,-5,LEAVES2:13)
Block(15,27,-3,LEAVES2:13)
Block(15,27,-2,LOG2:13)
Block(15,27,-1,LEAVES2:13)
Block(15,27,0,LEAVES2:13)
Block(15,27,1,LEAVES2:13)
Block(15,27,3,LEAVES2:13)
Block(15,27,4,LEAVES2:13)
Block(15,27,5,LEAVES2:13)
Block(15,27,6,LEAVES2:13)
Block(15,28,-2,LEAVES2:13)
Block(15,28,-1,LEAVES2:13)
Block(15,28,0,LEAVES2:13)
Block(15,28,4,LEAVES2:13)
Block(15,28,5,LEAVES2:13)
Block(15,29,-1,LEAVES2:13)
Block(16,20,-1,LEAVES2:13)
Block(16,21,-3,LEAVES2:13)
Block(16,21,-2,LEAVES2:13)
Block(16,22,-4,LEAVES2:13)
Block(16,22,-3,LEAVES2:13)
Block(16,22,-2,LEAVES2:13)
Block(16,22,-1,LEAVES2:13)
Block(16,22,2,LEAVES2:13)
Block(16,23,-3,LEAVES2:13)
Block(16,23,-2,LEAVES2:13)
Block(16,23,-1,LEAVES2:13)
Block(16,24,-6,LEAVES2:13)
Block(16,24,-2,LEAVES2:13)
Block(16,25,-4,LEAVES2:13)
Block(16,25,0,LEAVES2:13)
Block(16,25,3,LEAVES2:13)
Block(16,25,5,LEAVES2:13)
Block(16,25,6,LEAVES2:13)
Block(16,26,-5,LEAVES2:13)
Block(16,26,4,LEAVES2:13)
Block(16,26,5,LEAVES2:13)
Block(16,26,6,LEAVES2:13)
Block(16,27,-3,LEAVES2:13)
Block(16,27,-2,LEAVES2:13)
Block(16,27,-1,LEAVES2:13)
Block(16,27,3,LEAVES2:13)
Block(16,27,5,LEAVES2:13)
Block(16,28,-2,LEAVES2:13)
Block(16,28,-1,LEAVES2:13)
Block(17,21,-2,LEAVES2:13)
Block(17,21,0,LEAVES2:13)
Block(17,22,-3,LEAVES2:13)
Block(17,22,-2,LEAVES2:13)
Block(17,22,-1,LEAVES2:13)
Block(17,23,-2,LEAVES2:13)
Block(17,24,6,LEAVES2:13)
Block(17,25,4,LEAVES2:13)
Block(17,26,-1,LEAVES2:13)
Block(17,26,5,LEAVES2:13)
Block(17,27,-2,LEAVES2:13)
Block(18,22,-2,LEAVES2:13)
Block(18,26,6,LEAVES2:13)


#######################################################################
# +-----------------------------------------------------------------+ #
# |                             Entities                            | #
# +-----------------------------------------------------------------+ #
#######################################################################

# Entity() spawns an entity instead of a block. The entity is spawned only once when the BO3 is spawned.
# Entities are persistent by default so they don't de-spawn when no player is near, they are only unloaded.
# Usage: Entity(x,y,z,mobName,groupSize,NameTagOrNBTFileName) or Entity(x,y,z,mobName,groupSize)
# Use /tc entities or /otg entities to get a list of entities that can be used as mobName, this includes entities added by other mods.
# NameTagOrNBTFileName can be either a nametag for the mob or an nbt file (such as mymobinfo.nbt or mymobinfo.txt).
# When using a text file you can use the same mob spawning parameters used with the /summon command to equip the
# entity and give it custom attributes etc. You can copy the DATA part of a summon command including surrounding
# curly braces to a .txt file, for instance for: "/summon Skeleton x y z {DATA}"

#######################################################################
# +-----------------------------------------------------------------+ #
# |                            BO3 checks                           | #
# +-----------------------------------------------------------------+ #
#######################################################################

# Require a condition at a certain location in order for the BO3 to be spawned.
# BlockCheck(x,y,z,BlockName[,BlockName[,...]]) - one of the blocks must be at the location
# BlockCheckNot(x,y,z,BlockName[,BlockName[,...]]) - all the blocks must not be at the location
# LightCheck(x,y,z,minLightLevel,maxLightLevel) - light must be between min and max (inclusive)

# You can use "Solid" as a BlockName for matching all solid blocks or "All" to match all blocks that aren't air.

# Examples:
BlockCheck(0,-1,0,GRASS,DIRT,DIRT:2)
#   BlockCheck(0,-1,0,Solid)       Require any solid block just below the object
#   BlockCheck(0,-1,0,WOOL)        Require any type of wool just below the object
#   BlockCheck(0,-1,0,WOOL:0)      Require white wool just below the object
#   BlockCheckNot(0,-1,0,WOOL:0)   Require that there is no white wool below the object
#   LightCheck(0,0,0,0,1)          Require almost complete darkness just below the object

