#######################################################################
# +-----------------------------------------------------------------+ #
# |                            BO3 object                           | #
# +-----------------------------------------------------------------+ #
#######################################################################

# This is the config file of a custom object.
# If you add this object correctly to your BiomeConfigs, it will spawn in the world.

# This is the creator of this BO3 object
Author: BO3 BulkEdit (by LanToaster)

# A short description of this BO3 object
Description: This Object was Created with BO3_BulkEdit

# The BO3 version, don't change this! It can be used by external applications to do a version check.
Version: 3

# The settings mode, WriteAll, WriteWithoutComments or WriteDisable. See WorldConfig.
SettingsMode: WriteDisable


#######################################################################
# +-----------------------------------------------------------------+ #
# |                          Main settings                          | #
# +-----------------------------------------------------------------+ #
#######################################################################

# This needs to be set to true to spawn the object in the Tree and Sapling resources.
Tree: true

# The frequency of the BO3 from 1 to 200. Tries this many times to spawn this BO3 when using the CustomObject(...) resource.
# Ignored by Tree(..), Sapling(..) and CustomStructure(..)
Frequency: 1

# The rarity of the BO3 from 0 to 100. Each spawn attempt has rarity% chance to succeed when using the CustomObject(...) resource.
# Ignored by Tree(..), Sapling(..) and CustomStructure(..)
Rarity: 100

# If you set this to true, the BO3 will be placed with a random rotation.
RotateRandomly: True

# The spawn height of the BO3 - randomY, highestBlock or highestSolidBlock.
SpawnHeight: highestSolidBlock

# The height limits for the BO3.
MinHeight: 0

MaxHeight: 72

# Objects can have other objects attacthed to it: branches. Branches can also
# have branches attached to it, which can also have branches, etc. This is the
# maximum branch depth for this objects.
MaxBranchDepth: 10

# When spawned with the UseWorld keyword, this BO3 should NOT spawn in the following biomes.
# If you writer.write the BO3 name directly in the BiomeConfigs, this will be ignored.
ExcludedBiomes: All


#######################################################################
# +-----------------------------------------------------------------+ #
# |                      Source block settings                      | #
# +-----------------------------------------------------------------+ #
#######################################################################

# The block(s) the BO3 should spawn in.
SourceBlocks: AIR

# The maximum percentage of the BO3 that can be outside the SourceBlock.
# The BO3 won't be placed on a location with more blocks outside the SourceBlock than this percentage.
MaxPercentageOutsideSourceBlock: 0

# What to do when a block is about to be placed outside the SourceBlock? (dontPlace, placeAnyway)
OutsideSourceBlock: dontPlace


#######################################################################
# +-----------------------------------------------------------------+ #
# |                              Blocks                             | #
# +-----------------------------------------------------------------+ #
#######################################################################

# All the blocks used in the BO3 are listed here. Possible blocks:
# Block(x,y,z,id[.data][,nbtfile.nbt)
# RandomBlock(x,y,z,id[:data][,nbtfile.nbt],chance[,id[:data][,nbtfile.nbt],chance[,...]])
# So RandomBlock(0,0,0,CHEST,chest.nbt,50,CHEST,anotherchest.nbt,100) will spawn a chest at
# the BO3 origin, and give it a 50% chance to have the contents of chest.nbt, or, if that
# fails, a 100% percent chance to have the contents of anotherchest.nbt.
Block(5,-3,-6,LOG:14)
Block(1,-3,-4,LOG:14)
Block(3,-3,-4,LOG:14)
Block(4,-3,-3,LOG:14)
Block(3,-3,-2,LOG:14)
Block(1,-3,-1,LOG:14)
Block(4,-2,-5,LOG:14)
Block(5,-2,-5,LOG:14)
Block(1,-2,-4,LOG:14)
Block(3,-2,-4,LOG:14)
Block(3,-2,-3,LOG:14)
Block(2,-2,-2,LOG:14)
Block(4,-1,-5,LOG:14)
Block(1,-1,-4,LOG:14)
Block(2,-1,-4,LOG:14)
Block(3,-1,-4,LOG:14)
Block(3,-1,-3,LOG:14)
Block(2,-1,-2,LOG:14)
Block(4,0,-5,LOG:14)
Block(1,0,-4,LOG:14)
Block(2,0,-4,LOG:14)
Block(3,0,-4,LOG:14)
Block(3,0,-3,LOG:14)
Block(2,0,-2,LOG:14)
Block(2,1,-4,LOG:14)
Block(3,1,-4,LOG:14)
Block(3,1,-3,LOG:14)
Block(2,2,-4,LOG:14)
Block(3,2,-4,LOG:14)
Block(3,2,-3,LOG:14)
Block(3,3,-4,LOG:14)
Block(3,3,-3,LOG:14)
Block(3,4,-4,LOG:14)
Block(3,4,-3,LOG:14)
Block(3,5,-4,LOG:14)
Block(3,5,-3,LOG:14)
Block(3,6,-4,LOG:14)
Block(3,7,-4,LOG:14)
Block(3,8,-4,LOG:14)
Block(4,9,-4,LOG:14)
Block(4,10,-4,LOG:14)
Block(4,11,-4,LOG:14)
Block(5,12,-5,LOG:14)
Block(11,13,-6,LEAVES:4)
Block(5,13,-5,LOG:14)
Block(6,13,-5,LOG:14)
Block(10,13,-5,LEAVES:4)
Block(11,14,-7,LEAVES:4)
Block(5,14,-5,LOG:14)
Block(7,14,-4,LOG:14)
Block(10,14,-3,LEAVES:4)
Block(13,14,-2,LEAVES:4)
Block(8,15,-7,LEAVES:4)
Block(6,15,-6,LOG:14)
Block(13,15,-5,LEAVES:4)
Block(8,15,-4,LOG:14)
Block(9,15,-4,LOG:14)
Block(10,15,-3,LEAVES:4)
Block(12,15,-3,LEAVES:4)
Block(12,15,-2,LEAVES:4)
Block(11,15,0,LEAVES:4)
Block(9,16,-7,LEAVES:4)
Block(11,16,-7,LEAVES:4)
Block(6,16,-6,LOG:14)
Block(10,16,-6,LEAVES:4)
Block(11,16,-6,LEAVES:4)
Block(9,16,-5,LEAVES:4)
Block(10,16,-5,LOG:14)
Block(11,16,-5,LEAVES:4)
Block(12,16,-5,LEAVES:4)
Block(13,16,-5,LEAVES:4)
Block(11,16,-4,LEAVES:4)
Block(10,16,-3,LOG:14)
Block(11,16,-3,LOG:14)
Block(15,16,-3,LEAVES:4)
Block(10,16,-2,LEAVES:4)
Block(12,16,0,LEAVES:4)
Block(9,17,-8,LEAVES:4)
Block(11,17,-8,LEAVES:4)
Block(7,17,-7,LOG:14)
Block(5,17,-6,LOG:14)
Block(11,17,-6,LEAVES:4)
Block(6,17,-5,LOG:14)
Block(9,17,-5,LEAVES:4)
Block(10,17,-5,LEAVES:4)
Block(12,17,-5,LEAVES:4)
Block(13,17,-5,LEAVES:4)
Block(8,17,-4,LEAVES:4)
Block(12,17,-4,LEAVES:4)
Block(10,17,-3,LEAVES:4)
Block(10,17,-2,LEAVES:4)
Block(12,17,-2,LOG:14)
Block(14,17,-2,LEAVES:4)
Block(15,17,-2,LEAVES:4)
Block(9,17,-1,LEAVES:4)
Block(10,17,-1,LEAVES:4)
Block(14,17,0,LEAVES:4)
Block(6,18,-10,LEAVES:4)
Block(8,18,-10,LEAVES:4)
Block(6,18,-8,LEAVES:4)
Block(9,18,-8,LEAVES:4)
Block(5,18,-7,LEAVES:4)
Block(7,18,-7,LOG:14)
Block(9,18,-7,LEAVES:4)
Block(12,18,-7,LEAVES:4)
Block(-4,18,-5,LEAVES:4)
Block(-3,18,-5,LEAVES:4)
Block(-1,18,-5,LEAVES:4)
Block(1,18,-5,LEAVES:4)
Block(4,18,-5,LOG:14)
Block(12,18,-5,LEAVES:4)
Block(7,18,-4,LOG:14)
Block(10,18,-4,LEAVES:4)
Block(12,18,-2,LEAVES:4)
Block(13,18,-2,LEAVES:4)
Block(10,18,-1,LEAVES:4)
Block(12,18,-1,LEAVES:4)
Block(13,18,0,LEAVES:4)
Block(6,19,-11,LEAVES:4)
Block(6,19,-10,LEAVES:4)
Block(8,19,-10,LEAVES:4)
Block(9,19,-10,LEAVES:4)
Block(11,19,-10,LEAVES:4)
Block(6,19,-9,LEAVES:4)
Block(8,19,-9,LEAVES:4)
Block(3,19,-8,LEAVES:4)
Block(6,19,-8,LOG:14)
Block(9,19,-8,LEAVES:4)
Block(11,19,-8,LEAVES:4)
Block(2,19,-7,LEAVES:4)
Block(8,19,-7,LOG:14)
Block(-3,19,-6,LEAVES:4)
Block(-1,19,-6,LEAVES:4)
Block(8,19,-6,LEAVES:4)
Block(-3,19,-5,LEAVES:4)
Block(-2,19,-5,LEAVES:4)
Block(-1,19,-5,LEAVES:4)
Block(3,19,-5,LOG:14)
Block(10,19,-5,LEAVES:4)
Block(-5,19,-4,LEAVES:4)
Block(-3,19,-4,LEAVES:4)
Block(4,19,-4,LEAVES:4)
Block(6,19,-4,LEAVES:4)
Block(7,19,-4,LOG:14)
Block(9,19,-4,LEAVES:4)
Block(-4,19,-3,LEAVES:4)
Block(14,19,-3,LEAVES:4)
Block(6,19,-2,LEAVES:4)
Block(12,19,-1,LEAVES:4)
Block(13,19,0,LEAVES:4)
Block(4,20,-10,LEAVES:4)
Block(6,20,-9,LEAVES:4)
Block(11,20,-9,LEAVES:4)
Block(1,20,-8,LEAVES:4)
Block(2,20,-8,LEAVES:4)
Block(3,20,-8,LEAVES:4)
Block(6,20,-8,LOG:14)
Block(7,20,-8,LEAVES:4)
Block(9,20,-8,LOG:14)
Block(11,20,-8,LEAVES:4)
Block(3,20,-7,LEAVES:4)
Block(5,20,-7,LEAVES:4)
Block(-5,20,-6,LEAVES:4)
Block(1,20,-6,LEAVES:4)
Block(8,20,-6,LEAVES:4)
Block(9,20,-6,LOG:14)
Block(-2,20,-5,LEAVES:4)
Block(0,20,-5,LEAVES:4)
Block(1,20,-5,LOG:14)
Block(2,20,-5,LOG:14)
Block(10,20,-5,LEAVES:4)
Block(-3,20,-4,LEAVES:4)
Block(-1,20,-4,LEAVES:4)
Block(1,20,-4,LEAVES:4)
Block(4,20,-4,LEAVES:4)
Block(6,20,-4,LEAVES:4)
Block(8,20,-4,LOG:14)
Block(10,20,-4,LEAVES:4)
Block(-3,20,-3,LEAVES:4)
Block(6,20,-3,LOG:14)
Block(-2,20,-2,LEAVES:4)
Block(2,20,-2,LEAVES:4)
Block(4,20,-2,LEAVES:4)
Block(8,20,-2,LEAVES:4)
Block(12,20,-2,LEAVES:4)
Block(13,20,-1,LEAVES:4)
Block(7,21,-11,LEAVES:4)
Block(9,21,-11,LEAVES:4)
Block(4,21,-10,LEAVES:4)
Block(7,21,-10,LEAVES:4)
Block(7,21,-9,LEAVES:4)
Block(11,21,-9,LEAVES:4)
Block(6,21,-8,LEAVES:4)
Block(8,21,-8,LEAVES:4)
Block(9,21,-8,LOG:14)
Block(10,21,-8,LEAVES:4)
Block(-4,21,-7,LEAVES:4)
Block(-1,21,-7,LEAVES:4)
Block(1,21,-7,LEAVES:4)
Block(2,21,-7,LEAVES:4)
Block(7,21,-7,LEAVES:4)
Block(-2,21,-6,LEAVES:4)
Block(0,21,-6,LEAVES:4)
Block(8,21,-6,LEAVES:4)
Block(10,21,-6,LOG:14)
Block(11,21,-6,LEAVES:4)
Block(-6,21,-5,LEAVES:4)
Block(-3,21,-5,LOG:14)
Block(0,21,-5,LEAVES:4)
Block(3,21,-5,LEAVES:4)
Block(4,21,-5,LEAVES:4)
Block(5,21,-5,LEAVES:4)
Block(13,21,-5,LEAVES:4)
Block(-6,21,-4,LEAVES:4)
Block(0,21,-4,LOG:14)
Block(2,21,-4,LEAVES:4)
Block(3,21,-4,LEAVES:4)
Block(6,21,-4,LEAVES:4)
Block(7,21,-4,LEAVES:4)
Block(10,21,-4,LEAVES:4)
Block(-3,21,-3,LEAVES:4)
Block(0,21,-3,LEAVES:4)
Block(2,21,-3,LEAVES:4)
Block(4,21,-3,LEAVES:4)
Block(-3,21,-2,LEAVES:4)
Block(-1,21,-2,LEAVES:4)
Block(0,21,-2,LEAVES:4)
Block(3,21,-2,LEAVES:4)
Block(5,21,-2,LOG:14)
Block(6,21,-1,LEAVES:4)
Block(7,21,0,LEAVES:4)
Block(6,21,1,LEAVES:4)
Block(10,22,-11,LEAVES:4)
Block(11,22,-10,LEAVES:4)
Block(5,22,-9,LEAVES:4)
Block(6,22,-9,LEAVES:4)
Block(-2,22,-8,LEAVES:4)
Block(6,22,-8,LEAVES:4)
Block(-2,22,-7,LEAVES:4)
Block(1,22,-7,LEAVES:4)
Block(6,22,-7,LEAVES:4)
Block(8,22,-7,LEAVES:4)
Block(10,22,-7,LEAVES:4)
Block(11,22,-7,LEAVES:4)
Block(-3,22,-6,LEAVES:4)
Block(-2,22,-6,LEAVES:4)
Block(-1,22,-6,LEAVES:4)
Block(3,22,-6,LEAVES:4)
Block(5,22,-6,LEAVES:4)
Block(6,22,-6,LEAVES:4)
Block(8,22,-6,LEAVES:4)
Block(9,22,-6,LEAVES:4)
Block(10,22,-6,LEAVES:4)
Block(11,22,-6,LEAVES:4)
Block(-3,22,-5,LEAVES:4)
Block(-2,22,-5,LEAVES:4)
Block(1,22,-5,LEAVES:4)
Block(2,22,-5,LEAVES:4)
Block(12,22,-5,LEAVES:4)
Block(13,22,-5,LEAVES:4)
Block(-3,22,-4,LEAVES:4)
Block(-2,22,-4,LOG:14)
Block(-1,22,-4,LOG:14)
Block(0,22,-4,LEAVES:4)
Block(3,22,-4,LEAVES:4)
Block(10,22,-4,LEAVES:4)
Block(-5,22,-3,LEAVES:4)
Block(-3,22,-3,LOG:14)
Block(-2,22,-3,LEAVES:4)
Block(3,22,-3,LEAVES:4)
Block(-3,22,-2,LEAVES:4)
Block(6,22,-2,LEAVES:4)
Block(7,22,-2,LEAVES:4)
Block(4,22,-1,LEAVES:4)
Block(7,22,-1,LEAVES:4)
Block(-4,22,0,LEAVES:4)
Block(4,22,0,LEAVES:4)
Block(5,22,0,LEAVES:4)
Block(11,23,-10,LEAVES:4)
Block(5,23,-8,LEAVES:4)
Block(7,23,-8,LEAVES:4)
Block(9,23,-8,LEAVES:4)
Block(10,23,-8,LEAVES:4)
Block(-3,23,-7,LEAVES:4)
Block(-2,23,-6,LEAVES:4)
Block(1,23,-6,LEAVES:4)
Block(3,23,-6,LEAVES:4)
Block(9,23,-6,LEAVES:4)
Block(-2,23,-5,LEAVES:4)
Block(0,23,-5,LEAVES:4)
Block(5,23,-5,LEAVES:4)
Block(3,23,-4,LEAVES:4)
Block(4,23,-4,LEAVES:4)
Block(5,23,-4,LEAVES:4)
Block(-2,23,-3,LEAVES:4)
Block(0,23,-3,LEAVES:4)
Block(7,23,-3,LEAVES:4)
Block(3,23,-2,LEAVES:4)
Block(5,23,-2,LEAVES:4)
Block(7,23,-2,LEAVES:4)
Block(-4,23,-1,LEAVES:4)
Block(4,23,-1,LEAVES:4)
Block(-4,23,0,LEAVES:4)
Block(9,24,-9,LEAVES:4)
Block(2,24,-7,LEAVES:4)
Block(4,24,-7,LEAVES:4)
Block(9,24,-7,LEAVES:4)
Block(10,24,-6,LEAVES:4)
Block(11,24,-6,LEAVES:4)
Block(-4,24,-5,LEAVES:4)
Block(1,24,-4,LEAVES:4)
Block(3,24,-4,LOG:14)
Block(5,24,-4,LEAVES:4)
Block(6,24,-4,LEAVES:4)
Block(-3,24,-3,LEAVES:4)
Block(1,24,-3,LEAVES:4)
Block(3,24,-3,LEAVES:4)
Block(6,24,-3,LEAVES:4)
Block(-5,24,-2,LEAVES:4)
Block(-2,24,-2,LEAVES:4)
Block(2,24,-2,LEAVES:4)
Block(5,25,-6,LEAVES:4)
Block(6,25,-5,LEAVES:4)
Block(-4,25,-4,LEAVES:4)
Block(-3,25,-3,LEAVES:4)
Block(3,25,-3,LEAVES:4)
Block(5,26,-5,LEAVES:4)
Block(3,26,-4,LEAVES:4)
Block(5,26,-4,LEAVES:4)
Block(1,26,-2,LEAVES:4)
Block(2,27,-5,LEAVES:4)
Block(4,27,-5,LEAVES:4)
Block(3,27,-3,LEAVES:4)

#######################################################################
# +-----------------------------------------------------------------+ #
# |                            BO3 checks                           | #
# +-----------------------------------------------------------------+ #
#######################################################################

# Require a condition at a certain location in order for the BO3 to be spawned.
# BlockCheck(x,y,z,BlockName[,BlockName[,...]]) - one of the blocks must be at the location
# BlockCheckNot(x,y,z,BlockName[,BlockName[,...]]) - all the blocks must not be at the location
# LightCheck(x,y,z,minLightLevel,maxLightLevel) - light must be between min and max (inclusive)

# You can use "Solid" as a BlockName for matching all solid blocks or "All" to match all blocks that aren't air.

# Examples:
BlockCheck(0,-1,0,GRASS,DIRT,DIRT:2,SAND)
#   BlockCheck(0,-1,0,Solid)       Require any solid block just below the object
#   BlockCheck(0,-1,0,WOOL)        Require any type of wool just below the object
#   BlockCheck(0,-1,0,WOOL:0)      Require white wool just below the object
#   BlockCheckNot(0,-1,0,WOOL:0)   Require that there is no white wool below the object
#   LightCheck(0,0,0,0,1)          Require almost complete darkness just below the object

#######################################################################
# +-----------------------------------------------------------------+ #
# |                             Branches                            | #
# +-----------------------------------------------------------------+ #
#######################################################################

# Branches are objects that will spawn when this object spawns when it is used in
# the CustomStructure resource. Branches can also have branches, making complex
# structures possible. See the wiki for more details.

# Regular Branches spawn each branch with an independent chance of spawning.
# Branch(x,y,z,branchName,rotation,chance[,anotherBranchName,rotation,chance[,...]][IndividualChance])
# branchName - name of the object to spawn.
# rotation - NORTH, SOUTH, EAST or WEST.
# IndividualChance - The chance each branch has to spawn, assumed to be 100 when left blank

# Weighted Branches spawn branches with a dependent chance of spawning.
# WeightedBranch(x,y,z,branchName,rotation,chance[,anotherBranchName,rotation,chance[,...]][MaxChanceOutOf])
# MaxChanceOutOf - The chance all branches have to spawn out of, assumed to be 100 when left blank
BlockCheck(0,-1,0,GRASS)
