#######################################################################
# +-----------------------------------------------------------------+ #
# |                            BO3 object                           | #
# +-----------------------------------------------------------------+ #
#######################################################################

# This is the config file of a custom object.
# If you add this object correctly to your BiomeConfigs, it will spawn in the world.

# This is the creator of this BO3 object
Author: BO3 BulkEdit (by LanToaster)

# A short description of this BO3 object
Description: This Object was Created with BO3_BulkEdit

# The BO3 version, don't change this! It can be used by external applications to do a version check.
Version: 3

# The settings mode, WriteAll, WriteWithoutComments or WriteDisable. See WorldConfig.
SettingsMode: WriteDisable


#######################################################################
# +-----------------------------------------------------------------+ #
# |                          Main settings                          | #
# +-----------------------------------------------------------------+ #
#######################################################################

# This needs to be set to true to spawn the object in the Tree and Sapling resources.
Tree: true

# The frequency of the BO3 from 1 to 200. Tries this many times to spawn this BO3 when using the CustomObject(...) resource.
# Ignored by Tree(..), Sapling(..) and CustomStructure(..)
Frequency: 1

# The rarity of the BO3 from 0 to 100. Each spawn attempt has rarity% chance to succeed when using the CustomObject(...) resource.
# Ignored by Tree(..), Sapling(..) and CustomStructure(..)
Rarity: 100

# If you set this to true, the BO3 will be placed with a random rotation.
RotateRandomly: True

# The spawn height of the BO3 - randomY, highestBlock or highestSolidBlock.
SpawnHeight: highestSolidBlock

# The height limits for the BO3.
MinHeight: 0

MaxHeight: 72

# Objects can have other objects attacthed to it: branches. Branches can also
# have branches attached to it, which can also have branches, etc. This is the
# maximum branch depth for this objects.
MaxBranchDepth: 10

# When spawned with the UseWorld keyword, this BO3 should NOT spawn in the following biomes.
# If you writer.write the BO3 name directly in the BiomeConfigs, this will be ignored.
ExcludedBiomes: All


#######################################################################
# +-----------------------------------------------------------------+ #
# |                      Source block settings                      | #
# +-----------------------------------------------------------------+ #
#######################################################################

# The block(s) the BO3 should spawn in.
SourceBlocks: AIR

# The maximum percentage of the BO3 that can be outside the SourceBlock.
# The BO3 won't be placed on a location with more blocks outside the SourceBlock than this percentage.
MaxPercentageOutsideSourceBlock: 0

# What to do when a block is about to be placed outside the SourceBlock? (dontPlace, placeAnyway)
OutsideSourceBlock: dontPlace


#######################################################################
# +-----------------------------------------------------------------+ #
# |                              Blocks                             | #
# +-----------------------------------------------------------------+ #
#######################################################################

# All the blocks used in the BO3 are listed here. Possible blocks:
# Block(x,y,z,id[.data][,nbtfile.nbt)
# RandomBlock(x,y,z,id[:data][,nbtfile.nbt],chance[,id[:data][,nbtfile.nbt],chance[,...]])
# So RandomBlock(0,0,0,CHEST,chest.nbt,50,CHEST,anotherchest.nbt,100) will spawn a chest at
# the BO3 origin, and give it a 50% chance to have the contents of chest.nbt, or, if that
# fails, a 100% percent chance to have the contents of anotherchest.nbt.
Block(5,-3,-6,LOG:14)
Block(5,-3,-4,LOG:14)
Block(3,-3,-2,LOG:14)
Block(2,-2,-6,LOG:14)
Block(-1,-2,-5,LOG:14)
Block(4,-2,-5,LOG:14)
Block(0,-2,-4,LOG:14)
Block(2,-2,-2,LOG:14)
Block(1,-2,-1,LOG:14)
Block(2,-1,-5,LOG:14)
Block(1,-1,-4,LOG:14)
Block(3,-1,-4,LOG:14)
Block(2,-1,-3,LOG:14)
Block(2,0,-5,LOG:14)
Block(1,0,-4,LOG:14)
Block(2,0,-4,LOG:14)
Block(3,0,-4,LOG:14)
Block(2,0,-3,LOG:14)
Block(2,1,-4,LOG:14)
Block(3,1,-4,LOG:14)
Block(2,2,-4,LOG:14)
Block(2,3,-4,LOG:14)
Block(2,4,-4,LOG:14)
Block(2,5,-4,LOG:14)
Block(2,6,-4,LOG:14)
Block(2,7,-4,LOG:14)
Block(2,8,-4,LOG:14)
Block(2,9,-4,LOG:14)
Block(3,10,-4,LOG:14)
Block(1,10,-3,LOG:14)
Block(3,11,-5,LOG:14)
Block(1,11,-3,LOG:14)
Block(3,12,-5,LOG:14)
Block(1,12,-3,LOG:14)
Block(4,13,-5,LOG:14)
Block(0,13,-2,LOG:14)
Block(-4,14,-7,LEAVES:4)
Block(4,14,-5,LOG:14)
Block(0,14,-2,LOG:14)
Block(-1,15,-8,LEAVES:4)
Block(-2,15,-7,LEAVES:4)
Block(2,15,-7,LEAVES:4)
Block(-3,15,-6,LEAVES:4)
Block(-4,15,-5,LEAVES:4)
Block(4,15,-5,LOG:14)
Block(-4,15,-4,LEAVES:4)
Block(-2,15,-4,LEAVES:4)
Block(-1,15,-3,LOG:14)
Block(0,15,-2,LOG:14)
Block(-3,16,-9,LEAVES:4)
Block(3,16,-9,LEAVES:4)
Block(-5,16,-8,LEAVES:4)
Block(-4,16,-8,LEAVES:4)
Block(-3,16,-8,LEAVES:4)
Block(2,16,-8,LEAVES:4)
Block(-2,16,-7,LEAVES:4)
Block(3,16,-7,LEAVES:4)
Block(5,16,-7,LEAVES:4)
Block(-1,16,-6,LEAVES:4)
Block(3,16,-6,LOG:14)
Block(-3,16,-5,LOG:14)
Block(5,16,-5,LOG:14)
Block(-3,16,-4,LEAVES:4)
Block(-2,16,-4,LOG:14)
Block(0,16,-2,LOG:14)
Block(-5,17,-10,LEAVES:4)
Block(-4,17,-9,LEAVES:4)
Block(-5,17,-8,LEAVES:4)
Block(-4,17,-8,LEAVES:4)
Block(-3,17,-8,LEAVES:4)
Block(-5,17,-7,LEAVES:4)
Block(-3,17,-7,LEAVES:4)
Block(-2,17,-7,LEAVES:4)
Block(1,17,-7,LEAVES:4)
Block(-6,17,-6,LEAVES:4)
Block(-3,17,-6,LOG:14)
Block(3,17,-6,LOG:14)
Block(-6,17,-5,LEAVES:4)
Block(-4,17,-5,LEAVES:4)
Block(-3,17,-5,LEAVES:4)
Block(-1,17,-5,LEAVES:4)
Block(0,17,-5,LEAVES:4)
Block(5,17,-5,LOG:14)
Block(-5,17,-4,LEAVES:4)
Block(-4,17,-4,LEAVES:4)
Block(-1,17,-2,LOG:14)
Block(-5,18,-11,LEAVES:4)
Block(-4,18,-11,LEAVES:4)
Block(-4,18,-10,LEAVES:4)
Block(2,18,-9,LEAVES:4)
Block(-3,18,-8,LEAVES:4)
Block(1,18,-8,LEAVES:4)
Block(3,18,-8,LEAVES:4)
Block(5,18,-8,LEAVES:4)
Block(-4,18,-7,LEAVES:4)
Block(-2,18,-7,LEAVES:4)
Block(2,18,-7,LEAVES:4)
Block(3,18,-7,LOG:14)
Block(-2,18,-6,LEAVES:4)
Block(0,18,-6,LEAVES:4)
Block(2,18,-5,LOG:14)
Block(5,18,-5,LOG:14)
Block(4,18,-4,LEAVES:4)
Block(-2,18,-3,LOG:14)
Block(-1,18,-2,LOG:14)
Block(2,19,-10,LEAVES:4)
Block(-6,19,-9,LEAVES:4)
Block(-1,19,-9,LEAVES:4)
Block(-6,19,-8,LEAVES:4)
Block(-4,19,-8,LEAVES:4)
Block(-2,19,-8,LEAVES:4)
Block(-7,19,-7,LEAVES:4)
Block(-5,19,-7,LEAVES:4)
Block(-3,19,-7,LEAVES:4)
Block(1,19,-7,LEAVES:4)
Block(2,19,-7,LEAVES:4)
Block(3,19,-7,LEAVES:4)
Block(-5,19,-6,LEAVES:4)
Block(-3,19,-6,LEAVES:4)
Block(-2,19,-6,LEAVES:4)
Block(-5,19,-5,LEAVES:4)
Block(-4,19,-5,LEAVES:4)
Block(-3,19,-5,LEAVES:4)
Block(-2,19,-5,LEAVES:4)
Block(5,19,-5,LOG:14)
Block(-4,19,-4,LOG:14)
Block(-3,19,-4,LOG:14)
Block(-1,19,-2,LOG:14)
Block(-3,20,-11,LEAVES:4)
Block(-2,20,-10,LEAVES:4)
Block(4,20,-9,LEAVES:4)
Block(-7,20,-8,LEAVES:4)
Block(-5,20,-8,LEAVES:4)
Block(-4,20,-8,LEAVES:4)
Block(-3,20,-8,LEAVES:4)
Block(-2,20,-8,LEAVES:4)
Block(1,20,-8,LEAVES:4)
Block(5,20,-8,LEAVES:4)
Block(-6,20,-7,LEAVES:4)
Block(-3,20,-7,LEAVES:4)
Block(4,20,-7,LEAVES:4)
Block(-6,20,-6,LEAVES:4)
Block(-5,20,-6,LEAVES:4)
Block(-5,20,-5,LOG:14)
Block(-2,20,-5,LEAVES:4)
Block(6,20,-5,LOG:14)
Block(-7,20,-4,LEAVES:4)
Block(-6,20,-4,LEAVES:4)
Block(-2,20,-4,LEAVES:4)
Block(-6,20,-3,LEAVES:4)
Block(-4,20,-3,LEAVES:4)
Block(-1,20,-2,LOG:14)
Block(-4,21,-10,LEAVES:4)
Block(-5,21,-9,LEAVES:4)
Block(-3,21,-9,LEAVES:4)
Block(-2,21,-9,LEAVES:4)
Block(2,21,-7,LEAVES:4)
Block(-2,21,-6,LEAVES:4)
Block(7,21,-6,LOG:14)
Block(8,21,-6,LOG:14)
Block(-8,21,-5,LEAVES:4)
Block(-5,21,-5,LEAVES:4)
Block(-4,21,-5,LEAVES:4)
Block(-6,21,-4,LEAVES:4)
Block(-2,21,-4,LEAVES:4)
Block(6,21,-4,LOG:14)
Block(-5,21,-3,LEAVES:4)
Block(-2,21,-3,LOG:14)
Block(-4,21,-2,LEAVES:4)
Block(-1,21,-1,LOG:14)
Block(-5,22,-7,LEAVES:4)
Block(9,22,-7,LOG:14)
Block(-3,22,-5,LEAVES:4)
Block(-3,22,-4,LEAVES:4)
Block(1,22,-4,LEAVES:4)
Block(6,22,-4,LOG:14)
Block(-5,22,-3,LEAVES:4)
Block(-2,22,-3,LOG:14)
Block(0,22,-3,LEAVES:4)
Block(-1,22,0,LEAVES:4)
Block(0,22,0,LOG:14)
Block(-1,22,2,LEAVES:4)
Block(10,23,-9,LEAVES:4)
Block(8,23,-8,LEAVES:4)
Block(10,23,-8,LOG:14)
Block(11,23,-8,LEAVES:4)
Block(-3,23,-7,LEAVES:4)
Block(-6,23,-6,LEAVES:4)
Block(-4,23,-6,LEAVES:4)
Block(-3,23,-6,LEAVES:4)
Block(0,23,-6,LEAVES:4)
Block(8,23,-6,LEAVES:4)
Block(10,23,-6,LEAVES:4)
Block(1,23,-5,LEAVES:4)
Block(-4,23,-4,LEAVES:4)
Block(-3,23,-4,LOG:14)
Block(-2,23,-4,LEAVES:4)
Block(-2,23,-3,LEAVES:4)
Block(-1,23,-3,LOG:14)
Block(6,23,-3,LOG:14)
Block(-4,23,-2,LEAVES:4)
Block(0,23,-2,LEAVES:4)
Block(1,23,-2,LEAVES:4)
Block(6,23,-2,LEAVES:4)
Block(5,23,-1,LEAVES:4)
Block(0,23,0,LOG:14)
Block(7,23,0,LEAVES:4)
Block(7,24,-9,LEAVES:4)
Block(9,24,-9,LEAVES:4)
Block(10,24,-9,LEAVES:4)
Block(10,24,-8,LOG:14)
Block(11,24,-8,LEAVES:4)
Block(-3,24,-7,LEAVES:4)
Block(-1,24,-7,LEAVES:4)
Block(9,24,-7,LEAVES:4)
Block(10,24,-7,LEAVES:4)
Block(12,24,-7,LEAVES:4)
Block(-4,24,-6,LEAVES:4)
Block(-3,24,-6,LEAVES:4)
Block(7,24,-6,LEAVES:4)
Block(-2,24,-5,LEAVES:4)
Block(2,24,-5,LEAVES:4)
Block(8,24,-5,LEAVES:4)
Block(-6,24,-4,LEAVES:4)
Block(-5,24,-4,LEAVES:4)
Block(-3,24,-4,LOG:14)
Block(-2,24,-4,LEAVES:4)
Block(0,24,-4,LOG:14)
Block(2,24,-4,LEAVES:4)
Block(9,24,-4,LEAVES:4)
Block(-4,24,-3,LEAVES:4)
Block(-3,24,-3,LEAVES:4)
Block(0,24,-3,LEAVES:4)
Block(6,24,-3,LOG:14)
Block(-5,24,-2,LEAVES:4)
Block(3,24,-2,LEAVES:4)
Block(5,24,-2,LOG:14)
Block(-1,24,-1,LEAVES:4)
Block(2,24,-1,LEAVES:4)
Block(4,24,-1,LEAVES:4)
Block(9,24,0,LEAVES:4)
Block(-3,24,1,LEAVES:4)
Block(-1,24,1,LOG:14)
Block(1,24,1,LOG:14)
Block(2,24,1,LEAVES:4)
Block(-2,24,4,LEAVES:4)
Block(11,25,-11,LEAVES:4)
Block(9,25,-10,LEAVES:4)
Block(8,25,-9,LEAVES:4)
Block(11,25,-9,LEAVES:4)
Block(13,25,-9,LEAVES:4)
Block(14,25,-9,LEAVES:4)
Block(8,25,-8,LEAVES:4)
Block(11,25,-8,LOG:14)
Block(0,25,-7,LEAVES:4)
Block(1,25,-7,LEAVES:4)
Block(6,25,-7,LEAVES:4)
Block(8,25,-7,LEAVES:4)
Block(9,25,-7,LOG:14)
Block(12,25,-7,LEAVES:4)
Block(-1,25,-6,LEAVES:4)
Block(1,25,-6,LEAVES:4)
Block(9,25,-6,LEAVES:4)
Block(-2,25,-5,LEAVES:4)
Block(2,25,-5,LEAVES:4)
Block(8,25,-5,LEAVES:4)
Block(9,25,-5,LEAVES:4)
Block(10,25,-5,LEAVES:4)
Block(-6,25,-4,LEAVES:4)
Block(-3,25,-4,LEAVES:4)
Block(-1,25,-4,LEAVES:4)
Block(0,25,-4,LOG:14)
Block(7,25,-4,LEAVES:4)
Block(9,25,-4,LEAVES:4)
Block(-3,25,-3,LEAVES:4)
Block(-2,25,-3,LEAVES:4)
Block(1,25,-3,LEAVES:4)
Block(6,25,-3,LEAVES:4)
Block(0,25,-2,LEAVES:4)
Block(2,25,-2,LEAVES:4)
Block(7,25,-2,LOG:14)
Block(9,25,-2,LEAVES:4)
Block(10,25,-2,LEAVES:4)
Block(0,25,-1,LEAVES:4)
Block(1,25,-1,LEAVES:4)
Block(4,25,-1,LOG:14)
Block(5,25,-1,LEAVES:4)
Block(7,25,-1,LEAVES:4)
Block(8,25,-1,LEAVES:4)
Block(2,25,0,LEAVES:4)
Block(9,25,0,LEAVES:4)
Block(-2,25,1,LEAVES:4)
Block(-1,25,1,LOG:14)
Block(1,25,1,LEAVES:4)
Block(-4,25,2,LEAVES:4)
Block(-1,25,4,LEAVES:4)
Block(11,26,-11,LEAVES:4)
Block(10,26,-10,LEAVES:4)
Block(14,26,-10,LEAVES:4)
Block(11,26,-9,LOG:14)
Block(12,26,-9,LEAVES:4)
Block(13,26,-9,LEAVES:4)
Block(11,26,-8,LEAVES:4)
Block(0,26,-7,LEAVES:4)
Block(1,26,-7,LEAVES:4)
Block(6,26,-7,LEAVES:4)
Block(7,26,-7,LEAVES:4)
Block(8,26,-7,LEAVES:4)
Block(9,26,-7,LOG:14)
Block(-1,26,-6,LEAVES:4)
Block(0,26,-6,LEAVES:4)
Block(9,26,-6,LEAVES:4)
Block(12,26,-6,LEAVES:4)
Block(0,26,-5,LEAVES:4)
Block(-3,26,-4,LEAVES:4)
Block(1,26,-4,LEAVES:4)
Block(3,26,-4,LEAVES:4)
Block(5,26,-4,LEAVES:4)
Block(-5,26,-3,LEAVES:4)
Block(-3,26,-3,LEAVES:4)
Block(-2,26,-3,LEAVES:4)
Block(1,26,-3,LEAVES:4)
Block(3,26,-3,LEAVES:4)
Block(4,26,-3,LEAVES:4)
Block(6,26,-3,LEAVES:4)
Block(-3,26,-2,LEAVES:4)
Block(-1,26,-2,LEAVES:4)
Block(0,26,-2,LEAVES:4)
Block(2,26,-2,LEAVES:4)
Block(4,26,-2,LEAVES:4)
Block(5,26,-2,LEAVES:4)
Block(9,26,-2,LEAVES:4)
Block(-1,26,-1,LEAVES:4)
Block(4,26,-1,LOG:14)
Block(1,26,0,LEAVES:4)
Block(4,26,0,LEAVES:4)
Block(6,26,0,LEAVES:4)
Block(7,26,0,LEAVES:4)
Block(-1,26,1,LEAVES:4)
Block(2,26,1,LEAVES:4)
Block(1,26,2,LEAVES:4)
Block(-1,26,4,LEAVES:4)
Block(11,27,-11,LEAVES:4)
Block(8,27,-10,LEAVES:4)
Block(9,27,-10,LEAVES:4)
Block(11,27,-10,LEAVES:4)
Block(2,27,-5,LEAVES:4)
Block(8,27,-5,LEAVES:4)
Block(-3,27,-4,LEAVES:4)
Block(-1,27,-4,LEAVES:4)
Block(0,27,-4,LEAVES:4)
Block(1,27,-3,LEAVES:4)
Block(5,27,-3,LEAVES:4)
Block(7,27,-3,LEAVES:4)
Block(0,27,-2,LEAVES:4)
Block(7,27,-2,LEAVES:4)
Block(9,27,-2,LEAVES:4)
Block(1,27,-1,LEAVES:4)
Block(4,27,-1,LEAVES:4)
Block(7,27,-1,LEAVES:4)
Block(9,27,-1,LEAVES:4)
Block(5,27,0,LEAVES:4)
Block(-2,27,1,LEAVES:4)
Block(-1,27,1,LEAVES:4)
Block(1,27,1,LEAVES:4)
Block(4,27,1,LEAVES:4)
Block(-3,27,2,LEAVES:4)
Block(0,27,3,LEAVES:4)
Block(11,28,-9,LEAVES:4)
Block(9,28,-8,LEAVES:4)
Block(10,28,-8,LEAVES:4)
Block(13,28,-8,LEAVES:4)
Block(9,28,-7,LEAVES:4)
Block(9,28,-5,LEAVES:4)
Block(1,28,-4,LEAVES:4)
Block(-1,28,-3,LEAVES:4)
Block(4,28,-3,LEAVES:4)
Block(6,28,-2,LEAVES:4)
Block(-1,28,1,LEAVES:4)
Block(0,28,1,LEAVES:4)
Block(5,28,1,LEAVES:4)
Block(-2,28,2,LEAVES:4)
Block(8,29,-8,LEAVES:4)
Block(9,29,-6,LEAVES:4)
Block(10,29,-6,LEAVES:4)
Block(4,29,-1,LEAVES:4)
Block(5,29,-1,LEAVES:4)

#######################################################################
# +-----------------------------------------------------------------+ #
# |                            BO3 checks                           | #
# +-----------------------------------------------------------------+ #
#######################################################################

# Require a condition at a certain location in order for the BO3 to be spawned.
# BlockCheck(x,y,z,BlockName[,BlockName[,...]]) - one of the blocks must be at the location
# BlockCheckNot(x,y,z,BlockName[,BlockName[,...]]) - all the blocks must not be at the location
# LightCheck(x,y,z,minLightLevel,maxLightLevel) - light must be between min and max (inclusive)

# You can use "Solid" as a BlockName for matching all solid blocks or "All" to match all blocks that aren't air.

# Examples:
BlockCheck(0,-1,0,GRASS,DIRT,DIRT:2,SAND)
#   BlockCheck(0,-1,0,Solid)       Require any solid block just below the object
#   BlockCheck(0,-1,0,WOOL)        Require any type of wool just below the object
#   BlockCheck(0,-1,0,WOOL:0)      Require white wool just below the object
#   BlockCheckNot(0,-1,0,WOOL:0)   Require that there is no white wool below the object
#   LightCheck(0,0,0,0,1)          Require almost complete darkness just below the object

#######################################################################
# +-----------------------------------------------------------------+ #
# |                             Branches                            | #
# +-----------------------------------------------------------------+ #
#######################################################################

# Branches are objects that will spawn when this object spawns when it is used in
# the CustomStructure resource. Branches can also have branches, making complex
# structures possible. See the wiki for more details.

# Regular Branches spawn each branch with an independent chance of spawning.
# Branch(x,y,z,branchName,rotation,chance[,anotherBranchName,rotation,chance[,...]][IndividualChance])
# branchName - name of the object to spawn.
# rotation - NORTH, SOUTH, EAST or WEST.
# IndividualChance - The chance each branch has to spawn, assumed to be 100 when left blank

# Weighted Branches spawn branches with a dependent chance of spawning.
# WeightedBranch(x,y,z,branchName,rotation,chance[,anotherBranchName,rotation,chance[,...]][MaxChanceOutOf])
# MaxChanceOutOf - The chance all branches have to spawn out of, assumed to be 100 when left blank
BlockCheck(0,-1,0,GRASS)
