#######################################################################
# +-----------------------------------------------------------------+ #
# |                            BO3 object                           | #
# +-----------------------------------------------------------------+ #
#######################################################################

# This is the config file of a custom object.
# If you add this object correctly to your BiomeConfigs, it will spawn in the world.

# This is the creator of this BO3 object
Author: BO3 BulkEdit (by LanToaster)

# A short description of this BO3 object
Description: This Object was Created with BO3_BulkEdit

# The BO3 version, don't change this! It can be used by external applications to do a version check.
Version: 3

# The settings mode, WriteAll, WriteWithoutComments or WriteDisable. See WorldConfig.
SettingsMode: WriteDisable


#######################################################################
# +-----------------------------------------------------------------+ #
# |                          Main settings                          | #
# +-----------------------------------------------------------------+ #
#######################################################################

# This needs to be set to true to spawn the object in the Tree and Sapling resources.
Tree: true

# The frequency of the BO3 from 1 to 200. Tries this many times to spawn this BO3 when using the CustomObject(...) resource.
# Ignored by Tree(..), Sapling(..) and CustomStructure(..)
Frequency: 200

# The rarity of the BO3 from 0 to 100. Each spawn attempt has rarity% chance to succeed when using the CustomObject(...) resource.
# Ignored by Tree(..), Sapling(..) and CustomStructure(..)
Rarity: 10

# If you set this to true, the BO3 will be placed with a random rotation.
RotateRandomly: True

# The spawn height of the BO3 - randomY, highestBlock or highestSolidBlock.
SpawnHeight: highestSolidBlock

# The height limits for the BO3.
MinHeight: 0

MaxHeight: 200

# Objects can have other objects attacthed to it: branches. Branches can also
# have branches attached to it, which can also have branches, etc. This is the
# maximum branch depth for this objects.
MaxBranchDepth: 10

# When spawned with the UseWorld keyword, this BO3 should NOT spawn in the following biomes.
# If you writer.write the BO3 name directly in the BiomeConfigs, this will be ignored.
ExcludedBiomes: All


#######################################################################
# +-----------------------------------------------------------------+ #
# |                      Source block settings                      | #
# +-----------------------------------------------------------------+ #
#######################################################################

# The block(s) the BO3 should spawn in.
SourceBlocks: AIR

# The maximum percentage of the BO3 that can be outside the SourceBlock.
# The BO3 won't be placed on a location with more blocks outside the SourceBlock than this percentage.
MaxPercentageOutsideSourceBlock: 0

# What to do when a block is about to be placed outside the SourceBlock? (dontPlace, placeAnyway)
OutsideSourceBlock: dontPlace


#######################################################################
# +-----------------------------------------------------------------+ #
# |                              Blocks                             | #
# +-----------------------------------------------------------------+ #
#######################################################################

# All the blocks used in the BO3 are listed here. Possible blocks:
# Block(x,y,z,id[.data][,nbtfile.nbt)
# RandomBlock(x,y,z,id[:data][,nbtfile.nbt],chance[,id[:data][,nbtfile.nbt],chance[,...]])
# So RandomBlock(0,0,0,CHEST,chest.nbt,50,CHEST,anotherchest.nbt,100) will spawn a chest at
# the BO3 origin, and give it a 50% chance to have the contents of chest.nbt, or, if that
# fails, a 100% percent chance to have the contents of anotherchest.nbt.

Block(-3,0,2,LOG:14)
Block(-2,0,2,LOG:14)
Block(-1,0,2,LOG:14)
Block(-3,0,3,LOG:14)
Block(-2,0,3,LOG:14)
Block(-1,0,3,LOG:14)
Block(-3,0,4,LOG:14)
Block(-2,0,4,LOG:14)
Block(-1,0,4,LOG:14)
Block(-3,1,2,LOG:14)
Block(-2,1,2,LOG:14)
Block(-1,1,2,LOG:14)
Block(-3,1,3,LOG:14)
Block(-2,1,3,LOG:14)
Block(-1,1,3,LOG:14)
Block(-3,1,4,LOG:14)
Block(-2,1,4,LOG:14)
Block(-1,1,4,LOG:14)
Block(-2,2,2,LOG:14)
Block(-1,2,2,LOG:14)
Block(-3,2,3,LOG:14)
Block(-2,2,3,LOG:14)
Block(-1,2,3,LOG:14)
Block(-3,2,4,LOG:14)
Block(-2,2,4,LOG:14)
Block(-1,2,4,LOG:14)
Block(-2,3,2,LOG:14)
Block(-1,3,2,LOG:14)
Block(-3,3,3,LOG:14)
Block(-2,3,3,LOG:14)
Block(-1,3,3,LOG:14)
Block(-3,3,4,LOG:14)
Block(-2,3,4,LOG:14)
Block(-1,3,4,LOG:14)
Block(-2,4,2,LOG:14)
Block(-1,4,2,LOG:14)
Block(-3,4,3,LOG:14)
Block(-2,4,3,LOG:14)
Block(-1,4,3,LOG:14)
Block(-3,4,4,LOG:14)
Block(-2,4,4,LOG:14)
Block(-1,4,4,LOG:14)
Block(-2,5,2,LOG:14)
Block(-3,5,3,LOG:14)
Block(-2,5,3,LOG:14)
Block(-1,5,3,LOG:14)
Block(-3,5,4,LOG:14)
Block(-2,5,4,LOG:14)
Block(-1,5,4,LOG:14)
Block(-3,6,2,LOG:14)
Block(-2,6,2,LOG:14)
Block(-3,6,3,LOG:14)
Block(-2,6,3,LOG:14)
Block(-1,6,3,LOG:14)
Block(-3,6,4,LOG:14)
Block(-2,6,4,LOG:14)
Block(-1,6,4,LOG:14)
Block(-3,7,2,LOG:14)
Block(-2,7,2,LOG:14)
Block(-3,7,3,LOG:14)
Block(-2,7,3,LOG:14)
Block(-1,7,3,LOG:14)
Block(-3,7,4,LOG:14)
Block(-2,7,4,LOG:14)
Block(-3,8,2,LOG:14)
Block(-2,8,2,LOG:14)
Block(-3,8,3,LOG:14)
Block(-2,8,3,LOG:14)
Block(-1,8,3,LOG:14)
Block(-2,8,4,LOG:14)
Block(-3,9,2,LOG:14)
Block(-2,9,2,LOG:14)
Block(-3,9,3,LOG:14)
Block(-2,9,3,LOG:14)
Block(-1,9,3,LOG:14)
Block(-3,9,4,LOG:14)
Block(-2,9,4,LOG:14)
Block(-3,10,2,LOG:14)
Block(-2,10,2,LOG:14)
Block(-3,10,3,LOG:14)
Block(-2,10,3,LOG:14)
Block(-1,10,3,LOG:14)
Block(-3,10,4,LOG:14)
Block(-2,10,4,LOG:14)
Block(-3,11,2,LOG:14)
Block(-2,11,2,LOG:14)
Block(-3,11,3,LOG:14)
Block(-2,11,3,LOG:14)
Block(-1,11,3,LOG:14)
Block(-2,11,4,LOG:14)
Block(-1,11,4,LOG:14)
Block(-3,12,2,LOG:14)
Block(-2,12,2,LOG:14)
Block(-3,12,3,LOG:14)
Block(-2,12,3,LOG:14)
Block(-1,12,3,LOG:14)
Block(-2,12,4,LOG:14)
Block(-1,12,4,LOG:14)
Block(-2,13,2,LOG:14)
Block(-1,13,2,LOG:14)
Block(-3,13,3,LOG:14)
Block(-2,13,3,LOG:14)
Block(-1,13,3,LOG:14)
Block(-2,13,4,LOG:14)
Block(-1,13,4,LOG:14)
Block(-2,14,2,LOG:14)
Block(-1,14,2,LOG:14)
Block(-3,14,3,LOG:14)
Block(-2,14,3,LOG:14)
Block(-1,14,3,LOG:14)
Block(-2,14,4,LOG:14)
Block(-1,14,4,LOG:14)
Block(-2,15,2,LOG:14)
Block(-1,15,2,LOG:14)
Block(-3,15,3,LOG:14)
Block(-2,15,3,LOG:14)
Block(-1,15,3,LOG:14)
Block(-2,15,4,LOG:14)
Block(-1,15,4,LOG:14)
Block(-2,16,2,LOG:14)
Block(-1,16,2,LOG:14)
Block(-3,16,3,LOG:14)
Block(-2,16,3,LOG:14)
Block(-1,16,3,LOG:14)
Block(-2,16,4,LOG:14)
Block(-1,16,4,LOG:14)
Block(-2,17,2,LOG:14)
Block(-3,17,3,LOG:14)
Block(-2,17,3,LOG:14)
Block(-1,17,3,LOG:14)
Block(-2,17,4,LOG:14)
Block(-2,18,2,LOG:14)
Block(-3,18,3,LOG:14)
Block(-2,18,3,LOG:14)
Block(-1,18,3,LOG:14)
Block(-2,18,4,LOG:14)
Block(-2,19,2,LOG:14)
Block(-3,19,3,LOG:14)
Block(-2,19,3,LOG:14)
Block(-1,19,3,LOG:14)
Block(-2,19,4,LOG:14)
Block(-2,20,2,LOG:14)
Block(-3,20,3,LOG:14)
Block(-2,20,3,LOG:14)
Block(-1,20,3,LOG:14)
Block(-2,20,4,LOG:14)
Block(-3,21,2,LOG:14)
Block(-2,21,2,LOG:14)
Block(-3,21,3,LOG:14)
Block(-2,21,3,LOG:14)
Block(-1,21,3,LOG:14)
Block(-3,21,4,LOG:14)
Block(-2,21,4,LOG:14)
Block(-3,22,2,LOG:14)
Block(-2,22,2,LOG:14)
Block(-3,22,3,LOG:14)
Block(-2,22,3,LOG:14)
Block(-1,22,3,LOG:14)
Block(-2,22,4,LOG:14)
Block(-3,23,2,LOG:14)
Block(-2,23,2,LOG:14)
Block(-3,23,3,LOG:14)
Block(-2,23,3,LOG:14)
Block(-1,23,3,LOG:14)
Block(-2,23,4,LOG:14)
Block(-3,24,2,LOG:14)
Block(-2,24,2,LOG:14)
Block(-3,24,3,LOG:14)
Block(-2,24,3,LOG:14)
Block(-1,24,3,LOG:14)
Block(-2,24,4,LOG:14)
Block(-2,25,1,LOG:14)
Block(-3,25,2,LOG:14)
Block(-2,25,2,LOG:14)
Block(-1,25,2,LOG:14)
Block(-4,25,3,LOG:14)
Block(-3,25,3,LOG:14)
Block(-2,25,3,LOG:14)
Block(-1,25,3,LOG:14)
Block(0,25,3,LOG:14)
Block(-3,25,4,LOG:14)
Block(-2,25,4,LOG:14)
Block(-3,25,7,LOG:14)
Block(-3,25,8,LOG:14)
Block(-3,25,9,LOG:14)
Block(-1,26,-1,LOG:14)
Block(-2,26,0,LOG:14)
Block(-1,26,0,LOG:14)
Block(-2,26,1,LOG:14)
Block(-5,26,2,LOG:14)
Block(-4,26,2,LOG:14)
Block(-3,26,2,LOG:14)
Block(-2,26,2,LOG:14)
Block(-1,26,2,LOG:14)
Block(0,26,2,LOG:14)
Block(1,26,2,LOG:14)
Block(2,26,2,LOG:14)
Block(-8,26,3,LOG:14)
Block(-6,26,3,LOG:14)
Block(-5,26,3,LOG:14)
Block(-4,26,3,LOG:14)
Block(-3,26,3,LOG:14)
Block(-2,26,3,LOG:14)
Block(-1,26,3,LOG:14)
Block(0,26,3,LOG:14)
Block(1,26,3,LOG:14)
Block(-3,26,4,LOG:14)
Block(-2,26,4,LOG:14)
Block(-3,26,5,LOG:14)
Block(-3,26,6,LOG:14)
Block(-4,26,7,LEAVES:13)
Block(-3,26,7,LEAVES:13)
Block(-6,26,8,LEAVES:13)
Block(-4,26,9,LOG:14)
Block(-3,26,9,LEAVES:13)
Block(-2,26,9,LEAVES:13)
Block(-6,26,10,LEAVES:13)
Block(-5,26,10,LEAVES:13)
Block(-3,26,10,LEAVES:13)
Block(-2,26,10,LOG:14)
Block(-1,26,10,LEAVES:13)
Block(0,26,10,LEAVES:13)
Block(-3,26,11,LEAVES:13)
Block(-1,26,11,LEAVES:13)
Block(-2,26,12,LEAVES:13)
Block(0,27,-4,LEAVES:13)
Block(1,27,-4,LEAVES:13)
Block(-2,27,-3,LEAVES:13)
Block(-1,27,-2,LEAVES:13)
Block(0,27,-2,LOG:14)
Block(0,27,-1,LEAVES:13)
Block(3,27,0,LEAVES:13)
Block(-10,27,2,LEAVES:13)
Block(3,27,2,LOG:14)
Block(5,27,2,LEAVES:13)
Block(-9,27,3,LEAVES:13)
Block(-7,27,3,LOG:14)
Block(-6,27,3,LOG:14)
Block(-2,27,3,LOG:14)
Block(3,27,3,LEAVES:13)
Block(4,27,3,LEAVES:13)
Block(-10,27,4,LEAVES:13)
Block(-9,27,4,LOG:14)
Block(-8,27,4,LEAVES:13)
Block(-1,27,4,LOG:14)
Block(-8,27,5,LEAVES:13)
Block(-3,27,8,LEAVES:13)
Block(-5,27,9,LEAVES:13)
Block(-2,27,9,LEAVES:13)
Block(-3,27,10,LEAVES:13)
Block(-4,27,11,LEAVES:13)
Block(-3,27,11,LEAVES:13)
Block(0,28,-4,LEAVES:13)
Block(0,28,-3,LEAVES:13)
Block(-2,28,-2,LEAVES:13)
Block(-1,28,-2,LEAVES:13)
Block(1,28,-2,LEAVES:13)
Block(-2,28,-1,LEAVES:13)
Block(1,28,-1,LEAVES:13)
Block(2,28,-1,LEAVES:13)
Block(1,28,0,LEAVES:13)
Block(5,28,0,LEAVES:13)
Block(-9,28,1,LEAVES:13)
Block(-6,28,1,LEAVES:13)
Block(-5,28,1,LEAVES:13)
Block(-7,28,2,LOG:14)
Block(-5,28,2,LEAVES:13)
Block(3,28,2,LEAVES:13)
Block(-6,28,3,LEAVES:13)
Block(-7,28,4,LEAVES:13)
Block(-1,28,4,LOG:14)
Block(0,28,4,LOG:14)
Block(-3,28,5,LOG:14)
Block(-2,28,5,LOG:14)
Block(-8,29,0,LEAVES:13)
Block(-7,29,0,LEAVES:13)
Block(0,29,1,LEAVES:13)
Block(0,29,2,LEAVES:13)
Block(-9,29,3,LEAVES:13)
Block(-7,29,3,LEAVES:13)
Block(-1,29,3,LOG:14)
Block(0,29,3,LEAVES:13)
Block(1,29,3,LEAVES:13)
Block(2,29,3,LEAVES:13)
Block(-7,29,4,LEAVES:13)
Block(-4,29,4,LEAVES:13)
Block(-3,29,4,LEAVES:13)
Block(-2,29,4,LEAVES:13)
Block(0,29,4,LEAVES:13)
Block(1,29,4,LEAVES:13)
Block(2,29,4,LEAVES:13)
Block(-6,29,5,LEAVES:13)
Block(-5,29,5,LEAVES:13)
Block(-4,29,5,LEAVES:13)
Block(1,29,5,LOG:14)
Block(-4,29,6,LOG:14)
Block(-2,29,6,LEAVES:13)
Block(1,29,6,LEAVES:13)
Block(-6,29,7,LEAVES:13)
Block(-5,29,7,LEAVES:13)
Block(-2,29,7,LEAVES:13)
Block(-5,29,8,LEAVES:13)
Block(1,30,1,LEAVES:13)
Block(0,30,2,LEAVES:13)
Block(1,30,2,LEAVES:13)
Block(2,30,2,LEAVES:13)
Block(-5,30,3,LEAVES:13)
Block(-4,30,3,LEAVES:13)
Block(-3,30,3,LEAVES:13)
Block(1,30,3,LEAVES:13)
Block(2,30,3,LEAVES:13)
Block(-6,30,4,LEAVES:13)
Block(1,30,4,LEAVES:13)
Block(2,30,4,LEAVES:13)
Block(-5,30,5,LEAVES:13)
Block(-1,30,5,LEAVES:13)
Block(1,30,5,LEAVES:13)
Block(-1,30,6,LEAVES:13)

#######################################################################
# +-----------------------------------------------------------------+ #
# |                            BO3 checks                           | #
# +-----------------------------------------------------------------+ #
#######################################################################

# Require a condition at a certain location in order for the BO3 to be spawned.
# BlockCheck(x,y,z,BlockName[,BlockName[,...]]) - one of the blocks must be at the location
# BlockCheckNot(x,y,z,BlockName[,BlockName[,...]]) - all the blocks must not be at the location
# LightCheck(x,y,z,minLightLevel,maxLightLevel) - light must be between min and max (inclusive)

# You can use "Solid" as a BlockName for matching all solid blocks or "All" to match all blocks that aren't air.

# Examples:
BlockCheck(0,-1,0,GRASS,DIRT,DIRT:2,SAND)
#   BlockCheck(0,-1,0,Solid)       Require any solid block just below the object
#   BlockCheck(0,-1,0,WOOL)        Require any type of wool just below the object
#   BlockCheck(0,-1,0,WOOL:0)      Require white wool just below the object
#   BlockCheckNot(0,-1,0,WOOL:0)   Require that there is no white wool below the object
#   LightCheck(0,0,0,0,1)          Require almost complete darkness just below the object

#######################################################################
# +-----------------------------------------------------------------+ #
# |                             Branches                            | #
# +-----------------------------------------------------------------+ #
#######################################################################

# Branches are objects that will spawn when this object spawns when it is used in
# the CustomStructure resource. Branches can also have branches, making complex
# structures possible. See the wiki for more details.

# Regular Branches spawn each branch with an independent chance of spawning.
# Branch(x,y,z,branchName,rotation,chance[,anotherBranchName,rotation,chance[,...]][IndividualChance])
# branchName - name of the object to spawn.
# rotation - NORTH, SOUTH, EAST or WEST.
# IndividualChance - The chance each branch has to spawn, assumed to be 100 when left blank

# Weighted Branches spawn branches with a dependent chance of spawning.
# WeightedBranch(x,y,z,branchName,rotation,chance[,anotherBranchName,rotation,chance[,...]][MaxChanceOutOf])
# MaxChanceOutOf - The chance all branches have to spawn out of, assumed to be 100 when left blank

