#######################################################################
# +-----------------------------------------------------------------+ #
# |                            BO3 object                           | #
# +-----------------------------------------------------------------+ #
#######################################################################

# This is the config file of a custom object.
# If you add this object correctly to your BiomeConfigs, it will spawn in the world.

# This is the creator of this BO3 object
Author: BO3 BulkEdit (by LanToaster)

# A short description of this BO3 object
Description: This Object was Created with BO3_BulkEdit

# The BO3 version, don't change this! It can be used by external applications to do a version check.
Version: 3

# The settings mode, WriteAll, WriteWithoutComments or WriteDisable. See WorldConfig.
SettingsMode: WriteDisable


#######################################################################
# +-----------------------------------------------------------------+ #
# |                          Main settings                          | #
# +-----------------------------------------------------------------+ #
#######################################################################

# This needs to be set to true to spawn the object in the Tree and Sapling resources.
Tree: true

# The frequency of the BO3 from 1 to 200. Tries this many times to spawn this BO3 when using the CustomObject(...) resource.
# Ignored by Tree(..), Sapling(..) and CustomStructure(..)
Frequency: 1

# The rarity of the BO3 from 0 to 100. Each spawn attempt has rarity% chance to succeed when using the CustomObject(...) resource.
# Ignored by Tree(..), Sapling(..) and CustomStructure(..)
Rarity: 100

# If you set this to true, the BO3 will be placed with a random rotation.
RotateRandomly: True

# The spawn height of the BO3 - randomY, highestBlock or highestSolidBlock.
SpawnHeight: highestSolidBlock

# The height limits for the BO3.
MinHeight: 0

MaxHeight: 200

# Objects can have other objects attacthed to it: branches. Branches can also
# have branches attached to it, which can also have branches, etc. This is the
# maximum branch depth for this objects.
MaxBranchDepth: 10

# When spawned with the UseWorld keyword, this BO3 should NOT spawn in the following biomes.
# If you writer.write the BO3 name directly in the BiomeConfigs, this will be ignored.
ExcludedBiomes: All


#######################################################################
# +-----------------------------------------------------------------+ #
# |                      Source block settings                      | #
# +-----------------------------------------------------------------+ #
#######################################################################

# The block(s) the BO3 should spawn in.
SourceBlocks: AIR

# The maximum percentage of the BO3 that can be outside the SourceBlock.
# The BO3 won't be placed on a location with more blocks outside the SourceBlock than this percentage.
MaxPercentageOutsideSourceBlock: 0

# What to do when a block is about to be placed outside the SourceBlock? (dontPlace, placeAnyway)
OutsideSourceBlock: dontPlace


#######################################################################
# +-----------------------------------------------------------------+ #
# |                              Blocks                             | #
# +-----------------------------------------------------------------+ #
#######################################################################

# All the blocks used in the BO3 are listed here. Possible blocks:
# Block(x,y,z,id[.data][,nbtfile.nbt)
# RandomBlock(x,y,z,id[:data][,nbtfile.nbt],chance[,id[:data][,nbtfile.nbt],chance[,...]])
# So RandomBlock(0,0,0,CHEST,chest.nbt,50,CHEST,anotherchest.nbt,100) will spawn a chest at
# the BO3 origin, and give it a 50% chance to have the contents of chest.nbt, or, if that
# fails, a 100% percent chance to have the contents of anotherchest.nbt.

Block(-6,0,-3,LEAVES:14)
Block(-5,0,-3,LEAVES:14)
Block(-4,0,-3,LEAVES:14)
Block(-3,0,-3,LOG:12)
Block(-2,0,-3,LOG:12)
Block(-5,0,-2,LEAVES:14)
Block(-4,0,-2,LEAVES:14)
Block(-3,0,-2,LEAVES:14)
Block(-2,0,-2,LOG:12)
Block(-4,0,-1,LOG:12)
Block(-3,0,-1,LEAVES:14)
Block(-2,0,-1,LEAVES:14)
Block(-3,0,0,LEAVES:14)
Block(-3,0,1,LEAVES:14)
Block(-2,0,1,LEAVES:14)
Block(-4,0,2,LOG:12)
Block(-4,0,3,LOG:12)
Block(-4,0,4,LOG:12)
Block(-3,0,4,LOG:12)
Block(-2,0,4,LOG:12)
Block(-4,0,5,LOG:12)
Block(-1,0,5,LOG:12)
Block(-4,0,6,LOG:12)
Block(-1,0,6,LOG:12)
Block(-4,0,7,LOG:12)
Block(-3,0,7,LOG:12)
Block(-2,0,7,LOG:12)
Block(-4,1,-3,LOG:12)
Block(-3,1,-3,LOG:12)
Block(-2,1,-3,LOG:12)
Block(-5,1,-2,LEAVES:14)
Block(-4,1,-2,LEAVES:14)
Block(-3,1,-2,LEAVES:14)
Block(-2,1,-2,LOG:12)
Block(-6,1,-1,LEAVES:14)
Block(-5,1,-1,LEAVES:14)
Block(-4,1,-1,LEAVES:14)
Block(-3,1,-1,LEAVES:14)
Block(-2,1,-1,LEAVES:14)
Block(-5,1,0,LEAVES:14)
Block(-4,1,0,LEAVES:14)
Block(-3,1,0,LEAVES:14)
Block(-4,1,1,LEAVES:14)
Block(-3,1,1,LEAVES:14)
Block(-4,1,2,LEAVES:14)
Block(-4,1,3,LEAVES:14)
Block(-3,1,3,LEAVES:14)
Block(-2,1,3,LEAVES:14)
Block(-4,1,4,LEAVES:14)
Block(-3,1,4,LOG:12)
Block(-2,1,4,LEAVES:14)
Block(-1,1,4,LEAVES:14)
Block(-4,1,5,LOG:12)
Block(-3,1,5,LOG:12)
Block(-2,1,5,LOG:12)
Block(-1,1,5,LOG:12)
Block(0,1,5,LEAVES:14)
Block(1,1,5,LEAVES:14)
Block(-4,1,6,LOG:12)
Block(-3,1,6,LOG:12)
Block(-2,1,6,LOG:12)
Block(-1,1,6,LOG:12)
Block(0,1,6,LEAVES:14)
Block(1,1,6,LEAVES:14)
Block(2,1,6,LEAVES:14)
Block(-4,1,7,LOG:12)
Block(-3,1,7,LOG:12)
Block(-2,1,7,LOG:12)
Block(0,1,7,LEAVES:14)
Block(1,1,7,LEAVES:14)
Block(1,1,8,LEAVES:14)
Block(-4,2,-3,LOG:12)
Block(-3,2,-3,LOG:12)
Block(-4,2,-2,LOG:12)
Block(-3,2,-2,LOG:12)
Block(-2,2,-2,LOG:12)
Block(-5,2,-1,LEAVES:14)
Block(-4,2,-1,LEAVES:14)
Block(-3,2,-1,LEAVES:14)
Block(-5,2,0,LEAVES:14)
Block(-4,2,0,LEAVES:14)
Block(-3,2,0,LEAVES:14)
Block(-4,2,1,LEAVES:14)
Block(-4,2,3,LEAVES:14)
Block(-3,2,3,LEAVES:14)
Block(-2,2,3,LEAVES:14)
Block(-4,2,4,LEAVES:14)
Block(-3,2,4,LEAVES:14)
Block(-2,2,4,LEAVES:14)
Block(-4,2,5,LOG:12)
Block(-3,2,5,LOG:12)
Block(-2,2,5,LOG:12)
Block(-1,2,5,LEAVES:14)
Block(0,2,5,LEAVES:14)
Block(1,2,5,LEAVES:14)
Block(-4,2,6,LOG:12)
Block(-3,2,6,LOG:12)
Block(-2,2,6,LOG:12)
Block(-1,2,6,LOG:12)
Block(0,2,6,LEAVES:14)
Block(1,2,6,LEAVES:14)
Block(-4,2,7,LEAVES:14)
Block(-3,2,7,LEAVES:14)
Block(-2,2,7,LOG:12)
Block(-1,2,7,LEAVES:14)
Block(0,2,7,LEAVES:14)
Block(1,2,7,LEAVES:14)
Block(-3,2,8,LEAVES:14)
Block(-2,2,8,LEAVES:14)
Block(-1,2,8,LEAVES:14)
Block(0,2,8,LEAVES:14)
Block(-2,2,9,LEAVES:14)
Block(-1,2,9,LEAVES:14)
Block(0,2,9,LEAVES:14)
Block(-1,2,10,LEAVES:14)
Block(-4,3,-3,LOG:12)
Block(-3,3,-3,LOG:12)
Block(-4,3,-2,LOG:12)
Block(-3,3,-2,LOG:12)
Block(-3,3,4,LOG:12)
Block(-4,3,5,LOG:12)
Block(-3,3,5,LOG:12)
Block(-2,3,5,LOG:12)
Block(-1,3,5,LEAVES:14)
Block(0,3,5,LEAVES:14)
Block(-4,3,6,LOG:12)
Block(-3,3,6,LOG:12)
Block(-2,3,6,LOG:12)
Block(-1,3,6,LEAVES:14)
Block(0,3,6,LEAVES:14)
Block(-3,3,7,LOG:12)
Block(-2,3,7,LOG:12)
Block(-1,3,7,LEAVES:14)
Block(0,3,7,LEAVES:14)
Block(-3,3,8,LEAVES:14)
Block(-2,3,8,LEAVES:14)
Block(-1,3,8,LEAVES:14)
Block(0,3,8,LEAVES:14)
Block(-4,4,-3,LOG:12)
Block(-3,4,-3,LOG:12)
Block(-4,4,-2,LOG:12)
Block(-3,4,-2,LOG:12)
Block(-4,4,5,LOG:12)
Block(-3,4,5,LOG:12)
Block(-2,4,5,LOG:12)
Block(-3,4,6,LOG:12)
Block(-2,4,6,LOG:12)
Block(-4,5,-3,LOG:12)
Block(-3,5,-3,LOG:12)
Block(-4,5,-2,LOG:12)
Block(-3,5,-2,LOG:12)
Block(-3,5,5,LOG:12)
Block(-2,5,5,LOG:12)
Block(-3,5,6,LOG:12)
Block(-2,5,6,LOG:12)
Block(-4,6,-3,LOG:12)
Block(-3,6,-3,LOG:12)
Block(-4,6,-2,LOG:12)
Block(-3,6,-2,LOG:12)
Block(-3,6,5,LOG:12)
Block(-2,6,5,LOG:12)
Block(-3,6,6,LOG:12)
Block(-2,6,6,LOG:12)
Block(1,7,-9, LEAVES:5)
Block(-4,7,-3,LOG:12)
Block(-3,7,-3,LOG:12)
Block(-4,7,-2,LOG:12)
Block(-3,7,-2,LOG:12)
Block(-8,7,5, LEAVES:13)
Block(-3,7,5,LOG:12)
Block(-2,7,5,LOG:12)
Block(-3,7,6,LOG:12)
Block(-2,7,6,LOG:12)
Block(2,8,-11, LEAVES:5)
Block(2,8,-10, LEAVES:5)
Block(1,8,-9, LEAVES:5)
Block(1,8,-8, LEAVES:5)
Block(-10,8,-7, LEAVES:5)
Block(-9,8,-6, LEAVES:5)
Block(-4,8,-3,LOG:12)
Block(-3,8,-3,LOG:12)
Block(-4,8,-2,LOG:12)
Block(-3,8,-2,LOG:12)
Block(-7,8,3, LEAVES:13)
Block(-8,8,4, LEAVES:13)
Block(-8,8,5, LEAVES:13)
Block(-3,8,5,LOG:12)
Block(-2,8,5,LOG:12)
Block(-9,8,6, LEAVES:5)
Block(-3,8,6,LOG:12)
Block(-2,8,6,LOG:12)
Block(3,9,-12, LEAVES:5)
Block(2,9,-11, LEAVES:5)
Block(2,9,-10, LEAVES:5)
Block(1,9,-9, LEAVES:5)
Block(-11,9,-8, LEAVES:5)
Block(0,9,-8, LEAVES:5)
Block(1,9,-8, LEAVES:5)
Block(-11,9,-7, LEAVES:5)
Block(-10,9,-7, LEAVES:5)
Block(0,9,-7, LEAVES:13)
Block(-9,9,-6, LEAVES:5)
Block(-8,9,-6, LEAVES:13)
Block(-1,9,-6, LEAVES:13)
Block(0,9,-6, LEAVES:13)
Block(-7,9,-5, LEAVES:13)
Block(-6,9,-5, LEAVES:13)
Block(-1,9,-5, LEAVES:13)
Block(-5,9,-4, LEAVES:13)
Block(-4,9,-4, LEAVES:13)
Block(-3,9,-4, LEAVES:13)
Block(-2,9,-4, LEAVES:13)
Block(-1,9,-4, LEAVES:13)
Block(-5,9,-3, LEAVES:13)
Block(-4,9,-3,LOG:12)
Block(-3,9,-3,LOG:12)
Block(-1,9,-3, LEAVES:13)
Block(-5,9,-2, LEAVES:13)
Block(-4,9,-2,LOG:12)
Block(-3,9,-2,LOG:12)
Block(-1,9,-2, LEAVES:13)
Block(-5,9,-1, LEAVES:13)
Block(-1,9,-1, LEAVES:13)
Block(5,9,-1,LEAVES:5)
Block(-6,9,0, LEAVES:13)
Block(-5,9,0, LEAVES:13)
Block(-4,9,0, LEAVES:13)
Block(-3,9,0, LEAVES:13)
Block(-2,9,0, LEAVES:13)
Block(-1,9,0, LEAVES:13)
Block(4,9,0,LEAVES:5)
Block(5,9,0,LEAVES:5)
Block(-6,9,1, LEAVES:13)
Block(1,9,1, LEAVES:13)
Block(3,9,1,LEAVES:5)
Block(-7,9,2, LEAVES:13)
Block(-6,9,2, LEAVES:13)
Block(1,9,2, LEAVES:13)
Block(2,9,2, LEAVES:13)
Block(-7,9,3, LEAVES:13)
Block(-8,9,4, LEAVES:5)
Block(-7,9,4, LEAVES:13)
Block(-8,9,5, LEAVES:5)
Block(-3,9,5,LOG:12)
Block(-2,9,5,LOG:12)
Block(-9,9,6, LEAVES:5)
Block(-3,9,6,LOG:12)
Block(-2,9,6,LOG:12)
Block(-8,9,10,LEAVES:5)
Block(-10,9,11,LEAVES:5)
Block(-9,9,11,LEAVES:5)
Block(2,10,-11, LEAVES:5)
Block(2,10,-10, LEAVES:5)
Block(1,10,-9, LEAVES:5)
Block(-12,10,-8, LEAVES:5)
Block(-11,10,-8, LEAVES:5)
Block(-11,10,-7, LEAVES:5)
Block(-10,10,-7, LEAVES:5)
Block(0,10,-7, LEAVES:13)
Block(-9,10,-6, LEAVES:5)
Block(-8,10,-6, LEAVES:13)
Block(-1,10,-6, LEAVES:13)
Block(0,10,-6, LEAVES:13)
Block(-7,10,-5, LEAVES:13)
Block(-6,10,-5, LEAVES:13)
Block(-1,10,-5, LEAVES:13)
Block(-6,10,-4, LEAVES:13)
Block(-5,10,-4, LEAVES:13)
Block(-4,10,-4, LEAVES:13)
Block(-3,10,-4, LEAVES:13)
Block(-2,10,-4, LEAVES:13)
Block(-1,10,-4, LEAVES:13)
Block(-5,10,-3, LEAVES:13)
Block(-4,10,-3, LEAVES:13)
Block(-3,10,-3, LEAVES:13)
Block(-2,10,-3, LEAVES:13)
Block(-1,10,-3, LEAVES:13)
Block(-8,10,-2,LEAVES:13)
Block(-5,10,-2, LEAVES:13)
Block(-4,10,-2,LOG:12)
Block(-3,10,-2,LOG:12)
Block(-2,10,-2, LEAVES:13)
Block(-1,10,-2, LEAVES:13)
Block(-8,10,-1,LEAVES:13)
Block(-7,10,-1,LEAVES:13)
Block(-5,10,-1, LEAVES:13)
Block(-4,10,-1, LEAVES:13)
Block(-3,10,-1, LEAVES:13)
Block(-2,10,-1, LEAVES:13)
Block(-1,10,-1, LEAVES:13)
Block(-7,10,0,LEAVES:13)
Block(-6,10,0,LEAVES:13)
Block(-5,10,0, LEAVES:13)
Block(-4,10,0, LEAVES:13)
Block(-3,10,0, LEAVES:13)
Block(-2,10,0, LEAVES:13)
Block(-1,10,0, LEAVES:13)
Block(4,10,0,LEAVES:5)
Block(-6,10,1, LEAVES:13)
Block(0,10,1, LEAVES:13)
Block(1,10,1, LEAVES:13)
Block(3,10,1,LEAVES:5)
Block(4,10,1,LEAVES:5)
Block(-7,10,2, LEAVES:13)
Block(-6,10,2, LEAVES:13)
Block(-5,10,2,LEAVES:13)
Block(1,10,2, LEAVES:13)
Block(2,10,2,LEAVES:13)
Block(3,10,2,LEAVES:5)
Block(-7,10,3, LEAVES:13)
Block(-4,10,3,LEAVES:13)
Block(-3,10,3,LEAVES:13)
Block(2,10,3, LEAVES:13)
Block(3,10,3, LEAVES:5)
Block(-8,10,4, LEAVES:5)
Block(-4,10,4,LEAVES:13)
Block(-2,10,4,LEAVES:13)
Block(-1,10,4,LEAVES:13)
Block(0,10,4,LEAVES:13)
Block(1,10,4,LEAVES:13)
Block(-8,10,5, LEAVES:5)
Block(-4,10,5,LEAVES:13)
Block(-3,10,5,LOG:12)
Block(-2,10,5,LOG:12)
Block(-1,10,5,LEAVES:13)
Block(0,10,5,LEAVES:13)
Block(-9,10,6, LEAVES:5)
Block(-5,10,6,LEAVES:13)
Block(-3,10,6,LOG:12)
Block(-2,10,6,LOG:12)
Block(-1,10,6,LEAVES:13)
Block(-9,10,7, LEAVES:5)
Block(-5,10,7,LEAVES:13)
Block(-4,10,7,LEAVES:13)
Block(-3,10,7,LEAVES:13)
Block(-1,10,7,LEAVES:13)
Block(-6,10,8,LEAVES:13)
Block(-2,10,8,LEAVES:13)
Block(-1,10,8,LEAVES:13)
Block(-8,10,9,LEAVES:5)
Block(-7,10,9,LEAVES:13)
Block(-1,10,9,LEAVES:13)
Block(0,10,9,LEAVES:13)
Block(-9,10,10,LEAVES:5)
Block(-8,10,10,LEAVES:5)
Block(-9,10,11,LEAVES:5)
Block(1,10,11,LEAVES:5)
Block(1,10,12,LEAVES:5)
Block(2,11,-11, LEAVES:5)
Block(2,11,-10, LEAVES:5)
Block(1,11,-9, LEAVES:5)
Block(-12,11,-8, LEAVES:5)
Block(-11,11,-8, LEAVES:5)
Block(0,11,-8, LEAVES:5)
Block(1,11,-8, LEAVES:5)
Block(-10,11,-7, LEAVES:5)
Block(0,11,-7, LEAVES:13)
Block(-9,11,-6, LEAVES:5)
Block(-8,11,-6, LEAVES:13)
Block(-1,11,-6, LEAVES:13)
Block(-7,11,-5, LEAVES:13)
Block(-6,11,-5, LEAVES:13)
Block(-1,11,-5, LEAVES:13)
Block(-6,11,-4, LEAVES:13)
Block(-5,11,-4, LEAVES:13)
Block(-4,11,-4, LEAVES:13)
Block(-3,11,-4, LEAVES:13)
Block(-2,11,-4, LEAVES:13)
Block(-5,11,-3, LEAVES:13)
Block(-4,11,-3,LOG:12)
Block(-3,11,-3,LOG:12)
Block(-2,11,-3, LEAVES:13)
Block(-8,11,-2,LEAVES:13)
Block(-5,11,-2, LEAVES:13)
Block(-4,11,-2,LOG:12)
Block(-3,11,-2,LOG:12)
Block(-2,11,-2, LEAVES:13)
Block(-8,11,-1,LEAVES:13)
Block(-7,11,-1,LEAVES:13)
Block(-5,11,-1, LEAVES:13)
Block(-4,11,-1, LEAVES:13)
Block(-3,11,-1, LEAVES:13)
Block(-2,11,-1, LEAVES:13)
Block(5,11,-1,LEAVES:5)
Block(-7,11,0,LEAVES:13)
Block(-6,11,0,LEAVES:13)
Block(-5,11,0, LEAVES:13)
Block(-1,11,0, LEAVES:13)
Block(4,11,0,LEAVES:5)
Block(5,11,0,LEAVES:5)
Block(-6,11,1, LEAVES:13)
Block(-5,11,1,LEAVES:13)
Block(0,11,1, LEAVES:13)
Block(1,11,1, LEAVES:13)
Block(3,11,1,LEAVES:5)
Block(-6,11,2, LEAVES:13)
Block(-5,11,2,LEAVES:13)
Block(2,11,2,LEAVES:13)
Block(3,11,2,LEAVES:5)
Block(-7,11,3, LEAVES:13)
Block(-4,11,3,LEAVES:13)
Block(-3,11,3,LEAVES:13)
Block(2,11,3, LEAVES:13)
Block(3,11,3, LEAVES:5)
Block(-8,11,4, LEAVES:5)
Block(-7,11,4, LEAVES:13)
Block(-4,11,4,LEAVES:13)
Block(-3,11,4,LEAVES:13)
Block(-2,11,4,LEAVES:13)
Block(-1,11,4,LEAVES:13)
Block(0,11,4,LEAVES:13)
Block(4,11,4, LEAVES:5)
Block(-8,11,5, LEAVES:5)
Block(-3,11,5,LOG:12)
Block(-2,11,5,LOG:12)
Block(-1,11,5,LEAVES:13)
Block(0,11,5,LEAVES:13)
Block(-9,11,6, LEAVES:5)
Block(-5,11,6,LEAVES:13)
Block(-4,11,6,LEAVES:13)
Block(-3,11,6,LOG:12)
Block(-2,11,6,LOG:12)
Block(-1,11,6,LEAVES:13)
Block(-9,11,7, LEAVES:5)
Block(-5,11,7,LEAVES:13)
Block(-4,11,7,LEAVES:13)
Block(-3,11,7,LEAVES:13)
Block(-1,11,7,LEAVES:13)
Block(-6,11,8,LEAVES:13)
Block(-2,11,8,LEAVES:13)
Block(-1,11,8,LEAVES:13)
Block(-7,11,9,LEAVES:13)
Block(-1,11,9,LEAVES:13)
Block(-8,11,10,LEAVES:5)
Block(0,11,10,LEAVES:13)
Block(-10,11,11,LEAVES:5)
Block(-9,11,11,LEAVES:5)
Block(0,11,11,LEAVES:5)
Block(1,11,11,LEAVES:5)
Block(-10,11,12,LEAVES:5)
Block(1,11,12,LEAVES:5)
Block(2,11,13,LEAVES:5)
Block(1,12,-9, LEAVES:5)
Block(-12,12,-8, LEAVES:5)
Block(0,12,-8, LEAVES:5)
Block(-10,12,-7, LEAVES:5)
Block(0,12,-7, LEAVES:13)
Block(-9,12,-6, LEAVES:5)
Block(-8,12,-6, LEAVES:13)
Block(-1,12,-6, LEAVES:13)
Block(-8,12,-5, LEAVES:13)
Block(-7,12,-5, LEAVES:13)
Block(-6,12,-5, LEAVES:13)
Block(-1,12,-5, LEAVES:13)
Block(-6,12,-4, LEAVES:13)
Block(-5,12,-4, LEAVES:13)
Block(-4,12,-4, LEAVES:13)
Block(-3,12,-4, LEAVES:13)
Block(-2,12,-4, LEAVES:13)
Block(-5,12,-3, LEAVES:13)
Block(-4,12,-3,LOG:12)
Block(-3,12,-3,LOG:12)
Block(-2,12,-3, LEAVES:13)
Block(-8,12,-2,LEAVES:13)
Block(-5,12,-2, LEAVES:13)
Block(-4,12,-2,LOG:12)
Block(-3,12,-2,LOG:12)
Block(-2,12,-2, LEAVES:13)
Block(-8,12,-1,LEAVES:13)
Block(-7,12,-1,LEAVES:13)
Block(-5,12,-1, LEAVES:13)
Block(-4,12,-1, LEAVES:13)
Block(-3,12,-1, LEAVES:13)
Block(-2,12,-1, LEAVES:13)
Block(-7,12,0,LEAVES:13)
Block(-6,12,0,LEAVES:13)
Block(-5,12,0, LEAVES:13)
Block(-1,12,0, LEAVES:13)
Block(0,12,0, LEAVES:13)
Block(-6,12,1, LEAVES:13)
Block(0,12,1, LEAVES:13)
Block(1,12,1, LEAVES:13)
Block(3,12,1,LEAVES:5)
Block(-6,12,2, LEAVES:13)
Block(-5,12,2,LEAVES:13)
Block(-2,12,2, LEAVES:13)
Block(1,12,2, LEAVES:13)
Block(2,12,2,LEAVES:13)
Block(-7,12,3, LEAVES:13)
Block(-4,12,3,LEAVES:13)
Block(2,12,3, LEAVES:13)
Block(3,12,3, LEAVES:5)
Block(-4,12,4,LEAVES:13)
Block(-3,12,4,LEAVES:13)
Block(-2,12,4,LEAVES:13)
Block(-1,12,4,LEAVES:13)
Block(0,12,4,LEAVES:13)
Block(4,12,4, LEAVES:5)
Block(-4,12,5,LEAVES:13)
Block(-3,12,5,LOG:12)
Block(-2,12,5,LOG:12)
Block(-1,12,5,LEAVES:13)
Block(0,12,5,LEAVES:13)
Block(-9,12,6, LEAVES:5)
Block(-5,12,6,LEAVES:13)
Block(-4,12,6,LEAVES:13)
Block(-3,12,6,LOG:12)
Block(-2,12,6,LOG:12)
Block(-1,12,6,LEAVES:13)
Block(-5,12,7,LEAVES:13)
Block(-4,12,7,LEAVES:13)
Block(-3,12,7,LEAVES:13)
Block(-2,12,7,LEAVES:13)
Block(-1,12,7,LEAVES:13)
Block(-6,12,8,LEAVES:13)
Block(-2,12,8,LEAVES:13)
Block(-1,12,8,LEAVES:13)
Block(-7,12,9,LEAVES:13)
Block(-1,12,9,LEAVES:13)
Block(0,12,9,LEAVES:13)
Block(-8,12,10,LEAVES:5)
Block(0,12,10,LEAVES:13)
Block(-9,12,11,LEAVES:5)
Block(0,12,11,LEAVES:5)
Block(1,12,11,LEAVES:5)
Block(-2,12,12,LEAVES:5)
Block(1,12,12,LEAVES:5)
Block(2,12,13,LEAVES:5)
Block(-1,13,-6, LEAVES:13)
Block(-7,13,-5, LEAVES:13)
Block(-6,13,-5, LEAVES:13)
Block(-1,13,-5, LEAVES:13)
Block(-6,13,-4, LEAVES:13)
Block(-5,13,-4, LEAVES:13)
Block(-4,13,-4, LEAVES:13)
Block(-3,13,-4, LEAVES:13)
Block(-2,13,-4, LEAVES:13)
Block(-5,13,-3, LEAVES:13)
Block(-4,13,-3,LOG:12)
Block(-3,13,-3,LOG:12)
Block(-2,13,-3, LEAVES:13)
Block(-5,13,-2, LEAVES:13)
Block(-4,13,-2,LOG:12)
Block(-3,13,-2,LOG:12)
Block(-2,13,-2, LEAVES:13)
Block(-5,13,-1, LEAVES:13)
Block(-4,13,-1, LEAVES:13)
Block(-3,13,-1, LEAVES:13)
Block(-2,13,-1, LEAVES:13)
Block(-7,13,0,LEAVES:13)
Block(-6,13,0,LEAVES:13)
Block(-5,13,0, LEAVES:13)
Block(-1,13,0, LEAVES:13)
Block(0,13,0, LEAVES:13)
Block(-6,13,1,LEAVES:13)
Block(-2,13,1, LEAVES:13)
Block(0,13,1, LEAVES:13)
Block(3,13,1,LEAVES:5)
Block(-5,13,2,LEAVES:13)
Block(-2,13,2, LEAVES:13)
Block(1,13,2, LEAVES:13)
Block(2,13,2,LEAVES:13)
Block(-4,13,3,LEAVES:13)
Block(-1,13,3, LEAVES:13)
Block(-4,13,4,LEAVES:13)
Block(-3,13,4,LEAVES:13)
Block(-2,13,4,LEAVES:13)
Block(-1,13,4, LEAVES:13)
Block(0,13,4,LEAVES:13)
Block(-4,13,5,LEAVES:13)
Block(-3,13,5,LOG:12)
Block(-2,13,5,LOG:12)
Block(-1,13,5,LEAVES:13)
Block(0,13,5, LEAVES:13)
Block(-4,13,6,LEAVES:13)
Block(-3,13,6,LOG:12)
Block(-2,13,6,LOG:12)
Block(-1,13,6,LEAVES:13)
Block(-5,13,7,LEAVES:13)
Block(-4,13,7,LEAVES:13)
Block(-3,13,7,LEAVES:13)
Block(-2,13,7,LEAVES:13)
Block(-1,13,7,LEAVES:13)
Block(-6,13,8,LEAVES:13)
Block(-3,13,8,LEAVES:13)
Block(-1,13,8,LEAVES:13)
Block(-7,13,9,LEAVES:13)
Block(-3,13,9,LEAVES:13)
Block(-1,13,9,LEAVES:13)
Block(0,13,9,LEAVES:13)
Block(-8,13,10,LEAVES:5)
Block(-2,13,10,LEAVES:13)
Block(0,13,10,LEAVES:13)
Block(-2,13,11,LEAVES:5)
Block(1,13,11,LEAVES:5)
Block(-2,13,12,LEAVES:5)
Block(1,13,12,LEAVES:5)
Block(2,13,13,LEAVES:5)
Block(-6,14,-4, LEAVES:13)
Block(-5,14,-4, LEAVES:13)
Block(-3,14,-4, LEAVES:13)
Block(-2,14,-4, LEAVES:13)
Block(-5,14,-3, LEAVES:13)
Block(-4,14,-3,LOG:12)
Block(-3,14,-3,LOG:12)
Block(-5,14,-2, LEAVES:13)
Block(-4,14,-2,LOG:12)
Block(-3,14,-2,LOG:12)
Block(-2,14,-2, LEAVES:13)
Block(-7,14,-1, LEAVES:13)
Block(-5,14,-1, LEAVES:13)
Block(-4,14,-1, LEAVES:13)
Block(-3,14,-1, LEAVES:13)
Block(-2,14,-1, LEAVES:13)
Block(-8,14,0, LEAVES:13)
Block(-5,14,0, LEAVES:13)
Block(-3,14,0, LEAVES:13)
Block(-1,14,0, LEAVES:13)
Block(-6,14,1,LEAVES:13)
Block(-2,14,1, LEAVES:13)
Block(-5,14,2,LEAVES:13)
Block(-2,14,2, LEAVES:13)
Block(-4,14,3,LEAVES:13)
Block(-1,14,3, LEAVES:13)
Block(-4,14,4,LEAVES:13)
Block(-3,14,4,LEAVES:13)
Block(-2,14,4,LEAVES:13)
Block(-1,14,4, LEAVES:13)
Block(0,14,4,LEAVES:13)
Block(-4,14,5,LEAVES:13)
Block(-3,14,5,LOG:12)
Block(-2,14,5,LOG:12)
Block(0,14,5, LEAVES:13)
Block(-10,14,6,LEAVES:5)
Block(-9,14,6,LEAVES:5)
Block(-8,14,6,LEAVES:5)
Block(-7,14,6,LEAVES:13)
Block(-6,14,6,LEAVES:13)
Block(-5,14,6,LEAVES:13)
Block(-4,14,6,LEAVES:13)
Block(-3,14,6,LOG:12)
Block(-2,14,6,LOG:12)
Block(-1,14,6,LEAVES:13)
Block(-5,14,7,LEAVES:13)
Block(-4,14,7,LEAVES:13)
Block(-3,14,7,LEAVES:13)
Block(-2,14,7,LEAVES:13)
Block(-1,14,7,LEAVES:13)
Block(-6,14,8,LEAVES:13)
Block(-3,14,8,LEAVES:13)
Block(-1,14,8,LEAVES:13)
Block(-7,14,9,LEAVES:13)
Block(-3,14,9,LEAVES:13)
Block(-1,14,9,LEAVES:13)
Block(0,14,9,LEAVES:13)
Block(-2,14,10,LEAVES:13)
Block(0,14,10,LEAVES:13)
Block(-2,14,11,LEAVES:5)
Block(1,14,11,LEAVES:5)
Block(-2,14,12,LEAVES:5)
Block(-5,15,-7, LEAVES:13)
Block(-5,15,-6, LEAVES:13)
Block(-4,15,-4, LEAVES:13)
Block(0,15,-4, LEAVES:13)
Block(-4,15,-3,LOG:12)
Block(-3,15,-3,LOG:12)
Block(-2,15,-3, LEAVES:13)
Block(-5,15,-2, LEAVES:13)
Block(-4,15,-2, LEAVES:13)
Block(-3,15,-2,LOG:12)
Block(-7,15,-1, LEAVES:13)
Block(-6,15,-1, LEAVES:13)
Block(-3,15,-1, LEAVES:13)
Block(-9,15,0, LEAVES:5)
Block(-8,15,0, LEAVES:13)
Block(-3,15,0, LEAVES:13)
Block(-10,15,1, LEAVES:5)
Block(-3,15,1,LEAVES:13)
Block(-2,15,1, LEAVES:13)
Block(-5,15,2,LEAVES:13)
Block(-2,15,2, LEAVES:13)
Block(-3,15,3,LEAVES:13)
Block(-1,15,3, LEAVES:13)
Block(-3,15,4,LEAVES:13)
Block(-1,15,4, LEAVES:13)
Block(-3,15,5,LOG:12)
Block(-2,15,5,LEAVES:13)
Block(-1,15,5,LEAVES:13)
Block(0,15,5,LEAVES:13)
Block(1,15,5,LEAVES:13)
Block(-9,15,6,LEAVES:5)
Block(-8,15,6,LEAVES:5)
Block(-7,15,6,LEAVES:13)
Block(-6,15,6,LEAVES:13)
Block(-5,15,6,LEAVES:13)
Block(-4,15,6,LEAVES:13)
Block(-3,15,6,LOG:12)
Block(-2,15,6,LOG:12)
Block(-3,15,7,LEAVES:13)
Block(-2,15,7,LEAVES:13)
Block(-6,15,8,LEAVES:13)
Block(-3,15,8,LEAVES:13)
Block(-1,15,8,LEAVES:13)
Block(-3,15,9,LEAVES:13)
Block(-1,15,9,LEAVES:13)
Block(-2,15,10,LEAVES:13)
Block(-2,15,11,LEAVES:5)
Block(-6,16,-8, LEAVES:5)
Block(-5,16,-7, LEAVES:13)
Block(-5,16,-6, LEAVES:13)
Block(-5,16,-5, LEAVES:13)
Block(-4,16,-5, LEAVES:13)
Block(1,16,-5, LEAVES:13)
Block(-4,16,-4, LEAVES:13)
Block(-1,16,-4, LEAVES:13)
Block(0,16,-4, LEAVES:13)
Block(1,16,-4, LEAVES:13)
Block(-4,16,-3,LOG:12)
Block(-3,16,-3, LEAVES:13)
Block(-2,16,-3, LEAVES:13)
Block(-5,16,-2, LEAVES:13)
Block(-4,16,-2, LEAVES:13)
Block(-3,16,-2,LOG:12)
Block(-7,16,-1, LEAVES:13)
Block(-6,16,-1, LEAVES:13)
Block(-5,16,-1, LEAVES:13)
Block(-3,16,-1, LEAVES:13)
Block(-9,16,0, LEAVES:5)
Block(-8,16,0, LEAVES:13)
Block(-3,16,0, LEAVES:13)
Block(-10,16,1, LEAVES:5)
Block(-3,16,1,LEAVES:13)
Block(-2,16,1, LEAVES:13)
Block(-2,16,2, LEAVES:13)
Block(-3,16,3,LEAVES:13)
Block(-3,16,4,LEAVES:13)
Block(-3,16,5,LOG:12)
Block(-2,16,5,LEAVES:13)
Block(-1,16,5,LEAVES:13)
Block(0,16,5,LEAVES:13)
Block(1,16,5,LEAVES:13)
Block(2,16,5,LEAVES:13)
Block(3,16,5,LEAVES:5)
Block(4,16,5,LEAVES:5)
Block(-9,16,6,LEAVES:5)
Block(-8,16,6,LEAVES:5)
Block(-7,16,6,LEAVES:13)
Block(-6,16,6,LEAVES:13)
Block(-5,16,6,LEAVES:13)
Block(-4,16,6,LEAVES:13)
Block(-3,16,6,LOG:12)
Block(-2,16,6,LOG:12)
Block(-3,16,7,LEAVES:13)
Block(-3,16,8,LEAVES:13)
Block(-3,16,9,LEAVES:13)
Block(-2,16,10,LEAVES:13)
Block(-6,17,-8, LEAVES:5)
Block(-5,17,-7, LEAVES:13)
Block(-5,17,-6, LEAVES:13)
Block(-5,17,-5, LEAVES:13)
Block(-4,17,-5, LEAVES:13)
Block(1,17,-5, LEAVES:13)
Block(2,17,-5, LEAVES:5)
Block(3,17,-5, LEAVES:5)
Block(-4,17,-4, LEAVES:13)
Block(-1,17,-4, LEAVES:13)
Block(0,17,-4, LEAVES:13)
Block(1,17,-4, LEAVES:13)
Block(-4,17,-3,LOG:12)
Block(-3,17,-3, LEAVES:13)
Block(-2,17,-3, LEAVES:13)
Block(-1,17,-3, LEAVES:13)
Block(-5,17,-2, LEAVES:13)
Block(-4,17,-2, LEAVES:13)
Block(-3,17,-2,LOG:12)
Block(-7,17,-1, LEAVES:13)
Block(-6,17,-1, LEAVES:13)
Block(-5,17,-1, LEAVES:13)
Block(-3,17,-1, LEAVES:13)
Block(-9,17,0, LEAVES:5)
Block(-8,17,0, LEAVES:13)
Block(-3,17,0, LEAVES:13)
Block(-11,17,1, LEAVES:5)
Block(-10,17,1, LEAVES:5)
Block(-3,17,1,LEAVES:13)
Block(-2,17,1, LEAVES:13)
Block(-3,17,3,LEAVES:13)
Block(-3,17,4,LEAVES:13)
Block(-3,17,5,LOG:12)
Block(-2,17,5,LEAVES:13)
Block(-1,17,5,LEAVES:13)
Block(0,17,5,LEAVES:13)
Block(1,17,5,LEAVES:13)
Block(2,17,5,LEAVES:13)
Block(3,17,5,LEAVES:5)
Block(4,17,5,LEAVES:5)
Block(-9,17,6,LEAVES:5)
Block(-8,17,6,LEAVES:5)
Block(-7,17,6,LEAVES:13)
Block(-6,17,6,LEAVES:13)
Block(-5,17,6,LEAVES:13)
Block(-4,17,6,LEAVES:13)
Block(-3,17,6,LOG:12)
Block(-2,17,6,LOG:12)
Block(-3,17,7,LEAVES:13)
Block(-3,17,8,LEAVES:13)
Block(-3,17,9,LEAVES:13)
Block(-8,18,-11, LEAVES:5)
Block(-7,18,-9, LEAVES:5)
Block(-6,18,-9, LEAVES:5)
Block(-6,18,-8, LEAVES:5)
Block(-5,18,-7, LEAVES:13)
Block(-5,18,-6, LEAVES:13)
Block(-5,18,-5, LEAVES:13)
Block(-4,18,-5, LEAVES:13)
Block(1,18,-5, LEAVES:13)
Block(2,18,-5, LEAVES:5)
Block(3,18,-5, LEAVES:5)
Block(-4,18,-4, LEAVES:13)
Block(-1,18,-4, LEAVES:13)
Block(0,18,-4, LEAVES:13)
Block(-4,18,-3, LEAVES:13)
Block(-3,18,-3, LEAVES:13)
Block(-2,18,-3, LEAVES:13)
Block(-1,18,-3, LEAVES:13)
Block(-5,18,-2, LEAVES:13)
Block(-4,18,-2, LEAVES:13)
Block(-3,18,-2,LOG:12)
Block(-7,18,-1, LEAVES:13)
Block(-6,18,-1, LEAVES:13)
Block(-5,18,-1, LEAVES:13)
Block(-3,18,-1, LEAVES:13)
Block(-9,18,0, LEAVES:5)
Block(-8,18,0, LEAVES:13)
Block(-3,18,0, LEAVES:13)
Block(-10,18,1, LEAVES:5)
Block(-3,18,1,LEAVES:13)
Block(-3,18,3,LEAVES:13)
Block(-3,18,4,LEAVES:13)
Block(0,18,4, LEAVES:13)
Block(-3,18,5,LOG:12)
Block(-2,18,5,LEAVES:13)
Block(-1,18,5,LEAVES:13)
Block(0,18,5,LEAVES:13)
Block(1,18,5,LEAVES:13)
Block(2,18,5,LEAVES:13)
Block(3,18,5,LEAVES:5)
Block(4,18,5,LEAVES:5)
Block(-8,18,6,LEAVES:5)
Block(-7,18,6,LEAVES:13)
Block(-6,18,6,LEAVES:13)
Block(-5,18,6,LEAVES:13)
Block(-4,18,6,LEAVES:13)
Block(-3,18,6,LEAVES:13)
Block(-2,18,6,LOG:12)
Block(1,18,6, LEAVES:13)
Block(-3,18,7,LEAVES:13)
Block(-3,18,8,LEAVES:13)
Block(-8,19,-11, LEAVES:5)
Block(-7,19,-10, LEAVES:5)
Block(-7,19,-9, LEAVES:5)
Block(-6,19,-9, LEAVES:5)
Block(-6,19,-8, LEAVES:5)
Block(-6,19,-7, LEAVES:13)
Block(-5,19,-7, LEAVES:13)
Block(-5,19,-6, LEAVES:13)
Block(-5,19,-5, LEAVES:13)
Block(-4,19,-5, LEAVES:13)
Block(1,19,-5, LEAVES:13)
Block(2,19,-5, LEAVES:5)
Block(3,19,-5, LEAVES:5)
Block(-4,19,-4, LEAVES:13)
Block(-3,19,-4, LEAVES:13)
Block(-2,19,-4, LEAVES:13)
Block(-1,19,-4, LEAVES:13)
Block(0,19,-4, LEAVES:13)
Block(1,19,-4, LEAVES:13)
Block(2,19,-4, LEAVES:5)
Block(3,19,-4, LEAVES:5)
Block(-5,19,-3, LEAVES:13)
Block(-4,19,-3, LEAVES:13)
Block(-3,19,-3,LOG:12)
Block(-2,19,-3, LEAVES:13)
Block(-1,19,-3, LEAVES:13)
Block(-6,19,-2, LEAVES:13)
Block(-5,19,-2, LEAVES:13)
Block(-4,19,-2,LOG:12)
Block(-3,19,-2,LOG:12)
Block(-7,19,-1, LEAVES:13)
Block(-6,19,-1, LEAVES:13)
Block(-5,19,-1, LEAVES:13)
Block(-4,19,-1, LEAVES:13)
Block(-3,19,-1, LEAVES:13)
Block(-2,19,-1, LEAVES:13)
Block(-9,19,0, LEAVES:5)
Block(-8,19,0, LEAVES:13)
Block(-3,19,0, LEAVES:13)
Block(-10,19,1, LEAVES:5)
Block(-3,19,1,LEAVES:13)
Block(-2,19,1, LEAVES:13)
Block(-3,19,3,LEAVES:13)
Block(-1,19,3, LEAVES:13)
Block(-3,19,4,LEAVES:13)
Block(0,19,4, LEAVES:13)
Block(-3,19,5,LOG:12)
Block(-2,19,5,LEAVES:13)
Block(-1,19,5,LEAVES:13)
Block(0,19,5,LEAVES:13)
Block(1,19,5,LEAVES:13)
Block(2,19,5,LEAVES:13)
Block(-8,19,6,LEAVES:5)
Block(-7,19,6,LEAVES:13)
Block(-6,19,6,LEAVES:13)
Block(-5,19,6,LEAVES:13)
Block(-4,19,6,LEAVES:13)
Block(-3,19,6,LOG:12)
Block(-2,19,6,LOG:12)
Block(1,19,6, LEAVES:13)
Block(-3,19,7,LEAVES:13)
Block(-2,19,7,LEAVES:13)
Block(0,19,9,LEAVES:13)
Block(-8,20,-12, LEAVES:5)
Block(-8,20,-11, LEAVES:5)
Block(-7,20,-10, LEAVES:5)
Block(-7,20,-9, LEAVES:5)
Block(-6,20,-9, LEAVES:5)
Block(-6,20,-8, LEAVES:5)
Block(-6,20,-7, LEAVES:13)
Block(-5,20,-7, LEAVES:13)
Block(-5,20,-6, LEAVES:13)
Block(-4,20,-5, LEAVES:13)
Block(3,20,-5, LEAVES:5)
Block(4,20,-5, LEAVES:5)
Block(5,20,-5, LEAVES:5)
Block(-4,20,-4, LEAVES:13)
Block(-3,20,-4, LEAVES:13)
Block(-2,20,-4, LEAVES:13)
Block(0,20,-4, LEAVES:13)
Block(1,20,-4, LEAVES:13)
Block(2,20,-4, LEAVES:5)
Block(3,20,-4, LEAVES:5)
Block(-5,20,-3, LEAVES:13)
Block(-4,20,-3,LOG:12)
Block(-3,20,-3,LOG:12)
Block(-2,20,-3, LEAVES:13)
Block(-1,20,-3, LEAVES:13)
Block(0,20,-3, LEAVES:13)
Block(-6,20,-2, LEAVES:13)
Block(-5,20,-2, LEAVES:13)
Block(-4,20,-2,LOG:12)
Block(-3,20,-2,LOG:12)
Block(-2,20,-2, LEAVES:13)
Block(-1,20,-2, LEAVES:13)
Block(-7,20,-1, LEAVES:13)
Block(-6,20,-1, LEAVES:13)
Block(-5,20,-1, LEAVES:13)
Block(-4,20,-1, LEAVES:13)
Block(-2,20,-1, LEAVES:13)
Block(-9,20,0, LEAVES:5)
Block(-8,20,0, LEAVES:13)
Block(-3,20,0, LEAVES:13)
Block(-2,20,0, LEAVES:13)
Block(-11,20,1, LEAVES:5)
Block(-10,20,1, LEAVES:5)
Block(-2,20,1, LEAVES:13)
Block(-12,20,2, LEAVES:5)
Block(-11,20,2, LEAVES:5)
Block(-2,20,2, LEAVES:13)
Block(-1,20,2, LEAVES:13)
Block(-3,20,3,LEAVES:13)
Block(-1,20,3, LEAVES:13)
Block(-3,20,4,LEAVES:13)
Block(0,20,4, LEAVES:13)
Block(-3,20,5,LOG:12)
Block(-2,20,5,LEAVES:13)
Block(-1,20,5,LEAVES:13)
Block(0,20,5,LEAVES:13)
Block(1,20,5,LEAVES:13)
Block(-5,20,6,LEAVES:13)
Block(-4,20,6,LEAVES:13)
Block(-3,20,6,LOG:12)
Block(-2,20,6,LOG:12)
Block(1,20,6, LEAVES:13)
Block(-6,20,7,LEAVES:13)
Block(-5,20,7,LEAVES:13)
Block(-2,20,7,LEAVES:13)
Block(-7,20,8,LEAVES:13)
Block(-6,20,8,LEAVES:13)
Block(-1,20,8,LEAVES:13)
Block(-9,20,9,LEAVES:5)
Block(-8,20,9,LEAVES:5)
Block(0,20,9,LEAVES:13)
Block(-11,20,10,LEAVES:5)
Block(-10,20,10,LEAVES:5)
Block(-12,20,11,LEAVES:5)
Block(-8,21,-11, LEAVES:5)
Block(-7,21,-10, LEAVES:5)
Block(-7,21,-9, LEAVES:5)
Block(-6,21,-8, LEAVES:5)
Block(-6,21,-7, LEAVES:13)
Block(-5,21,-7, LEAVES:13)
Block(-5,21,-6, LEAVES:13)
Block(-4,21,-5, LEAVES:13)
Block(4,21,-5, LEAVES:5)
Block(5,21,-5, LEAVES:5)
Block(-4,21,-4, LEAVES:13)
Block(-3,21,-4, LEAVES:13)
Block(-2,21,-4, LEAVES:13)
Block(1,21,-4, LEAVES:13)
Block(3,21,-4, LEAVES:5)
Block(-5,21,-3, LEAVES:13)
Block(-4,21,-3, LEAVES:13)
Block(-3,21,-3,LOG:12)
Block(-2,21,-3, LEAVES:13)
Block(-1,21,-3, LEAVES:13)
Block(0,21,-3, LEAVES:13)
Block(-6,21,-2, LEAVES:13)
Block(-5,21,-2, LEAVES:13)
Block(-4,21,-2,LOG:12)
Block(-3,21,-2,LOG:12)
Block(-2,21,-2, LEAVES:13)
Block(-7,21,-1, LEAVES:13)
Block(-6,21,-1, LEAVES:13)
Block(-5,21,-1, LEAVES:13)
Block(-4,21,-1, LEAVES:13)
Block(-2,21,-1, LEAVES:13)
Block(-9,21,0, LEAVES:5)
Block(-8,21,0, LEAVES:13)
Block(-6,21,0,LEAVES:13)
Block(-3,21,0, LEAVES:13)
Block(-11,21,1, LEAVES:5)
Block(-10,21,1, LEAVES:5)
Block(-5,21,1,LEAVES:13)
Block(-2,21,1, LEAVES:13)
Block(3,21,1,LEAVES:5)
Block(-12,21,2, LEAVES:5)
Block(-5,21,2,LEAVES:13)
Block(-2,21,2, LEAVES:13)
Block(-1,21,2, LEAVES:13)
Block(1,21,2,LEAVES:13)
Block(2,21,2,LEAVES:13)
Block(-4,21,3,LEAVES:13)
Block(-1,21,3, LEAVES:13)
Block(0,21,3,LEAVES:13)
Block(-4,21,4,LEAVES:13)
Block(-3,21,4,LEAVES:13)
Block(-1,21,4,LEAVES:13)
Block(0,21,4, LEAVES:13)
Block(-3,21,5,LOG:12)
Block(-2,21,5,LEAVES:13)
Block(0,21,5, LEAVES:13)
Block(-4,21,6,LEAVES:13)
Block(-3,21,6,LOG:12)
Block(-2,21,6,LOG:12)
Block(1,21,6, LEAVES:13)
Block(-6,21,7,LEAVES:13)
Block(-5,21,7,LEAVES:13)
Block(-2,21,7,LEAVES:13)
Block(-7,21,8,LEAVES:13)
Block(-6,21,8,LEAVES:13)
Block(-1,21,8,LEAVES:13)
Block(-9,21,9,LEAVES:5)
Block(-8,21,9,LEAVES:5)
Block(0,21,9,LEAVES:13)
Block(-11,21,10,LEAVES:5)
Block(-10,21,10,LEAVES:5)
Block(-6,22,-8, LEAVES:5)
Block(-6,22,-7, LEAVES:13)
Block(-5,22,-7, LEAVES:13)
Block(-5,22,-6, LEAVES:13)
Block(-5,22,-5, LEAVES:13)
Block(-4,22,-5, LEAVES:13)
Block(4,22,-5, LEAVES:5)
Block(5,22,-5, LEAVES:5)
Block(-4,22,-4, LEAVES:13)
Block(-3,22,-4, LEAVES:13)
Block(0,22,-4, LEAVES:13)
Block(1,22,-4, LEAVES:13)
Block(2,22,-4, LEAVES:5)
Block(3,22,-4, LEAVES:5)
Block(-5,22,-3, LEAVES:13)
Block(-4,22,-3,LOG:12)
Block(-3,22,-3,LOG:12)
Block(-2,22,-3, LEAVES:13)
Block(-1,22,-3, LEAVES:13)
Block(0,22,-3, LEAVES:13)
Block(-7,22,-2,LEAVES:13)
Block(-6,22,-2, LEAVES:13)
Block(-5,22,-2, LEAVES:13)
Block(-4,22,-2,LOG:12)
Block(-3,22,-2,LOG:12)
Block(-2,22,-2, LEAVES:13)
Block(-7,22,-1, LEAVES:13)
Block(-6,22,-1, LEAVES:13)
Block(-5,22,-1, LEAVES:13)
Block(-4,22,-1, LEAVES:13)
Block(-3,22,-1, LEAVES:13)
Block(-2,22,-1, LEAVES:13)
Block(-9,22,0, LEAVES:5)
Block(-8,22,0, LEAVES:13)
Block(-6,22,0,LEAVES:13)
Block(-3,22,0, LEAVES:13)
Block(-2,22,0, LEAVES:13)
Block(4,22,0,LEAVES:5)
Block(-11,22,1, LEAVES:5)
Block(-10,22,1, LEAVES:5)
Block(-6,22,1,LEAVES:13)
Block(-5,22,1,LEAVES:13)
Block(-2,22,1, LEAVES:13)
Block(3,22,1,LEAVES:5)
Block(-12,22,2, LEAVES:5)
Block(-5,22,2,LEAVES:13)
Block(-1,22,2, LEAVES:13)
Block(1,22,2,LEAVES:13)
Block(2,22,2,LEAVES:13)
Block(-4,22,3,LEAVES:13)
Block(-1,22,3, LEAVES:13)
Block(0,22,3,LEAVES:13)
Block(-4,22,4,LEAVES:13)
Block(-3,22,4,LEAVES:13)
Block(-1,22,4,LEAVES:13)
Block(0,22,4, LEAVES:13)
Block(-3,22,5,LEAVES:13)
Block(-2,22,5,LEAVES:13)
Block(-4,22,6,LEAVES:13)
Block(-3,22,6,LOG:12)
Block(-2,22,6,LOG:12)
Block(1,22,6, LEAVES:13)
Block(-6,22,7,LEAVES:13)
Block(-5,22,7,LEAVES:13)
Block(-2,22,7,LEAVES:13)
Block(-7,22,8,LEAVES:13)
Block(-6,22,8,LEAVES:13)
Block(-1,22,8,LEAVES:13)
Block(-9,22,9,LEAVES:5)
Block(-8,22,9,LEAVES:5)
Block(0,22,9,LEAVES:13)
Block(-10,22,10,LEAVES:5)
Block(0,22,10,LEAVES:13)
Block(1,22,10,LEAVES:13)
Block(-5,23,-6, LEAVES:13)
Block(-4,23,-5, LEAVES:13)
Block(-4,23,-4, LEAVES:13)
Block(-3,23,-4, LEAVES:13)
Block(0,23,-4, LEAVES:13)
Block(1,23,-4, LEAVES:13)
Block(2,23,-4, LEAVES:5)
Block(-5,23,-3, LEAVES:13)
Block(-4,23,-3, LEAVES:13)
Block(-3,23,-3,LOG:12)
Block(-2,23,-3, LEAVES:13)
Block(-1,23,-3, LEAVES:13)
Block(0,23,-3, LEAVES:13)
Block(-5,23,-2, LEAVES:13)
Block(-4,23,-2,LOG:12)
Block(-3,23,-2,LOG:12)
Block(-2,23,-2, LEAVES:13)
Block(-7,23,-1, LEAVES:13)
Block(-6,23,-1, LEAVES:13)
Block(-4,23,-1, LEAVES:13)
Block(-3,23,-1, LEAVES:13)
Block(-2,23,-1, LEAVES:13)
Block(-9,23,0, LEAVES:5)
Block(-6,23,0,LEAVES:13)
Block(-3,23,0, LEAVES:13)
Block(-2,23,0, LEAVES:13)
Block(4,23,0,LEAVES:5)
Block(-5,23,1,LEAVES:13)
Block(-2,23,1, LEAVES:13)
Block(3,23,1,LEAVES:5)
Block(-5,23,2,LEAVES:13)
Block(-2,23,2, LEAVES:13)
Block(1,23,2,LEAVES:13)
Block(2,23,2,LEAVES:13)
Block(-4,23,3,LEAVES:13)
Block(-2,23,3, LEAVES:13)
Block(0,23,3,LEAVES:13)
Block(-4,23,4,LEAVES:13)
Block(-3,23,4,LEAVES:13)
Block(-1,23,4,LEAVES:13)
Block(0,23,4, LEAVES:13)
Block(-3,23,5,LEAVES:13)
Block(-2,23,5,LEAVES:13)
Block(-4,23,6,LEAVES:13)
Block(-3,23,6,LEAVES:13)
Block(-2,23,6,LOG:12)
Block(-6,23,7,LEAVES:13)
Block(-5,23,7,LEAVES:13)
Block(-2,23,7,LEAVES:13)
Block(-7,23,8,LEAVES:13)
Block(-6,23,8,LEAVES:13)
Block(-1,23,8,LEAVES:13)
Block(-9,23,9,LEAVES:5)
Block(-8,23,9,LEAVES:5)
Block(0,23,9,LEAVES:13)
Block(-11,23,10,LEAVES:5)
Block(-10,23,10,LEAVES:5)
Block(-12,23,11,LEAVES:5)
Block(-6,24,-8, LEAVES:5)
Block(-6,24,-7, LEAVES:13)
Block(-6,24,-6, LEAVES:13)
Block(-5,24,-6, LEAVES:13)
Block(-5,24,-5, LEAVES:13)
Block(1,24,-5, LEAVES:13)
Block(-4,24,-4, LEAVES:13)
Block(-1,24,-4, LEAVES:13)
Block(0,24,-4, LEAVES:13)
Block(1,24,-4, LEAVES:13)
Block(-4,24,-3, LEAVES:13)
Block(-3,24,-3,LOG:12)
Block(-2,24,-3, LEAVES:13)
Block(-1,24,-3, LEAVES:13)
Block(0,24,-3, LEAVES:13)
Block(-7,24,-2,LEAVES:13)
Block(-5,24,-2, LEAVES:13)
Block(-4,24,-2,LOG:12)
Block(-3,24,-2, LEAVES:13)
Block(-2,24,-2, LEAVES:13)
Block(-8,24,-1, LEAVES:13)
Block(-7,24,-1, LEAVES:13)
Block(-6,24,-1, LEAVES:13)
Block(-4,24,-1, LEAVES:13)
Block(-3,24,-1, LEAVES:13)
Block(-9,24,0, LEAVES:5)
Block(-6,24,0,LEAVES:13)
Block(-3,24,0, LEAVES:13)
Block(4,24,0,LEAVES:5)
Block(-5,24,1,LEAVES:13)
Block(-2,24,1, LEAVES:13)
Block(3,24,1,LEAVES:5)
Block(-5,24,2,LEAVES:13)
Block(-2,24,2, LEAVES:13)
Block(2,24,2,LEAVES:13)
Block(-4,24,3,LEAVES:13)
Block(-2,24,3, LEAVES:13)
Block(0,24,3,LEAVES:13)
Block(-4,24,4,LEAVES:13)
Block(-3,24,4,LEAVES:13)
Block(-1,24,4,LEAVES:13)
Block(-3,24,5,LEAVES:13)
Block(-2,24,5,LEAVES:13)
Block(-1,24,5, LEAVES:13)
Block(-4,24,6,LEAVES:13)
Block(-3,24,6,LEAVES:13)
Block(-2,24,6,LOG:12)
Block(-6,24,7,LEAVES:13)
Block(-5,24,7,LEAVES:13)
Block(-2,24,7,LEAVES:13)
Block(-7,24,8,LEAVES:13)
Block(-6,24,8,LEAVES:13)
Block(-1,24,8,LEAVES:13)
Block(-9,24,9,LEAVES:5)
Block(-11,24,10,LEAVES:5)
Block(-10,24,10,LEAVES:5)
Block(-7,25,-10, LEAVES:5)
Block(-7,25,-9, LEAVES:5)
Block(-6,25,-8, LEAVES:5)
Block(-6,25,-7, LEAVES:13)
Block(-5,25,-6, LEAVES:13)
Block(-5,25,-5, LEAVES:13)
Block(1,25,-5, LEAVES:13)
Block(2,25,-5, LEAVES:5)
Block(-5,25,-4, LEAVES:13)
Block(0,25,-4, LEAVES:13)
Block(1,25,-4, LEAVES:13)
Block(-4,25,-3, LEAVES:13)
Block(-3,25,-3,LOG:12)
Block(-2,25,-3, LEAVES:13)
Block(-1,25,-3, LEAVES:13)
Block(-6,25,-2, LEAVES:13)
Block(-5,25,-2, LEAVES:13)
Block(-4,25,-2,LOG:12)
Block(-3,25,-2, LEAVES:13)
Block(-9,25,-1, LEAVES:5)
Block(-8,25,-1, LEAVES:13)
Block(-7,25,-1, LEAVES:13)
Block(-3,25,-1, LEAVES:13)
Block(-10,25,0, LEAVES:5)
Block(-9,25,0, LEAVES:5)
Block(-6,25,0,LEAVES:13)
Block(-3,25,0, LEAVES:13)
Block(-5,25,1,LEAVES:13)
Block(-2,25,1, LEAVES:13)
Block(-5,25,2,LEAVES:13)
Block(-2,25,2, LEAVES:13)
Block(2,25,2,LEAVES:13)
Block(-4,25,3,LEAVES:13)
Block(-2,25,3, LEAVES:13)
Block(0,25,3,LEAVES:13)
Block(-4,25,4,LEAVES:13)
Block(-3,25,4,LEAVES:13)
Block(-2,25,4,LEAVES:13)
Block(-1,25,4,LEAVES:13)
Block(-3,25,5,LEAVES:13)
Block(-2,25,5,LEAVES:13)
Block(-1,25,5, LEAVES:13)
Block(-4,25,6,LEAVES:13)
Block(-3,25,6,LEAVES:13)
Block(-2,25,6,LOG:12)
Block(-1,25,6, LEAVES:13)
Block(-5,25,7,LEAVES:13)
Block(-2,25,7,LEAVES:13)
Block(0,25,7, LEAVES:13)
Block(-7,25,8,LEAVES:13)
Block(-1,25,8,LEAVES:13)
Block(-9,25,9,LEAVES:5)
Block(-8,25,9,LEAVES:5)
Block(0,25,9,LEAVES:13)
Block(-8,26,-11, LEAVES:5)
Block(-7,26,-10, LEAVES:5)
Block(-7,26,-9, LEAVES:5)
Block(-6,26,-8, LEAVES:5)
Block(-6,26,-7, LEAVES:13)
Block(-5,26,-6, LEAVES:13)
Block(-5,26,-5, LEAVES:13)
Block(1,26,-5, LEAVES:13)
Block(2,26,-5, LEAVES:5)
Block(3,26,-5, LEAVES:5)
Block(-5,26,-4, LEAVES:13)
Block(-4,26,-4, LEAVES:13)
Block(-1,26,-4, LEAVES:13)
Block(0,26,-4, LEAVES:13)
Block(1,26,-4, LEAVES:13)
Block(-4,26,-3, LEAVES:13)
Block(-3,26,-3,LOG:12)
Block(-2,26,-3, LEAVES:13)
Block(-1,26,-3, LEAVES:13)
Block(-6,26,-2, LEAVES:13)
Block(-5,26,-2, LEAVES:13)
Block(-4,26,-2,LOG:12)
Block(-3,26,-2, LEAVES:13)
Block(-8,26,-1, LEAVES:13)
Block(-7,26,-1, LEAVES:13)
Block(-3,26,-1, LEAVES:13)
Block(-11,26,0, LEAVES:5)
Block(-10,26,0, LEAVES:5)
Block(-9,26,0, LEAVES:5)
Block(-3,26,0, LEAVES:13)
Block(-12,26,1, LEAVES:5)
Block(-2,26,1, LEAVES:13)
Block(-5,26,2,LEAVES:13)
Block(-4,26,3,LEAVES:13)
Block(0,26,3,LEAVES:13)
Block(-4,26,4,LEAVES:13)
Block(-3,26,4,LEAVES:13)
Block(-1,26,4,LEAVES:13)
Block(-3,26,5,LEAVES:13)
Block(-2,26,5,LEAVES:13)
Block(-1,26,5, LEAVES:13)
Block(-4,26,6,LEAVES:13)
Block(-3,26,6,LOG:12)
Block(-2,26,6,LOG:12)
Block(-1,26,6, LEAVES:13)
Block(-6,26,7,LEAVES:13)
Block(-5,26,7,LEAVES:13)
Block(-2,26,7,LEAVES:13)
Block(0,26,7, LEAVES:13)
Block(-7,26,8,LEAVES:13)
Block(-1,26,13,LEAVES:5)
Block(-8,27,-12, LEAVES:5)
Block(-8,27,-11, LEAVES:5)
Block(-7,27,-10, LEAVES:5)
Block(-7,27,-9, LEAVES:5)
Block(-6,27,-8, LEAVES:5)
Block(-5,27,-6, LEAVES:13)
Block(-5,27,-5, LEAVES:13)
Block(2,27,-5, LEAVES:5)
Block(-5,27,-4, LEAVES:13)
Block(-4,27,-4, LEAVES:13)
Block(-1,27,-4, LEAVES:13)
Block(0,27,-4, LEAVES:13)
Block(-4,27,-3, LEAVES:13)
Block(-3,27,-3,LOG:12)
Block(-2,27,-3, LEAVES:13)
Block(-1,27,-3, LEAVES:13)
Block(-6,27,-2, LEAVES:13)
Block(-5,27,-2, LEAVES:13)
Block(-4,27,-2,LOG:12)
Block(-3,27,-2, LEAVES:13)
Block(-7,27,-1, LEAVES:13)
Block(-4,27,-1,LEAVES:13)
Block(-3,27,-1, LEAVES:13)
Block(-11,27,0, LEAVES:5)
Block(-10,27,0, LEAVES:5)
Block(-9,27,0, LEAVES:5)
Block(-3,27,0, LEAVES:13)
Block(-12,27,1, LEAVES:5)
Block(-3,27,1,LEAVES:13)
Block(-2,27,1, LEAVES:13)
Block(-2,27,2, LEAVES:13)
Block(-2,27,3, LEAVES:13)
Block(-3,27,4,LEAVES:13)
Block(-1,27,4, LEAVES:13)
Block(-3,27,5,LOG:12)
Block(-2,27,5,LOG:12)
Block(-1,27,5, LEAVES:13)
Block(-9,27,6,LEAVES:5)
Block(-8,27,6,LEAVES:5)
Block(-6,27,6,LEAVES:13)
Block(-3,27,6,LOG:12)
Block(-2,27,6,LOG:12)
Block(-1,27,6, LEAVES:13)
Block(0,27,7, LEAVES:13)
Block(-2,27,9,LEAVES:13)
Block(-2,27,10,LEAVES:13)
Block(-2,27,11,LEAVES:5)
Block(-2,27,12,LEAVES:5)
Block(-1,27,13,LEAVES:5)
Block(-8,28,-11, LEAVES:5)
Block(-7,28,-10, LEAVES:5)
Block(-7,28,-9, LEAVES:5)
Block(-6,28,-8, LEAVES:5)
Block(-6,28,-7, LEAVES:13)
Block(-5,28,-6, LEAVES:13)
Block(-5,28,-5, LEAVES:13)
Block(1,28,-5, LEAVES:13)
Block(2,28,-5, LEAVES:5)
Block(-5,28,-4, LEAVES:13)
Block(-4,28,-4, LEAVES:13)
Block(-1,28,-4, LEAVES:13)
Block(0,28,-4, LEAVES:13)
Block(-4,28,-3, LEAVES:13)
Block(-3,28,-3,LOG:12)
Block(-2,28,-3, LEAVES:13)
Block(-1,28,-3, LEAVES:13)
Block(-6,28,-2, LEAVES:13)
Block(-5,28,-2, LEAVES:13)
Block(-4,28,-2, LEAVES:13)
Block(-3,28,-2, LEAVES:13)
Block(-8,28,-1, LEAVES:13)
Block(-7,28,-1, LEAVES:13)
Block(-4,28,-1,LEAVES:13)
Block(-3,28,-1, LEAVES:13)
Block(-11,28,0, LEAVES:5)
Block(-10,28,0, LEAVES:5)
Block(-3,28,0,LEAVES:13)
Block(-13,28,1, LEAVES:5)
Block(-3,28,1,LEAVES:13)
Block(-2,28,1, LEAVES:13)
Block(-2,28,2, LEAVES:13)
Block(-3,28,3,LEAVES:13)
Block(-2,28,3, LEAVES:13)
Block(-3,28,4,LEAVES:13)
Block(-2,28,4,LEAVES:13)
Block(-1,28,4, LEAVES:13)
Block(-4,28,5,LEAVES:13)
Block(-3,28,5,LOG:12)
Block(-2,28,5,LEAVES:13)
Block(-1,28,5,LEAVES:13)
Block(-9,28,6,LEAVES:5)
Block(-8,28,6,LEAVES:5)
Block(-7,28,6,LEAVES:13)
Block(-6,28,6,LEAVES:13)
Block(-5,28,6,LEAVES:13)
Block(-4,28,6,LEAVES:13)
Block(-3,28,6,LOG:12)
Block(-2,28,6,LOG:12)
Block(-1,28,6,LEAVES:13)
Block(0,28,6,LEAVES:13)
Block(1,28,6,LEAVES:13)
Block(2,28,6,LEAVES:13)
Block(3,28,6,LEAVES:5)
Block(4,28,6,LEAVES:5)
Block(-3,28,7,LEAVES:13)
Block(-2,28,7,LEAVES:13)
Block(0,28,7, LEAVES:13)
Block(-3,28,8,LEAVES:13)
Block(-2,28,8,LEAVES:13)
Block(0,28,8, LEAVES:13)
Block(-2,28,9,LEAVES:13)
Block(-2,28,10,LEAVES:13)
Block(-2,28,11,LEAVES:5)
Block(-2,28,12,LEAVES:5)
Block(-1,28,13,LEAVES:5)
Block(-8,29,-11, LEAVES:5)
Block(-6,29,-8, LEAVES:5)
Block(-6,29,-7, LEAVES:13)
Block(-5,29,-6, LEAVES:13)
Block(-5,29,-5, LEAVES:13)
Block(-5,29,-4, LEAVES:13)
Block(-4,29,-4, LEAVES:13)
Block(0,29,-4, LEAVES:13)
Block(-4,29,-3, LEAVES:13)
Block(-3,29,-3, LEAVES:13)
Block(-2,29,-3, LEAVES:13)
Block(-6,29,-2, LEAVES:13)
Block(-5,29,-2, LEAVES:13)
Block(-4,29,-2,LOG:12)
Block(-3,29,-2,LOG:12)
Block(-8,29,-1, LEAVES:13)
Block(-7,29,-1, LEAVES:13)
Block(-3,29,-1, LEAVES:13)
Block(-11,29,0, LEAVES:5)
Block(-10,29,0, LEAVES:5)
Block(-9,29,0, LEAVES:5)
Block(-3,29,0, LEAVES:13)
Block(-13,29,1, LEAVES:5)
Block(-12,29,1, LEAVES:5)
Block(-3,29,1,LEAVES:13)
Block(-2,29,2, LEAVES:13)
Block(-3,29,3,LEAVES:13)
Block(-2,29,3, LEAVES:13)
Block(-3,29,4,LEAVES:13)
Block(-2,29,4,LEAVES:13)
Block(-1,29,4, LEAVES:13)
Block(-4,29,5,LEAVES:13)
Block(-3,29,5,LOG:12)
Block(-2,29,5,LEAVES:13)
Block(-1,29,5,LEAVES:13)
Block(-9,29,6,LEAVES:5)
Block(-8,29,6,LEAVES:5)
Block(-7,29,6,LEAVES:13)
Block(-6,29,6,LEAVES:13)
Block(-5,29,6,LEAVES:13)
Block(-4,29,6,LEAVES:13)
Block(-3,29,6,LOG:12)
Block(-2,29,6,LEAVES:13)
Block(-1,29,6,LEAVES:13)
Block(0,29,6,LEAVES:13)
Block(1,29,6,LEAVES:13)
Block(2,29,6,LEAVES:13)
Block(3,29,6,LEAVES:5)
Block(4,29,6,LEAVES:5)
Block(-3,29,7,LEAVES:13)
Block(-2,29,7,LEAVES:13)
Block(0,29,7, LEAVES:13)
Block(-3,29,8,LEAVES:13)
Block(-2,29,8,LEAVES:13)
Block(0,29,8, LEAVES:13)
Block(-2,29,9,LEAVES:13)
Block(-2,29,10,LEAVES:13)
Block(-2,29,11,LEAVES:5)
Block(-5,30,-5, LEAVES:13)
Block(-5,30,-4, LEAVES:13)
Block(-4,30,-4, LEAVES:13)
Block(-4,30,-3, LEAVES:13)
Block(-3,30,-3, LEAVES:13)
Block(-2,30,-3, LEAVES:13)
Block(-6,30,-2, LEAVES:13)
Block(-5,30,-2, LEAVES:13)
Block(-4,30,-2,LOG:12)
Block(-3,30,-2, LEAVES:13)
Block(-8,30,-1, LEAVES:13)
Block(-3,30,-1, LEAVES:13)
Block(-11,30,0, LEAVES:5)
Block(-3,30,0, LEAVES:13)
Block(-12,30,1, LEAVES:5)
Block(-3,30,1,LEAVES:13)
Block(-3,30,3,LEAVES:13)
Block(-3,30,4,LEAVES:13)
Block(-2,30,4,LEAVES:13)
Block(-1,30,4, LEAVES:13)
Block(-4,30,5,LEAVES:13)
Block(-3,30,5,LEAVES:13)
Block(-2,30,5,LEAVES:13)
Block(-1,30,5,LEAVES:13)
Block(-8,30,6,LEAVES:5)
Block(-7,30,6,LEAVES:13)
Block(-6,30,6,LEAVES:13)
Block(-5,30,6,LEAVES:13)
Block(-4,30,6,LEAVES:13)
Block(-3,30,6,LOG:12)
Block(-2,30,6,LEAVES:13)
Block(-1,30,6,LEAVES:13)
Block(0,30,6,LEAVES:13)
Block(1,30,6,LEAVES:13)
Block(2,30,6,LEAVES:13)
Block(-3,30,7,LEAVES:13)
Block(-2,30,7,LEAVES:13)
Block(-2,30,8,LEAVES:13)
Block(-2,30,9,LEAVES:13)
Block(-2,30,10,LEAVES:13)
Block(-2,30,11,LEAVES:5)
Block(-4,31,-3,LOG:12)
Block(-5,31,-2, LEAVES:13)
Block(-4,31,-2,LOG:12)
Block(-3,31,-2,LOG:12)
Block(0,31,-2, LEAVES:13)
Block(-3,31,3,LEAVES:13)
Block(-3,31,4,LEAVES:13)
Block(-4,31,5,LEAVES:13)
Block(-3,31,5,LOG:12)
Block(-2,31,5,LEAVES:13)
Block(-6,31,6,LEAVES:13)
Block(-5,31,6,LEAVES:13)
Block(-4,31,6,LEAVES:13)
Block(-3,31,6,LEAVES:13)
Block(-2,31,6,LEAVES:13)
Block(-1,31,6,LEAVES:13)
Block(0,31,6,LEAVES:13)
Block(1,31,6,LEAVES:13)
Block(-3,31,7,LEAVES:13)
Block(0,31,7,LEAVES:13)
Block(1,31,7,LEAVES:13)
Block(-2,31,8,LEAVES:13)
Block(1,31,8,LEAVES:13)
Block(2,31,8,LEAVES:13)
Block(-2,31,9,LEAVES:13)
Block(-3,32,-6, LEAVES:13)
Block(-3,32,-4, LEAVES:13)
Block(-6,32,-3, LEAVES:13)
Block(-4,32,-3, LEAVES:13)
Block(-3,32,-3, LEAVES:13)
Block(-4,32,-2,LOG:12)
Block(-3,32,-2,LOG:12)
Block(-2,32,-2, LEAVES:13)
Block(-1,32,-2, LEAVES:13)
Block(0,32,-2, LEAVES:13)
Block(1,32,-2, LEAVES:13)
Block(-4,32,-1, LEAVES:13)
Block(2,32,-1, LEAVES:5)
Block(-5,32,1, LEAVES:13)
Block(0,32,1,LEAVES:13)
Block(-5,32,2, LEAVES:13)
Block(-1,32,2,LEAVES:13)
Block(-6,32,3,LEAVES:13)
Block(-5,32,3,LEAVES:13)
Block(-1,32,3,LEAVES:13)
Block(-5,32,4,LEAVES:13)
Block(-4,32,4,LEAVES:13)
Block(-2,32,4,LEAVES:13)
Block(-4,32,5,LEAVES:13)
Block(-3,32,5,LEAVES:13)
Block(-2,32,5,LEAVES:13)
Block(-3,32,6,LEAVES:13)
Block(-2,32,6,LEAVES:13)
Block(-4,32,7,LEAVES:13)
Block(-1,32,7,LEAVES:13)
Block(0,32,7,LEAVES:13)
Block(1,32,7,LEAVES:13)
Block(-5,32,8,LEAVES:13)
Block(1,32,8,LEAVES:13)
Block(2,32,8,LEAVES:13)
Block(-6,32,9,LEAVES:13)
Block(-5,32,9,LEAVES:13)
Block(-7,32,10,LEAVES:13)
Block(-6,32,10,LEAVES:13)
Block(-7,32,11,LEAVES:5)
Block(-2,33,-8, LEAVES:5)
Block(-2,33,-7, LEAVES:5)
Block(-3,33,-6, LEAVES:13)
Block(-3,33,-5, LEAVES:13)
Block(-8,33,-4, LEAVES:13)
Block(-7,33,-4, LEAVES:13)
Block(-3,33,-4, LEAVES:13)
Block(-6,33,-3, LEAVES:13)
Block(-5,33,-3, LEAVES:13)
Block(-4,33,-3, LEAVES:13)
Block(-3,33,-3, LEAVES:13)
Block(-4,33,-2, LEAVES:13)
Block(-3,33,-2, LEAVES:13)
Block(-2,33,-2, LEAVES:13)
Block(-1,33,-2, LEAVES:13)
Block(0,33,-2, LEAVES:13)
Block(1,33,-2, LEAVES:13)
Block(-4,33,-1, LEAVES:13)
Block(2,33,-1, LEAVES:5)
Block(-4,33,0, LEAVES:13)
Block(-5,33,1, LEAVES:13)
Block(0,33,1,LEAVES:13)
Block(-5,33,2, LEAVES:13)
Block(-1,33,2,LEAVES:13)
Block(0,33,2,LEAVES:13)
Block(-6,33,3,LEAVES:13)
Block(-5,33,3,LEAVES:13)
Block(-1,33,3,LEAVES:13)
Block(-6,33,4, LEAVES:13)
Block(-5,33,4,LEAVES:13)
Block(-4,33,4,LEAVES:13)
Block(-2,33,4,LEAVES:13)
Block(-6,33,5, LEAVES:13)
Block(-4,33,5,LEAVES:13)
Block(-3,33,5,LEAVES:13)
Block(-2,33,5,LEAVES:13)
Block(-3,33,6,LEAVES:13)
Block(-2,33,6,LEAVES:13)
Block(-1,33,6,LEAVES:13)
Block(-4,33,7,LEAVES:13)
Block(-1,33,7,LEAVES:13)
Block(0,33,7,LEAVES:13)
Block(1,33,7,LEAVES:13)
Block(-5,33,8,LEAVES:13)
Block(1,33,8,LEAVES:13)
Block(2,33,8,LEAVES:5)
Block(-6,33,9,LEAVES:13)
Block(-5,33,9,LEAVES:13)
Block(-7,33,10,LEAVES:13)
Block(-6,33,10,LEAVES:13)
Block(-7,33,11,LEAVES:5)
Block(-2,34,-9, LEAVES:5)
Block(-2,34,-8, LEAVES:5)
Block(-2,34,-7, LEAVES:5)
Block(-3,34,-6, LEAVES:13)
Block(-3,34,-5, LEAVES:13)
Block(-8,34,-4, LEAVES:13)
Block(-7,34,-4, LEAVES:13)
Block(-3,34,-4, LEAVES:13)
Block(-6,34,-3, LEAVES:13)
Block(-5,34,-3, LEAVES:13)
Block(-4,34,-3, LEAVES:13)
Block(-3,34,-3, LEAVES:13)
Block(-4,34,-2, LEAVES:13)
Block(-3,34,-2, LEAVES:13)
Block(-2,34,-2, LEAVES:13)
Block(-1,34,-2, LEAVES:13)
Block(0,34,-2, LEAVES:13)
Block(1,34,-2, LEAVES:13)
Block(-4,34,-1, LEAVES:13)
Block(2,34,-1, LEAVES:5)
Block(-5,34,0, LEAVES:13)
Block(-4,34,0, LEAVES:13)
Block(-5,34,1, LEAVES:13)
Block(0,34,1,LEAVES:13)
Block(-5,34,2, LEAVES:13)
Block(-1,34,2,LEAVES:13)
Block(-6,34,3,LEAVES:13)
Block(-5,34,3,LEAVES:13)
Block(-1,34,3,LEAVES:13)
Block(-6,34,4, LEAVES:13)
Block(-5,34,4,LEAVES:13)
Block(-4,34,4,LEAVES:13)
Block(-2,34,4,LEAVES:13)
Block(-6,34,5, LEAVES:13)
Block(-4,34,5,LEAVES:13)
Block(-3,34,5,LEAVES:13)
Block(-2,34,5,LEAVES:13)
Block(-7,34,6, LEAVES:13)
Block(-3,34,6,LEAVES:13)
Block(-2,34,6,LEAVES:13)
Block(-1,34,6,LEAVES:13)
Block(-4,34,7,LEAVES:13)
Block(-1,34,7,LEAVES:13)
Block(0,34,7,LEAVES:13)
Block(-5,34,8,LEAVES:13)
Block(2,34,8,LEAVES:5)
Block(-6,34,9,LEAVES:13)
Block(-7,34,10,LEAVES:13)
Block(-6,34,10,LEAVES:13)
Block(-7,34,11,LEAVES:5)
Block(-8,34,12,LEAVES:5)
Block(-2,35,-9, LEAVES:5)
Block(-2,35,-8, LEAVES:5)
Block(-2,35,-7, LEAVES:5)
Block(-3,35,-6, LEAVES:13)
Block(-3,35,-5, LEAVES:13)
Block(-9,35,-4, LEAVES:5)
Block(-8,35,-4, LEAVES:13)
Block(-7,35,-4, LEAVES:13)
Block(-3,35,-4, LEAVES:13)
Block(-6,35,-3, LEAVES:13)
Block(-5,35,-3, LEAVES:13)
Block(-4,35,-3, LEAVES:13)
Block(-3,35,-3, LEAVES:13)
Block(-4,35,-2, LEAVES:13)
Block(-3,35,-2, LEAVES:13)
Block(-2,35,-2, LEAVES:13)
Block(-1,35,-2, LEAVES:13)
Block(0,35,-2, LEAVES:13)
Block(-4,35,-1, LEAVES:13)
Block(2,35,-1, LEAVES:5)
Block(-4,35,0, LEAVES:13)
Block(-5,35,1, LEAVES:13)
Block(0,35,1,LEAVES:13)
Block(-5,35,2, LEAVES:13)
Block(-1,35,2,LEAVES:13)
Block(-6,35,3,LEAVES:13)
Block(-5,35,3,LEAVES:13)
Block(-1,35,3,LEAVES:13)
Block(-6,35,4, LEAVES:13)
Block(-5,35,4,LEAVES:13)
Block(-4,35,4,LEAVES:13)
Block(-2,35,4,LEAVES:13)
Block(-6,35,5, LEAVES:13)
Block(-4,35,5,LEAVES:13)
Block(-3,35,5,LEAVES:13)
Block(-2,35,5,LEAVES:13)
Block(-3,35,6,LEAVES:13)
Block(-2,35,6,LEAVES:13)
Block(-1,35,6,LEAVES:13)
Block(-4,35,7,LEAVES:13)
Block(-1,35,7,LEAVES:13)
Block(0,35,7,LEAVES:13)
Block(1,35,7,LEAVES:13)
Block(-5,35,8,LEAVES:13)
Block(-6,35,9,LEAVES:13)
Block(-5,35,9,LEAVES:13)
Block(-7,35,11,LEAVES:5)
Block(-8,36,-4, LEAVES:13)
Block(-7,36,-4, LEAVES:13)
Block(-3,36,-4, LEAVES:13)
Block(-5,36,-3, LEAVES:13)
Block(-4,36,-3, LEAVES:13)
Block(-4,36,-2,LOG:12)
Block(-3,36,-2,LOG:12)
Block(-2,36,-2, LEAVES:13)
Block(-4,36,-1, LEAVES:13)
Block(-4,36,0, LEAVES:13)
Block(-1,36,2,LEAVES:13)
Block(-6,36,3, LEAVES:5)
Block(-5,36,3,LEAVES:5)
Block(-1,36,3,LEAVES:5)
Block(-5,36,4,LEAVES:5)
Block(-4,36,4,LEAVES:5)
Block(-2,36,4,LEAVES:5)
Block(-4,36,5,LEAVES:5)
Block(-3,36,5,LEAVES:5)
Block(-2,36,5,LEAVES:5)
Block(-3,36,6,LEAVES:5)
Block(-2,36,6,LEAVES:5)
Block(-1,36,6,LEAVES:5)
Block(-4,36,7,LEAVES:5)
Block(-2,36,7,LEAVES:5)
Block(0,36,7,LEAVES:5)
Block(-5,36,8,LEAVES:5)
Block(-6,36,9,LEAVES:5)
Block(-4,37,-2,LOG:0)
Block(-3,37,-2,LOG:0)
Block(0,37,3,LEAVES:5)
Block(-1,37,4,LEAVES:5)
Block(0,37,4,LEAVES:5)
Block(-3,37,5,LOG:0)
Block(-2,37,5,LEAVES:5)
Block(-3,37,6,LOG:0)
Block(-2,37,6,LEAVES:5)
Block(-2,37,7,LEAVES:5)
Block(-1,37,8,LEAVES:5)
Block(-1,37,9,LEAVES:5)
Block(-2,38,-5, LEAVES:13)
Block(-6,38,-4, LEAVES:13)
Block(-2,38,-4, LEAVES:13)
Block(-3,38,-3, LEAVES:13)
Block(-4,38,-2,LOG:0)
Block(-3,38,-2, LEAVES:13)
Block(-5,38,-1, LEAVES:13)
Block(-2,38,-1, LEAVES:13)
Block(-1,38,0, LEAVES:13)
Block(0,38,1, LEAVES:13)
Block(-5,38,2,LEAVES:13)
Block(-4,38,3,LEAVES:5)
Block(0,38,3,LEAVES:5)
Block(-4,38,4,LEAVES:5)
Block(-1,38,4,LEAVES:5)
Block(0,38,4,LEAVES:5)
Block(-3,38,5,LEAVES:5)
Block(-2,38,5,LEAVES:5)
Block(-1,38,5,LEAVES:5)
Block(-5,38,6,LEAVES:5)
Block(-4,38,6,LEAVES:5)
Block(-3,38,6,LEAVES:5)
Block(-2,38,6,LEAVES:5)
Block(-6,38,7,LEAVES:5)
Block(-2,38,7,LEAVES:5)
Block(-1,38,8,LEAVES:5)
Block(-1,38,9,LEAVES:5)
Block(-7,39,-5, LEAVES:13)
Block(-2,39,-5, LEAVES:13)
Block(-6,39,-4, LEAVES:13)
Block(-5,39,-4, LEAVES:13)
Block(-2,39,-4, LEAVES:13)
Block(-5,39,-3, LEAVES:13)
Block(-4,39,-3, LEAVES:13)
Block(-3,39,-3, LEAVES:13)
Block(-5,39,-2, LEAVES:13)
Block(-4,39,-2, LEAVES:13)
Block(-3,39,-2, LEAVES:13)
Block(-6,39,-1, LEAVES:13)
Block(-5,39,-1, LEAVES:13)
Block(-2,39,-1, LEAVES:13)
Block(-7,39,0, LEAVES:13)
Block(-6,39,0, LEAVES:13)
Block(-1,39,0, LEAVES:13)
Block(0,39,1, LEAVES:13)
Block(-5,39,2,LEAVES:13)
Block(-5,39,3,LEAVES:5)
Block(-4,39,3,LEAVES:5)
Block(0,39,3,LEAVES:5)
Block(-4,39,4,LEAVES:5)
Block(-1,39,4,LEAVES:5)
Block(0,39,4,LEAVES:5)
Block(-3,39,5,LEAVES:5)
Block(-2,39,5,LEAVES:5)
Block(-1,39,5,LEAVES:5)
Block(-5,39,6,LEAVES:5)
Block(-4,39,6,LEAVES:5)
Block(-3,39,6,LEAVES:5)
Block(-2,39,6,LEAVES:5)
Block(-7,39,7,LEAVES:5)
Block(-6,39,7,LEAVES:5)
Block(-2,39,7,LEAVES:5)
Block(-1,39,8,LEAVES:5)
Block(-1,39,9,LEAVES:5)
Block(-7,40,-5, LEAVES:13)
Block(-6,40,-4, LEAVES:13)
Block(-5,40,-4, LEAVES:13)
Block(-5,40,-3, LEAVES:13)
Block(-4,40,-3, LEAVES:13)
Block(-3,40,-3, LEAVES:13)
Block(-4,40,-2, LEAVES:13)
Block(-3,40,-2, LEAVES:13)
Block(-6,40,-1, LEAVES:13)
Block(-5,40,-1, LEAVES:13)
Block(-2,40,-1, LEAVES:13)
Block(-7,40,0, LEAVES:13)
Block(-6,40,0, LEAVES:13)
Block(-7,40,1, LEAVES:13)
Block(-5,40,2,LEAVES:13)
Block(-4,40,3,LEAVES:5)
Block(-4,40,4,LEAVES:5)
Block(-1,40,4,LEAVES:5)
Block(0,40,4,LEAVES:5)
Block(-3,40,5,LEAVES:5)
Block(-2,40,5,LEAVES:5)
Block(-1,40,5,LEAVES:5)
Block(-5,40,6,LEAVES:5)
Block(-4,40,6,LEAVES:5)
Block(-3,40,6,LEAVES:5)
Block(-2,40,6,LEAVES:5)
Block(-6,40,7,LEAVES:5)
Block(-2,40,7,LEAVES:5)
Block(-1,40,8,LEAVES:5)
Block(-4,41,-3, LEAVES:5)
Block(-4,41,-2,LOG:0)
Block(-5,41,2,LEAVES:5)
Block(-4,41,3,LEAVES:5)
Block(-4,41,4,LEAVES:5)
Block(-1,41,4,LEAVES:5)
Block(-3,41,5,LEAVES:5)
Block(-2,41,5,LEAVES:5)
Block(-5,41,6,LEAVES:5)
Block(-4,41,6,LEAVES:5)
Block(-3,41,6,LEAVES:5)
Block(-2,41,6,LEAVES:5)
Block(-6,41,7,LEAVES:5)
Block(-2,41,7,LEAVES:5)
Block(-1,41,8,LEAVES:5)
Block(-4,42,-2,LOG:0)
Block(-4,42,3,LEAVES:5)
Block(-4,42,4,LEAVES:5)
Block(-3,42,5,LEAVES:5)
Block(-2,42,5,LEAVES:5)
Block(-5,42,6,LEAVES:5)
Block(-4,42,6,LEAVES:5)
Block(-3,42,6,LEAVES:5)
Block(-2,42,7,LEAVES:5)
Block(-4,43,-2,LEAVES:5)
Block(-4,43,4,LEAVES:5)
Block(-4,43,6,LEAVES:5)
Block(-3,43,6,LEAVES:5)

#######################################################################
# +-----------------------------------------------------------------+ #
# |                            BO3 checks                           | #
# +-----------------------------------------------------------------+ #
#######################################################################

# Require a condition at a certain location in order for the BO3 to be spawned.
# BlockCheck(x,y,z,BlockName[,BlockName[,...]]) - one of the blocks must be at the location
# BlockCheckNot(x,y,z,BlockName[,BlockName[,...]]) - all the blocks must not be at the location
# LightCheck(x,y,z,minLightLevel,maxLightLevel) - light must be between min and max (inclusive)

# You can use "Solid" as a BlockName for matching all solid blocks or "All" to match all blocks that aren't air.

# Examples:
BlockCheck(0,-1,0,GRASS,DIRT,DIRT:2)
#   BlockCheck(0,-1,0,Solid)       Require any solid block just below the object
#   BlockCheck(0,-1,0,WOOL)        Require any type of wool just below the object
#   BlockCheck(0,-1,0,WOOL:0)      Require white wool just below the object
#   BlockCheckNot(0,-1,0,WOOL:0)   Require that there is no white wool below the object
#   LightCheck(0,0,0,0,1)          Require almost complete darkness just below the object

#######################################################################
# +-----------------------------------------------------------------+ #
# |                             Branches                            | #
# +-----------------------------------------------------------------+ #
#######################################################################

# Branches are objects that will spawn when this object spawns when it is used in
# the CustomStructure resource. Branches can also have branches, making complex
# structures possible. See the wiki for more details.

# Regular Branches spawn each branch with an independent chance of spawning.
# Branch(x,y,z,branchName,rotation,chance[,anotherBranchName,rotation,chance[,...]][IndividualChance])
# branchName - name of the object to spawn.
# rotation - NORTH, SOUTH, EAST or WEST.
# IndividualChance - The chance each branch has to spawn, assumed to be 100 when left blank

# Weighted Branches spawn branches with a dependent chance of spawning.
# WeightedBranch(x,y,z,branchName,rotation,chance[,anotherBranchName,rotation,chance[,...]][MaxChanceOutOf])
# MaxChanceOutOf - The chance all branches have to spawn out of, assumed to be 100 when left blank
 
