#######################################################################
# +-----------------------------------------------------------------+ #
# |                            BO3 object                           | #
# +-----------------------------------------------------------------+ #
#######################################################################

# The descriptions in this file are accurate only for TerrainControl and OTG.
# For MCW and OTG+ these descriptions are only accurate if the BO3 is used as a CustomObject.
# MCW and OTG+ completely reimplemented CustomStructure, check the MCW/OTG+ documentation for more information.

# This is the config file of a custom object.
# If you add this object correctly to your BiomeConfigs, it will spawn in the world.

# This is the creator of this BO3 object
Author: Unknown

# A short description of this BO3 object
Description: This BO3 was converted from a schematic using OTGEdit. The author and description information of the schematic could not be found. If you know who the author of the schematic is then please add this information.

# The BO3 version, don't change this! It can be used by external applications to do a version check.
Version: 3

# The settings mode, WriteAll, WriteWithoutComments or WriteDisable. See WorldConfig.
SettingsMode: WriteDisable

#######################################################################
# +-----------------------------------------------------------------+ #
# |                          Main settings                          | #
# +-----------------------------------------------------------------+ #
#######################################################################

# This needs to be set to true to spawn the object in the Tree and Sapling resources.
Tree: true

# The frequency of the BO3 from 1 to 200. Tries this many times to spawn this BO3 when using the CustomObject(...) resource.
# Ignored by Tree(..), Sapling(..) and CustomStructure(..)
Frequency: 40

# The rarity of the BO3 from 0 to 100. Each spawn attempt has rarity% chance to succeed when using the CustomObject(...) resource.
# Ignored by Tree(..), Sapling(..) and CustomStructure(..)
Rarity: 100.0

# If you set this to true, the BO3 will be placed with a random rotation.
RotateRandomly: true

# The spawn height of the BO3 - randomY, highestBlock or highestSolidBlock.
SpawnHeight: highestSolidBlock
SpawnHeightOffset: -1
# The height limits for the BO3.
MinHeight: 0

MaxHeight: 75

# Objects can have other objects attached to it: branches. Branches can also
# have branches attached to it, which can also have branches, etc. This is the
# maximum branch depth for this objects.
MaxBranchDepth: 10

# When spawned with the UseWorld keyword, this BO3 should NOT spawn in the following biomes.
# If you writer.write the BO3 name directly in the BiomeConfigs, this will be ignored.
ExcludedBiomes: All

# To optimise this BO3 for faster loading times you can use Notepad++ to find/replace comments and abbreviate things.
# Notepad++ find/replace with regex:
# Find: ^[#;].* replace to nothing removes all lines starting with # 
# Find: ^\s*$ replace to nothing removes most empty lines 
# Notepad++ find/replace without regex:
# *Warning: This will only work for OTG 1.10.2 v21 / OTG 1.11.2 v6 or higher. B( is not recognised by lower versions.
# Find: Block( replace to B(

#######################################################################
# +-----------------------------------------------------------------+ #
# |                      Source block settings                      | #
# +-----------------------------------------------------------------+ #
#######################################################################

# The block(s) the BO3 should spawn in.
SourceBlocks: AIR,GRASS,DIRT,DIRT:1,SAND

# The maximum percentage of the BO3 that can be outside the SourceBlock.
# The BO3 won't be placed on a location with more blocks outside the SourceBlock than this percentage.
MaxPercentageOutsideSourceBlock: 0

# What to do when a block is about to be placed outside the SourceBlock? (dontPlace, placeAnyway)
OutsideSourceBlock: dontPlace

#######################################################################
# +-----------------------------------------------------------------+ #
# |                              Blocks                             | #
# +-----------------------------------------------------------------+ #
#######################################################################

# All the blocks used in the BO3 are listed here. Possible blocks:
# Block(x,y,z,id[.data][,nbtfile.nbt) or B(x,y,z,id[.data][,nbtfile.nbt)
# RandomBlock(x,y,z,id[:data][,nbtfile.nbt],chance[,id[:data][,nbtfile.nbt],chance[,...]])
# So RandomBlock(0,0,0,CHEST,chest.nbt,50,CHEST,anotherchest.nbt,100) will spawn a chest at
# the BO3 origin, and give it a 50% chance to have the contents of chest.nbt, or, if that
# fails, a 100% percent chance to have the contents of anotherchest.nbt.

Block(4,9,15,LEAVES2:12)
Block(4,10,15,LEAVES2:12)
Block(4,11,14,LEAVES2:12)
Block(5,6,13,LEAVES2:12)
Block(5,6,15,LEAVES2:12)
Block(5,7,11,LEAVES2:12)
Block(5,8,11,LEAVES2:12)
Block(5,8,14,LEAVES2:12)
Block(5,9,10,LEAVES2:12)
Block(5,10,12,LEAVES2:12)
Block(5,11,12,LEAVES2:12)
Block(6,4,9,LEAVES2:12)
Block(6,4,11,LEAVES2:12)
Block(6,6,10,LEAVES2:12)
Block(6,7,14,162:12)
Block(6,8,8,LEAVES2:12)
Block(6,8,12,LEAVES2:12)
Block(6,8,13,LEAVES2:12)
Block(6,8,14,LEAVES2:12)
Block(6,9,8,LEAVES2:12)
Block(6,9,12,LEAVES2:12)
Block(6,11,15,LEAVES2:12)
Block(6,12,15,LEAVES2:12)
Block(7,5,10,162:12)
Block(7,6,8,LEAVES2:12)
Block(7,6,9,LEAVES2:12)
Block(7,6,10,LEAVES2:12)
Block(7,6,12,LEAVES2:12)
Block(7,6,14,LEAVES2:12)
Block(7,6,18,LEAVES2:12)
Block(7,7,8,LEAVES2:12)
Block(7,7,13,LEAVES2:12)
Block(7,7,14,162:12)
Block(7,7,18,LEAVES2:12)
Block(7,8,13,LEAVES2:12)
Block(7,8,14,LEAVES2:12)
Block(7,8,17,LEAVES2:12)
Block(7,9,11,LEAVES2:12)
Block(7,9,15,LEAVES2:12)
Block(7,10,11,LEAVES2:12)
Block(7,10,15,LEAVES2:12)
Block(7,12,13,LEAVES2:12)
Block(7,13,13,LEAVES2:12)
Block(7,14,13,LEAVES2:12)
Block(7,15,15,LEAVES2:12)
Block(7,16,15,LEAVES2:12)
Block(7,17,14,LEAVES2:12)
Block(8,3,16,LEAVES2:12)
Block(8,3,18,LEAVES2:12)
Block(8,4,8,LEAVES2:12)
Block(8,4,10,LEAVES2:12)
Block(8,5,9,LEAVES2:12)
Block(8,5,10,LEAVES2:12)
Block(8,5,11,162:12)
Block(8,5,17,LEAVES2:12)
Block(8,6,9,LEAVES2:12)
Block(8,6,10,LEAVES2:12)
Block(8,6,13,162:12)
Block(8,7,11,LEAVES2:12)
Block(8,7,13,162:12)
Block(8,7,15,LEAVES2:12)
Block(8,8,11,LEAVES2:12)
Block(8,8,15,LEAVES2:12)
Block(8,9,13,LEAVES2:12)
Block(8,10,9,LEAVES2:12)
Block(8,10,13,LEAVES2:12)
Block(8,11,9,LEAVES2:12)
Block(8,11,13,LEAVES2:12)
Block(8,12,9,LEAVES2:12)
Block(8,12,10,LEAVES2:12)
Block(8,12,13,LEAVES2:12)
Block(8,12,15,LEAVES2:12)
Block(8,13,10,LEAVES2:12)
Block(8,14,9,LEAVES2:12)
Block(8,14,14,LEAVES2:12)
Block(8,16,12,LEAVES2:12)
Block(8,17,12,LEAVES2:12)
Block(9,3,16,162:12)
Block(9,4,11,162:12)
Block(9,4,12,162:12)
Block(9,4,16,162:12)
Block(9,4,17,162:12)
Block(9,5,11,162:12)
Block(9,5,15,LEAVES2:12)
Block(9,5,16,LEAVES2:12)
Block(9,5,17,LEAVES2:12)
Block(9,6,13,162:12)
Block(9,6,15,LEAVES2:12)
Block(9,7,9,LEAVES2:12)
Block(9,8,9,LEAVES2:12)
Block(9,8,18,LEAVES2:12)
Block(9,9,8,LEAVES2:12)
Block(9,9,9,LEAVES2:12)
Block(9,9,10,LEAVES2:12)
Block(9,9,18,LEAVES2:12)
Block(9,11,9,LEAVES2:12)
Block(9,11,14,162:12)
Block(9,12,14,162:12)
Block(9,13,7,LEAVES2:12)
Block(9,13,14,162:12)
Block(9,14,7,LEAVES2:12)
Block(9,14,12,LEAVES2:12)
Block(9,14,13,LEAVES2:12)
Block(9,14,14,LEAVES2:12)
Block(9,15,12,LEAVES2:12)
Block(9,17,15,LEAVES2:12)
Block(9,18,15,LEAVES2:12)
Block(10,0,13,162:12)
Block(10,0,14,162:12)
Block(10,1,13,162:12)
Block(10,1,14,162:12)
Block(10,2,13,162:12)
Block(10,2,14,162:12)
Block(10,2,15,162:12)
Block(10,3,13,162:12)
Block(10,3,15,162:12)
Block(10,3,16,162:12)
Block(10,3,17,LEAVES2:12)
Block(10,4,12,162:12)
Block(10,4,13,162:12)
Block(10,4,16,LEAVES2:12)
Block(10,4,17,LEAVES2:12)
Block(10,5,16,LEAVES2:12)
Block(10,5,17,LEAVES2:12)
Block(10,6,13,162:12)
Block(10,6,18,LEAVES2:12)
Block(10,7,18,LEAVES2:12)
Block(10,8,14,162:12)
Block(10,9,14,162:12)
Block(10,9,16,LEAVES2:12)
Block(10,10,9,162:12)
Block(10,10,14,162:12)
Block(10,10,16,LEAVES2:12)
Block(10,11,7,LEAVES2:12)
Block(10,11,8,LEAVES2:12)
Block(10,11,9,LEAVES2:12)
Block(10,11,14,162:12)
Block(10,11,16,LEAVES2:12)
Block(10,12,7,LEAVES2:12)
Block(10,12,12,LEAVES2:12)
Block(10,12,14,LEAVES2:12)
Block(10,13,13,LEAVES2:12)
Block(10,13,14,LEAVES2:12)
Block(10,14,10,LEAVES2:12)
Block(10,14,13,LEAVES2:12)
Block(10,14,14,LEAVES2:12)
Block(10,15,10,LEAVES2:12)
Block(10,15,15,LEAVES2:12)
Block(10,16,15,LEAVES2:12)
Block(10,18,13,LEAVES2:12)
Block(10,19,13,LEAVES2:12)
Block(10,20,13,LEAVES2:12)
Block(11,4,13,162:12)
Block(11,4,18,LEAVES2:12)
Block(11,5,13,162:12)
Block(11,6,13,162:12)
Block(11,6,16,LEAVES2:12)
Block(11,7,13,162:12)
Block(11,7,16,LEAVES2:12)
Block(11,8,12,162:12)
Block(11,8,13,162:12)
Block(11,8,14,162:12)
Block(11,8,15,162:12)
Block(11,8,16,LEAVES2:12)
Block(11,9,7,LEAVES2:12)
Block(11,9,9,LEAVES2:12)
Block(11,9,10,162:12)
Block(11,9,11,162:12)
Block(11,9,12,162:12)
Block(11,10,8,LEAVES2:12)
Block(11,10,9,LEAVES2:12)
Block(11,10,10,162:12)
Block(11,11,8,LEAVES2:12)
Block(11,11,9,LEAVES2:12)
Block(11,11,14,162:12)
Block(11,11,18,LEAVES2:12)
Block(11,12,10,LEAVES2:12)
Block(11,12,14,162:12)
Block(11,12,18,LEAVES2:12)
Block(11,13,10,LEAVES2:12)
Block(11,13,15,LEAVES2:12)
Block(11,13,17,LEAVES2:12)
Block(11,14,14,LEAVES2:12)
Block(11,15,8,LEAVES2:12)
Block(11,15,13,LEAVES2:12)
Block(11,15,14,LEAVES2:12)
Block(11,16,8,LEAVES2:12)
Block(11,16,13,LEAVES2:12)
Block(11,17,8,LEAVES2:12)
Block(11,17,13,LEAVES2:12)
Block(12,6,13,162:12)
Block(12,8,15,162:12)
Block(12,8,16,LEAVES2:12)
Block(12,8,18,LEAVES2:12)
Block(12,9,12,LEAVES2:12)
Block(12,9,15,162:12)
Block(12,10,10,LEAVES2:12)
Block(12,10,12,LEAVES2:12)
Block(12,10,17,LEAVES2:12)
Block(12,11,11,LEAVES2:12)
Block(12,11,12,LEAVES2:12)
Block(12,11,14,LEAVES2:12)
Block(12,12,8,LEAVES2:12)
Block(12,12,13,162:12)
Block(12,12,15,LEAVES2:12)
Block(12,13,8,LEAVES2:12)
Block(12,13,13,LEAVES2:12)
Block(12,13,15,LEAVES2:12)
Block(12,14,8,LEAVES2:12)
Block(12,15,11,LEAVES2:12)
Block(12,16,11,LEAVES2:12)
Block(13,6,10,LEAVES2:12)
Block(13,6,12,LEAVES2:12)
Block(13,6,13,162:12)
Block(13,7,12,162:12)
Block(13,7,13,162:12)
Block(13,8,11,LEAVES2:12)
Block(13,9,16,162:12)
Block(13,9,17,162:12)
Block(13,10,9,LEAVES2:12)
Block(13,10,15,LEAVES2:12)
Block(13,10,16,LEAVES2:12)
Block(13,10,17,LEAVES2:12)
Block(13,11,9,LEAVES2:12)
Block(13,11,15,LEAVES2:12)
Block(13,12,13,162:12)
Block(13,13,11,LEAVES2:12)
Block(13,13,12,LEAVES2:12)
Block(13,13,13,LEAVES2:12)
Block(13,13,18,LEAVES2:12)
Block(13,14,11,LEAVES2:12)
Block(13,14,18,LEAVES2:12)
Block(13,16,14,LEAVES2:12)
Block(13,17,14,LEAVES2:12)
Block(14,7,11,162:12)
Block(14,8,9,LEAVES2:12)
Block(14,8,10,LEAVES2:12)
Block(14,8,11,LEAVES2:12)
Block(14,8,15,LEAVES2:12)
Block(14,8,17,LEAVES2:12)
Block(14,9,9,LEAVES2:12)
Block(14,9,16,LEAVES2:12)
Block(14,9,17,LEAVES2:12)
Block(14,10,16,LEAVES2:12)
Block(14,10,17,LEAVES2:12)
Block(14,11,11,LEAVES2:12)
Block(14,11,12,LEAVES2:12)
Block(14,11,13,LEAVES2:12)
Block(14,11,18,LEAVES2:12)
Block(14,12,12,LEAVES2:12)
Block(14,12,13,LEAVES2:12)
Block(14,12,18,LEAVES2:12)
Block(14,13,12,LEAVES2:12)
Block(14,13,13,LEAVES2:12)
Block(14,14,14,LEAVES2:12)
Block(14,14,16,LEAVES2:12)
Block(14,15,14,LEAVES2:12)
Block(14,15,16,LEAVES2:12)
Block(14,16,16,LEAVES2:12)
Block(14,17,12,LEAVES2:12)
Block(14,18,12,LEAVES2:12)
Block(14,19,12,LEAVES2:12)
Block(15,6,9,LEAVES2:12)
Block(15,6,11,LEAVES2:12)
Block(15,7,10,LEAVES2:12)
Block(15,7,11,LEAVES2:12)
Block(15,8,10,LEAVES2:12)
Block(15,8,11,LEAVES2:12)
Block(15,9,12,LEAVES2:12)
Block(15,9,18,LEAVES2:12)
Block(15,10,12,LEAVES2:12)
Block(15,11,16,LEAVES2:12)
Block(15,12,10,LEAVES2:12)
Block(15,12,14,LEAVES2:12)
Block(15,12,16,LEAVES2:12)
Block(15,13,10,LEAVES2:12)
Block(15,13,16,LEAVES2:12)
Block(15,14,10,LEAVES2:12)
Block(15,14,12,LEAVES2:12)
Block(15,15,12,LEAVES2:12)
Block(15,16,12,LEAVES2:12)
Block(16,7,12,LEAVES2:12)
Block(16,9,10,LEAVES2:12)
Block(16,10,10,LEAVES2:12)
Block(16,11,10,LEAVES2:12)


#######################################################################
# +-----------------------------------------------------------------+ #
# |                             Entities                            | #
# +-----------------------------------------------------------------+ #
#######################################################################

# Entity() spawns an entity instead of a block. The entity is spawned only once when the BO3 is spawned.
# Entities are persistent by default so they don't de-spawn when no player is near, they are only unloaded.
# Usage: Entity(x,y,z,mobName,groupSize,NameTagOrNBTFileName) or Entity(x,y,z,mobName,groupSize)
# Use /tc entities or /otg entities to get a list of entities that can be used as mobName, this includes entities added by other mods.
# NameTagOrNBTFileName can be either a nametag for the mob or an nbt file (such as mymobinfo.nbt or mymobinfo.txt).
# When using a text file you can use the same mob spawning parameters used with the /summon command to equip the
# entity and give it custom attributes etc. You can copy the DATA part of a summon command including surrounding
# curly braces to a .txt file, for instance for: "/summon Skeleton x y z {DATA}"

#######################################################################
# +-----------------------------------------------------------------+ #
# |                            BO3 checks                           | #
# +-----------------------------------------------------------------+ #
#######################################################################

# Require a condition at a certain location in order for the BO3 to be spawned.
# BlockCheck(x,y,z,BlockName[,BlockName[,...]]) - one of the blocks must be at the location
# BlockCheckNot(x,y,z,BlockName[,BlockName[,...]]) - all the blocks must not be at the location
# LightCheck(x,y,z,minLightLevel,maxLightLevel) - light must be between min and max (inclusive)

# You can use "Solid" as a BlockName for matching all solid blocks or "All" to match all blocks that aren't air.

# Examples:
BlockCheck(0,-1,0,GRASS,DIRT,DIRT:2,SAND)
#   BlockCheck(0,-1,0,Solid)       Require any solid block just below the object
#   BlockCheck(0,-1,0,WOOL)        Require any type of wool just below the object
#   BlockCheck(0,-1,0,WOOL:0)      Require white wool just below the object
#   BlockCheckNot(0,-1,0,WOOL:0)   Require that there is no white wool below the object
#   LightCheck(0,0,0,0,1)          Require almost complete darkness just below the object

