#######################################################################
# +-----------------------------------------------------------------+ #
# |                            BO3 object                           | #
# +-----------------------------------------------------------------+ #
#######################################################################

# The descriptions in this file are accurate only for TerrainControl and OTG.
# For MCW and OTG+ these descriptions are only accurate if the BO3 is used as a CustomObject.
# MCW and OTG+ completely reimplemented CustomStructure, check the MCW/OTG+ documentation for more information.

# This is the config file of a custom object.
# If you add this object correctly to your BiomeConfigs, it will spawn in the world.

# This is the creator of this BO3 object
Author: Unknown

# A short description of this BO3 object
Description: This BO3 was converted from a schematic using OTGEdit. The author and description information of the schematic could not be found. If you know who the author of the schematic is then please add this information.

# The BO3 version, don't change this! It can be used by external applications to do a version check.
Version: 3

# The settings mode, WriteAll, WriteWithoutComments or WriteDisable. See WorldConfig.
SettingsMode: WriteDisable

#######################################################################
# +-----------------------------------------------------------------+ #
# |                          Main settings                          | #
# +-----------------------------------------------------------------+ #
#######################################################################

# This needs to be set to true to spawn the object in the Tree and Sapling resources.
Tree: tree

# The frequency of the BO3 from 1 to 200. Tries this many times to spawn this BO3 when using the CustomObject(...) resource.
# Ignored by Tree(..), Sapling(..) and CustomStructure(..)
Frequency: 40

# The rarity of the BO3 from 0 to 100. Each spawn attempt has rarity% chance to succeed when using the CustomObject(...) resource.
# Ignored by Tree(..), Sapling(..) and CustomStructure(..)
Rarity: 100.0

# If you set this to true, the BO3 will be placed with a random rotation.
RotateRandomly: false

# The spawn height of the BO3 - randomY, highestBlock or highestSolidBlock.
SpawnHeight: highestSolidBlock
SpawnHeightOffset: -1
# The height limits for the BO3.
MinHeight: 0

MaxHeight: 256

# Objects can have other objects attached to it: branches. Branches can also
# have branches attached to it, which can also have branches, etc. This is the
# maximum branch depth for this objects.
MaxBranchDepth: 10

# When spawned with the UseWorld keyword, this BO3 should NOT spawn in the following biomes.
# If you writer.write the BO3 name directly in the BiomeConfigs, this will be ignored.
ExcludedBiomes: All

# To optimise this BO3 for faster loading times you can use Notepad++ to find/replace comments and abbreviate things.
# Notepad++ find/replace with regex:
# Find: ^[#;].* replace to nothing removes all lines starting with # 
# Find: ^\s*$ replace to nothing removes most empty lines 
# Notepad++ find/replace without regex:
# *Warning: This will only work for OTG 1.10.2 v21 / OTG 1.11.2 v6 or higher. B( is not recognised by lower versions.
# Find: Block( replace to B(

#######################################################################
# +-----------------------------------------------------------------+ #
# |                      Source block settings                      | #
# +-----------------------------------------------------------------+ #
#######################################################################

# The block(s) the BO3 should spawn in.
SourceBlocks: AIR,GRASS,DIRT,STONE

# The maximum percentage of the BO3 that can be outside the SourceBlock.
# The BO3 won't be placed on a location with more blocks outside the SourceBlock than this percentage.
MaxPercentageOutsideSourceBlock: 0

# What to do when a block is about to be placed outside the SourceBlock? (dontPlace, placeAnyway)
OutsideSourceBlock: dontPlace

#######################################################################
# +-----------------------------------------------------------------+ #
# |                              Blocks                             | #
# +-----------------------------------------------------------------+ #
#######################################################################

# All the blocks used in the BO3 are listed here. Possible blocks:
# Block(x,y,z,id[.data][,nbtfile.nbt) or B(x,y,z,id[.data][,nbtfile.nbt)
# RandomBlock(x,y,z,id[:data][,nbtfile.nbt],chance[,id[:data][,nbtfile.nbt],chance[,...]])
# So RandomBlock(0,0,0,CHEST,chest.nbt,50,CHEST,anotherchest.nbt,100) will spawn a chest at
# the BO3 origin, and give it a 50% chance to have the contents of chest.nbt, or, if that
# fails, a 100% percent chance to have the contents of anotherchest.nbt.

Block(-6,16,3,LEAVES:12)
Block(-5,8,9,LEAVES:12)
Block(-5,9,6,LEAVES:12)
Block(-5,9,8,LEAVES:12)
Block(-5,10,5,LEAVES:12)
Block(-5,15,2,LEAVES:12)
Block(-5,16,1,LEAVES:12)
Block(-5,16,2,LEAVES:12)
Block(-5,16,3,LEAVES:12)
Block(-5,16,4,LEAVES:12)
Block(-5,17,3,LEAVES:12)
Block(-5,17,6,LEAVES:12)
Block(-4,6,7,LEAVES:12)
Block(-4,6,11,LEAVES:12)
Block(-4,7,8,LEAVES:12)
Block(-4,7,10,LEAVES:12)
Block(-4,8,8,LEAVES:12)
Block(-4,8,9,LEAVES:12)
Block(-4,8,10,LEAVES:12)
Block(-4,9,5,LEAVES:12)
Block(-4,9,6,LEAVES:12)
Block(-4,9,7,LEAVES:12)
Block(-4,9,8,LEAVES:12)
Block(-4,9,9,LEAVES:12)
Block(-4,10,4,LEAVES:12)
Block(-4,10,5,LEAVES:12)
Block(-4,10,6,LEAVES:12)
Block(-4,10,8,LEAVES:12)
Block(-4,10,10,LEAVES:12)
Block(-4,11,5,LEAVES:12)
Block(-4,11,9,LEAVES:12)
Block(-4,12,10,LEAVES:12)
Block(-4,15,1,LEAVES:12)
Block(-4,15,2,LEAVES:12)
Block(-4,15,3,LEAVES:12)
Block(-4,16,0,LEAVES:12)
Block(-4,16,1,LEAVES:12)
Block(-4,16,2,LEAVES:12)
Block(-4,16,3,LEAVES:12)
Block(-4,17,0,LEAVES:12)
Block(-4,17,1,LEAVES:12)
Block(-4,17,2,LEAVES:12)
Block(-4,17,3,LEAVES:12)
Block(-4,17,4,LEAVES:12)
Block(-4,17,5,LEAVES:12)
Block(-4,17,6,LEAVES:12)
Block(-4,17,7,LEAVES:12)
Block(-4,18,-1,LEAVES:12)
Block(-4,18,3,LEAVES:12)
Block(-4,18,6,LEAVES:12)
Block(-4,19,2,LEAVES:12)
Block(-4,20,1,LEAVES:12)
Block(-4,20,6,LEAVES:12)
Block(-4,21,4,LEAVES:12)
Block(-4,21,5,LEAVES:12)
Block(-4,22,5,LEAVES:12)
Block(-4,22,8,LEAVES:12)
Block(-4,23,7,LEAVES:12)
Block(-3,6,6,LEAVES:12)
Block(-3,6,7,LEAVES:12)
Block(-3,6,8,LEAVES:12)
Block(-3,6,10,LEAVES:12)
Block(-3,6,11,LEAVES:12)
Block(-3,6,12,LEAVES:12)
Block(-3,7,7,LEAVES:12)
Block(-3,7,8,LEAVES:12)
Block(-3,7,9,LEAVES:12)
Block(-3,7,10,LEAVES:12)
Block(-3,7,11,LEAVES:12)
Block(-3,8,8,LEAVES:12)
Block(-3,8,9,LEAVES:12)
Block(-3,8,10,LEAVES:12)
Block(-3,9,4,LEAVES:12)
Block(-3,9,5,LEAVES:12)
Block(-3,9,6,LEAVES:12)
Block(-3,9,8,LEAVES:12)
Block(-3,9,9,LEAVES:12)
Block(-3,9,10,LEAVES:12)
Block(-3,10,5,LEAVES:12)
Block(-3,10,8,17:12)
Block(-3,10,9,LEAVES:12)
Block(-3,10,10,LEAVES:12)
Block(-3,10,11,LEAVES:12)
Block(-3,11,-3,LEAVES:12)
Block(-3,11,8,LEAVES:12)
Block(-3,11,9,LEAVES:12)
Block(-3,11,10,LEAVES:12)
Block(-3,12,-4,LEAVES:12)
Block(-3,12,9,LEAVES:12)
Block(-3,12,10,LEAVES:12)
Block(-3,12,11,LEAVES:12)
Block(-3,13,10,LEAVES:12)
Block(-3,14,-5,LEAVES:12)
Block(-3,14,-3,LEAVES:12)
Block(-3,15,-6,LEAVES:12)
Block(-3,15,-2,LEAVES:12)
Block(-3,15,1,LEAVES:12)
Block(-3,15,2,LEAVES:12)
Block(-3,16,1,LEAVES:12)
Block(-3,16,2,LEAVES:12)
Block(-3,16,3,LEAVES:12)
Block(-3,17,-1,LEAVES:12)
Block(-3,17,0,LEAVES:12)
Block(-3,17,1,LEAVES:12)
Block(-3,17,2,LEAVES:12)
Block(-3,17,3,LEAVES:12)
Block(-3,17,4,17:12)
Block(-3,17,5,LEAVES:12)
Block(-3,17,6,LEAVES:12)
Block(-3,18,-2,LEAVES:12)
Block(-3,18,-1,LEAVES:12)
Block(-3,18,0,LEAVES:12)
Block(-3,18,4,17:12)
Block(-3,18,5,LEAVES:12)
Block(-3,18,6,LEAVES:12)
Block(-3,18,7,LEAVES:12)
Block(-3,19,-1,LEAVES:12)
Block(-3,19,1,LEAVES:12)
Block(-3,19,2,LEAVES:12)
Block(-3,19,3,LEAVES:12)
Block(-3,19,5,LEAVES:12)
Block(-3,19,6,LEAVES:12)
Block(-3,20,0,LEAVES:12)
Block(-3,20,1,LEAVES:12)
Block(-3,20,2,LEAVES:12)
Block(-3,20,5,LEAVES:12)
Block(-3,20,6,LEAVES:12)
Block(-3,20,7,LEAVES:12)
Block(-3,21,1,LEAVES:12)
Block(-3,21,3,LEAVES:12)
Block(-3,21,4,LEAVES:12)
Block(-3,21,5,LEAVES:12)
Block(-3,21,6,LEAVES:12)
Block(-3,22,4,LEAVES:12)
Block(-3,22,5,LEAVES:12)
Block(-3,22,6,LEAVES:12)
Block(-3,22,7,LEAVES:12)
Block(-3,22,8,LEAVES:12)
Block(-3,22,9,LEAVES:12)
Block(-3,23,5,LEAVES:12)
Block(-3,23,6,LEAVES:12)
Block(-3,23,7,LEAVES:12)
Block(-3,23,8,LEAVES:12)
Block(-3,24,7,LEAVES:12)
Block(-3,24,9,LEAVES:12)
Block(-3,25,5,LEAVES:12)
Block(-3,25,8,LEAVES:12)
Block(-3,26,6,LEAVES:12)
Block(-3,27,8,LEAVES:12)
Block(-3,28,9,LEAVES:12)
Block(-2,6,7,LEAVES:12)
Block(-2,6,8,LEAVES:12)
Block(-2,6,9,LEAVES:12)
Block(-2,6,10,LEAVES:12)
Block(-2,6,11,LEAVES:12)
Block(-2,7,8,LEAVES:12)
Block(-2,7,9,LEAVES:12)
Block(-2,7,10,LEAVES:12)
Block(-2,8,8,LEAVES:12)
Block(-2,9,5,LEAVES:12)
Block(-2,9,8,17:12)
Block(-2,9,9,LEAVES:12)
Block(-2,10,7,LEAVES:12)
Block(-2,10,8,17:12)
Block(-2,10,9,LEAVES:12)
Block(-2,10,10,LEAVES:12)
Block(-2,11,-4,LEAVES:12)
Block(-2,11,-3,LEAVES:12)
Block(-2,11,-2,LEAVES:12)
Block(-2,11,9,LEAVES:12)
Block(-2,12,-5,LEAVES:12)
Block(-2,12,-4,LEAVES:12)
Block(-2,12,-3,LEAVES:12)
Block(-2,12,8,LEAVES:12)
Block(-2,12,9,LEAVES:12)
Block(-2,12,10,LEAVES:12)
Block(-2,13,-4,LEAVES:12)
Block(-2,13,9,LEAVES:12)
Block(-2,14,-6,LEAVES:12)
Block(-2,14,-5,LEAVES:12)
Block(-2,14,-4,LEAVES:12)
Block(-2,14,-3,LEAVES:12)
Block(-2,14,-2,LEAVES:12)
Block(-2,15,-7,LEAVES:12)
Block(-2,15,-6,LEAVES:12)
Block(-2,15,-5,LEAVES:12)
Block(-2,15,-3,LEAVES:12)
Block(-2,15,-2,LEAVES:12)
Block(-2,15,-1,LEAVES:12)
Block(-2,15,0,LEAVES:12)
Block(-2,15,1,LEAVES:12)
Block(-2,15,2,LEAVES:12)
Block(-2,16,-6,LEAVES:12)
Block(-2,16,-2,LEAVES:12)
Block(-2,16,0,LEAVES:12)
Block(-2,16,1,17:12)
Block(-2,16,2,LEAVES:12)
Block(-2,16,3,17:12)
Block(-2,17,-2,LEAVES:12)
Block(-2,17,-1,LEAVES:12)
Block(-2,17,0,LEAVES:12)
Block(-2,17,3,LEAVES:12)
Block(-2,17,5,LEAVES:12)
Block(-2,18,-3,LEAVES:12)
Block(-2,18,-2,LEAVES:12)
Block(-2,18,-1,LEAVES:12)
Block(-2,18,3,LEAVES:12)
Block(-2,18,4,LEAVES:12)
Block(-2,18,5,LEAVES:12)
Block(-2,18,6,LEAVES:12)
Block(-2,19,-2,LEAVES:12)
Block(-2,19,-1,LEAVES:12)
Block(-2,19,0,LEAVES:12)
Block(-2,19,1,LEAVES:12)
Block(-2,19,2,LEAVES:12)
Block(-2,19,4,LEAVES:12)
Block(-2,19,5,LEAVES:12)
Block(-2,19,6,LEAVES:12)
Block(-2,20,-1,LEAVES:12)
Block(-2,20,1,LEAVES:12)
Block(-2,20,2,LEAVES:12)
Block(-2,20,3,LEAVES:12)
Block(-2,20,5,LEAVES:12)
Block(-2,20,6,LEAVES:12)
Block(-2,21,2,LEAVES:12)
Block(-2,21,4,LEAVES:12)
Block(-2,21,5,LEAVES:12)
Block(-2,21,6,LEAVES:12)
Block(-2,21,7,LEAVES:12)
Block(-2,22,3,LEAVES:12)
Block(-2,22,4,LEAVES:12)
Block(-2,22,5,LEAVES:12)
Block(-2,22,6,LEAVES:12)
Block(-2,22,8,LEAVES:12)
Block(-2,23,-2,LEAVES:12)
Block(-2,23,4,LEAVES:12)
Block(-2,23,7,LEAVES:12)
Block(-2,23,8,LEAVES:12)
Block(-2,23,9,LEAVES:12)
Block(-2,24,8,LEAVES:12)
Block(-2,24,9,LEAVES:12)
Block(-2,24,10,LEAVES:12)
Block(-2,25,-1,LEAVES:12)
Block(-2,25,4,LEAVES:12)
Block(-2,25,5,LEAVES:12)
Block(-2,25,6,LEAVES:12)
Block(-2,25,7,LEAVES:12)
Block(-2,25,8,LEAVES:12)
Block(-2,25,9,LEAVES:12)
Block(-2,26,5,LEAVES:12)
Block(-2,26,6,LEAVES:12)
Block(-2,26,7,LEAVES:12)
Block(-2,26,8,LEAVES:12)
Block(-2,27,6,LEAVES:12)
Block(-2,27,7,LEAVES:12)
Block(-2,27,8,LEAVES:12)
Block(-2,27,9,LEAVES:12)
Block(-2,28,2,LEAVES:12)
Block(-2,28,8,LEAVES:12)
Block(-2,28,9,LEAVES:12)
Block(-2,28,10,LEAVES:12)
Block(-2,29,9,LEAVES:12)
Block(-1,0,2,17:12)
Block(-1,6,8,LEAVES:12)
Block(-1,6,9,LEAVES:12)
Block(-1,6,10,LEAVES:12)
Block(-1,7,9,LEAVES:12)
Block(-1,7,10,LEAVES:12)
Block(-1,7,11,LEAVES:12)
Block(-1,8,8,LEAVES:12)
Block(-1,8,9,17:12)
Block(-1,8,10,LEAVES:12)
Block(-1,8,11,17:12)
Block(-1,9,8,17:12)
Block(-1,9,9,17:12)
Block(-1,9,10,LEAVES:12)
Block(-1,9,12,LEAVES:12)
Block(-1,10,8,LEAVES:12)
Block(-1,10,9,LEAVES:12)
Block(-1,10,11,LEAVES:12)
Block(-1,11,-5,LEAVES:12)
Block(-1,11,-4,LEAVES:12)
Block(-1,11,-3,LEAVES:12)
Block(-1,11,11,LEAVES:12)
Block(-1,12,-5,LEAVES:12)
Block(-1,12,-4,LEAVES:12)
Block(-1,12,-3,17:12)
Block(-1,12,7,LEAVES:12)
Block(-1,12,9,LEAVES:12)
Block(-1,13,-3,17:12)
Block(-1,13,-2,17:12)
Block(-1,14,-5,LEAVES:12)
Block(-1,14,-4,LEAVES:12)
Block(-1,14,-3,LEAVES:12)
Block(-1,14,2,LEAVES:12)
Block(-1,15,-6,LEAVES:12)
Block(-1,15,-5,LEAVES:12)
Block(-1,15,-4,LEAVES:12)
Block(-1,15,-3,LEAVES:12)
Block(-1,15,-2,LEAVES:12)
Block(-1,15,-1,LEAVES:12)
Block(-1,15,0,LEAVES:12)
Block(-1,15,1,LEAVES:12)
Block(-1,15,2,LEAVES:12)
Block(-1,15,3,LEAVES:12)
Block(-1,16,-5,LEAVES:12)
Block(-1,16,-3,LEAVES:12)
Block(-1,16,-2,LEAVES:12)
Block(-1,16,-1,LEAVES:12)
Block(-1,16,0,LEAVES:12)
Block(-1,16,1,17:12)
Block(-1,16,2,17:12)
Block(-1,16,3,17:12)
Block(-1,16,5,LEAVES:12)
Block(-1,17,-2,LEAVES:12)
Block(-1,17,-1,LEAVES:12)
Block(-1,17,0,LEAVES:12)
Block(-1,17,1,17:12)
Block(-1,17,2,LEAVES:12)
Block(-1,17,3,LEAVES:12)
Block(-1,17,4,LEAVES:12)
Block(-1,17,5,LEAVES:12)
Block(-1,17,6,LEAVES:12)
Block(-1,17,10,LEAVES:12)
Block(-1,18,-2,LEAVES:12)
Block(-1,18,-1,17:12)
Block(-1,18,0,17:12)
Block(-1,18,1,LEAVES:12)
Block(-1,18,2,LEAVES:12)
Block(-1,18,3,LEAVES:12)
Block(-1,18,4,LEAVES:12)
Block(-1,18,5,LEAVES:12)
Block(-1,18,6,LEAVES:12)
Block(-1,18,9,LEAVES:12)
Block(-1,19,-1,LEAVES:12)
Block(-1,19,0,LEAVES:12)
Block(-1,19,1,LEAVES:12)
Block(-1,19,2,LEAVES:12)
Block(-1,19,5,LEAVES:12)
Block(-1,19,6,LEAVES:12)
Block(-1,19,7,LEAVES:12)
Block(-1,20,1,LEAVES:12)
Block(-1,20,2,LEAVES:12)
Block(-1,20,3,LEAVES:12)
Block(-1,20,5,17:12)
Block(-1,20,6,LEAVES:12)
Block(-1,20,9,LEAVES:12)
Block(-1,21,6,LEAVES:12)
Block(-1,21,7,17:12)
Block(-1,22,4,LEAVES:12)
Block(-1,23,-3,LEAVES:12)
Block(-1,23,-2,LEAVES:12)
Block(-1,23,-1,LEAVES:12)
Block(-1,23,6,LEAVES:12)
Block(-1,23,8,LEAVES:12)
Block(-1,24,-2,LEAVES:12)
Block(-1,24,9,LEAVES:12)
Block(-1,25,-2,LEAVES:12)
Block(-1,25,-1,LEAVES:12)
Block(-1,25,0,LEAVES:12)
Block(-1,25,5,LEAVES:12)
Block(-1,25,8,LEAVES:12)
Block(-1,25,9,LEAVES:12)
Block(-1,25,10,LEAVES:12)
Block(-1,26,-1,LEAVES:12)
Block(-1,26,4,LEAVES:12)
Block(-1,26,5,LEAVES:12)
Block(-1,26,6,LEAVES:12)
Block(-1,26,8,17:12)
Block(-1,26,9,LEAVES:12)
Block(-1,27,2,LEAVES:12)
Block(-1,27,5,LEAVES:12)
Block(-1,27,6,LEAVES:12)
Block(-1,27,8,LEAVES:12)
Block(-1,27,9,LEAVES:12)
Block(-1,27,10,LEAVES:12)
Block(-1,28,1,LEAVES:12)
Block(-1,28,2,LEAVES:12)
Block(-1,28,3,LEAVES:12)
Block(-1,28,9,LEAVES:12)
Block(-1,29,2,LEAVES:12)
Block(0,0,3,17:12)
Block(0,0,5,17:12)
Block(0,6,8,LEAVES:12)
Block(0,6,9,LEAVES:12)
Block(0,6,10,LEAVES:12)
Block(0,7,9,LEAVES:12)
Block(0,7,10,LEAVES:12)
Block(0,8,7,LEAVES:12)
Block(0,8,8,LEAVES:12)
Block(0,8,9,LEAVES:12)
Block(0,8,10,LEAVES:12)
Block(0,8,11,LEAVES:12)
Block(0,9,7,17:12)
Block(0,9,8,17:12)
Block(0,9,9,LEAVES:12)
Block(0,9,10,LEAVES:12)
Block(0,9,11,LEAVES:12)
Block(0,9,12,LEAVES:12)
Block(0,9,13,LEAVES:12)
Block(0,10,10,LEAVES:12)
Block(0,10,11,LEAVES:12)
Block(0,10,12,LEAVES:12)
Block(0,11,-4,LEAVES:12)
Block(0,11,-2,LEAVES:12)
Block(0,11,7,LEAVES:12)
Block(0,11,10,LEAVES:12)
Block(0,11,11,LEAVES:12)
Block(0,11,12,LEAVES:12)
Block(0,12,-6,LEAVES:12)
Block(0,12,-5,LEAVES:12)
Block(0,12,-4,LEAVES:12)
Block(0,12,6,LEAVES:12)
Block(0,12,7,LEAVES:12)
Block(0,12,8,LEAVES:12)
Block(0,12,9,LEAVES:12)
Block(0,12,10,LEAVES:12)
Block(0,12,11,LEAVES:12)
Block(0,13,-5,LEAVES:12)
Block(0,13,-2,17:12)
Block(0,13,7,LEAVES:12)
Block(0,13,9,LEAVES:12)
Block(0,14,-5,LEAVES:12)
Block(0,14,-4,17:12)
Block(0,14,1,LEAVES:12)
Block(0,14,2,LEAVES:12)
Block(0,14,3,LEAVES:12)
Block(0,15,-5,LEAVES:12)
Block(0,15,-4,LEAVES:12)
Block(0,15,-3,LEAVES:12)
Block(0,15,-2,LEAVES:12)
Block(0,15,-1,LEAVES:12)
Block(0,15,0,LEAVES:12)
Block(0,15,1,LEAVES:12)
Block(0,15,2,LEAVES:12)
Block(0,16,-2,LEAVES:12)
Block(0,16,-1,LEAVES:12)
Block(0,16,0,LEAVES:12)
Block(0,16,1,LEAVES:12)
Block(0,16,2,17:12)
Block(0,16,4,LEAVES:12)
Block(0,16,5,LEAVES:12)
Block(0,16,6,LEAVES:12)
Block(0,17,-1,LEAVES:12)
Block(0,17,1,LEAVES:12)
Block(0,17,2,17:12)
Block(0,17,3,LEAVES:12)
Block(0,17,4,LEAVES:12)
Block(0,17,5,LEAVES:12)
Block(0,17,7,LEAVES:12)
Block(0,17,9,LEAVES:12)
Block(0,17,10,LEAVES:12)
Block(0,17,11,LEAVES:12)
Block(0,18,0,LEAVES:12)
Block(0,18,1,LEAVES:12)
Block(0,18,2,LEAVES:12)
Block(0,18,3,LEAVES:12)
Block(0,18,4,LEAVES:12)
Block(0,18,5,LEAVES:12)
Block(0,18,8,LEAVES:12)
Block(0,18,9,LEAVES:12)
Block(0,18,10,LEAVES:12)
Block(0,19,1,LEAVES:12)
Block(0,19,2,LEAVES:12)
Block(0,19,3,LEAVES:12)
Block(0,19,6,LEAVES:12)
Block(0,19,9,LEAVES:12)
Block(0,20,2,LEAVES:12)
Block(0,20,3,LEAVES:12)
Block(0,20,4,LEAVES:12)
Block(0,20,6,LEAVES:12)
Block(0,20,8,LEAVES:12)
Block(0,20,9,LEAVES:12)
Block(0,20,10,LEAVES:12)
Block(0,21,3,LEAVES:12)
Block(0,21,5,17:12)
Block(0,21,6,17:12)
Block(0,21,7,17:12)
Block(0,21,8,LEAVES:12)
Block(0,21,9,LEAVES:12)
Block(0,22,-2,LEAVES:12)
Block(0,22,6,LEAVES:12)
Block(0,22,7,17:12)
Block(0,23,-2,LEAVES:12)
Block(0,23,-1,LEAVES:12)
Block(0,23,0,LEAVES:12)
Block(0,23,2,LEAVES:12)
Block(0,23,5,LEAVES:12)
Block(0,23,6,LEAVES:12)
Block(0,23,7,LEAVES:12)
Block(0,24,-3,LEAVES:12)
Block(0,24,-2,LEAVES:12)
Block(0,24,-1,LEAVES:12)
Block(0,24,1,LEAVES:12)
Block(0,24,5,LEAVES:12)
Block(0,24,6,17:12)
Block(0,24,7,17:12)
Block(0,25,-2,LEAVES:12)
Block(0,25,-1,LEAVES:12)
Block(0,25,0,LEAVES:12)
Block(0,25,1,LEAVES:12)
Block(0,25,2,LEAVES:12)
Block(0,25,6,17:12)
Block(0,25,9,LEAVES:12)
Block(0,26,-2,LEAVES:12)
Block(0,26,-1,LEAVES:12)
Block(0,26,0,LEAVES:12)
Block(0,26,2,LEAVES:12)
Block(0,26,5,LEAVES:12)
Block(0,26,9,LEAVES:12)
Block(0,27,-2,LEAVES:12)
Block(0,27,-1,LEAVES:12)
Block(0,27,0,LEAVES:12)
Block(0,27,1,LEAVES:12)
Block(0,27,2,LEAVES:12)
Block(0,27,3,LEAVES:12)
Block(0,27,5,LEAVES:12)
Block(0,27,6,LEAVES:12)
Block(0,27,7,LEAVES:12)
Block(0,27,8,LEAVES:12)
Block(0,27,9,LEAVES:12)
Block(0,28,-5,LEAVES:12)
Block(0,28,-1,LEAVES:12)
Block(0,28,0,LEAVES:12)
Block(0,28,1,LEAVES:12)
Block(0,28,2,LEAVES:12)
Block(0,28,6,LEAVES:12)
Block(0,29,1,LEAVES:12)
Block(1,0,3,17:12)
Block(1,0,4,17:12)
Block(1,0,5,17:12)
Block(1,0,6,17:12)
Block(1,0,9,17:12)
Block(1,1,5,17:12)
Block(1,1,8,17:12)
Block(1,2,5,17:12)
Block(1,3,5,17:12)
Block(1,6,9,LEAVES:12)
Block(1,6,10,LEAVES:12)
Block(1,6,11,LEAVES:12)
Block(1,7,8,LEAVES:12)
Block(1,7,9,LEAVES:12)
Block(1,7,10,LEAVES:12)
Block(1,8,5,17:12)
Block(1,8,6,17:12)
Block(1,8,8,LEAVES:12)
Block(1,8,9,LEAVES:12)
Block(1,8,10,LEAVES:12)
Block(1,9,6,17:12)
Block(1,9,7,17:12)
Block(1,9,8,17:12)
Block(1,9,9,LEAVES:12)
Block(1,9,10,LEAVES:12)
Block(1,9,11,LEAVES:12)
Block(1,9,12,LEAVES:12)
Block(1,10,8,LEAVES:12)
Block(1,10,9,17:12)
Block(1,10,11,LEAVES:12)
Block(1,10,12,LEAVES:12)
Block(1,10,13,LEAVES:12)
Block(1,11,-3,LEAVES:12)
Block(1,11,-2,LEAVES:12)
Block(1,11,-1,LEAVES:12)
Block(1,11,6,LEAVES:12)
Block(1,11,7,LEAVES:12)
Block(1,11,8,LEAVES:12)
Block(1,11,9,17:12)
Block(1,11,10,17:12)
Block(1,11,11,LEAVES:12)
Block(1,11,12,LEAVES:12)
Block(1,12,-7,LEAVES:12)
Block(1,12,-6,LEAVES:12)
Block(1,12,-5,LEAVES:12)
Block(1,12,-4,LEAVES:12)
Block(1,12,-2,17:12)
Block(1,12,-1,17:12)
Block(1,12,7,LEAVES:12)
Block(1,12,8,LEAVES:12)
Block(1,12,9,LEAVES:12)
Block(1,12,10,LEAVES:12)
Block(1,12,11,LEAVES:12)
Block(1,12,12,LEAVES:12)
Block(1,13,-6,LEAVES:12)
Block(1,13,-5,LEAVES:12)
Block(1,13,-4,LEAVES:12)
Block(1,13,-3,17:12)
Block(1,13,-2,17:12)
Block(1,13,8,LEAVES:12)
Block(1,13,10,LEAVES:12)
Block(1,13,11,LEAVES:12)
Block(1,14,-5,LEAVES:12)
Block(1,14,-4,LEAVES:12)
Block(1,14,-3,17:12)
Block(1,14,2,LEAVES:12)
Block(1,15,-5,LEAVES:12)
Block(1,15,-4,LEAVES:12)
Block(1,15,-3,LEAVES:12)
Block(1,15,-2,LEAVES:12)
Block(1,15,0,LEAVES:12)
Block(1,15,1,LEAVES:12)
Block(1,15,2,17:12)
Block(1,16,-4,LEAVES:12)
Block(1,16,-1,LEAVES:12)
Block(1,16,2,17:12)
Block(1,16,5,LEAVES:12)
Block(1,16,6,LEAVES:12)
Block(1,16,7,LEAVES:12)
Block(1,17,1,LEAVES:12)
Block(1,17,4,LEAVES:12)
Block(1,17,6,LEAVES:12)
Block(1,17,7,LEAVES:12)
Block(1,17,8,LEAVES:12)
Block(1,17,9,LEAVES:12)
Block(1,17,10,LEAVES:12)
Block(1,18,-6,LEAVES:12)
Block(1,18,1,LEAVES:12)
Block(1,18,2,LEAVES:12)
Block(1,18,7,LEAVES:12)
Block(1,18,9,LEAVES:12)
Block(1,18,10,17:12)
Block(1,19,2,LEAVES:12)
Block(1,19,3,LEAVES:12)
Block(1,19,4,LEAVES:12)
Block(1,19,6,LEAVES:12)
Block(1,20,1,LEAVES:12)
Block(1,20,2,LEAVES:12)
Block(1,20,3,LEAVES:12)
Block(1,20,5,LEAVES:12)
Block(1,20,6,LEAVES:12)
Block(1,20,7,LEAVES:12)
Block(1,20,9,LEAVES:12)
Block(1,20,10,LEAVES:12)
Block(1,20,11,LEAVES:12)
Block(1,21,-2,LEAVES:12)
Block(1,21,2,LEAVES:12)
Block(1,21,6,LEAVES:12)
Block(1,21,8,LEAVES:12)
Block(1,21,9,LEAVES:12)
Block(1,21,10,LEAVES:12)
Block(1,22,-3,LEAVES:12)
Block(1,22,-2,LEAVES:12)
Block(1,22,-1,LEAVES:12)
Block(1,22,5,LEAVES:12)
Block(1,22,6,LEAVES:12)
Block(1,22,7,17:12)
Block(1,22,9,LEAVES:12)
Block(1,23,-2,LEAVES:12)
Block(1,23,-1,LEAVES:12)
Block(1,23,1,LEAVES:12)
Block(1,23,2,LEAVES:12)
Block(1,23,3,LEAVES:12)
Block(1,23,4,LEAVES:12)
Block(1,23,5,LEAVES:12)
Block(1,23,6,LEAVES:12)
Block(1,23,7,17:12)
Block(1,24,-2,LEAVES:12)
Block(1,24,0,LEAVES:12)
Block(1,24,1,LEAVES:12)
Block(1,24,2,LEAVES:12)
Block(1,24,4,LEAVES:12)
Block(1,24,5,LEAVES:12)
Block(1,24,6,LEAVES:12)
Block(1,24,7,17:12)
Block(1,25,-4,LEAVES:12)
Block(1,25,-1,LEAVES:12)
Block(1,25,0,LEAVES:12)
Block(1,25,1,17:12)
Block(1,25,2,LEAVES:12)
Block(1,25,3,LEAVES:12)
Block(1,25,5,LEAVES:12)
Block(1,25,7,LEAVES:12)
Block(1,25,9,LEAVES:12)
Block(1,26,-3,LEAVES:12)
Block(1,26,-2,LEAVES:12)
Block(1,26,-1,LEAVES:12)
Block(1,26,1,17:12)
Block(1,26,2,LEAVES:12)
Block(1,26,3,LEAVES:12)
Block(1,26,8,LEAVES:12)
Block(1,26,9,LEAVES:12)
Block(1,26,10,LEAVES:12)
Block(1,27,-3,LEAVES:12)
Block(1,27,-2,LEAVES:12)
Block(1,27,-1,LEAVES:12)
Block(1,27,0,LEAVES:12)
Block(1,27,1,LEAVES:12)
Block(1,27,2,LEAVES:12)
Block(1,27,6,LEAVES:12)
Block(1,27,7,LEAVES:12)
Block(1,27,8,LEAVES:12)
Block(1,27,9,LEAVES:12)
Block(1,28,-6,LEAVES:12)
Block(1,28,-5,LEAVES:12)
Block(1,28,-4,LEAVES:12)
Block(1,28,-2,LEAVES:12)
Block(1,28,-1,LEAVES:12)
Block(1,28,0,LEAVES:12)
Block(1,28,1,LEAVES:12)
Block(1,28,5,LEAVES:12)
Block(1,28,6,LEAVES:12)
Block(1,28,7,LEAVES:12)
Block(1,29,-5,LEAVES:12)
Block(1,29,-1,LEAVES:12)
Block(1,29,6,LEAVES:12)
Block(2,0,4,17:12)
Block(2,0,6,17:12)
Block(2,0,8,17:12)
Block(2,1,4,17:12)
Block(2,1,5,17:12)
Block(2,1,6,17:12)
Block(2,1,7,17:12)
Block(2,1,8,17:12)
Block(2,2,4,17:12)
Block(2,2,5,17:12)
Block(2,2,6,17:12)
Block(2,2,7,17:12)
Block(2,3,4,17:12)
Block(2,3,5,17:12)
Block(2,3,6,17:12)
Block(2,4,4,17:12)
Block(2,4,5,17:12)
Block(2,5,4,17:12)
Block(2,5,5,17:12)
Block(2,6,4,17:12)
Block(2,6,5,17:12)
Block(2,6,10,LEAVES:12)
Block(2,7,3,17:12)
Block(2,7,4,17:12)
Block(2,7,5,17:12)
Block(2,7,9,LEAVES:12)
Block(2,8,2,17:12)
Block(2,8,3,17:12)
Block(2,8,4,17:12)
Block(2,8,5,17:12)
Block(2,9,2,17:12)
Block(2,9,3,17:12)
Block(2,9,5,17:12)
Block(2,9,6,17:12)
Block(2,9,8,LEAVES:12)
Block(2,9,9,LEAVES:12)
Block(2,9,10,LEAVES:12)
Block(2,9,11,LEAVES:12)
Block(2,10,3,17:12)
Block(2,10,7,LEAVES:12)
Block(2,10,8,LEAVES:12)
Block(2,10,9,LEAVES:12)
Block(2,10,11,LEAVES:12)
Block(2,10,12,LEAVES:12)
Block(2,11,-4,LEAVES:12)
Block(2,11,-3,LEAVES:12)
Block(2,11,-2,LEAVES:12)
Block(2,11,-1,LEAVES:12)
Block(2,11,0,LEAVES:12)
Block(2,11,7,LEAVES:12)
Block(2,11,8,LEAVES:12)
Block(2,11,10,17:12)
Block(2,12,-8,LEAVES:12)
Block(2,12,-7,LEAVES:12)
Block(2,12,-6,LEAVES:12)
Block(2,12,-5,LEAVES:12)
Block(2,12,-4,LEAVES:12)
Block(2,12,-3,LEAVES:12)
Block(2,12,-2,17:12)
Block(2,12,-1,17:12)
Block(2,12,0,17:12)
Block(2,12,8,LEAVES:12)
Block(2,12,10,LEAVES:12)
Block(2,12,11,LEAVES:12)
Block(2,12,12,LEAVES:12)
Block(2,12,13,LEAVES:12)
Block(2,13,-7,LEAVES:12)
Block(2,13,-6,LEAVES:12)
Block(2,13,-5,LEAVES:12)
Block(2,13,-4,LEAVES:12)
Block(2,13,10,LEAVES:12)
Block(2,13,11,LEAVES:12)
Block(2,13,12,LEAVES:12)
Block(2,14,-6,LEAVES:12)
Block(2,14,-5,LEAVES:12)
Block(2,14,-4,LEAVES:12)
Block(2,14,-3,LEAVES:12)
Block(2,14,2,17:12)
Block(2,14,11,LEAVES:12)
Block(2,15,-4,LEAVES:12)
Block(2,15,-3,LEAVES:12)
Block(2,15,-2,LEAVES:12)
Block(2,15,-1,LEAVES:12)
Block(2,15,0,LEAVES:12)
Block(2,15,1,LEAVES:12)
Block(2,15,2,17:12)
Block(2,16,-3,LEAVES:12)
Block(2,16,0,LEAVES:12)
Block(2,16,2,17:12)
Block(2,16,6,LEAVES:12)
Block(2,16,11,LEAVES:12)
Block(2,17,5,LEAVES:12)
Block(2,17,6,LEAVES:12)
Block(2,17,7,LEAVES:12)
Block(2,17,9,LEAVES:12)
Block(2,17,10,LEAVES:12)
Block(2,18,-7,LEAVES:12)
Block(2,18,-6,LEAVES:12)
Block(2,18,-5,LEAVES:12)
Block(2,18,-2,LEAVES:12)
Block(2,18,6,LEAVES:12)
Block(2,18,8,LEAVES:12)
Block(2,18,9,17:12)
Block(2,19,-6,LEAVES:12)
Block(2,19,3,LEAVES:12)
Block(2,19,5,LEAVES:12)
Block(2,19,6,LEAVES:12)
Block(2,19,7,LEAVES:12)
Block(2,19,8,17:12)
Block(2,19,9,17:12)
Block(2,20,-4,17:12)
Block(2,20,2,LEAVES:12)
Block(2,20,6,LEAVES:12)
Block(2,20,7,LEAVES:12)
Block(2,20,8,LEAVES:12)
Block(2,20,9,LEAVES:12)
Block(2,20,10,LEAVES:12)
Block(2,21,-3,LEAVES:12)
Block(2,21,-2,LEAVES:12)
Block(2,21,-1,LEAVES:12)
Block(2,21,7,17:12)
Block(2,21,9,LEAVES:12)
Block(2,21,10,LEAVES:12)
Block(2,21,11,LEAVES:12)
Block(2,21,12,LEAVES:12)
Block(2,22,-6,LEAVES:12)
Block(2,22,-4,LEAVES:12)
Block(2,22,-3,LEAVES:12)
Block(2,22,-2,LEAVES:12)
Block(2,22,4,LEAVES:12)
Block(2,22,6,LEAVES:12)
Block(2,22,7,17:12)
Block(2,22,10,LEAVES:12)
Block(2,22,11,LEAVES:12)
Block(2,23,-3,LEAVES:12)
Block(2,23,-2,LEAVES:12)
Block(2,23,0,17:12)
Block(2,23,1,LEAVES:12)
Block(2,23,2,LEAVES:12)
Block(2,23,4,LEAVES:12)
Block(2,23,5,LEAVES:12)
Block(2,23,6,LEAVES:12)
Block(2,23,9,LEAVES:12)
Block(2,24,-1,LEAVES:12)
Block(2,24,0,LEAVES:12)
Block(2,24,1,LEAVES:12)
Block(2,24,2,LEAVES:12)
Block(2,24,3,LEAVES:12)
Block(2,24,5,LEAVES:12)
Block(2,24,6,LEAVES:12)
Block(2,24,7,LEAVES:12)
Block(2,24,8,LEAVES:12)
Block(2,25,-5,LEAVES:12)
Block(2,25,-4,LEAVES:12)
Block(2,25,-3,LEAVES:12)
Block(2,25,-2,LEAVES:12)
Block(2,25,-1,LEAVES:12)
Block(2,25,2,LEAVES:12)
Block(2,25,6,LEAVES:12)
Block(2,25,7,LEAVES:12)
Block(2,25,8,LEAVES:12)
Block(2,25,9,LEAVES:12)
Block(2,25,10,LEAVES:12)
Block(2,26,-4,LEAVES:12)
Block(2,26,-3,LEAVES:12)
Block(2,26,-2,LEAVES:12)
Block(2,26,-1,LEAVES:12)
Block(2,26,1,LEAVES:12)
Block(2,26,2,LEAVES:12)
Block(2,26,7,LEAVES:12)
Block(2,26,8,LEAVES:12)
Block(2,26,9,LEAVES:12)
Block(2,27,-3,LEAVES:12)
Block(2,27,-2,LEAVES:12)
Block(2,27,-1,LEAVES:12)
Block(2,27,0,LEAVES:12)
Block(2,27,1,LEAVES:12)
Block(2,27,2,LEAVES:12)
Block(2,27,3,LEAVES:12)
Block(2,27,7,LEAVES:12)
Block(2,27,8,LEAVES:12)
Block(2,28,-5,LEAVES:12)
Block(2,28,-4,LEAVES:12)
Block(2,28,-3,LEAVES:12)
Block(2,28,-2,LEAVES:12)
Block(2,28,-1,LEAVES:12)
Block(2,28,0,LEAVES:12)
Block(2,28,1,LEAVES:12)
Block(2,28,2,LEAVES:12)
Block(2,28,6,LEAVES:12)
Block(2,29,-6,LEAVES:12)
Block(2,29,-5,LEAVES:12)
Block(2,29,-4,LEAVES:12)
Block(2,29,-2,LEAVES:12)
Block(2,29,1,LEAVES:12)
Block(2,30,-5,LEAVES:12)
Block(3,0,6,17:12)
Block(3,0,7,17:12)
Block(3,0,8,17:12)
Block(3,1,5,17:12)
Block(3,1,6,17:12)
Block(3,1,7,17:12)
Block(3,2,5,17:12)
Block(3,2,6,17:12)
Block(3,2,7,17:12)
Block(3,3,5,17:12)
Block(3,3,6,17:12)
Block(3,3,7,17:12)
Block(3,4,4,17:12)
Block(3,4,5,17:12)
Block(3,4,6,17:12)
Block(3,4,7,17:12)
Block(3,5,4,17:12)
Block(3,5,5,17:12)
Block(3,5,6,17:12)
Block(3,5,7,17:12)
Block(3,6,4,17:12)
Block(3,6,5,17:12)
Block(3,6,6,17:12)
Block(3,7,3,17:12)
Block(3,7,4,17:12)
Block(3,7,5,17:12)
Block(3,7,6,17:12)
Block(3,8,2,17:12)
Block(3,8,3,17:12)
Block(3,8,4,17:12)
Block(3,8,5,17:12)
Block(3,9,2,17:12)
Block(3,9,3,17:12)
Block(3,9,4,17:12)
Block(3,9,7,LEAVES:12)
Block(3,9,8,LEAVES:12)
Block(3,9,9,LEAVES:12)
Block(3,9,10,LEAVES:12)
Block(3,9,11,LEAVES:12)
Block(3,9,12,LEAVES:12)
Block(3,10,2,17:12)
Block(3,10,3,17:12)
Block(3,10,4,17:12)
Block(3,10,8,LEAVES:12)
Block(3,10,11,LEAVES:12)
Block(3,10,12,LEAVES:12)
Block(3,10,13,LEAVES:12)
Block(3,11,-3,LEAVES:12)
Block(3,11,-1,LEAVES:12)
Block(3,11,0,17:12)
Block(3,11,1,17:12)
Block(3,11,2,17:12)
Block(3,11,3,17:12)
Block(3,11,4,17:12)
Block(3,11,12,LEAVES:12)
Block(3,12,-7,LEAVES:12)
Block(3,12,-4,LEAVES:12)
Block(3,12,-3,17:12)
Block(3,12,-2,17:12)
Block(3,12,0,17:12)
Block(3,12,1,17:12)
Block(3,12,2,17:12)
Block(3,12,3,17:12)
Block(3,12,4,17:12)
Block(3,12,8,LEAVES:12)
Block(3,12,10,LEAVES:12)
Block(3,12,12,LEAVES:12)
Block(3,13,-8,LEAVES:12)
Block(3,13,-7,LEAVES:12)
Block(3,13,-6,LEAVES:12)
Block(3,13,-4,17:12)
Block(3,13,-3,17:12)
Block(3,13,3,17:12)
Block(3,13,9,LEAVES:12)
Block(3,13,11,LEAVES:12)
Block(3,13,12,LEAVES:12)
Block(3,13,13,LEAVES:12)
Block(3,14,-7,LEAVES:12)
Block(3,14,-6,LEAVES:12)
Block(3,14,-4,LEAVES:12)
Block(3,14,-3,LEAVES:12)
Block(3,14,-2,LEAVES:12)
Block(3,14,2,17:12)
Block(3,14,3,17:12)
Block(3,14,4,17:12)
Block(3,14,12,LEAVES:12)
Block(3,15,-3,LEAVES:12)
Block(3,15,0,LEAVES:12)
Block(3,15,2,17:12)
Block(3,15,3,17:12)
Block(3,15,7,LEAVES:12)
Block(3,16,1,17:12)
Block(3,16,2,17:12)
Block(3,16,10,LEAVES:12)
Block(3,16,11,LEAVES:12)
Block(3,16,12,LEAVES:12)
Block(3,17,1,17:12)
Block(3,17,2,17:12)
Block(3,17,6,LEAVES:12)
Block(3,17,8,LEAVES:12)
Block(3,17,9,LEAVES:12)
Block(3,17,10,LEAVES:12)
Block(3,17,11,LEAVES:12)
Block(3,18,-6,LEAVES:12)
Block(3,18,-5,LEAVES:12)
Block(3,18,-4,LEAVES:12)
Block(3,18,-3,LEAVES:12)
Block(3,18,-2,LEAVES:12)
Block(3,18,-1,LEAVES:12)
Block(3,18,0,17:12)
Block(3,18,1,17:12)
Block(3,18,8,LEAVES:12)
Block(3,18,10,LEAVES:12)
Block(3,19,-7,LEAVES:12)
Block(3,19,-6,LEAVES:12)
Block(3,19,-5,LEAVES:12)
Block(3,19,-2,LEAVES:12)
Block(3,19,0,17:12)
Block(3,19,1,17:12)
Block(3,19,6,LEAVES:12)
Block(3,19,7,17:12)
Block(3,19,8,17:12)
Block(3,20,-6,LEAVES:12)
Block(3,20,-4,17:12)
Block(3,20,-3,17:12)
Block(3,20,0,17:12)
Block(3,20,1,17:12)
Block(3,20,7,LEAVES:12)
Block(3,20,8,LEAVES:12)
Block(3,20,9,LEAVES:12)
Block(3,21,-6,LEAVES:12)
Block(3,21,-4,LEAVES:12)
Block(3,21,-2,LEAVES:12)
Block(3,21,0,17:12)
Block(3,21,5,LEAVES:12)
Block(3,21,7,LEAVES:12)
Block(3,21,8,LEAVES:12)
Block(3,21,9,LEAVES:12)
Block(3,21,10,LEAVES:12)
Block(3,21,11,LEAVES:12)
Block(3,21,12,LEAVES:12)
Block(3,21,13,LEAVES:12)
Block(3,22,-7,LEAVES:12)
Block(3,22,-6,LEAVES:12)
Block(3,22,-5,LEAVES:12)
Block(3,22,-4,LEAVES:12)
Block(3,22,-3,LEAVES:12)
Block(3,22,0,17:12)
Block(3,22,3,LEAVES:12)
Block(3,22,4,LEAVES:12)
Block(3,22,5,LEAVES:12)
Block(3,22,7,17:12)
Block(3,22,8,LEAVES:12)
Block(3,22,9,LEAVES:12)
Block(3,22,10,LEAVES:12)
Block(3,22,11,LEAVES:12)
Block(3,22,12,LEAVES:12)
Block(3,23,-6,LEAVES:12)
Block(3,23,-3,LEAVES:12)
Block(3,23,-2,LEAVES:12)
Block(3,23,-1,LEAVES:12)
Block(3,23,0,17:12)
Block(3,23,1,LEAVES:12)
Block(3,23,4,LEAVES:12)
Block(3,23,5,LEAVES:12)
Block(3,23,6,LEAVES:12)
Block(3,23,8,LEAVES:12)
Block(3,23,9,LEAVES:12)
Block(3,23,10,LEAVES:12)
Block(3,23,11,LEAVES:12)
Block(3,24,-2,LEAVES:12)
Block(3,24,-1,LEAVES:12)
Block(3,24,0,LEAVES:12)
Block(3,24,1,LEAVES:12)
Block(3,24,2,LEAVES:12)
Block(3,24,5,LEAVES:12)
Block(3,24,6,LEAVES:12)
Block(3,24,7,LEAVES:12)
Block(3,24,8,LEAVES:12)
Block(3,24,9,LEAVES:12)
Block(3,25,-4,LEAVES:12)
Block(3,25,-3,LEAVES:12)
Block(3,25,-2,LEAVES:12)
Block(3,25,-1,LEAVES:12)
Block(3,25,0,LEAVES:12)
Block(3,25,6,LEAVES:12)
Block(3,25,7,LEAVES:12)
Block(3,25,8,LEAVES:12)
Block(3,25,9,LEAVES:12)
Block(3,25,10,LEAVES:12)
Block(3,26,-5,LEAVES:12)
Block(3,26,-4,LEAVES:12)
Block(3,26,-3,LEAVES:12)
Block(3,26,-2,LEAVES:12)
Block(3,26,-1,LEAVES:12)
Block(3,26,0,LEAVES:12)
Block(3,26,1,LEAVES:12)
Block(3,26,2,LEAVES:12)
Block(3,26,3,LEAVES:12)
Block(3,26,7,LEAVES:12)
Block(3,26,8,LEAVES:12)
Block(3,26,9,LEAVES:12)
Block(3,27,-4,LEAVES:12)
Block(3,27,-3,LEAVES:12)
Block(3,27,-2,LEAVES:12)
Block(3,27,-1,LEAVES:12)
Block(3,27,0,LEAVES:12)
Block(3,27,1,LEAVES:12)
Block(3,27,2,LEAVES:12)
Block(3,28,-4,LEAVES:12)
Block(3,28,-3,LEAVES:12)
Block(3,28,-2,LEAVES:12)
Block(3,28,1,LEAVES:12)
Block(3,28,2,LEAVES:12)
Block(3,28,3,LEAVES:12)
Block(3,29,-5,LEAVES:12)
Block(3,29,-4,LEAVES:12)
Block(3,29,2,LEAVES:12)
Block(3,30,-6,LEAVES:12)
Block(4,0,6,17:12)
Block(4,1,6,17:12)
Block(4,2,5,17:12)
Block(4,2,6,17:12)
Block(4,3,5,17:12)
Block(4,3,6,17:12)
Block(4,4,-5,LEAVES:12)
Block(4,4,5,17:12)
Block(4,4,6,17:12)
Block(4,5,5,17:12)
Block(4,5,6,17:12)
Block(4,6,5,17:12)
Block(4,6,6,17:12)
Block(4,7,2,17:12)
Block(4,7,5,17:12)
Block(4,8,2,17:12)
Block(4,8,3,17:12)
Block(4,8,4,17:12)
Block(4,8,5,17:12)
Block(4,9,3,17:12)
Block(4,9,4,17:12)
Block(4,9,8,LEAVES:12)
Block(4,9,11,LEAVES:12)
Block(4,9,12,LEAVES:12)
Block(4,9,13,LEAVES:12)
Block(4,10,2,17:12)
Block(4,10,3,17:12)
Block(4,10,4,17:12)
Block(4,10,9,LEAVES:12)
Block(4,10,12,LEAVES:12)
Block(4,11,-7,LEAVES:12)
Block(4,11,2,17:12)
Block(4,11,3,17:12)
Block(4,11,8,LEAVES:12)
Block(4,12,1,17:12)
Block(4,12,2,17:12)
Block(4,12,3,17:12)
Block(4,12,4,17:12)
Block(4,12,7,LEAVES:12)
Block(4,12,8,LEAVES:12)
Block(4,12,9,LEAVES:12)
Block(4,13,-7,LEAVES:12)
Block(4,13,-4,17:12)
Block(4,13,-3,LEAVES:12)
Block(4,13,2,17:12)
Block(4,13,3,17:12)
Block(4,13,4,17:12)
Block(4,13,7,LEAVES:12)
Block(4,13,8,LEAVES:12)
Block(4,13,9,LEAVES:12)
Block(4,13,10,LEAVES:12)
Block(4,13,12,LEAVES:12)
Block(4,14,-7,LEAVES:12)
Block(4,14,-6,LEAVES:12)
Block(4,14,-5,LEAVES:12)
Block(4,14,-4,LEAVES:12)
Block(4,14,-3,LEAVES:12)
Block(4,14,3,17:12)
Block(4,14,4,17:12)
Block(4,14,8,LEAVES:12)
Block(4,14,9,LEAVES:12)
Block(4,15,-6,LEAVES:12)
Block(4,15,3,17:12)
Block(4,15,6,LEAVES:12)
Block(4,15,7,LEAVES:12)
Block(4,15,8,LEAVES:12)
Block(4,16,2,17:12)
Block(4,16,3,17:12)
Block(4,16,5,17:12)
Block(4,16,7,LEAVES:12)
Block(4,16,9,LEAVES:12)
Block(4,16,10,LEAVES:12)
Block(4,16,11,LEAVES:12)
Block(4,17,0,17:12)
Block(4,17,1,17:12)
Block(4,17,2,17:12)
Block(4,17,6,17:12)
Block(4,17,9,LEAVES:12)
Block(4,17,10,LEAVES:12)
Block(4,18,-5,LEAVES:12)
Block(4,18,-4,LEAVES:12)
Block(4,18,-3,LEAVES:12)
Block(4,18,-2,LEAVES:12)
Block(4,18,-1,17:12)
Block(4,18,0,17:12)
Block(4,18,1,17:12)
Block(4,18,6,17:12)
Block(4,18,7,17:12)
Block(4,19,-8,LEAVES:12)
Block(4,19,-7,LEAVES:12)
Block(4,19,-6,LEAVES:12)
Block(4,19,-5,LEAVES:12)
Block(4,19,-3,17:12)
Block(4,19,-2,LEAVES:12)
Block(4,19,-1,LEAVES:12)
Block(4,19,1,17:12)
Block(4,19,5,LEAVES:12)
Block(4,19,6,LEAVES:12)
Block(4,19,7,17:12)
Block(4,20,-7,LEAVES:12)
Block(4,20,-3,LEAVES:12)
Block(4,20,-2,LEAVES:12)
Block(4,20,0,17:12)
Block(4,20,6,LEAVES:12)
Block(4,20,7,17:12)
Block(4,20,8,LEAVES:12)
Block(4,21,-7,LEAVES:12)
Block(4,21,-6,LEAVES:12)
Block(4,21,-5,LEAVES:12)
Block(4,21,-4,LEAVES:12)
Block(4,21,4,LEAVES:12)
Block(4,21,5,LEAVES:12)
Block(4,21,6,LEAVES:12)
Block(4,21,7,LEAVES:12)
Block(4,21,8,LEAVES:12)
Block(4,21,9,LEAVES:12)
Block(4,21,12,LEAVES:12)
Block(4,22,-6,LEAVES:12)
Block(4,22,-5,LEAVES:12)
Block(4,22,-4,LEAVES:12)
Block(4,22,-3,LEAVES:12)
Block(4,22,4,LEAVES:12)
Block(4,22,5,LEAVES:12)
Block(4,22,7,17:12)
Block(4,22,8,LEAVES:12)
Block(4,22,9,LEAVES:12)
Block(4,22,10,17:12)
Block(4,22,11,LEAVES:12)
Block(4,22,12,LEAVES:12)
Block(4,22,13,LEAVES:12)
Block(4,23,-5,LEAVES:12)
Block(4,23,-4,LEAVES:12)
Block(4,23,-2,LEAVES:12)
Block(4,23,-1,LEAVES:12)
Block(4,23,0,17:12)
Block(4,23,1,LEAVES:12)
Block(4,23,2,LEAVES:12)
Block(4,23,3,LEAVES:12)
Block(4,23,4,LEAVES:12)
Block(4,23,5,LEAVES:12)
Block(4,23,6,17:12)
Block(4,23,7,17:12)
Block(4,23,8,LEAVES:12)
Block(4,23,9,LEAVES:12)
Block(4,23,11,LEAVES:12)
Block(4,23,12,LEAVES:12)
Block(4,24,-3,LEAVES:12)
Block(4,24,-2,LEAVES:12)
Block(4,24,-1,LEAVES:12)
Block(4,24,0,LEAVES:12)
Block(4,24,1,LEAVES:12)
Block(4,24,4,LEAVES:12)
Block(4,24,8,LEAVES:12)
Block(4,24,9,LEAVES:12)
Block(4,24,10,LEAVES:12)
Block(4,25,-3,LEAVES:12)
Block(4,25,-2,LEAVES:12)
Block(4,25,-1,LEAVES:12)
Block(4,25,7,LEAVES:12)
Block(4,25,8,LEAVES:12)
Block(4,25,9,LEAVES:12)
Block(4,26,-4,LEAVES:12)
Block(4,26,-2,LEAVES:12)
Block(4,26,-1,17:12)
Block(4,26,2,LEAVES:12)
Block(4,26,8,LEAVES:12)
Block(4,27,-3,LEAVES:12)
Block(4,27,-2,17:12)
Block(4,27,1,LEAVES:12)
Block(4,27,2,LEAVES:12)
Block(4,27,3,LEAVES:12)
Block(4,28,-4,LEAVES:12)
Block(4,28,-3,LEAVES:12)
Block(4,28,2,LEAVES:12)
Block(4,29,-6,LEAVES:12)
Block(4,30,-7,LEAVES:12)
Block(4,30,-6,LEAVES:12)
Block(4,30,-5,LEAVES:12)
Block(4,30,-2,LEAVES:12)
Block(4,31,-6,LEAVES:12)
Block(5,0,7,17:12)
Block(5,0,8,17:12)
Block(5,1,6,17:12)
Block(5,1,7,17:12)
Block(5,1,8,17:12)
Block(5,4,-6,LEAVES:12)
Block(5,4,-5,LEAVES:12)
Block(5,4,-4,LEAVES:12)
Block(5,5,-5,LEAVES:12)
Block(5,5,-2,LEAVES:12)
Block(5,6,-3,LEAVES:12)
Block(5,7,2,17:12)
Block(5,8,-2,LEAVES:12)
Block(5,9,-3,LEAVES:12)
Block(5,9,12,LEAVES:12)
Block(5,10,-7,LEAVES:12)
Block(5,10,4,17:12)
Block(5,10,5,17:12)
Block(5,10,6,LEAVES:12)
Block(5,10,8,LEAVES:12)
Block(5,10,9,LEAVES:12)
Block(5,10,10,LEAVES:12)
Block(5,11,-8,LEAVES:12)
Block(5,11,-7,LEAVES:12)
Block(5,11,-6,LEAVES:12)
Block(5,11,5,17:12)
Block(5,11,6,17:12)
Block(5,11,7,LEAVES:12)
Block(5,11,8,LEAVES:12)
Block(5,11,9,LEAVES:12)
Block(5,12,-7,LEAVES:12)
Block(5,12,-5,LEAVES:12)
Block(5,12,-3,LEAVES:12)
Block(5,12,3,17:12)
Block(5,12,8,LEAVES:12)
Block(5,13,-4,LEAVES:12)
Block(5,13,-3,LEAVES:12)
Block(5,13,-2,LEAVES:12)
Block(5,13,3,17:12)
Block(5,13,6,LEAVES:12)
Block(5,13,7,LEAVES:12)
Block(5,13,8,LEAVES:12)
Block(5,13,9,LEAVES:12)
Block(5,14,-6,LEAVES:12)
Block(5,14,-5,LEAVES:12)
Block(5,14,-4,LEAVES:12)
Block(5,14,-3,LEAVES:12)
Block(5,14,3,17:12)
Block(5,14,4,17:12)
Block(5,14,7,LEAVES:12)
Block(5,14,8,LEAVES:12)
Block(5,14,9,LEAVES:12)
Block(5,15,-7,LEAVES:12)
Block(5,15,-6,LEAVES:12)
Block(5,15,-5,LEAVES:12)
Block(5,15,3,17:12)
Block(5,15,4,17:12)
Block(5,15,5,17:12)
Block(5,15,7,LEAVES:12)
Block(5,15,8,LEAVES:12)
Block(5,15,9,LEAVES:12)
Block(5,16,-6,LEAVES:12)
Block(5,16,4,17:12)
Block(5,16,5,17:12)
Block(5,16,6,17:12)
Block(5,16,7,LEAVES:12)
Block(5,16,8,LEAVES:12)
Block(5,16,10,LEAVES:12)
Block(5,17,5,17:12)
Block(5,17,6,17:12)
Block(5,17,7,17:12)
Block(5,18,-6,LEAVES:12)
Block(5,18,-5,LEAVES:12)
Block(5,18,-4,LEAVES:12)
Block(5,18,-3,LEAVES:12)
Block(5,18,-2,17:12)
Block(5,18,-1,17:12)
Block(5,18,6,17:12)
Block(5,18,7,17:12)
Block(5,19,-7,LEAVES:12)
Block(5,19,-6,LEAVES:12)
Block(5,19,-5,LEAVES:12)
Block(5,19,-3,17:12)
Block(5,19,-2,LEAVES:12)
Block(5,19,-1,LEAVES:12)
Block(5,19,0,LEAVES:12)
Block(5,19,6,LEAVES:12)
Block(5,19,7,17:12)
Block(5,19,11,LEAVES:12)
Block(5,20,-8,LEAVES:12)
Block(5,20,-7,LEAVES:12)
Block(5,20,-6,LEAVES:12)
Block(5,20,-5,LEAVES:12)
Block(5,20,-4,LEAVES:12)
Block(5,20,-3,LEAVES:12)
Block(5,20,-2,LEAVES:12)
Block(5,20,-1,LEAVES:12)
Block(5,20,0,17:12)
Block(5,20,7,17:12)
Block(5,20,10,LEAVES:12)
Block(5,20,12,LEAVES:12)
Block(5,21,-8,LEAVES:12)
Block(5,21,-7,LEAVES:12)
Block(5,21,-6,LEAVES:12)
Block(5,21,-5,LEAVES:12)
Block(5,21,-4,LEAVES:12)
Block(5,21,-3,LEAVES:12)
Block(5,21,1,LEAVES:12)
Block(5,21,5,LEAVES:12)
Block(5,21,6,LEAVES:12)
Block(5,21,7,LEAVES:12)
Block(5,21,8,LEAVES:12)
Block(5,21,9,17:12)
Block(5,22,-7,LEAVES:12)
Block(5,22,-6,LEAVES:12)
Block(5,22,-5,LEAVES:12)
Block(5,22,-4,LEAVES:12)
Block(5,22,4,LEAVES:12)
Block(5,22,5,LEAVES:12)
Block(5,22,6,LEAVES:12)
Block(5,22,8,LEAVES:12)
Block(5,22,9,LEAVES:12)
Block(5,22,11,LEAVES:12)
Block(5,22,12,LEAVES:12)
Block(5,22,13,LEAVES:12)
Block(5,23,-5,LEAVES:12)
Block(5,23,-1,LEAVES:12)
Block(5,23,1,LEAVES:12)
Block(5,23,4,LEAVES:12)
Block(5,23,5,17:12)
Block(5,23,6,LEAVES:12)
Block(5,23,7,17:12)
Block(5,23,8,LEAVES:12)
Block(5,23,9,LEAVES:12)
Block(5,23,10,LEAVES:12)
Block(5,23,11,LEAVES:12)
Block(5,23,12,LEAVES:12)
Block(5,24,-2,LEAVES:12)
Block(5,24,-1,LEAVES:12)
Block(5,24,3,LEAVES:12)
Block(5,24,5,LEAVES:12)
Block(5,24,6,LEAVES:12)
Block(5,24,7,LEAVES:12)
Block(5,24,8,LEAVES:12)
Block(5,24,9,LEAVES:12)
Block(5,24,11,LEAVES:12)
Block(5,25,-2,17:12)
Block(5,25,-1,LEAVES:12)
Block(5,25,0,LEAVES:12)
Block(5,25,5,LEAVES:12)
Block(5,25,6,LEAVES:12)
Block(5,25,8,LEAVES:12)
Block(5,26,-5,LEAVES:12)
Block(5,26,-4,LEAVES:12)
Block(5,26,-3,LEAVES:12)
Block(5,26,-2,LEAVES:12)
Block(5,26,-1,LEAVES:12)
Block(5,26,3,LEAVES:12)
Block(5,27,-4,LEAVES:12)
Block(5,27,2,LEAVES:12)
Block(5,27,3,LEAVES:12)
Block(5,27,4,LEAVES:12)
Block(5,28,-5,LEAVES:12)
Block(5,28,-4,LEAVES:12)
Block(5,28,-3,LEAVES:12)
Block(5,28,0,LEAVES:12)
Block(5,28,3,LEAVES:12)
Block(5,29,-7,LEAVES:12)
Block(5,29,-6,LEAVES:12)
Block(5,29,-5,LEAVES:12)
Block(5,29,-4,LEAVES:12)
Block(5,29,-2,LEAVES:12)
Block(5,30,-6,LEAVES:12)
Block(5,30,-5,LEAVES:12)
Block(5,30,-4,LEAVES:12)
Block(5,30,-3,LEAVES:12)
Block(5,30,-2,LEAVES:12)
Block(5,30,-1,LEAVES:12)
Block(5,31,-5,LEAVES:12)
Block(5,31,-2,LEAVES:12)
Block(6,0,8,17:12)
Block(6,0,9,17:12)
Block(6,4,-5,LEAVES:12)
Block(6,5,-3,LEAVES:12)
Block(6,5,-2,LEAVES:12)
Block(6,5,-1,LEAVES:12)
Block(6,6,-4,LEAVES:12)
Block(6,6,-3,LEAVES:12)
Block(6,6,-2,LEAVES:12)
Block(6,7,-3,LEAVES:12)
Block(6,7,0,17:12)
Block(6,7,1,17:12)
Block(6,7,2,17:12)
Block(6,8,-3,LEAVES:12)
Block(6,8,-2,LEAVES:12)
Block(6,8,-1,LEAVES:12)
Block(6,8,1,LEAVES:12)
Block(6,9,-4,LEAVES:12)
Block(6,9,-3,LEAVES:12)
Block(6,9,-2,LEAVES:12)
Block(6,9,0,LEAVES:12)
Block(6,10,-8,LEAVES:12)
Block(6,10,-7,LEAVES:12)
Block(6,10,-6,LEAVES:12)
Block(6,10,-3,LEAVES:12)
Block(6,10,-2,LEAVES:12)
Block(6,10,3,LEAVES:12)
Block(6,10,5,LEAVES:12)
Block(6,10,6,LEAVES:12)
Block(6,10,7,LEAVES:12)
Block(6,10,8,LEAVES:12)
Block(6,10,9,LEAVES:12)
Block(6,11,-7,LEAVES:12)
Block(6,11,-6,LEAVES:12)
Block(6,11,-5,LEAVES:12)
Block(6,11,5,17:12)
Block(6,11,6,17:12)
Block(6,11,7,17:12)
Block(6,11,8,LEAVES:12)
Block(6,12,-6,LEAVES:12)
Block(6,12,-4,LEAVES:12)
Block(6,12,-3,LEAVES:12)
Block(6,12,-2,LEAVES:12)
Block(6,12,6,LEAVES:12)
Block(6,13,-5,LEAVES:12)
Block(6,13,-4,LEAVES:12)
Block(6,13,-3,LEAVES:12)
Block(6,13,2,17:12)
Block(6,13,3,17:12)
Block(6,13,6,LEAVES:12)
Block(6,13,7,LEAVES:12)
Block(6,13,8,LEAVES:12)
Block(6,14,-5,LEAVES:12)
Block(6,14,-4,LEAVES:12)
Block(6,14,-2,LEAVES:12)
Block(6,14,6,LEAVES:12)
Block(6,14,7,LEAVES:12)
Block(6,14,8,LEAVES:12)
Block(6,15,-6,LEAVES:12)
Block(6,15,-3,LEAVES:12)
Block(6,15,3,17:12)
Block(6,15,4,17:12)
Block(6,15,7,LEAVES:12)
Block(6,15,8,LEAVES:12)
Block(6,16,4,17:12)
Block(6,16,5,LEAVES:12)
Block(6,16,7,LEAVES:12)
Block(6,17,4,LEAVES:12)
Block(6,17,5,17:12)
Block(6,17,6,17:12)
Block(6,18,-7,LEAVES:12)
Block(6,18,-6,LEAVES:12)
Block(6,18,-5,LEAVES:12)
Block(6,18,-4,LEAVES:12)
Block(6,18,-2,17:12)
Block(6,18,1,LEAVES:12)
Block(6,19,-6,LEAVES:12)
Block(6,19,-5,LEAVES:12)
Block(6,19,-4,17:12)
Block(6,19,-3,17:12)
Block(6,19,-2,LEAVES:12)
Block(6,19,-1,LEAVES:12)
Block(6,19,2,LEAVES:12)
Block(6,19,10,LEAVES:12)
Block(6,19,11,LEAVES:12)
Block(6,19,12,LEAVES:12)
Block(6,20,-7,LEAVES:12)
Block(6,20,-6,17:12)
Block(6,20,-5,17:12)
Block(6,20,-3,LEAVES:12)
Block(6,20,-2,LEAVES:12)
Block(6,20,-1,LEAVES:12)
Block(6,20,0,17:12)
Block(6,20,8,17:12)
Block(6,20,9,17:12)
Block(6,20,10,LEAVES:12)
Block(6,20,11,LEAVES:12)
Block(6,20,12,LEAVES:12)
Block(6,20,13,LEAVES:12)
Block(6,21,-9,LEAVES:12)
Block(6,21,-8,LEAVES:12)
Block(6,21,-7,LEAVES:12)
Block(6,21,-5,LEAVES:12)
Block(6,21,-4,LEAVES:12)
Block(6,21,-3,LEAVES:12)
Block(6,21,-2,LEAVES:12)
Block(6,21,-1,LEAVES:12)
Block(6,21,0,17:12)
Block(6,21,1,LEAVES:12)
Block(6,21,2,LEAVES:12)
Block(6,21,6,LEAVES:12)
Block(6,21,7,LEAVES:12)
Block(6,21,8,LEAVES:12)
Block(6,21,9,17:12)
Block(6,21,10,17:12)
Block(6,21,12,LEAVES:12)
Block(6,22,-8,LEAVES:12)
Block(6,22,-7,LEAVES:12)
Block(6,22,-6,LEAVES:12)
Block(6,22,-5,LEAVES:12)
Block(6,22,-3,LEAVES:12)
Block(6,22,1,LEAVES:12)
Block(6,22,5,LEAVES:12)
Block(6,22,6,LEAVES:12)
Block(6,22,7,LEAVES:12)
Block(6,22,8,LEAVES:12)
Block(6,22,9,LEAVES:12)
Block(6,22,10,LEAVES:12)
Block(6,22,11,LEAVES:12)
Block(6,22,12,LEAVES:12)
Block(6,23,-7,LEAVES:12)
Block(6,23,-6,LEAVES:12)
Block(6,23,-5,LEAVES:12)
Block(6,23,-4,LEAVES:12)
Block(6,23,-1,LEAVES:12)
Block(6,23,3,LEAVES:12)
Block(6,23,4,LEAVES:12)
Block(6,23,5,LEAVES:12)
Block(6,23,6,LEAVES:12)
Block(6,23,7,LEAVES:12)
Block(6,23,8,LEAVES:12)
Block(6,23,9,LEAVES:12)
Block(6,23,10,LEAVES:12)
Block(6,23,11,LEAVES:12)
Block(6,24,-5,LEAVES:12)
Block(6,24,-3,LEAVES:12)
Block(6,24,-2,LEAVES:12)
Block(6,24,-1,LEAVES:12)
Block(6,24,2,LEAVES:12)
Block(6,24,3,LEAVES:12)
Block(6,24,4,LEAVES:12)
Block(6,24,5,LEAVES:12)
Block(6,24,6,LEAVES:12)
Block(6,24,7,LEAVES:12)
Block(6,24,8,LEAVES:12)
Block(6,24,10,LEAVES:12)
Block(6,24,11,LEAVES:12)
Block(6,24,12,LEAVES:12)
Block(6,25,-2,LEAVES:12)
Block(6,25,3,LEAVES:12)
Block(6,25,4,LEAVES:12)
Block(6,25,5,LEAVES:12)
Block(6,25,6,LEAVES:12)
Block(6,25,7,17:12)
Block(6,25,11,LEAVES:12)
Block(6,26,-6,LEAVES:12)
Block(6,26,-5,LEAVES:12)
Block(6,26,-4,LEAVES:12)
Block(6,26,2,LEAVES:12)
Block(6,26,3,LEAVES:12)
Block(6,26,4,LEAVES:12)
Block(6,26,6,LEAVES:12)
Block(6,27,-5,LEAVES:12)
Block(6,27,-4,LEAVES:12)
Block(6,27,-3,LEAVES:12)
Block(6,27,0,LEAVES:12)
Block(6,27,3,LEAVES:12)
Block(6,27,4,LEAVES:12)
Block(6,27,5,LEAVES:12)
Block(6,28,-4,LEAVES:12)
Block(6,28,-3,LEAVES:12)
Block(6,28,-2,LEAVES:12)
Block(6,28,-1,LEAVES:12)
Block(6,28,0,LEAVES:12)
Block(6,28,1,LEAVES:12)
Block(6,28,4,LEAVES:12)
Block(6,29,-6,LEAVES:12)
Block(6,29,-3,LEAVES:12)
Block(6,29,-2,LEAVES:12)
Block(6,29,-1,LEAVES:12)
Block(6,29,0,LEAVES:12)
Block(6,30,-5,LEAVES:12)
Block(6,30,-4,LEAVES:12)
Block(6,30,-3,LEAVES:12)
Block(6,30,-2,LEAVES:12)
Block(6,31,-3,LEAVES:12)
Block(7,0,9,17:12)
Block(7,4,-6,LEAVES:12)
Block(7,4,-5,LEAVES:12)
Block(7,4,-4,LEAVES:12)
Block(7,5,-5,LEAVES:12)
Block(7,5,-4,LEAVES:12)
Block(7,5,-3,LEAVES:12)
Block(7,5,-2,LEAVES:12)
Block(7,6,-4,17:12)
Block(7,6,-3,LEAVES:12)
Block(7,6,-2,LEAVES:12)
Block(7,6,0,17:12)
Block(7,7,-6,LEAVES:12)
Block(7,7,-4,LEAVES:12)
Block(7,7,-2,17:12)
Block(7,7,-1,17:12)
Block(7,7,0,17:12)
Block(7,7,2,LEAVES:12)
Block(7,8,-2,LEAVES:12)
Block(7,8,0,LEAVES:12)
Block(7,8,1,LEAVES:12)
Block(7,8,2,LEAVES:12)
Block(7,9,-4,LEAVES:12)
Block(7,9,-3,LEAVES:12)
Block(7,9,-2,LEAVES:12)
Block(7,9,-1,LEAVES:12)
Block(7,9,0,LEAVES:12)
Block(7,9,1,LEAVES:12)
Block(7,10,-7,LEAVES:12)
Block(7,10,-3,LEAVES:12)
Block(7,10,-2,LEAVES:12)
Block(7,10,-1,LEAVES:12)
Block(7,10,0,LEAVES:12)
Block(7,10,2,LEAVES:12)
Block(7,10,3,LEAVES:12)
Block(7,10,4,LEAVES:12)
Block(7,10,6,LEAVES:12)
Block(7,10,7,LEAVES:12)
Block(7,10,8,LEAVES:12)
Block(7,11,-6,LEAVES:12)
Block(7,11,-5,LEAVES:12)
Block(7,11,-4,LEAVES:12)
Block(7,11,-2,LEAVES:12)
Block(7,11,3,LEAVES:12)
Block(7,11,5,17:12)
Block(7,11,7,17:12)
Block(7,11,8,17:12)
Block(7,12,-5,LEAVES:12)
Block(7,12,-4,LEAVES:12)
Block(7,12,-3,LEAVES:12)
Block(7,12,0,LEAVES:12)
Block(7,12,6,LEAVES:12)
Block(7,12,8,17:12)
Block(7,13,-4,LEAVES:12)
Block(7,13,-1,LEAVES:12)
Block(7,13,2,17:12)
Block(7,13,5,LEAVES:12)
Block(7,13,6,LEAVES:12)
Block(7,13,7,LEAVES:12)
Block(7,13,8,LEAVES:12)
Block(7,14,-3,LEAVES:12)
Block(7,14,-2,LEAVES:12)
Block(7,14,-1,LEAVES:12)
Block(7,14,1,17:12)
Block(7,14,2,17:12)
Block(7,14,6,LEAVES:12)
Block(7,14,7,LEAVES:12)
Block(7,14,9,LEAVES:12)
Block(7,15,-4,LEAVES:12)
Block(7,15,-3,LEAVES:12)
Block(7,15,-2,LEAVES:12)
Block(7,16,-3,LEAVES:12)
Block(7,16,4,LEAVES:12)
Block(7,16,5,LEAVES:12)
Block(7,16,6,LEAVES:12)
Block(7,17,3,LEAVES:12)
Block(7,17,4,LEAVES:12)
Block(7,17,5,LEAVES:12)
Block(7,17,6,LEAVES:12)
Block(7,18,-7,LEAVES:12)
Block(7,18,-6,LEAVES:12)
Block(7,18,-5,LEAVES:12)
Block(7,18,-4,LEAVES:12)
Block(7,18,-3,LEAVES:12)
Block(7,18,0,LEAVES:12)
Block(7,18,1,LEAVES:12)
Block(7,18,2,LEAVES:12)
Block(7,18,4,LEAVES:12)
Block(7,18,5,17:12)
Block(7,18,7,LEAVES:12)
Block(7,18,9,LEAVES:12)
Block(7,19,-8,LEAVES:12)
Block(7,19,-6,LEAVES:12)
Block(7,19,-5,LEAVES:12)
Block(7,19,-4,LEAVES:12)
Block(7,19,-2,LEAVES:12)
Block(7,19,1,LEAVES:12)
Block(7,19,2,LEAVES:12)
Block(7,19,3,LEAVES:12)
Block(7,19,9,LEAVES:12)
Block(7,19,10,LEAVES:12)
Block(7,19,11,LEAVES:12)
Block(7,19,12,LEAVES:12)
Block(7,19,13,LEAVES:12)
Block(7,20,-7,LEAVES:12)
Block(7,20,-5,LEAVES:12)
Block(7,20,-3,17:12)
Block(7,20,-1,LEAVES:12)
Block(7,20,2,LEAVES:12)
Block(7,20,3,LEAVES:12)
Block(7,20,10,LEAVES:12)
Block(7,20,11,LEAVES:12)
Block(7,20,12,LEAVES:12)
Block(7,21,-8,LEAVES:12)
Block(7,21,-5,LEAVES:12)
Block(7,21,-4,LEAVES:12)
Block(7,21,-3,LEAVES:12)
Block(7,21,-2,LEAVES:12)
Block(7,21,1,LEAVES:12)
Block(7,21,4,LEAVES:12)
Block(7,21,5,LEAVES:12)
Block(7,21,6,LEAVES:12)
Block(7,21,7,LEAVES:12)
Block(7,21,8,LEAVES:12)
Block(7,21,9,LEAVES:12)
Block(7,21,11,LEAVES:12)
Block(7,22,-9,LEAVES:12)
Block(7,22,-8,LEAVES:12)
Block(7,22,-7,LEAVES:12)
Block(7,22,-6,LEAVES:12)
Block(7,22,-5,LEAVES:12)
Block(7,22,-4,LEAVES:12)
Block(7,22,-1,LEAVES:12)
Block(7,22,0,17:12)
Block(7,22,1,17:12)
Block(7,22,4,LEAVES:12)
Block(7,22,5,LEAVES:12)
Block(7,22,6,LEAVES:12)
Block(7,22,7,LEAVES:12)
Block(7,22,8,LEAVES:12)
Block(7,22,9,LEAVES:12)
Block(7,22,11,LEAVES:12)
Block(7,23,-8,LEAVES:12)
Block(7,23,-5,LEAVES:12)
Block(7,23,-4,LEAVES:12)
Block(7,23,-3,LEAVES:12)
Block(7,23,-2,LEAVES:12)
Block(7,23,-1,LEAVES:12)
Block(7,23,0,LEAVES:12)
Block(7,23,2,LEAVES:12)
Block(7,23,3,LEAVES:12)
Block(7,23,4,LEAVES:12)
Block(7,23,5,LEAVES:12)
Block(7,23,6,LEAVES:12)
Block(7,23,7,LEAVES:12)
Block(7,23,8,LEAVES:12)
Block(7,23,9,LEAVES:12)
Block(7,24,-4,LEAVES:12)
Block(7,24,-3,LEAVES:12)
Block(7,24,-2,LEAVES:12)
Block(7,24,-1,LEAVES:12)
Block(7,24,3,LEAVES:12)
Block(7,24,5,LEAVES:12)
Block(7,24,6,LEAVES:12)
Block(7,24,7,LEAVES:12)
Block(7,24,8,LEAVES:12)
Block(7,24,11,LEAVES:12)
Block(7,25,-3,LEAVES:12)
Block(7,25,-2,LEAVES:12)
Block(7,25,-1,LEAVES:12)
Block(7,25,3,LEAVES:12)
Block(7,25,4,LEAVES:12)
Block(7,25,5,LEAVES:12)
Block(7,25,6,LEAVES:12)
Block(7,25,7,LEAVES:12)
Block(7,26,-5,LEAVES:12)
Block(7,26,-2,LEAVES:12)
Block(7,26,2,LEAVES:12)
Block(7,26,3,LEAVES:12)
Block(7,26,4,LEAVES:12)
Block(7,27,-4,LEAVES:12)
Block(7,27,-1,LEAVES:12)
Block(7,27,0,LEAVES:12)
Block(7,27,1,LEAVES:12)
Block(7,27,3,LEAVES:12)
Block(7,27,4,LEAVES:12)
Block(7,28,-3,LEAVES:12)
Block(7,28,-2,LEAVES:12)
Block(7,28,-1,LEAVES:12)
Block(7,28,0,LEAVES:12)
Block(7,29,-2,LEAVES:12)
Block(7,29,-1,LEAVES:12)
Block(7,30,-3,LEAVES:12)
Block(8,4,-6,LEAVES:12)
Block(8,4,-5,LEAVES:12)
Block(8,5,-5,LEAVES:12)
Block(8,5,-4,LEAVES:12)
Block(8,5,-3,LEAVES:12)
Block(8,5,-2,LEAVES:12)
Block(8,6,-5,LEAVES:12)
Block(8,6,-3,LEAVES:12)
Block(8,6,-2,LEAVES:12)
Block(8,6,-1,LEAVES:12)
Block(8,6,0,17:12)
Block(8,7,-7,LEAVES:12)
Block(8,7,-6,LEAVES:12)
Block(8,7,-5,LEAVES:12)
Block(8,7,-4,LEAVES:12)
Block(8,7,-2,LEAVES:12)
Block(8,7,-1,17:12)
Block(8,7,1,LEAVES:12)
Block(8,7,2,LEAVES:12)
Block(8,7,3,LEAVES:12)
Block(8,8,-6,LEAVES:12)
Block(8,8,-5,LEAVES:12)
Block(8,8,0,LEAVES:12)
Block(8,8,1,LEAVES:12)
Block(8,8,2,LEAVES:12)
Block(8,9,-3,LEAVES:12)
Block(8,9,-2,LEAVES:12)
Block(8,9,0,LEAVES:12)
Block(8,9,1,LEAVES:12)
Block(8,9,2,LEAVES:12)
Block(8,10,-4,LEAVES:12)
Block(8,10,-3,LEAVES:12)
Block(8,10,-2,LEAVES:12)
Block(8,10,0,LEAVES:12)
Block(8,10,1,LEAVES:12)
Block(8,10,3,LEAVES:12)
Block(8,10,4,LEAVES:12)
Block(8,10,5,LEAVES:12)
Block(8,10,6,LEAVES:12)
Block(8,10,7,LEAVES:12)
Block(8,10,8,LEAVES:12)
Block(8,11,-5,LEAVES:12)
Block(8,11,-4,LEAVES:12)
Block(8,11,-3,LEAVES:12)
Block(8,11,1,LEAVES:12)
Block(8,11,2,LEAVES:12)
Block(8,11,3,LEAVES:12)
Block(8,11,4,17:12)
Block(8,11,5,17:12)
Block(8,11,7,LEAVES:12)
Block(8,12,-4,LEAVES:12)
Block(8,12,-1,LEAVES:12)
Block(8,12,0,LEAVES:12)
Block(8,12,1,LEAVES:12)
Block(8,12,3,LEAVES:12)
Block(8,12,4,LEAVES:12)
Block(8,12,5,LEAVES:12)
Block(8,12,6,LEAVES:12)
Block(8,12,7,LEAVES:12)
Block(8,13,-3,LEAVES:12)
Block(8,13,-2,LEAVES:12)
Block(8,13,-1,LEAVES:12)
Block(8,13,0,LEAVES:12)
Block(8,13,3,LEAVES:12)
Block(8,13,4,LEAVES:12)
Block(8,13,5,LEAVES:12)
Block(8,13,6,LEAVES:12)
Block(8,13,9,LEAVES:12)
Block(8,14,-2,LEAVES:12)
Block(8,14,-1,LEAVES:12)
Block(8,14,0,LEAVES:12)
Block(8,14,1,17:12)
Block(8,14,4,LEAVES:12)
Block(8,14,5,LEAVES:12)
Block(8,14,8,LEAVES:12)
Block(8,14,9,LEAVES:12)
Block(8,14,10,LEAVES:12)
Block(8,15,-3,LEAVES:12)
Block(8,15,-2,LEAVES:12)
Block(8,15,-1,LEAVES:12)
Block(8,15,0,17:12)
Block(8,15,1,17:12)
Block(8,15,9,LEAVES:12)
Block(8,16,-2,LEAVES:12)
Block(8,16,5,LEAVES:12)
Block(8,17,-3,LEAVES:12)
Block(8,17,4,LEAVES:12)
Block(8,17,5,LEAVES:12)
Block(8,17,6,LEAVES:12)
Block(8,17,7,LEAVES:12)
Block(8,18,-8,LEAVES:12)
Block(8,18,-7,LEAVES:12)
Block(8,18,-6,LEAVES:12)
Block(8,18,-4,LEAVES:12)
Block(8,18,1,LEAVES:12)
Block(8,18,3,LEAVES:12)
Block(8,18,4,17:12)
Block(8,18,5,17:12)
Block(8,18,6,LEAVES:12)
Block(8,18,7,LEAVES:12)
Block(8,18,8,LEAVES:12)
Block(8,18,9,LEAVES:12)
Block(8,18,10,LEAVES:12)
Block(8,19,-9,LEAVES:12)
Block(8,19,-8,LEAVES:12)
Block(8,19,-7,LEAVES:12)
Block(8,19,-5,LEAVES:12)
Block(8,19,-4,LEAVES:12)
Block(8,19,-3,LEAVES:12)
Block(8,19,0,LEAVES:12)
Block(8,19,1,LEAVES:12)
Block(8,19,2,LEAVES:12)
Block(8,19,4,17:12)
Block(8,19,7,LEAVES:12)
Block(8,19,9,LEAVES:12)
Block(8,19,10,LEAVES:12)
Block(8,19,11,LEAVES:12)
Block(8,19,12,LEAVES:12)
Block(8,20,-8,LEAVES:12)
Block(8,20,-6,LEAVES:12)
Block(8,20,-5,LEAVES:12)
Block(8,20,-4,LEAVES:12)
Block(8,20,-3,LEAVES:12)
Block(8,20,1,LEAVES:12)
Block(8,20,2,LEAVES:12)
Block(8,20,3,LEAVES:12)
Block(8,20,4,LEAVES:12)
Block(8,20,6,LEAVES:12)
Block(8,20,10,LEAVES:12)
Block(8,20,11,LEAVES:12)
Block(8,21,-5,LEAVES:12)
Block(8,21,-4,LEAVES:12)
Block(8,21,-3,17:12)
Block(8,21,-2,LEAVES:12)
Block(8,21,0,LEAVES:12)
Block(8,21,1,LEAVES:12)
Block(8,21,2,LEAVES:12)
Block(8,21,3,LEAVES:12)
Block(8,21,4,LEAVES:12)
Block(8,21,5,LEAVES:12)
Block(8,21,6,LEAVES:12)
Block(8,21,8,LEAVES:12)
Block(8,21,9,LEAVES:12)
Block(8,22,-8,LEAVES:12)
Block(8,22,-5,LEAVES:12)
Block(8,22,-4,LEAVES:12)
Block(8,22,-3,LEAVES:12)
Block(8,22,-2,LEAVES:12)
Block(8,22,-1,LEAVES:12)
Block(8,22,0,LEAVES:12)
Block(8,22,1,LEAVES:12)
Block(8,22,3,LEAVES:12)
Block(8,22,4,LEAVES:12)
Block(8,22,5,LEAVES:12)
Block(8,22,6,LEAVES:12)
Block(8,22,7,LEAVES:12)
Block(8,23,-4,LEAVES:12)
Block(8,23,-3,LEAVES:12)
Block(8,23,-2,LEAVES:12)
Block(8,23,-1,LEAVES:12)
Block(8,23,0,17:12)
Block(8,23,2,17:12)
Block(8,23,3,LEAVES:12)
Block(8,23,4,LEAVES:12)
Block(8,23,6,LEAVES:12)
Block(8,23,7,LEAVES:12)
Block(8,23,8,LEAVES:12)
Block(8,24,-3,LEAVES:12)
Block(8,24,-2,LEAVES:12)
Block(8,24,0,LEAVES:12)
Block(8,24,2,LEAVES:12)
Block(8,24,7,LEAVES:12)
Block(8,24,8,LEAVES:12)
Block(8,24,9,LEAVES:12)
Block(8,25,-2,LEAVES:12)
Block(8,25,4,LEAVES:12)
Block(8,25,8,LEAVES:12)
Block(8,26,3,LEAVES:12)
Block(8,26,4,LEAVES:12)
Block(8,26,5,LEAVES:12)
Block(8,27,0,LEAVES:12)
Block(8,27,4,LEAVES:12)
Block(8,28,-1,LEAVES:12)
Block(9,4,-6,LEAVES:12)
Block(9,4,-3,LEAVES:12)
Block(9,4,0,LEAVES:12)
Block(9,5,-5,LEAVES:12)
Block(9,5,-4,LEAVES:12)
Block(9,5,-3,LEAVES:12)
Block(9,5,-2,LEAVES:12)
Block(9,5,0,17:12)
Block(9,6,-3,LEAVES:12)
Block(9,6,-2,LEAVES:12)
Block(9,6,-1,LEAVES:12)
Block(9,6,0,17:12)
Block(9,7,-8,LEAVES:12)
Block(9,7,-7,LEAVES:12)
Block(9,7,-6,LEAVES:12)
Block(9,7,-2,LEAVES:12)
Block(9,7,-1,17:12)
Block(9,7,2,LEAVES:12)
Block(9,8,-7,LEAVES:12)
Block(9,8,-6,LEAVES:12)
Block(9,8,-5,LEAVES:12)
Block(9,8,-4,17:12)
Block(9,8,-3,17:12)
Block(9,8,-2,17:12)
Block(9,8,-1,LEAVES:12)
Block(9,8,1,LEAVES:12)
Block(9,8,2,LEAVES:12)
Block(9,8,3,LEAVES:12)
Block(9,9,-6,LEAVES:12)
Block(9,9,-4,LEAVES:12)
Block(9,9,-3,LEAVES:12)
Block(9,9,-2,LEAVES:12)
Block(9,9,1,LEAVES:12)
Block(9,9,2,LEAVES:12)
Block(9,9,3,LEAVES:12)
Block(9,10,-3,LEAVES:12)
Block(9,10,-1,LEAVES:12)
Block(9,10,0,LEAVES:12)
Block(9,10,1,LEAVES:12)
Block(9,10,4,LEAVES:12)
Block(9,10,5,LEAVES:12)
Block(9,10,6,LEAVES:12)
Block(9,10,7,LEAVES:12)
Block(9,10,8,LEAVES:12)
Block(9,10,9,LEAVES:12)
Block(9,11,-4,LEAVES:12)
Block(9,11,-2,LEAVES:12)
Block(9,11,0,LEAVES:12)
Block(9,11,1,LEAVES:12)
Block(9,11,2,LEAVES:12)
Block(9,11,3,LEAVES:12)
Block(9,11,4,LEAVES:12)
Block(9,11,5,17:12)
Block(9,11,6,LEAVES:12)
Block(9,11,7,LEAVES:12)
Block(9,11,8,LEAVES:12)
Block(9,12,-2,17:12)
Block(9,12,-1,LEAVES:12)
Block(9,12,0,LEAVES:12)
Block(9,12,1,LEAVES:12)
Block(9,12,3,LEAVES:12)
Block(9,12,4,LEAVES:12)
Block(9,12,5,17:12)
Block(9,12,6,LEAVES:12)
Block(9,12,7,LEAVES:12)
Block(9,13,-2,17:12)
Block(9,13,-1,LEAVES:12)
Block(9,13,0,LEAVES:12)
Block(9,13,1,17:12)
Block(9,13,2,LEAVES:12)
Block(9,13,3,LEAVES:12)
Block(9,13,4,LEAVES:12)
Block(9,13,5,LEAVES:12)
Block(9,13,8,LEAVES:12)
Block(9,13,9,LEAVES:12)
Block(9,13,10,LEAVES:12)
Block(9,14,-1,LEAVES:12)
Block(9,14,0,LEAVES:12)
Block(9,14,1,17:12)
Block(9,14,3,LEAVES:12)
Block(9,14,4,LEAVES:12)
Block(9,14,5,LEAVES:12)
Block(9,14,9,LEAVES:12)
Block(9,14,10,LEAVES:12)
Block(9,14,11,LEAVES:12)
Block(9,15,-3,LEAVES:12)
Block(9,15,-2,LEAVES:12)
Block(9,15,-1,LEAVES:12)
Block(9,15,0,17:12)
Block(9,15,1,LEAVES:12)
Block(9,15,4,LEAVES:12)
Block(9,15,10,LEAVES:12)
Block(9,16,-3,LEAVES:12)
Block(9,16,-2,LEAVES:12)
Block(9,16,-1,LEAVES:12)
Block(9,16,2,LEAVES:12)
Block(9,17,-4,LEAVES:12)
Block(9,17,-3,LEAVES:12)
Block(9,17,-2,LEAVES:12)
Block(9,17,5,LEAVES:12)
Block(9,17,6,LEAVES:12)
Block(9,18,-9,LEAVES:12)
Block(9,18,-8,LEAVES:12)
Block(9,18,-7,LEAVES:12)
Block(9,18,-3,LEAVES:12)
Block(9,18,1,LEAVES:12)
Block(9,18,6,17:12)
Block(9,18,7,LEAVES:12)
Block(9,18,9,LEAVES:12)
Block(9,18,10,LEAVES:12)
Block(9,18,11,LEAVES:12)
Block(9,19,-8,LEAVES:12)
Block(9,19,-4,LEAVES:12)
Block(9,19,1,LEAVES:12)
Block(9,19,3,17:12)
Block(9,19,4,17:12)
Block(9,19,5,LEAVES:12)
Block(9,19,6,17:12)
Block(9,19,9,LEAVES:12)
Block(9,19,10,LEAVES:12)
Block(9,19,11,LEAVES:12)
Block(9,20,-5,LEAVES:12)
Block(9,20,-4,LEAVES:12)
Block(9,20,-3,LEAVES:12)
Block(9,20,-2,LEAVES:12)
Block(9,20,1,LEAVES:12)
Block(9,20,2,LEAVES:12)
Block(9,20,3,LEAVES:12)
Block(9,20,4,LEAVES:12)
Block(9,20,5,LEAVES:12)
Block(9,20,6,LEAVES:12)
Block(9,20,7,LEAVES:12)
Block(9,20,10,LEAVES:12)
Block(9,21,-3,LEAVES:12)
Block(9,21,-2,LEAVES:12)
Block(9,21,-1,LEAVES:12)
Block(9,21,0,LEAVES:12)
Block(9,21,1,LEAVES:12)
Block(9,21,4,LEAVES:12)
Block(9,21,5,LEAVES:12)
Block(9,21,6,LEAVES:12)
Block(9,22,-6,LEAVES:12)
Block(9,22,-5,LEAVES:12)
Block(9,22,-4,LEAVES:12)
Block(9,22,-3,LEAVES:12)
Block(9,22,-2,LEAVES:12)
Block(9,22,-1,LEAVES:12)
Block(9,22,0,LEAVES:12)
Block(9,22,1,LEAVES:12)
Block(9,22,2,LEAVES:12)
Block(9,22,3,LEAVES:12)
Block(9,22,4,LEAVES:12)
Block(9,22,5,LEAVES:12)
Block(9,22,6,LEAVES:12)
Block(9,23,-5,LEAVES:12)
Block(9,23,-4,LEAVES:12)
Block(9,23,-3,LEAVES:12)
Block(9,23,-2,LEAVES:12)
Block(9,23,1,LEAVES:12)
Block(9,23,3,LEAVES:12)
Block(9,23,4,LEAVES:12)
Block(9,23,5,LEAVES:12)
Block(9,23,7,LEAVES:12)
Block(9,24,-4,LEAVES:12)
Block(9,24,-1,LEAVES:12)
Block(9,24,0,LEAVES:12)
Block(9,24,1,LEAVES:12)
Block(9,24,2,LEAVES:12)
Block(9,24,4,LEAVES:12)
Block(9,24,8,LEAVES:12)
Block(9,25,0,LEAVES:12)
Block(9,25,1,LEAVES:12)
Block(9,26,3,LEAVES:12)
Block(9,26,4,LEAVES:12)
Block(10,3,0,LEAVES:12)
Block(10,4,-4,LEAVES:12)
Block(10,4,-3,LEAVES:12)
Block(10,4,-2,LEAVES:12)
Block(10,4,-1,LEAVES:12)
Block(10,4,0,LEAVES:12)
Block(10,4,1,LEAVES:12)
Block(10,5,-3,LEAVES:12)
Block(10,5,-2,LEAVES:12)
Block(10,5,-1,LEAVES:12)
Block(10,5,0,17:12)
Block(10,5,1,LEAVES:12)
Block(10,6,-2,LEAVES:12)
Block(10,6,-1,LEAVES:12)
Block(10,6,0,LEAVES:12)
Block(10,7,-7,LEAVES:12)
Block(10,7,-5,LEAVES:12)
Block(10,7,-3,LEAVES:12)
Block(10,7,-2,LEAVES:12)
Block(10,7,-1,LEAVES:12)
Block(10,7,2,LEAVES:12)
Block(10,8,-6,LEAVES:12)
Block(10,8,-3,LEAVES:12)
Block(10,8,-2,LEAVES:12)
Block(10,8,-1,LEAVES:12)
Block(10,8,0,LEAVES:12)
Block(10,8,2,LEAVES:12)
Block(10,9,-5,LEAVES:12)
Block(10,9,-4,LEAVES:12)
Block(10,9,-3,LEAVES:12)
Block(10,9,-1,LEAVES:12)
Block(10,9,2,LEAVES:12)
Block(10,9,3,LEAVES:12)
Block(10,9,4,LEAVES:12)
Block(10,10,-4,LEAVES:12)
Block(10,10,-2,LEAVES:12)
Block(10,10,-1,LEAVES:12)
Block(10,10,0,LEAVES:12)
Block(10,10,3,LEAVES:12)
Block(10,10,4,LEAVES:12)
Block(10,10,5,LEAVES:12)
Block(10,10,6,LEAVES:12)
Block(10,10,7,LEAVES:12)
Block(10,10,8,LEAVES:12)
Block(10,11,-3,LEAVES:12)
Block(10,11,-2,LEAVES:12)
Block(10,11,-1,LEAVES:12)
Block(10,11,0,LEAVES:12)
Block(10,11,1,LEAVES:12)
Block(10,11,2,LEAVES:12)
Block(10,11,3,LEAVES:12)
Block(10,11,4,LEAVES:12)
Block(10,11,7,LEAVES:12)
Block(10,12,-2,LEAVES:12)
Block(10,12,-1,LEAVES:12)
Block(10,12,0,LEAVES:12)
Block(10,12,3,LEAVES:12)
Block(10,12,4,LEAVES:12)
Block(10,12,5,17:12)
Block(10,13,-1,LEAVES:12)
Block(10,13,0,LEAVES:12)
Block(10,13,1,17:12)
Block(10,13,3,LEAVES:12)
Block(10,13,4,LEAVES:12)
Block(10,13,5,LEAVES:12)
Block(10,13,7,LEAVES:12)
Block(10,13,9,LEAVES:12)
Block(10,14,-3,LEAVES:12)
Block(10,14,-2,LEAVES:12)
Block(10,14,-1,LEAVES:12)
Block(10,14,0,LEAVES:12)
Block(10,14,2,LEAVES:12)
Block(10,14,3,LEAVES:12)
Block(10,14,4,LEAVES:12)
Block(10,14,6,LEAVES:12)
Block(10,14,10,LEAVES:12)
Block(10,15,-4,LEAVES:12)
Block(10,15,-3,LEAVES:12)
Block(10,15,-2,LEAVES:12)
Block(10,15,-1,LEAVES:12)
Block(10,15,0,LEAVES:12)
Block(10,15,1,LEAVES:12)
Block(10,15,2,LEAVES:12)
Block(10,15,3,LEAVES:12)
Block(10,16,-3,LEAVES:12)
Block(10,16,-2,LEAVES:12)
Block(10,16,-1,LEAVES:12)
Block(10,16,1,LEAVES:12)
Block(10,16,2,LEAVES:12)
Block(10,16,3,LEAVES:12)
Block(10,16,5,LEAVES:12)
Block(10,17,-3,LEAVES:12)
Block(10,17,-2,LEAVES:12)
Block(10,17,-1,LEAVES:12)
Block(10,17,1,LEAVES:12)
Block(10,17,2,LEAVES:12)
Block(10,17,6,LEAVES:12)
Block(10,18,-8,LEAVES:12)
Block(10,18,-2,LEAVES:12)
Block(10,18,0,LEAVES:12)
Block(10,18,1,LEAVES:12)
Block(10,18,2,LEAVES:12)
Block(10,18,5,LEAVES:12)
Block(10,18,10,LEAVES:12)
Block(10,19,1,LEAVES:12)
Block(10,19,2,LEAVES:12)
Block(10,19,4,LEAVES:12)
Block(10,19,5,LEAVES:12)
Block(10,19,6,LEAVES:12)
Block(10,19,7,17:12)
Block(10,19,8,LEAVES:12)
Block(10,19,10,LEAVES:12)
Block(10,20,-3,LEAVES:12)
Block(10,20,-2,LEAVES:12)
Block(10,20,-1,LEAVES:12)
Block(10,20,0,LEAVES:12)
Block(10,20,1,LEAVES:12)
Block(10,20,2,LEAVES:12)
Block(10,20,4,LEAVES:12)
Block(10,20,5,LEAVES:12)
Block(10,20,6,LEAVES:12)
Block(10,21,-2,LEAVES:12)
Block(10,21,0,LEAVES:12)
Block(10,21,1,LEAVES:12)
Block(10,21,5,LEAVES:12)
Block(10,21,6,LEAVES:12)
Block(10,21,7,LEAVES:12)
Block(10,22,-5,LEAVES:12)
Block(10,22,1,LEAVES:12)
Block(10,22,3,LEAVES:12)
Block(10,22,4,LEAVES:12)
Block(10,22,5,LEAVES:12)
Block(10,22,6,LEAVES:12)
Block(10,23,-6,LEAVES:12)
Block(10,23,-5,LEAVES:12)
Block(10,23,-4,LEAVES:12)
Block(10,23,4,LEAVES:12)
Block(10,24,-5,LEAVES:12)
Block(10,24,-2,LEAVES:12)
Block(10,24,-1,LEAVES:12)
Block(10,24,0,LEAVES:12)
Block(10,25,-1,LEAVES:12)
Block(10,25,0,LEAVES:12)
Block(10,25,1,LEAVES:12)
Block(10,25,3,LEAVES:12)
Block(10,26,0,LEAVES:12)
Block(10,26,2,LEAVES:12)
Block(10,26,3,LEAVES:12)
Block(10,26,4,LEAVES:12)
Block(10,27,3,LEAVES:12)
Block(11,3,-1,LEAVES:12)
Block(11,3,0,LEAVES:12)
Block(11,3,1,LEAVES:12)
Block(11,4,-3,LEAVES:12)
Block(11,4,0,LEAVES:12)
Block(11,4,1,LEAVES:12)
Block(11,4,2,LEAVES:12)
Block(11,5,-2,LEAVES:12)
Block(11,5,1,LEAVES:12)
Block(11,6,-1,LEAVES:12)
Block(11,6,2,LEAVES:12)
Block(11,7,-6,LEAVES:12)
Block(11,7,-5,LEAVES:12)
Block(11,7,-4,LEAVES:12)
Block(11,7,-2,LEAVES:12)
Block(11,7,-1,LEAVES:12)
Block(11,7,0,LEAVES:12)
Block(11,7,1,LEAVES:12)
Block(11,7,2,LEAVES:12)
Block(11,7,3,LEAVES:12)
Block(11,8,-5,LEAVES:12)
Block(11,8,-3,LEAVES:12)
Block(11,8,-2,LEAVES:12)
Block(11,8,-1,LEAVES:12)
Block(11,8,2,LEAVES:12)
Block(11,9,-4,LEAVES:12)
Block(11,9,-2,LEAVES:12)
Block(11,9,-1,LEAVES:12)
Block(11,9,0,LEAVES:12)
Block(11,9,3,LEAVES:12)
Block(11,9,4,LEAVES:12)
Block(11,9,5,LEAVES:12)
Block(11,10,-1,LEAVES:12)
Block(11,10,0,LEAVES:12)
Block(11,10,1,LEAVES:12)
Block(11,10,2,LEAVES:12)
Block(11,10,3,LEAVES:12)
Block(11,10,4,LEAVES:12)
Block(11,10,7,LEAVES:12)
Block(11,11,-4,LEAVES:12)
Block(11,11,-3,LEAVES:12)
Block(11,11,-2,LEAVES:12)
Block(11,11,0,LEAVES:12)
Block(11,11,2,LEAVES:12)
Block(11,11,3,LEAVES:12)
Block(11,12,-3,LEAVES:12)
Block(11,12,-2,LEAVES:12)
Block(11,12,-1,LEAVES:12)
Block(11,12,1,17:12)
Block(11,12,2,LEAVES:12)
Block(11,13,-2,LEAVES:12)
Block(11,13,-1,LEAVES:12)
Block(11,13,0,LEAVES:12)
Block(11,13,1,LEAVES:12)
Block(11,13,4,LEAVES:12)
Block(11,13,6,LEAVES:12)
Block(11,13,7,LEAVES:12)
Block(11,13,8,LEAVES:12)
Block(11,14,-4,LEAVES:12)
Block(11,14,-3,LEAVES:12)
Block(11,14,-2,LEAVES:12)
Block(11,14,-1,LEAVES:12)
Block(11,14,0,LEAVES:12)
Block(11,14,3,LEAVES:12)
Block(11,14,5,LEAVES:12)
Block(11,14,6,LEAVES:12)
Block(11,14,7,LEAVES:12)
Block(11,15,-5,LEAVES:12)
Block(11,15,-4,LEAVES:12)
Block(11,15,-3,LEAVES:12)
Block(11,15,-2,LEAVES:12)
Block(11,15,-1,LEAVES:12)
Block(11,15,0,LEAVES:12)
Block(11,15,1,LEAVES:12)
Block(11,15,6,LEAVES:12)
Block(11,16,-4,LEAVES:12)
Block(11,16,-1,LEAVES:12)
Block(11,16,0,LEAVES:12)
Block(11,16,1,LEAVES:12)
Block(11,16,2,LEAVES:12)
Block(11,16,4,LEAVES:12)
Block(11,16,5,LEAVES:12)
Block(11,16,6,LEAVES:12)
Block(11,17,-2,LEAVES:12)
Block(11,17,0,LEAVES:12)
Block(11,17,1,LEAVES:12)
Block(11,17,2,LEAVES:12)
Block(11,17,5,LEAVES:12)
Block(11,17,6,LEAVES:12)
Block(11,17,7,LEAVES:12)
Block(11,18,1,LEAVES:12)
Block(11,18,2,LEAVES:12)
Block(11,18,3,LEAVES:12)
Block(11,18,4,LEAVES:12)
Block(11,18,5,LEAVES:12)
Block(11,18,6,LEAVES:12)
Block(11,19,2,LEAVES:12)
Block(11,19,3,LEAVES:12)
Block(11,19,4,LEAVES:12)
Block(11,19,5,LEAVES:12)
Block(11,19,6,LEAVES:12)
Block(11,19,7,LEAVES:12)
Block(11,20,-2,LEAVES:12)
Block(11,20,1,LEAVES:12)
Block(11,20,2,LEAVES:12)
Block(11,20,3,LEAVES:12)
Block(11,20,4,LEAVES:12)
Block(11,21,0,LEAVES:12)
Block(11,21,1,LEAVES:12)
Block(11,21,2,LEAVES:12)
Block(11,21,6,LEAVES:12)
Block(11,21,8,LEAVES:12)
Block(11,22,1,LEAVES:12)
Block(11,22,4,LEAVES:12)
Block(11,23,-5,LEAVES:12)
Block(11,24,-1,LEAVES:12)
Block(11,25,0,LEAVES:12)
Block(11,25,2,LEAVES:12)
Block(11,25,3,LEAVES:12)
Block(11,25,4,LEAVES:12)
Block(11,26,1,LEAVES:12)
Block(11,26,2,LEAVES:12)
Block(11,26,3,LEAVES:12)
Block(11,27,2,LEAVES:12)
Block(12,3,0,LEAVES:12)
Block(12,4,1,LEAVES:12)
Block(12,6,-2,LEAVES:12)
Block(12,6,-1,LEAVES:12)
Block(12,6,0,LEAVES:12)
Block(12,6,1,LEAVES:12)
Block(12,6,2,LEAVES:12)
Block(12,6,3,LEAVES:12)
Block(12,7,-5,LEAVES:12)
Block(12,7,-4,LEAVES:12)
Block(12,7,-3,LEAVES:12)
Block(12,7,-2,LEAVES:12)
Block(12,7,-1,LEAVES:12)
Block(12,7,0,LEAVES:12)
Block(12,7,1,LEAVES:12)
Block(12,7,2,LEAVES:12)
Block(12,8,-6,LEAVES:12)
Block(12,8,-5,LEAVES:12)
Block(12,8,-4,LEAVES:12)
Block(12,8,-2,LEAVES:12)
Block(12,8,1,LEAVES:12)
Block(12,9,-5,LEAVES:12)
Block(12,9,-1,LEAVES:12)
Block(12,9,4,LEAVES:12)
Block(12,10,0,LEAVES:12)
Block(12,10,3,LEAVES:12)
Block(12,11,-3,LEAVES:12)
Block(12,11,-1,LEAVES:12)
Block(12,11,0,LEAVES:12)
Block(12,11,1,LEAVES:12)
Block(12,11,2,LEAVES:12)
Block(12,11,3,LEAVES:12)
Block(12,12,-2,LEAVES:12)
Block(12,12,-1,LEAVES:12)
Block(12,12,0,LEAVES:12)
Block(12,13,-2,LEAVES:12)
Block(12,13,-1,LEAVES:12)
Block(12,13,0,LEAVES:12)
Block(12,13,1,LEAVES:12)
Block(12,13,2,LEAVES:12)
Block(12,13,7,LEAVES:12)
Block(12,14,-3,LEAVES:12)
Block(12,14,-1,LEAVES:12)
Block(12,14,0,LEAVES:12)
Block(12,14,1,LEAVES:12)
Block(12,14,6,LEAVES:12)
Block(12,14,7,LEAVES:12)
Block(12,14,8,LEAVES:12)
Block(12,15,-4,LEAVES:12)
Block(12,15,-1,LEAVES:12)
Block(12,15,0,LEAVES:12)
Block(12,15,1,LEAVES:12)
Block(12,15,7,LEAVES:12)
Block(12,16,0,LEAVES:12)
Block(12,16,1,LEAVES:12)
Block(12,16,5,LEAVES:12)
Block(12,17,-1,LEAVES:12)
Block(12,17,0,LEAVES:12)
Block(12,17,1,LEAVES:12)
Block(12,17,4,LEAVES:12)
Block(12,17,5,LEAVES:12)
Block(12,17,6,LEAVES:12)
Block(12,18,0,LEAVES:12)
Block(12,18,2,LEAVES:12)
Block(12,18,5,LEAVES:12)
Block(12,18,6,LEAVES:12)
Block(12,19,4,LEAVES:12)
Block(12,20,2,LEAVES:12)
Block(12,20,3,LEAVES:12)
Block(12,20,4,LEAVES:12)
Block(12,20,5,LEAVES:12)
Block(12,20,8,LEAVES:12)
Block(12,21,1,LEAVES:12)
Block(12,21,4,LEAVES:12)
Block(12,21,7,LEAVES:12)
Block(12,21,8,LEAVES:12)
Block(12,21,9,LEAVES:12)
Block(12,22,8,LEAVES:12)
Block(12,25,3,LEAVES:12)
Block(12,26,2,LEAVES:12)
Block(13,6,-1,LEAVES:12)
Block(13,6,2,LEAVES:12)
Block(13,7,-4,LEAVES:12)
Block(13,7,-2,LEAVES:12)
Block(13,7,1,LEAVES:12)
Block(13,8,-5,LEAVES:12)
Block(13,10,2,LEAVES:12)
Block(13,10,3,LEAVES:12)
Block(13,10,4,LEAVES:12)
Block(13,11,-2,LEAVES:12)
Block(13,11,-1,LEAVES:12)
Block(13,11,0,LEAVES:12)
Block(13,11,1,LEAVES:12)
Block(13,11,2,LEAVES:12)
Block(13,11,3,LEAVES:12)
Block(13,12,-1,LEAVES:12)
Block(13,12,2,LEAVES:12)
Block(13,13,-3,LEAVES:12)
Block(13,13,-2,LEAVES:12)
Block(13,13,-1,LEAVES:12)
Block(13,13,1,LEAVES:12)
Block(13,13,2,LEAVES:12)
Block(13,13,3,LEAVES:12)
Block(13,14,-2,LEAVES:12)
Block(13,14,-1,LEAVES:12)
Block(13,14,0,LEAVES:12)
Block(13,14,1,LEAVES:12)
Block(13,14,2,LEAVES:12)
Block(13,14,7,LEAVES:12)
Block(13,15,-1,LEAVES:12)
Block(13,15,0,LEAVES:12)
Block(13,15,1,LEAVES:12)
Block(13,16,-1,LEAVES:12)
Block(13,16,0,LEAVES:12)
Block(13,16,1,LEAVES:12)
Block(13,17,-2,LEAVES:12)
Block(13,17,-1,LEAVES:12)
Block(13,17,0,LEAVES:12)
Block(13,17,5,LEAVES:12)
Block(13,18,-1,LEAVES:12)
Block(13,19,3,LEAVES:12)
Block(13,19,4,LEAVES:12)
Block(13,19,5,LEAVES:12)
Block(13,20,4,LEAVES:12)
Block(13,20,5,LEAVES:12)
Block(13,20,6,LEAVES:12)
Block(13,20,7,LEAVES:12)
Block(13,20,8,LEAVES:12)
Block(13,20,9,LEAVES:12)
Block(13,21,5,LEAVES:12)
Block(13,21,6,LEAVES:12)
Block(13,21,7,LEAVES:12)
Block(13,21,8,LEAVES:12)
Block(13,22,7,LEAVES:12)
Block(14,10,1,LEAVES:12)
Block(14,10,2,LEAVES:12)
Block(14,10,3,LEAVES:12)
Block(14,11,-1,LEAVES:12)
Block(14,11,2,LEAVES:12)
Block(14,13,-2,LEAVES:12)
Block(14,13,2,LEAVES:12)
Block(14,14,-1,LEAVES:12)
Block(14,14,1,LEAVES:12)
Block(14,16,0,LEAVES:12)
Block(14,17,-1,LEAVES:12)
Block(14,19,4,LEAVES:12)
Block(14,20,5,LEAVES:12)
Block(14,20,8,LEAVES:12)
Block(14,21,7,LEAVES:12)
Block(15,10,2,LEAVES:12)


#######################################################################
# +-----------------------------------------------------------------+ #
# |                             Entities                            | #
# +-----------------------------------------------------------------+ #
#######################################################################

# Entity() spawns an entity instead of a block. The entity is spawned only once when the BO3 is spawned.
# Entities are persistent by default so they don't de-spawn when no player is near, they are only unloaded.
# Usage: Entity(x,y,z,mobName,groupSize,NameTagOrNBTFileName) or Entity(x,y,z,mobName,groupSize)
# Use /tc entities or /otg entities to get a list of entities that can be used as mobName, this includes entities added by other mods.
# NameTagOrNBTFileName can be either a nametag for the mob or an nbt file (such as mymobinfo.nbt or mymobinfo.txt).
# When using a text file you can use the same mob spawning parameters used with the /summon command to equip the
# entity and give it custom attributes etc. You can copy the DATA part of a summon command including surrounding
# curly braces to a .txt file, for instance for: "/summon Skeleton x y z {DATA}"

#######################################################################
# +-----------------------------------------------------------------+ #
# |                            BO3 checks                           | #
# +-----------------------------------------------------------------+ #
#######################################################################

# Require a condition at a certain location in order for the BO3 to be spawned.
# BlockCheck(x,y,z,BlockName[,BlockName[,...]]) - one of the blocks must be at the location
# BlockCheckNot(x,y,z,BlockName[,BlockName[,...]]) - all the blocks must not be at the location
# LightCheck(x,y,z,minLightLevel,maxLightLevel) - light must be between min and max (inclusive)

# You can use "Solid" as a BlockName for matching all solid blocks or "All" to match all blocks that aren't air.

# Examples:
BlockCheck(0,-1,0,GRASS,DIRT,STONE)
#   BlockCheck(0,-1,0,Solid)       Require any solid block just below the object
#   BlockCheck(0,-1,0,WOOL)        Require any type of wool just below the object
#   BlockCheck(0,-1,0,WOOL:0)      Require white wool just below the object
#   BlockCheckNot(0,-1,0,WOOL:0)   Require that there is no white wool below the object
#   LightCheck(0,0,0,0,1)          Require almost complete darkness just below the object

