#######################################################################
# +-----------------------------------------------------------------+ #
# |                            BO3 object                           | #
# +-----------------------------------------------------------------+ #
#######################################################################

# This is the config file of a custom object.
# If you add this object correctly to your BiomeConfigs, it will spawn in the world.

# This is the creator of this BO3 object
Author: BO3 BulkEdit (by LanToaster)

# A short description of this BO3 object
Description: This Object was Created with BO3_BulkEdit

# The BO3 version, don't change this! It can be used by external applications to do a version check.
Version: 3

# The settings mode, WriteAll, WriteWithoutComments or WriteDisable. See WorldConfig.
SettingsMode: WriteDisable


#######################################################################
# +-----------------------------------------------------------------+ #
# |                          Main settings                          | #
# +-----------------------------------------------------------------+ #
#######################################################################

# This needs to be set to true to spawn the object in the Tree and Sapling resources.
Tree: true

# The frequency of the BO3 from 1 to 200. Tries this many times to spawn this BO3 when using the CustomObject(...) resource.
# Ignored by Tree(..), Sapling(..) and CustomStructure(..)
Frequency: 200

# The rarity of the BO3 from 0 to 100. Each spawn attempt has rarity% chance to succeed when using the CustomObject(...) resource.
# Ignored by Tree(..), Sapling(..) and CustomStructure(..)
Rarity: 100

# If you set this to true, the BO3 will be placed with a random rotation.
RotateRandomly: True

# The spawn height of the BO3 - randomY, highestBlock or highestSolidBlock.
SpawnHeight: highestSolidBlock

# The height limits for the BO3.
MinHeight: 58

MaxHeight: 80

# Objects can have other objects attacthed to it: branches. Branches can also
# have branches attached to it, which can also have branches, etc. This is the
# maximum branch depth for this objects.
MaxBranchDepth: 10

# When spawned with the UseWorld keyword, this BO3 should NOT spawn in the following biomes.
# If you writer.write the BO3 name directly in the BiomeConfigs, this will be ignored.
ExcludedBiomes: All


#######################################################################
# +-----------------------------------------------------------------+ #
# |                      Source block settings                      | #
# +-----------------------------------------------------------------+ #
#######################################################################

# The block(s) the BO3 should spawn in.
SourceBlocks: AIR, STATIONARY_WATER, FLOWING_WATER

# The maximum percentage of the BO3 that can be outside the SourceBlock.
# The BO3 won't be placed on a location with more blocks outside the SourceBlock than this percentage.
MaxPercentageOutsideSourceBlock: 0

# What to do when a block is about to be placed outside the SourceBlock? (dontPlace, placeAnyway)
OutsideSourceBlock: dontPlace


#######################################################################
# +-----------------------------------------------------------------+ #
# |                              Blocks                             | #
# +-----------------------------------------------------------------+ #
#######################################################################

# All the blocks used in the BO3 are listed here. Possible blocks:
# Block(x,y,z,id[.data][,nbtfile.nbt)
# RandomBlock(x,y,z,id[:data][,nbtfile.nbt],chance[,id[:data][,nbtfile.nbt],chance[,...]])
# So RandomBlock(0,0,0,CHEST,chest.nbt,50,CHEST,anotherchest.nbt,100) will spawn a chest at
# the BO3 origin, and give it a 50% chance to have the contents of chest.nbt, or, if that
# fails, a 100% percent chance to have the contents of anotherchest.nbt.
Block(1,0,-2,LOG:3)
Block(0,0,-1,LOG:3)
Block(1,0,-1,LOG:3)
Block(2,0,-1,LOG:3)
Block(3,0,-1,LOG:3)
Block(1,0,0,LOG:3)
Block(2,0,0,LOG:3)
Block(1,1,-1,LOG:3)
Block(2,1,-1,LOG:3)
Block(1,1,0,LOG:3)
Block(2,1,0,LOG:3)
Block(1,2,-1,LOG:3)
Block(2,2,-1,LOG:3)
Block(1,2,0,LOG:3)
Block(2,2,0,LOG:3)
Block(1,3,-1,LOG:3)
Block(2,3,-1,LOG:3)
Block(1,3,0,LOG:3)
Block(2,3,0,LOG:3)
Block(1,4,-1,LOG:3)
Block(2,4,-1,LOG:3)
Block(1,4,0,LOG:3)
Block(2,4,0,LOG:3)
Block(0,5,-1,LOG:3)
Block(1,5,-1,LOG:3)
Block(2,5,-1,LOG:3)
Block(1,5,0,LOG:3)
Block(2,5,0,LOG:3)
Block(0,5,1,LOG:3)
Block(1,5,1,LOG:3)
Block(2,5,1,LOG:3)
Block(0,6,-1,LOG:3)
Block(1,6,-1,LOG:3)
Block(2,6,-1,LOG:3)
Block(1,6,0,LOG:3)
Block(2,6,0,LOG:3)
Block(0,6,1,LOG:3)
Block(1,6,1,LOG:3)
Block(2,6,1,LOG:3)
Block(0,7,-2,LOG:3)
Block(-1,7,-1,LOG:3)
Block(0,7,-1,LOG:3)
Block(1,7,-1,LOG:3)
Block(2,7,-1,LOG:3)
Block(1,7,0,LOG:3)
Block(2,7,0,LOG:3)
Block(0,7,1,LOG:3)
Block(2,7,1,LOG:3)
Block(1,7,2,LOG:3)
Block(-1,8,-2,LOG:3)
Block(0,8,-2,LOG:3)
Block(1,8,-2,LEAVES:3)
Block(-1,8,-1,LOG:3)
Block(0,8,-1,LOG:3)
Block(1,8,-1,LOG:3)
Block(2,8,-1,LOG:3)
Block(1,8,0,LOG:3)
Block(2,8,0,LOG:3)
Block(0,8,1,LOG:3)
Block(2,8,1,LOG:3)
Block(1,8,2,LOG:3)
Block(0,9,-3,LEAVES:3)
Block(1,9,-3,LEAVES:3)
Block(2,9,-3,LEAVES:3)
Block(-1,9,-2,LOG:3)
Block(0,9,-2,LOG:3)
Block(1,9,-2,LOG:3)
Block(2,9,-2,LEAVES:3)
Block(3,9,-2,LEAVES:3)
Block(-2,9,-1,LOG:3)
Block(-1,9,-1,LOG:3)
Block(0,9,-1,LOG:3)
Block(1,9,-1,LOG:3)
Block(2,9,-1,LOG:3)
Block(3,9,-1,LEAVES:3)
Block(-1,9,0,LEAVES:3)
Block(0,9,0,LEAVES:3)
Block(1,9,0,LOG:3)
Block(2,9,0,LOG:3)
Block(3,9,0,LEAVES:3)
Block(0,9,1,LOG:3)
Block(1,9,1,LEAVES:3)
Block(2,9,1,LOG:3)
Block(1,9,3,LOG:3)
Block(0,10,-4,LEAVES:3)
Block(1,10,-4,LEAVES:3)
Block(2,10,-4,LEAVES:3)
Block(-1,10,-3,LOG:3)
Block(0,10,-3,LOG:3)
Block(1,10,-3,LEAVES:3)
Block(2,10,-3,LEAVES:3)
Block(3,10,-3,LEAVES:3)
Block(-2,10,-2,LOG:3)
Block(-1,10,-2,LEAVES:3)
Block(0,10,-2,LEAVES:3)
Block(1,10,-2,LOG:3)
Block(2,10,-2,LOG:3)
Block(3,10,-2,LEAVES:3)
Block(4,10,-2,LEAVES:3)
Block(-2,10,-1,LEAVES:3)
Block(-1,10,-1,LOG:3)
Block(0,10,-1,LOG:3)
Block(1,10,-1,LOG:3)
Block(2,10,-1,LOG:3)
Block(3,10,-1,LEAVES:3)
Block(4,10,-1,LEAVES:3)
Block(-2,10,0,LEAVES:3)
Block(-1,10,0,LEAVES:3)
Block(0,10,0,LEAVES:3)
Block(1,10,0,LOG:3)
Block(2,10,0,LOG:3)
Block(3,10,0,LEAVES:3)
Block(4,10,0,LEAVES:3)
Block(-1,10,1,LEAVES:3)
Block(0,10,1,LOG:3)
Block(1,10,1,LEAVES:3)
Block(2,10,1,LOG:3)
Block(3,10,1,LEAVES:3)
Block(0,10,2,LOG:3)
Block(1,10,2,LEAVES:3)
Block(2,10,2,LOG:3)
Block(1,10,3,LOG:3)
Block(0,10,4,LEAVES:3)
Block(1,10,4,LEAVES:3)
Block(2,10,4,LEAVES:3)
Block(1,10,5,LEAVES:3)
Block(-1,11,-4,LEAVES:3)
Block(0,11,-4,LEAVES:3)
Block(1,11,-4,LEAVES:3)
Block(2,11,-4,LEAVES:3)
Block(3,11,-4,LEAVES:3)
Block(-2,11,-3,LOG:3)
Block(-1,11,-3,LEAVES:3)
Block(0,11,-3,LOG:3)
Block(1,11,-3,LEAVES:3)
Block(2,11,-3,LEAVES:3)
Block(3,11,-3,LEAVES:3)
Block(4,11,-3,LEAVES:3)
Block(-3,11,-2,LOG:3)
Block(-2,11,-2,LEAVES:3)
Block(-1,11,-2,LOG:3)
Block(0,11,-2,LEAVES:3)
Block(1,11,-2,LOG:3)
Block(2,11,-2,LOG:3)
Block(3,11,-2,LEAVES:3)
Block(4,11,-2,LEAVES:3)
Block(-2,11,-1,LEAVES:3)
Block(-1,11,-1,LEAVES:3)
Block(0,11,-1,LOG:3)
Block(1,11,-1,LOG:3)
Block(2,11,-1,LOG:3)
Block(3,11,-1,LEAVES:3)
Block(4,11,-1,LEAVES:3)
Block(-2,11,0,LEAVES:3)
Block(-1,11,0,LEAVES:3)
Block(0,11,0,LEAVES:3)
Block(1,11,0,LOG:3)
Block(2,11,0,LOG:3)
Block(3,11,0,LEAVES:3)
Block(4,11,0,LEAVES:3)
Block(-2,11,1,LEAVES:3)
Block(-1,11,1,LEAVES:3)
Block(0,11,1,LOG:3)
Block(1,11,1,LEAVES:3)
Block(2,11,1,LEAVES:3)
Block(3,11,1,LOG:3)
Block(4,11,1,LEAVES:3)
Block(-2,11,2,LEAVES:3)
Block(-1,11,2,LEAVES:3)
Block(0,11,2,LOG:3)
Block(1,11,2,LEAVES:3)
Block(2,11,2,LOG:3)
Block(3,11,2,LEAVES:3)
Block(4,11,2,LEAVES:3)
Block(-2,11,3,LEAVES:3)
Block(-1,11,3,LEAVES:3)
Block(0,11,3,LEAVES:3)
Block(1,11,3,LEAVES:3)
Block(2,11,3,LEAVES:3)
Block(3,11,3,LEAVES:3)
Block(4,11,3,LEAVES:3)
Block(-2,11,4,LEAVES:3)
Block(-1,11,4,LEAVES:3)
Block(0,11,4,LEAVES:3)
Block(1,11,4,LOG:3)
Block(2,11,4,LEAVES:3)
Block(3,11,4,LEAVES:3)
Block(4,11,4,LEAVES:3)
Block(-2,11,5,LEAVES:3)
Block(-1,11,5,LEAVES:3)
Block(0,11,5,LEAVES:3)
Block(1,11,5,LEAVES:3)
Block(2,11,5,LEAVES:3)
Block(3,11,5,LEAVES:3)
Block(4,11,5,LEAVES:3)
Block(-2,11,6,LEAVES:3)
Block(-1,11,6,LEAVES:3)
Block(0,11,6,LEAVES:3)
Block(1,11,6,LEAVES:3)
Block(2,11,6,LEAVES:3)
Block(3,11,6,LEAVES:3)
Block(4,11,6,LEAVES:3)
Block(-1,11,7,LEAVES:3)
Block(0,11,7,LEAVES:3)
Block(1,11,7,LEAVES:3)
Block(2,11,7,LEAVES:3)
Block(3,11,7,LEAVES:3)
Block(-3,12,-6,LEAVES:3)
Block(-4,12,-5,LEAVES:3)
Block(-3,12,-5,LEAVES:3)
Block(-2,12,-5,LEAVES:3)
Block(1,12,-5,LEAVES:3)
Block(-3,12,-4,LEAVES:3)
Block(-2,12,-4,LOG:3)
Block(-1,12,-4,LEAVES:3)
Block(0,12,-4,LOG:3)
Block(1,12,-4,LEAVES:3)
Block(2,12,-4,LEAVES:3)
Block(3,12,-4,LEAVES:3)
Block(-2,12,-3,LOG:3)
Block(-1,12,-3,LEAVES:3)
Block(0,12,-3,LEAVES:3)
Block(1,12,-3,LOG:3)
Block(2,12,-3,LEAVES:3)
Block(3,12,-3,LOG:3)
Block(4,12,-3,LEAVES:3)
Block(-3,12,-2,LOG:3)
Block(-2,12,-2,LEAVES:3)
Block(-1,12,-2,LOG:3)
Block(0,12,-2,LEAVES:3)
Block(1,12,-2,LEAVES:3)
Block(2,12,-2,LEAVES:3)
Block(3,12,-2,LEAVES:3)
Block(4,12,-2,LEAVES:3)
Block(-3,12,-1,LEAVES:3)
Block(-2,12,-1,LEAVES:3)
Block(-1,12,-1,LEAVES:3)
Block(0,12,-1,LOG:3)
Block(1,12,-1,LEAVES:3)
Block(2,12,-1,LEAVES:3)
Block(3,12,-1,LEAVES:3)
Block(4,12,-1,LEAVES:3)
Block(5,12,-1,LEAVES:3)
Block(-2,12,0,LEAVES:3)
Block(-1,12,0,LEAVES:3)
Block(0,12,0,LEAVES:3)
Block(1,12,0,LEAVES:3)
Block(2,12,0,LEAVES:3)
Block(3,12,0,LEAVES:3)
Block(4,12,0,LEAVES:3)
Block(-3,12,1,LEAVES:3)
Block(-2,12,1,LEAVES:3)
Block(-1,12,1,LEAVES:3)
Block(0,12,1,LOG:3)
Block(1,12,1,LEAVES:3)
Block(2,12,1,LEAVES:3)
Block(3,12,1,LEAVES:3)
Block(4,12,1,LEAVES:3)
Block(5,12,1,LEAVES:3)
Block(-3,12,2,LEAVES:3)
Block(-2,12,2,LEAVES:3)
Block(-1,12,2,LEAVES:3)
Block(0,12,2,LOG:3)
Block(1,12,2,LEAVES:3)
Block(2,12,2,LOG:3)
Block(3,12,2,LEAVES:3)
Block(4,12,2,LOG:3)
Block(5,12,2,LEAVES:3)
Block(-3,12,3,LEAVES:3)
Block(-2,12,3,LEAVES:3)
Block(-1,12,3,LEAVES:3)
Block(0,12,3,LEAVES:3)
Block(1,12,3,LEAVES:3)
Block(2,12,3,LEAVES:3)
Block(3,12,3,LEAVES:3)
Block(4,12,3,LEAVES:3)
Block(5,12,3,LEAVES:3)
Block(-4,12,4,LEAVES:3)
Block(-3,12,4,LEAVES:3)
Block(-2,12,4,LEAVES:3)
Block(-1,12,4,LEAVES:3)
Block(0,12,4,LEAVES:3)
Block(1,12,4,LOG:3)
Block(2,12,4,LEAVES:3)
Block(3,12,4,LEAVES:3)
Block(4,12,4,LEAVES:3)
Block(5,12,4,LEAVES:3)
Block(6,12,4,LEAVES:3)
Block(-3,12,5,LEAVES:3)
Block(-2,12,5,LEAVES:3)
Block(-1,12,5,LEAVES:3)
Block(0,12,5,LEAVES:3)
Block(1,12,5,LEAVES:3)
Block(2,12,5,LEAVES:3)
Block(3,12,5,LEAVES:3)
Block(4,12,5,LEAVES:3)
Block(5,12,5,LEAVES:3)
Block(-3,12,6,LEAVES:3)
Block(-2,12,6,LEAVES:3)
Block(-1,12,6,LEAVES:3)
Block(0,12,6,LEAVES:3)
Block(1,12,6,LEAVES:3)
Block(2,12,6,LEAVES:3)
Block(3,12,6,LEAVES:3)
Block(4,12,6,LEAVES:3)
Block(5,12,6,LEAVES:3)
Block(-3,12,7,LEAVES:3)
Block(-2,12,7,LEAVES:3)
Block(-1,12,7,LEAVES:3)
Block(0,12,7,LEAVES:3)
Block(1,12,7,LEAVES:3)
Block(2,12,7,LEAVES:3)
Block(3,12,7,LEAVES:3)
Block(4,12,7,LEAVES:3)
Block(5,12,7,LEAVES:3)
Block(-2,12,8,LEAVES:3)
Block(-1,12,8,LEAVES:3)
Block(0,12,8,LEAVES:3)
Block(1,12,8,LEAVES:3)
Block(2,12,8,LEAVES:3)
Block(3,12,8,LEAVES:3)
Block(4,12,8,LEAVES:3)
Block(1,12,9,LEAVES:3)
Block(-5,13,-8,LEAVES:3)
Block(-4,13,-8,LEAVES:3)
Block(-3,13,-8,LEAVES:3)
Block(-2,13,-8,LEAVES:3)
Block(-1,13,-8,LEAVES:3)
Block(-6,13,-7,LEAVES:3)
Block(-5,13,-7,LEAVES:3)
Block(-4,13,-7,LEAVES:3)
Block(-3,13,-7,LEAVES:3)
Block(-2,13,-7,LEAVES:3)
Block(-1,13,-7,LEAVES:3)
Block(0,13,-7,LEAVES:3)
Block(-6,13,-6,LEAVES:3)
Block(-5,13,-6,LEAVES:3)
Block(-4,13,-6,LEAVES:3)
Block(-3,13,-6,LEAVES:3)
Block(-2,13,-6,LEAVES:3)
Block(-1,13,-6,LEAVES:3)
Block(0,13,-6,LEAVES:3)
Block(6,13,-6,LEAVES:3)
Block(-6,13,-5,LEAVES:3)
Block(-5,13,-5,LEAVES:3)
Block(-4,13,-5,LEAVES:3)
Block(-3,13,-5,LEAVES:3)
Block(-2,13,-5,LEAVES:3)
Block(-1,13,-5,LEAVES:3)
Block(0,13,-5,LEAVES:3)
Block(-6,13,-4,LEAVES:3)
Block(-5,13,-4,LEAVES:3)
Block(-4,13,-4,LEAVES:3)
Block(-3,13,-4,LOG:3)
Block(-2,13,-4,LOG:3)
Block(-1,13,-4,LEAVES:3)
Block(0,13,-4,LOG:3)
Block(1,13,-4,LEAVES:3)
Block(2,13,-4,LEAVES:3)
Block(3,13,-4,LEAVES:3)
Block(4,13,-4,LOG:3)
Block(-6,13,-3,LEAVES:3)
Block(-5,13,-3,LEAVES:3)
Block(-4,13,-3,LEAVES:3)
Block(-3,13,-3,LEAVES:3)
Block(-2,13,-3,LEAVES:3)
Block(-1,13,-3,LEAVES:3)
Block(0,13,-3,LEAVES:3)
Block(1,13,-3,LOG:3)
Block(2,13,-3,LEAVES:3)
Block(3,13,-3,LOG:3)
Block(4,13,-3,LEAVES:3)
Block(-5,13,-2,LEAVES:3)
Block(-4,13,-2,LEAVES:3)
Block(-3,13,-2,LOG:3)
Block(-2,13,-2,LEAVES:3)
Block(-1,13,-2,LOG:3)
Block(0,13,-2,LEAVES:3)
Block(1,13,-2,LEAVES:3)
Block(2,13,-2,LEAVES:3)
Block(3,13,-2,LEAVES:3)
Block(4,13,-2,LEAVES:3)
Block(-2,13,-1,LEAVES:3)
Block(-1,13,-1,LOG:3)
Block(0,13,-1,LEAVES:3)
Block(1,13,-1,LEAVES:3)
Block(2,13,-1,LEAVES:3)
Block(3,13,-1,LEAVES:3)
Block(4,13,-1,LEAVES:3)
Block(-2,13,0,LEAVES:3)
Block(-1,13,0,LEAVES:3)
Block(0,13,0,LEAVES:3)
Block(1,13,0,LEAVES:3)
Block(2,13,0,LEAVES:3)
Block(3,13,0,LEAVES:3)
Block(4,13,0,LEAVES:3)
Block(-2,13,1,LEAVES:3)
Block(-1,13,1,LEAVES:3)
Block(0,13,1,LOG:3)
Block(1,13,1,LEAVES:3)
Block(2,13,1,LEAVES:3)
Block(3,13,1,LEAVES:3)
Block(4,13,1,LEAVES:3)
Block(-2,13,2,LEAVES:3)
Block(-1,13,2,LEAVES:3)
Block(0,13,2,LOG:3)
Block(1,13,2,LEAVES:3)
Block(2,13,2,LOG:3)
Block(3,13,2,LEAVES:3)
Block(4,13,2,LEAVES:3)
Block(5,13,2,LOG:3)
Block(-2,13,3,LEAVES:3)
Block(-1,13,3,LOG:3)
Block(0,13,3,LEAVES:3)
Block(1,13,3,LEAVES:3)
Block(2,13,3,LEAVES:3)
Block(3,13,3,LEAVES:3)
Block(4,13,3,LEAVES:3)
Block(-2,13,4,LEAVES:3)
Block(-1,13,4,LEAVES:3)
Block(0,13,4,LEAVES:3)
Block(1,13,4,LEAVES:3)
Block(2,13,4,LEAVES:3)
Block(3,13,4,LEAVES:3)
Block(4,13,4,LEAVES:3)
Block(-2,13,5,LEAVES:3)
Block(-1,13,5,LEAVES:3)
Block(0,13,5,LEAVES:3)
Block(1,13,5,LEAVES:3)
Block(2,13,5,LEAVES:3)
Block(3,13,5,LEAVES:3)
Block(4,13,5,LEAVES:3)
Block(-2,13,6,LEAVES:3)
Block(-1,13,6,LEAVES:3)
Block(0,13,6,LEAVES:3)
Block(1,13,6,LEAVES:3)
Block(2,13,6,LEAVES:3)
Block(3,13,6,LEAVES:3)
Block(4,13,6,LEAVES:3)
Block(-1,13,7,LEAVES:3)
Block(0,13,7,LEAVES:3)
Block(1,13,7,LEAVES:3)
Block(2,13,7,LEAVES:3)
Block(3,13,7,LEAVES:3)
Block(-3,14,-10,LEAVES:3)
Block(-6,14,-9,LEAVES:3)
Block(-5,14,-9,LEAVES:3)
Block(-4,14,-9,LEAVES:3)
Block(-3,14,-9,LEAVES:3)
Block(-2,14,-9,LEAVES:3)
Block(-1,14,-9,LEAVES:3)
Block(0,14,-9,LEAVES:3)
Block(-7,14,-8,LEAVES:3)
Block(-6,14,-8,LEAVES:3)
Block(-5,14,-8,LEAVES:3)
Block(-4,14,-8,LEAVES:3)
Block(-3,14,-8,LEAVES:3)
Block(-2,14,-8,LEAVES:3)
Block(-1,14,-8,LEAVES:3)
Block(0,14,-8,LEAVES:3)
Block(1,14,-8,LEAVES:3)
Block(-7,14,-7,LEAVES:3)
Block(-6,14,-7,LEAVES:3)
Block(-5,14,-7,LEAVES:3)
Block(-4,14,-7,LEAVES:3)
Block(-3,14,-7,LEAVES:3)
Block(-2,14,-7,LEAVES:3)
Block(-1,14,-7,LEAVES:3)
Block(0,14,-7,LEAVES:3)
Block(1,14,-7,LEAVES:3)
Block(5,14,-7,LEAVES:3)
Block(6,14,-7,LEAVES:3)
Block(7,14,-7,LEAVES:3)
Block(-7,14,-6,LEAVES:3)
Block(-6,14,-6,LEAVES:3)
Block(-5,14,-6,LEAVES:3)
Block(-4,14,-6,LEAVES:3)
Block(-3,14,-6,LEAVES:3)
Block(-2,14,-6,LEAVES:3)
Block(-1,14,-6,LEAVES:3)
Block(0,14,-6,LEAVES:3)
Block(1,14,-6,LEAVES:3)
Block(5,14,-6,LEAVES:3)
Block(6,14,-6,LEAVES:3)
Block(7,14,-6,LEAVES:3)
Block(-8,14,-5,LEAVES:3)
Block(-7,14,-5,LEAVES:3)
Block(-6,14,-5,LEAVES:3)
Block(-5,14,-5,LEAVES:3)
Block(-4,14,-5,LEAVES:3)
Block(-3,14,-5,LOG:3)
Block(-2,14,-5,LEAVES:3)
Block(-1,14,-5,LEAVES:3)
Block(0,14,-5,LOG:3)
Block(1,14,-5,LEAVES:3)
Block(2,14,-5,LEAVES:3)
Block(5,14,-5,LOG:3)
Block(6,14,-5,LEAVES:3)
Block(7,14,-5,LEAVES:3)
Block(-7,14,-4,LEAVES:3)
Block(-6,14,-4,LEAVES:3)
Block(-5,14,-4,LEAVES:3)
Block(-4,14,-4,LEAVES:3)
Block(-3,14,-4,LOG:3)
Block(-2,14,-4,LEAVES:3)
Block(-1,14,-4,LEAVES:3)
Block(0,14,-4,LEAVES:3)
Block(1,14,-4,LEAVES:3)
Block(2,14,-4,LEAVES:3)
Block(3,14,-4,LOG:3)
Block(-7,14,-3,LEAVES:3)
Block(-6,14,-3,LEAVES:3)
Block(-5,14,-3,LEAVES:3)
Block(-4,14,-3,LEAVES:3)
Block(-3,14,-3,LEAVES:3)
Block(-2,14,-3,LOG:3)
Block(-1,14,-3,LEAVES:3)
Block(0,14,-3,LEAVES:3)
Block(1,14,-3,LOG:3)
Block(2,14,-3,LEAVES:3)
Block(3,14,-3,LEAVES:3)
Block(-7,14,-2,LEAVES:3)
Block(-6,14,-2,LEAVES:3)
Block(-5,14,-2,LEAVES:3)
Block(-4,14,-2,LOG:3)
Block(-3,14,-2,LEAVES:3)
Block(-2,14,-2,LOG:3)
Block(-1,14,-2,LEAVES:3)
Block(0,14,-2,LEAVES:3)
Block(1,14,-2,LEAVES:3)
Block(2,14,-2,LEAVES:3)
Block(3,14,-2,LEAVES:3)
Block(4,14,-2,LEAVES:3)
Block(-6,14,-1,LEAVES:3)
Block(-5,14,-1,LEAVES:3)
Block(-4,14,-1,LEAVES:3)
Block(-3,14,-1,LEAVES:3)
Block(-2,14,-1,LEAVES:3)
Block(-1,14,-1,LOG:3)
Block(0,14,-1,LEAVES:3)
Block(1,14,-1,LEAVES:3)
Block(2,14,-1,LOG:3)
Block(3,14,-1,LEAVES:3)
Block(4,14,-1,LEAVES:3)
Block(-3,14,0,LEAVES:3)
Block(-2,14,0,LEAVES:3)
Block(-1,14,0,LEAVES:3)
Block(0,14,0,LEAVES:3)
Block(1,14,0,LEAVES:3)
Block(2,14,0,LEAVES:3)
Block(3,14,0,LEAVES:3)
Block(4,14,0,LEAVES:3)
Block(-1,14,1,LEAVES:3)
Block(0,14,1,LOG:3)
Block(1,14,1,LEAVES:3)
Block(2,14,1,LEAVES:3)
Block(3,14,1,LEAVES:3)
Block(0,14,2,LEAVES:3)
Block(1,14,2,LEAVES:3)
Block(2,14,2,LOG:3)
Block(5,14,2,LOG:3)
Block(-1,14,3,LOG:3)
Block(0,14,3,LOG:3)
Block(1,14,3,LEAVES:3)
Block(0,14,4,LEAVES:3)
Block(1,14,4,LEAVES:3)
Block(2,14,4,LEAVES:3)
Block(1,14,5,LEAVES:3)
Block(-5,15,-8,LEAVES:3)
Block(-4,15,-8,LEAVES:3)
Block(-3,15,-8,LEAVES:3)
Block(-2,15,-8,LEAVES:3)
Block(-1,15,-8,LEAVES:3)
Block(6,15,-8,LEAVES:3)
Block(-6,15,-7,LEAVES:3)
Block(-5,15,-7,LEAVES:3)
Block(-4,15,-7,LEAVES:3)
Block(-3,15,-7,LEAVES:3)
Block(-2,15,-7,LEAVES:3)
Block(-1,15,-7,LEAVES:3)
Block(0,15,-7,LEAVES:3)
Block(5,15,-7,LEAVES:3)
Block(6,15,-7,LEAVES:3)
Block(7,15,-7,LEAVES:3)
Block(-6,15,-6,LEAVES:3)
Block(-5,15,-6,LEAVES:3)
Block(-4,15,-6,LEAVES:3)
Block(-3,15,-6,LEAVES:3)
Block(-2,15,-6,LEAVES:3)
Block(-1,15,-6,LEAVES:3)
Block(0,15,-6,LEAVES:3)
Block(4,15,-6,LEAVES:3)
Block(5,15,-6,LEAVES:3)
Block(6,15,-6,LOG:3)
Block(7,15,-6,LEAVES:3)
Block(8,15,-6,LEAVES:3)
Block(-6,15,-5,LEAVES:3)
Block(-5,15,-5,LEAVES:3)
Block(-4,15,-5,LEAVES:3)
Block(-3,15,-5,LEAVES:3)
Block(-2,15,-5,LEAVES:3)
Block(-1,15,-5,LEAVES:3)
Block(0,15,-5,LOG:3)
Block(5,15,-5,LEAVES:3)
Block(6,15,-5,LEAVES:3)
Block(7,15,-5,LEAVES:3)
Block(-6,15,-4,LEAVES:3)
Block(-5,15,-4,LEAVES:3)
Block(-4,15,-4,LEAVES:3)
Block(-3,15,-4,LOG:3)
Block(-2,15,-4,LEAVES:3)
Block(-1,15,-4,LEAVES:3)
Block(0,15,-4,LEAVES:3)
Block(4,15,-4,LOG:3)
Block(6,15,-4,LEAVES:3)
Block(-6,15,-3,LEAVES:3)
Block(-5,15,-3,LEAVES:3)
Block(-4,15,-3,LOG:3)
Block(-3,15,-3,LEAVES:3)
Block(-2,15,-3,LEAVES:3)
Block(-1,15,-3,LEAVES:3)
Block(0,15,-3,LEAVES:3)
Block(1,15,-3,LOG:3)
Block(2,15,-3,LEAVES:3)
Block(-5,15,-2,LEAVES:3)
Block(-4,15,-2,LEAVES:3)
Block(-3,15,-2,LEAVES:3)
Block(-2,15,-2,LOG:3)
Block(-1,15,-2,LEAVES:3)
Block(0,15,-2,LEAVES:3)
Block(1,15,-2,LEAVES:3)
Block(2,15,-2,LEAVES:3)
Block(3,15,-2,LEAVES:3)
Block(-1,15,-1,LOG:3)
Block(0,15,-1,LEAVES:3)
Block(1,15,-1,LEAVES:3)
Block(2,15,-1,LOG:3)
Block(3,15,-1,LEAVES:3)
Block(-1,15,0,LEAVES:3)
Block(0,15,0,LEAVES:3)
Block(1,15,0,LEAVES:3)
Block(2,15,0,LEAVES:3)
Block(3,15,0,LEAVES:3)
Block(-1,15,1,LEAVES:3)
Block(0,15,1,LOG:3)
Block(1,15,1,LEAVES:3)
Block(2,15,1,LEAVES:3)
Block(0,15,2,LEAVES:3)
Block(2,15,2,LOG:3)
Block(-1,15,3,LOG:3)
Block(0,15,3,LOG:3)
Block(6,15,3,LOG:3)
Block(8,15,3,LEAVES:3)
Block(-6,16,-7,LEAVES:3)
Block(0,16,-7,LEAVES:3)
Block(5,16,-7,LEAVES:3)
Block(6,16,-7,LEAVES:3)
Block(7,16,-7,LEAVES:3)
Block(-3,16,-6,LEAVES:3)
Block(0,16,-6,LOG:3)
Block(5,16,-6,LEAVES:3)
Block(6,16,-6,LEAVES:3)
Block(7,16,-6,LEAVES:3)
Block(-4,16,-5,LOG:3)
Block(-3,16,-5,LOG:3)
Block(-2,16,-5,LEAVES:3)
Block(4,16,-5,LOG:3)
Block(5,16,-5,LEAVES:3)
Block(6,16,-5,LEAVES:3)
Block(7,16,-5,LEAVES:3)
Block(-3,16,-4,LEAVES:3)
Block(1,16,-4,LOG:3)
Block(-5,16,-3,LOG:3)
Block(-2,16,-3,LEAVES:3)
Block(-2,16,-2,LOG:3)
Block(-1,16,-2,LEAVES:3)
Block(0,16,-2,LEAVES:3)
Block(1,16,-2,LEAVES:3)
Block(-2,16,-1,LEAVES:3)
Block(-1,16,-1,LOG:3)
Block(0,16,-1,LEAVES:3)
Block(1,16,-1,LEAVES:3)
Block(2,16,-1,LOG:3)
Block(-3,16,0,LEAVES:3)
Block(-2,16,0,LEAVES:3)
Block(-1,16,0,LEAVES:3)
Block(0,16,0,LEAVES:3)
Block(1,16,0,LEAVES:3)
Block(2,16,0,LEAVES:3)
Block(3,16,0,LEAVES:3)
Block(-3,16,1,LEAVES:3)
Block(-2,16,1,LEAVES:3)
Block(-1,16,1,LEAVES:3)
Block(0,16,1,LOG:3)
Block(1,16,1,LEAVES:3)
Block(2,16,1,LEAVES:3)
Block(3,16,1,LEAVES:3)
Block(-3,16,2,LEAVES:3)
Block(-2,16,2,LEAVES:3)
Block(-1,16,2,LEAVES:3)
Block(0,16,2,LEAVES:3)
Block(1,16,2,LEAVES:3)
Block(2,16,2,LEAVES:3)
Block(3,16,2,LEAVES:3)
Block(7,16,2,LEAVES:3)
Block(8,16,2,LEAVES:3)
Block(9,16,2,LEAVES:3)
Block(-2,16,3,LEAVES:3)
Block(-1,16,3,LEAVES:3)
Block(0,16,3,LOG:3)
Block(1,16,3,LEAVES:3)
Block(2,16,3,LOG:3)
Block(7,16,3,LOG:3)
Block(8,16,3,LEAVES:3)
Block(9,16,3,LEAVES:3)
Block(-1,16,4,LOG:3)
Block(0,16,4,LEAVES:3)
Block(1,16,4,LEAVES:3)
Block(7,16,4,LEAVES:3)
Block(8,16,4,LEAVES:3)
Block(9,16,4,LEAVES:3)
Block(-1,17,-9,LEAVES:3)
Block(0,17,-9,LEAVES:3)
Block(1,17,-9,LEAVES:3)
Block(-7,17,-8,LEAVES:3)
Block(-6,17,-8,LEAVES:3)
Block(-5,17,-8,LEAVES:3)
Block(-2,17,-8,LEAVES:3)
Block(-1,17,-8,LEAVES:3)
Block(0,17,-8,LEAVES:3)
Block(1,17,-8,LEAVES:3)
Block(2,17,-8,LEAVES:3)
Block(-7,17,-7,LEAVES:3)
Block(-6,17,-7,LEAVES:3)
Block(-5,17,-7,LEAVES:3)
Block(-2,17,-7,LEAVES:3)
Block(-1,17,-7,LEAVES:3)
Block(0,17,-7,LEAVES:3)
Block(1,17,-7,LEAVES:3)
Block(2,17,-7,LEAVES:3)
Block(4,17,-7,LEAVES:3)
Block(5,17,-7,LEAVES:3)
Block(6,17,-7,LEAVES:3)
Block(-7,17,-6,LEAVES:3)
Block(-6,17,-6,LEAVES:3)
Block(-5,17,-6,LOG:3)
Block(-2,17,-6,LEAVES:3)
Block(-1,17,-6,LEAVES:3)
Block(0,17,-6,LOG:3)
Block(1,17,-6,LEAVES:3)
Block(2,17,-6,LEAVES:3)
Block(4,17,-6,LEAVES:3)
Block(5,17,-6,LEAVES:3)
Block(6,17,-6,LEAVES:3)
Block(-4,17,-5,LOG:3)
Block(-1,17,-5,LEAVES:3)
Block(0,17,-5,LEAVES:3)
Block(1,17,-5,LEAVES:3)
Block(4,17,-5,LOG:3)
Block(5,17,-5,LEAVES:3)
Block(6,17,-5,LEAVES:3)
Block(-3,17,-4,LEAVES:3)
Block(-2,17,-4,LEAVES:3)
Block(-1,17,-4,LEAVES:3)
Block(1,17,-4,LOG:3)
Block(-5,17,-3,LOG:3)
Block(-3,17,-3,LEAVES:3)
Block(-2,17,-3,LEAVES:3)
Block(-1,17,-3,LEAVES:3)
Block(0,17,-3,LEAVES:3)
Block(-3,17,-2,LEAVES:3)
Block(-2,17,-2,LOG:3)
Block(-1,17,-2,LEAVES:3)
Block(0,17,-2,LEAVES:3)
Block(1,17,-2,LEAVES:3)
Block(2,17,-2,LEAVES:3)
Block(-3,17,-1,LEAVES:3)
Block(-2,17,-1,LEAVES:3)
Block(-1,17,-1,LOG:3)
Block(0,17,-1,LEAVES:3)
Block(1,17,-1,LEAVES:3)
Block(2,17,-1,LEAVES:3)
Block(3,17,-1,LOG:3)
Block(-3,17,0,LEAVES:3)
Block(-2,17,0,LEAVES:3)
Block(-1,17,0,LEAVES:3)
Block(0,17,0,LEAVES:3)
Block(1,17,0,LEAVES:3)
Block(2,17,0,LEAVES:3)
Block(3,17,0,LEAVES:3)
Block(-4,17,1,LEAVES:3)
Block(-3,17,1,LEAVES:3)
Block(-2,17,1,LEAVES:3)
Block(-1,17,1,LEAVES:3)
Block(0,17,1,LOG:3)
Block(1,17,1,LEAVES:3)
Block(2,17,1,LEAVES:3)
Block(3,17,1,LEAVES:3)
Block(4,17,1,LEAVES:3)
Block(8,17,1,LEAVES:3)
Block(-3,17,2,LEAVES:3)
Block(-2,17,2,LEAVES:3)
Block(-1,17,2,LEAVES:3)
Block(0,17,2,LOG:3)
Block(1,17,2,LEAVES:3)
Block(2,17,2,LEAVES:3)
Block(3,17,2,LEAVES:3)
Block(7,17,2,LEAVES:3)
Block(8,17,2,LEAVES:3)
Block(9,17,2,LEAVES:3)
Block(-3,17,3,LEAVES:3)
Block(-2,17,3,LEAVES:3)
Block(-1,17,3,LEAVES:3)
Block(0,17,3,LOG:3)
Block(1,17,3,LEAVES:3)
Block(2,17,3,LOG:3)
Block(3,17,3,LEAVES:3)
Block(6,17,3,LEAVES:3)
Block(7,17,3,LEAVES:3)
Block(8,17,3,LOG:3)
Block(9,17,3,LEAVES:3)
Block(10,17,3,LEAVES:3)
Block(-2,17,4,LEAVES:3)
Block(-1,17,4,LOG:3)
Block(0,17,4,LEAVES:3)
Block(1,17,4,LEAVES:3)
Block(2,17,4,LEAVES:3)
Block(7,17,4,LEAVES:3)
Block(8,17,4,LEAVES:3)
Block(9,17,4,LEAVES:3)
Block(0,17,5,LEAVES:3)
Block(8,17,5,LEAVES:3)
Block(0,18,-10,LEAVES:3)
Block(-6,18,-9,LEAVES:3)
Block(-2,18,-9,LEAVES:3)
Block(-1,18,-9,LEAVES:3)
Block(0,18,-9,LEAVES:3)
Block(1,18,-9,LEAVES:3)
Block(2,18,-9,LEAVES:3)
Block(-7,18,-8,LEAVES:3)
Block(-6,18,-8,LEAVES:3)
Block(-5,18,-8,LEAVES:3)
Block(-2,18,-8,LEAVES:3)
Block(-1,18,-8,LEAVES:3)
Block(0,18,-8,LEAVES:3)
Block(1,18,-8,LEAVES:3)
Block(2,18,-8,LEAVES:3)
Block(5,18,-8,LEAVES:3)
Block(-8,18,-7,LEAVES:3)
Block(-7,18,-7,LEAVES:3)
Block(-6,18,-7,LOG:3)
Block(-5,18,-7,LEAVES:3)
Block(-4,18,-7,LEAVES:3)
Block(-3,18,-7,LEAVES:3)
Block(-2,18,-7,LEAVES:3)
Block(-1,18,-7,LEAVES:3)
Block(0,18,-7,LOG:3)
Block(1,18,-7,LEAVES:3)
Block(2,18,-7,LEAVES:3)
Block(3,18,-7,LEAVES:3)
Block(4,18,-7,LEAVES:3)
Block(5,18,-7,LEAVES:3)
Block(6,18,-7,LEAVES:3)
Block(-7,18,-6,LEAVES:3)
Block(-6,18,-6,LEAVES:3)
Block(-5,18,-6,LEAVES:3)
Block(-2,18,-6,LEAVES:3)
Block(-1,18,-6,LEAVES:3)
Block(0,18,-6,LEAVES:3)
Block(1,18,-6,LEAVES:3)
Block(2,18,-6,LEAVES:3)
Block(3,18,-6,LEAVES:3)
Block(4,18,-6,LEAVES:3)
Block(5,18,-6,LOG:3)
Block(6,18,-6,LEAVES:3)
Block(7,18,-6,LEAVES:3)
Block(-6,18,-5,LEAVES:3)
Block(-4,18,-5,LOG:3)
Block(-2,18,-5,LEAVES:3)
Block(-1,18,-5,LEAVES:3)
Block(0,18,-5,LEAVES:3)
Block(1,18,-5,LEAVES:3)
Block(2,18,-5,LEAVES:3)
Block(4,18,-5,LEAVES:3)
Block(5,18,-5,LEAVES:3)
Block(6,18,-5,LEAVES:3)
Block(-7,18,-4,LEAVES:3)
Block(-6,18,-4,LEAVES:3)
Block(-5,18,-4,LEAVES:3)
Block(-3,18,-4,LEAVES:3)
Block(-2,18,-4,LEAVES:3)
Block(-1,18,-4,LEAVES:3)
Block(0,18,-4,LEAVES:3)
Block(1,18,-4,LOG:3)
Block(5,18,-4,LEAVES:3)
Block(-6,18,-3,LOG:3)
Block(-4,18,-3,LEAVES:3)
Block(-3,18,-3,LEAVES:3)
Block(-2,18,-3,LOG:3)
Block(-1,18,-3,LEAVES:3)
Block(0,18,-3,LEAVES:3)
Block(-3,18,-2,LEAVES:3)
Block(-2,18,-2,LEAVES:3)
Block(-1,18,-2,LEAVES:3)
Block(0,18,-2,LEAVES:3)
Block(1,18,-2,LEAVES:3)
Block(-2,18,-1,LEAVES:3)
Block(-1,18,-1,LOG:3)
Block(0,18,-1,LEAVES:3)
Block(1,18,-1,LEAVES:3)
Block(2,18,-1,LEAVES:3)
Block(3,18,-1,LOG:3)
Block(-3,18,0,LEAVES:3)
Block(-2,18,0,LEAVES:3)
Block(-1,18,0,LEAVES:3)
Block(0,18,0,LEAVES:3)
Block(1,18,0,LEAVES:3)
Block(2,18,0,LEAVES:3)
Block(3,18,0,LEAVES:3)
Block(-3,18,1,LEAVES:3)
Block(-2,18,1,LEAVES:3)
Block(-1,18,1,LEAVES:3)
Block(0,18,1,LEAVES:3)
Block(1,18,1,LEAVES:3)
Block(2,18,1,LEAVES:3)
Block(3,18,1,LEAVES:3)
Block(-3,18,2,LEAVES:3)
Block(-2,18,2,LEAVES:3)
Block(-1,18,2,LEAVES:3)
Block(0,18,2,LOG:3)
Block(1,18,2,LEAVES:3)
Block(2,18,2,LEAVES:3)
Block(3,18,2,LEAVES:3)
Block(7,18,2,LEAVES:3)
Block(8,18,2,LEAVES:3)
Block(9,18,2,LEAVES:3)
Block(-2,18,3,LEAVES:3)
Block(-1,18,3,LEAVES:3)
Block(0,18,3,LEAVES:3)
Block(1,18,3,LEAVES:3)
Block(2,18,3,LOG:3)
Block(7,18,3,LEAVES:3)
Block(8,18,3,LEAVES:3)
Block(9,18,3,LEAVES:3)
Block(-2,18,4,LEAVES:3)
Block(-1,18,4,LOG:3)
Block(0,18,4,LOG:3)
Block(1,18,4,LEAVES:3)
Block(7,18,4,LEAVES:3)
Block(8,18,4,LEAVES:3)
Block(9,18,4,LEAVES:3)
Block(-2,18,5,LEAVES:3)
Block(-1,18,5,LEAVES:3)
Block(0,18,5,LEAVES:3)
Block(-1,19,-9,LEAVES:3)
Block(0,19,-9,LEAVES:3)
Block(1,19,-9,LEAVES:3)
Block(-7,19,-8,LEAVES:3)
Block(-6,19,-8,LEAVES:3)
Block(-5,19,-8,LEAVES:3)
Block(-2,19,-8,LEAVES:3)
Block(-1,19,-8,LEAVES:3)
Block(0,19,-8,LEAVES:3)
Block(1,19,-8,LEAVES:3)
Block(2,19,-8,LEAVES:3)
Block(-7,19,-7,LEAVES:3)
Block(-6,19,-7,LEAVES:3)
Block(-5,19,-7,LEAVES:3)
Block(-2,19,-7,LEAVES:3)
Block(-1,19,-7,LEAVES:3)
Block(0,19,-7,LEAVES:3)
Block(1,19,-7,LEAVES:3)
Block(2,19,-7,LEAVES:3)
Block(4,19,-7,LEAVES:3)
Block(5,19,-7,LEAVES:3)
Block(6,19,-7,LEAVES:3)
Block(-8,19,-6,LEAVES:3)
Block(-7,19,-6,LEAVES:3)
Block(-6,19,-6,LEAVES:3)
Block(-5,19,-6,LEAVES:3)
Block(-4,19,-6,LOG:3)
Block(-2,19,-6,LEAVES:3)
Block(-1,19,-6,LEAVES:3)
Block(0,19,-6,LEAVES:3)
Block(1,19,-6,LEAVES:3)
Block(2,19,-6,LEAVES:3)
Block(4,19,-6,LEAVES:3)
Block(5,19,-6,LEAVES:3)
Block(6,19,-6,LEAVES:3)
Block(-9,19,-5,LEAVES:3)
Block(-8,19,-5,LEAVES:3)
Block(-7,19,-5,LEAVES:3)
Block(-6,19,-5,LEAVES:3)
Block(-5,19,-5,LEAVES:3)
Block(-4,19,-5,LEAVES:3)
Block(-3,19,-5,LEAVES:3)
Block(-1,19,-5,LEAVES:3)
Block(0,19,-5,LEAVES:3)
Block(1,19,-5,LOG:3)
Block(4,19,-5,LEAVES:3)
Block(5,19,-5,LEAVES:3)
Block(6,19,-5,LEAVES:3)
Block(-9,19,-4,LEAVES:3)
Block(-8,19,-4,LEAVES:3)
Block(-7,19,-4,LEAVES:3)
Block(-6,19,-4,LEAVES:3)
Block(-5,19,-4,LEAVES:3)
Block(-4,19,-4,LEAVES:3)
Block(-3,19,-4,LEAVES:3)
Block(-2,19,-4,LEAVES:3)
Block(-1,19,-4,LEAVES:3)
Block(-9,19,-3,LEAVES:3)
Block(-8,19,-3,LEAVES:3)
Block(-7,19,-3,LEAVES:3)
Block(-6,19,-3,LOG:3)
Block(-5,19,-3,LEAVES:3)
Block(-4,19,-3,LEAVES:3)
Block(-3,19,-3,LEAVES:3)
Block(-2,19,-3,LEAVES:3)
Block(-1,19,-3,LEAVES:3)
Block(-8,19,-2,LEAVES:3)
Block(-7,19,-2,LEAVES:3)
Block(-6,19,-2,LEAVES:3)
Block(-5,19,-2,LEAVES:3)
Block(-4,19,-2,LEAVES:3)
Block(-3,19,-2,LEAVES:3)
Block(-2,19,-2,LEAVES:3)
Block(-1,19,-2,LEAVES:3)
Block(-7,19,-1,LEAVES:3)
Block(-6,19,-1,LEAVES:3)
Block(-5,19,-1,LEAVES:3)
Block(-1,19,-1,LOG:3)
Block(3,19,-1,LOG:3)
Block(0,19,0,LEAVES:3)
Block(-1,19,1,LEAVES:3)
Block(0,19,1,LEAVES:3)
Block(1,19,1,LEAVES:3)
Block(-1,19,2,LEAVES:3)
Block(0,19,2,LOG:3)
Block(-2,19,3,LEAVES:3)
Block(-1,19,3,LEAVES:3)
Block(0,19,3,LEAVES:3)
Block(2,19,3,LOG:3)
Block(8,19,3,LEAVES:3)
Block(-3,19,4,LEAVES:3)
Block(-2,19,4,LEAVES:3)
Block(-1,19,4,LOG:3)
Block(0,19,4,LOG:3)
Block(1,19,4,LEAVES:3)
Block(-2,19,5,LEAVES:3)
Block(-1,19,5,LEAVES:3)
Block(0,19,5,LEAVES:3)
Block(-1,19,6,LEAVES:3)
Block(-6,20,-8,LEAVES:3)
Block(-8,20,-7,LEAVES:3)
Block(-7,20,-7,LEAVES:3)
Block(-6,20,-7,LEAVES:3)
Block(-5,20,-7,LEAVES:3)
Block(-4,20,-7,LEAVES:3)
Block(0,20,-7,LEAVES:3)
Block(-9,20,-6,LEAVES:3)
Block(-8,20,-6,LEAVES:3)
Block(-7,20,-6,LEAVES:3)
Block(-6,20,-6,LEAVES:3)
Block(-5,20,-6,LOG:3)
Block(-4,20,-6,LEAVES:3)
Block(-3,20,-6,LEAVES:3)
Block(1,20,-6,LEAVES:3)
Block(5,20,-6,LEAVES:3)
Block(-9,20,-5,LEAVES:3)
Block(-8,20,-5,LEAVES:3)
Block(-7,20,-5,LEAVES:3)
Block(-6,20,-5,LEAVES:3)
Block(-5,20,-5,LEAVES:3)
Block(-4,20,-5,LEAVES:3)
Block(-3,20,-5,LEAVES:3)
Block(1,20,-5,LOG:3)
Block(-10,20,-4,LEAVES:3)
Block(-9,20,-4,LEAVES:3)
Block(-8,20,-4,LEAVES:3)
Block(-7,20,-4,LEAVES:3)
Block(-6,20,-4,LOG:3)
Block(-5,20,-4,LEAVES:3)
Block(-4,20,-4,LEAVES:3)
Block(-3,20,-4,LEAVES:3)
Block(-2,20,-4,LEAVES:3)
Block(-9,20,-3,LEAVES:3)
Block(-8,20,-3,LEAVES:3)
Block(-7,20,-3,LEAVES:3)
Block(-6,20,-3,LEAVES:3)
Block(-5,20,-3,LEAVES:3)
Block(-4,20,-3,LEAVES:3)
Block(-3,20,-3,LEAVES:3)
Block(-2,20,-3,LEAVES:3)
Block(-9,20,-2,LEAVES:3)
Block(-8,20,-2,LEAVES:3)
Block(-7,20,-2,LEAVES:3)
Block(-6,20,-2,LEAVES:3)
Block(-5,20,-2,LEAVES:3)
Block(-4,20,-2,LEAVES:3)
Block(-3,20,-2,LEAVES:3)
Block(-2,20,-2,LEAVES:3)
Block(-1,20,-2,LEAVES:3)
Block(0,20,-2,LEAVES:3)
Block(-8,20,-1,LEAVES:3)
Block(-7,20,-1,LEAVES:3)
Block(-6,20,-1,LEAVES:3)
Block(-5,20,-1,LEAVES:3)
Block(-4,20,-1,LEAVES:3)
Block(-2,20,-1,LEAVES:3)
Block(-1,20,-1,LOG:3)
Block(0,20,-1,LEAVES:3)
Block(4,20,-1,LOG:3)
Block(-6,20,0,LEAVES:3)
Block(-2,20,0,LEAVES:3)
Block(-1,20,0,LEAVES:3)
Block(0,20,0,LEAVES:3)
Block(0,20,2,LOG:3)
Block(1,20,2,LEAVES:3)
Block(2,20,2,LEAVES:3)
Block(3,20,2,LEAVES:3)
Block(-2,20,3,LEAVES:3)
Block(-1,20,3,LEAVES:3)
Block(0,20,3,LEAVES:3)
Block(1,20,3,LEAVES:3)
Block(2,20,3,LOG:3)
Block(3,20,3,LEAVES:3)
Block(-2,20,4,LEAVES:3)
Block(-1,20,4,LEAVES:3)
Block(0,20,4,LOG:3)
Block(1,20,4,LEAVES:3)
Block(2,20,4,LEAVES:3)
Block(3,20,4,LEAVES:3)
Block(-2,20,5,LEAVES:3)
Block(-1,20,5,LEAVES:3)
Block(0,20,5,LEAVES:3)
Block(0,21,-8,LEAVES:3)
Block(1,21,-8,LEAVES:3)
Block(2,21,-8,LEAVES:3)
Block(-7,21,-7,LEAVES:3)
Block(-6,21,-7,LEAVES:3)
Block(-5,21,-7,LEAVES:3)
Block(-1,21,-7,LEAVES:3)
Block(0,21,-7,LEAVES:3)
Block(1,21,-7,LEAVES:3)
Block(2,21,-7,LEAVES:3)
Block(3,21,-7,LEAVES:3)
Block(-8,21,-6,LEAVES:3)
Block(-7,21,-6,LEAVES:3)
Block(-6,21,-6,LEAVES:3)
Block(-5,21,-6,LOG:3)
Block(-4,21,-6,LEAVES:3)
Block(-1,21,-6,LEAVES:3)
Block(0,21,-6,LEAVES:3)
Block(1,21,-6,LEAVES:3)
Block(2,21,-6,LEAVES:3)
Block(3,21,-6,LEAVES:3)
Block(-9,21,-5,LEAVES:3)
Block(-8,21,-5,LEAVES:3)
Block(-7,21,-5,LEAVES:3)
Block(-6,21,-5,LEAVES:3)
Block(-5,21,-5,LEAVES:3)
Block(-4,21,-5,LEAVES:3)
Block(-3,21,-5,LEAVES:3)
Block(-1,21,-5,LEAVES:3)
Block(0,21,-5,LEAVES:3)
Block(1,21,-5,LOG:3)
Block(2,21,-5,LEAVES:3)
Block(3,21,-5,LEAVES:3)
Block(-9,21,-4,LEAVES:3)
Block(-8,21,-4,LEAVES:3)
Block(-7,21,-4,LEAVES:3)
Block(-6,21,-4,LEAVES:3)
Block(-5,21,-4,LEAVES:3)
Block(-4,21,-4,LEAVES:3)
Block(-3,21,-4,LEAVES:3)
Block(0,21,-4,LEAVES:3)
Block(1,21,-4,LEAVES:3)
Block(2,21,-4,LEAVES:3)
Block(-9,21,-3,LEAVES:3)
Block(-8,21,-3,LEAVES:3)
Block(-7,21,-3,LEAVES:3)
Block(-6,21,-3,LEAVES:3)
Block(-5,21,-3,LEAVES:3)
Block(-4,21,-3,LEAVES:3)
Block(-3,21,-3,LEAVES:3)
Block(-1,21,-3,LEAVES:3)
Block(-8,21,-2,LEAVES:3)
Block(-7,21,-2,LEAVES:3)
Block(-6,21,-2,LEAVES:3)
Block(-5,21,-2,LEAVES:3)
Block(-4,21,-2,LEAVES:3)
Block(-2,21,-2,LEAVES:3)
Block(-1,21,-2,LEAVES:3)
Block(0,21,-2,LEAVES:3)
Block(-7,21,-1,LEAVES:3)
Block(-6,21,-1,LEAVES:3)
Block(-5,21,-1,LEAVES:3)
Block(-3,21,-1,LEAVES:3)
Block(-2,21,-1,LEAVES:3)
Block(-1,21,-1,LOG:3)
Block(0,21,-1,LEAVES:3)
Block(1,21,-1,LEAVES:3)
Block(4,21,-1,LOG:3)
Block(-2,21,0,LEAVES:3)
Block(-1,21,0,LEAVES:3)
Block(0,21,0,LEAVES:3)
Block(-1,21,1,LEAVES:3)
Block(2,21,1,LEAVES:3)
Block(0,21,2,LOG:3)
Block(1,21,2,LEAVES:3)
Block(2,21,2,LEAVES:3)
Block(3,21,2,LEAVES:3)
Block(0,21,3,LEAVES:3)
Block(1,21,3,LEAVES:3)
Block(2,21,3,LOG:3)
Block(3,21,3,LEAVES:3)
Block(4,21,3,LEAVES:3)
Block(-1,21,4,LEAVES:3)
Block(0,21,4,LOG:3)
Block(1,21,4,LEAVES:3)
Block(2,21,4,LEAVES:3)
Block(3,21,4,LEAVES:3)
Block(2,21,5,LEAVES:3)
Block(1,22,-9,LEAVES:3)
Block(-1,22,-8,LEAVES:3)
Block(0,22,-8,LEAVES:3)
Block(1,22,-8,LEAVES:3)
Block(2,22,-8,LEAVES:3)
Block(3,22,-8,LEAVES:3)
Block(-5,22,-7,LOG:3)
Block(-1,22,-7,LEAVES:3)
Block(0,22,-7,LEAVES:3)
Block(1,22,-7,LEAVES:3)
Block(2,22,-7,LEAVES:3)
Block(3,22,-7,LEAVES:3)
Block(-2,22,-6,LEAVES:3)
Block(-1,22,-6,LEAVES:3)
Block(0,22,-6,LEAVES:3)
Block(1,22,-6,LOG:3)
Block(2,22,-6,LEAVES:3)
Block(3,22,-6,LEAVES:3)
Block(4,22,-6,LEAVES:3)
Block(-6,22,-5,LEAVES:3)
Block(-1,22,-5,LEAVES:3)
Block(0,22,-5,LEAVES:3)
Block(1,22,-5,LEAVES:3)
Block(2,22,-5,LEAVES:3)
Block(3,22,-5,LEAVES:3)
Block(-7,22,-4,LEAVES:3)
Block(-6,22,-4,LEAVES:3)
Block(-5,22,-4,LEAVES:3)
Block(-1,22,-4,LEAVES:3)
Block(0,22,-4,LEAVES:3)
Block(1,22,-4,LEAVES:3)
Block(2,22,-4,LEAVES:3)
Block(3,22,-4,LEAVES:3)
Block(-6,22,-3,LEAVES:3)
Block(1,22,-3,LEAVES:3)
Block(-2,22,-2,LEAVES:3)
Block(-1,22,-2,LEAVES:3)
Block(0,22,-2,LEAVES:3)
Block(-2,22,-1,LEAVES:3)
Block(-1,22,-1,LEAVES:3)
Block(0,22,-1,LEAVES:3)
Block(4,22,-1,LOG:3)
Block(-2,22,0,LEAVES:3)
Block(-1,22,0,LEAVES:3)
Block(0,22,0,LEAVES:3)
Block(0,22,2,LOG:3)
Block(1,22,2,LEAVES:3)
Block(2,22,2,LEAVES:3)
Block(3,22,2,LEAVES:3)
Block(1,22,3,LEAVES:3)
Block(2,22,3,LEAVES:3)
Block(3,22,3,LEAVES:3)
Block(1,22,4,LEAVES:3)
Block(2,22,4,LEAVES:3)
Block(3,22,4,LEAVES:3)
Block(0,22,5,LOG:3)
Block(-6,23,-8,LEAVES:3)
Block(0,23,-8,LEAVES:3)
Block(1,23,-8,LEAVES:3)
Block(2,23,-8,LEAVES:3)
Block(-6,23,-7,LOG:3)
Block(-1,23,-7,LEAVES:3)
Block(0,23,-7,LEAVES:3)
Block(1,23,-7,LEAVES:3)
Block(2,23,-7,LEAVES:3)
Block(3,23,-7,LEAVES:3)
Block(-1,23,-6,LEAVES:3)
Block(0,23,-6,LEAVES:3)
Block(1,23,-6,LEAVES:3)
Block(2,23,-6,LEAVES:3)
Block(3,23,-6,LEAVES:3)
Block(-1,23,-5,LEAVES:3)
Block(0,23,-5,LEAVES:3)
Block(1,23,-5,LEAVES:3)
Block(2,23,-5,LEAVES:3)
Block(3,23,-5,LEAVES:3)
Block(0,23,-4,LEAVES:3)
Block(1,23,-4,LEAVES:3)
Block(2,23,-4,LEAVES:3)
Block(-1,23,-1,LEAVES:3)
Block(5,23,-1,LOG:3)
Block(6,23,-1,LEAVES:3)
Block(0,23,3,LOG:3)
Block(2,23,3,LEAVES:3)
Block(0,23,4,LEAVES:3)
Block(-1,23,5,LEAVES:3)
Block(0,23,5,LOG:3)
Block(1,23,5,LEAVES:3)
Block(0,23,6,LEAVES:3)
Block(-7,24,-9,LEAVES:3)
Block(-6,24,-9,LEAVES:3)
Block(-5,24,-9,LEAVES:3)
Block(-7,24,-8,LEAVES:3)
Block(-6,24,-8,LEAVES:3)
Block(-5,24,-8,LEAVES:3)
Block(-7,24,-7,LEAVES:3)
Block(-6,24,-7,LOG:3)
Block(-5,24,-7,LEAVES:3)
Block(1,24,-6,LEAVES:3)
Block(5,24,-3,LEAVES:3)
Block(6,24,-3,LEAVES:3)
Block(7,24,-3,LEAVES:3)
Block(4,24,-2,LEAVES:3)
Block(5,24,-2,LEAVES:3)
Block(6,24,-2,LEAVES:3)
Block(7,24,-2,LEAVES:3)
Block(8,24,-2,LEAVES:3)
Block(4,24,-1,LEAVES:3)
Block(5,24,-1,LOG:3)
Block(6,24,-1,LEAVES:3)
Block(7,24,-1,LEAVES:3)
Block(8,24,-1,LEAVES:3)
Block(4,24,0,LEAVES:3)
Block(5,24,0,LEAVES:3)
Block(6,24,0,LEAVES:3)
Block(7,24,0,LEAVES:3)
Block(8,24,0,LEAVES:3)
Block(5,24,1,LEAVES:3)
Block(6,24,1,LEAVES:3)
Block(7,24,1,LEAVES:3)
Block(-2,24,2,LEAVES:3)
Block(-1,24,2,LEAVES:3)
Block(0,24,2,LEAVES:3)
Block(1,24,2,LEAVES:3)
Block(2,24,2,LEAVES:3)
Block(-3,24,3,LEAVES:3)
Block(-2,24,3,LEAVES:3)
Block(-1,24,3,LEAVES:3)
Block(0,24,3,LOG:3)
Block(1,24,3,LEAVES:3)
Block(2,24,3,LEAVES:3)
Block(3,24,3,LEAVES:3)
Block(-3,24,4,LEAVES:3)
Block(-2,24,4,LEAVES:3)
Block(-1,24,4,LEAVES:3)
Block(0,24,4,LEAVES:3)
Block(1,24,4,LEAVES:3)
Block(2,24,4,LEAVES:3)
Block(3,24,4,LEAVES:3)
Block(-3,24,5,LEAVES:3)
Block(-2,24,5,LEAVES:3)
Block(-1,24,5,LEAVES:3)
Block(0,24,5,LOG:3)
Block(1,24,5,LEAVES:3)
Block(2,24,5,LEAVES:3)
Block(3,24,5,LEAVES:3)
Block(-3,24,6,LEAVES:3)
Block(-2,24,6,LEAVES:3)
Block(-1,24,6,LEAVES:3)
Block(0,24,6,LEAVES:3)
Block(1,24,6,LEAVES:3)
Block(2,24,6,LEAVES:3)
Block(3,24,6,LEAVES:3)
Block(-3,24,7,LEAVES:3)
Block(-2,24,7,LEAVES:3)
Block(-1,24,7,LEAVES:3)
Block(0,24,7,LEAVES:3)
Block(1,24,7,LEAVES:3)
Block(2,24,7,LEAVES:3)
Block(3,24,7,LEAVES:3)
Block(-2,24,8,LEAVES:3)
Block(-1,24,8,LEAVES:3)
Block(0,24,8,LEAVES:3)
Block(1,24,8,LEAVES:3)
Block(2,24,8,LEAVES:3)
Block(-6,25,-10,LEAVES:3)
Block(-7,25,-9,LEAVES:3)
Block(-6,25,-9,LEAVES:3)
Block(-5,25,-9,LEAVES:3)
Block(-8,25,-8,LEAVES:3)
Block(-7,25,-8,LEAVES:3)
Block(-6,25,-8,LOG:3)
Block(-5,25,-8,LEAVES:3)
Block(-4,25,-8,LEAVES:3)
Block(-7,25,-7,LEAVES:3)
Block(-6,25,-7,LEAVES:3)
Block(-5,25,-7,LEAVES:3)
Block(-6,25,-6,LEAVES:3)
Block(6,25,-4,LEAVES:3)
Block(4,25,-3,LEAVES:3)
Block(5,25,-3,LEAVES:3)
Block(6,25,-3,LEAVES:3)
Block(7,25,-3,LEAVES:3)
Block(8,25,-3,LEAVES:3)
Block(4,25,-2,LEAVES:3)
Block(5,25,-2,LEAVES:3)
Block(6,25,-2,LEAVES:3)
Block(7,25,-2,LEAVES:3)
Block(8,25,-2,LEAVES:3)
Block(3,25,-1,LEAVES:3)
Block(4,25,-1,LEAVES:3)
Block(5,25,-1,LEAVES:3)
Block(6,25,-1,LOG:3)
Block(7,25,-1,LEAVES:3)
Block(8,25,-1,LEAVES:3)
Block(9,25,-1,LEAVES:3)
Block(0,25,0,LEAVES:3)
Block(4,25,0,LEAVES:3)
Block(5,25,0,LEAVES:3)
Block(6,25,0,LEAVES:3)
Block(7,25,0,LEAVES:3)
Block(8,25,0,LEAVES:3)
Block(-3,25,1,LEAVES:3)
Block(-2,25,1,LEAVES:3)
Block(-1,25,1,LEAVES:3)
Block(0,25,1,LEAVES:3)
Block(1,25,1,LEAVES:3)
Block(2,25,1,LEAVES:3)
Block(3,25,1,LEAVES:3)
Block(4,25,1,LEAVES:3)
Block(5,25,1,LEAVES:3)
Block(6,25,1,LEAVES:3)
Block(7,25,1,LEAVES:3)
Block(8,25,1,LEAVES:3)
Block(-4,25,2,LEAVES:3)
Block(-3,25,2,LEAVES:3)
Block(-2,25,2,LEAVES:3)
Block(-1,25,2,LEAVES:3)
Block(0,25,2,LEAVES:3)
Block(1,25,2,LEAVES:3)
Block(2,25,2,LEAVES:3)
Block(3,25,2,LEAVES:3)
Block(4,25,2,LEAVES:3)
Block(6,25,2,LEAVES:3)
Block(-4,25,3,LEAVES:3)
Block(-3,25,3,LEAVES:3)
Block(-2,25,3,LEAVES:3)
Block(-1,25,3,LEAVES:3)
Block(0,25,3,LOG:3)
Block(1,25,3,LEAVES:3)
Block(2,25,3,LEAVES:3)
Block(3,25,3,LEAVES:3)
Block(4,25,3,LEAVES:3)
Block(-4,25,4,LEAVES:3)
Block(-3,25,4,LEAVES:3)
Block(-2,25,4,LEAVES:3)
Block(-1,25,4,LEAVES:3)
Block(0,25,4,LEAVES:3)
Block(1,25,4,LEAVES:3)
Block(2,25,4,LEAVES:3)
Block(3,25,4,LEAVES:3)
Block(4,25,4,LEAVES:3)
Block(-5,25,5,LEAVES:3)
Block(-4,25,5,LEAVES:3)
Block(-3,25,5,LEAVES:3)
Block(-2,25,5,LEAVES:3)
Block(-1,25,5,LEAVES:3)
Block(0,25,5,LOG:3)
Block(1,25,5,LEAVES:3)
Block(2,25,5,LEAVES:3)
Block(3,25,5,LEAVES:3)
Block(4,25,5,LEAVES:3)
Block(5,25,5,LEAVES:3)
Block(-4,25,6,LEAVES:3)
Block(-3,25,6,LEAVES:3)
Block(-2,25,6,LEAVES:3)
Block(-1,25,6,LEAVES:3)
Block(0,25,6,LEAVES:3)
Block(1,25,6,LEAVES:3)
Block(2,25,6,LEAVES:3)
Block(3,25,6,LEAVES:3)
Block(4,25,6,LEAVES:3)
Block(-4,25,7,LEAVES:3)
Block(-3,25,7,LEAVES:3)
Block(-2,25,7,LEAVES:3)
Block(-1,25,7,LEAVES:3)
Block(0,25,7,LEAVES:3)
Block(1,25,7,LEAVES:3)
Block(2,25,7,LEAVES:3)
Block(3,25,7,LEAVES:3)
Block(4,25,7,LEAVES:3)
Block(-4,25,8,LEAVES:3)
Block(-3,25,8,LEAVES:3)
Block(-2,25,8,LEAVES:3)
Block(-1,25,8,LEAVES:3)
Block(0,25,8,LEAVES:3)
Block(1,25,8,LEAVES:3)
Block(2,25,8,LEAVES:3)
Block(3,25,8,LEAVES:3)
Block(4,25,8,LEAVES:3)
Block(-3,25,9,LEAVES:3)
Block(-2,25,9,LEAVES:3)
Block(-1,25,9,LEAVES:3)
Block(0,25,9,LEAVES:3)
Block(1,25,9,LEAVES:3)
Block(2,25,9,LEAVES:3)
Block(3,25,9,LEAVES:3)
Block(0,25,10,LEAVES:3)
Block(-7,26,-9,LEAVES:3)
Block(-6,26,-9,LEAVES:3)
Block(-5,26,-9,LEAVES:3)
Block(-7,26,-8,LEAVES:3)
Block(-6,26,-8,LEAVES:3)
Block(-5,26,-8,LEAVES:3)
Block(-7,26,-7,LEAVES:3)
Block(-6,26,-7,LEAVES:3)
Block(-5,26,-7,LEAVES:3)
Block(5,26,-3,LEAVES:3)
Block(6,26,-3,LEAVES:3)
Block(7,26,-3,LEAVES:3)
Block(4,26,-2,LEAVES:3)
Block(5,26,-2,LEAVES:3)
Block(6,26,-2,LEAVES:3)
Block(7,26,-2,LEAVES:3)
Block(8,26,-2,LEAVES:3)
Block(4,26,-1,LEAVES:3)
Block(5,26,-1,LEAVES:3)
Block(6,26,-1,LEAVES:3)
Block(7,26,-1,LEAVES:3)
Block(8,26,-1,LEAVES:3)
Block(4,26,0,LEAVES:3)
Block(5,26,0,LEAVES:3)
Block(6,26,0,LEAVES:3)
Block(7,26,0,LEAVES:3)
Block(8,26,0,LEAVES:3)
Block(5,26,1,LEAVES:3)
Block(6,26,1,LEAVES:3)
Block(7,26,1,LEAVES:3)
Block(-2,26,2,LEAVES:3)
Block(-1,26,2,LEAVES:3)
Block(0,26,2,LEAVES:3)
Block(1,26,2,LEAVES:3)
Block(2,26,2,LEAVES:3)
Block(-3,26,3,LEAVES:3)
Block(-2,26,3,LEAVES:3)
Block(-1,26,3,LEAVES:3)
Block(0,26,3,LOG:3)
Block(1,26,3,LEAVES:3)
Block(2,26,3,LEAVES:3)
Block(3,26,3,LEAVES:3)
Block(-3,26,4,LEAVES:3)
Block(-2,26,4,LEAVES:3)
Block(-1,26,4,LEAVES:3)
Block(0,26,4,LEAVES:3)
Block(1,26,4,LEAVES:3)
Block(2,26,4,LEAVES:3)
Block(3,26,4,LEAVES:3)
Block(-3,26,5,LEAVES:3)
Block(-2,26,5,LEAVES:3)
Block(-1,26,5,LEAVES:3)
Block(0,26,5,LEAVES:3)
Block(1,26,5,LEAVES:3)
Block(2,26,5,LEAVES:3)
Block(3,26,5,LEAVES:3)
Block(-3,26,6,LEAVES:3)
Block(-2,26,6,LEAVES:3)
Block(-1,26,6,LEAVES:3)
Block(0,26,6,LEAVES:3)
Block(1,26,6,LEAVES:3)
Block(2,26,6,LEAVES:3)
Block(3,26,6,LEAVES:3)
Block(-3,26,7,LEAVES:3)
Block(-2,26,7,LEAVES:3)
Block(-1,26,7,LEAVES:3)
Block(0,26,7,LEAVES:3)
Block(1,26,7,LEAVES:3)
Block(2,26,7,LEAVES:3)
Block(3,26,7,LEAVES:3)
Block(-2,26,8,LEAVES:3)
Block(-1,26,8,LEAVES:3)
Block(0,26,8,LEAVES:3)
Block(1,26,8,LEAVES:3)
Block(2,26,8,LEAVES:3)
Block(-6,27,-8,LEAVES:3)
Block(6,27,-1,LEAVES:3)
Block(-1,27,2,LEAVES:3)
Block(0,27,2,LEAVES:3)
Block(1,27,2,LEAVES:3)
Block(-1,27,3,LEAVES:3)
Block(0,27,3,LOG:3)
Block(1,27,3,LEAVES:3)
Block(-1,27,4,LEAVES:3)
Block(0,27,4,LEAVES:3)
Block(1,27,4,LEAVES:3)
Block(-1,27,5,LEAVES:3)
Block(0,27,5,LEAVES:3)
Block(1,27,5,LEAVES:3)
Block(0,27,6,LEAVES:3)
Block(0,28,1,LEAVES:3)
Block(-1,28,2,LEAVES:3)
Block(0,28,2,LEAVES:3)
Block(1,28,2,LEAVES:3)
Block(-2,28,3,LEAVES:3)
Block(-1,28,3,LEAVES:3)
Block(0,28,3,LOG:3)
Block(1,28,3,LEAVES:3)
Block(2,28,3,LEAVES:3)
Block(-1,28,4,LEAVES:3)
Block(0,28,4,LEAVES:3)
Block(1,28,4,LEAVES:3)
Block(0,28,5,LEAVES:3)
Block(-1,29,2,LEAVES:3)
Block(0,29,2,LEAVES:3)
Block(1,29,2,LEAVES:3)
Block(-1,29,3,LEAVES:3)
Block(0,29,3,LEAVES:3)
Block(1,29,3,LEAVES:3)
Block(-1,29,4,LEAVES:3)
Block(0,29,4,LEAVES:3)
Block(1,29,4,LEAVES:3)
Block(0,30,3,LEAVES:3)

#######################################################################
# +-----------------------------------------------------------------+ #
# |                            BO3 checks                           | #
# +-----------------------------------------------------------------+ #
#######################################################################

# Require a condition at a certain location in order for the BO3 to be spawned.
# BlockCheck(x,y,z,BlockName[,BlockName[,...]]) - one of the blocks must be at the location
# BlockCheckNot(x,y,z,BlockName[,BlockName[,...]]) - all the blocks must not be at the location
# LightCheck(x,y,z,minLightLevel,maxLightLevel) - light must be between min and max (inclusive)

# You can use "Solid" as a BlockName for matching all solid blocks or "All" to match all blocks that aren't air.

# Examples:

#   BlockCheck(0,-1,0,Solid)       Require any solid block just below the object
#   BlockCheck(0,-1,0,WOOL)        Require any type of wool just below the object
#   BlockCheck(0,-1,0,WOOL:0)      Require white wool just below the object
#   BlockCheckNot(0,-1,0,WOOL:0)   Require that there is no white wool below the object
#   LightCheck(0,0,0,0,1)          Require almost complete darkness just below the object

#######################################################################
# +-----------------------------------------------------------------+ #
# |                             Branches                            | #
# +-----------------------------------------------------------------+ #
#######################################################################

# Branches are objects that will spawn when this object spawns when it is used in
# the CustomStructure resource. Branches can also have branches, making complex
# structures possible. See the wiki for more details.

# Regular Branches spawn each branch with an independent chance of spawning.
# Branch(x,y,z,branchName,rotation,chance[,anotherBranchName,rotation,chance[,...]][IndividualChance])
# branchName - name of the object to spawn.
# rotation - NORTH, SOUTH, EAST or WEST.
# IndividualChance - The chance each branch has to spawn, assumed to be 100 when left blank

# Weighted Branches spawn branches with a dependent chance of spawning.
# WeightedBranch(x,y,z,branchName,rotation,chance[,anotherBranchName,rotation,chance[,...]][MaxChanceOutOf])
# MaxChanceOutOf - The chance all branches have to spawn out of, assumed to be 100 when left blank
BlockCheck(0,-1,0,STONE,GRASS,DIRT,SAND,GRAVEL)
