#######################################################################
# +-----------------------------------------------------------------+ #
# |                            BO3 object                           | #
# +-----------------------------------------------------------------+ #
#######################################################################

# This is the config file of a custom object.
# If you add this object correctly to your BiomeConfigs, it will spawn in the world.

# This is the creator of this BO3 object
Author: BO3 BulkEdit (by LanToaster)

# A short description of this BO3 object
Description: This Object was Created with BO3_BulkEdit

# The BO3 version, don't change this! It can be used by external applications to do a version check.
Version: 3

# The settings mode, WriteAll, WriteWithoutComments or WriteDisable. See WorldConfig.
SettingsMode: WriteDisable


#######################################################################
# +-----------------------------------------------------------------+ #
# |                          Main settings                          | #
# +-----------------------------------------------------------------+ #
#######################################################################

# This needs to be set to true to spawn the object in the Tree and Sapling resources.
Tree: true

# The frequency of the BO3 from 1 to 200. Tries this many times to spawn this BO3 when using the CustomObject(...) resource.
# Ignored by Tree(..), Sapling(..) and CustomStructure(..)
Frequency: 1

# The rarity of the BO3 from 0 to 100. Each spawn attempt has rarity% chance to succeed when using the CustomObject(...) resource.
# Ignored by Tree(..), Sapling(..) and CustomStructure(..)
Rarity: 300

# If you set this to true, the BO3 will be placed with a random rotation.
RotateRandomly: True

# The spawn height of the BO3 - randomY, highestBlock or highestSolidBlock.
SpawnHeight: highestSolidBlock
SpawnHeightOffset: -1
# The height limits for the BO3.
MinHeight: 0

MaxHeight: 73

# Objects can have other objects attacthed to it: branches. Branches can also
# have branches attached to it, which can also have branches, etc. This is the
# maximum branch depth for this objects.
MaxBranchDepth: 10

# When spawned with the UseWorld keyword, this BO3 should NOT spawn in the following biomes.
# If you writer.write the BO3 name directly in the BiomeConfigs, this will be ignored.
ExcludedBiomes: All


#######################################################################
# +-----------------------------------------------------------------+ #
# |                      Source block settings                      | #
# +-----------------------------------------------------------------+ #
#######################################################################

# The block(s) the BO3 should spawn in.
SourceBlocks: AIR,GRASS,DIRT,DIRT:2,STONE,SAND,CLAY,GRAVEL

# The maximum percentage of the BO3 that can be outside the SourceBlock.
# The BO3 won't be placed on a location with more blocks outside the SourceBlock than this percentage.
MaxPercentageOutsideSourceBlock: 5

# What to do when a block is about to be placed outside the SourceBlock? (dontPlace, placeAnyway)
OutsideSourceBlock: placeAnyway


#######################################################################
# +-----------------------------------------------------------------+ #
# |                              Blocks                             | #
# +-----------------------------------------------------------------+ #
#######################################################################

# All the blocks used in the BO3 are listed here. Possible blocks:
# Block(x,y,z,id[.data][,nbtfile.nbt)
# RandomBlock(x,y,z,id[:data][,nbtfile.nbt],chance[,id[:data][,nbtfile.nbt],chance[,...]])
# So RandomBlock(0,0,0,CHEST,chest.nbt,50,CHEST,anotherchest.nbt,100) will spawn a chest at
# the BO3 origin, and give it a 50% chance to have the contents of chest.nbt, or, if that
# fails, a 100% percent chance to have the contents of anotherchest.nbt.
Block(0,0,0,LOG:15)
Block(-2,0,-1,LOG:15)
Block(1,0,-2,LOG:15)
Block(0,0,1,LOG:15)
Block(0,0,-1,LOG:15)
Block(-1,0,0,LOG:15)
Block(1,0,0,LOG:15)
Block(1,0,2,LOG:15)
Block(-2,0,0,LOG:15)
Block(0,0,-2,LOG:15)
Block(-1,0,-1,LOG:15)
Block(2,0,0,LOG:15)
Block(0,0,2,LOG:15)
Block(1,0,1,LOG:15)
Block(-1,0,1,LOG:15)
Block(1,0,-1,LOG:15)
Block(-2,0,2,TALLGRASS:1)
Block(0,0,-3,LOG:15)
Block(2,0,-1,LOG:15)
Block(-1,0,2,LOG:15)
Block(-2,0,1,LOG:15)
Block(2,0,1,LOG:15)
Block(-1,0,-2,LOG:15)
Block(-3,0,0,LOG:15)
Block(3,0,0,LOG:15)
Block(0,0,3,LOG:15)
Block(-2,0,-2,TALLGRASS:1)
Block(2,0,-2,TALLGRASS:1)
Block(2,0,2,TALLGRASS:2)
Block(-7,0,4,LOG:15)
Block(6,0,6,LOG:15)
Block(-2,0,7,LEAVES:3)
Block(-3,0,7,LEAVES:3)
Block(-3,0,6,LEAVES:3)
Block(-4,0,6,LEAVES:3)
Block(0,0,7,LEAVES:3)
Block(-1,0,7,LEAVES:3)
Block(1,0,7,LEAVES:3)
Block(2,0,6,LEAVES:3)
Block(2,0,7,LEAVES:3)
Block(5,0,6,LEAVES:3)
Block(5,0,7,LEAVES:3)
Block(5,0,8,LEAVES:3)
Block(4,0,8,LEAVES:3)
Block(6,0,7,LEAVES:3)
Block(7,0,7,LEAVES:3)
Block(7,0,6,LEAVES:3)
Block(8,0,6,LEAVES:3)
Block(6,0,5,LEAVES:3)
Block(6,0,4,LEAVES:3)
Block(5,0,4,LEAVES:3)
Block(5,0,5,LEAVES:3)
Block(6,0,3,LEAVES:3)
Block(7,0,-4,LEAVES:3)
Block(6,0,-3,LEAVES:3)
Block(7,0,-3,LEAVES:3)
Block(6,0,-2,LEAVES:3)
Block(6,0,-4,LEAVES:3)
Block(5,0,-4,LEAVES:3)
Block(4,0,-4,LEAVES:3)
Block(7,0,-5,LEAVES:3)
Block(7,0,-6,LEAVES:3)
Block(7,0,-7,LEAVES:3)
Block(6,0,-5,LEAVES:3)
Block(5,0,-5,LEAVES:3)
Block(5,0,-6,LEAVES:3)
Block(8,0,-4,LEAVES:3)
Block(9,0,-4,LEAVES:3)
Block(8,0,-3,LEAVES:3)
Block(8,0,-2,LEAVES:3)
Block(1,0,-8,LEAVES:3)
Block(0,0,-8,LEAVES:3)
Block(-1,0,-9,LEAVES:3)
Block(0,0,-9,LEAVES:3)
Block(2,0,-8,LEAVES:3)
Block(3,0,-8,LEAVES:3)
Block(4,0,-8,LEAVES:3)
Block(1,0,-7,LEAVES:3)
Block(2,0,-7,LEAVES:3)
Block(1,0,-6,LEAVES:3)
Block(0,0,-6,LEAVES:3)
Block(2,0,-9,LEAVES:3)
Block(-6,0,-5,LEAVES:3)
Block(-7,0,-5,LEAVES:3)
Block(-7,0,-4,LEAVES:3)
Block(-7,0,-3,LEAVES:3)
Block(-5,0,-5,LEAVES:3)
Block(-4,0,-4,LEAVES:3)
Block(-5,0,-4,LEAVES:3)
Block(-7,0,-6,LEAVES:3)
Block(-7,0,-7,LEAVES:3)
Block(-6,0,-7,LEAVES:3)
Block(-8,0,-5,LEAVES:3)
Block(-8,0,4,LEAVES:3)
Block(-9,0,4,LEAVES:3)
Block(-9,0,3,LEAVES:3)
Block(-9,0,2,LEAVES:3)
Block(-8,0,5,LEAVES:3)
Block(-8,0,6,LEAVES:3)
Block(-8,0,7,LEAVES:3)
Block(-7,0,3,LEAVES:3)
Block(-6,0,4,LEAVES:3)
Block(-7,0,5,LEAVES:3)
Block(-7,0,2,LEAVES:3)
Block(-7,0,1,LEAVES:3)
Block(-5,0,4,LEAVES:3)
Block(3,0,7,VINE:2)
Block(5,0,-8,VINE:1)
Block(-6,0,3,TALLGRASS:2)
Block(-6,0,-4,TALLGRASS:2)
Block(0,0,6,TALLGRASS:2)
Block(-1,0,6,TALLGRASS:2)
Block(1,0,-3,TALLGRASS:2)
Block(3,0,1,TALLGRASS:2)
Block(1,0,3,LOG:15)
Block(0,0,4,LOG:15)
Block(-1,0,3,LOG:15)
Block(0,12,0,LOG:15)
Block(-1,12,0,LOG:15)
Block(0,12,-1,LOG:15)
Block(1,12,0,LOG:15)
Block(1,12,1,LOG:15)
Block(0,12,1,LOG:15)
Block(-1,12,-1,LOG:15)
Block(0,12,2,LOG:15)
Block(-1,12,3,LEAVES:3)
Block(-2,12,3,LEAVES:3)
Block(-1,12,2,LEAVES:3)
Block(-2,12,4,LEAVES:3)
Block(-1,12,4,LEAVES:3)
Block(0,12,3,LEAVES:3)
Block(0,12,4,VINE:4)
Block(-4,12,1,VINE:8)
Block(2,12,-1,VINE:1)
Block(-1,12,-4,VINE:1)
Block(4,12,-1,VINE:2)
Block(-7,12,4,VINE:8)
Block(-1,12,-9,VINE:1)
Block(5,12,-8,VINE:1)
Block(4,12,2,VINE:2)
Block(-5,12,-4,VINE:8)
Block(7,12,2,VINE:8)
Block(2,12,7,VINE:4)
Block(0,11,0,LOG:15)
Block(-1,11,0,LOG:15)
Block(-1,11,-1,LOG:15)
Block(0,11,-1,LOG:15)
Block(1,11,0,LOG:15)
Block(0,11,1,LOG:15)
Block(1,11,1,LOG:15)
Block(0,11,4,VINE:4)
Block(-4,11,1,VINE:8)
Block(-1,11,-4,VINE:1)
Block(4,11,-1,VINE:2)
Block(-7,11,4,VINE:8)
Block(-1,11,-9,VINE:1)
Block(5,11,-8,VINE:1)
Block(4,11,2,VINE:2)
Block(-5,11,-4,VINE:8)
Block(7,11,2,VINE:8)
Block(2,11,7,VINE:4)
Block(0,10,0,LOG:15)
Block(-1,10,0,LOG:15)
Block(-1,10,-1,LOG:15)
Block(0,10,-1,LOG:15)
Block(1,10,0,LOG:15)
Block(1,10,1,LOG:15)
Block(0,10,1,LOG:15)
Block(0,10,4,VINE:4)
Block(-4,10,1,VINE:8)
Block(4,10,-1,VINE:2)
Block(-7,10,4,VINE:8)
Block(-1,10,-9,VINE:1)
Block(5,10,-8,VINE:1)
Block(4,10,2,VINE:2)
Block(-5,10,-4,VINE:8)
Block(7,10,2,VINE:8)
Block(2,10,7,VINE:4)
Block(0,9,0,LOG:15)
Block(-1,9,0,LOG:15)
Block(0,9,-1,LOG:15)
Block(1,9,0,LOG:15)
Block(1,9,1,LOG:15)
Block(1,9,-1,LOG:15)
Block(0,9,1,LOG:15)
Block(-1,9,-1,LOG:15)
Block(0,9,4,VINE:4)
Block(4,9,-1,VINE:2)
Block(-7,9,4,VINE:8)
Block(-4,9,1,VINE:8)
Block(-1,9,-9,VINE:1)
Block(5,9,-8,VINE:1)
Block(4,9,2,VINE:2)
Block(-5,9,-4,VINE:8)
Block(7,9,2,VINE:8)
Block(2,9,7,VINE:4)
Block(0,8,0,LOG:15)
Block(-1,8,0,LOG:15)
Block(-1,8,-1,LOG:15)
Block(0,8,-1,LOG:15)
Block(1,8,-1,LOG:15)
Block(1,8,0,LOG:15)
Block(1,8,1,LOG:15)
Block(0,8,1,LOG:15)
Block(0,8,4,VINE:4)
Block(4,8,-1,VINE:2)
Block(-7,8,4,VINE:8)
Block(-4,8,1,VINE:8)
Block(-1,8,-9,VINE:1)
Block(5,8,-8,VINE:1)
Block(4,8,2,VINE:2)
Block(-5,8,-4,VINE:8)
Block(7,8,2,VINE:8)
Block(2,8,7,VINE:4)
Block(0,7,0,LOG:15)
Block(-1,7,0,LOG:15)
Block(-1,7,-1,LOG:15)
Block(0,7,-1,LOG:15)
Block(1,7,-1,LOG:15)
Block(1,7,0,LOG:15)
Block(1,7,1,LOG:15)
Block(0,7,1,LOG:15)
Block(0,7,4,VINE:4)
Block(4,7,-1,VINE:2)
Block(-7,7,4,VINE:8)
Block(-4,7,1,VINE:8)
Block(5,7,-8,VINE:1)
Block(4,7,2,VINE:2)
Block(-5,7,-4,VINE:8)
Block(7,7,2,VINE:8)
Block(2,7,7,VINE:4)
Block(0,6,0,LOG:15)
Block(-1,6,0,LOG:15)
Block(-1,6,-1,LOG:15)
Block(0,6,-1,LOG:15)
Block(1,6,-1,LOG:15)
Block(1,6,0,LOG:15)
Block(1,6,1,LOG:15)
Block(0,6,1,LOG:15)
Block(0,6,4,VINE:4)
Block(4,6,-1,VINE:2)
Block(-4,6,1,VINE:8)
Block(5,6,-8,VINE:1)
Block(4,6,2,VINE:2)
Block(-5,6,-4,VINE:8)
Block(7,6,2,VINE:8)
Block(2,6,7,VINE:4)
Block(-7,6,4,VINE:8)
Block(0,5,0,LOG:15)
Block(-1,5,0,LOG:15)
Block(-1,5,-1,LOG:15)
Block(0,5,-1,LOG:15)
Block(1,5,-1,LOG:15)
Block(1,5,0,LOG:15)
Block(0,5,1,LOG:15)
Block(1,5,1,LOG:15)
Block(0,5,4,VINE:4)
Block(4,5,-1,VINE:2)
Block(-4,5,1,VINE:8)
Block(5,5,-8,VINE:1)
Block(4,5,2,VINE:2)
Block(-5,5,-4,VINE:8)
Block(7,5,2,VINE:8)
Block(2,5,7,VINE:4)
Block(-7,5,4,VINE:8)
Block(0,4,0,LOG:15)
Block(-1,4,0,LOG:15)
Block(0,4,1,LOG:15)
Block(1,4,0,LOG:15)
Block(0,4,-1,LOG:15)
Block(-1,4,-1,LOG:15)
Block(1,4,-1,LOG:15)
Block(1,4,1,LOG:15)
Block(2,4,0,LOG:15)
Block(4,4,-1,VINE:2)
Block(-4,4,1,VINE:8)
Block(5,4,-8,VINE:1)
Block(4,4,2,VINE:2)
Block(-5,4,-4,VINE:8)
Block(7,4,2,VINE:8)
Block(2,4,7,VINE:4)
Block(-7,4,4,VINE:8)
Block(0,3,0,LOG:15)
Block(0,3,-1,LOG:15)
Block(-1,3,0,LOG:15)
Block(0,3,1,LOG:15)
Block(1,3,0,LOG:15)
Block(-1,3,-1,LOG:15)
Block(1,3,-1,LOG:15)
Block(1,3,1,LOG:15)
Block(0,3,-2,LOG:15)
Block(2,3,0,LOG:15)
Block(4,3,-1,VINE:2)
Block(5,3,-8,VINE:1)
Block(4,3,2,VINE:2)
Block(7,3,2,VINE:8)
Block(-5,3,-4,VINE:8)
Block(2,3,7,VINE:4)
Block(-7,3,4,VINE:8)
Block(0,2,0,LOG:15)
Block(-1,2,0,LOG:15)
Block(0,2,-1,LOG:15)
Block(1,2,0,LOG:15)
Block(0,2,1,LOG:15)
Block(-2,2,0,LOG:15)
Block(-1,2,-1,LOG:15)
Block(0,2,-2,LOG:15)
Block(1,2,-1,LOG:15)
Block(2,2,0,LOG:15)
Block(1,2,1,LOG:15)
Block(0,2,2,LOG:15)
Block(-1,2,1,LOG:15)
Block(1,2,-2,LOG:15)
Block(5,2,-8,VINE:1)
Block(4,2,2,VINE:2)
Block(-5,2,-4,VINE:8)
Block(2,2,7,VINE:4)
Block(-7,2,4,VINE:8)
Block(6,2,6,LEAVES:3)
Block(5,2,6,LEAVES:3)
Block(6,2,5,LEAVES:3)
Block(-8,2,4,LEAVES:3)
Block(-7,2,3,LEAVES:3)
Block(-6,2,-5,LEAVES:3)
Block(-7,2,-5,LEAVES:3)
Block(2,2,-8,LEAVES:3)
Block(1,2,-8,LEAVES:3)
Block(1,2,-7,LEAVES:3)
Block(7,2,-4,LEAVES:3)
Block(7,2,-5,LEAVES:3)
Block(6,2,-4,LEAVES:3)
Block(0,1,0,LOG:15)
Block(-1,1,0,LOG:15)
Block(0,1,-1,LOG:15)
Block(1,1,0,LOG:15)
Block(0,1,1,LOG:15)
Block(0,1,2,LOG:15)
Block(-1,1,1,LOG:15)
Block(-2,1,0,LOG:15)
Block(-1,1,-1,LOG:15)
Block(0,1,-2,LOG:15)
Block(1,1,-1,LOG:15)
Block(2,1,0,LOG:15)
Block(1,1,1,LOG:15)
Block(0,1,-3,LOG:15)
Block(1,1,-2,LOG:15)
Block(2,1,-1,LOG:15)
Block(-1,1,-2,LOG:15)
Block(-2,1,-1,LOG:15)
Block(4,1,2,VINE:2)
Block(-5,1,-4,VINE:8)
Block(2,1,7,VINE:4)
Block(-8,1,4,LEAVES:3)
Block(-7,1,3,LEAVES:3)
Block(-7,1,5,LEAVES:3)
Block(-7,1,4,VINE:8)
Block(-6,1,4,LEAVES:3)
Block(-9,1,4,LEAVES:3)
Block(-8,1,5,LEAVES:3)
Block(-8,1,3,LEAVES:3)
Block(-6,1,3,LEAVES:3)
Block(-1,1,7,LEAVES:3)
Block(-2,1,7,LEAVES:3)
Block(-3,1,6,LEAVES:3)
Block(-2,1,6,LEAVES:3)
Block(-6,1,-5,LEAVES:3)
Block(-6,1,-6,LEAVES:3)
Block(-7,1,-6,LEAVES:3)
Block(-6,1,-4,LEAVES:3)
Block(-7,1,-4,LEAVES:3)
Block(-5,1,-5,LEAVES:3)
Block(-8,1,-5,LEAVES:3)
Block(-7,1,-5,LEAVES:3)
Block(1,1,-8,LEAVES:3)
Block(0,1,-8,LEAVES:3)
Block(1,1,-7,LEAVES:3)
Block(2,1,-7,LEAVES:3)
Block(2,1,-8,LEAVES:3)
Block(3,1,-8,LEAVES:3)
Block(2,1,-9,LEAVES:3)
Block(7,1,-4,LEAVES:3)
Block(6,1,-4,LEAVES:3)
Block(5,1,-4,LEAVES:3)
Block(7,1,-5,LEAVES:3)
Block(7,1,-6,LEAVES:3)
Block(7,1,-3,LEAVES:3)
Block(8,1,-4,LEAVES:3)
Block(7,1,-2,LEAVES:3)
Block(6,1,6,LEAVES:3)
Block(5,1,6,LEAVES:3)
Block(5,1,5,LEAVES:3)
Block(5,1,4,LEAVES:3)
Block(7,1,6,LEAVES:3)
Block(8,1,6,LEAVES:3)
Block(7,1,7,LEAVES:3)
Block(5,1,7,LEAVES:3)
Block(6,1,5,LEAVES:3)
Block(7,1,5,LEAVES:3)
Block(6,1,7,LEAVES:3)
Block(6,1,8,LEAVES:3)
Block(5,1,-8,VINE:1)
Block(0,13,0,LOG:15)
Block(-1,13,0,LOG:15)
Block(-1,13,-1,LOG:15)
Block(0,13,-1,LOG:15)
Block(1,13,0,LOG:15)
Block(1,13,1,LOG:15)
Block(0,13,1,LOG:15)
Block(-1,13,3,LOG:15)
Block(-1,13,2,LEAVES:3)
Block(-2,13,3,LEAVES:3)
Block(-1,13,4,LEAVES:3)
Block(0,13,3,LEAVES:3)
Block(-2,13,4,LEAVES:3)
Block(-3,13,3,LEAVES:3)
Block(-3,13,4,LEAVES:3)
Block(-1,13,5,LEAVES:3)
Block(-2,13,5,LEAVES:3)
Block(0,13,4,VINE:4)
Block(-2,13,2,LEAVES:3)
Block(1,13,3,LEAVES:3)
Block(0,13,2,LEAVES:3)
Block(-4,13,1,VINE:8)
Block(2,13,-1,VINE:1)
Block(-1,13,-4,VINE:1)
Block(-7,13,4,VINE:8)
Block(-1,13,-9,VINE:1)
Block(5,13,-8,VINE:1)
Block(4,13,2,VINE:2)
Block(4,13,-1,VINE:2)
Block(-5,13,-4,VINE:8)
Block(7,13,2,VINE:8)
Block(2,13,7,VINE:4)
Block(0,18,0,LOG:15)
Block(-1,18,0,LOG:15)
Block(0,18,-1,LOG:15)
Block(1,18,0,LOG:15)
Block(1,18,1,LOG:15)
Block(0,18,1,LOG:15)
Block(0,18,4,VINE:4)
Block(-4,18,1,VINE:8)
Block(2,18,-1,VINE:1)
Block(-1,18,-4,VINE:1)
Block(4,18,-1,VINE:2)
Block(-7,18,4,VINE:8)
Block(-1,18,-9,VINE:1)
Block(5,18,-8,VINE:1)
Block(4,18,2,VINE:2)
Block(-5,18,-4,VINE:8)
Block(7,18,2,VINE:8)
Block(2,18,7,VINE:4)
Block(0,19,0,LOG:15)
Block(-1,19,0,LOG:15)
Block(0,19,-1,LOG:15)
Block(1,19,0,LOG:15)
Block(1,19,1,LOG:15)
Block(0,19,1,LOG:15)
Block(0,19,-2,LOG:15)
Block(-1,19,-3,LEAVES:3)
Block(-2,19,-3,LEAVES:3)
Block(-2,19,-4,LEAVES:3)
Block(-1,19,-4,VINE:1)
Block(0,19,-4,LEAVES:3)
Block(0,19,-3,LEAVES:3)
Block(-2,19,-2,LEAVES:3)
Block(-1,19,-2,LEAVES:3)
Block(-3,19,-4,LEAVES:3)
Block(-3,19,-3,LEAVES:3)
Block(-2,19,-5,LEAVES:3)
Block(-1,19,-5,LEAVES:3)
Block(0,19,4,VINE:4)
Block(-4,19,1,VINE:8)
Block(2,19,-1,VINE:1)
Block(4,19,-1,VINE:2)
Block(-7,19,4,VINE:8)
Block(-1,19,-9,VINE:1)
Block(5,19,-8,VINE:1)
Block(4,19,2,VINE:2)
Block(-5,19,-4,VINE:8)
Block(7,19,2,VINE:8)
Block(2,19,7,VINE:4)
Block(0,20,0,LOG:15)
Block(-1,20,0,LOG:15)
Block(0,20,-1,LOG:15)
Block(1,20,0,LOG:15)
Block(1,20,1,LOG:15)
Block(0,20,1,LOG:15)
Block(-1,20,-3,LOG:15)
Block(-2,20,-3,LEAVES:3)
Block(-1,20,-4,VINE:1)
Block(0,20,-3,LEAVES:3)
Block(-1,20,-2,LEAVES:3)
Block(-3,20,-3,LEAVES:3)
Block(-3,20,-4,LEAVES:3)
Block(-2,20,-4,LEAVES:3)
Block(-2,20,-5,LEAVES:3)
Block(-1,20,-5,LEAVES:3)
Block(0,20,-5,LEAVES:3)
Block(0,20,-4,LEAVES:3)
Block(1,20,-3,LEAVES:3)
Block(1,20,-4,LEAVES:3)
Block(-2,20,-2,LEAVES:3)
Block(0,20,-2,LEAVES:3)
Block(-1,20,-6,LEAVES:3)
Block(0,20,-6,LEAVES:3)
Block(-2,20,-6,LEAVES:3)
Block(-3,20,-5,LEAVES:3)
Block(-4,20,-4,LEAVES:3)
Block(-4,20,-3,LEAVES:3)
Block(-3,20,-2,LEAVES:3)
Block(-2,20,-1,LEAVES:3)
Block(0,20,4,VINE:4)
Block(-4,20,1,VINE:8)
Block(2,20,-1,VINE:1)
Block(4,20,-1,VINE:2)
Block(-7,20,4,VINE:8)
Block(-1,20,-9,VINE:1)
Block(5,20,-8,VINE:1)
Block(4,20,2,VINE:2)
Block(-5,20,-4,VINE:8)
Block(7,20,2,VINE:8)
Block(2,20,7,VINE:4)
Block(0,21,0,LOG:15)
Block(-1,21,0,LOG:15)
Block(0,21,-1,LOG:15)
Block(1,21,0,LOG:15)
Block(1,21,1,LOG:15)
Block(0,21,1,LOG:15)
Block(-1,21,-3,LEAVES:3)
Block(-2,21,-3,LEAVES:3)
Block(-2,21,-4,LEAVES:3)
Block(-1,21,-4,VINE:1)
Block(0,21,-4,LEAVES:3)
Block(0,21,-3,LEAVES:3)
Block(-1,21,-2,LEAVES:3)
Block(0,21,-2,LEAVES:3)
Block(-1,21,-5,LEAVES:3)
Block(-2,21,-5,LEAVES:3)
Block(-3,21,-3,LEAVES:3)
Block(-3,21,-4,LEAVES:3)
Block(0,21,4,VINE:4)
Block(-4,21,1,VINE:8)
Block(2,21,-1,VINE:1)
Block(4,21,-1,VINE:2)
Block(-7,21,4,VINE:8)
Block(-1,21,-9,VINE:1)
Block(5,21,-8,VINE:1)
Block(4,21,2,VINE:2)
Block(-5,21,-4,VINE:8)
Block(7,21,2,VINE:8)
Block(2,21,7,VINE:4)
Block(0,22,0,LOG:15)
Block(-1,22,0,LOG:15)
Block(0,22,-1,LOG:15)
Block(1,22,0,LOG:15)
Block(1,22,1,LOG:15)
Block(0,22,1,LOG:15)
Block(0,22,4,VINE:4)
Block(-4,22,1,VINE:8)
Block(2,22,-1,VINE:1)
Block(-1,22,-4,VINE:1)
Block(4,22,-1,VINE:2)
Block(-7,22,4,VINE:8)
Block(-1,22,-9,VINE:1)
Block(5,22,-8,VINE:1)
Block(4,22,2,VINE:2)
Block(-5,22,-4,VINE:8)
Block(7,22,2,VINE:8)
Block(2,22,7,VINE:4)
Block(0,23,0,LOG:15)
Block(-1,23,0,LOG:15)
Block(0,23,-1,LOG:15)
Block(1,23,0,LOG:15)
Block(0,23,1,LOG:15)
Block(3,23,-1,LEAVES:3)
Block(2,23,7,VINE:4)
Block(0,23,4,VINE:4)
Block(-4,23,1,VINE:8)
Block(2,23,-1,VINE:1)
Block(-1,23,-4,VINE:1)
Block(4,23,-1,VINE:2)
Block(-7,23,4,VINE:8)
Block(-1,23,-9,VINE:1)
Block(5,23,-8,VINE:1)
Block(4,23,2,VINE:2)
Block(-5,23,-4,VINE:8)
Block(7,23,2,VINE:8)
Block(0,24,0,LOG:15)
Block(-1,24,0,LOG:15)
Block(0,24,-1,LOG:15)
Block(1,24,0,LOG:15)
Block(0,24,1,LOG:15)
Block(2,24,0,LOG:15)
Block(3,24,-2,LEAVES:3)
Block(4,24,-1,VINE:2)
Block(3,24,-1,LEAVES:3)
Block(2,24,-1,VINE:1)
Block(3,24,0,LEAVES:3)
Block(2,24,7,VINE:4)
Block(2,24,-2,LEAVES:3)
Block(3,24,-3,LEAVES:3)
Block(4,24,-2,LEAVES:3)
Block(5,24,-1,LEAVES:3)
Block(4,24,0,LEAVES:3)
Block(1,24,-1,LEAVES:3)
Block(3,24,1,LEAVES:3)
Block(0,24,4,VINE:4)
Block(-4,24,1,VINE:8)
Block(-1,24,-4,VINE:1)
Block(-7,24,4,VINE:8)
Block(-1,24,-9,VINE:1)
Block(5,24,-8,VINE:1)
Block(4,24,2,VINE:2)
Block(-5,24,-4,VINE:8)
Block(7,24,2,VINE:8)
Block(0,14,0,LOG:15)
Block(-1,14,0,LOG:15)
Block(0,14,-1,LOG:15)
Block(1,14,0,LOG:15)
Block(1,14,1,LOG:15)
Block(0,14,1,LOG:15)
Block(-1,14,3,LEAVES:3)
Block(-3,14,3,LEAVES:3)
Block(-2,14,3,LEAVES:3)
Block(-2,14,4,LEAVES:3)
Block(-1,14,4,LEAVES:3)
Block(-1,14,5,LEAVES:3)
Block(0,14,4,VINE:4)
Block(1,14,3,LEAVES:3)
Block(0,14,3,LEAVES:3)
Block(0,14,2,LEAVES:3)
Block(-2,14,2,LEAVES:3)
Block(-2,14,1,LEAVES:3)
Block(-1,14,1,LEAVES:3)
Block(-1,14,2,LEAVES:3)
Block(-3,14,4,LEAVES:3)
Block(-2,14,5,LEAVES:3)
Block(-3,14,2,LEAVES:3)
Block(-4,14,1,VINE:8)
Block(2,14,-1,VINE:1)
Block(-1,14,-4,VINE:1)
Block(4,14,-1,VINE:2)
Block(-7,14,4,VINE:8)
Block(-1,14,-9,VINE:1)
Block(5,14,-8,VINE:1)
Block(4,14,2,VINE:2)
Block(-5,14,-4,VINE:8)
Block(7,14,2,VINE:8)
Block(2,14,7,VINE:4)
Block(0,15,0,LOG:15)
Block(-1,15,0,LOG:15)
Block(0,15,-1,LOG:15)
Block(1,15,0,LOG:15)
Block(1,15,1,LOG:15)
Block(0,15,1,LOG:15)
Block(-2,15,4,LEAVES:3)
Block(-2,15,3,LEAVES:3)
Block(-1,15,3,LEAVES:3)
Block(-1,15,4,LEAVES:3)
Block(-2,15,2,LEAVES:3)
Block(-1,15,2,LEAVES:3)
Block(0,15,2,LEAVES:3)
Block(0,15,3,LEAVES:3)
Block(0,15,4,VINE:4)
Block(-4,15,1,VINE:8)
Block(2,15,-1,VINE:1)
Block(-1,15,-4,VINE:1)
Block(4,15,-1,VINE:2)
Block(-7,15,4,VINE:8)
Block(-1,15,-9,VINE:1)
Block(5,15,-8,VINE:1)
Block(4,15,2,VINE:2)
Block(-5,15,-4,VINE:8)
Block(7,15,2,VINE:8)
Block(2,15,7,VINE:4)
Block(0,16,0,LOG:15)
Block(-1,16,0,LOG:15)
Block(0,16,-1,LOG:15)
Block(1,16,0,LOG:15)
Block(1,16,1,LOG:15)
Block(0,16,1,LOG:15)
Block(0,16,4,VINE:4)
Block(-4,16,1,VINE:8)
Block(2,16,-1,VINE:1)
Block(-1,16,-4,VINE:1)
Block(4,16,-1,VINE:2)
Block(-7,16,4,VINE:8)
Block(-1,16,-9,VINE:1)
Block(5,16,-8,VINE:1)
Block(4,16,2,VINE:2)
Block(-5,16,-4,VINE:8)
Block(7,16,2,VINE:8)
Block(2,16,7,VINE:4)
Block(0,17,0,LOG:15)
Block(-1,17,0,LOG:15)
Block(0,17,-1,LOG:15)
Block(1,17,0,LOG:15)
Block(1,17,1,LOG:15)
Block(0,17,1,LOG:15)
Block(0,17,4,VINE:4)
Block(-4,17,1,VINE:8)
Block(2,17,-1,VINE:1)
Block(-1,17,-4,VINE:1)
Block(4,17,-1,VINE:2)
Block(-7,17,4,VINE:8)
Block(-1,17,-9,VINE:1)
Block(5,17,-8,VINE:1)
Block(4,17,2,VINE:2)
Block(-5,17,-4,VINE:8)
Block(7,17,2,VINE:8)
Block(2,17,7,VINE:4)
Block(0,25,0,LOG:15)
Block(-1,25,0,LOG:15)
Block(0,25,-1,LOG:15)
Block(1,25,0,LOG:15)
Block(0,25,1,LOG:15)
Block(3,25,-1,LOG:15)
Block(4,25,-1,VINE:2)
Block(3,25,-2,LEAVES:3)
Block(2,25,-1,VINE:1)
Block(3,25,0,LEAVES:3)
Block(2,25,7,VINE:4)
Block(2,25,-2,LEAVES:3)
Block(3,25,-3,LEAVES:3)
Block(4,25,-2,LEAVES:3)
Block(5,25,-1,LEAVES:3)
Block(5,25,-2,LEAVES:3)
Block(4,25,0,LEAVES:3)
Block(4,25,1,LEAVES:3)
Block(3,25,1,LEAVES:3)
Block(2,25,0,LEAVES:3)
Block(1,25,-1,LEAVES:3)
Block(1,25,-2,LEAVES:3)
Block(2,25,-3,LEAVES:3)
Block(4,25,-3,LEAVES:3)
Block(5,25,0,LEAVES:3)
Block(0,25,4,VINE:4)
Block(-4,25,1,VINE:8)
Block(-1,25,-4,VINE:1)
Block(-7,25,4,VINE:8)
Block(-1,25,-9,VINE:1)
Block(5,25,-8,VINE:1)
Block(4,25,2,VINE:2)
Block(-5,25,-4,VINE:8)
Block(7,25,2,VINE:8)
Block(0,26,0,LOG:15)
Block(-1,26,0,LOG:15)
Block(0,26,-1,LOG:15)
Block(1,26,0,LOG:15)
Block(0,26,1,LOG:15)
Block(3,26,-1,LEAVES:3)
Block(3,26,-2,LEAVES:3)
Block(2,26,-1,VINE:1)
Block(3,26,0,LEAVES:3)
Block(2,26,7,VINE:4)
Block(2,26,-2,LEAVES:3)
Block(4,26,-2,LEAVES:3)
Block(4,26,-1,LEAVES:3)
Block(4,26,0,LEAVES:3)
Block(2,26,0,LEAVES:3)
Block(1,26,-1,LEAVES:3)
Block(3,26,-3,LEAVES:3)
Block(5,26,-1,LEAVES:3)
Block(3,26,1,LEAVES:3)
Block(0,26,4,VINE:4)
Block(-4,26,1,VINE:8)
Block(-1,26,-4,VINE:1)
Block(-7,26,4,VINE:8)
Block(-1,26,-9,VINE:1)
Block(5,26,-8,VINE:1)
Block(4,26,2,VINE:2)
Block(-5,26,-4,VINE:8)
Block(7,26,2,VINE:8)

Block(0,27,0,LOG:15)
Block(-1,27,0,LOG:15)
Block(0,27,-1,LOG:15)
Block(1,27,0,LOG:15)
Block(0,27,1,LOG:15)
Block(3,27,-1,LEAVES:3)
Block(2,27,7,VINE:4)
Block(0,27,4,VINE:4)
Block(-4,27,1,VINE:8)
Block(2,27,-1,VINE:1)
Block(-1,27,-4,VINE:1)
Block(-7,27,4,VINE:8)
Block(-1,27,-9,VINE:1)
Block(5,27,-8,VINE:1)
Block(4,27,2,VINE:2)
Block(-5,27,-4,VINE:8)
Block(7,27,2,VINE:8)
Block(0,28,0,LOG:15)
Block(-1,28,0,LOG:15)
Block(0,28,-1,LOG:15)
Block(1,28,0,LOG:15)
Block(0,28,1,LOG:15)
Block(0,28,2,LOG:15)
Block(-1,28,3,LEAVES:3)
Block(1,28,3,LEAVES:3)
Block(0,28,3,LEAVES:3)
Block(2,28,7,VINE:4)
Block(0,28,4,VINE:4)
Block(-4,28,1,VINE:8)
Block(2,28,-1,VINE:1)
Block(-1,28,-4,VINE:1)
Block(-7,28,4,VINE:8)
Block(-1,28,-9,VINE:1)
Block(5,28,-8,VINE:1)
Block(4,28,2,VINE:2)
Block(-5,28,-4,VINE:8)
Block(7,28,2,VINE:8)
Block(0,29,0,LOG:15)
Block(-1,29,0,LOG:15)
Block(0,29,-1,LOG:15)
Block(1,29,0,LOG:15)
Block(0,29,1,LOG:15)
Block(-1,29,3,LOG:15)
Block(1,29,3,LOG:15)
Block(-1,29,2,LEAVES:3)
Block(-2,29,3,LEAVES:3)
Block(-1,29,4,LEAVES:3)
Block(0,29,3,LEAVES:3)
Block(1,29,4,LEAVES:3)
Block(2,29,3,LEAVES:3)
Block(1,29,2,LEAVES:3)
Block(-1,29,-9,VINE:1)
Block(2,29,7,VINE:4)
Block(0,29,4,VINE:4)
Block(-2,29,4,LEAVES:3)
Block(2,29,4,LEAVES:3)
Block(-4,29,1,VINE:8)
Block(2,29,-1,VINE:1)
Block(-1,29,-4,VINE:1)
Block(-7,29,4,VINE:8)
Block(5,29,-8,VINE:1)
Block(4,29,2,VINE:2)
Block(-5,29,-4,VINE:8)
Block(7,29,2,VINE:8)
Block(0,30,0,LOG:15)
Block(-1,30,0,LOG:15)
Block(0,30,-1,LOG:15)
Block(1,30,0,LOG:15)
Block(0,30,1,LOG:15)
Block(-1,30,3,LEAVES:3)
Block(1,30,3,LEAVES:3)
Block(2,30,2,LEAVES:3)
Block(1,30,2,LEAVES:3)
Block(2,30,3,LEAVES:3)
Block(-2,30,3,LEAVES:3)
Block(-1,30,4,LEAVES:3)
Block(0,30,4,VINE:4)
Block(1,30,4,LEAVES:3)
Block(0,30,3,LEAVES:3)
Block(0,30,2,LEAVES:3)
Block(-1,30,2,LEAVES:3)
Block(-1,30,-9,VINE:1)
Block(2,30,-1,VINE:1)
Block(2,30,7,VINE:4)
Block(-1,30,5,LEAVES:3)
Block(0,30,5,LEAVES:3)
Block(1,30,5,LEAVES:3)
Block(2,30,4,LEAVES:3)
Block(-2,30,4,LEAVES:3)
Block(-3,30,4,LEAVES:3)
Block(-3,30,3,LEAVES:3)
Block(-2,30,2,LEAVES:3)
Block(2,30,5,LEAVES:3)
Block(3,30,3,LEAVES:3)
Block(3,30,4,LEAVES:3)
Block(-2,30,5,LEAVES:3)
Block(-4,30,1,VINE:8)
Block(-1,30,-4,VINE:1)
Block(-7,30,4,VINE:8)
Block(5,30,-8,VINE:1)
Block(4,30,2,VINE:2)
Block(-5,30,-4,VINE:8)
Block(7,30,2,VINE:8)
Block(0,31,0,LOG:15)
Block(-1,31,0,LOG:15)
Block(0,31,-1,LOG:15)
Block(1,31,0,LOG:15)
Block(0,31,1,LOG:15)
Block(-1,31,-9,VINE:1)
Block(2,31,-1,VINE:1)
Block(2,31,7,VINE:4)
Block(-2,31,3,LEAVES:3)
Block(-2,31,4,LEAVES:3)
Block(0,31,4,LEAVES:3)
Block(1,31,4,LEAVES:3)
Block(1,31,3,LEAVES:3)
Block(2,31,4,LEAVES:3)
Block(0,31,3,LEAVES:3)
Block(-1,31,3,LEAVES:3)
Block(-4,31,1,VINE:8)
Block(-1,31,-4,VINE:1)
Block(-7,31,4,VINE:8)
Block(5,31,-8,VINE:1)
Block(4,31,2,VINE:2)
Block(-5,31,-4,VINE:8)
Block(7,31,2,VINE:8)
Block(0,32,0,LOG:15)
Block(-6,32,1,LEAVES:3)
Block(-1,32,0,LOG:15)
Block(0,32,-1,LOG:15)
Block(1,32,0,LOG:15)
Block(0,32,1,LOG:15)
Block(-1,32,-9,VINE:1)
Block(2,32,-1,VINE:1)
Block(-4,32,1,VINE:8)
Block(2,32,7,VINE:4)
Block(-1,32,-4,VINE:1)
Block(-7,32,4,VINE:8)
Block(5,32,-8,VINE:1)
Block(4,32,2,VINE:2)
Block(-5,32,-4,VINE:8)
Block(7,32,2,VINE:8)
Block(0,33,0,LOG:15)
Block(-6,33,1,LEAVES:3)
Block(-1,33,0,LOG:15)
Block(0,33,-1,LOG:15)
Block(0,33,1,LOG:15)
Block(1,33,0,LOG:15)
Block(-1,33,-4,VINE:1)
Block(-1,33,-9,VINE:1)
Block(2,33,-1,VINE:1)
Block(-4,33,1,VINE:8)
Block(2,33,7,VINE:4)
Block(-7,33,4,VINE:8)
Block(5,33,-8,VINE:1)
Block(4,33,2,VINE:2)
Block(-5,33,-4,VINE:8)
Block(7,33,2,VINE:8)
Block(0,34,0,LOG:15)
Block(1,34,0,LOG:15)
Block(-6,34,1,LEAVES:3)
Block(0,34,7,LEAVES:3)
Block(0,34,-1,LOG:15)
Block(-1,34,0,LOG:15)
Block(0,34,1,LOG:15)
Block(-1,34,-4,VINE:1)
Block(-1,34,-9,VINE:1)
Block(2,34,-1,VINE:1)
Block(0,34,3,VINE:2)
Block(-4,34,1,VINE:8)
Block(2,34,7,VINE:4)
Block(-7,34,4,VINE:8)
Block(5,34,-8,VINE:1)
Block(-5,34,-4,VINE:8)
Block(7,34,2,VINE:8)
Block(4,34,2,VINE:2)
Block(0,35,0,LOG:15)
Block(0,35,1,LOG:15)
Block(2,35,0,LOG:15)
Block(0,35,-2,LOG:15)
Block(0,35,-1,LOG:15)
Block(-6,35,1,LEAVES:3)
Block(0,35,7,LEAVES:3)
Block(-1,35,-4,VINE:1)
Block(-1,35,-9,VINE:1)
Block(5,35,-8,VINE:1)
Block(2,35,-1,VINE:1)
Block(0,35,3,VINE:2)
Block(-4,35,1,VINE:8)
Block(-7,35,4,VINE:8)
Block(2,35,7,VINE:4)
Block(4,35,2,VINE:2)
Block(-5,35,-4,VINE:8)
Block(7,35,2,VINE:8)
Block(0,36,0,LOG:15)
Block(0,36,2,LOG:15)
Block(-1,36,0,LOG:15)
Block(0,36,-2,LOG:15)
Block(2,36,0,LOG:15)
Block(-6,36,1,LEAVES:3)
Block(0,36,7,LEAVES:3)
Block(-1,36,-4,VINE:1)
Block(-1,36,-9,VINE:1)
Block(5,36,-8,VINE:1)
Block(2,36,-1,VINE:1)
Block(0,36,3,VINE:2)
Block(4,36,2,VINE:2)
Block(-4,36,1,VINE:8)
Block(-7,36,4,VINE:8)
Block(2,36,7,VINE:4)
Block(-5,36,-4,VINE:8)
Block(7,36,2,VINE:8)
Block(0,37,-2,LOG:15)
Block(0,37,2,LOG:15)
Block(0,37,0,LOG:15)
Block(-2,37,1,LOG:15)
Block(2,37,0,LOG:15)
Block(-6,37,1,LEAVES:3)
Block(0,37,7,LEAVES:3)
Block(-1,37,-4,VINE:1)
Block(-1,37,-9,VINE:1)
Block(5,37,-8,VINE:1)
Block(2,37,-1,VINE:1)
Block(0,37,3,VINE:2)
Block(4,37,2,VINE:2)
Block(-4,37,1,VINE:8)
Block(-7,37,4,VINE:8)
Block(2,37,7,VINE:4)
Block(-5,37,-4,VINE:8)
Block(7,37,2,VINE:8)
Block(0,38,0,LOG:15)
Block(-2,38,1,LOG:15)
Block(1,38,1,LOG:15)
Block(2,38,2,LOG:15)
Block(0,38,-3,LOG:15)
Block(-1,38,3,LOG:15)
Block(-6,38,1,LEAVES:3)
Block(0,38,7,LEAVES:3)
Block(-1,38,-4,VINE:1)
Block(-1,38,-9,VINE:1)
Block(5,38,-8,VINE:1)
Block(2,38,-1,VINE:1)
Block(0,38,3,VINE:2)
Block(4,38,2,VINE:2)
Block(-4,38,1,VINE:8)
Block(-7,38,4,VINE:8)
Block(2,38,7,VINE:4)
Block(-5,38,-4,VINE:8)
Block(7,38,2,VINE:8)
Block(0,39,0,LOG:15)
Block(-3,39,1,LOG:15)
Block(-4,39,2,LOG:15)
Block(0,39,4,LOG:15)
Block(2,39,3,LOG:15)
Block(3,39,2,LOG:15)
Block(4,39,1,LOG:15)
Block(-1,39,-3,LOG:15)
Block(1,39,-3,LOG:15)
Block(-2,39,-2,LOG:15)
Block(-2,39,-4,LOG:15)
Block(2,39,0,LOG:15)
Block(-6,39,1,LEAVES:3)
Block(0,39,7,LEAVES:3)
Block(-1,39,-4,VINE:1)
Block(5,39,-8,VINE:1)
Block(-1,39,-9,VINE:1)
Block(2,39,-1,VINE:1)
Block(0,39,3,VINE:2)
Block(4,39,2,VINE:2)
Block(-4,39,1,VINE:8)
Block(-7,39,4,VINE:8)
Block(2,39,7,VINE:4)
Block(-5,39,-4,VINE:8)
Block(7,39,2,VINE:8)
Block(0,40,0,LOG:15)
Block(-2,40,-1,LOG:15)
Block(-4,40,0,LOG:15)
Block(-3,40,-3,LOG:15)
Block(-3,40,-4,LOG:15)
Block(-3,40,3,LOG:15)
Block(-1,40,3,LOG:15)
Block(-1,40,4,LOG:15)
Block(3,40,3,LOG:15)
Block(3,40,0,LOG:15)
Block(4,40,0,LOG:15)
Block(2,40,-2,LOG:15)
Block(3,40,-2,LOG:15)
Block(3,40,-3,LOG:15)
Block(1,40,-4,LOG:15)
Block(0,40,4,LEAVES:3)
Block(5,40,0,LEAVES:3)
Block(-5,40,0,LEAVES:3)
Block(0,40,-5,LEAVES:3)
Block(1,40,-5,LEAVES:3)
Block(-2,40,-5,LEAVES:3)
Block(-2,40,-4,LEAVES:3)
Block(-3,40,-5,LEAVES:3)
Block(-4,40,-4,LEAVES:3)
Block(-4,40,-3,LEAVES:3)
Block(-4,40,-2,LEAVES:3)
Block(-4,40,-1,LEAVES:3)
Block(-5,40,-1,LEAVES:3)
Block(-5,40,1,LEAVES:3)
Block(-4,40,3,LEAVES:3)
Block(-4,40,2,LEAVES:3)
Block(-4,40,1,LEAVES:3)
Block(-3,40,4,LEAVES:3)
Block(-2,40,4,LEAVES:3)
Block(-1,40,5,LEAVES:3)
Block(3,40,4,LOG:15)
Block(4,40,2,LEAVES:3)
Block(4,40,1,LEAVES:3)
Block(5,40,2,LEAVES:3)
Block(5,40,1,LEAVES:3)
Block(2,40,-4,LEAVES:3)
Block(2,40,-3,LEAVES:3)
Block(3,40,-4,LEAVES:3)
Block(4,40,-3,LEAVES:3)
Block(4,40,-2,LEAVES:3)
Block(4,40,-1,LEAVES:3)
Block(3,40,-1,LEAVES:3)
Block(5,40,-1,LEAVES:3)
Block(4,40,3,LEAVES:3)
Block(0,40,5,LEAVES:3)
Block(2,40,4,LEAVES:3)
Block(1,40,5,LEAVES:3)
Block(-5,40,2,LEAVES:3)
Block(-1,40,-5,LEAVES:3)
Block(0,40,-6,LEAVES:3)
Block(-1,40,-6,LEAVES:3)
Block(-2,40,-6,LEAVES:3)
Block(-5,40,-3,LEAVES:3)
Block(-5,40,-2,LEAVES:3)
Block(-5,40,3,LEAVES:3)
Block(-4,40,4,LEAVES:3)
Block(-3,40,5,LEAVES:3)
Block(-2,40,5,LEAVES:3)
Block(2,40,5,LEAVES:3)
Block(3,40,5,LEAVES:3)
Block(4,40,4,LEAVES:3)
Block(5,40,-2,LEAVES:3)
Block(3,40,-5,LEAVES:3)
Block(2,40,-5,LEAVES:3)
Block(1,40,-6,LEAVES:3)
Block(-6,40,1,LEAVES:3)
Block(0,40,7,LEAVES:3)
Block(1,40,4,LEAVES:3)
Block(4,40,-4,LEAVES:3)
Block(-1,40,-9,VINE:1)
Block(5,40,-8,VINE:1)
Block(2,40,-1,VINE:1)
Block(0,40,3,VINE:2)
Block(-7,40,4,VINE:8)
Block(2,40,7,VINE:4)
Block(-5,40,-4,VINE:8)
Block(-6,40,3,LEAVES:3)
Block(-5,40,4,LEAVES:3)
Block(-4,40,5,LEAVES:3)
Block(-6,40,2,LEAVES:3)
Block(-6,40,-1,LEAVES:3)
Block(-6,40,-2,LEAVES:3)
Block(-1,40,6,LEAVES:3)
Block(0,40,6,LEAVES:3)
Block(-2,40,6,LEAVES:3)
Block(-3,40,6,LEAVES:3)
Block(1,40,6,LEAVES:3)
Block(7,40,2,VINE:8)
Block(0,41,0,LEAVES:3)
Block(-1,41,0,LEAVES:3)
Block(-2,41,0,LEAVES:3)
Block(-3,41,0,LOG:15)
Block(-4,41,0,LEAVES:3)
Block(-5,41,0,LOG:15)
Block(1,41,0,LEAVES:3)
Block(2,41,0,LOG:15)
Block(3,41,0,LEAVES:3)
Block(4,41,0,LEAVES:3)
Block(5,41,0,LOG:15)
Block(0,41,1,LEAVES:3)
Block(0,41,2,LEAVES:3)
Block(0,41,3,LEAVES:3)
Block(0,41,4,LEAVES:3)
Block(0,41,5,LOG:15)
Block(0,41,-1,LEAVES:3)
Block(0,41,-2,LEAVES:3)
Block(0,41,-3,LEAVES:3)
Block(0,41,-4,LEAVES:3)
Block(0,41,-5,LEAVES:3)
Block(1,41,-5,LOG:15)
Block(-1,41,-5,LOG:15)
Block(-2,41,-5,LEAVES:3)
Block(-5,41,-1,LEAVES:3)
Block(-5,41,2,LEAVES:3)
Block(-5,41,1,LEAVES:3)
Block(-1,41,5,LEAVES:3)
Block(1,41,5,LEAVES:3)
Block(5,41,-1,LEAVES:3)
Block(5,41,1,LEAVES:3)
Block(5,41,2,LEAVES:3)
Block(4,41,3,LEAVES:3)
Block(3,41,4,LOG:15)
Block(2,41,4,LEAVES:3)
Block(-2,41,4,LEAVES:3)
Block(-3,41,3,LEAVES:3)
Block(-4,41,3,LOG:15)
Block(-4,41,-2,LEAVES:3)
Block(-4,41,-3,LEAVES:3)
Block(-3,41,-4,LEAVES:3)
Block(2,41,-4,LEAVES:3)
Block(3,41,-4,LOG:15)
Block(4,41,-3,LEAVES:3)
Block(4,41,-2,LEAVES:3)
Block(-3,41,-2,LEAVES:3)
Block(-3,41,-3,LEAVES:3)
Block(-2,41,-3,LEAVES:3)
Block(-2,41,-4,LOG:15)
Block(-1,41,-4,LEAVES:3)
Block(-1,41,-3,LEAVES:3)
Block(-1,41,-2,LEAVES:3)
Block(-1,41,-1,LEAVES:3)
Block(-2,41,-1,LEAVES:3)
Block(-3,41,-1,LEAVES:3)
Block(-4,41,-1,LOG:15)
Block(-2,41,-2,LEAVES:3)
Block(-4,41,1,LEAVES:3)
Block(-3,41,1,LEAVES:3)
Block(-2,41,1,LEAVES:3)
Block(-1,41,1,LEAVES:3)
Block(-1,41,2,LOG:15)
Block(-2,41,2,LEAVES:3)
Block(-3,41,2,LEAVES:3)
Block(-4,41,2,LEAVES:3)
Block(-2,41,3,LEAVES:3)
Block(-1,41,3,LEAVES:3)
Block(-1,41,4,LEAVES:3)
Block(1,41,4,LEAVES:3)
Block(2,41,3,LEAVES:3)
Block(1,41,3,LEAVES:3)
Block(1,41,2,LEAVES:3)
Block(1,41,1,LEAVES:3)
Block(2,41,1,LEAVES:3)
Block(3,41,1,LEAVES:3)
Block(4,41,1,LEAVES:3)
Block(4,41,2,LEAVES:3)
Block(3,41,2,LEAVES:3)
Block(3,41,3,LEAVES:3)
Block(2,41,2,LEAVES:3)
Block(3,41,-1,LEAVES:3)
Block(4,41,-1,LEAVES:3)
Block(2,41,-1,LEAVES:3)
Block(1,41,-1,LEAVES:3)
Block(1,41,-2,LOG:15)
Block(2,41,-3,LEAVES:3)
Block(2,41,-2,LEAVES:3)
Block(3,41,-2,LEAVES:3)
Block(3,41,-3,LEAVES:3)
Block(1,41,-3,LEAVES:3)
Block(1,41,-4,LEAVES:3)
Block(-5,41,-2,LOG:15)
Block(-5,41,-3,LEAVES:3)
Block(-4,41,-4,LEAVES:3)
Block(-3,41,-5,LOG:15)
Block(-3,41,-6,LEAVES:3)
Block(-2,41,-6,LOG:15)
Block(-1,41,-6,LEAVES:3)
Block(0,41,-7,LEAVES:3)
Block(-1,41,-7,LOG:15)
Block(0,41,-6,LEAVES:3)
Block(1,41,-6,LEAVES:3)
Block(2,41,-6,LOG:15)
Block(2,41,-5,LEAVES:3)
Block(3,41,-5,LEAVES:3)
Block(4,41,-5,LEAVES:3)
Block(5,41,-4,LOG:15)
Block(4,41,-4,LOG:15)
Block(5,41,-3,LEAVES:3)
Block(5,41,-2,LEAVES:3)
Block(6,41,-1,LEAVES:3)
Block(6,41,0,LOG:15)
Block(6,41,1,LEAVES:3)
Block(5,41,3,LEAVES:3)
Block(5,41,4,LEAVES:3)
Block(4,41,4,LEAVES:3)
Block(2,41,5,LEAVES:3)
Block(3,41,5,LOG:15)
Block(1,41,6,LEAVES:3)
Block(0,41,6,LEAVES:3)
Block(-1,41,6,LOG:15)
Block(-2,41,5,LEAVES:3)
Block(-3,41,5,LEAVES:3)
Block(-3,41,4,LEAVES:3)
Block(-4,41,4,LEAVES:3)
Block(-5,41,3,LEAVES:3)
Block(-6,41,1,LOG:15)
Block(-6,41,0,LEAVES:3)
Block(-6,41,-1,LEAVES:3)
Block(-4,41,-5,LEAVES:3)
Block(7,41,0,LEAVES:3)
Block(8,41,0,LEAVES:3)
Block(7,41,1,LOG:15)
Block(7,41,-1,LOG:15)
Block(6,41,-2,LEAVES:3)
Block(6,41,-3,LEAVES:3)
Block(6,41,2,LOG:15)
Block(6,41,3,LEAVES:3)
Block(4,41,5,LEAVES:3)
Block(5,41,5,LOG:15)
Block(3,41,6,LEAVES:3)
Block(2,41,6,LEAVES:3)
Block(1,41,7,LEAVES:3)
Block(0,41,7,LOG:15)
Block(-1,41,7,LEAVES:3)
Block(-2,41,6,LEAVES:3)
Block(8,41,-1,LEAVES:3)
Block(7,41,-2,LEAVES:3)
Block(3,41,-6,LEAVES:3)
Block(4,41,-6,LEAVES:3)
Block(5,41,-5,LEAVES:3)
Block(6,41,-4,LEAVES:3)
Block(3,41,-7,LEAVES:3)
Block(2,41,-7,LOG:15)
Block(1,41,-7,LEAVES:3)
Block(1,41,-8,LOG:15)
Block(0,41,-8,LEAVES:3)
Block(2,41,-8,LEAVES:3)
Block(-2,41,-7,LEAVES:3)
Block(-3,41,-7,LEAVES:3)
Block(-4,41,-6,LEAVES:3)
Block(-5,41,-4,VINE:8)
Block(-1,41,-8,LEAVES:3)
Block(-6,41,-2,LEAVES:3)
Block(-7,41,0,LEAVES:3)
Block(-7,41,-1,LEAVES:3)
Block(-6,41,-3,LEAVES:3)
Block(-6,41,2,LEAVES:3)
Block(-7,41,1,LEAVES:3)
Block(-5,41,4,LOG:15)
Block(-6,41,3,LEAVES:3)
Block(-4,41,5,LEAVES:3)
Block(-3,41,6,LEAVES:3)
Block(-2,41,7,LEAVES:3)
Block(7,41,2,VINE:8)
Block(8,41,1,LEAVES:3)
Block(6,41,4,LEAVES:3)
Block(7,41,3,LEAVES:3)
Block(2,41,7,VINE:4)
Block(3,41,7,LEAVES:3)
Block(4,41,6,LOG:15)
Block(5,41,-6,LOG:15)
Block(6,41,-5,LOG:15)
Block(-7,41,-2,LEAVES:3)
Block(-8,41,-1,LEAVES:3)
Block(-8,41,0,LEAVES:3)
Block(-8,41,1,LEAVES:3)
Block(-7,41,2,LEAVES:3)
Block(-7,41,3,LEAVES:3)
Block(-8,41,2,LEAVES:3)
Block(-6,41,4,LEAVES:3)
Block(-5,41,5,LEAVES:3)
Block(-6,41,5,LEAVES:3)
Block(-4,41,6,LEAVES:3)
Block(-5,41,6,LEAVES:3)
Block(-7,41,-3,LEAVES:3)
Block(-6,41,-4,LEAVES:3)
Block(-5,41,-5,LEAVES:3)
Block(-5,41,-6,LEAVES:3)
Block(-8,41,-2,LEAVES:3)
Block(-7,41,-4,LEAVES:3)
Block(-6,41,-5,LEAVES:3)
Block(-4,41,-7,LEAVES:3)
Block(-2,41,-8,LEAVES:3)
Block(3,41,-8,LEAVES:3)
Block(4,41,-7,LEAVES:3)
Block(5,41,-7,LEAVES:3)
Block(6,41,-6,LEAVES:3)
Block(7,41,-6,LEAVES:3)
Block(7,41,-5,LEAVES:3)
Block(7,41,-4,LEAVES:3)
Block(7,41,-3,LEAVES:3)
Block(8,41,-3,LEAVES:3)
Block(8,41,-2,LEAVES:3)
Block(8,41,2,LEAVES:3)
Block(8,41,3,LEAVES:3)
Block(7,41,4,LEAVES:3)
Block(6,41,5,LEAVES:3)
Block(5,41,6,LEAVES:3)
Block(5,41,7,LEAVES:3)
Block(4,41,7,LEAVES:3)
Block(6,41,6,LEAVES:3)
Block(7,41,5,LEAVES:3)
Block(3,41,8,LEAVES:3)
Block(2,41,8,LEAVES:3)
Block(1,41,8,LEAVES:3)
Block(0,41,8,LEAVES:3)
Block(-1,41,8,LEAVES:3)
Block(6,41,-7,LEAVES:3)
Block(4,41,8,LEAVES:3)
Block(-1,41,-9,VINE:1)
Block(5,41,-8,VINE:1)
Block(-7,41,4,VINE:8)
Block(-2,41,-9,LEAVES:3)
Block(0,41,-9,LEAVES:3)
Block(1,41,-9,LEAVES:3)
Block(-1,41,-10,LEAVES:3)
Block(-3,41,-8,LEAVES:3)
Block(-4,41,-8,LEAVES:3)
Block(-3,41,-9,LEAVES:3)
Block(2,41,-9,LEAVES:3)
Block(4,41,-8,LEAVES:3)
Block(4,41,-9,LEAVES:3)
Block(5,41,-9,LEAVES:3)
Block(6,41,-8,LEAVES:3)
Block(3,41,-9,LEAVES:3)
Block(0,41,-10,LEAVES:3)
Block(1,41,-10,LEAVES:3)
Block(-4,41,7,LEAVES:3)
Block(-3,41,7,LEAVES:3)
Block(-8,41,3,LEAVES:3)
Block(-8,41,4,LEAVES:3)
Block(-7,41,5,LEAVES:3)
Block(-8,41,5,LEAVES:3)
Block(-6,41,6,LEAVES:3)
Block(-7,41,6,LEAVES:3)
Block(-9,41,4,LEAVES:3)
Block(-9,41,3,LEAVES:3)
Block(-9,41,2,LEAVES:3)
Block(-9,41,1,LEAVES:3)
Block(-3,42,0,LEAVES:3)
Block(-2,42,0,LEAVES:3)
Block(-1,42,0,LEAVES:3)
Block(0,42,0,LEAVES:3)
Block(1,42,0,LEAVES:3)
Block(2,42,0,LEAVES:3)
Block(0,42,-3,LEAVES:3)
Block(0,42,-2,LEAVES:3)
Block(0,42,-1,LEAVES:3)
Block(0,42,1,LEAVES:3)
Block(0,42,2,LEAVES:3)
Block(0,42,3,LEAVES:3)
Block(1,42,2,LEAVES:3)
Block(1,42,1,LEAVES:3)
Block(1,42,-2,LEAVES:3)
Block(1,42,-1,LEAVES:3)
Block(2,42,-1,LEAVES:3)
Block(2,42,1,LEAVES:3)
Block(-3,42,1,LEAVES:3)
Block(-2,42,-1,LEAVES:3)
Block(-2,42,1,LEAVES:3)
Block(-2,42,2,LEAVES:3)
Block(-1,42,3,LEAVES:3)
Block(-1,42,2,LEAVES:3)
Block(-1,42,1,LEAVES:3)
Block(-1,42,-1,LEAVES:3)
Block(-1,42,-2,LEAVES:3)
Block(-3,42,-1,LEAVES:3)
Block(-3,42,-2,LEAVES:3)
Block(-2,42,-2,LEAVES:3)
Block(-1,42,-3,LEAVES:3)
Block(0,42,-4,LEAVES:3)
Block(1,42,-4,LEAVES:3)
Block(1,42,-3,LEAVES:3)
Block(2,42,-3,LEAVES:3)
Block(2,42,-2,LEAVES:3)
Block(3,42,-1,LEAVES:3)
Block(3,42,0,LEAVES:3)
Block(3,42,-2,LEAVES:3)
Block(3,42,1,LEAVES:3)
Block(2,42,2,LEAVES:3)
Block(-2,42,-3,LEAVES:3)
Block(-1,42,-4,LEAVES:3)
Block(0,42,-5,LEAVES:3)
Block(1,42,3,LEAVES:3)
Block(3,42,-3,LEAVES:3)
Block(2,42,-4,LEAVES:3)
Block(1,42,-5,LEAVES:3)
Block(-2,42,-4,LEAVES:3)
Block(-1,42,-5,LEAVES:3)
Block(-3,42,-3,LEAVES:3)
Block(-4,42,0,LEAVES:3)
Block(-4,42,-1,LEAVES:3)
Block(4,42,-1,LEAVES:3)
Block(4,42,-2,LEAVES:3)
Block(-5,42,0,LEAVES:3)
Block(-4,42,-2,LEAVES:3)
Block(-5,42,-1,LEAVES:3)
Block(-5,42,-2,LEAVES:3)
Block(-3,42,-4,LEAVES:3)
Block(-4,42,-3,LEAVES:3)
Block(-2,42,-5,LEAVES:3)
Block(0,42,-6,LEAVES:3)
Block(1,42,-6,LEAVES:3)
Block(2,42,-6,LEAVES:3)
Block(2,42,-5,LEAVES:3)
Block(3,42,-4,LEAVES:3)
Block(4,42,-4,LEAVES:3)
Block(3,42,-5,LEAVES:3)
Block(4,42,-3,LEAVES:3)
Block(6,42,0,LEAVES:3)
Block(5,42,0,LEAVES:3)
Block(4,42,0,LEAVES:3)
Block(5,42,-1,LEAVES:3)
Block(5,42,-2,LEAVES:3)
Block(5,42,1,LEAVES:3)
Block(4,42,1,LEAVES:3)
Block(4,42,2,LEAVES:3)
Block(3,42,2,LEAVES:3)
Block(3,42,3,LEAVES:3)
Block(3,42,4,LEAVES:3)
Block(3,42,5,LEAVES:3)
Block(2,42,3,LEAVES:3)
Block(2,42,4,LEAVES:3)
Block(2,42,5,LEAVES:3)
Block(1,42,4,LEAVES:3)
Block(0,42,5,LEAVES:3)
Block(-1,42,5,LEAVES:3)
Block(-1,42,6,LEAVES:3)
Block(-1,42,4,LEAVES:3)
Block(0,42,4,LEAVES:3)
Block(-2,42,5,LEAVES:3)
Block(-2,42,4,LEAVES:3)
Block(-3,42,4,LEAVES:3)
Block(-3,42,3,LEAVES:3)
Block(-4,42,3,LEAVES:3)
Block(-2,42,3,LEAVES:3)
Block(-3,42,2,LEAVES:3)
Block(-4,42,1,LEAVES:3)
Block(-4,42,2,LEAVES:3)
Block(-5,42,1,LEAVES:3)
Block(4,42,3,LEAVES:3)
Block(5,42,2,LEAVES:3)
Block(6,42,1,LEAVES:3)
Block(4,42,4,LEAVES:3)
Block(1,42,5,LEAVES:3)
Block(-6,42,1,LEAVES:3)
Block(-5,42,4,LEAVES:3)
Block(0,42,7,LEAVES:3)
Block(4,42,6,LEAVES:3)
Block(7,42,1,LEAVES:3)
Block(7,42,-1,LEAVES:3)
Block(5,42,-4,LEAVES:3)
Block(6,42,-5,LEAVES:3)
Block(2,42,-7,LEAVES:3)
Block(-3,42,-5,LEAVES:3)
Block(-5,42,3,LEAVES:3)
Block(-5,42,2,LEAVES:3)
Block(-6,42,2,LEAVES:3)
Block(-4,42,5,LEAVES:3)
Block(-4,42,4,LEAVES:3)
Block(-3,42,5,LEAVES:3)
Block(0,42,6,LEAVES:3)
Block(1,42,6,LEAVES:3)
Block(2,42,6,LEAVES:3)
Block(3,42,6,LEAVES:3)
Block(1,42,7,LEAVES:3)
Block(2,42,7,VINE:4)
Block(4,42,5,LEAVES:3)
Block(5,42,4,LEAVES:3)
Block(5,42,3,LEAVES:3)
Block(6,42,3,LEAVES:3)
Block(6,42,2,LEAVES:3)
Block(7,42,0,LEAVES:3)
Block(6,42,-1,LEAVES:3)
Block(6,42,-2,LEAVES:3)
Block(6,42,-3,LEAVES:3)
Block(6,42,-4,LEAVES:3)
Block(5,42,-3,LEAVES:3)
Block(4,42,-5,LEAVES:3)
Block(5,42,-5,LEAVES:3)
Block(4,42,-6,LEAVES:3)
Block(3,42,-6,LEAVES:3)
Block(-1,42,-6,LEAVES:3)
Block(7,42,-2,LEAVES:3)
Block(5,42,5,LEAVES:3)
Block(-6,42,4,VINE:8)
Block(-6,42,-1,LEAVES:3)
Block(-6,42,-2,LEAVES:3)
Block(-6,42,-3,LEAVES:3)
Block(-5,42,-3,LEAVES:3)
Block(-5,42,-4,LEAVES:3)
Block(-4,42,-4,LEAVES:3)
Block(-4,42,-5,LEAVES:3)
Block(-3,42,-6,LEAVES:3)
Block(-2,42,-6,LEAVES:3)
Block(-1,42,-7,LEAVES:3)
Block(0,42,-7,LEAVES:3)
Block(0,42,-8,LEAVES:3)
Block(1,42,-8,LEAVES:3)
Block(1,42,-7,LEAVES:3)
Block(2,42,-8,LEAVES:3)
Block(3,42,-8,LEAVES:3)
Block(5,42,-6,LEAVES:3)
Block(4,42,-7,LEAVES:3)
Block(3,42,-7,LEAVES:3)
Block(-6,42,3,LEAVES:3)
Block(-6,42,5,LEAVES:3)
Block(-5,42,5,LEAVES:3)
Block(-4,42,6,LEAVES:3)
Block(-3,42,6,LEAVES:3)
Block(-2,42,6,LEAVES:3)
Block(-7,42,3,LEAVES:3)
Block(-7,42,5,LEAVES:3)
Block(-8,42,4,LEAVES:3)
Block(-8,42,3,LEAVES:3)
Block(-8,42,2,LEAVES:3)
Block(-7,42,2,LEAVES:3)
Block(-7,42,1,LEAVES:3)
Block(-6,42,0,LEAVES:3)
Block(-7,42,0,LEAVES:3)
Block(-7,42,-1,LEAVES:3)
Block(-8,42,1,LEAVES:3)
Block(-7,42,4,LEAVES:3)
Block(-3,43,-2,LEAVES:3)
Block(-3,43,-1,LEAVES:3)
Block(-3,43,0,LEAVES:3)
Block(-3,43,1,LEAVES:3)
Block(-3,43,2,LEAVES:3)
Block(-3,43,3,LEAVES:3)
Block(-2,43,3,LEAVES:3)
Block(-1,43,2,LEAVES:3)
Block(-1,43,1,LEAVES:3)
Block(0,43,1,LEAVES:3)
Block(0,43,0,LEAVES:3)
Block(1,43,1,LEAVES:3)
Block(1,43,2,LEAVES:3)
Block(0,43,2,LEAVES:3)
Block(-1,43,0,LEAVES:3)
Block(-1,43,-1,LEAVES:3)
Block(-2,43,-1,LEAVES:3)
Block(-2,43,-2,LEAVES:3)
Block(-2,43,0,LEAVES:3)
Block(-2,43,1,LEAVES:3)
Block(-2,43,2,LEAVES:3)
Block(-4,43,0,LEAVES:3)
Block(-4,43,1,LEAVES:3)
Block(-3,43,-3,LEAVES:3)
Block(-2,43,-3,LEAVES:3)
Block(-1,43,-3,LEAVES:3)
Block(0,43,-3,LEAVES:3)
Block(0,43,-4,LEAVES:3)
Block(1,43,-4,LEAVES:3)
Block(1,43,-3,LEAVES:3)
Block(1,43,-2,LEAVES:3)
Block(1,43,-1,LEAVES:3)
Block(1,43,0,LEAVES:3)
Block(0,43,-1,LEAVES:3)
Block(0,43,-2,LEAVES:3)
Block(2,43,-2,LEAVES:3)
Block(3,43,-2,LEAVES:3)
Block(3,43,-1,LEAVES:3)
Block(3,43,0,LEAVES:3)
Block(2,43,1,LEAVES:3)
Block(2,43,-1,LEAVES:3)
Block(2,43,0,LEAVES:3)
Block(3,43,1,LEAVES:3)
Block(4,43,1,LEAVES:3)
Block(3,43,2,LEAVES:3)
Block(2,43,2,LEAVES:3)
Block(1,43,3,LEAVES:3)
Block(0,43,3,LEAVES:3)
Block(-1,43,3,LEAVES:3)
Block(-1,43,-2,LEAVES:3)
Block(-4,43,-1,LEAVES:3)
Block(-4,43,2,LEAVES:3)
Block(2,43,-3,LEAVES:3)
Block(4,43,0,LEAVES:3)
Block(4,43,-1,LEAVES:3)
Block(-1,43,4,LEAVES:3)
Block(0,43,4,LEAVES:3)
Block(-2,43,4,LEAVES:3)
Block(2,43,3,LEAVES:3)
Block(1,43,4,LEAVES:3)
Block(-1,43,-4,LEAVES:3)
Block(0,43,-5,LEAVES:3)
Block(1,43,-5,LEAVES:3)
Block(2,43,-5,LEAVES:3)
Block(2,43,-4,LEAVES:3)
Block(3,43,-3,LEAVES:3)
Block(3,43,-4,LEAVES:3)
Block(4,43,-2,LEAVES:3)
Block(-2,43,-4,LEAVES:3)


#######################################################################
# +-----------------------------------------------------------------+ #
# |                            BO3 checks                           | #
# +-----------------------------------------------------------------+ #
#######################################################################

# Require a condition at a certain location in order for the BO3 to be spawned.
# BlockCheck(x,y,z,BlockName[,BlockName[,...]]) - one of the blocks must be at the location
# BlockCheckNot(x,y,z,BlockName[,BlockName[,...]]) - all the blocks must not be at the location
# LightCheck(x,y,z,minLightLevel,maxLightLevel) - light must be between min and max (inclusive)

# You can use "Solid" as a BlockName for matching all solid blocks or "All" to match all blocks that aren't air.

# Examples:
BlockCheck(0,-1,0,GRASS,DIRT,DIRT:2,SAND,STONE,CLAY,GRAVEL)
#   BlockCheck(0,-1,0,Solid)       Require any solid block just below the object
#   BlockCheck(0,-1,0,WOOL)        Require any type of wool just below the object
#   BlockCheck(0,-1,0,WOOL:0)      Require white wool just below the object
#   BlockCheckNot(0,-1,0,WOOL:0)   Require that there is no white wool below the object
#   LightCheck(0,0,0,0,1)          Require almost complete darkness just below the object

#######################################################################
# +-----------------------------------------------------------------+ #
# |                             Branches                            | #
# +-----------------------------------------------------------------+ #
#######################################################################

# Branches are objects that will spawn when this object spawns when it is used in
# the CustomStructure resource. Branches can also have branches, making complex
# structures possible. See the wiki for more details.

# Regular Branches spawn each branch with an independent chance of spawning.
# Branch(x,y,z,branchName,rotation,chance[,anotherBranchName,rotation,chance[,...]][IndividualChance])
# branchName - name of the object to spawn.
# rotation - NORTH, SOUTH, EAST or WEST.
# IndividualChance - The chance each branch has to spawn, assumed to be 100 when left blank

# Weighted Branches spawn branches with a dependent chance of spawning.
# WeightedBranch(x,y,z,branchName,rotation,chance[,anotherBranchName,rotation,chance[,...]][MaxChanceOutOf])
# MaxChanceOutOf - The chance all branches have to spawn out of, assumed to be 100 when left blank

