#######################################################################
# +-----------------------------------------------------------------+ #
# |                            BO3 object                           | #
# +-----------------------------------------------------------------+ #
#######################################################################

# This is the config file of a custom object.
# If you add this object correctly to your BiomeConfigs, it will spawn in the world.

# This is the creator of this BO3 object
Author: BO3 BulkEdit (by LanToaster)

# A short description of this BO3 object
Description: This Object was Created with BO3_BulkEdit

# The BO3 version, don't change this! It can be used by external applications to do a version check.
Version: 3

# The settings mode, WriteAll, WriteWithoutComments or WriteDisable. See WorldConfig.
SettingsMode: WriteDisable


#######################################################################
# +-----------------------------------------------------------------+ #
# |                          Main settings                          | #
# +-----------------------------------------------------------------+ #
#######################################################################

# This needs to be set to true to spawn the object in the Tree and Sapling resources.
Tree: true

# The frequency of the BO3 from 1 to 200. Tries this many times to spawn this BO3 when using the CustomObject(...) resource.
# Ignored by Tree(..), Sapling(..) and CustomStructure(..)
Frequency: 1

# The rarity of the BO3 from 0 to 100. Each spawn attempt has rarity% chance to succeed when using the CustomObject(...) resource.
# Ignored by Tree(..), Sapling(..) and CustomStructure(..)
Rarity: 200

# If you set this to true, the BO3 will be placed with a random rotation.
RotateRandomly: True

# The spawn height of the BO3 - randomY, highestBlock or highestSolidBlock.
SpawnHeight: highestSolidBlock
SpawnHeightOffset: -1
# The height limits for the BO3.
MinHeight: 0

MaxHeight: 68

# Objects can have other objects attacthed to it: branches. Branches can also
# have branches attached to it, which can also have branches, etc. This is the
# maximum branch depth for this objects.
MaxBranchDepth: 10

# When spawned with the UseWorld keyword, this BO3 should NOT spawn in the following biomes.
# If you writer.write the BO3 name directly in the BiomeConfigs, this will be ignored.
ExcludedBiomes: All


#######################################################################
# +-----------------------------------------------------------------+ #
# |                      Source block settings                      | #
# +-----------------------------------------------------------------+ #
#######################################################################

# The block(s) the BO3 should spawn in.
SourceBlocks: AIR,GRASS,DIRT,DIRT:2,STONE,SAND,CLAY,GRAVEL,STATIONARY_WATER

# The maximum percentage of the BO3 that can be outside the SourceBlock.
# The BO3 won't be placed on a location with more blocks outside the SourceBlock than this percentage.
MaxPercentageOutsideSourceBlock: 0

# What to do when a block is about to be placed outside the SourceBlock? (dontPlace, placeAnyway)
OutsideSourceBlock: dontPlace


#######################################################################
# +-----------------------------------------------------------------+ #
# |                              Blocks                             | #
# +-----------------------------------------------------------------+ #
#######################################################################

# All the blocks used in the BO3 are listed here. Possible blocks:
# Block(x,y,z,id[.data][,nbtfile.nbt)
# RandomBlock(x,y,z,id[:data][,nbtfile.nbt],chance[,id[:data][,nbtfile.nbt],chance[,...]])
# So RandomBlock(0,0,0,CHEST,chest.nbt,50,CHEST,anotherchest.nbt,100) will spawn a chest at
# the BO3 origin, and give it a 50% chance to have the contents of chest.nbt, or, if that
# fails, a 100% percent chance to have the contents of anotherchest.nbt.

Block(-6,0,-9,LEAVES:3)
Block(-1,0,-9,LEVES:3)
Block(0,0,-9,LEVES:3)
Block(1,0,-9,LEVES:3)
Block(-7,0,-8,LEAVES:3)
Block(-6,0,-8,LEAVES:3)
Block(0,0,-8,LEVES:3)
Block(4,0,-8,LEVES:3)
Block(5,0,-8,LEVES:3)
Block(6,0,-8,LEVES:3)
Block(-6,0,-7,LEAVES:3)
Block(6,0,-7,LEVES:3)
Block(-4,0,-6,LEAVES:3)
Block(0,0,-6,LEAVES:3)
Block(1,0,-6,LOG:3)
Block(6,0,-6,LEVES:3)
Block(-2,0,-5,LOG:3)
Block(-1,0,-5,LEAVES:3)
Block(0,0,-5,LOG:3)
Block(1,0,-5,LOG:3)
Block(2,0,-5,LOG:3)
Block(-3,0,-4,LOG:3)
Block(-2,0,-4,LOG:3)
Block(-1,0,-4,LOG:3)
Block(2,0,-4,LOG:3)
Block(3,0,-4,LEAVES:3)
Block(-7,0,-3,LEAVES:3)
Block(-2,0,-3,LOG:3)
Block(2,0,-3,LOG:3)
Block(3,0,-3,LOG:3)
Block(7,0,-3,LEAVES:3)
Block(-8,0,-2,LEAVES:3)
Block(-7,0,-2,LEAVES:3)
Block(-4,0,-2,LEAVES:3)
Block(-3,0,-2,LOG:3)
Block(3,0,-2,LOG:3)
Block(7,0,-2,LEAVES:3)
Block(-7,0,-1,LEAVES:3)
Block(-4,0,-1,LEAVES:3)
Block(-3,0,-1,LOG:3)
Block(3,0,-1,LOG:3)
Block(-4,0,0,LOG:3)
Block(-3,0,0,LOG:3)
Block(-2,0,0,LOG:3)
Block(-1,0,0,LOG:3)
Block(2,0,0,LOG:3)
Block(3,0,0,LEAVES:3)
Block(-3,0,1,LOG:3)
Block(-2,0,1,LEAVES:3)
Block(-1,0,1,LOG:3)
Block(2,0,1,LOG:3)
Block(3,0,1,LOG:3)
Block(-1,0,2,LOG:3)
Block(0,0,2,LOG:3)
Block(1,0,2,LOG:3)
Block(2,0,2,LOG:3)
Block(0,0,3,LEAVES:3)
Block(1,0,3,LOG:3)
Block(2,0,3,LEAVES:3)
Block(6,0,4,LEAVES:3)
Block(-5,0,5,LEAVES:7)
Block(5,0,5,LEAVES:3)
Block(6,0,5,LEAVES:3)
Block(7,0,5,LEAVES:3)
Block(-6,0,6,LEVES:3)
Block(-5,0,6,LEVES:3)
Block(6,0,6,LEAVES:3)
Block(0,1,-9,LEVES:3)
Block(-6,1,-8,LEAVES:3)
Block(3,1,-8,LEVES:3)
Block(4,1,-8,LEVES:3)
Block(5,1,-8,LEVES:3)
Block(6,1,-8,LEVES:3)
Block(5,1,-7,WEB:0)
Block(6,1,-7,LEVES:3)
Block(-4,1,-6,LEAVES:3)
Block(0,1,-6,LEAVES:3)
Block(-1,1,-5,LEAVES:3)
Block(0,1,-5,LOG:3)
Block(1,1,-5,LOG:3)
Block(2,1,-5,LOG:3)
Block(-2,1,-4,LOG:3)
Block(-1,1,-4,LOG:3)
Block(2,1,-4,LOG:3)
Block(-2,1,-3,LOG:3)
Block(2,1,-3,LOG:3)
Block(-7,1,-2,LEAVES:3)
Block(-4,1,-2,LEAVES:3)
Block(-3,1,-2,LOG:3)
Block(2,1,-2,LOG:1)
Block(3,1,-2,LOG:1)
Block(4,1,-2,LEAVES:3)
Block(6,1,-2,WEB:0)
Block(7,1,-2,LEAVES:3)
Block(-7,1,-1,LEAVES:3)
Block(-3,1,-1,LOG:3)
Block(3,1,-1,LOG:3)
Block(-3,1,0,LOG:3)
Block(-2,1,0,LOG:3)
Block(-1,1,0,LOG:3)
Block(2,1,0,LOG:3)
Block(3,1,0,LEAVES:3)
Block(-1,1,1,LOG:3)
Block(2,1,1,LOG:3)
Block(3,1,1,LOG:3)
Block(0,1,2,LOG:3)
Block(1,1,2,LOG:3)
Block(2,1,2,LOG:3)
Block(3,1,2,LEAVES:3)
Block(6,1,5,LEAVES:3)
Block(-5,1,6,LEVES:3)
Block(-6,2,-8,LEAVES:3)
Block(-5,2,-8,LEAVES:3)
Block(4,2,-8,LEVES:3)
Block(5,2,-8,LEVES:3)
Block(-6,2,-7,LEAVES:3)
Block(-4,2,-7,LEAVES:3)
Block(5,2,-7,LEVES:3)
Block(-4,2,-6,LEAVES:3)
Block(-1,2,-5,LEAVES:3)
Block(0,2,-5,LOG:3)
Block(1,2,-5,LOG:3)
Block(-2,2,-4,LOG:3)
Block(-1,2,-4,LOG:3)
Block(2,2,-4,LOG:3)
Block(-7,2,-3,LEAVES:3)
Block(-2,2,-3,LOG:3)
Block(2,2,-3,LOG:3)
Block(-7,2,-2,LEAVES:3)
Block(-6,2,-2,LEAVES:3)
Block(-3,2,-2,LOG:3)
Block(3,2,-2,LOG:3)
Block(4,2,-2,LEAVES:3)
Block(5,2,-2,LEAVES:3)
Block(6,2,-2,LEAVES:3)
Block(7,2,-2,LEAVES:3)
Block(-7,2,-1,LEAVES:3)
Block(-3,2,-1,LOG:3)
Block(3,2,-1,LOG:3)
Block(-2,2,0,LOG:3)
Block(-1,2,0,LOG:3)
Block(2,2,0,LOG:3)
Block(3,2,0,LEAVES:3)
Block(-1,2,1,LOG:3)
Block(2,2,1,LOG:3)
Block(3,2,1,LEAVES:3)
Block(0,2,2,LOG:3)
Block(1,2,2,LOG:3)
Block(2,2,2,LOG:3)
Block(6,2,4,LEAVES:3)
Block(-5,2,5,LEAVES:7)
Block(5,2,5,LEAVES:3)
Block(6,2,5,LEAVES:3)
Block(7,2,5,LEAVES:3)
Block(-5,2,6,LEVES:3)
Block(-4,2,6,LEVES:3)
Block(6,2,6,LEAVES:3)
Block(5,3,-8,LEVES:3)
Block(-2,3,-5,LEAVES:3)
Block(0,3,-5,LOG:3)
Block(1,3,-5,LOG:3)
Block(-2,3,-4,LOG:3)
Block(-1,3,-4,LOG:3)
Block(2,3,-4,LOG:3)
Block(-2,3,-3,LOG:3)
Block(2,3,-3,LOG:3)
Block(-3,3,-2,LOG:3)
Block(3,3,-2,LOG:3)
Block(-3,3,-1,LOG:3)
Block(3,3,-1,LOG:3)
Block(4,3,-1,LEAVES:3)
Block(-2,3,0,LOG:3)
Block(-1,3,0,LOG:3)
Block(2,3,0,LOG:3)
Block(-1,3,1,LOG:3)
Block(0,3,1,LOG:3)
Block(2,3,1,LOG:3)
Block(3,3,1,LEAVES:3)
Block(0,3,2,LOG:3)
Block(1,3,2,LOG:3)
Block(6,3,5,LEAVES:3)
Block(0,4,-5,LOG:3)
Block(1,4,-5,LOG:3)
Block(-2,4,-4,LEAVES:3)
Block(-1,4,-4,LOG:3)
Block(2,4,-4,LOG:3)
Block(-2,4,-3,LOG:3)
Block(2,4,-3,LOG:3)
Block(3,4,-3,LEAVES:3)
Block(-3,4,-2,LOG:3)
Block(-2,4,-2,LOG:3)
Block(3,4,-2,LOG:3)
Block(4,4,-2,LEAVES:3)
Block(-3,4,-1,LOG:3)
Block(-2,4,-1,LOG:3)
Block(3,4,-1,LOG:3)
Block(-2,4,0,LOG:3)
Block(-1,4,0,LOG:3)
Block(2,4,0,LOG:3)
Block(-1,4,1,LOG:3)
Block(0,4,1,LOG:3)
Block(2,4,1,LOG:3)
Block(0,4,2,LOG:3)
Block(1,4,2,LOG:3)
Block(0,5,-5,LOG:3)
Block(1,5,-5,LOG:3)
Block(-2,5,-4,LEAVES:3)
Block(-1,5,-4,LOG:3)
Block(2,5,-4,LOG:3)
Block(-3,5,-3,LEAVES:3)
Block(-2,5,-3,LOG:3)
Block(1,5,-3,LOG:3)
Block(2,5,-3,LOG:3)
Block(3,5,-3,LEAVES:3)
Block(-3,5,-2,LOG:3)
Block(1,5,-2,LOG:3)
Block(2,5,-2,LOG:3)
Block(3,5,-2,LOG:3)
Block(4,5,-2,LEAVES:3)
Block(-2,5,-1,LOG:3)
Block(3,5,-1,LOG:3)
Block(-2,5,0,LOG:3)
Block(-1,5,0,LOG:3)
Block(1,5,0,LOG:3)
Block(2,5,0,LOG:3)
Block(3,5,0,LOG:3)
Block(0,5,1,LOG:3)
Block(2,5,1,LOG:3)
Block(0,5,2,LOG:3)
Block(1,5,2,LOG:3)
Block(0,6,-5,LOG:3)
Block(1,6,-5,LOG:3)
Block(-2,6,-4,LEAVES:3)
Block(-1,6,-4,LOG:3)
Block(2,6,-4,LOG:3)
Block(3,6,-4,LEAVES:3)
Block(-3,6,-3,LEAVES:3)
Block(-2,6,-3,LOG:3)
Block(0,6,-3,DIRT:0)
Block(1,6,-3,LOG:3)
Block(2,6,-3,LOG:3)
Block(3,6,-3,LEAVES:3)
Block(-3,6,-2,LOG:3)
Block(-2,6,-2,LOG:3)
Block(0,6,-2,LOG:3)
Block(2,6,-2,LOG:3)
Block(3,6,-2,LOG:3)
Block(-2,6,-1,LOG:3)
Block(3,6,-1,LOG:3)
Block(-2,6,0,LOG:3)
Block(-1,6,0,LOG:3)
Block(1,6,0,LOG:3)
Block(3,6,0,LOG:3)
Block(0,6,1,LOG:3)
Block(2,6,1,LOG:3)
Block(0,6,2,LOG:3)
Block(1,6,2,LOG:3)
Block(0,7,-5,LOG:3)
Block(1,7,-5,LOG:3)
Block(2,7,-5,LEAVES:3)
Block(3,7,-5,LEAVES:4)
Block(-2,7,-4,LOG:3)
Block(-1,7,-4,LOG:3)
Block(1,7,-4,LOG:3)
Block(2,7,-4,LOG:3)
Block(3,7,-4,LEAVES:3)
Block(-2,7,-3,LOG:3)
Block(-1,7,-3,LOG:3)
Block(2,7,-3,LOG:3)
Block(-3,7,-2,LEAVES:3)
Block(-2,7,-2,LOG:3)
Block(3,7,-2,LOG:3)
Block(-2,7,-1,LOG:3)
Block(-1,7,-1,LOG:3)
Block(3,7,-1,LOG:3)
Block(-2,7,0,LOG:3)
Block(-1,7,0,LOG:3)
Block(3,7,0,LOG:3)
Block(0,7,1,LOG:3)
Block(1,7,1,LOG:3)
Block(2,7,1,LOG:3)
Block(0,7,2,LOG:3)
Block(1,7,2,LOG:3)
Block(-1,8,-5,LEAVES:3)
Block(0,8,-5,LOG:3)
Block(1,8,-5,LOG:3)
Block(2,8,-5,LEAVES:3)
Block(3,8,-5,LEAVES:3)
Block(-2,8,-4,LOG:3)
Block(-1,8,-4,LOG:3)
Block(2,8,-4,LOG:3)
Block(3,8,-4,LEAVES:3)
Block(-2,8,-3,LOG:3)
Block(2,8,-3,LOG:3)
Block(-2,8,-2,LOG:3)
Block(3,8,-2,LOG:3)
Block(-3,8,-1,LEAVES:3)
Block(-2,8,-1,LOG:3)
Block(3,8,-1,LOG:3)
Block(-2,8,0,LOG:3)
Block(-1,8,0,LOG:3)
Block(3,8,0,LOG:3)
Block(0,8,1,LOG:3)
Block(2,8,1,LOG:3)
Block(0,8,2,LOG:3)
Block(1,8,2,LOG:3)
Block(0,9,-6,LEAVES:4)
Block(-1,9,-5,LEAVES:3)
Block(0,9,-5,LOG:3)
Block(1,9,-5,LEAVES:3)
Block(-1,9,-4,LOG:3)
Block(0,9,-4,LOG:3)
Block(1,9,-4,LEAVES:3)
Block(2,9,-4,LOG:3)
Block(-2,9,-3,LOG:3)
Block(-1,9,-3,LEAVES:3)
Block(0,9,-3,LOG:3)
Block(1,9,-3,LOG:3)
Block(2,9,-3,LOG:3)
Block(-2,9,-2,LOG:3)
Block(-1,9,-2,LOG:3)
Block(0,9,-2,LOG:3)
Block(2,9,-2,LOG:3)
Block(-2,9,-1,LEAVES:3)
Block(-1,9,-1,LOG:3)
Block(0,9,-1,LOG:3)
Block(1,9,-1,LOG:3)
Block(2,9,-1,LOG:3)
Block(-2,9,0,LOG:3)
Block(-1,9,0,LOG:3)
Block(0,9,0,LOG:3)
Block(1,9,0,LOG:3)
Block(2,9,0,LOG:3)
Block(3,9,0,LOG:3)
Block(-1,9,1,LEAVES:3)
Block(0,9,1,LOG:3)
Block(1,9,1,LOG:3)
Block(2,9,1,LOG:3)
Block(-1,9,2,LEAVES:3)
Block(0,9,2,LOG:3)
Block(0,10,-5,LEAVES:3)
Block(-1,10,-4,LEAVES:3)
Block(0,10,-4,LOG:3)
Block(1,10,-4,LEAVES:3)
Block(-1,10,-3,LEAVES:3)
Block(0,10,-3,LOG:3)
Block(1,10,-3,LOG:3)
Block(2,10,-3,LOG:3)
Block(-2,10,-2,LOG:3)
Block(-1,10,-2,LOG:3)
Block(0,10,-2,LOG:3)
Block(2,10,-2,LOG:3)
Block(-1,10,-1,LOG:3)
Block(0,10,-1,LOG:3)
Block(1,10,-1,LOG:3)
Block(-1,10,0,LOG:3)
Block(0,10,0,LOG:3)
Block(1,10,0,LOG:3)
Block(2,10,0,LOG:3)
Block(-1,10,1,LEAVES:3)
Block(0,10,1,LOG:3)
Block(0,11,-4,LOG:3)
Block(1,11,-4,LEAVES:3)
Block(-1,11,-3,LEAVES:3)
Block(0,11,-3,LOG:3)
Block(1,11,-3,LOG:3)
Block(2,11,-3,LOG:3)
Block(-2,11,-2,LOG:3)
Block(-1,11,-2,LOG:3)
Block(0,11,-2,LOG:3)
Block(2,11,-2,LOG:3)
Block(-1,11,-1,LOG:3)
Block(0,11,-1,LOG:3)
Block(1,11,-1,LOG:3)
Block(-1,11,0,LOG:3)
Block(0,11,0,LOG:3)
Block(1,11,0,LOG:3)
Block(0,11,1,LEAVES:3)
Block(1,11,1,LEAVES:3)
Block(-2,11,2,LEAVES:3)
Block(0,12,-4,LOG:3)
Block(-2,12,-3,LEAVES:3)
Block(0,12,-3,LOG:3)
Block(1,12,-3,LOG:3)
Block(2,12,-3,LOG:3)
Block(-2,12,-2,LOG:3)
Block(-1,12,-2,LOG:3)
Block(0,12,-2,LOG:3)
Block(2,12,-2,LOG:3)
Block(-1,12,-1,LOG:3)
Block(0,12,-1,LOG:3)
Block(1,12,-1,LOG:3)
Block(-2,12,0,LEAVES:3)
Block(-1,12,0,LEAVES:3)
Block(0,12,0,LOG:3)
Block(1,12,0,LOG:3)
Block(-2,12,1,LEAVES:3)
Block(-1,12,1,LEAVES:3)
Block(0,12,1,LEAVES:3)
Block(1,12,1,LEAVES:3)
Block(-2,12,2,LEAVES:3)
Block(-1,12,2,LEAVES:3)
Block(-1,13,-3,LEAVES:3)
Block(0,13,-3,LOG:3)
Block(1,13,-3,LOG:3)
Block(-1,13,-2,LOG:3)
Block(0,13,-2,LOG:3)
Block(2,13,-2,LOG:3)
Block(-2,13,-1,LEAVES:3)
Block(-1,13,-1,LOG:3)
Block(0,13,-1,LOG:3)
Block(1,13,-1,LOG:3)
Block(-1,13,0,LEAVES:3)
Block(0,13,0,LOG:3)
Block(1,13,0,LOG:3)
Block(2,13,0,LEAVES:3)
Block(0,13,1,LEAVES:3)
Block(1,13,1,LEAVES:3)
Block(-1,14,-3,LEAVES:3)
Block(0,14,-3,LOG:3)
Block(1,14,-3,LOG:3)
Block(-1,14,-2,LOG:3)
Block(0,14,-2,LOG:3)
Block(2,14,-2,LOG:3)
Block(-1,14,-1,LOG:3)
Block(0,14,-1,LOG:3)
Block(1,14,-1,LOG:3)
Block(2,14,-1,LEAVES:3)
Block(3,14,-1,LEAVES:3)
Block(0,14,0,LOG:3)
Block(1,14,0,LOG:3)
Block(2,14,0,LEAVES:3)
Block(3,14,0,LEAVES:3)
Block(0,15,-4,LEAVES:3)
Block(1,15,-4,LEAVES:3)
Block(0,15,-3,LOG:3)
Block(1,15,-3,LOG:3)
Block(2,15,-3,LEAVES:3)
Block(-1,15,-2,LOG:3)
Block(0,15,-2,LOG:3)
Block(2,15,-2,LOG:3)
Block(3,15,-2,LEAVES:3)
Block(-1,15,-1,LOG:3)
Block(0,15,-1,LOG:3)
Block(1,15,-1,LOG:3)
Block(0,15,0,LOG:3)
Block(1,15,0,LOG:3)
Block(0,16,-5,LEAVES:3)
Block(-1,16,-4,LEAVES:3)
Block(0,16,-4,LEAVES:3)
Block(1,16,-4,LEAVES:3)
Block(-1,16,-3,LEAVES:4)
Block(0,16,-3,LOG:3)
Block(1,16,-3,LOG:3)
Block(-1,16,-2,LOG:3)
Block(0,16,-2,LOG:3)
Block(2,16,-2,LOG:3)
Block(3,16,-2,LEAVES:3)
Block(-1,16,-1,LOG:3)
Block(0,16,-1,LOG:3)
Block(1,16,-1,LOG:3)
Block(0,16,0,LOG:3)
Block(1,16,0,LOG:3)
Block(1,17,-5,LEAVES:4)
Block(0,17,-4,LEAVES:3)
Block(1,17,-4,LEAVES:3)
Block(0,17,-3,LOG:3)
Block(1,17,-3,LOG:3)
Block(-1,17,-2,LOG:3)
Block(0,17,-2,LOG:3)
Block(2,17,-2,LOG:3)
Block(-1,17,-1,LOG:3)
Block(0,17,-1,LOG:3)
Block(1,17,-1,LOG:3)
Block(0,17,0,LOG:3)
Block(1,17,0,LOG:3)
Block(-1,18,-3,LEAVES:3)
Block(0,18,-3,LOG:3)
Block(1,18,-3,LOG:3)
Block(-1,18,-2,LOG:3)
Block(0,18,-2,LOG:3)
Block(2,18,-2,LOG:3)
Block(-1,18,-1,LOG:3)
Block(0,18,-1,LOG:3)
Block(1,18,-1,LOG:3)
Block(0,18,0,LOG:3)
Block(1,18,0,LOG:3)
Block(-1,19,-3,LEAVES:3)
Block(0,19,-3,LOG:3)
Block(1,19,-3,LOG:3)
Block(-1,19,-2,LOG:3)
Block(0,19,-2,LOG:3)
Block(2,19,-2,LOG:3)
Block(-1,19,-1,LOG:3)
Block(0,19,-1,LOG:3)
Block(1,19,-1,LOG:3)
Block(0,19,0,LOG:3)
Block(1,19,0,LOG:3)
Block(-2,20,-3,LEAVES:3)
Block(-1,20,-3,LEAVES:3)
Block(0,20,-3,LOG:3)
Block(1,20,-3,LOG:3)
Block(-1,20,-2,LOG:3)
Block(0,20,-2,LOG:3)
Block(2,20,-2,LOG:3)
Block(-1,20,-1,LOG:3)
Block(0,20,-1,LOG:3)
Block(1,20,-1,LOG:3)
Block(0,20,0,LOG:3)
Block(1,20,0,LOG:3)
Block(-2,20,2,LEAVES:3)
Block(0,21,-4,LEAVES:3)
Block(0,21,-3,LOG:3)
Block(1,21,-3,LOG:3)
Block(-2,21,-2,LEAVES:3)
Block(-1,21,-2,LOG:3)
Block(0,21,-2,LOG:3)
Block(2,21,-2,LOG:3)
Block(-1,21,-1,LOG:3)
Block(0,21,-1,LOG:3)
Block(1,21,-1,LOG:3)
Block(0,21,0,LOG:3)
Block(1,21,0,LOG:3)
Block(-2,21,2,LEAVES:3)
Block(1,22,-4,LEAVES:3)
Block(0,22,-3,LOG:3)
Block(1,22,-3,LOG:3)
Block(-1,22,-2,LOG:3)
Block(0,22,-2,LOG:3)
Block(2,22,-2,LOG:3)
Block(-2,22,-1,LEAVES:3)
Block(-1,22,-1,LOG:3)
Block(0,22,-1,LOG:3)
Block(1,22,-1,LOG:3)
Block(0,22,0,LOG:3)
Block(1,22,0,LOG:3)
Block(-2,22,2,LEAVES:3)
Block(6,23,-6,LEAVES:3)
Block(0,23,-3,LOG:3)
Block(1,23,-3,LOG:3)
Block(2,23,-3,LEAVES:3)
Block(-1,23,-2,LOG:3)
Block(0,23,-2,LOG:3)
Block(2,23,-2,LOG:3)
Block(-1,23,-1,LOG:3)
Block(0,23,-1,LOG:3)
Block(1,23,-1,LOG:3)
Block(-1,23,0,LEAVES:3)
Block(0,23,0,LOG:3)
Block(1,23,0,LOG:3)
Block(-1,23,1,LEAVES:3)
Block(-2,23,2,LEAVES:3)
Block(-1,23,2,LEAVES:3)
Block(6,24,-6,LEAVES:3)
Block(0,24,-3,LOG:3)
Block(1,24,-3,LOG:3)
Block(-1,24,-2,LOG:3)
Block(0,24,-2,LOG:3)
Block(2,24,-2,LOG:3)
Block(3,24,-2,LEAVES:3)
Block(-2,24,-1,LEAVES:3)
Block(-1,24,-1,LOG:3)
Block(0,24,-1,LOG:3)
Block(1,24,-1,LOG:3)
Block(-1,24,0,LOG:3)
Block(0,24,0,LOG:3)
Block(1,24,0,LOG:3)
Block(-3,24,1,LEAVES:3)
Block(-2,24,1,LEAVES:3)
Block(-1,24,1,LOG:3)
Block(0,24,1,LEAVES:3)
Block(1,24,1,LEAVES:3)
Block(-4,24,2,LEAVES:3)
Block(-3,24,2,LEAVES:3)
Block(-2,24,2,LOG:3)
Block(-1,24,2,LEAVES:3)
Block(-3,24,3,LEAVES:4)
Block(-2,24,3,LEAVES:3)
Block(-1,24,3,LEAVES:3)
Block(6,25,-6,LEAVES:3)
Block(0,25,-3,LOG:3)
Block(1,25,-3,LOG:3)
Block(-1,25,-2,LOG:3)
Block(0,25,-2,LOG:3)
Block(2,25,-2,LOG:3)
Block(-2,25,-1,LEAVES:3)
Block(-1,25,-1,LOG:3)
Block(0,25,-1,LOG:3)
Block(1,25,-1,LOG:3)
Block(2,25,-1,LEAVES:3)
Block(-3,25,0,LEAVES:4)
Block(-1,25,0,LEAVES:3)
Block(0,25,0,LOG:3)
Block(1,25,0,LOG:3)
Block(-4,25,1,LEAVES:3)
Block(-3,25,1,LEAVES:3)
Block(-1,25,1,LEAVES:4)
Block(1,25,1,LEAVES:3)
Block(-5,25,2,LEAVES:3)
Block(-4,25,2,LEAVES:3)
Block(-3,25,2,LOG:3)
Block(-2,25,2,LEAVES:3)
Block(-4,25,3,LEAVES:3)
Block(-3,25,3,LEAVES:3)
Block(-2,25,3,LEAVES:3)
Block(-3,25,4,LEAVES:3)
Block(6,26,-6,LEAVES:3)
Block(0,26,-3,LOG:3)
Block(1,26,-3,LOG:3)
Block(-1,26,-2,LOG:3)
Block(0,26,-2,LOG:3)
Block(2,26,-2,LOG:3)
Block(-1,26,-1,LOG:3)
Block(0,26,-1,LOG:3)
Block(1,26,-1,LOG:3)
Block(2,26,-1,LEAVES:3)
Block(3,26,-1,LEAVES:3)
Block(4,26,-1,LEAVES:3)
Block(0,26,0,LOG:3)
Block(1,26,0,LOG:3)
Block(2,26,0,LEAVES:3)
Block(3,26,0,LEAVES:3)
Block(-4,26,1,LEAVES:3)
Block(0,26,1,LEAVES:3)
Block(3,26,1,LEAVES:3)
Block(-4,26,2,LEAVES:4)
Block(-3,26,2,LEAVES:3)
Block(-2,26,2,LEAVES:3)
Block(-3,26,3,LEAVES:3)
Block(6,27,-6,LEAVES:3)
Block(3,27,-4,LEAVES:3)
Block(0,27,-3,LOG:3)
Block(1,27,-3,LOG:3)
Block(3,27,-3,LEAVES:3)
Block(-1,27,-2,LOG:3)
Block(0,27,-2,LOG:3)
Block(2,27,-2,LOG:3)
Block(-1,27,-1,LOG:3)
Block(0,27,-1,LOG:3)
Block(1,27,-1,LOG:3)
Block(2,27,-1,LEAVES:3)
Block(3,27,-1,LEAVES:3)
Block(0,27,0,LOG:3)
Block(1,27,0,LOG:3)
Block(2,27,0,LEAVES:3)
Block(3,27,0,LEAVES:3)
Block(0,27,1,LEAVES:3)
Block(6,28,-7,LEAVES:3)
Block(7,28,-7,LEAVES:3)
Block(5,28,-6,LEAVES:3)
Block(6,28,-6,LEAVES:3)
Block(7,28,-6,LEAVES:3)
Block(3,28,-5,LEAVES:4)
Block(4,28,-5,LEAVES:3)
Block(5,28,-5,LEAVES:3)
Block(6,28,-5,LEAVES:3)
Block(7,28,-5,LEAVES:3)
Block(2,28,-4,LEAVES:3)
Block(3,28,-4,LOG:3)
Block(4,28,-4,LEAVES:3)
Block(5,28,-4,LEAVES:4)
Block(0,28,-3,LOG:3)
Block(1,28,-3,LOG:3)
Block(2,28,-3,LOG:3)
Block(3,28,-3,LOG:3)
Block(4,28,-3,LEAVES:3)
Block(-1,28,-2,LOG:3)
Block(2,28,-2,LOG:3)
Block(3,28,-2,LEAVES:3)
Block(-1,28,-1,LOG:3)
Block(0,28,-1,LOG:3)
Block(1,28,-1,LOG:3)
Block(0,28,0,LOG:3)
Block(1,28,0,LOG:3)
Block(2,28,0,LEAVES:3)
Block(1,28,1,LEAVES:3)
Block(6,29,-8,LEAVES:3)
Block(7,29,-8,LEAVES:3)
Block(5,29,-7,LEAVES:3)
Block(6,29,-7,LEAVES:3)
Block(7,29,-7,LEAVES:3)
Block(8,29,-7,LEAVES:3)
Block(4,29,-6,LEAVES:3)
Block(5,29,-6,LOG:3)
Block(6,29,-6,LEAVES:3)
Block(7,29,-6,LOG:3)
Block(8,29,-6,LEAVES:3)
Block(4,29,-5,LEAVES:3)
Block(5,29,-5,LOG:3)
Block(6,29,-5,LOG:3)
Block(7,29,-5,LEAVES:3)
Block(8,29,-5,LEAVES:3)
Block(3,29,-4,LEAVES:3)
Block(4,29,-4,LOG:3)
Block(5,29,-4,LEAVES:3)
Block(6,29,-4,LEAVES:3)
Block(7,29,-4,LEAVES:3)
Block(0,29,-3,LOG:3)
Block(1,29,-3,LOG:3)
Block(2,29,-3,LEAVES:3)
Block(4,29,-3,LEAVES:3)
Block(-1,29,-2,LOG:3)
Block(2,29,-2,LOG:3)
Block(-1,29,-1,LOG:3)
Block(0,29,-1,LOG:3)
Block(1,29,-1,LOG:3)
Block(2,29,-1,LEAVES:3)
Block(0,29,0,LOG:3)
Block(1,29,0,LOG:3)
Block(2,29,0,LEAVES:3)
Block(6,30,-7,LEAVES:3)
Block(-4,30,-6,LEAVES:3)
Block(5,30,-6,LEAVES:3)
Block(6,30,-6,LEAVES:3)
Block(7,30,-6,LEAVES:3)
Block(5,30,-5,LEAVES:3)
Block(6,30,-5,LEAVES:3)
Block(7,30,-5,LEAVES:3)
Block(0,30,-4,LEAVES:3)
Block(1,30,-4,LEAVES:3)
Block(4,30,-4,LEAVES:3)
Block(0,30,-3,LOG:3)
Block(1,30,-3,LOG:3)
Block(0,30,-2,LOG:3)
Block(2,30,-2,LEAVES:3)
Block(-1,30,-1,LOG:3)
Block(0,30,-1,LOG:3)
Block(1,30,-1,LOG:3)
Block(0,30,0,LOG:3)
Block(1,30,0,LOG:3)
Block(1,30,2,LEAVES:3)
Block(2,31,-7,LEAVES:3)
Block(-4,31,-6,LEAVES:3)
Block(6,31,-6,LEAVES:3)
Block(5,31,-5,LEAVES:4)
Block(6,31,-5,LEAVES:3)
Block(-1,31,-4,LEAVES:3)
Block(0,31,-4,LEAVES:3)
Block(1,31,-4,LEAVES:3)
Block(-1,31,-3,LEAVES:3)
Block(0,31,-3,LOG:3)
Block(1,31,-3,LOG:3)
Block(0,31,-2,LOG:3)
Block(1,31,-2,LOG:3)
Block(0,31,-1,LOG:3)
Block(1,31,-1,LOG:3)
Block(5,31,-1,LEAVES:3)
Block(3,31,1,LEAVES:3)
Block(1,31,2,LEAVES:3)
Block(2,32,-7,LEAVES:3)
Block(-4,32,-6,LEAVES:3)
Block(5,32,-5,LEAVES:3)
Block(-1,32,-4,LEAVES:3)
Block(0,32,-3,LOG:3)
Block(-6,32,-2,LEAVES:4)
Block(-1,32,-2,LEAVES:3)
Block(0,32,-2,LOG:3)
Block(1,32,-2,LOG:3)
Block(0,32,-1,LOG:3)
Block(1,32,-1,LOG:3)
Block(5,32,-1,LEAVES:3)
Block(3,32,1,LEAVES:3)
Block(1,32,2,LEAVES:3)
Block(-3,32,3,LEAVES:3)
Block(6,32,3,LEAVES:3)
Block(2,33,-7,LEAVES:3)
Block(-4,33,-6,LEAVES:3)
Block(5,33,-5,LEAVES:3)
Block(-6,33,-2,LEAVES:3)
Block(0,33,-2,LOG:3)
Block(1,33,-2,LOG:3)
Block(-1,33,-1,LEAVES:3)
Block(0,33,-1,LOG:3)
Block(1,33,-1,LOG:3)
Block(5,33,-1,LEAVES:3)
Block(0,33,0,LOG:3)
Block(3,33,1,LEAVES:3)
Block(1,33,2,LEAVES:3)
Block(-3,33,3,LEAVES:3)
Block(6,33,3,LEAVES:3)
Block(2,34,-7,LEAVES:3)
Block(-4,34,-6,LEAVES:3)
Block(5,34,-5,LEAVES:3)
Block(-3,34,-4,LEAVES:4)
Block(-2,34,-4,LEAVES:3)
Block(0,34,-3,LOG:3)
Block(-6,34,-2,LEAVES:3)
Block(1,34,-2,LOG:3)
Block(0,34,-1,LEAVES:3)
Block(1,34,-1,LOG:3)
Block(5,34,-1,LEAVES:3)
Block(-2,34,0,LEAVES:3)
Block(0,34,0,LEAVES:3)
Block(2,34,0,LOG:3)
Block(-1,34,1,LOG:3)
Block(3,34,1,LEAVES:3)
Block(4,34,1,LEAVES:3)
Block(1,34,2,LEAVES:3)
Block(3,34,2,LEAVES:3)
Block(-3,34,3,LEAVES:3)
Block(6,34,3,LEAVES:3)
Block(4,35,-8,LEAVES:3)
Block(2,35,-7,LEAVES:3)
Block(3,35,-7,LEAVES:3)
Block(4,35,-7,LEAVES:3)
Block(5,35,-7,LEAVES:4)
Block(-4,35,-6,LEAVES:3)
Block(2,35,-6,LEAVES:3)
Block(3,35,-6,LEAVES:3)
Block(4,35,-6,LEAVES:3)
Block(5,35,-6,LEAVES:3)
Block(6,35,-6,LEAVES:3)
Block(-5,35,-5,LEAVES:3)
Block(-4,35,-5,LEAVES:3)
Block(-3,35,-5,LOG:3)
Block(-2,35,-5,LEAVES:3)
Block(-1,35,-5,LEAVES:3)
Block(1,35,-5,LEAVES:3)
Block(2,35,-5,LOG:3)
Block(3,35,-5,LEAVES:3)
Block(4,35,-5,LEAVES:3)
Block(5,35,-5,LEAVES:3)
Block(-5,35,-4,LEAVES:3)
Block(-4,35,-4,LEAVES:3)
Block(-3,35,-4,LEAVES:3)
Block(-2,35,-4,LOG:3)
Block(-1,35,-4,LOG:3)
Block(0,35,-4,LEAVES:4)
Block(1,35,-4,LEAVES:3)
Block(2,35,-4,LOG:3)
Block(3,35,-4,LEAVES:3)
Block(-3,35,-3,LEAVES:3)
Block(0,35,-3,LEAVES:3)
Block(2,35,-3,LOG:3)
Block(3,35,-3,LOG:3)
Block(-6,35,-2,LEAVES:3)
Block(0,35,-2,LEAVES:3)
Block(1,35,-2,LEAVES:3)
Block(0,35,-1,LEAVES:3)
Block(1,35,-1,LOG:3)
Block(5,35,-1,LEAVES:3)
Block(-2,35,0,LEAVES:3)
Block(1,35,0,LEAVES:3)
Block(2,35,0,LEAVES:3)
Block(3,35,0,LEAVES:3)
Block(5,35,0,LEAVES:3)
Block(6,35,0,LEAVES:3)
Block(-3,35,1,LEAVES:3)
Block(-2,35,1,LEAVES:3)
Block(-1,35,1,LEAVES:3)
Block(0,35,1,LEAVES:3)
Block(2,35,1,LEAVES:3)
Block(3,35,1,LOG:3)
Block(4,35,1,LOG:3)
Block(5,35,1,LEAVES:3)
Block(6,35,1,LEAVES:3)
Block(7,35,1,LEAVES:3)
Block(-4,35,2,LEAVES:3)
Block(-3,35,2,LEAVES:3)
Block(-2,35,2,LOG:3)
Block(-1,35,2,LEAVES:3)
Block(0,35,2,LEAVES:3)
Block(1,35,2,LOG:3)
Block(3,35,2,LEAVES:3)
Block(4,35,2,LEAVES:3)
Block(5,35,2,LEAVES:3)
Block(6,35,2,LEAVES:3)
Block(-6,35,3,LEAVES:3)
Block(-5,35,3,LEAVES:3)
Block(-4,35,3,LEAVES:3)
Block(-3,35,3,LOG:3)
Block(-2,35,3,LOG:3)
Block(-1,35,3,LEAVES:3)
Block(0,35,3,LEAVES:3)
Block(4,35,3,LEAVES:3)
Block(5,35,3,LOG:3)
Block(6,35,3,LEAVES:3)
Block(-6,35,4,LEAVES:4)
Block(-5,35,4,LEAVES:3)
Block(-4,35,4,LEAVES:3)
Block(-2,35,4,LEAVES:3)
Block(-1,35,4,LEAVES:3)
Block(0,35,4,LEAVES:3)
Block(-4,35,5,LEAVES:3)
Block(-3,35,5,LEAVES:3)
Block(-1,35,5,LEAVES:3)
Block(0,35,5,LEAVES:3)
Block(-3,35,6,LEAVES:3)
Block(-2,35,6,LEAVES:3)
Block(-1,35,6,LEAVES:3)
Block(-4,35,7,LEAVES:3)
Block(-2,35,7,LEAVES:3)
Block(3,36,-9,LEAVES:3)
Block(4,36,-9,LEAVES:3)
Block(2,36,-8,LEAVES:3)
Block(3,36,-8,LEAVES:3)
Block(4,36,-8,LEAVES:3)
Block(5,36,-8,LEAVES:3)
Block(-4,36,-7,LEAVES:3)
Block(-3,36,-7,LEAVES:3)
Block(1,36,-7,LEAVES:3)
Block(2,36,-7,LEAVES:3)
Block(3,36,-7,LEAVES:3)
Block(4,36,-7,LOG:3)
Block(5,36,-7,LEAVES:3)
Block(6,36,-7,LEAVES:3)
Block(-5,36,-6,LEAVES:3)
Block(-4,36,-6,LEAVES:3)
Block(-3,36,-6,LEAVES:3)
Block(-2,36,-6,LEAVES:3)
Block(1,36,-6,LEAVES:3)
Block(2,36,-6,LOG:3)
Block(3,36,-6,LEAVES:3)
Block(4,36,-6,LEAVES:3)
Block(5,36,-6,LEAVES:3)
Block(6,36,-6,LEAVES:3)
Block(-6,36,-5,LEAVES:3)
Block(-5,36,-5,LEAVES:3)
Block(-4,36,-5,LEAVES:3)
Block(-3,36,-5,LOG:3)
Block(-2,36,-5,LEAVES:3)
Block(2,36,-5,LEAVES:3)
Block(3,36,-5,LEAVES:3)
Block(4,36,-5,LEAVES:3)
Block(5,36,-5,LEAVES:3)
Block(6,36,-5,LEAVES:3)
Block(7,36,-5,LEAVES:3)
Block(-7,36,-4,LEAVES:3)
Block(-6,36,-4,LEAVES:3)
Block(-5,36,-4,LOG:3)
Block(-4,36,-4,LEAVES:3)
Block(-3,36,-4,LEAVES:3)
Block(-2,36,-4,LEAVES:3)
Block(-1,36,-4,LEAVES:3)
Block(2,36,-4,LEAVES:3)
Block(3,36,-4,LEAVES:3)
Block(4,36,-4,LEAVES:3)
Block(5,36,-4,LEAVES:3)
Block(6,36,-4,LEAVES:3)
Block(-6,36,-3,LEAVES:3)
Block(-5,36,-3,LEAVES:3)
Block(-4,36,-3,LEAVES:3)
Block(-3,36,-3,LEAVES:3)
Block(-2,36,-3,LEAVES:3)
Block(2,36,-3,LEAVES:3)
Block(4,36,-3,LOG:3)
Block(5,36,-3,LEAVES:3)
Block(-8,36,-2,LEAVES:3)
Block(-7,36,-2,LEAVES:3)
Block(-6,36,-2,LEAVES:3)
Block(-5,36,-2,LEAVES:3)
Block(-2,36,-2,LEAVES:3)
Block(-1,36,-2,LEAVES:3)
Block(1,36,-2,LEAVES:3)
Block(2,36,-2,LEAVES:3)
Block(4,36,-2,LEAVES:3)
Block(5,36,-2,LEAVES:3)
Block(-8,36,-1,LEAVES:4)
Block(-7,36,-1,LEAVES:3)
Block(-6,36,-1,LEAVES:3)
Block(0,36,-1,LEAVES:3)
Block(1,36,-1,LOG:3)
Block(4,36,-1,LEAVES:3)
Block(5,36,-1,LEAVES:3)
Block(6,36,-1,LEAVES:3)
Block(-7,36,0,LEAVES:3)
Block(-6,36,0,LEAVES:4)
Block(-4,36,0,LEAVES:3)
Block(-3,36,0,LEAVES:3)
Block(-2,36,0,LEAVES:3)
Block(-1,36,0,LEAVES:3)
Block(1,36,0,LEAVES:3)
Block(3,36,0,LEAVES:3)
Block(4,36,0,LEAVES:3)
Block(5,36,0,LEAVES:3)
Block(6,36,0,LEAVES:3)
Block(-5,36,1,LEAVES:3)
Block(-4,36,1,LEAVES:3)
Block(-3,36,1,LEAVES:3)
Block(-2,36,1,LEAVES:3)
Block(-1,36,1,LEAVES:3)
Block(3,36,1,LEAVES:3)
Block(4,36,1,LEAVES:3)
Block(5,36,1,LOG:3)
Block(6,36,1,LEAVES:3)
Block(7,36,1,LEAVES:3)
Block(-6,36,2,LEAVES:3)
Block(-5,36,2,LEAVES:3)
Block(-4,36,2,LEAVES:3)
Block(-3,36,2,LEAVES:3)
Block(-2,36,2,LEAVES:3)
Block(-1,36,2,LEAVES:3)
Block(0,36,2,LEAVES:3)
Block(2,36,2,LEAVES:3)
Block(3,36,2,LEAVES:3)
Block(4,36,2,LEAVES:3)
Block(5,36,2,LEAVES:3)
Block(6,36,2,LEAVES:3)
Block(7,36,2,LEAVES:3)
Block(-7,36,3,LEAVES:3)
Block(-6,36,3,LEAVES:3)
Block(-5,36,3,LEAVES:3)
Block(-4,36,3,LEAVES:3)
Block(-3,36,3,LOG:3)
Block(-2,36,3,LEAVES:3)
Block(-1,36,3,LEAVES:3)
Block(0,36,3,LEAVES:3)
Block(1,36,3,LEAVES:3)
Block(2,36,3,LEAVES:3)
Block(3,36,3,LEAVES:3)
Block(4,36,3,LEAVES:3)
Block(5,36,3,LEAVES:3)
Block(6,36,3,LEAVES:3)
Block(-8,36,4,LEAVES:3)
Block(-7,36,4,LEAVES:3)
Block(-6,36,4,LEAVES:3)
Block(-5,36,4,LEAVES:3)
Block(-4,36,4,LEAVES:3)
Block(-3,36,4,LEAVES:3)
Block(-2,36,4,LEAVES:3)
Block(-1,36,4,LEAVES:3)
Block(0,36,4,LEAVES:3)
Block(1,36,4,LEAVES:3)
Block(2,36,4,LEAVES:3)
Block(4,36,4,LEAVES:3)
Block(-6,36,5,LEAVES:3)
Block(-5,36,5,LEAVES:3)
Block(-4,36,5,LOG:3)
Block(-3,36,5,LEAVES:3)
Block(-2,36,5,LOG:3)
Block(-1,36,5,LEAVES:3)
Block(0,36,5,LEAVES:3)
Block(1,36,5,LEAVES:3)
Block(-5,36,6,LEAVES:3)
Block(-4,36,6,LEAVES:3)
Block(-3,36,6,LEAVES:3)
Block(-2,36,6,LEAVES:3)
Block(-1,36,6,LEAVES:3)
Block(0,36,6,LEAVES:3)
Block(1,36,6,LEAVES:3)
Block(-4,36,7,LEAVES:3)
Block(-3,36,7,LEAVES:3)
Block(-2,36,7,LOG:3)
Block(-1,36,7,LEAVES:3)
Block(0,36,7,LEAVES:3)
Block(-3,36,8,LEAVES:3)
Block(-2,36,8,LEAVES:3)
Block(-1,36,8,LEAVES:3)
Block(4,37,-9,LEAVES:3)
Block(5,37,-9,LEAVES:3)
Block(-5,37,-8,LEAVES:3)
Block(-4,37,-8,LEAVES:3)
Block(-3,37,-8,LEAVES:3)
Block(1,37,-8,LEAVES:3)
Block(2,37,-8,LEAVES:3)
Block(3,37,-8,LEAVES:3)
Block(4,37,-8,LEAVES:3)
Block(5,37,-8,LOG:3)
Block(6,37,-8,LEAVES:3)
Block(-6,37,-7,LEAVES:3)
Block(-5,37,-7,LOG:3)
Block(-4,37,-7,LEAVES:3)
Block(-3,37,-7,LEAVES:3)
Block(-2,37,-7,LEAVES:3)
Block(0,37,-7,LEAVES:3)
Block(1,37,-7,LOG:3)
Block(2,37,-7,LEAVES:3)
Block(3,37,-7,LEAVES:3)
Block(4,37,-7,LEAVES:3)
Block(5,37,-7,LEAVES:3)
Block(6,37,-7,LEAVES:3)
Block(7,37,-7,LEAVES:3)
Block(-7,37,-6,LEAVES:3)
Block(-6,37,-6,LEAVES:3)
Block(-5,37,-6,LEAVES:3)
Block(-4,37,-6,LEAVES:3)
Block(-3,37,-6,LEAVES:3)
Block(-2,37,-6,LOG:3)
Block(-1,37,-6,LEAVES:3)
Block(0,37,-6,LEAVES:3)
Block(1,37,-6,LEAVES:3)
Block(2,37,-6,LEAVES:3)
Block(3,37,-6,LEAVES:3)
Block(4,37,-6,LEAVES:3)
Block(5,37,-6,LEAVES:3)
Block(6,37,-6,LEAVES:3)
Block(7,37,-6,LEAVES:3)
Block(8,37,-6,LEAVES:3)
Block(-7,37,-5,LEAVES:3)
Block(-6,37,-5,LOG:3)
Block(-5,37,-5,LOG:3)
Block(-4,37,-5,LEAVES:3)
Block(-3,37,-5,LEAVES:3)
Block(-2,37,-5,LEAVES:3)
Block(-1,37,-5,LEAVES:3)
Block(2,37,-5,LEAVES:3)
Block(3,37,-5,LEAVES:3)
Block(4,37,-5,LEAVES:3)
Block(5,37,-5,LEAVES:3)
Block(6,37,-5,LEAVES:3)
Block(7,37,-5,LOG:3)
Block(8,37,-5,LEAVES:3)
Block(-8,37,-4,LEAVES:3)
Block(-7,37,-4,LEAVES:3)
Block(-6,37,-4,LEAVES:3)
Block(-5,37,-4,LEAVES:3)
Block(-4,37,-4,LEAVES:3)
Block(-3,37,-4,LEAVES:3)
Block(-2,37,-4,LEAVES:3)
Block(-1,37,-4,LEAVES:3)
Block(2,37,-4,LEAVES:3)
Block(3,37,-4,LEAVES:3)
Block(4,37,-4,LEAVES:3)
Block(5,37,-4,LEAVES:3)
Block(6,37,-4,LEAVES:3)
Block(7,37,-4,LEAVES:3)
Block(8,37,-4,LEAVES:3)
Block(-8,37,-3,LEAVES:3)
Block(-7,37,-3,LEAVES:3)
Block(-6,37,-3,LEAVES:3)
Block(-5,37,-3,LEAVES:3)
Block(-4,37,-3,LEAVES:3)
Block(-3,37,-3,LEAVES:3)
Block(-2,37,-3,LEAVES:3)
Block(-1,37,-3,LEAVES:3)
Block(2,37,-3,LEAVES:3)
Block(4,37,-3,LEAVES:3)
Block(5,37,-3,LEAVES:3)
Block(6,37,-3,LEAVES:3)
Block(-9,37,-2,LEAVES:3)
Block(-8,37,-2,LEAVES:3)
Block(-7,37,-2,LEAVES:3)
Block(-6,37,-2,LEAVES:3)
Block(-5,37,-2,LEAVES:3)
Block(-4,37,-2,LEAVES:3)
Block(-3,37,-2,LEAVES:3)
Block(-2,37,-2,LEAVES:3)
Block(-1,37,-2,LEAVES:3)
Block(1,37,-2,LEAVES:3)
Block(-9,37,-1,LEAVES:3)
Block(-8,37,-1,LEAVES:3)
Block(-7,37,-1,LOG:3)
Block(-6,37,-1,LEAVES:3)
Block(-5,37,-1,LEAVES:3)
Block(-4,37,-1,LEAVES:3)
Block(-3,37,-1,LEAVES:3)
Block(-2,37,-1,LEAVES:3)
Block(-1,37,-1,LEAVES:3)
Block(0,37,-1,LEAVES:3)
Block(1,37,-1,LOG:3)
Block(2,37,-1,LEAVES:3)
Block(5,37,-1,LEAVES:3)
Block(-8,37,0,LEAVES:3)
Block(-7,37,0,LEAVES:3)
Block(-6,37,0,LEAVES:3)
Block(-5,37,0,LEAVES:3)
Block(-2,37,0,LOG:3)
Block(1,37,0,LEAVES:3)
Block(3,37,0,LEAVES:3)
Block(4,37,0,LEAVES:3)
Block(5,37,0,LEAVES:3)
Block(6,37,0,LEAVES:3)
Block(7,37,0,LEAVES:3)
Block(-8,37,1,LEAVES:3)
Block(-7,37,1,LEAVES:3)
Block(-6,37,1,LEAVES:3)
Block(-2,37,1,LEAVES:3)
Block(2,37,1,LEAVES:3)
Block(3,37,1,LEAVES:3)
Block(4,37,1,LEAVES:3)
Block(5,37,1,LEAVES:3)
Block(6,37,1,LEAVES:3)
Block(7,37,1,LOG:3)
Block(8,37,1,LEAVES:3)
Block(-9,37,2,LEAVES:3)
Block(-8,37,2,LEAVES:3)
Block(-7,37,2,LEAVES:3)
Block(-6,37,2,LEAVES:3)
Block(-5,37,2,LEAVES:3)
Block(-3,37,2,LEAVES:3)
Block(-2,37,2,LEAVES:3)
Block(-1,37,2,LEAVES:3)
Block(0,37,2,LEAVES:3)
Block(3,37,2,LEAVES:3)
Block(4,37,2,LOG:3)
Block(5,37,2,LEAVES:3)
Block(6,37,2,LEAVES:3)
Block(7,37,2,LEAVES:3)
Block(8,37,2,LEAVES:3)
Block(-9,37,3,LEAVES:3)
Block(-8,37,3,LEAVES:3)
Block(-7,37,3,LEAVES:3)
Block(-6,37,3,LEAVES:3)
Block(-5,37,3,LEAVES:3)
Block(-4,37,3,LOG:3)
Block(-3,37,3,LEAVES:3)
Block(-2,37,3,LEAVES:3)
Block(-1,37,3,LEAVES:3)
Block(0,37,3,LEAVES:3)
Block(1,37,3,LEAVES:3)
Block(2,37,3,LEAVES:3)
Block(4,37,3,LEAVES:3)
Block(5,37,3,LEAVES:3)
Block(6,37,3,LEAVES:3)
Block(7,37,3,LEAVES:3)
Block(-9,37,4,LEAVES:3)
Block(-8,37,4,LEAVES:3)
Block(-7,37,4,LOG:3)
Block(-6,37,4,LEAVES:3)
Block(-5,37,4,LEAVES:3)
Block(-4,37,4,LEAVES:3)
Block(-3,37,4,LEAVES:3)
Block(-2,37,4,LEAVES:3)
Block(-1,37,4,LEAVES:3)
Block(0,37,4,LEAVES:3)
Block(1,37,4,LOG:3)
Block(2,37,4,LEAVES:3)
Block(4,37,4,LEAVES:3)
Block(5,37,4,LOG:3)
Block(6,37,4,LEAVES:3)
Block(-8,37,5,LEAVES:3)
Block(-7,37,5,LEAVES:3)
Block(-6,37,5,LEAVES:3)
Block(-4,37,5,LEAVES:3)
Block(-3,37,5,LEAVES:3)
Block(-2,37,5,LEAVES:3)
Block(-1,37,5,LEAVES:3)
Block(0,37,5,LEAVES:3)
Block(1,37,5,LEAVES:3)
Block(2,37,5,LEAVES:3)
Block(4,37,5,LEAVES:3)
Block(5,37,5,LEAVES:3)
Block(-7,37,6,LEAVES:3)
Block(-6,37,6,LEAVES:3)
Block(-4,37,6,LEAVES:3)
Block(-3,37,6,LOG:3)
Block(-2,37,6,LEAVES:3)
Block(-1,37,6,LEAVES:3)
Block(0,37,6,LOG:3)
Block(1,37,6,LEAVES:3)
Block(2,37,6,LEAVES:3)
Block(-3,37,7,LEAVES:3)
Block(-2,37,7,LEAVES:3)
Block(-1,37,7,LEAVES:3)
Block(0,37,7,LEAVES:3)
Block(1,37,7,LEAVES:3)
Block(-3,37,8,LEAVES:3)
Block(-2,37,8,LOG:3)
Block(-1,37,8,LEAVES:3)
Block(0,37,8,LEAVES:3)
Block(4,38,-8,LEAVES:3)
Block(5,38,-8,LEAVES:3)
Block(-5,38,-7,LEAVES:3)
Block(-4,38,-7,LEAVES:3)
Block(-3,38,-7,LEAVES:3)
Block(1,38,-7,LEAVES:3)
Block(3,38,-7,LEAVES:3)
Block(4,38,-7,LEAVES:3)
Block(5,38,-7,LEAVES:3)
Block(6,38,-7,LEAVES:3)
Block(-6,38,-6,LEAVES:3)
Block(-5,38,-6,LEAVES:3)
Block(-4,38,-6,LEAVES:3)
Block(-3,38,-6,LEAVES:3)
Block(-2,38,-6,LEAVES:3)
Block(2,38,-6,LEAVES:3)
Block(3,38,-6,LEAVES:3)
Block(4,38,-6,LEAVES:3)
Block(5,38,-6,LEAVES:3)
Block(6,38,-6,LEAVES:3)
Block(7,38,-6,LEAVES:3)
Block(-7,38,-5,LEAVES:3)
Block(-6,38,-5,LEAVES:3)
Block(-5,38,-5,LEAVES:3)
Block(-4,38,-5,LEAVES:3)
Block(-3,38,-5,LEAVES:3)
Block(-2,38,-5,LEAVES:3)
Block(-1,38,-5,LEAVES:3)
Block(2,38,-5,LEAVES:3)
Block(3,38,-5,LEAVES:3)
Block(4,38,-5,LEAVES:3)
Block(5,38,-5,LEAVES:3)
Block(6,38,-5,LEAVES:3)
Block(7,38,-5,LEAVES:3)
Block(-7,38,-4,LEAVES:3)
Block(-6,38,-4,LEAVES:3)
Block(-5,38,-4,LEAVES:3)
Block(-4,38,-4,LEAVES:3)
Block(-3,38,-4,LEAVES:3)
Block(-2,38,-4,LEAVES:3)
Block(-1,38,-4,LEAVES:3)
Block(3,38,-4,LEAVES:3)
Block(4,38,-4,LEAVES:3)
Block(5,38,-4,LEAVES:3)
Block(6,38,-4,LEAVES:3)
Block(7,38,-4,LEAVES:3)
Block(-6,38,-3,LEAVES:3)
Block(-5,38,-3,LEAVES:3)
Block(-4,38,-3,LEAVES:3)
Block(-3,38,-3,LEAVES:3)
Block(-2,38,-3,LEAVES:3)
Block(-1,38,-3,LEAVES:4)
Block(4,38,-3,LEAVES:3)
Block(5,38,-3,LEAVES:4)
Block(-6,38,-2,LEAVES:3)
Block(-5,38,-2,LEAVES:3)
Block(-4,38,-2,LEAVES:3)
Block(-3,38,-2,LEAVES:3)
Block(-2,38,-2,LEAVES:3)
Block(1,38,-2,LEAVES:3)
Block(-7,38,-1,LEAVES:3)
Block(-5,38,-1,LEAVES:3)
Block(-4,38,-1,LEAVES:3)
Block(1,38,-1,LOG:3)
Block(2,38,-1,LEAVES:3)
Block(3,38,-1,LEAVES:3)
Block(-8,38,0,LEAVES:3)
Block(-7,38,0,LEAVES:3)
Block(-6,38,0,LEAVES:4)
Block(1,38,0,LEAVES:3)
Block(3,38,0,LEAVES:3)
Block(4,38,0,LEAVES:3)
Block(5,38,0,LEAVES:3)
Block(-7,38,1,LEAVES:3)
Block(-2,38,1,LEAVES:3)
Block(-1,38,1,LEAVES:3)
Block(3,38,1,LEAVES:4)
Block(4,38,1,LEAVES:3)
Block(5,38,1,LEAVES:3)
Block(6,38,1,LEAVES:3)
Block(7,38,1,LEAVES:3)
Block(-6,38,2,LEAVES:3)
Block(-2,38,2,LEAVES:3)
Block(-1,38,2,LEAVES:3)
Block(0,38,2,LEAVES:3)
Block(4,38,2,LEAVES:3)
Block(5,38,2,LEAVES:3)
Block(6,38,2,LEAVES:3)
Block(7,38,2,LEAVES:3)
Block(-8,38,3,LEAVES:3)
Block(-7,38,3,LEAVES:3)
Block(-6,38,3,LEAVES:3)
Block(-5,38,3,LEAVES:3)
Block(-4,38,3,LEAVES:3)
Block(-3,38,3,LEAVES:3)
Block(-2,38,3,LEAVES:3)
Block(-1,38,3,LEAVES:3)
Block(4,38,3,LEAVES:3)
Block(5,38,3,LEAVES:3)
Block(6,38,3,LEAVES:3)
Block(-8,38,4,LEAVES:3)
Block(-7,38,4,LEAVES:3)
Block(-6,38,4,LEAVES:3)
Block(-5,38,4,LEAVES:3)
Block(-4,38,4,LEAVES:3)
Block(-3,38,4,LEAVES:3)
Block(-2,38,4,LEAVES:3)
Block(-1,38,4,LEAVES:3)
Block(0,38,4,LEAVES:3)
Block(1,38,4,LEAVES:3)
Block(5,38,4,LEAVES:3)
Block(-8,38,5,LEAVES:3)
Block(-7,38,5,LEAVES:3)
Block(-6,38,5,LEAVES:3)
Block(-3,38,5,LEAVES:3)
Block(-2,38,5,LEAVES:3)
Block(-1,38,5,LEAVES:3)
Block(0,38,5,LEAVES:3)
Block(1,38,5,LEAVES:3)
Block(-7,38,6,LEAVES:3)
Block(-6,38,6,LEAVES:3)
Block(-3,38,6,LEAVES:3)
Block(-2,38,6,LEAVES:3)
Block(-1,38,6,LEAVES:3)
Block(0,38,6,LEAVES:3)
Block(1,38,6,LEAVES:3)
Block(-1,38,7,LEAVES:3)
Block(0,38,7,LEAVES:3)
Block(-2,38,8,LEAVES:3)
Block(-4,39,-7,LEAVES:3)
Block(5,39,-7,LEAVES:3)
Block(-5,39,-6,LEAVES:3)
Block(-4,39,-6,LEAVES:3)
Block(-3,39,-6,LEAVES:3)
Block(4,39,-6,LEAVES:3)
Block(5,39,-6,LEAVES:3)
Block(6,39,-6,LEAVES:4)
Block(-6,39,-5,LEAVES:4)
Block(-5,39,-5,LEAVES:3)
Block(-4,39,-5,LEAVES:3)
Block(-3,39,-5,LEAVES:3)
Block(-2,39,-5,LEAVES:3)
Block(3,39,-5,LEAVES:4)
Block(4,39,-5,LEAVES:3)
Block(5,39,-5,LEAVES:3)
Block(6,39,-5,LEAVES:3)
Block(-5,39,-4,LEAVES:3)
Block(-4,39,-4,LEAVES:3)
Block(-3,39,-4,LEAVES:3)
Block(4,39,-4,LEAVES:3)
Block(5,39,-4,LEAVES:3)
Block(-4,39,-3,LEAVES:4)
Block(-2,39,-2,LEAVES:3)
Block(1,39,-1,LEAVES:4)
Block(2,39,-1,LEAVES:3)
Block(-7,39,0,LEAVES:3)
Block(5,39,1,LEAVES:3)
Block(4,39,2,LEAVES:3)
Block(5,39,2,LEAVES:4)
Block(-7,39,3,LEAVES:3)
Block(-6,39,3,LEAVES:4)
Block(-2,39,3,LEAVES:3)
Block(-8,39,4,LEAVES:3)
Block(-7,39,4,LEAVES:3)
Block(-6,39,4,LEAVES:3)
Block(-2,39,4,LEAVES:3)
Block(-1,39,4,LEAVES:3)
Block(-7,39,5,LEAVES:3)
Block(-6,39,5,LEAVES:3)
Block(-2,39,5,LEAVES:3)
Block(-1,39,5,LEAVES:3)
Block(0,39,5,LEAVES:3)
Block(4,40,-5,LEAVES:3)
Block(5,40,-5,LEAVES:3)
Block(5,40,-4,LEAVES:3)
Block(-1,40,4,LEAVES:4)
Block(-3,35,-6,VINE:2)
Block(-3,35,-7,VINE:0)
Block(-4,35,-7,VINE:1)
Block(7,34,3,VINE:2)
Block(-2,34,3,VINE:2)
Block(-4,34,3,VINE:8)
Block(-1,34,2,VINE:4)
Block(5,34,0,VINE:4)
Block(4,34,-5,VINE:8)
Block(3,34,-5,VINE:0)
Block(2,34,-5,VINE:0)
Block(3,34,-6,VINE:0)
Block(-3,34,-6,VINE:2)
Block(-4,34,-7,VINE:1)
Block(6,33,4,VINE:4)
Block(7,33,3,VINE:2)
Block(1,33,3,VINE:4)
Block(-2,33,3,VINE:2)
Block(-4,33,3,VINE:8)
Block(-1,33,2,VINE:4)
Block(5,33,0,VINE:4)
Block(4,33,-5,VINE:8)
Block(-3,33,-6,VINE:2)
Block(-4,33,-7,VINE:1)
Block(6,32,4,VINE:4)
Block(7,32,3,VINE:2)
Block(1,32,3,VINE:4)
Block(-2,32,3,VINE:2)
Block(-4,32,3,VINE:8)
Block(-1,32,2,VINE:4)
Block(5,32,0,VINE:4)
Block(5,32,-4,VINE:4)
Block(4,32,-5,VINE:8)
Block(-3,32,-6,VINE:2)
Block(-4,32,-7,VINE:1)
Block(6,31,4,VINE:4)
Block(7,31,3,VINE:2)
Block(1,31,3,VINE:4)
Block(-2,31,3,VINE:2)
Block(-4,31,3,VINE:8)
Block(-1,31,2,VINE:4)
Block(5,31,0,VINE:4)
Block(5,31,-4,VINE:4)
Block(4,31,-5,VINE:8)
Block(-3,31,-6,VINE:2)
Block(-5,31,-6,VINE:8)
Block(-4,31,-7,VINE:1)
Block(6,30,4,VINE:4)
Block(7,30,3,VINE:2)
Block(1,30,3,VINE:4)
Block(-2,30,3,VINE:2)
Block(-4,30,3,VINE:8)
Block(-1,30,2,VINE:4)
Block(5,30,0,VINE:4)
Block(-2,30,-1,VINE:8)
Block(-1,30,-2,VINE:1)
Block(6,30,-4,VINE:4)
Block(5,30,-4,VINE:4)
Block(4,30,-5,VINE:8)
Block(-3,30,-6,VINE:2)
Block(-5,30,-6,VINE:8)
Block(-4,30,-7,VINE:1)
Block(6,29,4,VINE:4)
Block(7,29,3,VINE:2)
Block(1,29,3,VINE:4)
Block(-2,29,3,VINE:2)
Block(-4,29,3,VINE:8)
Block(-1,29,2,VINE:4)
Block(5,29,0,VINE:4)
Block(-2,29,-1,VINE:8)
Block(-1,29,-3,VINE:8)
Block(0,29,-4,VINE:1)
Block(-3,29,-6,VINE:2)
Block(-5,29,-6,VINE:8)
Block(-4,29,-7,VINE:1)
Block(6,28,4,VINE:4)
Block(7,28,3,VINE:2)
Block(1,28,3,VINE:4)
Block(-2,28,3,VINE:2)
Block(-4,28,3,VINE:8)
Block(-1,28,2,VINE:4)
Block(5,28,0,VINE:4)
Block(-2,28,-1,VINE:8)
Block(-1,28,-3,VINE:8)
Block(0,28,-4,VINE:1)
Block(-3,28,-6,VINE:2)
Block(-5,28,-6,VINE:8)
Block(-4,28,-7,VINE:1)
Block(6,27,4,VINE:4)
Block(7,27,3,VINE:2)
Block(1,27,3,VINE:4)
Block(-2,27,3,VINE:2)
Block(-4,27,3,VINE:8)
Block(0,27,2,VINE:4)
Block(-1,27,2,VINE:4)
Block(5,27,0,VINE:4)
Block(-2,27,-1,VINE:8)
Block(3,27,-2,VINE:2)
Block(-1,27,-3,VINE:8)
Block(0,27,-4,VINE:1)
Block(7,27,-6,VINE:2)
Block(5,27,-6,VINE:8)
Block(-3,27,-6,VINE:2)
Block(-5,27,-6,VINE:8)
Block(6,27,-7,VINE:1)
Block(-4,27,-7,VINE:1)
Block(6,26,4,VINE:4)
Block(7,26,3,VINE:2)
Block(1,26,3,VINE:4)
Block(-2,26,3,VINE:2)
Block(-4,26,3,VINE:8)
Block(0,26,2,VINE:4)
Block(-1,26,2,VINE:4)
Block(5,26,0,VINE:4)
Block(-2,26,-1,VINE:8)
Block(3,26,-2,VINE:2)
Block(-1,26,-3,VINE:8)
Block(0,26,-4,VINE:1)
Block(7,26,-6,VINE:2)
Block(5,26,-6,VINE:8)
Block(-3,26,-6,VINE:2)
Block(-5,26,-6,VINE:8)
Block(6,26,-7,VINE:1)
Block(-4,26,-7,VINE:1)
Block(6,25,4,VINE:4)
Block(7,25,3,VINE:2)
Block(1,25,3,VINE:4)
Block(0,25,2,VINE:4)
Block(-1,25,2,VINE:4)
Block(5,25,0,VINE:4)
Block(2,25,0,VINE:2)
Block(3,25,-2,VINE:2)
Block(-1,25,-3,VINE:8)
Block(0,25,-4,VINE:1)
Block(7,25,-6,VINE:2)
Block(5,25,-6,VINE:8)
Block(-3,25,-6,VINE:2)
Block(-5,25,-6,VINE:8)
Block(6,25,-7,VINE:1)
Block(-4,25,-7,VINE:1)
Block(6,24,4,VINE:4)
Block(7,24,3,VINE:2)
Block(1,24,3,VINE:4)
Block(0,24,2,VINE:4)
Block(5,24,0,VINE:4)
Block(2,24,0,VINE:2)
Block(-1,24,-3,VINE:8)
Block(0,24,-4,VINE:1)
Block(7,24,-6,VINE:2)
Block(5,24,-6,VINE:8)
Block(-3,24,-6,VINE:2)
Block(-5,24,-6,VINE:8)
Block(6,24,-7,VINE:1)
Block(-4,24,-7,VINE:1)
Block(6,23,4,VINE:4)
Block(7,23,3,VINE:2)
Block(1,23,3,VINE:4)
Block(0,23,2,VINE:4)
Block(0,23,1,VINE:4)
Block(5,23,0,VINE:4)
Block(2,23,0,VINE:2)
Block(-1,23,-3,VINE:8)
Block(0,23,-4,VINE:1)
Block(7,23,-6,VINE:2)
Block(5,23,-6,VINE:8)
Block(-3,23,-6,VINE:2)
Block(-5,23,-6,VINE:8)
Block(6,23,-7,VINE:1)
Block(-4,23,-7,VINE:1)
Block(7,22,3,VINE:2)
Block(1,22,3,VINE:4)
Block(0,22,2,VINE:4)
Block(0,22,1,VINE:4)
Block(5,22,0,VINE:4)
Block(2,22,0,VINE:2)
Block(2,22,-3,VINE:2)
Block(-1,22,-3,VINE:8)
Block(0,22,-4,VINE:1)
Block(7,22,-6,VINE:2)
Block(5,22,-6,VINE:8)
Block(-3,22,-6,VINE:2)
Block(-5,22,-6,VINE:8)
Block(6,22,-7,VINE:1)
Block(-4,22,-7,VINE:1)
Block(1,21,3,VINE:4)
Block(0,21,2,VINE:4)
Block(-3,21,2,VINE:8)
Block(0,21,1,VINE:4)
Block(5,21,0,VINE:4)
Block(2,21,0,VINE:2)
Block(2,21,-1,VINE:4)
Block(2,21,-3,VINE:2)
Block(-1,21,-3,VINE:8)
Block(7,21,-6,VINE:2)
Block(5,21,-6,VINE:8)
Block(-3,21,-6,VINE:2)
Block(-5,21,-6,VINE:8)
Block(6,21,-7,VINE:1)
Block(-4,21,-7,VINE:1)
Block(1,20,3,VINE:4)
Block(0,20,2,VINE:4)
Block(-3,20,2,VINE:8)
Block(0,20,1,VINE:4)
Block(2,20,0,VINE:2)
Block(-1,20,0,VINE:8)
Block(2,20,-1,VINE:4)
Block(-2,20,-2,VINE:8)
Block(2,20,-3,VINE:2)
Block(1,20,-4,VINE:1)
Block(7,20,-6,VINE:2)
Block(5,20,-6,VINE:8)
Block(-3,20,-6,VINE:2)
Block(-5,20,-6,VINE:8)
Block(6,20,-7,VINE:1)
Block(-4,20,-7,VINE:1)
Block(1,19,3,VINE:4)
Block(0,19,2,VINE:4)
Block(-3,19,2,VINE:8)
Block(0,19,1,VINE:4)
Block(2,19,0,VINE:2)
Block(-1,19,0,VINE:8)
Block(2,19,-1,VINE:4)
Block(-2,19,-2,VINE:8)
Block(2,19,-3,VINE:2)
Block(1,19,-4,VINE:1)
Block(-1,19,-4,VINE:1)
Block(7,19,-6,VINE:2)
Block(5,19,-6,VINE:8)
Block(-3,19,-6,VINE:2)
Block(-5,19,-6,VINE:8)
Block(6,19,-7,VINE:1)
Block(-4,19,-7,VINE:1)
Block(1,18,3,VINE:4)
Block(0,18,2,VINE:4)
Block(-3,18,2,VINE:8)
Block(0,18,1,VINE:4)
Block(2,18,0,VINE:2)
Block(-1,18,0,VINE:8)
Block(2,18,-1,VINE:4)
Block(-2,18,-2,VINE:8)
Block(2,18,-3,VINE:2)
Block(1,18,-4,VINE:1)
Block(-1,18,-4,VINE:1)
Block(7,18,-6,VINE:2)
Block(5,18,-6,VINE:8)
Block(-3,18,-6,VINE:2)
Block(-5,18,-6,VINE:8)
Block(6,18,-7,VINE:1)
Block(-4,18,-7,VINE:1)
Block(1,17,3,VINE:4)
Block(0,17,2,VINE:4)
Block(-3,17,2,VINE:8)
Block(0,17,1,VINE:4)
Block(2,17,0,VINE:2)
Block(-1,17,0,VINE:8)
Block(2,17,-1,VINE:4)
Block(-2,17,-2,VINE:8)
Block(2,17,-3,VINE:2)
Block(-1,17,-4,VINE:1)
Block(7,17,-6,VINE:2)
Block(5,17,-6,VINE:8)
Block(-3,17,-6,VINE:2)
Block(-5,17,-6,VINE:8)
Block(-4,17,-7,VINE:1)
Block(1,16,3,VINE:4)
Block(0,16,2,VINE:4)
Block(-3,16,2,VINE:8)
Block(0,16,1,VINE:4)
Block(2,16,0,VINE:2)
Block(-1,16,0,VINE:8)
Block(2,16,-1,VINE:4)
Block(-2,16,-2,VINE:8)
Block(2,16,-3,VINE:2)
Block(7,16,-6,VINE:2)
Block(-3,16,-6,VINE:2)
Block(-5,16,-6,VINE:8)
Block(-4,16,-7,VINE:1)
Block(1,15,3,VINE:4)
Block(0,15,2,VINE:4)
Block(-3,15,2,VINE:8)
Block(0,15,1,VINE:4)
Block(2,15,0,VINE:2)
Block(-1,15,0,VINE:8)
Block(2,15,-1,VINE:4)
Block(-2,15,-2,VINE:8)
Block(7,15,-6,VINE:2)
Block(-3,15,-6,VINE:2)
Block(-5,15,-6,VINE:8)
Block(-4,15,-7,VINE:1)
Block(1,14,3,VINE:4)
Block(0,14,2,VINE:4)
Block(-3,14,2,VINE:8)
Block(0,14,1,VINE:4)
Block(-1,14,0,VINE:8)
Block(-2,14,-2,VINE:8)
Block(7,14,-6,VINE:2)
Block(-3,14,-6,VINE:2)
Block(-5,14,-6,VINE:8)
Block(-4,14,-7,VINE:1)
Block(1,13,3,VINE:4)
Block(0,13,2,VINE:4)
Block(-3,13,2,VINE:8)
Block(-2,13,-2,VINE:8)
Block(7,13,-6,VINE:2)
Block(-3,13,-6,VINE:2)
Block(-5,13,-6,VINE:8)
Block(-4,13,-7,VINE:1)
Block(1,12,3,VINE:4)
Block(0,12,2,VINE:4)
Block(-3,12,2,VINE:8)
Block(-3,12,-2,VINE:8)
Block(-3,12,-6,VINE:2)
Block(-5,12,-6,VINE:8)
Block(-4,12,-7,VINE:1)
Block(1,11,3,VINE:4)
Block(0,11,2,VINE:4)
Block(-3,11,2,VINE:8)
Block(-1,11,1,VINE:4)
Block(-2,11,0,VINE:8)
Block(2,11,-1,VINE:2)
Block(3,11,-2,VINE:2)
Block(-3,11,-2,VINE:8)
Block(2,11,-4,VINE:1)
Block(1,11,-5,VINE:1)
Block(-3,11,-6,VINE:2)
Block(-4,11,-7,VINE:1)
Block(1,10,3,VINE:4)
Block(0,10,2,VINE:4)
Block(-3,10,2,VINE:8)
Block(2,10,1,VINE:4)
Block(-2,10,0,VINE:8)
Block(2,10,-1,VINE:2)
Block(3,10,-2,VINE:2)
Block(-3,10,-2,VINE:8)
Block(2,10,-4,VINE:1)
Block(1,10,-5,VINE:1)
Block(-3,10,-6,VINE:2)
Block(-4,10,-7,VINE:1)
Block(1,9,3,VINE:4)
Block(-3,9,2,VINE:8)
Block(3,9,-2,VINE:2)
Block(-3,9,-2,VINE:8)
Block(-3,9,-6,VINE:2)
Block(-4,9,-7,VINE:1)
Block(1,8,3,VINE:4)
Block(-3,8,2,VINE:8)
Block(-3,8,-2,VINE:8)
Block(-3,8,-6,VINE:2)
Block(-4,8,-7,VINE:1)
Block(1,7,3,VINE:4)
Block(-3,7,2,VINE:8)
Block(-3,7,-6,VINE:2)
Block(-4,7,-7,VINE:1)
Block(1,6,3,VINE:4)
Block(-3,6,2,VINE:8)
Block(-3,6,-6,VINE:2)
Block(-4,6,-7,VINE:1)
Block(1,5,3,VINE:4)
Block(-3,5,2,VINE:8)
Block(-3,5,-6,VINE:2)
Block(-4,5,-7,VINE:1)
Block(1,4,3,VINE:4)
Block(-3,4,2,VINE:8)
Block(-3,4,-6,VINE:2)
Block(1,3,3,VINE:4)
Block(-3,3,2,VINE:8)
Block(-3,3,-6,VINE:2)
Block(-4,2,7,VINE:4)
Block(-5,2,7,VINE:4)
Block(-3,2,6,VINE:2)
Block(-4,2,5,VINE:1)
Block(1,2,3,VINE:4)
Block(-3,2,2,VINE:8)
Block(6,2,-1,VINE:4)
Block(5,2,-1,VINE:4)
Block(-6,2,-1,VINE:4)
Block(-5,2,-2,VINE:2)
Block(6,2,-3,VINE:1)
Block(5,2,-3,VINE:1)
Block(-6,2,-3,VINE:1)
Block(5,2,-6,VINE:4)
Block(-3,2,-6,VINE:2)
Block(4,2,-7,VINE:4)
Block(-3,2,-7,VINE:2)
Block(-5,2,-7,VINE:8)
Block(-4,2,-8,VINE:1)
Block(-4,1,7,VINE:4)
Block(-3,1,6,VINE:2)
Block(1,1,3,VINE:4)
Block(-3,1,2,VINE:8)
Block(-6,1,-1,VINE:4)
Block(-5,1,-2,VINE:2)
Block(5,1,-3,VINE:1)
Block(-6,1,-3,VINE:1)
Block(5,1,-6,VINE:4)
Block(4,1,-7,VINE:4)
Block(0,1,-7,VINE:1)
Block(-3,1,-7,VINE:2)
Block(-5,1,-7,VINE:8)
Block(-4,1,-8,VINE:1)
Block(-3,0,6,VINE:2)
Block(-3,0,5,TALLGRASS:1)
Block(-4,0,5,TALLGRASS:1)
Block(5,0,4,TALLGRASS:1)
Block(4,0,4,TALLGRASS:2)
Block(1,0,4,TALLGRASS:1)
Block(-1,0,4,TALLGRASS:2)
Block(-2,0,4,TALLGRASS:1)
Block(-3,0,4,TALLGRASS:1)
Block(-4,0,4,TALLGRASS:1)
Block(5,0,3,TALLGRASS:1)
Block(4,0,3,TALLGRASS:1)
Block(3,0,3,TALLGRASS:1)
Block(-1,0,3,RED_FLOWER:5)
Block(-2,0,3,TALLGRASS:1)
Block(-3,0,3,TALLGRASS:1)
Block(-4,0,3,TALLGRASS:2)
Block(6,0,2,TALLGRASS:1)
Block(5,0,2,TALLGRASS:2)
Block(4,0,2,TALLGRASS:1)
Block(-2,0,2,TALLGRASS:1)
Block(-3,0,2,TALLGRASS:1)
Block(-4,0,1,TALLGRASS:1)
Block(5,0,0,TALLGRASS:1)
Block(4,0,0,RED_FLOWER:5)
Block(-5,0,0,TALLGRASS:1)
Block(-6,0,0,TALLGRASS:1)
Block(6,0,-1,TALLGRASS:2)
Block(5,0,-1,TALLGRASS:1)
Block(-6,0,-1,TALLGRASS:2)
Block(6,0,-2,TALLGRASS:1)
Block(5,0,-2,TALLGRASS:1)
Block(4,0,-2,TALLGRASS:1)
Block(-5,0,-2,TALLGRASS:1)
Block(-6,0,-2,TALLGRASS:1)
Block(5,0,-3,TALLGRASS:1)
Block(4,0,-3,TALLGRASS:1)
Block(-4,0,-3,RED_FLOWER:5)
Block(-5,0,-3,TALLGRASS:2)
Block(-6,0,-3,VINE:1)
Block(4,0,-4,TALLGRASS:1)
Block(-4,0,-4,TALLGRASS:1)
Block(-5,0,-4,TALLGRASS:2)
Block(-6,0,-4,TALLGRASS:1)
Block(4,0,-5,TALLGRASS:1)
Block(3,0,-5,RED_FLOWER:5)
Block(-3,0,-5,TALLGRASS:1)
Block(-4,0,-5,TALLGRASS:1)
Block(-5,0,-5,TALLGRASS:1)
Block(5,0,-6,TALLGRASS:1)
Block(4,0,-6,TALLGRASS:2)
Block(3,0,-6,TALLGRASS:1)
Block(-1,0,-6,TALLGRASS:1)
Block(-2,0,-6,TALLGRASS:1)
Block(-3,0,-6,TALLGRASS:1)
Block(4,0,-7,TALLGRASS:1)
Block(3,0,-7,TALLGRASS:1)
Block(2,0,-7,TALLGRASS:1)
Block(1,0,-7,TALLGRASS:1)
Block(-1,0,-7,TALLGRASS:1)
Block(-2,0,-7,TALLGRASS:2)
Block(-3,0,-7,VINE:2)
Block(-4,0,-7,TALLGRASS:2)
Block(-5,0,-7,TALLGRASS:1)
Block(1,0,-8,TALLGRASS:2)
Block(-1,0,-8,TALLGRASS:1)
Block(-4,0,-8,VINE:1)
Block(-5,0,-8,TALLGRASS:1)

#######################################################################
# +-----------------------------------------------------------------+ #
# |                            BO3 checks                           | #
# +-----------------------------------------------------------------+ #
#######################################################################

# Require a condition at a certain location in order for the BO3 to be spawned.
# BlockCheck(x,y,z,BlockName[,BlockName[,...]]) - one of the blocks must be at the location
# BlockCheckNot(x,y,z,BlockName[,BlockName[,...]]) - all the blocks must not be at the location
# LightCheck(x,y,z,minLightLevel,maxLightLevel) - light must be between min and max (inclusive)

# You can use "Solid" as a BlockName for matching all solid blocks or "All" to match all blocks that aren't air.

# Examples:
BlockCheck(0,-1,0,GRASS,DIRT,DIRT:2,SAND,STONE,CLAY,GRAVEL)
#   BlockCheck(0,-1,0,Solid)       Require any solid block just below the object
#   BlockCheck(0,-1,0,WOOL)        Require any type of wool just below the object
#   BlockCheck(0,-1,0,WOOL:0)      Require white wool just below the object
#   BlockCheckNot(0,-1,0,WOOL:0)   Require that there is no white wool below the object
#   LightCheck(0,0,0,0,1)          Require almost complete darkness just below the object

#######################################################################
# +-----------------------------------------------------------------+ #
# |                             Branches                            | #
# +-----------------------------------------------------------------+ #
#######################################################################

# Branches are objects that will spawn when this object spawns when it is used in
# the CustomStructure resource. Branches can also have branches, making complex
# structures possible. See the wiki for more details.

# Regular Branches spawn each branch with an independent chance of spawning.
# Branch(x,y,z,branchName,rotation,chance[,anotherBranchName,rotation,chance[,...]][IndividualChance])
# branchName - name of the object to spawn.
# rotation - NORTH, SOUTH, EAST or WEST.
# IndividualChance - The chance each branch has to spawn, assumed to be 100 when left blank

# Weighted Branches spawn branches with a dependent chance of spawning.
# WeightedBranch(x,y,z,branchName,rotation,chance[,anotherBranchName,rotation,chance[,...]][MaxChanceOutOf])
# MaxChanceOutOf - The chance all branches have to spawn out of, assumed to be 100 when left blank

