#######################################################################
# +-----------------------------------------------------------------+ #
# |                            BO3 object                           | #
# +-----------------------------------------------------------------+ #
#######################################################################

# This is the config file of a custom object.
# If you add this object correctly to your BiomeConfigs, it will spawn in the world.

# This is the creator of this BO3 object
Author: BO3 BulkEdit (by LanToaster)

# A short description of this BO3 object
Description: This Object was Created with BO3_BulkEdit

# The BO3 version, don't change this! It can be used by external applications to do a version check.
Version: 3

# The settings mode, WriteAll, WriteWithoutComments or WriteDisable. See WorldConfig.
SettingsMode: WriteDisable


#######################################################################
# +-----------------------------------------------------------------+ #
# |                          Main settings                          | #
# +-----------------------------------------------------------------+ #
#######################################################################

# This needs to be set to true to spawn the object in the Tree and Sapling resources.
Tree: true

# The frequency of the BO3 from 1 to 200. Tries this many times to spawn this BO3 when using the CustomObject(...) resource.
# Ignored by Tree(..), Sapling(..) and CustomStructure(..)
Frequency: 1

# The rarity of the BO3 from 0 to 100. Each spawn attempt has rarity% chance to succeed when using the CustomObject(...) resource.
# Ignored by Tree(..), Sapling(..) and CustomStructure(..)
Rarity: 100.0

# If you set this to true, the BO3 will be placed with a random rotation.
RotateRandomly: true

# The spawn height of the BO3 - randomY, highestBlock or highestSolidBlock.
SpawnHeight: highestSolidBlock
SpawnHeightOffset: -4
# The height limits for the BO3.
MinHeight: 0

MaxHeight: 256

# Objects can have other objects attacthed to it: branches. Branches can also
# have branches attached to it, which can also have branches, etc. This is the
# maximum branch depth for this objects.
MaxBranchDepth: 10

# When spawned with the UseWorld keyword, this BO3 should NOT spawn in the following biomes.
# If you writer.write the BO3 name directly in the BiomeConfigs, this will be ignored.
ExcludedBiomes: All


#######################################################################
# +-----------------------------------------------------------------+ #
# |                      Source block settings                      | #
# +-----------------------------------------------------------------+ #
#######################################################################

# The block(s) the BO3 should spawn in.
SourceBlocks: AIR,GRASS,DIRT,STONE

# The maximum percentage of the BO3 that can be outside the SourceBlock.
# The BO3 won't be placed on a location with more blocks outside the SourceBlock than this percentage.
MaxPercentageOutsideSourceBlock: 0

# What to do when a block is about to be placed outside the SourceBlock? (placeAnyway, placeAnyway)
OutsideSourceBlock: dontplace


#######################################################################
# +-----------------------------------------------------------------+ #
# |                              Blocks                             | #
# +-----------------------------------------------------------------+ #
#######################################################################

# All the blocks used in the BO3 are listed here. Possible blocks:
# Block(x,y,z,id[.data][,nbtfile.nbt)
# RandomBlock(x,y,z,id[:data][,nbtfile.nbt],chance[,id[:data][,nbtfile.nbt],chance[,...]])
# So RandomBlock(0,0,0,CHEST,chest.nbt,50,CHEST,anotherchest.nbt,100) will spawn a chest at
# the BO3 origin, and give it a 50% chance to have the contents of chest.nbt, or, if that
# fails, a 100% percent chance to have the contents of anotherchest.nbt.
Block(-1,0,-4,LOG:12)
Block(-2,0,-3,LOG:12)
Block(-1,0,-3,LOG:12)
Block(0,0,-3,LOG:12)
Block(4,0,-3,LOG:12)
Block(-1,0,-2,LOG:12)
Block(0,0,-2,LOG:12)
Block(1,0,-2,LOG:12)
Block(2,0,-2,LOG:12)
Block(3,0,-2,LOG:12)
Block(4,0,-2,LOG:12)
Block(-1,0,-1,LOG:12)
Block(0,0,-1,LOG:12)
Block(2,0,-1,LOG:12)
Block(3,0,-1,LOG:12)
Block(-2,0,0,LOG:12)
Block(-1,0,0,LOG:12)
Block(0,0,0,LOG:12)
Block(1,0,0,LOG:12)
Block(2,0,0,LOG:12)
Block(-2,0,1,LOG:12)
Block(0,0,1,LOG:12)
Block(1,0,1,LOG:12)
Block(2,0,1,LOG:12)
Block(3,0,1,LOG:12)
Block(-2,0,2,LOG:12)
Block(-1,0,2,LOG:12)
Block(3,0,2,LOG:12)
Block(4,0,2,LOG:12)
Block(-3,0,3,LOG:12)
Block(-2,0,3,LOG:12)
Block(5,0,3,LOG:12)
Block(0,1,-3,LOG:12)
Block(0,1,-2,LOG:12)
Block(1,1,-2,LOG:12)
Block(3,1,-2,LOG:12)
Block(-1,1,-1,LOG:12)
Block(0,1,-1,LOG:12)
Block(2,1,-1,LOG:12)
Block(3,1,-1,LOG:12)
Block(-1,1,0,LOG:12)
Block(0,1,0,LOG:12)
Block(1,1,0,LOG:12)
Block(2,1,0,LOG:12)
Block(-2,1,1,LOG:12)
Block(-1,1,1,LOG:12)
Block(0,1,1,LOG:12)
Block(2,1,1,LOG:12)
Block(-2,1,2,LOG:12)
Block(-1,1,2,LOG:12)
Block(3,1,2,LOG:12)
Block(4,1,2,LOG:12)
Block(0,2,-3,LOG:12)
Block(0,2,-2,LOG:12)
Block(1,2,-2,LOG:12)
Block(-1,2,-1,LOG:12)
Block(0,2,-1,LOG:12)
Block(2,2,-1,LOG:12)
Block(3,2,-1,LOG:12)
Block(-1,2,0,LOG:12)
Block(0,2,0,LOG:12)
Block(1,2,0,LOG:12)
Block(2,2,0,LOG:12)
Block(-2,2,1,LOG:12)
Block(-1,2,1,LOG:12)
Block(3,2,1,LOG:12)
Block(-1,2,2,LOG:12)
Block(3,2,2,LOG:12)
Block(0,3,-2,LOG:12)
Block(0,3,-1,LOG:12)
Block(1,3,-1,LOG:12)
Block(2,3,-1,LOG:12)
Block(3,3,-1,LOG:12)
Block(-1,3,0,LOG:12)
Block(0,3,0,LOG:12)
Block(1,3,0,LOG:12)
Block(2,3,0,LOG:12)
Block(-1,3,1,LOG:12)
Block(2,3,1,LOG:12)
Block(3,3,1,LOG:12)
Block(0,4,-2,LOG:12)
Block(1,4,-2,LOG:12)
Block(0,4,-1,LOG:12)
Block(2,4,-1,LOG:12)
Block(3,4,-1,LOG:12)
Block(-1,4,0,LOG:12)
Block(0,4,0,LOG:12)
Block(1,4,0,LOG:12)
Block(2,4,0,LOG:12)
Block(3,4,0,LOG:12)
Block(-1,4,1,LOG:12)
Block(0,4,1,LOG:12)
Block(2,4,1,LOG:12)
Block(1,5,-2,LOG:12)
Block(2,5,-2,LOG:12)
Block(0,5,-1,LOG:12)
Block(2,5,-1,LOG:12)
Block(3,5,-1,LOG:12)
Block(-1,5,0,LOG:12)
Block(0,5,0,LOG:12)
Block(1,5,0,LOG:12)
Block(2,5,0,LOG:12)
Block(3,5,0,LOG:12)
Block(-1,5,1,LOG:12)
Block(0,5,1,LOG:12)
Block(1,5,1,LOG:12)
Block(2,5,1,LOG:12)
Block(1,5,2,LOG:12)
Block(-9,6,-8,LEAVES:12)
Block(-5,6,-2,LOG:12)
Block(2,6,-2,LOG:12)
Block(1,6,-1,LOG:12)
Block(2,6,-1,LOG:12)
Block(0,6,0,LOG:12)
Block(1,6,0,LOG:12)
Block(2,6,0,LOG:12)
Block(3,6,0,LOG:12)
Block(-1,6,1,LOG:12)
Block(0,6,1,LOG:12)
Block(2,6,1,LOG:12)
Block(1,6,2,LOG:12)
Block(-11,7,-11,LEAVES:12)
Block(-10,7,-11,LEAVES:12)
Block(-8,7,-11,LEAVES:12)
Block(-11,7,-10,LEAVES:12)
Block(-10,7,-10,LEAVES:12)
Block(-9,7,-10,LEAVES:12)
Block(-8,7,-10,LEAVES:12)
Block(-7,7,-10,LEAVES:12)
Block(-10,7,-9,LEAVES:12)
Block(-9,7,-9,LEAVES:12)
Block(-8,7,-9,LEAVES:12)
Block(-6,7,-3,LOG:12)
Block(-5,7,-3,LOG:12)
Block(-5,7,-2,LOG:12)
Block(-4,7,-2,LOG:12)
Block(-2,7,-2,LOG:12)
Block(-1,7,-2,LOG:12)
Block(0,7,-2,LOG:12)
Block(-4,7,-1,LOG:12)
Block(-3,7,-1,LOG:12)
Block(-2,7,-1,LOG:12)
Block(-1,7,-1,LOG:12)
Block(0,7,-1,LOG:12)
Block(1,7,-1,LOG:12)
Block(2,7,-1,LOG:12)
Block(-1,7,0,LOG:12)
Block(0,7,0,LOG:12)
Block(1,7,0,LOG:12)
Block(2,7,0,LOG:12)
Block(3,7,0,LOG:12)
Block(0,7,1,LOG:12)
Block(1,7,1,LOG:12)
Block(2,7,1,LOG:12)
Block(3,7,1,LOG:12)
Block(4,7,1,LOG:12)
Block(1,7,2,LOG:12)
Block(2,7,2,LOG:12)
Block(4,7,2,LOG:12)
Block(2,7,10,LEAVES:12)
Block(3,7,11,LEAVES:12)
Block(-11,8,-12,LEAVES:12)
Block(-10,8,-12,LEAVES:12)
Block(-9,8,-12,LEAVES:12)
Block(-8,8,-12,LEAVES:12)
Block(-7,8,-12,LEAVES:12)
Block(6,8,-12,LEAVES:12)
Block(-12,8,-11,LEAVES:12)
Block(-11,8,-11,LEAVES:12)
Block(-10,8,-11,LEAVES:12)
Block(-9,8,-11,LEAVES:12)
Block(-8,8,-11,LEAVES:12)
Block(-7,8,-11,LEAVES:12)
Block(6,8,-11,LEAVES:12)
Block(7,8,-11,LEAVES:12)
Block(-12,8,-10,LEAVES:12)
Block(-11,8,-10,LEAVES:12)
Block(-10,8,-10,LEAVES:12)
Block(-9,8,-10,LEAVES:12)
Block(-8,8,-10,LEAVES:12)
Block(-7,8,-10,LEAVES:12)
Block(-6,8,-10,LEAVES:12)
Block(5,8,-10,LEAVES:12)
Block(6,8,-10,LEAVES:12)
Block(7,8,-10,LEAVES:12)
Block(-12,8,-9,LEAVES:12)
Block(-10,8,-9,LEAVES:12)
Block(-9,8,-9,LEAVES:12)
Block(-8,8,-9,LEAVES:12)
Block(-6,8,-9,LEAVES:12)
Block(-11,8,-8,LEAVES:12)
Block(-10,8,-8,LEAVES:12)
Block(-9,8,-8,LEAVES:12)
Block(-8,8,-8,LEAVES:12)
Block(-5,8,-4,LOG:12)
Block(-6,8,-3,LOG:12)
Block(-5,8,-3,LOG:12)
Block(-5,8,-2,LOG:12)
Block(-4,8,-2,LOG:12)
Block(-3,8,-2,LOG:12)
Block(-2,8,-2,LOG:12)
Block(-1,8,-2,LOG:12)
Block(0,8,-2,LOG:12)
Block(-3,8,-1,LOG:12)
Block(-2,8,-1,LOG:12)
Block(-1,8,-1,LOG:12)
Block(0,8,-1,LOG:12)
Block(1,8,-1,LOG:12)
Block(0,8,0,LOG:12)
Block(2,8,1,LOG:12)
Block(3,8,1,LOG:12)
Block(4,8,1,LOG:12)
Block(1,8,2,LOG:12)
Block(2,8,2,LOG:12)
Block(3,8,2,LOG:12)
Block(2,8,3,LOG:12)
Block(2,8,7,LEAVES:12)
Block(1,8,8,LEAVES:12)
Block(2,8,9,LEAVES:12)
Block(3,8,9,LEAVES:12)
Block(3,8,11,LEAVES:12)
Block(-10,9,-12,LEAVES:12)
Block(-9,9,-12,LEAVES:12)
Block(-8,9,-12,LEAVES:12)
Block(6,9,-12,LEAVES:12)
Block(7,9,-12,LEAVES:12)
Block(-12,9,-11,LEAVES:12)
Block(-11,9,-11,LEAVES:12)
Block(-10,9,-11,LEAVES:12)
Block(-9,9,-11,LEAVES:12)
Block(-8,9,-11,LEAVES:12)
Block(-7,9,-11,LEAVES:12)
Block(-6,9,-11,LEAVES:12)
Block(5,9,-11,LEAVES:12)
Block(6,9,-11,LEAVES:12)
Block(7,9,-11,LEAVES:12)
Block(8,9,-11,LEAVES:12)
Block(-12,9,-10,LEAVES:12)
Block(-11,9,-10,LEAVES:12)
Block(-10,9,-10,LEAVES:12)
Block(-9,9,-10,LEAVES:12)
Block(-8,9,-10,LOG:12)
Block(-6,9,-10,LEAVES:12)
Block(4,9,-10,LEAVES:12)
Block(5,9,-10,LEAVES:12)
Block(6,9,-10,LEAVES:12)
Block(7,9,-10,LEAVES:12)
Block(8,9,-10,LEAVES:12)
Block(-12,9,-9,LEAVES:12)
Block(-11,9,-9,LEAVES:12)
Block(-10,9,-9,LEAVES:12)
Block(-8,9,-9,LOG:12)
Block(-7,9,-9,LEAVES:12)
Block(-6,9,-9,LEAVES:12)
Block(-5,9,-9,LEAVES:12)
Block(5,9,-9,LEAVES:12)
Block(6,9,-9,LEAVES:12)
Block(7,9,-9,LEAVES:12)
Block(8,9,-9,LEAVES:12)
Block(-11,9,-8,LEAVES:12)
Block(-10,9,-8,LEAVES:12)
Block(-9,9,-8,LEAVES:12)
Block(-8,9,-8,LOG:12)
Block(-7,9,-8,LEAVES:12)
Block(5,9,-8,LEAVES:12)
Block(6,9,-8,LEAVES:12)
Block(7,9,-8,LEAVES:12)
Block(6,9,-7,LEAVES:12)
Block(6,9,-6,LEAVES:12)
Block(-7,9,-5,LEAVES:12)
Block(-5,9,-5,LOG:12)
Block(-6,9,-4,LOG:12)
Block(-5,9,-4,LOG:12)
Block(-5,9,-3,LOG:12)
Block(-1,9,-2,LOG:12)
Block(0,9,-2,LOG:12)
Block(-1,9,-1,LOG:12)
Block(0,9,-1,LOG:12)
Block(0,9,0,LOG:12)
Block(2,9,1,LOG:12)
Block(3,9,1,LOG:12)
Block(5,9,1,LOG:12)
Block(2,9,2,LOG:12)
Block(3,9,2,LOG:12)
Block(4,9,2,LOG:12)
Block(5,9,2,LOG:12)
Block(2,9,3,LOG:12)
Block(3,9,7,LEAVES:12)
Block(1,9,8,LEAVES:12)
Block(3,9,8,LEAVES:12)
Block(1,9,9,LEAVES:12)
Block(-1,9,10,LEAVES:12)
Block(1,9,10,LEAVES:12)
Block(3,9,10,LEAVES:12)
Block(4,9,10,LEAVES:12)
Block(0,9,11,LEAVES:12)
Block(1,9,11,LEAVES:12)
Block(2,9,11,LEAVES:12)
Block(-1,9,12,LEAVES:12)
Block(0,9,12,LEAVES:12)
Block(1,9,12,LEAVES:12)
Block(2,9,12,LEAVES:12)
Block(6,10,-13,LEAVES:12)
Block(7,10,-13,LEAVES:12)
Block(-11,10,-12,LEAVES:12)
Block(-8,10,-12,LEAVES:12)
Block(5,10,-12,LEAVES:12)
Block(6,10,-12,LEAVES:12)
Block(7,10,-12,LEAVES:12)
Block(-11,10,-11,LEAVES:12)
Block(-10,10,-11,LEAVES:12)
Block(-9,10,-11,LEAVES:12)
Block(-8,10,-11,LEAVES:12)
Block(4,10,-11,LEAVES:12)
Block(5,10,-11,LEAVES:12)
Block(6,10,-11,LEAVES:12)
Block(7,10,-11,LEAVES:12)
Block(8,10,-11,LEAVES:12)
Block(-12,10,-10,LEAVES:12)
Block(-11,10,-10,LEAVES:12)
Block(-10,10,-10,LEAVES:12)
Block(-8,10,-10,LEAVES:12)
Block(4,10,-10,LEAVES:12)
Block(5,10,-10,LEAVES:12)
Block(6,10,-10,LEAVES:12)
Block(7,10,-10,LEAVES:12)
Block(8,10,-10,LEAVES:12)
Block(-12,10,-9,LEAVES:12)
Block(-11,10,-9,LEAVES:12)
Block(-10,10,-9,LEAVES:12)
Block(-9,10,-9,LEAVES:12)
Block(-8,10,-9,LEAVES:12)
Block(4,10,-9,LEAVES:12)
Block(5,10,-9,LEAVES:12)
Block(6,10,-9,LEAVES:12)
Block(7,10,-9,LEAVES:12)
Block(-11,10,-8,LEAVES:12)
Block(-10,10,-8,LEAVES:12)
Block(-9,10,-8,LEAVES:12)
Block(-8,10,-8,LOG:12)
Block(-6,10,-8,LEAVES:12)
Block(3,10,-8,LOG:12)
Block(4,10,-8,LOG:12)
Block(5,10,-8,LOG:12)
Block(7,10,-8,LEAVES:12)
Block(8,10,-8,LEAVES:12)
Block(-8,10,-7,LOG:12)
Block(-7,10,-7,LOG:12)
Block(4,10,-7,LEAVES:12)
Block(6,10,-7,LEAVES:12)
Block(7,10,-7,LEAVES:12)
Block(8,10,-7,LEAVES:12)
Block(-10,10,-6,LEAVES:12)
Block(-8,10,-6,LEAVES:12)
Block(-7,10,-6,LOG:12)
Block(-6,10,-6,LOG:12)
Block(5,10,-6,LEAVES:12)
Block(6,10,-6,LEAVES:12)
Block(-6,10,-5,LOG:12)
Block(-5,10,-5,LOG:12)
Block(4,10,-5,LEAVES:12)
Block(-5,10,-4,LOG:12)
Block(-1,10,-3,LOG:12)
Block(-1,10,-2,LOG:12)
Block(-1,10,-1,LOG:12)
Block(0,10,-1,LOG:12)
Block(6,10,0,LOG:12)
Block(5,10,1,LOG:12)
Block(6,10,1,LOG:12)
Block(2,10,2,LOG:12)
Block(3,10,2,LOG:12)
Block(4,10,2,LOG:12)
Block(5,10,2,LOG:12)
Block(2,10,3,LOG:12)
Block(3,10,3,LOG:12)
Block(1,10,6,LEAVES:12)
Block(-1,10,7,LEAVES:12)
Block(1,10,7,LEAVES:12)
Block(4,10,7,LOG:12)
Block(3,10,8,LOG:12)
Block(4,10,8,LOG:12)
Block(0,10,9,LEAVES:12)
Block(2,10,9,LOG:12)
Block(3,10,9,LOG:12)
Block(0,10,10,LEAVES:12)
Block(1,10,10,LEAVES:12)
Block(2,10,10,LOG:12)
Block(3,10,10,LEAVES:12)
Block(-2,10,11,LEAVES:12)
Block(0,10,11,LEAVES:12)
Block(1,10,11,LEAVES:12)
Block(2,10,11,LEAVES:12)
Block(3,10,11,LEAVES:12)
Block(-2,10,12,LEAVES:12)
Block(0,10,12,LEAVES:12)
Block(2,10,12,LEAVES:12)
Block(3,10,12,LEAVES:12)
Block(4,10,12,LEAVES:12)
Block(0,10,13,LEAVES:12)
Block(1,10,13,LEAVES:12)
Block(6,11,-13,LEAVES:12)
Block(7,11,-13,LEAVES:12)
Block(6,11,-12,LEAVES:12)
Block(7,11,-12,LEAVES:12)
Block(-11,11,-11,LEAVES:12)
Block(-10,11,-11,LEAVES:12)
Block(-9,11,-11,LEAVES:12)
Block(-8,11,-11,LEAVES:12)
Block(4,11,-11,LEAVES:12)
Block(5,11,-11,LEAVES:12)
Block(6,11,-11,LEAVES:12)
Block(7,11,-11,LEAVES:12)
Block(8,11,-11,LEAVES:12)
Block(-11,11,-10,LEAVES:12)
Block(-10,11,-10,LEAVES:12)
Block(-9,11,-10,LEAVES:12)
Block(-7,11,-10,LEAVES:12)
Block(5,11,-10,LEAVES:12)
Block(6,11,-10,LEAVES:12)
Block(7,11,-10,LEAVES:12)
Block(8,11,-10,LEAVES:12)
Block(-12,11,-9,LEAVES:12)
Block(-11,11,-9,LEAVES:12)
Block(-9,11,-9,LEAVES:12)
Block(-8,11,-9,LEAVES:12)
Block(-7,11,-9,LEAVES:12)
Block(0,11,-9,LOG:12)
Block(1,11,-9,LOG:12)
Block(2,11,-9,LOG:12)
Block(4,11,-9,LEAVES:12)
Block(6,11,-9,LEAVES:12)
Block(7,11,-9,LEAVES:12)
Block(8,11,-9,LEAVES:12)
Block(-11,11,-8,LEAVES:12)
Block(-8,11,-8,LEAVES:12)
Block(2,11,-8,LOG:12)
Block(3,11,-8,LOG:12)
Block(4,11,-8,LEAVES:12)
Block(5,11,-8,LOG:12)
Block(6,11,-8,LOG:12)
Block(7,11,-8,LEAVES:12)
Block(8,11,-8,LEAVES:12)
Block(9,11,-8,LEAVES:12)
Block(-7,11,-7,LEAVES:12)
Block(3,11,-7,LEAVES:12)
Block(4,11,-7,LEAVES:12)
Block(6,11,-7,LOG:12)
Block(7,11,-7,LEAVES:12)
Block(8,11,-7,LEAVES:12)
Block(-6,11,-6,LOG:12)
Block(3,11,-6,LEAVES:12)
Block(5,11,-6,LEAVES:12)
Block(6,11,-6,LEAVES:12)
Block(8,11,-6,LEAVES:12)
Block(-6,11,-5,LOG:12)
Block(5,11,-5,LEAVES:12)
Block(9,11,-5,LEAVES:12)
Block(6,11,-4,LEAVES:12)
Block(-2,11,-3,LOG:12)
Block(-1,11,-3,LOG:12)
Block(-2,11,-2,LOG:12)
Block(-1,11,-2,LOG:12)
Block(7,11,-1,LOG:12)
Block(6,11,0,LOG:12)
Block(7,11,0,LOG:12)
Block(6,11,1,LOG:12)
Block(3,11,2,LOG:12)
Block(4,11,2,LOG:12)
Block(3,11,3,LOG:12)
Block(4,11,3,LOG:12)
Block(4,11,5,LOG:12)
Block(4,11,6,LOG:12)
Block(-2,11,7,LEAVES:12)
Block(-1,11,7,LEAVES:12)
Block(4,11,7,LOG:12)
Block(-1,11,9,LEAVES:12)
Block(0,11,9,LEAVES:12)
Block(1,11,9,LEAVES:12)
Block(3,11,9,LEAVES:12)
Block(5,11,9,LEAVES:12)
Block(-2,11,10,LEAVES:12)
Block(-1,11,10,LEAVES:12)
Block(0,11,10,LEAVES:12)
Block(1,11,10,LOG:12)
Block(2,11,10,LOG:12)
Block(3,11,10,LEAVES:12)
Block(-2,11,11,LEAVES:12)
Block(-1,11,11,LEAVES:12)
Block(0,11,11,LOG:12)
Block(1,11,11,LOG:12)
Block(2,11,11,LEAVES:12)
Block(3,11,11,LEAVES:12)
Block(5,11,11,LEAVES:12)
Block(-2,11,12,LEAVES:12)
Block(0,11,12,LEAVES:12)
Block(1,11,12,LEAVES:12)
Block(2,11,12,LEAVES:12)
Block(3,11,12,LEAVES:12)
Block(-1,11,13,LEAVES:12)
Block(0,11,13,LEAVES:12)
Block(1,11,13,LEAVES:12)
Block(2,11,13,LEAVES:12)
Block(-8,12,-12,LEAVES:12)
Block(-7,12,-11,LEAVES:12)
Block(6,12,-11,LEAVES:12)
Block(7,12,-11,LEAVES:12)
Block(-9,12,-10,LEAVES:12)
Block(5,12,-10,LEAVES:12)
Block(6,12,-10,LEAVES:12)
Block(7,12,-10,LEAVES:12)
Block(9,12,-10,LEAVES:12)
Block(11,12,-10,LEAVES:12)
Block(-11,12,-9,LEAVES:12)
Block(-8,12,-9,LEAVES:12)
Block(0,12,-9,LOG:12)
Block(1,12,-9,LOG:12)
Block(4,12,-9,LEAVES:12)
Block(5,12,-9,LEAVES:12)
Block(6,12,-9,LEAVES:12)
Block(7,12,-9,LEAVES:12)
Block(8,12,-9,LEAVES:12)
Block(9,12,-9,LEAVES:12)
Block(10,12,-9,LEAVES:12)
Block(11,12,-9,LEAVES:12)
Block(-7,12,-8,LEAVES:12)
Block(-1,12,-8,LOG:12)
Block(0,12,-8,LOG:12)
Block(3,12,-8,LEAVES:12)
Block(4,12,-8,LEAVES:12)
Block(5,12,-8,LEAVES:12)
Block(6,12,-8,LEAVES:12)
Block(8,12,-8,LEAVES:12)
Block(9,12,-8,LEAVES:12)
Block(11,12,-8,LEAVES:12)
Block(3,12,-7,LEAVES:12)
Block(4,12,-7,LEAVES:12)
Block(6,12,-7,LOG:12)
Block(7,12,-7,LOG:12)
Block(-10,12,-6,LEAVES:12)
Block(-6,12,-6,LOG:12)
Block(5,12,-6,LEAVES:12)
Block(6,12,-6,LEAVES:12)
Block(7,12,-6,LEAVES:12)
Block(9,12,-6,LEAVES:12)
Block(10,12,-6,LEAVES:12)
Block(11,12,-6,LEAVES:12)
Block(-7,12,-5,LOG:12)
Block(-6,12,-5,LOG:12)
Block(4,12,-5,LEAVES:12)
Block(6,12,-5,LEAVES:12)
Block(9,12,-5,LEAVES:12)
Block(10,12,-5,LEAVES:12)
Block(-2,12,-4,LOG:12)
Block(-1,12,-4,LOG:12)
Block(6,12,-4,LEAVES:12)
Block(7,12,-4,LEAVES:12)
Block(10,12,-4,LEAVES:12)
Block(11,12,-4,LEAVES:12)
Block(-2,12,-3,LOG:12)
Block(-1,12,-3,LOG:12)
Block(9,12,-3,LEAVES:12)
Block(-3,12,-2,LOG:12)
Block(-2,12,-2,LOG:12)
Block(8,12,-2,LOG:12)
Block(7,12,-1,LOG:12)
Block(8,12,-1,LOG:12)
Block(9,12,-1,LOG:12)
Block(9,12,0,LOG:12)
Block(9,12,1,LOG:12)
Block(4,12,2,LOG:12)
Block(3,12,3,LOG:12)
Block(4,12,3,LOG:12)
Block(10,12,3,LEAVES:12)
Block(4,12,4,LOG:12)
Block(4,12,5,LOG:12)
Block(0,12,7,LEAVES:12)
Block(1,12,7,LEAVES:12)
Block(-2,12,9,LEAVES:12)
Block(-1,12,9,LEAVES:12)
Block(0,12,9,LEAVES:12)
Block(1,12,10,LEAVES:12)
Block(2,12,10,LEAVES:12)
Block(3,12,10,LEAVES:12)
Block(-2,12,11,LEAVES:12)
Block(-1,12,11,LEAVES:12)
Block(0,12,11,LEAVES:12)
Block(1,12,11,LEAVES:12)
Block(4,12,11,LEAVES:12)
Block(-1,12,12,LEAVES:12)
Block(0,12,12,LEAVES:12)
Block(1,12,12,LEAVES:12)
Block(3,12,12,LEAVES:12)
Block(-1,12,13,LEAVES:12)
Block(0,12,13,LEAVES:12)
Block(1,12,13,LEAVES:12)
Block(-8,13,-12,LEAVES:12)
Block(-9,13,-11,LEAVES:12)
Block(-8,13,-11,LEAVES:12)
Block(-7,13,-11,LEAVES:12)
Block(10,13,-11,LEAVES:12)
Block(-10,13,-10,LEAVES:12)
Block(-9,13,-10,LEAVES:12)
Block(-7,13,-10,LEAVES:12)
Block(8,13,-10,LEAVES:12)
Block(10,13,-10,LEAVES:12)
Block(12,13,-10,LEAVES:12)
Block(-9,13,-9,LEAVES:12)
Block(-7,13,-9,LEAVES:12)
Block(6,13,-9,LEAVES:12)
Block(9,13,-9,LEAVES:12)
Block(10,13,-9,LEAVES:12)
Block(11,13,-9,LEAVES:12)
Block(12,13,-9,LEAVES:12)
Block(-10,13,-8,LEAVES:12)
Block(-8,13,-8,LEAVES:12)
Block(-1,13,-8,LOG:12)
Block(5,13,-8,LEAVES:12)
Block(6,13,-8,LEAVES:12)
Block(7,13,-8,LEAVES:12)
Block(8,13,-8,LEAVES:12)
Block(10,13,-8,LEAVES:12)
Block(11,13,-8,LEAVES:12)
Block(12,13,-8,LEAVES:12)
Block(-2,13,-7,LOG:12)
Block(-1,13,-7,LOG:12)
Block(4,13,-7,LEAVES:12)
Block(6,13,-7,LEAVES:12)
Block(7,13,-7,LEAVES:12)
Block(8,13,-7,LEAVES:12)
Block(10,13,-7,LEAVES:12)
Block(11,13,-7,LEAVES:12)
Block(13,13,-7,LEAVES:12)
Block(-9,13,-6,LEAVES:12)
Block(-8,13,-6,LOG:12)
Block(-7,13,-6,LOG:12)
Block(5,13,-6,LEAVES:12)
Block(6,13,-6,LEAVES:12)
Block(8,13,-6,LEAVES:12)
Block(9,13,-6,LEAVES:12)
Block(10,13,-6,LEAVES:12)
Block(-9,13,-5,LOG:12)
Block(-8,13,-5,LOG:12)
Block(-7,13,-5,LOG:12)
Block(-3,13,-5,LOG:12)
Block(-2,13,-5,LOG:12)
Block(5,13,-5,LEAVES:12)
Block(8,13,-5,LEAVES:12)
Block(9,13,-5,LEAVES:12)
Block(11,13,-5,LEAVES:12)
Block(12,13,-5,LEAVES:12)
Block(-2,13,-4,LOG:12)
Block(-1,13,-4,LOG:12)
Block(9,13,-4,LEAVES:12)
Block(10,13,-4,LEAVES:12)
Block(11,13,-4,LEAVES:12)
Block(-11,13,-3,LEAVES:12)
Block(-2,13,-3,LOG:12)
Block(9,13,-3,LOG:12)
Block(10,13,-3,LOG:12)
Block(-9,13,-2,LEAVES:12)
Block(-4,13,-2,LOG:12)
Block(-3,13,-2,LOG:12)
Block(8,13,-2,LOG:12)
Block(9,13,-2,LOG:12)
Block(-4,13,-1,LOG:12)
Block(-3,13,-1,LOG:12)
Block(9,13,0,LOG:12)
Block(-9,13,1,LEAVES:12)
Block(9,13,1,LOG:12)
Block(10,13,1,LEAVES:12)
Block(-10,13,2,LEAVES:12)
Block(-7,13,2,LOG:12)
Block(10,13,2,LEAVES:12)
Block(-11,13,3,LEAVES:12)
Block(-10,13,3,LEAVES:12)
Block(-9,13,3,LEAVES:12)
Block(4,13,3,LOG:12)
Block(10,13,3,LEAVES:12)
Block(11,13,3,LEAVES:12)
Block(-9,13,4,LEAVES:12)
Block(-8,13,4,LEAVES:12)
Block(-7,13,4,LEAVES:12)
Block(3,13,4,LOG:12)
Block(4,13,4,LOG:12)
Block(9,13,4,LEAVES:12)
Block(10,13,4,LEAVES:12)
Block(11,13,4,LEAVES:12)
Block(-9,13,5,LEAVES:12)
Block(-8,13,5,LEAVES:12)
Block(-7,13,5,LEAVES:12)
Block(9,13,5,LEAVES:12)
Block(10,13,5,LEAVES:12)
Block(11,13,5,LEAVES:12)
Block(-8,13,6,LEAVES:12)
Block(-7,13,6,LEAVES:12)
Block(2,13,6,LEAVES:12)
Block(9,13,6,LEAVES:12)
Block(1,13,8,LEAVES:12)
Block(-2,13,9,LEAVES:12)
Block(0,13,9,LEAVES:12)
Block(1,13,9,LEAVES:12)
Block(-3,13,10,LEAVES:12)
Block(-2,13,10,LEAVES:12)
Block(-1,13,10,LEAVES:12)
Block(0,13,10,LEAVES:12)
Block(1,13,10,LEAVES:12)
Block(2,13,10,LEAVES:12)
Block(-2,13,11,LEAVES:12)
Block(-1,13,11,LEAVES:12)
Block(0,13,11,LEAVES:12)
Block(1,13,11,LEAVES:12)
Block(-2,13,12,LEAVES:12)
Block(-1,13,12,LEAVES:12)
Block(0,13,12,LEAVES:12)
Block(1,13,12,LEAVES:12)
Block(2,13,12,LEAVES:12)
Block(-2,13,13,LEAVES:12)
Block(-1,13,13,LEAVES:12)
Block(0,13,13,LEAVES:12)
Block(10,14,-11,LEAVES:12)
Block(11,14,-11,LEAVES:12)
Block(8,14,-10,LEAVES:12)
Block(9,14,-10,LEAVES:12)
Block(10,14,-10,LEAVES:12)
Block(11,14,-10,LEAVES:12)
Block(12,14,-10,LEAVES:12)
Block(-12,14,-9,LEAVES:12)
Block(-7,14,-9,LEAVES:12)
Block(5,14,-9,LEAVES:12)
Block(8,14,-9,LEAVES:12)
Block(9,14,-9,LEAVES:12)
Block(10,14,-9,LEAVES:12)
Block(11,14,-9,LEAVES:12)
Block(12,14,-9,LEAVES:12)
Block(-7,14,-8,LEAVES:12)
Block(5,14,-8,LEAVES:12)
Block(8,14,-8,LEAVES:12)
Block(9,14,-8,LEAVES:12)
Block(10,14,-8,LEAVES:12)
Block(11,14,-8,LEAVES:12)
Block(12,14,-8,LEAVES:12)
Block(-2,14,-7,LOG:12)
Block(5,14,-7,LEAVES:12)
Block(6,14,-7,LEAVES:12)
Block(7,14,-7,LEAVES:12)
Block(8,14,-7,LEAVES:12)
Block(9,14,-7,LEAVES:12)
Block(10,14,-7,LEAVES:12)
Block(11,14,-7,LEAVES:12)
Block(12,14,-7,LEAVES:12)
Block(-9,14,-6,LOG:12)
Block(-8,14,-6,LOG:12)
Block(-2,14,-6,LOG:12)
Block(9,14,-6,LEAVES:12)
Block(10,14,-6,LOG:12)
Block(12,14,-6,LEAVES:12)
Block(-9,14,-5,LOG:12)
Block(-2,14,-5,LOG:12)
Block(-1,14,-5,LOG:12)
Block(9,14,-5,LEAVES:12)
Block(10,14,-5,LOG:12)
Block(11,14,-5,LEAVES:12)
Block(12,14,-5,LEAVES:12)
Block(-12,14,-4,LEAVES:12)
Block(-11,14,-4,LEAVES:12)
Block(-9,14,-4,LOG:12)
Block(-8,14,-4,LEAVES:12)
Block(9,14,-4,LEAVES:12)
Block(10,14,-4,LOG:12)
Block(11,14,-4,LEAVES:12)
Block(12,14,-4,LEAVES:12)
Block(-10,14,-3,LEAVES:12)
Block(6,14,-3,LEAVES:12)
Block(9,14,-3,LOG:12)
Block(10,14,-3,LOG:12)
Block(12,14,-3,LEAVES:12)
Block(-11,14,-2,LEAVES:12)
Block(-10,14,-2,LEAVES:12)
Block(-4,14,-2,LOG:12)
Block(-4,14,-1,LOG:12)
Block(7,14,-1,LEAVES:12)
Block(-11,14,0,LEAVES:12)
Block(-10,14,0,LEAVES:12)
Block(-5,14,0,LOG:12)
Block(-4,14,0,LOG:12)
Block(-9,14,1,LEAVES:12)
Block(-7,14,1,LEAVES:12)
Block(9,14,1,LOG:12)
Block(10,14,1,LEAVES:12)
Block(11,14,1,LEAVES:12)
Block(-12,14,2,LEAVES:12)
Block(-10,14,2,LEAVES:12)
Block(-9,14,2,LEAVES:12)
Block(-7,14,2,LOG:12)
Block(-6,14,2,LOG:12)
Block(9,14,2,LOG:12)
Block(10,14,2,LOG:12)
Block(11,14,2,LEAVES:12)
Block(12,14,2,LEAVES:12)
Block(-12,14,3,LEAVES:12)
Block(-10,14,3,LEAVES:12)
Block(-9,14,3,LOG:12)
Block(-8,14,3,LOG:12)
Block(-7,14,3,LOG:12)
Block(8,14,3,LEAVES:12)
Block(9,14,3,LEAVES:12)
Block(10,14,3,LOG:12)
Block(11,14,3,LEAVES:12)
Block(-12,14,4,LEAVES:12)
Block(-11,14,4,LEAVES:12)
Block(-10,14,4,LEAVES:12)
Block(-8,14,4,LEAVES:12)
Block(3,14,4,LOG:12)
Block(4,14,4,LOG:12)
Block(8,14,4,LEAVES:12)
Block(9,14,4,LEAVES:12)
Block(10,14,4,LEAVES:12)
Block(11,14,4,LEAVES:12)
Block(-10,14,5,LEAVES:12)
Block(-9,14,5,LEAVES:12)
Block(-8,14,5,LEAVES:12)
Block(-7,14,5,LEAVES:12)
Block(-6,14,5,LEAVES:12)
Block(-1,14,5,LEAVES:12)
Block(2,14,5,LOG:12)
Block(3,14,5,LOG:12)
Block(8,14,5,LEAVES:12)
Block(9,14,5,LEAVES:12)
Block(10,14,5,LEAVES:12)
Block(11,14,5,LEAVES:12)
Block(12,14,5,LEAVES:12)
Block(-10,14,6,LEAVES:12)
Block(-9,14,6,LEAVES:12)
Block(-8,14,6,LEAVES:12)
Block(-7,14,6,LEAVES:12)
Block(-6,14,6,LEAVES:12)
Block(0,14,6,LEAVES:12)
Block(1,14,6,LOG:12)
Block(2,14,6,LOG:12)
Block(9,14,6,LEAVES:12)
Block(10,14,6,LEAVES:12)
Block(11,14,6,LEAVES:12)
Block(-8,14,7,LEAVES:12)
Block(1,14,7,LEAVES:12)
Block(9,14,7,LEAVES:12)
Block(10,14,7,LEAVES:12)
Block(11,14,7,LEAVES:12)
Block(-1,14,9,LEAVES:12)
Block(1,14,9,LEAVES:12)
Block(2,14,9,LEAVES:12)
Block(1,14,10,LEAVES:12)
Block(0,14,11,LEAVES:12)
Block(1,14,11,LEAVES:12)
Block(9,15,-11,LEAVES:12)
Block(10,15,-11,LEAVES:12)
Block(-6,15,-10,LEAVES:12)
Block(8,15,-10,LEAVES:12)
Block(10,15,-10,LEAVES:12)
Block(12,15,-10,LEAVES:12)
Block(-11,15,-9,LEAVES:12)
Block(8,15,-9,LEAVES:12)
Block(9,15,-9,LEAVES:12)
Block(10,15,-9,LEAVES:12)
Block(12,15,-9,LEAVES:12)
Block(-10,15,-8,LEAVES:12)
Block(11,15,-8,LEAVES:12)
Block(-11,15,-7,LEAVES:12)
Block(-9,15,-7,LEAVES:12)
Block(-8,15,-7,LOG:12)
Block(-6,15,-7,LEAVES:12)
Block(-5,15,-7,LEAVES:12)
Block(6,15,-7,LEAVES:12)
Block(7,15,-7,LEAVES:12)
Block(9,15,-7,LEAVES:12)
Block(10,15,-7,LEAVES:12)
Block(11,15,-7,LEAVES:12)
Block(-8,15,-6,LOG:12)
Block(-2,15,-6,LOG:12)
Block(-1,15,-6,LOG:12)
Block(5,15,-6,LEAVES:12)
Block(8,15,-6,LEAVES:12)
Block(9,15,-6,LEAVES:12)
Block(10,15,-6,LEAVES:12)
Block(12,15,-6,LEAVES:12)
Block(-11,15,-5,LEAVES:12)
Block(-10,15,-5,LEAVES:12)
Block(-9,15,-5,LEAVES:12)
Block(-8,15,-5,LEAVES:12)
Block(-1,15,-5,LOG:12)
Block(8,15,-5,LEAVES:12)
Block(9,15,-5,LEAVES:12)
Block(10,15,-5,LEAVES:12)
Block(-10,15,-4,LEAVES:12)
Block(-9,15,-4,LOG:12)
Block(8,15,-4,LEAVES:12)
Block(10,15,-4,LEAVES:12)
Block(11,15,-4,LEAVES:12)
Block(-13,15,-3,LEAVES:12)
Block(-12,15,-3,LEAVES:12)
Block(-11,15,-3,LEAVES:12)
Block(-10,15,-3,LOG:12)
Block(-9,15,-3,LOG:12)
Block(8,15,-3,LEAVES:12)
Block(9,15,-3,LEAVES:12)
Block(-11,15,-2,LEAVES:12)
Block(-10,15,-2,LEAVES:12)
Block(5,15,-2,LEAVES:12)
Block(6,15,-2,LEAVES:12)
Block(-11,15,-1,LEAVES:12)
Block(-4,15,-1,LOG:12)
Block(6,15,-1,LEAVES:12)
Block(-10,15,0,LEAVES:12)
Block(-9,15,0,LEAVES:12)
Block(-8,15,0,LEAVES:12)
Block(-6,15,0,LOG:12)
Block(-5,15,0,LOG:12)
Block(-4,15,0,LOG:12)
Block(-11,15,1,LEAVES:12)
Block(-10,15,1,LEAVES:12)
Block(-9,15,1,LEAVES:12)
Block(-8,15,1,LEAVES:12)
Block(-7,15,1,LEAVES:12)
Block(-6,15,1,LOG:12)
Block(-5,15,1,LOG:12)
Block(-4,15,1,LOG:12)
Block(9,15,1,LEAVES:12)
Block(10,15,1,LEAVES:12)
Block(-12,15,2,LEAVES:12)
Block(-11,15,2,LEAVES:12)
Block(-10,15,2,LOG:12)
Block(-9,15,2,LOG:12)
Block(-8,15,2,LEAVES:12)
Block(-6,15,2,LOG:12)
Block(8,15,2,LEAVES:12)
Block(12,15,2,LEAVES:12)
Block(-12,15,3,LEAVES:12)
Block(-11,15,3,LEAVES:12)
Block(-10,15,3,LEAVES:12)
Block(-9,15,3,LOG:12)
Block(-8,15,3,LOG:12)
Block(-7,15,3,LEAVES:12)
Block(-6,15,3,LEAVES:12)
Block(4,15,3,LOG:12)
Block(5,15,3,LOG:12)
Block(7,15,3,LEAVES:12)
Block(9,15,3,LEAVES:12)
Block(10,15,3,LOG:12)
Block(11,15,3,LEAVES:12)
Block(12,15,3,LEAVES:12)
Block(13,15,3,LEAVES:12)
Block(-11,15,4,LEAVES:12)
Block(-10,15,4,LEAVES:12)
Block(-9,15,4,LEAVES:12)
Block(-8,15,4,LEAVES:12)
Block(-7,15,4,LEAVES:12)
Block(-6,15,4,LEAVES:12)
Block(4,15,4,LOG:12)
Block(7,15,4,LEAVES:12)
Block(8,15,4,LEAVES:12)
Block(9,15,4,LEAVES:12)
Block(10,15,4,LOG:12)
Block(11,15,4,LEAVES:12)
Block(12,15,4,LEAVES:12)
Block(-11,15,5,LEAVES:12)
Block(-9,15,5,LEAVES:12)
Block(-8,15,5,LEAVES:12)
Block(-7,15,5,LEAVES:12)
Block(-6,15,5,LEAVES:12)
Block(0,15,5,LEAVES:12)
Block(6,15,5,LEAVES:12)
Block(8,15,5,LEAVES:12)
Block(9,15,5,LOG:12)
Block(10,15,5,LOG:12)
Block(11,15,5,LEAVES:12)
Block(12,15,5,LEAVES:12)
Block(-10,15,6,LEAVES:12)
Block(-8,15,6,LEAVES:12)
Block(-6,15,6,LEAVES:12)
Block(-3,15,6,LEAVES:12)
Block(1,15,6,LOG:12)
Block(2,15,6,LOG:12)
Block(8,15,6,LEAVES:12)
Block(9,15,6,LEAVES:12)
Block(11,15,6,LEAVES:12)
Block(-8,15,7,LEAVES:12)
Block(0,15,7,LOG:12)
Block(1,15,7,LOG:12)
Block(2,15,7,LEAVES:12)
Block(9,15,7,LEAVES:12)
Block(10,15,7,LEAVES:12)
Block(11,15,7,LEAVES:12)
Block(-1,15,9,LEAVES:12)
Block(0,15,9,LEAVES:12)
Block(-8,16,-13,LEAVES:12)
Block(-7,16,-12,LEAVES:12)
Block(-6,16,-12,LEAVES:12)
Block(-5,16,-12,LEAVES:12)
Block(-4,16,-12,LEAVES:12)
Block(3,16,-12,LEAVES:12)
Block(-6,16,-11,LEAVES:12)
Block(3,16,-11,LEAVES:12)
Block(-9,16,-10,LEAVES:12)
Block(2,16,-10,LEAVES:12)
Block(3,16,-10,LEAVES:12)
Block(10,16,-10,LEAVES:12)
Block(-9,16,-9,LEAVES:12)
Block(-8,16,-9,LOG:12)
Block(-7,16,-9,LOG:12)
Block(9,16,-9,LEAVES:12)
Block(10,16,-9,LEAVES:12)
Block(-8,16,-8,LOG:12)
Block(-7,16,-8,LEAVES:12)
Block(1,16,-8,LEAVES:12)
Block(9,16,-8,LEAVES:12)
Block(10,16,-8,LEAVES:12)
Block(11,16,-8,LEAVES:12)
Block(-8,16,-7,LOG:12)
Block(-7,16,-7,LEAVES:12)
Block(3,16,-7,LEAVES:12)
Block(7,16,-7,LEAVES:12)
Block(8,16,-7,LEAVES:12)
Block(9,16,-7,LEAVES:12)
Block(10,16,-7,LEAVES:12)
Block(11,16,-7,LEAVES:12)
Block(12,16,-7,LEAVES:12)
Block(-11,16,-6,LEAVES:12)
Block(-10,16,-6,LEAVES:12)
Block(-4,16,-6,LEAVES:12)
Block(-1,16,-6,LOG:12)
Block(0,16,-6,LOG:12)
Block(2,16,-6,LEAVES:12)
Block(8,16,-6,LEAVES:12)
Block(9,16,-6,LEAVES:12)
Block(10,16,-6,LEAVES:12)
Block(11,16,-6,LEAVES:12)
Block(-11,16,-5,LEAVES:12)
Block(-10,16,-5,LEAVES:12)
Block(-9,16,-5,LEAVES:12)
Block(-7,16,-5,LEAVES:12)
Block(0,16,-5,LOG:12)
Block(1,16,-5,LOG:12)
Block(2,16,-5,LEAVES:12)
Block(5,16,-5,LEAVES:12)
Block(7,16,-5,LEAVES:12)
Block(9,16,-5,LEAVES:12)
Block(11,16,-5,LEAVES:12)
Block(-12,16,-4,LEAVES:12)
Block(-11,16,-4,LEAVES:12)
Block(-10,16,-4,LEAVES:12)
Block(-9,16,-4,LEAVES:12)
Block(-7,16,-4,LEAVES:12)
Block(5,16,-4,LEAVES:12)
Block(8,16,-4,LEAVES:12)
Block(9,16,-4,LEAVES:12)
Block(-11,16,-3,LEAVES:12)
Block(-10,16,-3,LOG:12)
Block(-9,16,-3,LEAVES:12)
Block(-8,16,-3,LEAVES:12)
Block(-10,16,-2,LEAVES:12)
Block(-9,16,-2,LEAVES:12)
Block(-12,16,-1,LEAVES:12)
Block(-11,16,-1,LEAVES:12)
Block(-10,16,-1,LEAVES:12)
Block(-9,16,-1,LEAVES:12)
Block(5,16,-1,LEAVES:12)
Block(6,16,-1,LEAVES:12)
Block(-10,16,0,LEAVES:12)
Block(-9,16,0,LEAVES:12)
Block(-8,16,0,LEAVES:12)
Block(-4,16,0,LOG:12)
Block(4,16,0,LEAVES:12)
Block(7,16,0,LEAVES:12)
Block(-10,16,1,LEAVES:12)
Block(-8,16,1,LEAVES:12)
Block(-4,16,1,LOG:12)
Block(3,16,1,LEAVES:12)
Block(4,16,1,LEAVES:12)
Block(5,16,1,LEAVES:12)
Block(7,16,1,LEAVES:12)
Block(10,16,1,LEAVES:12)
Block(11,16,1,LEAVES:12)
Block(-11,16,2,LEAVES:12)
Block(-10,16,2,LOG:12)
Block(3,16,2,LEAVES:12)
Block(5,16,2,LOG:12)
Block(6,16,2,LOG:12)
Block(7,16,2,LEAVES:12)
Block(8,16,2,LEAVES:12)
Block(9,16,2,LEAVES:12)
Block(10,16,2,LEAVES:12)
Block(13,16,2,LEAVES:12)
Block(-11,16,3,LEAVES:12)
Block(-10,16,3,LEAVES:12)
Block(-9,16,3,LEAVES:12)
Block(-8,16,3,LEAVES:12)
Block(-7,16,3,LEAVES:12)
Block(5,16,3,LOG:12)
Block(7,16,3,LEAVES:12)
Block(8,16,3,LEAVES:12)
Block(11,16,3,LEAVES:12)
Block(12,16,3,LEAVES:12)
Block(13,16,3,LEAVES:12)
Block(-10,16,4,LEAVES:12)
Block(-8,16,4,LEAVES:12)
Block(-7,16,4,LEAVES:12)
Block(7,16,4,LEAVES:12)
Block(8,16,4,LEAVES:12)
Block(9,16,4,LEAVES:12)
Block(10,16,4,LEAVES:12)
Block(12,16,4,LEAVES:12)
Block(-12,16,5,LEAVES:12)
Block(-11,16,5,LEAVES:12)
Block(-10,16,5,LEAVES:12)
Block(-9,16,5,LEAVES:12)
Block(-8,16,5,LEAVES:12)
Block(-7,16,5,LEAVES:12)
Block(-6,16,5,LEAVES:12)
Block(0,16,5,LEAVES:12)
Block(2,16,5,LEAVES:12)
Block(7,16,5,LEAVES:12)
Block(8,16,5,LEAVES:12)
Block(9,16,5,LOG:12)
Block(10,16,5,LEAVES:12)
Block(12,16,5,LEAVES:12)
Block(-12,16,6,LEAVES:12)
Block(-8,16,6,LEAVES:12)
Block(-5,16,6,LEAVES:12)
Block(9,16,6,LOG:12)
Block(-8,16,7,LEAVES:12)
Block(-7,16,7,LEAVES:12)
Block(-2,16,7,LEAVES:12)
Block(-1,16,7,LOG:12)
Block(0,16,7,LOG:12)
Block(3,16,7,LEAVES:12)
Block(7,16,7,LEAVES:12)
Block(9,16,7,LEAVES:12)
Block(11,16,7,LEAVES:12)
Block(-1,16,8,LEAVES:12)
Block(0,16,8,LEAVES:12)
Block(1,16,8,LEAVES:12)
Block(3,16,8,LEAVES:12)
Block(-2,16,9,LEAVES:12)
Block(-1,16,9,LEAVES:12)
Block(0,16,9,LEAVES:12)
Block(1,16,9,LEAVES:12)
Block(2,16,10,LEAVES:12)
Block(-8,17,-13,LEAVES:12)
Block(-6,17,-13,LEAVES:12)
Block(3,17,-13,LEAVES:12)
Block(-8,17,-12,LEAVES:12)
Block(-6,17,-12,LEAVES:12)
Block(-5,17,-12,LEAVES:12)
Block(-3,17,-12,LEAVES:12)
Block(1,17,-12,LEAVES:12)
Block(3,17,-12,LEAVES:12)
Block(-6,17,-11,LEAVES:12)
Block(-4,17,-11,LEAVES:12)
Block(-3,17,-11,LEAVES:12)
Block(3,17,-11,LEAVES:12)
Block(4,17,-11,LEAVES:12)
Block(5,17,-11,LEAVES:12)
Block(-9,17,-10,LEAVES:12)
Block(-7,17,-10,LOG:12)
Block(-6,17,-10,LOG:12)
Block(-5,17,-10,LEAVES:12)
Block(2,17,-10,LEAVES:12)
Block(3,17,-10,LEAVES:12)
Block(4,17,-10,LEAVES:12)
Block(5,17,-10,LEAVES:12)
Block(-11,17,-9,LEAVES:12)
Block(-10,17,-9,LEAVES:12)
Block(-9,17,-9,LEAVES:12)
Block(-8,17,-9,LOG:12)
Block(-7,17,-9,LOG:12)
Block(-6,17,-9,LEAVES:12)
Block(2,17,-9,LEAVES:12)
Block(3,17,-9,LEAVES:12)
Block(4,17,-9,LEAVES:12)
Block(-7,17,-8,LEAVES:12)
Block(-5,17,-8,LEAVES:12)
Block(2,17,-8,LEAVES:12)
Block(8,17,-8,LEAVES:12)
Block(9,17,-8,LEAVES:12)
Block(10,17,-8,LEAVES:12)
Block(-10,17,-7,LEAVES:12)
Block(-9,17,-7,LEAVES:12)
Block(-7,17,-7,LEAVES:12)
Block(-5,17,-7,LEAVES:12)
Block(-1,17,-7,LOG:12)
Block(7,17,-7,LEAVES:12)
Block(8,17,-7,LEAVES:12)
Block(9,17,-7,LEAVES:12)
Block(10,17,-7,LEAVES:12)
Block(11,17,-7,LEAVES:12)
Block(-8,17,-6,LEAVES:12)
Block(-5,17,-6,LEAVES:12)
Block(-1,17,-6,LOG:12)
Block(3,17,-6,LEAVES:12)
Block(7,17,-6,LEAVES:12)
Block(8,17,-6,LEAVES:12)
Block(9,17,-6,LEAVES:12)
Block(10,17,-6,LEAVES:12)
Block(11,17,-6,LEAVES:12)
Block(1,17,-5,LOG:12)
Block(5,17,-5,LEAVES:12)
Block(7,17,-5,LEAVES:12)
Block(9,17,-5,LEAVES:12)
Block(10,17,-5,LEAVES:12)
Block(11,17,-5,LEAVES:12)
Block(-8,17,-4,LEAVES:12)
Block(1,17,-4,LOG:12)
Block(2,17,-4,LOG:12)
Block(4,17,-4,LEAVES:12)
Block(5,17,-4,LEAVES:12)
Block(8,17,-4,LEAVES:12)
Block(9,17,-4,LEAVES:12)
Block(10,17,-4,LEAVES:12)
Block(-12,17,-3,LEAVES:12)
Block(-11,17,-3,LEAVES:12)
Block(-10,17,-3,LEAVES:12)
Block(-9,17,-3,LEAVES:12)
Block(-3,17,-3,LEAVES:12)
Block(-2,17,-3,LEAVES:12)
Block(10,17,-3,LEAVES:12)
Block(-11,17,-2,LEAVES:12)
Block(-10,17,-2,LEAVES:12)
Block(-8,17,-2,LEAVES:12)
Block(5,17,-2,LEAVES:12)
Block(6,17,-2,LEAVES:12)
Block(7,17,-2,LEAVES:12)
Block(-10,17,-1,LEAVES:12)
Block(-3,17,-1,LEAVES:12)
Block(5,17,-1,LEAVES:12)
Block(6,17,-1,LEAVES:12)
Block(-11,17,0,LEAVES:12)
Block(3,17,0,LEAVES:12)
Block(5,17,0,LEAVES:12)
Block(-4,17,1,LOG:12)
Block(2,17,1,LEAVES:12)
Block(5,17,1,LEAVES:12)
Block(6,17,1,LEAVES:12)
Block(-11,17,2,LEAVES:12)
Block(-10,17,2,LEAVES:12)
Block(-9,17,2,LEAVES:12)
Block(-8,17,2,LEAVES:12)
Block(-4,17,2,LOG:12)
Block(2,17,2,LEAVES:12)
Block(6,17,2,LOG:12)
Block(7,17,2,LOG:12)
Block(8,17,2,LEAVES:12)
Block(9,17,2,LEAVES:12)
Block(10,17,2,LEAVES:12)
Block(-10,17,3,LEAVES:12)
Block(-9,17,3,LEAVES:12)
Block(-8,17,3,LEAVES:12)
Block(-7,17,3,LEAVES:12)
Block(7,17,3,LEAVES:12)
Block(8,17,3,LEAVES:12)
Block(9,17,3,LEAVES:12)
Block(10,17,3,LEAVES:12)
Block(12,17,3,LEAVES:12)
Block(-10,17,4,LEAVES:12)
Block(-9,17,4,LEAVES:12)
Block(-8,17,4,LEAVES:12)
Block(-7,17,4,LEAVES:12)
Block(-6,17,4,LEAVES:12)
Block(0,17,4,LEAVES:12)
Block(6,17,4,LEAVES:12)
Block(7,17,4,LEAVES:12)
Block(10,17,4,LEAVES:12)
Block(11,17,4,LEAVES:12)
Block(12,17,4,LEAVES:12)
Block(-11,17,5,LEAVES:12)
Block(-10,17,5,LEAVES:12)
Block(-9,17,5,LEAVES:12)
Block(-8,17,5,LEAVES:12)
Block(-7,17,5,LEAVES:12)
Block(-6,17,5,LEAVES:12)
Block(-1,17,5,LEAVES:12)
Block(0,17,5,LEAVES:12)
Block(7,17,5,LEAVES:12)
Block(9,17,5,LEAVES:12)
Block(10,17,5,LEAVES:12)
Block(11,17,5,LEAVES:12)
Block(-11,17,6,LEAVES:12)
Block(-9,17,6,LEAVES:12)
Block(-8,17,6,LEAVES:12)
Block(-7,17,6,LEAVES:12)
Block(-1,17,6,LOG:12)
Block(0,17,6,LEAVES:12)
Block(1,17,6,LEAVES:12)
Block(9,17,6,LEAVES:12)
Block(10,17,6,LEAVES:12)
Block(-8,17,7,LEAVES:12)
Block(-7,17,7,LEAVES:12)
Block(-1,17,7,LOG:12)
Block(0,17,7,LEAVES:12)
Block(1,17,7,LEAVES:12)
Block(-1,17,8,LEAVES:12)
Block(0,17,8,LEAVES:12)
Block(-1,17,9,LEAVES:12)
Block(0,17,9,LEAVES:12)
Block(2,17,9,LEAVES:12)
Block(-2,17,10,LEAVES:12)
Block(-1,17,10,LEAVES:12)
Block(0,17,10,LEAVES:12)
Block(1,17,10,LEAVES:12)
Block(-1,17,11,LEAVES:12)
Block(0,17,11,LEAVES:12)
Block(-7,18,-14,LEAVES:12)
Block(-6,18,-14,LEAVES:12)
Block(-8,18,-13,LEAVES:12)
Block(-7,18,-13,LEAVES:12)
Block(-4,18,-13,LEAVES:12)
Block(3,18,-13,LEAVES:12)
Block(4,18,-13,LEAVES:12)
Block(-8,18,-12,LEAVES:12)
Block(-6,18,-12,LOG:12)
Block(-5,18,-12,LEAVES:12)
Block(-4,18,-12,LEAVES:12)
Block(-3,18,-12,LEAVES:12)
Block(2,18,-12,LEAVES:12)
Block(3,18,-12,LEAVES:12)
Block(4,18,-12,LEAVES:12)
Block(5,18,-12,LEAVES:12)
Block(-8,18,-11,LEAVES:12)
Block(-7,18,-11,LEAVES:12)
Block(-6,18,-11,LOG:12)
Block(-5,18,-11,LEAVES:12)
Block(-3,18,-11,LEAVES:12)
Block(1,18,-11,LEAVES:12)
Block(2,18,-11,LEAVES:12)
Block(3,18,-11,LOG:12)
Block(5,18,-11,LEAVES:12)
Block(-9,18,-10,LEAVES:12)
Block(-7,18,-10,LEAVES:12)
Block(-6,18,-10,LOG:12)
Block(-5,18,-10,LEAVES:12)
Block(-4,18,-10,LEAVES:12)
Block(2,18,-10,LOG:12)
Block(3,18,-10,LOG:12)
Block(4,18,-10,LEAVES:12)
Block(5,18,-10,LEAVES:12)
Block(-10,18,-9,LEAVES:12)
Block(-9,18,-9,LEAVES:12)
Block(-4,18,-9,LEAVES:12)
Block(1,18,-9,LEAVES:12)
Block(2,18,-9,LOG:12)
Block(3,18,-9,LEAVES:12)
Block(4,18,-9,LEAVES:12)
Block(5,18,-9,LEAVES:12)
Block(-11,18,-8,LEAVES:12)
Block(-5,18,-8,LEAVES:12)
Block(-1,18,-8,LOG:12)
Block(0,18,-8,LOG:12)
Block(2,18,-8,LEAVES:12)
Block(3,18,-8,LEAVES:12)
Block(8,18,-8,LEAVES:12)
Block(9,18,-8,LEAVES:12)
Block(10,18,-8,LEAVES:12)
Block(-10,18,-7,LEAVES:12)
Block(-9,18,-7,LEAVES:12)
Block(-8,18,-7,LEAVES:12)
Block(-1,18,-7,LOG:12)
Block(2,18,-7,LEAVES:12)
Block(3,18,-7,LEAVES:12)
Block(7,18,-7,LEAVES:12)
Block(8,18,-7,LEAVES:12)
Block(9,18,-7,LEAVES:12)
Block(10,18,-7,LEAVES:12)
Block(11,18,-7,LEAVES:12)
Block(-11,18,-6,LEAVES:12)
Block(-7,18,-6,LEAVES:12)
Block(-6,18,-6,LEAVES:12)
Block(-1,18,-6,LEAVES:12)
Block(5,18,-6,LEAVES:12)
Block(7,18,-6,LEAVES:12)
Block(8,18,-6,LEAVES:12)
Block(9,18,-6,LEAVES:12)
Block(10,18,-6,LEAVES:12)
Block(11,18,-6,LEAVES:12)
Block(-10,18,-5,LEAVES:12)
Block(-9,18,-5,LEAVES:12)
Block(-1,18,-5,LEAVES:12)
Block(7,18,-5,LEAVES:12)
Block(10,18,-5,LEAVES:12)
Block(-11,18,-4,LEAVES:12)
Block(-10,18,-4,LEAVES:12)
Block(2,18,-4,LOG:12)
Block(9,18,-4,LEAVES:12)
Block(-11,18,-3,LEAVES:12)
Block(-10,18,-3,LEAVES:12)
Block(-9,18,-3,LEAVES:12)
Block(-8,18,-3,LEAVES:12)
Block(-2,18,-3,LEAVES:12)
Block(2,18,-3,LOG:12)
Block(3,18,-3,LEAVES:12)
Block(4,18,-3,LEAVES:12)
Block(8,18,-3,LEAVES:12)
Block(10,18,-3,LEAVES:12)
Block(-11,18,-2,LEAVES:12)
Block(-10,18,-2,LEAVES:12)
Block(-8,18,-2,LEAVES:12)
Block(-2,18,-2,LEAVES:12)
Block(-1,18,-2,LEAVES:12)
Block(0,18,-2,LEAVES:12)
Block(2,18,-2,LEAVES:12)
Block(3,18,-2,LEAVES:12)
Block(-2,18,0,LEAVES:12)
Block(3,18,0,LEAVES:12)
Block(5,18,0,LEAVES:12)
Block(7,18,0,LEAVES:12)
Block(1,18,1,LEAVES:12)
Block(4,18,1,LEAVES:12)
Block(5,18,1,LEAVES:12)
Block(6,18,1,LEAVES:12)
Block(7,18,1,LEAVES:12)
Block(8,18,1,LEAVES:12)
Block(-4,18,2,LOG:12)
Block(5,18,2,LEAVES:12)
Block(6,18,2,LEAVES:12)
Block(7,18,2,LOG:12)
Block(8,18,2,LEAVES:12)
Block(9,18,2,LEAVES:12)
Block(10,18,2,LEAVES:12)
Block(-11,18,3,LEAVES:12)
Block(-10,18,3,LEAVES:12)
Block(-9,18,3,LEAVES:12)
Block(-5,18,3,LOG:12)
Block(-4,18,3,LOG:12)
Block(2,18,3,LEAVES:12)
Block(7,18,3,LOG:12)
Block(8,18,3,LOG:12)
Block(9,18,3,LEAVES:12)
Block(10,18,3,LEAVES:12)
Block(11,18,3,LEAVES:12)
Block(-10,18,4,LEAVES:12)
Block(-5,18,4,LEAVES:12)
Block(-1,18,4,LEAVES:12)
Block(0,18,4,LEAVES:12)
Block(4,18,4,LEAVES:12)
Block(7,18,4,LEAVES:12)
Block(8,18,4,LOG:12)
Block(9,18,4,LEAVES:12)
Block(-6,18,5,LEAVES:12)
Block(-5,18,5,LEAVES:12)
Block(-2,18,5,LEAVES:12)
Block(1,18,5,LEAVES:12)
Block(3,18,5,LEAVES:12)
Block(7,18,5,LEAVES:12)
Block(8,18,5,LEAVES:12)
Block(9,18,5,LEAVES:12)
Block(11,18,5,LEAVES:12)
Block(-4,18,6,LEAVES:12)
Block(-3,18,6,LEAVES:12)
Block(-2,18,6,LEAVES:12)
Block(-1,18,6,LOG:12)
Block(0,18,6,LOG:12)
Block(1,18,6,LEAVES:12)
Block(2,18,6,LEAVES:12)
Block(7,18,6,LEAVES:12)
Block(9,18,6,LEAVES:12)
Block(-3,18,7,LEAVES:12)
Block(-1,18,7,LEAVES:12)
Block(0,18,7,LEAVES:12)
Block(9,18,7,LEAVES:12)
Block(-9,18,8,LEAVES:12)
Block(-3,18,8,LEAVES:12)
Block(-2,18,8,LEAVES:12)
Block(-1,18,8,LEAVES:12)
Block(0,18,8,LEAVES:12)
Block(-2,18,9,LEAVES:12)
Block(-1,18,9,LEAVES:12)
Block(1,18,9,LEAVES:12)
Block(-1,18,10,LEAVES:12)
Block(0,18,10,LEAVES:12)
Block(0,18,11,LEAVES:12)
Block(1,18,11,LEAVES:12)
Block(-7,19,-14,LEAVES:12)
Block(-7,19,-13,LEAVES:12)
Block(-5,19,-13,LEAVES:12)
Block(2,19,-13,LEAVES:12)
Block(4,19,-13,LEAVES:12)
Block(-9,19,-12,LEAVES:12)
Block(-8,19,-12,LEAVES:12)
Block(-6,19,-12,LEAVES:12)
Block(-5,19,-12,LEAVES:12)
Block(1,19,-12,LEAVES:12)
Block(2,19,-12,LEAVES:12)
Block(-7,19,-11,LEAVES:12)
Block(-5,19,-11,LEAVES:12)
Block(0,19,-11,LEAVES:12)
Block(1,19,-11,LEAVES:12)
Block(2,19,-11,LEAVES:12)
Block(3,19,-11,LEAVES:12)
Block(4,19,-11,LEAVES:12)
Block(0,19,-10,LEAVES:12)
Block(2,19,-10,LEAVES:12)
Block(3,19,-10,LEAVES:12)
Block(4,19,-10,LEAVES:12)
Block(5,19,-10,LEAVES:12)
Block(-7,19,-9,LEAVES:12)
Block(1,19,-9,LEAVES:12)
Block(2,19,-9,LOG:12)
Block(3,19,-9,LEAVES:12)
Block(4,19,-9,LEAVES:12)
Block(0,19,-8,LOG:12)
Block(1,19,-8,LOG:12)
Block(2,19,-8,LOG:12)
Block(3,19,-8,LEAVES:12)
Block(4,19,-8,LEAVES:12)
Block(-10,19,-7,LEAVES:12)
Block(-9,19,-7,LEAVES:12)
Block(3,19,-7,LEAVES:12)
Block(8,19,-7,LEAVES:12)
Block(9,19,-7,LEAVES:12)
Block(2,19,-6,LEAVES:12)
Block(8,19,-6,LEAVES:12)
Block(9,19,-6,LEAVES:12)
Block(10,19,-6,LEAVES:12)
Block(-6,19,-5,LEAVES:12)
Block(2,19,-5,LEAVES:12)
Block(3,19,-5,LEAVES:12)
Block(4,19,-5,LEAVES:12)
Block(5,19,-5,LEAVES:12)
Block(9,19,-5,LEAVES:12)
Block(-9,19,-4,LEAVES:12)
Block(0,19,-4,LEAVES:12)
Block(2,19,-4,LEAVES:12)
Block(3,19,-4,LEAVES:12)
Block(-3,19,-3,LEAVES:12)
Block(1,19,-3,LOG:12)
Block(2,19,-3,LOG:12)
Block(3,19,-3,LEAVES:12)
Block(4,19,-3,LEAVES:12)
Block(-11,19,-2,LEAVES:12)
Block(-4,19,-2,LEAVES:12)
Block(-2,19,-2,LEAVES:12)
Block(1,19,-2,LOG:12)
Block(2,19,-2,LOG:12)
Block(3,19,-2,LEAVES:12)
Block(-11,19,-1,LEAVES:12)
Block(-6,19,-1,LEAVES:12)
Block(-4,19,-1,LEAVES:12)
Block(-2,19,-1,LEAVES:12)
Block(0,19,-1,LEAVES:12)
Block(2,19,-1,LEAVES:12)
Block(3,19,-1,LEAVES:12)
Block(4,19,-1,LEAVES:12)
Block(6,19,-1,LEAVES:12)
Block(-3,19,0,LEAVES:12)
Block(-2,19,0,LEAVES:12)
Block(1,19,0,LEAVES:12)
Block(2,19,0,LEAVES:12)
Block(3,19,0,LEAVES:12)
Block(5,19,0,LEAVES:12)
Block(-1,19,1,LEAVES:12)
Block(1,19,1,LEAVES:12)
Block(4,19,1,LEAVES:12)
Block(7,19,1,LEAVES:12)
Block(8,19,1,LEAVES:12)
Block(9,19,1,LEAVES:12)
Block(-8,19,2,LEAVES:12)
Block(-2,19,2,LEAVES:12)
Block(2,19,2,LEAVES:12)
Block(3,19,2,LEAVES:12)
Block(6,19,2,LEAVES:12)
Block(8,19,2,LEAVES:12)
Block(-5,19,3,LOG:12)
Block(-2,19,3,LEAVES:12)
Block(-1,19,3,LEAVES:12)
Block(0,19,3,LEAVES:12)
Block(6,19,3,LEAVES:12)
Block(8,19,3,LEAVES:12)
Block(10,19,3,LEAVES:12)
Block(-8,19,4,LEAVES:12)
Block(-7,19,4,LEAVES:12)
Block(-6,19,4,LOG:12)
Block(-5,19,4,LOG:12)
Block(-4,19,4,LEAVES:12)
Block(1,19,4,LOG:12)
Block(-8,19,5,LEAVES:12)
Block(-6,19,5,LEAVES:12)
Block(-3,19,5,LEAVES:12)
Block(-1,19,5,LEAVES:12)
Block(0,19,5,LOG:12)
Block(1,19,5,LOG:12)
Block(9,19,5,LEAVES:12)
Block(10,19,5,LEAVES:12)
Block(-7,19,6,LEAVES:12)
Block(-5,19,6,LEAVES:12)
Block(-2,19,6,LEAVES:12)
Block(-1,19,6,LEAVES:12)
Block(0,19,6,LOG:12)
Block(1,19,6,LEAVES:12)
Block(2,19,6,LEAVES:12)
Block(9,19,6,LEAVES:12)
Block(10,19,6,LEAVES:12)
Block(-2,19,7,LEAVES:12)
Block(-1,19,7,LEAVES:12)
Block(0,19,7,LEAVES:12)
Block(1,19,7,LEAVES:12)
Block(2,19,7,LEAVES:12)
Block(-2,19,8,LEAVES:12)
Block(-1,19,8,LEAVES:12)
Block(0,19,8,LEAVES:12)
Block(1,19,8,LEAVES:12)
Block(-4,19,9,LEAVES:12)
Block(-1,19,9,LEAVES:12)
Block(0,19,9,LEAVES:12)
Block(1,19,9,LEAVES:12)
Block(0,19,10,LEAVES:12)
Block(-7,20,-13,LEAVES:12)
Block(-7,20,-12,LEAVES:12)
Block(-6,20,-12,LEAVES:12)
Block(-5,20,-12,LEAVES:12)
Block(2,20,-12,LEAVES:12)
Block(4,20,-12,LEAVES:12)
Block(-6,20,-11,LEAVES:12)
Block(2,20,-11,LEAVES:12)
Block(3,20,-11,LEAVES:12)
Block(-6,20,-10,LEAVES:12)
Block(3,20,-10,LEAVES:12)
Block(4,20,-10,LEAVES:12)
Block(-5,20,-9,LEAVES:12)
Block(1,20,-9,LEAVES:12)
Block(2,20,-9,LEAVES:12)
Block(3,20,-9,LEAVES:12)
Block(4,20,-9,LEAVES:12)
Block(-9,20,-8,LEAVES:12)
Block(-7,20,-8,LEAVES:12)
Block(3,20,-8,LEAVES:12)
Block(4,20,-8,LEAVES:12)
Block(-9,20,-7,LEAVES:12)
Block(-7,20,-7,LEAVES:12)
Block(-9,20,-6,LEAVES:12)
Block(-7,20,-6,LEAVES:12)
Block(-1,20,-6,LEAVES:12)
Block(2,20,-5,LEAVES:12)
Block(3,20,-5,LEAVES:12)
Block(0,20,-4,LEAVES:12)
Block(1,20,-4,LEAVES:12)
Block(2,20,-4,LEAVES:12)
Block(4,20,-4,LEAVES:12)
Block(0,20,-3,LEAVES:12)
Block(1,20,-3,LEAVES:12)
Block(2,20,-3,LOG:12)
Block(3,20,-3,LEAVES:12)
Block(4,20,-3,LEAVES:12)
Block(5,20,-3,LEAVES:12)
Block(-10,20,-2,LEAVES:12)
Block(-5,20,-2,LEAVES:12)
Block(-4,20,-2,LEAVES:12)
Block(-3,20,-2,LEAVES:12)
Block(-2,20,-2,LEAVES:12)
Block(-1,20,-2,LEAVES:12)
Block(0,20,-2,LEAVES:12)
Block(1,20,-2,LOG:12)
Block(2,20,-2,LEAVES:12)
Block(3,20,-2,LEAVES:12)
Block(-4,20,-1,LEAVES:12)
Block(-1,20,-1,LEAVES:12)
Block(0,20,-1,LOG:12)
Block(1,20,-1,LOG:12)
Block(2,20,-1,LEAVES:12)
Block(4,20,-1,LEAVES:12)
Block(6,20,-1,LEAVES:12)
Block(-4,20,0,LEAVES:12)
Block(-3,20,0,LEAVES:12)
Block(-1,20,0,LEAVES:12)
Block(0,20,0,LOG:12)
Block(2,20,0,LEAVES:12)
Block(-6,20,1,LEAVES:12)
Block(0,20,1,LEAVES:12)
Block(1,20,1,LEAVES:12)
Block(3,20,1,LEAVES:12)
Block(4,20,1,LEAVES:12)
Block(7,20,1,LEAVES:12)
Block(-8,20,2,LEAVES:12)
Block(-5,20,2,LEAVES:12)
Block(1,20,2,LEAVES:12)
Block(2,20,2,LOG:12)
Block(9,20,2,LEAVES:12)
Block(-8,20,3,LOG:12)
Block(-7,20,3,LOG:12)
Block(-6,20,3,LEAVES:12)
Block(-5,20,3,LEAVES:12)
Block(-4,20,3,LEAVES:12)
Block(0,20,3,LEAVES:12)
Block(1,20,3,LOG:12)
Block(2,20,3,LOG:12)
Block(7,20,3,LEAVES:12)
Block(9,20,3,LEAVES:12)
Block(-9,20,4,LEAVES:12)
Block(-8,20,4,LEAVES:12)
Block(-7,20,4,LOG:12)
Block(-6,20,4,LOG:12)
Block(-5,20,4,LEAVES:12)
Block(0,20,4,LEAVES:12)
Block(1,20,4,LOG:12)
Block(2,20,4,LEAVES:12)
Block(7,20,4,LEAVES:12)
Block(-9,20,5,LEAVES:12)
Block(-6,20,5,LEAVES:12)
Block(-3,20,5,LEAVES:12)
Block(1,20,5,LEAVES:12)
Block(2,20,5,LEAVES:12)
Block(3,20,5,LEAVES:12)
Block(-8,20,6,LEAVES:12)
Block(-5,20,6,LEAVES:12)
Block(-2,20,6,LEAVES:12)
Block(-1,20,6,LEAVES:12)
Block(0,20,6,LEAVES:12)
Block(1,20,6,LEAVES:12)
Block(2,20,6,LEAVES:12)
Block(-7,20,7,LEAVES:12)
Block(1,20,7,LEAVES:12)
Block(-5,20,8,LEAVES:12)
Block(1,20,8,LEAVES:12)
Block(-6,21,-12,LEAVES:12)
Block(2,21,-11,LEAVES:12)
Block(4,21,-11,LEAVES:12)
Block(2,21,-10,LEAVES:12)
Block(0,21,-9,LEAVES:12)
Block(1,21,-9,LEAVES:12)
Block(4,21,-9,LEAVES:12)
Block(4,21,-7,LEAVES:12)
Block(-10,21,-6,LEAVES:12)
Block(3,21,-6,LEAVES:12)
Block(2,21,-5,LEAVES:12)
Block(0,21,-4,LEAVES:12)
Block(1,21,-4,LEAVES:12)
Block(2,21,-4,LEAVES:12)
Block(3,21,-4,LEAVES:12)
Block(-2,21,-3,LEAVES:12)
Block(1,21,-3,LEAVES:12)
Block(2,21,-3,LEAVES:12)
Block(3,21,-3,LEAVES:12)
Block(4,21,-3,LEAVES:12)
Block(-5,21,-2,LEAVES:12)
Block(-3,21,-2,LEAVES:12)
Block(-2,21,-2,LEAVES:12)
Block(-1,21,-2,LEAVES:12)
Block(0,21,-2,LEAVES:12)
Block(1,21,-2,LEAVES:12)
Block(2,21,-2,LEAVES:12)
Block(-6,21,-1,LEAVES:12)
Block(-1,21,-1,LEAVES:12)
Block(1,21,-1,LEAVES:12)
Block(-6,21,0,LEAVES:12)
Block(-1,21,0,LEAVES:12)
Block(5,21,0,LEAVES:12)
Block(-5,21,1,LEAVES:12)
Block(0,21,1,LEAVES:12)
Block(2,21,1,LEAVES:12)
Block(6,21,1,LEAVES:12)
Block(-8,21,2,LEAVES:12)
Block(2,21,2,LEAVES:12)
Block(4,21,2,LEAVES:12)
Block(5,21,2,LEAVES:12)
Block(7,21,2,LEAVES:12)
Block(-8,21,3,LEAVES:12)
Block(-6,21,3,LEAVES:12)
Block(-3,21,3,LEAVES:12)
Block(-6,21,4,LEAVES:12)
Block(-2,21,4,LEAVES:12)
Block(0,21,4,LEAVES:12)
Block(-6,21,6,LEAVES:12)
Block(-4,21,6,LEAVES:12)
Block(-2,21,6,LEAVES:12)
Block(0,21,6,LEAVES:12)
Block(1,21,6,LEAVES:12)
Block(-3,21,7,LEAVES:12)
Block(-1,21,7,LEAVES:12)
Block(0,21,7,LEAVES:12)
Block(1,21,7,LEAVES:12)
Block(0,21,8,LEAVES:12)
Block(2,22,-9,LEAVES:12)
Block(3,22,-9,LEAVES:12)
Block(3,22,-7,LEAVES:12)
Block(0,22,-5,LEAVES:12)
Block(-4,22,-4,LEAVES:12)
Block(-1,22,-4,LEAVES:12)
Block(1,22,-4,LEAVES:12)
Block(2,22,-4,LEAVES:12)
Block(-4,22,-3,LEAVES:12)
Block(1,22,-3,LEAVES:12)
Block(2,22,-3,LEAVES:12)
Block(3,22,-3,LEAVES:12)
Block(-3,22,-2,LEAVES:12)
Block(-1,22,-2,LEAVES:12)
Block(0,22,-2,LEAVES:12)
Block(1,22,-2,LEAVES:12)
Block(4,22,-2,LEAVES:12)
Block(-1,22,-1,LEAVES:12)
Block(1,22,-1,LEAVES:12)
Block(-4,22,0,LEAVES:12)
Block(-3,22,0,LEAVES:12)
Block(4,22,0,LEAVES:12)
Block(2,22,1,LEAVES:12)
Block(4,22,1,LEAVES:12)
Block(5,22,1,LEAVES:12)
Block(-8,22,2,LEAVES:12)
Block(-6,22,3,LEAVES:12)
Block(3,22,3,LEAVES:12)
Block(-6,22,4,LEAVES:12)
Block(-5,22,4,LEAVES:12)
Block(-4,22,4,LEAVES:12)
Block(-6,22,5,LEAVES:12)
Block(-4,22,5,LEAVES:12)
Block(0,22,5,LEAVES:12)
Block(-4,22,6,LEAVES:12)
Block(0,22,7,LEAVES:12)
Block(1,23,-3,LEAVES:12)
Block(0,23,-2,LEAVES:12)
Block(1,23,-2,LEAVES:12)

#######################################################################
# +-----------------------------------------------------------------+ #
# |                            BO3 checks                           | #
# +-----------------------------------------------------------------+ #
#######################################################################

# Require a condition at a certain location in order for the BO3 to be spawned.
# BlockCheck(x,y,z,BlockName[,BlockName[,...]]) - one of the blocks must be at the location
# BlockCheckNot(x,y,z,BlockName[,BlockName[,...]]) - all the blocks must not be at the location
# LightCheck(x,y,z,minLightLevel,maxLightLevel) - light must be between min and max (inclusive)

# You can use "Solid" as a BlockName for matching all solid blocks or "All" to match all blocks that aren't air.

# Examples:
BlockCheck(0,-1,0,GRASS,DIRT,DIRT:2,STONE)
#   BlockCheck(0,-1,0,Solid)       Require any solid block just below the object
#   BlockCheck(0,-1,0,WOOL)        Require any type of wool just below the object
#   BlockCheck(0,-1,0,WOOL:0)      Require white wool just below the object
#   BlockCheckNot(0,-1,0,WOOL:0)   Require that there is no white wool below the object
#   LightCheck(0,0,0,0,1)          Require almost complete darkness just below the object

#######################################################################
# +-----------------------------------------------------------------+ #
# |                             Branches                            | #
# +-----------------------------------------------------------------+ #
#######################################################################

# Branches are objects that will spawn when this object spawns when it is used in
# the CustomStructure resource. Branches can also have branches, making complex
# structures possible. See the wiki for more details.

# Regular Branches spawn each branch with an independent chance of spawning.
# Branch(x,y,z,branchName,rotation,chance[,anotherBranchName,rotation,chance[,...]][IndividualChance])
# branchName - name of the object to spawn.
# rotation - NORTH, SOUTH, EAST or WEST.
# IndividualChance - The chance each branch has to spawn, assumed to be 100 when left blank

# Weighted Branches spawn branches with a dependent chance of spawning.
# WeightedBranch(x,y,z,branchName,rotation,chance[,anotherBranchName,rotation,chance[,...]][MaxChanceOutOf])
# MaxChanceOutOf - The chance all branches have to spawn out of, assumed to be 100 when left blank
