#######################################################################
# +-----------------------------------------------------------------+ #
# |                            BO3 object                           | #
# +-----------------------------------------------------------------+ #
#######################################################################

# The descriptions in this file are accurate only for TerrainControl and OTG.
# For MCW and OTG+ these descriptions are only accurate if the BO3 is used as a CustomObject.
# MCW and OTG+ completely reimplemented CustomStructure, check the MCW/OTG+ documentation for more information.

# This is the config file of a custom object.
# If you add this object correctly to your BiomeConfigs, it will spawn in the world.

# This is the creator of this BO3 object
Author: Unknown

# A short description of this BO3 object
Description: This BO3 was converted from a schematic using OTGEdit. The author and description information of the schematic could not be found. If you know who the author of the schematic is then please add this information.

# The BO3 version, don't change this! It can be used by external applications to do a version check.
Version: 3

# The settings mode, WriteAll, WriteWithoutComments or WriteDisable. See WorldConfig.
SettingsMode: WriteDisable

#######################################################################
# +-----------------------------------------------------------------+ #
# |                          Main settings                          | #
# +-----------------------------------------------------------------+ #
#######################################################################

# This needs to be set to true to spawn the object in the Tree and Sapling resources.
Tree: true

# The frequency of the BO3 from 1 to 200. Tries this many times to spawn this BO3 when using the CustomObject(...) resource.
# Ignored by Tree(..), Sapling(..) and CustomStructure(..)
Frequency: 40

# The rarity of the BO3 from 0 to 100. Each spawn attempt has rarity% chance to succeed when using the CustomObject(...) resource.
# Ignored by Tree(..), Sapling(..) and CustomStructure(..)
Rarity: 100.0

# If you set this to true, the BO3 will be placed with a random rotation.
RotateRandomly: true

# The spawn height of the BO3 - randomY, highestBlock or highestSolidBlock.
SpawnHeight: highestSolidBlock

# The height limits for the BO3.
MinHeight: 0

MaxHeight: 256

# Objects can have other objects attached to it: branches. Branches can also
# have branches attached to it, which can also have branches, etc. This is the
# maximum branch depth for this objects.
MaxBranchDepth: 10

# When spawned with the UseWorld keyword, this BO3 should NOT spawn in the following biomes.
# If you writer.write the BO3 name directly in the BiomeConfigs, this will be ignored.
ExcludedBiomes: All

# To optimise this BO3 for faster loading times you can use Notepad++ to find/replace comments and abbreviate things.
# Notepad++ find/replace with regex:
# Find: ^[#;].* replace to nothing removes all lines starting with # 
# Find: ^\s*$ replace to nothing removes most empty lines 
# Notepad++ find/replace without regex:
# *Warning: This will only work for OTG 1.10.2 v21 / OTG 1.11.2 v6 or higher. B( is not recognised by lower versions.
# Find: Block( replace to B(

#######################################################################
# +-----------------------------------------------------------------+ #
# |                      Source block settings                      | #
# +-----------------------------------------------------------------+ #
#######################################################################

# The block(s) the BO3 should spawn in.
SourceBlocks: AIR

# The maximum percentage of the BO3 that can be outside the SourceBlock.
# The BO3 won't be placed on a location with more blocks outside the SourceBlock than this percentage.
MaxPercentageOutsideSourceBlock: 0

# What to do when a block is about to be placed outside the SourceBlock? (dontPlace, placeAnyway)
OutsideSourceBlock: dontPlace

#######################################################################
# +-----------------------------------------------------------------+ #
# |                              Blocks                             | #
# +-----------------------------------------------------------------+ #
#######################################################################

# All the blocks used in the BO3 are listed here. Possible blocks:
# Block(x,y,z,id[.data][,nbtfile.nbt) or B(x,y,z,id[.data][,nbtfile.nbt)
# RandomBlock(x,y,z,id[:data][,nbtfile.nbt],chance[,id[:data][,nbtfile.nbt],chance[,...]])
# So RandomBlock(0,0,0,CHEST,chest.nbt,50,CHEST,anotherchest.nbt,100) will spawn a chest at
# the BO3 origin, and give it a 50% chance to have the contents of chest.nbt, or, if that
# fails, a 100% percent chance to have the contents of anotherchest.nbt.

Block(-13,6,-1,LEAVES:12)
Block(-13,7,-2,LEAVES:12)
Block(-13,7,-1,LEAVES:12)
Block(-13,8,-6,LEAVES:12)
Block(-13,14,3,LEAVES:12)
Block(-13,15,2,LEAVES:12)
Block(-13,15,3,LEAVES:12)
Block(-13,16,-2,LEAVES:12)
Block(-12,7,-2,LEAVES:12)
Block(-12,8,-6,LEAVES:12)
Block(-12,8,-5,LEAVES:12)
Block(-12,11,-4,LEAVES:12)
Block(-12,11,-2,LEAVES:12)
Block(-12,12,-4,LEAVES:12)
Block(-12,12,0,LEAVES:12)
Block(-12,15,2,LEAVES:12)
Block(-12,16,-2,LEAVES:12)
Block(-12,16,-1,LEAVES:12)
Block(-12,19,0,LEAVES:12)
Block(-12,19,2,LEAVES:12)
Block(-12,20,0,LEAVES:12)
Block(-11,5,-1,LEAVES:12)
Block(-11,6,-7,LEAVES:12)
Block(-11,7,-5,LEAVES:12)
Block(-11,7,-4,LEAVES:12)
Block(-11,7,-2,LEAVES:12)
Block(-11,8,-5,LEAVES:12)
Block(-11,8,-3,LEAVES:12)
Block(-11,8,-2,LEAVES:12)
Block(-11,10,-1,LEAVES:12)
Block(-11,10,1,LEAVES:12)
Block(-11,10,2,LEAVES:12)
Block(-11,11,-4,LEAVES:12)
Block(-11,11,-3,LEAVES:12)
Block(-11,11,1,LEAVES:12)
Block(-11,12,1,LEAVES:12)
Block(-11,13,3,LEAVES:12)
Block(-11,14,-3,LEAVES:12)
Block(-11,15,-1,LEAVES:12)
Block(-11,15,0,LEAVES:12)
Block(-11,15,2,LEAVES:12)
Block(-11,16,-1,LEAVES:12)
Block(-11,16,1,LEAVES:12)
Block(-11,16,2,LEAVES:12)
Block(-11,18,3,LEAVES:12)
Block(-11,18,5,LEAVES:12)
Block(-11,18,6,LEAVES:12)
Block(-11,19,0,LEAVES:12)
Block(-11,19,1,LEAVES:12)
Block(-10,5,-7,LEAVES:12)
Block(-10,5,-6,LEAVES:12)
Block(-10,5,-2,LEAVES:12)
Block(-10,6,-2,LEAVES:12)
Block(-10,7,-4,LEAVES:12)
Block(-10,8,-3,LEAVES:12)
Block(-10,9,0,LEAVES:12)
Block(-10,9,1,LEAVES:12)
Block(-10,10,-7,LEAVES:12)
Block(-10,10,-6,LEAVES:12)
Block(-10,10,-3,LEAVES:12)
Block(-10,10,1,LEAVES:12)
Block(-10,11,-3,LEAVES:12)
Block(-10,11,1,LEAVES:12)
Block(-10,11,3,LEAVES:12)
Block(-10,12,-3,LEAVES:12)
Block(-10,12,1,LEAVES:12)
Block(-10,12,2,LEAVES:12)
Block(-10,13,-3,LEAVES:12)
Block(-10,13,-2,LEAVES:12)
Block(-10,13,2,LEAVES:12)
Block(-10,13,5,LEAVES:12)
Block(-10,14,2,LEAVES:12)
Block(-10,14,12,LEAVES:12)
Block(-10,15,0,LEAVES:12)
Block(-10,15,11,LEAVES:12)
Block(-10,15,12,LEAVES:12)
Block(-10,16,1,LEAVES:12)
Block(-10,16,7,LEAVES:12)
Block(-10,17,4,LEAVES:12)
Block(-10,17,5,LEAVES:12)
Block(-10,18,-3,LEAVES:12)
Block(-10,18,-2,LEAVES:12)
Block(-10,18,1,LEAVES:12)
Block(-10,18,5,LEAVES:12)
Block(-10,19,1,LEAVES:12)
Block(-10,19,5,LEAVES:12)
Block(-10,20,1,LEAVES:12)
Block(-9,5,-6,LEAVES:12)
Block(-9,6,-6,LEAVES:12)
Block(-9,6,-2,LEAVES:12)
Block(-9,6,-1,LEAVES:12)
Block(-9,6,0,LEAVES:12)
Block(-9,7,-4,LEAVES:12)
Block(-9,7,-2,LEAVES:12)
Block(-9,8,-3,LEAVES:12)
Block(-9,9,-5,LEAVES:12)
Block(-9,9,-4,LEAVES:12)
Block(-9,9,-3,LEAVES:12)
Block(-9,9,-1,LEAVES:12)
Block(-9,9,0,LEAVES:12)
Block(-9,10,-6,LEAVES:12)
Block(-9,10,-5,LEAVES:12)
Block(-9,10,-3,LEAVES:12)
Block(-9,10,2,LEAVES:12)
Block(-9,11,-5,LEAVES:12)
Block(-9,12,9,LEAVES:12)
Block(-9,13,-2,LEAVES:12)
Block(-9,13,4,LEAVES:12)
Block(-9,13,5,LEAVES:12)
Block(-9,14,-2,LEAVES:12)
Block(-9,14,2,LEAVES:12)
Block(-9,14,3,LEAVES:12)
Block(-9,14,4,LEAVES:12)
Block(-9,15,0,LEAVES:12)
Block(-9,15,2,LEAVES:12)
Block(-9,15,11,LEAVES:12)
Block(-9,16,1,LEAVES:12)
Block(-9,16,7,LEAVES:12)
Block(-9,16,8,LEAVES:12)
Block(-9,17,-1,LEAVES:12)
Block(-9,17,0,LEAVES:12)
Block(-9,17,1,LEAVES:12)
Block(-9,17,3,LEAVES:12)
Block(-9,17,4,LEAVES:12)
Block(-9,18,-2,LEAVES:12)
Block(-9,18,-1,LEAVES:12)
Block(-9,18,1,LEAVES:12)
Block(-9,18,6,LEAVES:12)
Block(-9,19,-1,LEAVES:12)
Block(-9,19,9,LEAVES:12)
Block(-9,19,11,LEAVES:12)
Block(-9,20,9,LEAVES:12)
Block(-8,4,-4,LEAVES:12)
Block(-8,5,-5,LEAVES:12)
Block(-8,6,-6,LEAVES:12)
Block(-8,6,-5,LEAVES:12)
Block(-8,7,-5,LEAVES:12)
Block(-8,7,-4,LEAVES:12)
Block(-8,7,-3,LEAVES:12)
Block(-8,7,-2,LEAVES:12)
Block(-8,7,17,LEAVES:12)
Block(-8,8,-3,LOG:12)
Block(-8,8,-2,LEAVES:12)
Block(-8,8,-1,LEAVES:12)
Block(-8,8,16,LEAVES:12)
Block(-8,8,17,LEAVES:12)
Block(-8,9,-3,LEAVES:12)
Block(-8,9,-1,LEAVES:12)
Block(-8,9,12,LEAVES:12)
Block(-8,10,-3,LEAVES:12)
Block(-8,10,-2,LEAVES:12)
Block(-8,11,-2,LEAVES:12)
Block(-8,11,10,LEAVES:12)
Block(-8,12,-3,LEAVES:12)
Block(-8,12,0,LEAVES:12)
Block(-8,12,10,LEAVES:12)
Block(-8,13,-1,LEAVES:12)
Block(-8,13,5,LEAVES:12)
Block(-8,13,6,LEAVES:12)
Block(-8,13,12,LEAVES:12)
Block(-8,14,-2,LEAVES:12)
Block(-8,14,-1,LEAVES:12)
Block(-8,14,6,LEAVES:12)
Block(-8,15,-1,LEAVES:12)
Block(-8,15,0,LEAVES:12)
Block(-8,15,1,LEAVES:12)
Block(-8,15,2,LEAVES:12)
Block(-8,15,8,LEAVES:12)
Block(-8,15,9,LEAVES:12)
Block(-8,15,11,LEAVES:12)
Block(-8,16,1,LOG:12)
Block(-8,16,2,LOG:12)
Block(-8,16,3,LEAVES:12)
Block(-8,16,8,LEAVES:12)
Block(-8,16,10,LEAVES:12)
Block(-8,16,11,LEAVES:12)
Block(-8,17,1,LEAVES:12)
Block(-8,17,3,LEAVES:12)
Block(-8,18,1,LEAVES:12)
Block(-8,18,2,LEAVES:12)
Block(-8,18,12,LEAVES:12)
Block(-8,18,14,LEAVES:12)
Block(-8,18,15,LEAVES:12)
Block(-8,19,2,LEAVES:12)
Block(-8,19,9,LEAVES:12)
Block(-8,19,10,LEAVES:12)
Block(-8,20,1,LEAVES:12)
Block(-7,5,-3,LEAVES:12)
Block(-7,5,14,LEAVES:12)
Block(-7,6,-3,LEAVES:12)
Block(-7,6,-1,LEAVES:12)
Block(-7,7,-5,LEAVES:12)
Block(-7,7,-3,LEAVES:12)
Block(-7,7,-2,LEAVES:12)
Block(-7,7,-1,LEAVES:12)
Block(-7,8,-7,LEAVES:12)
Block(-7,8,-5,LEAVES:12)
Block(-7,8,-3,LOG:12)
Block(-7,8,-2,LOG:12)
Block(-7,8,2,LEAVES:12)
Block(-7,8,16,LEAVES:12)
Block(-7,9,-4,LEAVES:12)
Block(-7,9,-3,LEAVES:12)
Block(-7,9,12,LEAVES:12)
Block(-7,9,13,LEAVES:12)
Block(-7,10,-5,LEAVES:12)
Block(-7,10,-4,LEAVES:12)
Block(-7,11,-9,LEAVES:12)
Block(-7,11,-2,LEAVES:12)
Block(-7,11,-1,LEAVES:12)
Block(-7,11,12,LEAVES:12)
Block(-7,12,-1,LEAVES:12)
Block(-7,12,0,LEAVES:12)
Block(-7,12,3,LEAVES:12)
Block(-7,12,6,LEAVES:12)
Block(-7,12,10,LEAVES:12)
Block(-7,12,11,LEAVES:12)
Block(-7,12,14,LEAVES:12)
Block(-7,12,16,LEAVES:12)
Block(-7,13,-1,LEAVES:12)
Block(-7,13,1,LEAVES:12)
Block(-7,13,3,LEAVES:12)
Block(-7,13,6,LEAVES:12)
Block(-7,13,7,LEAVES:12)
Block(-7,13,11,LEAVES:12)
Block(-7,13,14,LEAVES:12)
Block(-7,14,1,LEAVES:12)
Block(-7,14,3,LEAVES:12)
Block(-7,14,5,LEAVES:12)
Block(-7,14,11,LEAVES:12)
Block(-7,15,-1,LEAVES:12)
Block(-7,15,1,LEAVES:12)
Block(-7,15,2,LEAVES:12)
Block(-7,15,3,LEAVES:12)
Block(-7,15,5,LEAVES:12)
Block(-7,15,9,LEAVES:12)
Block(-7,16,-3,LEAVES:12)
Block(-7,16,-1,LEAVES:12)
Block(-7,16,1,LEAVES:12)
Block(-7,16,2,LOG:12)
Block(-7,16,6,LEAVES:12)
Block(-7,16,10,LEAVES:12)
Block(-7,17,1,LEAVES:12)
Block(-7,17,13,LEAVES:12)
Block(-7,17,14,LEAVES:12)
Block(-7,18,6,LEAVES:12)
Block(-7,18,7,LEAVES:12)
Block(-7,18,10,LEAVES:12)
Block(-7,18,14,LEAVES:12)
Block(-7,19,2,LEAVES:12)
Block(-7,19,3,LEAVES:12)
Block(-7,19,10,LEAVES:12)
Block(-7,19,14,LEAVES:12)
Block(-7,20,3,LEAVES:12)
Block(-7,20,4,LEAVES:12)
Block(-7,20,10,LEAVES:12)
Block(-7,21,3,LEAVES:12)
Block(-6,5,15,LEAVES:12)
Block(-6,6,-3,LEAVES:12)
Block(-6,6,17,LEAVES:12)
Block(-6,7,-7,LEAVES:12)
Block(-6,7,11,LEAVES:12)
Block(-6,8,-6,LEAVES:12)
Block(-6,8,-5,LEAVES:12)
Block(-6,8,-2,LOG:12)
Block(-6,8,-1,LEAVES:12)
Block(-6,8,13,LEAVES:12)
Block(-6,8,14,LEAVES:12)
Block(-6,8,16,LEAVES:12)
Block(-6,9,-3,LEAVES:12)
Block(-6,9,-1,LEAVES:12)
Block(-6,9,13,LEAVES:12)
Block(-6,9,15,LEAVES:12)
Block(-6,9,16,LEAVES:12)
Block(-6,10,-6,LEAVES:12)
Block(-6,10,-5,LEAVES:12)
Block(-6,10,-4,LEAVES:12)
Block(-6,10,-3,LEAVES:12)
Block(-6,11,-9,LEAVES:12)
Block(-6,11,-8,LEAVES:12)
Block(-6,11,17,LEAVES:12)
Block(-6,11,19,LEAVES:12)
Block(-6,11,20,LEAVES:12)
Block(-6,12,0,LEAVES:12)
Block(-6,12,14,LEAVES:12)
Block(-6,12,15,LEAVES:12)
Block(-6,13,4,LEAVES:12)
Block(-6,13,7,LEAVES:12)
Block(-6,13,13,LEAVES:12)
Block(-6,13,14,LEAVES:12)
Block(-6,14,-7,LEAVES:12)
Block(-6,14,-5,LEAVES:12)
Block(-6,14,1,LEAVES:12)
Block(-6,14,3,LEAVES:12)
Block(-6,14,4,LEAVES:12)
Block(-6,14,7,LEAVES:12)
Block(-6,14,11,LEAVES:12)
Block(-6,14,12,LEAVES:12)
Block(-6,14,13,LEAVES:12)
Block(-6,15,-7,LEAVES:12)
Block(-6,15,4,LOG:12)
Block(-6,15,9,LEAVES:12)
Block(-6,15,11,LEAVES:12)
Block(-6,16,-2,LEAVES:12)
Block(-6,16,-1,LEAVES:12)
Block(-6,16,2,LOG:12)
Block(-6,16,3,LOG:12)
Block(-6,16,4,LOG:12)
Block(-6,16,10,LEAVES:12)
Block(-6,17,1,LEAVES:12)
Block(-6,17,3,LEAVES:12)
Block(-6,17,8,LEAVES:12)
Block(-6,17,9,LEAVES:12)
Block(-6,17,10,LEAVES:12)
Block(-6,17,12,LEAVES:12)
Block(-6,17,13,LEAVES:12)
Block(-6,18,-2,LEAVES:12)
Block(-6,18,0,LEAVES:12)
Block(-6,18,1,LEAVES:12)
Block(-6,18,7,LEAVES:12)
Block(-6,18,8,LEAVES:12)
Block(-6,18,10,LEAVES:12)
Block(-6,18,15,LEAVES:12)
Block(-6,19,8,LEAVES:12)
Block(-5,5,-4,LEAVES:12)
Block(-5,5,-3,LEAVES:12)
Block(-5,5,11,LEAVES:12)
Block(-5,5,15,LEAVES:12)
Block(-5,5,16,LEAVES:12)
Block(-5,6,-6,LEAVES:12)
Block(-5,6,-3,LEAVES:12)
Block(-5,6,11,LEAVES:12)
Block(-5,6,12,LEAVES:12)
Block(-5,6,16,LEAVES:12)
Block(-5,6,19,LEAVES:12)
Block(-5,7,-6,LEAVES:12)
Block(-5,7,-3,LEAVES:12)
Block(-5,7,16,LEAVES:12)
Block(-5,8,-7,LEAVES:12)
Block(-5,8,-6,LEAVES:12)
Block(-5,8,-4,LEAVES:12)
Block(-5,8,-2,LOG:12)
Block(-5,8,-1,LOG:12)
Block(-5,8,14,LEAVES:12)
Block(-5,9,-10,LEAVES:12)
Block(-5,9,-1,LOG:12)
Block(-5,9,0,LEAVES:12)
Block(-5,9,1,LEAVES:12)
Block(-5,9,15,LEAVES:12)
Block(-5,10,-8,LEAVES:12)
Block(-5,10,-7,LEAVES:12)
Block(-5,10,-5,LEAVES:12)
Block(-5,10,-4,LEAVES:12)
Block(-5,10,0,LEAVES:12)
Block(-5,10,18,LEAVES:12)
Block(-5,10,19,LEAVES:12)
Block(-5,11,-8,LEAVES:12)
Block(-5,11,-6,LEAVES:12)
Block(-5,11,-5,LEAVES:12)
Block(-5,11,-2,LEAVES:12)
Block(-5,11,11,LEAVES:12)
Block(-5,11,12,LEAVES:12)
Block(-5,11,15,LEAVES:12)
Block(-5,11,19,LEAVES:12)
Block(-5,12,4,LEAVES:12)
Block(-5,12,9,LEAVES:12)
Block(-5,12,15,LEAVES:12)
Block(-5,12,19,LEAVES:12)
Block(-5,13,-4,LEAVES:12)
Block(-5,13,-2,LEAVES:12)
Block(-5,13,-1,LEAVES:12)
Block(-5,13,0,LEAVES:12)
Block(-5,13,1,LEAVES:12)
Block(-5,13,4,LEAVES:12)
Block(-5,13,8,LEAVES:12)
Block(-5,13,14,LEAVES:12)
Block(-5,13,15,LEAVES:12)
Block(-5,14,-7,LEAVES:12)
Block(-5,14,-6,LEAVES:12)
Block(-5,14,1,LEAVES:12)
Block(-5,14,7,LEAVES:12)
Block(-5,14,8,LEAVES:12)
Block(-5,15,1,LEAVES:12)
Block(-5,15,4,LOG:12)
Block(-5,15,5,LOG:12)
Block(-5,15,8,LEAVES:12)
Block(-5,15,9,LEAVES:12)
Block(-5,15,10,LEAVES:12)
Block(-5,15,11,LEAVES:12)
Block(-5,16,-3,LEAVES:12)
Block(-5,16,-2,LEAVES:12)
Block(-5,16,9,LOG:12)
Block(-5,16,10,LOG:12)
Block(-5,16,11,LOG:12)
Block(-5,16,12,LEAVES:12)
Block(-5,17,3,LEAVES:12)
Block(-5,17,4,LEAVES:12)
Block(-5,17,5,LEAVES:12)
Block(-5,17,10,LEAVES:12)
Block(-5,17,12,LEAVES:12)
Block(-5,18,-1,LEAVES:12)
Block(-5,18,0,LEAVES:12)
Block(-5,18,4,LEAVES:12)
Block(-5,18,10,LEAVES:12)
Block(-5,18,11,LEAVES:12)
Block(-5,18,12,LEAVES:12)
Block(-5,19,2,LEAVES:12)
Block(-5,19,7,LEAVES:12)
Block(-5,19,11,LEAVES:12)
Block(-5,20,10,LEAVES:12)
Block(-4,6,-4,LEAVES:12)
Block(-4,6,12,LEAVES:12)
Block(-4,6,18,LEAVES:12)
Block(-4,6,19,LEAVES:12)
Block(-4,7,-10,LEAVES:12)
Block(-4,7,-6,LEAVES:12)
Block(-4,7,-5,LEAVES:12)
Block(-4,7,-4,LEAVES:12)
Block(-4,7,-3,LEAVES:12)
Block(-4,7,12,LEAVES:12)
Block(-4,7,16,LEAVES:12)
Block(-4,7,17,LEAVES:12)
Block(-4,7,18,LEAVES:12)
Block(-4,8,-10,LEAVES:12)
Block(-4,8,-9,LEAVES:12)
Block(-4,8,-5,LEAVES:12)
Block(-4,8,-3,LEAVES:12)
Block(-4,8,-2,LEAVES:12)
Block(-4,8,14,LEAVES:12)
Block(-4,8,16,LEAVES:12)
Block(-4,9,-5,LEAVES:12)
Block(-4,9,-1,LOG:12)
Block(-4,9,0,LOG:12)
Block(-4,9,1,LOG:12)
Block(-4,9,15,LEAVES:12)
Block(-4,10,-7,LEAVES:12)
Block(-4,10,-5,LEAVES:12)
Block(-4,10,-2,LOG:12)
Block(-4,10,-1,LOG:12)
Block(-4,10,1,LOG:12)
Block(-4,10,13,LEAVES:12)
Block(-4,10,14,LEAVES:12)
Block(-4,10,15,LEAVES:12)
Block(-4,10,17,LEAVES:12)
Block(-4,10,18,LEAVES:12)
Block(-4,11,-6,LEAVES:12)
Block(-4,11,-5,LEAVES:12)
Block(-4,11,12,LEAVES:12)
Block(-4,11,13,LEAVES:12)
Block(-4,11,15,LEAVES:12)
Block(-4,11,20,LEAVES:12)
Block(-4,12,-3,LEAVES:12)
Block(-4,12,-2,LEAVES:12)
Block(-4,12,-1,LEAVES:12)
Block(-4,12,0,LEAVES:12)
Block(-4,12,12,LEAVES:12)
Block(-4,12,13,LEAVES:12)
Block(-4,13,-10,LEAVES:12)
Block(-4,13,-9,LEAVES:12)
Block(-4,13,-6,LEAVES:12)
Block(-4,13,-2,LEAVES:12)
Block(-4,13,0,LEAVES:12)
Block(-4,13,10,LEAVES:12)
Block(-4,13,12,LEAVES:12)
Block(-4,14,-6,LEAVES:12)
Block(-4,14,-2,LEAVES:12)
Block(-4,14,10,LEAVES:12)
Block(-4,14,12,LEAVES:12)
Block(-4,14,14,LEAVES:12)
Block(-4,15,-6,LEAVES:12)
Block(-4,15,0,LEAVES:12)
Block(-4,15,1,LEAVES:12)
Block(-4,15,5,LOG:12)
Block(-4,15,6,LOG:12)
Block(-4,15,8,LOG:12)
Block(-4,15,9,LOG:12)
Block(-4,15,10,LEAVES:12)
Block(-4,15,11,LEAVES:12)
Block(-4,15,12,LEAVES:12)
Block(-4,15,14,LEAVES:12)
Block(-4,16,1,LEAVES:12)
Block(-4,16,6,LEAVES:12)
Block(-4,16,8,LEAVES:12)
Block(-4,16,9,LOG:12)
Block(-4,16,10,LEAVES:12)
Block(-4,16,11,LEAVES:12)
Block(-4,16,15,LEAVES:12)
Block(-4,17,4,LEAVES:12)
Block(-4,17,10,LEAVES:12)
Block(-4,18,-1,LEAVES:12)
Block(-4,18,11,LEAVES:12)
Block(-4,19,-1,LEAVES:12)
Block(-4,19,7,LEAVES:12)
Block(-4,19,8,LEAVES:12)
Block(-4,19,11,LEAVES:12)
Block(-4,19,12,LEAVES:12)
Block(-4,20,12,LEAVES:12)
Block(-4,20,13,LEAVES:12)
Block(-4,21,12,LEAVES:12)
Block(-4,22,9,LEAVES:12)
Block(-4,22,11,LEAVES:12)
Block(-4,23,9,LEAVES:12)
Block(-3,5,14,LEAVES:12)
Block(-3,6,-2,LEAVES:12)
Block(-3,6,13,LEAVES:12)
Block(-3,6,19,LEAVES:12)
Block(-3,6,20,LEAVES:12)
Block(-3,7,-3,LEAVES:12)
Block(-3,7,-2,LEAVES:12)
Block(-3,7,12,LEAVES:12)
Block(-3,7,13,LEAVES:12)
Block(-3,8,-9,LEAVES:12)
Block(-3,8,-3,LEAVES:12)
Block(-3,8,-2,LEAVES:12)
Block(-3,8,13,LEAVES:12)
Block(-3,8,14,LEAVES:12)
Block(-3,8,15,LOG:12)
Block(-3,8,16,LEAVES:12)
Block(-3,9,-9,LEAVES:12)
Block(-3,9,-5,LEAVES:12)
Block(-3,9,-4,LEAVES:12)
Block(-3,9,-3,LEAVES:12)
Block(-3,9,15,LOG:12)
Block(-3,9,16,LEAVES:12)
Block(-3,9,17,LEAVES:12)
Block(-3,10,-7,LEAVES:12)
Block(-3,10,-5,LEAVES:12)
Block(-3,10,-3,LOG:12)
Block(-3,10,-2,LOG:12)
Block(-3,10,1,LOG:12)
Block(-3,10,2,LOG:12)
Block(-3,10,3,LOG:12)
Block(-3,10,15,LEAVES:12)
Block(-3,10,17,LEAVES:12)
Block(-3,11,-6,LEAVES:12)
Block(-3,11,15,LEAVES:12)
Block(-3,11,16,LEAVES:12)
Block(-3,12,-8,LEAVES:12)
Block(-3,12,-7,LEAVES:12)
Block(-3,12,-6,LEAVES:12)
Block(-3,12,-4,LEAVES:12)
Block(-3,12,-3,LEAVES:12)
Block(-3,12,-1,LEAVES:12)
Block(-3,12,9,LEAVES:12)
Block(-3,12,16,LEAVES:12)
Block(-3,13,-9,LEAVES:12)
Block(-3,13,-8,LEAVES:12)
Block(-3,13,-6,LEAVES:12)
Block(-3,13,-1,LEAVES:12)
Block(-3,13,13,LEAVES:12)
Block(-3,13,15,LEAVES:12)
Block(-3,14,-8,LEAVES:12)
Block(-3,14,2,LEAVES:12)
Block(-3,14,6,LOG:12)
Block(-3,14,10,LEAVES:12)
Block(-3,14,12,LEAVES:12)
Block(-3,14,13,LEAVES:12)
Block(-3,15,1,LEAVES:12)
Block(-3,15,2,LEAVES:12)
Block(-3,15,6,LOG:12)
Block(-3,15,7,LOG:12)
Block(-3,15,8,LOG:12)
Block(-3,15,10,LEAVES:12)
Block(-3,16,7,LEAVES:12)
Block(-3,16,8,LEAVES:12)
Block(-3,16,11,LEAVES:12)
Block(-3,16,12,LEAVES:12)
Block(-3,17,6,LEAVES:12)
Block(-3,17,10,LEAVES:12)
Block(-3,17,12,LEAVES:12)
Block(-3,18,7,LEAVES:12)
Block(-3,18,8,LEAVES:12)
Block(-3,18,9,LEAVES:12)
Block(-3,18,10,LEAVES:12)
Block(-3,18,11,LEAVES:12)
Block(-3,19,8,LEAVES:12)
Block(-3,19,10,LEAVES:12)
Block(-3,19,11,LEAVES:12)
Block(-3,21,12,LEAVES:12)
Block(-3,21,14,LEAVES:12)
Block(-3,21,15,LEAVES:12)
Block(-3,22,9,LEAVES:12)
Block(-3,22,10,LEAVES:12)
Block(-2,5,17,LEAVES:12)
Block(-2,6,-2,LEAVES:12)
Block(-2,6,15,LEAVES:12)
Block(-2,6,17,LEAVES:12)
Block(-2,7,-7,LEAVES:12)
Block(-2,7,15,LEAVES:12)
Block(-2,7,17,LEAVES:12)
Block(-2,7,19,LEAVES:12)
Block(-2,8,-8,LEAVES:12)
Block(-2,8,-2,LEAVES:12)
Block(-2,8,-1,LEAVES:12)
Block(-2,8,13,LEAVES:12)
Block(-2,8,15,LEAVES:12)
Block(-2,8,16,LEAVES:12)
Block(-2,8,17,LEAVES:12)
Block(-2,8,19,LEAVES:12)
Block(-2,9,-9,LEAVES:12)
Block(-2,9,-8,LEAVES:12)
Block(-2,9,11,LEAVES:12)
Block(-2,9,13,LOG:12)
Block(-2,9,14,LOG:12)
Block(-2,9,15,LOG:12)
Block(-2,9,16,LEAVES:12)
Block(-2,9,20,LEAVES:12)
Block(-2,10,-8,LEAVES:12)
Block(-2,10,-7,LEAVES:12)
Block(-2,10,-6,LEAVES:12)
Block(-2,10,-5,LEAVES:12)
Block(-2,10,-4,LOG:12)
Block(-2,10,-3,LOG:12)
Block(-2,10,3,LOG:12)
Block(-2,10,4,LOG:12)
Block(-2,10,13,LOG:12)
Block(-2,10,15,LEAVES:12)
Block(-2,11,-6,LOG:12)
Block(-2,11,-5,LOG:12)
Block(-2,11,-4,LOG:12)
Block(-2,11,4,LOG:12)
Block(-2,11,5,LOG:12)
Block(-2,12,-6,LEAVES:12)
Block(-2,12,-4,LEAVES:12)
Block(-2,12,13,LEAVES:12)
Block(-2,12,16,LEAVES:12)
Block(-2,12,17,LEAVES:12)
Block(-2,13,-6,LEAVES:12)
Block(-2,13,-5,LEAVES:12)
Block(-2,13,6,LOG:12)
Block(-2,13,9,LEAVES:12)
Block(-2,13,10,LEAVES:12)
Block(-2,13,13,LEAVES:12)
Block(-2,13,16,LEAVES:12)
Block(-2,13,17,LEAVES:12)
Block(-2,13,18,LEAVES:12)
Block(-2,14,-5,LEAVES:12)
Block(-2,14,2,LEAVES:12)
Block(-2,14,3,LOG:12)
Block(-2,14,4,LOG:12)
Block(-2,14,5,LOG:12)
Block(-2,14,6,LOG:12)
Block(-2,14,10,LEAVES:12)
Block(-2,14,12,LEAVES:12)
Block(-2,14,17,LEAVES:12)
Block(-2,15,-6,LEAVES:12)
Block(-2,15,2,LOG:12)
Block(-2,15,3,LOG:12)
Block(-2,15,6,LEAVES:12)
Block(-2,15,10,LEAVES:12)
Block(-2,15,11,LEAVES:12)
Block(-2,16,6,LEAVES:12)
Block(-2,16,7,LEAVES:12)
Block(-2,16,11,LEAVES:12)
Block(-2,16,14,LEAVES:12)
Block(-2,17,11,LEAVES:12)
Block(-2,17,12,LEAVES:12)
Block(-2,17,13,LEAVES:12)
Block(-2,17,14,LEAVES:12)
Block(-2,18,8,LEAVES:12)
Block(-2,18,9,LEAVES:12)
Block(-2,18,13,LEAVES:12)
Block(-2,19,10,LEAVES:12)
Block(-2,19,11,LEAVES:12)
Block(-2,20,13,LEAVES:12)
Block(-2,20,14,LEAVES:12)
Block(-2,21,6,LEAVES:12)
Block(-2,21,7,LEAVES:12)
Block(-2,21,10,LEAVES:12)
Block(-2,21,14,LEAVES:12)
Block(-2,22,10,LEAVES:12)
Block(-2,22,14,LEAVES:12)
Block(-2,23,10,LEAVES:12)
Block(-1,6,18,LEAVES:12)
Block(-1,7,-4,LEAVES:12)
Block(-1,7,15,LEAVES:12)
Block(-1,7,17,LEAVES:12)
Block(-1,7,18,LEAVES:12)
Block(-1,8,-6,LEAVES:12)
Block(-1,8,-4,LEAVES:12)
Block(-1,9,-6,LEAVES:12)
Block(-1,9,-4,LEAVES:12)
Block(-1,9,-2,LEAVES:12)
Block(-1,9,12,LEAVES:12)
Block(-1,9,13,LEAVES:12)
Block(-1,9,16,LEAVES:12)
Block(-1,9,17,LEAVES:12)
Block(-1,10,-8,LEAVES:12)
Block(-1,10,-6,LEAVES:12)
Block(-1,10,-5,LEAVES:12)
Block(-1,10,-4,LEAVES:12)
Block(-1,10,-2,LEAVES:12)
Block(-1,10,12,LOG:12)
Block(-1,10,13,LOG:12)
Block(-1,10,14,LEAVES:12)
Block(-1,10,15,LEAVES:12)
Block(-1,10,17,LEAVES:12)
Block(-1,11,-10,LEAVES:12)
Block(-1,11,-8,LEAVES:12)
Block(-1,11,-6,LEAVES:12)
Block(-1,11,-5,LEAVES:12)
Block(-1,11,-1,LEAVES:12)
Block(-1,11,5,LOG:12)
Block(-1,11,12,LEAVES:12)
Block(-1,11,14,LEAVES:12)
Block(-1,11,15,LEAVES:12)
Block(-1,12,-6,LEAVES:12)
Block(-1,12,5,LOG:12)
Block(-1,12,8,LEAVES:12)
Block(-1,12,9,LEAVES:12)
Block(-1,13,5,LOG:12)
Block(-1,13,9,LEAVES:12)
Block(-1,13,16,LEAVES:12)
Block(-1,14,-5,LEAVES:12)
Block(-1,14,-4,LEAVES:12)
Block(-1,14,5,LOG:12)
Block(-1,14,12,LEAVES:12)
Block(-1,14,13,LEAVES:12)
Block(-1,15,-4,LEAVES:12)
Block(-1,15,-3,LEAVES:12)
Block(-1,15,1,LOG:12)
Block(-1,15,2,LOG:12)
Block(-1,15,9,LEAVES:12)
Block(-1,15,10,LEAVES:12)
Block(-1,16,-4,LEAVES:12)
Block(-1,16,1,LOG:12)
Block(-1,16,7,LEAVES:12)
Block(-1,16,10,LEAVES:12)
Block(-1,16,13,LEAVES:12)
Block(-1,16,14,LEAVES:12)
Block(-1,17,7,LEAVES:12)
Block(-1,17,11,LEAVES:12)
Block(-1,17,12,LEAVES:12)
Block(-1,17,13,LEAVES:12)
Block(-1,17,14,LEAVES:12)
Block(-1,17,16,LEAVES:12)
Block(-1,18,6,LEAVES:12)
Block(-1,18,7,LEAVES:12)
Block(-1,18,8,LEAVES:12)
Block(-1,18,9,LEAVES:12)
Block(-1,18,11,LEAVES:12)
Block(-1,18,14,LEAVES:12)
Block(-1,19,2,LEAVES:12)
Block(-1,19,8,LEAVES:12)
Block(-1,19,10,LEAVES:12)
Block(-1,20,8,LEAVES:12)
Block(-1,20,9,LEAVES:12)
Block(-1,20,10,LEAVES:12)
Block(-1,20,12,LEAVES:12)
Block(-1,20,13,LEAVES:12)
Block(-1,21,7,LEAVES:12)
Block(-1,21,8,LEAVES:12)
Block(-1,21,10,LEAVES:12)
Block(-1,21,15,LEAVES:12)
Block(-1,22,8,LEAVES:12)
Block(0,5,17,LEAVES:12)
Block(0,5,18,LEAVES:12)
Block(0,6,5,LOG:12)
Block(0,6,14,LEAVES:12)
Block(0,6,15,LEAVES:12)
Block(0,6,16,LEAVES:12)
Block(0,6,17,LEAVES:12)
Block(0,6,18,LEAVES:12)
Block(0,7,-7,LEAVES:12)
Block(0,7,5,LOG:12)
Block(0,7,12,LEAVES:12)
Block(0,7,15,LEAVES:12)
Block(0,8,-3,LEAVES:12)
Block(0,8,6,LOG:12)
Block(0,8,15,LEAVES:12)
Block(0,9,-6,LEAVES:12)
Block(0,9,-4,LEAVES:12)
Block(0,9,-3,LEAVES:12)
Block(0,9,6,LOG:12)
Block(0,9,11,LEAVES:12)
Block(0,9,12,LEAVES:12)
Block(0,9,15,LEAVES:12)
Block(0,10,5,LOG:12)
Block(0,10,6,LOG:12)
Block(0,10,12,LOG:12)
Block(0,10,15,LEAVES:12)
Block(0,10,17,LEAVES:12)
Block(0,10,18,LEAVES:12)
Block(0,10,19,LEAVES:12)
Block(0,11,-9,LEAVES:12)
Block(0,11,-8,LEAVES:12)
Block(0,11,-5,LEAVES:12)
Block(0,11,-4,LEAVES:12)
Block(0,11,5,LOG:12)
Block(0,11,11,LOG:12)
Block(0,11,12,LOG:12)
Block(0,11,13,LEAVES:12)
Block(0,11,14,LEAVES:12)
Block(0,11,17,LEAVES:12)
Block(0,11,18,LEAVES:12)
Block(0,12,-6,LEAVES:12)
Block(0,12,-4,LEAVES:12)
Block(0,12,0,LEAVES:12)
Block(0,12,5,LOG:12)
Block(0,12,8,LEAVES:12)
Block(0,12,11,LEAVES:12)
Block(0,12,16,LEAVES:12)
Block(0,13,-9,LEAVES:12)
Block(0,13,-7,LEAVES:12)
Block(0,13,-6,LEAVES:12)
Block(0,13,-1,LEAVES:12)
Block(0,13,0,LEAVES:12)
Block(0,13,13,LEAVES:12)
Block(0,13,14,LEAVES:12)
Block(0,13,16,LEAVES:12)
Block(0,14,-5,LEAVES:12)
Block(0,14,11,LEAVES:12)
Block(0,14,13,LEAVES:12)
Block(0,14,15,LEAVES:12)
Block(0,14,16,LEAVES:12)
Block(0,15,-2,LOG:12)
Block(0,15,-1,LOG:12)
Block(0,15,4,LEAVES:12)
Block(0,15,9,LEAVES:12)
Block(0,15,10,LEAVES:12)
Block(0,15,11,LEAVES:12)
Block(0,16,-1,LOG:12)
Block(0,16,0,LOG:12)
Block(0,16,1,LOG:12)
Block(0,16,8,LEAVES:12)
Block(0,16,14,LEAVES:12)
Block(0,16,15,LEAVES:12)
Block(0,16,17,LEAVES:12)
Block(0,16,19,LEAVES:12)
Block(0,16,20,LEAVES:12)
Block(0,17,7,LEAVES:12)
Block(0,17,8,LEAVES:12)
Block(0,17,9,LOG:12)
Block(0,17,10,LOG:12)
Block(0,17,14,LEAVES:12)
Block(0,17,15,LEAVES:12)
Block(0,18,6,LEAVES:12)
Block(0,18,8,LEAVES:12)
Block(0,18,9,LEAVES:12)
Block(0,18,10,LOG:12)
Block(0,18,11,LEAVES:12)
Block(0,19,2,LEAVES:12)
Block(0,19,3,LEAVES:12)
Block(0,19,10,LOG:12)
Block(0,19,11,LEAVES:12)
Block(0,19,12,LEAVES:12)
Block(0,20,10,LEAVES:12)
Block(0,20,12,LEAVES:12)
Block(0,21,10,LEAVES:12)
Block(0,21,11,LEAVES:12)
Block(0,22,4,LEAVES:12)
Block(0,22,6,LEAVES:12)
Block(0,22,11,LEAVES:12)
Block(0,23,4,LEAVES:12)
Block(0,23,10,LEAVES:12)
Block(1,0,5,LOG:12)
Block(1,0,6,LOG:12)
Block(1,1,5,LOG:12)
Block(1,1,6,LOG:12)
Block(1,2,5,LOG:12)
Block(1,3,5,LOG:12)
Block(1,4,5,LOG:12)
Block(1,5,4,LOG:12)
Block(1,5,5,LOG:12)
Block(1,5,6,LOG:12)
Block(1,5,14,LEAVES:12)
Block(1,6,4,LOG:12)
Block(1,6,5,LOG:12)
Block(1,6,6,LOG:12)
Block(1,6,14,LEAVES:12)
Block(1,6,16,LEAVES:12)
Block(1,7,-3,LEAVES:12)
Block(1,7,4,LOG:12)
Block(1,7,5,LOG:12)
Block(1,7,6,LOG:12)
Block(1,7,12,LEAVES:12)
Block(1,7,13,LEAVES:12)
Block(1,8,-7,LEAVES:12)
Block(1,8,-6,LEAVES:12)
Block(1,8,-3,LEAVES:12)
Block(1,8,5,LOG:12)
Block(1,8,6,LOG:12)
Block(1,8,14,LEAVES:12)
Block(1,8,15,LEAVES:12)
Block(1,9,-6,LEAVES:12)
Block(1,9,5,LOG:12)
Block(1,9,6,LOG:12)
Block(1,9,7,LOG:12)
Block(1,9,15,LEAVES:12)
Block(1,9,17,LEAVES:12)
Block(1,10,-6,LEAVES:12)
Block(1,10,-3,LEAVES:12)
Block(1,10,5,LOG:12)
Block(1,10,6,LOG:12)
Block(1,10,7,LOG:12)
Block(1,10,11,LEAVES:12)
Block(1,10,14,LEAVES:12)
Block(1,10,15,LEAVES:12)
Block(1,10,16,LEAVES:12)
Block(1,10,18,LEAVES:12)
Block(1,11,-10,LEAVES:12)
Block(1,11,-9,LEAVES:12)
Block(1,11,5,LOG:12)
Block(1,11,7,LOG:12)
Block(1,11,10,LOG:12)
Block(1,11,11,LOG:12)
Block(1,11,12,LEAVES:12)
Block(1,11,13,LEAVES:12)
Block(1,11,14,LEAVES:12)
Block(1,11,16,LEAVES:12)
Block(1,11,19,LEAVES:12)
Block(1,12,-4,LEAVES:12)
Block(1,12,-3,LEAVES:12)
Block(1,12,-2,LEAVES:12)
Block(1,12,5,LOG:12)
Block(1,12,11,LOG:12)
Block(1,12,13,LEAVES:12)
Block(1,12,16,LEAVES:12)
Block(1,13,-8,LEAVES:12)
Block(1,13,-7,LEAVES:12)
Block(1,13,-3,LEAVES:12)
Block(1,13,-1,LEAVES:12)
Block(1,13,5,LOG:12)
Block(1,13,11,LOG:12)
Block(1,13,12,LOG:12)
Block(1,13,14,LEAVES:12)
Block(1,14,-5,LEAVES:12)
Block(1,14,-4,LEAVES:12)
Block(1,14,5,LEAVES:12)
Block(1,14,11,LEAVES:12)
Block(1,14,15,LEAVES:12)
Block(1,15,5,LEAVES:12)
Block(1,15,12,LEAVES:12)
Block(1,15,18,LEAVES:12)
Block(1,15,19,LEAVES:12)
Block(1,16,7,LEAVES:12)
Block(1,16,8,LOG:12)
Block(1,16,9,LOG:12)
Block(1,16,10,LEAVES:12)
Block(1,16,11,LEAVES:12)
Block(1,16,12,LEAVES:12)
Block(1,16,15,LEAVES:12)
Block(1,16,19,LEAVES:12)
Block(1,17,-3,LEAVES:12)
Block(1,17,-1,LEAVES:12)
Block(1,17,1,LEAVES:12)
Block(1,17,9,LOG:12)
Block(1,17,10,LEAVES:12)
Block(1,17,12,LEAVES:12)
Block(1,17,14,LEAVES:12)
Block(1,17,15,LEAVES:12)
Block(1,17,19,LEAVES:12)
Block(1,18,-3,LEAVES:12)
Block(1,18,3,LEAVES:12)
Block(1,18,4,LEAVES:12)
Block(1,18,6,LEAVES:12)
Block(1,18,8,LEAVES:12)
Block(1,18,10,LEAVES:12)
Block(1,18,11,LEAVES:12)
Block(1,18,12,LEAVES:12)
Block(1,18,14,LEAVES:12)
Block(1,18,15,LEAVES:12)
Block(1,19,3,LEAVES:12)
Block(1,19,5,LEAVES:12)
Block(1,19,6,LEAVES:12)
Block(1,19,8,LEAVES:12)
Block(1,19,10,LEAVES:12)
Block(1,19,11,LEAVES:12)
Block(1,19,15,LEAVES:12)
Block(1,20,10,LEAVES:12)
Block(1,21,7,LEAVES:12)
Block(1,21,9,LEAVES:12)
Block(1,21,10,LEAVES:12)
Block(1,22,4,LEAVES:12)
Block(1,22,5,LEAVES:12)
Block(1,22,11,LEAVES:12)
Block(1,22,12,LEAVES:12)
Block(1,23,12,LEAVES:12)
Block(1,23,13,LEAVES:12)
Block(1,24,12,LEAVES:12)
Block(2,0,4,LOG:12)
Block(2,0,5,LOG:12)
Block(2,0,6,LOG:12)
Block(2,1,4,LOG:12)
Block(2,1,5,LOG:12)
Block(2,1,6,LOG:12)
Block(2,2,4,LOG:12)
Block(2,2,5,LOG:12)
Block(2,2,6,LOG:12)
Block(2,3,4,LOG:12)
Block(2,3,5,LOG:12)
Block(2,3,6,LOG:12)
Block(2,4,4,LOG:12)
Block(2,4,5,LOG:12)
Block(2,5,5,LOG:12)
Block(2,6,13,LEAVES:12)
Block(2,6,14,LEAVES:12)
Block(2,6,16,LEAVES:12)
Block(2,7,-8,LEAVES:12)
Block(2,7,-7,LEAVES:12)
Block(2,7,6,LOG:12)
Block(2,7,13,LEAVES:12)
Block(2,7,15,LEAVES:12)
Block(2,7,16,LEAVES:12)
Block(2,8,-7,LEAVES:12)
Block(2,8,6,LOG:12)
Block(2,8,15,LEAVES:12)
Block(2,8,16,LEAVES:12)
Block(2,9,-2,LEAVES:12)
Block(2,9,6,LOG:12)
Block(2,9,17,LEAVES:12)
Block(2,9,19,LEAVES:12)
Block(2,9,20,LEAVES:12)
Block(2,10,-7,LEAVES:12)
Block(2,10,-6,LEAVES:12)
Block(2,10,-2,LEAVES:12)
Block(2,10,4,LOG:12)
Block(2,10,5,LOG:12)
Block(2,10,7,LOG:12)
Block(2,10,14,LEAVES:12)
Block(2,10,15,LEAVES:12)
Block(2,11,-6,LEAVES:12)
Block(2,11,0,LEAVES:12)
Block(2,11,4,LOG:12)
Block(2,11,7,LOG:12)
Block(2,11,8,LOG:12)
Block(2,11,9,LOG:12)
Block(2,11,10,LOG:12)
Block(2,11,12,LEAVES:12)
Block(2,11,18,LEAVES:12)
Block(2,11,19,LEAVES:12)
Block(2,12,-6,LEAVES:12)
Block(2,12,-3,LEAVES:12)
Block(2,12,8,LOG:12)
Block(2,12,9,LOG:12)
Block(2,12,10,LOG:12)
Block(2,12,12,LEAVES:12)
Block(2,12,16,LEAVES:12)
Block(2,12,17,LEAVES:12)
Block(2,12,18,LEAVES:12)
Block(2,13,-8,LEAVES:12)
Block(2,13,-4,LEAVES:12)
Block(2,13,-3,LEAVES:12)
Block(2,13,-1,LEAVES:12)
Block(2,13,5,LOG:12)
Block(2,13,12,LOG:12)
Block(2,13,14,LEAVES:12)
Block(2,13,16,LEAVES:12)
Block(2,14,-8,LEAVES:12)
Block(2,14,-4,LEAVES:12)
Block(2,14,-2,LEAVES:12)
Block(2,14,-1,LEAVES:12)
Block(2,14,4,LOG:12)
Block(2,14,5,LOG:12)
Block(2,14,6,LOG:12)
Block(2,14,7,LEAVES:12)
Block(2,14,12,LOG:12)
Block(2,14,13,LOG:12)
Block(2,14,15,LEAVES:12)
Block(2,15,1,LEAVES:12)
Block(2,15,5,LEAVES:12)
Block(2,15,6,LOG:12)
Block(2,15,9,LEAVES:12)
Block(2,15,13,LEAVES:12)
Block(2,15,14,LEAVES:12)
Block(2,15,15,LEAVES:12)
Block(2,15,17,LEAVES:12)
Block(2,15,18,LEAVES:12)
Block(2,16,0,LEAVES:12)
Block(2,16,1,LEAVES:12)
Block(2,16,2,LEAVES:12)
Block(2,16,3,LEAVES:12)
Block(2,16,6,LOG:12)
Block(2,16,7,LOG:12)
Block(2,16,8,LOG:12)
Block(2,16,9,LEAVES:12)
Block(2,16,12,LEAVES:12)
Block(2,16,13,LEAVES:12)
Block(2,16,15,LEAVES:12)
Block(2,16,20,LEAVES:12)
Block(2,17,-3,LEAVES:12)
Block(2,17,-2,LEAVES:12)
Block(2,17,6,LEAVES:12)
Block(2,17,10,LEAVES:12)
Block(2,17,12,LEAVES:12)
Block(2,17,13,LEAVES:12)
Block(2,18,4,LEAVES:12)
Block(2,19,5,LEAVES:12)
Block(2,19,7,LEAVES:12)
Block(2,19,8,LEAVES:12)
Block(2,19,11,LEAVES:12)
Block(2,19,12,LEAVES:12)
Block(2,20,8,LEAVES:12)
Block(2,20,9,LEAVES:12)
Block(2,20,10,LEAVES:12)
Block(2,20,12,LEAVES:12)
Block(2,21,1,LEAVES:12)
Block(2,21,2,LEAVES:12)
Block(2,21,5,LEAVES:12)
Block(2,21,7,LEAVES:12)
Block(2,21,9,LEAVES:12)
Block(2,21,10,LEAVES:12)
Block(2,22,5,LEAVES:12)
Block(2,22,9,LEAVES:12)
Block(2,23,5,LEAVES:12)
Block(3,0,4,LOG:12)
Block(3,0,5,LOG:12)
Block(3,0,6,LOG:12)
Block(3,1,5,LOG:12)
Block(3,2,4,LOG:12)
Block(3,2,5,LOG:12)
Block(3,3,5,LOG:12)
Block(3,5,16,LEAVES:12)
Block(3,6,14,LEAVES:12)
Block(3,7,-8,LEAVES:12)
Block(3,7,0,LEAVES:12)
Block(3,7,15,LEAVES:12)
Block(3,7,16,LEAVES:12)
Block(3,8,-1,LEAVES:12)
Block(3,8,0,LEAVES:12)
Block(3,8,18,LEAVES:12)
Block(3,8,19,LEAVES:12)
Block(3,9,-5,LEAVES:12)
Block(3,9,0,LEAVES:12)
Block(3,9,11,LEAVES:12)
Block(3,9,12,LEAVES:12)
Block(3,9,15,LEAVES:12)
Block(3,9,19,LEAVES:12)
Block(3,10,-6,LEAVES:12)
Block(3,10,-5,LEAVES:12)
Block(3,10,-2,LEAVES:12)
Block(3,10,-1,LEAVES:12)
Block(3,10,10,LOG:12)
Block(3,10,11,LOG:12)
Block(3,10,14,LEAVES:12)
Block(3,10,15,LEAVES:12)
Block(3,10,19,LEAVES:12)
Block(3,11,-6,LEAVES:12)
Block(3,11,-5,LEAVES:12)
Block(3,11,-1,LEAVES:12)
Block(3,11,2,LOG:12)
Block(3,11,3,LOG:12)
Block(3,11,4,LOG:12)
Block(3,11,10,LOG:12)
Block(3,11,13,LEAVES:12)
Block(3,11,15,LEAVES:12)
Block(3,11,19,LEAVES:12)
Block(3,11,20,LEAVES:12)
Block(3,12,-1,LEAVES:12)
Block(3,12,12,LEAVES:12)
Block(3,12,13,LEAVES:12)
Block(3,13,-3,LEAVES:12)
Block(3,13,13,LEAVES:12)
Block(3,13,14,LEAVES:12)
Block(3,13,15,LEAVES:12)
Block(3,13,16,LEAVES:12)
Block(3,14,-2,LEAVES:12)
Block(3,14,3,LOG:12)
Block(3,14,4,LOG:12)
Block(3,14,13,LOG:12)
Block(3,14,14,LOG:12)
Block(3,14,15,LOG:12)
Block(3,14,16,LEAVES:12)
Block(3,14,17,LEAVES:12)
Block(3,15,1,LEAVES:12)
Block(3,15,2,LEAVES:12)
Block(3,15,3,LOG:12)
Block(3,15,13,LEAVES:12)
Block(3,15,15,LEAVES:12)
Block(3,15,17,LEAVES:12)
Block(3,16,-6,LEAVES:12)
Block(3,16,-5,LEAVES:12)
Block(3,16,-2,LEAVES:12)
Block(3,16,2,LEAVES:12)
Block(3,16,6,LOG:12)
Block(3,16,8,LEAVES:12)
Block(3,16,9,LEAVES:12)
Block(3,16,10,LEAVES:12)
Block(3,16,13,LEAVES:12)
Block(3,16,15,LEAVES:12)
Block(3,16,16,LEAVES:12)
Block(3,17,-2,LEAVES:12)
Block(3,17,2,LEAVES:12)
Block(3,17,6,LOG:12)
Block(3,17,7,LEAVES:12)
Block(3,17,8,LEAVES:12)
Block(3,17,10,LEAVES:12)
Block(3,17,16,LEAVES:12)
Block(3,18,-2,LEAVES:12)
Block(3,18,4,LEAVES:12)
Block(3,18,6,LOG:12)
Block(3,18,10,LEAVES:12)
Block(3,18,15,LEAVES:12)
Block(3,19,5,LEAVES:12)
Block(3,19,6,LEAVES:12)
Block(3,19,7,LEAVES:12)
Block(3,20,3,LEAVES:12)
Block(3,20,4,LEAVES:12)
Block(3,20,5,LEAVES:12)
Block(3,20,7,LEAVES:12)
Block(3,20,8,LEAVES:12)
Block(3,20,12,LEAVES:12)
Block(3,20,13,LEAVES:12)
Block(3,20,14,LEAVES:12)
Block(3,21,2,LEAVES:12)
Block(3,21,3,LEAVES:12)
Block(3,21,5,LEAVES:12)
Block(3,21,8,LEAVES:12)
Block(3,21,9,LEAVES:12)
Block(3,21,10,LEAVES:12)
Block(3,21,13,LEAVES:12)
Block(3,22,3,LEAVES:12)
Block(3,22,11,LEAVES:12)
Block(4,4,18,LEAVES:12)
Block(4,4,19,LEAVES:12)
Block(4,5,-3,LEAVES:12)
Block(4,5,12,LEAVES:12)
Block(4,5,16,LEAVES:12)
Block(4,5,17,LEAVES:12)
Block(4,5,18,LEAVES:12)
Block(4,6,14,LEAVES:12)
Block(4,6,16,LEAVES:12)
Block(4,7,15,LEAVES:12)
Block(4,8,-1,LEAVES:12)
Block(4,8,13,LEAVES:12)
Block(4,8,14,LEAVES:12)
Block(4,8,15,LEAVES:12)
Block(4,8,17,LEAVES:12)
Block(4,8,18,LEAVES:12)
Block(4,9,-5,LEAVES:12)
Block(4,9,-4,LEAVES:12)
Block(4,9,11,LOG:12)
Block(4,9,12,LEAVES:12)
Block(4,9,13,LEAVES:12)
Block(4,9,15,LEAVES:12)
Block(4,9,20,LEAVES:12)
Block(4,10,1,LOG:12)
Block(4,10,2,LOG:12)
Block(4,10,11,LOG:12)
Block(4,10,13,LEAVES:12)
Block(4,10,17,LEAVES:12)
Block(4,11,-5,LEAVES:12)
Block(4,11,1,LEAVES:12)
Block(4,11,2,LOG:12)
Block(4,11,10,LOG:12)
Block(4,11,15,LEAVES:12)
Block(4,11,17,LEAVES:12)
Block(4,12,-5,LEAVES:12)
Block(4,12,-3,LEAVES:12)
Block(4,12,-1,LEAVES:12)
Block(4,12,0,LEAVES:12)
Block(4,12,1,LEAVES:12)
Block(4,12,10,LOG:12)
Block(4,12,12,LEAVES:12)
Block(4,12,15,LEAVES:12)
Block(4,12,17,LEAVES:12)
Block(4,12,19,LEAVES:12)
Block(4,13,-3,LEAVES:12)
Block(4,13,-1,LEAVES:12)
Block(4,13,11,LEAVES:12)
Block(4,13,12,LEAVES:12)
Block(4,13,13,LEAVES:12)
Block(4,13,15,LEAVES:12)
Block(4,13,16,LEAVES:12)
Block(4,13,17,LEAVES:12)
Block(4,13,19,LEAVES:12)
Block(4,14,-2,LEAVES:12)
Block(4,14,7,LEAVES:12)
Block(4,14,11,LEAVES:12)
Block(4,14,13,LEAVES:12)
Block(4,14,15,LEAVES:12)
Block(4,14,16,LEAVES:12)
Block(4,14,20,LEAVES:12)
Block(4,15,-4,LEAVES:12)
Block(4,15,-3,LEAVES:12)
Block(4,15,-2,LEAVES:12)
Block(4,15,0,LEAVES:12)
Block(4,15,1,LOG:12)
Block(4,15,2,LOG:12)
Block(4,15,3,LOG:12)
Block(4,15,4,LEAVES:12)
Block(4,15,8,LEAVES:12)
Block(4,15,9,LEAVES:12)
Block(4,15,15,LEAVES:12)
Block(4,16,-5,LEAVES:12)
Block(4,16,-4,LEAVES:12)
Block(4,16,-2,LEAVES:12)
Block(4,16,3,LEAVES:12)
Block(4,16,9,LEAVES:12)
Block(4,16,10,LEAVES:12)
Block(4,17,-4,LEAVES:12)
Block(4,17,2,LEAVES:12)
Block(4,17,3,LEAVES:12)
Block(4,17,16,LEAVES:12)
Block(4,17,17,LEAVES:12)
Block(4,18,3,LEAVES:12)
Block(4,18,4,LEAVES:12)
Block(4,18,5,LOG:12)
Block(4,18,6,LOG:12)
Block(4,18,9,LEAVES:12)
Block(4,18,10,LEAVES:12)
Block(4,18,17,LEAVES:12)
Block(4,18,18,LEAVES:12)
Block(4,19,5,LOG:12)
Block(4,19,6,LEAVES:12)
Block(4,19,7,LEAVES:12)
Block(4,19,10,LEAVES:12)
Block(4,19,17,LEAVES:12)
Block(4,20,5,LEAVES:12)
Block(4,20,7,LEAVES:12)
Block(4,20,13,LEAVES:12)
Block(4,21,5,LEAVES:12)
Block(4,21,6,LEAVES:12)
Block(4,21,8,LEAVES:12)
Block(4,22,6,LEAVES:12)
Block(4,22,8,LEAVES:12)
Block(4,23,5,LEAVES:12)
Block(5,4,19,LEAVES:12)
Block(5,4,20,LEAVES:12)
Block(5,5,-2,LEAVES:12)
Block(5,5,12,LEAVES:12)
Block(5,6,0,LEAVES:12)
Block(5,6,13,LEAVES:12)
Block(5,6,14,LEAVES:12)
Block(5,6,15,LEAVES:12)
Block(5,6,16,LEAVES:12)
Block(5,7,-6,LEAVES:12)
Block(5,7,7,LEAVES:12)
Block(5,7,15,LOG:12)
Block(5,7,16,LOG:12)
Block(5,7,17,LEAVES:12)
Block(5,8,-4,LEAVES:12)
Block(5,8,-3,LEAVES:12)
Block(5,8,-1,LEAVES:12)
Block(5,8,6,LEAVES:12)
Block(5,8,7,LEAVES:12)
Block(5,8,15,LEAVES:12)
Block(5,8,17,LEAVES:12)
Block(5,9,-4,LEAVES:12)
Block(5,9,-2,LEAVES:12)
Block(5,9,-1,LEAVES:12)
Block(5,9,2,LEAVES:12)
Block(5,9,11,LOG:12)
Block(5,9,12,LOG:12)
Block(5,9,15,LEAVES:12)
Block(5,9,16,LEAVES:12)
Block(5,10,-3,LEAVES:12)
Block(5,10,1,LOG:12)
Block(5,10,9,LEAVES:12)
Block(5,10,14,LEAVES:12)
Block(5,10,16,LEAVES:12)
Block(5,11,-4,LEAVES:12)
Block(5,11,0,LEAVES:12)
Block(5,11,2,LOG:12)
Block(5,11,3,LEAVES:12)
Block(5,11,15,LEAVES:12)
Block(5,11,18,LEAVES:12)
Block(5,12,-5,LEAVES:12)
Block(5,12,-4,LEAVES:12)
Block(5,12,-3,LEAVES:12)
Block(5,12,-2,LEAVES:12)
Block(5,12,10,LOG:12)
Block(5,12,15,LEAVES:12)
Block(5,12,17,LEAVES:12)
Block(5,12,18,LEAVES:12)
Block(5,13,-4,LEAVES:12)
Block(5,13,-3,LEAVES:12)
Block(5,13,-2,LEAVES:12)
Block(5,13,-1,LEAVES:12)
Block(5,13,11,LEAVES:12)
Block(5,14,-2,LOG:12)
Block(5,14,-1,LOG:12)
Block(5,14,0,LOG:12)
Block(5,14,1,LOG:12)
Block(5,14,7,LEAVES:12)
Block(5,14,8,LEAVES:12)
Block(5,14,12,LEAVES:12)
Block(5,14,13,LEAVES:12)
Block(5,14,16,LEAVES:12)
Block(5,14,17,LEAVES:12)
Block(5,15,-2,LEAVES:12)
Block(5,15,0,LEAVES:12)
Block(5,15,1,LOG:12)
Block(5,15,7,LEAVES:12)
Block(5,15,8,LEAVES:12)
Block(5,15,15,LEAVES:12)
Block(5,15,17,LEAVES:12)
Block(5,16,-2,LEAVES:12)
Block(5,16,-1,LEAVES:12)
Block(5,16,5,LEAVES:12)
Block(5,16,7,LEAVES:12)
Block(5,16,12,LEAVES:12)
Block(5,16,14,LEAVES:12)
Block(5,16,15,LEAVES:12)
Block(5,17,-1,LEAVES:12)
Block(5,17,5,LEAVES:12)
Block(5,17,7,LEAVES:12)
Block(5,17,9,LEAVES:12)
Block(5,17,11,LEAVES:12)
Block(5,18,-2,LEAVES:12)
Block(5,18,3,LEAVES:12)
Block(5,18,5,LEAVES:12)
Block(5,18,6,LEAVES:12)
Block(5,18,7,LEAVES:12)
Block(5,18,9,LEAVES:12)
Block(5,18,10,LEAVES:12)
Block(5,18,11,LEAVES:12)
Block(5,19,1,LEAVES:12)
Block(5,19,3,LEAVES:12)
Block(5,19,5,LEAVES:12)
Block(5,19,6,LEAVES:12)
Block(5,19,10,LEAVES:12)
Block(5,20,5,LEAVES:12)
Block(5,22,6,LEAVES:12)
Block(5,22,7,LEAVES:12)
Block(5,23,7,LEAVES:12)
Block(5,23,8,LEAVES:12)
Block(5,24,7,LEAVES:12)
Block(6,4,15,LEAVES:12)
Block(6,5,-2,LEAVES:12)
Block(6,5,15,LEAVES:12)
Block(6,5,17,LEAVES:12)
Block(6,5,19,LEAVES:12)
Block(6,6,-6,LEAVES:12)
Block(6,6,-5,LEAVES:12)
Block(6,6,-1,LEAVES:12)
Block(6,6,2,LEAVES:12)
Block(6,6,13,LEAVES:12)
Block(6,6,15,LEAVES:12)
Block(6,6,16,LEAVES:12)
Block(6,6,17,LEAVES:12)
Block(6,6,19,LEAVES:12)
Block(6,7,-1,LEAVES:12)
Block(6,7,11,LEAVES:12)
Block(6,7,13,LEAVES:12)
Block(6,7,14,LOG:12)
Block(6,7,15,LOG:12)
Block(6,7,16,LEAVES:12)
Block(6,7,20,LEAVES:12)
Block(6,8,-3,LEAVES:12)
Block(6,8,6,LEAVES:12)
Block(6,8,12,LOG:12)
Block(6,8,13,LOG:12)
Block(6,8,14,LOG:12)
Block(6,8,15,LEAVES:12)
Block(6,9,-2,LEAVES:12)
Block(6,9,2,LEAVES:12)
Block(6,9,3,LEAVES:12)
Block(6,9,10,LEAVES:12)
Block(6,9,12,LOG:12)
Block(6,10,0,LOG:12)
Block(6,10,1,LOG:12)
Block(6,10,2,LEAVES:12)
Block(6,10,10,LEAVES:12)
Block(6,10,16,LEAVES:12)
Block(6,10,17,LEAVES:12)
Block(6,10,18,LEAVES:12)
Block(6,11,-6,LEAVES:12)
Block(6,11,-5,LEAVES:12)
Block(6,11,-2,LEAVES:12)
Block(6,11,0,LEAVES:12)
Block(6,11,2,LOG:12)
Block(6,11,3,LOG:12)
Block(6,11,12,LEAVES:12)
Block(6,11,14,LEAVES:12)
Block(6,11,15,LEAVES:12)
Block(6,11,17,LEAVES:12)
Block(6,11,18,LEAVES:12)
Block(6,12,-2,LEAVES:12)
Block(6,12,0,LEAVES:12)
Block(6,12,2,LEAVES:12)
Block(6,12,4,LEAVES:12)
Block(6,12,6,LEAVES:12)
Block(6,12,9,LOG:12)
Block(6,12,10,LOG:12)
Block(6,12,15,LEAVES:12)
Block(6,12,17,LEAVES:12)
Block(6,13,-4,LEAVES:12)
Block(6,13,-3,LOG:12)
Block(6,13,-2,LOG:12)
Block(6,13,-1,LEAVES:12)
Block(6,13,0,LEAVES:12)
Block(6,13,2,LEAVES:12)
Block(6,13,4,LEAVES:12)
Block(6,13,8,LEAVES:12)
Block(6,13,9,LOG:12)
Block(6,13,11,LEAVES:12)
Block(6,13,15,LEAVES:12)
Block(6,14,-6,LEAVES:12)
Block(6,14,-4,LEAVES:12)
Block(6,14,-2,LOG:12)
Block(6,14,-1,LEAVES:12)
Block(6,14,3,LEAVES:12)
Block(6,14,8,LEAVES:12)
Block(6,14,10,LEAVES:12)
Block(6,14,11,LEAVES:12)
Block(6,14,12,LEAVES:12)
Block(6,15,-2,LEAVES:12)
Block(6,15,4,LEAVES:12)
Block(6,15,17,LEAVES:12)
Block(6,15,18,LEAVES:12)
Block(6,15,19,LEAVES:12)
Block(6,16,8,LEAVES:12)
Block(6,16,12,LEAVES:12)
Block(6,16,13,LEAVES:12)
Block(6,16,14,LEAVES:12)
Block(6,16,15,LEAVES:12)
Block(6,16,18,LEAVES:12)
Block(6,17,-1,LEAVES:12)
Block(6,17,0,LEAVES:12)
Block(6,17,5,LEAVES:12)
Block(6,17,7,LEAVES:12)
Block(6,17,8,LEAVES:12)
Block(6,17,9,LEAVES:12)
Block(6,17,10,LEAVES:12)
Block(6,17,11,LEAVES:12)
Block(6,17,16,LEAVES:12)
Block(6,18,0,LEAVES:12)
Block(6,18,1,LEAVES:12)
Block(6,19,0,LEAVES:12)
Block(6,19,2,LEAVES:12)
Block(6,19,3,LEAVES:12)
Block(6,19,6,LEAVES:12)
Block(6,19,7,LEAVES:12)
Block(6,20,5,LEAVES:12)
Block(6,20,7,LEAVES:12)
Block(6,21,2,LEAVES:12)
Block(6,21,4,LEAVES:12)
Block(6,21,5,LEAVES:12)
Block(7,4,18,LEAVES:12)
Block(7,5,15,LEAVES:12)
Block(7,5,17,LEAVES:12)
Block(7,5,18,LEAVES:12)
Block(7,6,-5,LEAVES:12)
Block(7,6,1,LEAVES:12)
Block(7,6,7,LEAVES:12)
Block(7,7,-5,LEAVES:12)
Block(7,7,-1,LEAVES:12)
Block(7,7,0,LEAVES:12)
Block(7,7,1,LEAVES:12)
Block(7,7,12,LEAVES:12)
Block(7,7,13,LEAVES:12)
Block(7,7,16,LEAVES:12)
Block(7,7,17,LEAVES:12)
Block(7,8,-3,LEAVES:12)
Block(7,8,-1,LEAVES:12)
Block(7,8,3,LEAVES:12)
Block(7,8,4,LEAVES:12)
Block(7,8,6,LEAVES:12)
Block(7,8,15,LEAVES:12)
Block(7,8,17,LEAVES:12)
Block(7,9,-2,LOG:12)
Block(7,9,-1,LOG:12)
Block(7,9,0,LOG:12)
Block(7,9,3,LEAVES:12)
Block(7,9,5,LEAVES:12)
Block(7,9,6,LEAVES:12)
Block(7,9,12,LEAVES:12)
Block(7,9,14,LEAVES:12)
Block(7,9,15,LEAVES:12)
Block(7,10,-4,LEAVES:12)
Block(7,10,-3,LEAVES:12)
Block(7,10,-2,LEAVES:12)
Block(7,10,0,LOG:12)
Block(7,10,1,LEAVES:12)
Block(7,10,6,LEAVES:12)
Block(7,10,10,LEAVES:12)
Block(7,10,11,LEAVES:12)
Block(7,10,13,LEAVES:12)
Block(7,10,14,LEAVES:12)
Block(7,11,-5,LEAVES:12)
Block(7,11,-4,LEAVES:12)
Block(7,11,-2,LEAVES:12)
Block(7,11,1,LEAVES:12)
Block(7,11,3,LOG:12)
Block(7,11,4,LOG:12)
Block(7,11,6,LEAVES:12)
Block(7,11,7,LEAVES:12)
Block(7,11,9,LEAVES:12)
Block(7,11,10,LEAVES:12)
Block(7,11,11,LEAVES:12)
Block(7,11,14,LEAVES:12)
Block(7,12,-4,LEAVES:12)
Block(7,12,-2,LEAVES:12)
Block(7,12,0,LEAVES:12)
Block(7,12,1,LEAVES:12)
Block(7,12,4,LEAVES:12)
Block(7,12,5,LEAVES:12)
Block(7,12,11,LEAVES:12)
Block(7,13,9,LOG:12)
Block(7,13,14,LEAVES:12)
Block(7,13,15,LEAVES:12)
Block(7,14,-5,LEAVES:12)
Block(7,14,-4,LEAVES:12)
Block(7,14,-1,LEAVES:12)
Block(7,14,0,LEAVES:12)
Block(7,14,10,LEAVES:12)
Block(7,14,15,LEAVES:12)
Block(7,15,-2,LEAVES:12)
Block(7,15,0,LEAVES:12)
Block(7,15,8,LEAVES:12)
Block(7,15,13,LEAVES:12)
Block(7,15,14,LEAVES:12)
Block(7,15,18,LEAVES:12)
Block(7,16,-5,LEAVES:12)
Block(7,16,-3,LEAVES:12)
Block(7,16,-2,LEAVES:12)
Block(7,16,4,LEAVES:12)
Block(7,16,5,LEAVES:12)
Block(7,16,6,LEAVES:12)
Block(7,16,7,LEAVES:12)
Block(7,16,8,LEAVES:12)
Block(7,16,10,LEAVES:12)
Block(7,16,13,LEAVES:12)
Block(7,16,14,LEAVES:12)
Block(7,17,5,LEAVES:12)
Block(7,17,10,LEAVES:12)
Block(7,17,13,LEAVES:12)
Block(7,17,14,LEAVES:12)
Block(7,18,5,LEAVES:12)
Block(7,18,10,LEAVES:12)
Block(7,19,1,LEAVES:12)
Block(7,19,2,LEAVES:12)
Block(7,20,7,LEAVES:12)
Block(7,20,8,LEAVES:12)
Block(7,20,9,LEAVES:12)
Block(7,21,3,LEAVES:12)
Block(7,21,4,LEAVES:12)
Block(7,21,8,LEAVES:12)
Block(7,22,6,LEAVES:12)
Block(8,4,18,LEAVES:12)
Block(8,5,-3,LEAVES:12)
Block(8,5,1,LEAVES:12)
Block(8,5,5,LEAVES:12)
Block(8,5,6,LEAVES:12)
Block(8,5,15,LEAVES:12)
Block(8,6,-4,LEAVES:12)
Block(8,6,1,LEAVES:12)
Block(8,6,2,LEAVES:12)
Block(8,6,3,LEAVES:12)
Block(8,6,6,LEAVES:12)
Block(8,6,9,LEAVES:12)
Block(8,6,15,LEAVES:12)
Block(8,7,-5,LEAVES:12)
Block(8,7,-4,LEAVES:12)
Block(8,7,6,LEAVES:12)
Block(8,7,11,LEAVES:12)
Block(8,7,12,LEAVES:12)
Block(8,8,-4,LEAVES:12)
Block(8,8,-3,LEAVES:12)
Block(8,8,-2,LEAVES:12)
Block(8,8,-1,LEAVES:12)
Block(8,8,4,LEAVES:12)
Block(8,8,17,LEAVES:12)
Block(8,8,18,LEAVES:12)
Block(8,8,19,LEAVES:12)
Block(8,9,-3,LOG:12)
Block(8,9,-2,LOG:12)
Block(8,9,-1,LEAVES:12)
Block(8,9,0,LEAVES:12)
Block(8,9,5,LEAVES:12)
Block(8,9,13,LEAVES:12)
Block(8,9,14,LEAVES:12)
Block(8,9,18,LEAVES:12)
Block(8,10,-2,LEAVES:12)
Block(8,10,0,LEAVES:12)
Block(8,10,1,LEAVES:12)
Block(8,10,4,LOG:12)
Block(8,10,5,LOG:12)
Block(8,10,8,LEAVES:12)
Block(8,10,9,LEAVES:12)
Block(8,10,13,LEAVES:12)
Block(8,10,16,LEAVES:12)
Block(8,11,-3,LEAVES:12)
Block(8,11,-2,LEAVES:12)
Block(8,11,-1,LEAVES:12)
Block(8,11,1,LEAVES:12)
Block(8,11,2,LEAVES:12)
Block(8,11,4,LOG:12)
Block(8,11,5,LEAVES:12)
Block(8,11,7,LEAVES:12)
Block(8,11,9,LEAVES:12)
Block(8,11,13,LEAVES:12)
Block(8,11,14,LEAVES:12)
Block(8,12,-2,LEAVES:12)
Block(8,12,-1,LEAVES:12)
Block(8,12,5,LEAVES:12)
Block(8,12,7,LEAVES:12)
Block(8,12,9,LEAVES:12)
Block(8,12,11,LEAVES:12)
Block(8,12,12,LEAVES:12)
Block(8,12,13,LEAVES:12)
Block(8,12,16,LEAVES:12)
Block(8,13,-2,LEAVES:12)
Block(8,13,5,LEAVES:12)
Block(8,13,9,LOG:12)
Block(8,13,11,LEAVES:12)
Block(8,13,15,LEAVES:12)
Block(8,13,16,LEAVES:12)
Block(8,14,-6,LEAVES:12)
Block(8,14,-5,LEAVES:12)
Block(8,14,9,LOG:12)
Block(8,14,10,LEAVES:12)
Block(8,15,0,LEAVES:12)
Block(8,15,1,LEAVES:12)
Block(8,15,2,LEAVES:12)
Block(8,15,3,LEAVES:12)
Block(8,15,4,LEAVES:12)
Block(8,15,8,LEAVES:12)
Block(8,15,9,LEAVES:12)
Block(8,15,10,LEAVES:12)
Block(8,15,12,LEAVES:12)
Block(8,15,13,LEAVES:12)
Block(8,16,-4,LEAVES:12)
Block(8,16,-3,LEAVES:12)
Block(8,16,1,LEAVES:12)
Block(8,16,4,LEAVES:12)
Block(8,16,7,LEAVES:12)
Block(8,16,8,LEAVES:12)
Block(8,16,10,LEAVES:12)
Block(8,16,15,LEAVES:12)
Block(8,17,-1,LEAVES:12)
Block(8,17,8,LEAVES:12)
Block(8,18,4,LEAVES:12)
Block(8,18,5,LEAVES:12)
Block(8,19,5,LEAVES:12)
Block(8,20,8,LEAVES:12)
Block(8,21,3,LEAVES:12)
Block(8,22,3,LEAVES:12)
Block(9,5,0,LEAVES:12)
Block(9,6,-2,LEAVES:12)
Block(9,6,0,LEAVES:12)
Block(9,6,2,LEAVES:12)
Block(9,6,8,LEAVES:12)
Block(9,6,9,LEAVES:12)
Block(9,6,14,LEAVES:12)
Block(9,6,15,LEAVES:12)
Block(9,7,-2,LEAVES:12)
Block(9,7,0,LEAVES:12)
Block(9,7,2,LEAVES:12)
Block(9,7,6,LEAVES:12)
Block(9,7,7,LEAVES:12)
Block(9,7,8,LEAVES:12)
Block(9,7,15,LEAVES:12)
Block(9,8,-4,LEAVES:12)
Block(9,8,-2,LEAVES:12)
Block(9,8,-1,LEAVES:12)
Block(9,8,0,LEAVES:12)
Block(9,8,2,LEAVES:12)
Block(9,8,4,LEAVES:12)
Block(9,8,6,LEAVES:12)
Block(9,8,18,LEAVES:12)
Block(9,9,-6,LEAVES:12)
Block(9,9,-4,LEAVES:12)
Block(9,9,-2,LEAVES:12)
Block(9,9,-1,LEAVES:12)
Block(9,9,3,LEAVES:12)
Block(9,9,5,LOG:12)
Block(9,9,13,LEAVES:12)
Block(9,10,-4,LEAVES:12)
Block(9,10,-3,LEAVES:12)
Block(9,10,-2,LEAVES:12)
Block(9,10,3,LEAVES:12)
Block(9,10,4,LEAVES:12)
Block(9,10,5,LOG:12)
Block(9,10,7,LEAVES:12)
Block(9,10,8,LEAVES:12)
Block(9,10,9,LEAVES:12)
Block(9,10,13,LEAVES:12)
Block(9,11,-3,LEAVES:12)
Block(9,11,2,LEAVES:12)
Block(9,11,3,LEAVES:12)
Block(9,11,5,LEAVES:12)
Block(9,11,8,LEAVES:12)
Block(9,11,10,LEAVES:12)
Block(9,11,14,LEAVES:12)
Block(9,11,15,LEAVES:12)
Block(9,12,-1,LEAVES:12)
Block(9,12,0,LEAVES:12)
Block(9,12,3,LEAVES:12)
Block(9,12,7,LEAVES:12)
Block(9,12,8,LEAVES:12)
Block(9,12,16,LEAVES:12)
Block(9,13,-3,LEAVES:12)
Block(9,13,-2,LEAVES:12)
Block(9,13,0,LEAVES:12)
Block(9,13,1,LEAVES:12)
Block(9,13,8,LEAVES:12)
Block(9,13,9,LEAVES:12)
Block(9,13,10,LEAVES:12)
Block(9,13,11,LEAVES:12)
Block(9,14,-2,LEAVES:12)
Block(9,14,0,LEAVES:12)
Block(9,14,9,LOG:12)
Block(9,14,10,LOG:12)
Block(9,14,11,LEAVES:12)
Block(9,14,12,LEAVES:12)
Block(9,15,1,LEAVES:12)
Block(9,15,3,LEAVES:12)
Block(9,15,10,LEAVES:12)
Block(9,15,12,LEAVES:12)
Block(9,16,-4,LEAVES:12)
Block(9,16,10,LEAVES:12)
Block(9,16,11,LEAVES:12)
Block(9,17,-4,LEAVES:12)
Block(9,17,6,LEAVES:12)
Block(9,17,11,LEAVES:12)
Block(9,18,5,LEAVES:12)
Block(9,18,6,LEAVES:12)
Block(9,18,10,LEAVES:12)
Block(10,5,-3,LEAVES:12)
Block(10,5,4,LEAVES:12)
Block(10,6,1,LEAVES:12)
Block(10,6,3,LEAVES:12)
Block(10,6,9,LEAVES:12)
Block(10,6,10,LEAVES:12)
Block(10,6,15,LEAVES:12)
Block(10,6,16,LEAVES:12)
Block(10,7,-2,LEAVES:12)
Block(10,7,0,LEAVES:12)
Block(10,7,1,LEAVES:12)
Block(10,7,2,LEAVES:12)
Block(10,7,3,LEAVES:12)
Block(10,8,3,LEAVES:12)
Block(10,8,4,LEAVES:12)
Block(10,8,5,LEAVES:12)
Block(10,8,6,LEAVES:12)
Block(10,9,-5,LEAVES:12)
Block(10,9,-4,LEAVES:12)
Block(10,9,-1,LEAVES:12)
Block(10,9,0,LEAVES:12)
Block(10,9,5,LOG:12)
Block(10,9,6,LEAVES:12)
Block(10,9,7,LEAVES:12)
Block(10,10,-4,LEAVES:12)
Block(10,10,-2,LEAVES:12)
Block(10,10,0,LEAVES:12)
Block(10,10,5,LEAVES:12)
Block(10,10,7,LEAVES:12)
Block(10,10,12,LEAVES:12)
Block(10,11,-5,LEAVES:12)
Block(10,11,-3,LEAVES:12)
Block(10,11,-2,LEAVES:12)
Block(10,11,5,LEAVES:12)
Block(10,11,6,LEAVES:12)
Block(10,11,10,LEAVES:12)
Block(10,11,12,LEAVES:12)
Block(10,12,-1,LEAVES:12)
Block(10,12,6,LEAVES:12)
Block(10,12,10,LEAVES:12)
Block(10,12,12,LEAVES:12)
Block(10,12,14,LEAVES:12)
Block(10,13,-2,LEAVES:12)
Block(10,13,-1,LEAVES:12)
Block(10,13,5,LEAVES:12)
Block(10,13,8,LEAVES:12)
Block(10,13,10,LEAVES:12)
Block(10,13,11,LEAVES:12)
Block(10,13,12,LEAVES:12)
Block(10,13,14,LEAVES:12)
Block(10,14,6,LEAVES:12)
Block(10,14,8,LEAVES:12)
Block(10,14,10,LOG:12)
Block(10,14,11,LEAVES:12)
Block(10,14,15,LEAVES:12)
Block(10,15,10,LEAVES:12)
Block(10,17,6,LEAVES:12)
Block(10,17,11,LEAVES:12)
Block(10,17,12,LEAVES:12)
Block(10,18,12,LEAVES:12)
Block(10,18,13,LEAVES:12)
Block(10,19,12,LEAVES:12)
Block(11,5,1,LEAVES:12)
Block(11,5,7,LEAVES:12)
Block(11,5,16,LEAVES:12)
Block(11,6,-3,LEAVES:12)
Block(11,6,-2,LEAVES:12)
Block(11,6,1,LEAVES:12)
Block(11,6,5,LEAVES:12)
Block(11,6,7,LEAVES:12)
Block(11,7,-2,LEAVES:12)
Block(11,7,5,LEAVES:12)
Block(11,7,7,LEAVES:12)
Block(11,7,9,LEAVES:12)
Block(11,8,-2,LEAVES:12)
Block(11,8,3,LEAVES:12)
Block(11,8,5,LEAVES:12)
Block(11,8,6,LEAVES:12)
Block(11,8,7,LEAVES:12)
Block(11,8,9,LEAVES:12)
Block(11,9,-6,LEAVES:12)
Block(11,9,-5,LEAVES:12)
Block(11,9,1,LEAVES:12)
Block(11,9,3,LEAVES:12)
Block(11,9,5,LEAVES:12)
Block(11,9,6,LEAVES:12)
Block(11,9,10,LEAVES:12)
Block(11,10,0,LEAVES:12)
Block(11,10,1,LEAVES:12)
Block(11,10,2,LEAVES:12)
Block(11,10,5,LEAVES:12)
Block(11,10,9,LEAVES:12)
Block(11,11,-4,LEAVES:12)
Block(11,11,-3,LEAVES:12)
Block(11,11,1,LEAVES:12)
Block(11,11,13,LEAVES:12)
Block(11,12,-1,LEAVES:12)
Block(11,12,6,LEAVES:12)
Block(11,12,7,LEAVES:12)
Block(11,12,10,LEAVES:12)
Block(11,12,12,LEAVES:12)
Block(11,12,13,LEAVES:12)
Block(11,13,7,LEAVES:12)
Block(11,13,8,LEAVES:12)
Block(11,14,7,LEAVES:12)
Block(11,14,8,LEAVES:12)
Block(11,14,11,LEAVES:12)
Block(11,14,12,LEAVES:12)
Block(11,15,10,LEAVES:12)
Block(11,15,12,LEAVES:12)
Block(11,16,7,LEAVES:12)
Block(11,16,9,LEAVES:12)
Block(11,16,10,LEAVES:12)
Block(12,5,-4,LEAVES:12)
Block(12,5,-3,LEAVES:12)
Block(12,5,4,LEAVES:12)
Block(12,6,-3,LEAVES:12)
Block(12,6,8,LEAVES:12)
Block(12,7,5,LEAVES:12)
Block(12,7,7,LEAVES:12)
Block(12,7,8,LEAVES:12)
Block(12,8,-3,LEAVES:12)
Block(12,8,-2,LEAVES:12)
Block(12,9,-2,LEAVES:12)
Block(12,9,2,LEAVES:12)
Block(12,9,3,LEAVES:12)
Block(12,9,6,LEAVES:12)
Block(12,9,7,LEAVES:12)
Block(12,10,1,LEAVES:12)
Block(12,10,5,LEAVES:12)
Block(12,10,7,LEAVES:12)
Block(12,10,13,LEAVES:12)
Block(12,11,-4,LEAVES:12)
Block(12,11,2,LEAVES:12)
Block(12,11,4,LEAVES:12)
Block(12,11,5,LEAVES:12)
Block(12,11,9,LEAVES:12)
Block(12,11,10,LEAVES:12)
Block(12,11,13,LEAVES:12)
Block(12,12,-4,LEAVES:12)
Block(12,12,10,LEAVES:12)
Block(12,13,10,LEAVES:12)
Block(12,14,6,LEAVES:12)
Block(12,14,7,LEAVES:12)
Block(12,15,12,LEAVES:12)
Block(12,15,13,LEAVES:12)
Block(12,15,14,LEAVES:12)
Block(12,16,8,LEAVES:12)
Block(12,16,9,LEAVES:12)
Block(12,16,13,LEAVES:12)
Block(12,17,11,LEAVES:12)
Block(13,5,-4,LEAVES:12)
Block(13,5,8,LEAVES:12)
Block(13,6,4,LEAVES:12)
Block(13,6,5,LEAVES:12)
Block(13,6,8,LEAVES:12)
Block(13,7,-1,LEAVES:12)
Block(13,7,5,LEAVES:12)
Block(13,8,-2,LEAVES:12)
Block(13,8,-1,LEAVES:12)
Block(13,8,5,LEAVES:12)
Block(13,9,1,LEAVES:12)
Block(13,9,2,LEAVES:12)
Block(13,10,7,LEAVES:12)
Block(13,10,8,LEAVES:12)
Block(13,10,9,LEAVES:12)
Block(13,11,3,LEAVES:12)
Block(13,11,4,LEAVES:12)
Block(13,11,8,LEAVES:12)
Block(13,11,9,LEAVES:12)
Block(13,12,6,LEAVES:12)
Block(13,13,9,LEAVES:12)
Block(13,13,10,LEAVES:12)
Block(13,14,10,LEAVES:12)
Block(13,15,13,LEAVES:12)
Block(13,16,8,LEAVES:12)
Block(13,17,8,LEAVES:12)
Block(14,5,3,LEAVES:12)
Block(14,5,4,LEAVES:12)
Block(14,6,4,LEAVES:12)
Block(14,7,-1,LEAVES:12)
Block(14,8,4,LEAVES:12)
Block(14,8,5,LEAVES:12)
Block(14,9,5,LEAVES:12)
Block(14,10,8,LEAVES:12)
Block(14,11,3,LEAVES:12)
Block(14,12,3,LEAVES:12)
Block(14,12,11,LEAVES:12)
Block(14,13,10,LEAVES:12)
Block(14,13,11,LEAVES:12)
Block(15,5,3,LEAVES:12)
Block(15,7,6,LEAVES:12)
Block(15,8,5,LEAVES:12)
Block(15,8,6,LEAVES:12)
Block(15,12,11,LEAVES:12)
Block(16,7,6,LEAVES:12)


#######################################################################
# +-----------------------------------------------------------------+ #
# |                             Entities                            | #
# +-----------------------------------------------------------------+ #
#######################################################################

# Entity() spawns an entity instead of a block. The entity is spawned only once when the BO3 is spawned.
# Entities are persistent by default so they don't de-spawn when no player is near, they are only unloaded.
# Usage: Entity(x,y,z,mobName,groupSize,NameTagOrNBTFileName) or Entity(x,y,z,mobName,groupSize)
# Use /tc entities or /otg entities to get a list of entities that can be used as mobName, this includes entities added by other mods.
# NameTagOrNBTFileName can be either a nametag for the mob or an nbt file (such as mymobinfo.nbt or mymobinfo.txt).
# When using a text file you can use the same mob spawning parameters used with the /summon command to equip the
# entity and give it custom attributes etc. You can copy the DATA part of a summon command including surrounding
# curly braces to a .txt file, for instance for: "/summon Skeleton x y z {DATA}"

#######################################################################
# +-----------------------------------------------------------------+ #
# |                            BO3 checks                           | #
# +-----------------------------------------------------------------+ #
#######################################################################

# Require a condition at a certain location in order for the BO3 to be spawned.
# BlockCheck(x,y,z,BlockName[,BlockName[,...]]) - one of the blocks must be at the location
# BlockCheckNot(x,y,z,BlockName[,BlockName[,...]]) - all the blocks must not be at the location
# LightCheck(x,y,z,minLightLevel,maxLightLevel) - light must be between min and max (inclusive)

# You can use "Solid" as a BlockName for matching all solid blocks or "All" to match all blocks that aren't air.

# Examples:
BlockCheck(0,-1,0,GRASS,DIRT,DIRT:2,SAND)
#   BlockCheck(0,-1,0,Solid)       Require any solid block just below the object
#   BlockCheck(0,-1,0,WOOL)        Require any type of wool just below the object
#   BlockCheck(0,-1,0,WOOL:0)      Require white wool just below the object
#   BlockCheckNot(0,-1,0,WOOL:0)   Require that there is no white wool below the object
#   LightCheck(0,0,0,0,1)          Require almost complete darkness just below the object

