#######################################################################
# +-----------------------------------------------------------------+ #
# |                            BO3 object                           | #
# +-----------------------------------------------------------------+ #
#######################################################################

# The descriptions in this file are accurate only for TerrainControl and OTG.
# For MCW and OTG+ these descriptions are only accurate if the BO3 is used as a CustomObject.
# MCW and OTG+ completely reimplemented CustomStructure, check the MCW/OTG+ documentation for more information.

# This is the config file of a custom object.
# If you add this object correctly to your BiomeConfigs, it will spawn in the world.

# This is the creator of this BO3 object
Author: Unknown

# A short description of this BO3 object
Description: This BO3 was converted from a schematic using OTGEdit. The author and description information of the schematic could not be found. If you know who the author of the schematic is then please add this information.

# The BO3 version, don't change this! It can be used by external applications to do a version check.
Version: 3

# The settings mode, WriteAll, WriteWithoutComments or WriteDisable. See WorldConfig.
SettingsMode: WriteDisable

#######################################################################
# +-----------------------------------------------------------------+ #
# |                          Main settings                          | #
# +-----------------------------------------------------------------+ #
#######################################################################

# This needs to be set to true to spawn the object in the Tree and Sapling resources.
Tree: true

# The frequency of the BO3 from 1 to 200. Tries this many times to spawn this BO3 when using the CustomObject(...) resource.
# Ignored by Tree(..), Sapling(..) and CustomStructure(..)
Frequency: 40

# The rarity of the BO3 from 0 to 100. Each spawn attempt has rarity% chance to succeed when using the CustomObject(...) resource.
# Ignored by Tree(..), Sapling(..) and CustomStructure(..)
Rarity: 100.0

# If you set this to true, the BO3 will be placed with a random rotation.
RotateRandomly: true

# The spawn height of the BO3 - randomY, highestBlock or highestSolidBlock.
SpawnHeight: highestSolidBlock

# The height limits for the BO3.
MinHeight: 0

MaxHeight: 256

# Objects can have other objects attached to it: branches. Branches can also
# have branches attached to it, which can also have branches, etc. This is the
# maximum branch depth for this objects.
MaxBranchDepth: 10

# When spawned with the UseWorld keyword, this BO3 should NOT spawn in the following biomes.
# If you writer.write the BO3 name directly in the BiomeConfigs, this will be ignored.
ExcludedBiomes: All

# To optimise this BO3 for faster loading times you can use Notepad++ to find/replace comments and abbreviate things.
# Notepad++ find/replace with regex:
# Find: ^[#;].* replace to nothing removes all lines starting with # 
# Find: ^\s*$ replace to nothing removes most empty lines 
# Notepad++ find/replace without regex:
# *Warning: This will only work for OTG 1.10.2 v21 / OTG 1.11.2 v6 or higher. B( is not recognised by lower versions.
# Find: Block( replace to B(

#######################################################################
# +-----------------------------------------------------------------+ #
# |                      Source block settings                      | #
# +-----------------------------------------------------------------+ #
#######################################################################

# The block(s) the BO3 should spawn in.
SourceBlocks: AIR

# The maximum percentage of the BO3 that can be outside the SourceBlock.
# The BO3 won't be placed on a location with more blocks outside the SourceBlock than this percentage.
MaxPercentageOutsideSourceBlock: 0

# What to do when a block is about to be placed outside the SourceBlock? (dontPlace, placeAnyway)
OutsideSourceBlock: dontPlace

#######################################################################
# +-----------------------------------------------------------------+ #
# |                              Blocks                             | #
# +-----------------------------------------------------------------+ #
#######################################################################

# All the blocks used in the BO3 are listed here. Possible blocks:
# Block(x,y,z,id[.data][,nbtfile.nbt) or B(x,y,z,id[.data][,nbtfile.nbt)
# RandomBlock(x,y,z,id[:data][,nbtfile.nbt],chance[,id[:data][,nbtfile.nbt],chance[,...]])
# So RandomBlock(0,0,0,CHEST,chest.nbt,50,CHEST,anotherchest.nbt,100) will spawn a chest at
# the BO3 origin, and give it a 50% chance to have the contents of chest.nbt, or, if that
# fails, a 100% percent chance to have the contents of anotherchest.nbt.

Block(-11,7,8,LEAVES:12)
Block(-11,8,7,LEAVES:12)
Block(-11,8,8,LEAVES:12)
Block(-11,9,3,LEAVES:12)
Block(-10,5,5,LEAVES:12)
Block(-10,8,7,LEAVES:12)
Block(-10,9,3,LEAVES:12)
Block(-10,9,4,LEAVES:12)
Block(-10,12,5,LEAVES:12)
Block(-10,12,7,LEAVES:12)
Block(-10,13,5,LEAVES:12)
Block(-9,4,6,LEAVES:12)
Block(-9,5,6,LEAVES:12)
Block(-9,6,8,LEAVES:12)
Block(-9,7,2,LEAVES:12)
Block(-9,8,4,LEAVES:12)
Block(-9,8,5,LEAVES:12)
Block(-9,8,7,LEAVES:12)
Block(-9,9,4,LEAVES:12)
Block(-9,9,6,LEAVES:12)
Block(-9,9,7,LEAVES:12)
Block(-9,11,8,LEAVES:12)
Block(-9,11,10,LEAVES:12)
Block(-9,11,11,LEAVES:12)
Block(-9,12,5,LEAVES:12)
Block(-9,12,6,LEAVES:12)
Block(-8,4,8,LEAVES:12)
Block(-8,5,2,LEAVES:12)
Block(-8,5,6,LEAVES:12)
Block(-8,5,7,LEAVES:12)
Block(-8,6,2,LEAVES:12)
Block(-8,6,3,LEAVES:12)
Block(-8,6,7,LEAVES:12)
Block(-8,6,10,LEAVES:12)
Block(-8,7,7,LEAVES:12)
Block(-8,8,5,LEAVES:12)
Block(-8,9,6,LEAVES:12)
Block(-8,10,9,LEAVES:12)
Block(-8,10,10,LEAVES:12)
Block(-8,11,2,LEAVES:12)
Block(-8,11,3,LEAVES:12)
Block(-8,11,6,LEAVES:12)
Block(-8,11,10,LEAVES:12)
Block(-8,12,6,LEAVES:12)
Block(-8,12,10,LEAVES:12)
Block(-8,13,6,LEAVES:12)
Block(-8,15,13,LEAVES:12)
Block(-8,16,12,LEAVES:12)
Block(-8,16,13,LEAVES:12)
Block(-8,17,8,LEAVES:12)
Block(-7,6,3,LEAVES:12)
Block(-7,6,9,LEAVES:12)
Block(-7,6,10,LEAVES:12)
Block(-7,7,3,LEAVES:12)
Block(-7,7,7,LEAVES:12)
Block(-7,7,8,LEAVES:12)
Block(-7,7,9,LEAVES:12)
Block(-7,8,5,LEAVES:12)
Block(-7,8,7,LEAVES:12)
Block(-7,9,6,LEAVES:12)
Block(-7,10,4,LEAVES:12)
Block(-7,10,5,LEAVES:12)
Block(-7,10,6,LEAVES:12)
Block(-7,10,8,LEAVES:12)
Block(-7,10,9,LEAVES:12)
Block(-7,11,3,LEAVES:12)
Block(-7,11,4,LEAVES:12)
Block(-7,11,6,LEAVES:12)
Block(-7,11,11,LEAVES:12)
Block(-7,12,4,LEAVES:12)
Block(-7,13,10,LEAVES:12)
Block(-7,14,4,LEAVES:12)
Block(-7,15,3,LEAVES:12)
Block(-7,15,4,LEAVES:12)
Block(-7,16,-1,LEAVES:12)
Block(-7,16,12,LEAVES:12)
Block(-7,17,8,LEAVES:12)
Block(-7,17,9,LEAVES:12)
Block(-7,20,10,LEAVES:12)
Block(-7,20,12,LEAVES:12)
Block(-7,21,10,LEAVES:12)
Block(-6,5,5,LEAVES:12)
Block(-6,6,4,LEAVES:12)
Block(-6,6,10,LEAVES:12)
Block(-6,6,11,LEAVES:12)
Block(-6,7,3,LEAVES:12)
Block(-6,7,4,LEAVES:12)
Block(-6,7,21,LEAVES:12)
Block(-6,8,4,LEAVES:12)
Block(-6,8,5,LEAVES:12)
Block(-6,8,6,LEAVES:12)
Block(-6,8,7,LEAVES:12)
Block(-6,8,20,LEAVES:12)
Block(-6,8,21,LEAVES:12)
Block(-6,9,6,LOG:12)
Block(-6,9,7,LEAVES:12)
Block(-6,9,8,LEAVES:12)
Block(-6,9,16,LEAVES:12)
Block(-6,10,6,LEAVES:12)
Block(-6,10,8,LEAVES:12)
Block(-6,11,6,LEAVES:12)
Block(-6,11,7,LEAVES:12)
Block(-6,12,1,LEAVES:12)
Block(-6,12,7,LEAVES:12)
Block(-6,12,11,LEAVES:12)
Block(-6,13,6,LEAVES:12)
Block(-6,13,11,LEAVES:12)
Block(-6,14,13,LEAVES:12)
Block(-6,15,3,LEAVES:12)
Block(-6,15,7,LEAVES:12)
Block(-6,16,-1,LEAVES:12)
Block(-6,16,0,LEAVES:12)
Block(-6,16,9,LEAVES:12)
Block(-6,16,10,LEAVES:12)
Block(-6,16,12,LEAVES:12)
Block(-6,17,9,LEAVES:12)
Block(-6,17,11,LEAVES:12)
Block(-6,17,12,LEAVES:12)
Block(-6,19,1,LEAVES:12)
Block(-6,19,3,LEAVES:12)
Block(-6,19,13,LEAVES:12)
Block(-6,19,15,LEAVES:12)
Block(-6,19,16,LEAVES:12)
Block(-6,20,1,LEAVES:12)
Block(-6,20,10,LEAVES:12)
Block(-6,20,11,LEAVES:12)
Block(-5,5,8,LEAVES:12)
Block(-5,5,18,LEAVES:12)
Block(-5,6,6,LEAVES:12)
Block(-5,6,8,LEAVES:12)
Block(-5,7,6,LEAVES:12)
Block(-5,7,8,LEAVES:12)
Block(-5,7,10,LEAVES:12)
Block(-5,8,4,LEAVES:12)
Block(-5,8,6,LEAVES:12)
Block(-5,8,7,LEAVES:12)
Block(-5,8,8,LEAVES:12)
Block(-5,8,10,LEAVES:12)
Block(-5,8,20,LEAVES:12)
Block(-5,9,2,LEAVES:12)
Block(-5,9,4,LEAVES:12)
Block(-5,9,6,LOG:12)
Block(-5,9,7,LEAVES:12)
Block(-5,9,11,LEAVES:12)
Block(-5,9,16,LEAVES:12)
Block(-5,9,17,LEAVES:12)
Block(-5,10,6,LEAVES:12)
Block(-5,11,2,LEAVES:12)
Block(-5,12,2,LEAVES:12)
Block(-5,12,7,LEAVES:12)
Block(-5,12,8,LEAVES:12)
Block(-5,12,13,LEAVES:12)
Block(-5,12,18,LEAVES:12)
Block(-5,12,20,LEAVES:12)
Block(-5,13,4,LEAVES:12)
Block(-5,13,7,LEAVES:12)
Block(-5,13,8,LEAVES:12)
Block(-5,13,9,LEAVES:12)
Block(-5,13,11,LEAVES:12)
Block(-5,13,12,LEAVES:12)
Block(-5,13,18,LEAVES:12)
Block(-5,14,-2,LEAVES:12)
Block(-5,14,7,LEAVES:12)
Block(-5,14,8,LEAVES:12)
Block(-5,14,12,LEAVES:12)
Block(-5,14,15,LEAVES:12)
Block(-5,14,18,LEAVES:12)
Block(-5,15,0,LEAVES:12)
Block(-5,15,1,LEAVES:12)
Block(-5,15,3,LEAVES:12)
Block(-5,15,12,LEAVES:12)
Block(-5,15,17,LEAVES:12)
Block(-5,15,18,LEAVES:12)
Block(-5,16,0,LEAVES:12)
Block(-5,16,2,LEAVES:12)
Block(-5,16,3,LEAVES:12)
Block(-5,16,10,LEAVES:12)
Block(-5,16,13,LEAVES:12)
Block(-5,17,11,LEAVES:12)
Block(-5,18,4,LEAVES:12)
Block(-5,18,6,LEAVES:12)
Block(-5,18,7,LEAVES:12)
Block(-5,18,14,LEAVES:12)
Block(-5,18,15,LEAVES:12)
Block(-5,19,1,LEAVES:12)
Block(-5,19,2,LEAVES:12)
Block(-5,19,7,LEAVES:12)
Block(-5,19,8,LEAVES:12)
Block(-5,19,11,LEAVES:12)
Block(-5,19,15,LEAVES:12)
Block(-5,20,11,LEAVES:12)
Block(-5,20,15,LEAVES:12)
Block(-5,21,11,LEAVES:12)
Block(-4,4,19,LEAVES:12)
Block(-4,5,5,LEAVES:12)
Block(-4,5,19,LEAVES:12)
Block(-4,6,9,LEAVES:12)
Block(-4,6,21,LEAVES:12)
Block(-4,7,6,LEAVES:12)
Block(-4,7,8,LEAVES:12)
Block(-4,7,9,LEAVES:12)
Block(-4,7,15,LEAVES:12)
Block(-4,8,17,LEAVES:12)
Block(-4,8,18,LEAVES:12)
Block(-4,8,20,LEAVES:12)
Block(-4,9,3,LEAVES:12)
Block(-4,9,4,LEAVES:12)
Block(-4,9,6,LOG:12)
Block(-4,9,7,LEAVES:12)
Block(-4,9,8,LEAVES:12)
Block(-4,9,17,LEAVES:12)
Block(-4,9,19,LEAVES:12)
Block(-4,9,20,LEAVES:12)
Block(-4,10,6,LOG:12)
Block(-4,10,7,LOG:12)
Block(-4,10,8,LEAVES:12)
Block(-4,11,3,LEAVES:12)
Block(-4,11,4,LEAVES:12)
Block(-4,11,5,LEAVES:12)
Block(-4,11,6,LEAVES:12)
Block(-4,11,21,LEAVES:12)
Block(-4,11,23,LEAVES:12)
Block(-4,11,24,LEAVES:12)
Block(-4,12,-2,LEAVES:12)
Block(-4,12,2,LEAVES:12)
Block(-4,12,3,LEAVES:12)
Block(-4,12,15,LEAVES:12)
Block(-4,12,18,LEAVES:12)
Block(-4,12,19,LEAVES:12)
Block(-4,13,-2,LEAVES:12)
Block(-4,13,-1,LEAVES:12)
Block(-4,13,3,LEAVES:12)
Block(-4,13,6,LEAVES:12)
Block(-4,14,3,LEAVES:12)
Block(-4,14,8,LEAVES:12)
Block(-4,14,14,LEAVES:12)
Block(-4,14,15,LEAVES:12)
Block(-4,15,1,LEAVES:12)
Block(-4,15,8,LEAVES:12)
Block(-4,15,12,LEAVES:12)
Block(-4,15,13,LEAVES:12)
Block(-4,15,14,LEAVES:12)
Block(-4,15,17,LEAVES:12)
Block(-4,16,2,LEAVES:12)
Block(-4,16,10,LEAVES:12)
Block(-4,16,12,LEAVES:12)
Block(-4,16,13,LEAVES:12)
Block(-4,16,14,LEAVES:12)
Block(-4,17,5,LEAVES:12)
Block(-4,17,6,LEAVES:12)
Block(-4,17,11,LEAVES:12)
Block(-4,18,-2,LEAVES:12)
Block(-4,18,-1,LEAVES:12)
Block(-4,18,2,LEAVES:12)
Block(-4,18,6,LEAVES:12)
Block(-4,18,9,LEAVES:12)
Block(-4,18,10,LEAVES:12)
Block(-4,18,11,LEAVES:12)
Block(-4,18,13,LEAVES:12)
Block(-4,18,14,LEAVES:12)
Block(-4,19,2,LEAVES:12)
Block(-4,19,6,LEAVES:12)
Block(-4,19,8,LEAVES:12)
Block(-4,19,9,LEAVES:12)
Block(-4,19,11,LEAVES:12)
Block(-4,19,15,LEAVES:12)
Block(-4,19,16,LEAVES:12)
Block(-4,19,17,LEAVES:12)
Block(-4,20,2,LEAVES:12)
Block(-4,20,9,LEAVES:12)
Block(-4,20,15,LEAVES:12)
Block(-3,4,21,LEAVES:12)
Block(-3,5,9,LEAVES:12)
Block(-3,5,15,LEAVES:12)
Block(-3,5,19,LEAVES:12)
Block(-3,5,20,LEAVES:12)
Block(-3,6,5,LEAVES:12)
Block(-3,6,6,LEAVES:12)
Block(-3,6,9,LEAVES:12)
Block(-3,6,15,LEAVES:12)
Block(-3,6,16,LEAVES:12)
Block(-3,6,20,LEAVES:12)
Block(-3,6,23,LEAVES:12)
Block(-3,7,6,LEAVES:12)
Block(-3,7,20,LEAVES:12)
Block(-3,8,6,LEAVES:12)
Block(-3,8,18,LEAVES:12)
Block(-3,9,2,LEAVES:12)
Block(-3,9,3,LEAVES:12)
Block(-3,9,19,LEAVES:12)
Block(-3,10,7,LOG:12)
Block(-3,10,8,LEAVES:12)
Block(-3,10,9,LEAVES:12)
Block(-3,10,10,LEAVES:12)
Block(-3,10,22,LEAVES:12)
Block(-3,10,23,LEAVES:12)
Block(-3,11,4,LEAVES:12)
Block(-3,11,5,LEAVES:12)
Block(-3,11,7,LOG:12)
Block(-3,11,8,LOG:12)
Block(-3,11,9,LEAVES:12)
Block(-3,11,15,LEAVES:12)
Block(-3,11,16,LEAVES:12)
Block(-3,11,19,LEAVES:12)
Block(-3,11,23,LEAVES:12)
Block(-3,12,7,LEAVES:12)
Block(-3,12,16,LEAVES:12)
Block(-3,12,19,LEAVES:12)
Block(-3,12,23,LEAVES:12)
Block(-3,13,-1,LEAVES:12)
Block(-3,13,5,LEAVES:12)
Block(-3,13,6,LEAVES:12)
Block(-3,13,10,LEAVES:12)
Block(-3,13,18,LEAVES:12)
Block(-3,13,19,LEAVES:12)
Block(-3,14,-1,LEAVES:12)
Block(-3,14,3,LEAVES:12)
Block(-3,14,4,LEAVES:12)
Block(-3,14,5,LEAVES:12)
Block(-3,14,9,LEAVES:12)
Block(-3,14,12,LEAVES:12)
Block(-3,14,15,LEAVES:12)
Block(-3,14,16,LEAVES:12)
Block(-3,15,1,LEAVES:12)
Block(-3,15,3,LEAVES:12)
Block(-3,15,8,LEAVES:12)
Block(-3,15,9,LEAVES:12)
Block(-3,15,11,LOG:12)
Block(-3,15,14,LEAVES:12)
Block(-3,15,15,LEAVES:12)
Block(-3,15,17,LEAVES:12)
Block(-3,16,2,LEAVES:12)
Block(-3,16,9,LEAVES:12)
Block(-3,16,10,LEAVES:12)
Block(-3,16,11,LOG:12)
Block(-3,16,12,LEAVES:12)
Block(-3,16,14,LEAVES:12)
Block(-3,16,16,LEAVES:12)
Block(-3,16,17,LEAVES:12)
Block(-3,17,0,LEAVES:12)
Block(-3,17,1,LEAVES:12)
Block(-3,17,2,LEAVES:12)
Block(-3,17,4,LEAVES:12)
Block(-3,17,5,LEAVES:12)
Block(-3,17,11,LOG:12)
Block(-3,17,12,LEAVES:12)
Block(-3,17,13,LEAVES:12)
Block(-3,18,-1,LEAVES:12)
Block(-3,18,0,LEAVES:12)
Block(-3,18,2,LEAVES:12)
Block(-3,18,7,LEAVES:12)
Block(-3,18,11,LEAVES:12)
Block(-3,18,13,LEAVES:12)
Block(-3,18,18,LEAVES:12)
Block(-3,18,20,LEAVES:12)
Block(-3,18,21,LEAVES:12)
Block(-3,19,0,LEAVES:12)
Block(-3,19,11,LEAVES:12)
Block(-3,19,12,LEAVES:12)
Block(-3,19,15,LEAVES:12)
Block(-3,19,16,LEAVES:12)
Block(-3,20,12,LEAVES:12)
Block(-3,21,11,LEAVES:12)
Block(-2,5,4,LEAVES:12)
Block(-2,5,5,LEAVES:12)
Block(-2,6,5,LEAVES:12)
Block(-2,6,16,LEAVES:12)
Block(-2,6,22,LEAVES:12)
Block(-2,6,23,LEAVES:12)
Block(-2,7,16,LEAVES:12)
Block(-2,7,20,LEAVES:12)
Block(-2,7,21,LEAVES:12)
Block(-2,7,22,LEAVES:12)
Block(-2,8,5,LEAVES:12)
Block(-2,8,6,LEAVES:12)
Block(-2,8,18,LEAVES:12)
Block(-2,8,20,LEAVES:12)
Block(-2,9,6,LEAVES:12)
Block(-2,9,19,LEAVES:12)
Block(-2,10,9,LEAVES:12)
Block(-2,10,17,LEAVES:12)
Block(-2,10,18,LEAVES:12)
Block(-2,10,19,LEAVES:12)
Block(-2,10,21,LEAVES:12)
Block(-2,10,22,LEAVES:12)
Block(-2,11,4,LEAVES:12)
Block(-2,11,8,LOG:12)
Block(-2,11,16,LEAVES:12)
Block(-2,11,17,LEAVES:12)
Block(-2,11,18,LEAVES:12)
Block(-2,11,19,LEAVES:12)
Block(-2,11,24,LEAVES:12)
Block(-2,12,1,LEAVES:12)
Block(-2,12,4,LEAVES:12)
Block(-2,12,8,LOG:12)
Block(-2,12,9,LOG:12)
Block(-2,12,12,LEAVES:12)
Block(-2,12,16,LEAVES:12)
Block(-2,12,17,LEAVES:12)
Block(-2,13,0,LEAVES:12)
Block(-2,13,6,LEAVES:12)
Block(-2,13,7,LEAVES:12)
Block(-2,13,12,LEAVES:12)
Block(-2,13,13,LEAVES:12)
Block(-2,13,17,LEAVES:12)
Block(-2,13,20,LEAVES:12)
Block(-2,14,-1,LEAVES:12)
Block(-2,14,0,LEAVES:12)
Block(-2,14,10,LOG:12)
Block(-2,14,11,LOG:12)
Block(-2,14,13,LEAVES:12)
Block(-2,14,17,LEAVES:12)
Block(-2,15,0,LEAVES:12)
Block(-2,15,1,LEAVES:12)
Block(-2,15,2,LEAVES:12)
Block(-2,15,3,LEAVES:12)
Block(-2,15,11,LOG:12)
Block(-2,15,13,LEAVES:12)
Block(-2,15,15,LEAVES:12)
Block(-2,16,1,LOG:12)
Block(-2,16,2,LOG:12)
Block(-2,16,3,LOG:12)
Block(-2,16,4,LEAVES:12)
Block(-2,16,9,LEAVES:12)
Block(-2,16,11,LEAVES:12)
Block(-2,16,12,LEAVES:12)
Block(-2,16,13,LEAVES:12)
Block(-2,16,15,LEAVES:12)
Block(-2,16,16,LEAVES:12)
Block(-2,17,2,LEAVES:12)
Block(-2,17,4,LEAVES:12)
Block(-2,17,7,LEAVES:12)
Block(-2,17,9,LEAVES:12)
Block(-2,17,11,LEAVES:12)
Block(-2,17,12,LEAVES:12)
Block(-2,17,16,LEAVES:12)
Block(-2,17,19,LEAVES:12)
Block(-2,17,20,LEAVES:12)
Block(-2,18,2,LEAVES:12)
Block(-2,18,3,LEAVES:12)
Block(-2,18,11,LEAVES:12)
Block(-2,18,12,LEAVES:12)
Block(-2,18,13,LEAVES:12)
Block(-2,18,16,LEAVES:12)
Block(-2,18,20,LEAVES:12)
Block(-2,19,3,LEAVES:12)
Block(-2,19,16,LEAVES:12)
Block(-2,19,20,LEAVES:12)
Block(-2,20,2,LEAVES:12)
Block(-2,20,12,LEAVES:12)
Block(-2,20,13,LEAVES:12)
Block(-2,20,16,LEAVES:12)
Block(-2,21,13,LEAVES:12)
Block(-2,21,14,LEAVES:12)
Block(-2,22,13,LEAVES:12)
Block(-1,5,4,LEAVES:12)
Block(-1,5,18,LEAVES:12)
Block(-1,6,17,LEAVES:12)
Block(-1,6,23,LEAVES:12)
Block(-1,6,24,LEAVES:12)
Block(-1,7,7,LEAVES:12)
Block(-1,7,16,LEAVES:12)
Block(-1,7,17,LEAVES:12)
Block(-1,8,6,LEAVES:12)
Block(-1,8,7,LEAVES:12)
Block(-1,8,17,LEAVES:12)
Block(-1,8,18,LEAVES:12)
Block(-1,8,19,LEAVES:12)
Block(-1,8,20,LEAVES:12)
Block(-1,9,19,LOG:12)
Block(-1,9,20,LEAVES:12)
Block(-1,9,21,LEAVES:12)
Block(-1,10,19,LEAVES:12)
Block(-1,10,21,LEAVES:12)
Block(-1,11,19,LEAVES:12)
Block(-1,11,20,LEAVES:12)
Block(-1,12,4,LEAVES:12)
Block(-1,12,9,LOG:12)
Block(-1,12,20,LEAVES:12)
Block(-1,13,2,LEAVES:12)
Block(-1,13,4,LEAVES:12)
Block(-1,13,9,LOG:12)
Block(-1,13,10,LEAVES:12)
Block(-1,13,13,LEAVES:12)
Block(-1,13,19,LEAVES:12)
Block(-1,13,20,LEAVES:12)
Block(-1,14,2,LEAVES:12)
Block(-1,14,4,LEAVES:12)
Block(-1,14,6,LEAVES:12)
Block(-1,14,9,LOG:12)
Block(-1,14,10,LOG:12)
Block(-1,14,13,LEAVES:12)
Block(-1,14,14,LEAVES:12)
Block(-1,14,17,LEAVES:12)
Block(-1,14,18,LEAVES:12)
Block(-1,14,19,LEAVES:12)
Block(-1,15,0,LEAVES:12)
Block(-1,15,2,LEAVES:12)
Block(-1,15,3,LEAVES:12)
Block(-1,15,4,LOG:12)
Block(-1,15,6,LEAVES:12)
Block(-1,15,11,LEAVES:12)
Block(-1,15,13,LEAVES:12)
Block(-1,15,14,LEAVES:12)
Block(-1,15,15,LEAVES:12)
Block(-1,15,16,LOG:12)
Block(-1,15,17,LEAVES:12)
Block(-1,16,-2,LEAVES:12)
Block(-1,16,0,LEAVES:12)
Block(-1,16,2,LEAVES:12)
Block(-1,16,3,LOG:12)
Block(-1,16,4,LOG:12)
Block(-1,16,7,LEAVES:12)
Block(-1,16,16,LEAVES:12)
Block(-1,17,2,LEAVES:12)
Block(-1,17,8,LEAVES:12)
Block(-1,17,9,LEAVES:12)
Block(-1,17,12,LEAVES:12)
Block(-1,17,13,LEAVES:12)
Block(-1,17,14,LEAVES:12)
Block(-1,17,15,LEAVES:12)
Block(-1,17,16,LEAVES:12)
Block(-1,17,18,LEAVES:12)
Block(-1,17,19,LEAVES:12)
Block(-1,18,11,LEAVES:12)
Block(-1,18,13,LEAVES:12)
Block(-1,18,14,LEAVES:12)
Block(-1,18,16,LEAVES:12)
Block(-1,18,21,LEAVES:12)
Block(-1,19,3,LEAVES:12)
Block(-1,19,4,LEAVES:12)
Block(-1,19,8,LEAVES:12)
Block(-1,19,10,LEAVES:12)
Block(-1,19,11,LEAVES:12)
Block(-1,19,14,LEAVES:12)
Block(-1,20,4,LEAVES:12)
Block(-1,20,5,LEAVES:12)
Block(-1,20,7,LEAVES:12)
Block(-1,20,8,LEAVES:12)
Block(-1,21,3,LEAVES:12)
Block(-1,21,4,LEAVES:12)
Block(0,5,21,LEAVES:12)
Block(0,6,19,LEAVES:12)
Block(0,6,21,LEAVES:12)
Block(0,7,7,LEAVES:12)
Block(0,7,19,LEAVES:12)
Block(0,7,21,LEAVES:12)
Block(0,7,23,LEAVES:12)
Block(0,8,17,LEAVES:12)
Block(0,8,19,LEAVES:12)
Block(0,8,20,LEAVES:12)
Block(0,8,21,LEAVES:12)
Block(0,8,23,LEAVES:12)
Block(0,9,15,LEAVES:12)
Block(0,9,17,LEAVES:12)
Block(0,9,19,LOG:12)
Block(0,9,20,LEAVES:12)
Block(0,9,24,LEAVES:12)
Block(0,10,19,LEAVES:12)
Block(0,12,1,LEAVES:12)
Block(0,12,15,LEAVES:12)
Block(0,12,20,LEAVES:12)
Block(0,12,21,LEAVES:12)
Block(0,13,5,LEAVES:12)
Block(0,13,9,LOG:12)
Block(0,13,14,LEAVES:12)
Block(0,13,20,LEAVES:12)
Block(0,13,21,LEAVES:12)
Block(0,13,22,LEAVES:12)
Block(0,14,2,LEAVES:12)
Block(0,14,4,LEAVES:12)
Block(0,14,5,LEAVES:12)
Block(0,14,10,LEAVES:12)
Block(0,14,11,LEAVES:12)
Block(0,14,13,LEAVES:12)
Block(0,14,14,LEAVES:12)
Block(0,14,21,LEAVES:12)
Block(0,15,4,LOG:12)
Block(0,15,11,LEAVES:12)
Block(0,15,14,LEAVES:12)
Block(0,15,15,LEAVES:12)
Block(0,15,16,LOG:12)
Block(0,15,17,LEAVES:12)
Block(0,16,-1,LEAVES:12)
Block(0,16,0,LEAVES:12)
Block(0,16,3,LEAVES:12)
Block(0,16,4,LEAVES:12)
Block(0,16,11,LEAVES:12)
Block(0,16,15,LOG:12)
Block(0,16,16,LOG:12)
Block(0,16,17,LEAVES:12)
Block(0,16,18,LEAVES:12)
Block(0,17,2,LEAVES:12)
Block(0,17,4,LEAVES:12)
Block(0,17,5,LEAVES:12)
Block(0,17,7,LEAVES:12)
Block(0,17,8,LEAVES:12)
Block(0,17,16,LEAVES:12)
Block(0,17,18,LEAVES:12)
Block(0,18,-1,LEAVES:12)
Block(0,18,1,LEAVES:12)
Block(0,18,2,LEAVES:12)
Block(0,18,13,LEAVES:12)
Block(0,18,14,LEAVES:12)
Block(0,18,15,LEAVES:12)
Block(0,18,16,LEAVES:12)
Block(0,18,17,LEAVES:12)
Block(0,19,9,LEAVES:12)
Block(0,19,10,LEAVES:12)
Block(0,19,14,LEAVES:12)
Block(0,19,17,LEAVES:12)
Block(0,20,7,LEAVES:12)
Block(0,20,12,LEAVES:12)
Block(0,20,16,LEAVES:12)
Block(0,21,3,LEAVES:12)
Block(0,21,4,LEAVES:12)
Block(0,24,5,LEAVES:12)
Block(0,24,7,LEAVES:12)
Block(0,25,5,LEAVES:12)
Block(1,5,18,LEAVES:12)
Block(1,6,22,LEAVES:12)
Block(1,7,19,LEAVES:12)
Block(1,7,21,LEAVES:12)
Block(1,7,22,LEAVES:12)
Block(1,9,16,LEAVES:12)
Block(1,9,17,LEAVES:12)
Block(1,9,18,LOG:12)
Block(1,9,19,LOG:12)
Block(1,9,20,LEAVES:12)
Block(1,9,21,LEAVES:12)
Block(1,10,16,LOG:12)
Block(1,10,17,LOG:12)
Block(1,10,18,LOG:12)
Block(1,10,19,LEAVES:12)
Block(1,10,21,LEAVES:12)
Block(1,11,16,LOG:12)
Block(1,11,18,LEAVES:12)
Block(1,11,19,LEAVES:12)
Block(1,12,5,LEAVES:12)
Block(1,12,18,LEAVES:12)
Block(1,13,1,LEAVES:12)
Block(1,13,2,LEAVES:12)
Block(1,13,5,LEAVES:12)
Block(1,13,8,LOG:12)
Block(1,13,9,LOG:12)
Block(1,13,10,LEAVES:12)
Block(1,13,16,LEAVES:12)
Block(1,13,18,LEAVES:12)
Block(1,14,0,LEAVES:12)
Block(1,14,2,LEAVES:12)
Block(1,14,5,LOG:12)
Block(1,14,10,LEAVES:12)
Block(1,14,16,LEAVES:12)
Block(1,14,18,LEAVES:12)
Block(1,14,20,LEAVES:12)
Block(1,15,-1,LEAVES:12)
Block(1,15,0,LEAVES:12)
Block(1,15,2,LEAVES:12)
Block(1,15,4,LOG:12)
Block(1,15,5,LOG:12)
Block(1,15,14,LEAVES:12)
Block(1,15,16,LEAVES:12)
Block(1,15,17,LEAVES:12)
Block(1,15,18,LEAVES:12)
Block(1,15,20,LEAVES:12)
Block(1,16,-5,LEAVES:12)
Block(1,16,-2,LEAVES:12)
Block(1,16,-1,LEAVES:12)
Block(1,16,6,LEAVES:12)
Block(1,16,10,LEAVES:12)
Block(1,16,11,LEAVES:12)
Block(1,16,12,LEAVES:12)
Block(1,16,14,LOG:12)
Block(1,16,15,LOG:12)
Block(1,16,16,LEAVES:12)
Block(1,16,17,LEAVES:12)
Block(1,16,21,LEAVES:12)
Block(1,17,4,LEAVES:12)
Block(1,17,5,LEAVES:12)
Block(1,17,6,LEAVES:12)
Block(1,17,11,LEAVES:12)
Block(1,17,16,LEAVES:12)
Block(1,18,0,LEAVES:12)
Block(1,18,1,LEAVES:12)
Block(1,18,5,LEAVES:12)
Block(1,18,8,LEAVES:12)
Block(1,18,14,LEAVES:12)
Block(1,19,2,LEAVES:12)
Block(1,19,3,LEAVES:12)
Block(1,19,9,LEAVES:12)
Block(1,19,17,LEAVES:12)
Block(1,19,18,LEAVES:12)
Block(1,20,4,LEAVES:12)
Block(1,20,5,LEAVES:12)
Block(1,20,7,LEAVES:12)
Block(1,20,9,LEAVES:12)
Block(1,20,18,LEAVES:12)
Block(1,20,19,LEAVES:12)
Block(1,21,4,LEAVES:12)
Block(1,21,6,LEAVES:12)
Block(1,21,7,LEAVES:12)
Block(1,21,18,LEAVES:12)
Block(1,23,8,LEAVES:12)
Block(1,23,10,LEAVES:12)
Block(1,23,11,LEAVES:12)
Block(1,24,5,LEAVES:12)
Block(1,24,6,LEAVES:12)
Block(2,5,22,LEAVES:12)
Block(2,6,18,LEAVES:12)
Block(2,6,19,LEAVES:12)
Block(2,6,22,LEAVES:12)
Block(2,7,19,LEAVES:12)
Block(2,8,1,LEAVES:12)
Block(2,8,19,LEAVES:12)
Block(2,9,0,LEAVES:12)
Block(2,9,1,LEAVES:12)
Block(2,9,15,LEAVES:12)
Block(2,9,16,LEAVES:12)
Block(2,10,-4,LEAVES:12)
Block(2,10,21,LEAVES:12)
Block(2,10,22,LEAVES:12)
Block(2,10,23,LEAVES:12)
Block(2,11,15,LOG:12)
Block(2,11,16,LOG:12)
Block(2,11,17,LEAVES:12)
Block(2,11,18,LEAVES:12)
Block(2,11,22,LEAVES:12)
Block(2,12,-3,LEAVES:12)
Block(2,12,0,LEAVES:12)
Block(2,12,1,LEAVES:12)
Block(2,12,15,LOG:12)
Block(2,12,20,LEAVES:12)
Block(2,13,1,LEAVES:12)
Block(2,13,2,LOG:12)
Block(2,13,3,LOG:12)
Block(2,13,7,LOG:12)
Block(2,13,8,LOG:12)
Block(2,13,9,LEAVES:12)
Block(2,13,19,LEAVES:12)
Block(2,14,3,LOG:12)
Block(2,14,4,LOG:12)
Block(2,14,5,LOG:12)
Block(2,14,6,LOG:12)
Block(2,14,7,LOG:12)
Block(2,14,16,LEAVES:12)
Block(2,14,18,LEAVES:12)
Block(2,14,19,LEAVES:12)
Block(2,15,-1,LEAVES:12)
Block(2,15,1,LEAVES:12)
Block(2,15,2,LEAVES:12)
Block(2,15,12,LEAVES:12)
Block(2,16,-5,LEAVES:12)
Block(2,16,-4,LEAVES:12)
Block(2,16,2,LEAVES:12)
Block(2,16,8,LEAVES:12)
Block(2,16,11,LEAVES:12)
Block(2,16,12,LEAVES:12)
Block(2,16,13,LOG:12)
Block(2,16,14,LOG:12)
Block(2,16,17,LEAVES:12)
Block(2,16,18,LEAVES:12)
Block(2,17,2,LEAVES:12)
Block(2,17,5,LEAVES:12)
Block(2,17,6,LEAVES:12)
Block(2,17,7,LEAVES:12)
Block(2,17,16,LEAVES:12)
Block(2,17,17,LEAVES:12)
Block(2,17,18,LEAVES:12)
Block(2,18,0,LEAVES:12)
Block(2,18,2,LEAVES:12)
Block(2,18,3,LEAVES:12)
Block(2,18,7,LEAVES:12)
Block(2,18,10,LEAVES:12)
Block(2,18,13,LEAVES:12)
Block(2,18,15,LEAVES:12)
Block(2,18,16,LEAVES:12)
Block(2,18,17,LEAVES:12)
Block(2,19,-3,LEAVES:12)
Block(2,19,-1,LEAVES:12)
Block(2,19,0,LEAVES:12)
Block(2,19,7,LEAVES:12)
Block(2,19,12,LEAVES:12)
Block(2,20,-3,LEAVES:12)
Block(2,20,5,LEAVES:12)
Block(2,21,6,LEAVES:12)
Block(2,22,9,LEAVES:12)
Block(2,22,10,LEAVES:12)
Block(2,23,2,LEAVES:12)
Block(2,23,3,LEAVES:12)
Block(2,23,6,LEAVES:12)
Block(2,23,10,LEAVES:12)
Block(2,24,6,LEAVES:12)
Block(2,24,10,LEAVES:12)
Block(2,25,6,LEAVES:12)
Block(3,5,17,LEAVES:12)
Block(3,5,18,LEAVES:12)
Block(3,6,-2,LEAVES:12)
Block(3,6,18,LEAVES:12)
Block(3,8,18,LEAVES:12)
Block(3,8,19,LEAVES:12)
Block(3,9,0,LEAVES:12)
Block(3,9,19,LEAVES:12)
Block(3,9,20,LEAVES:12)
Block(3,10,-4,LEAVES:12)
Block(3,10,-3,LEAVES:12)
Block(3,10,9,LOG:12)
Block(3,10,19,LEAVES:12)
Block(3,10,20,LEAVES:12)
Block(3,10,22,LEAVES:12)
Block(3,11,-2,LEAVES:12)
Block(3,11,8,LOG:12)
Block(3,11,9,LOG:12)
Block(3,11,15,LEAVES:12)
Block(3,11,17,LEAVES:12)
Block(3,12,-2,LEAVES:12)
Block(3,12,0,LEAVES:12)
Block(3,12,2,LOG:12)
Block(3,12,8,LOG:12)
Block(3,12,9,LOG:12)
Block(3,12,10,LOG:12)
Block(3,12,14,LOG:12)
Block(3,12,15,LOG:12)
Block(3,12,17,LEAVES:12)
Block(3,12,19,LEAVES:12)
Block(3,13,-2,LEAVES:12)
Block(3,13,0,LEAVES:12)
Block(3,13,2,LOG:12)
Block(3,13,8,LOG:12)
Block(3,13,10,LOG:12)
Block(3,13,11,LOG:12)
Block(3,13,14,LOG:12)
Block(3,13,15,LEAVES:12)
Block(3,13,16,LEAVES:12)
Block(3,13,19,LEAVES:12)
Block(3,14,-6,LEAVES:12)
Block(3,14,-2,LEAVES:12)
Block(3,14,3,LOG:12)
Block(3,14,11,LOG:12)
Block(3,14,12,LOG:12)
Block(3,14,16,LEAVES:12)
Block(3,15,-4,LEAVES:12)
Block(3,15,-3,LEAVES:12)
Block(3,15,-1,LEAVES:12)
Block(3,15,2,LEAVES:12)
Block(3,15,3,LEAVES:12)
Block(3,15,12,LOG:12)
Block(3,15,13,LOG:12)
Block(3,15,14,LEAVES:12)
Block(3,15,16,LEAVES:12)
Block(3,16,-4,LEAVES:12)
Block(3,16,-2,LEAVES:12)
Block(3,16,-1,LEAVES:12)
Block(3,16,12,LEAVES:12)
Block(3,16,13,LOG:12)
Block(3,17,18,LEAVES:12)
Block(3,17,19,LEAVES:12)
Block(3,17,20,LEAVES:12)
Block(3,18,0,LEAVES:12)
Block(3,18,2,LEAVES:12)
Block(3,18,3,LEAVES:12)
Block(3,18,9,LEAVES:12)
Block(3,18,10,LEAVES:12)
Block(3,18,14,LEAVES:12)
Block(3,18,15,LEAVES:12)
Block(3,18,16,LEAVES:12)
Block(3,18,19,LEAVES:12)
Block(3,19,-3,LEAVES:12)
Block(3,19,-2,LEAVES:12)
Block(3,19,3,LEAVES:12)
Block(3,19,7,LEAVES:12)
Block(3,19,8,LEAVES:12)
Block(3,19,9,LEAVES:12)
Block(3,19,12,LEAVES:12)
Block(3,19,13,LEAVES:12)
Block(3,19,17,LEAVES:12)
Block(3,20,5,LEAVES:12)
Block(3,20,7,LEAVES:12)
Block(3,21,6,LEAVES:12)
Block(3,22,4,LEAVES:12)
Block(3,22,5,LEAVES:12)
Block(3,22,6,LEAVES:12)
Block(3,22,8,LEAVES:12)
Block(3,22,9,LEAVES:12)
Block(3,22,14,LEAVES:12)
Block(3,22,16,LEAVES:12)
Block(3,23,3,LEAVES:12)
Block(3,23,4,LEAVES:12)
Block(3,23,6,LEAVES:12)
Block(3,23,11,LEAVES:12)
Block(3,23,14,LEAVES:12)
Block(3,24,4,LEAVES:12)
Block(4,5,-1,LEAVES:12)
Block(4,5,17,LEAVES:12)
Block(4,6,-1,LEAVES:12)
Block(4,7,1,LEAVES:12)
Block(4,7,17,LEAVES:12)
Block(4,7,20,LEAVES:12)
Block(4,8,-5,LEAVES:12)
Block(4,8,7,LOG:12)
Block(4,8,8,LOG:12)
Block(4,8,19,LEAVES:12)
Block(4,8,20,LEAVES:12)
Block(4,9,-3,LEAVES:12)
Block(4,9,-2,LEAVES:12)
Block(4,9,0,LEAVES:12)
Block(4,9,7,LOG:12)
Block(4,9,8,LOG:12)
Block(4,10,-3,LEAVES:12)
Block(4,10,-1,LEAVES:12)
Block(4,10,0,LEAVES:12)
Block(4,10,7,LOG:12)
Block(4,10,8,LOG:12)
Block(4,10,9,LOG:12)
Block(4,10,19,LEAVES:12)
Block(4,11,0,LEAVES:12)
Block(4,11,1,LOG:12)
Block(4,11,8,LOG:12)
Block(4,11,15,LEAVES:12)
Block(4,11,16,LEAVES:12)
Block(4,12,-6,LEAVES:12)
Block(4,12,-2,LEAVES:12)
Block(4,12,-1,LEAVES:12)
Block(4,12,1,LOG:12)
Block(4,12,2,LOG:12)
Block(4,12,3,LEAVES:12)
Block(4,12,4,LEAVES:12)
Block(4,12,8,LOG:12)
Block(4,12,14,LEAVES:12)
Block(4,12,15,LEAVES:12)
Block(4,13,-6,LEAVES:12)
Block(4,13,-5,LEAVES:12)
Block(4,13,-2,LEAVES:12)
Block(4,13,-1,LEAVES:12)
Block(4,13,2,LEAVES:12)
Block(4,13,14,LOG:12)
Block(4,13,15,LEAVES:12)
Block(4,14,-1,LEAVES:12)
Block(4,14,3,LOG:12)
Block(4,14,12,LOG:12)
Block(4,14,13,LOG:12)
Block(4,14,14,LOG:12)
Block(4,14,15,LEAVES:12)
Block(4,14,17,LEAVES:12)
Block(4,14,19,LEAVES:12)
Block(4,15,-3,LEAVES:12)
Block(4,15,3,LOG:12)
Block(4,15,15,LEAVES:12)
Block(4,15,16,LEAVES:12)
Block(4,15,17,LEAVES:12)
Block(4,16,-2,LEAVES:12)
Block(4,16,16,LEAVES:12)
Block(4,16,17,LEAVES:12)
Block(4,17,1,LEAVES:12)
Block(4,17,2,LEAVES:12)
Block(4,17,5,LEAVES:12)
Block(4,17,11,LEAVES:12)
Block(4,17,19,LEAVES:12)
Block(4,18,-6,LEAVES:12)
Block(4,18,-5,LEAVES:12)
Block(4,18,-2,LEAVES:12)
Block(4,18,2,LEAVES:12)
Block(4,18,4,LEAVES:12)
Block(4,18,10,LEAVES:12)
Block(4,18,11,LEAVES:12)
Block(4,18,13,LEAVES:12)
Block(4,18,14,LEAVES:12)
Block(4,18,16,LEAVES:12)
Block(4,19,-2,LEAVES:12)
Block(4,19,2,LEAVES:12)
Block(4,19,3,LEAVES:12)
Block(4,19,4,LEAVES:12)
Block(4,19,6,LOG:12)
Block(4,19,13,LEAVES:12)
Block(4,19,14,LEAVES:12)
Block(4,19,15,LEAVES:12)
Block(4,19,16,LEAVES:12)
Block(4,20,-2,LEAVES:12)
Block(4,20,4,LEAVES:12)
Block(4,20,5,LEAVES:12)
Block(4,20,6,LOG:12)
Block(4,20,7,LEAVES:12)
Block(4,21,6,LOG:12)
Block(4,21,7,LEAVES:12)
Block(4,21,8,LEAVES:12)
Block(4,21,17,LEAVES:12)
Block(4,21,19,LEAVES:12)
Block(4,21,20,LEAVES:12)
Block(4,22,6,LOG:12)
Block(4,22,8,LEAVES:12)
Block(4,22,14,LEAVES:12)
Block(4,22,15,LEAVES:12)
Block(4,23,6,LEAVES:12)
Block(4,23,7,LEAVES:12)
Block(4,24,7,LEAVES:12)
Block(4,25,6,LEAVES:12)
Block(5,0,7,LOG:12)
Block(5,1,7,LOG:12)
Block(5,2,7,LOG:12)
Block(5,3,7,LOG:12)
Block(5,5,1,LEAVES:12)
Block(5,5,6,LOG:12)
Block(5,5,7,LOG:12)
Block(5,6,-5,LEAVES:12)
Block(5,6,-1,LEAVES:12)
Block(5,6,0,LEAVES:12)
Block(5,6,6,LOG:12)
Block(5,6,7,LOG:12)
Block(5,6,18,LEAVES:12)
Block(5,7,-5,LEAVES:12)
Block(5,7,-4,LEAVES:12)
Block(5,7,0,LEAVES:12)
Block(5,7,3,LEAVES:12)
Block(5,7,6,LOG:12)
Block(5,7,7,LOG:12)
Block(5,7,18,LEAVES:12)
Block(5,7,20,LEAVES:12)
Block(5,8,0,LEAVES:12)
Block(5,8,6,LOG:12)
Block(5,8,7,LOG:12)
Block(5,8,20,LEAVES:12)
Block(5,9,-2,LEAVES:12)
Block(5,9,8,LOG:12)
Block(5,9,14,LEAVES:12)
Block(5,10,-1,LEAVES:12)
Block(5,10,8,LOG:12)
Block(5,10,16,LEAVES:12)
Block(5,10,17,LEAVES:12)
Block(5,10,19,LEAVES:12)
Block(5,11,1,LOG:12)
Block(5,11,2,LEAVES:12)
Block(5,11,3,LEAVES:12)
Block(5,11,16,LEAVES:12)
Block(5,11,18,LEAVES:12)
Block(5,11,19,LEAVES:12)
Block(5,12,-5,LEAVES:12)
Block(5,12,-4,LEAVES:12)
Block(5,12,-1,LEAVES:12)
Block(5,12,3,LEAVES:12)
Block(5,12,8,LOG:12)
Block(5,12,14,LEAVES:12)
Block(5,13,-5,LEAVES:12)
Block(5,13,-1,LEAVES:12)
Block(5,13,1,LEAVES:12)
Block(5,13,2,LEAVES:12)
Block(5,13,3,LEAVES:12)
Block(5,13,8,LOG:12)
Block(5,13,14,LOG:12)
Block(5,13,15,LOG:12)
Block(5,13,20,LEAVES:12)
Block(5,13,22,LEAVES:12)
Block(5,13,23,LEAVES:12)
Block(5,14,-5,LEAVES:12)
Block(5,14,-1,LEAVES:12)
Block(5,14,0,LEAVES:12)
Block(5,14,1,LEAVES:12)
Block(5,14,17,LEAVES:12)
Block(5,14,18,LEAVES:12)
Block(5,15,-3,LEAVES:12)
Block(5,15,-1,LEAVES:12)
Block(5,15,2,LOG:12)
Block(5,15,3,LOG:12)
Block(5,15,11,LEAVES:12)
Block(5,15,15,LEAVES:12)
Block(5,15,16,LEAVES:12)
Block(5,15,17,LEAVES:12)
Block(5,16,-2,LEAVES:12)
Block(5,16,11,LEAVES:12)
Block(5,16,12,LEAVES:12)
Block(5,16,16,LEAVES:12)
Block(5,16,19,LEAVES:12)
Block(5,17,-4,LEAVES:12)
Block(5,17,-3,LEAVES:12)
Block(5,17,-2,LEAVES:12)
Block(5,17,0,LEAVES:12)
Block(5,17,1,LEAVES:12)
Block(5,17,7,LOG:12)
Block(5,17,8,LEAVES:12)
Block(5,17,16,LEAVES:12)
Block(5,18,-5,LEAVES:12)
Block(5,18,-4,LEAVES:12)
Block(5,18,-2,LEAVES:12)
Block(5,18,3,LEAVES:12)
Block(5,18,6,LEAVES:12)
Block(5,18,7,LOG:12)
Block(5,18,8,LEAVES:12)
Block(5,18,14,LEAVES:12)
Block(5,19,-4,LEAVES:12)
Block(5,19,6,LOG:12)
Block(5,19,7,LOG:12)
Block(5,19,8,LEAVES:12)
Block(5,19,10,LEAVES:12)
Block(5,19,15,LEAVES:12)
Block(5,20,4,LEAVES:12)
Block(5,20,6,LEAVES:12)
Block(5,20,7,LEAVES:12)
Block(5,20,8,LEAVES:12)
Block(5,20,10,LEAVES:12)
Block(5,20,18,LEAVES:12)
Block(5,20,19,LEAVES:12)
Block(5,21,2,LEAVES:12)
Block(5,21,4,LEAVES:12)
Block(5,21,6,LEAVES:12)
Block(5,21,7,LEAVES:12)
Block(5,21,11,LEAVES:12)
Block(5,21,12,LEAVES:12)
Block(5,21,15,LEAVES:12)
Block(5,21,19,LEAVES:12)
Block(5,22,6,LEAVES:12)
Block(5,22,15,LEAVES:12)
Block(5,22,19,LEAVES:12)
Block(5,23,15,LEAVES:12)
Block(5,24,7,LEAVES:12)
Block(5,24,8,LEAVES:12)
Block(5,25,8,LEAVES:12)
Block(5,25,9,LEAVES:12)
Block(5,26,8,LEAVES:12)
Block(6,0,6,LOG:12)
Block(6,0,7,LOG:12)
Block(6,0,8,LOG:12)
Block(6,1,6,LOG:12)
Block(6,1,7,LOG:12)
Block(6,1,8,LOG:12)
Block(6,2,6,LOG:12)
Block(6,2,7,LOG:12)
Block(6,2,8,LOG:12)
Block(6,3,7,LOG:12)
Block(6,3,8,LOG:12)
Block(6,4,6,LOG:12)
Block(6,4,7,LOG:12)
Block(6,4,8,LOG:12)
Block(6,5,6,LOG:12)
Block(6,5,7,LOG:12)
Block(6,5,8,LOG:12)
Block(6,6,7,LOG:12)
Block(6,6,20,LEAVES:12)
Block(6,7,-4,LEAVES:12)
Block(6,7,2,LEAVES:12)
Block(6,7,3,LEAVES:12)
Block(6,7,7,LOG:12)
Block(6,7,14,LEAVES:12)
Block(6,7,18,LEAVES:12)
Block(6,7,19,LEAVES:12)
Block(6,8,-4,LEAVES:12)
Block(6,8,0,LEAVES:12)
Block(6,8,1,LEAVES:12)
Block(6,8,2,LEAVES:12)
Block(6,8,7,LOG:12)
Block(6,8,14,LEAVES:12)
Block(6,8,15,LEAVES:12)
Block(6,8,19,LEAVES:12)
Block(6,8,22,LEAVES:12)
Block(6,9,-2,LEAVES:12)
Block(6,9,0,LEAVES:12)
Block(6,9,19,LEAVES:12)
Block(6,10,-1,LOG:12)
Block(6,10,0,LOG:12)
Block(6,10,17,LEAVES:12)
Block(6,11,-3,LEAVES:12)
Block(6,11,-2,LEAVES:12)
Block(6,11,-1,LEAVES:12)
Block(6,11,0,LOG:12)
Block(6,11,1,LOG:12)
Block(6,11,2,LEAVES:12)
Block(6,11,18,LEAVES:12)
Block(6,12,-4,LEAVES:12)
Block(6,12,-3,LEAVES:12)
Block(6,12,-1,LEAVES:12)
Block(6,12,4,LEAVES:12)
Block(6,12,15,LOG:12)
Block(6,12,21,LEAVES:12)
Block(6,12,22,LEAVES:12)
Block(6,13,-4,LEAVES:12)
Block(6,13,-3,LEAVES:12)
Block(6,13,2,LEAVES:12)
Block(6,13,3,LEAVES:12)
Block(6,13,8,LOG:12)
Block(6,13,14,LEAVES:12)
Block(6,13,15,LOG:12)
Block(6,13,18,LEAVES:12)
Block(6,13,22,LEAVES:12)
Block(6,14,-5,LEAVES:12)
Block(6,14,-4,LEAVES:12)
Block(6,14,8,LOG:12)
Block(6,14,17,LEAVES:12)
Block(6,14,18,LEAVES:12)
Block(6,14,22,LEAVES:12)
Block(6,15,-4,LEAVES:12)
Block(6,15,-3,LEAVES:12)
Block(6,15,-2,LEAVES:12)
Block(6,15,-1,LEAVES:12)
Block(6,15,0,LOG:12)
Block(6,15,1,LOG:12)
Block(6,15,2,LOG:12)
Block(6,15,7,LOG:12)
Block(6,15,8,LOG:12)
Block(6,15,18,LEAVES:12)
Block(6,16,-2,LOG:12)
Block(6,16,-1,LOG:12)
Block(6,16,0,LOG:12)
Block(6,16,7,LOG:12)
Block(6,16,12,LEAVES:12)
Block(6,16,18,LEAVES:12)
Block(6,16,19,LEAVES:12)
Block(6,17,-2,LEAVES:12)
Block(6,17,0,LEAVES:12)
Block(6,17,5,LEAVES:12)
Block(6,17,7,LOG:12)
Block(6,17,12,LEAVES:12)
Block(6,17,16,LEAVES:12)
Block(6,17,17,LEAVES:12)
Block(6,17,18,LEAVES:12)
Block(6,18,-2,LEAVES:12)
Block(6,18,-1,LEAVES:12)
Block(6,18,9,LEAVES:12)
Block(6,18,14,LEAVES:12)
Block(6,18,16,LEAVES:12)
Block(6,19,-1,LEAVES:12)
Block(6,19,6,LEAVES:12)
Block(6,19,8,LEAVES:12)
Block(6,19,9,LEAVES:12)
Block(6,19,15,LEAVES:12)
Block(6,20,-2,LEAVES:12)
Block(6,20,13,LEAVES:12)
Block(6,20,14,LEAVES:12)
Block(6,20,15,LEAVES:12)
Block(6,20,17,LEAVES:12)
Block(6,20,18,LEAVES:12)
Block(6,21,3,LEAVES:12)
Block(6,21,4,LEAVES:12)
Block(6,21,7,LEAVES:12)
Block(6,21,8,LEAVES:12)
Block(6,21,12,LEAVES:12)
Block(6,21,13,LEAVES:12)
Block(6,21,15,LEAVES:12)
Block(6,21,20,LEAVES:12)
Block(6,22,6,LEAVES:12)
Block(6,22,8,LEAVES:12)
Block(6,22,13,LEAVES:12)
Block(6,23,3,LEAVES:12)
Block(6,23,5,LEAVES:12)
Block(6,23,6,LEAVES:12)
Block(7,0,6,LOG:12)
Block(7,0,7,LOG:12)
Block(7,1,6,LOG:12)
Block(7,2,7,LOG:12)
Block(7,3,7,LOG:12)
Block(7,4,7,LOG:12)
Block(7,5,7,LOG:12)
Block(7,6,-2,LEAVES:12)
Block(7,7,-3,LEAVES:12)
Block(7,7,3,LEAVES:12)
Block(7,7,4,LEAVES:12)
Block(7,8,-4,LEAVES:12)
Block(7,8,-3,LEAVES:12)
Block(7,8,15,LEAVES:12)
Block(7,8,21,LEAVES:12)
Block(7,8,22,LEAVES:12)
Block(7,9,-3,LEAVES:12)
Block(7,9,-2,LEAVES:12)
Block(7,9,-1,LEAVES:12)
Block(7,9,0,LEAVES:12)
Block(7,9,15,LEAVES:12)
Block(7,9,19,LEAVES:12)
Block(7,9,20,LEAVES:12)
Block(7,9,21,LEAVES:12)
Block(7,10,-1,LOG:12)
Block(7,10,0,LEAVES:12)
Block(7,10,1,LEAVES:12)
Block(7,10,17,LEAVES:12)
Block(7,10,19,LEAVES:12)
Block(7,11,-1,LEAVES:12)
Block(7,11,1,LEAVES:12)
Block(7,11,18,LEAVES:12)
Block(7,12,-1,LEAVES:12)
Block(7,12,0,LEAVES:12)
Block(7,12,15,LOG:12)
Block(7,12,16,LOG:12)
Block(7,12,17,LEAVES:12)
Block(7,12,18,LEAVES:12)
Block(7,12,20,LEAVES:12)
Block(7,12,21,LEAVES:12)
Block(7,13,-2,LEAVES:12)
Block(7,13,0,LEAVES:12)
Block(7,13,8,LOG:12)
Block(7,13,9,LOG:12)
Block(7,13,15,LEAVES:12)
Block(7,13,16,LEAVES:12)
Block(7,13,18,LEAVES:12)
Block(7,13,23,LEAVES:12)
Block(7,14,-2,LEAVES:12)
Block(7,14,-1,LEAVES:12)
Block(7,14,0,LEAVES:12)
Block(7,14,2,LEAVES:12)
Block(7,14,16,LEAVES:12)
Block(7,15,-4,LEAVES:12)
Block(7,15,-2,LEAVES:12)
Block(7,15,-1,LEAVES:12)
Block(7,15,0,LEAVES:12)
Block(7,15,2,LEAVES:12)
Block(7,15,14,LEAVES:12)
Block(7,16,-6,LEAVES:12)
Block(7,16,-4,LEAVES:12)
Block(7,16,-2,LEAVES:12)
Block(7,16,-1,LEAVES:12)
Block(7,16,3,LEAVES:12)
Block(7,16,13,LEAVES:12)
Block(7,16,19,LEAVES:12)
Block(7,16,20,LEAVES:12)
Block(7,17,-2,LEAVES:12)
Block(7,17,9,LEAVES:12)
Block(7,17,12,LEAVES:12)
Block(7,17,13,LEAVES:12)
Block(7,18,5,LEAVES:12)
Block(7,18,6,LEAVES:12)
Block(7,18,9,LEAVES:12)
Block(7,18,12,LOG:12)
Block(7,18,13,LOG:12)
Block(7,18,14,LOG:12)
Block(7,18,15,LEAVES:12)
Block(7,18,16,LEAVES:12)
Block(7,19,-1,LEAVES:12)
Block(7,19,0,LEAVES:12)
Block(7,19,6,LEAVES:12)
Block(7,19,14,LOG:12)
Block(7,19,15,LOG:12)
Block(7,19,16,LEAVES:12)
Block(7,19,17,LEAVES:12)
Block(7,20,0,LEAVES:12)
Block(7,20,1,LEAVES:12)
Block(7,20,6,LEAVES:12)
Block(7,20,15,LEAVES:12)
Block(7,20,17,LEAVES:12)
Block(7,21,0,LEAVES:12)
Block(7,21,2,LEAVES:12)
Block(7,21,3,LEAVES:12)
Block(7,21,15,LEAVES:12)
Block(7,21,16,LEAVES:12)
Block(7,22,8,LEAVES:12)
Block(7,22,9,LEAVES:12)
Block(7,22,10,LEAVES:12)
Block(7,22,16,LEAVES:12)
Block(7,23,4,LEAVES:12)
Block(7,23,5,LEAVES:12)
Block(7,23,9,LEAVES:12)
Block(7,23,15,LEAVES:12)
Block(7,24,7,LEAVES:12)
Block(8,6,1,LEAVES:12)
Block(8,7,-1,LEAVES:12)
Block(8,7,1,LEAVES:12)
Block(8,7,3,LEAVES:12)
Block(8,7,16,LEAVES:12)
Block(8,7,17,LEAVES:12)
Block(8,8,-1,LEAVES:12)
Block(8,8,1,LEAVES:12)
Block(8,8,2,LEAVES:12)
Block(8,8,3,LEAVES:12)
Block(8,8,15,LEAVES:12)
Block(8,8,16,LEAVES:12)
Block(8,8,22,LEAVES:12)
Block(8,8,23,LEAVES:12)
Block(8,9,-3,LEAVES:12)
Block(8,9,-2,LEAVES:12)
Block(8,9,-1,LEAVES:12)
Block(8,9,0,LEAVES:12)
Block(8,9,1,LEAVES:12)
Block(8,9,3,LEAVES:12)
Block(8,9,11,LEAVES:12)
Block(8,9,15,LEAVES:12)
Block(8,9,16,LEAVES:12)
Block(8,10,-5,LEAVES:12)
Block(8,10,-3,LEAVES:12)
Block(8,10,-1,LEAVES:12)
Block(8,10,0,LEAVES:12)
Block(8,10,4,LEAVES:12)
Block(8,10,16,LEAVES:12)
Block(8,10,17,LEAVES:12)
Block(8,10,18,LEAVES:12)
Block(8,10,19,LEAVES:12)
Block(8,11,-1,LEAVES:12)
Block(8,11,16,LOG:12)
Block(8,11,17,LOG:12)
Block(8,11,18,LOG:12)
Block(8,11,19,LEAVES:12)
Block(8,11,20,LEAVES:12)
Block(8,12,-3,LEAVES:12)
Block(8,12,16,LOG:12)
Block(8,12,18,LEAVES:12)
Block(8,12,20,LEAVES:12)
Block(8,13,0,LEAVES:12)
Block(8,13,1,LEAVES:12)
Block(8,13,9,LOG:12)
Block(8,13,18,LEAVES:12)
Block(8,13,19,LEAVES:12)
Block(8,14,-2,LEAVES:12)
Block(8,14,0,LEAVES:12)
Block(8,14,1,LEAVES:12)
Block(8,14,2,LEAVES:12)
Block(8,14,9,LOG:12)
Block(8,14,19,LEAVES:12)
Block(8,15,1,LEAVES:12)
Block(8,15,17,LEAVES:12)
Block(8,15,18,LEAVES:12)
Block(8,16,-5,LEAVES:12)
Block(8,16,-4,LEAVES:12)
Block(8,16,-1,LEAVES:12)
Block(8,16,0,LEAVES:12)
Block(8,16,15,LEAVES:12)
Block(8,16,17,LEAVES:12)
Block(8,17,-2,LEAVES:12)
Block(8,17,0,LEAVES:12)
Block(8,17,4,LEAVES:12)
Block(8,17,5,LEAVES:12)
Block(8,17,11,LOG:12)
Block(8,17,12,LOG:12)
Block(8,17,15,LEAVES:12)
Block(8,17,17,LEAVES:12)
Block(8,17,19,LEAVES:12)
Block(8,18,-5,LEAVES:12)
Block(8,18,-3,LEAVES:12)
Block(8,18,-2,LEAVES:12)
Block(8,18,4,LEAVES:12)
Block(8,18,5,LEAVES:12)
Block(8,18,12,LOG:12)
Block(8,18,13,LEAVES:12)
Block(8,18,15,LEAVES:12)
Block(8,18,16,LEAVES:12)
Block(8,18,17,LEAVES:12)
Block(8,18,19,LEAVES:12)
Block(8,19,0,LEAVES:12)
Block(8,19,11,LEAVES:12)
Block(8,19,13,LEAVES:12)
Block(8,19,15,LEAVES:12)
Block(8,19,16,LEAVES:12)
Block(8,19,20,LEAVES:12)
Block(8,20,5,LEAVES:12)
Block(8,20,6,LEAVES:12)
Block(8,20,15,LEAVES:12)
Block(8,21,6,LEAVES:12)
Block(8,22,9,LEAVES:12)
Block(8,22,16,LEAVES:12)
Block(8,22,17,LEAVES:12)
Block(8,23,4,LEAVES:12)
Block(8,23,17,LEAVES:12)
Block(8,23,18,LEAVES:12)
Block(8,24,4,LEAVES:12)
Block(8,24,17,LEAVES:12)
Block(9,5,0,LEAVES:12)
Block(9,5,13,LEAVES:12)
Block(9,6,-2,LEAVES:12)
Block(9,7,2,LEAVES:12)
Block(9,7,20,LEAVES:12)
Block(9,8,-1,LEAVES:12)
Block(9,8,1,LEAVES:12)
Block(9,8,2,LEAVES:12)
Block(9,8,15,LEAVES:12)
Block(9,8,18,LEAVES:12)
Block(9,8,20,LEAVES:12)
Block(9,9,-2,LEAVES:12)
Block(9,9,-1,LEAVES:12)
Block(9,9,11,LEAVES:12)
Block(9,9,12,LEAVES:12)
Block(9,9,18,LEAVES:12)
Block(9,9,20,LEAVES:12)
Block(9,9,22,LEAVES:12)
Block(9,10,-4,LEAVES:12)
Block(9,10,-3,LEAVES:12)
Block(9,10,0,LEAVES:12)
Block(9,10,1,LEAVES:12)
Block(9,10,16,LEAVES:12)
Block(9,10,18,LEAVES:12)
Block(9,10,19,LEAVES:12)
Block(9,10,20,LEAVES:12)
Block(9,10,22,LEAVES:12)
Block(9,11,-1,LEAVES:12)
Block(9,11,1,LEAVES:12)
Block(9,11,14,LEAVES:12)
Block(9,11,16,LEAVES:12)
Block(9,11,18,LEAVES:12)
Block(9,11,19,LEAVES:12)
Block(9,11,23,LEAVES:12)
Block(9,12,-4,LEAVES:12)
Block(9,12,-2,LEAVES:12)
Block(9,12,-1,LEAVES:12)
Block(9,12,0,LEAVES:12)
Block(9,12,1,LEAVES:12)
Block(9,12,2,LEAVES:12)
Block(9,12,13,LEAVES:12)
Block(9,12,15,LEAVES:12)
Block(9,12,18,LEAVES:12)
Block(9,13,-3,LEAVES:12)
Block(9,13,-2,LEAVES:12)
Block(9,13,0,LEAVES:12)
Block(9,13,1,LEAVES:12)
Block(9,13,13,LEAVES:12)
Block(9,14,-2,LEAVES:12)
Block(9,14,7,LOG:12)
Block(9,14,8,LOG:12)
Block(9,14,9,LOG:12)
Block(9,14,10,LOG:12)
Block(9,14,19,LEAVES:12)
Block(9,14,20,LEAVES:12)
Block(9,15,-2,LEAVES:12)
Block(9,15,2,LEAVES:12)
Block(9,15,10,LOG:12)
Block(9,15,14,LEAVES:12)
Block(9,15,20,LEAVES:12)
Block(9,15,21,LEAVES:12)
Block(9,16,-6,LEAVES:12)
Block(9,16,-5,LEAVES:12)
Block(9,16,10,LOG:12)
Block(9,16,11,LOG:12)
Block(9,16,18,LEAVES:12)
Block(9,16,20,LEAVES:12)
Block(9,17,0,LEAVES:12)
Block(9,17,1,LEAVES:12)
Block(9,17,2,LEAVES:12)
Block(9,17,4,LEAVES:12)
Block(9,17,11,LOG:12)
Block(9,17,15,LEAVES:12)
Block(9,17,17,LEAVES:12)
Block(9,17,18,LEAVES:12)
Block(9,18,-4,LEAVES:12)
Block(9,18,-3,LEAVES:12)
Block(9,18,1,LEAVES:12)
Block(9,18,4,LEAVES:12)
Block(9,19,-1,LEAVES:12)
Block(9,19,0,LEAVES:12)
Block(9,19,1,LEAVES:12)
Block(9,19,7,LEAVES:12)
Block(9,19,12,LEAVES:12)
Block(9,19,13,LEAVES:12)
Block(9,19,16,LEAVES:12)
Block(9,19,17,LEAVES:12)
Block(9,20,6,LEAVES:12)
Block(9,20,7,LEAVES:12)
Block(9,20,15,LEAVES:12)
Block(9,20,17,LEAVES:12)
Block(9,21,12,LEAVES:12)
Block(9,21,14,LEAVES:12)
Block(9,21,15,LEAVES:12)
Block(9,22,2,LEAVES:12)
Block(9,22,4,LEAVES:12)
Block(9,23,2,LEAVES:12)
Block(10,4,1,LEAVES:12)
Block(10,4,14,LEAVES:12)
Block(10,5,1,LEAVES:12)
Block(10,5,14,LEAVES:12)
Block(10,6,2,LEAVES:12)
Block(10,6,3,LEAVES:12)
Block(10,6,16,LEAVES:12)
Block(10,7,-3,LEAVES:12)
Block(10,7,-2,LEAVES:12)
Block(10,7,-1,LEAVES:12)
Block(10,7,2,LEAVES:12)
Block(10,7,10,LEAVES:12)
Block(10,7,17,LEAVES:12)
Block(10,8,-1,LEAVES:12)
Block(10,8,0,LEAVES:12)
Block(10,8,2,LEAVES:12)
Block(10,8,12,LEAVES:12)
Block(10,8,13,LEAVES:12)
Block(10,8,15,LEAVES:12)
Block(10,8,21,LEAVES:12)
Block(10,9,-1,LEAVES:12)
Block(10,9,1,LEAVES:12)
Block(10,9,2,LEAVES:12)
Block(10,9,12,LEAVES:12)
Block(10,9,14,LEAVES:12)
Block(10,9,15,LEAVES:12)
Block(10,9,18,LEAVES:12)
Block(10,9,20,LEAVES:12)
Block(10,9,21,LEAVES:12)
Block(10,10,-5,LEAVES:12)
Block(10,10,-4,LEAVES:12)
Block(10,11,1,LEAVES:12)
Block(10,11,2,LEAVES:12)
Block(10,11,3,LEAVES:12)
Block(10,11,5,LEAVES:12)
Block(10,11,6,LEAVES:12)
Block(10,11,15,LEAVES:12)
Block(10,11,16,LEAVES:12)
Block(10,11,18,LEAVES:12)
Block(10,11,19,LEAVES:12)
Block(10,11,20,LEAVES:12)
Block(10,12,-4,LEAVES:12)
Block(10,12,-3,LEAVES:12)
Block(10,12,-2,LEAVES:12)
Block(10,12,0,LEAVES:12)
Block(10,12,1,LEAVES:12)
Block(10,12,2,LEAVES:12)
Block(10,12,13,LEAVES:12)
Block(10,12,14,LEAVES:12)
Block(10,12,18,LEAVES:12)
Block(10,12,20,LEAVES:12)
Block(10,13,-3,LEAVES:12)
Block(10,13,0,LEAVES:12)
Block(10,13,5,LOG:12)
Block(10,13,6,LOG:12)
Block(10,13,15,LEAVES:12)
Block(10,13,17,LEAVES:12)
Block(10,13,18,LEAVES:12)
Block(10,14,3,LEAVES:12)
Block(10,14,6,LOG:12)
Block(10,14,7,LOG:12)
Block(10,14,10,LOG:12)
Block(10,15,-3,LEAVES:12)
Block(10,15,-2,LEAVES:12)
Block(10,15,3,LEAVES:12)
Block(10,15,6,LOG:12)
Block(10,15,18,LEAVES:12)
Block(10,16,-2,LEAVES:12)
Block(10,16,5,LEAVES:12)
Block(10,16,14,LEAVES:12)
Block(10,16,15,LEAVES:12)
Block(10,16,18,LEAVES:12)
Block(10,17,-1,LEAVES:12)
Block(10,17,1,LEAVES:12)
Block(10,17,15,LEAVES:12)
Block(10,18,-4,LEAVES:12)
Block(10,18,1,LEAVES:12)
Block(10,18,2,LEAVES:12)
Block(10,18,4,LEAVES:12)
Block(10,18,15,LEAVES:12)
Block(10,19,-4,LEAVES:12)
Block(10,19,1,LEAVES:12)
Block(10,19,3,LEAVES:12)
Block(10,19,4,LEAVES:12)
Block(10,19,7,LEAVES:12)
Block(10,19,11,LEAVES:12)
Block(10,19,12,LEAVES:12)
Block(10,20,17,LEAVES:12)
Block(10,20,18,LEAVES:12)
Block(10,20,19,LEAVES:12)
Block(10,21,5,LEAVES:12)
Block(10,21,7,LEAVES:12)
Block(10,21,8,LEAVES:12)
Block(10,21,13,LEAVES:12)
Block(10,21,14,LEAVES:12)
Block(10,21,18,LEAVES:12)
Block(10,22,2,LEAVES:12)
Block(10,22,3,LEAVES:12)
Block(10,22,16,LEAVES:12)
Block(11,4,3,LEAVES:12)
Block(11,4,16,LEAVES:12)
Block(11,5,-3,LEAVES:12)
Block(11,5,1,LEAVES:12)
Block(11,5,2,LEAVES:12)
Block(11,5,10,LEAVES:12)
Block(11,5,14,LEAVES:12)
Block(11,5,15,LEAVES:12)
Block(11,6,-3,LEAVES:12)
Block(11,6,-2,LEAVES:12)
Block(11,6,2,LEAVES:12)
Block(11,6,5,LEAVES:12)
Block(11,6,10,LEAVES:12)
Block(11,6,11,LEAVES:12)
Block(11,6,15,LEAVES:12)
Block(11,6,18,LEAVES:12)
Block(11,7,-2,LEAVES:12)
Block(11,7,2,LEAVES:12)
Block(11,7,15,LEAVES:12)
Block(11,7,21,LEAVES:12)
Block(11,8,0,LEAVES:12)
Block(11,8,13,LEAVES:12)
Block(11,8,17,LEAVES:12)
Block(11,8,18,LEAVES:12)
Block(11,8,21,LEAVES:12)
Block(11,9,-2,LEAVES:12)
Block(11,9,-1,LEAVES:12)
Block(11,9,1,LEAVES:12)
Block(11,9,14,LEAVES:12)
Block(11,9,18,LEAVES:12)
Block(11,10,-1,LEAVES:12)
Block(11,10,2,LOG:12)
Block(11,10,4,LEAVES:12)
Block(11,10,5,LEAVES:12)
Block(11,10,17,LEAVES:12)
Block(11,10,18,LEAVES:12)
Block(11,11,-3,LEAVES:12)
Block(11,11,-2,LEAVES:12)
Block(11,11,1,LEAVES:12)
Block(11,11,2,LOG:12)
Block(11,11,3,LOG:12)
Block(11,11,5,LEAVES:12)
Block(11,11,10,LEAVES:12)
Block(11,11,11,LEAVES:12)
Block(11,11,14,LEAVES:12)
Block(11,11,15,LEAVES:12)
Block(11,11,18,LEAVES:12)
Block(11,12,-4,LEAVES:12)
Block(11,12,-3,LEAVES:12)
Block(11,12,1,LEAVES:12)
Block(11,12,3,LOG:12)
Block(11,12,4,LOG:12)
Block(11,12,5,LOG:12)
Block(11,12,14,LEAVES:12)
Block(11,12,18,LEAVES:12)
Block(11,12,20,LEAVES:12)
Block(11,12,21,LEAVES:12)
Block(11,12,22,LEAVES:12)
Block(11,13,-3,LEAVES:12)
Block(11,13,1,LEAVES:12)
Block(11,13,5,LOG:12)
Block(11,13,11,LOG:12)
Block(11,13,12,LOG:12)
Block(11,13,13,LOG:12)
Block(11,13,14,LEAVES:12)
Block(11,13,16,LEAVES:12)
Block(11,13,17,LEAVES:12)
Block(11,13,21,LEAVES:12)
Block(11,14,-1,LEAVES:12)
Block(11,14,5,LEAVES:12)
Block(11,14,10,LOG:12)
Block(11,14,11,LOG:12)
Block(11,14,19,LEAVES:12)
Block(11,15,-2,LEAVES:12)
Block(11,15,-1,LEAVES:12)
Block(11,15,3,LEAVES:12)
Block(11,15,4,LEAVES:12)
Block(11,15,5,LOG:12)
Block(11,15,6,LOG:12)
Block(11,15,10,LOG:12)
Block(11,15,13,LEAVES:12)
Block(11,15,14,LEAVES:12)
Block(11,16,-1,LEAVES:12)
Block(11,16,0,LEAVES:12)
Block(11,16,4,LEAVES:12)
Block(11,16,7,LEAVES:12)
Block(11,16,14,LEAVES:12)
Block(11,17,4,LEAVES:12)
Block(11,18,2,LEAVES:12)
Block(11,18,14,LEAVES:12)
Block(11,18,15,LEAVES:12)
Block(11,19,3,LEAVES:12)
Block(11,19,15,LEAVES:12)
Block(11,20,6,LEAVES:12)
Block(11,20,7,LEAVES:12)
Block(11,20,18,LEAVES:12)
Block(11,21,-1,LEAVES:12)
Block(11,21,0,LEAVES:12)
Block(11,21,3,LEAVES:12)
Block(11,21,7,LEAVES:12)
Block(11,21,13,LEAVES:12)
Block(11,22,3,LEAVES:12)
Block(11,22,7,LEAVES:12)
Block(11,22,13,LEAVES:12)
Block(11,23,3,LEAVES:12)
Block(12,6,-3,LEAVES:12)
Block(12,6,-2,LEAVES:12)
Block(12,6,4,LEAVES:12)
Block(12,6,5,LEAVES:12)
Block(12,6,11,LEAVES:12)
Block(12,6,17,LEAVES:12)
Block(12,6,18,LEAVES:12)
Block(12,7,-2,LEAVES:12)
Block(12,7,2,LEAVES:12)
Block(12,7,3,LEAVES:12)
Block(12,7,4,LEAVES:12)
Block(12,7,11,LEAVES:12)
Block(12,7,15,LEAVES:12)
Block(12,7,16,LEAVES:12)
Block(12,7,17,LEAVES:12)
Block(12,8,0,LEAVES:12)
Block(12,8,2,LEAVES:12)
Block(12,8,13,LEAVES:12)
Block(12,8,15,LEAVES:12)
Block(12,8,17,LEAVES:12)
Block(12,9,-1,LEAVES:12)
Block(12,9,0,LEAVES:12)
Block(12,9,1,LOG:12)
Block(12,9,14,LEAVES:12)
Block(12,10,-1,LEAVES:12)
Block(12,10,0,LEAVES:12)
Block(12,10,1,LOG:12)
Block(12,10,2,LOG:12)
Block(12,10,3,LEAVES:12)
Block(12,10,4,LEAVES:12)
Block(12,10,12,LEAVES:12)
Block(12,10,13,LEAVES:12)
Block(12,10,14,LOG:12)
Block(12,10,16,LEAVES:12)
Block(12,10,17,LEAVES:12)
Block(12,10,18,LEAVES:12)
Block(12,11,-2,LEAVES:12)
Block(12,11,-1,LEAVES:12)
Block(12,11,1,LEAVES:12)
Block(12,11,6,LEAVES:12)
Block(12,11,11,LEAVES:12)
Block(12,11,12,LEAVES:12)
Block(12,11,14,LOG:12)
Block(12,11,18,LEAVES:12)
Block(12,11,19,LEAVES:12)
Block(12,12,-1,LEAVES:12)
Block(12,12,12,LEAVES:12)
Block(12,12,13,LOG:12)
Block(12,12,14,LOG:12)
Block(12,12,21,LEAVES:12)
Block(12,13,11,LEAVES:12)
Block(12,13,12,LEAVES:12)
Block(12,13,13,LOG:12)
Block(12,13,16,LEAVES:12)
Block(12,14,-1,LEAVES:12)
Block(12,14,7,LEAVES:12)
Block(12,14,16,LEAVES:12)
Block(12,15,5,LOG:12)
Block(12,15,9,LOG:12)
Block(12,15,10,LOG:12)
Block(12,15,13,LEAVES:12)
Block(12,16,0,LEAVES:12)
Block(12,16,4,LOG:12)
Block(12,16,5,LOG:12)
Block(12,16,6,LEAVES:12)
Block(12,16,7,LEAVES:12)
Block(12,17,0,LEAVES:12)
Block(12,17,4,LEAVES:12)
Block(12,17,5,LEAVES:12)
Block(12,17,6,LEAVES:12)
Block(12,17,16,LEAVES:12)
Block(12,18,2,LEAVES:12)
Block(12,18,4,LEAVES:12)
Block(12,18,15,LEAVES:12)
Block(12,18,16,LEAVES:12)
Block(12,19,3,LEAVES:12)
Block(12,20,1,LEAVES:12)
Block(12,20,2,LEAVES:12)
Block(12,20,3,LEAVES:12)
Block(12,20,5,LEAVES:12)
Block(12,20,6,LEAVES:12)
Block(12,21,0,LEAVES:12)
Block(12,21,1,LEAVES:12)
Block(12,21,3,LEAVES:12)
Block(12,21,8,LEAVES:12)
Block(12,22,1,LEAVES:12)
Block(13,5,0,LEAVES:12)
Block(13,5,13,LEAVES:12)
Block(13,6,-1,LEAVES:12)
Block(13,6,5,LEAVES:12)
Block(13,6,6,LEAVES:12)
Block(13,6,12,LEAVES:12)
Block(13,6,18,LEAVES:12)
Block(13,6,19,LEAVES:12)
Block(13,7,-2,LEAVES:12)
Block(13,7,-1,LEAVES:12)
Block(13,7,11,LEAVES:12)
Block(13,7,12,LEAVES:12)
Block(13,7,16,LEAVES:12)
Block(13,8,-1,LEAVES:12)
Block(13,8,0,LEAVES:12)
Block(13,8,1,LEAVES:12)
Block(13,8,2,LEAVES:12)
Block(13,8,12,LEAVES:12)
Block(13,8,13,LEAVES:12)
Block(13,8,14,LOG:12)
Block(13,8,15,LEAVES:12)
Block(13,9,1,LOG:12)
Block(13,9,2,LEAVES:12)
Block(13,9,3,LEAVES:12)
Block(13,9,14,LOG:12)
Block(13,9,15,LEAVES:12)
Block(13,9,16,LEAVES:12)
Block(13,9,19,LEAVES:12)
Block(13,10,1,LEAVES:12)
Block(13,10,3,LEAVES:12)
Block(13,10,9,LEAVES:12)
Block(13,10,14,LOG:12)
Block(13,10,16,LEAVES:12)
Block(13,10,18,LEAVES:12)
Block(13,10,19,LEAVES:12)
Block(13,11,1,LEAVES:12)
Block(13,11,2,LEAVES:12)
Block(13,11,14,LEAVES:12)
Block(13,11,15,LEAVES:12)
Block(13,12,2,LEAVES:12)
Block(13,12,15,LEAVES:12)
Block(13,13,1,LEAVES:12)
Block(13,13,11,LEAVES:12)
Block(13,13,14,LEAVES:12)
Block(13,14,7,LEAVES:12)
Block(13,14,8,LEAVES:12)
Block(13,15,2,LEAVES:12)
Block(13,15,9,LOG:12)
Block(13,16,1,LEAVES:12)
Block(13,16,4,LOG:12)
Block(13,16,7,LEAVES:12)
Block(13,16,8,LEAVES:12)
Block(13,16,9,LOG:12)
Block(13,17,0,LEAVES:12)
Block(13,17,1,LEAVES:12)
Block(13,17,3,LOG:12)
Block(13,17,4,LOG:12)
Block(13,17,9,LEAVES:12)
Block(13,17,11,LEAVES:12)
Block(13,17,16,LEAVES:12)
Block(13,18,1,LEAVES:12)
Block(13,18,2,LEAVES:12)
Block(13,18,3,LOG:12)
Block(13,18,4,LEAVES:12)
Block(13,18,9,LEAVES:12)
Block(13,19,3,LOG:12)
Block(13,19,4,LEAVES:12)
Block(13,19,5,LEAVES:12)
Block(13,20,3,LEAVES:12)
Block(13,20,5,LEAVES:12)
Block(13,21,3,LEAVES:12)
Block(13,21,4,LEAVES:12)
Block(13,22,4,LEAVES:12)
Block(13,23,3,LEAVES:12)
Block(14,5,3,LEAVES:12)
Block(14,5,16,LEAVES:12)
Block(14,6,1,LEAVES:12)
Block(14,6,3,LEAVES:12)
Block(14,6,14,LEAVES:12)
Block(14,6,16,LEAVES:12)
Block(14,7,1,LEAVES:12)
Block(14,7,3,LEAVES:12)
Block(14,7,5,LEAVES:12)
Block(14,7,14,LEAVES:12)
Block(14,7,16,LEAVES:12)
Block(14,7,18,LEAVES:12)
Block(14,8,-1,LEAVES:12)
Block(14,8,1,LEAVES:12)
Block(14,8,2,LEAVES:12)
Block(14,8,3,LEAVES:12)
Block(14,8,5,LEAVES:12)
Block(14,8,12,LEAVES:12)
Block(14,8,14,LEAVES:12)
Block(14,8,15,LEAVES:12)
Block(14,8,16,LEAVES:12)
Block(14,8,18,LEAVES:12)
Block(14,9,-3,LEAVES:12)
Block(14,9,-1,LEAVES:12)
Block(14,9,1,LOG:12)
Block(14,9,2,LEAVES:12)
Block(14,9,6,LEAVES:12)
Block(14,9,10,LEAVES:12)
Block(14,9,12,LEAVES:12)
Block(14,9,14,LEAVES:12)
Block(14,9,15,LEAVES:12)
Block(14,9,19,LEAVES:12)
Block(14,10,1,LEAVES:12)
Block(14,10,10,LEAVES:12)
Block(14,10,14,LEAVES:12)
Block(14,11,12,LEAVES:12)
Block(14,12,2,LEAVES:12)
Block(14,12,3,LEAVES:12)
Block(14,12,6,LEAVES:12)
Block(14,12,15,LEAVES:12)
Block(14,12,16,LEAVES:12)
Block(14,13,3,LEAVES:12)
Block(14,13,4,LEAVES:12)
Block(14,13,8,LEAVES:12)
Block(14,13,9,LEAVES:12)
Block(14,13,11,LEAVES:12)
Block(14,13,16,LEAVES:12)
Block(14,13,17,LEAVES:12)
Block(14,14,3,LEAVES:12)
Block(14,14,8,LEAVES:12)
Block(14,14,10,LEAVES:12)
Block(14,14,11,LEAVES:12)
Block(14,14,16,LEAVES:12)
Block(14,15,5,LEAVES:12)
Block(14,16,3,LEAVES:12)
Block(14,16,5,LEAVES:12)
Block(14,16,9,LOG:12)
Block(14,16,12,LEAVES:12)
Block(14,16,14,LEAVES:12)
Block(14,16,15,LEAVES:12)
Block(14,17,3,LEAVES:12)
Block(14,17,5,LEAVES:12)
Block(14,17,7,LEAVES:12)
Block(14,17,9,LEAVES:12)
Block(14,17,10,LEAVES:12)
Block(14,18,1,LEAVES:12)
Block(14,18,3,LEAVES:12)
Block(14,18,4,LEAVES:12)
Block(14,18,5,LEAVES:12)
Block(14,18,7,LEAVES:12)
Block(14,19,-1,LEAVES:12)
Block(14,19,1,LEAVES:12)
Block(14,19,3,LEAVES:12)
Block(14,19,4,LEAVES:12)
Block(14,19,8,LEAVES:12)
Block(14,20,3,LEAVES:12)
Block(14,22,4,LEAVES:12)
Block(14,22,5,LEAVES:12)
Block(14,23,5,LEAVES:12)
Block(14,23,6,LEAVES:12)
Block(14,24,5,LEAVES:12)
Block(15,5,0,LEAVES:12)
Block(15,5,13,LEAVES:12)
Block(15,6,4,LEAVES:12)
Block(15,6,17,LEAVES:12)
Block(15,7,1,LEAVES:12)
Block(15,7,3,LEAVES:12)
Block(15,7,4,LEAVES:12)
Block(15,7,14,LEAVES:12)
Block(15,7,16,LEAVES:12)
Block(15,7,17,LEAVES:12)
Block(15,9,-2,LEAVES:12)
Block(15,9,-1,LEAVES:12)
Block(15,9,2,LEAVES:12)
Block(15,9,3,LEAVES:12)
Block(15,9,11,LEAVES:12)
Block(15,9,12,LEAVES:12)
Block(15,9,15,LEAVES:12)
Block(15,9,16,LEAVES:12)
Block(15,10,1,LEAVES:12)
Block(15,10,3,LEAVES:12)
Block(15,10,6,LEAVES:12)
Block(15,10,10,LEAVES:12)
Block(15,10,11,LEAVES:12)
Block(15,10,14,LEAVES:12)
Block(15,10,16,LEAVES:12)
Block(15,11,-2,LEAVES:12)
Block(15,11,0,LEAVES:12)
Block(15,11,1,LEAVES:12)
Block(15,11,6,LEAVES:12)
Block(15,11,7,LEAVES:12)
Block(15,11,11,LEAVES:12)
Block(15,11,13,LEAVES:12)
Block(15,11,14,LEAVES:12)
Block(15,12,11,LEAVES:12)
Block(15,13,9,LEAVES:12)
Block(15,14,10,LEAVES:12)
Block(15,15,2,LEAVES:12)
Block(15,15,9,LOG:12)
Block(15,15,13,LEAVES:12)
Block(15,15,14,LEAVES:12)
Block(15,16,6,LEAVES:12)
Block(15,16,7,LEAVES:12)
Block(15,16,9,LOG:12)
Block(15,16,10,LEAVES:12)
Block(15,16,14,LEAVES:12)
Block(15,17,3,LEAVES:12)
Block(15,17,5,LEAVES:12)
Block(15,17,6,LEAVES:12)
Block(15,17,10,LEAVES:12)
Block(15,17,14,LEAVES:12)
Block(15,18,10,LEAVES:12)
Block(15,19,0,LEAVES:12)
Block(15,19,1,LEAVES:12)
Block(15,19,4,LEAVES:12)
Block(15,19,5,LEAVES:12)
Block(15,20,3,LEAVES:12)
Block(15,20,5,LEAVES:12)
Block(15,21,0,LEAVES:12)
Block(15,21,2,LEAVES:12)
Block(15,21,3,LEAVES:12)
Block(16,5,4,LEAVES:12)
Block(16,5,17,LEAVES:12)
Block(16,6,0,LEAVES:12)
Block(16,6,1,LEAVES:12)
Block(16,6,4,LEAVES:12)
Block(16,6,13,LEAVES:12)
Block(16,6,14,LEAVES:12)
Block(16,6,17,LEAVES:12)
Block(16,7,1,LEAVES:12)
Block(16,7,14,LEAVES:12)
Block(16,8,1,LEAVES:12)
Block(16,8,14,LEAVES:12)
Block(16,9,-3,LEAVES:12)
Block(16,9,-2,LEAVES:12)
Block(16,9,10,LEAVES:12)
Block(16,9,11,LEAVES:12)
Block(16,10,3,LEAVES:12)
Block(16,10,4,LEAVES:12)
Block(16,10,5,LEAVES:12)
Block(16,10,16,LEAVES:12)
Block(16,10,17,LEAVES:12)
Block(16,10,18,LEAVES:12)
Block(16,11,-1,LEAVES:12)
Block(16,11,0,LEAVES:12)
Block(16,11,4,LEAVES:12)
Block(16,11,7,LEAVES:12)
Block(16,11,12,LEAVES:12)
Block(16,11,13,LEAVES:12)
Block(16,11,14,LEAVES:12)
Block(16,11,17,LEAVES:12)
Block(16,12,2,LEAVES:12)
Block(16,12,7,LEAVES:12)
Block(16,12,11,LEAVES:12)
Block(16,12,12,LEAVES:12)
Block(16,12,13,LEAVES:12)
Block(16,12,15,LEAVES:12)
Block(16,13,9,LEAVES:12)
Block(16,13,11,LEAVES:12)
Block(16,14,10,LOG:12)
Block(16,15,6,LEAVES:12)
Block(16,15,8,LEAVES:12)
Block(16,15,9,LOG:12)
Block(16,15,10,LOG:12)
Block(16,15,12,LEAVES:12)
Block(16,15,13,LEAVES:12)
Block(16,16,2,LEAVES:12)
Block(16,16,3,LEAVES:12)
Block(16,16,6,LEAVES:12)
Block(16,16,7,LEAVES:12)
Block(16,16,8,LEAVES:12)
Block(16,16,10,LEAVES:12)
Block(16,16,15,LEAVES:12)
Block(16,17,3,LEAVES:12)
Block(16,17,8,LEAVES:12)
Block(16,18,3,LEAVES:12)
Block(16,19,-1,LEAVES:12)
Block(16,19,0,LEAVES:12)
Block(16,20,5,LEAVES:12)
Block(16,20,6,LEAVES:12)
Block(16,20,7,LEAVES:12)
Block(16,21,1,LEAVES:12)
Block(16,21,2,LEAVES:12)
Block(16,21,6,LEAVES:12)
Block(16,22,4,LEAVES:12)
Block(17,5,-1,LEAVES:12)
Block(17,5,0,LEAVES:12)
Block(17,5,12,LEAVES:12)
Block(17,5,13,LEAVES:12)
Block(17,6,0,LEAVES:12)
Block(17,6,13,LEAVES:12)
Block(17,8,0,LEAVES:12)
Block(17,8,1,LEAVES:12)
Block(17,8,13,LEAVES:12)
Block(17,8,14,LEAVES:12)
Block(17,9,1,LEAVES:12)
Block(17,9,14,LEAVES:12)
Block(17,10,4,LEAVES:12)
Block(17,10,9,LEAVES:12)
Block(17,10,17,LEAVES:12)
Block(17,11,-1,LEAVES:12)
Block(17,11,8,LEAVES:12)
Block(17,11,12,LEAVES:12)
Block(17,11,14,LEAVES:12)
Block(17,11,15,LEAVES:12)
Block(17,12,-1,LEAVES:12)
Block(17,12,7,LEAVES:12)
Block(17,12,8,LEAVES:12)
Block(17,12,12,LEAVES:12)
Block(17,13,8,LEAVES:12)
Block(17,13,9,LEAVES:12)
Block(17,13,10,LOG:12)
Block(17,13,11,LEAVES:12)
Block(17,14,10,LOG:12)
Block(17,14,11,LEAVES:12)
Block(17,14,12,LEAVES:12)
Block(17,15,1,LEAVES:12)
Block(17,15,2,LEAVES:12)
Block(17,15,10,LEAVES:12)
Block(17,15,12,LEAVES:12)
Block(17,16,2,LEAVES:12)
Block(17,16,10,LEAVES:12)
Block(17,16,11,LEAVES:12)
Block(17,17,11,LEAVES:12)
Block(17,18,2,LEAVES:12)
Block(17,18,3,LEAVES:12)
Block(17,18,10,LEAVES:12)
Block(17,19,3,LEAVES:12)
Block(17,20,6,LEAVES:12)
Block(17,21,1,LEAVES:12)
Block(17,22,1,LEAVES:12)
Block(18,5,-1,LEAVES:12)
Block(18,5,12,LEAVES:12)
Block(18,7,2,LEAVES:12)
Block(18,7,15,LEAVES:12)
Block(18,8,1,LEAVES:12)
Block(18,8,2,LEAVES:12)
Block(18,8,14,LEAVES:12)
Block(18,8,15,LEAVES:12)
Block(18,10,12,LEAVES:12)
Block(18,11,10,LEAVES:12)
Block(18,11,12,LEAVES:12)
Block(18,12,10,LEAVES:12)
Block(18,12,12,LEAVES:12)
Block(18,12,14,LEAVES:12)
Block(18,13,8,LEAVES:12)
Block(18,13,10,LEAVES:12)
Block(18,13,11,LEAVES:12)
Block(18,13,12,LEAVES:12)
Block(18,13,14,LEAVES:12)
Block(18,14,6,LEAVES:12)
Block(18,14,8,LEAVES:12)
Block(18,14,10,LEAVES:12)
Block(18,14,11,LEAVES:12)
Block(18,14,15,LEAVES:12)
Block(18,15,1,LEAVES:12)
Block(18,15,10,LEAVES:12)
Block(18,17,4,LEAVES:12)
Block(18,17,11,LEAVES:12)
Block(18,17,12,LEAVES:12)
Block(18,18,3,LEAVES:12)
Block(18,18,4,LEAVES:12)
Block(18,18,12,LEAVES:12)
Block(18,18,13,LEAVES:12)
Block(18,19,12,LEAVES:12)
Block(19,7,2,LEAVES:12)
Block(19,7,15,LEAVES:12)
Block(19,10,9,LEAVES:12)
Block(19,11,13,LEAVES:12)
Block(19,12,10,LEAVES:12)
Block(19,12,12,LEAVES:12)
Block(19,12,13,LEAVES:12)
Block(19,14,7,LEAVES:12)
Block(19,14,8,LEAVES:12)
Block(19,14,11,LEAVES:12)
Block(19,14,12,LEAVES:12)
Block(19,15,10,LEAVES:12)
Block(19,15,12,LEAVES:12)
Block(19,16,7,LEAVES:12)
Block(19,16,9,LEAVES:12)
Block(19,16,10,LEAVES:12)
Block(19,17,4,LEAVES:12)
Block(20,10,13,LEAVES:12)
Block(20,11,9,LEAVES:12)
Block(20,11,10,LEAVES:12)
Block(20,11,13,LEAVES:12)
Block(20,12,10,LEAVES:12)
Block(20,13,10,LEAVES:12)
Block(20,14,6,LEAVES:12)
Block(20,14,7,LEAVES:12)
Block(20,15,12,LEAVES:12)
Block(20,15,13,LEAVES:12)
Block(20,15,14,LEAVES:12)
Block(20,16,8,LEAVES:12)
Block(20,16,9,LEAVES:12)
Block(20,16,13,LEAVES:12)
Block(20,17,11,LEAVES:12)
Block(21,10,8,LEAVES:12)
Block(21,10,9,LEAVES:12)
Block(21,11,9,LEAVES:12)
Block(21,13,9,LEAVES:12)
Block(21,13,10,LEAVES:12)
Block(21,14,10,LEAVES:12)
Block(21,15,13,LEAVES:12)
Block(21,16,8,LEAVES:12)
Block(21,17,8,LEAVES:12)
Block(22,10,8,LEAVES:12)
Block(22,12,11,LEAVES:12)
Block(22,13,10,LEAVES:12)
Block(22,13,11,LEAVES:12)
Block(23,12,11,LEAVES:12)


#######################################################################
# +-----------------------------------------------------------------+ #
# |                             Entities                            | #
# +-----------------------------------------------------------------+ #
#######################################################################

# Entity() spawns an entity instead of a block. The entity is spawned only once when the BO3 is spawned.
# Entities are persistent by default so they don't de-spawn when no player is near, they are only unloaded.
# Usage: Entity(x,y,z,mobName,groupSize,NameTagOrNBTFileName) or Entity(x,y,z,mobName,groupSize)
# Use /tc entities or /otg entities to get a list of entities that can be used as mobName, this includes entities added by other mods.
# NameTagOrNBTFileName can be either a nametag for the mob or an nbt file (such as mymobinfo.nbt or mymobinfo.txt).
# When using a text file you can use the same mob spawning parameters used with the /summon command to equip the
# entity and give it custom attributes etc. You can copy the DATA part of a summon command including surrounding
# curly braces to a .txt file, for instance for: "/summon Skeleton x y z {DATA}"

#######################################################################
# +-----------------------------------------------------------------+ #
# |                            BO3 checks                           | #
# +-----------------------------------------------------------------+ #
#######################################################################

# Require a condition at a certain location in order for the BO3 to be spawned.
# BlockCheck(x,y,z,BlockName[,BlockName[,...]]) - one of the blocks must be at the location
# BlockCheckNot(x,y,z,BlockName[,BlockName[,...]]) - all the blocks must not be at the location
# LightCheck(x,y,z,minLightLevel,maxLightLevel) - light must be between min and max (inclusive)

# You can use "Solid" as a BlockName for matching all solid blocks or "All" to match all blocks that aren't air.

# Examples:
BlockCheck(0,-1,0,GRASS,DIRT,DIRT:2,SAND)
#   BlockCheck(0,-1,0,Solid)       Require any solid block just below the object
#   BlockCheck(0,-1,0,WOOL)        Require any type of wool just below the object
#   BlockCheck(0,-1,0,WOOL:0)      Require white wool just below the object
#   BlockCheckNot(0,-1,0,WOOL:0)   Require that there is no white wool below the object
#   LightCheck(0,0,0,0,1)          Require almost complete darkness just below the object

