#######################################################################
# +-----------------------------------------------------------------+ #
# |                            BO3 object                           | #
# +-----------------------------------------------------------------+ #
#######################################################################

# The descriptions in this file are accurate only for TerrainControl and OTG.
# For MCW and OTG+ these descriptions are only accurate if the BO3 is used as a CustomObject.
# MCW and OTG+ completely reimplemented CustomStructure, check the MCW/OTG+ documentation for more information.

# This is the config file of a custom object.
# If you add this object correctly to your BiomeConfigs, it will spawn in the world.

# This is the creator of this BO3 object
Author: Unknown

# A short description of this BO3 object
Description: This BO3 was converted from a schematic using OTGEdit. The author and description information of the schematic could not be found. If you know who the author of the schematic is then please add this information.

# The BO3 version, don't change this! It can be used by external applications to do a version check.
Version: 3

# The settings mode, WriteAll, WriteWithoutComments or WriteDisable. See WorldConfig.
SettingsMode: WriteDisable

#######################################################################
# +-----------------------------------------------------------------+ #
# |                          Main settings                          | #
# +-----------------------------------------------------------------+ #
#######################################################################

# This needs to be set to true to spawn the object in the Tree and Sapling resources.
Tree: true

# The frequency of the BO3 from 1 to 200. Tries this many times to spawn this BO3 when using the CustomObject(...) resource.
# Ignored by Tree(..), Sapling(..) and CustomStructure(..)
Frequency: 40

# The rarity of the BO3 from 0 to 100. Each spawn attempt has rarity% chance to succeed when using the CustomObject(...) resource.
# Ignored by Tree(..), Sapling(..) and CustomStructure(..)
Rarity: 100.0

# If you set this to true, the BO3 will be placed with a random rotation.
RotateRandomly: true

# The spawn height of the BO3 - randomY, highestBlock or highestSolidBlock.
SpawnHeight: highestSolidBlock

# The height limits for the BO3.
MinHeight: 0

MaxHeight: 256

# Objects can have other objects attached to it: branches. Branches can also
# have branches attached to it, which can also have branches, etc. This is the
# maximum branch depth for this objects.
MaxBranchDepth: 10

# When spawned with the UseWorld keyword, this BO3 should NOT spawn in the following biomes.
# If you writer.write the BO3 name directly in the BiomeConfigs, this will be ignored.
ExcludedBiomes: All

# To optimise this BO3 for faster loading times you can use Notepad++ to find/replace comments and abbreviate things.
# Notepad++ find/replace with regex:
# Find: ^[#;].* replace to nothing removes all lines starting with # 
# Find: ^\s*$ replace to nothing removes most empty lines 
# Notepad++ find/replace without regex:
# *Warning: This will only work for OTG 1.10.2 v21 / OTG 1.11.2 v6 or higher. B( is not recognised by lower versions.
# Find: Block( replace to B(

#######################################################################
# +-----------------------------------------------------------------+ #
# |                      Source block settings                      | #
# +-----------------------------------------------------------------+ #
#######################################################################

# The block(s) the BO3 should spawn in.
SourceBlocks: AIR

# The maximum percentage of the BO3 that can be outside the SourceBlock.
# The BO3 won't be placed on a location with more blocks outside the SourceBlock than this percentage.
MaxPercentageOutsideSourceBlock: 0

# What to do when a block is about to be placed outside the SourceBlock? (dontPlace, placeAnyway)
OutsideSourceBlock: dontPlace

#######################################################################
# +-----------------------------------------------------------------+ #
# |                              Blocks                             | #
# +-----------------------------------------------------------------+ #
#######################################################################

# All the blocks used in the BO3 are listed here. Possible blocks:
# Block(x,y,z,id[.data][,nbtfile.nbt) or B(x,y,z,id[.data][,nbtfile.nbt)
# RandomBlock(x,y,z,id[:data][,nbtfile.nbt],chance[,id[:data][,nbtfile.nbt],chance[,...]])
# So RandomBlock(0,0,0,CHEST,chest.nbt,50,CHEST,anotherchest.nbt,100) will spawn a chest at
# the BO3 origin, and give it a 50% chance to have the contents of chest.nbt, or, if that
# fails, a 100% percent chance to have the contents of anotherchest.nbt.

Block(-7,10,-1,LEAVES:12)
Block(-7,11,-2,LEAVES:12)
Block(-7,11,-1,LEAVES:12)
Block(-7,12,-6,LEAVES:12)
Block(-7,15,6,LEAVES:12)
Block(-7,16,5,LEAVES:12)
Block(-7,16,6,LEAVES:12)
Block(-7,17,1,LEAVES:12)
Block(-6,8,-4,LEAVES:12)
Block(-6,11,-2,LEAVES:12)
Block(-6,12,-6,LEAVES:12)
Block(-6,12,-5,LEAVES:12)
Block(-6,13,3,LEAVES:12)
Block(-6,15,-4,LEAVES:12)
Block(-6,15,-2,LEAVES:12)
Block(-6,16,-4,LEAVES:12)
Block(-6,16,5,LEAVES:12)
Block(-6,17,1,LEAVES:12)
Block(-6,17,2,LEAVES:12)
Block(-6,20,3,LEAVES:12)
Block(-6,20,5,LEAVES:12)
Block(-6,21,3,LEAVES:12)
Block(-5,7,-3,LEAVES:12)
Block(-5,8,-3,LEAVES:12)
Block(-5,9,-1,LEAVES:12)
Block(-5,10,-7,LEAVES:12)
Block(-5,11,-5,LEAVES:12)
Block(-5,11,-4,LEAVES:12)
Block(-5,11,-2,LEAVES:12)
Block(-5,12,-5,LEAVES:12)
Block(-5,12,-3,LEAVES:12)
Block(-5,12,-2,LEAVES:12)
Block(-5,12,4,LEAVES:12)
Block(-5,13,4,LEAVES:12)
Block(-5,14,-1,LEAVES:12)
Block(-5,14,1,LEAVES:12)
Block(-5,14,2,LEAVES:12)
Block(-5,14,6,LEAVES:12)
Block(-5,15,-4,LEAVES:12)
Block(-5,15,-3,LEAVES:12)
Block(-5,15,0,LEAVES:12)
Block(-5,16,2,LEAVES:12)
Block(-5,16,3,LEAVES:12)
Block(-5,16,5,LEAVES:12)
Block(-5,17,2,LEAVES:12)
Block(-5,17,4,LEAVES:12)
Block(-5,17,5,LEAVES:12)
Block(-5,18,10,LEAVES:12)
Block(-5,19,6,LEAVES:12)
Block(-5,19,8,LEAVES:12)
Block(-5,19,9,LEAVES:12)
Block(-5,19,10,LEAVES:12)
Block(-5,20,3,LEAVES:12)
Block(-5,20,4,LEAVES:12)
Block(-5,20,5,LEAVES:12)
Block(-4,7,-1,LEAVES:12)
Block(-4,8,-7,LEAVES:12)
Block(-4,8,-3,LEAVES:12)
Block(-4,8,-2,LEAVES:12)
Block(-4,9,-7,LEAVES:12)
Block(-4,9,-6,LEAVES:12)
Block(-4,9,-2,LEAVES:12)
Block(-4,9,1,LEAVES:12)
Block(-4,10,-2,LEAVES:12)
Block(-4,10,16,LEAVES:12)
Block(-4,11,-4,LEAVES:12)
Block(-4,11,15,LEAVES:12)
Block(-4,11,16,LEAVES:12)
Block(-4,12,-3,LEAVES:12)
Block(-4,12,6,LEAVES:12)
Block(-4,12,11,LEAVES:12)
Block(-4,13,0,LEAVES:12)
Block(-4,13,1,LEAVES:12)
Block(-4,13,4,LEAVES:12)
Block(-4,13,5,LEAVES:12)
Block(-4,14,-7,LEAVES:12)
Block(-4,14,-6,LEAVES:12)
Block(-4,14,-3,LEAVES:12)
Block(-4,14,0,LEAVES:12)
Block(-4,14,1,LEAVES:12)
Block(-4,14,5,LEAVES:12)
Block(-4,14,8,LEAVES:12)
Block(-4,15,-3,LEAVES:12)
Block(-4,15,1,LEAVES:12)
Block(-4,15,5,LEAVES:12)
Block(-4,16,-3,LEAVES:12)
Block(-4,16,3,LEAVES:12)
Block(-4,16,7,LEAVES:12)
Block(-4,17,4,LEAVES:12)
Block(-4,18,7,LEAVES:12)
Block(-4,18,8,LEAVES:12)
Block(-4,19,0,LEAVES:12)
Block(-4,19,1,LEAVES:12)
Block(-4,19,4,LEAVES:12)
Block(-4,19,8,LEAVES:12)
Block(-4,19,9,LEAVES:12)
Block(-4,20,4,LEAVES:12)
Block(-4,20,5,LEAVES:12)
Block(-4,20,6,LEAVES:12)
Block(-4,20,8,LEAVES:12)
Block(-4,21,4,LEAVES:12)
Block(-4,23,7,LEAVES:12)
Block(-4,23,9,LEAVES:12)
Block(-4,24,7,LEAVES:12)
Block(-3,8,13,LEAVES:12)
Block(-3,9,-6,LEAVES:12)
Block(-3,9,0,LEAVES:12)
Block(-3,9,1,LEAVES:12)
Block(-3,10,-6,LEAVES:12)
Block(-3,10,-2,LEAVES:12)
Block(-3,10,-1,LEAVES:12)
Block(-3,10,0,LEAVES:12)
Block(-3,11,-4,LEAVES:12)
Block(-3,11,-2,LEAVES:12)
Block(-3,11,15,LEAVES:12)
Block(-3,12,-3,LOG:12)
Block(-3,12,11,LEAVES:12)
Block(-3,12,12,LEAVES:12)
Block(-3,13,-5,LEAVES:12)
Block(-3,13,-4,LEAVES:12)
Block(-3,13,-3,LEAVES:12)
Block(-3,13,-1,LEAVES:12)
Block(-3,13,0,LEAVES:12)
Block(-3,14,-6,LEAVES:12)
Block(-3,14,-5,LEAVES:12)
Block(-3,14,-3,LEAVES:12)
Block(-3,14,1,LEAVES:12)
Block(-3,14,2,LEAVES:12)
Block(-3,14,7,LEAVES:12)
Block(-3,14,8,LEAVES:12)
Block(-3,15,-5,LEAVES:12)
Block(-3,15,1,LEAVES:12)
Block(-3,15,5,LEAVES:12)
Block(-3,15,6,LEAVES:12)
Block(-3,15,7,LEAVES:12)
Block(-3,15,8,LEAVES:12)
Block(-3,15,13,LEAVES:12)
Block(-3,15,15,LEAVES:12)
Block(-3,16,3,LEAVES:12)
Block(-3,16,5,LEAVES:12)
Block(-3,16,8,LEAVES:12)
Block(-3,16,13,LEAVES:12)
Block(-3,17,4,LEAVES:12)
Block(-3,17,10,LEAVES:12)
Block(-3,18,2,LEAVES:12)
Block(-3,18,3,LEAVES:12)
Block(-3,18,4,LEAVES:12)
Block(-3,18,6,LEAVES:12)
Block(-3,18,7,LEAVES:12)
Block(-3,19,1,LEAVES:12)
Block(-3,19,2,LEAVES:12)
Block(-3,19,4,LEAVES:12)
Block(-3,19,6,LEAVES:12)
Block(-3,19,7,LEAVES:12)
Block(-3,19,9,LEAVES:12)
Block(-3,20,2,LEAVES:12)
Block(-3,20,6,LEAVES:12)
Block(-3,20,8,LEAVES:12)
Block(-3,20,9,LEAVES:12)
Block(-3,22,10,LEAVES:12)
Block(-3,22,12,LEAVES:12)
Block(-3,22,13,LEAVES:12)
Block(-3,23,7,LEAVES:12)
Block(-3,23,8,LEAVES:12)
Block(-2,7,14,LEAVES:12)
Block(-2,8,-4,LEAVES:12)
Block(-2,8,14,LEAVES:12)
Block(-2,9,-5,LEAVES:12)
Block(-2,9,1,LEAVES:12)
Block(-2,9,2,LEAVES:12)
Block(-2,9,16,LEAVES:12)
Block(-2,10,-6,LEAVES:12)
Block(-2,10,-5,LEAVES:12)
Block(-2,10,10,LEAVES:12)
Block(-2,11,-5,LEAVES:12)
Block(-2,11,-4,LEAVES:12)
Block(-2,11,-3,LEAVES:12)
Block(-2,11,-2,LEAVES:12)
Block(-2,11,12,LEAVES:12)
Block(-2,11,13,LEAVES:12)
Block(-2,11,15,LEAVES:12)
Block(-2,12,-3,LOG:12)
Block(-2,12,-2,LEAVES:12)
Block(-2,12,-1,LEAVES:12)
Block(-2,12,12,LEAVES:12)
Block(-2,12,14,LEAVES:12)
Block(-2,12,15,LEAVES:12)
Block(-2,13,-3,LEAVES:12)
Block(-2,13,-1,LEAVES:12)
Block(-2,13,3,LEAVES:12)
Block(-2,14,-3,LEAVES:12)
Block(-2,14,-2,LEAVES:12)
Block(-2,14,2,LEAVES:12)
Block(-2,14,8,LEAVES:12)
Block(-2,14,9,LEAVES:12)
Block(-2,14,16,LEAVES:12)
Block(-2,14,18,LEAVES:12)
Block(-2,14,19,LEAVES:12)
Block(-2,15,-2,LEAVES:12)
Block(-2,15,1,LEAVES:12)
Block(-2,15,2,LEAVES:12)
Block(-2,15,10,LEAVES:12)
Block(-2,15,13,LEAVES:12)
Block(-2,15,14,LEAVES:12)
Block(-2,16,-3,LEAVES:12)
Block(-2,16,2,LEAVES:12)
Block(-2,16,3,LEAVES:12)
Block(-2,16,4,LEAVES:12)
Block(-2,16,5,LEAVES:12)
Block(-2,16,8,LEAVES:12)
Block(-2,16,9,LEAVES:12)
Block(-2,17,3,LOG:12)
Block(-2,17,4,LOG:12)
Block(-2,17,5,LEAVES:12)
Block(-2,17,6,LEAVES:12)
Block(-2,17,9,LEAVES:12)
Block(-2,17,12,LEAVES:12)
Block(-2,18,4,LEAVES:12)
Block(-2,18,6,LEAVES:12)
Block(-2,18,9,LEAVES:12)
Block(-2,19,4,LEAVES:12)
Block(-2,19,5,LEAVES:12)
Block(-2,19,7,LEAVES:12)
Block(-2,20,5,LEAVES:12)
Block(-2,20,8,LEAVES:12)
Block(-2,21,4,LEAVES:12)
Block(-2,21,11,LEAVES:12)
Block(-2,21,12,LEAVES:12)
Block(-2,22,4,LEAVES:12)
Block(-2,22,5,LEAVES:12)
Block(-2,22,8,LEAVES:12)
Block(-2,22,12,LEAVES:12)
Block(-2,23,8,LEAVES:12)
Block(-2,23,12,LEAVES:12)
Block(-2,24,8,LEAVES:12)
Block(-1,7,16,LEAVES:12)
Block(-1,8,-1,LEAVES:12)
Block(-1,8,10,LEAVES:12)
Block(-1,8,14,LEAVES:12)
Block(-1,8,15,LEAVES:12)
Block(-1,9,-3,LEAVES:12)
Block(-1,9,-1,LEAVES:12)
Block(-1,9,10,LEAVES:12)
Block(-1,9,11,LEAVES:12)
Block(-1,9,15,LEAVES:12)
Block(-1,9,18,LEAVES:12)
Block(-1,10,-3,LEAVES:12)
Block(-1,10,-1,LEAVES:12)
Block(-1,10,1,LEAVES:12)
Block(-1,10,15,LEAVES:12)
Block(-1,11,-5,LEAVES:12)
Block(-1,11,-3,LEAVES:12)
Block(-1,11,-2,LEAVES:12)
Block(-1,11,-1,LEAVES:12)
Block(-1,11,1,LEAVES:12)
Block(-1,11,13,LEAVES:12)
Block(-1,12,-7,LEAVES:12)
Block(-1,12,-5,LEAVES:12)
Block(-1,12,-3,LOG:12)
Block(-1,12,-2,LEAVES:12)
Block(-1,12,2,LEAVES:12)
Block(-1,12,14,LEAVES:12)
Block(-1,13,-3,LOG:12)
Block(-1,13,6,LEAVES:12)
Block(-1,13,17,LEAVES:12)
Block(-1,13,18,LEAVES:12)
Block(-1,14,4,LEAVES:12)
Block(-1,14,6,LEAVES:12)
Block(-1,14,10,LEAVES:12)
Block(-1,14,11,LEAVES:12)
Block(-1,14,14,LEAVES:12)
Block(-1,14,18,LEAVES:12)
Block(-1,15,-2,LEAVES:12)
Block(-1,15,-1,LEAVES:12)
Block(-1,15,4,LEAVES:12)
Block(-1,15,6,LEAVES:12)
Block(-1,15,8,LEAVES:12)
Block(-1,15,14,LEAVES:12)
Block(-1,15,18,LEAVES:12)
Block(-1,16,-1,LEAVES:12)
Block(-1,16,0,LEAVES:12)
Block(-1,16,2,LEAVES:12)
Block(-1,16,4,LEAVES:12)
Block(-1,16,5,LEAVES:12)
Block(-1,16,6,LEAVES:12)
Block(-1,16,8,LEAVES:12)
Block(-1,16,14,LEAVES:12)
Block(-1,17,-1,LEAVES:12)
Block(-1,17,0,LEAVES:12)
Block(-1,17,2,LEAVES:12)
Block(-1,17,4,LOG:12)
Block(-1,17,5,LEAVES:12)
Block(-1,17,9,LEAVES:12)
Block(-1,17,11,LEAVES:12)
Block(-1,17,12,LEAVES:12)
Block(-1,18,4,LOG:12)
Block(-1,18,5,LEAVES:12)
Block(-1,18,9,LEAVES:12)
Block(-1,18,10,LEAVES:12)
Block(-1,18,11,LEAVES:12)
Block(-1,19,7,LEAVES:12)
Block(-1,19,9,LEAVES:12)
Block(-1,20,5,LEAVES:12)
Block(-1,20,6,LEAVES:12)
Block(-1,20,8,LEAVES:12)
Block(-1,21,6,LEAVES:12)
Block(-1,21,7,LEAVES:12)
Block(-1,21,8,LEAVES:12)
Block(-1,21,10,LEAVES:12)
Block(-1,21,11,LEAVES:12)
Block(-1,22,5,LEAVES:12)
Block(-1,22,6,LEAVES:12)
Block(-1,22,8,LEAVES:12)
Block(-1,22,13,LEAVES:12)
Block(-1,23,6,LEAVES:12)
Block(0,8,-4,LEAVES:12)
Block(0,9,0,LEAVES:12)
Block(0,9,11,LEAVES:12)
Block(0,9,17,LEAVES:12)
Block(0,9,18,LEAVES:12)
Block(0,10,-3,LEAVES:12)
Block(0,10,-1,LEAVES:12)
Block(0,10,0,LEAVES:12)
Block(0,10,11,LEAVES:12)
Block(0,10,15,LEAVES:12)
Block(0,10,16,LEAVES:12)
Block(0,10,17,LEAVES:12)
Block(0,11,13,LEAVES:12)
Block(0,11,15,LEAVES:12)
Block(0,12,-6,LEAVES:12)
Block(0,12,-5,LEAVES:12)
Block(0,12,-2,LEAVES:12)
Block(0,12,-1,LEAVES:12)
Block(0,12,14,LEAVES:12)
Block(0,13,-3,LOG:12)
Block(0,13,-2,LOG:12)
Block(0,13,-1,LEAVES:12)
Block(0,13,3,LEAVES:12)
Block(0,13,12,LEAVES:12)
Block(0,13,13,LEAVES:12)
Block(0,13,14,LEAVES:12)
Block(0,13,16,LEAVES:12)
Block(0,13,17,LEAVES:12)
Block(0,14,-6,LEAVES:12)
Block(0,14,-4,LEAVES:12)
Block(0,14,-3,LEAVES:12)
Block(0,14,7,LEAVES:12)
Block(0,14,11,LEAVES:12)
Block(0,14,12,LEAVES:12)
Block(0,14,14,LEAVES:12)
Block(0,14,19,LEAVES:12)
Block(0,15,4,LEAVES:12)
Block(0,15,6,LEAVES:12)
Block(0,15,7,LEAVES:12)
Block(0,15,12,LEAVES:12)
Block(0,16,7,LEAVES:12)
Block(0,17,1,LEAVES:12)
Block(0,17,2,LEAVES:12)
Block(0,17,5,LEAVES:12)
Block(0,17,6,LEAVES:12)
Block(0,17,12,LEAVES:12)
Block(0,17,13,LEAVES:12)
Block(0,18,4,LOG:12)
Block(0,18,5,LEAVES:12)
Block(0,18,6,LEAVES:12)
Block(0,19,1,LEAVES:12)
Block(0,19,3,LEAVES:12)
Block(0,19,4,LEAVES:12)
Block(0,19,6,LEAVES:12)
Block(0,19,7,LEAVES:12)
Block(0,19,8,LEAVES:12)
Block(0,19,9,LEAVES:12)
Block(0,20,7,LOG:12)
Block(0,20,8,LOG:12)
Block(0,20,9,LEAVES:12)
Block(0,20,10,LEAVES:12)
Block(0,21,8,LEAVES:12)
Block(0,21,10,LEAVES:12)
Block(0,22,8,LEAVES:12)
Block(0,22,9,LEAVES:12)
Block(0,23,9,LEAVES:12)
Block(0,24,8,LEAVES:12)
Block(1,8,0,LEAVES:12)
Block(1,8,13,LEAVES:12)
Block(1,9,-4,LEAVES:12)
Block(1,9,-3,LEAVES:12)
Block(1,9,0,LEAVES:12)
Block(1,9,12,LEAVES:12)
Block(1,9,18,LEAVES:12)
Block(1,9,19,LEAVES:12)
Block(1,10,-3,LEAVES:12)
Block(1,10,11,LEAVES:12)
Block(1,10,12,LEAVES:12)
Block(1,11,-3,LEAVES:12)
Block(1,11,12,LEAVES:12)
Block(1,11,13,LEAVES:12)
Block(1,11,14,LEAVES:12)
Block(1,11,15,LEAVES:12)
Block(1,12,-7,LEAVES:12)
Block(1,12,-6,LEAVES:12)
Block(1,12,13,LOG:12)
Block(1,12,14,LOG:12)
Block(1,12,15,LOG:12)
Block(1,12,16,LEAVES:12)
Block(1,13,-2,LOG:12)
Block(1,13,-1,LEAVES:12)
Block(1,13,0,LEAVES:12)
Block(1,13,1,LEAVES:12)
Block(1,13,7,LEAVES:12)
Block(1,13,11,LOG:12)
Block(1,13,12,LOG:12)
Block(1,13,13,LOG:12)
Block(1,13,14,LEAVES:12)
Block(1,13,16,LEAVES:12)
Block(1,14,-5,LEAVES:12)
Block(1,14,-4,LEAVES:12)
Block(1,14,-2,LOG:12)
Block(1,14,0,LEAVES:12)
Block(1,14,3,LEAVES:12)
Block(1,14,4,LEAVES:12)
Block(1,14,7,LEAVES:12)
Block(1,14,11,LOG:12)
Block(1,14,14,LEAVES:12)
Block(1,14,15,LEAVES:12)
Block(1,15,-3,LEAVES:12)
Block(1,15,-2,LEAVES:12)
Block(1,15,4,LEAVES:12)
Block(1,15,15,LEAVES:12)
Block(1,16,-4,LEAVES:12)
Block(1,16,-3,LEAVES:12)
Block(1,16,4,LEAVES:12)
Block(1,16,10,LEAVES:12)
Block(1,16,14,LEAVES:12)
Block(1,17,-8,LEAVES:12)
Block(1,17,0,LEAVES:12)
Block(1,17,1,LEAVES:12)
Block(1,17,3,LOG:12)
Block(1,17,4,LOG:12)
Block(1,17,8,LEAVES:12)
Block(1,17,10,LEAVES:12)
Block(1,18,4,LOG:12)
Block(1,18,6,LEAVES:12)
Block(1,18,7,LEAVES:12)
Block(1,18,8,LEAVES:12)
Block(1,18,10,LEAVES:12)
Block(1,18,12,LEAVES:12)
Block(1,19,2,LEAVES:12)
Block(1,19,3,LEAVES:12)
Block(1,19,6,LEAVES:12)
Block(1,19,7,LEAVES:12)
Block(1,19,8,LOG:12)
Block(1,19,9,LOG:12)
Block(1,19,10,LEAVES:12)
Block(1,19,12,LEAVES:12)
Block(1,20,4,LEAVES:12)
Block(1,20,5,LEAVES:12)
Block(1,20,6,LEAVES:12)
Block(1,20,8,LOG:12)
Block(1,20,9,LEAVES:12)
Block(1,20,13,LEAVES:12)
Block(1,21,8,LEAVES:12)
Block(1,23,9,LEAVES:12)
Block(1,23,10,LEAVES:12)
Block(1,24,10,LEAVES:12)
Block(1,24,11,LEAVES:12)
Block(1,25,10,LEAVES:12)
Block(2,8,-5,LEAVES:12)
Block(2,8,-4,LEAVES:12)
Block(2,8,16,LEAVES:12)
Block(2,9,-4,LEAVES:12)
Block(2,9,14,LEAVES:12)
Block(2,9,16,LEAVES:12)
Block(2,10,14,LEAVES:12)
Block(2,10,16,LEAVES:12)
Block(2,10,18,LEAVES:12)
Block(2,11,-4,LEAVES:12)
Block(2,11,-3,LEAVES:12)
Block(2,11,12,LEAVES:12)
Block(2,11,14,LEAVES:12)
Block(2,11,15,LEAVES:12)
Block(2,11,16,LEAVES:12)
Block(2,11,18,LEAVES:12)
Block(2,12,-3,LEAVES:12)
Block(2,12,10,LEAVES:12)
Block(2,12,12,LEAVES:12)
Block(2,12,14,LEAVES:12)
Block(2,12,15,LEAVES:12)
Block(2,12,19,LEAVES:12)
Block(2,13,-6,LEAVES:12)
Block(2,13,0,LEAVES:12)
Block(2,13,2,LEAVES:12)
Block(2,13,3,LEAVES:12)
Block(2,13,14,LEAVES:12)
Block(2,14,-5,LEAVES:12)
Block(2,14,-2,LOG:12)
Block(2,14,3,LEAVES:12)
Block(2,14,10,LOG:12)
Block(2,14,11,LOG:12)
Block(2,15,-5,LEAVES:12)
Block(2,15,-2,LOG:12)
Block(2,15,-1,LOG:12)
Block(2,15,10,LOG:12)
Block(2,15,15,LEAVES:12)
Block(2,15,16,LEAVES:12)
Block(2,16,-4,LEAVES:12)
Block(2,16,3,LEAVES:12)
Block(2,16,4,LEAVES:12)
Block(2,16,7,LEAVES:12)
Block(2,16,16,LEAVES:12)
Block(2,16,17,LEAVES:12)
Block(2,17,-8,LEAVES:12)
Block(2,17,-7,LEAVES:12)
Block(2,17,3,LOG:12)
Block(2,17,4,LEAVES:12)
Block(2,17,11,LEAVES:12)
Block(2,17,16,LEAVES:12)
Block(2,18,7,LEAVES:12)
Block(2,18,8,LEAVES:12)
Block(2,18,9,LOG:12)
Block(2,18,10,LEAVES:12)
Block(2,18,11,LEAVES:12)
Block(2,19,2,LEAVES:12)
Block(2,19,9,LOG:12)
Block(2,20,-6,LEAVES:12)
Block(2,20,-4,LEAVES:12)
Block(2,20,2,LEAVES:12)
Block(2,20,5,LEAVES:12)
Block(2,20,6,LEAVES:12)
Block(2,20,9,LEAVES:12)
Block(2,20,10,LEAVES:12)
Block(2,21,-6,LEAVES:12)
Block(2,21,8,LEAVES:12)
Block(2,21,10,LEAVES:12)
Block(2,22,5,LEAVES:12)
Block(2,22,7,LEAVES:12)
Block(2,22,8,LEAVES:12)
Block(3,0,4,LOG:12)
Block(3,1,4,LOG:12)
Block(3,5,5,LOG:12)
Block(3,6,5,LOG:12)
Block(3,7,5,LOG:12)
Block(3,8,-5,LEAVES:12)
Block(3,8,4,LOG:12)
Block(3,8,13,LEAVES:12)
Block(3,9,4,LOG:12)
Block(3,9,17,LEAVES:12)
Block(3,10,-2,LEAVES:12)
Block(3,10,4,LOG:12)
Block(3,10,14,LEAVES:12)
Block(3,10,16,LEAVES:12)
Block(3,10,17,LEAVES:12)
Block(3,11,-3,LEAVES:12)
Block(3,11,-2,LEAVES:12)
Block(3,12,-5,LEAVES:12)
Block(3,12,11,LEAVES:12)
Block(3,12,12,LEAVES:12)
Block(3,12,15,LEAVES:12)
Block(3,12,16,LEAVES:12)
Block(3,13,-5,LEAVES:12)
Block(3,13,2,LEAVES:12)
Block(3,13,14,LEAVES:12)
Block(3,13,16,LEAVES:12)
Block(3,14,-3,LEAVES:12)
Block(3,14,11,LEAVES:12)
Block(3,14,13,LEAVES:12)
Block(3,14,14,LEAVES:12)
Block(3,15,-9,LEAVES:12)
Block(3,15,-1,LOG:12)
Block(3,15,0,LOG:12)
Block(3,15,5,LEAVES:12)
Block(3,15,10,LOG:12)
Block(3,16,-7,LEAVES:12)
Block(3,16,-6,LEAVES:12)
Block(3,16,-4,LEAVES:12)
Block(3,16,0,LOG:12)
Block(3,16,1,LOG:12)
Block(3,16,3,LOG:12)
Block(3,16,4,LEAVES:12)
Block(3,16,5,LEAVES:12)
Block(3,16,11,LEAVES:12)
Block(3,17,-7,LEAVES:12)
Block(3,17,-5,LEAVES:12)
Block(3,17,-4,LEAVES:12)
Block(3,17,3,LOG:12)
Block(3,17,7,LEAVES:12)
Block(3,17,8,LEAVES:12)
Block(3,17,9,LOG:12)
Block(3,17,11,LEAVES:12)
Block(3,18,8,LEAVES:12)
Block(3,18,9,LOG:12)
Block(3,18,14,LEAVES:12)
Block(3,19,-3,LEAVES:12)
Block(3,19,-1,LEAVES:12)
Block(3,19,0,LEAVES:12)
Block(3,19,8,LEAVES:12)
Block(3,19,13,LEAVES:12)
Block(3,19,14,LEAVES:12)
Block(3,20,-6,LEAVES:12)
Block(3,20,-5,LEAVES:12)
Block(3,20,4,LEAVES:12)
Block(3,20,5,LEAVES:12)
Block(3,20,9,LEAVES:12)
Block(3,21,10,LEAVES:12)
Block(3,21,11,LEAVES:12)
Block(3,21,12,LEAVES:12)
Block(3,22,6,LEAVES:12)
Block(3,22,7,LEAVES:12)
Block(3,22,11,LEAVES:12)
Block(3,23,9,LEAVES:12)
Block(4,0,3,LOG:12)
Block(4,0,4,LOG:12)
Block(4,0,5,LOG:12)
Block(4,1,3,LOG:12)
Block(4,1,4,LOG:12)
Block(4,2,4,LOG:12)
Block(4,3,4,LOG:12)
Block(4,3,5,LOG:12)
Block(4,4,4,LOG:12)
Block(4,4,5,LOG:12)
Block(4,5,4,LOG:12)
Block(4,5,5,LOG:12)
Block(4,5,6,LOG:12)
Block(4,6,4,LOG:12)
Block(4,6,5,LOG:12)
Block(4,7,4,LOG:12)
Block(4,7,5,LOG:12)
Block(4,8,4,LOG:12)
Block(4,8,5,LOG:12)
Block(4,8,17,LEAVES:12)
Block(4,9,4,LOG:12)
Block(4,9,5,LOG:12)
Block(4,9,13,LEAVES:12)
Block(4,9,14,LEAVES:12)
Block(4,9,17,LEAVES:12)
Block(4,10,-2,LEAVES:12)
Block(4,10,4,LOG:12)
Block(4,10,5,LOG:12)
Block(4,10,14,LEAVES:12)
Block(4,11,4,LOG:12)
Block(4,11,14,LEAVES:12)
Block(4,12,-3,LEAVES:12)
Block(4,12,10,LEAVES:12)
Block(4,12,11,LEAVES:12)
Block(4,13,-9,LEAVES:12)
Block(4,13,-5,LEAVES:12)
Block(4,13,-4,LEAVES:12)
Block(4,13,16,LEAVES:12)
Block(4,13,17,LEAVES:12)
Block(4,13,18,LEAVES:12)
Block(4,14,-9,LEAVES:12)
Block(4,14,-8,LEAVES:12)
Block(4,14,-4,LEAVES:12)
Block(4,14,-1,LEAVES:12)
Block(4,14,3,LOG:12)
Block(4,14,12,LEAVES:12)
Block(4,14,13,LEAVES:12)
Block(4,14,17,LEAVES:12)
Block(4,15,-4,LEAVES:12)
Block(4,15,-2,LOG:12)
Block(4,15,-1,LOG:12)
Block(4,15,2,LOG:12)
Block(4,15,3,LOG:12)
Block(4,15,5,LEAVES:12)
Block(4,15,10,LOG:12)
Block(4,15,15,LEAVES:12)
Block(4,16,-6,LEAVES:12)
Block(4,16,1,LOG:12)
Block(4,16,2,LOG:12)
Block(4,16,3,LOG:12)
Block(4,16,6,LEAVES:12)
Block(4,16,7,LEAVES:12)
Block(4,16,9,LOG:12)
Block(4,16,10,LOG:12)
Block(4,16,11,LEAVES:12)
Block(4,17,-5,LEAVES:12)
Block(4,17,7,LEAVES:12)
Block(4,17,9,LOG:12)
Block(4,18,-2,LEAVES:12)
Block(4,18,-1,LEAVES:12)
Block(4,19,-9,LEAVES:12)
Block(4,19,-8,LEAVES:12)
Block(4,19,-5,LEAVES:12)
Block(4,19,-1,LEAVES:12)
Block(4,19,7,LEAVES:12)
Block(4,19,8,LEAVES:12)
Block(4,19,13,LEAVES:12)
Block(4,20,-5,LEAVES:12)
Block(4,20,-1,LEAVES:12)
Block(4,20,8,LEAVES:12)
Block(4,20,9,LEAVES:12)
Block(4,20,10,LEAVES:12)
Block(4,21,-5,LEAVES:12)
Block(4,21,11,LEAVES:12)
Block(4,22,6,LOG:12)
Block(4,23,6,LEAVES:12)
Block(4,23,11,LEAVES:12)
Block(4,23,13,LEAVES:12)
Block(4,24,11,LEAVES:12)
Block(5,0,3,LOG:12)
Block(5,0,4,LOG:12)
Block(5,0,5,LOG:12)
Block(5,1,3,LOG:12)
Block(5,1,4,LOG:12)
Block(5,1,5,LOG:12)
Block(5,2,3,LOG:12)
Block(5,2,4,LOG:12)
Block(5,2,5,LOG:12)
Block(5,3,3,LOG:12)
Block(5,3,4,LOG:12)
Block(5,3,5,LOG:12)
Block(5,4,3,LOG:12)
Block(5,4,4,LOG:12)
Block(5,5,4,LOG:12)
Block(5,8,4,LOG:12)
Block(5,8,5,LOG:12)
Block(5,8,12,LEAVES:12)
Block(5,8,13,LEAVES:12)
Block(5,9,4,LOG:12)
Block(5,9,13,LEAVES:12)
Block(5,10,3,LOG:12)
Block(5,10,4,LOG:12)
Block(5,11,3,LOG:12)
Block(5,11,4,LOG:12)
Block(5,11,13,LEAVES:12)
Block(5,11,14,LEAVES:12)
Block(5,12,3,LOG:12)
Block(5,12,4,LOG:12)
Block(5,12,14,LEAVES:12)
Block(5,13,4,LOG:12)
Block(5,13,5,LOG:12)
Block(5,13,17,LEAVES:12)
Block(5,14,-8,LEAVES:12)
Block(5,14,-2,LEAVES:12)
Block(5,14,-1,LEAVES:12)
Block(5,14,4,LOG:12)
Block(5,14,12,LEAVES:12)
Block(5,15,-8,LEAVES:12)
Block(5,15,-4,LEAVES:12)
Block(5,15,-3,LEAVES:12)
Block(5,15,-2,LOG:12)
Block(5,15,3,LOG:12)
Block(5,15,4,LOG:12)
Block(5,15,12,LEAVES:12)
Block(5,16,-6,LEAVES:12)
Block(5,16,-4,LEAVES:12)
Block(5,16,-3,LOG:12)
Block(5,16,-2,LOG:12)
Block(5,16,6,LEAVES:12)
Block(5,16,9,LOG:12)
Block(5,16,12,LEAVES:12)
Block(5,17,-5,LEAVES:12)
Block(5,17,14,LEAVES:12)
Block(5,18,-7,LEAVES:12)
Block(5,18,-6,LEAVES:12)
Block(5,18,-5,LEAVES:12)
Block(5,18,-3,LEAVES:12)
Block(5,18,-2,LEAVES:12)
Block(5,18,3,LEAVES:12)
Block(5,18,8,LEAVES:12)
Block(5,18,9,LEAVES:12)
Block(5,19,-8,LEAVES:12)
Block(5,19,-7,LEAVES:12)
Block(5,19,-5,LEAVES:12)
Block(5,19,0,LEAVES:12)
Block(5,19,2,LEAVES:12)
Block(5,19,3,LEAVES:12)
Block(5,19,8,LEAVES:12)
Block(5,19,9,LEAVES:12)
Block(5,19,10,LEAVES:12)
Block(5,19,11,LEAVES:12)
Block(5,19,13,LEAVES:12)
Block(5,20,-7,LEAVES:12)
Block(5,20,-2,LEAVES:12)
Block(5,20,10,LEAVES:12)
Block(5,20,12,LEAVES:12)
Block(5,20,13,LEAVES:12)
Block(5,22,6,LOG:12)
Block(5,22,14,LEAVES:12)
Block(5,22,16,LEAVES:12)
Block(5,22,17,LEAVES:12)
Block(5,23,11,LEAVES:12)
Block(5,23,12,LEAVES:12)
Block(6,0,3,LOG:12)
Block(6,0,4,LOG:12)
Block(6,1,4,LOG:12)
Block(6,2,5,LOG:12)
Block(6,3,5,LOG:12)
Block(6,8,12,LEAVES:12)
Block(6,9,16,LEAVES:12)
Block(6,10,15,LEAVES:12)
Block(6,10,16,LEAVES:12)
Block(6,11,4,LOG:12)
Block(6,11,11,LEAVES:12)
Block(6,11,14,LEAVES:12)
Block(6,11,15,LEAVES:12)
Block(6,12,4,LOG:12)
Block(6,13,-6,LEAVES:12)
Block(6,13,4,LOG:12)
Block(6,13,5,LOG:12)
Block(6,14,-7,LEAVES:12)
Block(6,14,-1,LEAVES:12)
Block(6,14,0,LEAVES:12)
Block(6,14,6,LOG:12)
Block(6,15,-8,LEAVES:12)
Block(6,15,-7,LEAVES:12)
Block(6,15,14,LEAVES:12)
Block(6,16,-7,LEAVES:12)
Block(6,16,-6,LEAVES:12)
Block(6,16,-5,LEAVES:12)
Block(6,16,-4,LOG:12)
Block(6,16,-3,LOG:12)
Block(6,16,0,LEAVES:12)
Block(6,16,8,LOG:12)
Block(6,16,9,LOG:12)
Block(6,16,12,LEAVES:12)
Block(6,16,13,LEAVES:12)
Block(6,17,-6,LOG:12)
Block(6,17,-5,LOG:12)
Block(6,17,-4,LOG:12)
Block(6,17,-3,LEAVES:12)
Block(6,17,8,LEAVES:12)
Block(6,17,9,LEAVES:12)
Block(6,17,13,LEAVES:12)
Block(6,17,16,LEAVES:12)
Block(6,18,-5,LEAVES:12)
Block(6,18,-3,LEAVES:12)
Block(6,18,9,LEAVES:12)
Block(6,18,13,LEAVES:12)
Block(6,19,-5,LEAVES:12)
Block(6,19,-4,LEAVES:12)
Block(6,19,2,LEAVES:12)
Block(6,19,11,LEAVES:12)
Block(6,20,-4,LEAVES:12)
Block(6,20,-2,LEAVES:12)
Block(6,20,-1,LEAVES:12)
Block(6,20,12,LEAVES:12)
Block(6,21,-5,LEAVES:12)
Block(6,21,6,LOG:12)
Block(6,21,15,LEAVES:12)
Block(6,21,16,LEAVES:12)
Block(6,22,6,LOG:12)
Block(6,22,8,LEAVES:12)
Block(6,22,9,LEAVES:12)
Block(6,22,12,LEAVES:12)
Block(6,22,16,LEAVES:12)
Block(6,23,0,LEAVES:12)
Block(6,23,2,LEAVES:12)
Block(6,23,12,LEAVES:12)
Block(6,23,16,LEAVES:12)
Block(6,24,0,LEAVES:12)
Block(6,24,12,LEAVES:12)
Block(7,7,13,LEAVES:12)
Block(7,10,15,LEAVES:12)
Block(7,11,0,LEAVES:12)
Block(7,11,11,LEAVES:12)
Block(7,11,12,LEAVES:12)
Block(7,12,-1,LEAVES:12)
Block(7,12,0,LEAVES:12)
Block(7,13,-5,LEAVES:12)
Block(7,13,-3,LEAVES:12)
Block(7,13,5,LOG:12)
Block(7,14,-5,LEAVES:12)
Block(7,14,-3,LEAVES:12)
Block(7,14,4,LOG:12)
Block(7,14,5,LOG:12)
Block(7,14,6,LOG:12)
Block(7,14,13,LEAVES:12)
Block(7,14,15,LEAVES:12)
Block(7,15,-5,LEAVES:12)
Block(7,15,-3,LEAVES:12)
Block(7,15,-1,LEAVES:12)
Block(7,15,1,LEAVES:12)
Block(7,15,4,LOG:12)
Block(7,15,7,LOG:12)
Block(7,15,8,LOG:12)
Block(7,15,13,LEAVES:12)
Block(7,16,-7,LEAVES:12)
Block(7,16,-5,LEAVES:12)
Block(7,16,-4,LEAVES:12)
Block(7,16,-3,LEAVES:12)
Block(7,16,-1,LEAVES:12)
Block(7,16,1,LEAVES:12)
Block(7,16,2,LOG:12)
Block(7,16,3,LOG:12)
Block(7,16,4,LOG:12)
Block(7,16,8,LOG:12)
Block(7,17,-9,LEAVES:12)
Block(7,17,-7,LEAVES:12)
Block(7,17,-5,LEAVES:12)
Block(7,17,-4,LEAVES:12)
Block(7,17,0,LEAVES:12)
Block(7,17,3,LOG:12)
Block(7,17,8,LOG:12)
Block(7,17,9,LEAVES:12)
Block(7,17,15,LEAVES:12)
Block(7,17,16,LEAVES:12)
Block(7,18,-5,LEAVES:12)
Block(7,18,-3,LEAVES:12)
Block(7,18,3,LOG:12)
Block(7,18,7,LOG:12)
Block(7,18,8,LOG:12)
Block(7,18,9,LOG:12)
Block(7,18,13,LEAVES:12)
Block(7,18,14,LEAVES:12)
Block(7,18,15,LEAVES:12)
Block(7,19,-1,LEAVES:12)
Block(7,19,0,LEAVES:12)
Block(7,19,2,LEAVES:12)
Block(7,19,7,LOG:12)
Block(7,19,9,LOG:12)
Block(7,19,10,LOG:12)
Block(7,19,11,LEAVES:12)
Block(7,19,13,LEAVES:12)
Block(7,20,-4,LEAVES:12)
Block(7,20,-3,LEAVES:12)
Block(7,20,-1,LEAVES:12)
Block(7,20,1,LEAVES:12)
Block(7,20,2,LEAVES:12)
Block(7,20,7,LOG:12)
Block(7,20,10,LOG:12)
Block(7,20,12,LEAVES:12)
Block(7,21,-3,LEAVES:12)
Block(7,21,-2,LEAVES:12)
Block(7,21,6,LOG:12)
Block(7,21,7,LOG:12)
Block(7,21,10,LEAVES:12)
Block(7,21,11,LEAVES:12)
Block(7,21,12,LEAVES:12)
Block(7,21,14,LEAVES:12)
Block(7,21,15,LEAVES:12)
Block(7,22,-3,LEAVES:12)
Block(7,22,3,LEAVES:12)
Block(7,22,5,LEAVES:12)
Block(7,22,6,LEAVES:12)
Block(7,22,9,LEAVES:12)
Block(7,22,10,LEAVES:12)
Block(7,22,12,LEAVES:12)
Block(7,22,17,LEAVES:12)
Block(7,23,0,LEAVES:12)
Block(7,23,1,LEAVES:12)
Block(7,23,10,LEAVES:12)
Block(8,6,14,LEAVES:12)
Block(8,7,14,LEAVES:12)
Block(8,8,16,LEAVES:12)
Block(8,9,-3,LEAVES:12)
Block(8,9,10,LEAVES:12)
Block(8,10,12,LEAVES:12)
Block(8,10,13,LEAVES:12)
Block(8,10,15,LEAVES:12)
Block(8,11,12,LEAVES:12)
Block(8,11,14,LEAVES:12)
Block(8,11,15,LEAVES:12)
Block(8,12,-1,LEAVES:12)
Block(8,13,-6,LEAVES:12)
Block(8,13,-5,LEAVES:12)
Block(8,13,-4,LEAVES:12)
Block(8,13,16,LEAVES:12)
Block(8,13,18,LEAVES:12)
Block(8,13,19,LEAVES:12)
Block(8,14,-2,LEAVES:12)
Block(8,14,6,LOG:12)
Block(8,14,7,LOG:12)
Block(8,14,13,LEAVES:12)
Block(8,14,14,LEAVES:12)
Block(8,15,-5,LEAVES:12)
Block(8,15,-3,LEAVES:12)
Block(8,15,-2,LEAVES:12)
Block(8,15,1,LOG:12)
Block(8,15,3,LEAVES:12)
Block(8,15,7,LOG:12)
Block(8,16,-3,LEAVES:12)
Block(8,16,-1,LEAVES:12)
Block(8,16,1,LOG:12)
Block(8,16,2,LOG:12)
Block(8,16,11,LEAVES:12)
Block(8,17,-8,LEAVES:12)
Block(8,17,-7,LEAVES:12)
Block(8,17,-4,LEAVES:12)
Block(8,17,-3,LEAVES:12)
Block(8,17,-2,LEAVES:12)
Block(8,17,2,LEAVES:12)
Block(8,17,5,LEAVES:12)
Block(8,17,10,LEAVES:12)
Block(8,17,16,LEAVES:12)
Block(8,17,17,LEAVES:12)
Block(8,18,-5,LEAVES:12)
Block(8,18,-3,LEAVES:12)
Block(8,18,2,LEAVES:12)
Block(8,18,3,LOG:12)
Block(8,18,9,LEAVES:12)
Block(8,18,10,LEAVES:12)
Block(8,19,-8,LEAVES:12)
Block(8,19,-6,LEAVES:12)
Block(8,19,-5,LEAVES:12)
Block(8,19,0,LEAVES:12)
Block(8,19,2,LOG:12)
Block(8,19,3,LOG:12)
Block(8,19,10,LEAVES:12)
Block(8,19,11,LEAVES:12)
Block(8,19,12,LEAVES:12)
Block(8,19,13,LEAVES:12)
Block(8,20,1,LEAVES:12)
Block(8,20,10,LOG:12)
Block(8,20,11,LOG:12)
Block(8,20,12,LOG:12)
Block(8,20,13,LEAVES:12)
Block(8,20,14,LEAVES:12)
Block(8,21,4,LEAVES:12)
Block(8,21,5,LEAVES:12)
Block(8,21,12,LEAVES:12)
Block(8,21,14,LEAVES:12)
Block(8,22,-3,LEAVES:12)
Block(8,22,-2,LEAVES:12)
Block(8,22,1,LEAVES:12)
Block(8,22,5,LEAVES:12)
Block(8,22,12,LEAVES:12)
Block(8,22,13,LEAVES:12)
Block(8,23,1,LEAVES:12)
Block(8,23,5,LEAVES:12)
Block(8,23,13,LEAVES:12)
Block(8,24,1,LEAVES:12)
Block(8,24,12,LEAVES:12)
Block(9,6,16,LEAVES:12)
Block(9,7,10,LEAVES:12)
Block(9,7,14,LEAVES:12)
Block(9,7,15,LEAVES:12)
Block(9,8,-2,LEAVES:12)
Block(9,8,10,LEAVES:12)
Block(9,8,11,LEAVES:12)
Block(9,8,15,LEAVES:12)
Block(9,8,18,LEAVES:12)
Block(9,9,-2,LEAVES:12)
Block(9,9,15,LEAVES:12)
Block(9,10,0,LEAVES:12)
Block(9,10,10,LEAVES:12)
Block(9,10,13,LEAVES:12)
Block(9,11,-6,LEAVES:12)
Block(9,11,9,LEAVES:12)
Block(9,11,10,LEAVES:12)
Block(9,11,14,LEAVES:12)
Block(9,12,-4,LEAVES:12)
Block(9,12,-3,LEAVES:12)
Block(9,12,-1,LEAVES:12)
Block(9,12,5,LEAVES:12)
Block(9,12,17,LEAVES:12)
Block(9,12,18,LEAVES:12)
Block(9,13,-4,LEAVES:12)
Block(9,13,-2,LEAVES:12)
Block(9,13,-1,LEAVES:12)
Block(9,13,10,LEAVES:12)
Block(9,13,11,LOG:12)
Block(9,13,14,LEAVES:12)
Block(9,13,18,LEAVES:12)
Block(9,14,-6,LEAVES:12)
Block(9,14,-5,LEAVES:12)
Block(9,14,-2,LEAVES:12)
Block(9,14,0,LOG:12)
Block(9,14,10,LOG:12)
Block(9,14,11,LOG:12)
Block(9,14,14,LEAVES:12)
Block(9,14,18,LEAVES:12)
Block(9,15,-5,LEAVES:12)
Block(9,15,0,LOG:12)
Block(9,15,1,LOG:12)
Block(9,15,2,LEAVES:12)
Block(9,15,3,LEAVES:12)
Block(9,15,7,LOG:12)
Block(9,15,8,LOG:12)
Block(9,15,9,LOG:12)
Block(9,15,10,LOG:12)
Block(9,15,14,LEAVES:12)
Block(9,16,-5,LEAVES:12)
Block(9,16,-3,LEAVES:12)
Block(9,16,-2,LEAVES:12)
Block(9,16,14,LEAVES:12)
Block(9,17,-9,LEAVES:12)
Block(9,17,-8,LEAVES:12)
Block(9,17,-2,LEAVES:12)
Block(9,17,4,LEAVES:12)
Block(9,17,5,LEAVES:12)
Block(9,17,12,LEAVES:12)
Block(9,17,14,LEAVES:12)
Block(9,18,-3,LEAVES:12)
Block(9,18,-2,LEAVES:12)
Block(9,18,-1,LEAVES:12)
Block(9,18,2,LEAVES:12)
Block(9,18,3,LEAVES:12)
Block(9,18,4,LEAVES:12)
Block(9,18,12,LEAVES:12)
Block(9,18,14,LEAVES:12)
Block(9,18,16,LEAVES:12)
Block(9,19,-7,LEAVES:12)
Block(9,19,-6,LEAVES:12)
Block(9,19,-2,LEAVES:12)
Block(9,19,0,LEAVES:12)
Block(9,19,1,LOG:12)
Block(9,19,2,LOG:12)
Block(9,19,10,LEAVES:12)
Block(9,19,12,LEAVES:12)
Block(9,19,13,LEAVES:12)
Block(9,19,14,LEAVES:12)
Block(9,19,16,LEAVES:12)
Block(9,20,-4,LEAVES:12)
Block(9,20,1,LOG:12)
Block(9,20,8,LEAVES:12)
Block(9,20,10,LEAVES:12)
Block(9,20,12,LEAVES:12)
Block(9,20,13,LEAVES:12)
Block(9,20,17,LEAVES:12)
Block(9,21,-1,LEAVES:12)
Block(9,21,0,LEAVES:12)
Block(9,21,1,LEAVES:12)
Block(9,21,3,LEAVES:12)
Block(9,21,4,LEAVES:12)
Block(9,21,12,LEAVES:12)
Block(9,22,-2,LEAVES:12)
Block(9,22,-1,LEAVES:12)
Block(9,22,1,LEAVES:12)
Block(9,22,6,LEAVES:12)
Block(9,23,-1,LEAVES:12)
Block(9,23,13,LEAVES:12)
Block(9,23,14,LEAVES:12)
Block(9,24,14,LEAVES:12)
Block(9,24,15,LEAVES:12)
Block(9,25,14,LEAVES:12)
Block(10,8,0,LEAVES:12)
Block(10,8,7,LEAVES:12)
Block(10,8,11,LEAVES:12)
Block(10,8,17,LEAVES:12)
Block(10,8,18,LEAVES:12)
Block(10,9,-6,LEAVES:12)
Block(10,9,-2,LEAVES:12)
Block(10,9,-1,LEAVES:12)
Block(10,9,11,LEAVES:12)
Block(10,9,15,LEAVES:12)
Block(10,9,16,LEAVES:12)
Block(10,9,17,LEAVES:12)
Block(10,10,-6,LEAVES:12)
Block(10,10,-5,LEAVES:12)
Block(10,10,-1,LEAVES:12)
Block(10,10,2,LEAVES:12)
Block(10,10,13,LEAVES:12)
Block(10,10,15,LEAVES:12)
Block(10,11,-1,LEAVES:12)
Block(10,11,9,LEAVES:12)
Block(10,11,14,LEAVES:12)
Block(10,12,-3,LEAVES:12)
Block(10,12,5,LEAVES:12)
Block(10,12,6,LEAVES:12)
Block(10,12,11,LOG:12)
Block(10,12,12,LOG:12)
Block(10,12,13,LEAVES:12)
Block(10,12,14,LEAVES:12)
Block(10,12,16,LEAVES:12)
Block(10,12,17,LEAVES:12)
Block(10,13,-7,LEAVES:12)
Block(10,13,-6,LEAVES:12)
Block(10,13,-2,LEAVES:12)
Block(10,13,11,LOG:12)
Block(10,13,12,LEAVES:12)
Block(10,13,14,LEAVES:12)
Block(10,13,19,LEAVES:12)
Block(10,14,-6,LEAVES:12)
Block(10,14,0,LOG:12)
Block(10,14,1,LEAVES:12)
Block(10,14,2,LEAVES:12)
Block(10,14,12,LEAVES:12)
Block(10,15,-6,LEAVES:12)
Block(10,15,-5,LEAVES:12)
Block(10,15,-2,LEAVES:12)
Block(10,15,2,LEAVES:12)
Block(10,15,7,LEAVES:12)
Block(10,15,8,LOG:12)
Block(10,15,9,LEAVES:12)
Block(10,16,-6,LEAVES:12)
Block(10,16,-5,LEAVES:12)
Block(10,16,-2,LEAVES:12)
Block(10,16,0,LEAVES:12)
Block(10,16,2,LEAVES:12)
Block(10,16,7,LEAVES:12)
Block(10,16,8,LEAVES:12)
Block(10,16,11,LEAVES:12)
Block(10,17,-5,LEAVES:12)
Block(10,17,-2,LEAVES:12)
Block(10,17,-1,LEAVES:12)
Block(10,17,5,LEAVES:12)
Block(10,17,6,LEAVES:12)
Block(10,17,7,LEAVES:12)
Block(10,17,8,LEAVES:12)
Block(10,17,15,LEAVES:12)
Block(10,18,-2,LEAVES:12)
Block(10,18,-1,LEAVES:12)
Block(10,18,3,LEAVES:12)
Block(10,18,12,LEAVES:12)
Block(10,18,14,LEAVES:12)
Block(10,18,15,LEAVES:12)
Block(10,19,-7,LEAVES:12)
Block(10,19,-1,LEAVES:12)
Block(10,19,0,LEAVES:12)
Block(10,19,1,LEAVES:12)
Block(10,19,2,LEAVES:12)
Block(10,20,-7,LEAVES:12)
Block(10,20,0,LOG:12)
Block(10,20,1,LOG:12)
Block(10,20,2,LEAVES:12)
Block(10,20,3,LEAVES:12)
Block(10,20,9,LEAVES:12)
Block(10,20,10,LEAVES:12)
Block(10,20,13,LEAVES:12)
Block(10,20,14,LEAVES:12)
Block(10,21,1,LEAVES:12)
Block(10,21,3,LEAVES:12)
Block(10,21,12,LEAVES:12)
Block(10,21,14,LEAVES:12)
Block(10,22,1,LEAVES:12)
Block(10,22,2,LEAVES:12)
Block(10,22,9,LEAVES:12)
Block(10,22,11,LEAVES:12)
Block(10,22,12,LEAVES:12)
Block(10,23,2,LEAVES:12)
Block(10,24,1,LEAVES:12)
Block(11,7,8,LEAVES:12)
Block(11,7,13,LEAVES:12)
Block(11,8,8,LEAVES:12)
Block(11,8,12,LEAVES:12)
Block(11,8,18,LEAVES:12)
Block(11,8,19,LEAVES:12)
Block(11,9,10,LEAVES:12)
Block(11,9,11,LEAVES:12)
Block(11,9,12,LEAVES:12)
Block(11,10,-5,LEAVES:12)
Block(11,10,1,LEAVES:12)
Block(11,10,2,LEAVES:12)
Block(11,10,4,LEAVES:12)
Block(11,10,12,LEAVES:12)
Block(11,10,13,LEAVES:12)
Block(11,10,14,LEAVES:12)
Block(11,10,15,LEAVES:12)
Block(11,11,-5,LEAVES:12)
Block(11,11,-1,LEAVES:12)
Block(11,11,0,LEAVES:12)
Block(11,11,1,LEAVES:12)
Block(11,11,6,LEAVES:12)
Block(11,11,7,LEAVES:12)
Block(11,11,9,LEAVES:12)
Block(11,11,12,LOG:12)
Block(11,11,13,LOG:12)
Block(11,11,14,LOG:12)
Block(11,11,15,LEAVES:12)
Block(11,11,16,LEAVES:12)
Block(11,12,-3,LEAVES:12)
Block(11,12,-1,LEAVES:12)
Block(11,12,6,LEAVES:12)
Block(11,12,8,LEAVES:12)
Block(11,12,9,LEAVES:12)
Block(11,12,12,LOG:12)
Block(11,12,14,LEAVES:12)
Block(11,12,16,LEAVES:12)
Block(11,13,-7,LEAVES:12)
Block(11,13,-2,LEAVES:12)
Block(11,13,-1,LOG:12)
Block(11,13,0,LOG:12)
Block(11,13,14,LEAVES:12)
Block(11,13,15,LEAVES:12)
Block(11,14,-4,LEAVES:12)
Block(11,14,-3,LEAVES:12)
Block(11,14,-2,LEAVES:12)
Block(11,14,0,LOG:12)
Block(11,14,1,LEAVES:12)
Block(11,14,5,LEAVES:12)
Block(11,14,8,LOG:12)
Block(11,14,9,LOG:12)
Block(11,14,10,LEAVES:12)
Block(11,14,12,LEAVES:12)
Block(11,14,13,LEAVES:12)
Block(11,14,15,LEAVES:12)
Block(11,15,-5,LEAVES:12)
Block(11,15,-4,LEAVES:12)
Block(11,15,-2,LEAVES:12)
Block(11,15,3,LEAVES:12)
Block(11,15,7,LEAVES:12)
Block(11,15,8,LOG:12)
Block(11,15,14,LEAVES:12)
Block(11,16,-5,LEAVES:12)
Block(11,16,-4,LEAVES:12)
Block(11,16,3,LEAVES:12)
Block(11,16,8,LOG:12)
Block(11,16,15,LEAVES:12)
Block(11,17,1,LEAVES:12)
Block(11,17,3,LEAVES:12)
Block(11,17,7,LEAVES:12)
Block(11,17,11,LEAVES:12)
Block(11,17,12,LEAVES:12)
Block(11,17,15,LEAVES:12)
Block(11,18,1,LEAVES:12)
Block(11,18,3,LEAVES:12)
Block(11,18,4,LEAVES:12)
Block(11,18,5,LEAVES:12)
Block(11,18,12,LEAVES:12)
Block(11,19,-1,LEAVES:12)
Block(11,19,1,LEAVES:12)
Block(11,19,2,LEAVES:12)
Block(11,19,3,LEAVES:12)
Block(11,19,5,LEAVES:12)
Block(11,19,12,LEAVES:12)
Block(11,20,-3,LEAVES:12)
Block(11,20,-1,LEAVES:12)
Block(11,20,1,LEAVES:12)
Block(11,20,2,LEAVES:12)
Block(11,20,6,LEAVES:12)
Block(11,20,8,LEAVES:12)
Block(11,20,9,LEAVES:12)
Block(11,21,1,LEAVES:12)
Block(11,21,5,LEAVES:12)
Block(11,21,7,LEAVES:12)
Block(11,21,14,LEAVES:12)
Block(11,21,15,LEAVES:12)
Block(11,21,16,LEAVES:12)
Block(11,22,5,LEAVES:12)
Block(11,22,10,LEAVES:12)
Block(11,22,11,LEAVES:12)
Block(11,22,15,LEAVES:12)
Block(11,23,2,LEAVES:12)
Block(11,23,3,LEAVES:12)
Block(11,23,13,LEAVES:12)
Block(11,24,3,LEAVES:12)
Block(11,24,4,LEAVES:12)
Block(11,25,3,LEAVES:12)
Block(12,7,10,LEAVES:12)
Block(12,7,16,LEAVES:12)
Block(12,8,4,LEAVES:12)
Block(12,8,8,LEAVES:12)
Block(12,8,9,LEAVES:12)
Block(12,8,14,LEAVES:12)
Block(12,8,16,LEAVES:12)
Block(12,9,-3,LEAVES:12)
Block(12,9,4,LEAVES:12)
Block(12,9,5,LEAVES:12)
Block(12,9,9,LEAVES:12)
Block(12,9,12,LEAVES:12)
Block(12,9,14,LEAVES:12)
Block(12,9,16,LEAVES:12)
Block(12,9,18,LEAVES:12)
Block(12,10,-4,LEAVES:12)
Block(12,10,2,LEAVES:12)
Block(12,10,3,LEAVES:12)
Block(12,10,9,LEAVES:12)
Block(12,10,12,LEAVES:12)
Block(12,10,14,LEAVES:12)
Block(12,10,15,LEAVES:12)
Block(12,10,16,LEAVES:12)
Block(12,10,18,LEAVES:12)
Block(12,11,-5,LEAVES:12)
Block(12,11,-4,LEAVES:12)
Block(12,11,7,LEAVES:12)
Block(12,11,10,LEAVES:12)
Block(12,11,12,LEAVES:12)
Block(12,11,14,LEAVES:12)
Block(12,11,15,LEAVES:12)
Block(12,11,19,LEAVES:12)
Block(12,12,-4,LEAVES:12)
Block(12,12,-3,LEAVES:12)
Block(12,12,-2,LEAVES:12)
Block(12,12,-1,LEAVES:12)
Block(12,12,8,LEAVES:12)
Block(12,12,14,LEAVES:12)
Block(12,13,-2,LOG:12)
Block(12,13,-1,LOG:12)
Block(12,13,0,LEAVES:12)
Block(12,13,6,LEAVES:12)
Block(12,13,9,LOG:12)
Block(12,13,11,LEAVES:12)
Block(12,13,12,LEAVES:12)
Block(12,14,-2,LEAVES:12)
Block(12,14,0,LEAVES:12)
Block(12,14,4,LEAVES:12)
Block(12,14,5,LEAVES:12)
Block(12,14,6,LEAVES:12)
Block(12,14,8,LEAVES:12)
Block(12,14,9,LOG:12)
Block(12,14,12,LEAVES:12)
Block(12,14,15,LEAVES:12)
Block(12,14,16,LEAVES:12)
Block(12,15,-4,LEAVES:12)
Block(12,15,-2,LEAVES:12)
Block(12,15,-1,LEAVES:12)
Block(12,15,8,LEAVES:12)
Block(12,15,12,LEAVES:12)
Block(12,15,16,LEAVES:12)
Block(12,15,17,LEAVES:12)
Block(12,16,-1,LEAVES:12)
Block(12,16,0,LEAVES:12)
Block(12,16,2,LEAVES:12)
Block(12,16,8,LOG:12)
Block(12,16,10,LEAVES:12)
Block(12,16,11,LEAVES:12)
Block(12,16,16,LEAVES:12)
Block(12,17,-2,LEAVES:12)
Block(12,17,4,LEAVES:12)
Block(12,17,5,LEAVES:12)
Block(12,17,7,LOG:12)
Block(12,17,8,LOG:12)
Block(12,17,11,LEAVES:12)
Block(12,18,1,LEAVES:12)
Block(12,18,3,LEAVES:12)
Block(12,18,4,LEAVES:12)
Block(12,18,6,LEAVES:12)
Block(12,18,7,LEAVES:12)
Block(12,19,11,LEAVES:12)
Block(12,19,12,LEAVES:12)
Block(12,20,-2,LEAVES:12)
Block(12,20,-1,LEAVES:12)
Block(12,20,2,LEAVES:12)
Block(12,20,3,LEAVES:12)
Block(12,20,8,LEAVES:12)
Block(12,20,10,LEAVES:12)
Block(12,20,11,LEAVES:12)
Block(12,20,12,LEAVES:12)
Block(12,21,1,LEAVES:12)
Block(12,21,3,LEAVES:12)
Block(12,21,5,LEAVES:12)
Block(12,21,6,LEAVES:12)
Block(12,21,15,LEAVES:12)
Block(12,22,-2,LEAVES:12)
Block(12,22,0,LEAVES:12)
Block(12,22,1,LEAVES:12)
Block(12,22,10,LEAVES:12)
Block(12,23,10,LEAVES:12)
Block(13,7,13,LEAVES:12)
Block(13,8,17,LEAVES:12)
Block(13,9,0,LEAVES:12)
Block(13,9,5,LEAVES:12)
Block(13,9,11,LEAVES:12)
Block(13,9,12,LEAVES:12)
Block(13,9,14,LEAVES:12)
Block(13,9,16,LEAVES:12)
Block(13,9,17,LEAVES:12)
Block(13,10,-2,LEAVES:12)
Block(13,10,0,LEAVES:12)
Block(13,10,5,LEAVES:12)
Block(13,10,9,LEAVES:12)
Block(13,10,10,LEAVES:12)
Block(13,10,11,LEAVES:12)
Block(13,11,-2,LEAVES:12)
Block(13,11,0,LEAVES:12)
Block(13,11,2,LEAVES:12)
Block(13,11,7,LEAVES:12)
Block(13,11,9,LEAVES:12)
Block(13,11,11,LEAVES:12)
Block(13,11,12,LEAVES:12)
Block(13,11,15,LEAVES:12)
Block(13,11,16,LEAVES:12)
Block(13,12,-4,LEAVES:12)
Block(13,12,-2,LEAVES:12)
Block(13,12,-1,LEAVES:12)
Block(13,12,0,LEAVES:12)
Block(13,12,2,LEAVES:12)
Block(13,12,8,LOG:12)
Block(13,12,9,LOG:12)
Block(13,12,14,LEAVES:12)
Block(13,12,16,LEAVES:12)
Block(13,13,-6,LEAVES:12)
Block(13,13,-4,LEAVES:12)
Block(13,13,-2,LEAVES:12)
Block(13,13,-1,LEAVES:12)
Block(13,13,3,LEAVES:12)
Block(13,13,6,LEAVES:12)
Block(13,13,7,LEAVES:12)
Block(13,13,8,LEAVES:12)
Block(13,13,9,LOG:12)
Block(13,13,10,LEAVES:12)
Block(13,13,11,LEAVES:12)
Block(13,13,13,LEAVES:12)
Block(13,13,14,LEAVES:12)
Block(13,14,-2,LEAVES:12)
Block(13,14,2,LEAVES:12)
Block(13,14,5,LEAVES:12)
Block(13,14,6,LEAVES:12)
Block(13,14,7,LEAVES:12)
Block(13,14,8,LEAVES:12)
Block(13,14,13,LEAVES:12)
Block(13,15,2,LEAVES:12)
Block(13,15,3,LEAVES:12)
Block(13,15,6,LEAVES:12)
Block(13,15,7,LEAVES:12)
Block(13,15,10,LEAVES:12)
Block(13,16,-1,LEAVES:12)
Block(13,16,0,LEAVES:12)
Block(13,16,4,LEAVES:12)
Block(13,16,7,LEAVES:12)
Block(13,16,10,LEAVES:12)
Block(13,17,0,LEAVES:12)
Block(13,17,1,LEAVES:12)
Block(13,17,4,LEAVES:12)
Block(13,17,5,LEAVES:12)
Block(13,17,6,LOG:12)
Block(13,17,7,LOG:12)
Block(13,18,0,LEAVES:12)
Block(13,18,1,LEAVES:12)
Block(13,18,6,LOG:12)
Block(13,18,13,LEAVES:12)
Block(13,19,1,LEAVES:12)
Block(13,19,9,LEAVES:12)
Block(13,19,10,LEAVES:12)
Block(13,19,12,LEAVES:12)
Block(13,19,13,LEAVES:12)
Block(13,20,-3,LEAVES:12)
Block(13,20,-2,LEAVES:12)
Block(13,20,2,LEAVES:12)
Block(13,20,3,LEAVES:12)
Block(13,20,6,LEAVES:12)
Block(13,20,10,LEAVES:12)
Block(13,21,3,LEAVES:12)
Block(13,21,4,LEAVES:12)
Block(13,21,5,LEAVES:12)
Block(13,21,6,LEAVES:12)
Block(13,21,10,LEAVES:12)
Block(13,22,-1,LEAVES:12)
Block(13,22,0,LEAVES:12)
Block(13,22,4,LEAVES:12)
Block(13,22,6,LEAVES:12)
Block(13,23,2,LEAVES:12)
Block(14,7,17,LEAVES:12)
Block(14,8,7,LEAVES:12)
Block(14,8,13,LEAVES:12)
Block(14,8,14,LEAVES:12)
Block(14,8,17,LEAVES:12)
Block(14,9,-3,LEAVES:12)
Block(14,9,6,LEAVES:12)
Block(14,9,12,LEAVES:12)
Block(14,9,13,LEAVES:12)
Block(14,9,14,LEAVES:12)
Block(14,10,1,LEAVES:12)
Block(14,10,5,LEAVES:12)
Block(14,10,6,LEAVES:12)
Block(14,10,14,LEAVES:12)
Block(14,11,-2,LEAVES:12)
Block(14,11,0,LEAVES:12)
Block(14,11,1,LEAVES:12)
Block(14,11,6,LEAVES:12)
Block(14,11,7,LEAVES:12)
Block(14,11,8,LEAVES:12)
Block(14,11,9,LEAVES:12)
Block(14,11,10,LEAVES:12)
Block(14,11,11,LEAVES:12)
Block(14,12,8,LOG:12)
Block(14,12,9,LEAVES:12)
Block(14,12,10,LEAVES:12)
Block(14,12,16,LEAVES:12)
Block(14,12,17,LEAVES:12)
Block(14,12,18,LEAVES:12)
Block(14,13,-5,LEAVES:12)
Block(14,13,-4,LEAVES:12)
Block(14,13,-1,LEAVES:12)
Block(14,13,0,LEAVES:12)
Block(14,13,8,LEAVES:12)
Block(14,13,10,LEAVES:12)
Block(14,13,12,LEAVES:12)
Block(14,13,13,LEAVES:12)
Block(14,13,17,LEAVES:12)
Block(14,14,-2,LEAVES:12)
Block(14,14,0,LEAVES:12)
Block(14,14,8,LEAVES:12)
Block(14,14,9,LEAVES:12)
Block(14,14,15,LEAVES:12)
Block(14,15,-5,LEAVES:12)
Block(14,15,-3,LEAVES:12)
Block(14,15,-2,LEAVES:12)
Block(14,15,3,LEAVES:12)
Block(14,15,9,LEAVES:12)
Block(14,15,10,LEAVES:12)
Block(14,16,-1,LEAVES:12)
Block(14,16,0,LEAVES:12)
Block(14,16,3,LEAVES:12)
Block(14,16,7,LEAVES:12)
Block(14,16,8,LEAVES:12)
Block(14,16,9,LEAVES:12)
Block(14,17,0,LEAVES:12)
Block(14,17,5,LEAVES:12)
Block(14,17,7,LEAVES:12)
Block(14,18,6,LOG:12)
Block(14,18,13,LEAVES:12)
Block(14,19,0,LEAVES:12)
Block(14,19,1,LEAVES:12)
Block(14,19,4,LEAVES:12)
Block(14,19,5,LEAVES:12)
Block(14,19,6,LEAVES:12)
Block(14,19,8,LEAVES:12)
Block(14,19,9,LEAVES:12)
Block(14,20,1,LEAVES:12)
Block(14,20,3,LEAVES:12)
Block(14,20,4,LEAVES:12)
Block(14,20,6,LEAVES:12)
Block(14,20,11,LEAVES:12)
Block(14,21,4,LEAVES:12)
Block(14,22,-1,LEAVES:12)
Block(14,23,-1,LEAVES:12)
Block(15,7,12,LEAVES:12)
Block(15,7,13,LEAVES:12)
Block(15,8,10,LEAVES:12)
Block(15,8,13,LEAVES:12)
Block(15,9,1,LEAVES:12)
Block(15,9,8,LEAVES:12)
Block(15,9,10,LEAVES:12)
Block(15,10,-3,LEAVES:12)
Block(15,10,-2,LEAVES:12)
Block(15,10,1,LEAVES:12)
Block(15,10,8,LEAVES:12)
Block(15,10,10,LEAVES:12)
Block(15,10,12,LEAVES:12)
Block(15,10,13,LEAVES:12)
Block(15,10,14,LEAVES:12)
Block(15,11,-2,LEAVES:12)
Block(15,11,6,LEAVES:12)
Block(15,11,8,LEAVES:12)
Block(15,11,9,LEAVES:12)
Block(15,11,10,LEAVES:12)
Block(15,11,12,LEAVES:12)
Block(15,11,14,LEAVES:12)
Block(15,12,-2,LEAVES:12)
Block(15,12,4,LEAVES:12)
Block(15,12,6,LEAVES:12)
Block(15,12,8,LOG:12)
Block(15,12,9,LEAVES:12)
Block(15,12,13,LEAVES:12)
Block(15,12,17,LEAVES:12)
Block(15,13,-6,LEAVES:12)
Block(15,13,-5,LEAVES:12)
Block(15,13,8,LEAVES:12)
Block(15,13,12,LEAVES:12)
Block(15,14,0,LEAVES:12)
Block(15,14,1,LEAVES:12)
Block(15,14,2,LEAVES:12)
Block(15,14,5,LEAVES:12)
Block(15,14,12,LEAVES:12)
Block(15,15,-4,LEAVES:12)
Block(15,15,-3,LEAVES:12)
Block(15,15,1,LEAVES:12)
Block(15,15,4,LEAVES:12)
Block(15,15,9,LEAVES:12)
Block(15,15,10,LEAVES:12)
Block(15,15,11,LEAVES:12)
Block(15,16,-1,LEAVES:12)
Block(15,16,3,LEAVES:12)
Block(15,16,4,LEAVES:12)
Block(15,16,10,LEAVES:12)
Block(15,16,11,LEAVES:12)
Block(15,17,4,LEAVES:12)
Block(15,17,5,LEAVES:12)
Block(15,17,6,LEAVES:12)
Block(15,17,7,LEAVES:12)
Block(15,17,10,LEAVES:12)
Block(15,18,2,LEAVES:12)
Block(15,18,6,LOG:12)
Block(15,18,7,LEAVES:12)
Block(15,18,8,LEAVES:12)
Block(15,19,1,LEAVES:12)
Block(15,19,2,LEAVES:12)
Block(15,19,6,LEAVES:12)
Block(15,19,8,LEAVES:12)
Block(15,20,6,LEAVES:12)
Block(15,20,7,LEAVES:12)
Block(15,21,7,LEAVES:12)
Block(15,22,6,LEAVES:12)
Block(16,7,12,LEAVES:12)
Block(16,8,7,LEAVES:12)
Block(16,9,-4,LEAVES:12)
Block(16,9,-3,LEAVES:12)
Block(16,9,11,LEAVES:12)
Block(16,9,15,LEAVES:12)
Block(16,10,-3,LEAVES:12)
Block(16,10,8,LEAVES:12)
Block(16,10,10,LEAVES:12)
Block(16,10,11,LEAVES:12)
Block(16,10,14,LEAVES:12)
Block(16,10,15,LEAVES:12)
Block(16,12,-3,LEAVES:12)
Block(16,12,-2,LEAVES:12)
Block(16,12,5,LEAVES:12)
Block(16,12,6,LEAVES:12)
Block(16,12,9,LEAVES:12)
Block(16,12,10,LEAVES:12)
Block(16,13,-2,LEAVES:12)
Block(16,13,8,LEAVES:12)
Block(16,13,10,LEAVES:12)
Block(16,14,1,LEAVES:12)
Block(16,14,5,LEAVES:12)
Block(16,14,7,LEAVES:12)
Block(16,14,8,LEAVES:12)
Block(16,15,-4,LEAVES:12)
Block(16,15,6,LEAVES:12)
Block(16,15,8,LEAVES:12)
Block(16,16,-4,LEAVES:12)
Block(16,16,6,LEAVES:12)
Block(16,16,8,LEAVES:12)
Block(16,16,10,LEAVES:12)
Block(16,17,4,LEAVES:12)
Block(16,17,6,LEAVES:12)
Block(16,17,7,LEAVES:12)
Block(16,17,8,LEAVES:12)
Block(16,17,10,LEAVES:12)
Block(16,18,2,LEAVES:12)
Block(16,18,4,LEAVES:12)
Block(16,18,6,LEAVES:12)
Block(16,18,7,LEAVES:12)
Block(16,18,11,LEAVES:12)
Block(16,19,6,LEAVES:12)
Block(16,21,7,LEAVES:12)
Block(16,21,8,LEAVES:12)
Block(16,22,8,LEAVES:12)
Block(16,22,9,LEAVES:12)
Block(16,23,8,LEAVES:12)
Block(17,8,11,LEAVES:12)
Block(17,9,-4,LEAVES:12)
Block(17,9,7,LEAVES:12)
Block(17,9,8,LEAVES:12)
Block(17,9,11,LEAVES:12)
Block(17,9,15,LEAVES:12)
Block(17,10,8,LEAVES:12)
Block(17,11,-1,LEAVES:12)
Block(17,11,8,LEAVES:12)
Block(17,12,-2,LEAVES:12)
Block(17,12,-1,LEAVES:12)
Block(17,12,4,LEAVES:12)
Block(17,12,5,LEAVES:12)
Block(17,13,10,LEAVES:12)
Block(17,13,11,LEAVES:12)
Block(17,13,12,LEAVES:12)
Block(17,14,5,LEAVES:12)
Block(17,14,6,LEAVES:12)
Block(17,14,7,LEAVES:12)
Block(17,14,11,LEAVES:12)
Block(17,15,9,LEAVES:12)
Block(17,16,6,LEAVES:12)
Block(17,16,8,LEAVES:12)
Block(17,16,9,LEAVES:12)
Block(17,18,3,LEAVES:12)
Block(17,18,4,LEAVES:12)
Block(17,18,7,LEAVES:12)
Block(17,18,8,LEAVES:12)
Block(17,19,6,LEAVES:12)
Block(17,19,8,LEAVES:12)
Block(17,20,3,LEAVES:12)
Block(17,20,5,LEAVES:12)
Block(17,20,6,LEAVES:12)
Block(18,8,6,LEAVES:12)
Block(18,8,7,LEAVES:12)
Block(18,9,7,LEAVES:12)
Block(18,11,-1,LEAVES:12)
Block(18,11,7,LEAVES:12)
Block(18,11,8,LEAVES:12)
Block(18,12,8,LEAVES:12)
Block(18,13,11,LEAVES:12)
Block(18,14,6,LEAVES:12)
Block(18,14,9,LEAVES:12)
Block(18,15,5,LEAVES:12)
Block(18,15,6,LEAVES:12)
Block(18,15,9,LEAVES:12)
Block(18,16,6,LEAVES:12)
Block(18,17,6,LEAVES:12)
Block(18,18,2,LEAVES:12)
Block(18,18,3,LEAVES:12)
Block(18,19,8,LEAVES:12)
Block(18,19,9,LEAVES:12)
Block(18,19,10,LEAVES:12)
Block(18,20,4,LEAVES:12)
Block(18,20,5,LEAVES:12)
Block(18,20,9,LEAVES:12)
Block(18,21,7,LEAVES:12)
Block(19,8,6,LEAVES:12)
Block(19,10,9,LEAVES:12)
Block(19,11,8,LEAVES:12)
Block(19,11,9,LEAVES:12)
Block(19,14,4,LEAVES:12)
Block(19,14,5,LEAVES:12)
Block(19,15,5,LEAVES:12)
Block(19,17,5,LEAVES:12)
Block(19,17,6,LEAVES:12)
Block(19,18,6,LEAVES:12)
Block(19,19,9,LEAVES:12)
Block(19,20,4,LEAVES:12)
Block(19,21,4,LEAVES:12)
Block(20,10,9,LEAVES:12)
Block(20,14,4,LEAVES:12)
Block(20,16,7,LEAVES:12)
Block(20,17,6,LEAVES:12)
Block(20,17,7,LEAVES:12)
Block(21,16,7,LEAVES:12)


#######################################################################
# +-----------------------------------------------------------------+ #
# |                             Entities                            | #
# +-----------------------------------------------------------------+ #
#######################################################################

# Entity() spawns an entity instead of a block. The entity is spawned only once when the BO3 is spawned.
# Entities are persistent by default so they don't de-spawn when no player is near, they are only unloaded.
# Usage: Entity(x,y,z,mobName,groupSize,NameTagOrNBTFileName) or Entity(x,y,z,mobName,groupSize)
# Use /tc entities or /otg entities to get a list of entities that can be used as mobName, this includes entities added by other mods.
# NameTagOrNBTFileName can be either a nametag for the mob or an nbt file (such as mymobinfo.nbt or mymobinfo.txt).
# When using a text file you can use the same mob spawning parameters used with the /summon command to equip the
# entity and give it custom attributes etc. You can copy the DATA part of a summon command including surrounding
# curly braces to a .txt file, for instance for: "/summon Skeleton x y z {DATA}"

#######################################################################
# +-----------------------------------------------------------------+ #
# |                            BO3 checks                           | #
# +-----------------------------------------------------------------+ #
#######################################################################

# Require a condition at a certain location in order for the BO3 to be spawned.
# BlockCheck(x,y,z,BlockName[,BlockName[,...]]) - one of the blocks must be at the location
# BlockCheckNot(x,y,z,BlockName[,BlockName[,...]]) - all the blocks must not be at the location
# LightCheck(x,y,z,minLightLevel,maxLightLevel) - light must be between min and max (inclusive)

# You can use "Solid" as a BlockName for matching all solid blocks or "All" to match all blocks that aren't air.

# Examples:
BlockCheck(0,-1,0,GRASS,DIRT,DIRT:2,SAND)
#   BlockCheck(0,-1,0,Solid)       Require any solid block just below the object
#   BlockCheck(0,-1,0,WOOL)        Require any type of wool just below the object
#   BlockCheck(0,-1,0,WOOL:0)      Require white wool just below the object
#   BlockCheckNot(0,-1,0,WOOL:0)   Require that there is no white wool below the object
#   LightCheck(0,0,0,0,1)          Require almost complete darkness just below the object

