#######################################################################
# +-----------------------------------------------------------------+ #
# |                            BO3 object                           | #
# +-----------------------------------------------------------------+ #
#######################################################################

# The descriptions in this file are accurate only for TerrainControl and OTG.
# For MCW and OTG+ these descriptions are only accurate if the BO3 is used as a CustomObject.
# MCW and OTG+ completely reimplemented CustomStructure, check the MCW/OTG+ documentation for more information.

# This is the config file of a custom object.
# If you add this object correctly to your BiomeConfigs, it will spawn in the world.

# This is the creator of this BO3 object
Author: Unknown

# A short description of this BO3 object
Description: This BO3 was converted from a schematic using OTGEdit. The author and description information of the schematic could not be found. If you know who the author of the schematic is then please add this information.

# The BO3 version, don't change this! It can be used by external applications to do a version check.
Version: 3

# The settings mode, WriteAll, WriteWithoutComments or WriteDisable. See WorldConfig.
SettingsMode: WriteDisable

#######################################################################
# +-----------------------------------------------------------------+ #
# |                          Main settings                          | #
# +-----------------------------------------------------------------+ #
#######################################################################

# This needs to be set to true to spawn the object in the Tree and Sapling resources.
Tree: true

# The frequency of the BO3 from 1 to 200. Tries this many times to spawn this BO3 when using the CustomObject(...) resource.
# Ignored by Tree(..), Sapling(..) and CustomStructure(..)
Frequency: 40

# The rarity of the BO3 from 0 to 100. Each spawn attempt has rarity% chance to succeed when using the CustomObject(...) resource.
# Ignored by Tree(..), Sapling(..) and CustomStructure(..)
Rarity: 100.0

# If you set this to true, the BO3 will be placed with a random rotation.
RotateRandomly: true

# The spawn height of the BO3 - randomY, highestBlock or highestSolidBlock.
SpawnHeight: highestSolidBlock

# The height limits for the BO3.
MinHeight: 0

MaxHeight: 256

# Objects can have other objects attached to it: branches. Branches can also
# have branches attached to it, which can also have branches, etc. This is the
# maximum branch depth for this objects.
MaxBranchDepth: 10

# When spawned with the UseWorld keyword, this BO3 should NOT spawn in the following biomes.
# If you writer.write the BO3 name directly in the BiomeConfigs, this will be ignored.
ExcludedBiomes: All

# To optimise this BO3 for faster loading times you can use Notepad++ to find/replace comments and abbreviate things.
# Notepad++ find/replace with regex:
# Find: ^[#;].* replace to nothing removes all lines starting with # 
# Find: ^\s*$ replace to nothing removes most empty lines 
# Notepad++ find/replace without regex:
# *Warning: This will only work for OTG 1.10.2 v21 / OTG 1.11.2 v6 or higher. B( is not recognised by lower versions.
# Find: Block( replace to B(

#######################################################################
# +-----------------------------------------------------------------+ #
# |                      Source block settings                      | #
# +-----------------------------------------------------------------+ #
#######################################################################

# The block(s) the BO3 should spawn in.
SourceBlocks: AIR

# The maximum percentage of the BO3 that can be outside the SourceBlock.
# The BO3 won't be placed on a location with more blocks outside the SourceBlock than this percentage.
MaxPercentageOutsideSourceBlock: 0

# What to do when a block is about to be placed outside the SourceBlock? (dontPlace, placeAnyway)
OutsideSourceBlock: dontPlace

#######################################################################
# +-----------------------------------------------------------------+ #
# |                              Blocks                             | #
# +-----------------------------------------------------------------+ #
#######################################################################

# All the blocks used in the BO3 are listed here. Possible blocks:
# Block(x,y,z,id[.data][,nbtfile.nbt) or B(x,y,z,id[.data][,nbtfile.nbt)
# RandomBlock(x,y,z,id[:data][,nbtfile.nbt],chance[,id[:data][,nbtfile.nbt],chance[,...]])
# So RandomBlock(0,0,0,CHEST,chest.nbt,50,CHEST,anotherchest.nbt,100) will spawn a chest at
# the BO3 origin, and give it a 50% chance to have the contents of chest.nbt, or, if that
# fails, a 100% percent chance to have the contents of anotherchest.nbt.

Block(-10,10,13,LEAVES:12)
Block(-10,11,12,LEAVES:12)
Block(-10,11,13,LEAVES:12)
Block(-10,12,8,LEAVES:12)
Block(-9,8,10,LEAVES:12)
Block(-9,11,12,LEAVES:12)
Block(-9,12,8,LEAVES:12)
Block(-9,12,9,LEAVES:12)
Block(-9,15,5,LEAVES:12)
Block(-9,15,10,LEAVES:12)
Block(-9,15,12,LEAVES:12)
Block(-9,16,4,LEAVES:12)
Block(-9,16,5,LEAVES:12)
Block(-9,16,10,LEAVES:12)
Block(-9,17,0,LEAVES:12)
Block(-8,7,11,LEAVES:12)
Block(-8,8,8,LEAVES:12)
Block(-8,8,11,LEAVES:12)
Block(-8,9,7,LEAVES:12)
Block(-8,9,8,LEAVES:12)
Block(-8,9,13,LEAVES:12)
Block(-8,10,3,LEAVES:12)
Block(-8,10,7,LEAVES:12)
Block(-8,11,9,LEAVES:12)
Block(-8,11,10,LEAVES:12)
Block(-8,11,12,LEAVES:12)
Block(-8,12,9,LEAVES:12)
Block(-8,12,11,LEAVES:12)
Block(-8,12,12,LEAVES:12)
Block(-8,13,2,LEAVES:12)
Block(-8,14,13,LEAVES:12)
Block(-8,14,15,LEAVES:12)
Block(-8,14,16,LEAVES:12)
Block(-8,15,10,LEAVES:12)
Block(-8,15,11,LEAVES:12)
Block(-8,16,4,LEAVES:12)
Block(-8,17,0,LEAVES:12)
Block(-8,17,1,LEAVES:12)
Block(-8,20,2,LEAVES:12)
Block(-8,20,4,LEAVES:12)
Block(-8,21,2,LEAVES:12)
Block(-7,6,5,LEAVES:12)
Block(-7,7,13,LEAVES:12)
Block(-7,8,7,LEAVES:12)
Block(-7,8,11,LEAVES:12)
Block(-7,8,12,LEAVES:12)
Block(-7,9,7,LEAVES:12)
Block(-7,9,8,LEAVES:12)
Block(-7,9,12,LEAVES:12)
Block(-7,9,15,LEAVES:12)
Block(-7,10,3,LEAVES:12)
Block(-7,10,4,LEAVES:12)
Block(-7,10,12,LEAVES:12)
Block(-7,11,10,LEAVES:12)
Block(-7,12,3,LEAVES:12)
Block(-7,12,11,LEAVES:12)
Block(-7,13,3,LEAVES:12)
Block(-7,13,5,LEAVES:12)
Block(-7,13,7,LEAVES:12)
Block(-7,13,14,LEAVES:12)
Block(-7,13,15,LEAVES:12)
Block(-7,14,5,LEAVES:12)
Block(-7,14,7,LEAVES:12)
Block(-7,14,8,LEAVES:12)
Block(-7,14,11,LEAVES:12)
Block(-7,14,15,LEAVES:12)
Block(-7,15,-1,LEAVES:12)
Block(-7,15,11,LEAVES:12)
Block(-7,15,15,LEAVES:12)
Block(-7,16,1,LEAVES:12)
Block(-7,16,2,LEAVES:12)
Block(-7,16,4,LEAVES:12)
Block(-7,16,11,LEAVES:12)
Block(-7,17,1,LEAVES:12)
Block(-7,17,3,LEAVES:12)
Block(-7,17,4,LEAVES:12)
Block(-7,19,5,LEAVES:12)
Block(-7,19,7,LEAVES:12)
Block(-7,19,8,LEAVES:12)
Block(-7,20,2,LEAVES:12)
Block(-7,20,3,LEAVES:12)
Block(-6,5,6,LEAVES:12)
Block(-6,6,6,LEAVES:12)
Block(-6,7,8,LEAVES:12)
Block(-6,8,2,LEAVES:12)
Block(-6,9,4,LEAVES:12)
Block(-6,9,5,LEAVES:12)
Block(-6,9,7,LEAVES:12)
Block(-6,9,8,LEAVES:12)
Block(-6,9,14,LEAVES:12)
Block(-6,9,15,LEAVES:12)
Block(-6,10,4,LEAVES:12)
Block(-6,10,6,LEAVES:12)
Block(-6,10,7,LEAVES:12)
Block(-6,10,8,LEAVES:12)
Block(-6,10,12,LEAVES:12)
Block(-6,10,13,LEAVES:12)
Block(-6,10,14,LEAVES:12)
Block(-6,11,10,LEAVES:12)
Block(-6,11,12,LEAVES:12)
Block(-6,12,5,LEAVES:12)
Block(-6,12,8,LEAVES:12)
Block(-6,12,10,LEAVES:12)
Block(-6,12,11,LEAVES:12)
Block(-6,13,-1,LEAVES:12)
Block(-6,13,3,LEAVES:12)
Block(-6,13,4,LEAVES:12)
Block(-6,13,5,LEAVES:12)
Block(-6,13,6,LEAVES:12)
Block(-6,13,9,LEAVES:12)
Block(-6,13,10,LEAVES:12)
Block(-6,13,11,LEAVES:12)
Block(-6,13,13,LEAVES:12)
Block(-6,13,14,LEAVES:12)
Block(-6,14,-1,LEAVES:12)
Block(-6,14,0,LEAVES:12)
Block(-6,14,4,LEAVES:12)
Block(-6,14,7,LEAVES:12)
Block(-6,14,8,LEAVES:12)
Block(-6,14,9,LEAVES:12)
Block(-6,14,11,LEAVES:12)
Block(-6,14,16,LEAVES:12)
Block(-6,15,4,LEAVES:12)
Block(-6,15,9,LEAVES:12)
Block(-6,16,2,LEAVES:12)
Block(-6,17,3,LEAVES:12)
Block(-6,18,6,LEAVES:12)
Block(-6,18,7,LEAVES:12)
Block(-6,19,-1,LEAVES:12)
Block(-6,19,0,LEAVES:12)
Block(-6,19,3,LEAVES:12)
Block(-6,19,7,LEAVES:12)
Block(-6,20,3,LEAVES:12)
Block(-6,20,7,LEAVES:12)
Block(-6,21,3,LEAVES:12)
Block(-5,5,8,LEAVES:12)
Block(-5,6,2,LEAVES:12)
Block(-5,6,6,LEAVES:12)
Block(-5,6,7,LEAVES:12)
Block(-5,7,2,LEAVES:12)
Block(-5,7,3,LEAVES:12)
Block(-5,7,7,LEAVES:12)
Block(-5,7,10,LEAVES:12)
Block(-5,8,7,LEAVES:12)
Block(-5,8,10,LEAVES:12)
Block(-5,9,-2,LEAVES:12)
Block(-5,9,5,LEAVES:12)
Block(-5,9,9,LEAVES:12)
Block(-5,9,15,LEAVES:12)
Block(-5,9,16,LEAVES:12)
Block(-5,10,-3,LEAVES:12)
Block(-5,10,-2,LEAVES:12)
Block(-5,10,6,LEAVES:12)
Block(-5,10,8,LEAVES:12)
Block(-5,10,9,LEAVES:12)
Block(-5,11,-7,LEAVES:12)
Block(-5,11,9,LEAVES:12)
Block(-5,11,10,LEAVES:12)
Block(-5,11,11,LEAVES:12)
Block(-5,11,12,LEAVES:12)
Block(-5,12,2,LEAVES:12)
Block(-5,12,3,LEAVES:12)
Block(-5,12,6,LEAVES:12)
Block(-5,12,10,LEAVES:12)
Block(-5,12,11,LOG:12)
Block(-5,12,12,LEAVES:12)
Block(-5,12,13,LEAVES:12)
Block(-5,13,6,LEAVES:12)
Block(-5,13,10,LEAVES:12)
Block(-5,13,11,LEAVES:12)
Block(-5,13,13,LEAVES:12)
Block(-5,14,0,LEAVES:12)
Block(-5,14,6,LEAVES:12)
Block(-5,14,7,LEAVES:12)
Block(-5,14,11,LEAVES:12)
Block(-5,14,12,LEAVES:12)
Block(-5,15,0,LEAVES:12)
Block(-5,15,4,LEAVES:12)
Block(-5,15,5,LEAVES:12)
Block(-5,15,6,LEAVES:12)
Block(-5,15,12,LEAVES:12)
Block(-5,16,2,LEAVES:12)
Block(-5,16,4,LEAVES:12)
Block(-5,16,11,LEAVES:12)
Block(-5,17,3,LEAVES:12)
Block(-5,18,1,LEAVES:12)
Block(-5,18,2,LEAVES:12)
Block(-5,18,3,LEAVES:12)
Block(-5,18,5,LEAVES:12)
Block(-5,18,6,LEAVES:12)
Block(-5,19,0,LEAVES:12)
Block(-5,19,1,LEAVES:12)
Block(-5,19,3,LEAVES:12)
Block(-5,19,8,LEAVES:12)
Block(-5,20,1,LEAVES:12)
Block(-4,7,-5,LEAVES:12)
Block(-4,7,3,LEAVES:12)
Block(-4,7,9,LEAVES:12)
Block(-4,7,10,LEAVES:12)
Block(-4,8,3,LEAVES:12)
Block(-4,8,7,LEAVES:12)
Block(-4,8,8,LEAVES:12)
Block(-4,8,9,LEAVES:12)
Block(-4,8,13,LEAVES:12)
Block(-4,9,5,LEAVES:12)
Block(-4,9,7,LEAVES:12)
Block(-4,9,11,LEAVES:12)
Block(-4,9,13,LEAVES:12)
Block(-4,10,-3,LEAVES:12)
Block(-4,10,6,LEAVES:12)
Block(-4,10,11,LEAVES:12)
Block(-4,10,13,LEAVES:12)
Block(-4,10,15,LEAVES:12)
Block(-4,11,-7,LEAVES:12)
Block(-4,11,-6,LEAVES:12)
Block(-4,11,4,LEAVES:12)
Block(-4,11,5,LEAVES:12)
Block(-4,11,6,LEAVES:12)
Block(-4,11,8,LEAVES:12)
Block(-4,11,9,LEAVES:12)
Block(-4,11,11,LEAVES:12)
Block(-4,11,12,LEAVES:12)
Block(-4,11,13,LEAVES:12)
Block(-4,11,15,LEAVES:12)
Block(-4,11,16,LEAVES:12)
Block(-4,12,3,LEAVES:12)
Block(-4,12,4,LEAVES:12)
Block(-4,12,6,LEAVES:12)
Block(-4,12,7,LEAVES:12)
Block(-4,12,9,LEAVES:12)
Block(-4,12,11,LOG:12)
Block(-4,12,12,LEAVES:12)
Block(-4,12,15,LEAVES:12)
Block(-4,12,16,LEAVES:12)
Block(-4,13,2,LEAVES:12)
Block(-4,13,4,LEAVES:12)
Block(-4,13,11,LEAVES:12)
Block(-4,14,-5,LEAVES:12)
Block(-4,14,-3,LEAVES:12)
Block(-4,14,1,LEAVES:12)
Block(-4,14,7,LEAVES:12)
Block(-4,14,8,LEAVES:12)
Block(-4,15,-5,LEAVES:12)
Block(-4,15,0,LEAVES:12)
Block(-4,15,1,LEAVES:12)
Block(-4,15,12,LEAVES:12)
Block(-4,15,13,LEAVES:12)
Block(-4,16,1,LEAVES:12)
Block(-4,16,2,LEAVES:12)
Block(-4,16,3,LEAVES:12)
Block(-4,16,4,LEAVES:12)
Block(-4,16,13,LEAVES:12)
Block(-4,16,14,LEAVES:12)
Block(-4,17,3,LOG:12)
Block(-4,17,4,LEAVES:12)
Block(-4,17,5,LEAVES:12)
Block(-4,17,13,LEAVES:12)
Block(-4,18,3,LEAVES:12)
Block(-4,18,5,LEAVES:12)
Block(-4,19,3,LEAVES:12)
Block(-4,19,4,LEAVES:12)
Block(-4,19,5,LEAVES:12)
Block(-4,20,4,LEAVES:12)
Block(-4,20,5,LEAVES:12)
Block(-4,21,0,LEAVES:12)
Block(-4,21,3,LEAVES:12)
Block(-3,6,-4,LEAVES:12)
Block(-3,6,5,LEAVES:12)
Block(-3,7,-4,LEAVES:12)
Block(-3,7,4,LEAVES:12)
Block(-3,7,10,LEAVES:12)
Block(-3,7,11,LEAVES:12)
Block(-3,8,-2,LEAVES:12)
Block(-3,8,3,LEAVES:12)
Block(-3,8,4,LEAVES:12)
Block(-3,8,6,LOG:12)
Block(-3,8,10,LEAVES:12)
Block(-3,9,-8,LEAVES:12)
Block(-3,9,4,LEAVES:12)
Block(-3,9,5,LEAVES:12)
Block(-3,9,6,LOG:12)
Block(-3,9,7,LEAVES:12)
Block(-3,9,13,LEAVES:12)
Block(-3,9,14,LEAVES:12)
Block(-3,10,-6,LEAVES:12)
Block(-3,10,-5,LEAVES:12)
Block(-3,10,-3,LEAVES:12)
Block(-3,10,6,LOG:12)
Block(-3,10,7,LOG:12)
Block(-3,10,8,LEAVES:12)
Block(-3,10,11,LEAVES:12)
Block(-3,10,13,LEAVES:12)
Block(-3,10,14,LEAVES:12)
Block(-3,11,-6,LEAVES:12)
Block(-3,11,-4,LEAVES:12)
Block(-3,11,-3,LEAVES:12)
Block(-3,11,6,LEAVES:12)
Block(-3,11,8,LEAVES:12)
Block(-3,12,6,LEAVES:12)
Block(-3,12,7,LEAVES:12)
Block(-3,12,8,LEAVES:12)
Block(-3,12,9,LEAVES:12)
Block(-3,12,10,LOG:12)
Block(-3,12,11,LOG:12)
Block(-3,12,12,LEAVES:12)
Block(-3,12,13,LEAVES:12)
Block(-3,12,15,LEAVES:12)
Block(-3,13,-2,LEAVES:12)
Block(-3,13,0,LEAVES:12)
Block(-3,13,1,LEAVES:12)
Block(-3,13,5,LEAVES:12)
Block(-3,13,7,LEAVES:12)
Block(-3,13,10,LOG:12)
Block(-3,13,11,LEAVES:12)
Block(-3,13,12,LEAVES:12)
Block(-3,13,13,LEAVES:12)
Block(-3,14,-5,LEAVES:12)
Block(-3,14,-4,LEAVES:12)
Block(-3,14,3,LEAVES:12)
Block(-3,14,5,LEAVES:12)
Block(-3,14,6,LEAVES:12)
Block(-3,14,8,LEAVES:12)
Block(-3,14,10,LEAVES:12)
Block(-3,14,11,LEAVES:12)
Block(-3,15,3,LEAVES:12)
Block(-3,15,5,LEAVES:12)
Block(-3,15,7,LEAVES:12)
Block(-3,16,1,LEAVES:12)
Block(-3,16,3,LEAVES:12)
Block(-3,16,4,LEAVES:12)
Block(-3,16,5,LEAVES:12)
Block(-3,16,7,LEAVES:12)
Block(-3,16,13,LEAVES:12)
Block(-3,16,15,LEAVES:12)
Block(-3,17,-1,LEAVES:12)
Block(-3,17,1,LEAVES:12)
Block(-3,17,2,LEAVES:12)
Block(-3,17,3,LOG:12)
Block(-3,17,4,LOG:12)
Block(-3,17,8,LEAVES:12)
Block(-3,17,13,LEAVES:12)
Block(-3,18,3,LEAVES:12)
Block(-3,20,4,LEAVES:12)
Block(-3,20,5,LEAVES:12)
Block(-3,21,0,LEAVES:12)
Block(-3,21,1,LEAVES:12)
Block(-3,21,5,LEAVES:12)
Block(-3,21,6,LEAVES:12)
Block(-3,22,5,LEAVES:12)
Block(-3,24,2,LEAVES:12)
Block(-3,24,4,LEAVES:12)
Block(-3,25,2,LEAVES:12)
Block(-2,6,-2,LEAVES:12)
Block(-2,6,8,LEAVES:12)
Block(-2,7,-8,LEAVES:12)
Block(-2,7,-4,LEAVES:12)
Block(-2,7,-3,LEAVES:12)
Block(-2,7,6,LEAVES:12)
Block(-2,7,8,LEAVES:12)
Block(-2,8,-8,LEAVES:12)
Block(-2,8,-7,LEAVES:12)
Block(-2,8,-3,LEAVES:12)
Block(-2,8,0,LEAVES:12)
Block(-2,8,6,LEAVES:12)
Block(-2,8,8,LEAVES:12)
Block(-2,8,10,LEAVES:12)
Block(-2,8,14,LEAVES:12)
Block(-2,9,-3,LEAVES:12)
Block(-2,9,4,LEAVES:12)
Block(-2,9,6,LEAVES:12)
Block(-2,9,7,LEAVES:12)
Block(-2,9,8,LEAVES:12)
Block(-2,9,10,LEAVES:12)
Block(-2,9,11,LEAVES:12)
Block(-2,9,14,LEAVES:12)
Block(-2,10,-5,LEAVES:12)
Block(-2,10,2,LEAVES:12)
Block(-2,10,4,LEAVES:12)
Block(-2,10,6,LEAVES:12)
Block(-2,10,7,LOG:12)
Block(-2,10,11,LEAVES:12)
Block(-2,10,16,LEAVES:12)
Block(-2,11,-4,LEAVES:12)
Block(-2,11,6,LEAVES:12)
Block(-2,11,7,LOG:12)
Block(-2,11,8,LOG:12)
Block(-2,11,10,LEAVES:12)
Block(-2,11,11,LEAVES:12)
Block(-2,12,-1,LEAVES:12)
Block(-2,12,0,LEAVES:12)
Block(-2,12,7,LEAVES:12)
Block(-2,12,8,LEAVES:12)
Block(-2,12,12,LEAVES:12)
Block(-2,12,13,LEAVES:12)
Block(-2,12,15,LEAVES:12)
Block(-2,13,-8,LEAVES:12)
Block(-2,13,-7,LEAVES:12)
Block(-2,13,-4,LEAVES:12)
Block(-2,13,0,LEAVES:12)
Block(-2,13,2,LEAVES:12)
Block(-2,13,7,LEAVES:12)
Block(-2,13,8,LEAVES:12)
Block(-2,13,10,LOG:12)
Block(-2,13,12,LEAVES:12)
Block(-2,13,13,LEAVES:12)
Block(-2,13,14,LEAVES:12)
Block(-2,13,15,LEAVES:12)
Block(-2,14,-4,LEAVES:12)
Block(-2,14,0,LEAVES:12)
Block(-2,14,6,LEAVES:12)
Block(-2,14,8,LEAVES:12)
Block(-2,14,9,LEAVES:12)
Block(-2,14,10,LEAVES:12)
Block(-2,14,14,LEAVES:12)
Block(-2,15,-4,LEAVES:12)
Block(-2,15,3,LEAVES:12)
Block(-2,15,5,LEAVES:12)
Block(-2,15,6,LEAVES:12)
Block(-2,15,8,LEAVES:12)
Block(-2,15,12,LEAVES:12)
Block(-2,15,16,LEAVES:12)
Block(-2,15,18,LEAVES:12)
Block(-2,15,19,LEAVES:12)
Block(-2,16,3,LEAVES:12)
Block(-2,16,13,LEAVES:12)
Block(-2,16,14,LEAVES:12)
Block(-2,17,0,LEAVES:12)
Block(-2,17,1,LEAVES:12)
Block(-2,17,3,LEAVES:12)
Block(-2,17,4,LOG:12)
Block(-2,17,5,LOG:12)
Block(-2,18,3,LEAVES:12)
Block(-2,18,5,LEAVES:12)
Block(-2,19,-1,LEAVES:12)
Block(-2,19,0,LEAVES:12)
Block(-2,19,2,LEAVES:12)
Block(-2,19,3,LEAVES:12)
Block(-2,19,11,LEAVES:12)
Block(-2,20,1,LEAVES:12)
Block(-2,20,2,LEAVES:12)
Block(-2,20,4,LEAVES:12)
Block(-2,20,10,LEAVES:12)
Block(-2,20,11,LEAVES:12)
Block(-2,21,1,LEAVES:12)
Block(-2,21,3,LEAVES:12)
Block(-2,21,4,LEAVES:12)
Block(-2,21,6,LEAVES:12)
Block(-2,23,5,LEAVES:12)
Block(-2,23,7,LEAVES:12)
Block(-2,23,8,LEAVES:12)
Block(-2,24,2,LEAVES:12)
Block(-2,24,3,LEAVES:12)
Block(-1,6,5,LEAVES:12)
Block(-1,7,9,LEAVES:12)
Block(-1,8,-7,LEAVES:12)
Block(-1,8,-1,LEAVES:12)
Block(-1,8,0,LEAVES:12)
Block(-1,8,6,LEAVES:12)
Block(-1,8,8,LEAVES:12)
Block(-1,8,9,LEAVES:12)
Block(-1,8,10,LEAVES:12)
Block(-1,8,16,LEAVES:12)
Block(-1,9,-7,LEAVES:12)
Block(-1,9,-3,LEAVES:12)
Block(-1,9,-2,LEAVES:12)
Block(-1,9,-1,LEAVES:12)
Block(-1,9,10,LEAVES:12)
Block(-1,9,14,LEAVES:12)
Block(-1,9,15,LEAVES:12)
Block(-1,10,-5,LEAVES:12)
Block(-1,10,-3,LEAVES:12)
Block(-1,10,3,LEAVES:12)
Block(-1,10,4,LEAVES:12)
Block(-1,10,7,LEAVES:12)
Block(-1,10,8,LEAVES:12)
Block(-1,10,10,LEAVES:12)
Block(-1,10,11,LEAVES:12)
Block(-1,10,15,LEAVES:12)
Block(-1,10,18,LEAVES:12)
Block(-1,11,-4,LEAVES:12)
Block(-1,11,-3,LOG:12)
Block(-1,11,-2,LOG:12)
Block(-1,11,6,LEAVES:12)
Block(-1,11,8,LOG:12)
Block(-1,11,10,LEAVES:12)
Block(-1,11,11,LEAVES:12)
Block(-1,11,15,LEAVES:12)
Block(-1,12,-6,LEAVES:12)
Block(-1,12,-5,LEAVES:12)
Block(-1,12,-4,LEAVES:12)
Block(-1,12,-2,LOG:12)
Block(-1,12,-1,LOG:12)
Block(-1,12,0,LOG:12)
Block(-1,12,3,LEAVES:12)
Block(-1,12,5,LEAVES:12)
Block(-1,12,6,LEAVES:12)
Block(-1,12,8,LOG:12)
Block(-1,12,9,LOG:12)
Block(-1,12,11,LEAVES:12)
Block(-1,12,13,LEAVES:12)
Block(-1,13,-7,LEAVES:12)
Block(-1,13,-6,LEAVES:12)
Block(-1,13,-4,LEAVES:12)
Block(-1,13,0,LOG:12)
Block(-1,13,1,LOG:12)
Block(-1,13,6,LEAVES:12)
Block(-1,13,9,LOG:12)
Block(-1,13,10,LOG:12)
Block(-1,13,14,LEAVES:12)
Block(-1,14,-6,LEAVES:12)
Block(-1,14,2,LEAVES:12)
Block(-1,14,3,LEAVES:12)
Block(-1,14,6,LEAVES:12)
Block(-1,14,9,LOG:12)
Block(-1,14,17,LEAVES:12)
Block(-1,14,18,LEAVES:12)
Block(-1,15,3,LEAVES:12)
Block(-1,15,9,LEAVES:12)
Block(-1,15,10,LEAVES:12)
Block(-1,15,11,LEAVES:12)
Block(-1,15,14,LEAVES:12)
Block(-1,15,18,LEAVES:12)
Block(-1,16,3,LEAVES:12)
Block(-1,16,5,LOG:12)
Block(-1,16,6,LOG:12)
Block(-1,16,14,LEAVES:12)
Block(-1,16,18,LEAVES:12)
Block(-1,17,-1,LEAVES:12)
Block(-1,17,0,LEAVES:12)
Block(-1,17,3,LEAVES:12)
Block(-1,17,4,LEAVES:12)
Block(-1,17,5,LOG:12)
Block(-1,17,8,LEAVES:12)
Block(-1,17,14,LEAVES:12)
Block(-1,18,-1,LEAVES:12)
Block(-1,18,0,LEAVES:12)
Block(-1,18,4,LEAVES:12)
Block(-1,18,5,LEAVES:12)
Block(-1,18,6,LEAVES:12)
Block(-1,18,7,LEAVES:12)
Block(-1,19,1,LEAVES:12)
Block(-1,19,2,LEAVES:12)
Block(-1,19,4,LEAVES:12)
Block(-1,19,6,LEAVES:12)
Block(-1,20,2,LEAVES:12)
Block(-1,20,4,LEAVES:12)
Block(-1,20,10,LEAVES:12)
Block(-1,21,3,LEAVES:12)
Block(-1,21,6,LEAVES:12)
Block(-1,21,7,LEAVES:12)
Block(-1,22,6,LEAVES:12)
Block(-1,22,7,LEAVES:12)
Block(-1,23,-1,LEAVES:12)
Block(-1,23,0,LEAVES:12)
Block(-1,23,3,LEAVES:12)
Block(-1,23,7,LEAVES:12)
Block(-1,24,3,LEAVES:12)
Block(-1,24,7,LEAVES:12)
Block(-1,24,8,LEAVES:12)
Block(-1,24,10,LEAVES:12)
Block(-1,25,3,LEAVES:12)
Block(-1,25,8,LEAVES:12)
Block(0,6,9,LEAVES:12)
Block(0,7,-5,LEAVES:12)
Block(0,7,5,LEAVES:12)
Block(0,7,6,LEAVES:12)
Block(0,7,9,LEAVES:12)
Block(0,8,-6,LEAVES:12)
Block(0,8,0,LEAVES:12)
Block(0,8,1,LEAVES:12)
Block(0,8,6,LEAVES:12)
Block(0,8,9,LEAVES:12)
Block(0,9,-7,LEAVES:12)
Block(0,9,-6,LEAVES:12)
Block(0,9,6,LEAVES:12)
Block(0,10,-6,LEAVES:12)
Block(0,10,-5,LEAVES:12)
Block(0,10,-4,LOG:12)
Block(0,10,-3,LEAVES:12)
Block(0,10,2,LEAVES:12)
Block(0,10,3,LEAVES:12)
Block(0,10,11,LEAVES:12)
Block(0,10,12,LEAVES:12)
Block(0,10,17,LEAVES:12)
Block(0,10,18,LEAVES:12)
Block(0,11,-4,LOG:12)
Block(0,11,-3,LOG:12)
Block(0,11,-2,LEAVES:12)
Block(0,11,8,LEAVES:12)
Block(0,11,9,LEAVES:12)
Block(0,11,10,LEAVES:12)
Block(0,11,11,LEAVES:12)
Block(0,11,12,LEAVES:12)
Block(0,11,15,LEAVES:12)
Block(0,11,16,LEAVES:12)
Block(0,11,17,LEAVES:12)
Block(0,12,-4,LEAVES:12)
Block(0,12,-2,LEAVES:12)
Block(0,12,4,LEAVES:12)
Block(0,12,5,LEAVES:12)
Block(0,12,9,LEAVES:12)
Block(0,12,13,LEAVES:12)
Block(0,12,15,LOG:12)
Block(0,12,16,LOG:12)
Block(0,13,-4,LEAVES:12)
Block(0,13,-3,LEAVES:12)
Block(0,13,1,LOG:12)
Block(0,13,2,LOG:12)
Block(0,13,7,LEAVES:12)
Block(0,13,14,LEAVES:12)
Block(0,14,-3,LEAVES:12)
Block(0,14,2,LOG:12)
Block(0,14,9,LOG:12)
Block(0,14,12,LEAVES:12)
Block(0,14,13,LEAVES:12)
Block(0,14,14,LEAVES:12)
Block(0,14,16,LEAVES:12)
Block(0,14,17,LEAVES:12)
Block(0,15,-4,LEAVES:12)
Block(0,15,7,LOG:12)
Block(0,15,11,LEAVES:12)
Block(0,15,12,LEAVES:12)
Block(0,15,14,LEAVES:12)
Block(0,15,19,LEAVES:12)
Block(0,16,2,LEAVES:12)
Block(0,16,3,LEAVES:12)
Block(0,16,6,LOG:12)
Block(0,16,7,LOG:12)
Block(0,16,9,LEAVES:12)
Block(0,16,12,LEAVES:12)
Block(0,17,3,LEAVES:12)
Block(0,17,9,LEAVES:12)
Block(0,18,0,LEAVES:12)
Block(0,18,6,LEAVES:12)
Block(0,18,7,LEAVES:12)
Block(0,18,11,LEAVES:12)
Block(0,19,0,LEAVES:12)
Block(0,19,1,LEAVES:12)
Block(0,19,4,LEAVES:12)
Block(0,19,5,LEAVES:12)
Block(0,19,6,LEAVES:12)
Block(0,20,1,LEAVES:12)
Block(0,20,2,LEAVES:12)
Block(0,20,4,LEAVES:12)
Block(0,20,7,LEAVES:12)
Block(0,20,8,LEAVES:12)
Block(0,20,10,LEAVES:12)
Block(0,21,3,LEAVES:12)
Block(0,21,7,LEAVES:12)
Block(0,21,9,LEAVES:12)
Block(0,21,10,LEAVES:12)
Block(0,22,1,LEAVES:12)
Block(0,22,2,LEAVES:12)
Block(0,22,3,LEAVES:12)
Block(0,22,5,LEAVES:12)
Block(0,22,6,LEAVES:12)
Block(0,23,0,LEAVES:12)
Block(0,23,1,LEAVES:12)
Block(0,23,3,LEAVES:12)
Block(0,23,8,LEAVES:12)
Block(0,23,11,LEAVES:12)
Block(0,23,13,LEAVES:12)
Block(0,23,14,LEAVES:12)
Block(0,24,1,LEAVES:12)
Block(0,24,8,LEAVES:12)
Block(0,24,9,LEAVES:12)
Block(1,6,4,LEAVES:12)
Block(1,6,5,LEAVES:12)
Block(1,7,-2,LEAVES:12)
Block(1,7,5,LEAVES:12)
Block(1,8,-4,LEAVES:12)
Block(1,8,-2,LEAVES:12)
Block(1,9,-4,LEAVES:12)
Block(1,9,-2,LEAVES:12)
Block(1,9,0,LEAVES:12)
Block(1,9,5,LEAVES:12)
Block(1,9,6,LEAVES:12)
Block(1,9,13,LEAVES:12)
Block(1,10,-6,LEAVES:12)
Block(1,10,-4,LEAVES:12)
Block(1,10,-3,LEAVES:12)
Block(1,10,-2,LEAVES:12)
Block(1,10,0,LEAVES:12)
Block(1,10,6,LEAVES:12)
Block(1,10,12,LEAVES:12)
Block(1,10,18,LEAVES:12)
Block(1,10,19,LEAVES:12)
Block(1,11,-8,LEAVES:12)
Block(1,11,-6,LEAVES:12)
Block(1,11,-4,LEAVES:12)
Block(1,11,-3,LEAVES:12)
Block(1,11,1,LEAVES:12)
Block(1,11,9,LEAVES:12)
Block(1,11,11,LEAVES:12)
Block(1,11,12,LEAVES:12)
Block(1,12,-4,LEAVES:12)
Block(1,12,4,LEAVES:12)
Block(1,12,12,LEAVES:12)
Block(1,12,13,LEAVES:12)
Block(1,12,14,LOG:12)
Block(1,12,15,LOG:12)
Block(1,13,1,LEAVES:12)
Block(1,13,4,LEAVES:12)
Block(1,13,12,LOG:12)
Block(1,13,13,LOG:12)
Block(1,13,14,LOG:12)
Block(1,13,15,LEAVES:12)
Block(1,13,16,LEAVES:12)
Block(1,14,-3,LEAVES:12)
Block(1,14,-2,LEAVES:12)
Block(1,14,2,LOG:12)
Block(1,14,3,LOG:12)
Block(1,14,8,LOG:12)
Block(1,14,9,LOG:12)
Block(1,14,10,LOG:12)
Block(1,14,11,LOG:12)
Block(1,14,12,LOG:12)
Block(1,14,14,LEAVES:12)
Block(1,14,16,LEAVES:12)
Block(1,15,-2,LEAVES:12)
Block(1,15,-1,LEAVES:12)
Block(1,15,4,LEAVES:12)
Block(1,15,7,LOG:12)
Block(1,15,8,LOG:12)
Block(1,15,14,LEAVES:12)
Block(1,15,15,LEAVES:12)
Block(1,16,-2,LEAVES:12)
Block(1,16,3,LEAVES:12)
Block(1,16,4,LEAVES:12)
Block(1,16,11,LEAVES:12)
Block(1,16,15,LEAVES:12)
Block(1,17,2,LEAVES:12)
Block(1,17,5,LEAVES:12)
Block(1,17,9,LEAVES:12)
Block(1,17,10,LEAVES:12)
Block(1,17,14,LEAVES:12)
Block(1,18,1,LEAVES:12)
Block(1,18,5,LEAVES:12)
Block(1,18,6,LEAVES:12)
Block(1,18,7,LEAVES:12)
Block(1,18,8,LEAVES:12)
Block(1,18,10,LEAVES:12)
Block(1,18,13,LEAVES:12)
Block(1,19,0,LEAVES:12)
Block(1,19,1,LEAVES:12)
Block(1,19,10,LEAVES:12)
Block(1,20,-4,LEAVES:12)
Block(1,20,1,LEAVES:12)
Block(1,20,2,LEAVES:12)
Block(1,20,3,LOG:12)
Block(1,20,4,LEAVES:12)
Block(1,20,8,LEAVES:12)
Block(1,21,3,LOG:12)
Block(1,21,4,LEAVES:12)
Block(1,21,5,LEAVES:12)
Block(1,21,9,LEAVES:12)
Block(1,22,3,LEAVES:12)
Block(1,22,5,LEAVES:12)
Block(1,22,12,LEAVES:12)
Block(1,22,13,LEAVES:12)
Block(1,23,3,LEAVES:12)
Block(1,23,4,LEAVES:12)
Block(1,23,5,LEAVES:12)
Block(1,23,6,LEAVES:12)
Block(1,23,9,LEAVES:12)
Block(1,23,13,LEAVES:12)
Block(1,24,4,LEAVES:12)
Block(1,24,9,LEAVES:12)
Block(1,24,13,LEAVES:12)
Block(1,25,3,LEAVES:12)
Block(1,25,9,LEAVES:12)
Block(2,6,4,LEAVES:12)
Block(2,7,-5,LEAVES:12)
Block(2,8,-1,LEAVES:12)
Block(2,8,7,LEAVES:12)
Block(2,8,20,LEAVES:12)
Block(2,9,-4,LEAVES:12)
Block(2,9,-3,LEAVES:12)
Block(2,9,-2,LEAVES:12)
Block(2,9,-1,LEAVES:12)
Block(2,9,6,LEAVES:12)
Block(2,9,7,LEAVES:12)
Block(2,9,16,LEAVES:12)
Block(2,9,19,LEAVES:12)
Block(2,9,20,LEAVES:12)
Block(2,10,-4,LEAVES:12)
Block(2,10,-3,LEAVES:12)
Block(2,10,14,LEAVES:12)
Block(2,10,15,LEAVES:12)
Block(2,10,16,LEAVES:12)
Block(2,11,-8,LEAVES:12)
Block(2,11,-7,LEAVES:12)
Block(2,11,-6,LEAVES:12)
Block(2,11,-3,LEAVES:12)
Block(2,11,-2,LEAVES:12)
Block(2,11,14,LEAVES:12)
Block(2,11,16,LEAVES:12)
Block(2,11,18,LEAVES:12)
Block(2,12,-4,LEAVES:12)
Block(2,12,-2,LEAVES:12)
Block(2,12,12,LEAVES:12)
Block(2,12,14,LEAVES:12)
Block(2,12,15,LEAVES:12)
Block(2,12,16,LEAVES:12)
Block(2,12,18,LEAVES:12)
Block(2,13,-7,LEAVES:12)
Block(2,13,-5,LEAVES:12)
Block(2,13,-4,LEAVES:12)
Block(2,13,8,LOG:12)
Block(2,13,10,LEAVES:12)
Block(2,13,12,LEAVES:12)
Block(2,13,14,LEAVES:12)
Block(2,13,15,LEAVES:12)
Block(2,13,19,LEAVES:12)
Block(2,14,3,LOG:12)
Block(2,14,8,LOG:12)
Block(2,14,14,LEAVES:12)
Block(2,15,4,LEAVES:12)
Block(2,16,-2,LEAVES:12)
Block(2,16,15,LEAVES:12)
Block(2,16,16,LEAVES:12)
Block(2,17,5,LEAVES:12)
Block(2,17,16,LEAVES:12)
Block(2,17,17,LEAVES:12)
Block(2,18,3,LEAVES:12)
Block(2,18,5,LEAVES:12)
Block(2,18,6,LEAVES:12)
Block(2,18,12,LEAVES:12)
Block(2,18,13,LEAVES:12)
Block(2,18,16,LEAVES:12)
Block(2,19,0,LEAVES:12)
Block(2,19,3,LOG:12)
Block(2,19,4,LOG:12)
Block(2,19,5,LEAVES:12)
Block(2,19,6,LEAVES:12)
Block(2,19,7,LEAVES:12)
Block(2,19,10,LEAVES:12)
Block(2,19,11,LEAVES:12)
Block(2,19,12,LEAVES:12)
Block(2,20,-4,LEAVES:12)
Block(2,20,-3,LEAVES:12)
Block(2,20,1,LEAVES:12)
Block(2,20,3,LOG:12)
Block(2,20,4,LEAVES:12)
Block(2,20,5,LEAVES:12)
Block(2,20,7,LEAVES:12)
Block(2,20,8,LEAVES:12)
Block(2,20,10,LEAVES:12)
Block(2,21,-1,LEAVES:12)
Block(2,21,1,LEAVES:12)
Block(2,21,3,LEAVES:12)
Block(2,21,4,LEAVES:12)
Block(2,21,8,LEAVES:12)
Block(2,21,9,LEAVES:12)
Block(2,22,3,LEAVES:12)
Block(2,22,7,LEAVES:12)
Block(2,22,8,LEAVES:12)
Block(2,22,9,LEAVES:12)
Block(2,22,11,LEAVES:12)
Block(2,22,12,LEAVES:12)
Block(2,23,-2,LEAVES:12)
Block(2,23,0,LEAVES:12)
Block(2,23,6,LEAVES:12)
Block(2,23,7,LEAVES:12)
Block(2,23,9,LEAVES:12)
Block(2,23,14,LEAVES:12)
Block(2,24,-2,LEAVES:12)
Block(2,24,4,LEAVES:12)
Block(2,24,5,LEAVES:12)
Block(2,24,7,LEAVES:12)
Block(2,25,5,LEAVES:12)
Block(2,25,6,LEAVES:12)
Block(2,26,5,LEAVES:12)
Block(3,6,17,LEAVES:12)
Block(3,7,-6,LEAVES:12)
Block(3,7,-1,LEAVES:12)
Block(3,8,-5,LEAVES:12)
Block(3,8,-4,LEAVES:12)
Block(3,8,-1,LEAVES:12)
Block(3,8,7,LEAVES:12)
Block(3,9,-4,LEAVES:12)
Block(3,9,13,LEAVES:12)
Block(3,9,19,LEAVES:12)
Block(3,10,-4,LEAVES:12)
Block(3,10,15,LEAVES:12)
Block(3,10,16,LEAVES:12)
Block(3,10,17,LEAVES:12)
Block(3,11,-8,LEAVES:12)
Block(3,11,-7,LEAVES:12)
Block(3,11,14,LEAVES:12)
Block(3,11,16,LEAVES:12)
Block(3,11,17,LEAVES:12)
Block(3,12,-2,LEAVES:12)
Block(3,12,-1,LEAVES:12)
Block(3,12,0,LEAVES:12)
Block(3,13,-6,LEAVES:12)
Block(3,13,-5,LEAVES:12)
Block(3,13,-1,LEAVES:12)
Block(3,13,3,LOG:12)
Block(3,13,4,LOG:12)
Block(3,13,8,LOG:12)
Block(3,13,11,LEAVES:12)
Block(3,13,12,LEAVES:12)
Block(3,13,15,LEAVES:12)
Block(3,13,16,LEAVES:12)
Block(3,13,17,LEAVES:12)
Block(3,13,19,LEAVES:12)
Block(3,14,-6,LEAVES:12)
Block(3,14,-4,LEAVES:12)
Block(3,14,-3,LEAVES:12)
Block(3,14,-2,LOG:12)
Block(3,14,-1,LOG:12)
Block(3,14,2,LOG:12)
Block(3,14,3,LOG:12)
Block(3,14,14,LEAVES:12)
Block(3,14,16,LEAVES:12)
Block(3,14,17,LEAVES:12)
Block(3,15,-6,LEAVES:12)
Block(3,15,-1,LOG:12)
Block(3,15,0,LOG:12)
Block(3,15,1,LOG:12)
Block(3,15,2,LOG:12)
Block(3,15,11,LEAVES:12)
Block(3,15,13,LEAVES:12)
Block(3,15,14,LEAVES:12)
Block(3,16,-1,LEAVES:12)
Block(3,16,1,LOG:12)
Block(3,17,1,LEAVES:12)
Block(3,17,2,LEAVES:12)
Block(3,17,8,LEAVES:12)
Block(3,17,10,LOG:12)
Block(3,18,-5,LEAVES:12)
Block(3,18,4,LOG:12)
Block(3,18,6,LEAVES:12)
Block(3,18,7,LEAVES:12)
Block(3,18,10,LOG:12)
Block(3,18,13,LEAVES:12)
Block(3,18,14,LEAVES:12)
Block(3,19,-3,LEAVES:12)
Block(3,19,-2,LEAVES:12)
Block(3,19,0,LEAVES:12)
Block(3,19,3,LEAVES:12)
Block(3,19,4,LOG:12)
Block(3,19,5,LEAVES:12)
Block(3,19,6,LEAVES:12)
Block(3,19,7,LEAVES:12)
Block(3,19,9,LOG:12)
Block(3,19,10,LOG:12)
Block(3,20,-3,LEAVES:12)
Block(3,20,-1,LEAVES:12)
Block(3,20,0,LEAVES:12)
Block(3,20,7,LEAVES:12)
Block(3,20,8,LEAVES:12)
Block(3,20,9,LOG:12)
Block(3,20,10,LEAVES:12)
Block(3,21,0,LEAVES:12)
Block(3,21,1,LEAVES:12)
Block(3,21,4,LEAVES:12)
Block(3,21,5,LEAVES:12)
Block(3,21,9,LOG:12)
Block(3,21,10,LEAVES:12)
Block(3,21,11,LEAVES:12)
Block(3,22,1,LEAVES:12)
Block(3,22,3,LEAVES:12)
Block(3,22,4,LEAVES:12)
Block(3,22,5,LEAVES:12)
Block(3,22,9,LEAVES:12)
Block(3,22,11,LEAVES:12)
Block(3,23,-2,LEAVES:12)
Block(3,23,-1,LEAVES:12)
Block(3,23,0,LEAVES:12)
Block(3,23,2,LEAVES:12)
Block(3,23,3,LEAVES:12)
Block(3,23,9,LEAVES:12)
Block(3,23,10,LEAVES:12)
Block(3,24,10,LEAVES:12)
Block(3,25,9,LEAVES:12)
Block(4,0,7,LOG:12)
Block(4,0,8,LOG:12)
Block(4,1,7,LOG:12)
Block(4,2,7,LOG:12)
Block(4,3,7,LOG:12)
Block(4,4,7,LOG:12)
Block(4,5,7,LOG:12)
Block(4,5,18,LEAVES:12)
Block(4,6,-5,LEAVES:12)
Block(4,6,18,LEAVES:12)
Block(4,7,-6,LEAVES:12)
Block(4,7,-5,LEAVES:12)
Block(4,7,20,LEAVES:12)
Block(4,8,-5,LEAVES:12)
Block(4,8,-3,LEAVES:12)
Block(4,8,14,LEAVES:12)
Block(4,9,-9,LEAVES:12)
Block(4,9,16,LEAVES:12)
Block(4,9,17,LEAVES:12)
Block(4,9,19,LEAVES:12)
Block(4,10,-7,LEAVES:12)
Block(4,10,-6,LEAVES:12)
Block(4,10,-5,LEAVES:12)
Block(4,10,-4,LEAVES:12)
Block(4,10,13,LEAVES:12)
Block(4,10,14,LEAVES:12)
Block(4,10,16,LEAVES:12)
Block(4,10,17,LEAVES:12)
Block(4,10,18,LEAVES:12)
Block(4,10,19,LEAVES:12)
Block(4,11,-7,LEAVES:12)
Block(4,11,-5,LEAVES:12)
Block(4,11,-4,LEAVES:12)
Block(4,11,14,LEAVES:12)
Block(4,12,-4,LOG:12)
Block(4,12,-3,LOG:12)
Block(4,12,-1,LEAVES:12)
Block(4,12,8,LOG:12)
Block(4,12,14,LEAVES:12)
Block(4,12,20,LEAVES:12)
Block(4,12,22,LEAVES:12)
Block(4,12,23,LEAVES:12)
Block(4,13,-6,LEAVES:12)
Block(4,13,-3,LOG:12)
Block(4,13,-2,LOG:12)
Block(4,13,-1,LEAVES:12)
Block(4,13,0,LEAVES:12)
Block(4,13,4,LOG:12)
Block(4,13,8,LOG:12)
Block(4,13,10,LEAVES:12)
Block(4,13,11,LEAVES:12)
Block(4,13,17,LEAVES:12)
Block(4,13,18,LEAVES:12)
Block(4,14,-6,LEAVES:12)
Block(4,14,-5,LEAVES:12)
Block(4,14,-2,LOG:12)
Block(4,14,16,LEAVES:12)
Block(4,14,17,LEAVES:12)
Block(4,14,18,LEAVES:12)
Block(4,15,1,LEAVES:12)
Block(4,15,9,LOG:12)
Block(4,15,10,LOG:12)
Block(4,15,12,LEAVES:12)
Block(4,15,13,LEAVES:12)
Block(4,15,17,LEAVES:12)
Block(4,16,-5,LEAVES:12)
Block(4,16,-1,LEAVES:12)
Block(4,16,0,LEAVES:12)
Block(4,16,1,LOG:12)
Block(4,16,4,LOG:12)
Block(4,16,10,LOG:12)
Block(4,16,15,LEAVES:12)
Block(4,17,-5,LEAVES:12)
Block(4,17,-4,LEAVES:12)
Block(4,17,0,LOG:12)
Block(4,17,1,LOG:12)
Block(4,17,3,LEAVES:12)
Block(4,17,4,LOG:12)
Block(4,17,6,LEAVES:12)
Block(4,17,10,LOG:12)
Block(4,17,11,LEAVES:12)
Block(4,17,16,LEAVES:12)
Block(4,18,0,LEAVES:12)
Block(4,18,2,LEAVES:12)
Block(4,18,3,LEAVES:12)
Block(4,18,4,LOG:12)
Block(4,18,6,LEAVES:12)
Block(4,18,9,LEAVES:12)
Block(4,18,11,LEAVES:12)
Block(4,18,15,LEAVES:12)
Block(4,18,16,LEAVES:12)
Block(4,19,-2,LEAVES:12)
Block(4,19,3,LEAVES:12)
Block(4,19,9,LEAVES:12)
Block(4,19,11,LEAVES:12)
Block(4,19,13,LEAVES:12)
Block(4,20,-1,LEAVES:12)
Block(4,20,3,LEAVES:12)
Block(4,20,7,LEAVES:12)
Block(4,20,9,LEAVES:12)
Block(4,20,10,LEAVES:12)
Block(4,20,11,LEAVES:12)
Block(4,20,13,LEAVES:12)
Block(4,21,-1,LEAVES:12)
Block(4,21,0,LEAVES:12)
Block(4,21,2,LEAVES:12)
Block(4,21,3,LEAVES:12)
Block(4,21,5,LEAVES:12)
Block(4,21,7,LEAVES:12)
Block(4,21,9,LEAVES:12)
Block(4,21,10,LEAVES:12)
Block(4,21,14,LEAVES:12)
Block(4,22,-5,LEAVES:12)
Block(4,22,-4,LEAVES:12)
Block(4,22,-1,LEAVES:12)
Block(4,22,3,LEAVES:12)
Block(4,22,5,LEAVES:12)
Block(4,22,6,LEAVES:12)
Block(4,22,7,LEAVES:12)
Block(4,22,9,LEAVES:12)
Block(4,23,-1,LEAVES:12)
Block(4,23,1,LEAVES:12)
Block(4,23,2,LEAVES:12)
Block(4,23,3,LEAVES:12)
Block(4,23,6,LEAVES:12)
Block(4,24,-1,LEAVES:12)
Block(4,24,4,LEAVES:12)
Block(4,24,10,LEAVES:12)
Block(4,24,11,LEAVES:12)
Block(4,25,11,LEAVES:12)
Block(4,25,12,LEAVES:12)
Block(4,26,11,LEAVES:12)
Block(5,0,6,LOG:12)
Block(5,0,7,LOG:12)
Block(5,0,8,LOG:12)
Block(5,1,6,LOG:12)
Block(5,1,7,LOG:12)
Block(5,1,8,LOG:12)
Block(5,2,6,LOG:12)
Block(5,2,7,LOG:12)
Block(5,3,6,LOG:12)
Block(5,3,7,LOG:12)
Block(5,4,6,LOG:12)
Block(5,4,7,LOG:12)
Block(5,5,6,LOG:12)
Block(5,5,7,LOG:12)
Block(5,5,20,LEAVES:12)
Block(5,6,-3,LEAVES:12)
Block(5,6,6,LOG:12)
Block(5,6,7,LOG:12)
Block(5,6,8,LOG:12)
Block(5,6,14,LEAVES:12)
Block(5,6,18,LEAVES:12)
Block(5,6,19,LEAVES:12)
Block(5,7,-9,LEAVES:12)
Block(5,7,-6,LEAVES:12)
Block(5,7,-5,LEAVES:12)
Block(5,7,-4,LEAVES:12)
Block(5,7,7,LOG:12)
Block(5,7,14,LEAVES:12)
Block(5,7,15,LEAVES:12)
Block(5,7,19,LEAVES:12)
Block(5,7,22,LEAVES:12)
Block(5,8,-9,LEAVES:12)
Block(5,8,-8,LEAVES:12)
Block(5,8,-4,LEAVES:12)
Block(5,8,-1,LEAVES:12)
Block(5,8,7,LOG:12)
Block(5,8,19,LEAVES:12)
Block(5,9,-4,LEAVES:12)
Block(5,9,-3,LEAVES:12)
Block(5,9,7,LOG:12)
Block(5,9,12,LEAVES:12)
Block(5,9,13,LEAVES:12)
Block(5,9,17,LEAVES:12)
Block(5,10,-6,LEAVES:12)
Block(5,10,-4,LEAVES:12)
Block(5,10,-3,LEAVES:12)
Block(5,10,13,LEAVES:12)
Block(5,10,18,LEAVES:12)
Block(5,11,-5,LEAVES:12)
Block(5,11,8,LOG:12)
Block(5,11,21,LEAVES:12)
Block(5,11,22,LEAVES:12)
Block(5,12,-4,LOG:12)
Block(5,12,-2,LEAVES:12)
Block(5,12,-1,LEAVES:12)
Block(5,12,5,LOG:12)
Block(5,12,8,LOG:12)
Block(5,12,13,LEAVES:12)
Block(5,12,14,LEAVES:12)
Block(5,12,15,LEAVES:12)
Block(5,12,18,LEAVES:12)
Block(5,12,22,LEAVES:12)
Block(5,13,-9,LEAVES:12)
Block(5,13,-8,LEAVES:12)
Block(5,13,-5,LEAVES:12)
Block(5,13,-1,LEAVES:12)
Block(5,13,4,LOG:12)
Block(5,13,5,LOG:12)
Block(5,13,8,LOG:12)
Block(5,13,9,LOG:12)
Block(5,13,14,LEAVES:12)
Block(5,13,18,LEAVES:12)
Block(5,13,22,LEAVES:12)
Block(5,14,-5,LEAVES:12)
Block(5,14,-1,LEAVES:12)
Block(5,14,4,LOG:12)
Block(5,14,9,LOG:12)
Block(5,14,17,LEAVES:12)
Block(5,14,18,LEAVES:12)
Block(5,15,-5,LEAVES:12)
Block(5,15,4,LOG:12)
Block(5,15,9,LOG:12)
Block(5,15,12,LEAVES:12)
Block(5,15,13,LEAVES:12)
Block(5,16,4,LOG:12)
Block(5,16,12,LEAVES:12)
Block(5,17,-4,LEAVES:12)
Block(5,17,0,LOG:12)
Block(5,17,1,LEAVES:12)
Block(5,17,2,LEAVES:12)
Block(5,17,3,LEAVES:12)
Block(5,17,8,LEAVES:12)
Block(5,18,-4,LEAVES:12)
Block(5,18,0,LOG:12)
Block(5,18,1,LEAVES:12)
Block(5,18,2,LEAVES:12)
Block(5,18,12,LEAVES:12)
Block(5,18,15,LEAVES:12)
Block(5,19,-2,LEAVES:12)
Block(5,19,-1,LOG:12)
Block(5,19,0,LOG:12)
Block(5,19,9,LEAVES:12)
Block(5,19,11,LEAVES:12)
Block(5,19,12,LEAVES:12)
Block(5,20,-1,LEAVES:12)
Block(5,20,2,LEAVES:12)
Block(5,20,3,LEAVES:12)
Block(5,21,-3,LEAVES:12)
Block(5,21,-2,LEAVES:12)
Block(5,21,-1,LEAVES:12)
Block(5,21,1,LEAVES:12)
Block(5,21,2,LEAVES:12)
Block(5,21,3,LEAVES:12)
Block(5,21,6,LEAVES:12)
Block(5,21,7,LEAVES:12)
Block(5,21,10,LEAVES:12)
Block(5,21,11,LEAVES:12)
Block(5,22,-4,LEAVES:12)
Block(5,22,-3,LEAVES:12)
Block(5,22,-1,LEAVES:12)
Block(5,22,4,LEAVES:12)
Block(5,22,6,LEAVES:12)
Block(5,22,9,LEAVES:12)
Block(5,22,11,LEAVES:12)
Block(5,22,13,LEAVES:12)
Block(5,22,15,LEAVES:12)
Block(5,23,-3,LEAVES:12)
Block(5,23,1,LEAVES:12)
Block(5,23,6,LEAVES:12)
Block(5,23,8,LEAVES:12)
Block(5,23,9,LEAVES:12)
Block(5,23,13,LEAVES:12)
Block(5,24,1,LEAVES:12)
Block(6,0,6,LOG:12)
Block(6,0,7,LOG:12)
Block(6,0,8,LOG:12)
Block(6,1,7,LOG:12)
Block(6,5,7,LOG:12)
Block(6,6,7,LOG:12)
Block(6,6,8,LOG:12)
Block(6,7,7,LOG:12)
Block(6,7,8,LOG:12)
Block(6,7,15,LEAVES:12)
Block(6,7,21,LEAVES:12)
Block(6,7,22,LEAVES:12)
Block(6,8,-8,LEAVES:12)
Block(6,8,-2,LEAVES:12)
Block(6,8,-1,LEAVES:12)
Block(6,8,7,LOG:12)
Block(6,8,8,LOG:12)
Block(6,8,15,LEAVES:12)
Block(6,8,19,LEAVES:12)
Block(6,8,20,LEAVES:12)
Block(6,8,21,LEAVES:12)
Block(6,9,-8,LEAVES:12)
Block(6,9,-4,LEAVES:12)
Block(6,9,-3,LEAVES:12)
Block(6,9,-2,LEAVES:12)
Block(6,9,7,LOG:12)
Block(6,9,8,LOG:12)
Block(6,9,12,LEAVES:12)
Block(6,9,17,LEAVES:12)
Block(6,9,19,LEAVES:12)
Block(6,10,-6,LEAVES:12)
Block(6,10,-4,LEAVES:12)
Block(6,10,6,LOG:12)
Block(6,10,7,LOG:12)
Block(6,10,8,LOG:12)
Block(6,10,18,LEAVES:12)
Block(6,11,-5,LOG:12)
Block(6,11,-4,LOG:12)
Block(6,11,6,LOG:12)
Block(6,11,7,LOG:12)
Block(6,11,8,LOG:12)
Block(6,11,15,LEAVES:12)
Block(6,11,16,LEAVES:12)
Block(6,11,17,LEAVES:12)
Block(6,11,18,LEAVES:12)
Block(6,11,20,LEAVES:12)
Block(6,11,21,LEAVES:12)
Block(6,12,-7,LEAVES:12)
Block(6,12,-6,LEAVES:12)
Block(6,12,-5,LEAVES:12)
Block(6,12,-4,LOG:12)
Block(6,12,-3,LEAVES:12)
Block(6,12,-2,LEAVES:12)
Block(6,12,5,LOG:12)
Block(6,12,6,LOG:12)
Block(6,12,8,LOG:12)
Block(6,12,14,LEAVES:12)
Block(6,12,15,LEAVES:12)
Block(6,12,16,LEAVES:12)
Block(6,12,18,LEAVES:12)
Block(6,12,23,LEAVES:12)
Block(6,13,-8,LEAVES:12)
Block(6,13,-7,LEAVES:12)
Block(6,13,-5,LEAVES:12)
Block(6,13,0,LEAVES:12)
Block(6,13,8,LOG:12)
Block(6,13,16,LEAVES:12)
Block(6,14,-7,LEAVES:12)
Block(6,14,14,LEAVES:12)
Block(6,15,9,LOG:12)
Block(6,15,14,LEAVES:12)
Block(6,16,-2,LEAVES:12)
Block(6,16,4,LOG:12)
Block(6,16,9,LOG:12)
Block(6,16,16,LEAVES:12)
Block(6,17,-3,LEAVES:12)
Block(6,17,1,LEAVES:12)
Block(6,17,3,LEAVES:12)
Block(6,17,4,LOG:12)
Block(6,17,10,LEAVES:12)
Block(6,17,12,LEAVES:12)
Block(6,18,-4,LEAVES:12)
Block(6,18,-3,LEAVES:12)
Block(6,18,5,LEAVES:12)
Block(6,18,8,LEAVES:12)
Block(6,18,9,LEAVES:12)
Block(6,18,12,LEAVES:12)
Block(6,18,13,LEAVES:12)
Block(6,18,15,LEAVES:12)
Block(6,19,-3,LEAVES:12)
Block(6,19,-2,LEAVES:12)
Block(6,19,-1,LOG:12)
Block(6,19,0,LEAVES:12)
Block(6,19,4,LEAVES:12)
Block(6,19,5,LEAVES:12)
Block(6,19,9,LEAVES:12)
Block(6,19,12,LEAVES:12)
Block(6,19,14,LEAVES:12)
Block(6,19,15,LEAVES:12)
Block(6,20,-1,LOG:12)
Block(6,20,0,LEAVES:12)
Block(6,20,1,LEAVES:12)
Block(6,20,3,LEAVES:12)
Block(6,20,4,LEAVES:12)
Block(6,20,9,LEAVES:12)
Block(6,21,-1,LEAVES:12)
Block(6,21,1,LEAVES:12)
Block(6,21,5,LEAVES:12)
Block(6,21,6,LEAVES:12)
Block(6,21,16,LEAVES:12)
Block(6,21,18,LEAVES:12)
Block(6,21,19,LEAVES:12)
Block(6,22,-1,LEAVES:12)
Block(6,22,0,LEAVES:12)
Block(6,22,11,LEAVES:12)
Block(6,22,12,LEAVES:12)
Block(6,22,13,LEAVES:12)
Block(6,22,14,LEAVES:12)
Block(6,23,0,LEAVES:12)
Block(6,23,7,LEAVES:12)
Block(6,23,8,LEAVES:12)
Block(6,23,12,LEAVES:12)
Block(6,24,-1,LEAVES:12)
Block(6,24,10,LEAVES:12)
Block(7,6,17,LEAVES:12)
Block(7,7,-6,LEAVES:12)
Block(7,7,16,LEAVES:12)
Block(7,7,22,LEAVES:12)
Block(7,7,23,LEAVES:12)
Block(7,8,-7,LEAVES:12)
Block(7,8,-1,LEAVES:12)
Block(7,8,0,LEAVES:12)
Block(7,8,7,LOG:12)
Block(7,8,15,LEAVES:12)
Block(7,8,16,LEAVES:12)
Block(7,9,-8,LEAVES:12)
Block(7,9,-7,LEAVES:12)
Block(7,9,6,LOG:12)
Block(7,9,7,LOG:12)
Block(7,9,8,LOG:12)
Block(7,9,16,LEAVES:12)
Block(7,9,17,LEAVES:12)
Block(7,9,18,LEAVES:12)
Block(7,9,19,LEAVES:12)
Block(7,10,-7,LEAVES:12)
Block(7,10,-6,LEAVES:12)
Block(7,10,-5,LEAVES:12)
Block(7,10,-4,LEAVES:12)
Block(7,10,7,LOG:12)
Block(7,10,8,LOG:12)
Block(7,10,16,LOG:12)
Block(7,10,17,LOG:12)
Block(7,10,18,LOG:12)
Block(7,10,19,LEAVES:12)
Block(7,10,20,LEAVES:12)
Block(7,11,-5,LOG:12)
Block(7,11,-4,LEAVES:12)
Block(7,11,-3,LEAVES:12)
Block(7,11,15,LEAVES:12)
Block(7,11,18,LEAVES:12)
Block(7,11,20,LEAVES:12)
Block(7,12,-5,LEAVES:12)
Block(7,12,-3,LEAVES:12)
Block(7,12,18,LEAVES:12)
Block(7,12,19,LEAVES:12)
Block(7,13,-5,LEAVES:12)
Block(7,13,-4,LEAVES:12)
Block(7,13,19,LEAVES:12)
Block(7,14,-4,LEAVES:12)
Block(7,14,16,LEAVES:12)
Block(7,14,18,LEAVES:12)
Block(7,15,-5,LEAVES:12)
Block(7,15,10,LEAVES:12)
Block(7,15,14,LEAVES:12)
Block(7,15,15,LEAVES:12)
Block(7,16,1,LEAVES:12)
Block(7,16,2,LEAVES:12)
Block(7,16,9,LOG:12)
Block(7,16,10,LEAVES:12)
Block(7,16,11,LEAVES:12)
Block(7,16,15,LEAVES:12)
Block(7,16,18,LEAVES:12)
Block(7,17,-1,LEAVES:12)
Block(7,17,1,LEAVES:12)
Block(7,17,4,LOG:12)
Block(7,17,7,LEAVES:12)
Block(7,17,8,LEAVES:12)
Block(7,17,9,LOG:12)
Block(7,17,10,LOG:12)
Block(7,17,15,LEAVES:12)
Block(7,18,-1,LEAVES:12)
Block(7,18,1,LEAVES:12)
Block(7,18,3,LEAVES:12)
Block(7,18,4,LOG:12)
Block(7,18,8,LEAVES:12)
Block(7,18,13,LEAVES:12)
Block(7,19,-3,LEAVES:12)
Block(7,19,-1,LEAVES:12)
Block(7,19,0,LEAVES:12)
Block(7,19,1,LEAVES:12)
Block(7,19,3,LEAVES:12)
Block(7,19,4,LEAVES:12)
Block(7,19,14,LEAVES:12)
Block(7,20,-5,LEAVES:12)
Block(7,20,-3,LEAVES:12)
Block(7,20,-1,LEAVES:12)
Block(7,20,0,LEAVES:12)
Block(7,20,1,LEAVES:12)
Block(7,20,4,LEAVES:12)
Block(7,20,8,LEAVES:12)
Block(7,20,9,LEAVES:12)
Block(7,20,17,LEAVES:12)
Block(7,20,18,LEAVES:12)
Block(7,21,-1,LEAVES:12)
Block(7,21,9,LEAVES:12)
Block(7,21,10,LEAVES:12)
Block(7,21,11,LEAVES:12)
Block(7,21,14,LEAVES:12)
Block(7,21,18,LEAVES:12)
Block(7,22,12,LEAVES:12)
Block(7,22,14,LEAVES:12)
Block(7,22,18,LEAVES:12)
Block(7,23,0,LEAVES:12)
Block(7,23,1,LEAVES:12)
Block(7,23,2,LEAVES:12)
Block(7,23,4,LEAVES:12)
Block(7,23,7,LEAVES:12)
Block(7,23,14,LEAVES:12)
Block(7,24,1,LEAVES:12)
Block(7,24,2,LEAVES:12)
Block(7,24,7,LEAVES:12)
Block(7,25,1,LEAVES:12)
Block(8,6,20,LEAVES:12)
Block(8,7,-3,LEAVES:12)
Block(8,7,18,LEAVES:12)
Block(8,7,20,LEAVES:12)
Block(8,8,-5,LEAVES:12)
Block(8,8,-3,LEAVES:12)
Block(8,8,18,LEAVES:12)
Block(8,8,20,LEAVES:12)
Block(8,8,22,LEAVES:12)
Block(8,9,-5,LEAVES:12)
Block(8,9,-3,LEAVES:12)
Block(8,9,-1,LEAVES:12)
Block(8,9,7,LOG:12)
Block(8,9,16,LEAVES:12)
Block(8,9,18,LEAVES:12)
Block(8,9,19,LEAVES:12)
Block(8,9,20,LEAVES:12)
Block(8,9,22,LEAVES:12)
Block(8,10,-7,LEAVES:12)
Block(8,10,-5,LEAVES:12)
Block(8,10,-4,LEAVES:12)
Block(8,10,-3,LEAVES:12)
Block(8,10,-1,LEAVES:12)
Block(8,10,6,LOG:12)
Block(8,10,7,LOG:12)
Block(8,10,14,LEAVES:12)
Block(8,10,15,LOG:12)
Block(8,10,16,LOG:12)
Block(8,10,18,LEAVES:12)
Block(8,10,19,LEAVES:12)
Block(8,10,23,LEAVES:12)
Block(8,11,-9,LEAVES:12)
Block(8,11,-7,LEAVES:12)
Block(8,11,-5,LEAVES:12)
Block(8,11,-4,LEAVES:12)
Block(8,11,0,LEAVES:12)
Block(8,11,7,LOG:12)
Block(8,11,14,LOG:12)
Block(8,11,15,LOG:12)
Block(8,11,18,LEAVES:12)
Block(8,12,-5,LEAVES:12)
Block(8,13,17,LEAVES:12)
Block(8,13,19,LEAVES:12)
Block(8,13,20,LEAVES:12)
Block(8,14,-4,LEAVES:12)
Block(8,14,-3,LEAVES:12)
Block(8,14,16,LEAVES:12)
Block(8,14,17,LEAVES:12)
Block(8,14,20,LEAVES:12)
Block(8,14,21,LEAVES:12)
Block(8,15,-3,LEAVES:12)
Block(8,15,-2,LEAVES:12)
Block(8,15,3,LEAVES:12)
Block(8,15,12,LEAVES:12)
Block(8,15,20,LEAVES:12)
Block(8,16,-3,LEAVES:12)
Block(8,16,-2,LEAVES:12)
Block(8,16,3,LEAVES:12)
Block(8,16,11,LEAVES:12)
Block(8,16,17,LEAVES:12)
Block(8,16,18,LEAVES:12)
Block(8,17,2,LEAVES:12)
Block(8,17,5,LEAVES:12)
Block(8,17,7,LEAVES:12)
Block(8,17,10,LOG:12)
Block(8,17,11,LOG:12)
Block(8,17,15,LEAVES:12)
Block(8,17,16,LEAVES:12)
Block(8,17,17,LEAVES:12)
Block(8,18,-1,LEAVES:12)
Block(8,18,1,LEAVES:12)
Block(8,18,2,LEAVES:12)
Block(8,18,3,LOG:12)
Block(8,18,4,LOG:12)
Block(8,18,11,LOG:12)
Block(8,18,12,LOG:12)
Block(8,18,13,LOG:12)
Block(8,18,15,LEAVES:12)
Block(8,19,1,LEAVES:12)
Block(8,19,2,LEAVES:12)
Block(8,19,4,LEAVES:12)
Block(8,19,10,LEAVES:12)
Block(8,19,13,LOG:12)
Block(8,19,14,LEAVES:12)
Block(8,20,-4,LEAVES:12)
Block(8,20,-3,LEAVES:12)
Block(8,20,0,LEAVES:12)
Block(8,20,1,LEAVES:12)
Block(8,20,3,LEAVES:12)
Block(8,20,4,LEAVES:12)
Block(8,20,9,LEAVES:12)
Block(8,20,10,LEAVES:12)
Block(8,20,12,LEAVES:12)
Block(8,20,13,LEAVES:12)
Block(8,20,14,LEAVES:12)
Block(8,20,16,LEAVES:12)
Block(8,20,17,LEAVES:12)
Block(8,21,-1,LEAVES:12)
Block(8,21,1,LEAVES:12)
Block(8,21,11,LEAVES:12)
Block(8,21,12,LEAVES:12)
Block(8,21,14,LEAVES:12)
Block(8,21,19,LEAVES:12)
Block(8,22,-4,LEAVES:12)
Block(8,22,-2,LEAVES:12)
Block(8,22,-1,LEAVES:12)
Block(8,22,5,LEAVES:12)
Block(8,22,7,LEAVES:12)
Block(8,22,8,LEAVES:12)
Block(8,22,12,LEAVES:12)
Block(8,23,2,LEAVES:12)
Block(8,23,3,LEAVES:12)
Block(9,6,17,LEAVES:12)
Block(9,7,-6,LEAVES:12)
Block(9,7,21,LEAVES:12)
Block(9,8,-2,LEAVES:12)
Block(9,8,18,LEAVES:12)
Block(9,8,20,LEAVES:12)
Block(9,8,21,LEAVES:12)
Block(9,9,-5,LEAVES:12)
Block(9,9,-3,LEAVES:12)
Block(9,9,-2,LEAVES:12)
Block(9,10,1,LEAVES:12)
Block(9,10,15,LEAVES:12)
Block(9,10,16,LEAVES:12)
Block(9,10,19,LEAVES:12)
Block(9,10,20,LEAVES:12)
Block(9,11,-8,LEAVES:12)
Block(9,11,-7,LEAVES:12)
Block(9,11,-4,LEAVES:12)
Block(9,11,-3,LEAVES:12)
Block(9,11,0,LEAVES:12)
Block(9,11,1,LEAVES:12)
Block(9,11,6,LOG:12)
Block(9,11,7,LOG:12)
Block(9,11,14,LOG:12)
Block(9,11,18,LEAVES:12)
Block(9,11,20,LEAVES:12)
Block(9,12,-5,LEAVES:12)
Block(9,12,-4,LEAVES:12)
Block(9,12,-3,LEAVES:12)
Block(9,12,7,LOG:12)
Block(9,12,13,LOG:12)
Block(9,12,14,LOG:12)
Block(9,12,15,LEAVES:12)
Block(9,12,17,LEAVES:12)
Block(9,12,18,LEAVES:12)
Block(9,13,-8,LEAVES:12)
Block(9,13,-6,LEAVES:12)
Block(9,13,-5,LEAVES:12)
Block(9,14,16,LEAVES:12)
Block(9,15,5,LEAVES:12)
Block(9,15,12,LEAVES:12)
Block(9,15,13,LEAVES:12)
Block(9,16,-1,LEAVES:12)
Block(9,16,2,LEAVES:12)
Block(9,16,3,LEAVES:12)
Block(9,16,4,LEAVES:12)
Block(9,16,12,LEAVES:12)
Block(9,16,18,LEAVES:12)
Block(9,16,19,LEAVES:12)
Block(9,17,-2,LEAVES:12)
Block(9,17,-1,LEAVES:12)
Block(9,17,0,LEAVES:12)
Block(9,17,2,LEAVES:12)
Block(9,17,4,LEAVES:12)
Block(9,17,7,LEAVES:12)
Block(9,17,11,LEAVES:12)
Block(9,17,12,LEAVES:12)
Block(9,18,-1,LEAVES:12)
Block(9,18,3,LOG:12)
Block(9,18,4,LEAVES:12)
Block(9,18,12,LEAVES:12)
Block(9,18,13,LEAVES:12)
Block(9,18,14,LEAVES:12)
Block(9,18,15,LEAVES:12)
Block(9,18,16,LEAVES:12)
Block(9,19,-1,LEAVES:12)
Block(9,19,2,LEAVES:12)
Block(9,19,3,LOG:12)
Block(9,19,10,LEAVES:12)
Block(9,19,13,LOG:12)
Block(9,19,14,LOG:12)
Block(9,19,15,LEAVES:12)
Block(9,19,16,LEAVES:12)
Block(9,20,-5,LEAVES:12)
Block(9,20,-4,LEAVES:12)
Block(9,20,3,LEAVES:12)
Block(9,20,14,LEAVES:12)
Block(9,20,16,LEAVES:12)
Block(9,21,1,LEAVES:12)
Block(9,21,2,LEAVES:12)
Block(9,21,3,LEAVES:12)
Block(9,21,6,LEAVES:12)
Block(9,21,7,LEAVES:12)
Block(9,21,14,LEAVES:12)
Block(9,21,15,LEAVES:12)
Block(9,22,-3,LEAVES:12)
Block(9,22,-2,LEAVES:12)
Block(9,22,-1,LEAVES:12)
Block(9,22,0,LEAVES:12)
Block(9,22,2,LEAVES:12)
Block(9,22,3,LEAVES:12)
Block(9,22,7,LEAVES:12)
Block(9,22,15,LEAVES:12)
Block(9,23,0,LEAVES:12)
Block(9,23,3,LEAVES:12)
Block(9,23,7,LEAVES:12)
Block(9,23,14,LEAVES:12)
Block(9,24,3,LEAVES:12)
Block(10,6,21,LEAVES:12)
Block(10,7,-2,LEAVES:12)
Block(10,7,17,LEAVES:12)
Block(10,7,18,LEAVES:12)
Block(10,7,21,LEAVES:12)
Block(10,8,-6,LEAVES:12)
Block(10,8,-5,LEAVES:12)
Block(10,8,-2,LEAVES:12)
Block(10,8,18,LEAVES:12)
Block(10,9,-5,LEAVES:12)
Block(10,9,18,LEAVES:12)
Block(10,10,-5,LEAVES:12)
Block(10,10,14,LEAVES:12)
Block(10,10,15,LEAVES:12)
Block(10,11,-9,LEAVES:12)
Block(10,11,-8,LEAVES:12)
Block(10,11,0,LEAVES:12)
Block(10,11,7,LOG:12)
Block(10,11,15,LEAVES:12)
Block(10,11,20,LEAVES:12)
Block(10,11,21,LEAVES:12)
Block(10,11,22,LEAVES:12)
Block(10,12,-4,LEAVES:12)
Block(10,12,-3,LEAVES:12)
Block(10,12,-2,LEAVES:12)
Block(10,12,-1,LEAVES:12)
Block(10,12,6,LOG:12)
Block(10,12,7,LOG:12)
Block(10,12,12,LOG:12)
Block(10,12,13,LOG:12)
Block(10,12,16,LEAVES:12)
Block(10,12,17,LEAVES:12)
Block(10,12,21,LEAVES:12)
Block(10,13,-7,LEAVES:12)
Block(10,13,-6,LEAVES:12)
Block(10,13,-2,LEAVES:12)
Block(10,13,5,LOG:12)
Block(10,13,6,LOG:12)
Block(10,13,11,LOG:12)
Block(10,13,12,LOG:12)
Block(10,13,19,LEAVES:12)
Block(10,14,-4,LEAVES:12)
Block(10,14,9,LEAVES:12)
Block(10,14,13,LEAVES:12)
Block(10,14,14,LEAVES:12)
Block(10,14,16,LEAVES:12)
Block(10,15,-2,LEAVES:12)
Block(10,15,0,LEAVES:12)
Block(10,15,8,LEAVES:12)
Block(10,15,9,LEAVES:12)
Block(10,15,13,LEAVES:12)
Block(10,15,15,LEAVES:12)
Block(10,15,16,LEAVES:12)
Block(10,16,-3,LEAVES:12)
Block(10,16,-2,LEAVES:12)
Block(10,16,4,LEAVES:12)
Block(10,16,14,LEAVES:12)
Block(10,16,16,LEAVES:12)
Block(10,17,-2,LEAVES:12)
Block(10,17,0,LEAVES:12)
Block(10,17,6,LEAVES:12)
Block(10,17,7,LEAVES:12)
Block(10,17,14,LEAVES:12)
Block(10,17,16,LEAVES:12)
Block(10,17,17,LEAVES:12)
Block(10,17,18,LEAVES:12)
Block(10,17,19,LEAVES:12)
Block(10,17,20,LEAVES:12)
Block(10,18,0,LEAVES:12)
Block(10,18,4,LEAVES:12)
Block(10,18,5,LEAVES:12)
Block(10,18,6,LEAVES:12)
Block(10,18,12,LEAVES:12)
Block(10,18,14,LEAVES:12)
Block(10,18,15,LEAVES:12)
Block(10,18,16,LEAVES:12)
Block(10,18,18,LEAVES:12)
Block(10,19,-2,LEAVES:12)
Block(10,19,-1,LEAVES:12)
Block(10,19,2,LEAVES:12)
Block(10,19,3,LOG:12)
Block(10,19,4,LEAVES:12)
Block(10,19,10,LEAVES:12)
Block(10,19,12,LEAVES:12)
Block(10,19,14,LOG:12)
Block(10,19,15,LEAVES:12)
Block(10,19,19,LEAVES:12)
Block(10,20,-1,LEAVES:12)
Block(10,20,3,LEAVES:12)
Block(10,20,14,LEAVES:12)
Block(10,21,1,LEAVES:12)
Block(10,21,2,LEAVES:12)
Block(10,21,3,LEAVES:12)
Block(10,21,5,LEAVES:12)
Block(10,21,6,LEAVES:12)
Block(10,22,-3,LEAVES:12)
Block(10,22,0,LEAVES:12)
Block(10,22,1,LEAVES:12)
Block(10,22,3,LEAVES:12)
Block(10,22,8,LEAVES:12)
Block(10,22,15,LEAVES:12)
Block(10,22,16,LEAVES:12)
Block(10,23,-3,LEAVES:12)
Block(10,23,1,LEAVES:12)
Block(10,23,16,LEAVES:12)
Block(10,23,17,LEAVES:12)
Block(10,24,16,LEAVES:12)
Block(11,6,16,LEAVES:12)
Block(11,6,17,LEAVES:12)
Block(11,7,-7,LEAVES:12)
Block(11,7,-6,LEAVES:12)
Block(11,7,-1,LEAVES:12)
Block(11,7,8,LEAVES:12)
Block(11,7,17,LEAVES:12)
Block(11,8,-6,LEAVES:12)
Block(11,8,-1,LEAVES:12)
Block(11,8,7,LEAVES:12)
Block(11,8,8,LEAVES:12)
Block(11,9,1,LEAVES:12)
Block(11,9,3,LEAVES:12)
Block(11,9,17,LEAVES:12)
Block(11,9,18,LEAVES:12)
Block(11,10,-6,LEAVES:12)
Block(11,10,-5,LEAVES:12)
Block(11,10,17,LEAVES:12)
Block(11,10,18,LEAVES:12)
Block(11,11,-5,LEAVES:12)
Block(11,11,-3,LEAVES:12)
Block(11,11,-2,LEAVES:12)
Block(11,11,0,LEAVES:12)
Block(11,11,11,LEAVES:12)
Block(11,11,15,LEAVES:12)
Block(11,11,16,LEAVES:12)
Block(11,11,21,LEAVES:12)
Block(11,12,-3,LEAVES:12)
Block(11,12,-2,LEAVES:12)
Block(11,12,-1,LEAVES:12)
Block(11,12,0,LEAVES:12)
Block(11,12,6,LEAVES:12)
Block(11,12,7,LOG:12)
Block(11,12,8,LOG:12)
Block(11,12,9,LOG:12)
Block(11,12,11,LEAVES:12)
Block(11,12,12,LEAVES:12)
Block(11,12,16,LEAVES:12)
Block(11,12,19,LEAVES:12)
Block(11,13,-7,LEAVES:12)
Block(11,13,4,LOG:12)
Block(11,13,5,LOG:12)
Block(11,13,9,LOG:12)
Block(11,13,10,LOG:12)
Block(11,13,11,LOG:12)
Block(11,13,16,LEAVES:12)
Block(11,14,-7,LEAVES:12)
Block(11,14,1,LEAVES:12)
Block(11,14,3,LEAVES:12)
Block(11,14,4,LOG:12)
Block(11,14,9,LOG:12)
Block(11,14,11,LOG:12)
Block(11,14,14,LEAVES:12)
Block(11,15,-2,LEAVES:12)
Block(11,15,-1,LEAVES:12)
Block(11,15,8,LEAVES:12)
Block(11,15,13,LEAVES:12)
Block(11,15,15,LEAVES:12)
Block(11,16,-3,LEAVES:12)
Block(11,16,2,LEAVES:12)
Block(11,16,4,LEAVES:12)
Block(11,16,5,LEAVES:12)
Block(11,16,17,LEAVES:12)
Block(11,16,18,LEAVES:12)
Block(11,16,19,LEAVES:12)
Block(11,17,1,LEAVES:12)
Block(11,17,7,LEAVES:12)
Block(11,17,8,LEAVES:12)
Block(11,17,11,LEAVES:12)
Block(11,17,12,LEAVES:12)
Block(11,17,14,LEAVES:12)
Block(11,17,15,LEAVES:12)
Block(11,17,16,LEAVES:12)
Block(11,17,17,LEAVES:12)
Block(11,17,19,LEAVES:12)
Block(11,18,0,LEAVES:12)
Block(11,18,1,LEAVES:12)
Block(11,18,15,LEAVES:12)
Block(11,18,19,LEAVES:12)
Block(11,19,-1,LEAVES:12)
Block(11,19,0,LEAVES:12)
Block(11,19,1,LEAVES:12)
Block(11,19,2,LEAVES:12)
Block(11,19,3,LOG:12)
Block(11,19,4,LEAVES:12)
Block(11,19,6,LEAVES:12)
Block(11,19,8,LEAVES:12)
Block(11,19,11,LEAVES:12)
Block(11,19,12,LEAVES:12)
Block(11,19,15,LEAVES:12)
Block(11,19,16,LEAVES:12)
Block(11,20,3,LOG:12)
Block(11,20,4,LOG:12)
Block(11,20,5,LEAVES:12)
Block(11,20,6,LEAVES:12)
Block(11,20,14,LEAVES:12)
Block(11,20,16,LEAVES:12)
Block(11,21,3,LEAVES:12)
Block(11,21,5,LEAVES:12)
Block(11,21,11,LEAVES:12)
Block(11,21,13,LEAVES:12)
Block(11,21,14,LEAVES:12)
Block(11,22,3,LEAVES:12)
Block(11,22,4,LEAVES:12)
Block(11,23,4,LEAVES:12)
Block(11,24,3,LEAVES:12)
Block(12,5,5,LEAVES:12)
Block(12,6,16,LEAVES:12)
Block(12,7,-7,LEAVES:12)
Block(12,7,1,LEAVES:12)
Block(12,8,-5,LEAVES:12)
Block(12,8,-1,LEAVES:12)
Block(12,8,0,LEAVES:12)
Block(12,8,7,LEAVES:12)
Block(12,8,19,LEAVES:12)
Block(12,9,-5,LEAVES:12)
Block(12,9,-4,LEAVES:12)
Block(12,9,0,LEAVES:12)
Block(12,9,3,LEAVES:12)
Block(12,9,4,LEAVES:12)
Block(12,9,18,LEAVES:12)
Block(12,9,19,LEAVES:12)
Block(12,10,-5,LEAVES:12)
Block(12,10,-4,LEAVES:12)
Block(12,10,0,LEAVES:12)
Block(12,11,-2,LEAVES:12)
Block(12,11,7,LEAVES:12)
Block(12,12,-1,LEAVES:12)
Block(12,12,5,LEAVES:12)
Block(12,12,7,LEAVES:12)
Block(12,12,8,LOG:12)
Block(12,12,12,LEAVES:12)
Block(12,12,18,LEAVES:12)
Block(12,12,19,LEAVES:12)
Block(12,13,2,LEAVES:12)
Block(12,13,3,LEAVES:12)
Block(12,13,5,LEAVES:12)
Block(12,13,9,LEAVES:12)
Block(12,13,12,LEAVES:12)
Block(12,13,16,LEAVES:12)
Block(12,13,17,LEAVES:12)
Block(12,13,18,LEAVES:12)
Block(12,14,-5,LEAVES:12)
Block(12,14,-4,LEAVES:12)
Block(12,14,-1,LEAVES:12)
Block(12,14,2,LOG:12)
Block(12,14,3,LOG:12)
Block(12,14,4,LOG:12)
Block(12,14,9,LOG:12)
Block(12,14,11,LOG:12)
Block(12,14,12,LOG:12)
Block(12,14,14,LEAVES:12)
Block(12,14,16,LEAVES:12)
Block(12,15,-1,LEAVES:12)
Block(12,15,3,LEAVES:12)
Block(12,15,5,LEAVES:12)
Block(12,15,6,LEAVES:12)
Block(12,15,8,LOG:12)
Block(12,15,9,LOG:12)
Block(12,15,15,LEAVES:12)
Block(12,15,17,LEAVES:12)
Block(12,16,-1,LEAVES:12)
Block(12,16,5,LEAVES:12)
Block(12,16,7,LEAVES:12)
Block(12,16,8,LEAVES:12)
Block(12,16,13,LEAVES:12)
Block(12,16,14,LEAVES:12)
Block(12,16,15,LEAVES:12)
Block(12,16,17,LEAVES:12)
Block(12,16,18,LEAVES:12)
Block(12,17,3,LEAVES:12)
Block(12,17,5,LEAVES:12)
Block(12,17,12,LEAVES:12)
Block(12,17,13,LEAVES:12)
Block(12,17,14,LEAVES:12)
Block(12,17,15,LEAVES:12)
Block(12,17,20,LEAVES:12)
Block(12,18,0,LEAVES:12)
Block(12,18,3,LEAVES:12)
Block(12,18,5,LEAVES:12)
Block(12,18,7,LEAVES:12)
Block(12,18,9,LEAVES:12)
Block(12,18,11,LEAVES:12)
Block(12,18,12,LEAVES:12)
Block(12,18,13,LEAVES:12)
Block(12,18,14,LEAVES:12)
Block(12,19,1,LEAVES:12)
Block(12,19,3,LEAVES:12)
Block(12,19,4,LEAVES:12)
Block(12,19,5,LEAVES:12)
Block(12,19,6,LEAVES:12)
Block(12,19,7,LEAVES:12)
Block(12,19,10,LEAVES:12)
Block(12,19,11,LEAVES:12)
Block(12,20,-1,LEAVES:12)
Block(12,20,1,LEAVES:12)
Block(12,20,3,LEAVES:12)
Block(12,20,4,LOG:12)
Block(12,20,8,LEAVES:12)
Block(12,20,16,LEAVES:12)
Block(12,20,17,LEAVES:12)
Block(12,20,18,LEAVES:12)
Block(12,21,3,LEAVES:12)
Block(12,21,12,LEAVES:12)
Block(12,21,13,LEAVES:12)
Block(12,21,17,LEAVES:12)
Block(12,22,15,LEAVES:12)
Block(12,23,4,LEAVES:12)
Block(12,23,5,LEAVES:12)
Block(12,24,5,LEAVES:12)
Block(12,24,6,LEAVES:12)
Block(12,25,5,LEAVES:12)
Block(13,4,6,LEAVES:12)
Block(13,5,6,LEAVES:12)
Block(13,6,8,LEAVES:12)
Block(13,7,2,LEAVES:12)
Block(13,8,4,LEAVES:12)
Block(13,8,5,LEAVES:12)
Block(13,8,7,LEAVES:12)
Block(13,8,19,LEAVES:12)
Block(13,9,-4,LEAVES:12)
Block(13,9,2,LEAVES:12)
Block(13,9,3,LEAVES:12)
Block(13,9,4,LEAVES:12)
Block(13,9,6,LEAVES:12)
Block(13,9,7,LEAVES:12)
Block(13,10,-4,LEAVES:12)
Block(13,10,0,LEAVES:12)
Block(13,10,1,LEAVES:12)
Block(13,10,2,LEAVES:12)
Block(13,11,-2,LEAVES:12)
Block(13,11,0,LEAVES:12)
Block(13,11,8,LEAVES:12)
Block(13,11,9,LOG:12)
Block(13,11,10,LOG:12)
Block(13,11,11,LEAVES:12)
Block(13,11,14,LEAVES:12)
Block(13,12,-1,LEAVES:12)
Block(13,12,0,LOG:12)
Block(13,12,3,LEAVES:12)
Block(13,12,5,LEAVES:12)
Block(13,12,6,LEAVES:12)
Block(13,12,7,LEAVES:12)
Block(13,12,8,LOG:12)
Block(13,12,9,LOG:12)
Block(13,12,13,LEAVES:12)
Block(13,12,19,LEAVES:12)
Block(13,12,20,LEAVES:12)
Block(13,13,-3,LEAVES:12)
Block(13,13,-2,LEAVES:12)
Block(13,13,-1,LEAVES:12)
Block(13,13,0,LOG:12)
Block(13,13,1,LOG:12)
Block(13,13,2,LOG:12)
Block(13,13,3,LEAVES:12)
Block(13,13,4,LEAVES:12)
Block(13,13,8,LEAVES:12)
Block(13,13,11,LEAVES:12)
Block(13,13,12,LEAVES:12)
Block(13,13,13,LEAVES:12)
Block(13,14,-4,LEAVES:12)
Block(13,14,-3,LEAVES:12)
Block(13,14,-1,LEAVES:12)
Block(13,14,2,LOG:12)
Block(13,14,4,LEAVES:12)
Block(13,14,8,LEAVES:12)
Block(13,14,12,LOG:12)
Block(13,14,13,LOG:12)
Block(13,14,14,LEAVES:12)
Block(13,14,15,LEAVES:12)
Block(13,14,16,LEAVES:12)
Block(13,15,-3,LEAVES:12)
Block(13,15,6,LEAVES:12)
Block(13,15,8,LOG:12)
Block(13,15,12,LEAVES:12)
Block(13,15,13,LOG:12)
Block(13,15,14,LOG:12)
Block(13,15,15,LOG:12)
Block(13,15,16,LEAVES:12)
Block(13,15,17,LEAVES:12)
Block(13,16,2,LEAVES:12)
Block(13,16,7,LEAVES:12)
Block(13,16,13,LEAVES:12)
Block(13,16,15,LEAVES:12)
Block(13,16,17,LEAVES:12)
Block(13,17,6,LEAVES:12)
Block(13,17,10,LEAVES:12)
Block(13,17,11,LEAVES:12)
Block(13,17,15,LEAVES:12)
Block(13,17,16,LEAVES:12)
Block(13,18,3,LEAVES:12)
Block(13,18,4,LEAVES:12)
Block(13,18,5,LEAVES:12)
Block(13,18,6,LEAVES:12)
Block(13,18,7,LEAVES:12)
Block(13,18,11,LEAVES:12)
Block(13,18,13,LEAVES:12)
Block(13,18,14,LEAVES:12)
Block(13,18,16,LEAVES:12)
Block(13,19,7,LEAVES:12)
Block(13,19,11,LEAVES:12)
Block(13,19,14,LEAVES:12)
Block(13,19,15,LEAVES:12)
Block(13,20,0,LEAVES:12)
Block(13,20,1,LEAVES:12)
Block(13,20,4,LEAVES:12)
Block(13,20,5,LEAVES:12)
Block(13,20,7,LEAVES:12)
Block(13,20,17,LEAVES:12)
Block(13,21,3,LEAVES:12)
Block(13,21,5,LEAVES:12)
Block(13,21,12,LEAVES:12)
Block(13,22,0,LEAVES:12)
Block(13,22,2,LEAVES:12)
Block(13,22,3,LEAVES:12)
Block(13,22,12,LEAVES:12)
Block(14,4,8,LEAVES:12)
Block(14,5,2,LEAVES:12)
Block(14,5,6,LEAVES:12)
Block(14,5,7,LEAVES:12)
Block(14,6,2,LEAVES:12)
Block(14,6,3,LEAVES:12)
Block(14,6,7,LEAVES:12)
Block(14,6,10,LEAVES:12)
Block(14,7,7,LEAVES:12)
Block(14,7,16,LEAVES:12)
Block(14,8,-2,LEAVES:12)
Block(14,8,5,LEAVES:12)
Block(14,8,15,LEAVES:12)
Block(14,8,16,LEAVES:12)
Block(14,9,-3,LEAVES:12)
Block(14,9,3,LEAVES:12)
Block(14,9,4,LEAVES:12)
Block(14,9,6,LEAVES:12)
Block(14,9,11,LEAVES:12)
Block(14,10,-4,LEAVES:12)
Block(14,10,-3,LEAVES:12)
Block(14,10,9,LEAVES:12)
Block(14,10,10,LOG:12)
Block(14,10,11,LOG:12)
Block(14,10,12,LOG:12)
Block(14,11,-3,LEAVES:12)
Block(14,11,-2,LEAVES:12)
Block(14,11,-1,LOG:12)
Block(14,11,0,LEAVES:12)
Block(14,11,2,LEAVES:12)
Block(14,11,3,LEAVES:12)
Block(14,11,6,LEAVES:12)
Block(14,11,7,LOG:12)
Block(14,11,10,LOG:12)
Block(14,11,17,LEAVES:12)
Block(14,12,-1,LOG:12)
Block(14,12,0,LOG:12)
Block(14,12,1,LEAVES:12)
Block(14,12,6,LEAVES:12)
Block(14,12,7,LOG:12)
Block(14,12,8,LOG:12)
Block(14,12,10,LEAVES:12)
Block(14,12,15,LEAVES:12)
Block(14,12,17,LEAVES:12)
Block(14,13,-1,LEAVES:12)
Block(14,13,1,LEAVES:12)
Block(14,13,4,LEAVES:12)
Block(14,13,6,LEAVES:12)
Block(14,13,10,LEAVES:12)
Block(14,13,11,LEAVES:12)
Block(14,13,15,LEAVES:12)
Block(14,13,17,LEAVES:12)
Block(14,13,19,LEAVES:12)
Block(14,14,-1,LEAVES:12)
Block(14,14,0,LEAVES:12)
Block(14,14,4,LEAVES:12)
Block(14,14,8,LEAVES:12)
Block(14,14,9,LEAVES:12)
Block(14,14,10,LEAVES:12)
Block(14,14,13,LEAVES:12)
Block(14,14,15,LEAVES:12)
Block(14,14,16,LEAVES:12)
Block(14,14,17,LEAVES:12)
Block(14,14,19,LEAVES:12)
Block(14,15,0,LEAVES:12)
Block(14,15,6,LEAVES:12)
Block(14,15,8,LOG:12)
Block(14,15,11,LEAVES:12)
Block(14,15,12,LEAVES:12)
Block(14,15,13,LEAVES:12)
Block(14,15,15,LEAVES:12)
Block(14,15,16,LEAVES:12)
Block(14,15,20,LEAVES:12)
Block(14,16,-1,LEAVES:12)
Block(14,16,6,LEAVES:12)
Block(14,16,7,LOG:12)
Block(14,16,8,LOG:12)
Block(14,16,15,LEAVES:12)
Block(14,17,2,LEAVES:12)
Block(14,17,3,LEAVES:12)
Block(14,17,5,LEAVES:12)
Block(14,17,6,LEAVES:12)
Block(14,17,7,LEAVES:12)
Block(14,17,9,LEAVES:12)
Block(14,17,10,LEAVES:12)
Block(14,17,15,LEAVES:12)
Block(14,18,3,LEAVES:12)
Block(14,18,4,LEAVES:12)
Block(14,18,5,LEAVES:12)
Block(14,18,7,LEAVES:12)
Block(14,18,12,LEAVES:12)
Block(14,18,14,LEAVES:12)
Block(14,18,15,LEAVES:12)
Block(14,18,16,LEAVES:12)
Block(14,18,17,LEAVES:12)
Block(14,19,3,LEAVES:12)
Block(14,19,5,LEAVES:12)
Block(14,19,17,LEAVES:12)
Block(14,19,18,LEAVES:12)
Block(14,20,-1,LEAVES:12)
Block(14,20,0,LEAVES:12)
Block(14,20,17,LEAVES:12)
Block(14,21,5,LEAVES:12)
Block(14,21,6,LEAVES:12)
Block(14,21,7,LEAVES:12)
Block(14,22,1,LEAVES:12)
Block(14,22,2,LEAVES:12)
Block(14,22,6,LEAVES:12)
Block(14,23,4,LEAVES:12)
Block(15,5,13,LEAVES:12)
Block(15,6,3,LEAVES:12)
Block(15,6,9,LEAVES:12)
Block(15,6,10,LEAVES:12)
Block(15,7,3,LEAVES:12)
Block(15,7,7,LEAVES:12)
Block(15,7,8,LEAVES:12)
Block(15,7,9,LEAVES:12)
Block(15,8,1,LEAVES:12)
Block(15,8,5,LEAVES:12)
Block(15,8,7,LEAVES:12)
Block(15,8,15,LEAVES:12)
Block(15,9,-1,LEAVES:12)
Block(15,9,1,LEAVES:12)
Block(15,9,6,LEAVES:12)
Block(15,9,11,LEAVES:12)
Block(15,9,12,LOG:12)
Block(15,9,13,LOG:12)
Block(15,10,-1,LEAVES:12)
Block(15,10,1,LEAVES:12)
Block(15,10,3,LEAVES:12)
Block(15,10,4,LEAVES:12)
Block(15,10,5,LEAVES:12)
Block(15,10,6,LOG:12)
Block(15,10,8,LEAVES:12)
Block(15,10,9,LEAVES:12)
Block(15,10,12,LOG:12)
Block(15,11,-3,LEAVES:12)
Block(15,11,-1,LEAVES:12)
Block(15,11,0,LEAVES:12)
Block(15,11,1,LEAVES:12)
Block(15,11,3,LEAVES:12)
Block(15,11,4,LEAVES:12)
Block(15,11,6,LOG:12)
Block(15,11,7,LOG:12)
Block(15,11,11,LEAVES:12)
Block(15,11,14,LEAVES:12)
Block(15,12,-5,LEAVES:12)
Block(15,12,-3,LEAVES:12)
Block(15,12,-1,LEAVES:12)
Block(15,12,0,LEAVES:12)
Block(15,12,4,LEAVES:12)
Block(15,12,6,LEAVES:12)
Block(15,12,13,LEAVES:12)
Block(15,12,15,LEAVES:12)
Block(15,12,18,LEAVES:12)
Block(15,13,-1,LEAVES:12)
Block(15,13,5,LEAVES:12)
Block(15,13,11,LEAVES:12)
Block(15,13,12,LEAVES:12)
Block(15,13,13,LEAVES:12)
Block(15,13,15,LEAVES:12)
Block(15,13,17,LEAVES:12)
Block(15,13,18,LEAVES:12)
Block(15,14,4,LEAVES:12)
Block(15,14,5,LEAVES:12)
Block(15,15,0,LEAVES:12)
Block(15,15,1,LEAVES:12)
Block(15,15,5,LEAVES:12)
Block(15,15,6,LEAVES:12)
Block(15,15,7,LEAVES:12)
Block(15,15,8,LEAVES:12)
Block(15,15,12,LEAVES:12)
Block(15,15,13,LEAVES:12)
Block(15,15,16,LEAVES:12)
Block(15,15,17,LEAVES:12)
Block(15,16,1,LEAVES:12)
Block(15,16,2,LEAVES:12)
Block(15,16,7,LOG:12)
Block(15,16,8,LEAVES:12)
Block(15,16,9,LEAVES:12)
Block(15,16,15,LEAVES:12)
Block(15,16,17,LEAVES:12)
Block(15,17,1,LEAVES:12)
Block(15,17,2,LEAVES:12)
Block(15,17,7,LEAVES:12)
Block(15,17,9,LEAVES:12)
Block(15,17,12,LEAVES:12)
Block(15,17,14,LEAVES:12)
Block(15,17,15,LEAVES:12)
Block(15,18,7,LEAVES:12)
Block(15,18,8,LEAVES:12)
Block(15,19,2,LEAVES:12)
Block(15,19,3,LEAVES:12)
Block(15,19,8,LEAVES:12)
Block(15,20,3,LEAVES:12)
Block(15,20,7,LEAVES:12)
Block(15,21,6,LEAVES:12)
Block(15,22,1,LEAVES:12)
Block(15,23,1,LEAVES:12)
Block(16,4,14,LEAVES:12)
Block(16,5,5,LEAVES:12)
Block(16,5,14,LEAVES:12)
Block(16,6,4,LEAVES:12)
Block(16,6,10,LEAVES:12)
Block(16,6,11,LEAVES:12)
Block(16,6,16,LEAVES:12)
Block(16,7,3,LEAVES:12)
Block(16,7,4,LEAVES:12)
Block(16,7,10,LEAVES:12)
Block(16,8,-2,LEAVES:12)
Block(16,8,4,LEAVES:12)
Block(16,8,5,LEAVES:12)
Block(16,8,6,LOG:12)
Block(16,8,7,LEAVES:12)
Block(16,8,12,LEAVES:12)
Block(16,8,13,LEAVES:12)
Block(16,8,15,LEAVES:12)
Block(16,9,2,LEAVES:12)
Block(16,9,6,LOG:12)
Block(16,9,7,LEAVES:12)
Block(16,9,8,LEAVES:12)
Block(16,9,12,LEAVES:12)
Block(16,9,13,LOG:12)
Block(16,9,14,LEAVES:12)
Block(16,9,15,LEAVES:12)
Block(16,10,-1,LEAVES:12)
Block(16,10,1,LEAVES:12)
Block(16,10,2,LEAVES:12)
Block(16,10,6,LOG:12)
Block(16,10,8,LEAVES:12)
Block(16,11,6,LEAVES:12)
Block(16,11,7,LEAVES:12)
Block(16,11,16,LEAVES:12)
Block(16,11,18,LEAVES:12)
Block(16,11,19,LEAVES:12)
Block(16,12,-4,LEAVES:12)
Block(16,12,-3,LEAVES:12)
Block(16,12,0,LEAVES:12)
Block(16,12,1,LEAVES:12)
Block(16,12,7,LEAVES:12)
Block(16,12,9,LEAVES:12)
Block(16,12,13,LEAVES:12)
Block(16,12,14,LEAVES:12)
Block(16,12,15,LEAVES:12)
Block(16,12,18,LEAVES:12)
Block(16,13,-1,LEAVES:12)
Block(16,13,1,LEAVES:12)
Block(16,13,6,LEAVES:12)
Block(16,13,7,LEAVES:12)
Block(16,13,9,LEAVES:12)
Block(16,13,15,LEAVES:12)
Block(16,14,-4,LEAVES:12)
Block(16,14,-2,LEAVES:12)
Block(16,14,-1,LEAVES:12)
Block(16,14,7,LEAVES:12)
Block(16,14,9,LEAVES:12)
Block(16,14,11,LEAVES:12)
Block(16,14,15,LEAVES:12)
Block(16,15,5,LEAVES:12)
Block(16,15,7,LEAVES:12)
Block(16,15,8,LEAVES:12)
Block(16,15,9,LEAVES:12)
Block(16,15,11,LEAVES:12)
Block(16,15,12,LEAVES:12)
Block(16,16,1,LEAVES:12)
Block(16,16,3,LEAVES:12)
Block(16,16,5,LEAVES:12)
Block(16,16,7,LOG:12)
Block(16,16,8,LEAVES:12)
Block(16,16,12,LEAVES:12)
Block(16,16,17,LEAVES:12)
Block(16,16,18,LEAVES:12)
Block(16,16,19,LEAVES:12)
Block(16,17,7,LEAVES:12)
Block(16,17,13,LEAVES:12)
Block(16,17,14,LEAVES:12)
Block(16,17,18,LEAVES:12)
Block(16,18,4,LEAVES:12)
Block(16,18,16,LEAVES:12)
Block(16,19,3,LEAVES:12)
Block(16,19,4,LEAVES:12)
Block(16,19,8,LEAVES:12)
Block(16,19,9,LEAVES:12)
Block(16,20,9,LEAVES:12)
Block(16,20,10,LEAVES:12)
Block(16,21,9,LEAVES:12)
Block(17,4,16,LEAVES:12)
Block(17,5,8,LEAVES:12)
Block(17,5,10,LEAVES:12)
Block(17,5,14,LEAVES:12)
Block(17,5,15,LEAVES:12)
Block(17,6,6,LEAVES:12)
Block(17,6,8,LEAVES:12)
Block(17,6,10,LEAVES:12)
Block(17,6,11,LEAVES:12)
Block(17,6,15,LEAVES:12)
Block(17,6,18,LEAVES:12)
Block(17,7,6,LEAVES:12)
Block(17,7,8,LEAVES:12)
Block(17,7,10,LEAVES:12)
Block(17,7,15,LEAVES:12)
Block(17,8,2,LEAVES:12)
Block(17,8,4,LEAVES:12)
Block(17,8,5,LOG:12)
Block(17,8,6,LEAVES:12)
Block(17,8,7,LEAVES:12)
Block(17,8,8,LEAVES:12)
Block(17,8,10,LEAVES:12)
Block(17,8,13,LEAVES:12)
Block(17,9,-2,LEAVES:12)
Block(17,9,-1,LEAVES:12)
Block(17,9,2,LEAVES:12)
Block(17,9,4,LEAVES:12)
Block(17,9,6,LEAVES:12)
Block(17,9,7,LEAVES:12)
Block(17,9,11,LEAVES:12)
Block(17,9,13,LOG:12)
Block(17,9,14,LOG:12)
Block(17,10,-1,LEAVES:12)
Block(17,10,6,LEAVES:12)
Block(17,10,17,LEAVES:12)
Block(17,10,18,LEAVES:12)
Block(17,11,-1,LEAVES:12)
Block(17,11,10,LEAVES:12)
Block(17,11,11,LEAVES:12)
Block(17,11,13,LEAVES:12)
Block(17,11,14,LEAVES:12)
Block(17,11,18,LEAVES:12)
Block(17,12,-5,LEAVES:12)
Block(17,12,-4,LEAVES:12)
Block(17,12,6,LEAVES:12)
Block(17,12,7,LEAVES:12)
Block(17,12,8,LEAVES:12)
Block(17,12,14,LEAVES:12)
Block(17,12,18,LEAVES:12)
Block(17,13,1,LEAVES:12)
Block(17,13,2,LEAVES:12)
Block(17,13,3,LEAVES:12)
Block(17,13,8,LEAVES:12)
Block(17,13,9,LEAVES:12)
Block(17,13,10,LEAVES:12)
Block(17,13,14,LEAVES:12)
Block(17,14,-3,LEAVES:12)
Block(17,14,-2,LEAVES:12)
Block(17,14,2,LEAVES:12)
Block(17,14,7,LEAVES:12)
Block(17,14,8,LEAVES:12)
Block(17,14,9,LEAVES:12)
Block(17,14,10,LEAVES:12)
Block(17,14,14,LEAVES:12)
Block(17,14,15,LEAVES:12)
Block(17,15,0,LEAVES:12)
Block(17,15,15,LEAVES:12)
Block(17,16,4,LEAVES:12)
Block(17,16,5,LEAVES:12)
Block(17,16,8,LEAVES:12)
Block(17,16,9,LEAVES:12)
Block(17,16,18,LEAVES:12)
Block(17,17,7,LEAVES:12)
Block(17,17,9,LEAVES:12)
Block(17,17,13,LEAVES:12)
Block(17,18,4,LEAVES:12)
Block(17,18,6,LEAVES:12)
Block(17,18,7,LEAVES:12)
Block(17,18,13,LEAVES:12)
Block(18,5,5,LEAVES:12)
Block(18,6,9,LEAVES:12)
Block(18,6,11,LEAVES:12)
Block(18,6,17,LEAVES:12)
Block(18,6,18,LEAVES:12)
Block(18,7,6,LEAVES:12)
Block(18,7,8,LEAVES:12)
Block(18,7,9,LEAVES:12)
Block(18,7,11,LEAVES:12)
Block(18,7,15,LEAVES:12)
Block(18,7,16,LEAVES:12)
Block(18,7,17,LEAVES:12)
Block(18,8,-3,LEAVES:12)
Block(18,8,-2,LEAVES:12)
Block(18,8,13,LEAVES:12)
Block(18,8,15,LEAVES:12)
Block(18,9,-2,LEAVES:12)
Block(18,9,3,LEAVES:12)
Block(18,9,4,LEAVES:12)
Block(18,9,7,LEAVES:12)
Block(18,9,8,LEAVES:12)
Block(18,9,14,LOG:12)
Block(18,10,6,LEAVES:12)
Block(18,10,8,LEAVES:12)
Block(18,10,12,LEAVES:12)
Block(18,10,13,LEAVES:12)
Block(18,10,14,LEAVES:12)
Block(18,10,16,LEAVES:12)
Block(18,10,17,LEAVES:12)
Block(18,11,-2,LEAVES:12)
Block(18,11,-1,LEAVES:12)
Block(18,11,3,LEAVES:12)
Block(18,11,5,LEAVES:12)
Block(18,11,6,LEAVES:12)
Block(18,11,11,LEAVES:12)
Block(18,11,12,LEAVES:12)
Block(18,11,13,LEAVES:12)
Block(18,11,14,LEAVES:12)
Block(18,11,19,LEAVES:12)
Block(18,12,-1,LEAVES:12)
Block(18,12,10,LEAVES:12)
Block(18,12,12,LEAVES:12)
Block(18,13,2,LEAVES:12)
Block(18,13,6,LEAVES:12)
Block(18,13,7,LEAVES:12)
Block(18,13,10,LEAVES:12)
Block(18,13,16,LEAVES:12)
Block(18,14,-3,LEAVES:12)
Block(18,14,7,LEAVES:12)
Block(18,14,15,LEAVES:12)
Block(18,14,16,LEAVES:12)
Block(18,15,-3,LEAVES:12)
Block(18,15,7,LEAVES:12)
Block(18,16,3,LEAVES:12)
Block(18,16,4,LEAVES:12)
Block(18,17,9,LEAVES:12)
Block(18,17,10,LEAVES:12)
Block(18,17,11,LEAVES:12)
Block(18,18,5,LEAVES:12)
Block(18,18,6,LEAVES:12)
Block(18,18,10,LEAVES:12)
Block(18,19,8,LEAVES:12)
Block(19,5,9,LEAVES:12)
Block(19,5,13,LEAVES:12)
Block(19,6,5,LEAVES:12)
Block(19,6,6,LEAVES:12)
Block(19,6,9,LEAVES:12)
Block(19,6,12,LEAVES:12)
Block(19,6,18,LEAVES:12)
Block(19,6,19,LEAVES:12)
Block(19,7,6,LEAVES:12)
Block(19,7,11,LEAVES:12)
Block(19,7,12,LEAVES:12)
Block(19,8,-3,LEAVES:12)
Block(19,8,6,LEAVES:12)
Block(19,8,12,LEAVES:12)
Block(19,8,13,LEAVES:12)
Block(19,8,14,LEAVES:12)
Block(19,8,15,LEAVES:12)
Block(19,9,2,LEAVES:12)
Block(19,9,3,LEAVES:12)
Block(19,9,14,LOG:12)
Block(19,9,15,LEAVES:12)
Block(19,9,16,LEAVES:12)
Block(19,10,0,LEAVES:12)
Block(19,10,8,LEAVES:12)
Block(19,10,9,LEAVES:12)
Block(19,10,10,LEAVES:12)
Block(19,10,14,LEAVES:12)
Block(19,10,16,LEAVES:12)
Block(19,11,-1,LEAVES:12)
Block(19,11,0,LEAVES:12)
Block(19,11,4,LEAVES:12)
Block(19,11,5,LEAVES:12)
Block(19,11,9,LEAVES:12)
Block(19,11,14,LEAVES:12)
Block(19,11,15,LEAVES:12)
Block(19,12,5,LEAVES:12)
Block(19,12,6,LEAVES:12)
Block(19,12,7,LEAVES:12)
Block(19,12,15,LEAVES:12)
Block(19,13,6,LEAVES:12)
Block(19,13,14,LEAVES:12)
Block(19,13,16,LEAVES:12)
Block(19,15,6,LEAVES:12)
Block(19,15,7,LEAVES:12)
Block(19,16,7,LEAVES:12)
Block(19,17,10,LEAVES:12)
Block(19,18,5,LEAVES:12)
Block(19,19,5,LEAVES:12)
Block(20,5,4,LEAVES:12)
Block(20,5,5,LEAVES:12)
Block(20,5,16,LEAVES:12)
Block(20,6,5,LEAVES:12)
Block(20,6,14,LEAVES:12)
Block(20,6,16,LEAVES:12)
Block(20,7,14,LEAVES:12)
Block(20,7,16,LEAVES:12)
Block(20,7,18,LEAVES:12)
Block(20,8,5,LEAVES:12)
Block(20,8,6,LEAVES:12)
Block(20,8,12,LEAVES:12)
Block(20,8,14,LEAVES:12)
Block(20,8,15,LEAVES:12)
Block(20,8,16,LEAVES:12)
Block(20,8,18,LEAVES:12)
Block(20,9,6,LEAVES:12)
Block(20,9,10,LEAVES:12)
Block(20,9,12,LEAVES:12)
Block(20,9,14,LEAVES:12)
Block(20,9,15,LEAVES:12)
Block(20,9,19,LEAVES:12)
Block(20,10,0,LEAVES:12)
Block(20,10,9,LEAVES:12)
Block(20,10,14,LEAVES:12)
Block(20,11,4,LEAVES:12)
Block(20,12,4,LEAVES:12)
Block(20,12,5,LEAVES:12)
Block(20,12,15,LEAVES:12)
Block(20,12,16,LEAVES:12)
Block(20,13,16,LEAVES:12)
Block(20,13,17,LEAVES:12)
Block(20,14,8,LEAVES:12)
Block(20,14,16,LEAVES:12)
Block(20,15,7,LEAVES:12)
Block(20,15,8,LEAVES:12)
Block(21,5,4,LEAVES:12)
Block(21,5,13,LEAVES:12)
Block(21,6,17,LEAVES:12)
Block(21,7,7,LEAVES:12)
Block(21,7,14,LEAVES:12)
Block(21,7,16,LEAVES:12)
Block(21,7,17,LEAVES:12)
Block(21,8,6,LEAVES:12)
Block(21,8,7,LEAVES:12)
Block(21,9,11,LEAVES:12)
Block(21,9,12,LEAVES:12)
Block(21,9,15,LEAVES:12)
Block(21,9,16,LEAVES:12)
Block(21,10,14,LEAVES:12)
Block(21,10,16,LEAVES:12)
Block(21,11,11,LEAVES:12)
Block(21,11,13,LEAVES:12)
Block(21,11,14,LEAVES:12)
Block(21,14,8,LEAVES:12)
Block(22,5,17,LEAVES:12)
Block(22,6,13,LEAVES:12)
Block(22,6,14,LEAVES:12)
Block(22,6,17,LEAVES:12)
Block(22,7,7,LEAVES:12)
Block(22,7,14,LEAVES:12)
Block(22,8,14,LEAVES:12)
Block(22,9,10,LEAVES:12)
Block(22,9,11,LEAVES:12)
Block(22,10,16,LEAVES:12)
Block(22,10,17,LEAVES:12)
Block(22,10,18,LEAVES:12)
Block(22,11,12,LEAVES:12)
Block(22,11,13,LEAVES:12)
Block(22,11,17,LEAVES:12)
Block(22,12,15,LEAVES:12)
Block(23,5,12,LEAVES:12)
Block(23,5,13,LEAVES:12)
Block(23,6,13,LEAVES:12)
Block(23,8,13,LEAVES:12)
Block(23,8,14,LEAVES:12)
Block(23,9,14,LEAVES:12)
Block(23,10,17,LEAVES:12)
Block(23,11,12,LEAVES:12)
Block(23,12,12,LEAVES:12)
Block(24,5,12,LEAVES:12)
Block(24,7,15,LEAVES:12)
Block(24,8,14,LEAVES:12)
Block(24,8,15,LEAVES:12)
Block(25,7,15,LEAVES:12)


#######################################################################
# +-----------------------------------------------------------------+ #
# |                             Entities                            | #
# +-----------------------------------------------------------------+ #
#######################################################################

# Entity() spawns an entity instead of a block. The entity is spawned only once when the BO3 is spawned.
# Entities are persistent by default so they don't de-spawn when no player is near, they are only unloaded.
# Usage: Entity(x,y,z,mobName,groupSize,NameTagOrNBTFileName) or Entity(x,y,z,mobName,groupSize)
# Use /tc entities or /otg entities to get a list of entities that can be used as mobName, this includes entities added by other mods.
# NameTagOrNBTFileName can be either a nametag for the mob or an nbt file (such as mymobinfo.nbt or mymobinfo.txt).
# When using a text file you can use the same mob spawning parameters used with the /summon command to equip the
# entity and give it custom attributes etc. You can copy the DATA part of a summon command including surrounding
# curly braces to a .txt file, for instance for: "/summon Skeleton x y z {DATA}"

#######################################################################
# +-----------------------------------------------------------------+ #
# |                            BO3 checks                           | #
# +-----------------------------------------------------------------+ #
#######################################################################

# Require a condition at a certain location in order for the BO3 to be spawned.
# BlockCheck(x,y,z,BlockName[,BlockName[,...]]) - one of the blocks must be at the location
# BlockCheckNot(x,y,z,BlockName[,BlockName[,...]]) - all the blocks must not be at the location
# LightCheck(x,y,z,minLightLevel,maxLightLevel) - light must be between min and max (inclusive)

# You can use "Solid" as a BlockName for matching all solid blocks or "All" to match all blocks that aren't air.

# Examples:
BlockCheck(0,-1,0,GRASS,DIRT,DIRT:2,SAND)
#   BlockCheck(0,-1,0,Solid)       Require any solid block just below the object
#   BlockCheck(0,-1,0,WOOL)        Require any type of wool just below the object
#   BlockCheck(0,-1,0,WOOL:0)      Require white wool just below the object
#   BlockCheckNot(0,-1,0,WOOL:0)   Require that there is no white wool below the object
#   LightCheck(0,0,0,0,1)          Require almost complete darkness just below the object

