#######################################################################
# +-----------------------------------------------------------------+ #
# |                            BO3 object                           | #
# +-----------------------------------------------------------------+ #
#######################################################################

# This is the config file of a custom object.
# If you add this object correctly to your BiomeConfigs, it will spawn in the world.

# This is the creator of this BO3 object
Author: BO3 BulkEdit (by LanToaster)

# A short description of this BO3 object
Description: This Object was Created with BO3_BulkEdit

# The BO3 version, don't change this! It can be used by external applications to do a version check.
Version: 3

# The settings mode, WriteAll, WriteWithoutComments or WriteDisable. See WorldConfig.
SettingsMode: WriteDisable


#######################################################################
# +-----------------------------------------------------------------+ #
# |                          Main settings                          | #
# +-----------------------------------------------------------------+ #
#######################################################################

# This needs to be set to true to spawn the object in the Tree and Sapling resources.
Tree: true

# The frequency of the BO3 from 1 to 200. Tries this many times to spawn this BO3 when using the CustomObject(...) resource.
# Ignored by Tree(..), Sapling(..) and CustomStructure(..)
Frequency: 1

# The rarity of the BO3 from 0 to 100. Each spawn attempt has rarity% chance to succeed when using the CustomObject(...) resource.
# Ignored by Tree(..), Sapling(..) and CustomStructure(..)
Rarity: 100.0

# If you set this to true, the BO3 will be placed with a random rotation.
RotateRandomly: true

# The spawn height of the BO3 - randomY, highestBlock or highestSolidBlock.
SpawnHeight: highestSolidBlock

# The height limits for the BO3.
MinHeight: 0

MaxHeight: 68

# Objects can have other objects attacthed to it: branches. Branches can also
# have branches attached to it, which can also have branches, etc. This is the
# maximum branch depth for this objects.
MaxBranchDepth: 10

# When spawned with the UseWorld keyword, this BO3 should NOT spawn in the following biomes.
# If you writer.write the BO3 name directly in the BiomeConfigs, this will be ignored.
ExcludedBiomes: All


#######################################################################
# +-----------------------------------------------------------------+ #
# |                      Source block settings                      | #
# +-----------------------------------------------------------------+ #
#######################################################################

# The block(s) the BO3 should spawn in.
SourceBlocks: AIR

# The maximum percentage of the BO3 that can be outside the SourceBlock.
# The BO3 won't be placed on a location with more blocks outside the SourceBlock than this percentage.
MaxPercentageOutsideSourceBlock: 0

# What to do when a block is about to be placed outside the SourceBlock? (dontPlace, placeAnyway)
OutsideSourceBlock: dontPlace


#######################################################################
# +-----------------------------------------------------------------+ #
# |                              Blocks                             | #
# +-----------------------------------------------------------------+ #
#######################################################################

# All the blocks used in the BO3 are listed here. Possible blocks:
# Block(x,y,z,id[.data][,nbtfile.nbt)
# RandomBlock(x,y,z,id[:data][,nbtfile.nbt],chance[,id[:data][,nbtfile.nbt],chance[,...]])
# So RandomBlock(0,0,0,CHEST,chest.nbt,50,CHEST,anotherchest.nbt,100) will spawn a chest at
# the BO3 origin, and give it a 50% chance to have the contents of chest.nbt, or, if that
# fails, a 100% percent chance to have the contents of anotherchest.nbt.
Block(-2,0,-3,LOG2:12)
Block(1,0,-2,LOG2:12)
Block(2,0,-2,LOG2:12)
Block(-1,0,-1,LOG2:12)
Block(-3,0,0,LOG2:12)
Block(-1,0,0,LOG2:12)
Block(0,0,0,LOG2:12)
Block(0,0,1,LOG2:12)
Block(2,0,2,LOG2:12)
Block(3,0,2,LOG2:12)
Block(-2,1,-3,LOG2:12)
Block(1,1,-2,LOG2:12)
Block(2,1,-2,LOG2:12)
Block(-1,1,-1,LOG2:12)
Block(-3,1,0,LOG2:12)
Block(-1,1,0,LOG2:12)
Block(0,1,0,LOG2:12)
Block(0,1,1,LOG2:12)
Block(2,1,2,LOG2:12)
Block(3,1,2,LOG2:12)
Block(-2,2,-3,LOG2:12)
Block(1,2,-2,LOG2:12)
Block(2,2,-2,LOG2:12)
Block(-1,2,-1,LOG2:12)
Block(-3,2,0,LOG2:12)
Block(-1,2,0,LOG2:12)
Block(0,2,0,LOG2:12)
Block(0,2,1,LOG2:12)
Block(2,2,2,LOG2:12)
Block(3,2,2,LOG2:12)
Block(-2,3,-3,LOG2:12)
Block(1,3,-2,LOG2:12)
Block(2,3,-2,LOG2:12)
Block(-1,3,-1,LOG2:12)
Block(-4,3,0,LOG2:12)
Block(-3,3,0,LOG2:12)
Block(-1,3,0,LOG2:12)
Block(0,3,0,LOG2:12)
Block(0,3,1,LOG2:12)
Block(2,3,2,LOG2:12)
Block(3,3,2,LOG2:12)
Block(-2,4,-4,LOG2:12)
Block(-3,4,-3,LOG2:12)
Block(-2,4,-3,LOG2:12)
Block(1,4,-3,LOG2:12)
Block(1,4,-2,LOG2:12)
Block(2,4,-2,LOG2:12)
Block(-1,4,-1,LOG2:12)
Block(-4,4,0,LOG2:12)
Block(-1,4,0,LOG2:12)
Block(0,4,0,LOG2:12)
Block(0,4,1,LOG2:12)
Block(2,4,2,LOG2:12)
Block(3,4,2,LOG2:12)
Block(2,4,3,LOG2:12)
Block(-2,5,-5,LOG2:12)
Block(-2,5,-4,LOG2:12)
Block(-3,5,-3,LOG2:12)
Block(1,5,-3,LOG2:12)
Block(2,5,-3,LOG2:12)
Block(2,5,-2,LOG2:12)
Block(-1,5,-1,LOG2:12)
Block(-4,5,0,LOG2:12)
Block(-2,5,0,LOG2:12)
Block(-1,5,0,LOG2:12)
Block(0,5,0,LOG2:12)
Block(-1,5,1,LOG2:12)
Block(2,5,2,LOG2:12)
Block(2,5,3,LOG2:12)
Block(3,5,3,LOG2:12)
Block(-2,6,-5,LOG2:12)
Block(-3,6,-3,LOG2:12)
Block(1,6,-3,LOG2:12)
Block(2,6,-3,LOG2:12)
Block(-2,6,-1,LOG2:12)
Block(-5,6,0,LOG2:12)
Block(-4,6,0,LOG2:12)
Block(-2,6,0,LOG2:12)
Block(-1,6,0,LOG2:12)
Block(-5,6,1,LOG2:12)
Block(-1,6,1,LOG2:12)
Block(2,6,3,LOG2:12)
Block(3,6,3,LOG2:12)
Block(-2,7,-6,LOG2:12)
Block(-2,7,-5,LOG2:12)
Block(-4,7,-3,LOG2:12)
Block(-3,7,-3,LOG2:12)
Block(1,7,-3,LOG2:12)
Block(2,7,-3,LOG2:12)
Block(-2,7,-1,LOG2:12)
Block(-2,7,0,LOG2:12)
Block(-1,7,0,LOG2:12)
Block(-5,7,1,LOG2:12)
Block(-1,7,1,LOG2:12)
Block(2,7,3,LOG2:12)
Block(3,7,3,LOG2:12)
Block(2,7,4,LOG2:12)
Block(-2,8,-14,LEAVES:12)
Block(-2,8,-13,LEAVES:12)
Block(-7,8,-12,LEAVES:12)
Block(-6,8,-12,LEAVES:12)
Block(-1,8,-8,LEAVES:12)
Block(-2,8,-7,LOG2:12)
Block(-2,8,-6,LOG2:12)
Block(1,8,-4,LOG2:12)
Block(-4,8,-3,LOG2:12)
Block(1,8,-3,LOG2:12)
Block(2,8,-3,LOG2:12)
Block(-2,8,-1,LOG2:12)
Block(-2,8,0,LOG2:12)
Block(-1,8,0,LOG2:12)
Block(-5,8,1,LOG2:12)
Block(-3,8,1,LOG2:12)
Block(-2,8,1,LOG2:12)
Block(-1,8,1,LOG2:12)
Block(-5,8,2,LOG2:12)
Block(3,8,3,LOG2:12)
Block(2,8,4,LOG2:12)
Block(-7,9,-16,LEAVES:12)
Block(-3,9,-13,LEAVES:12)
Block(-2,9,-13,LEAVES:12)
Block(-6,9,-12,LEAVES:12)
Block(-5,9,-12,LEAVES:12)
Block(-1,9,-9,LEAVES:12)
Block(-2,9,-8,LOG2:12)
Block(-1,9,-8,LEAVES:12)
Block(-2,9,-7,LOG2:12)
Block(-4,9,-4,LOG2:12)
Block(1,9,-4,LOG2:12)
Block(-4,9,-3,LOG2:12)
Block(2,9,-3,LOG2:12)
Block(-2,9,0,LOG2:12)
Block(-1,9,0,LOG2:12)
Block(-3,9,1,LOG2:12)
Block(-2,9,1,LOG2:12)
Block(-5,9,2,LOG2:12)
Block(1,9,4,LOG2:12)
Block(2,9,4,LOG2:12)
Block(3,9,4,LOG2:12)
Block(-7,10,-16,LEAVES:12)
Block(-7,10,-15,LEAVES:12)
Block(-6,10,-15,LEAVES:12)
Block(-3,10,-13,LEAVES:12)
Block(-5,10,-12,LEAVES:12)
Block(-3,10,-12,LEAVES:12)
Block(-3,10,-10,LOG2:12)
Block(-2,10,-10,LEAVES:12)
Block(-3,10,-9,LOG2:12)
Block(-2,10,-9,LEAVES:12)
Block(-1,10,-9,LEAVES:12)
Block(-3,10,-8,LOG2:12)
Block(-2,10,-8,LOG2:12)
Block(-4,10,-4,LOG2:12)
Block(1,10,-4,LOG2:12)
Block(2,10,-4,LOG2:12)
Block(-3,10,0,LOG2:12)
Block(-2,10,0,LOG2:12)
Block(-3,10,1,LOG2:12)
Block(-2,10,1,LOG2:12)
Block(-6,10,2,LOG2:12)
Block(-5,10,2,LOG2:12)
Block(1,10,4,LOG2:12)
Block(3,10,4,LOG2:12)
Block(-6,11,-15,LEAVES:12)
Block(-5,11,-15,LEAVES:12)
Block(-2,11,-15,LEAVES:12)
Block(-1,11,-15,LEAVES:12)
Block(-9,11,-14,LEAVES:12)
Block(-5,11,-14,LEAVES:12)
Block(-2,11,-14,LEAVES:12)
Block(-5,11,-13,LEAVES:12)
Block(-5,11,-12,LEAVES:12)
Block(-4,11,-12,LEAVES:12)
Block(-3,11,-12,LEAVES:12)
Block(-6,11,-11,LEAVES:12)
Block(-4,11,-11,LOG2:12)
Block(-3,11,-11,LEAVES:12)
Block(-7,11,-10,LEAVES:12)
Block(-6,11,-10,LEAVES:12)
Block(-4,11,-10,LOG2:12)
Block(-3,11,-10,LOG2:12)
Block(-2,11,-10,LEAVES:12)
Block(-7,11,-9,LEAVES:12)
Block(-8,11,-8,LEAVES:12)
Block(-7,11,-8,LEAVES:12)
Block(-5,11,-4,LOG2:12)
Block(-4,11,-4,LOG2:12)
Block(1,11,-4,LOG2:12)
Block(2,11,-4,LOG2:12)
Block(-3,11,-1,LOG2:12)
Block(-3,11,0,LOG2:12)
Block(-2,11,0,LOG2:12)
Block(-3,11,1,LOG2:12)
Block(-2,11,1,LOG2:12)
Block(-6,11,2,LOG2:12)
Block(1,11,4,LOG2:12)
Block(3,11,4,LOG2:12)
Block(1,11,5,LOG2:12)
Block(4,11,6,LEAVES:12)
Block(4,11,7,LEAVES:12)
Block(-1,11,8,LEAVES:12)
Block(0,11,8,LEAVES:12)
Block(5,11,12,LEAVES:12)
Block(-5,12,-15,LEAVES:12)
Block(-4,12,-15,LEAVES:12)
Block(-9,12,-14,LEAVES:12)
Block(-8,12,-14,LEAVES:12)
Block(-4,12,-14,LEAVES:12)
Block(-3,12,-14,LEAVES:12)
Block(-2,12,-14,LEAVES:12)
Block(-8,12,-13,LEAVES:12)
Block(-7,12,-13,LEAVES:12)
Block(-6,12,-13,LEAVES:12)
Block(-5,12,-13,LEAVES:12)
Block(-4,12,-13,LEAVES:12)
Block(-3,12,-13,LEAVES:12)
Block(-5,12,-12,LEAVES:12)
Block(-4,12,-12,LOG2:12)
Block(-3,12,-12,LEAVES:12)
Block(-6,12,-11,LEAVES:12)
Block(-5,12,-11,LEAVES:12)
Block(-4,12,-11,LOG2:12)
Block(-3,12,-11,LEAVES:12)
Block(-4,12,-10,LEAVES:12)
Block(-4,12,-9,LEAVES:12)
Block(-4,12,-8,LEAVES:12)
Block(-4,12,-7,LEAVES:12)
Block(-3,12,-7,LEAVES:12)
Block(2,12,-5,LOG2:12)
Block(-5,12,-4,LOG2:12)
Block(1,12,-4,LOG2:12)
Block(2,12,-4,LOG2:12)
Block(2,12,-3,LOG2:12)
Block(-3,12,-1,LOG2:12)
Block(-2,12,-1,LOG2:12)
Block(-3,12,0,LOG2:12)
Block(-3,12,1,LOG2:12)
Block(-2,12,1,LOG2:12)
Block(-6,12,2,LOG2:12)
Block(-4,12,2,LOG2:12)
Block(-3,12,2,LOG2:12)
Block(-6,12,3,LOG2:12)
Block(-1,12,4,LEAVES:12)
Block(3,12,4,LOG2:12)
Block(4,12,4,LOG2:12)
Block(1,12,5,LOG2:12)
Block(3,12,7,LEAVES:12)
Block(4,12,7,LEAVES:12)
Block(0,12,8,LEAVES:12)
Block(1,12,8,LEAVES:12)
Block(5,12,11,LEAVES:12)
Block(5,12,12,LEAVES:12)
Block(-5,13,-16,LEAVES:12)
Block(-5,13,-15,LEAVES:12)
Block(-4,13,-14,LEAVES:12)
Block(-3,13,-14,LEAVES:12)
Block(-2,13,-14,LEAVES:12)
Block(-5,13,-13,LEAVES:12)
Block(-4,13,-13,LEAVES:12)
Block(-3,13,-13,LEAVES:12)
Block(-8,13,-12,LEAVES:12)
Block(-7,13,-12,LEAVES:12)
Block(-6,13,-12,LEAVES:12)
Block(-5,13,-12,LEAVES:12)
Block(-4,13,-12,LEAVES:12)
Block(-3,13,-12,LEAVES:12)
Block(-2,13,-12,LEAVES:12)
Block(-1,13,-12,LEAVES:12)
Block(0,13,-12,LEAVES:12)
Block(-5,13,-11,LEAVES:12)
Block(-4,13,-11,LEAVES:12)
Block(-3,13,-11,LEAVES:12)
Block(2,13,-5,LOG2:12)
Block(-6,13,-4,LOG2:12)
Block(-5,13,-4,LOG2:12)
Block(2,13,-3,LOG2:12)
Block(3,13,-3,LOG2:12)
Block(-3,13,-1,LOG2:12)
Block(-2,13,-1,LOG2:12)
Block(-4,13,2,LOG2:12)
Block(-3,13,2,LOG2:12)
Block(-2,13,2,LOG2:12)
Block(-7,13,3,LOG2:12)
Block(-6,13,3,LOG2:12)
Block(-8,13,4,LEAVES:12)
Block(-7,13,4,LOG2:12)
Block(-1,13,4,LEAVES:12)
Block(4,13,4,LOG2:12)
Block(-8,13,5,LEAVES:12)
Block(-1,13,5,LEAVES:12)
Block(0,13,5,LEAVES:12)
Block(1,13,5,LOG2:12)
Block(-13,13,6,LEAVES:12)
Block(-12,13,6,LEAVES:12)
Block(1,13,6,LOG2:12)
Block(3,13,7,LEAVES:12)
Block(1,13,8,LEAVES:12)
Block(3,13,8,LEAVES:12)
Block(-7,13,10,LEAVES:12)
Block(4,13,10,LEAVES:12)
Block(4,13,11,LEAVES:12)
Block(5,13,11,LEAVES:12)
Block(-4,14,-15,LEAVES:12)
Block(-2,14,-15,LEAVES:12)
Block(-1,14,-15,LEAVES:12)
Block(-4,14,-14,LEAVES:12)
Block(-2,14,-14,LEAVES:12)
Block(-6,14,-13,LEAVES:12)
Block(-5,14,-13,LEAVES:12)
Block(-10,14,-12,LEAVES:12)
Block(-9,14,-12,LEAVES:12)
Block(-8,14,-12,LEAVES:12)
Block(-4,14,-12,LEAVES:12)
Block(-3,14,-12,LEAVES:12)
Block(-2,14,-12,LEAVES:12)
Block(0,14,-12,LEAVES:12)
Block(1,14,-12,LEAVES:12)
Block(-5,14,-11,LEAVES:12)
Block(-3,14,-11,LEAVES:12)
Block(-6,14,-10,LEAVES:12)
Block(-5,14,-10,LEAVES:12)
Block(-3,14,-10,LEAVES:12)
Block(2,14,-5,LOG2:12)
Block(-6,14,-4,LOG2:12)
Block(3,14,-3,LOG2:12)
Block(-3,14,-1,LOG2:12)
Block(-2,14,-1,LOG2:12)
Block(-13,14,2,LEAVES:12)
Block(-4,14,2,LOG2:12)
Block(-2,14,2,LOG2:12)
Block(9,14,3,LEAVES:12)
Block(-7,14,4,LOG2:12)
Block(4,14,4,LOG2:12)
Block(5,14,4,LOG2:12)
Block(9,14,4,LEAVES:12)
Block(-9,14,5,LEAVES:12)
Block(-8,14,5,LEAVES:12)
Block(-7,14,5,LOG2:12)
Block(0,14,5,LEAVES:12)
Block(1,14,5,LEAVES:12)
Block(4,14,5,LEAVES:12)
Block(5,14,5,LEAVES:12)
Block(-12,14,6,LEAVES:12)
Block(-11,14,6,LEAVES:12)
Block(-3,14,6,LEAVES:12)
Block(1,14,6,LOG2:12)
Block(2,14,6,LOG2:12)
Block(4,14,6,LEAVES:12)
Block(1,14,7,LEAVES:12)
Block(2,14,7,LOG2:12)
Block(1,14,8,LEAVES:12)
Block(2,14,8,LEAVES:12)
Block(3,14,8,LEAVES:12)
Block(-7,14,9,LEAVES:12)
Block(0,14,9,LEAVES:12)
Block(3,14,9,LEAVES:12)
Block(10,14,9,LEAVES:12)
Block(-7,14,10,LEAVES:12)
Block(-1,14,10,LEAVES:12)
Block(0,14,10,LEAVES:12)
Block(3,14,10,LEAVES:12)
Block(4,14,10,LEAVES:12)
Block(-1,14,11,LEAVES:12)
Block(-2,14,12,LEAVES:12)
Block(-1,14,12,LEAVES:12)
Block(-4,15,-16,LEAVES:12)
Block(-4,15,-15,LEAVES:12)
Block(-1,15,-15,LEAVES:12)
Block(0,15,-15,LEAVES:12)
Block(-6,15,-13,LEAVES:12)
Block(-4,15,-12,LEAVES:12)
Block(-2,15,-12,LEAVES:12)
Block(-6,15,-10,LEAVES:12)
Block(-3,15,-10,LEAVES:12)
Block(-7,15,-9,LEAVES:12)
Block(-6,15,-9,LEAVES:12)
Block(-7,15,-8,LEAVES:12)
Block(-7,15,-7,LEAVES:12)
Block(-7,15,-6,LEAVES:12)
Block(-12,15,-5,LEAVES:12)
Block(-11,15,-5,LEAVES:12)
Block(-7,15,-5,LOG2:12)
Block(-6,15,-5,LOG2:12)
Block(2,15,-5,LOG2:12)
Block(3,15,-5,LOG2:12)
Block(-6,15,-4,LOG2:12)
Block(3,15,-3,LOG2:12)
Block(-3,15,-2,LOG2:12)
Block(3,15,-2,LOG2:12)
Block(4,15,-2,LOG2:12)
Block(-6,15,-1,LEAVES:12)
Block(-3,15,-1,LOG2:12)
Block(-2,15,-1,LOG2:12)
Block(4,15,1,LEAVES:12)
Block(-13,15,2,LEAVES:12)
Block(-4,15,2,LOG2:12)
Block(-2,15,2,LOG2:12)
Block(-1,15,2,LOG2:12)
Block(-13,15,3,LEAVES:12)
Block(-12,15,3,LEAVES:12)
Block(-4,15,3,LOG2:12)
Block(0,15,3,LEAVES:12)
Block(5,15,4,LOG2:12)
Block(8,15,4,LEAVES:12)
Block(9,15,4,LEAVES:12)
Block(-9,15,5,LEAVES:12)
Block(-8,15,5,LOG2:12)
Block(-7,15,5,LOG2:12)
Block(1,15,5,LEAVES:12)
Block(2,15,5,LEAVES:12)
Block(5,15,5,LEAVES:12)
Block(6,15,5,LEAVES:12)
Block(-11,15,6,LEAVES:12)
Block(-9,15,6,LEAVES:12)
Block(-3,15,6,LEAVES:12)
Block(-2,15,6,LEAVES:12)
Block(2,15,6,LEAVES:12)
Block(3,15,6,LEAVES:12)
Block(4,15,6,LEAVES:12)
Block(-2,15,7,LEAVES:12)
Block(-1,15,7,LEAVES:12)
Block(0,15,7,LEAVES:12)
Block(1,15,7,LEAVES:12)
Block(2,15,7,LOG2:12)
Block(3,15,7,LEAVES:12)
Block(-8,15,8,LEAVES:12)
Block(1,15,8,LEAVES:12)
Block(2,15,8,LOG2:12)
Block(3,15,8,LEAVES:12)
Block(10,15,8,LEAVES:12)
Block(-8,15,9,LEAVES:12)
Block(-7,15,9,LEAVES:12)
Block(0,15,9,LEAVES:12)
Block(1,15,9,LEAVES:12)
Block(2,15,9,LEAVES:12)
Block(3,15,9,LEAVES:12)
Block(10,15,9,LEAVES:12)
Block(2,15,10,LEAVES:12)
Block(2,15,11,LEAVES:12)
Block(2,15,12,LEAVES:12)
Block(2,15,13,LEAVES:12)
Block(3,15,13,LEAVES:12)
Block(-7,16,-14,LEAVES:12)
Block(-6,16,-14,LEAVES:12)
Block(-6,16,-13,LEAVES:12)
Block(-4,16,-12,LEAVES:12)
Block(-2,16,-12,LEAVES:12)
Block(-1,16,-12,LEAVES:12)
Block(0,16,-12,LEAVES:12)
Block(-3,16,-10,LEAVES:12)
Block(-2,16,-10,LEAVES:12)
Block(-12,16,-9,LEAVES:12)
Block(-2,16,-9,LEAVES:12)
Block(-1,16,-9,LEAVES:12)
Block(-7,16,-8,LEAVES:12)
Block(-1,16,-8,LEAVES:12)
Block(-8,16,-6,LEAVES:12)
Block(-7,16,-6,LEAVES:12)
Block(-11,16,-5,LEAVES:12)
Block(-10,16,-5,LEAVES:12)
Block(-7,16,-5,LOG2:12)
Block(3,16,-5,LOG2:12)
Block(-6,16,-2,LEAVES:12)
Block(-3,16,-2,LOG2:12)
Block(4,16,-2,LOG2:12)
Block(-6,16,-1,LEAVES:12)
Block(-3,16,-1,LOG2:12)
Block(4,16,1,LEAVES:12)
Block(-1,16,2,LOG2:12)
Block(4,16,2,LEAVES:12)
Block(5,16,2,LEAVES:12)
Block(-12,16,3,LEAVES:12)
Block(-11,16,3,LEAVES:12)
Block(-8,16,3,LEAVES:12)
Block(-7,16,3,LEAVES:12)
Block(-4,16,3,LOG2:12)
Block(0,16,3,LEAVES:12)
Block(1,16,3,LEAVES:12)
Block(-15,16,4,LEAVES:12)
Block(-11,16,4,LEAVES:12)
Block(-8,16,4,LEAVES:12)
Block(1,16,4,LEAVES:12)
Block(5,16,4,LOG2:12)
Block(6,16,4,LOG2:12)
Block(8,16,4,LEAVES:12)
Block(-11,16,5,LEAVES:12)
Block(-9,16,5,LOG2:12)
Block(-8,16,5,LOG2:12)
Block(1,16,5,LEAVES:12)
Block(6,16,5,LEAVES:12)
Block(8,16,5,LEAVES:12)
Block(-11,16,6,LEAVES:12)
Block(-10,16,6,LEAVES:12)
Block(-9,16,6,LOG2:12)
Block(2,16,6,LEAVES:12)
Block(3,16,6,LEAVES:12)
Block(4,16,6,LEAVES:12)
Block(-12,16,7,LEAVES:12)
Block(-9,16,7,LEAVES:12)
Block(1,16,7,LEAVES:12)
Block(2,16,7,LEAVES:12)
Block(3,16,7,LEAVES:12)
Block(9,16,7,LEAVES:12)
Block(-13,16,8,LEAVES:12)
Block(-12,16,8,LEAVES:12)
Block(-9,16,8,LEAVES:12)
Block(-8,16,8,LEAVES:12)
Block(-2,16,8,LEAVES:12)
Block(-1,16,8,LEAVES:12)
Block(0,16,8,LEAVES:12)
Block(1,16,8,LEAVES:12)
Block(2,16,8,LEAVES:12)
Block(3,16,8,LEAVES:12)
Block(4,16,8,LEAVES:12)
Block(5,16,8,LEAVES:12)
Block(6,16,8,LEAVES:12)
Block(9,16,8,LEAVES:12)
Block(10,16,8,LEAVES:12)
Block(-13,16,9,LEAVES:12)
Block(1,16,9,LEAVES:12)
Block(2,16,9,LEAVES:12)
Block(3,16,9,LEAVES:12)
Block(-14,16,10,LEAVES:12)
Block(-13,16,10,LEAVES:12)
Block(-7,17,-15,LEAVES:12)
Block(-7,17,-14,LEAVES:12)
Block(-4,17,-13,LEAVES:12)
Block(-4,17,-12,LEAVES:12)
Block(0,17,-12,LEAVES:12)
Block(-12,17,-9,LEAVES:12)
Block(-12,17,-8,LEAVES:12)
Block(-11,17,-8,LEAVES:12)
Block(-8,17,-6,LEAVES:12)
Block(3,17,-6,LOG2:12)
Block(-10,17,-5,LEAVES:12)
Block(-8,17,-5,LOG2:12)
Block(-7,17,-5,LOG2:12)
Block(3,17,-5,LOG2:12)
Block(-7,17,-3,LEAVES:12)
Block(8,17,-3,LEAVES:12)
Block(-7,17,-2,LEAVES:12)
Block(-6,17,-2,LEAVES:12)
Block(-4,17,-2,LOG2:12)
Block(-3,17,-2,LOG2:12)
Block(4,17,-2,LOG2:12)
Block(5,17,-2,LOG2:12)
Block(8,17,-2,LEAVES:12)
Block(3,17,-1,LEAVES:12)
Block(4,17,-1,LEAVES:12)
Block(-12,17,1,LEAVES:12)
Block(-1,17,2,LOG2:12)
Block(5,17,2,LEAVES:12)
Block(6,17,2,LEAVES:12)
Block(9,17,2,LEAVES:12)
Block(10,17,2,LEAVES:12)
Block(-11,17,3,LEAVES:12)
Block(-10,17,3,LEAVES:12)
Block(-4,17,3,LOG2:12)
Block(-1,17,3,LOG2:12)
Block(0,17,3,LOG2:12)
Block(2,17,3,LEAVES:12)
Block(6,17,3,LEAVES:12)
Block(9,17,3,LEAVES:12)
Block(-15,17,4,LEAVES:12)
Block(-14,17,4,LEAVES:12)
Block(-10,17,4,LEAVES:12)
Block(-9,17,4,LEAVES:12)
Block(-8,17,4,LEAVES:12)
Block(6,17,4,LOG2:12)
Block(7,17,4,LOG2:12)
Block(-14,17,5,LEAVES:12)
Block(-13,17,5,LEAVES:12)
Block(-12,17,5,LEAVES:12)
Block(-11,17,5,LEAVES:12)
Block(-10,17,5,LEAVES:12)
Block(-9,17,5,LEAVES:12)
Block(2,17,5,LEAVES:12)
Block(4,17,5,LEAVES:12)
Block(5,17,5,LEAVES:12)
Block(6,17,5,LEAVES:12)
Block(7,17,5,LOG2:12)
Block(8,17,5,LEAVES:12)
Block(-11,17,6,LEAVES:12)
Block(-10,17,6,LOG2:12)
Block(-9,17,6,LOG2:12)
Block(2,17,6,LEAVES:12)
Block(4,17,6,LEAVES:12)
Block(5,17,6,LEAVES:12)
Block(8,17,6,LEAVES:12)
Block(-12,17,7,LEAVES:12)
Block(-11,17,7,LEAVES:12)
Block(-10,17,7,LEAVES:12)
Block(-9,17,7,LEAVES:12)
Block(0,17,7,LEAVES:12)
Block(1,17,7,LEAVES:12)
Block(4,17,7,LEAVES:12)
Block(5,17,7,LEAVES:12)
Block(8,17,7,LEAVES:12)
Block(9,17,7,LEAVES:12)
Block(-10,17,8,LEAVES:12)
Block(-4,17,8,LEAVES:12)
Block(-3,17,8,LEAVES:12)
Block(-2,17,8,LEAVES:12)
Block(2,17,8,LEAVES:12)
Block(3,17,8,LEAVES:12)
Block(4,17,8,LEAVES:12)
Block(6,17,8,LEAVES:12)
Block(7,17,8,LEAVES:12)
Block(-10,17,9,LEAVES:12)
Block(1,17,9,LEAVES:12)
Block(3,17,9,LEAVES:12)
Block(4,17,9,LEAVES:12)
Block(-10,17,10,LEAVES:12)
Block(0,17,10,LEAVES:12)
Block(1,17,10,LEAVES:12)
Block(3,17,10,LEAVES:12)
Block(-10,17,11,LEAVES:12)
Block(-9,17,11,LEAVES:12)
Block(-4,18,-13,LEAVES:12)
Block(6,18,-9,LEAVES:12)
Block(-11,18,-8,LEAVES:12)
Block(-10,18,-8,LEAVES:12)
Block(-7,18,-8,LEAVES:12)
Block(-6,18,-8,LEAVES:12)
Block(6,18,-8,LEAVES:12)
Block(-14,18,-7,LEAVES:12)
Block(-10,18,-7,LEAVES:12)
Block(-7,18,-7,LEAVES:12)
Block(1,18,-7,LEAVES:12)
Block(2,18,-7,LEAVES:12)
Block(-10,18,-6,LEAVES:12)
Block(3,18,-6,LOG2:12)
Block(-10,18,-5,LEAVES:12)
Block(-9,18,-5,LOG2:12)
Block(-8,18,-5,LOG2:12)
Block(3,18,-5,LEAVES:12)
Block(-11,18,-4,LEAVES:12)
Block(-8,18,-4,LEAVES:12)
Block(-12,18,-3,LEAVES:12)
Block(-11,18,-3,LEAVES:12)
Block(-8,18,-3,LEAVES:12)
Block(-7,18,-3,LEAVES:12)
Block(7,18,-3,LEAVES:12)
Block(-12,18,-2,LEAVES:12)
Block(-4,18,-2,LOG2:12)
Block(-3,18,-2,LOG2:12)
Block(5,18,-2,LOG2:12)
Block(7,18,-2,LEAVES:12)
Block(8,18,-2,LEAVES:12)
Block(-13,18,-1,LEAVES:12)
Block(-12,18,-1,LEAVES:12)
Block(4,18,-1,LEAVES:12)
Block(5,18,-1,LEAVES:12)
Block(5,18,0,LEAVES:12)
Block(-12,18,1,LEAVES:12)
Block(-11,18,1,LEAVES:12)
Block(-11,18,2,LEAVES:12)
Block(6,18,2,LEAVES:12)
Block(7,18,2,LEAVES:12)
Block(9,18,2,LEAVES:12)
Block(-11,18,3,LEAVES:12)
Block(-5,18,3,LOG2:12)
Block(-4,18,3,LOG2:12)
Block(0,18,3,LOG2:12)
Block(2,18,3,LEAVES:12)
Block(3,18,3,LEAVES:12)
Block(7,18,3,LEAVES:12)
Block(8,18,3,LEAVES:12)
Block(9,18,3,LEAVES:12)
Block(-10,18,4,LEAVES:12)
Block(-9,18,4,LEAVES:12)
Block(-8,18,4,LEAVES:12)
Block(-5,18,4,LOG2:12)
Block(2,18,4,LEAVES:12)
Block(3,18,4,LEAVES:12)
Block(4,18,4,LEAVES:12)
Block(5,18,4,LEAVES:12)
Block(6,18,4,LEAVES:12)
Block(7,18,4,LEAVES:12)
Block(8,18,4,LEAVES:12)
Block(-11,18,5,LEAVES:12)
Block(-10,18,5,LEAVES:12)
Block(-9,18,5,LEAVES:12)
Block(2,18,5,LEAVES:12)
Block(5,18,5,LEAVES:12)
Block(6,18,5,LEAVES:12)
Block(7,18,5,LOG2:12)
Block(8,18,5,LEAVES:12)
Block(-14,18,6,LEAVES:12)
Block(-13,18,6,LEAVES:12)
Block(-12,18,6,LEAVES:12)
Block(-11,18,6,LEAVES:12)
Block(-10,18,6,LEAVES:12)
Block(-9,18,6,LEAVES:12)
Block(-8,18,6,LEAVES:12)
Block(-7,18,6,LEAVES:12)
Block(-6,18,6,LEAVES:12)
Block(5,18,6,LEAVES:12)
Block(6,18,6,LEAVES:12)
Block(7,18,6,LEAVES:12)
Block(8,18,6,LEAVES:12)
Block(-11,18,7,LEAVES:12)
Block(-10,18,7,LEAVES:12)
Block(-9,18,7,LEAVES:12)
Block(0,18,7,LEAVES:12)
Block(7,18,7,LEAVES:12)
Block(2,18,8,LEAVES:12)
Block(4,18,8,LEAVES:12)
Block(7,18,8,LEAVES:12)
Block(7,18,9,LEAVES:12)
Block(0,18,10,LEAVES:12)
Block(3,18,10,LEAVES:12)
Block(7,18,10,LEAVES:12)
Block(8,18,10,LEAVES:12)
Block(-1,18,11,LEAVES:12)
Block(0,18,11,LEAVES:12)
Block(-1,18,12,LEAVES:12)
Block(1,19,-11,LEAVES:12)
Block(-11,19,-10,LEAVES:12)
Block(-10,19,-8,LEAVES:12)
Block(-9,19,-8,LEAVES:12)
Block(5,19,-8,LEAVES:12)
Block(6,19,-8,LEAVES:12)
Block(-14,19,-7,LEAVES:12)
Block(-13,19,-7,LEAVES:12)
Block(-9,19,-7,LEAVES:12)
Block(-8,19,-7,LEAVES:12)
Block(-7,19,-7,LEAVES:12)
Block(2,19,-7,LEAVES:12)
Block(3,19,-7,LEAVES:12)
Block(-13,19,-6,LEAVES:12)
Block(-12,19,-6,LEAVES:12)
Block(-11,19,-6,LEAVES:12)
Block(-10,19,-6,LEAVES:12)
Block(-9,19,-6,LEAVES:12)
Block(-8,19,-6,LEAVES:12)
Block(3,19,-6,LOG2:12)
Block(-10,19,-5,LEAVES:12)
Block(-9,19,-5,LOG2:12)
Block(-8,19,-5,LEAVES:12)
Block(3,19,-5,LEAVES:12)
Block(-11,19,-4,LEAVES:12)
Block(-10,19,-4,LEAVES:12)
Block(-9,19,-4,LEAVES:12)
Block(-8,19,-4,LEAVES:12)
Block(3,19,-4,LEAVES:12)
Block(4,19,-4,LEAVES:12)
Block(7,19,-4,LEAVES:12)
Block(-9,19,-3,LEAVES:12)
Block(-5,19,-3,LOG2:12)
Block(-4,19,-3,LOG2:12)
Block(7,19,-3,LEAVES:12)
Block(-9,19,-2,LEAVES:12)
Block(-4,19,-2,LOG2:12)
Block(-3,19,-2,LOG2:12)
Block(5,19,-2,LOG2:12)
Block(6,19,-2,LOG2:12)
Block(7,19,-2,LEAVES:12)
Block(-9,19,-1,LEAVES:12)
Block(5,19,-1,LEAVES:12)
Block(6,19,-1,LOG2:12)
Block(7,19,-1,LEAVES:12)
Block(-9,19,0,LEAVES:12)
Block(-8,19,0,LEAVES:12)
Block(5,19,0,LEAVES:12)
Block(6,19,0,LEAVES:12)
Block(6,19,1,LEAVES:12)
Block(8,19,1,LEAVES:12)
Block(6,19,2,LEAVES:12)
Block(8,19,2,LEAVES:12)
Block(9,19,2,LEAVES:12)
Block(-10,19,3,LEAVES:12)
Block(-8,19,3,LEAVES:12)
Block(-7,19,3,LEAVES:12)
Block(0,19,3,LOG2:12)
Block(1,19,3,LOG2:12)
Block(7,19,3,LEAVES:12)
Block(8,19,3,LEAVES:12)
Block(9,19,3,LEAVES:12)
Block(-10,19,4,LEAVES:12)
Block(-8,19,4,LEAVES:12)
Block(-5,19,4,LOG2:12)
Block(6,19,4,LEAVES:12)
Block(7,19,4,LEAVES:12)
Block(8,19,4,LEAVES:12)
Block(-12,19,5,LEAVES:12)
Block(-11,19,5,LEAVES:12)
Block(3,19,5,LEAVES:12)
Block(4,19,5,LEAVES:12)
Block(5,19,5,LEAVES:12)
Block(6,19,5,LEAVES:12)
Block(7,19,5,LEAVES:12)
Block(8,19,5,LEAVES:12)
Block(9,19,5,LEAVES:12)
Block(10,19,5,LEAVES:12)
Block(11,19,5,LEAVES:12)
Block(-16,19,6,LEAVES:12)
Block(-15,19,6,LEAVES:12)
Block(-14,19,6,LEAVES:12)
Block(-10,19,6,LEAVES:12)
Block(-9,19,6,LEAVES:12)
Block(-8,19,6,LEAVES:12)
Block(-6,19,6,LEAVES:12)
Block(-5,19,6,LEAVES:12)
Block(-1,19,6,LEAVES:12)
Block(0,19,6,LEAVES:12)
Block(6,19,6,LEAVES:12)
Block(7,19,6,LEAVES:12)
Block(8,19,6,LEAVES:12)
Block(-11,19,7,LEAVES:12)
Block(-9,19,7,LEAVES:12)
Block(0,19,7,LEAVES:12)
Block(-12,19,8,LEAVES:12)
Block(-11,19,8,LEAVES:12)
Block(-9,19,8,LEAVES:12)
Block(2,19,8,LEAVES:12)
Block(4,19,8,LEAVES:12)
Block(5,19,8,LEAVES:12)
Block(6,19,8,LEAVES:12)
Block(3,19,10,LEAVES:12)
Block(4,19,10,LEAVES:12)
Block(4,19,11,LEAVES:12)
Block(5,19,11,LEAVES:12)
Block(-1,19,12,LEAVES:12)
Block(5,19,12,LEAVES:12)
Block(1,20,-11,LEAVES:12)
Block(-11,20,-10,LEAVES:12)
Block(-10,20,-10,LEAVES:12)
Block(1,20,-10,LEAVES:12)
Block(2,20,-10,LEAVES:12)
Block(-10,20,-9,LEAVES:12)
Block(-10,20,-8,LEAVES:12)
Block(5,20,-8,LEAVES:12)
Block(-9,20,-7,LEAVES:12)
Block(-8,20,-7,LEAVES:12)
Block(-7,20,-7,LEAVES:12)
Block(3,20,-7,LEAVES:12)
Block(4,20,-7,LOG2:12)
Block(5,20,-7,LEAVES:12)
Block(-10,20,-6,LEAVES:12)
Block(-9,20,-6,LEAVES:12)
Block(-8,20,-6,LEAVES:12)
Block(3,20,-6,LOG2:12)
Block(4,20,-6,LOG2:12)
Block(-13,20,-5,LEAVES:12)
Block(-12,20,-5,LEAVES:12)
Block(-11,20,-5,LEAVES:12)
Block(-10,20,-5,LEAVES:12)
Block(-9,20,-5,LEAVES:12)
Block(-8,20,-5,LEAVES:12)
Block(-7,20,-5,LEAVES:12)
Block(-6,20,-5,LEAVES:12)
Block(-5,20,-5,LEAVES:12)
Block(6,20,-5,LEAVES:12)
Block(-10,20,-4,LEAVES:12)
Block(-9,20,-4,LEAVES:12)
Block(-8,20,-4,LEAVES:12)
Block(4,20,-4,LEAVES:12)
Block(5,20,-4,LEAVES:12)
Block(6,20,-4,LEAVES:12)
Block(7,20,-4,LEAVES:12)
Block(8,20,-4,LEAVES:12)
Block(9,20,-4,LEAVES:12)
Block(-5,20,-3,LOG2:12)
Block(-4,20,-3,LOG2:12)
Block(1,20,-3,LEAVES:12)
Block(5,20,-3,LEAVES:12)
Block(8,20,-3,LEAVES:12)
Block(-4,20,-2,LOG2:12)
Block(5,20,-2,LEAVES:12)
Block(5,20,-1,LEAVES:12)
Block(6,20,-1,LOG2:12)
Block(7,20,-1,LEAVES:12)
Block(4,20,0,LEAVES:12)
Block(7,20,0,LEAVES:12)
Block(-10,20,1,LEAVES:12)
Block(-9,20,1,LEAVES:12)
Block(3,20,1,LEAVES:12)
Block(4,20,1,LEAVES:12)
Block(7,20,1,LEAVES:12)
Block(8,20,1,LEAVES:12)
Block(-10,20,2,LEAVES:12)
Block(3,20,2,LEAVES:12)
Block(7,20,2,LEAVES:12)
Block(9,20,2,LEAVES:12)
Block(10,20,2,LEAVES:12)
Block(-10,20,3,LEAVES:12)
Block(-7,20,3,LEAVES:12)
Block(-6,20,3,LEAVES:12)
Block(1,20,3,LOG2:12)
Block(2,20,3,LEAVES:12)
Block(3,20,3,LEAVES:12)
Block(7,20,3,LEAVES:12)
Block(9,20,3,LEAVES:12)
Block(-5,20,4,LOG2:12)
Block(5,20,4,LEAVES:12)
Block(6,20,4,LEAVES:12)
Block(-12,20,5,LEAVES:12)
Block(-1,20,5,LEAVES:12)
Block(1,20,5,LEAVES:12)
Block(2,20,5,LEAVES:12)
Block(3,20,5,LEAVES:12)
Block(7,20,5,LEAVES:12)
Block(8,20,5,LEAVES:12)
Block(9,20,5,LEAVES:12)
Block(11,20,5,LEAVES:12)
Block(12,20,5,LEAVES:12)
Block(-10,20,6,LEAVES:12)
Block(-8,20,6,LEAVES:12)
Block(-1,20,6,LEAVES:12)
Block(6,20,6,LEAVES:12)
Block(8,20,6,LEAVES:12)
Block(2,20,7,LEAVES:12)
Block(5,20,7,LEAVES:12)
Block(6,20,7,LEAVES:12)
Block(8,20,7,LEAVES:12)
Block(-12,20,8,LEAVES:12)
Block(-9,20,8,LEAVES:12)
Block(2,20,8,LEAVES:12)
Block(6,20,8,LEAVES:12)
Block(-13,20,9,LEAVES:12)
Block(-12,20,9,LEAVES:12)
Block(-13,20,10,LEAVES:12)
Block(2,21,-10,LEAVES:12)
Block(3,21,-10,LEAVES:12)
Block(6,21,-10,LEAVES:12)
Block(7,21,-10,LEAVES:12)
Block(-1,21,-9,LEAVES:12)
Block(3,21,-9,LEAVES:12)
Block(6,21,-9,LEAVES:12)
Block(-9,21,-8,LEAVES:12)
Block(-7,21,-8,LEAVES:12)
Block(-6,21,-8,LEAVES:12)
Block(3,21,-8,LEAVES:12)
Block(-9,21,-7,LEAVES:12)
Block(-7,21,-7,LEAVES:12)
Block(3,21,-7,LEAVES:12)
Block(4,21,-7,LOG2:12)
Block(5,21,-7,LEAVES:12)
Block(-11,21,-6,LEAVES:12)
Block(-10,21,-6,LEAVES:12)
Block(2,21,-6,LEAVES:12)
Block(4,21,-6,LEAVES:12)
Block(5,21,-6,LEAVES:12)
Block(-15,21,-5,LEAVES:12)
Block(-14,21,-5,LEAVES:12)
Block(-13,21,-5,LEAVES:12)
Block(-9,21,-5,LEAVES:12)
Block(-8,21,-5,LEAVES:12)
Block(-7,21,-5,LEAVES:12)
Block(-5,21,-5,LEAVES:12)
Block(-4,21,-5,LEAVES:12)
Block(1,21,-5,LEAVES:12)
Block(2,21,-5,LEAVES:12)
Block(5,21,-5,LEAVES:12)
Block(6,21,-5,LEAVES:12)
Block(-10,21,-4,LEAVES:12)
Block(-8,21,-4,LEAVES:12)
Block(1,21,-4,LEAVES:12)
Block(5,21,-4,LEAVES:12)
Block(6,21,-4,LEAVES:12)
Block(-11,21,-3,LEAVES:12)
Block(-10,21,-3,LEAVES:12)
Block(-8,21,-3,LEAVES:12)
Block(-5,21,-3,LOG2:12)
Block(-4,21,-3,LOG2:12)
Block(0,21,-3,LEAVES:12)
Block(1,21,-3,LEAVES:12)
Block(2,21,-3,LEAVES:12)
Block(6,21,-3,LEAVES:12)
Block(7,21,-3,LEAVES:12)
Block(8,21,-3,LEAVES:12)
Block(2,21,-2,LEAVES:12)
Block(3,21,-2,LEAVES:12)
Block(4,21,-2,LEAVES:12)
Block(5,21,-2,LEAVES:12)
Block(6,21,-2,LEAVES:12)
Block(7,21,-2,LEAVES:12)
Block(5,21,-1,LEAVES:12)
Block(6,21,-1,LOG2:12)
Block(7,21,-1,LEAVES:12)
Block(4,21,0,LEAVES:12)
Block(5,21,0,LEAVES:12)
Block(6,21,0,LEAVES:12)
Block(7,21,0,LEAVES:12)
Block(8,21,0,LEAVES:12)
Block(6,21,1,LEAVES:12)
Block(7,21,1,LEAVES:12)
Block(6,21,2,LEAVES:12)
Block(7,21,2,LEAVES:12)
Block(10,21,2,LEAVES:12)
Block(11,21,2,LEAVES:12)
Block(-5,21,3,LOG2:12)
Block(1,21,3,LOG2:12)
Block(2,21,3,LOG2:12)
Block(6,21,3,LEAVES:12)
Block(-13,21,4,LEAVES:12)
Block(-12,21,4,LEAVES:12)
Block(-5,21,4,LOG2:12)
Block(5,21,4,LEAVES:12)
Block(6,21,4,LEAVES:12)
Block(7,21,4,LEAVES:12)
Block(-12,21,5,LEAVES:12)
Block(-5,21,5,LOG2:12)
Block(7,21,5,LEAVES:12)
Block(9,21,5,LEAVES:12)
Block(-10,21,6,LEAVES:12)
Block(-8,21,6,LEAVES:12)
Block(-7,21,6,LEAVES:12)
Block(-6,21,6,LEAVES:12)
Block(2,21,7,LEAVES:12)
Block(5,21,7,LEAVES:12)
Block(8,21,7,LEAVES:12)
Block(-9,21,8,LEAVES:12)
Block(-8,21,8,LEAVES:12)
Block(4,21,8,LEAVES:12)
Block(5,21,8,LEAVES:12)
Block(-8,21,9,LEAVES:12)
Block(-7,21,9,LEAVES:12)
Block(4,21,9,LEAVES:12)
Block(-13,21,10,LEAVES:12)
Block(-7,21,10,LEAVES:12)
Block(2,22,-12,LEAVES:12)
Block(-9,22,-10,LEAVES:12)
Block(-8,22,-10,LEAVES:12)
Block(3,22,-10,LEAVES:12)
Block(4,22,-10,LEAVES:12)
Block(-9,22,-9,LEAVES:12)
Block(-1,22,-9,LEAVES:12)
Block(0,22,-9,LEAVES:12)
Block(4,22,-9,LEAVES:12)
Block(5,22,-9,LEAVES:12)
Block(6,22,-9,LEAVES:12)
Block(-9,22,-8,LEAVES:12)
Block(-6,22,-8,LEAVES:12)
Block(-5,22,-8,LEAVES:12)
Block(0,22,-8,LEAVES:12)
Block(1,22,-8,LEAVES:12)
Block(2,22,-8,LEAVES:12)
Block(3,22,-8,LEAVES:12)
Block(4,22,-8,LEAVES:12)
Block(5,22,-8,LEAVES:12)
Block(3,22,-7,LEAVES:12)
Block(4,22,-7,LOG2:12)
Block(5,22,-7,LEAVES:12)
Block(-11,22,-6,LEAVES:12)
Block(2,22,-6,LEAVES:12)
Block(3,22,-6,LEAVES:12)
Block(4,22,-6,LEAVES:12)
Block(5,22,-6,LEAVES:12)
Block(-9,22,-5,LEAVES:12)
Block(-7,22,-5,LEAVES:12)
Block(4,22,-5,LEAVES:12)
Block(5,22,-5,LEAVES:12)
Block(-6,22,-4,LOG2:12)
Block(-5,22,-4,LOG2:12)
Block(4,22,-4,LEAVES:12)
Block(5,22,-4,LEAVES:12)
Block(-11,22,-3,LEAVES:12)
Block(-8,22,-3,LEAVES:12)
Block(-5,22,-3,LOG2:12)
Block(4,22,-3,LEAVES:12)
Block(6,22,-3,LEAVES:12)
Block(7,22,-3,LEAVES:12)
Block(8,22,-3,LEAVES:12)
Block(-12,22,-2,LEAVES:12)
Block(-11,22,-2,LEAVES:12)
Block(4,22,-2,LEAVES:12)
Block(5,22,-2,LEAVES:12)
Block(6,22,-2,LEAVES:12)
Block(7,22,-2,LEAVES:12)
Block(-12,22,-1,LEAVES:12)
Block(2,22,-1,LEAVES:12)
Block(3,22,-1,LEAVES:12)
Block(4,22,-1,LEAVES:12)
Block(5,22,-1,LEAVES:12)
Block(6,22,-1,LEAVES:12)
Block(7,22,-1,LEAVES:12)
Block(8,22,-1,LEAVES:12)
Block(9,22,-1,LEAVES:12)
Block(10,22,-1,LEAVES:12)
Block(5,22,0,LEAVES:12)
Block(6,22,0,LEAVES:12)
Block(7,22,0,LEAVES:12)
Block(-13,22,3,LEAVES:12)
Block(-5,22,3,LOG2:12)
Block(2,22,3,LOG2:12)
Block(4,22,3,LEAVES:12)
Block(5,22,3,LEAVES:12)
Block(-13,22,4,LEAVES:12)
Block(2,22,4,LOG2:12)
Block(5,22,4,LEAVES:12)
Block(-10,22,5,LEAVES:12)
Block(-6,22,5,LOG2:12)
Block(-5,22,5,LOG2:12)
Block(7,22,5,LEAVES:12)
Block(9,22,5,LEAVES:12)
Block(10,22,5,LEAVES:12)
Block(11,22,5,LEAVES:12)
Block(-10,22,6,LEAVES:12)
Block(-6,22,6,LEAVES:12)
Block(8,22,7,LEAVES:12)
Block(9,22,7,LEAVES:12)
Block(9,22,8,LEAVES:12)
Block(10,22,8,LEAVES:12)
Block(4,22,9,LEAVES:12)
Block(10,22,9,LEAVES:12)
Block(2,23,-12,LEAVES:12)
Block(3,23,-12,LEAVES:12)
Block(3,23,-11,LEAVES:12)
Block(3,23,-10,LEAVES:12)
Block(4,23,-9,LEAVES:12)
Block(5,23,-9,LEAVES:12)
Block(6,23,-9,LEAVES:12)
Block(3,23,-8,LEAVES:12)
Block(4,23,-8,LEAVES:12)
Block(5,23,-8,LEAVES:12)
Block(-12,23,-7,LEAVES:12)
Block(-11,23,-7,LEAVES:12)
Block(0,23,-7,LEAVES:12)
Block(1,23,-7,LEAVES:12)
Block(2,23,-7,LEAVES:12)
Block(3,23,-7,LEAVES:12)
Block(4,23,-7,LEAVES:12)
Block(5,23,-7,LEAVES:12)
Block(6,23,-7,LEAVES:12)
Block(7,23,-7,LEAVES:12)
Block(8,23,-7,LEAVES:12)
Block(-11,23,-6,LEAVES:12)
Block(3,23,-6,LEAVES:12)
Block(4,23,-6,LEAVES:12)
Block(5,23,-6,LEAVES:12)
Block(-9,23,-5,LEAVES:12)
Block(-7,23,-5,LEAVES:12)
Block(-6,23,-5,LEAVES:12)
Block(-5,23,-5,LEAVES:12)
Block(-6,23,-4,LOG2:12)
Block(6,23,-4,LEAVES:12)
Block(8,23,-4,LEAVES:12)
Block(9,23,-4,LEAVES:12)
Block(-8,23,-3,LEAVES:12)
Block(-7,23,-3,LEAVES:12)
Block(6,23,-3,LEAVES:12)
Block(8,23,-3,LEAVES:12)
Block(-7,23,-2,LEAVES:12)
Block(-6,23,-2,LEAVES:12)
Block(4,23,-2,LEAVES:12)
Block(5,23,-2,LEAVES:12)
Block(-12,23,-1,LEAVES:12)
Block(-6,23,-1,LEAVES:12)
Block(0,23,-1,LEAVES:12)
Block(1,23,-1,LEAVES:12)
Block(2,23,-1,LEAVES:12)
Block(6,23,-1,LEAVES:12)
Block(7,23,-1,LEAVES:12)
Block(8,23,-1,LEAVES:12)
Block(10,23,-1,LEAVES:12)
Block(11,23,-1,LEAVES:12)
Block(5,23,0,LEAVES:12)
Block(7,23,0,LEAVES:12)
Block(4,23,1,LEAVES:12)
Block(5,23,1,LEAVES:12)
Block(7,23,1,LEAVES:12)
Block(4,23,2,LEAVES:12)
Block(-5,23,3,LOG2:12)
Block(4,23,3,LEAVES:12)
Block(2,23,4,LOG2:12)
Block(7,23,4,LEAVES:12)
Block(-10,23,5,LEAVES:12)
Block(-6,23,5,LOG2:12)
Block(7,23,5,LEAVES:12)
Block(11,23,5,LEAVES:12)
Block(4,24,-10,LEAVES:12)
Block(6,24,-10,LEAVES:12)
Block(7,24,-10,LEAVES:12)
Block(4,24,-9,LEAVES:12)
Block(6,24,-9,LEAVES:12)
Block(-12,24,-8,LEAVES:12)
Block(2,24,-8,LEAVES:12)
Block(3,24,-8,LEAVES:12)
Block(-12,24,-7,LEAVES:12)
Block(-2,24,-7,LEAVES:12)
Block(-1,24,-7,LEAVES:12)
Block(0,24,-7,LEAVES:12)
Block(4,24,-7,LEAVES:12)
Block(5,24,-7,LEAVES:12)
Block(6,24,-7,LEAVES:12)
Block(8,24,-7,LEAVES:12)
Block(9,24,-7,LEAVES:12)
Block(-9,24,-6,LEAVES:12)
Block(3,24,-6,LEAVES:12)
Block(5,24,-6,LEAVES:12)
Block(6,24,-6,LEAVES:12)
Block(7,24,-6,LEAVES:12)
Block(-9,24,-5,LEAVES:12)
Block(-6,24,-5,LOG2:12)
Block(-5,24,-5,LEAVES:12)
Block(2,24,-5,LEAVES:12)
Block(3,24,-5,LEAVES:12)
Block(5,24,-5,LEAVES:12)
Block(6,24,-5,LEAVES:12)
Block(-6,24,-4,LOG2:12)
Block(6,24,-4,LEAVES:12)
Block(9,24,-4,LEAVES:12)
Block(10,24,-4,LEAVES:12)
Block(4,24,-2,LEAVES:12)
Block(6,24,-1,LEAVES:12)
Block(8,24,-1,LEAVES:12)
Block(4,24,1,LEAVES:12)
Block(7,24,1,LEAVES:12)
Block(-5,24,2,LOG2:12)
Block(3,24,2,LEAVES:12)
Block(4,24,2,LEAVES:12)
Block(-5,24,3,LOG2:12)
Block(3,24,3,LEAVES:12)
Block(5,24,3,LEAVES:12)
Block(2,24,4,LOG2:12)
Block(3,24,4,LOG2:12)
Block(5,24,4,LEAVES:12)
Block(7,24,4,LEAVES:12)
Block(-6,24,5,LOG2:12)
Block(0,24,5,LEAVES:12)
Block(1,24,5,LEAVES:12)
Block(-6,24,6,LOG2:12)
Block(-5,24,6,LEAVES:12)
Block(-5,24,7,LEAVES:12)
Block(-10,24,8,LEAVES:12)
Block(-9,24,8,LEAVES:12)
Block(6,24,9,LEAVES:12)
Block(-4,24,12,LEAVES:12)
Block(4,25,-12,LEAVES:12)
Block(5,25,-12,LEAVES:12)
Block(4,25,-11,LEAVES:12)
Block(4,25,-10,LEAVES:12)
Block(7,25,-10,LEAVES:12)
Block(8,25,-10,LEAVES:12)
Block(-5,25,-8,LEAVES:12)
Block(2,25,-8,LEAVES:12)
Block(-5,25,-7,LEAVES:12)
Block(4,25,-7,LEAVES:12)
Block(6,25,-7,LEAVES:12)
Block(-10,25,-6,LEAVES:12)
Block(-9,25,-6,LEAVES:12)
Block(-6,25,-5,LOG2:12)
Block(2,25,-5,LEAVES:12)
Block(5,25,-5,LEAVES:12)
Block(1,25,-4,LEAVES:12)
Block(2,25,-4,LEAVES:12)
Block(1,25,-3,LEAVES:12)
Block(3,25,-3,LEAVES:12)
Block(4,25,-3,LEAVES:12)
Block(-4,25,-2,LEAVES:12)
Block(4,25,-2,LEAVES:12)
Block(6,25,-1,LEAVES:12)
Block(8,25,-1,LEAVES:12)
Block(9,25,-1,LEAVES:12)
Block(10,25,-1,LEAVES:12)
Block(0,25,1,LEAVES:12)
Block(7,25,1,LEAVES:12)
Block(8,25,1,LEAVES:12)
Block(-5,25,2,LOG2:12)
Block(8,25,2,LEAVES:12)
Block(9,25,2,LEAVES:12)
Block(3,25,3,LEAVES:12)
Block(9,25,3,LEAVES:12)
Block(-10,25,4,LEAVES:12)
Block(3,25,4,LOG2:12)
Block(4,25,4,LEAVES:12)
Block(5,25,4,LEAVES:12)
Block(1,25,5,LEAVES:12)
Block(2,25,5,LEAVES:12)
Block(-6,25,6,LOG2:12)
Block(-6,25,7,LEAVES:12)
Block(-5,25,7,LEAVES:12)
Block(-9,25,8,LEAVES:12)
Block(-8,25,8,LEAVES:12)
Block(6,25,8,LEAVES:12)
Block(6,25,9,LEAVES:12)
Block(-4,25,11,LEAVES:12)
Block(-4,25,12,LEAVES:12)
Block(-10,26,-10,LEAVES:12)
Block(1,26,-9,LEAVES:12)
Block(2,26,-9,LEAVES:12)
Block(2,26,-8,LEAVES:12)
Block(-6,26,-7,LEAVES:12)
Block(-5,26,-7,LEAVES:12)
Block(4,26,-7,LEAVES:12)
Block(6,26,-7,LEAVES:12)
Block(7,26,-7,LEAVES:12)
Block(8,26,-7,LEAVES:12)
Block(-9,26,-6,LEAVES:12)
Block(-8,26,-6,LEAVES:12)
Block(-7,26,-5,LOG2:12)
Block(-6,26,-5,LOG2:12)
Block(5,26,-5,LEAVES:12)
Block(6,26,-5,LEAVES:12)
Block(3,26,-4,LEAVES:12)
Block(6,26,-4,LEAVES:12)
Block(7,26,-4,LEAVES:12)
Block(-4,26,-3,LEAVES:12)
Block(1,26,-3,LEAVES:12)
Block(3,26,-3,LEAVES:12)
Block(7,26,-3,LEAVES:12)
Block(-4,26,-2,LEAVES:12)
Block(6,26,-2,LEAVES:12)
Block(6,26,-1,LEAVES:12)
Block(10,26,-1,LEAVES:12)
Block(0,26,1,LEAVES:12)
Block(-5,26,2,LOG2:12)
Block(0,26,2,LEAVES:12)
Block(1,26,2,LEAVES:12)
Block(-10,26,4,LEAVES:12)
Block(3,26,4,LOG2:12)
Block(4,26,4,LEAVES:12)
Block(-10,26,5,LEAVES:12)
Block(-9,26,5,LEAVES:12)
Block(2,26,5,LEAVES:12)
Block(3,26,5,LOG2:12)
Block(4,26,5,LEAVES:12)
Block(-7,26,6,LOG2:12)
Block(-6,26,6,LOG2:12)
Block(-7,26,7,LOG2:12)
Block(-6,26,7,LEAVES:12)
Block(5,26,7,LEAVES:12)
Block(-8,26,8,LEAVES:12)
Block(-6,26,8,LEAVES:12)
Block(5,26,8,LEAVES:12)
Block(6,26,8,LEAVES:12)
Block(-5,26,10,LEAVES:12)
Block(-5,26,11,LEAVES:12)
Block(-4,26,11,LEAVES:12)
Block(-10,27,-10,LEAVES:12)
Block(1,27,-10,LEAVES:12)
Block(-10,27,-9,LEAVES:12)
Block(-9,27,-9,LEAVES:12)
Block(1,27,-9,LEAVES:12)
Block(4,27,-8,LEAVES:12)
Block(-6,27,-7,LEAVES:12)
Block(4,27,-7,LEAVES:12)
Block(8,27,-7,LEAVES:12)
Block(-8,27,-6,LEAVES:12)
Block(-7,27,-6,LOG2:12)
Block(-6,27,-6,LEAVES:12)
Block(-7,27,-5,LOG2:12)
Block(-5,27,-4,LEAVES:12)
Block(-5,27,-3,LEAVES:12)
Block(-4,27,-3,LEAVES:12)
Block(6,27,-2,LEAVES:12)
Block(-5,27,2,LOG2:12)
Block(-4,27,2,LOG2:12)
Block(1,27,2,LEAVES:12)
Block(2,27,2,LEAVES:12)
Block(5,27,2,LEAVES:12)
Block(6,27,2,LEAVES:12)
Block(-2,27,3,LEAVES:12)
Block(2,27,3,LEAVES:12)
Block(5,27,3,LEAVES:12)
Block(2,27,4,LEAVES:12)
Block(-9,27,5,LEAVES:12)
Block(-8,27,5,LEAVES:12)
Block(-5,27,5,LEAVES:12)
Block(-4,27,5,LEAVES:12)
Block(2,27,5,LEAVES:12)
Block(3,27,5,LOG2:12)
Block(4,27,5,LEAVES:12)
Block(-12,27,6,LEAVES:12)
Block(-8,27,6,LEAVES:12)
Block(-5,27,6,LEAVES:12)
Block(1,27,6,LEAVES:12)
Block(4,27,6,LEAVES:12)
Block(-8,27,7,LEAVES:12)
Block(-7,27,7,LOG2:12)
Block(0,27,7,LEAVES:12)
Block(1,27,7,LEAVES:12)
Block(4,27,7,LEAVES:12)
Block(5,27,7,LEAVES:12)
Block(-8,27,8,LEAVES:12)
Block(-7,27,8,LEAVES:12)
Block(-6,27,8,LEAVES:12)
Block(0,27,8,LEAVES:12)
Block(-9,27,9,LEAVES:12)
Block(-6,27,9,LEAVES:12)
Block(-1,27,9,LEAVES:12)
Block(0,27,9,LEAVES:12)
Block(-10,27,10,LEAVES:12)
Block(-9,27,10,LEAVES:12)
Block(-6,27,10,LEAVES:12)
Block(-5,27,10,LEAVES:12)
Block(-10,27,11,LEAVES:12)
Block(-11,27,12,LEAVES:12)
Block(-10,27,12,LEAVES:12)
Block(-9,28,-9,LEAVES:12)
Block(-8,28,-9,LEAVES:12)
Block(-5,28,-9,LEAVES:12)
Block(-4,28,-9,LEAVES:12)
Block(-12,28,-8,LEAVES:12)
Block(-8,28,-8,LEAVES:12)
Block(-5,28,-8,LEAVES:12)
Block(4,28,-8,LEAVES:12)
Block(-8,28,-7,LEAVES:12)
Block(-8,28,-6,LEAVES:12)
Block(-7,28,-6,LOG2:12)
Block(-6,28,-6,LEAVES:12)
Block(-9,28,-5,LEAVES:12)
Block(-6,28,-5,LEAVES:12)
Block(-10,28,-4,LEAVES:12)
Block(-9,28,-4,LEAVES:12)
Block(-6,28,-4,LEAVES:12)
Block(-5,28,-4,LEAVES:12)
Block(-10,28,-3,LEAVES:12)
Block(-11,28,-2,LEAVES:12)
Block(-10,28,-2,LEAVES:12)
Block(1,28,0,LEAVES:12)
Block(-4,28,2,LOG2:12)
Block(2,28,2,LEAVES:12)
Block(3,28,2,LEAVES:12)
Block(-9,28,3,LEAVES:12)
Block(-2,28,3,LEAVES:12)
Block(-1,28,3,LEAVES:12)
Block(3,28,3,LEAVES:12)
Block(4,28,3,LEAVES:12)
Block(5,28,3,LEAVES:12)
Block(-1,28,4,LEAVES:12)
Block(0,28,4,LEAVES:12)
Block(1,28,4,LEAVES:12)
Block(2,28,4,LEAVES:12)
Block(3,28,4,LEAVES:12)
Block(4,28,4,LEAVES:12)
Block(-8,28,5,LEAVES:12)
Block(-7,28,5,LEAVES:12)
Block(2,28,5,LEAVES:12)
Block(3,28,5,LOG2:12)
Block(4,28,5,LEAVES:12)
Block(-12,28,6,LEAVES:12)
Block(-11,28,6,LEAVES:12)
Block(-7,28,6,LEAVES:12)
Block(-6,28,6,LEAVES:12)
Block(-5,28,6,LEAVES:12)
Block(1,28,6,LEAVES:12)
Block(2,28,6,LEAVES:12)
Block(3,28,6,LEAVES:12)
Block(4,28,6,LEAVES:12)
Block(-11,28,7,LEAVES:12)
Block(-10,28,7,LEAVES:12)
Block(-9,28,7,LEAVES:12)
Block(-8,28,7,LEAVES:12)
Block(-7,28,7,LOG2:12)
Block(-6,28,7,LEAVES:12)
Block(3,28,7,LEAVES:12)
Block(-8,28,8,LEAVES:12)
Block(-7,28,8,LOG2:12)
Block(-6,28,8,LEAVES:12)
Block(3,28,8,LEAVES:12)
Block(-9,28,9,LEAVES:12)
Block(-8,28,9,LEAVES:12)
Block(-7,28,9,LEAVES:12)
Block(-6,28,9,LEAVES:12)
Block(3,28,9,LEAVES:12)
Block(-7,28,10,LEAVES:12)
Block(3,28,10,LEAVES:12)
Block(4,28,10,LEAVES:12)
Block(-7,28,11,LEAVES:12)
Block(-7,28,12,LEAVES:12)
Block(-7,28,13,LEAVES:12)
Block(-6,28,13,LEAVES:12)
Block(-9,29,-11,LEAVES:12)
Block(-8,29,-9,LEAVES:12)
Block(-7,29,-9,LEAVES:12)
Block(-12,29,-8,LEAVES:12)
Block(-11,29,-8,LEAVES:12)
Block(-7,29,-8,LEAVES:12)
Block(-6,29,-8,LEAVES:12)
Block(-5,29,-8,LEAVES:12)
Block(-11,29,-7,LEAVES:12)
Block(-10,29,-7,LEAVES:12)
Block(-9,29,-7,LEAVES:12)
Block(-8,29,-7,LEAVES:12)
Block(-7,29,-7,LEAVES:12)
Block(-6,29,-7,LEAVES:12)
Block(-8,29,-6,LEAVES:12)
Block(-7,29,-6,LOG2:12)
Block(-6,29,-6,LEAVES:12)
Block(-9,29,-5,LEAVES:12)
Block(-8,29,-5,LEAVES:12)
Block(-7,29,-5,LEAVES:12)
Block(-6,29,-5,LEAVES:12)
Block(-7,29,-4,LEAVES:12)
Block(-7,29,-3,LEAVES:12)
Block(-7,29,-2,LEAVES:12)
Block(-7,29,-1,LEAVES:12)
Block(-6,29,-1,LEAVES:12)
Block(0,29,-1,LEAVES:12)
Block(0,29,0,LEAVES:12)
Block(1,29,0,LEAVES:12)
Block(2,29,0,LEAVES:12)
Block(-5,29,1,LEAVES:12)
Block(-4,29,1,LOG2:12)
Block(-3,29,1,LOG2:12)
Block(2,29,1,LEAVES:12)
Block(-4,29,2,LOG2:12)
Block(2,29,2,LEAVES:12)
Block(-9,29,3,LEAVES:12)
Block(-8,29,3,LEAVES:12)
Block(3,29,3,LEAVES:12)
Block(4,29,3,LEAVES:12)
Block(5,29,3,LEAVES:12)
Block(-8,29,4,LEAVES:12)
Block(2,29,4,LEAVES:12)
Block(3,29,4,LEAVES:12)
Block(4,29,4,LEAVES:12)
Block(-8,29,5,LEAVES:12)
Block(-1,29,5,LEAVES:12)
Block(0,29,5,LEAVES:12)
Block(1,29,5,LEAVES:12)
Block(2,29,5,LEAVES:12)
Block(3,29,5,LEAVES:12)
Block(4,29,5,LEAVES:12)
Block(5,29,5,LEAVES:12)
Block(6,29,5,LEAVES:12)
Block(7,29,5,LEAVES:12)
Block(-7,29,6,LEAVES:12)
Block(-6,29,6,LEAVES:12)
Block(-5,29,6,LEAVES:12)
Block(2,29,6,LEAVES:12)
Block(3,29,6,LEAVES:12)
Block(4,29,6,LEAVES:12)
Block(-8,29,7,LEAVES:12)
Block(-7,29,7,LEAVES:12)
Block(-6,29,7,LEAVES:12)
Block(-11,29,8,LEAVES:12)
Block(-10,29,8,LEAVES:12)
Block(-9,29,8,LEAVES:12)
Block(-8,29,8,LEAVES:12)
Block(-7,29,8,LEAVES:12)
Block(-6,29,8,LEAVES:12)
Block(-5,29,8,LEAVES:12)
Block(-4,29,8,LEAVES:12)
Block(-3,29,8,LEAVES:12)
Block(-8,29,9,LEAVES:12)
Block(-7,29,9,LEAVES:12)
Block(-6,29,9,LEAVES:12)
Block(-9,30,-11,LEAVES:12)
Block(-8,30,-11,LEAVES:12)
Block(-8,30,-10,LEAVES:12)
Block(-8,30,-9,LEAVES:12)
Block(-7,30,-8,LEAVES:12)
Block(-6,30,-8,LEAVES:12)
Block(-5,30,-8,LEAVES:12)
Block(-8,30,-7,LEAVES:12)
Block(-7,30,-7,LEAVES:12)
Block(-6,30,-7,LEAVES:12)
Block(-11,30,-6,LEAVES:12)
Block(-10,30,-6,LEAVES:12)
Block(-9,30,-6,LEAVES:12)
Block(-8,30,-6,LEAVES:12)
Block(-7,30,-6,LEAVES:12)
Block(-6,30,-6,LEAVES:12)
Block(-5,30,-6,LEAVES:12)
Block(-4,30,-6,LEAVES:12)
Block(-3,30,-6,LEAVES:12)
Block(-8,30,-5,LEAVES:12)
Block(-7,30,-5,LEAVES:12)
Block(-6,30,-5,LEAVES:12)
Block(-5,30,-3,LEAVES:12)
Block(-1,30,0,LEAVES:12)
Block(0,30,0,LEAVES:12)
Block(-4,30,1,LEAVES:12)
Block(-3,30,1,LOG2:12)
Block(3,30,2,LEAVES:12)
Block(5,30,2,LEAVES:12)
Block(6,30,2,LEAVES:12)
Block(3,30,3,LEAVES:12)
Block(5,30,3,LEAVES:12)
Block(1,30,4,LEAVES:12)
Block(2,30,4,LEAVES:12)
Block(-7,30,5,LEAVES:12)
Block(-5,30,5,LEAVES:12)
Block(-4,30,5,LEAVES:12)
Block(-3,30,5,LEAVES:12)
Block(-2,30,5,LEAVES:12)
Block(-1,30,5,LEAVES:12)
Block(1,30,5,LEAVES:12)
Block(3,30,5,LEAVES:12)
Block(4,30,5,LEAVES:12)
Block(5,30,5,LEAVES:12)
Block(7,30,5,LEAVES:12)
Block(8,30,5,LEAVES:12)
Block(-7,30,6,LEAVES:12)
Block(-5,30,6,LEAVES:12)
Block(2,30,6,LEAVES:12)
Block(4,30,6,LEAVES:12)
Block(-9,30,7,LEAVES:12)
Block(-8,30,7,LEAVES:12)
Block(1,30,7,LEAVES:12)
Block(2,30,7,LEAVES:12)
Block(4,30,7,LEAVES:12)
Block(-13,30,8,LEAVES:12)
Block(-12,30,8,LEAVES:12)
Block(-11,30,8,LEAVES:12)
Block(-7,30,8,LEAVES:12)
Block(-6,30,8,LEAVES:12)
Block(-5,30,8,LEAVES:12)
Block(-3,30,8,LEAVES:12)
Block(-2,30,8,LEAVES:12)
Block(-8,30,9,LEAVES:12)
Block(-6,30,9,LEAVES:12)
Block(-9,30,10,LEAVES:12)
Block(-8,30,10,LEAVES:12)
Block(-6,30,10,LEAVES:12)
Block(-7,31,-9,LEAVES:12)
Block(-5,31,-9,LEAVES:12)
Block(-4,31,-9,LEAVES:12)
Block(-7,31,-8,LEAVES:12)
Block(-5,31,-8,LEAVES:12)
Block(-9,31,-7,LEAVES:12)
Block(-8,31,-7,LEAVES:12)
Block(-13,31,-6,LEAVES:12)
Block(-12,31,-6,LEAVES:12)
Block(-11,31,-6,LEAVES:12)
Block(-7,31,-6,LEAVES:12)
Block(-6,31,-6,LEAVES:12)
Block(-5,31,-6,LEAVES:12)
Block(-3,31,-6,LEAVES:12)
Block(-2,31,-6,LEAVES:12)
Block(-8,31,-5,LEAVES:12)
Block(-6,31,-5,LEAVES:12)
Block(-9,31,-4,LEAVES:12)
Block(-8,31,-4,LEAVES:12)
Block(-6,31,-4,LEAVES:12)
Block(-5,31,-3,LEAVES:12)
Block(-5,31,-2,LEAVES:12)
Block(-4,31,-2,LEAVES:12)
Block(-1,31,0,LEAVES:12)
Block(3,31,0,LEAVES:12)
Block(4,31,0,LEAVES:12)
Block(-3,31,1,LOG2:12)
Block(-1,31,1,LEAVES:12)
Block(3,31,1,LEAVES:12)
Block(3,31,2,LEAVES:12)
Block(6,31,2,LEAVES:12)
Block(7,31,2,LEAVES:12)
Block(-7,31,3,LEAVES:12)
Block(-6,31,3,LEAVES:12)
Block(0,31,3,LEAVES:12)
Block(-7,31,4,LEAVES:12)
Block(0,31,4,LEAVES:12)
Block(1,31,4,LEAVES:12)
Block(-7,31,5,LEAVES:12)
Block(-4,31,5,LEAVES:12)
Block(-3,31,5,LEAVES:12)
Block(3,31,5,LEAVES:12)
Block(5,31,5,LEAVES:12)
Block(-9,31,7,LEAVES:12)
Block(1,31,7,LEAVES:12)
Block(4,31,7,LEAVES:12)
Block(-7,31,8,LEAVES:12)
Block(-5,31,8,LEAVES:12)
Block(0,31,8,LEAVES:12)
Block(1,31,8,LEAVES:12)
Block(0,31,9,LEAVES:12)
Block(-9,31,10,LEAVES:12)
Block(-6,31,10,LEAVES:12)
Block(-10,31,11,LEAVES:12)
Block(-9,31,11,LEAVES:12)
Block(-10,31,12,LEAVES:12)
Block(-7,32,-11,LEAVES:12)
Block(-6,32,-11,LEAVES:12)
Block(-7,32,-10,LEAVES:12)
Block(-7,32,-9,LEAVES:12)
Block(-4,32,-9,LEAVES:12)
Block(-3,32,-9,LEAVES:12)
Block(-9,32,-7,LEAVES:12)
Block(-7,32,-6,LEAVES:12)
Block(-5,32,-6,LEAVES:12)
Block(-9,32,-4,LEAVES:12)
Block(-6,32,-4,LEAVES:12)
Block(-10,32,-3,LEAVES:12)
Block(-9,32,-3,LEAVES:12)
Block(-10,32,-2,LEAVES:12)
Block(-4,32,-2,LEAVES:12)
Block(-3,32,-2,LEAVES:12)
Block(0,32,-2,LEAVES:12)
Block(1,32,-2,LEAVES:12)
Block(-7,32,-1,LEAVES:12)
Block(-3,32,-1,LEAVES:12)
Block(0,32,-1,LEAVES:12)
Block(-3,32,0,LEAVES:12)
Block(-3,32,1,LOG2:12)
Block(-2,32,1,LOG2:12)
Block(-1,32,1,LEAVES:12)
Block(-4,32,2,LEAVES:12)
Block(-1,32,2,LEAVES:12)
Block(-5,32,3,LEAVES:12)
Block(-4,32,3,LEAVES:12)
Block(-1,32,3,LEAVES:12)
Block(0,32,3,LEAVES:12)
Block(1,32,3,LEAVES:12)
Block(-5,32,4,LEAVES:12)
Block(1,32,4,LEAVES:12)
Block(-6,32,5,LEAVES:12)
Block(-5,32,5,LEAVES:12)
Block(3,32,5,LEAVES:12)
Block(5,32,5,LEAVES:12)
Block(6,32,5,LEAVES:12)
Block(7,32,5,LEAVES:12)
Block(-10,32,6,LEAVES:12)
Block(-9,32,6,LEAVES:12)
Block(-9,32,7,LEAVES:12)
Block(4,32,7,LEAVES:12)
Block(5,32,7,LEAVES:12)
Block(-7,32,8,LEAVES:12)
Block(-5,32,8,LEAVES:12)
Block(-4,32,8,LEAVES:12)
Block(-3,32,8,LEAVES:12)
Block(5,32,8,LEAVES:12)
Block(6,32,8,LEAVES:12)
Block(0,32,9,LEAVES:12)
Block(6,32,9,LEAVES:12)
Block(-6,32,10,LEAVES:12)
Block(-5,32,10,LEAVES:12)
Block(-5,32,11,LEAVES:12)
Block(-4,32,11,LEAVES:12)
Block(-10,32,12,LEAVES:12)
Block(-4,32,12,LEAVES:12)
Block(-10,33,-8,LEAVES:12)
Block(-9,33,-8,LEAVES:12)
Block(-9,33,-7,LEAVES:12)
Block(-7,33,-6,LEAVES:12)
Block(-5,33,-6,LEAVES:12)
Block(-4,33,-6,LEAVES:12)
Block(-3,33,-6,LEAVES:12)
Block(-6,33,-4,LEAVES:12)
Block(-5,33,-4,LEAVES:12)
Block(-4,33,-4,LEAVES:12)
Block(-5,33,-3,LEAVES:12)
Block(-4,33,-3,LEAVES:12)
Block(-10,33,-2,LEAVES:12)
Block(-4,33,-2,LEAVES:12)
Block(-3,33,-2,LEAVES:12)
Block(-2,33,-2,LEAVES:12)
Block(-7,33,-1,LEAVES:12)
Block(-6,33,-1,LEAVES:12)
Block(-2,33,-1,LEAVES:12)
Block(-1,33,-1,LEAVES:12)
Block(0,33,-1,LEAVES:12)
Block(-6,33,0,LEAVES:12)
Block(-5,33,0,LEAVES:12)
Block(-4,33,0,LEAVES:12)
Block(-3,33,0,LEAVES:12)
Block(-2,33,0,LEAVES:12)
Block(-1,33,0,LEAVES:12)
Block(-3,33,1,LEAVES:12)
Block(-2,33,1,LOG2:12)
Block(-1,33,1,LEAVES:12)
Block(-4,33,2,LEAVES:12)
Block(-3,33,2,LEAVES:12)
Block(-2,33,2,LEAVES:12)
Block(-1,33,2,LEAVES:12)
Block(0,33,2,LEAVES:12)
Block(-2,33,3,LEAVES:12)
Block(0,33,3,LEAVES:12)
Block(-2,33,4,LEAVES:12)
Block(3,33,4,LEAVES:12)
Block(-10,33,5,LEAVES:12)
Block(-2,33,5,LEAVES:12)
Block(3,33,5,LEAVES:12)
Block(7,33,5,LEAVES:12)
Block(-10,33,6,LEAVES:12)
Block(-2,33,6,LEAVES:12)
Block(-1,33,6,LEAVES:12)
Block(-7,33,7,LEAVES:12)
Block(-7,33,8,LEAVES:12)
Block(-3,33,8,LEAVES:12)
Block(-10,34,-9,LEAVES:12)
Block(-10,34,-8,LEAVES:12)
Block(-7,34,-7,LEAVES:12)
Block(-7,34,-6,LEAVES:12)
Block(-3,34,-6,LEAVES:12)
Block(-4,34,-4,LEAVES:12)
Block(-3,34,-4,LEAVES:12)
Block(-3,34,-3,LEAVES:12)
Block(-3,34,-2,LEAVES:12)
Block(-2,34,-1,LEAVES:12)
Block(-1,34,-1,LEAVES:12)
Block(0,34,-1,LEAVES:12)
Block(-3,34,0,LEAVES:12)
Block(-2,34,0,LEAVES:12)
Block(-1,34,0,LEAVES:12)
Block(-6,34,1,LEAVES:12)
Block(-5,34,1,LEAVES:12)
Block(-4,34,1,LEAVES:12)
Block(-3,34,1,LEAVES:12)
Block(-2,34,1,LEAVES:12)
Block(-1,34,1,LEAVES:12)
Block(0,34,1,LEAVES:12)
Block(1,34,1,LEAVES:12)
Block(2,34,1,LEAVES:12)
Block(-3,34,2,LEAVES:12)
Block(-2,34,2,LEAVES:12)
Block(-1,34,2,LEAVES:12)
Block(3,34,4,LEAVES:12)
Block(-7,34,7,LEAVES:12)
Block(-7,35,-7,LEAVES:12)
Block(-2,35,-2,LEAVES:12)
Block(0,35,-2,LEAVES:12)
Block(1,35,-2,LEAVES:12)
Block(-2,35,-1,LEAVES:12)
Block(0,35,-1,LEAVES:12)
Block(-4,35,0,LEAVES:12)
Block(-3,35,0,LEAVES:12)
Block(-8,35,1,LEAVES:12)
Block(-7,35,1,LEAVES:12)
Block(-6,35,1,LEAVES:12)
Block(-2,35,1,LEAVES:12)
Block(-1,35,1,LEAVES:12)
Block(0,35,1,LEAVES:12)
Block(2,35,1,LEAVES:12)
Block(3,35,1,LEAVES:12)
Block(-3,35,2,LEAVES:12)
Block(-1,35,2,LEAVES:12)
Block(-4,35,3,LEAVES:12)
Block(-3,35,3,LEAVES:12)
Block(-1,35,3,LEAVES:12)
Block(-2,36,-4,LEAVES:12)
Block(-1,36,-4,LEAVES:12)
Block(-2,36,-3,LEAVES:12)
Block(-2,36,-2,LEAVES:12)
Block(1,36,-2,LEAVES:12)
Block(2,36,-2,LEAVES:12)
Block(-4,36,0,LEAVES:12)
Block(-2,36,1,LEAVES:12)
Block(0,36,1,LEAVES:12)
Block(-4,36,3,LEAVES:12)
Block(-1,36,3,LEAVES:12)
Block(-5,36,4,LEAVES:12)
Block(-4,36,4,LEAVES:12)
Block(-5,36,5,LEAVES:12)
Block(-5,37,-1,LEAVES:12)
Block(-4,37,-1,LEAVES:12)
Block(-4,37,0,LEAVES:12)
Block(-2,37,1,LEAVES:12)
Block(0,37,1,LEAVES:12)
Block(1,37,1,LEAVES:12)
Block(2,37,1,LEAVES:12)
Block(-1,37,3,LEAVES:12)
Block(0,37,3,LEAVES:12)
Block(0,37,4,LEAVES:12)
Block(1,37,4,LEAVES:12)
Block(-5,37,5,LEAVES:12)
Block(1,37,5,LEAVES:12)
Block(-5,38,-2,LEAVES:12)
Block(-5,38,-1,LEAVES:12)
Block(-2,38,0,LEAVES:12)
Block(-2,38,1,LEAVES:12)
Block(2,38,1,LEAVES:12)
Block(-2,39,0,LEAVES:12)

#######################################################################
# +-----------------------------------------------------------------+ #
# |                            BO3 checks                           | #
# +-----------------------------------------------------------------+ #
#######################################################################

# Require a condition at a certain location in order for the BO3 to be spawned.
# BlockCheck(x,y,z,BlockName[,BlockName[,...]]) - one of the blocks must be at the location
# BlockCheckNot(x,y,z,BlockName[,BlockName[,...]]) - all the blocks must not be at the location
# LightCheck(x,y,z,minLightLevel,maxLightLevel) - light must be between min and max (inclusive)

# You can use "Solid" as a BlockName for matching all solid blocks or "All" to match all blocks that aren't air.

# Examples:
BlockCheck(0,-1,0,GRASS,DIRT,DIRT:2,SAND)
#   BlockCheck(0,-1,0,Solid)       Require any solid block just below the object
#   BlockCheck(0,-1,0,WOOL)        Require any type of wool just below the object
#   BlockCheck(0,-1,0,WOOL:0)      Require white wool just below the object
#   BlockCheckNot(0,-1,0,WOOL:0)   Require that there is no white wool below the object
#   LightCheck(0,0,0,0,1)          Require almost complete darkness just below the object

#######################################################################
# +-----------------------------------------------------------------+ #
# |                             Branches                            | #
# +-----------------------------------------------------------------+ #
#######################################################################

# Branches are objects that will spawn when this object spawns when it is used in
# the CustomStructure resource. Branches can also have branches, making complex
# structures possible. See the wiki for more details.

# Regular Branches spawn each branch with an independent chance of spawning.
# Branch(x,y,z,branchName,rotation,chance[,anotherBranchName,rotation,chance[,...]][IndividualChance])
# branchName - name of the object to spawn.
# rotation - NORTH, SOUTH, EAST or WEST.
# IndividualChance - The chance each branch has to spawn, assumed to be 100 when left blank

# Weighted Branches spawn branches with a dependent chance of spawning.
# WeightedBranch(x,y,z,branchName,rotation,chance[,anotherBranchName,rotation,chance[,...]][MaxChanceOutOf])
# MaxChanceOutOf - The chance all branches have to spawn out of, assumed to be 100 when left blank
