#######################################################################
# +-----------------------------------------------------------------+ #
# |                            BO3 object                           | #
# +-----------------------------------------------------------------+ #
#######################################################################

# This is the config file of a custom object.
# If you add this object correctly to your BiomeConfigs, it will spawn in the world.

# This is the creator of this BO3 object
Author: BO3 BulkEdit (by LanToaster)

# A short description of this BO3 object
Description: This Object was Created with BO3_BulkEdit

# The BO3 version, don't change this! It can be used by external applications to do a version check.
Version: 3

# The settings mode, WriteAll, WriteWithoutComments or WriteDisable. See WorldConfig.
SettingsMode: WriteDisable


#######################################################################
# +-----------------------------------------------------------------+ #
# |                          Main settings                          | #
# +-----------------------------------------------------------------+ #
#######################################################################

# This needs to be set to true to spawn the object in the Tree and Sapling resources.
Tree: true

# The frequency of the BO3 from 1 to 200. Tries this many times to spawn this BO3 when using the CustomObject(...) resource.
# Ignored by Tree(..), Sapling(..) and CustomStructure(..)
Frequency: 1

# The rarity of the BO3 from 0 to 100. Each spawn attempt has rarity% chance to succeed when using the CustomObject(...) resource.
# Ignored by Tree(..), Sapling(..) and CustomStructure(..)
Rarity: 100.0

# If you set this to true, the BO3 will be placed with a random rotation.
RotateRandomly: true

# The spawn height of the BO3 - randomY, highestBlock or highestSolidBlock.
SpawnHeight: highestSolidBlock
SpawnHeightOffset: -1
# The height limits for the BO3.
MinHeight: 0

MaxHeight: 72

# Objects can have other objects attacthed to it: branches. Branches can also
# have branches attached to it, which can also have branches, etc. This is the
# maximum branch depth for this objects.
MaxBranchDepth: 10

# When spawned with the UseWorld keyword, this BO3 should NOT spawn in the following biomes.
# If you writer.write the BO3 name directly in the BiomeConfigs, this will be ignored.
ExcludedBiomes: All


#######################################################################
# +-----------------------------------------------------------------+ #
# |                      Source block settings                      | #
# +-----------------------------------------------------------------+ #
#######################################################################

# The block(s) the BO3 should spawn in.
SourceBlocks: AIR,GRASS,DIRT,STATIONARY_WATER,FLOWING_WATER,SAND,CLAY

# The maximum percentage of the BO3 that can be outside the SourceBlock.
# The BO3 won't be placed on a location with more blocks outside the SourceBlock than this percentage.
MaxPercentageOutsideSourceBlock: 5

# What to do when a block is about to be placed outside the SourceBlock? (dontPlace, placeAnyway)
OutsideSourceBlock: placeAnyway


#######################################################################
# +-----------------------------------------------------------------+ #
# |                              Blocks                             | #
# +-----------------------------------------------------------------+ #
#######################################################################

# All the blocks used in the BO3 are listed here. Possible blocks:
# Block(x,y,z,id[.data][,nbtfile.nbt)
# RandomBlock(x,y,z,id[:data][,nbtfile.nbt],chance[,id[:data][,nbtfile.nbt],chance[,...]])
# So RandomBlock(0,0,0,CHEST,chest.nbt,50,CHEST,anotherchest.nbt,100) will spawn a chest at
# the BO3 origin, and give it a 50% chance to have the contents of chest.nbt, or, if that
# fails, a 100% percent chance to have the contents of anotherchest.nbt.
Block(3,1,-1,LOG:15)
Block(4,1,-1,LOG:15)
Block(2,1,0,LOG:15)
Block(3,1,0,LOG:15)
Block(4,1,0,LOG:15)
Block(5,1,0,LOG:15)
Block(2,1,1,LOG:15)
Block(3,1,1,LOG:15)
Block(4,1,1,LOG:15)
Block(3,2,-1,LOG:15)
Block(4,2,-1,LOG:15)
Block(2,2,0,LOG:15)
Block(3,2,0,LOG:15)
Block(4,2,0,LOG:15)
Block(5,2,0,LOG:15)
Block(2,2,1,LOG:15)
Block(3,2,1,LOG:15)
Block(4,2,1,LOG:15)
Block(3,3,-1,LOG:15)
Block(4,3,-1,LOG:15)
Block(2,3,0,LOG:15)
Block(3,3,0,LOG:15)
Block(4,3,0,LOG:15)
Block(5,3,0,LOG:15)
Block(2,3,1,LOG:15)
Block(3,3,1,LOG:15)
Block(4,3,1,LOG:15)
Block(3,4,-1,LOG:15)
Block(4,4,-1,LOG:15)
Block(2,4,0,LOG:15)
Block(3,4,0,LOG:15)
Block(4,4,0,LOG:15)
Block(5,4,0,LOG:15)
Block(2,4,1,LOG:15)
Block(3,4,1,LOG:15)
Block(4,4,1,LOG:15)
Block(1,5,-13,LEAVES:15)
Block(0,5,-10,LEAVES:15)
Block(3,5,-1,LOG:15)
Block(4,5,-1,LOG:15)
Block(2,5,0,LOG:15)
Block(3,5,0,LOG:15)
Block(4,5,0,LOG:15)
Block(3,5,1,LOG:15)
Block(4,5,1,LOG:15)
Block(1,6,-13,LEAVES:15)
Block(0,6,-10,LEAVES:15)
Block(9,6,-10,LEAVES:15)
Block(3,6,-1,LOG:15)
Block(4,6,-1,LOG:15)
Block(2,6,0,LOG:15)
Block(3,6,0,LOG:15)
Block(4,6,0,LOG:15)
Block(3,6,1,LOG:15)
Block(4,6,1,LOG:15)
Block(1,7,-13,LEAVES:15)
Block(0,7,-10,LEAVES:15)
Block(9,7,-10,LEAVES:15)
Block(3,7,-1,LOG:15)
Block(4,7,-1,LOG:15)
Block(2,7,0,LOG:15)
Block(3,7,0,LOG:15)
Block(4,7,0,LOG:15)
Block(3,7,1,LOG:15)
Block(4,7,1,LOG:15)
Block(1,8,-13,LEAVES:15)
Block(0,8,-10,LEAVES:15)
Block(9,8,-10,LEAVES:15)
Block(3,8,-1,LOG:15)
Block(4,8,-1,LOG:15)
Block(2,8,0,LOG:15)
Block(3,8,0,LOG:15)
Block(4,8,0,LOG:15)
Block(3,8,1,LOG:15)
Block(4,8,1,LOG:15)
Block(1,9,-13,LEAVES:15)
Block(0,9,-10,LEAVES:15)
Block(9,9,-10,LEAVES:15)
Block(3,9,-1,LOG:15)
Block(4,9,-1,LOG:15)
Block(2,9,0,LOG:15)
Block(3,9,0,LOG:15)
Block(4,9,0,LOG:15)
Block(3,9,1,LOG:15)
Block(4,9,1,LOG:15)
Block(1,10,-13,LEAVES:15)
Block(0,10,-10,LEAVES:15)
Block(9,10,-10,LEAVES:15)
Block(3,10,-1,LOG:15)
Block(4,10,-1,LOG:15)
Block(2,10,0,LOG:15)
Block(3,10,0,LOG:15)
Block(4,10,0,LOG:15)
Block(3,10,1,LOG:15)
Block(1,11,-13,LEAVES:15)
Block(0,11,-10,LEAVES:15)
Block(9,11,-10,LEAVES:15)
Block(3,11,-1,LOG:15)
Block(4,11,-1,LOG:15)
Block(2,11,0,LOG:15)
Block(3,11,0,LOG:15)
Block(4,11,0,LOG:15)
Block(3,11,1,LOG:15)
Block(8,12,-14,LEAVES:15)
Block(1,12,-13,LEAVES:15)
Block(0,12,-10,LEAVES:15)
Block(9,12,-10,LEAVES:15)
Block(3,12,-1,LOG:15)
Block(4,12,-1,LOG:15)
Block(2,12,0,LOG:15)
Block(3,12,0,LOG:15)
Block(4,12,0,LOG:15)
Block(-12,12,1,LEAVES:15)
Block(3,12,1,LOG:15)
Block(8,13,-14,LEAVES:15)
Block(1,13,-13,LEAVES:15)
Block(-2,13,-11,LEAVES:15)
Block(0,13,-10,LEAVES:15)
Block(9,13,-10,LEAVES:15)
Block(3,13,-1,LOG:15)
Block(4,13,-1,LOG:15)
Block(2,13,0,LOG:15)
Block(3,13,0,LOG:15)
Block(4,13,0,LOG:15)
Block(-12,13,1,LEAVES:15)
Block(3,13,1,LOG:15)
Block(-6,13,4,LEAVES:15)
Block(8,14,-14,LEAVES:15)
Block(1,14,-13,LEAVES:15)
Block(-2,14,-11,LEAVES:15)
Block(0,14,-10,LEAVES:15)
Block(9,14,-10,LEAVES:15)
Block(3,14,-1,LOG:15)
Block(4,14,-1,LOG:15)
Block(2,14,0,LOG:15)
Block(3,14,0,LOG:15)
Block(4,14,0,LOG:15)
Block(-12,14,1,LEAVES:15)
Block(3,14,1,LOG:15)
Block(-6,14,4,LEAVES:15)
Block(-10,14,7,LEAVES:15)
Block(8,15,-14,LEAVES:15)
Block(1,15,-13,LEAVES:15)
Block(-2,15,-11,LEAVES:15)
Block(0,15,-10,LEAVES:15)
Block(9,15,-10,LEAVES:15)
Block(-9,15,-2,LEAVES:15)
Block(3,15,-1,LOG:15)
Block(4,15,-1,LOG:15)
Block(-7,15,0,LEAVES:15)
Block(2,15,0,LOG:15)
Block(3,15,0,LOG:15)
Block(4,15,0,LOG:15)
Block(-12,15,1,LEAVES:15)
Block(3,15,1,LOG:15)
Block(-7,15,2,LEAVES:15)
Block(-6,15,4,LEAVES:15)
Block(-10,15,7,LEAVES:15)
Block(8,16,-14,LEAVES:15)
Block(1,16,-13,LEAVES:15)
Block(-2,16,-11,LEAVES:15)
Block(0,16,-10,LEAVES:15)
Block(9,16,-10,LEAVES:15)
Block(-9,16,-2,LEAVES:15)
Block(2,16,-1,LOG:15)
Block(3,16,-1,LOG:15)
Block(4,16,-1,LOG:15)
Block(-7,16,0,LEAVES:15)
Block(2,16,0,LOG:15)
Block(3,16,0,LOG:15)
Block(4,16,0,LOG:15)
Block(-12,16,1,LEAVES:15)
Block(3,16,1,LOG:15)
Block(-7,16,2,LEAVES:15)
Block(-6,16,4,LEAVES:15)
Block(-10,16,7,LEAVES:15)
Block(8,17,-14,LEAVES:15)
Block(1,17,-13,LEAVES:15)
Block(-2,17,-11,LEAVES:15)
Block(0,17,-10,LEAVES:15)
Block(9,17,-10,LEAVES:15)
Block(-9,17,-2,LEAVES:15)
Block(2,17,-1,LOG:15)
Block(3,17,-1,LOG:15)
Block(4,17,-1,LOG:15)
Block(-7,17,0,LEAVES:15)
Block(2,17,0,LOG:15)
Block(3,17,0,LOG:15)
Block(4,17,0,LOG:15)
Block(-12,17,1,LEAVES:15)
Block(3,17,1,LOG:15)
Block(-7,17,2,LEAVES:15)
Block(-6,17,4,LEAVES:15)
Block(-10,17,7,LEAVES:15)
Block(8,18,-14,LEAVES:15)
Block(1,18,-13,LEAVES:15)
Block(12,18,-13,LEAVES:15)
Block(-2,18,-11,LEAVES:15)
Block(0,18,-10,LEAVES:15)
Block(9,18,-10,LEAVES:15)
Block(-9,18,-2,LEAVES:15)
Block(2,18,-1,LOG:15)
Block(3,18,-1,LOG:15)
Block(4,18,-1,LOG:15)
Block(-7,18,0,LEAVES:15)
Block(2,18,0,LOG:15)
Block(3,18,0,LOG:15)
Block(4,18,0,LOG:15)
Block(-12,18,1,LEAVES:15)
Block(3,18,1,LOG:15)
Block(-7,18,2,LEAVES:15)
Block(-6,18,4,LEAVES:15)
Block(-10,18,7,LEAVES:15)
Block(8,19,-14,LEAVES:15)
Block(1,19,-13,LEAVES:15)
Block(12,19,-13,LEAVES:15)
Block(-2,19,-11,LEAVES:15)
Block(0,19,-10,LEAVES:15)
Block(9,19,-10,LEAVES:15)
Block(-9,19,-2,LEAVES:15)
Block(2,19,-1,LOG:15)
Block(3,19,-1,LOG:15)
Block(4,19,-1,LOG:15)
Block(-7,19,0,LEAVES:15)
Block(2,19,0,LOG:15)
Block(3,19,0,LOG:15)
Block(4,19,0,LOG:15)
Block(-12,19,1,LEAVES:15)
Block(3,19,1,LOG:15)
Block(-7,19,2,LEAVES:15)
Block(-6,19,4,LEAVES:15)
Block(-10,19,7,LEAVES:15)
Block(8,20,-14,LEAVES:15)
Block(1,20,-13,LEAVES:15)
Block(12,20,-13,LEAVES:15)
Block(-2,20,-11,LEAVES:15)
Block(0,20,-10,LEAVES:15)
Block(9,20,-10,LEAVES:15)
Block(-9,20,-2,LEAVES:15)
Block(2,20,-1,LOG:15)
Block(3,20,-1,LOG:15)
Block(4,20,-1,LOG:15)
Block(-7,20,0,LEAVES:15)
Block(2,20,0,LOG:15)
Block(3,20,0,LOG:15)
Block(4,20,0,LOG:15)
Block(-12,20,1,LEAVES:15)
Block(3,20,1,LOG:15)
Block(-7,20,2,LEAVES:15)
Block(-6,20,4,LEAVES:15)
Block(-10,20,7,LEAVES:15)
Block(8,21,-14,LEAVES:15)
Block(9,21,-14,LEAVES:15)
Block(0,21,-13,LEAVES:15)
Block(1,21,-13,LEAVES:15)
Block(5,21,-13,LEAVES:15)
Block(12,21,-13,LEAVES:15)
Block(-2,21,-11,LEAVES:15)
Block(0,21,-10,LEAVES:15)
Block(9,21,-10,LEAVES:15)
Block(-9,21,-2,LEAVES:15)
Block(2,21,-1,LOG:15)
Block(3,21,-1,LOG:15)
Block(4,21,-1,LOG:15)
Block(-7,21,0,LEAVES:15)
Block(2,21,0,LOG:15)
Block(3,21,0,LOG:15)
Block(4,21,0,LOG:15)
Block(-12,21,1,LEAVES:15)
Block(3,21,1,LOG:15)
Block(-7,21,2,LEAVES:15)
Block(-6,21,4,LEAVES:15)
Block(-10,21,7,LEAVES:15)
Block(7,21,11,LEAVES:15)
Block(8,22,-14,LEAVES:15)
Block(9,22,-14,LEAVES:15)
Block(0,22,-13,LEAVES:15)
Block(1,22,-13,LEAVES:15)
Block(5,22,-13,LEAVES:15)
Block(9,22,-13,LEAVES:15)
Block(12,22,-13,LEAVES:15)
Block(-2,22,-11,LEAVES:15)
Block(0,22,-10,LEAVES:15)
Block(9,22,-10,LEAVES:15)
Block(-9,22,-2,LEAVES:15)
Block(2,22,-1,LOG:15)
Block(3,22,-1,LOG:15)
Block(4,22,-1,LOG:15)
Block(-7,22,0,LEAVES:15)
Block(2,22,0,LOG:15)
Block(3,22,0,LOG:15)
Block(4,22,0,LOG:15)
Block(-12,22,1,LEAVES:15)
Block(3,22,1,LOG:15)
Block(-7,22,2,LEAVES:15)
Block(-6,22,4,LEAVES:15)
Block(-10,22,7,LEAVES:15)
Block(7,22,11,LEAVES:15)
Block(8,23,-14,LEAVES:15)
Block(9,23,-14,LEAVES:15)
Block(0,23,-13,LEAVES:15)
Block(1,23,-13,LEAVES:15)
Block(5,23,-13,LEAVES:15)
Block(9,23,-13,LEAVES:15)
Block(12,23,-13,LEAVES:15)
Block(14,23,-12,LEAVES:15)
Block(-2,23,-11,LEAVES:15)
Block(0,23,-10,LEAVES:15)
Block(9,23,-10,LEAVES:15)
Block(-9,23,-2,LEAVES:15)
Block(2,23,-1,LOG:15)
Block(3,23,-1,LOG:15)
Block(4,23,-1,LOG:15)
Block(-7,23,0,LEAVES:15)
Block(2,23,0,LOG:15)
Block(3,23,0,LOG:15)
Block(4,23,0,LOG:15)
Block(-12,23,1,LEAVES:15)
Block(3,23,1,LOG:15)
Block(-7,23,2,LEAVES:15)
Block(-6,23,4,LEAVES:15)
Block(-10,23,7,LEAVES:15)
Block(7,23,11,LEAVES:15)
Block(8,24,-14,LEAVES:15)
Block(9,24,-14,LEAVES:15)
Block(0,24,-13,LEAVES:15)
Block(1,24,-13,LEAVES:15)
Block(5,24,-13,LEAVES:15)
Block(9,24,-13,LEAVES:15)
Block(12,24,-13,LEAVES:15)
Block(4,24,-12,LEAVES:15)
Block(14,24,-12,LEAVES:15)
Block(-2,24,-11,LEAVES:15)
Block(0,24,-10,LEAVES:15)
Block(9,24,-10,LEAVES:15)
Block(4,24,-3,LOG:15)
Block(-9,24,-2,LEAVES:15)
Block(3,24,-2,LOG:15)
Block(3,24,-1,LOG:15)
Block(4,24,-1,LOG:15)
Block(-7,24,0,LEAVES:15)
Block(2,24,0,LOG:15)
Block(3,24,0,LOG:15)
Block(4,24,0,LOG:15)
Block(-12,24,1,LEAVES:15)
Block(2,24,1,LOG:15)
Block(-7,24,2,LEAVES:15)
Block(-6,24,4,LEAVES:15)
Block(-10,24,7,LEAVES:15)
Block(6,24,8,LEAVES:15)
Block(7,24,11,LEAVES:15)
Block(8,25,-14,LEAVES:15)
Block(9,25,-14,LEAVES:15)
Block(0,25,-13,LEAVES:15)
Block(1,25,-13,LEAVES:15)
Block(5,25,-13,LEAVES:15)
Block(9,25,-13,LEAVES:15)
Block(12,25,-13,LEAVES:15)
Block(4,25,-12,LEAVES:15)
Block(14,25,-12,LEAVES:15)
Block(-2,25,-11,LEAVES:15)
Block(11,25,-11,LEAVES:15)
Block(0,25,-10,LEAVES:15)
Block(9,25,-10,LEAVES:15)
Block(6,25,-6,LOG:15)
Block(5,25,-5,LOG:15)
Block(6,25,-5,LOG:15)
Block(5,25,-4,LOG:15)
Block(3,25,-3,LOG:15)
Block(4,25,-3,LOG:15)
Block(-9,25,-2,LEAVES:15)
Block(3,25,-2,LOG:15)
Block(3,25,-1,LOG:15)
Block(-7,25,0,LEAVES:15)
Block(2,25,0,LOG:15)
Block(3,25,0,LOG:15)
Block(4,25,0,LOG:15)
Block(-12,25,1,LEAVES:15)
Block(2,25,1,LOG:15)
Block(-7,25,2,LEAVES:15)
Block(-6,25,4,LEAVES:15)
Block(-10,25,7,LEAVES:15)
Block(8,25,7,LEAVES:15)
Block(6,25,8,LEAVES:15)
Block(7,25,11,LEAVES:15)
Block(8,26,-14,LEAVES:15)
Block(9,26,-14,LEAVES:15)
Block(0,26,-13,LEAVES:15)
Block(1,26,-13,LEAVES:15)
Block(5,26,-13,LEAVES:15)
Block(9,26,-13,LEAVES:15)
Block(11,26,-13,LEAVES:15)
Block(12,26,-13,LEAVES:15)
Block(4,26,-12,LEAVES:15)
Block(14,26,-12,LEAVES:15)
Block(-2,26,-11,LEAVES:15)
Block(11,26,-11,LEAVES:15)
Block(0,26,-10,LEAVES:15)
Block(9,26,-10,LEAVES:15)
Block(7,26,-7,LOG:15)
Block(6,26,-6,LOG:15)
Block(5,26,-5,LOG:15)
Block(6,26,-5,LOG:15)
Block(5,26,-4,LOG:15)
Block(-9,26,-2,LEAVES:15)
Block(3,26,-1,LOG:15)
Block(-7,26,0,LEAVES:15)
Block(2,26,0,LOG:15)
Block(3,26,0,LOG:15)
Block(4,26,0,LOG:15)
Block(-12,26,1,LEAVES:15)
Block(2,26,1,LOG:15)
Block(-7,26,2,LEAVES:15)
Block(-8,26,3,LEAVES:15)
Block(-6,26,4,LEAVES:15)
Block(-10,26,7,LEAVES:15)
Block(8,26,7,LEAVES:15)
Block(6,26,8,LEAVES:15)
Block(7,26,10,LEAVES:15)
Block(7,26,11,LEAVES:15)
Block(8,27,-14,LEAVES:15)
Block(9,27,-14,LEAVES:15)
Block(0,27,-13,LEAVES:15)
Block(1,27,-13,LEAVES:15)
Block(5,27,-13,LEAVES:15)
Block(9,27,-13,LEAVES:15)
Block(11,27,-13,LEAVES:15)
Block(12,27,-13,LEAVES:15)
Block(4,27,-12,LEAVES:15)
Block(14,27,-12,LEAVES:15)
Block(-2,27,-11,LEAVES:15)
Block(11,27,-11,LEAVES:15)
Block(0,27,-10,LEAVES:15)
Block(9,27,-10,LEAVES:15)
Block(7,27,-8,LOG:15)
Block(7,27,-7,LOG:15)
Block(-9,27,-2,LEAVES:15)
Block(3,27,-1,LOG:15)
Block(-7,27,0,LEAVES:15)
Block(2,27,0,LOG:15)
Block(3,27,0,LOG:15)
Block(4,27,0,LOG:15)
Block(-12,27,1,LEAVES:15)
Block(1,27,1,LOG:15)
Block(2,27,1,LOG:15)
Block(-7,27,2,LEAVES:15)
Block(-8,27,3,LEAVES:15)
Block(-6,27,4,LEAVES:15)
Block(-10,27,7,LEAVES:15)
Block(8,27,7,LEAVES:15)
Block(6,27,8,LEAVES:15)
Block(7,27,10,LEAVES:15)
Block(7,27,11,LEAVES:15)
Block(6,28,-14,LEAVES:15)
Block(8,28,-14,LEAVES:15)
Block(9,28,-14,LEAVES:15)
Block(0,28,-13,LEAVES:15)
Block(1,28,-13,LEAVES:15)
Block(5,28,-13,LEAVES:15)
Block(9,28,-13,LEAVES:15)
Block(11,28,-13,LEAVES:15)
Block(12,28,-13,LEAVES:15)
Block(4,28,-12,LEAVES:15)
Block(14,28,-12,LEAVES:15)
Block(-2,28,-11,LEAVES:15)
Block(11,28,-11,LEAVES:15)
Block(0,28,-10,LEAVES:15)
Block(9,28,-10,LEAVES:15)
Block(7,28,-8,LOG:15)
Block(-9,28,-2,LEAVES:15)
Block(3,28,-1,LOG:15)
Block(-7,28,0,LEAVES:15)
Block(2,28,0,LOG:15)
Block(3,28,0,LOG:15)
Block(4,28,0,LOG:15)
Block(-12,28,1,LEAVES:15)
Block(1,28,1,LOG:15)
Block(2,28,1,LOG:15)
Block(-7,28,2,LEAVES:15)
Block(-8,28,3,LEAVES:15)
Block(-6,28,4,LEAVES:15)
Block(-10,28,7,LEAVES:15)
Block(8,28,7,LEAVES:15)
Block(6,28,8,LEAVES:15)
Block(7,28,10,LEAVES:15)
Block(7,28,11,LEAVES:15)
Block(6,29,-14,LEAVES:15)
Block(8,29,-14,LEAVES:15)
Block(9,29,-14,LEAVES:15)
Block(0,29,-13,LEAVES:15)
Block(1,29,-13,LEAVES:15)
Block(5,29,-13,LEAVES:15)
Block(9,29,-13,LEAVES:15)
Block(11,29,-13,LEAVES:15)
Block(12,29,-13,LEAVES:15)
Block(4,29,-12,LEAVES:15)
Block(11,29,-12,LEAVES:15)
Block(14,29,-12,LEAVES:15)
Block(-2,29,-11,LEAVES:15)
Block(11,29,-11,LEAVES:15)
Block(0,29,-10,LEAVES:15)
Block(9,29,-10,LEAVES:15)
Block(7,29,-8,LOG:15)
Block(8,29,-8,LOG:15)
Block(-9,29,-2,LEAVES:15)
Block(3,29,-1,LOG:15)
Block(-7,29,0,LEAVES:15)
Block(2,29,0,LOG:15)
Block(3,29,0,LOG:15)
Block(4,29,0,LOG:15)
Block(-12,29,1,LEAVES:15)
Block(-8,29,1,LEAVES:15)
Block(0,29,1,LOG:15)
Block(1,29,1,LOG:15)
Block(2,29,1,LOG:15)
Block(-7,29,2,LEAVES:15)
Block(1,29,2,LOG:15)
Block(-8,29,3,LEAVES:15)
Block(-6,29,4,LEAVES:15)
Block(-10,29,7,LEAVES:15)
Block(8,29,7,LEAVES:15)
Block(6,29,8,LEAVES:15)
Block(7,29,10,LEAVES:15)
Block(7,29,11,LEAVES:15)
Block(6,30,-14,LEAVES:15)
Block(8,30,-14,LEAVES:15)
Block(9,30,-14,LEAVES:15)
Block(0,30,-13,LEAVES:15)
Block(1,30,-13,LEAVES:15)
Block(5,30,-13,LEAVES:15)
Block(9,30,-13,LEAVES:15)
Block(11,30,-13,LEAVES:15)
Block(12,30,-13,LEAVES:15)
Block(4,30,-12,LEAVES:15)
Block(11,30,-12,LEAVES:15)
Block(14,30,-12,LEAVES:15)
Block(-2,30,-11,LEAVES:15)
Block(11,30,-11,LEAVES:15)
Block(0,30,-10,LEAVES:15)
Block(9,30,-10,LEAVES:15)
Block(7,30,-9,LEAVES:15)
Block(8,30,-8,LOG:15)
Block(10,30,-8,LEAVES:15)
Block(10,30,-7,LEAVES:15)
Block(-9,30,-2,LEAVES:15)
Block(3,30,-1,LOG:15)
Block(-7,30,0,LEAVES:15)
Block(3,30,0,LOG:15)
Block(4,30,0,LOG:15)
Block(-12,30,1,LEAVES:15)
Block(-8,30,1,LEAVES:15)
Block(0,30,1,LOG:15)
Block(1,30,1,LOG:15)
Block(3,30,1,LOG:15)
Block(-7,30,2,LEAVES:15)
Block(-1,30,2,LOG:15)
Block(0,30,2,LOG:15)
Block(-8,30,3,LEAVES:15)
Block(-6,30,4,LEAVES:15)
Block(-10,30,7,LEAVES:15)
Block(8,30,7,LEAVES:15)
Block(6,30,8,LEAVES:15)
Block(7,30,10,LEAVES:15)
Block(7,30,11,LEAVES:15)
Block(14,31,-16,LEAVES:15)
Block(14,31,-15,LEAVES:15)
Block(6,31,-14,LEAVES:15)
Block(8,31,-14,LEAVES:15)
Block(9,31,-14,LEAVES:15)
Block(1,31,-13,LEAVES:15)
Block(5,31,-13,LEAVES:15)
Block(9,31,-13,LEAVES:15)
Block(11,31,-13,LEAVES:15)
Block(12,31,-13,LEAVES:15)
Block(4,31,-12,LEAVES:15)
Block(9,31,-12,LEAVES:15)
Block(10,31,-12,LEAVES:15)
Block(11,31,-12,LEAVES:15)
Block(14,31,-12,LEAVES:15)
Block(-2,31,-11,LEAVES:15)
Block(9,31,-11,LEAVES:15)
Block(10,31,-11,LEAVES:15)
Block(11,31,-11,LEAVES:15)
Block(0,31,-10,LEAVES:15)
Block(9,31,-10,LEAVES:15)
Block(7,31,-9,LEAVES:15)
Block(8,31,-9,LEAVES:15)
Block(10,31,-9,LEAVES:15)
Block(11,31,-9,LEAVES:15)
Block(8,31,-8,LOG:15)
Block(9,31,-8,LOG:15)
Block(10,31,-8,LEAVES:15)
Block(11,31,-8,LEAVES:15)
Block(12,31,-8,LEAVES:15)
Block(14,31,-8,LEAVES:15)
Block(10,31,-7,LEAVES:15)
Block(11,31,-7,LEAVES:15)
Block(14,31,-7,LEAVES:15)
Block(10,31,-6,LEAVES:15)
Block(14,31,-6,LEAVES:15)
Block(15,31,-6,LEAVES:15)
Block(14,31,-5,LEAVES:15)
Block(15,31,-5,LEAVES:15)
Block(-9,31,-2,LEAVES:15)
Block(3,31,-1,LOG:15)
Block(-7,31,0,LEAVES:15)
Block(3,31,0,LOG:15)
Block(4,31,0,LOG:15)
Block(-12,31,1,LEAVES:15)
Block(-8,31,1,LEAVES:15)
Block(3,31,1,LOG:15)
Block(-7,31,2,LEAVES:15)
Block(-3,31,2,LOG:15)
Block(-2,31,2,LOG:15)
Block(-1,31,2,LOG:15)
Block(-8,31,3,LEAVES:15)
Block(-6,31,4,LEAVES:15)
Block(-10,31,7,LEAVES:15)
Block(8,31,7,LEAVES:15)
Block(6,31,8,LEAVES:15)
Block(7,31,10,LEAVES:15)
Block(7,31,11,LEAVES:15)
Block(4,32,-16,LEAVES:15)
Block(7,32,-16,LEAVES:15)
Block(8,32,-16,LEAVES:15)
Block(11,32,-16,LEAVES:15)
Block(14,32,-16,LEAVES:15)
Block(4,32,-15,LEAVES:15)
Block(7,32,-15,LEAVES:15)
Block(8,32,-15,LEAVES:15)
Block(9,32,-15,LEAVES:15)
Block(14,32,-15,LEAVES:15)
Block(15,32,-15,LEAVES:15)
Block(6,32,-14,LEAVES:15)
Block(8,32,-14,LEAVES:15)
Block(9,32,-14,LEAVES:15)
Block(14,32,-14,LEAVES:15)
Block(0,32,-13,LEAVES:15)
Block(5,32,-13,LEAVES:15)
Block(6,32,-13,LEAVES:15)
Block(7,32,-13,LEAVES:15)
Block(9,32,-13,LEAVES:15)
Block(10,32,-13,LEAVES:15)
Block(11,32,-13,LEAVES:15)
Block(12,32,-13,LEAVES:15)
Block(13,32,-13,LEAVES:15)
Block(14,32,-13,LEAVES:15)
Block(-1,32,-12,LEAVES:15)
Block(4,32,-12,LEAVES:15)
Block(6,32,-12,LEAVES:15)
Block(7,32,-12,LEAVES:15)
Block(8,32,-12,LEAVES:15)
Block(9,32,-12,LEAVES:15)
Block(10,32,-12,LEAVES:15)
Block(11,32,-12,LEAVES:15)
Block(14,32,-12,LEAVES:15)
Block(-2,32,-11,LEAVES:15)
Block(8,32,-11,LEAVES:15)
Block(9,32,-11,LEAVES:15)
Block(11,32,-11,LEAVES:15)
Block(0,32,-10,LEAVES:15)
Block(7,32,-10,LEAVES:15)
Block(8,32,-10,LEAVES:15)
Block(9,32,-10,LEAVES:15)
Block(12,32,-10,LEAVES:15)
Block(13,32,-10,LEAVES:15)
Block(14,32,-10,LEAVES:15)
Block(-3,32,-9,LEAVES:15)
Block(-2,32,-9,LEAVES:15)
Block(6,32,-9,LOG:15)
Block(7,32,-9,LOG:15)
Block(8,32,-9,LEAVES:15)
Block(9,32,-9,LOG:15)
Block(10,32,-9,LOG:15)
Block(11,32,-9,LEAVES:15)
Block(13,32,-9,LEAVES:15)
Block(14,32,-9,LEAVES:15)
Block(0,32,-8,LEAVES:15)
Block(1,32,-8,LEAVES:15)
Block(4,32,-8,LEAVES:15)
Block(8,32,-8,LOG:15)
Block(9,32,-8,LOG:15)
Block(10,32,-8,LEAVES:15)
Block(11,32,-8,LEAVES:15)
Block(0,32,-7,LEAVES:15)
Block(1,32,-7,LEAVES:15)
Block(4,32,-7,LEAVES:15)
Block(10,32,-7,LEAVES:15)
Block(11,32,-7,LEAVES:15)
Block(4,32,-6,LEAVES:15)
Block(5,32,-6,LEAVES:15)
Block(4,32,-5,LEAVES:15)
Block(5,32,-5,LEAVES:15)
Block(-9,32,-2,LEAVES:15)
Block(-7,32,0,LEAVES:15)
Block(3,32,0,LOG:15)
Block(4,32,0,LOG:15)
Block(-12,32,1,LEAVES:15)
Block(-8,32,1,LEAVES:15)
Block(3,32,1,LOG:15)
Block(-7,32,2,LEAVES:15)
Block(-4,32,2,LOG:15)
Block(-3,32,2,LOG:15)
Block(-2,32,2,LOG:15)
Block(-8,32,3,LEAVES:15)
Block(-6,32,4,LEAVES:15)
Block(-10,32,7,LEAVES:15)
Block(8,32,7,LEAVES:15)
Block(6,32,8,LEAVES:15)
Block(7,32,10,LEAVES:15)
Block(7,32,11,LEAVES:15)
Block(-3,33,-16,LEAVES:15)
Block(-2,33,-16,LEAVES:15)
Block(1,33,-16,LEAVES:15)
Block(4,33,-16,LEAVES:15)
Block(11,33,-16,LEAVES:15)
Block(12,33,-16,LEAVES:15)
Block(-3,33,-15,LEAVES:15)
Block(-2,33,-15,LEAVES:15)
Block(-1,33,-15,LEAVES:15)
Block(4,33,-15,LEAVES:15)
Block(5,33,-15,LEAVES:15)
Block(8,33,-15,LEAVES:15)
Block(9,33,-15,LEAVES:15)
Block(11,33,-15,LEAVES:15)
Block(12,33,-15,LEAVES:15)
Block(4,33,-14,LEAVES:15)
Block(8,33,-14,LEAVES:15)
Block(9,33,-14,LEAVES:15)
Block(10,33,-14,LEAVES:15)
Block(11,33,-14,LEAVES:15)
Block(13,33,-14,LEAVES:15)
Block(-4,33,-13,LEAVES:15)
Block(-3,33,-13,LEAVES:15)
Block(3,33,-13,LEAVES:15)
Block(4,33,-13,LEAVES:15)
Block(5,33,-13,LEAVES:15)
Block(8,33,-13,LEAVES:15)
Block(9,33,-13,LEAVES:15)
Block(10,33,-13,LEAVES:15)
Block(11,33,-13,LEAVES:15)
Block(12,33,-13,LEAVES:15)
Block(13,33,-13,LEAVES:15)
Block(-4,33,-12,LEAVES:15)
Block(-3,33,-12,LEAVES:15)
Block(-2,33,-12,LEAVES:15)
Block(4,33,-12,LEAVES:15)
Block(8,33,-12,LEAVES:15)
Block(10,33,-12,LEAVES:15)
Block(11,33,-12,LEAVES:15)
Block(12,33,-12,LEAVES:15)
Block(13,33,-12,LEAVES:15)
Block(14,33,-12,LEAVES:15)
Block(-2,33,-11,LEAVES:15)
Block(5,33,-11,LEAVES:15)
Block(6,33,-11,LEAVES:15)
Block(9,33,-11,LEAVES:15)
Block(11,33,-11,LEAVES:15)
Block(12,33,-11,LEAVES:15)
Block(-3,33,-10,LEAVES:15)
Block(-2,33,-10,LEAVES:15)
Block(2,33,-10,LEAVES:15)
Block(3,33,-10,LEAVES:15)
Block(4,33,-10,LEAVES:15)
Block(5,33,-10,LOG:15)
Block(6,33,-10,LOG:15)
Block(9,33,-10,LEAVES:15)
Block(11,33,-10,LOG:15)
Block(12,33,-10,LEAVES:15)
Block(-2,33,-9,LEAVES:15)
Block(1,33,-9,LEAVES:15)
Block(3,33,-9,LEAVES:15)
Block(4,33,-9,LEAVES:15)
Block(8,33,-9,LEAVES:15)
Block(9,33,-9,LEAVES:15)
Block(10,33,-9,LEAVES:15)
Block(11,33,-9,LEAVES:15)
Block(1,33,-8,LEAVES:15)
Block(4,33,-8,LEAVES:15)
Block(7,33,-8,LEAVES:15)
Block(8,33,-8,LEAVES:15)
Block(9,33,-8,LEAVES:15)
Block(10,33,-8,LEAVES:15)
Block(8,33,-7,LOG:15)
Block(14,33,-7,LEAVES:15)
Block(9,33,-6,LEAVES:15)
Block(4,33,-5,LEAVES:15)
Block(5,33,-5,LEAVES:15)
Block(4,33,-4,LEAVES:15)
Block(5,33,-4,LEAVES:15)
Block(-9,33,-2,LEAVES:15)
Block(2,33,-2,LEAVES:15)
Block(3,33,-2,LEAVES:15)
Block(5,33,-1,LEAVES:15)
Block(6,33,-1,LEAVES:15)
Block(9,33,-1,LEAVES:15)
Block(-8,33,0,LEAVES:15)
Block(-7,33,0,LEAVES:15)
Block(3,33,0,LOG:15)
Block(4,33,0,LOG:15)
Block(5,33,0,LEAVES:15)
Block(6,33,0,LEAVES:15)
Block(9,33,0,LEAVES:15)
Block(-12,33,1,LEAVES:15)
Block(-8,33,1,LEAVES:15)
Block(3,33,1,LOG:15)
Block(9,33,1,LEAVES:15)
Block(10,33,1,LEAVES:15)
Block(-7,33,2,LEAVES:15)
Block(-4,33,2,LOG:15)
Block(9,33,2,LEAVES:15)
Block(10,33,2,LEAVES:15)
Block(-8,33,3,LEAVES:15)
Block(-6,33,4,LEAVES:15)
Block(-10,33,7,LEAVES:15)
Block(8,33,7,LEAVES:15)
Block(6,33,8,LEAVES:15)
Block(7,33,10,LEAVES:15)
Block(7,33,11,LEAVES:15)
Block(11,34,-16,LEAVES:15)
Block(-1,34,-15,LEAVES:15)
Block(11,34,-15,LEAVES:15)
Block(6,34,-14,LEAVES:15)
Block(7,34,-14,LEAVES:15)
Block(10,34,-14,LEAVES:15)
Block(11,34,-14,LEAVES:15)
Block(-2,34,-13,LEAVES:15)
Block(-1,34,-13,LEAVES:15)
Block(3,34,-13,LEAVES:15)
Block(5,34,-13,LEAVES:15)
Block(6,34,-13,LEAVES:15)
Block(7,34,-13,LEAVES:15)
Block(10,34,-13,LEAVES:15)
Block(11,34,-13,LEAVES:15)
Block(12,34,-13,LEAVES:15)
Block(-2,34,-12,LEAVES:15)
Block(2,34,-12,LEAVES:15)
Block(3,34,-12,LEAVES:15)
Block(4,34,-12,LEAVES:15)
Block(10,34,-12,LEAVES:15)
Block(11,34,-12,LEAVES:15)
Block(12,34,-12,LEAVES:15)
Block(14,34,-12,LEAVES:15)
Block(15,34,-12,LEAVES:15)
Block(2,34,-11,LEAVES:15)
Block(4,34,-11,LOG:15)
Block(9,34,-11,LEAVES:15)
Block(11,34,-11,LEAVES:15)
Block(12,34,-11,LOG:15)
Block(13,34,-11,LOG:15)
Block(15,34,-11,LEAVES:15)
Block(1,34,-10,LEAVES:15)
Block(2,34,-10,LEAVES:15)
Block(5,34,-10,LOG:15)
Block(6,34,-10,LEAVES:15)
Block(7,34,-10,LEAVES:15)
Block(10,34,-10,LEAVES:15)
Block(11,34,-10,LEAVES:15)
Block(12,34,-10,LEAVES:15)
Block(15,34,-10,LEAVES:15)
Block(1,34,-9,LEAVES:15)
Block(2,34,-9,LEAVES:15)
Block(3,34,-9,LEAVES:15)
Block(6,34,-9,LEAVES:15)
Block(7,34,-9,LEAVES:15)
Block(8,34,-9,LEAVES:15)
Block(9,34,-9,LEAVES:15)
Block(10,34,-9,LEAVES:15)
Block(11,34,-9,LEAVES:15)
Block(2,34,-8,LEAVES:15)
Block(3,34,-8,LEAVES:15)
Block(4,34,-8,LEAVES:15)
Block(8,34,-8,LEAVES:15)
Block(9,34,-8,LEAVES:15)
Block(10,34,-8,LEAVES:15)
Block(11,34,-8,LEAVES:15)
Block(3,34,-7,LEAVES:15)
Block(4,34,-7,LEAVES:15)
Block(8,34,-7,LOG:15)
Block(9,34,-7,LEAVES:15)
Block(1,34,-6,LEAVES:15)
Block(2,34,-6,LEAVES:15)
Block(3,34,-6,LEAVES:15)
Block(4,34,-6,LEAVES:15)
Block(5,34,-6,LEAVES:15)
Block(8,34,-6,LOG:15)
Block(9,34,-6,LEAVES:15)
Block(1,34,-5,LEAVES:15)
Block(2,34,-5,LEAVES:15)
Block(3,34,-5,LEAVES:15)
Block(5,34,-5,LEAVES:15)
Block(3,34,-4,LEAVES:15)
Block(2,34,-3,LEAVES:15)
Block(3,34,-3,LEAVES:15)
Block(7,34,-3,LEAVES:15)
Block(8,34,-3,LEAVES:15)
Block(9,34,-3,LEAVES:15)
Block(-9,34,-2,LEAVES:15)
Block(3,34,-2,LEAVES:15)
Block(6,34,-2,LEAVES:15)
Block(8,34,-2,LEAVES:15)
Block(9,34,-2,LEAVES:15)
Block(13,34,-2,LEAVES:15)
Block(14,34,-2,LEAVES:15)
Block(6,34,-1,LEAVES:15)
Block(9,34,-1,LEAVES:15)
Block(13,34,-1,LEAVES:15)
Block(14,34,-1,LEAVES:15)
Block(-8,34,0,LEAVES:15)
Block(-7,34,0,LEAVES:15)
Block(3,34,0,LOG:15)
Block(4,34,0,LOG:15)
Block(-12,34,1,LEAVES:15)
Block(-8,34,1,LEAVES:15)
Block(3,34,1,LOG:15)
Block(-7,34,2,LEAVES:15)
Block(-5,34,2,LOG:15)
Block(-4,34,2,LOG:15)
Block(-8,34,3,LEAVES:15)
Block(-6,34,4,LEAVES:15)
Block(-10,34,7,LEAVES:15)
Block(8,34,7,LEAVES:15)
Block(6,34,8,LEAVES:15)
Block(7,34,10,LEAVES:15)
Block(7,34,11,LEAVES:15)
Block(8,35,-15,LEAVES:15)
Block(9,35,-15,LEAVES:15)
Block(13,35,-15,LEAVES:15)
Block(9,35,-14,LEAVES:15)
Block(10,35,-14,LEAVES:15)
Block(13,35,-14,LEAVES:15)
Block(0,35,-13,LEAVES:15)
Block(6,35,-13,LEAVES:15)
Block(9,35,-13,LEAVES:15)
Block(10,35,-13,LEAVES:15)
Block(12,35,-13,LEAVES:15)
Block(13,35,-13,LEAVES:15)
Block(1,35,-12,LEAVES:15)
Block(2,35,-12,LEAVES:15)
Block(5,35,-12,LEAVES:15)
Block(6,35,-12,LEAVES:15)
Block(7,35,-12,LEAVES:15)
Block(8,35,-12,LEAVES:15)
Block(9,35,-12,LEAVES:15)
Block(11,35,-12,LEAVES:15)
Block(12,35,-12,LEAVES:15)
Block(3,35,-11,LOG:15)
Block(5,35,-11,LEAVES:15)
Block(7,35,-11,LEAVES:15)
Block(8,35,-11,LEAVES:15)
Block(9,35,-11,LEAVES:15)
Block(11,35,-11,LEAVES:15)
Block(12,35,-11,LEAVES:15)
Block(13,35,-11,LEAVES:15)
Block(14,35,-11,LEAVES:15)
Block(15,35,-11,LEAVES:15)
Block(5,35,-10,LEAVES:15)
Block(6,35,-10,LEAVES:15)
Block(13,35,-10,LEAVES:15)
Block(0,35,-9,LEAVES:15)
Block(1,35,-9,LEAVES:15)
Block(5,35,-9,LEAVES:15)
Block(6,35,-9,LEAVES:15)
Block(7,35,-9,LEAVES:15)
Block(10,35,-9,LEAVES:15)
Block(13,35,-9,LEAVES:15)
Block(0,35,-8,LEAVES:15)
Block(1,35,-8,LEAVES:15)
Block(4,35,-8,LEAVES:15)
Block(5,35,-8,LEAVES:15)
Block(6,35,-8,LEAVES:15)
Block(7,35,-8,LEAVES:15)
Block(4,35,-7,LEAVES:15)
Block(5,35,-7,LEAVES:15)
Block(6,35,-7,LEAVES:15)
Block(11,35,-7,LEAVES:15)
Block(12,35,-7,LEAVES:15)
Block(3,35,-6,LEAVES:15)
Block(4,35,-6,LEAVES:15)
Block(5,35,-6,LEAVES:15)
Block(8,35,-6,LEAVES:15)
Block(9,35,-6,LEAVES:15)
Block(11,35,-6,LEAVES:15)
Block(12,35,-6,LEAVES:15)
Block(3,35,-5,LEAVES:15)
Block(7,35,-5,LEAVES:15)
Block(8,35,-5,LOG:15)
Block(7,35,-4,LEAVES:15)
Block(6,35,-3,LEAVES:15)
Block(7,35,-3,LEAVES:15)
Block(11,35,-3,LEAVES:15)
Block(12,35,-3,LEAVES:15)
Block(-9,35,-2,LEAVES:15)
Block(6,35,-2,LEAVES:15)
Block(12,35,-2,LEAVES:15)
Block(13,35,-2,LEAVES:15)
Block(-8,35,0,LEAVES:15)
Block(-7,35,0,LEAVES:15)
Block(3,35,0,LOG:15)
Block(4,35,0,LOG:15)
Block(8,35,0,LEAVES:15)
Block(9,35,0,LEAVES:15)
Block(-12,35,1,LEAVES:15)
Block(-8,35,1,LEAVES:15)
Block(3,35,1,LOG:15)
Block(8,35,1,LEAVES:15)
Block(9,35,1,LEAVES:15)
Block(-7,35,2,LEAVES:15)
Block(-5,35,2,LOG:15)
Block(-8,35,3,LEAVES:15)
Block(-6,35,4,LEAVES:15)
Block(-10,35,7,LEAVES:15)
Block(8,35,7,LEAVES:15)
Block(6,35,8,LEAVES:15)
Block(7,35,10,LEAVES:15)
Block(7,35,11,LEAVES:15)
Block(3,36,-15,LEAVES:15)
Block(13,36,-15,LEAVES:15)
Block(14,36,-15,LEAVES:15)
Block(3,36,-14,LEAVES:15)
Block(13,36,-14,LEAVES:15)
Block(14,36,-14,LEAVES:15)
Block(-1,36,-13,LEAVES:15)
Block(0,36,-13,LEAVES:15)
Block(2,36,-13,LEAVES:15)
Block(3,36,-13,LEAVES:15)
Block(10,36,-13,LEAVES:15)
Block(-3,36,-12,LEAVES:15)
Block(-2,36,-12,LEAVES:15)
Block(-1,36,-12,LEAVES:15)
Block(1,36,-12,LEAVES:15)
Block(2,36,-12,LEAVES:15)
Block(9,36,-12,LEAVES:15)
Block(10,36,-12,LEAVES:15)
Block(11,36,-12,LEAVES:15)
Block(-3,36,-11,LEAVES:15)
Block(-2,36,-11,LEAVES:15)
Block(2,36,-11,LEAVES:15)
Block(3,36,-11,LEAVES:15)
Block(4,36,-11,LEAVES:15)
Block(5,36,-11,LEAVES:15)
Block(12,36,-11,LEAVES:15)
Block(13,36,-11,LEAVES:15)
Block(3,36,-10,LEAVES:15)
Block(3,36,-9,LEAVES:15)
Block(6,36,-9,LEAVES:15)
Block(13,36,-9,LEAVES:15)
Block(5,36,-8,LEAVES:15)
Block(13,36,-8,LEAVES:15)
Block(6,36,-7,LEAVES:15)
Block(5,36,-6,LEAVES:15)
Block(6,36,-6,LEAVES:15)
Block(11,36,-6,LEAVES:15)
Block(6,36,-5,LEAVES:15)
Block(7,36,-5,LEAVES:15)
Block(10,36,-5,LEAVES:15)
Block(11,36,-5,LEAVES:15)
Block(8,36,-4,LOG:15)
Block(10,36,-4,LEAVES:15)
Block(10,36,-3,LEAVES:15)
Block(11,36,-3,LEAVES:15)
Block(-9,36,-2,LEAVES:15)
Block(5,36,-2,LEAVES:15)
Block(6,36,-2,LEAVES:15)
Block(10,36,-2,LEAVES:15)
Block(5,36,-1,LEAVES:15)
Block(6,36,-1,LEAVES:15)
Block(9,36,-1,LEAVES:15)
Block(10,36,-1,LEAVES:15)
Block(-8,36,0,LEAVES:15)
Block(-7,36,0,LEAVES:15)
Block(3,36,0,LOG:15)
Block(4,36,0,LOG:15)
Block(10,36,0,LEAVES:15)
Block(-12,36,1,LEAVES:15)
Block(-8,36,1,LEAVES:15)
Block(3,36,1,LOG:15)
Block(4,36,1,LOG:15)
Block(-7,36,2,LEAVES:15)
Block(-6,36,2,LOG:15)
Block(-5,36,2,LOG:15)
Block(-8,36,3,LEAVES:15)
Block(-6,36,4,LEAVES:15)
Block(-10,36,7,LEAVES:15)
Block(8,36,7,LEAVES:15)
Block(6,36,8,LEAVES:15)
Block(7,36,10,LEAVES:15)
Block(7,36,11,LEAVES:15)
Block(3,37,-15,LEAVES:15)
Block(4,37,-15,LEAVES:15)
Block(3,37,-14,LEAVES:15)
Block(4,37,-14,LEAVES:15)
Block(0,37,-13,LEAVES:15)
Block(0,37,-12,LEAVES:15)
Block(5,37,-12,LEAVES:15)
Block(6,37,-12,LEAVES:15)
Block(11,37,-12,LEAVES:15)
Block(12,37,-12,LEAVES:15)
Block(2,37,-11,LEAVES:15)
Block(5,37,-11,LEAVES:15)
Block(6,37,-11,LEAVES:15)
Block(12,37,-11,LEAVES:15)
Block(3,37,-9,LEAVES:15)
Block(3,37,-8,LEAVES:15)
Block(4,37,-8,LEAVES:15)
Block(8,37,-8,LEAVES:15)
Block(4,37,-7,LEAVES:15)
Block(5,37,-7,LEAVES:15)
Block(8,37,-7,LEAVES:15)
Block(4,37,-6,LEAVES:15)
Block(5,37,-6,LEAVES:15)
Block(7,37,-6,LEAVES:15)
Block(8,37,-6,LEAVES:15)
Block(2,37,-5,LEAVES:15)
Block(3,37,-5,LEAVES:15)
Block(4,37,-5,LEAVES:15)
Block(6,37,-5,LEAVES:15)
Block(7,37,-5,LEAVES:15)
Block(2,37,-4,LEAVES:15)
Block(3,37,-4,LEAVES:15)
Block(7,37,-4,LEAVES:15)
Block(8,37,-4,LEAVES:15)
Block(9,37,-4,LEAVES:15)
Block(10,37,-4,LEAVES:15)
Block(8,37,-3,LEAVES:15)
Block(-9,37,-2,LEAVES:15)
Block(8,37,-2,LEAVES:15)
Block(10,37,-1,LEAVES:15)
Block(-8,37,0,LEAVES:15)
Block(-7,37,0,LEAVES:15)
Block(3,37,0,LOG:15)
Block(4,37,0,LOG:15)
Block(-12,37,1,LEAVES:15)
Block(-8,37,1,LEAVES:15)
Block(3,37,1,LOG:15)
Block(4,37,1,LOG:15)
Block(-7,37,2,LEAVES:15)
Block(-6,37,2,LOG:15)
Block(-5,37,2,LOG:15)
Block(4,37,2,LOG:15)
Block(-8,37,3,LEAVES:15)
Block(-6,37,3,LOG:15)
Block(-6,37,4,LEAVES:15)
Block(-10,37,7,LEAVES:15)
Block(8,37,7,LEAVES:15)
Block(6,37,8,LEAVES:15)
Block(8,37,8,LEAVES:15)
Block(7,37,10,LEAVES:15)
Block(7,37,11,LEAVES:15)
Block(2,38,-12,LEAVES:15)
Block(2,38,-11,LEAVES:15)
Block(8,38,-8,LEAVES:15)
Block(9,38,-8,LEAVES:15)
Block(8,38,-7,LEAVES:15)
Block(9,38,-7,LEAVES:15)
Block(-13,38,-6,LEAVES:15)
Block(-12,38,-6,LEAVES:15)
Block(5,38,-6,LEAVES:15)
Block(-13,38,-5,LEAVES:15)
Block(-12,38,-5,LEAVES:15)
Block(5,38,-5,LEAVES:15)
Block(10,38,-5,LEAVES:15)
Block(11,38,-5,LEAVES:15)
Block(-9,38,-4,LEAVES:15)
Block(7,38,-4,LEAVES:15)
Block(10,38,-4,LEAVES:15)
Block(11,38,-4,LEAVES:15)
Block(-10,38,-3,LEAVES:15)
Block(-9,38,-3,LEAVES:15)
Block(-8,38,-3,LEAVES:15)
Block(-9,38,-2,LEAVES:15)
Block(8,38,-2,LEAVES:15)
Block(-10,38,-1,LEAVES:15)
Block(4,38,-1,LOG:15)
Block(8,38,-1,LEAVES:15)
Block(-14,38,0,LEAVES:15)
Block(-13,38,0,LEAVES:15)
Block(-12,38,0,LEAVES:15)
Block(-10,38,0,LEAVES:15)
Block(-8,38,0,LEAVES:15)
Block(-7,38,0,LEAVES:15)
Block(3,38,0,LOG:15)
Block(4,38,0,LOG:15)
Block(-14,38,1,LEAVES:15)
Block(-13,38,1,LEAVES:15)
Block(-12,38,1,LEAVES:15)
Block(-11,38,1,LEAVES:15)
Block(-10,38,1,LEAVES:15)
Block(-8,38,1,LEAVES:15)
Block(-7,38,1,LOG:15)
Block(3,38,1,LOG:15)
Block(4,38,1,LOG:15)
Block(-10,38,2,LEAVES:15)
Block(-9,38,2,LEAVES:15)
Block(-7,38,2,LEAVES:15)
Block(-4,38,2,LOG:15)
Block(4,38,2,LOG:15)
Block(-16,38,3,LEAVES:15)
Block(-15,38,3,LEAVES:15)
Block(-9,38,3,LEAVES:15)
Block(-8,38,3,LEAVES:15)
Block(-13,38,4,LEAVES:15)
Block(-12,38,4,LEAVES:15)
Block(-9,38,4,LEAVES:15)
Block(-8,38,4,LEAVES:15)
Block(-7,38,4,LOG:15)
Block(-13,38,5,LEAVES:15)
Block(-12,38,5,LEAVES:15)
Block(-9,38,5,LEAVES:15)
Block(-5,38,5,LEAVES:15)
Block(-9,38,6,LEAVES:15)
Block(-8,38,6,LEAVES:15)
Block(-5,38,6,LEAVES:15)
Block(-10,38,7,LEAVES:15)
Block(-9,38,7,LEAVES:15)
Block(-8,38,7,LEAVES:15)
Block(8,38,7,LEAVES:15)
Block(6,38,8,LEAVES:15)
Block(8,38,8,LEAVES:15)
Block(7,38,10,LEAVES:15)
Block(9,38,10,LEAVES:15)
Block(7,38,11,LEAVES:15)
Block(-10,39,-9,LEAVES:15)
Block(-9,39,-9,LEAVES:15)
Block(-10,39,-8,LEAVES:15)
Block(-9,39,-8,LEAVES:15)
Block(-6,39,-7,LEAVES:15)
Block(-6,39,-6,LEAVES:15)
Block(-12,39,-5,LEAVES:15)
Block(-5,39,-5,LEAVES:15)
Block(-4,39,-5,LEAVES:15)
Block(7,39,-5,LEAVES:15)
Block(-16,39,-4,LEAVES:15)
Block(-15,39,-4,LEAVES:15)
Block(-12,39,-4,LEAVES:15)
Block(-10,39,-4,LEAVES:15)
Block(-9,39,-4,LEAVES:15)
Block(-8,39,-4,LEAVES:15)
Block(-5,39,-4,LEAVES:15)
Block(-4,39,-4,LEAVES:15)
Block(7,39,-4,LEAVES:15)
Block(-16,39,-3,LEAVES:15)
Block(-15,39,-3,LEAVES:15)
Block(-14,39,-3,LEAVES:15)
Block(-11,39,-3,LEAVES:15)
Block(-10,39,-3,LEAVES:15)
Block(-9,39,-3,LEAVES:15)
Block(-8,39,-3,LEAVES:15)
Block(-7,39,-3,LEAVES:15)
Block(-1,39,-3,LEAVES:15)
Block(-11,39,-2,LEAVES:15)
Block(-10,39,-2,LEAVES:15)
Block(-9,39,-2,LEAVES:15)
Block(-1,39,-2,LEAVES:15)
Block(-13,39,-1,LEAVES:15)
Block(-10,39,-1,LEAVES:15)
Block(-9,39,-1,LEAVES:15)
Block(4,39,-1,LOG:15)
Block(-11,39,0,LEAVES:15)
Block(-10,39,0,LEAVES:15)
Block(-8,39,0,LEAVES:15)
Block(-7,39,0,LOG:15)
Block(3,39,0,LOG:15)
Block(4,39,0,LOG:15)
Block(-15,39,1,LEAVES:15)
Block(-12,39,1,LEAVES:15)
Block(-11,39,1,LEAVES:15)
Block(-10,39,1,LEAVES:15)
Block(-9,39,1,LEAVES:15)
Block(-8,39,1,LOG:15)
Block(-7,39,1,LOG:15)
Block(-6,39,1,LEAVES:15)
Block(-5,39,1,LEAVES:15)
Block(3,39,1,LOG:15)
Block(-16,39,2,LEAVES:15)
Block(-15,39,2,LEAVES:15)
Block(-11,39,2,LEAVES:15)
Block(-10,39,2,LEAVES:15)
Block(-9,39,2,LEAVES:15)
Block(-8,39,2,LEAVES:15)
Block(-7,39,2,LEAVES:15)
Block(-6,39,2,LEAVES:15)
Block(-5,39,2,LEAVES:15)
Block(-4,39,2,LOG:15)
Block(4,39,2,LOG:15)
Block(-15,39,3,LEAVES:15)
Block(-12,39,3,LEAVES:15)
Block(-11,39,3,LEAVES:15)
Block(-10,39,3,LEAVES:15)
Block(-9,39,3,LEAVES:15)
Block(-8,39,3,LEAVES:15)
Block(-7,39,3,LEAVES:15)
Block(-6,39,3,LEAVES:15)
Block(-5,39,3,LEAVES:15)
Block(-4,39,3,LEAVES:15)
Block(-3,39,3,LEAVES:15)
Block(4,39,3,LOG:15)
Block(-12,39,4,LEAVES:15)
Block(-10,39,4,LEAVES:15)
Block(-9,39,4,LEAVES:15)
Block(-8,39,4,LEAVES:15)
Block(-7,39,4,LOG:15)
Block(-6,39,4,LEAVES:15)
Block(-5,39,4,LEAVES:15)
Block(-4,39,4,LEAVES:15)
Block(-3,39,4,LEAVES:15)
Block(-2,39,4,LEAVES:15)
Block(-7,39,5,LOG:15)
Block(-6,39,5,LEAVES:15)
Block(-5,39,5,LEAVES:15)
Block(-4,39,5,LEAVES:15)
Block(-1,39,5,LEAVES:15)
Block(-12,39,6,LEAVES:15)
Block(-11,39,6,LEAVES:15)
Block(-6,39,6,LEAVES:15)
Block(-5,39,6,LEAVES:15)
Block(-4,39,6,LEAVES:15)
Block(-3,39,6,LEAVES:15)
Block(-1,39,6,LEAVES:15)
Block(-12,39,7,LEAVES:15)
Block(-11,39,7,LEAVES:15)
Block(-9,39,7,LEAVES:15)
Block(-5,39,7,LEAVES:15)
Block(-4,39,7,LEAVES:15)
Block(-1,39,7,LEAVES:15)
Block(0,39,7,LEAVES:15)
Block(8,39,7,LEAVES:15)
Block(-1,39,8,LEAVES:15)
Block(0,39,8,LEAVES:15)
Block(6,39,8,LEAVES:15)
Block(8,39,8,LEAVES:15)
Block(-14,39,9,LEAVES:15)
Block(-13,39,9,LEAVES:15)
Block(-11,39,10,LEAVES:15)
Block(-10,39,10,LEAVES:15)
Block(-7,39,10,LEAVES:15)
Block(7,39,10,LEAVES:15)
Block(9,39,10,LEAVES:15)
Block(-11,39,11,LEAVES:15)
Block(-10,39,11,LEAVES:15)
Block(-7,39,11,LEAVES:15)
Block(7,39,11,LEAVES:15)
Block(-7,39,12,LEAVES:15)
Block(-6,39,12,LEAVES:15)
Block(-7,39,13,LEAVES:15)
Block(-6,39,13,LEAVES:15)
Block(-9,40,-8,LEAVES:15)
Block(-13,40,-7,LEAVES:15)
Block(-12,40,-7,LEAVES:15)
Block(-9,40,-7,LEAVES:15)
Block(-6,40,-7,LEAVES:15)
Block(-13,40,-6,LEAVES:15)
Block(-12,40,-6,LEAVES:15)
Block(-11,40,-6,LEAVES:15)
Block(-6,40,-6,LEAVES:15)
Block(-5,40,-6,LEAVES:15)
Block(-10,40,-5,LEAVES:15)
Block(-6,40,-5,LEAVES:15)
Block(-14,40,-4,LEAVES:15)
Block(-13,40,-4,LEAVES:15)
Block(-12,40,-4,LEAVES:15)
Block(-11,40,-4,LEAVES:15)
Block(-10,40,-4,LEAVES:15)
Block(-9,40,-4,LEAVES:15)
Block(-7,40,-4,LEAVES:15)
Block(-6,40,-4,LEAVES:15)
Block(-4,40,-4,LEAVES:15)
Block(-14,40,-3,LEAVES:15)
Block(-13,40,-3,LEAVES:15)
Block(-12,40,-3,LEAVES:15)
Block(-11,40,-3,LEAVES:15)
Block(-10,40,-3,LEAVES:15)
Block(-8,40,-3,LEAVES:15)
Block(-7,40,-3,LEAVES:15)
Block(-4,40,-3,LEAVES:15)
Block(-1,40,-3,LEAVES:15)
Block(-12,40,-2,LEAVES:15)
Block(-10,40,-2,LEAVES:15)
Block(-8,40,-2,LEAVES:15)
Block(-7,40,-2,LEAVES:15)
Block(-6,40,-2,LEAVES:15)
Block(-1,40,-2,LEAVES:15)
Block(0,40,-2,LEAVES:15)
Block(-13,40,-1,LEAVES:15)
Block(-10,40,-1,LEAVES:15)
Block(-8,40,-1,LEAVES:15)
Block(-7,40,-1,LOG:15)
Block(-6,40,-1,LEAVES:15)
Block(-1,40,-1,LEAVES:15)
Block(4,40,-1,LOG:15)
Block(-15,40,0,LEAVES:15)
Block(-12,40,0,LEAVES:15)
Block(-11,40,0,LEAVES:15)
Block(-10,40,0,LEAVES:15)
Block(-9,40,0,LEAVES:15)
Block(-8,40,0,LEAVES:15)
Block(-7,40,0,LEAVES:15)
Block(-6,40,0,LEAVES:15)
Block(-5,40,0,LEAVES:15)
Block(-2,40,0,LEAVES:15)
Block(-1,40,0,LEAVES:15)
Block(2,40,0,LOG:15)
Block(3,40,0,LOG:15)
Block(4,40,0,LOG:15)
Block(-11,40,1,LEAVES:15)
Block(-10,40,1,LEAVES:15)
Block(-9,40,1,LOG:15)
Block(-8,40,1,LOG:15)
Block(-7,40,1,LEAVES:15)
Block(-6,40,1,LEAVES:15)
Block(-5,40,1,LEAVES:15)
Block(-4,40,1,LEAVES:15)
Block(-2,40,1,LEAVES:15)
Block(-1,40,1,LEAVES:15)
Block(3,40,1,LOG:15)
Block(-14,40,2,LEAVES:15)
Block(-13,40,2,LEAVES:15)
Block(-12,40,2,LEAVES:15)
Block(-11,40,2,LEAVES:15)
Block(-10,40,2,LEAVES:15)
Block(-8,40,2,LEAVES:15)
Block(-7,40,2,LEAVES:15)
Block(-6,40,2,LEAVES:15)
Block(-3,40,2,LOG:15)
Block(4,40,2,LOG:15)
Block(-14,40,3,LEAVES:15)
Block(-13,40,3,LEAVES:15)
Block(-12,40,3,LEAVES:15)
Block(-9,40,3,LEAVES:15)
Block(-8,40,3,LEAVES:15)
Block(-7,40,3,LEAVES:15)
Block(-6,40,3,LEAVES:15)
Block(-5,40,3,LEAVES:15)
Block(-3,40,3,LEAVES:15)
Block(-2,40,3,LEAVES:15)
Block(-1,40,3,LEAVES:15)
Block(4,40,3,LOG:15)
Block(-10,40,4,LEAVES:15)
Block(-9,40,4,LEAVES:15)
Block(-8,40,4,LEAVES:15)
Block(-7,40,4,LEAVES:15)
Block(-4,40,4,LEAVES:15)
Block(-3,40,4,LEAVES:15)
Block(-2,40,4,LEAVES:15)
Block(-1,40,4,LEAVES:15)
Block(3,40,4,LEAVES:15)
Block(4,40,4,LEAVES:15)
Block(5,40,4,LOG:15)
Block(-15,40,5,LEAVES:15)
Block(-14,40,5,LEAVES:15)
Block(-11,40,5,LEAVES:15)
Block(-10,40,5,LEAVES:15)
Block(-9,40,5,LEAVES:15)
Block(-8,40,5,LEAVES:15)
Block(-7,40,5,LEAVES:15)
Block(-6,40,5,LEAVES:15)
Block(-5,40,5,LEAVES:15)
Block(-4,40,5,LEAVES:15)
Block(-3,40,5,LEAVES:15)
Block(-2,40,5,LEAVES:15)
Block(-1,40,5,LEAVES:15)
Block(3,40,5,LEAVES:15)
Block(4,40,5,LEAVES:15)
Block(-15,40,6,LEAVES:15)
Block(-14,40,6,LEAVES:15)
Block(-13,40,6,LEAVES:15)
Block(-11,40,6,LEAVES:15)
Block(-10,40,6,LEAVES:15)
Block(-9,40,6,LEAVES:15)
Block(-8,40,6,LOG:15)
Block(-7,40,6,LEAVES:15)
Block(-5,40,6,LEAVES:15)
Block(-4,40,6,LEAVES:15)
Block(-13,40,7,LEAVES:15)
Block(-9,40,7,LEAVES:15)
Block(-4,40,7,LEAVES:15)
Block(8,40,7,LEAVES:15)
Block(-14,40,8,LEAVES:15)
Block(-13,40,8,LEAVES:15)
Block(-9,40,8,LEAVES:15)
Block(-8,40,8,LEAVES:15)
Block(-7,40,8,LEAVES:15)
Block(6,40,8,LEAVES:15)
Block(8,40,8,LEAVES:15)
Block(-13,40,9,LEAVES:15)
Block(-10,40,9,LEAVES:15)
Block(-8,40,9,LEAVES:15)
Block(-7,40,9,LEAVES:15)
Block(-3,40,9,LEAVES:15)
Block(-2,40,9,LEAVES:15)
Block(-10,40,10,LEAVES:15)
Block(-7,40,10,LEAVES:15)
Block(-3,40,10,LEAVES:15)
Block(-2,40,10,LEAVES:15)
Block(7,40,10,LEAVES:15)
Block(9,40,10,LEAVES:15)
Block(7,40,11,LEAVES:15)
Block(-9,41,-7,LEAVES:15)
Block(-8,41,-7,LEAVES:15)
Block(-11,41,-6,LEAVES:15)
Block(-9,41,-6,LEAVES:15)
Block(-8,41,-6,LEAVES:15)
Block(-11,41,-5,LEAVES:15)
Block(-9,41,-5,LEAVES:15)
Block(-4,41,-5,LEAVES:15)
Block(-3,41,-5,LEAVES:15)
Block(-12,41,-4,LEAVES:15)
Block(-11,41,-4,LEAVES:15)
Block(-10,41,-4,LEAVES:15)
Block(-7,41,-4,LEAVES:15)
Block(-4,41,-4,LEAVES:15)
Block(-3,41,-4,LEAVES:15)
Block(-12,41,-3,LEAVES:15)
Block(-8,41,-3,LEAVES:15)
Block(-7,41,-3,LEAVES:15)
Block(-4,41,-3,LEAVES:15)
Block(-3,41,-3,LEAVES:15)
Block(-12,41,-2,LEAVES:15)
Block(-9,41,-2,LEAVES:15)
Block(-8,41,-2,LEAVES:15)
Block(-6,41,-2,LEAVES:15)
Block(-4,41,-2,LEAVES:15)
Block(-3,41,-2,LEAVES:15)
Block(-13,41,-1,LEAVES:15)
Block(-12,41,-1,LEAVES:15)
Block(-9,41,-1,LEAVES:15)
Block(-8,41,-1,LEAVES:15)
Block(-7,41,-1,LOG:15)
Block(-6,41,-1,LEAVES:15)
Block(-4,41,-1,LEAVES:15)
Block(-3,41,-1,LEAVES:15)
Block(1,41,-1,LEAVES:15)
Block(2,41,-1,LEAVES:15)
Block(4,41,-1,LOG:15)
Block(5,41,-1,LOG:15)
Block(-12,41,0,LEAVES:15)
Block(-11,41,0,LEAVES:15)
Block(-10,41,0,LEAVES:15)
Block(-9,41,0,LEAVES:15)
Block(-8,41,0,LEAVES:15)
Block(-7,41,0,LEAVES:15)
Block(-6,41,0,LEAVES:15)
Block(-5,41,0,LEAVES:15)
Block(-3,41,0,LEAVES:15)
Block(-2,41,0,LEAVES:15)
Block(1,41,0,LEAVES:15)
Block(2,41,0,LOG:15)
Block(3,41,0,LOG:15)
Block(4,41,0,LOG:15)
Block(-10,41,1,LOG:15)
Block(-8,41,1,LEAVES:15)
Block(-7,41,1,LEAVES:15)
Block(-3,41,1,LEAVES:15)
Block(-2,41,1,LEAVES:15)
Block(3,41,1,LOG:15)
Block(-10,41,2,LEAVES:15)
Block(-9,41,2,LEAVES:15)
Block(-8,41,2,LEAVES:15)
Block(-7,41,2,LEAVES:15)
Block(-6,41,2,LEAVES:15)
Block(-3,41,2,LOG:15)
Block(-13,41,3,LEAVES:15)
Block(-12,41,3,LEAVES:15)
Block(-10,41,3,LEAVES:15)
Block(-9,41,3,LEAVES:15)
Block(-8,41,3,LEAVES:15)
Block(-7,41,3,LEAVES:15)
Block(-6,41,3,LEAVES:15)
Block(-4,41,3,LEAVES:15)
Block(-3,41,3,LEAVES:15)
Block(1,41,3,LEAVES:15)
Block(2,41,3,LEAVES:15)
Block(-13,41,4,LEAVES:15)
Block(-12,41,4,LEAVES:15)
Block(-10,41,4,LEAVES:15)
Block(-9,41,4,LEAVES:15)
Block(-8,41,4,LEAVES:15)
Block(-7,41,4,LEAVES:15)
Block(-6,41,4,LEAVES:15)
Block(-5,41,4,LEAVES:15)
Block(-4,41,4,LEAVES:15)
Block(2,41,4,LEAVES:15)
Block(3,41,4,LEAVES:15)
Block(5,41,4,LOG:15)
Block(-13,41,5,LEAVES:15)
Block(-12,41,5,LEAVES:15)
Block(-11,41,5,LEAVES:15)
Block(-8,41,5,LEAVES:15)
Block(-6,41,5,LEAVES:15)
Block(-5,41,5,LEAVES:15)
Block(-4,41,5,LEAVES:15)
Block(-3,41,5,LEAVES:15)
Block(5,41,5,LOG:15)
Block(-13,41,6,LEAVES:15)
Block(-9,41,6,LEAVES:15)
Block(-8,41,6,LOG:15)
Block(-5,41,6,LEAVES:15)
Block(-4,41,6,LEAVES:15)
Block(-2,41,6,LEAVES:15)
Block(-1,41,6,LEAVES:15)
Block(-9,41,7,LEAVES:15)
Block(-8,41,7,LOG:15)
Block(-4,41,7,LEAVES:15)
Block(-2,41,7,LEAVES:15)
Block(-1,41,7,LEAVES:15)
Block(8,41,7,LEAVES:15)
Block(-10,41,8,LEAVES:15)
Block(-9,41,8,LEAVES:15)
Block(-5,41,8,LEAVES:15)
Block(-4,41,8,LEAVES:15)
Block(6,41,8,LEAVES:15)
Block(8,41,8,LEAVES:15)
Block(-10,41,9,LEAVES:15)
Block(-4,41,9,LEAVES:15)
Block(-3,41,9,LEAVES:15)
Block(7,41,10,LEAVES:15)
Block(9,41,10,LEAVES:15)
Block(-8,41,11,LEAVES:15)
Block(-7,41,11,LEAVES:15)
Block(6,41,11,LEAVES:15)
Block(7,41,11,LEAVES:15)
Block(-8,41,12,LEAVES:15)
Block(-7,41,12,LEAVES:15)
Block(-9,42,-7,LEAVES:15)
Block(-9,42,-5,LEAVES:15)
Block(-10,42,-4,LEAVES:15)
Block(-9,42,-4,LEAVES:15)
Block(-4,42,-4,LEAVES:15)
Block(-15,42,-3,LEAVES:15)
Block(-14,42,-3,LEAVES:15)
Block(-10,42,-3,LEAVES:15)
Block(-9,42,-3,LEAVES:15)
Block(-8,42,-3,LEAVES:15)
Block(-5,42,-3,LEAVES:15)
Block(-4,42,-3,LEAVES:15)
Block(-14,42,-2,LEAVES:15)
Block(-13,42,-2,LEAVES:15)
Block(-10,42,-2,LEAVES:15)
Block(-8,42,-2,LEAVES:15)
Block(-7,42,-2,LOG:15)
Block(-5,42,-2,LEAVES:15)
Block(6,42,-2,LOG:15)
Block(-14,42,-1,LEAVES:15)
Block(-13,42,-1,LEAVES:15)
Block(-11,42,-1,LEAVES:15)
Block(-10,42,-1,LEAVES:15)
Block(-8,42,-1,LEAVES:15)
Block(-5,42,-1,LEAVES:15)
Block(-4,42,-1,LEAVES:15)
Block(5,42,-1,LOG:15)
Block(-16,42,0,LEAVES:15)
Block(-15,42,0,LEAVES:15)
Block(-14,42,0,LEAVES:15)
Block(-12,42,0,LEAVES:15)
Block(-11,42,0,LEAVES:15)
Block(-10,42,0,LEAVES:15)
Block(-9,42,0,LEAVES:15)
Block(-5,42,0,LEAVES:15)
Block(-4,42,0,LEAVES:15)
Block(1,42,0,LEAVES:15)
Block(2,42,0,LOG:15)
Block(3,42,0,LOG:15)
Block(-16,42,1,LEAVES:15)
Block(-15,42,1,LEAVES:15)
Block(-11,42,1,LEAVES:15)
Block(-10,42,1,LEAVES:15)
Block(-9,42,1,LEAVES:15)
Block(-8,42,1,LEAVES:15)
Block(-6,42,1,LEAVES:15)
Block(-5,42,1,LEAVES:15)
Block(-4,42,1,LEAVES:15)
Block(-3,42,1,LEAVES:15)
Block(0,42,1,LEAVES:15)
Block(1,42,1,LEAVES:15)
Block(-10,42,2,LEAVES:15)
Block(-9,42,2,LEAVES:15)
Block(-8,42,2,LEAVES:15)
Block(-5,42,2,LEAVES:15)
Block(-2,42,2,LOG:15)
Block(0,42,2,LEAVES:15)
Block(-10,42,3,LEAVES:15)
Block(-7,42,3,LEAVES:15)
Block(0,42,3,LEAVES:15)
Block(1,42,3,LEAVES:15)
Block(6,42,3,LEAVES:15)
Block(7,42,3,LEAVES:15)
Block(-10,42,4,LEAVES:15)
Block(-8,42,4,LEAVES:15)
Block(-5,42,4,LEAVES:15)
Block(-4,42,4,LEAVES:15)
Block(0,42,4,LEAVES:15)
Block(6,42,4,LEAVES:15)
Block(7,42,4,LEAVES:15)
Block(-11,42,5,LEAVES:15)
Block(-10,42,5,LEAVES:15)
Block(-5,42,5,LEAVES:15)
Block(-4,42,5,LEAVES:15)
Block(-1,42,5,LEAVES:15)
Block(0,42,5,LEAVES:15)
Block(6,42,5,LOG:15)
Block(10,42,5,LEAVES:15)
Block(-10,42,6,LEAVES:15)
Block(-9,42,6,LEAVES:15)
Block(-6,42,6,LEAVES:15)
Block(-5,42,6,LEAVES:15)
Block(0,42,6,LEAVES:15)
Block(5,42,6,LOG:15)
Block(6,42,6,LOG:15)
Block(10,42,6,LEAVES:15)
Block(-8,42,7,LOG:15)
Block(-6,42,7,LEAVES:15)
Block(8,42,7,LEAVES:15)
Block(-6,42,8,LEAVES:15)
Block(-5,42,8,LEAVES:15)
Block(6,42,8,LEAVES:15)
Block(8,42,8,LEAVES:15)
Block(-11,42,9,LEAVES:15)
Block(-10,42,9,LEAVES:15)
Block(-6,42,9,LEAVES:15)
Block(5,42,9,LEAVES:15)
Block(6,42,9,LEAVES:15)
Block(-11,42,10,LEAVES:15)
Block(-10,42,10,LEAVES:15)
Block(-7,42,10,LEAVES:15)
Block(-6,42,10,LEAVES:15)
Block(5,42,10,LEAVES:15)
Block(6,42,10,LEAVES:15)
Block(7,42,10,LEAVES:15)
Block(9,42,10,LEAVES:15)
Block(-6,42,11,LEAVES:15)
Block(6,42,11,LEAVES:15)
Block(7,42,11,LEAVES:15)
Block(3,42,12,LEAVES:15)
Block(4,42,12,LEAVES:15)
Block(6,42,13,LEAVES:15)
Block(7,42,13,LEAVES:15)
Block(10,42,13,LEAVES:15)
Block(6,42,14,LEAVES:15)
Block(7,42,14,LEAVES:15)
Block(-12,43,-6,LEAVES:15)
Block(-11,43,-6,LEAVES:15)
Block(-7,43,-6,LEAVES:15)
Block(-11,43,-5,LEAVES:15)
Block(-10,43,-5,LEAVES:15)
Block(-7,43,-5,LEAVES:15)
Block(-11,43,-4,LEAVES:15)
Block(-10,43,-4,LEAVES:15)
Block(-8,43,-4,LEAVES:15)
Block(-7,43,-4,LEAVES:15)
Block(-13,43,-3,LEAVES:15)
Block(-12,43,-3,LEAVES:15)
Block(-11,43,-3,LEAVES:15)
Block(-10,43,-3,LEAVES:15)
Block(-9,43,-3,LEAVES:15)
Block(-8,43,-3,LEAVES:15)
Block(6,43,-3,LOG:15)
Block(-13,43,-2,LEAVES:15)
Block(-12,43,-2,LEAVES:15)
Block(-10,43,-2,LEAVES:15)
Block(-9,43,-2,LEAVES:15)
Block(-8,43,-2,LEAVES:15)
Block(-7,43,-2,LEAVES:15)
Block(-6,43,-2,LEAVES:15)
Block(-5,43,-2,LEAVES:15)
Block(-2,43,-2,LEAVES:15)
Block(6,43,-2,LOG:15)
Block(7,43,-2,LOG:15)
Block(-13,43,-1,LEAVES:15)
Block(-7,43,-1,LEAVES:15)
Block(-6,43,-1,LEAVES:15)
Block(-5,43,-1,LEAVES:15)
Block(-2,43,-1,LEAVES:15)
Block(-13,43,0,LEAVES:15)
Block(-8,43,0,LEAVES:15)
Block(-7,43,0,LEAVES:15)
Block(-6,43,0,LEAVES:15)
Block(-5,43,0,LEAVES:15)
Block(-3,43,0,LEAVES:15)
Block(-2,43,0,LEAVES:15)
Block(2,43,0,LOG:15)
Block(3,43,0,LOG:15)
Block(-11,43,1,LEAVES:15)
Block(-8,43,1,LEAVES:15)
Block(-7,43,1,LEAVES:15)
Block(-6,43,1,LEAVES:15)
Block(-5,43,1,LEAVES:15)
Block(-4,43,1,LEAVES:15)
Block(-3,43,1,LEAVES:15)
Block(-8,43,2,LEAVES:15)
Block(-7,43,2,LEAVES:15)
Block(-3,43,2,LEAVES:15)
Block(-2,43,2,LEAVES:15)
Block(-1,43,2,LEAVES:15)
Block(0,43,2,LEAVES:15)
Block(-13,43,3,LEAVES:15)
Block(-12,43,3,LEAVES:15)
Block(-10,43,3,LEAVES:15)
Block(-8,43,3,LEAVES:15)
Block(-2,43,3,LEAVES:15)
Block(-12,43,4,LEAVES:15)
Block(-11,43,4,LEAVES:15)
Block(-10,43,4,LEAVES:15)
Block(-8,43,4,LEAVES:15)
Block(-2,43,4,LEAVES:15)
Block(7,43,4,LEAVES:15)
Block(-12,43,5,LEAVES:15)
Block(-11,43,5,LEAVES:15)
Block(-9,43,5,LEAVES:15)
Block(-8,43,5,LEAVES:15)
Block(0,43,5,LEAVES:15)
Block(3,43,5,LEAVES:15)
Block(4,43,5,LEAVES:15)
Block(7,43,5,LEAVES:15)
Block(10,43,5,LEAVES:15)
Block(-14,43,6,LEAVES:15)
Block(-13,43,6,LEAVES:15)
Block(-12,43,6,LEAVES:15)
Block(-10,43,6,LEAVES:15)
Block(-9,43,6,LEAVES:15)
Block(3,43,6,LEAVES:15)
Block(4,43,6,LOG:15)
Block(5,43,6,LEAVES:15)
Block(10,43,6,LEAVES:15)
Block(11,43,6,LEAVES:15)
Block(-14,43,7,LEAVES:15)
Block(-13,43,7,LEAVES:15)
Block(-9,43,7,LEAVES:15)
Block(-8,43,7,LEAVES:15)
Block(-7,43,7,LEAVES:15)
Block(-6,43,7,LEAVES:15)
Block(7,43,7,LOG:15)
Block(8,43,7,LEAVES:15)
Block(10,43,7,LEAVES:15)
Block(-8,43,8,LEAVES:15)
Block(2,43,8,LEAVES:15)
Block(3,43,8,LEAVES:15)
Block(6,43,8,LEAVES:15)
Block(7,43,8,LOG:15)
Block(8,43,8,LEAVES:15)
Block(9,43,8,LEAVES:15)
Block(10,43,8,LEAVES:15)
Block(-8,43,9,LEAVES:15)
Block(2,43,9,LEAVES:15)
Block(3,43,9,LEAVES:15)
Block(4,43,9,LEAVES:15)
Block(5,43,9,LEAVES:15)
Block(6,43,9,LEAVES:15)
Block(-6,43,10,LEAVES:15)
Block(4,43,10,LEAVES:15)
Block(7,43,10,LEAVES:15)
Block(9,43,10,LEAVES:15)
Block(3,43,11,LEAVES:15)
Block(4,43,11,LEAVES:15)
Block(6,43,11,LEAVES:15)
Block(7,43,11,LEAVES:15)
Block(8,43,11,LEAVES:15)
Block(9,43,11,LEAVES:15)
Block(10,43,11,LEAVES:15)
Block(4,43,12,LEAVES:15)
Block(7,43,12,LEAVES:15)
Block(9,43,12,LEAVES:15)
Block(10,43,12,LEAVES:15)
Block(14,43,12,LEAVES:15)
Block(15,43,12,LEAVES:15)
Block(7,43,13,LEAVES:15)
Block(10,43,13,LEAVES:15)
Block(14,43,13,LEAVES:15)
Block(15,43,13,LEAVES:15)
Block(3,44,-14,LEAVES:15)
Block(4,44,-14,LEAVES:15)
Block(3,44,-13,LEAVES:15)
Block(4,44,-13,LEAVES:15)
Block(7,44,-12,LEAVES:15)
Block(7,44,-11,LEAVES:15)
Block(8,44,-11,LEAVES:15)
Block(9,44,-11,LEAVES:15)
Block(8,44,-10,LEAVES:15)
Block(9,44,-10,LEAVES:15)
Block(12,44,-9,LEAVES:15)
Block(2,44,-8,LEAVES:15)
Block(3,44,-8,LEAVES:15)
Block(12,44,-8,LEAVES:15)
Block(2,44,-7,LEAVES:15)
Block(3,44,-7,LEAVES:15)
Block(-7,44,-6,LEAVES:15)
Block(-6,44,-6,LEAVES:15)
Block(-7,44,-5,LEAVES:15)
Block(-6,44,-5,LEAVES:15)
Block(0,44,-5,LEAVES:15)
Block(1,44,-5,LEAVES:15)
Block(7,44,-5,LEAVES:15)
Block(8,44,-5,LEAVES:15)
Block(-10,44,-4,LEAVES:15)
Block(3,44,-4,LEAVES:15)
Block(4,44,-4,LEAVES:15)
Block(6,44,-4,LOG:15)
Block(7,44,-4,LEAVES:15)
Block(8,44,-4,LEAVES:15)
Block(-10,44,-3,LEAVES:15)
Block(-5,44,-3,LEAVES:15)
Block(-4,44,-3,LEAVES:15)
Block(3,44,-3,LEAVES:15)
Block(4,44,-3,LEAVES:15)
Block(7,44,-3,LEAVES:15)
Block(-8,44,-2,LEAVES:15)
Block(-5,44,-2,LEAVES:15)
Block(-4,44,-2,LEAVES:15)
Block(-2,44,-2,LEAVES:15)
Block(-1,44,-2,LEAVES:15)
Block(5,44,-2,LEAVES:15)
Block(6,44,-2,LEAVES:15)
Block(7,44,-2,LOG:15)
Block(8,44,-2,LEAVES:15)
Block(-2,44,-1,LEAVES:15)
Block(-1,44,-1,LEAVES:15)
Block(7,44,-1,LEAVES:15)
Block(8,44,-1,LEAVES:15)
Block(9,44,-1,LEAVES:15)
Block(12,44,-1,LEAVES:15)
Block(-11,44,0,LEAVES:15)
Block(-7,44,0,LEAVES:15)
Block(-5,44,0,LEAVES:15)
Block(2,44,0,LOG:15)
Block(4,44,0,LOG:15)
Block(8,44,0,LEAVES:15)
Block(9,44,0,LEAVES:15)
Block(12,44,0,LEAVES:15)
Block(-11,44,1,LEAVES:15)
Block(-7,44,1,LEAVES:15)
Block(-5,44,1,LEAVES:15)
Block(-3,44,1,LEAVES:15)
Block(-2,44,1,LEAVES:15)
Block(0,44,1,LEAVES:15)
Block(1,44,1,LEAVES:15)
Block(12,44,1,LEAVES:15)
Block(13,44,1,LEAVES:15)
Block(-3,44,2,LEAVES:15)
Block(-2,44,2,LEAVES:15)
Block(0,44,2,LEAVES:15)
Block(1,44,2,LEAVES:15)
Block(12,44,2,LEAVES:15)
Block(13,44,2,LEAVES:15)
Block(-8,44,3,LEAVES:15)
Block(-7,44,3,LEAVES:15)
Block(1,44,3,LEAVES:15)
Block(-8,44,4,LEAVES:15)
Block(-7,44,4,LEAVES:15)
Block(-2,44,4,LEAVES:15)
Block(1,44,4,LEAVES:15)
Block(-11,44,5,LEAVES:15)
Block(-2,44,5,LEAVES:15)
Block(7,44,5,LEAVES:15)
Block(8,44,5,LEAVES:15)
Block(-11,44,6,LEAVES:15)
Block(-6,44,6,LEAVES:15)
Block(-5,44,6,LEAVES:15)
Block(5,44,6,LEAVES:15)
Block(7,44,6,LEAVES:15)
Block(8,44,6,LEAVES:15)
Block(-9,44,7,LEAVES:15)
Block(-6,44,7,LEAVES:15)
Block(-5,44,7,LEAVES:15)
Block(-4,44,7,LEAVES:15)
Block(-3,44,7,LEAVES:15)
Block(3,44,7,LOG:15)
Block(5,44,7,LEAVES:15)
Block(7,44,7,LEAVES:15)
Block(8,44,7,LEAVES:15)
Block(12,44,7,LEAVES:15)
Block(13,44,7,LEAVES:15)
Block(-4,44,8,LEAVES:15)
Block(-3,44,8,LEAVES:15)
Block(4,44,8,LEAVES:15)
Block(5,44,8,LEAVES:15)
Block(6,44,8,LEAVES:15)
Block(8,44,8,LEAVES:15)
Block(9,44,8,LEAVES:15)
Block(12,44,8,LEAVES:15)
Block(13,44,8,LEAVES:15)
Block(-8,44,9,LEAVES:15)
Block(4,44,9,LEAVES:15)
Block(5,44,9,LEAVES:15)
Block(8,44,9,LOG:15)
Block(9,44,9,LEAVES:15)
Block(-8,44,10,LEAVES:15)
Block(-6,44,10,LEAVES:15)
Block(-5,44,10,LEAVES:15)
Block(7,44,10,LEAVES:15)
Block(8,44,10,LEAVES:15)
Block(-3,44,11,LEAVES:15)
Block(-2,44,11,LEAVES:15)
Block(1,44,11,LEAVES:15)
Block(6,44,11,LEAVES:15)
Block(7,44,11,LEAVES:15)
Block(8,44,11,LEAVES:15)
Block(12,44,11,LEAVES:15)
Block(13,44,11,LEAVES:15)
Block(-3,44,12,LEAVES:15)
Block(-2,44,12,LEAVES:15)
Block(1,44,12,LEAVES:15)
Block(7,44,12,LEAVES:15)
Block(13,44,12,LEAVES:15)
Block(14,44,12,LEAVES:15)
Block(1,44,13,LEAVES:15)
Block(2,44,13,LEAVES:15)
Block(1,44,14,LEAVES:15)
Block(2,44,14,LEAVES:15)
Block(9,44,14,LEAVES:15)
Block(10,44,14,LEAVES:15)
Block(9,44,15,LEAVES:15)
Block(10,44,15,LEAVES:15)
Block(4,45,-13,LEAVES:15)
Block(0,45,-12,LEAVES:15)
Block(1,45,-12,LEAVES:15)
Block(4,45,-12,LEAVES:15)
Block(7,45,-12,LEAVES:15)
Block(0,45,-11,LEAVES:15)
Block(1,45,-11,LEAVES:15)
Block(2,45,-11,LEAVES:15)
Block(7,45,-11,LEAVES:15)
Block(8,45,-11,LEAVES:15)
Block(7,45,-10,LEAVES:15)
Block(9,45,-10,LEAVES:15)
Block(-1,45,-9,LEAVES:15)
Block(0,45,-9,LEAVES:15)
Block(3,45,-9,LEAVES:15)
Block(5,45,-9,LEAVES:15)
Block(6,45,-9,LEAVES:15)
Block(7,45,-9,LEAVES:15)
Block(9,45,-9,LEAVES:15)
Block(12,45,-9,LEAVES:15)
Block(-1,45,-8,LEAVES:15)
Block(0,45,-8,LEAVES:15)
Block(1,45,-8,LEAVES:15)
Block(3,45,-8,LEAVES:15)
Block(5,45,-8,LEAVES:15)
Block(6,45,-8,LEAVES:15)
Block(7,45,-8,LEAVES:15)
Block(12,45,-8,LEAVES:15)
Block(13,45,-8,LEAVES:15)
Block(1,45,-7,LEAVES:15)
Block(12,45,-7,LEAVES:15)
Block(0,45,-6,LEAVES:15)
Block(1,45,-6,LEAVES:15)
Block(4,45,-6,LEAVES:15)
Block(5,45,-6,LEAVES:15)
Block(6,45,-6,LEAVES:15)
Block(7,45,-6,LEAVES:15)
Block(8,45,-6,LEAVES:15)
Block(11,45,-6,LEAVES:15)
Block(12,45,-6,LEAVES:15)
Block(1,45,-5,LEAVES:15)
Block(4,45,-5,LEAVES:15)
Block(5,45,-5,LEAVES:15)
Block(6,45,-5,LOG:15)
Block(7,45,-5,LEAVES:15)
Block(8,45,-5,LEAVES:15)
Block(11,45,-5,LEAVES:15)
Block(12,45,-5,LEAVES:15)
Block(4,45,-4,LEAVES:15)
Block(6,45,-4,LEAVES:15)
Block(7,45,-4,LEAVES:15)
Block(11,45,-4,LEAVES:15)
Block(12,45,-4,LEAVES:15)
Block(-8,45,-3,LEAVES:15)
Block(5,45,-3,LEAVES:15)
Block(6,45,-3,LEAVES:15)
Block(8,45,-3,LOG:15)
Block(9,45,-3,LOG:15)
Block(10,45,-3,LEAVES:15)
Block(11,45,-3,LEAVES:15)
Block(12,45,-3,LEAVES:15)
Block(-8,45,-2,LEAVES:15)
Block(6,45,-2,LEAVES:15)
Block(9,45,-2,LEAVES:15)
Block(11,45,-2,LEAVES:15)
Block(12,45,-2,LEAVES:15)
Block(9,45,-1,LEAVES:15)
Block(12,45,-1,LEAVES:15)
Block(1,45,0,LOG:15)
Block(4,45,0,LOG:15)
Block(-3,45,1,LEAVES:15)
Block(-3,45,2,LEAVES:15)
Block(-2,45,2,LEAVES:15)
Block(-6,45,3,LEAVES:15)
Block(-5,45,3,LEAVES:15)
Block(-2,45,3,LEAVES:15)
Block(1,45,3,LEAVES:15)
Block(-6,45,4,LEAVES:15)
Block(-5,45,4,LEAVES:15)
Block(-4,45,4,LEAVES:15)
Block(1,45,4,LEAVES:15)
Block(2,45,4,LEAVES:15)
Block(1,45,5,LEAVES:15)
Block(7,45,5,LEAVES:15)
Block(-9,45,6,LEAVES:15)
Block(-7,45,6,LEAVES:15)
Block(-6,45,6,LEAVES:15)
Block(-3,45,6,LEAVES:15)
Block(0,45,6,LEAVES:15)
Block(1,45,6,LEAVES:15)
Block(-9,45,7,LEAVES:15)
Block(-7,45,7,LEAVES:15)
Block(-6,45,7,LEAVES:15)
Block(-5,45,7,LEAVES:15)
Block(-3,45,7,LEAVES:15)
Block(2,45,7,LOG:15)
Block(7,45,7,LEAVES:15)
Block(8,45,7,LEAVES:15)
Block(-5,45,8,LEAVES:15)
Block(6,45,8,LEAVES:15)
Block(7,45,8,LEAVES:15)
Block(12,45,8,LEAVES:15)
Block(-6,45,9,LEAVES:15)
Block(-5,45,9,LEAVES:15)
Block(-1,45,9,LEAVES:15)
Block(0,45,9,LEAVES:15)
Block(1,45,9,LEAVES:15)
Block(7,45,9,LEAVES:15)
Block(8,45,9,LEAVES:15)
Block(11,45,9,LEAVES:15)
Block(12,45,9,LEAVES:15)
Block(-5,45,10,LEAVES:15)
Block(-2,45,10,LEAVES:15)
Block(0,45,10,LEAVES:15)
Block(1,45,10,LEAVES:15)
Block(5,45,10,LEAVES:15)
Block(6,45,10,LEAVES:15)
Block(7,45,10,LEAVES:15)
Block(9,45,10,LOG:15)
Block(11,45,10,LEAVES:15)
Block(-2,45,11,LEAVES:15)
Block(1,45,11,LEAVES:15)
Block(5,45,11,LEAVES:15)
Block(6,45,11,LEAVES:15)
Block(9,45,11,LOG:15)
Block(11,45,11,LEAVES:15)
Block(12,45,11,LEAVES:15)
Block(6,45,12,LEAVES:15)
Block(7,45,12,LEAVES:15)
Block(11,45,12,LEAVES:15)
Block(6,45,13,LEAVES:15)
Block(7,45,13,LEAVES:15)
Block(10,45,13,LEAVES:15)
Block(11,45,13,LEAVES:15)
Block(11,45,14,LEAVES:15)
Block(4,46,-12,LEAVES:15)
Block(5,46,-12,LEAVES:15)
Block(-3,46,-11,LEAVES:15)
Block(-2,46,-11,LEAVES:15)
Block(2,46,-11,LEAVES:15)
Block(4,46,-11,LEAVES:15)
Block(5,46,-11,LEAVES:15)
Block(-3,46,-10,LEAVES:15)
Block(-2,46,-10,LEAVES:15)
Block(2,46,-10,LEAVES:15)
Block(4,46,-10,LEAVES:15)
Block(9,46,-10,LEAVES:15)
Block(10,46,-10,LEAVES:15)
Block(1,46,-9,LEAVES:15)
Block(2,46,-9,LEAVES:15)
Block(3,46,-9,LEAVES:15)
Block(6,46,-9,LEAVES:15)
Block(9,46,-9,LEAVES:15)
Block(10,46,-9,LEAVES:15)
Block(1,46,-8,LEAVES:15)
Block(5,46,-8,LEAVES:15)
Block(6,46,-8,LEAVES:15)
Block(7,46,-8,LEAVES:15)
Block(9,46,-8,LEAVES:15)
Block(10,46,-8,LEAVES:15)
Block(5,46,-7,LEAVES:15)
Block(7,46,-7,LEAVES:15)
Block(9,46,-7,LEAVES:15)
Block(14,46,-7,LEAVES:15)
Block(15,46,-7,LEAVES:15)
Block(4,46,-6,LEAVES:15)
Block(5,46,-6,LEAVES:15)
Block(6,46,-6,LOG:15)
Block(7,46,-6,LEAVES:15)
Block(8,46,-6,LEAVES:15)
Block(9,46,-6,LEAVES:15)
Block(10,46,-6,LEAVES:15)
Block(11,46,-6,LEAVES:15)
Block(14,46,-6,LEAVES:15)
Block(15,46,-6,LEAVES:15)
Block(-4,46,-5,LEAVES:15)
Block(-3,46,-5,LEAVES:15)
Block(4,46,-5,LEAVES:15)
Block(6,46,-5,LEAVES:15)
Block(10,46,-5,LEAVES:15)
Block(11,46,-5,LEAVES:15)
Block(-4,46,-4,LEAVES:15)
Block(-3,46,-4,LEAVES:15)
Block(10,46,-4,LEAVES:15)
Block(6,46,-3,LEAVES:15)
Block(7,46,-3,LEAVES:15)
Block(9,46,-3,LOG:15)
Block(10,46,-3,LOG:15)
Block(14,46,-3,LEAVES:15)
Block(15,46,-3,LEAVES:15)
Block(-6,46,-2,LEAVES:15)
Block(-5,46,-2,LEAVES:15)
Block(6,46,-2,LEAVES:15)
Block(7,46,-2,LEAVES:15)
Block(9,46,-2,LEAVES:15)
Block(15,46,-2,LEAVES:15)
Block(-3,46,-1,LEAVES:15)
Block(-2,46,-1,LEAVES:15)
Block(1,46,-1,LEAVES:15)
Block(-3,46,0,LEAVES:15)
Block(-2,46,0,LEAVES:15)
Block(1,46,0,LEAVES:15)
Block(4,46,0,LOG:15)
Block(11,46,0,LEAVES:15)
Block(12,46,0,LEAVES:15)
Block(0,46,1,LOG:15)
Block(1,46,1,LEAVES:15)
Block(2,46,1,LEAVES:15)
Block(11,46,1,LEAVES:15)
Block(12,46,1,LEAVES:15)
Block(1,46,2,LEAVES:15)
Block(2,46,2,LEAVES:15)
Block(-2,46,3,LEAVES:15)
Block(-1,46,3,LEAVES:15)
Block(-4,46,4,LEAVES:15)
Block(-2,46,4,LEAVES:15)
Block(-1,46,4,LEAVES:15)
Block(-4,46,5,LEAVES:15)
Block(-2,46,5,LEAVES:15)
Block(3,46,5,LEAVES:15)
Block(4,46,5,LEAVES:15)
Block(-5,46,6,LEAVES:15)
Block(-4,46,6,LEAVES:15)
Block(-3,46,6,LEAVES:15)
Block(0,46,6,LEAVES:15)
Block(3,46,6,LEAVES:15)
Block(4,46,6,LEAVES:15)
Block(5,46,6,LEAVES:15)
Block(9,46,6,LEAVES:15)
Block(-5,46,7,LEAVES:15)
Block(-1,46,7,LEAVES:15)
Block(0,46,7,LEAVES:15)
Block(5,46,7,LEAVES:15)
Block(6,46,7,LEAVES:15)
Block(9,46,7,LEAVES:15)
Block(-1,46,8,LEAVES:15)
Block(1,46,8,LOG:15)
Block(5,46,8,LEAVES:15)
Block(6,46,8,LEAVES:15)
Block(8,46,8,LEAVES:15)
Block(9,46,8,LEAVES:15)
Block(-2,46,9,LEAVES:15)
Block(-1,46,9,LEAVES:15)
Block(3,46,9,LEAVES:15)
Block(4,46,9,LEAVES:15)
Block(5,46,9,LEAVES:15)
Block(7,46,9,LEAVES:15)
Block(8,46,9,LEAVES:15)
Block(-2,46,10,LEAVES:15)
Block(3,46,10,LEAVES:15)
Block(4,46,10,LEAVES:15)
Block(5,46,10,LEAVES:15)
Block(8,46,10,LEAVES:15)
Block(9,46,10,LEAVES:15)
Block(10,46,10,LEAVES:15)
Block(11,46,10,LEAVES:15)
Block(9,46,11,LEAVES:15)
Block(0,46,12,LEAVES:15)
Block(1,46,12,LEAVES:15)
Block(9,46,12,LEAVES:15)
Block(0,46,13,LEAVES:15)
Block(1,46,13,LEAVES:15)
Block(11,46,13,LEAVES:15)
Block(4,47,-12,LEAVES:15)
Block(-2,47,-10,LEAVES:15)
Block(4,47,-10,LEAVES:15)
Block(-6,47,-9,LEAVES:15)
Block(-5,47,-9,LEAVES:15)
Block(-2,47,-9,LEAVES:15)
Block(1,47,-9,LEAVES:15)
Block(3,47,-9,LEAVES:15)
Block(4,47,-9,LEAVES:15)
Block(9,47,-9,LEAVES:15)
Block(-6,47,-8,LEAVES:15)
Block(-5,47,-8,LEAVES:15)
Block(-4,47,-8,LEAVES:15)
Block(1,47,-8,LEAVES:15)
Block(2,47,-8,LEAVES:15)
Block(4,47,-8,LEAVES:15)
Block(5,47,-8,LEAVES:15)
Block(8,47,-8,LEAVES:15)
Block(9,47,-8,LEAVES:15)
Block(1,47,-7,LEAVES:15)
Block(6,47,-7,LOG:15)
Block(8,47,-7,LEAVES:15)
Block(9,47,-7,LEAVES:15)
Block(-7,47,-6,LEAVES:15)
Block(-6,47,-6,LEAVES:15)
Block(-3,47,-6,LEAVES:15)
Block(0,47,-6,LEAVES:15)
Block(1,47,-6,LEAVES:15)
Block(8,47,-6,LEAVES:15)
Block(9,47,-6,LEAVES:15)
Block(14,47,-6,LEAVES:15)
Block(-7,47,-5,LEAVES:15)
Block(-6,47,-5,LEAVES:15)
Block(-5,47,-5,LEAVES:15)
Block(-3,47,-5,LEAVES:15)
Block(3,47,-5,LEAVES:15)
Block(4,47,-5,LEAVES:15)
Block(5,47,-5,LEAVES:15)
Block(8,47,-5,LEAVES:15)
Block(9,47,-5,LEAVES:15)
Block(10,47,-5,LEAVES:15)
Block(13,47,-5,LEAVES:15)
Block(14,47,-5,LEAVES:15)
Block(-5,47,-4,LEAVES:15)
Block(3,47,-4,LEAVES:15)
Block(4,47,-4,LEAVES:15)
Block(5,47,-4,LEAVES:15)
Block(7,47,-4,LEAVES:15)
Block(8,47,-4,LEAVES:15)
Block(11,47,-4,LOG:15)
Block(13,47,-4,LEAVES:15)
Block(-6,47,-3,LEAVES:15)
Block(-5,47,-3,LEAVES:15)
Block(-1,47,-3,LEAVES:15)
Block(0,47,-3,LEAVES:15)
Block(1,47,-3,LEAVES:15)
Block(8,47,-3,LEAVES:15)
Block(13,47,-3,LEAVES:15)
Block(14,47,-3,LEAVES:15)
Block(-5,47,-2,LEAVES:15)
Block(-2,47,-2,LEAVES:15)
Block(0,47,-2,LEAVES:15)
Block(1,47,-2,LEAVES:15)
Block(5,47,-2,LEAVES:15)
Block(6,47,-2,LEAVES:15)
Block(8,47,-2,LEAVES:15)
Block(9,47,-2,LEAVES:15)
Block(13,47,-2,LEAVES:15)
Block(-2,47,-1,LEAVES:15)
Block(1,47,-1,LEAVES:15)
Block(3,47,-1,LOG:15)
Block(5,47,-1,LEAVES:15)
Block(6,47,-1,LEAVES:15)
Block(8,47,-1,LEAVES:15)
Block(9,47,-1,LEAVES:15)
Block(12,47,-1,LEAVES:15)
Block(13,47,-1,LEAVES:15)
Block(4,47,0,LOG:15)
Block(13,47,0,LEAVES:15)
Block(0,47,1,LOG:15)
Block(3,47,1,LEAVES:15)
Block(4,47,1,LEAVES:15)
Block(5,47,1,LOG:15)
Block(3,47,2,LEAVES:15)
Block(4,47,2,LEAVES:15)
Block(-2,47,3,LEAVES:15)
Block(1,47,4,LEAVES:15)
Block(2,47,4,LEAVES:15)
Block(-2,47,5,LEAVES:15)
Block(4,47,5,LEAVES:15)
Block(5,47,5,LEAVES:15)
Block(8,47,5,LEAVES:15)
Block(-3,47,6,LEAVES:15)
Block(-2,47,6,LEAVES:15)
Block(3,47,6,LEAVES:15)
Block(4,47,6,LEAVES:15)
Block(5,47,6,LEAVES:15)
Block(8,47,6,LEAVES:15)
Block(9,47,6,LEAVES:15)
Block(10,47,6,LEAVES:15)
Block(-2,47,7,LEAVES:15)
Block(-1,47,7,LEAVES:15)
Block(2,47,7,LEAVES:15)
Block(3,47,7,LEAVES:15)
Block(8,47,7,LEAVES:15)
Block(9,47,7,LEAVES:15)
Block(10,47,7,LEAVES:15)
Block(0,47,8,LOG:15)
Block(2,47,8,LEAVES:15)
Block(6,47,8,LEAVES:15)
Block(8,47,8,LEAVES:15)
Block(9,47,8,LEAVES:15)
Block(2,47,9,LEAVES:15)
Block(3,47,9,LEAVES:15)
Block(6,47,9,LEAVES:15)
Block(8,47,9,LEAVES:15)
Block(11,47,9,LEAVES:15)
Block(12,47,9,LEAVES:15)
Block(-3,47,10,LEAVES:15)
Block(-2,47,10,LEAVES:15)
Block(2,47,10,LEAVES:15)
Block(8,47,10,LEAVES:15)
Block(11,47,10,LEAVES:15)
Block(12,47,10,LEAVES:15)
Block(-3,47,11,LEAVES:15)
Block(-2,47,11,LEAVES:15)
Block(1,47,11,LEAVES:15)
Block(2,47,11,LEAVES:15)
Block(2,47,12,LEAVES:15)
Block(9,47,12,LEAVES:15)
Block(9,47,13,LEAVES:15)
Block(1,48,-11,LEAVES:15)
Block(2,48,-11,LEAVES:15)
Block(6,48,-11,LEAVES:15)
Block(2,48,-10,LEAVES:15)
Block(3,48,-10,LEAVES:15)
Block(6,48,-10,LEAVES:15)
Block(-2,48,-9,LEAVES:15)
Block(-1,48,-9,LEAVES:15)
Block(2,48,-9,LEAVES:15)
Block(3,48,-9,LEAVES:15)
Block(5,48,-9,LEAVES:15)
Block(6,48,-9,LEAVES:15)
Block(-4,48,-8,LEAVES:15)
Block(-2,48,-8,LEAVES:15)
Block(-1,48,-8,LEAVES:15)
Block(0,48,-8,LEAVES:15)
Block(1,48,-8,LEAVES:15)
Block(2,48,-8,LEAVES:15)
Block(4,48,-8,LEAVES:15)
Block(5,48,-8,LEAVES:15)
Block(6,48,-8,LEAVES:15)
Block(7,48,-8,LEAVES:15)
Block(11,48,-8,LEAVES:15)
Block(-4,48,-7,LEAVES:15)
Block(-2,48,-7,LEAVES:15)
Block(0,48,-7,LEAVES:15)
Block(1,48,-7,LEAVES:15)
Block(3,48,-7,LEAVES:15)
Block(4,48,-7,LEAVES:15)
Block(5,48,-7,LEAVES:15)
Block(6,48,-7,LEAVES:15)
Block(7,48,-7,LEAVES:15)
Block(8,48,-7,LEAVES:15)
Block(11,48,-7,LEAVES:15)
Block(-5,48,-6,LEAVES:15)
Block(-4,48,-6,LEAVES:15)
Block(-3,48,-6,LEAVES:15)
Block(0,48,-6,LEAVES:15)
Block(3,48,-6,LEAVES:15)
Block(4,48,-6,LEAVES:15)
Block(6,48,-6,LEAVES:15)
Block(7,48,-6,LEAVES:15)
Block(8,48,-6,LEAVES:15)
Block(10,48,-6,LEAVES:15)
Block(11,48,-6,LEAVES:15)
Block(-5,48,-5,LEAVES:15)
Block(-4,48,-5,LEAVES:15)
Block(-1,48,-5,LEAVES:15)
Block(0,48,-5,LEAVES:15)
Block(5,48,-5,LEAVES:15)
Block(6,48,-5,LEAVES:15)
Block(7,48,-5,LEAVES:15)
Block(9,48,-5,LEAVES:15)
Block(10,48,-5,LEAVES:15)
Block(-5,48,-4,LEAVES:15)
Block(-4,48,-4,LEAVES:15)
Block(-1,48,-4,LEAVES:15)
Block(5,48,-4,LEAVES:15)
Block(6,48,-4,LEAVES:15)
Block(8,48,-4,LEAVES:15)
Block(10,48,-4,LEAVES:15)
Block(11,48,-4,LEAVES:15)
Block(12,48,-4,LEAVES:15)
Block(13,48,-4,LEAVES:15)
Block(-2,48,-3,LEAVES:15)
Block(-1,48,-3,LEAVES:15)
Block(1,48,-3,LEAVES:15)
Block(2,48,-3,LEAVES:15)
Block(3,48,-3,LEAVES:15)
Block(4,48,-3,LEAVES:15)
Block(5,48,-3,LEAVES:15)
Block(8,48,-3,LEAVES:15)
Block(11,48,-3,LEAVES:15)
Block(-2,48,-2,LEAVES:15)
Block(-1,48,-2,LEAVES:15)
Block(1,48,-2,LEAVES:15)
Block(2,48,-2,LOG:15)
Block(3,48,-2,LEAVES:15)
Block(4,48,-2,LEAVES:15)
Block(5,48,-2,LEAVES:15)
Block(8,48,-2,LEAVES:15)
Block(9,48,-2,LEAVES:15)
Block(11,48,-2,LEAVES:15)
Block(8,48,-1,LEAVES:15)
Block(13,48,-1,LEAVES:15)
Block(0,48,0,LEAVES:15)
Block(1,48,0,LEAVES:15)
Block(4,48,0,LEAVES:15)
Block(7,48,0,LEAVES:15)
Block(8,48,0,LEAVES:15)
Block(-6,48,1,LEAVES:15)
Block(-5,48,1,LEAVES:15)
Block(-1,48,1,LOG:15)
Block(0,48,1,LOG:15)
Block(1,48,1,LEAVES:15)
Block(2,48,1,LEAVES:15)
Block(4,48,1,LEAVES:15)
Block(5,48,1,LOG:15)
Block(6,48,1,LOG:15)
Block(-6,48,2,LEAVES:15)
Block(-5,48,2,LEAVES:15)
Block(2,48,2,LEAVES:15)
Block(1,48,3,LEAVES:15)
Block(2,48,3,LEAVES:15)
Block(6,48,3,LEAVES:15)
Block(7,48,3,LEAVES:15)
Block(8,48,3,LEAVES:15)
Block(-8,48,4,LEAVES:15)
Block(-7,48,4,LEAVES:15)
Block(-5,48,4,LEAVES:15)
Block(-4,48,4,LEAVES:15)
Block(0,48,4,LEAVES:15)
Block(2,48,4,LEAVES:15)
Block(5,48,4,LEAVES:15)
Block(7,48,4,LEAVES:15)
Block(8,48,4,LEAVES:15)
Block(12,48,4,LEAVES:15)
Block(13,48,4,LEAVES:15)
Block(-5,48,5,LEAVES:15)
Block(-4,48,5,LEAVES:15)
Block(-3,48,5,LEAVES:15)
Block(-1,48,5,LEAVES:15)
Block(0,48,5,LEAVES:15)
Block(5,48,5,LEAVES:15)
Block(8,48,5,LEAVES:15)
Block(12,48,5,LEAVES:15)
Block(13,48,5,LEAVES:15)
Block(-5,48,6,LEAVES:15)
Block(-4,48,6,LEAVES:15)
Block(-3,48,6,LEAVES:15)
Block(-1,48,6,LEAVES:15)
Block(0,48,6,LEAVES:15)
Block(-6,48,7,LEAVES:15)
Block(-5,48,7,LEAVES:15)
Block(-4,48,7,LEAVES:15)
Block(-2,48,7,LEAVES:15)
Block(-1,48,7,LEAVES:15)
Block(0,48,7,LEAVES:15)
Block(-6,48,8,LEAVES:15)
Block(-5,48,8,LEAVES:15)
Block(-1,48,8,LEAVES:15)
Block(0,48,8,LEAVES:15)
Block(1,48,8,LEAVES:15)
Block(2,48,8,LEAVES:15)
Block(0,48,9,LEAVES:15)
Block(8,48,9,LEAVES:15)
Block(0,48,10,LEAVES:15)
Block(8,48,10,LEAVES:15)
Block(2,48,11,LEAVES:15)
Block(6,49,-11,LEAVES:15)
Block(7,49,-11,LEAVES:15)
Block(6,49,-10,LEAVES:15)
Block(7,49,-10,LEAVES:15)
Block(-2,49,-9,LEAVES:15)
Block(3,49,-9,LEAVES:15)
Block(3,49,-8,LEAVES:15)
Block(8,49,-8,LEAVES:15)
Block(9,49,-8,LEAVES:15)
Block(11,49,-8,LEAVES:15)
Block(12,49,-8,LEAVES:15)
Block(-2,49,-7,LEAVES:15)
Block(5,49,-7,LEAVES:15)
Block(8,49,-7,LEAVES:15)
Block(9,49,-7,LEAVES:15)
Block(11,49,-7,LEAVES:15)
Block(12,49,-7,LEAVES:15)
Block(-3,49,-6,LEAVES:15)
Block(-2,49,-6,LEAVES:15)
Block(3,49,-6,LEAVES:15)
Block(8,49,-6,LEAVES:15)
Block(-2,49,-5,LEAVES:15)
Block(-1,49,-5,LEAVES:15)
Block(2,49,-5,LEAVES:15)
Block(3,49,-5,LEAVES:15)
Block(6,49,-5,LEAVES:15)
Block(8,49,-5,LEAVES:15)
Block(13,49,-5,LEAVES:15)
Block(14,49,-5,LEAVES:15)
Block(-4,49,-4,LEAVES:15)
Block(0,49,-4,LOG:15)
Block(2,49,-4,LEAVES:15)
Block(6,49,-4,LEAVES:15)
Block(10,49,-4,LEAVES:15)
Block(13,49,-4,LEAVES:15)
Block(14,49,-4,LEAVES:15)
Block(-8,49,-3,LEAVES:15)
Block(-7,49,-3,LEAVES:15)
Block(-4,49,-3,LEAVES:15)
Block(-1,49,-3,LEAVES:15)
Block(1,49,-3,LOG:15)
Block(2,49,-3,LEAVES:15)
Block(3,49,-3,LEAVES:15)
Block(5,49,-3,LEAVES:15)
Block(6,49,-3,LEAVES:15)
Block(-8,49,-2,LEAVES:15)
Block(-7,49,-2,LEAVES:15)
Block(-6,49,-2,LEAVES:15)
Block(-3,49,-2,LEAVES:15)
Block(-2,49,-2,LEAVES:15)
Block(-1,49,-2,LEAVES:15)
Block(0,49,-2,LEAVES:15)
Block(2,49,-2,LEAVES:15)
Block(3,49,-2,LEAVES:15)
Block(5,49,-2,LEAVES:15)
Block(6,49,-2,LEAVES:15)
Block(11,49,-2,LEAVES:15)
Block(-3,49,-1,LEAVES:15)
Block(-2,49,-1,LEAVES:15)
Block(-1,49,-1,LEAVES:15)
Block(1,49,-1,LEAVES:15)
Block(2,49,-1,LEAVES:15)
Block(3,49,-1,LEAVES:15)
Block(5,49,-1,LEAVES:15)
Block(10,49,-1,LEAVES:15)
Block(11,49,-1,LEAVES:15)
Block(-9,49,0,LEAVES:15)
Block(-8,49,0,LEAVES:15)
Block(-5,49,0,LEAVES:15)
Block(-2,49,0,LEAVES:15)
Block(-1,49,0,LEAVES:15)
Block(2,49,0,LEAVES:15)
Block(3,49,0,LEAVES:15)
Block(4,49,0,LEAVES:15)
Block(7,49,0,LEAVES:15)
Block(10,49,0,LEAVES:15)
Block(11,49,0,LEAVES:15)
Block(-9,49,1,LEAVES:15)
Block(-8,49,1,LEAVES:15)
Block(-7,49,1,LEAVES:15)
Block(-5,49,1,LEAVES:15)
Block(2,49,1,LEAVES:15)
Block(6,49,1,LEAVES:15)
Block(7,49,1,LEAVES:15)
Block(-7,49,2,LEAVES:15)
Block(-2,49,2,LOG:15)
Block(6,49,2,LOG:15)
Block(-8,49,3,LEAVES:15)
Block(-7,49,3,LEAVES:15)
Block(-3,49,3,LEAVES:15)
Block(-2,49,3,LEAVES:15)
Block(-1,49,3,LEAVES:15)
Block(5,49,3,LEAVES:15)
Block(6,49,3,LEAVES:15)
Block(10,49,3,LEAVES:15)
Block(11,49,3,LEAVES:15)
Block(-7,49,4,LEAVES:15)
Block(-4,49,4,LEAVES:15)
Block(-2,49,4,LEAVES:15)
Block(-1,49,4,LEAVES:15)
Block(0,49,4,LEAVES:15)
Block(1,49,4,LEAVES:15)
Block(3,49,4,LEAVES:15)
Block(4,49,4,LEAVES:15)
Block(5,49,4,LEAVES:15)
Block(11,49,4,LEAVES:15)
Block(12,49,4,LEAVES:15)
Block(-4,49,5,LEAVES:15)
Block(-1,49,5,LEAVES:15)
Block(0,49,5,LEAVES:15)
Block(1,49,5,LEAVES:15)
Block(3,49,5,LEAVES:15)
Block(4,49,5,LEAVES:15)
Block(-3,49,6,LEAVES:15)
Block(7,49,6,LEAVES:15)
Block(8,49,6,LEAVES:15)
Block(-3,49,7,LEAVES:15)
Block(2,49,7,LEAVES:15)
Block(3,49,7,LEAVES:15)
Block(7,49,7,LEAVES:15)
Block(8,49,7,LEAVES:15)
Block(-1,49,8,LEAVES:15)
Block(2,49,8,LEAVES:15)
Block(3,49,8,LEAVES:15)
Block(0,49,10,LEAVES:15)
Block(0,49,11,LEAVES:15)
Block(-5,50,-8,LEAVES:15)
Block(-4,50,-8,LEAVES:15)
Block(0,50,-8,LEAVES:15)
Block(5,50,-8,LEAVES:15)
Block(-4,50,-7,LEAVES:15)
Block(-3,50,-7,LEAVES:15)
Block(0,50,-7,LEAVES:15)
Block(5,50,-7,LEAVES:15)
Block(-4,50,-6,LEAVES:15)
Block(-3,50,-6,LEAVES:15)
Block(-1,50,-6,LEAVES:15)
Block(0,50,-6,LEAVES:15)
Block(-6,50,-5,LEAVES:15)
Block(-5,50,-5,LEAVES:15)
Block(-4,50,-5,LEAVES:15)
Block(-2,50,-5,LEAVES:15)
Block(-1,50,-5,LEAVES:15)
Block(10,50,-5,LEAVES:15)
Block(-6,50,-4,LEAVES:15)
Block(-5,50,-4,LEAVES:15)
Block(-1,50,-4,LEAVES:15)
Block(0,50,-4,LEAVES:15)
Block(1,50,-4,LEAVES:15)
Block(2,50,-4,LEAVES:15)
Block(10,50,-4,LEAVES:15)
Block(-4,50,-3,LEAVES:15)
Block(-3,50,-3,LEAVES:15)
Block(0,50,-3,LEAVES:15)
Block(5,50,-3,LEAVES:15)
Block(-6,50,-2,LEAVES:15)
Block(-4,50,-2,LEAVES:15)
Block(-3,50,-2,LEAVES:15)
Block(0,50,-2,LEAVES:15)
Block(-6,50,-1,LEAVES:15)
Block(-4,50,-1,LEAVES:15)
Block(1,50,-1,LEAVES:15)
Block(2,50,-1,LEAVES:15)
Block(5,50,-1,LEAVES:15)
Block(-7,50,0,LEAVES:15)
Block(-6,50,0,LEAVES:15)
Block(-5,50,0,LEAVES:15)
Block(-2,50,0,LEAVES:15)
Block(1,50,0,LEAVES:15)
Block(2,50,0,LEAVES:15)
Block(4,50,0,LEAVES:15)
Block(5,50,0,LEAVES:15)
Block(10,50,0,LEAVES:15)
Block(-7,50,1,LEAVES:15)
Block(-3,50,1,LEAVES:15)
Block(-2,50,1,LEAVES:15)
Block(5,50,1,LEAVES:15)
Block(6,50,1,LEAVES:15)
Block(9,50,1,LEAVES:15)
Block(10,50,1,LEAVES:15)
Block(-3,50,2,LEAVES:15)
Block(-2,50,2,LOG:15)
Block(7,50,2,LOG:15)
Block(9,50,2,LEAVES:15)
Block(-4,50,3,LEAVES:15)
Block(-3,50,3,LEAVES:15)
Block(1,50,3,LEAVES:15)
Block(2,50,3,LEAVES:15)
Block(9,50,3,LEAVES:15)
Block(10,50,3,LEAVES:15)
Block(-4,50,4,LEAVES:15)
Block(2,50,4,LEAVES:15)
Block(3,50,4,LEAVES:15)
Block(4,50,4,LEAVES:15)
Block(5,50,4,LEAVES:15)
Block(9,50,4,LEAVES:15)
Block(4,50,5,LEAVES:15)
Block(5,50,5,LEAVES:15)
Block(8,50,5,LEAVES:15)
Block(9,50,5,LEAVES:15)
Block(-2,50,6,LEAVES:15)
Block(-1,50,6,LEAVES:15)
Block(9,50,6,LEAVES:15)
Block(-2,50,7,LEAVES:15)
Block(-1,50,7,LEAVES:15)
Block(-1,50,8,LEAVES:15)
Block(0,51,-8,LEAVES:15)
Block(1,51,-8,LEAVES:15)
Block(0,51,-7,LEAVES:15)
Block(1,51,-7,LEAVES:15)
Block(-3,51,-6,LEAVES:15)
Block(-3,51,-5,LEAVES:15)
Block(2,51,-5,LEAVES:15)
Block(3,51,-5,LEAVES:15)
Block(-1,51,-4,LEAVES:15)
Block(2,51,-4,LEAVES:15)
Block(3,51,-4,LEAVES:15)
Block(-4,51,-3,LEAVES:15)
Block(0,51,-2,LEAVES:15)
Block(2,51,-2,LEAVES:15)
Block(3,51,-2,LEAVES:15)
Block(7,51,-2,LEAVES:15)
Block(-4,51,-1,LEAVES:15)
Block(0,51,-1,LEAVES:15)
Block(3,51,-1,LEAVES:15)
Block(4,51,-1,LEAVES:15)
Block(7,51,-1,LEAVES:15)
Block(-5,51,0,LEAVES:15)
Block(-4,51,0,LEAVES:15)
Block(1,51,0,LEAVES:15)
Block(3,51,0,LEAVES:15)
Block(4,51,0,LEAVES:15)
Block(6,51,0,LEAVES:15)
Block(7,51,0,LEAVES:15)
Block(-4,51,1,LEAVES:15)
Block(-3,51,1,LEAVES:15)
Block(0,51,1,LEAVES:15)
Block(1,51,1,LEAVES:15)
Block(2,51,1,LEAVES:15)
Block(3,51,1,LEAVES:15)
Block(5,51,1,LEAVES:15)
Block(6,51,1,LEAVES:15)
Block(-2,51,2,LOG:15)
Block(0,51,2,LEAVES:15)
Block(1,51,2,LEAVES:15)
Block(2,51,2,LEAVES:15)
Block(6,51,2,LEAVES:15)
Block(7,51,2,LEAVES:15)
Block(8,51,2,LEAVES:15)
Block(9,51,2,LEAVES:15)
Block(0,51,3,LEAVES:15)
Block(1,51,3,LEAVES:15)
Block(7,51,3,LEAVES:15)
Block(-5,51,4,LEAVES:15)
Block(-4,51,4,LEAVES:15)
Block(0,51,4,LEAVES:15)
Block(7,51,4,LEAVES:15)
Block(-5,51,5,LEAVES:15)
Block(-4,51,5,LEAVES:15)
Block(-1,51,5,LEAVES:15)
Block(0,51,5,LEAVES:15)
Block(9,51,5,LEAVES:15)
Block(0,51,6,LEAVES:15)
Block(-1,52,-5,LEAVES:15)
Block(-1,52,-4,LEAVES:15)
Block(-7,52,-2,LEAVES:15)
Block(-6,52,-2,LEAVES:15)
Block(-2,52,-2,LEAVES:15)
Block(7,52,-2,LEAVES:15)
Block(8,52,-2,LEAVES:15)
Block(-6,52,-1,LEAVES:15)
Block(-5,52,-1,LEAVES:15)
Block(-2,52,-1,LEAVES:15)
Block(7,52,-1,LEAVES:15)
Block(8,52,-1,LEAVES:15)
Block(-6,52,0,LEAVES:15)
Block(-5,52,0,LEAVES:15)
Block(-3,52,0,LEAVES:15)
Block(-2,52,0,LEAVES:15)
Block(4,52,0,LEAVES:15)
Block(-8,52,1,LEAVES:15)
Block(-7,52,1,LEAVES:15)
Block(-6,52,1,LEAVES:15)
Block(-4,52,1,LEAVES:15)
Block(-3,52,1,LEAVES:15)
Block(4,52,1,LEAVES:15)
Block(9,52,1,LEAVES:15)
Block(10,52,1,LEAVES:15)
Block(-8,52,2,LEAVES:15)
Block(-7,52,2,LEAVES:15)
Block(-3,52,2,LEAVES:15)
Block(-2,52,2,LEAVES:15)
Block(-1,52,2,LEAVES:15)
Block(0,52,2,LEAVES:15)
Block(6,52,2,LEAVES:15)
Block(9,52,2,LEAVES:15)
Block(10,52,2,LEAVES:15)
Block(-2,52,3,LEAVES:15)
Block(-2,52,4,LEAVES:15)
Block(7,52,4,LEAVES:15)
Block(0,52,5,LEAVES:15)
Block(7,52,5,LEAVES:15)
Block(-2,53,-2,LEAVES:15)
Block(-1,53,-2,LEAVES:15)
Block(-2,53,-1,LEAVES:15)
Block(-1,53,-1,LEAVES:15)
Block(-5,53,0,LEAVES:15)
Block(-5,53,1,LEAVES:15)
Block(0,53,1,LEAVES:15)
Block(1,53,1,LEAVES:15)
Block(6,53,1,LEAVES:15)
Block(-3,53,2,LEAVES:15)
Block(0,53,2,LEAVES:15)
Block(1,53,2,LEAVES:15)
Block(6,53,2,LEAVES:15)
Block(-2,53,4,LEAVES:15)
Block(-2,53,5,LEAVES:15)
Block(-3,54,1,LEAVES:15)
Block(-3,54,2,LEAVES:15)

#######################################################################
# +-----------------------------------------------------------------+ #
# |                            BO3 checks                           | #
# +-----------------------------------------------------------------+ #
#######################################################################

# Require a condition at a certain location in order for the BO3 to be spawned.
# BlockCheck(x,y,z,BlockName[,BlockName[,...]]) - one of the blocks must be at the location
# BlockCheckNot(x,y,z,BlockName[,BlockName[,...]]) - all the blocks must not be at the location
# LightCheck(x,y,z,minLightLevel,maxLightLevel) - light must be between min and max (inclusive)

# You can use "Solid" as a BlockName for matching all solid blocks or "All" to match all blocks that aren't air.

# Examples:
BlockCheck(0,-1,0,GRASS,DIRT,DIRT:2,SAND,CLAY,STONE)
#   BlockCheck(0,-1,0,Solid)       Require any solid block just below the object
#   BlockCheck(0,-1,0,WOOL)        Require any type of wool just below the object
#   BlockCheck(0,-1,0,WOOL:0)      Require white wool just below the object
#   BlockCheckNot(0,-1,0,WOOL:0)   Require that there is no white wool below the object
#   LightCheck(0,0,0,0,1)          Require almost complete darkness just below the object

#######################################################################
# +-----------------------------------------------------------------+ #
# |                             Branches                            | #
# +-----------------------------------------------------------------+ #
#######################################################################

# Branches are objects that will spawn when this object spawns when it is used in
# the CustomStructure resource. Branches can also have branches, making complex
# structures possible. See the wiki for more details.

# Regular Branches spawn each branch with an independent chance of spawning.
# Branch(x,y,z,branchName,rotation,chance[,anotherBranchName,rotation,chance[,...]][IndividualChance])
# branchName - name of the object to spawn.
# rotation - NORTH, SOUTH, EAST or WEST.
# IndividualChance - The chance each branch has to spawn, assumed to be 100 when left blank

# Weighted Branches spawn branches with a dependent chance of spawning.
# WeightedBranch(x,y,z,branchName,rotation,chance[,anotherBranchName,rotation,chance[,...]][MaxChanceOutOf])
# MaxChanceOutOf - The chance all branches have to spawn out of, assumed to be 100 when left blank
