#######################################################################
# +-----------------------------------------------------------------+ #
# |                            BO3 object                           | #
# +-----------------------------------------------------------------+ #
#######################################################################

# This is the config file of a custom object.
# If you add this object correctly to your BiomeConfigs, it will spawn in the world.

# This is the creator of this BO3 object
Author: BO3 BulkEdit (by LanToaster)

# A short description of this BO3 object
Description: This Object was Created with BO3_BulkEdit

# The BO3 version, don't change this! It can be used by external applications to do a version check.
Version: 3

# The settings mode, WriteAll, WriteWithoutComments or WriteDisable. See WorldConfig.
SettingsMode: WriteDisable


#######################################################################
# +-----------------------------------------------------------------+ #
# |                          Main settings                          | #
# +-----------------------------------------------------------------+ #
#######################################################################

# This needs to be set to true to spawn the object in the Tree and Sapling resources.
Tree: true

# The frequency of the BO3 from 1 to 200. Tries this many times to spawn this BO3 when using the CustomObject(...) resource.
# Ignored by Tree(..), Sapling(..) and CustomStructure(..)
Frequency: 1

# The rarity of the BO3 from 0 to 100. Each spawn attempt has rarity% chance to succeed when using the CustomObject(...) resource.
# Ignored by Tree(..), Sapling(..) and CustomStructure(..)
Rarity: 100.0

# If you set this to true, the BO3 will be placed with a random rotation.
RotateRandomly: true

# The spawn height of the BO3 - randomY, highestBlock or highestSolidBlock.
SpawnHeight: highestSolidBlock
SpawnHeightOffset: -1
# The height limits for the BO3.
MinHeight: 0

MaxHeight: 72

# Objects can have other objects attacthed to it: branches. Branches can also
# have branches attached to it, which can also have branches, etc. This is the
# maximum branch depth for this objects.
MaxBranchDepth: 10

# When spawned with the UseWorld keyword, this BO3 should NOT spawn in the following biomes.
# If you writer.write the BO3 name directly in the BiomeConfigs, this will be ignored.
ExcludedBiomes: All


#######################################################################
# +-----------------------------------------------------------------+ #
# |                      Source block settings                      | #
# +-----------------------------------------------------------------+ #
#######################################################################

# The block(s) the BO3 should spawn in.
SourceBlocks: AIR,GRASS,DIRT,STATIONARY_WATER,FLOWING_WATER,SAND,CLAY

# The maximum percentage of the BO3 that can be outside the SourceBlock.
# The BO3 won't be placed on a location with more blocks outside the SourceBlock than this percentage.
MaxPercentageOutsideSourceBlock: 5

# What to do when a block is about to be placed outside the SourceBlock? (dontPlace, placeAnyway)
OutsideSourceBlock: placeAnyway


#######################################################################
# +-----------------------------------------------------------------+ #
# |                              Blocks                             | #
# +-----------------------------------------------------------------+ #
#######################################################################

# All the blocks used in the BO3 are listed here. Possible blocks:
# Block(x,y,z,id[.data][,nbtfile.nbt)
# RandomBlock(x,y,z,id[:data][,nbtfile.nbt],chance[,id[:data][,nbtfile.nbt],chance[,...]])
# So RandomBlock(0,0,0,CHEST,chest.nbt,50,CHEST,anotherchest.nbt,100) will spawn a chest at
# the BO3 origin, and give it a 50% chance to have the contents of chest.nbt, or, if that
# fails, a 100% percent chance to have the contents of anotherchest.nbt.
Block(1,0,-3,LOG:15)
Block(2,0,-3,LOG:15)
Block(3,0,-3,LOG:15)
Block(1,0,-2,LOG:15)
Block(2,0,-2,LOG:15)
Block(3,0,-2,LOG:15)
Block(2,0,-1,LOG:15)
Block(3,0,-1,LOG:15)
Block(2,1,-3,LOG:15)
Block(3,1,-3,LOG:15)
Block(1,1,-2,LOG:15)
Block(2,1,-2,LOG:15)
Block(3,1,-2,LOG:15)
Block(2,1,-1,LOG:15)
Block(3,1,-1,LOG:15)
Block(2,2,-3,LOG:15)
Block(3,2,-3,LOG:15)
Block(1,2,-2,LOG:15)
Block(2,2,-2,LOG:15)
Block(3,2,-2,LOG:15)
Block(2,2,-1,LOG:15)
Block(3,2,-1,LOG:15)
Block(2,3,-3,LOG:15)
Block(3,3,-3,LOG:15)
Block(1,3,-2,LOG:15)
Block(2,3,-2,LOG:15)
Block(3,3,-2,LOG:15)
Block(2,3,-1,LOG:15)
Block(3,3,-1,LOG:15)
Block(2,4,-3,LOG:15)
Block(3,4,-3,LOG:15)
Block(1,4,-2,LOG:15)
Block(2,4,-2,LOG:15)
Block(3,4,-2,LOG:15)
Block(-15,4,-1,LEAVES:15)
Block(2,4,-1,LOG:15)
Block(3,4,-1,LOG:15)
Block(2,5,-3,LOG:15)
Block(3,5,-3,LOG:15)
Block(1,5,-2,LOG:15)
Block(2,5,-2,LOG:15)
Block(3,5,-2,LOG:15)
Block(-15,5,-1,LEAVES:15)
Block(2,5,-1,LOG:15)
Block(3,5,-1,LOG:15)
Block(2,5,7,LEAVES:15)
Block(2,6,-3,LOG:15)
Block(3,6,-3,LOG:15)
Block(-11,6,-2,LEAVES:15)
Block(1,6,-2,LOG:15)
Block(2,6,-2,LOG:15)
Block(3,6,-2,LOG:15)
Block(-15,6,-1,LEAVES:15)
Block(2,6,-1,LOG:15)
Block(3,6,-1,LOG:15)
Block(2,6,7,LEAVES:15)
Block(2,7,-3,LOG:15)
Block(3,7,-3,LOG:15)
Block(-11,7,-2,LEAVES:15)
Block(1,7,-2,LOG:15)
Block(2,7,-2,LOG:15)
Block(3,7,-2,LOG:15)
Block(-15,7,-1,LEAVES:15)
Block(2,7,-1,LOG:15)
Block(3,7,-1,LOG:15)
Block(2,7,7,LEAVES:15)
Block(2,8,-3,LOG:15)
Block(3,8,-3,LOG:15)
Block(-11,8,-2,LEAVES:15)
Block(1,8,-2,LOG:15)
Block(2,8,-2,LOG:15)
Block(3,8,-2,LOG:15)
Block(11,8,-2,LEAVES:15)
Block(-15,8,-1,LEAVES:15)
Block(2,8,-1,LOG:15)
Block(3,8,-1,LOG:15)
Block(2,8,7,LEAVES:15)
Block(2,9,-3,LOG:15)
Block(3,9,-3,LOG:15)
Block(-11,9,-2,LEAVES:15)
Block(1,9,-2,LOG:15)
Block(2,9,-2,LOG:15)
Block(3,9,-2,LOG:15)
Block(11,9,-2,LEAVES:15)
Block(-15,9,-1,LEAVES:15)
Block(2,9,-1,LOG:15)
Block(3,9,-1,LOG:15)
Block(12,9,2,LEAVES:15)
Block(2,9,7,LEAVES:15)
Block(2,10,-3,LOG:15)
Block(3,10,-3,LOG:15)
Block(-11,10,-2,LEAVES:15)
Block(1,10,-2,LOG:15)
Block(2,10,-2,LOG:15)
Block(3,10,-2,LOG:15)
Block(11,10,-2,LEAVES:15)
Block(-15,10,-1,LEAVES:15)
Block(2,10,-1,LOG:15)
Block(3,10,-1,LOG:15)
Block(12,10,2,LEAVES:15)
Block(2,10,7,LEAVES:15)
Block(2,11,-3,LOG:15)
Block(-11,11,-2,LEAVES:15)
Block(1,11,-2,LOG:15)
Block(2,11,-2,LOG:15)
Block(3,11,-2,LOG:15)
Block(11,11,-2,LEAVES:15)
Block(-15,11,-1,LEAVES:15)
Block(-8,11,-1,LEAVES:15)
Block(2,11,-1,LOG:15)
Block(3,11,-1,LOG:15)
Block(12,11,2,LEAVES:15)
Block(2,11,7,LEAVES:15)
Block(2,12,-3,LOG:15)
Block(-11,12,-2,LEAVES:15)
Block(1,12,-2,LOG:15)
Block(2,12,-2,LOG:15)
Block(3,12,-2,LOG:15)
Block(11,12,-2,LEAVES:15)
Block(-15,12,-1,LEAVES:15)
Block(-8,12,-1,LEAVES:15)
Block(2,12,-1,LOG:15)
Block(3,12,-1,LOG:15)
Block(12,12,2,LEAVES:15)
Block(2,12,7,LEAVES:15)
Block(-8,12,9,LEAVES:15)
Block(2,13,-3,LOG:15)
Block(-11,13,-2,LEAVES:15)
Block(1,13,-2,LOG:15)
Block(2,13,-2,LOG:15)
Block(3,13,-2,LOG:15)
Block(11,13,-2,LEAVES:15)
Block(-15,13,-1,LEAVES:15)
Block(-8,13,-1,LEAVES:15)
Block(2,13,-1,LOG:15)
Block(3,13,-1,LOG:15)
Block(14,13,-1,LEAVES:15)
Block(12,13,0,LEAVES:15)
Block(12,13,2,LEAVES:15)
Block(2,13,7,LEAVES:15)
Block(-8,13,9,LEAVES:15)
Block(2,14,-3,LOG:15)
Block(-11,14,-2,LEAVES:15)
Block(1,14,-2,LOG:15)
Block(2,14,-2,LOG:15)
Block(3,14,-2,LOG:15)
Block(11,14,-2,LEAVES:15)
Block(-15,14,-1,LEAVES:15)
Block(-8,14,-1,LEAVES:15)
Block(2,14,-1,LOG:15)
Block(3,14,-1,LOG:15)
Block(14,14,-1,LEAVES:15)
Block(12,14,0,LEAVES:15)
Block(12,14,2,LEAVES:15)
Block(2,14,7,LEAVES:15)
Block(-8,14,9,LEAVES:15)
Block(2,15,-3,LOG:15)
Block(-11,15,-2,LEAVES:15)
Block(1,15,-2,LOG:15)
Block(2,15,-2,LOG:15)
Block(3,15,-2,LOG:15)
Block(11,15,-2,LEAVES:15)
Block(-15,15,-1,LEAVES:15)
Block(-8,15,-1,LEAVES:15)
Block(2,15,-1,LOG:15)
Block(3,15,-1,LOG:15)
Block(14,15,-1,LEAVES:15)
Block(12,15,0,LEAVES:15)
Block(12,15,2,LEAVES:15)
Block(2,15,7,LEAVES:15)
Block(-8,15,9,LEAVES:15)
Block(2,15,9,LEAVES:15)
Block(2,16,-3,LOG:15)
Block(-11,16,-2,LEAVES:15)
Block(1,16,-2,LOG:15)
Block(2,16,-2,LOG:15)
Block(3,16,-2,LOG:15)
Block(11,16,-2,LEAVES:15)
Block(-15,16,-1,LEAVES:15)
Block(-8,16,-1,LEAVES:15)
Block(2,16,-1,LOG:15)
Block(3,16,-1,LOG:15)
Block(14,16,-1,LEAVES:15)
Block(12,16,0,LEAVES:15)
Block(12,16,2,LEAVES:15)
Block(2,16,7,LEAVES:15)
Block(5,16,8,LEAVES:15)
Block(-8,16,9,LEAVES:15)
Block(2,16,9,LEAVES:15)
Block(2,17,-9,LEAVES:15)
Block(-13,17,-3,LEAVES:15)
Block(2,17,-3,LOG:15)
Block(-11,17,-2,LEAVES:15)
Block(1,17,-2,LOG:15)
Block(2,17,-2,LOG:15)
Block(3,17,-2,LOG:15)
Block(11,17,-2,LEAVES:15)
Block(-15,17,-1,LEAVES:15)
Block(-8,17,-1,LEAVES:15)
Block(1,17,-1,LOG:15)
Block(2,17,-1,LOG:15)
Block(3,17,-1,LOG:15)
Block(14,17,-1,LEAVES:15)
Block(4,17,0,LOG:15)
Block(12,17,0,LEAVES:15)
Block(-12,17,2,LEAVES:15)
Block(12,17,2,LEAVES:15)
Block(5,17,3,LEAVES:15)
Block(2,17,7,LEAVES:15)
Block(5,17,8,LEAVES:15)
Block(-8,17,9,LEAVES:15)
Block(2,17,9,LEAVES:15)
Block(-8,17,11,LEAVES:15)
Block(2,18,-9,LEAVES:15)
Block(-13,18,-3,LEAVES:15)
Block(2,18,-3,LOG:15)
Block(-11,18,-2,LEAVES:15)
Block(1,18,-2,LOG:15)
Block(2,18,-2,LOG:15)
Block(3,18,-2,LOG:15)
Block(11,18,-2,LEAVES:15)
Block(-15,18,-1,LEAVES:15)
Block(-8,18,-1,LEAVES:15)
Block(1,18,-1,LOG:15)
Block(2,18,-1,LOG:15)
Block(14,18,-1,LEAVES:15)
Block(4,18,0,LOG:15)
Block(12,18,0,LEAVES:15)
Block(5,18,1,LOG:15)
Block(-12,18,2,LEAVES:15)
Block(12,18,2,LEAVES:15)
Block(5,18,3,LEAVES:15)
Block(4,18,4,LEAVES:15)
Block(2,18,7,LEAVES:15)
Block(7,18,7,LEAVES:15)
Block(4,18,8,LEAVES:15)
Block(-8,18,9,LEAVES:15)
Block(2,18,9,LEAVES:15)
Block(-8,18,11,LEAVES:15)
Block(2,19,-9,LEAVES:15)
Block(-13,19,-3,LEAVES:15)
Block(2,19,-3,LOG:15)
Block(-11,19,-2,LEAVES:15)
Block(1,19,-2,LOG:15)
Block(2,19,-2,LOG:15)
Block(3,19,-2,LOG:15)
Block(11,19,-2,LEAVES:15)
Block(-15,19,-1,LEAVES:15)
Block(-8,19,-1,LEAVES:15)
Block(1,19,-1,LOG:15)
Block(2,19,-1,LOG:15)
Block(9,19,-1,LEAVES:15)
Block(10,19,-1,LEAVES:15)
Block(14,19,-1,LEAVES:15)
Block(9,19,0,LEAVES:15)
Block(10,19,0,LEAVES:15)
Block(12,19,0,LEAVES:15)
Block(5,19,1,LOG:15)
Block(13,19,1,LEAVES:15)
Block(-12,19,2,LEAVES:15)
Block(6,19,2,LOG:15)
Block(7,19,2,LOG:15)
Block(12,19,2,LEAVES:15)
Block(13,19,2,LEAVES:15)
Block(5,19,3,LEAVES:15)
Block(4,19,4,LEAVES:15)
Block(4,19,5,LEAVES:15)
Block(8,19,5,LEAVES:15)
Block(9,19,5,LEAVES:15)
Block(4,19,6,LEAVES:15)
Block(5,19,6,LEAVES:15)
Block(8,19,6,LEAVES:15)
Block(9,19,6,LEAVES:15)
Block(2,19,7,LEAVES:15)
Block(7,19,7,LEAVES:15)
Block(-8,19,8,LEAVES:15)
Block(5,19,8,LEAVES:15)
Block(6,19,8,LEAVES:15)
Block(7,19,8,LEAVES:15)
Block(-8,19,9,LEAVES:15)
Block(2,19,9,LEAVES:15)
Block(4,19,9,LEAVES:15)
Block(9,19,9,LEAVES:15)
Block(10,19,9,LEAVES:15)
Block(13,19,9,LEAVES:15)
Block(9,19,10,LEAVES:15)
Block(10,19,10,LEAVES:15)
Block(13,19,10,LEAVES:15)
Block(-8,19,11,LEAVES:15)
Block(13,19,11,LEAVES:15)
Block(14,19,11,LEAVES:15)
Block(13,19,12,LEAVES:15)
Block(14,19,12,LEAVES:15)
Block(2,20,-9,LEAVES:15)
Block(6,20,-6,LEAVES:15)
Block(7,20,-6,LEAVES:15)
Block(6,20,-5,LEAVES:15)
Block(7,20,-5,LEAVES:15)
Block(10,20,-4,LEAVES:15)
Block(-13,20,-3,LEAVES:15)
Block(2,20,-3,LOG:15)
Block(10,20,-3,LEAVES:15)
Block(-11,20,-2,LEAVES:15)
Block(1,20,-2,LOG:15)
Block(2,20,-2,LOG:15)
Block(3,20,-2,LOG:15)
Block(11,20,-2,LEAVES:15)
Block(-15,20,-1,LEAVES:15)
Block(-8,20,-1,LEAVES:15)
Block(1,20,-1,LOG:15)
Block(2,20,-1,LOG:15)
Block(14,20,-1,LEAVES:15)
Block(-10,20,0,LEAVES:15)
Block(5,20,0,LEAVES:15)
Block(6,20,0,LEAVES:15)
Block(10,20,0,LEAVES:15)
Block(12,20,0,LEAVES:15)
Block(5,20,1,LEAVES:15)
Block(6,20,1,LEAVES:15)
Block(7,20,1,LEAVES:15)
Block(10,20,1,LEAVES:15)
Block(13,20,1,LEAVES:15)
Block(-12,20,2,LEAVES:15)
Block(1,20,2,LEAVES:15)
Block(6,20,2,LEAVES:15)
Block(7,20,2,LOG:15)
Block(8,20,2,LEAVES:15)
Block(12,20,2,LEAVES:15)
Block(13,20,2,LEAVES:15)
Block(14,20,2,LEAVES:15)
Block(1,20,3,LEAVES:15)
Block(2,20,3,LEAVES:15)
Block(3,20,3,LEAVES:15)
Block(4,20,3,LEAVES:15)
Block(5,20,3,LEAVES:15)
Block(6,20,3,LOG:15)
Block(7,20,3,LOG:15)
Block(13,20,3,LEAVES:15)
Block(4,20,4,LEAVES:15)
Block(5,20,4,LEAVES:15)
Block(6,20,4,LOG:15)
Block(7,20,4,LEAVES:15)
Block(9,20,4,LEAVES:15)
Block(10,20,4,LEAVES:15)
Block(12,20,4,LEAVES:15)
Block(13,20,4,LEAVES:15)
Block(4,20,5,LEAVES:15)
Block(5,20,5,LEAVES:15)
Block(6,20,5,LEAVES:15)
Block(7,20,5,LEAVES:15)
Block(8,20,5,LEAVES:15)
Block(9,20,5,LEAVES:15)
Block(10,20,5,LEAVES:15)
Block(4,20,6,LEAVES:15)
Block(5,20,6,LEAVES:15)
Block(7,20,6,LEAVES:15)
Block(8,20,6,LEAVES:15)
Block(10,20,6,LEAVES:15)
Block(11,20,6,LEAVES:15)
Block(2,20,7,LEAVES:15)
Block(6,20,7,LEAVES:15)
Block(7,20,7,LEAVES:15)
Block(10,20,7,LEAVES:15)
Block(11,20,7,LEAVES:15)
Block(12,20,7,LEAVES:15)
Block(13,20,7,LEAVES:15)
Block(-8,20,8,LEAVES:15)
Block(4,20,8,LEAVES:15)
Block(5,20,8,LEAVES:15)
Block(7,20,8,LEAVES:15)
Block(10,20,8,LEAVES:15)
Block(12,20,8,LEAVES:15)
Block(13,20,8,LEAVES:15)
Block(-8,20,9,LEAVES:15)
Block(2,20,9,LEAVES:15)
Block(4,20,9,LEAVES:15)
Block(10,20,9,LEAVES:15)
Block(13,20,9,LEAVES:15)
Block(-8,20,11,LEAVES:15)
Block(2,21,-9,LEAVES:15)
Block(7,21,-5,LEAVES:15)
Block(3,21,-4,LEAVES:15)
Block(4,21,-4,LEAVES:15)
Block(7,21,-4,LEAVES:15)
Block(10,21,-4,LEAVES:15)
Block(-13,21,-3,LEAVES:15)
Block(2,21,-3,LOG:15)
Block(3,21,-3,LEAVES:15)
Block(4,21,-3,LEAVES:15)
Block(5,21,-3,LEAVES:15)
Block(10,21,-3,LEAVES:15)
Block(11,21,-3,LEAVES:15)
Block(-11,21,-2,LEAVES:15)
Block(1,21,-2,LOG:15)
Block(2,21,-2,LOG:15)
Block(3,21,-2,LOG:15)
Block(10,21,-2,LEAVES:15)
Block(11,21,-2,LEAVES:15)
Block(-15,21,-1,LEAVES:15)
Block(-8,21,-1,LEAVES:15)
Block(1,21,-1,LOG:15)
Block(2,21,-1,LOG:15)
Block(3,21,-1,LEAVES:15)
Block(6,21,-1,LEAVES:15)
Block(9,21,-1,LEAVES:15)
Block(10,21,-1,LEAVES:15)
Block(14,21,-1,LEAVES:15)
Block(-10,21,0,LEAVES:15)
Block(1,21,0,LEAVES:15)
Block(2,21,0,LEAVES:15)
Block(3,21,0,LEAVES:15)
Block(4,21,0,LEAVES:15)
Block(6,21,0,LEAVES:15)
Block(10,21,0,LEAVES:15)
Block(12,21,0,LEAVES:15)
Block(1,21,1,LEAVES:15)
Block(2,21,1,LEAVES:15)
Block(3,21,1,LEAVES:15)
Block(4,21,1,LEAVES:15)
Block(5,21,1,LEAVES:15)
Block(6,21,1,LEAVES:15)
Block(10,21,1,LEAVES:15)
Block(11,21,1,LEAVES:15)
Block(-12,21,2,LEAVES:15)
Block(0,21,2,LEAVES:15)
Block(1,21,2,LEAVES:15)
Block(2,21,2,LEAVES:15)
Block(3,21,2,LEAVES:15)
Block(4,21,2,LEAVES:15)
Block(7,21,2,LOG:15)
Block(8,21,2,LOG:15)
Block(9,21,2,LEAVES:15)
Block(10,21,2,LEAVES:15)
Block(11,21,2,LEAVES:15)
Block(12,21,2,LEAVES:15)
Block(0,21,3,LEAVES:15)
Block(1,21,3,LEAVES:15)
Block(2,21,3,LEAVES:15)
Block(3,21,3,LEAVES:15)
Block(4,21,3,LEAVES:15)
Block(7,21,3,LEAVES:15)
Block(8,21,3,LEAVES:15)
Block(9,21,3,LEAVES:15)
Block(10,21,3,LEAVES:15)
Block(14,21,3,LEAVES:15)
Block(15,21,3,LEAVES:15)
Block(-1,21,4,LEAVES:15)
Block(2,21,4,LEAVES:15)
Block(4,21,4,LEAVES:15)
Block(5,21,4,LEAVES:15)
Block(6,21,4,LOG:15)
Block(7,21,4,LEAVES:15)
Block(8,21,4,LOG:15)
Block(9,21,4,LEAVES:15)
Block(10,21,4,LEAVES:15)
Block(12,21,4,LEAVES:15)
Block(14,21,4,LEAVES:15)
Block(15,21,4,LEAVES:15)
Block(4,21,5,LEAVES:15)
Block(5,21,5,LEAVES:15)
Block(6,21,5,LOG:15)
Block(7,21,5,LEAVES:15)
Block(11,21,5,LEAVES:15)
Block(12,21,5,LEAVES:15)
Block(4,21,6,LEAVES:15)
Block(8,21,6,LEAVES:15)
Block(11,21,6,LEAVES:15)
Block(2,21,7,LEAVES:15)
Block(6,21,7,LEAVES:15)
Block(10,21,7,LEAVES:15)
Block(11,21,7,LEAVES:15)
Block(15,21,7,LEAVES:15)
Block(-8,21,8,LEAVES:15)
Block(0,21,8,LEAVES:15)
Block(1,21,8,LEAVES:15)
Block(4,21,8,LEAVES:15)
Block(5,21,8,LEAVES:15)
Block(10,21,8,LEAVES:15)
Block(-8,21,9,LEAVES:15)
Block(0,21,9,LEAVES:15)
Block(1,21,9,LEAVES:15)
Block(2,21,9,LEAVES:15)
Block(4,21,9,LEAVES:15)
Block(12,21,10,LEAVES:15)
Block(13,21,10,LEAVES:15)
Block(-8,21,11,LEAVES:15)
Block(-2,21,11,LEAVES:15)
Block(-1,21,11,LEAVES:15)
Block(12,21,11,LEAVES:15)
Block(13,21,11,LEAVES:15)
Block(1,21,12,LEAVES:15)
Block(2,21,12,LEAVES:15)
Block(5,21,12,LEAVES:15)
Block(1,21,13,LEAVES:15)
Block(2,21,13,LEAVES:15)
Block(5,21,13,LEAVES:15)
Block(5,21,14,LEAVES:15)
Block(6,21,14,LEAVES:15)
Block(5,21,15,LEAVES:15)
Block(6,21,15,LEAVES:15)
Block(-2,22,-13,LEAVES:15)
Block(2,22,-9,LEAVES:15)
Block(1,22,-7,LEAVES:15)
Block(7,22,-4,LEAVES:15)
Block(8,22,-4,LEAVES:15)
Block(-13,22,-3,LEAVES:15)
Block(2,22,-3,LOG:15)
Block(5,22,-3,LEAVES:15)
Block(7,22,-3,LEAVES:15)
Block(8,22,-3,LEAVES:15)
Block(-11,22,-2,LEAVES:15)
Block(1,22,-2,LOG:15)
Block(2,22,-2,LOG:15)
Block(3,22,-2,LOG:15)
Block(5,22,-2,LEAVES:15)
Block(7,22,-2,LEAVES:15)
Block(12,22,-2,LEAVES:15)
Block(13,22,-2,LEAVES:15)
Block(-15,22,-1,LEAVES:15)
Block(-8,22,-1,LEAVES:15)
Block(1,22,-1,LOG:15)
Block(2,22,-1,LOG:15)
Block(4,22,-1,LEAVES:15)
Block(5,22,-1,LEAVES:15)
Block(6,22,-1,LEAVES:15)
Block(9,22,-1,LEAVES:15)
Block(12,22,-1,LEAVES:15)
Block(13,22,-1,LEAVES:15)
Block(14,22,-1,LEAVES:15)
Block(-10,22,0,LEAVES:15)
Block(3,22,0,LEAVES:15)
Block(4,22,0,LEAVES:15)
Block(8,22,0,LEAVES:15)
Block(9,22,0,LEAVES:15)
Block(12,22,0,LEAVES:15)
Block(8,22,1,LOG:15)
Block(10,22,1,LEAVES:15)
Block(-12,22,2,LEAVES:15)
Block(1,22,2,LEAVES:15)
Block(7,22,2,LEAVES:15)
Block(8,22,2,LEAVES:15)
Block(12,22,2,LEAVES:15)
Block(13,22,2,LEAVES:15)
Block(2,22,3,LEAVES:15)
Block(3,22,3,LEAVES:15)
Block(7,22,3,LEAVES:15)
Block(8,22,3,LEAVES:15)
Block(10,22,3,LEAVES:15)
Block(13,22,3,LEAVES:15)
Block(14,22,3,LEAVES:15)
Block(-2,22,4,LEAVES:15)
Block(-1,22,4,LEAVES:15)
Block(1,22,4,LEAVES:15)
Block(2,22,4,LEAVES:15)
Block(3,22,4,LEAVES:15)
Block(4,22,4,LEAVES:15)
Block(5,22,4,LEAVES:15)
Block(6,22,4,LEAVES:15)
Block(7,22,4,LEAVES:15)
Block(9,22,4,LEAVES:15)
Block(10,22,4,LEAVES:15)
Block(15,22,4,LEAVES:15)
Block(-2,22,5,LEAVES:15)
Block(-1,22,5,LEAVES:15)
Block(0,22,5,LEAVES:15)
Block(2,22,5,LEAVES:15)
Block(3,22,5,LEAVES:15)
Block(4,22,5,LEAVES:15)
Block(5,22,5,LEAVES:15)
Block(6,22,5,LEAVES:15)
Block(7,22,5,LEAVES:15)
Block(9,22,5,LOG:15)
Block(10,22,5,LOG:15)
Block(11,22,5,LEAVES:15)
Block(14,22,5,LEAVES:15)
Block(15,22,5,LEAVES:15)
Block(4,22,6,LEAVES:15)
Block(5,22,6,LOG:15)
Block(8,22,6,LEAVES:15)
Block(9,22,6,LEAVES:15)
Block(10,22,6,LEAVES:15)
Block(11,22,6,LOG:15)
Block(12,22,6,LOG:15)
Block(14,22,6,LEAVES:15)
Block(-3,22,7,LEAVES:15)
Block(-2,22,7,LEAVES:15)
Block(1,22,7,LEAVES:15)
Block(2,22,7,LEAVES:15)
Block(4,22,7,LEAVES:15)
Block(5,22,7,LEAVES:15)
Block(6,22,7,LEAVES:15)
Block(14,22,7,LEAVES:15)
Block(15,22,7,LEAVES:15)
Block(-8,22,8,LEAVES:15)
Block(-3,22,8,LEAVES:15)
Block(-2,22,8,LEAVES:15)
Block(-1,22,8,LEAVES:15)
Block(1,22,8,LEAVES:15)
Block(4,22,8,LEAVES:15)
Block(5,22,8,LEAVES:15)
Block(9,22,8,LEAVES:15)
Block(10,22,8,LEAVES:15)
Block(14,22,8,LEAVES:15)
Block(-8,22,9,LEAVES:15)
Block(-1,22,9,LEAVES:15)
Block(2,22,9,LEAVES:15)
Block(4,22,9,LEAVES:15)
Block(9,22,9,LEAVES:15)
Block(10,22,9,LEAVES:15)
Block(13,22,9,LEAVES:15)
Block(14,22,9,LEAVES:15)
Block(-2,22,10,LEAVES:15)
Block(-1,22,10,LEAVES:15)
Block(3,22,10,LEAVES:15)
Block(4,22,10,LEAVES:15)
Block(5,22,10,LEAVES:15)
Block(14,22,10,LEAVES:15)
Block(-8,22,11,LEAVES:15)
Block(-1,22,11,LEAVES:15)
Block(2,22,11,LEAVES:15)
Block(4,22,11,LEAVES:15)
Block(5,22,11,LEAVES:15)
Block(9,22,11,LEAVES:15)
Block(10,22,11,LEAVES:15)
Block(2,22,12,LEAVES:15)
Block(5,22,12,LEAVES:15)
Block(9,22,12,LEAVES:15)
Block(10,22,12,LEAVES:15)
Block(-2,23,-13,LEAVES:15)
Block(0,23,-9,LEAVES:15)
Block(2,23,-9,LEAVES:15)
Block(1,23,-7,LEAVES:15)
Block(7,23,-4,LEAVES:15)
Block(-13,23,-3,LEAVES:15)
Block(2,23,-3,LOG:15)
Block(-11,23,-2,LEAVES:15)
Block(1,23,-2,LOG:15)
Block(2,23,-2,LOG:15)
Block(3,23,-2,LOG:15)
Block(7,23,-2,LEAVES:15)
Block(12,23,-2,LEAVES:15)
Block(-15,23,-1,LEAVES:15)
Block(-8,23,-1,LEAVES:15)
Block(1,23,-1,LOG:15)
Block(2,23,-1,LOG:15)
Block(6,23,-1,LEAVES:15)
Block(7,23,-1,LEAVES:15)
Block(8,23,-1,LEAVES:15)
Block(12,23,-1,LEAVES:15)
Block(13,23,-1,LEAVES:15)
Block(-10,23,0,LEAVES:15)
Block(7,23,0,LEAVES:15)
Block(8,23,0,LEAVES:15)
Block(9,23,0,LEAVES:15)
Block(11,23,0,LEAVES:15)
Block(12,23,0,LEAVES:15)
Block(9,23,1,LOG:15)
Block(11,23,1,LEAVES:15)
Block(-12,23,2,LEAVES:15)
Block(-10,23,2,LEAVES:15)
Block(7,23,2,LEAVES:15)
Block(8,23,2,LEAVES:15)
Block(11,23,2,LEAVES:15)
Block(12,23,2,LEAVES:15)
Block(2,23,3,LEAVES:15)
Block(6,23,3,LEAVES:15)
Block(7,23,3,LEAVES:15)
Block(8,23,3,LEAVES:15)
Block(9,23,3,LEAVES:15)
Block(11,23,3,LEAVES:15)
Block(12,23,3,LEAVES:15)
Block(-1,23,4,LEAVES:15)
Block(2,23,4,LEAVES:15)
Block(3,23,4,LEAVES:15)
Block(4,23,4,LEAVES:15)
Block(6,23,4,LEAVES:15)
Block(7,23,4,LEAVES:15)
Block(8,23,4,LEAVES:15)
Block(9,23,4,LEAVES:15)
Block(10,23,4,LEAVES:15)
Block(11,23,4,LEAVES:15)
Block(12,23,4,LEAVES:15)
Block(0,23,5,LEAVES:15)
Block(2,23,5,LEAVES:15)
Block(3,23,5,LEAVES:15)
Block(4,23,5,LEAVES:15)
Block(6,23,5,LEAVES:15)
Block(7,23,5,LEAVES:15)
Block(8,23,5,LEAVES:15)
Block(10,23,5,LEAVES:15)
Block(11,23,5,LEAVES:15)
Block(0,23,6,LEAVES:15)
Block(2,23,6,LEAVES:15)
Block(3,23,6,LEAVES:15)
Block(6,23,6,LEAVES:15)
Block(7,23,6,LEAVES:15)
Block(8,23,6,LEAVES:15)
Block(11,23,6,LEAVES:15)
Block(12,23,6,LEAVES:15)
Block(13,23,6,LEAVES:15)
Block(14,23,6,LEAVES:15)
Block(-1,23,7,LEAVES:15)
Block(0,23,7,LEAVES:15)
Block(1,23,7,LEAVES:15)
Block(2,23,7,LEAVES:15)
Block(4,23,7,LEAVES:15)
Block(5,23,7,LOG:15)
Block(7,23,7,LEAVES:15)
Block(8,23,7,LEAVES:15)
Block(12,23,7,LEAVES:15)
Block(-8,23,8,LEAVES:15)
Block(-1,23,8,LEAVES:15)
Block(3,23,8,LEAVES:15)
Block(4,23,8,LEAVES:15)
Block(5,23,8,LOG:15)
Block(12,23,8,LEAVES:15)
Block(-8,23,9,LEAVES:15)
Block(2,23,9,LEAVES:15)
Block(3,23,9,LEAVES:15)
Block(14,23,9,LEAVES:15)
Block(2,23,10,LEAVES:15)
Block(3,23,10,LEAVES:15)
Block(7,23,10,LEAVES:15)
Block(8,23,10,LEAVES:15)
Block(-8,23,11,LEAVES:15)
Block(2,23,11,LEAVES:15)
Block(8,23,11,LEAVES:15)
Block(9,23,11,LEAVES:15)
Block(4,23,13,LEAVES:15)
Block(5,23,13,LEAVES:15)
Block(4,23,14,LEAVES:15)
Block(5,23,14,LEAVES:15)
Block(-2,24,-13,LEAVES:15)
Block(0,24,-9,LEAVES:15)
Block(2,24,-9,LEAVES:15)
Block(1,24,-8,LEAVES:15)
Block(1,24,-7,LEAVES:15)
Block(-13,24,-3,LEAVES:15)
Block(2,24,-3,LOG:15)
Block(4,24,-3,LEAVES:15)
Block(5,24,-3,LEAVES:15)
Block(9,24,-3,LEAVES:15)
Block(-11,24,-2,LEAVES:15)
Block(1,24,-2,LOG:15)
Block(2,24,-2,LOG:15)
Block(3,24,-2,LOG:15)
Block(5,24,-2,LEAVES:15)
Block(6,24,-2,LEAVES:15)
Block(9,24,-2,LEAVES:15)
Block(-15,24,-1,LEAVES:15)
Block(-8,24,-1,LEAVES:15)
Block(1,24,-1,LOG:15)
Block(2,24,-1,LOG:15)
Block(5,24,-1,LEAVES:15)
Block(6,24,-1,LEAVES:15)
Block(7,24,-1,LEAVES:15)
Block(8,24,-1,LEAVES:15)
Block(9,24,-1,LEAVES:15)
Block(10,24,-1,LEAVES:15)
Block(-10,24,0,LEAVES:15)
Block(-8,24,0,LEAVES:15)
Block(3,24,0,LEAVES:15)
Block(4,24,0,LEAVES:15)
Block(5,24,0,LEAVES:15)
Block(7,24,0,LEAVES:15)
Block(8,24,0,LEAVES:15)
Block(9,24,0,LEAVES:15)
Block(3,24,1,LEAVES:15)
Block(4,24,1,LEAVES:15)
Block(8,24,1,LEAVES:15)
Block(9,24,1,LEAVES:15)
Block(10,24,1,LEAVES:15)
Block(11,24,1,LEAVES:15)
Block(-12,24,2,LEAVES:15)
Block(-10,24,2,LEAVES:15)
Block(9,24,2,LEAVES:15)
Block(11,24,2,LEAVES:15)
Block(12,24,2,LEAVES:15)
Block(13,24,2,LEAVES:15)
Block(9,24,3,LEAVES:15)
Block(12,24,3,LEAVES:15)
Block(13,24,3,LEAVES:15)
Block(2,24,4,LEAVES:15)
Block(9,24,4,LEAVES:15)
Block(11,24,4,LEAVES:15)
Block(3,24,5,LEAVES:15)
Block(9,24,5,LEAVES:15)
Block(14,24,5,LEAVES:15)
Block(15,24,5,LEAVES:15)
Block(2,24,6,LEAVES:15)
Block(11,24,6,LEAVES:15)
Block(14,24,6,LEAVES:15)
Block(15,24,6,LEAVES:15)
Block(1,24,7,LEAVES:15)
Block(2,24,7,LEAVES:15)
Block(7,24,7,LEAVES:15)
Block(-8,24,8,LEAVES:15)
Block(2,24,8,LEAVES:15)
Block(3,24,8,LEAVES:15)
Block(4,24,8,LEAVES:15)
Block(6,24,8,LEAVES:15)
Block(7,24,8,LEAVES:15)
Block(12,24,8,LEAVES:15)
Block(-8,24,9,LEAVES:15)
Block(4,24,9,LOG:15)
Block(6,24,9,LEAVES:15)
Block(12,24,9,LEAVES:15)
Block(6,24,10,LEAVES:15)
Block(7,24,10,LEAVES:15)
Block(-8,24,11,LEAVES:15)
Block(1,24,11,LEAVES:15)
Block(2,24,11,LEAVES:15)
Block(6,24,11,LEAVES:15)
Block(1,24,12,LEAVES:15)
Block(2,24,12,LEAVES:15)
Block(5,24,12,LEAVES:15)
Block(6,24,12,LEAVES:15)
Block(6,24,13,LEAVES:15)
Block(-2,25,-13,LEAVES:15)
Block(0,25,-9,LEAVES:15)
Block(2,25,-9,LEAVES:15)
Block(1,25,-8,LEAVES:15)
Block(1,25,-7,LEAVES:15)
Block(-13,25,-3,LEAVES:15)
Block(2,25,-3,LOG:15)
Block(9,25,-3,LEAVES:15)
Block(10,25,-3,LEAVES:15)
Block(-11,25,-2,LEAVES:15)
Block(1,25,-2,LOG:15)
Block(2,25,-2,LOG:15)
Block(9,25,-2,LEAVES:15)
Block(10,25,-2,LEAVES:15)
Block(-15,25,-1,LEAVES:15)
Block(-8,25,-1,LEAVES:15)
Block(1,25,-1,LOG:15)
Block(2,25,-1,LOG:15)
Block(6,25,-1,LEAVES:15)
Block(9,25,-1,LEAVES:15)
Block(-10,25,0,LEAVES:15)
Block(-8,25,0,LEAVES:15)
Block(6,25,0,LEAVES:15)
Block(11,25,0,LEAVES:15)
Block(12,25,0,LEAVES:15)
Block(7,25,1,LEAVES:15)
Block(8,25,1,LEAVES:15)
Block(11,25,1,LEAVES:15)
Block(12,25,1,LEAVES:15)
Block(-12,25,2,LEAVES:15)
Block(-10,25,2,LEAVES:15)
Block(8,25,2,LEAVES:15)
Block(12,25,2,LEAVES:15)
Block(9,25,3,LEAVES:15)
Block(9,25,4,LEAVES:15)
Block(-1,25,5,LEAVES:15)
Block(0,25,5,LEAVES:15)
Block(4,25,5,LEAVES:15)
Block(5,25,5,LEAVES:15)
Block(11,25,5,LEAVES:15)
Block(0,25,6,LEAVES:15)
Block(1,25,6,LEAVES:15)
Block(4,25,6,LEAVES:15)
Block(5,25,6,LEAVES:15)
Block(11,25,6,LEAVES:15)
Block(0,25,7,LEAVES:15)
Block(1,25,7,LEAVES:15)
Block(3,25,7,LEAVES:15)
Block(4,25,7,LEAVES:15)
Block(5,25,7,LEAVES:15)
Block(-8,25,8,LEAVES:15)
Block(-2,25,8,LEAVES:15)
Block(-1,25,8,LEAVES:15)
Block(0,25,8,LEAVES:15)
Block(2,25,8,LEAVES:15)
Block(3,25,8,LEAVES:15)
Block(-8,25,9,LEAVES:15)
Block(-2,25,9,LEAVES:15)
Block(-1,25,9,LEAVES:15)
Block(3,25,9,LEAVES:15)
Block(4,25,9,LEAVES:15)
Block(5,25,9,LEAVES:15)
Block(6,25,9,LEAVES:15)
Block(4,25,10,LEAVES:15)
Block(-8,25,11,LEAVES:15)
Block(4,25,11,LEAVES:15)
Block(6,25,12,LEAVES:15)
Block(-2,26,-13,LEAVES:15)
Block(0,26,-9,LEAVES:15)
Block(2,26,-9,LEAVES:15)
Block(1,26,-8,LEAVES:15)
Block(1,26,-7,LEAVES:15)
Block(-13,26,-3,LEAVES:15)
Block(2,26,-3,LOG:15)
Block(-11,26,-2,LEAVES:15)
Block(1,26,-2,LOG:15)
Block(2,26,-2,LOG:15)
Block(-15,26,-1,LEAVES:15)
Block(-8,26,-1,LEAVES:15)
Block(1,26,-1,LOG:15)
Block(2,26,-1,LOG:15)
Block(-10,26,0,LEAVES:15)
Block(-8,26,0,LEAVES:15)
Block(8,26,0,LEAVES:15)
Block(7,26,1,LEAVES:15)
Block(8,26,1,LEAVES:15)
Block(-12,26,2,LEAVES:15)
Block(-10,26,2,LEAVES:15)
Block(8,26,2,LEAVES:15)
Block(4,26,5,LEAVES:15)
Block(5,26,5,LEAVES:15)
Block(6,26,5,LEAVES:15)
Block(4,26,6,LEAVES:15)
Block(5,26,6,LEAVES:15)
Block(1,26,7,LEAVES:15)
Block(4,26,7,LEAVES:15)
Block(-8,26,8,LEAVES:15)
Block(1,26,8,LEAVES:15)
Block(6,26,8,LEAVES:15)
Block(7,26,8,LEAVES:15)
Block(-8,26,9,LEAVES:15)
Block(3,26,9,LEAVES:15)
Block(6,26,9,LEAVES:15)
Block(7,26,9,LEAVES:15)
Block(-8,26,11,LEAVES:15)
Block(4,26,11,LEAVES:15)
Block(4,26,12,LEAVES:15)
Block(-2,27,-13,LEAVES:15)
Block(1,27,-10,LEAVES:15)
Block(0,27,-9,LEAVES:15)
Block(2,27,-9,LEAVES:15)
Block(1,27,-8,LEAVES:15)
Block(1,27,-7,LEAVES:15)
Block(-13,27,-3,LEAVES:15)
Block(2,27,-3,LOG:15)
Block(-11,27,-2,LEAVES:15)
Block(1,27,-2,LOG:15)
Block(2,27,-2,LOG:15)
Block(-15,27,-1,LEAVES:15)
Block(-8,27,-1,LEAVES:15)
Block(1,27,-1,LOG:15)
Block(2,27,-1,LOG:15)
Block(-10,27,0,LEAVES:15)
Block(-8,27,0,LEAVES:15)
Block(-7,27,1,LEAVES:15)
Block(-12,27,2,LEAVES:15)
Block(-10,27,2,LEAVES:15)
Block(-8,27,8,LEAVES:15)
Block(3,27,8,LEAVES:15)
Block(-8,27,9,LEAVES:15)
Block(3,27,9,LEAVES:15)
Block(-8,27,11,LEAVES:15)
Block(-2,28,-13,LEAVES:15)
Block(1,28,-10,LEAVES:15)
Block(0,28,-9,LEAVES:15)
Block(2,28,-9,LEAVES:15)
Block(1,28,-8,LEAVES:15)
Block(1,28,-7,LEAVES:15)
Block(-13,28,-3,LEAVES:15)
Block(2,28,-3,LOG:15)
Block(-11,28,-2,LEAVES:15)
Block(1,28,-2,LOG:15)
Block(2,28,-2,LOG:15)
Block(-15,28,-1,LEAVES:15)
Block(-8,28,-1,LEAVES:15)
Block(1,28,-1,LOG:15)
Block(2,28,-1,LOG:15)
Block(3,28,-1,LOG:15)
Block(-11,28,0,LEAVES:15)
Block(-10,28,0,LEAVES:15)
Block(-8,28,0,LEAVES:15)
Block(-9,28,1,LEAVES:15)
Block(-7,28,1,LEAVES:15)
Block(-12,28,2,LEAVES:15)
Block(-10,28,2,LEAVES:15)
Block(-8,28,7,LEAVES:15)
Block(-8,28,8,LEAVES:15)
Block(-8,28,9,LEAVES:15)
Block(-8,28,11,LEAVES:15)
Block(0,29,-15,LEAVES:15)
Block(-2,29,-13,LEAVES:15)
Block(1,29,-10,LEAVES:15)
Block(0,29,-9,LEAVES:15)
Block(2,29,-9,LEAVES:15)
Block(1,29,-8,LEAVES:15)
Block(1,29,-7,LEAVES:15)
Block(-13,29,-3,LEAVES:15)
Block(2,29,-3,LOG:15)
Block(-11,29,-2,LEAVES:15)
Block(1,29,-2,LOG:15)
Block(2,29,-2,LOG:15)
Block(-15,29,-1,LEAVES:15)
Block(-8,29,-1,LEAVES:15)
Block(0,29,-1,LOG:15)
Block(1,29,-1,LOG:15)
Block(2,29,-1,LOG:15)
Block(3,29,-1,LOG:15)
Block(-11,29,0,LEAVES:15)
Block(-10,29,0,LEAVES:15)
Block(-8,29,0,LEAVES:15)
Block(-6,29,0,LEAVES:15)
Block(-9,29,1,LEAVES:15)
Block(-7,29,1,LEAVES:15)
Block(-12,29,2,LEAVES:15)
Block(-10,29,2,LEAVES:15)
Block(-8,29,3,LEAVES:15)
Block(-8,29,7,LEAVES:15)
Block(-8,29,8,LEAVES:15)
Block(-8,29,9,LEAVES:15)
Block(-8,29,11,LEAVES:15)
Block(0,30,-15,LEAVES:15)
Block(-2,30,-13,LEAVES:15)
Block(1,30,-10,LEAVES:15)
Block(0,30,-9,LEAVES:15)
Block(2,30,-9,LEAVES:15)
Block(1,30,-8,LEAVES:15)
Block(1,30,-7,LEAVES:15)
Block(-13,30,-3,LEAVES:15)
Block(2,30,-3,LOG:15)
Block(-11,30,-2,LEAVES:15)
Block(-10,30,-2,LEAVES:15)
Block(-9,30,-2,LEAVES:15)
Block(1,30,-2,LOG:15)
Block(2,30,-2,LOG:15)
Block(-15,30,-1,LEAVES:15)
Block(-10,30,-1,LEAVES:15)
Block(-9,30,-1,LEAVES:15)
Block(-8,30,-1,LEAVES:15)
Block(-1,30,-1,LOG:15)
Block(0,30,-1,LOG:15)
Block(1,30,-1,LOG:15)
Block(2,30,-1,LOG:15)
Block(3,30,-1,LOG:15)
Block(-11,30,0,LEAVES:15)
Block(-10,30,0,LEAVES:15)
Block(-8,30,0,LEAVES:15)
Block(-6,30,0,LEAVES:15)
Block(-5,30,0,LEAVES:15)
Block(-2,30,0,LOG:15)
Block(-1,30,0,LOG:15)
Block(4,30,0,LOG:15)
Block(-9,30,1,LEAVES:15)
Block(-7,30,1,LEAVES:15)
Block(-6,30,1,LEAVES:15)
Block(-2,30,1,LOG:15)
Block(-12,30,2,LEAVES:15)
Block(-10,30,2,LEAVES:15)
Block(-8,30,3,LEAVES:15)
Block(-11,30,4,LEAVES:15)
Block(-10,30,4,LEAVES:15)
Block(-11,30,5,LEAVES:15)
Block(-10,30,5,LEAVES:15)
Block(-13,30,7,LEAVES:15)
Block(-12,30,7,LEAVES:15)
Block(-8,30,7,LEAVES:15)
Block(-10,30,8,LEAVES:15)
Block(-9,30,8,LEAVES:15)
Block(-8,30,8,LEAVES:15)
Block(-6,30,8,LEAVES:15)
Block(-10,30,9,LEAVES:15)
Block(-9,30,9,LEAVES:15)
Block(-8,30,9,LEAVES:15)
Block(-6,30,9,LEAVES:15)
Block(-6,30,10,LEAVES:15)
Block(-5,30,10,LEAVES:15)
Block(-8,30,11,LEAVES:15)
Block(-6,30,11,LEAVES:15)
Block(-5,30,11,LEAVES:15)
Block(0,31,-15,LEAVES:15)
Block(-2,31,-13,LEAVES:15)
Block(1,31,-10,LEAVES:15)
Block(0,31,-9,LEAVES:15)
Block(2,31,-9,LEAVES:15)
Block(1,31,-8,LEAVES:15)
Block(1,31,-7,LEAVES:15)
Block(-13,31,-3,LEAVES:15)
Block(2,31,-3,LOG:15)
Block(3,31,-3,LOG:15)
Block(-11,31,-2,LEAVES:15)
Block(1,31,-2,LOG:15)
Block(2,31,-2,LOG:15)
Block(-15,31,-1,LEAVES:15)
Block(-10,31,-1,LEAVES:15)
Block(-9,31,-1,LEAVES:15)
Block(-8,31,-1,LEAVES:15)
Block(-6,31,-1,LEAVES:15)
Block(0,31,-1,LOG:15)
Block(1,31,-1,LOG:15)
Block(2,31,-1,LOG:15)
Block(3,31,-1,LOG:15)
Block(-13,31,0,LEAVES:15)
Block(-12,31,0,LEAVES:15)
Block(-11,31,0,LEAVES:15)
Block(-9,31,0,LEAVES:15)
Block(-8,31,0,LEAVES:15)
Block(-7,31,0,LEAVES:15)
Block(-6,31,0,LEAVES:15)
Block(-5,31,0,LEAVES:15)
Block(-2,31,0,LOG:15)
Block(-1,31,0,LOG:15)
Block(4,31,0,LOG:15)
Block(5,31,0,LOG:15)
Block(-13,31,1,LEAVES:15)
Block(-12,31,1,LEAVES:15)
Block(-11,31,1,LEAVES:15)
Block(-9,31,1,LEAVES:15)
Block(-7,31,1,LEAVES:15)
Block(-6,31,1,LEAVES:15)
Block(-5,31,1,LEAVES:15)
Block(-2,31,1,LOG:15)
Block(-12,31,2,LEAVES:15)
Block(-10,31,2,LEAVES:15)
Block(-7,31,2,LEAVES:15)
Block(-6,31,2,LEAVES:15)
Block(-5,31,2,LEAVES:15)
Block(-4,31,2,LOG:15)
Block(-3,31,2,LOG:15)
Block(-14,31,3,LEAVES:15)
Block(-13,31,3,LEAVES:15)
Block(-10,31,3,LEAVES:15)
Block(-8,31,3,LEAVES:15)
Block(-7,31,3,LEAVES:15)
Block(-6,31,3,LEAVES:15)
Block(-14,31,4,LEAVES:15)
Block(-13,31,4,LEAVES:15)
Block(-12,31,4,LEAVES:15)
Block(-10,31,4,LEAVES:15)
Block(-12,31,5,LEAVES:15)
Block(-13,31,6,LEAVES:15)
Block(-12,31,6,LEAVES:15)
Block(-8,31,6,LEAVES:15)
Block(-7,31,6,LEAVES:15)
Block(-6,31,6,LEAVES:15)
Block(-12,31,7,LEAVES:15)
Block(-9,31,7,LEAVES:15)
Block(-8,31,7,LEAVES:15)
Block(-7,31,7,LEAVES:15)
Block(-6,31,7,LEAVES:15)
Block(-2,31,7,LEAVES:15)
Block(-1,31,7,LEAVES:15)
Block(-9,31,8,LEAVES:15)
Block(-8,31,8,LEAVES:15)
Block(-6,31,8,LEAVES:15)
Block(-2,31,8,LEAVES:15)
Block(-1,31,8,LEAVES:15)
Block(-8,31,9,LEAVES:15)
Block(-8,31,11,LEAVES:15)
Block(-7,31,11,LEAVES:15)
Block(0,32,-15,LEAVES:15)
Block(-2,32,-13,LEAVES:15)
Block(1,32,-10,LEAVES:15)
Block(0,32,-9,LEAVES:15)
Block(2,32,-9,LEAVES:15)
Block(1,32,-8,LEAVES:15)
Block(1,32,-7,LEAVES:15)
Block(8,32,-5,LEAVES:15)
Block(8,32,-4,LEAVES:15)
Block(-14,32,-3,LEAVES:15)
Block(-13,32,-3,LEAVES:15)
Block(2,32,-3,LOG:15)
Block(3,32,-3,LOG:15)
Block(-11,32,-2,LEAVES:15)
Block(1,32,-2,LOG:15)
Block(2,32,-2,LOG:15)
Block(6,32,-2,LEAVES:15)
Block(-15,32,-1,LEAVES:15)
Block(2,32,-1,LOG:15)
Block(8,32,-1,LEAVES:15)
Block(-9,32,0,LEAVES:15)
Block(-8,32,0,LEAVES:15)
Block(-7,32,0,LEAVES:15)
Block(-6,32,0,LEAVES:15)
Block(3,32,0,LOG:15)
Block(4,32,0,LOG:15)
Block(5,32,0,LOG:15)
Block(8,32,0,LEAVES:15)
Block(9,32,0,LEAVES:15)
Block(-11,32,1,LEAVES:15)
Block(-9,32,1,LEAVES:15)
Block(-8,32,1,LEAVES:15)
Block(-7,32,1,LEAVES:15)
Block(-6,32,1,LEAVES:15)
Block(-5,32,1,LOG:15)
Block(-2,32,1,LOG:15)
Block(-12,32,2,LEAVES:15)
Block(-11,32,2,LEAVES:15)
Block(-10,32,2,LEAVES:15)
Block(-9,32,2,LEAVES:15)
Block(-8,32,2,LEAVES:15)
Block(-6,32,2,LEAVES:15)
Block(-4,32,2,LOG:15)
Block(-3,32,2,LOG:15)
Block(-12,32,3,LEAVES:15)
Block(-11,32,3,LEAVES:15)
Block(-10,32,3,LEAVES:15)
Block(-8,32,3,LEAVES:15)
Block(-7,32,3,LEAVES:15)
Block(-5,32,3,LOG:15)
Block(-4,32,3,LOG:15)
Block(-3,32,3,LEAVES:15)
Block(-12,32,4,LEAVES:15)
Block(-8,32,4,LEAVES:15)
Block(-7,32,4,LEAVES:15)
Block(-8,32,5,LEAVES:15)
Block(-9,32,6,LEAVES:15)
Block(-8,32,6,LEAVES:15)
Block(-4,32,6,LEAVES:15)
Block(-3,32,6,LEAVES:15)
Block(-9,32,7,LEAVES:15)
Block(-8,32,7,LEAVES:15)
Block(-3,32,7,LEAVES:15)
Block(-2,32,7,LEAVES:15)
Block(-8,32,8,LEAVES:15)
Block(-8,32,9,LEAVES:15)
Block(-7,32,9,LEAVES:15)
Block(-6,32,9,LEAVES:15)
Block(-7,32,10,LEAVES:15)
Block(-6,32,10,LEAVES:15)
Block(-8,32,11,LEAVES:15)
Block(-7,32,11,LEAVES:15)
Block(0,33,-15,LEAVES:15)
Block(-2,33,-13,LEAVES:15)
Block(-12,33,-11,LEAVES:15)
Block(-11,33,-11,LEAVES:15)
Block(8,33,-11,LEAVES:15)
Block(9,33,-11,LEAVES:15)
Block(-12,33,-10,LEAVES:15)
Block(-11,33,-10,LEAVES:15)
Block(1,33,-10,LEAVES:15)
Block(8,33,-10,LEAVES:15)
Block(9,33,-10,LEAVES:15)
Block(-8,33,-9,LEAVES:15)
Block(0,33,-9,LEAVES:15)
Block(2,33,-9,LEAVES:15)
Block(12,33,-9,LEAVES:15)
Block(-8,33,-8,LEAVES:15)
Block(1,33,-8,LEAVES:15)
Block(12,33,-8,LEAVES:15)
Block(1,33,-7,LEAVES:15)
Block(4,33,-6,LEAVES:15)
Block(8,33,-6,LEAVES:15)
Block(-13,33,-5,LEAVES:15)
Block(-12,33,-5,LEAVES:15)
Block(7,33,-5,LEAVES:15)
Block(8,33,-5,LEAVES:15)
Block(9,33,-5,LEAVES:15)
Block(-13,33,-4,LEAVES:15)
Block(-12,33,-4,LEAVES:15)
Block(3,33,-4,LOG:15)
Block(6,33,-4,LEAVES:15)
Block(7,33,-4,LEAVES:15)
Block(8,33,-4,LEAVES:15)
Block(10,33,-4,LEAVES:15)
Block(-14,33,-3,LEAVES:15)
Block(-13,33,-3,LEAVES:15)
Block(2,33,-3,LOG:15)
Block(3,33,-3,LOG:15)
Block(4,33,-3,LOG:15)
Block(-15,33,-2,LEAVES:15)
Block(-14,33,-2,LEAVES:15)
Block(-12,33,-2,LEAVES:15)
Block(-11,33,-2,LEAVES:15)
Block(-8,33,-2,LEAVES:15)
Block(-3,33,-2,LEAVES:15)
Block(1,33,-2,LOG:15)
Block(2,33,-2,LOG:15)
Block(4,33,-2,LEAVES:15)
Block(5,33,-2,LEAVES:15)
Block(6,33,-2,LEAVES:15)
Block(7,33,-2,LEAVES:15)
Block(11,33,-2,LEAVES:15)
Block(-15,33,-1,LEAVES:15)
Block(-14,33,-1,LEAVES:15)
Block(-12,33,-1,LEAVES:15)
Block(-11,33,-1,LEAVES:15)
Block(-9,33,-1,LEAVES:15)
Block(-8,33,-1,LEAVES:15)
Block(-3,33,-1,LEAVES:15)
Block(2,33,-1,LOG:15)
Block(5,33,-1,LEAVES:15)
Block(6,33,-1,LEAVES:15)
Block(8,33,-1,LEAVES:15)
Block(9,33,-1,LEAVES:15)
Block(10,33,-1,LEAVES:15)
Block(12,33,-1,LEAVES:15)
Block(-12,33,0,LEAVES:15)
Block(-11,33,0,LEAVES:15)
Block(-9,33,0,LEAVES:15)
Block(-8,33,0,LEAVES:15)
Block(5,33,0,LOG:15)
Block(6,33,0,LOG:15)
Block(7,33,0,LEAVES:15)
Block(8,33,0,LEAVES:15)
Block(9,33,0,LEAVES:15)
Block(10,33,0,LEAVES:15)
Block(12,33,0,LEAVES:15)
Block(-8,33,1,LEAVES:15)
Block(-7,33,1,LOG:15)
Block(-6,33,1,LOG:15)
Block(-5,33,1,LOG:15)
Block(5,33,1,LOG:15)
Block(8,33,1,LEAVES:15)
Block(12,33,1,LEAVES:15)
Block(13,33,1,LEAVES:15)
Block(-10,33,2,LEAVES:15)
Block(-9,33,2,LEAVES:15)
Block(-8,33,2,LEAVES:15)
Block(-7,33,2,LEAVES:15)
Block(12,33,2,LEAVES:15)
Block(13,33,2,LEAVES:15)
Block(-10,33,3,LEAVES:15)
Block(-9,33,3,LEAVES:15)
Block(-8,33,3,LEAVES:15)
Block(-4,33,3,LOG:15)
Block(-9,33,4,LEAVES:15)
Block(-8,33,4,LEAVES:15)
Block(-6,33,4,LOG:15)
Block(-5,33,4,LOG:15)
Block(-4,33,4,LOG:15)
Block(-7,33,5,LOG:15)
Block(-6,33,5,LEAVES:15)
Block(-5,33,5,LEAVES:15)
Block(-5,33,6,LEAVES:15)
Block(-4,33,6,LEAVES:15)
Block(-10,33,7,LEAVES:15)
Block(-9,33,7,LEAVES:15)
Block(-8,33,7,LEAVES:15)
Block(-5,33,7,LEAVES:15)
Block(-10,33,8,LEAVES:15)
Block(-9,33,8,LEAVES:15)
Block(-8,33,8,LEAVES:15)
Block(-6,33,8,LEAVES:15)
Block(-5,33,8,LEAVES:15)
Block(-8,33,9,LEAVES:15)
Block(-6,33,9,LEAVES:15)
Block(-5,33,9,LEAVES:15)
Block(-6,33,10,LEAVES:15)
Block(-8,33,11,LEAVES:15)
Block(-7,33,11,LEAVES:15)
Block(0,34,-15,LEAVES:15)
Block(-2,34,-13,LEAVES:15)
Block(-11,34,-10,LEAVES:15)
Block(1,34,-10,LEAVES:15)
Block(9,34,-10,LEAVES:15)
Block(-15,34,-9,LEAVES:15)
Block(-14,34,-9,LEAVES:15)
Block(-11,34,-9,LEAVES:15)
Block(-8,34,-9,LEAVES:15)
Block(0,34,-9,LEAVES:15)
Block(2,34,-9,LEAVES:15)
Block(5,34,-9,LEAVES:15)
Block(6,34,-9,LEAVES:15)
Block(9,34,-9,LEAVES:15)
Block(12,34,-9,LEAVES:15)
Block(-15,34,-8,LEAVES:15)
Block(-14,34,-8,LEAVES:15)
Block(-13,34,-8,LEAVES:15)
Block(-8,34,-8,LEAVES:15)
Block(-7,34,-8,LEAVES:15)
Block(1,34,-8,LEAVES:15)
Block(5,34,-8,LEAVES:15)
Block(6,34,-8,LEAVES:15)
Block(7,34,-8,LEAVES:15)
Block(12,34,-8,LEAVES:15)
Block(13,34,-8,LEAVES:15)
Block(-8,34,-7,LEAVES:15)
Block(1,34,-7,LEAVES:15)
Block(4,34,-7,LEAVES:15)
Block(12,34,-7,LEAVES:15)
Block(-15,34,-6,LEAVES:15)
Block(-12,34,-6,LEAVES:15)
Block(-9,34,-6,LEAVES:15)
Block(-8,34,-6,LEAVES:15)
Block(3,34,-6,LEAVES:15)
Block(4,34,-6,LEAVES:15)
Block(5,34,-6,LEAVES:15)
Block(8,34,-6,LEAVES:15)
Block(11,34,-6,LEAVES:15)
Block(12,34,-6,LEAVES:15)
Block(-15,34,-5,LEAVES:15)
Block(-14,34,-5,LEAVES:15)
Block(-12,34,-5,LEAVES:15)
Block(-9,34,-5,LEAVES:15)
Block(4,34,-5,LEAVES:15)
Block(5,34,-5,LEAVES:15)
Block(6,34,-5,LEAVES:15)
Block(7,34,-5,LEAVES:15)
Block(8,34,-5,LEAVES:15)
Block(10,34,-5,LEAVES:15)
Block(-14,34,-4,LEAVES:15)
Block(-10,34,-4,LEAVES:15)
Block(4,34,-4,LOG:15)
Block(5,34,-4,LEAVES:15)
Block(6,34,-4,LEAVES:15)
Block(7,34,-4,LEAVES:15)
Block(8,34,-4,LEAVES:15)
Block(9,34,-4,LEAVES:15)
Block(10,34,-4,LEAVES:15)
Block(11,34,-4,LEAVES:15)
Block(-15,34,-3,LEAVES:15)
Block(-14,34,-3,LEAVES:15)
Block(-10,34,-3,LEAVES:15)
Block(-9,34,-3,LEAVES:15)
Block(-8,34,-3,LEAVES:15)
Block(-6,34,-3,LEAVES:15)
Block(-5,34,-3,LEAVES:15)
Block(-4,34,-3,LEAVES:15)
Block(3,34,-3,LOG:15)
Block(4,34,-3,LOG:15)
Block(5,34,-3,LEAVES:15)
Block(6,34,-3,LEAVES:15)
Block(9,34,-3,LEAVES:15)
Block(10,34,-3,LEAVES:15)
Block(11,34,-3,LEAVES:15)
Block(12,34,-3,LEAVES:15)
Block(-14,34,-2,LEAVES:15)
Block(-12,34,-2,LEAVES:15)
Block(-11,34,-2,LEAVES:15)
Block(-10,34,-2,LEAVES:15)
Block(-9,34,-2,LEAVES:15)
Block(-8,34,-2,LEAVES:15)
Block(-7,34,-2,LEAVES:15)
Block(-4,34,-2,LEAVES:15)
Block(-3,34,-2,LEAVES:15)
Block(5,34,-2,LEAVES:15)
Block(6,34,-2,LEAVES:15)
Block(8,34,-2,LOG:15)
Block(9,34,-2,LEAVES:15)
Block(10,34,-2,LEAVES:15)
Block(11,34,-2,LEAVES:15)
Block(12,34,-2,LEAVES:15)
Block(13,34,-2,LEAVES:15)
Block(-12,34,-1,LEAVES:15)
Block(-11,34,-1,LEAVES:15)
Block(-8,34,-1,LOG:15)
Block(-4,34,-1,LEAVES:15)
Block(-3,34,-1,LEAVES:15)
Block(7,34,-1,LOG:15)
Block(9,34,-1,LEAVES:15)
Block(11,34,-1,LEAVES:15)
Block(12,34,-1,LEAVES:15)
Block(13,34,-1,LEAVES:15)
Block(-8,34,0,LOG:15)
Block(7,34,0,LOG:15)
Block(-12,34,1,LEAVES:15)
Block(-11,34,1,LEAVES:15)
Block(-10,34,1,LEAVES:15)
Block(-7,34,1,LOG:15)
Block(-6,34,1,LOG:15)
Block(-11,34,2,LEAVES:15)
Block(-10,34,2,LEAVES:15)
Block(-7,34,2,LEAVES:15)
Block(5,34,2,LOG:15)
Block(8,34,2,LEAVES:15)
Block(9,34,2,LEAVES:15)
Block(-11,34,3,LEAVES:15)
Block(-10,34,3,LEAVES:15)
Block(-9,34,3,LEAVES:15)
Block(-8,34,3,LEAVES:15)
Block(-7,34,3,LEAVES:15)
Block(8,34,3,LEAVES:15)
Block(9,34,3,LEAVES:15)
Block(-13,34,4,LEAVES:15)
Block(-12,34,4,LEAVES:15)
Block(-11,34,4,LEAVES:15)
Block(-9,34,4,LEAVES:15)
Block(-8,34,4,LEAVES:15)
Block(-4,34,4,LOG:15)
Block(-13,34,5,LEAVES:15)
Block(-12,34,5,LEAVES:15)
Block(-8,34,5,LEAVES:15)
Block(-7,34,5,LEAVES:15)
Block(-6,34,5,LEAVES:15)
Block(-5,34,5,LEAVES:15)
Block(6,34,5,LEAVES:15)
Block(7,34,5,LEAVES:15)
Block(-7,34,6,LEAVES:15)
Block(9,34,6,LEAVES:15)
Block(10,34,6,LEAVES:15)
Block(13,34,6,LEAVES:15)
Block(-8,34,7,LEAVES:15)
Block(-7,34,7,LEAVES:15)
Block(9,34,7,LEAVES:15)
Block(10,34,7,LEAVES:15)
Block(13,34,7,LEAVES:15)
Block(-8,34,8,LEAVES:15)
Block(-5,34,8,LEAVES:15)
Block(13,34,8,LEAVES:15)
Block(14,34,8,LEAVES:15)
Block(-8,34,9,LEAVES:15)
Block(-6,34,9,LEAVES:15)
Block(13,34,9,LEAVES:15)
Block(14,34,9,LEAVES:15)
Block(-6,34,10,LEAVES:15)
Block(-8,34,11,LEAVES:15)
Block(-7,34,11,LEAVES:15)
Block(0,35,-15,LEAVES:15)
Block(-2,35,-13,LEAVES:15)
Block(1,35,-10,LEAVES:15)
Block(-11,35,-9,LEAVES:15)
Block(-10,35,-9,LEAVES:15)
Block(0,35,-9,LEAVES:15)
Block(2,35,-9,LEAVES:15)
Block(9,35,-9,LEAVES:15)
Block(10,35,-9,LEAVES:15)
Block(-13,35,-8,LEAVES:15)
Block(-11,35,-8,LEAVES:15)
Block(-10,35,-8,LEAVES:15)
Block(1,35,-8,LEAVES:15)
Block(7,35,-8,LEAVES:15)
Block(9,35,-8,LEAVES:15)
Block(10,35,-8,LEAVES:15)
Block(-13,35,-7,LEAVES:15)
Block(-12,35,-7,LEAVES:15)
Block(-11,35,-7,LEAVES:15)
Block(-6,35,-7,LEAVES:15)
Block(-5,35,-7,LEAVES:15)
Block(1,35,-7,LEAVES:15)
Block(7,35,-7,LEAVES:15)
Block(9,35,-7,LEAVES:15)
Block(14,35,-7,LEAVES:15)
Block(15,35,-7,LEAVES:15)
Block(-14,35,-6,LEAVES:15)
Block(-13,35,-6,LEAVES:15)
Block(-12,35,-6,LEAVES:15)
Block(-9,35,-6,LEAVES:15)
Block(-6,35,-6,LEAVES:15)
Block(-5,35,-6,LEAVES:15)
Block(4,35,-6,LEAVES:15)
Block(6,35,-6,LEAVES:15)
Block(7,35,-6,LEAVES:15)
Block(8,35,-6,LEAVES:15)
Block(11,35,-6,LEAVES:15)
Block(14,35,-6,LEAVES:15)
Block(15,35,-6,LEAVES:15)
Block(-14,35,-5,LEAVES:15)
Block(-10,35,-5,LEAVES:15)
Block(-9,35,-5,LEAVES:15)
Block(-8,35,-5,LEAVES:15)
Block(6,35,-5,LEAVES:15)
Block(10,35,-5,LEAVES:15)
Block(11,35,-5,LEAVES:15)
Block(-10,35,-4,LEAVES:15)
Block(-9,35,-4,LEAVES:15)
Block(4,35,-4,LOG:15)
Block(6,35,-4,LEAVES:15)
Block(10,35,-4,LEAVES:15)
Block(11,35,-4,LEAVES:15)
Block(-11,35,-3,LEAVES:15)
Block(-10,35,-3,LEAVES:15)
Block(-9,35,-3,LEAVES:15)
Block(-8,35,-3,LOG:15)
Block(-6,35,-3,LEAVES:15)
Block(-5,35,-3,LEAVES:15)
Block(-4,35,-3,LEAVES:15)
Block(4,35,-3,LOG:15)
Block(5,35,-3,LEAVES:15)
Block(7,35,-3,LEAVES:15)
Block(9,35,-3,LOG:15)
Block(10,35,-3,LEAVES:15)
Block(11,35,-3,LEAVES:15)
Block(14,35,-3,LEAVES:15)
Block(15,35,-3,LEAVES:15)
Block(-11,35,-2,LEAVES:15)
Block(-9,35,-2,LEAVES:15)
Block(-8,35,-2,LOG:15)
Block(-6,35,-2,LEAVES:15)
Block(-5,35,-2,LEAVES:15)
Block(-4,35,-2,LEAVES:15)
Block(3,35,-2,LEAVES:15)
Block(6,35,-2,LEAVES:15)
Block(7,35,-2,LEAVES:15)
Block(8,35,-2,LEAVES:15)
Block(9,35,-2,LOG:15)
Block(10,35,-2,LEAVES:15)
Block(11,35,-2,LEAVES:15)
Block(13,35,-2,LEAVES:15)
Block(15,35,-2,LEAVES:15)
Block(-14,35,-1,LEAVES:15)
Block(-13,35,-1,LEAVES:15)
Block(-3,35,-1,LEAVES:15)
Block(3,35,-1,LEAVES:15)
Block(5,35,-1,LEAVES:15)
Block(6,35,-1,LEAVES:15)
Block(7,35,-1,LEAVES:15)
Block(8,35,-1,LEAVES:15)
Block(13,35,-1,LEAVES:15)
Block(14,35,-1,LEAVES:15)
Block(-14,35,0,LEAVES:15)
Block(-13,35,0,LEAVES:15)
Block(-10,35,0,LEAVES:15)
Block(-9,35,0,LEAVES:15)
Block(-8,35,0,LEAVES:15)
Block(-7,35,0,LEAVES:15)
Block(-6,35,0,LEAVES:15)
Block(6,35,0,LEAVES:15)
Block(8,35,0,LOG:15)
Block(9,35,0,LOG:15)
Block(11,35,0,LEAVES:15)
Block(12,35,0,LEAVES:15)
Block(13,35,0,LEAVES:15)
Block(-9,35,1,LEAVES:15)
Block(-8,35,1,LEAVES:15)
Block(-7,35,1,LOG:15)
Block(-6,35,1,LEAVES:15)
Block(5,35,1,LEAVES:15)
Block(6,35,1,LEAVES:15)
Block(9,35,1,LEAVES:15)
Block(11,35,1,LEAVES:15)
Block(12,35,1,LEAVES:15)
Block(13,35,1,LEAVES:15)
Block(-15,35,2,LEAVES:15)
Block(-8,35,2,LEAVES:15)
Block(-7,35,2,LEAVES:15)
Block(-6,35,2,LEAVES:15)
Block(5,35,2,LOG:15)
Block(6,35,2,LEAVES:15)
Block(7,35,2,LEAVES:15)
Block(9,35,2,LEAVES:15)
Block(-13,35,3,LEAVES:15)
Block(-12,35,3,LEAVES:15)
Block(-10,35,3,LEAVES:15)
Block(-9,35,3,LEAVES:15)
Block(5,35,3,LOG:15)
Block(7,35,3,LEAVES:15)
Block(-13,35,4,LEAVES:15)
Block(-12,35,4,LEAVES:15)
Block(-10,35,4,LEAVES:15)
Block(-9,35,4,LEAVES:15)
Block(-5,35,4,LEAVES:15)
Block(-4,35,4,LEAVES:15)
Block(6,35,4,LEAVES:15)
Block(7,35,4,LEAVES:15)
Block(11,35,4,LEAVES:15)
Block(12,35,4,LEAVES:15)
Block(13,35,4,LEAVES:15)
Block(-9,35,5,LEAVES:15)
Block(-8,35,5,LEAVES:15)
Block(-5,35,5,LEAVES:15)
Block(-4,35,5,LOG:15)
Block(7,35,5,LEAVES:15)
Block(10,35,5,LEAVES:15)
Block(12,35,5,LEAVES:15)
Block(13,35,5,LEAVES:15)
Block(-9,35,6,LEAVES:15)
Block(-8,35,6,LEAVES:15)
Block(10,35,6,LEAVES:15)
Block(13,35,6,LEAVES:15)
Block(-8,35,7,LEAVES:15)
Block(-7,35,7,LEAVES:15)
Block(-8,35,8,LEAVES:15)
Block(-7,35,8,LEAVES:15)
Block(-8,35,9,LEAVES:15)
Block(-6,35,9,LEAVES:15)
Block(-10,35,10,LEAVES:15)
Block(-6,35,10,LEAVES:15)
Block(-8,35,11,LEAVES:15)
Block(-7,35,11,LEAVES:15)
Block(0,36,-15,LEAVES:15)
Block(-2,36,-13,LEAVES:15)
Block(1,36,-13,LEAVES:15)
Block(1,36,-10,LEAVES:15)
Block(-11,36,-9,LEAVES:15)
Block(0,36,-9,LEAVES:15)
Block(2,36,-9,LEAVES:15)
Block(9,36,-9,LEAVES:15)
Block(1,36,-8,LEAVES:15)
Block(2,36,-8,LEAVES:15)
Block(-11,36,-7,LEAVES:15)
Block(1,36,-7,LEAVES:15)
Block(9,36,-7,LEAVES:15)
Block(-12,36,-6,LEAVES:15)
Block(-11,36,-6,LEAVES:15)
Block(-6,36,-6,LEAVES:15)
Block(8,36,-6,LEAVES:15)
Block(9,36,-6,LEAVES:15)
Block(14,36,-6,LEAVES:15)
Block(-15,36,-5,LEAVES:15)
Block(-12,36,-5,LEAVES:15)
Block(-11,36,-5,LEAVES:15)
Block(-10,36,-5,LEAVES:15)
Block(-9,36,-5,LEAVES:15)
Block(-8,36,-5,LEAVES:15)
Block(-7,36,-5,LEAVES:15)
Block(-6,36,-5,LEAVES:15)
Block(6,36,-5,LEAVES:15)
Block(9,36,-5,LEAVES:15)
Block(10,36,-5,LEAVES:15)
Block(13,36,-5,LEAVES:15)
Block(14,36,-5,LEAVES:15)
Block(-15,36,-4,LEAVES:15)
Block(-14,36,-4,LEAVES:15)
Block(-9,36,-4,LOG:15)
Block(-8,36,-4,LEAVES:15)
Block(-7,36,-4,LEAVES:15)
Block(-6,36,-4,LEAVES:15)
Block(4,36,-4,LOG:15)
Block(10,36,-4,LEAVES:15)
Block(11,36,-4,LOG:15)
Block(13,36,-4,LEAVES:15)
Block(-9,36,-3,LOG:15)
Block(-7,36,-3,LEAVES:15)
Block(-6,36,-3,LEAVES:15)
Block(-5,36,-3,LEAVES:15)
Block(2,36,-3,LEAVES:15)
Block(4,36,-3,LOG:15)
Block(5,36,-3,LOG:15)
Block(9,36,-3,LEAVES:15)
Block(10,36,-3,LOG:15)
Block(13,36,-3,LEAVES:15)
Block(14,36,-3,LEAVES:15)
Block(-13,36,-2,LEAVES:15)
Block(-12,36,-2,LEAVES:15)
Block(-11,36,-2,LEAVES:15)
Block(-10,36,-2,LEAVES:15)
Block(-9,36,-2,LEAVES:15)
Block(-8,36,-2,LEAVES:15)
Block(-7,36,-2,LEAVES:15)
Block(2,36,-2,LEAVES:15)
Block(3,36,-2,LEAVES:15)
Block(7,36,-2,LEAVES:15)
Block(8,36,-2,LEAVES:15)
Block(9,36,-2,LEAVES:15)
Block(10,36,-2,LEAVES:15)
Block(11,36,-2,LEAVES:15)
Block(13,36,-2,LEAVES:15)
Block(-15,36,-1,LEAVES:15)
Block(-13,36,-1,LEAVES:15)
Block(-12,36,-1,LEAVES:15)
Block(-11,36,-1,LEAVES:15)
Block(-9,36,-1,LEAVES:15)
Block(-8,36,-1,LEAVES:15)
Block(-7,36,-1,LEAVES:15)
Block(2,36,-1,LEAVES:15)
Block(3,36,-1,LEAVES:15)
Block(4,36,-1,LEAVES:15)
Block(8,36,-1,LEAVES:15)
Block(9,36,-1,LEAVES:15)
Block(10,36,-1,LEAVES:15)
Block(11,36,-1,LEAVES:15)
Block(12,36,-1,LEAVES:15)
Block(13,36,-1,LEAVES:15)
Block(-15,36,0,LEAVES:15)
Block(-9,36,0,LOG:15)
Block(-8,36,0,LOG:15)
Block(-7,36,0,LEAVES:15)
Block(6,36,0,LEAVES:15)
Block(8,36,0,LEAVES:15)
Block(10,36,0,LEAVES:15)
Block(13,36,0,LEAVES:15)
Block(15,36,0,LEAVES:15)
Block(-15,36,1,LEAVES:15)
Block(-11,36,1,LEAVES:15)
Block(-10,36,1,LEAVES:15)
Block(-9,36,1,LEAVES:15)
Block(-6,36,1,LEAVES:15)
Block(-5,36,1,LEAVES:15)
Block(1,36,1,LEAVES:15)
Block(6,36,1,LEAVES:15)
Block(7,36,1,LEAVES:15)
Block(8,36,1,LEAVES:15)
Block(9,36,1,LOG:15)
Block(10,36,1,LOG:15)
Block(12,36,1,LEAVES:15)
Block(15,36,1,LEAVES:15)
Block(-15,36,2,LEAVES:15)
Block(-12,36,2,LEAVES:15)
Block(-10,36,2,LEAVES:15)
Block(-9,36,2,LEAVES:15)
Block(-7,36,2,LEAVES:15)
Block(-6,36,2,LEAVES:15)
Block(-5,36,2,LEAVES:15)
Block(-4,36,2,LEAVES:15)
Block(7,36,2,LEAVES:15)
Block(10,36,2,LOG:15)
Block(11,36,2,LEAVES:15)
Block(12,36,2,LEAVES:15)
Block(-12,36,3,LEAVES:15)
Block(-9,36,3,LEAVES:15)
Block(-5,36,3,LEAVES:15)
Block(-4,36,3,LEAVES:15)
Block(-2,36,3,LEAVES:15)
Block(5,36,3,LOG:15)
Block(11,36,3,LEAVES:15)
Block(-8,36,4,LEAVES:15)
Block(-2,36,4,LEAVES:15)
Block(1,36,4,LEAVES:15)
Block(2,36,4,LEAVES:15)
Block(10,36,4,LEAVES:15)
Block(11,36,4,LEAVES:15)
Block(15,36,4,LEAVES:15)
Block(-8,36,5,LEAVES:15)
Block(-4,36,5,LOG:15)
Block(1,36,5,LEAVES:15)
Block(2,36,5,LEAVES:15)
Block(10,36,5,LEAVES:15)
Block(-4,36,6,LOG:15)
Block(-8,36,7,LEAVES:15)
Block(-7,36,7,LEAVES:15)
Block(-6,36,7,LEAVES:15)
Block(-1,36,7,LEAVES:15)
Block(0,36,7,LEAVES:15)
Block(12,36,7,LEAVES:15)
Block(13,36,7,LEAVES:15)
Block(-7,36,8,LEAVES:15)
Block(-6,36,8,LEAVES:15)
Block(2,36,8,LEAVES:15)
Block(3,36,8,LEAVES:15)
Block(6,36,8,LEAVES:15)
Block(12,36,8,LEAVES:15)
Block(13,36,8,LEAVES:15)
Block(-8,36,9,LEAVES:15)
Block(-6,36,9,LEAVES:15)
Block(2,36,9,LEAVES:15)
Block(3,36,9,LEAVES:15)
Block(6,36,9,LEAVES:15)
Block(-10,36,10,LEAVES:15)
Block(-9,36,10,LEAVES:15)
Block(-8,36,10,LEAVES:15)
Block(-6,36,10,LEAVES:15)
Block(6,36,10,LEAVES:15)
Block(7,36,10,LEAVES:15)
Block(-8,36,11,LEAVES:15)
Block(-7,36,11,LEAVES:15)
Block(-6,36,11,LEAVES:15)
Block(-5,36,11,LEAVES:15)
Block(-2,36,11,LEAVES:15)
Block(6,36,11,LEAVES:15)
Block(7,36,11,LEAVES:15)
Block(-6,36,12,LEAVES:15)
Block(-5,36,12,LEAVES:15)
Block(-2,36,12,LEAVES:15)
Block(-2,36,13,LEAVES:15)
Block(-1,36,13,LEAVES:15)
Block(-2,36,14,LEAVES:15)
Block(-1,36,14,LEAVES:15)
Block(0,37,-15,LEAVES:15)
Block(-2,37,-13,LEAVES:15)
Block(1,37,-13,LEAVES:15)
Block(1,37,-10,LEAVES:15)
Block(0,37,-9,LEAVES:15)
Block(2,37,-9,LEAVES:15)
Block(-14,37,-8,LEAVES:15)
Block(-13,37,-8,LEAVES:15)
Block(-9,37,-8,LEAVES:15)
Block(1,37,-8,LEAVES:15)
Block(2,37,-8,LEAVES:15)
Block(6,37,-8,LEAVES:15)
Block(7,37,-8,LEAVES:15)
Block(11,37,-8,LEAVES:15)
Block(-13,37,-7,LEAVES:15)
Block(-12,37,-7,LEAVES:15)
Block(-9,37,-7,LEAVES:15)
Block(1,37,-7,LEAVES:15)
Block(7,37,-7,LEAVES:15)
Block(8,37,-7,LEAVES:15)
Block(11,37,-7,LEAVES:15)
Block(-13,37,-6,LEAVES:15)
Block(-12,37,-6,LEAVES:15)
Block(-10,37,-6,LEAVES:15)
Block(-9,37,-6,LEAVES:15)
Block(7,37,-6,LEAVES:15)
Block(8,37,-6,LEAVES:15)
Block(10,37,-6,LEAVES:15)
Block(11,37,-6,LEAVES:15)
Block(-15,37,-5,LEAVES:15)
Block(-14,37,-5,LEAVES:15)
Block(-13,37,-5,LEAVES:15)
Block(-12,37,-5,LEAVES:15)
Block(-11,37,-5,LEAVES:15)
Block(-10,37,-5,LEAVES:15)
Block(4,37,-5,LOG:15)
Block(5,37,-5,LEAVES:15)
Block(6,37,-5,LEAVES:15)
Block(7,37,-5,LEAVES:15)
Block(9,37,-5,LEAVES:15)
Block(10,37,-5,LEAVES:15)
Block(-15,37,-4,LEAVES:15)
Block(-14,37,-4,LEAVES:15)
Block(-12,37,-4,LEAVES:15)
Block(-11,37,-4,LEAVES:15)
Block(-10,37,-4,LEAVES:15)
Block(-9,37,-4,LEAVES:15)
Block(-8,37,-4,LEAVES:15)
Block(-7,37,-4,LEAVES:15)
Block(5,37,-4,LEAVES:15)
Block(6,37,-4,LOG:15)
Block(10,37,-4,LEAVES:15)
Block(11,37,-4,LEAVES:15)
Block(12,37,-4,LEAVES:15)
Block(13,37,-4,LEAVES:15)
Block(-14,37,-3,LEAVES:15)
Block(-12,37,-3,LEAVES:15)
Block(-9,37,-3,LEAVES:15)
Block(-8,37,-3,LEAVES:15)
Block(-7,37,-3,LEAVES:15)
Block(-6,37,-3,LEAVES:15)
Block(11,37,-3,LEAVES:15)
Block(-15,37,-2,LEAVES:15)
Block(-14,37,-2,LEAVES:15)
Block(-13,37,-2,LEAVES:15)
Block(-10,37,-2,LEAVES:15)
Block(-9,37,-2,LEAVES:15)
Block(-7,37,-2,LEAVES:15)
Block(-6,37,-2,LEAVES:15)
Block(2,37,-2,LEAVES:15)
Block(3,37,-2,LEAVES:15)
Block(4,37,-2,LOG:15)
Block(9,37,-2,LEAVES:15)
Block(10,37,-2,LEAVES:15)
Block(11,37,-2,LEAVES:15)
Block(-15,37,-1,LEAVES:15)
Block(-11,37,-1,LEAVES:15)
Block(-10,37,-1,LEAVES:15)
Block(-7,37,-1,LEAVES:15)
Block(0,37,-1,LEAVES:15)
Block(3,37,-1,LEAVES:15)
Block(13,37,-1,LEAVES:15)
Block(-11,37,0,LEAVES:15)
Block(-9,37,0,LOG:15)
Block(-2,37,0,LEAVES:15)
Block(-1,37,0,LEAVES:15)
Block(0,37,0,LEAVES:15)
Block(2,37,0,LEAVES:15)
Block(3,37,0,LEAVES:15)
Block(4,37,0,LEAVES:15)
Block(6,37,0,LEAVES:15)
Block(10,37,0,LEAVES:15)
Block(-12,37,1,LEAVES:15)
Block(-11,37,1,LEAVES:15)
Block(-7,37,1,LEAVES:15)
Block(-6,37,1,LEAVES:15)
Block(-1,37,1,LEAVES:15)
Block(0,37,1,LEAVES:15)
Block(1,37,1,LEAVES:15)
Block(2,37,1,LEAVES:15)
Block(3,37,1,LEAVES:15)
Block(6,37,1,LEAVES:15)
Block(7,37,1,LEAVES:15)
Block(9,37,1,LEAVES:15)
Block(10,37,1,LEAVES:15)
Block(15,37,1,LEAVES:15)
Block(-12,37,2,LEAVES:15)
Block(-7,37,2,LEAVES:15)
Block(-6,37,2,LEAVES:15)
Block(-5,37,2,LEAVES:15)
Block(6,37,2,LEAVES:15)
Block(10,37,2,LEAVES:15)
Block(11,37,2,LOG:15)
Block(14,37,2,LEAVES:15)
Block(15,37,2,LEAVES:15)
Block(-9,37,3,LEAVES:15)
Block(-8,37,3,LEAVES:15)
Block(-5,37,3,LEAVES:15)
Block(-2,37,3,LEAVES:15)
Block(-1,37,3,LEAVES:15)
Block(2,37,3,LEAVES:15)
Block(5,37,3,LEAVES:15)
Block(6,37,3,LEAVES:15)
Block(12,37,3,LOG:15)
Block(14,37,3,LEAVES:15)
Block(-10,37,4,LEAVES:15)
Block(-9,37,4,LEAVES:15)
Block(-8,37,4,LEAVES:15)
Block(-7,37,4,LEAVES:15)
Block(-2,37,4,LEAVES:15)
Block(-1,37,4,LEAVES:15)
Block(0,37,4,LEAVES:15)
Block(2,37,4,LEAVES:15)
Block(5,37,4,LOG:15)
Block(14,37,4,LEAVES:15)
Block(15,37,4,LEAVES:15)
Block(-10,37,5,LEAVES:15)
Block(-9,37,5,LEAVES:15)
Block(-2,37,5,LEAVES:15)
Block(0,37,5,LEAVES:15)
Block(9,37,5,LEAVES:15)
Block(10,37,5,LEAVES:15)
Block(14,37,5,LEAVES:15)
Block(-10,37,6,LEAVES:15)
Block(-9,37,6,LEAVES:15)
Block(-6,37,6,LEAVES:15)
Block(-3,37,6,LOG:15)
Block(-2,37,6,LEAVES:15)
Block(-1,37,6,LEAVES:15)
Block(0,37,6,LEAVES:15)
Block(4,37,6,LEAVES:15)
Block(5,37,6,LEAVES:15)
Block(6,37,6,LEAVES:15)
Block(9,37,6,LEAVES:15)
Block(10,37,6,LEAVES:15)
Block(13,37,6,LEAVES:15)
Block(14,37,6,LEAVES:15)
Block(-10,37,7,LEAVES:15)
Block(-9,37,7,LEAVES:15)
Block(-8,37,7,LEAVES:15)
Block(-6,37,7,LEAVES:15)
Block(0,37,7,LEAVES:15)
Block(3,37,7,LEAVES:15)
Block(5,37,7,LEAVES:15)
Block(6,37,7,LEAVES:15)
Block(10,37,7,LEAVES:15)
Block(11,37,7,LEAVES:15)
Block(14,37,7,LEAVES:15)
Block(-8,37,8,LEAVES:15)
Block(3,37,8,LEAVES:15)
Block(6,37,8,LEAVES:15)
Block(10,37,8,LEAVES:15)
Block(11,37,8,LEAVES:15)
Block(-9,37,9,LEAVES:15)
Block(-8,37,9,LEAVES:15)
Block(-4,37,9,LEAVES:15)
Block(-3,37,9,LEAVES:15)
Block(-2,37,9,LEAVES:15)
Block(-9,37,10,LEAVES:15)
Block(-8,37,10,LEAVES:15)
Block(-6,37,10,LEAVES:15)
Block(-5,37,10,LEAVES:15)
Block(-3,37,10,LEAVES:15)
Block(-2,37,10,LEAVES:15)
Block(2,37,10,LEAVES:15)
Block(3,37,10,LEAVES:15)
Block(-6,37,11,LEAVES:15)
Block(-5,37,11,LEAVES:15)
Block(-2,37,11,LEAVES:15)
Block(2,37,11,LEAVES:15)
Block(3,37,11,LEAVES:15)
Block(0,38,-15,LEAVES:15)
Block(-2,38,-13,LEAVES:15)
Block(1,38,-13,LEAVES:15)
Block(1,38,-10,LEAVES:15)
Block(0,38,-9,LEAVES:15)
Block(2,38,-9,LEAVES:15)
Block(-9,38,-8,LEAVES:15)
Block(-8,38,-8,LEAVES:15)
Block(1,38,-8,LEAVES:15)
Block(2,38,-8,LEAVES:15)
Block(11,38,-8,LEAVES:15)
Block(12,38,-8,LEAVES:15)
Block(-9,38,-7,LEAVES:15)
Block(-8,38,-7,LEAVES:15)
Block(1,38,-7,LEAVES:15)
Block(11,38,-7,LEAVES:15)
Block(12,38,-7,LEAVES:15)
Block(-12,38,-6,LEAVES:15)
Block(3,38,-6,LOG:15)
Block(8,38,-6,LEAVES:15)
Block(-12,38,-5,LEAVES:15)
Block(-7,38,-5,LEAVES:15)
Block(-6,38,-5,LEAVES:15)
Block(3,38,-5,LOG:15)
Block(8,38,-5,LEAVES:15)
Block(13,38,-5,LEAVES:15)
Block(14,38,-5,LEAVES:15)
Block(-10,38,-4,LEAVES:15)
Block(-7,38,-4,LEAVES:15)
Block(-6,38,-4,LEAVES:15)
Block(7,38,-4,LOG:15)
Block(10,38,-4,LEAVES:15)
Block(13,38,-4,LEAVES:15)
Block(14,38,-4,LEAVES:15)
Block(-12,38,-3,LEAVES:15)
Block(-13,38,-2,LEAVES:15)
Block(-12,38,-2,LEAVES:15)
Block(-9,38,-2,LEAVES:15)
Block(-7,38,-2,LEAVES:15)
Block(4,38,-2,LOG:15)
Block(11,38,-2,LEAVES:15)
Block(-12,38,-1,LEAVES:15)
Block(-11,38,-1,LEAVES:15)
Block(-9,38,-1,LEAVES:15)
Block(-8,38,-1,LEAVES:15)
Block(-7,38,-1,LEAVES:15)
Block(-6,38,-1,LEAVES:15)
Block(3,38,-1,LEAVES:15)
Block(4,38,-1,LEAVES:15)
Block(7,38,-1,LEAVES:15)
Block(8,38,-1,LEAVES:15)
Block(11,38,-1,LEAVES:15)
Block(12,38,-1,LEAVES:15)
Block(-10,38,0,LOG:15)
Block(-8,38,0,LEAVES:15)
Block(0,38,0,LEAVES:15)
Block(3,38,0,LEAVES:15)
Block(4,38,0,LEAVES:15)
Block(5,38,0,LEAVES:15)
Block(8,38,0,LEAVES:15)
Block(9,38,0,LEAVES:15)
Block(12,38,0,LEAVES:15)
Block(-8,38,1,LEAVES:15)
Block(-7,38,1,LEAVES:15)
Block(1,38,1,LEAVES:15)
Block(3,38,1,LEAVES:15)
Block(4,38,1,LEAVES:15)
Block(8,38,1,LEAVES:15)
Block(9,38,1,LEAVES:15)
Block(11,38,1,LEAVES:15)
Block(12,38,1,LEAVES:15)
Block(-13,38,2,LEAVES:15)
Block(-12,38,2,LEAVES:15)
Block(-8,38,2,LEAVES:15)
Block(1,38,2,LEAVES:15)
Block(2,38,2,LEAVES:15)
Block(3,38,2,LEAVES:15)
Block(4,38,2,LEAVES:15)
Block(6,38,2,LEAVES:15)
Block(7,38,2,LEAVES:15)
Block(8,38,2,LEAVES:15)
Block(9,38,2,LEAVES:15)
Block(10,38,2,LEAVES:15)
Block(11,38,2,LEAVES:15)
Block(-13,38,3,LEAVES:15)
Block(-12,38,3,LEAVES:15)
Block(-9,38,3,LEAVES:15)
Block(-8,38,3,LEAVES:15)
Block(-5,38,3,LEAVES:15)
Block(-4,38,3,LEAVES:15)
Block(0,38,3,LEAVES:15)
Block(1,38,3,LEAVES:15)
Block(2,38,3,LEAVES:15)
Block(5,38,3,LEAVES:15)
Block(6,38,3,LEAVES:15)
Block(7,38,3,LEAVES:15)
Block(8,38,3,LEAVES:15)
Block(9,38,3,LEAVES:15)
Block(11,38,3,LEAVES:15)
Block(12,38,3,LEAVES:15)
Block(13,38,3,LEAVES:15)
Block(14,38,3,LEAVES:15)
Block(-8,38,4,LEAVES:15)
Block(-7,38,4,LEAVES:15)
Block(-5,38,4,LEAVES:15)
Block(-4,38,4,LEAVES:15)
Block(0,38,4,LEAVES:15)
Block(4,38,4,LEAVES:15)
Block(5,38,4,LOG:15)
Block(12,38,4,LEAVES:15)
Block(-7,38,5,LEAVES:15)
Block(-5,38,5,LEAVES:15)
Block(0,38,5,LEAVES:15)
Block(1,38,5,LEAVES:15)
Block(4,38,5,LEAVES:15)
Block(5,38,5,LOG:15)
Block(12,38,5,LEAVES:15)
Block(-8,38,6,LEAVES:15)
Block(-7,38,6,LEAVES:15)
Block(-6,38,6,LEAVES:15)
Block(-3,38,6,LEAVES:15)
Block(0,38,6,LEAVES:15)
Block(1,38,6,LEAVES:15)
Block(3,38,6,LEAVES:15)
Block(4,38,6,LEAVES:15)
Block(8,38,6,LEAVES:15)
Block(9,38,6,LEAVES:15)
Block(14,38,6,LEAVES:15)
Block(-8,38,7,LEAVES:15)
Block(-4,38,7,LEAVES:15)
Block(-3,38,7,LOG:15)
Block(3,38,7,LEAVES:15)
Block(9,38,7,LEAVES:15)
Block(10,38,7,LEAVES:15)
Block(-4,38,8,LEAVES:15)
Block(-5,38,9,LEAVES:15)
Block(-4,38,9,LEAVES:15)
Block(0,38,9,LEAVES:15)
Block(1,38,9,LEAVES:15)
Block(5,38,9,LEAVES:15)
Block(6,38,9,LEAVES:15)
Block(-6,38,10,LEAVES:15)
Block(-5,38,10,LEAVES:15)
Block(1,38,10,LEAVES:15)
Block(2,38,10,LEAVES:15)
Block(5,38,10,LEAVES:15)
Block(6,38,10,LEAVES:15)
Block(-3,38,12,LEAVES:15)
Block(-2,38,12,LEAVES:15)
Block(-3,38,13,LEAVES:15)
Block(-2,38,13,LEAVES:15)
Block(0,39,-15,LEAVES:15)
Block(-2,39,-13,LEAVES:15)
Block(1,39,-13,LEAVES:15)
Block(6,39,-11,LEAVES:15)
Block(7,39,-11,LEAVES:15)
Block(1,39,-10,LEAVES:15)
Block(6,39,-10,LEAVES:15)
Block(7,39,-10,LEAVES:15)
Block(0,39,-9,LEAVES:15)
Block(2,39,-9,LEAVES:15)
Block(10,39,-9,LEAVES:15)
Block(1,39,-8,LEAVES:15)
Block(2,39,-8,LEAVES:15)
Block(10,39,-8,LEAVES:15)
Block(1,39,-7,LEAVES:15)
Block(3,39,-6,LOG:15)
Block(-10,39,-5,LEAVES:15)
Block(5,39,-5,LEAVES:15)
Block(6,39,-5,LEAVES:15)
Block(10,39,-5,LEAVES:15)
Block(-15,39,-4,LEAVES:15)
Block(-14,39,-4,LEAVES:15)
Block(-10,39,-4,LEAVES:15)
Block(4,39,-4,LEAVES:15)
Block(5,39,-4,LEAVES:15)
Block(6,39,-4,LEAVES:15)
Block(8,39,-4,LOG:15)
Block(10,39,-4,LEAVES:15)
Block(-14,39,-3,LEAVES:15)
Block(-13,39,-3,LEAVES:15)
Block(-10,39,-3,LEAVES:15)
Block(4,39,-3,LEAVES:15)
Block(-14,39,-2,LEAVES:15)
Block(-13,39,-2,LEAVES:15)
Block(-11,39,-2,LEAVES:15)
Block(-10,39,-2,LEAVES:15)
Block(3,39,-2,LEAVES:15)
Block(4,39,-2,LEAVES:15)
Block(5,39,-2,LEAVES:15)
Block(-15,39,-1,LEAVES:15)
Block(-14,39,-1,LEAVES:15)
Block(-12,39,-1,LEAVES:15)
Block(-11,39,-1,LEAVES:15)
Block(-7,39,-1,LEAVES:15)
Block(3,39,-1,LEAVES:15)
Block(4,39,-1,LOG:15)
Block(6,39,-1,LEAVES:15)
Block(7,39,-1,LEAVES:15)
Block(10,39,-1,LEAVES:15)
Block(12,39,-1,LEAVES:15)
Block(13,39,-1,LEAVES:15)
Block(-15,39,0,LEAVES:15)
Block(-11,39,0,LEAVES:15)
Block(-10,39,0,LEAVES:15)
Block(-9,39,0,LEAVES:15)
Block(-8,39,0,LEAVES:15)
Block(3,39,0,LEAVES:15)
Block(6,39,0,LEAVES:15)
Block(7,39,0,LEAVES:15)
Block(10,39,0,LEAVES:15)
Block(12,39,0,LEAVES:15)
Block(13,39,0,LEAVES:15)
Block(-10,39,1,LEAVES:15)
Block(3,39,1,LEAVES:15)
Block(6,39,1,LEAVES:15)
Block(9,39,1,LEAVES:15)
Block(10,39,1,LEAVES:15)
Block(11,39,1,LEAVES:15)
Block(-10,39,2,LEAVES:15)
Block(3,39,2,LEAVES:15)
Block(9,39,2,LEAVES:15)
Block(10,39,2,LEAVES:15)
Block(11,39,2,LEAVES:15)
Block(14,39,2,LEAVES:15)
Block(15,39,2,LEAVES:15)
Block(-8,39,3,LEAVES:15)
Block(-5,39,3,LEAVES:15)
Block(2,39,3,LEAVES:15)
Block(3,39,3,LEAVES:15)
Block(8,39,3,LEAVES:15)
Block(11,39,3,LEAVES:15)
Block(14,39,3,LEAVES:15)
Block(15,39,3,LEAVES:15)
Block(3,39,4,LEAVES:15)
Block(4,39,4,LEAVES:15)
Block(7,39,4,LEAVES:15)
Block(8,39,4,LEAVES:15)
Block(-5,39,5,LEAVES:15)
Block(5,39,5,LOG:15)
Block(7,39,5,LEAVES:15)
Block(12,39,5,LEAVES:15)
Block(-6,39,6,LEAVES:15)
Block(-5,39,6,LEAVES:15)
Block(0,39,6,LEAVES:15)
Block(7,39,6,LEAVES:15)
Block(8,39,6,LEAVES:15)
Block(12,39,6,LEAVES:15)
Block(-5,39,7,LEAVES:15)
Block(-4,39,7,LEAVES:15)
Block(-3,39,7,LOG:15)
Block(-1,39,7,LEAVES:15)
Block(0,39,7,LEAVES:15)
Block(2,39,7,LEAVES:15)
Block(3,39,7,LEAVES:15)
Block(7,39,7,LEAVES:15)
Block(-3,39,8,LOG:15)
Block(-1,39,8,LEAVES:15)
Block(2,39,8,LEAVES:15)
Block(3,39,8,LEAVES:15)
Block(6,39,8,LEAVES:15)
Block(7,39,8,LEAVES:15)
Block(-1,39,9,LEAVES:15)
Block(0,39,9,LEAVES:15)
Block(7,39,9,LEAVES:15)
Block(-6,39,10,LEAVES:15)
Block(-5,39,10,LEAVES:15)
Block(-1,39,10,LEAVES:15)
Block(-6,39,11,LEAVES:15)
Block(-5,39,11,LEAVES:15)
Block(-2,39,11,LEAVES:15)
Block(-1,39,11,LEAVES:15)
Block(-1,39,12,LEAVES:15)
Block(0,40,-15,LEAVES:15)
Block(-2,40,-13,LEAVES:15)
Block(1,40,-13,LEAVES:15)
Block(1,40,-10,LEAVES:15)
Block(7,40,-10,LEAVES:15)
Block(0,40,-9,LEAVES:15)
Block(2,40,-9,LEAVES:15)
Block(3,40,-9,LEAVES:15)
Block(4,40,-9,LEAVES:15)
Block(7,40,-9,LEAVES:15)
Block(10,40,-9,LEAVES:15)
Block(1,40,-8,LEAVES:15)
Block(2,40,-8,LEAVES:15)
Block(3,40,-8,LEAVES:15)
Block(4,40,-8,LEAVES:15)
Block(5,40,-8,LEAVES:15)
Block(10,40,-8,LEAVES:15)
Block(11,40,-8,LEAVES:15)
Block(1,40,-7,LEAVES:15)
Block(2,40,-7,LOG:15)
Block(3,40,-7,LOG:15)
Block(10,40,-7,LEAVES:15)
Block(2,40,-6,LEAVES:15)
Block(3,40,-6,LEAVES:15)
Block(6,40,-6,LEAVES:15)
Block(9,40,-6,LEAVES:15)
Block(10,40,-6,LEAVES:15)
Block(2,40,-5,LEAVES:15)
Block(3,40,-5,LEAVES:15)
Block(4,40,-5,LEAVES:15)
Block(6,40,-5,LEAVES:15)
Block(-10,40,-4,LEAVES:15)
Block(-9,40,-4,LEAVES:15)
Block(3,40,-4,LEAVES:15)
Block(4,40,-4,LEAVES:15)
Block(9,40,-4,LOG:15)
Block(-10,40,-3,LEAVES:15)
Block(-9,40,-3,LEAVES:15)
Block(3,40,-3,LEAVES:15)
Block(4,40,-3,LEAVES:15)
Block(5,40,-3,LEAVES:15)
Block(8,40,-3,LEAVES:15)
Block(9,40,-3,LEAVES:15)
Block(10,40,-3,LEAVES:15)
Block(-13,40,-2,LEAVES:15)
Block(4,40,-2,LEAVES:15)
Block(7,40,-2,LEAVES:15)
Block(9,40,-2,LEAVES:15)
Block(10,40,-2,LEAVES:15)
Block(14,40,-2,LEAVES:15)
Block(15,40,-2,LEAVES:15)
Block(-13,40,-1,LEAVES:15)
Block(-8,40,-1,LEAVES:15)
Block(-7,40,-1,LEAVES:15)
Block(3,40,-1,LOG:15)
Block(4,40,-1,LOG:15)
Block(7,40,-1,LEAVES:15)
Block(10,40,-1,LEAVES:15)
Block(14,40,-1,LEAVES:15)
Block(15,40,-1,LEAVES:15)
Block(-11,40,0,LEAVES:15)
Block(-8,40,0,LEAVES:15)
Block(-7,40,0,LEAVES:15)
Block(3,40,0,LEAVES:15)
Block(6,40,0,LEAVES:15)
Block(0,40,1,LEAVES:15)
Block(1,40,1,LEAVES:15)
Block(2,40,1,LEAVES:15)
Block(5,40,1,LEAVES:15)
Block(-10,40,2,LEAVES:15)
Block(1,40,2,LEAVES:15)
Block(2,40,2,LEAVES:15)
Block(3,40,2,LEAVES:15)
Block(5,40,2,LEAVES:15)
Block(11,40,2,LEAVES:15)
Block(-10,40,3,LEAVES:15)
Block(1,40,3,LEAVES:15)
Block(2,40,3,LEAVES:15)
Block(4,40,3,LEAVES:15)
Block(5,40,3,LEAVES:15)
Block(11,40,3,LEAVES:15)
Block(-8,40,4,LEAVES:15)
Block(-7,40,4,LEAVES:15)
Block(-3,40,4,LEAVES:15)
Block(-1,40,4,LEAVES:15)
Block(0,40,4,LEAVES:15)
Block(1,40,4,LEAVES:15)
Block(3,40,4,LEAVES:15)
Block(4,40,4,LEAVES:15)
Block(-7,40,5,LEAVES:15)
Block(-6,40,5,LEAVES:15)
Block(-3,40,5,LEAVES:15)
Block(-1,40,5,LEAVES:15)
Block(0,40,5,LEAVES:15)
Block(4,40,5,LEAVES:15)
Block(5,40,5,LEAVES:15)
Block(6,40,5,LEAVES:15)
Block(7,40,5,LEAVES:15)
Block(-7,40,6,LEAVES:15)
Block(-6,40,6,LEAVES:15)
Block(-4,40,6,LEAVES:15)
Block(-3,40,6,LEAVES:15)
Block(5,40,6,LEAVES:15)
Block(-9,40,7,LEAVES:15)
Block(-8,40,7,LEAVES:15)
Block(-7,40,7,LEAVES:15)
Block(-5,40,7,LEAVES:15)
Block(-4,40,7,LEAVES:15)
Block(5,40,7,LEAVES:15)
Block(-9,40,8,LEAVES:15)
Block(-8,40,8,LEAVES:15)
Block(-4,40,8,LEAVES:15)
Block(-3,40,8,LEAVES:15)
Block(-2,40,8,LEAVES:15)
Block(-1,40,8,LEAVES:15)
Block(7,40,8,LEAVES:15)
Block(-3,40,9,LEAVES:15)
Block(-3,40,10,LEAVES:15)
Block(-1,40,11,LEAVES:15)
Block(0,41,-15,LEAVES:15)
Block(-2,41,-13,LEAVES:15)
Block(1,41,-13,LEAVES:15)
Block(1,41,-10,LEAVES:15)
Block(0,41,-9,LEAVES:15)
Block(2,41,-9,LEAVES:15)
Block(7,41,-9,LEAVES:15)
Block(8,41,-9,LEAVES:15)
Block(1,41,-8,LEAVES:15)
Block(2,41,-8,LOG:15)
Block(5,41,-8,LEAVES:15)
Block(7,41,-8,LEAVES:15)
Block(8,41,-8,LEAVES:15)
Block(5,41,-7,LEAVES:15)
Block(7,41,-7,LEAVES:15)
Block(12,41,-7,LEAVES:15)
Block(13,41,-7,LEAVES:15)
Block(4,41,-6,LEAVES:15)
Block(5,41,-6,LEAVES:15)
Block(6,41,-6,LEAVES:15)
Block(9,41,-6,LEAVES:15)
Block(12,41,-6,LEAVES:15)
Block(13,41,-6,LEAVES:15)
Block(4,41,-5,LEAVES:15)
Block(8,41,-5,LEAVES:15)
Block(9,41,-5,LEAVES:15)
Block(4,41,-4,LEAVES:15)
Block(8,41,-4,LEAVES:15)
Block(9,41,-4,LOG:15)
Block(7,41,-3,LEAVES:15)
Block(8,41,-3,LEAVES:15)
Block(12,41,-3,LEAVES:15)
Block(13,41,-3,LEAVES:15)
Block(7,41,-2,LEAVES:15)
Block(13,41,-2,LEAVES:15)
Block(14,41,-2,LEAVES:15)
Block(-11,41,-1,LEAVES:15)
Block(2,41,-1,LOG:15)
Block(-11,41,0,LEAVES:15)
Block(4,41,0,LOG:15)
Block(9,41,0,LEAVES:15)
Block(10,41,0,LEAVES:15)
Block(5,41,1,LEAVES:15)
Block(6,41,1,LEAVES:15)
Block(9,41,1,LEAVES:15)
Block(10,41,1,LEAVES:15)
Block(2,41,2,LEAVES:15)
Block(5,41,2,LEAVES:15)
Block(6,41,2,LEAVES:15)
Block(2,41,3,LEAVES:15)
Block(-3,41,4,LEAVES:15)
Block(-2,41,4,LEAVES:15)
Block(2,41,4,LEAVES:15)
Block(7,41,4,LEAVES:15)
Block(8,41,4,LEAVES:15)
Block(-3,41,5,LEAVES:15)
Block(-2,41,5,LEAVES:15)
Block(4,41,5,LEAVES:15)
Block(7,41,5,LEAVES:15)
Block(8,41,5,LEAVES:15)
Block(-6,41,6,LEAVES:15)
Block(-6,41,7,LEAVES:15)
Block(-1,41,7,LEAVES:15)
Block(0,41,7,LEAVES:15)
Block(5,41,7,LEAVES:15)
Block(-4,41,8,LEAVES:15)
Block(-1,41,8,LEAVES:15)
Block(0,41,8,LEAVES:15)
Block(5,41,8,LEAVES:15)
Block(-3,41,10,LEAVES:15)
Block(-3,41,11,LEAVES:15)
Block(-2,42,-15,LEAVES:15)
Block(-1,42,-15,LEAVES:15)
Block(0,42,-15,LEAVES:15)
Block(2,42,-14,LEAVES:15)
Block(-2,42,-13,LEAVES:15)
Block(1,42,-13,LEAVES:15)
Block(2,42,-13,LEAVES:15)
Block(-3,42,-10,LEAVES:15)
Block(-2,42,-10,LEAVES:15)
Block(1,42,-10,LEAVES:15)
Block(-3,42,-9,LEAVES:15)
Block(-2,42,-9,LEAVES:15)
Block(0,42,-9,LEAVES:15)
Block(1,42,-9,LOG:15)
Block(2,42,-9,LEAVES:15)
Block(7,42,-9,LEAVES:15)
Block(-4,42,-8,LEAVES:15)
Block(-3,42,-8,LEAVES:15)
Block(2,42,-8,LOG:15)
Block(-5,42,-7,LEAVES:15)
Block(-4,42,-7,LEAVES:15)
Block(-3,42,-7,LEAVES:15)
Block(7,42,-7,LEAVES:15)
Block(-2,42,-6,LEAVES:15)
Block(-1,42,-6,LEAVES:15)
Block(0,42,-6,LEAVES:15)
Block(2,42,-6,LEAVES:15)
Block(6,42,-6,LEAVES:15)
Block(7,42,-6,LEAVES:15)
Block(12,42,-6,LEAVES:15)
Block(-2,42,-5,LEAVES:15)
Block(-1,42,-5,LEAVES:15)
Block(0,42,-5,LEAVES:15)
Block(1,42,-5,LEAVES:15)
Block(2,42,-5,LEAVES:15)
Block(7,42,-5,LEAVES:15)
Block(8,42,-5,LEAVES:15)
Block(11,42,-5,LEAVES:15)
Block(12,42,-5,LEAVES:15)
Block(1,42,-4,LEAVES:15)
Block(2,42,-4,LEAVES:15)
Block(3,42,-4,LEAVES:15)
Block(9,42,-4,LOG:15)
Block(11,42,-4,LEAVES:15)
Block(2,42,-3,LEAVES:15)
Block(3,42,-3,LEAVES:15)
Block(5,42,-3,LEAVES:15)
Block(11,42,-3,LEAVES:15)
Block(12,42,-3,LEAVES:15)
Block(-5,42,-2,LEAVES:15)
Block(-4,42,-2,LEAVES:15)
Block(5,42,-2,LEAVES:15)
Block(6,42,-2,LEAVES:15)
Block(7,42,-2,LEAVES:15)
Block(11,42,-2,LEAVES:15)
Block(-5,42,-1,LEAVES:15)
Block(-4,42,-1,LEAVES:15)
Block(1,42,-1,LOG:15)
Block(6,42,-1,LEAVES:15)
Block(7,42,-1,LEAVES:15)
Block(10,42,-1,LEAVES:15)
Block(11,42,-1,LEAVES:15)
Block(4,42,0,LOG:15)
Block(11,42,0,LEAVES:15)
Block(-7,42,1,LEAVES:15)
Block(-6,42,1,LEAVES:15)
Block(0,42,1,LEAVES:15)
Block(1,42,1,LEAVES:15)
Block(-4,42,2,LEAVES:15)
Block(-3,42,2,LEAVES:15)
Block(0,42,2,LEAVES:15)
Block(1,42,2,LEAVES:15)
Block(-4,42,3,LEAVES:15)
Block(-3,42,3,LEAVES:15)
Block(0,42,3,LEAVES:15)
Block(-2,42,4,LEAVES:15)
Block(-1,42,4,LEAVES:15)
Block(0,42,4,LEAVES:15)
Block(1,42,4,LEAVES:15)
Block(4,42,4,LEAVES:15)
Block(0,42,5,LEAVES:15)
Block(1,42,5,LEAVES:15)
Block(2,42,5,LEAVES:15)
Block(4,42,5,LEAVES:15)
Block(5,42,5,LEAVES:15)
Block(1,42,6,LEAVES:15)
Block(2,42,6,LEAVES:15)
Block(5,42,6,LEAVES:15)
Block(-4,42,7,LEAVES:15)
Block(5,42,7,LEAVES:15)
Block(6,42,7,LEAVES:15)
Block(-4,42,8,LEAVES:15)
Block(5,42,8,LEAVES:15)
Block(6,42,8,LEAVES:15)
Block(-1,43,-15,LEAVES:15)
Block(-5,43,-14,LEAVES:15)
Block(-4,43,-14,LEAVES:15)
Block(-1,43,-14,LEAVES:15)
Block(2,43,-14,LEAVES:15)
Block(-5,43,-13,LEAVES:15)
Block(-4,43,-13,LEAVES:15)
Block(-3,43,-13,LEAVES:15)
Block(-2,43,-13,LEAVES:15)
Block(1,43,-13,LEAVES:15)
Block(2,43,-13,LEAVES:15)
Block(3,43,-13,LEAVES:15)
Block(2,43,-12,LEAVES:15)
Block(-6,43,-11,LEAVES:15)
Block(-5,43,-11,LEAVES:15)
Block(-2,43,-11,LEAVES:15)
Block(1,43,-11,LEAVES:15)
Block(2,43,-11,LEAVES:15)
Block(-6,43,-10,LEAVES:15)
Block(-5,43,-10,LEAVES:15)
Block(-4,43,-10,LEAVES:15)
Block(-2,43,-10,LEAVES:15)
Block(-4,43,-9,LEAVES:15)
Block(1,43,-9,LOG:15)
Block(-5,43,-8,LEAVES:15)
Block(-4,43,-8,LEAVES:15)
Block(0,43,-8,LEAVES:15)
Block(1,43,-8,LEAVES:15)
Block(2,43,-8,LEAVES:15)
Block(4,43,-8,LEAVES:15)
Block(5,43,-8,LEAVES:15)
Block(9,43,-8,LEAVES:15)
Block(-4,43,-7,LEAVES:15)
Block(-3,43,-7,LEAVES:15)
Block(-1,43,-7,LEAVES:15)
Block(1,43,-7,LEAVES:15)
Block(2,43,-7,LEAVES:15)
Block(5,43,-7,LEAVES:15)
Block(6,43,-7,LEAVES:15)
Block(7,43,-7,LEAVES:15)
Block(9,43,-7,LEAVES:15)
Block(-7,43,-6,LEAVES:15)
Block(-6,43,-6,LEAVES:15)
Block(-3,43,-6,LEAVES:15)
Block(-1,43,-6,LEAVES:15)
Block(0,43,-6,LEAVES:15)
Block(2,43,-6,LEAVES:15)
Block(5,43,-6,LEAVES:15)
Block(6,43,-6,LEAVES:15)
Block(7,43,-6,LEAVES:15)
Block(8,43,-6,LEAVES:15)
Block(9,43,-6,LEAVES:15)
Block(-7,43,-5,LEAVES:15)
Block(-6,43,-5,LEAVES:15)
Block(-5,43,-5,LEAVES:15)
Block(0,43,-5,LEAVES:15)
Block(1,43,-5,LEAVES:15)
Block(3,43,-5,LEAVES:15)
Block(4,43,-5,LEAVES:15)
Block(5,43,-5,LEAVES:15)
Block(7,43,-5,LEAVES:15)
Block(8,43,-5,LEAVES:15)
Block(0,43,-4,LEAVES:15)
Block(2,43,-4,LEAVES:15)
Block(3,43,-4,LEAVES:15)
Block(4,43,-4,LEAVES:15)
Block(8,43,-4,LEAVES:15)
Block(9,43,-4,LEAVES:15)
Block(10,43,-4,LEAVES:15)
Block(11,43,-4,LEAVES:15)
Block(-8,43,-3,LEAVES:15)
Block(-7,43,-3,LEAVES:15)
Block(-4,43,-3,LEAVES:15)
Block(-2,43,-3,LEAVES:15)
Block(-1,43,-3,LEAVES:15)
Block(0,43,-3,LEAVES:15)
Block(2,43,-3,LEAVES:15)
Block(5,43,-3,LEAVES:15)
Block(9,43,-3,LEAVES:15)
Block(-8,43,-2,LEAVES:15)
Block(-7,43,-2,LEAVES:15)
Block(-6,43,-2,LEAVES:15)
Block(-4,43,-2,LEAVES:15)
Block(-2,43,-2,LEAVES:15)
Block(-1,43,-2,LEAVES:15)
Block(0,43,-2,LEAVES:15)
Block(5,43,-2,LEAVES:15)
Block(6,43,-2,LEAVES:15)
Block(9,43,-2,LEAVES:15)
Block(-6,43,-1,LEAVES:15)
Block(1,43,-1,LOG:15)
Block(5,43,-1,LEAVES:15)
Block(11,43,-1,LEAVES:15)
Block(-7,43,0,LEAVES:15)
Block(-6,43,0,LEAVES:15)
Block(-3,43,0,LEAVES:15)
Block(-2,43,0,LEAVES:15)
Block(-1,43,0,LEAVES:15)
Block(0,43,0,LEAVES:15)
Block(1,43,0,LEAVES:15)
Block(4,43,0,LEAVES:15)
Block(5,43,0,LEAVES:15)
Block(-6,43,1,LEAVES:15)
Block(-3,43,1,LEAVES:15)
Block(-2,43,1,LEAVES:15)
Block(-1,43,1,LEAVES:15)
Block(0,43,1,LEAVES:15)
Block(1,43,1,LEAVES:15)
Block(4,43,1,LOG:15)
Block(5,43,1,LEAVES:15)
Block(-3,43,2,LEAVES:15)
Block(-1,43,2,LEAVES:15)
Block(0,43,2,LEAVES:15)
Block(4,43,2,LEAVES:15)
Block(5,43,2,LEAVES:15)
Block(-2,43,3,LEAVES:15)
Block(-1,43,3,LEAVES:15)
Block(3,43,3,LEAVES:15)
Block(4,43,3,LEAVES:15)
Block(5,43,3,LEAVES:15)
Block(-1,43,4,LEAVES:15)
Block(2,43,4,LEAVES:15)
Block(4,43,4,LEAVES:15)
Block(5,43,4,LEAVES:15)
Block(9,43,4,LEAVES:15)
Block(10,43,4,LEAVES:15)
Block(2,43,5,LEAVES:15)
Block(5,43,5,LEAVES:15)
Block(9,43,5,LEAVES:15)
Block(10,43,5,LEAVES:15)
Block(-1,44,-15,LEAVES:15)
Block(-1,44,-14,LEAVES:15)
Block(0,44,-14,LEAVES:15)
Block(-4,44,-13,LEAVES:15)
Block(-3,44,-13,LEAVES:15)
Block(-2,44,-13,LEAVES:15)
Block(-1,44,-13,LEAVES:15)
Block(0,44,-13,LEAVES:15)
Block(1,44,-13,LEAVES:15)
Block(-3,44,-12,LEAVES:15)
Block(-1,44,-12,LEAVES:15)
Block(4,44,-12,LEAVES:15)
Block(5,44,-12,LEAVES:15)
Block(-4,44,-11,LEAVES:15)
Block(-3,44,-11,LEAVES:15)
Block(-2,44,-11,LEAVES:15)
Block(1,44,-11,LEAVES:15)
Block(4,44,-11,LEAVES:15)
Block(5,44,-11,LEAVES:15)
Block(-4,44,-10,LEAVES:15)
Block(0,44,-10,LEAVES:15)
Block(1,44,-10,LEAVES:15)
Block(0,44,-9,LEAVES:15)
Block(1,44,-9,LOG:15)
Block(-1,44,-8,LEAVES:15)
Block(0,44,-8,LEAVES:15)
Block(4,44,-8,LEAVES:15)
Block(5,44,-8,LEAVES:15)
Block(9,44,-8,LEAVES:15)
Block(10,44,-8,LEAVES:15)
Block(-1,44,-7,LEAVES:15)
Block(5,44,-7,LEAVES:15)
Block(6,44,-7,LEAVES:15)
Block(9,44,-7,LEAVES:15)
Block(10,44,-7,LEAVES:15)
Block(-3,44,-6,LEAVES:15)
Block(-2,44,-6,LEAVES:15)
Block(6,44,-6,LEAVES:15)
Block(-5,44,-5,LEAVES:15)
Block(-3,44,-5,LEAVES:15)
Block(-2,44,-5,LEAVES:15)
Block(1,44,-5,LEAVES:15)
Block(2,44,-5,LEAVES:15)
Block(6,44,-5,LEAVES:15)
Block(11,44,-5,LEAVES:15)
Block(12,44,-5,LEAVES:15)
Block(-5,44,-4,LEAVES:15)
Block(-3,44,-4,LEAVES:15)
Block(1,44,-4,LEAVES:15)
Block(2,44,-4,LEAVES:15)
Block(3,44,-4,LEAVES:15)
Block(8,44,-4,LEAVES:15)
Block(11,44,-4,LEAVES:15)
Block(12,44,-4,LEAVES:15)
Block(-6,44,-3,LEAVES:15)
Block(-5,44,-3,LEAVES:15)
Block(-4,44,-3,LEAVES:15)
Block(-1,44,-3,LEAVES:15)
Block(2,44,-3,LEAVES:15)
Block(3,44,-3,LEAVES:15)
Block(-6,44,-2,LEAVES:15)
Block(-2,44,-2,LEAVES:15)
Block(-1,44,-2,LEAVES:15)
Block(0,44,-2,LEAVES:15)
Block(2,44,-2,LEAVES:15)
Block(3,44,-2,LEAVES:15)
Block(9,44,-2,LEAVES:15)
Block(-2,44,-1,LEAVES:15)
Block(0,44,-1,LOG:15)
Block(2,44,-1,LEAVES:15)
Block(7,44,-1,LEAVES:15)
Block(8,44,-1,LEAVES:15)
Block(9,44,-1,LEAVES:15)
Block(-3,44,0,LEAVES:15)
Block(-2,44,0,LEAVES:15)
Block(-1,44,0,LEAVES:15)
Block(0,44,0,LEAVES:15)
Block(1,44,0,LEAVES:15)
Block(2,44,0,LEAVES:15)
Block(3,44,0,LEAVES:15)
Block(4,44,0,LEAVES:15)
Block(7,44,0,LEAVES:15)
Block(8,44,0,LEAVES:15)
Block(-3,44,1,LEAVES:15)
Block(-1,44,1,LEAVES:15)
Block(3,44,1,LEAVES:15)
Block(4,44,1,LOG:15)
Block(3,44,2,LEAVES:15)
Block(-1,44,3,LEAVES:15)
Block(0,44,3,LEAVES:15)
Block(2,44,3,LEAVES:15)
Block(3,44,3,LEAVES:15)
Block(7,44,3,LEAVES:15)
Block(8,44,3,LEAVES:15)
Block(-1,44,4,LEAVES:15)
Block(0,44,4,LEAVES:15)
Block(2,44,4,LEAVES:15)
Block(8,44,4,LEAVES:15)
Block(9,44,4,LEAVES:15)
Block(4,44,6,LEAVES:15)
Block(5,44,6,LEAVES:15)
Block(4,44,7,LEAVES:15)
Block(5,44,7,LEAVES:15)
Block(-1,45,-14,LEAVES:15)
Block(-1,45,-13,LEAVES:15)
Block(0,45,-13,LEAVES:15)
Block(-1,45,-12,LEAVES:15)
Block(-2,45,-11,LEAVES:15)
Block(-1,45,-11,LEAVES:15)
Block(4,45,-11,LEAVES:15)
Block(-1,45,-10,LEAVES:15)
Block(0,45,-10,LEAVES:15)
Block(3,45,-10,LEAVES:15)
Block(4,45,-10,LEAVES:15)
Block(1,45,-9,LOG:15)
Block(3,45,-9,LEAVES:15)
Block(3,45,-8,LEAVES:15)
Block(4,45,-8,LEAVES:15)
Block(-2,45,-7,LEAVES:15)
Block(-1,45,-7,LEAVES:15)
Block(3,45,-7,LEAVES:15)
Block(-3,45,-6,LEAVES:15)
Block(-2,45,-6,LEAVES:15)
Block(-1,45,-6,LEAVES:15)
Block(2,45,-6,LEAVES:15)
Block(3,45,-6,LEAVES:15)
Block(3,45,-5,LEAVES:15)
Block(8,45,-5,LEAVES:15)
Block(-3,45,-4,LEAVES:15)
Block(8,45,-4,LEAVES:15)
Block(-4,45,-3,LEAVES:15)
Block(-3,45,-3,LEAVES:15)
Block(2,45,-3,LEAVES:15)
Block(-3,45,-2,LEAVES:15)
Block(-2,45,-2,LEAVES:15)
Block(1,45,-2,LEAVES:15)
Block(2,45,-2,LEAVES:15)
Block(-1,45,-1,LOG:15)
Block(1,45,-1,LEAVES:15)
Block(2,45,-1,LEAVES:15)
Block(1,45,0,LEAVES:15)
Block(2,45,0,LEAVES:15)
Block(7,45,0,LEAVES:15)
Block(-4,45,1,LEAVES:15)
Block(-3,45,1,LEAVES:15)
Block(1,45,1,LEAVES:15)
Block(2,45,1,LEAVES:15)
Block(3,45,1,LEAVES:15)
Block(6,45,1,LEAVES:15)
Block(7,45,1,LEAVES:15)
Block(-4,45,2,LEAVES:15)
Block(-3,45,2,LEAVES:15)
Block(0,45,2,LEAVES:15)
Block(1,45,2,LEAVES:15)
Block(4,45,2,LOG:15)
Block(6,45,2,LEAVES:15)
Block(1,45,3,LEAVES:15)
Block(6,45,3,LEAVES:15)
Block(7,45,3,LEAVES:15)
Block(1,45,4,LEAVES:15)
Block(2,45,4,LEAVES:15)
Block(6,45,4,LEAVES:15)
Block(1,45,5,LEAVES:15)
Block(2,45,5,LEAVES:15)
Block(5,45,5,LEAVES:15)
Block(6,45,5,LEAVES:15)
Block(6,45,6,LEAVES:15)
Block(-4,46,-13,LEAVES:15)
Block(-3,46,-13,LEAVES:15)
Block(0,46,-13,LEAVES:15)
Block(1,46,-13,LEAVES:15)
Block(-3,46,-12,LEAVES:15)
Block(-2,46,-12,LEAVES:15)
Block(1,46,-12,LEAVES:15)
Block(-3,46,-11,LEAVES:15)
Block(-2,46,-11,LEAVES:15)
Block(0,46,-11,LEAVES:15)
Block(1,46,-11,LEAVES:15)
Block(-5,46,-10,LEAVES:15)
Block(-4,46,-10,LEAVES:15)
Block(-3,46,-10,LEAVES:15)
Block(-1,46,-10,LEAVES:15)
Block(0,46,-10,LEAVES:15)
Block(-5,46,-9,LEAVES:15)
Block(-4,46,-9,LEAVES:15)
Block(0,46,-9,LEAVES:15)
Block(1,46,-9,LEAVES:15)
Block(2,46,-9,LEAVES:15)
Block(3,46,-9,LEAVES:15)
Block(1,46,-8,LEAVES:15)
Block(1,46,-7,LEAVES:15)
Block(3,46,-6,LEAVES:15)
Block(-6,46,-5,LEAVES:15)
Block(-5,46,-5,LEAVES:15)
Block(-1,46,-5,LEAVES:15)
Block(-5,46,-4,LEAVES:15)
Block(-4,46,-4,LEAVES:15)
Block(-1,46,-4,LEAVES:15)
Block(-5,46,-3,LEAVES:15)
Block(-4,46,-3,LEAVES:15)
Block(-2,46,-3,LEAVES:15)
Block(-1,46,-3,LEAVES:15)
Block(-7,46,-2,LEAVES:15)
Block(-6,46,-2,LEAVES:15)
Block(-5,46,-2,LEAVES:15)
Block(-3,46,-2,LEAVES:15)
Block(-2,46,-2,LEAVES:15)
Block(-1,46,-2,LEAVES:15)
Block(0,46,-2,LEAVES:15)
Block(4,46,-2,LEAVES:15)
Block(-7,46,-1,LEAVES:15)
Block(-6,46,-1,LEAVES:15)
Block(-2,46,-1,LEAVES:15)
Block(-1,46,-1,LEAVES:15)
Block(0,46,-1,LEAVES:15)
Block(1,46,-1,LEAVES:15)
Block(4,46,-1,LEAVES:15)
Block(-1,46,0,LEAVES:15)
Block(0,46,0,LEAVES:15)
Block(1,46,0,LEAVES:15)
Block(3,46,0,LEAVES:15)
Block(4,46,0,LEAVES:15)
Block(-2,46,1,LEAVES:15)
Block(-1,46,1,LEAVES:15)
Block(0,46,1,LEAVES:15)
Block(2,46,1,LEAVES:15)
Block(3,46,1,LEAVES:15)
Block(-2,46,2,LEAVES:15)
Block(-1,46,2,LEAVES:15)
Block(1,46,2,LEAVES:15)
Block(3,46,2,LEAVES:15)
Block(4,46,2,LEAVES:15)
Block(5,46,2,LEAVES:15)
Block(6,46,2,LEAVES:15)
Block(4,46,3,LEAVES:15)
Block(4,46,4,LEAVES:15)
Block(6,46,5,LEAVES:15)
Block(1,47,-13,LEAVES:15)
Block(2,47,-13,LEAVES:15)
Block(1,47,-12,LEAVES:15)
Block(2,47,-12,LEAVES:15)
Block(-2,47,-11,LEAVES:15)
Block(-2,47,-10,LEAVES:15)
Block(3,47,-10,LEAVES:15)
Block(4,47,-10,LEAVES:15)
Block(0,47,-9,LEAVES:15)
Block(3,47,-9,LEAVES:15)
Block(4,47,-9,LEAVES:15)
Block(1,47,-7,LEAVES:15)
Block(1,47,-6,LEAVES:15)
Block(-1,47,-5,LEAVES:15)
Block(0,47,-5,LEAVES:15)
Block(-1,47,-4,LEAVES:15)
Block(0,47,-4,LEAVES:15)
Block(-4,47,-3,LEAVES:15)
Block(-4,47,-2,LEAVES:15)
Block(1,47,-2,LEAVES:15)
Block(2,47,-2,LEAVES:15)
Block(4,47,-2,LEAVES:15)
Block(5,47,-2,LEAVES:15)
Block(-2,47,-1,LEAVES:15)
Block(1,47,-1,LEAVES:15)
Block(2,47,-1,LEAVES:15)
Block(4,47,-1,LEAVES:15)
Block(5,47,-1,LEAVES:15)
Block(1,47,0,LEAVES:15)
Block(-1,47,1,LEAVES:15)
Block(1,47,1,LEAVES:15)
Block(6,47,1,LEAVES:15)
Block(7,47,1,LEAVES:15)
Block(-1,47,2,LEAVES:15)
Block(3,47,2,LEAVES:15)
Block(6,47,2,LEAVES:15)
Block(7,47,2,LEAVES:15)
Block(4,47,4,LEAVES:15)
Block(4,47,5,LEAVES:15)
Block(0,48,-10,LEAVES:15)
Block(0,48,-9,LEAVES:15)
Block(-2,48,-2,LEAVES:15)
Block(-2,48,-1,LEAVES:15)
Block(3,48,1,LEAVES:15)
Block(3,48,2,LEAVES:15)

#######################################################################
# +-----------------------------------------------------------------+ #
# |                            BO3 checks                           | #
# +-----------------------------------------------------------------+ #
#######################################################################

# Require a condition at a certain location in order for the BO3 to be spawned.
# BlockCheck(x,y,z,BlockName[,BlockName[,...]]) - one of the blocks must be at the location
# BlockCheckNot(x,y,z,BlockName[,BlockName[,...]]) - all the blocks must not be at the location
# LightCheck(x,y,z,minLightLevel,maxLightLevel) - light must be between min and max (inclusive)

# You can use "Solid" as a BlockName for matching all solid blocks or "All" to match all blocks that aren't air.

# Examples:
BlockCheck(0,-1,0,GRASS,DIRT,DIRT:2,SAND,CLAY,STONE)
#   BlockCheck(0,-1,0,Solid)       Require any solid block just below the object
#   BlockCheck(0,-1,0,WOOL)        Require any type of wool just below the object
#   BlockCheck(0,-1,0,WOOL:0)      Require white wool just below the object
#   BlockCheckNot(0,-1,0,WOOL:0)   Require that there is no white wool below the object
#   LightCheck(0,0,0,0,1)          Require almost complete darkness just below the object

#######################################################################
# +-----------------------------------------------------------------+ #
# |                             Branches                            | #
# +-----------------------------------------------------------------+ #
#######################################################################

# Branches are objects that will spawn when this object spawns when it is used in
# the CustomStructure resource. Branches can also have branches, making complex
# structures possible. See the wiki for more details.

# Regular Branches spawn each branch with an independent chance of spawning.
# Branch(x,y,z,branchName,rotation,chance[,anotherBranchName,rotation,chance[,...]][IndividualChance])
# branchName - name of the object to spawn.
# rotation - NORTH, SOUTH, EAST or WEST.
# IndividualChance - The chance each branch has to spawn, assumed to be 100 when left blank

# Weighted Branches spawn branches with a dependent chance of spawning.
# WeightedBranch(x,y,z,branchName,rotation,chance[,anotherBranchName,rotation,chance[,...]][MaxChanceOutOf])
# MaxChanceOutOf - The chance all branches have to spawn out of, assumed to be 100 when left blank
