#######################################################################
# +-----------------------------------------------------------------+ #
# |                            BO3 object                           | #
# +-----------------------------------------------------------------+ #
#######################################################################

# This is the config file of a custom object.
# If you add this object correctly to your BiomeConfigs, it will spawn in the world.

# This is the creator of this BO3 object
Author: BO3 BulkEdit (by LanToaster)

# A short description of this BO3 object
Description: This Object was Created with BO3_BulkEdit

# The BO3 version, don't change this! It can be used by external applications to do a version check.
Version: 3

# The settings mode, WriteAll, WriteWithoutComments or WriteDisable. See WorldConfig.
SettingsMode: WriteDisable


#######################################################################
# +-----------------------------------------------------------------+ #
# |                          Main settings                          | #
# +-----------------------------------------------------------------+ #
#######################################################################

# This needs to be set to true to spawn the object in the Tree and Sapling resources.
Tree: true

# The frequency of the BO3 from 1 to 200. Tries this many times to spawn this BO3 when using the CustomObject(...) resource.
# Ignored by Tree(..), Sapling(..) and CustomStructure(..)
Frequency: 1

# The rarity of the BO3 from 0 to 100. Each spawn attempt has rarity% chance to succeed when using the CustomObject(...) resource.
# Ignored by Tree(..), Sapling(..) and CustomStructure(..)
Rarity: 100.0

# If you set this to true, the BO3 will be placed with a random rotation.
RotateRandomly: true

# The spawn height of the BO3 - randomY, highestBlock or highestSolidBlock.
SpawnHeight: highestSolidBlock

# The height limits for the BO3.
MinHeight: 0

MaxHeight: 256

# Objects can have other objects attacthed to it: branches. Branches can also
# have branches attached to it, which can also have branches, etc. This is the
# maximum branch depth for this objects.
MaxBranchDepth: 10

# When spawned with the UseWorld keyword, this BO3 should NOT spawn in the following biomes.
# If you writer.write the BO3 name directly in the BiomeConfigs, this will be ignored.
ExcludedBiomes: All


#######################################################################
# +-----------------------------------------------------------------+ #
# |                      Source block settings                      | #
# +-----------------------------------------------------------------+ #
#######################################################################

# The block(s) the BO3 should spawn in.
SourceBlocks: AIR

# The maximum percentage of the BO3 that can be outside the SourceBlock.
# The BO3 won't be placed on a location with more blocks outside the SourceBlock than this percentage.
MaxPercentageOutsideSourceBlock: 0

# What to do when a block is about to be placed outside the SourceBlock? (dontPlace, placeAnyway)
OutsideSourceBlock: dontPlace


#######################################################################
# +-----------------------------------------------------------------+ #
# |                              Blocks                             | #
# +-----------------------------------------------------------------+ #
#######################################################################

# All the blocks used in the BO3 are listed here. Possible blocks:
# Block(x,y,z,id[.data][,nbtfile.nbt)
# RandomBlock(x,y,z,id[:data][,nbtfile.nbt],chance[,id[:data][,nbtfile.nbt],chance[,...]])
# So RandomBlock(0,0,0,CHEST,chest.nbt,50,CHEST,anotherchest.nbt,100) will spawn a chest at
# the BO3 origin, and give it a 50% chance to have the contents of chest.nbt, or, if that
# fails, a 100% percent chance to have the contents of anotherchest.nbt.
Block(3,0,-7,LOG2:12)
Block(2,0,-6,LOG2:12)
Block(3,0,-6,LOG2:12)
Block(4,0,-6,LOG2:12)
Block(0,0,-5,LOG2:12)
Block(2,0,-5,LOG2:12)
Block(3,0,-5,LOG2:12)
Block(4,0,-5,LOG2:12)
Block(1,0,-4,LOG2:12)
Block(2,0,-4,LOG2:12)
Block(3,0,-4,LOG2:12)
Block(2,0,-3,LOG2:12)
Block(3,0,-3,LOG2:12)
Block(4,0,-2,LOG2:12)
Block(3,1,-6,LOG2:12)
Block(4,1,-6,LOG2:12)
Block(2,1,-5,LOG2:12)
Block(3,1,-5,LOG2:12)
Block(1,1,-4,LOG2:12)
Block(2,1,-4,LOG2:12)
Block(3,1,-4,LOG2:12)
Block(3,1,-3,LOG2:12)
Block(3,2,-6,LOG2:12)
Block(2,2,-5,LOG2:12)
Block(3,2,-5,LOG2:12)
Block(2,2,-4,LOG2:12)
Block(3,2,-4,LOG2:12)
Block(9,2,1,LEAVES:15)
Block(8,2,2,LEAVES:15)
Block(9,3,-10,LEAVES:15)
Block(11,3,-10,LEAVES:15)
Block(11,3,-9,LEAVES:15)
Block(-7,3,-8,LEAVES:15)
Block(-6,3,-7,LEAVES:15)
Block(-8,3,-6,LEAVES:15)
Block(3,3,-6,LOG2:12)
Block(2,3,-5,LOG2:12)
Block(3,3,-5,LOG2:12)
Block(2,3,-4,LOG2:12)
Block(7,3,0,LEAVES:15)
Block(8,3,0,LEAVES:15)
Block(10,3,0,LEAVES:15)
Block(9,3,1,LEAVES:15)
Block(11,3,1,LEAVES:15)
Block(9,3,3,LEAVES:15)
Block(11,3,3,LEAVES:15)
Block(7,3,4,LEAVES:15)
Block(10,4,-11,LEAVES:15)
Block(8,4,-10,LEAVES:15)
Block(9,4,-10,LEAVES:15)
Block(10,4,-10,LEAVES:15)
Block(12,4,-10,LEAVES:15)
Block(-7,4,-9,LEAVES:15)
Block(-6,4,-9,LEAVES:15)
Block(-5,4,-9,LEAVES:15)
Block(11,4,-9,LEAVES:15)
Block(-7,4,-8,LEAVES:15)
Block(9,4,-8,LEAVES:15)
Block(-9,4,-7,LEAVES:15)
Block(-8,4,-7,LEAVES:15)
Block(-7,4,-7,LEAVES:15)
Block(-6,4,-7,LEAVES:15)
Block(10,4,-7,LEAVES:15)
Block(-9,4,-6,LEAVES:15)
Block(-7,4,-6,LEAVES:15)
Block(-6,4,-6,LEAVES:15)
Block(-5,4,-6,LEAVES:15)
Block(-3,4,-5,LEAVES:15)
Block(2,4,-5,LOG2:12)
Block(3,4,-5,LOG2:12)
Block(-5,4,-4,LEAVES:15)
Block(2,4,-4,LOG2:12)
Block(3,4,-4,LOG2:12)
Block(8,4,0,LEAVES:15)
Block(9,4,0,LEAVES:15)
Block(9,4,1,LEAVES:15)
Block(10,4,1,LEAVES:15)
Block(12,4,1,LEAVES:15)
Block(6,4,2,LEAVES:15)
Block(7,4,2,LEAVES:15)
Block(10,4,2,LEAVES:15)
Block(11,4,2,LEAVES:15)
Block(12,4,2,LEAVES:15)
Block(6,4,3,LEAVES:15)
Block(8,4,3,LEAVES:15)
Block(11,4,3,LEAVES:15)
Block(7,4,4,LEAVES:15)
Block(8,4,4,LEAVES:15)
Block(9,4,4,LEAVES:15)
Block(8,4,5,LEAVES:15)
Block(11,5,-12,LEAVES:15)
Block(11,5,-11,LEAVES:15)
Block(12,5,-11,LEAVES:15)
Block(-8,5,-10,LEAVES:15)
Block(-6,5,-10,LEAVES:15)
Block(9,5,-10,LEAVES:15)
Block(11,5,-10,LEAVES:15)
Block(12,5,-10,LEAVES:15)
Block(13,5,-10,LEAVES:15)
Block(-7,5,-9,LOG2:12)
Block(-5,5,-9,LEAVES:15)
Block(7,5,-9,LEAVES:15)
Block(9,5,-9,LEAVES:15)
Block(-10,5,-8,LEAVES:15)
Block(-9,5,-8,LEAVES:15)
Block(-8,5,-8,LEAVES:15)
Block(-7,5,-8,LOG2:12)
Block(-4,5,-8,LEAVES:15)
Block(10,5,-8,LEAVES:15)
Block(11,5,-8,LEAVES:15)
Block(-10,5,-7,LEAVES:15)
Block(-6,5,-7,LEAVES:15)
Block(-5,5,-7,LEAVES:15)
Block(-4,5,-7,LEAVES:15)
Block(8,5,-7,LEAVES:15)
Block(10,5,-7,LEAVES:15)
Block(12,5,-7,LEAVES:15)
Block(-10,5,-6,LEAVES:15)
Block(-9,5,-6,LEAVES:15)
Block(-7,5,-6,LEAVES:15)
Block(-6,5,-6,LEAVES:15)
Block(9,5,-6,LEAVES:15)
Block(10,5,-6,LEAVES:15)
Block(11,5,-6,LEAVES:15)
Block(-8,5,-5,LEAVES:15)
Block(-7,5,-5,LEAVES:15)
Block(2,5,-5,LOG2:12)
Block(8,5,-5,LEAVES:15)
Block(-4,5,-4,LEAVES:15)
Block(-2,5,-4,LEAVES:15)
Block(1,5,-4,LOG2:12)
Block(2,5,-4,LOG2:12)
Block(3,5,-4,LOG2:12)
Block(8,5,-4,LEAVES:15)
Block(-7,5,-3,LEAVES:15)
Block(-6,5,-3,LEAVES:15)
Block(-5,5,-3,LEAVES:15)
Block(-3,5,-3,LEAVES:15)
Block(3,5,-3,LOG2:12)
Block(5,5,-3,LEAVES:15)
Block(-6,5,-2,LEAVES:15)
Block(-5,5,-2,LEAVES:15)
Block(-4,5,-2,LEAVES:15)
Block(5,5,-2,LEAVES:15)
Block(6,5,-2,LEAVES:15)
Block(7,5,-2,LEAVES:15)
Block(8,5,-2,LEAVES:15)
Block(5,5,-1,LEAVES:15)
Block(8,5,-1,LEAVES:15)
Block(9,5,-1,LEAVES:15)
Block(7,5,0,LEAVES:15)
Block(10,5,0,LEAVES:15)
Block(6,5,1,LEAVES:15)
Block(8,5,1,LEAVES:15)
Block(9,5,1,LOG2:12)
Block(10,5,1,LEAVES:15)
Block(6,5,2,LEAVES:15)
Block(9,5,2,LOG2:12)
Block(6,5,3,LEAVES:15)
Block(8,5,3,LOG2:12)
Block(9,5,3,LEAVES:15)
Block(9,5,4,LEAVES:15)
Block(8,5,5,LEAVES:15)
Block(11,6,-12,LEAVES:15)
Block(-6,6,-10,LEAVES:15)
Block(10,6,-10,LEAVES:15)
Block(13,6,-10,LEAVES:15)
Block(-7,6,-9,LEAVES:15)
Block(-5,6,-9,LEAVES:15)
Block(10,6,-9,LOG2:12)
Block(-10,6,-8,LEAVES:15)
Block(6,6,-8,LEAVES:15)
Block(8,6,-8,LEAVES:15)
Block(9,6,-8,LEAVES:15)
Block(10,6,-8,LEAVES:15)
Block(11,6,-8,LOG2:12)
Block(13,6,-8,LEAVES:15)
Block(-7,6,-7,LOG2:12)
Block(-6,6,-7,LOG2:12)
Block(-5,6,-7,LEAVES:15)
Block(-3,6,-7,LEAVES:15)
Block(-2,6,-7,LEAVES:15)
Block(4,6,-7,LEAVES:15)
Block(6,6,-7,LEAVES:15)
Block(7,6,-7,LEAVES:15)
Block(10,6,-7,LEAVES:15)
Block(11,6,-7,LEAVES:15)
Block(12,6,-7,LEAVES:15)
Block(-9,6,-6,LEAVES:15)
Block(-7,6,-6,LOG2:12)
Block(-6,6,-6,LOG2:12)
Block(-5,6,-6,LEAVES:15)
Block(5,6,-6,LEAVES:15)
Block(6,6,-6,LEAVES:15)
Block(11,6,-6,LEAVES:15)
Block(-7,6,-5,LEAVES:15)
Block(-6,6,-5,LEAVES:15)
Block(-5,6,-5,LEAVES:15)
Block(-3,6,-5,LEAVES:15)
Block(-2,6,-5,LEAVES:15)
Block(-1,6,-5,LEAVES:15)
Block(7,6,-5,LEAVES:15)
Block(11,6,-5,LEAVES:15)
Block(-8,6,-4,LEAVES:15)
Block(1,6,-4,LOG2:12)
Block(2,6,-4,LOG2:12)
Block(3,6,-4,LOG2:12)
Block(4,6,-4,LOG2:12)
Block(7,6,-4,LEAVES:15)
Block(8,6,-4,LEAVES:15)
Block(-7,6,-3,LEAVES:15)
Block(-6,6,-3,LEAVES:15)
Block(1,6,-3,LOG2:12)
Block(3,6,-3,LOG2:12)
Block(4,6,-3,LEAVES:15)
Block(5,6,-3,LEAVES:15)
Block(6,6,-3,LEAVES:15)
Block(-6,6,-2,LEAVES:15)
Block(-3,6,-2,LEAVES:15)
Block(4,6,-2,LEAVES:15)
Block(3,6,-1,LEAVES:15)
Block(4,6,-1,LEAVES:15)
Block(7,6,-1,LEAVES:15)
Block(10,6,-1,LEAVES:15)
Block(8,6,0,LOG2:12)
Block(9,6,0,LOG2:12)
Block(10,6,0,LEAVES:15)
Block(5,6,1,LEAVES:15)
Block(6,6,1,LEAVES:15)
Block(9,6,1,LOG2:12)
Block(11,6,1,LEAVES:15)
Block(8,6,2,LEAVES:15)
Block(11,6,2,LEAVES:15)
Block(6,6,3,LEAVES:15)
Block(7,6,3,LEAVES:15)
Block(10,6,3,LEAVES:15)
Block(8,6,4,LEAVES:15)
Block(9,6,4,LEAVES:15)
Block(11,6,4,LEAVES:15)
Block(9,6,5,LEAVES:15)
Block(9,7,-12,LEAVES:15)
Block(10,7,-12,LEAVES:15)
Block(11,7,-12,LEAVES:15)
Block(-8,7,-10,LEAVES:15)
Block(9,7,-10,LEAVES:15)
Block(11,7,-10,LEAVES:15)
Block(12,7,-10,LEAVES:15)
Block(13,7,-10,LEAVES:15)
Block(-9,7,-9,LEAVES:15)
Block(-6,7,-9,LEAVES:15)
Block(-4,7,-9,LEAVES:15)
Block(-2,7,-9,LEAVES:15)
Block(0,7,-9,LEAVES:15)
Block(6,7,-9,LEAVES:15)
Block(9,7,-9,LOG2:12)
Block(10,7,-9,LEAVES:15)
Block(11,7,-9,LEAVES:15)
Block(-7,7,-8,LEAVES:15)
Block(-6,7,-8,LEAVES:15)
Block(-4,7,-8,LEAVES:15)
Block(-2,7,-8,LEAVES:15)
Block(4,7,-8,LEAVES:15)
Block(6,7,-8,LEAVES:15)
Block(8,7,-8,LOG2:12)
Block(9,7,-8,LOG2:12)
Block(10,7,-8,LEAVES:15)
Block(11,7,-8,LEAVES:15)
Block(-8,7,-7,LEAVES:15)
Block(-7,7,-7,LEAVES:15)
Block(-5,7,-7,LEAVES:15)
Block(-4,7,-7,LEAVES:15)
Block(-2,7,-7,LEAVES:15)
Block(1,7,-7,LEAVES:15)
Block(4,7,-7,LEAVES:15)
Block(5,7,-7,LEAVES:15)
Block(6,7,-7,LEAVES:15)
Block(7,7,-7,LEAVES:15)
Block(9,7,-7,LEAVES:15)
Block(10,7,-7,LEAVES:15)
Block(11,7,-7,LEAVES:15)
Block(-10,7,-6,LEAVES:15)
Block(-9,7,-6,LEAVES:15)
Block(-7,7,-6,LEAVES:15)
Block(-6,7,-6,LOG2:12)
Block(-5,7,-6,LEAVES:15)
Block(-4,7,-6,LEAVES:15)
Block(-2,7,-6,LEAVES:15)
Block(-1,7,-6,LEAVES:15)
Block(0,7,-6,LEAVES:15)
Block(2,7,-6,LEAVES:15)
Block(4,7,-6,LEAVES:15)
Block(6,7,-6,LEAVES:15)
Block(8,7,-6,LEAVES:15)
Block(11,7,-6,LEAVES:15)
Block(12,7,-6,LEAVES:15)
Block(-8,7,-5,LEAVES:15)
Block(-6,7,-5,LOG2:12)
Block(-5,7,-5,LOG2:12)
Block(-4,7,-5,LEAVES:15)
Block(4,7,-5,LEAVES:15)
Block(5,7,-5,LEAVES:15)
Block(8,7,-5,LEAVES:15)
Block(-7,7,-4,LEAVES:15)
Block(-5,7,-4,LOG2:12)
Block(-4,7,-4,LOG2:12)
Block(0,7,-4,LOG2:12)
Block(1,7,-4,LOG2:12)
Block(2,7,-4,LEAVES:15)
Block(3,7,-4,LOG2:12)
Block(5,7,-4,LEAVES:15)
Block(9,7,-4,LEAVES:15)
Block(-8,7,-3,LEAVES:15)
Block(-6,7,-3,LEAVES:15)
Block(-5,7,-3,LEAVES:15)
Block(-4,7,-3,LEAVES:15)
Block(-2,7,-3,LEAVES:15)
Block(-1,7,-3,LEAVES:15)
Block(1,7,-3,LOG2:12)
Block(3,7,-3,LOG2:12)
Block(4,7,-3,LOG2:12)
Block(6,7,-3,LEAVES:15)
Block(8,7,-3,LEAVES:15)
Block(-8,7,-2,LEAVES:15)
Block(-7,7,-2,LEAVES:15)
Block(-3,7,-2,LEAVES:15)
Block(0,7,-2,LEAVES:15)
Block(4,7,-2,LEAVES:15)
Block(5,7,-2,LEAVES:15)
Block(7,7,-2,LEAVES:15)
Block(8,7,-2,LEAVES:15)
Block(9,7,-2,LEAVES:15)
Block(3,7,-1,LEAVES:15)
Block(4,7,-1,LEAVES:15)
Block(6,7,-1,LOG2:12)
Block(7,7,-1,LOG2:12)
Block(8,7,-1,LEAVES:15)
Block(-6,7,0,LEAVES:15)
Block(-5,7,0,LEAVES:15)
Block(-4,7,0,LEAVES:15)
Block(6,7,0,LEAVES:15)
Block(7,7,0,LOG2:12)
Block(8,7,0,LOG2:12)
Block(9,7,0,LEAVES:15)
Block(5,7,1,LEAVES:15)
Block(6,7,1,LEAVES:15)
Block(9,7,2,LEAVES:15)
Block(10,7,2,LEAVES:15)
Block(7,7,3,LEAVES:15)
Block(8,7,3,LEAVES:15)
Block(9,7,3,LEAVES:15)
Block(8,7,4,LEAVES:15)
Block(9,7,4,LEAVES:15)
Block(-2,8,-11,LEAVES:15)
Block(8,8,-11,LEAVES:15)
Block(10,8,-11,LEAVES:15)
Block(11,8,-11,LEAVES:15)
Block(-1,8,-10,LEAVES:15)
Block(10,8,-10,LEAVES:15)
Block(12,8,-10,LEAVES:15)
Block(-8,8,-9,LEAVES:15)
Block(-5,8,-9,LEAVES:15)
Block(-2,8,-9,LEAVES:15)
Block(0,8,-9,LEAVES:15)
Block(2,8,-9,LEAVES:15)
Block(4,8,-9,LEAVES:15)
Block(6,8,-9,LEAVES:15)
Block(10,8,-9,LEAVES:15)
Block(12,8,-9,LEAVES:15)
Block(-8,8,-8,LEAVES:15)
Block(-7,8,-8,LEAVES:15)
Block(-5,8,-8,LEAVES:15)
Block(-2,8,-8,LEAVES:15)
Block(-1,8,-8,LEAVES:15)
Block(1,8,-8,LEAVES:15)
Block(5,8,-8,LEAVES:15)
Block(8,8,-8,LOG2:12)
Block(9,8,-8,LEAVES:15)
Block(10,8,-8,LEAVES:15)
Block(11,8,-8,LEAVES:15)
Block(12,8,-8,LEAVES:15)
Block(-8,8,-7,LEAVES:15)
Block(-7,8,-7,LEAVES:15)
Block(-3,8,-7,LEAVES:15)
Block(-1,8,-7,LEAVES:15)
Block(6,8,-7,LEAVES:15)
Block(7,8,-7,LOG2:12)
Block(8,8,-7,LOG2:12)
Block(9,8,-7,LEAVES:15)
Block(12,8,-7,LEAVES:15)
Block(-9,8,-6,LEAVES:15)
Block(-6,8,-6,LEAVES:15)
Block(-4,8,-6,LEAVES:15)
Block(-1,8,-6,LEAVES:15)
Block(1,8,-6,LEAVES:15)
Block(6,8,-6,LEAVES:15)
Block(7,8,-6,LOG2:12)
Block(8,8,-6,LEAVES:15)
Block(12,8,-6,LEAVES:15)
Block(-9,8,-5,LEAVES:15)
Block(-8,8,-5,LEAVES:15)
Block(-4,8,-5,LOG2:12)
Block(2,8,-5,LEAVES:15)
Block(9,8,-5,LEAVES:15)
Block(12,8,-5,LEAVES:15)
Block(-7,8,-4,LEAVES:15)
Block(-5,8,-4,LOG2:12)
Block(-4,8,-4,LOG2:12)
Block(-3,8,-4,LOG2:12)
Block(0,8,-4,LOG2:12)
Block(1,8,-4,LOG2:12)
Block(4,8,-4,LOG2:12)
Block(6,8,-4,LEAVES:15)
Block(7,8,-4,LEAVES:15)
Block(9,8,-4,LEAVES:15)
Block(10,8,-4,LEAVES:15)
Block(11,8,-4,LEAVES:15)
Block(-4,8,-3,LOG2:12)
Block(-3,8,-3,LOG2:12)
Block(-2,8,-3,LOG2:12)
Block(0,8,-3,LOG2:12)
Block(1,8,-3,LOG2:12)
Block(3,8,-3,LOG2:12)
Block(4,8,-3,LOG2:12)
Block(8,8,-3,LEAVES:15)
Block(-4,8,-2,LEAVES:15)
Block(-1,8,-2,LEAVES:15)
Block(0,8,-2,LOG2:12)
Block(1,8,-2,LOG2:12)
Block(7,8,-2,LOG2:12)
Block(-7,8,-1,LEAVES:15)
Block(-6,8,-1,LEAVES:15)
Block(-4,8,-1,LEAVES:15)
Block(-3,8,-1,LEAVES:15)
Block(-1,8,-1,LEAVES:15)
Block(0,8,-1,LEAVES:15)
Block(3,8,-1,LEAVES:15)
Block(5,8,-1,LEAVES:15)
Block(6,8,-1,LOG2:12)
Block(7,8,-1,LOG2:12)
Block(8,8,-1,LEAVES:15)
Block(-7,8,0,LEAVES:15)
Block(-5,8,0,LEAVES:15)
Block(-4,8,0,LEAVES:15)
Block(-3,8,0,LEAVES:15)
Block(-1,8,0,LEAVES:15)
Block(3,8,0,LEAVES:15)
Block(-6,8,1,LEAVES:15)
Block(-1,8,1,LEAVES:15)
Block(4,8,1,LEAVES:15)
Block(7,8,1,LEAVES:15)
Block(8,8,1,LEAVES:15)
Block(5,8,2,LEAVES:15)
Block(7,8,2,LEAVES:15)
Block(8,8,2,LEAVES:15)
Block(4,8,3,LEAVES:15)
Block(6,8,3,LEAVES:15)
Block(7,8,3,LEAVES:15)
Block(8,8,3,LEAVES:15)
Block(6,8,4,LEAVES:15)
Block(-10,8,5,LEAVES:15)
Block(-9,8,5,LEAVES:15)
Block(-9,8,6,LEAVES:15)
Block(0,8,7,LEAVES:15)
Block(2,8,7,LEAVES:15)
Block(1,8,8,LEAVES:15)
Block(-2,9,-12,LEAVES:15)
Block(-2,9,-11,LEAVES:15)
Block(-1,9,-11,LEAVES:15)
Block(-4,9,-10,LEAVES:15)
Block(-5,9,-9,LEAVES:15)
Block(6,9,-9,LEAVES:15)
Block(7,9,-9,LEAVES:15)
Block(9,9,-9,LEAVES:15)
Block(-7,9,-8,LEAVES:15)
Block(-4,9,-8,LEAVES:15)
Block(0,9,-8,LEAVES:15)
Block(1,9,-8,LEAVES:15)
Block(3,9,-8,LEAVES:15)
Block(5,9,-8,LEAVES:15)
Block(6,9,-8,LEAVES:15)
Block(7,9,-8,LEAVES:15)
Block(10,9,-8,LEAVES:15)
Block(11,9,-8,LEAVES:15)
Block(-5,9,-7,LEAVES:15)
Block(-4,9,-7,LEAVES:15)
Block(-3,9,-7,LEAVES:15)
Block(-2,9,-7,LEAVES:15)
Block(1,9,-7,LEAVES:15)
Block(8,9,-7,LEAVES:15)
Block(11,9,-7,LEAVES:15)
Block(12,9,-7,LEAVES:15)
Block(-7,9,-6,LEAVES:15)
Block(-6,9,-6,LEAVES:15)
Block(-5,9,-6,LEAVES:15)
Block(-4,9,-6,LEAVES:15)
Block(-1,9,-6,LEAVES:15)
Block(0,9,-6,LEAVES:15)
Block(1,9,-6,LEAVES:15)
Block(4,9,-6,LEAVES:15)
Block(6,9,-6,LEAVES:15)
Block(7,9,-6,LOG2:12)
Block(8,9,-6,LOG2:12)
Block(-8,9,-5,LEAVES:15)
Block(-7,9,-5,LEAVES:15)
Block(-6,9,-5,LEAVES:15)
Block(-1,9,-5,LEAVES:15)
Block(1,9,-5,LEAVES:15)
Block(2,9,-5,LEAVES:15)
Block(4,9,-5,LEAVES:15)
Block(6,9,-5,LOG2:12)
Block(7,9,-5,LOG2:12)
Block(9,9,-5,LEAVES:15)
Block(10,9,-5,LEAVES:15)
Block(-6,9,-4,LEAVES:15)
Block(-5,9,-4,LEAVES:15)
Block(-4,9,-4,LEAVES:15)
Block(-3,9,-4,LEAVES:15)
Block(-2,9,-4,LOG2:12)
Block(-1,9,-4,LEAVES:15)
Block(0,9,-4,LOG2:12)
Block(1,9,-4,LEAVES:15)
Block(4,9,-4,LOG2:12)
Block(5,9,-4,LOG2:12)
Block(6,9,-4,LOG2:12)
Block(8,9,-4,LEAVES:15)
Block(12,9,-4,LEAVES:15)
Block(-8,9,-3,LEAVES:15)
Block(-6,9,-3,LEAVES:15)
Block(-4,9,-3,LEAVES:15)
Block(-3,9,-3,LOG2:12)
Block(-2,9,-3,LOG2:12)
Block(-1,9,-3,LOG2:12)
Block(0,9,-3,LOG2:12)
Block(1,9,-3,LOG2:12)
Block(4,9,-3,LOG2:12)
Block(5,9,-3,LOG2:12)
Block(6,9,-3,LOG2:12)
Block(8,9,-3,LEAVES:15)
Block(11,9,-3,LEAVES:15)
Block(-3,9,-2,LEAVES:15)
Block(-2,9,-2,LOG2:12)
Block(-1,9,-2,LOG2:12)
Block(0,9,-2,LOG2:12)
Block(1,9,-2,LOG2:12)
Block(4,9,-2,LEAVES:15)
Block(5,9,-2,LOG2:12)
Block(6,9,-2,LOG2:12)
Block(10,9,-2,LEAVES:15)
Block(-6,9,-1,LEAVES:15)
Block(-4,9,-1,LEAVES:15)
Block(-1,9,-1,LEAVES:15)
Block(0,9,-1,LEAVES:15)
Block(1,9,-1,LEAVES:15)
Block(2,9,-1,LEAVES:15)
Block(3,9,-1,LEAVES:15)
Block(6,9,-1,LOG2:12)
Block(7,9,-1,LEAVES:15)
Block(8,9,-1,LEAVES:15)
Block(9,9,-1,LEAVES:15)
Block(10,9,-1,LEAVES:15)
Block(-5,9,0,LEAVES:15)
Block(-3,9,0,LEAVES:15)
Block(-2,9,0,LEAVES:15)
Block(-1,9,0,LEAVES:15)
Block(4,9,0,LEAVES:15)
Block(-6,9,1,LEAVES:15)
Block(-3,9,1,LEAVES:15)
Block(-2,9,1,LEAVES:15)
Block(-1,9,1,LEAVES:15)
Block(0,9,1,LEAVES:15)
Block(8,9,1,LEAVES:15)
Block(9,9,1,LEAVES:15)
Block(-6,9,2,LEAVES:15)
Block(-2,9,2,LEAVES:15)
Block(-1,9,2,LEAVES:15)
Block(0,9,2,LEAVES:15)
Block(1,9,2,LEAVES:15)
Block(4,9,2,LEAVES:15)
Block(5,9,2,LEAVES:15)
Block(-6,9,3,LEAVES:15)
Block(-5,9,3,LEAVES:15)
Block(-1,9,3,LEAVES:15)
Block(3,9,3,LEAVES:15)
Block(6,9,3,LEAVES:15)
Block(7,9,3,LEAVES:15)
Block(-10,9,4,LEAVES:15)
Block(-8,9,4,LEAVES:15)
Block(-7,9,4,LEAVES:15)
Block(-5,9,4,LEAVES:15)
Block(3,9,4,LEAVES:15)
Block(8,9,4,LEAVES:15)
Block(7,9,5,LEAVES:15)
Block(-8,9,6,LEAVES:15)
Block(-1,9,6,LEAVES:15)
Block(5,9,6,LEAVES:15)
Block(7,9,6,LEAVES:15)
Block(-11,9,7,LEAVES:15)
Block(-9,9,7,LEAVES:15)
Block(0,9,7,LEAVES:15)
Block(2,9,7,LEAVES:15)
Block(-8,9,8,LEAVES:15)
Block(2,9,8,LEAVES:15)
Block(-1,9,9,LEAVES:15)
Block(0,9,9,LEAVES:15)
Block(3,9,9,LEAVES:15)
Block(2,9,10,LEAVES:15)
Block(3,9,10,LEAVES:15)
Block(-3,10,-11,LEAVES:15)
Block(-3,10,-10,LEAVES:15)
Block(-2,10,-10,LEAVES:15)
Block(7,10,-10,LEAVES:15)
Block(-5,10,-9,LEAVES:15)
Block(-4,10,-9,LEAVES:15)
Block(5,10,-9,LEAVES:15)
Block(8,10,-9,LEAVES:15)
Block(10,10,-9,LEAVES:15)
Block(11,10,-9,LEAVES:15)
Block(-7,10,-8,LEAVES:15)
Block(0,10,-8,LEAVES:15)
Block(4,10,-8,LEAVES:15)
Block(5,10,-8,LEAVES:15)
Block(10,10,-8,LEAVES:15)
Block(11,10,-8,LEAVES:15)
Block(-8,10,-7,LEAVES:15)
Block(-7,10,-7,LEAVES:15)
Block(1,10,-7,LEAVES:15)
Block(2,10,-7,LEAVES:15)
Block(3,10,-7,LEAVES:15)
Block(5,10,-7,LEAVES:15)
Block(12,10,-7,LEAVES:15)
Block(-6,10,-6,LEAVES:15)
Block(-3,10,-6,LEAVES:15)
Block(2,10,-6,LEAVES:15)
Block(6,10,-6,LEAVES:15)
Block(8,10,-6,LEAVES:15)
Block(-6,10,-5,LEAVES:15)
Block(-1,10,-5,LEAVES:15)
Block(1,10,-5,LEAVES:15)
Block(4,10,-5,LEAVES:15)
Block(6,10,-5,LOG2:12)
Block(7,10,-5,LEAVES:15)
Block(10,10,-5,LEAVES:15)
Block(11,10,-5,LEAVES:15)
Block(-7,10,-4,LEAVES:15)
Block(-2,10,-4,LEAVES:15)
Block(0,10,-4,LEAVES:15)
Block(4,10,-4,LEAVES:15)
Block(5,10,-4,LOG2:12)
Block(6,10,-4,LOG2:12)
Block(7,10,-4,LEAVES:15)
Block(-8,10,-3,LEAVES:15)
Block(-6,10,-3,LEAVES:15)
Block(-5,10,-3,LEAVES:15)
Block(-3,10,-3,LEAVES:15)
Block(-2,10,-3,LOG2:12)
Block(-1,10,-3,LOG2:12)
Block(0,10,-3,LOG2:12)
Block(2,10,-3,LEAVES:15)
Block(3,10,-3,LEAVES:15)
Block(5,10,-3,LOG2:12)
Block(6,10,-3,LEAVES:15)
Block(8,10,-3,LEAVES:15)
Block(9,10,-3,LEAVES:15)
Block(10,10,-3,LEAVES:15)
Block(-7,10,-2,LEAVES:15)
Block(-6,10,-2,LEAVES:15)
Block(-5,10,-2,LEAVES:15)
Block(-2,10,-2,LEAVES:15)
Block(-1,10,-2,LOG2:12)
Block(0,10,-2,LOG2:12)
Block(4,10,-2,LEAVES:15)
Block(6,10,-2,LEAVES:15)
Block(10,10,-2,LEAVES:15)
Block(-4,10,-1,LEAVES:15)
Block(-2,10,-1,LEAVES:15)
Block(-1,10,-1,LOG2:12)
Block(0,10,-1,LOG2:12)
Block(1,10,-1,LEAVES:15)
Block(2,10,-1,LEAVES:15)
Block(3,10,-1,LEAVES:15)
Block(4,10,-1,LEAVES:15)
Block(6,10,-1,LEAVES:15)
Block(7,10,-1,LEAVES:15)
Block(8,10,-1,LEAVES:15)
Block(9,10,-1,LEAVES:15)
Block(-4,10,0,LEAVES:15)
Block(-2,10,0,LEAVES:15)
Block(0,10,0,LOG2:12)
Block(1,10,0,LEAVES:15)
Block(3,10,0,LEAVES:15)
Block(8,10,0,LEAVES:15)
Block(-7,10,1,LEAVES:15)
Block(-4,10,1,LEAVES:15)
Block(-3,10,1,LEAVES:15)
Block(-2,10,1,LEAVES:15)
Block(-1,10,1,LEAVES:15)
Block(0,10,1,LEAVES:15)
Block(3,10,1,LEAVES:15)
Block(9,10,1,LEAVES:15)
Block(-8,10,2,LEAVES:15)
Block(-4,10,2,LEAVES:15)
Block(-2,10,2,LEAVES:15)
Block(-1,10,2,LEAVES:15)
Block(6,10,2,LEAVES:15)
Block(8,10,2,LEAVES:15)
Block(-10,10,3,LEAVES:15)
Block(-6,10,3,LEAVES:15)
Block(-3,10,3,LEAVES:15)
Block(3,10,3,LEAVES:15)
Block(6,10,3,LEAVES:15)
Block(7,10,3,LEAVES:15)
Block(-11,10,4,LEAVES:15)
Block(-3,10,4,LEAVES:15)
Block(8,10,4,LEAVES:15)
Block(-13,10,5,LEAVES:15)
Block(-12,10,5,LEAVES:15)
Block(-11,10,5,LOG2:12)
Block(-9,10,5,LEAVES:15)
Block(-6,10,5,LEAVES:15)
Block(-5,10,5,LEAVES:15)
Block(2,10,5,LEAVES:15)
Block(4,10,5,LEAVES:15)
Block(7,10,5,LEAVES:15)
Block(9,10,5,LEAVES:15)
Block(-9,10,6,LEAVES:15)
Block(-8,10,6,LEAVES:15)
Block(-2,10,6,LEAVES:15)
Block(-1,10,6,LEAVES:15)
Block(0,10,6,LEAVES:15)
Block(2,10,6,LEAVES:15)
Block(4,10,6,LEAVES:15)
Block(5,10,6,LEAVES:15)
Block(8,10,6,LEAVES:15)
Block(-11,10,7,LEAVES:15)
Block(-7,10,7,LEAVES:15)
Block(-5,10,7,LEAVES:15)
Block(-3,10,7,LEAVES:15)
Block(-1,10,7,LOG2:12)
Block(0,10,7,LOG2:12)
Block(1,10,7,LEAVES:15)
Block(2,10,7,LEAVES:15)
Block(6,10,7,LEAVES:15)
Block(-12,10,8,LEAVES:15)
Block(-9,10,8,LEAVES:15)
Block(-1,10,8,LEAVES:15)
Block(1,10,8,LEAVES:15)
Block(3,10,8,LEAVES:15)
Block(4,10,8,LEAVES:15)
Block(-10,10,9,LEAVES:15)
Block(-1,10,9,LEAVES:15)
Block(2,10,9,LEAVES:15)
Block(-1,10,10,LEAVES:15)
Block(0,10,10,LEAVES:15)
Block(2,10,10,LEAVES:15)
Block(3,10,10,LEAVES:15)
Block(0,10,11,LEAVES:15)
Block(1,10,11,LEAVES:15)
Block(-3,11,-9,LEAVES:15)
Block(-2,11,-9,LEAVES:15)
Block(8,11,-9,LEAVES:15)
Block(-4,11,-8,LEAVES:15)
Block(-2,11,-8,LEAVES:15)
Block(4,11,-8,LEAVES:15)
Block(9,11,-8,LEAVES:15)
Block(10,11,-8,LEAVES:15)
Block(-5,11,-7,LEAVES:15)
Block(-3,11,-7,LEAVES:15)
Block(0,11,-7,LEAVES:15)
Block(2,11,-7,LEAVES:15)
Block(11,11,-7,LEAVES:15)
Block(-7,11,-6,LEAVES:15)
Block(-6,11,-6,LEAVES:15)
Block(-2,11,-6,LEAVES:15)
Block(0,11,-6,LEAVES:15)
Block(2,11,-6,LEAVES:15)
Block(4,11,-6,LEAVES:15)
Block(5,11,-6,LEAVES:15)
Block(6,11,-6,LEAVES:15)
Block(7,11,-6,LEAVES:15)
Block(9,11,-6,LEAVES:15)
Block(10,11,-6,LEAVES:15)
Block(-5,11,-5,LEAVES:15)
Block(-4,11,-5,LEAVES:15)
Block(1,11,-5,LEAVES:15)
Block(5,11,-5,LEAVES:15)
Block(6,11,-5,LEAVES:15)
Block(8,11,-5,LEAVES:15)
Block(10,11,-5,LEAVES:15)
Block(11,11,-5,LEAVES:15)
Block(-8,11,-4,LEAVES:15)
Block(-5,11,-4,LEAVES:15)
Block(-3,11,-4,LEAVES:15)
Block(1,11,-4,LEAVES:15)
Block(2,11,-4,LEAVES:15)
Block(5,11,-4,LEAVES:15)
Block(7,11,-4,LEAVES:15)
Block(9,11,-4,LEAVES:15)
Block(-7,11,-3,LEAVES:15)
Block(-6,11,-3,LEAVES:15)
Block(-2,11,-3,LEAVES:15)
Block(-1,11,-3,LOG2:12)
Block(2,11,-3,LEAVES:15)
Block(7,11,-3,LEAVES:15)
Block(8,11,-3,LEAVES:15)
Block(10,11,-3,LEAVES:15)
Block(-6,11,-2,LEAVES:15)
Block(-4,11,-2,LEAVES:15)
Block(-1,11,-2,LOG2:12)
Block(0,11,-2,LOG2:12)
Block(2,11,-2,LEAVES:15)
Block(6,11,-2,LEAVES:15)
Block(9,11,-2,LEAVES:15)
Block(-2,11,-1,LEAVES:15)
Block(-1,11,-1,LOG2:12)
Block(0,11,-1,LOG2:12)
Block(2,11,-1,LEAVES:15)
Block(3,11,-1,LEAVES:15)
Block(8,11,-1,LEAVES:15)
Block(9,11,-1,LEAVES:15)
Block(-6,11,0,LEAVES:15)
Block(-5,11,0,LEAVES:15)
Block(-4,11,0,LEAVES:15)
Block(-3,11,0,LEAVES:15)
Block(-1,11,0,LEAVES:15)
Block(0,11,0,LOG2:12)
Block(4,11,0,LEAVES:15)
Block(8,11,0,LEAVES:15)
Block(9,11,0,LEAVES:15)
Block(-8,11,1,LEAVES:15)
Block(-7,11,1,LEAVES:15)
Block(-6,11,1,LEAVES:15)
Block(-2,11,1,LEAVES:15)
Block(-1,11,1,LEAVES:15)
Block(0,11,1,LOG2:12)
Block(2,11,1,LEAVES:15)
Block(3,11,1,LEAVES:15)
Block(5,11,1,LEAVES:15)
Block(7,11,1,LEAVES:15)
Block(-7,11,2,LEAVES:15)
Block(-3,11,2,LEAVES:15)
Block(-2,11,2,LEAVES:15)
Block(0,11,2,LEAVES:15)
Block(5,11,2,LEAVES:15)
Block(7,11,2,LEAVES:15)
Block(9,11,2,LEAVES:15)
Block(-11,11,3,LEAVES:15)
Block(-10,11,3,LEAVES:15)
Block(-9,11,3,LEAVES:15)
Block(-6,11,3,LEAVES:15)
Block(-5,11,3,LEAVES:15)
Block(-3,11,3,LEAVES:15)
Block(-2,11,3,LEAVES:15)
Block(0,11,3,LEAVES:15)
Block(3,11,3,LEAVES:15)
Block(4,11,3,LEAVES:15)
Block(7,11,3,LEAVES:15)
Block(8,11,3,LOG2:12)
Block(-11,11,4,LEAVES:15)
Block(-10,11,4,LEAVES:15)
Block(-8,11,4,LEAVES:15)
Block(-7,11,4,LEAVES:15)
Block(-6,11,4,LEAVES:15)
Block(-3,11,4,LEAVES:15)
Block(0,11,4,LEAVES:15)
Block(1,11,4,LEAVES:15)
Block(2,11,4,LEAVES:15)
Block(4,11,4,LEAVES:15)
Block(5,11,4,LEAVES:15)
Block(7,11,4,LOG2:12)
Block(8,11,4,LOG2:12)
Block(-13,11,5,LEAVES:15)
Block(-10,11,5,LEAVES:15)
Block(-9,11,5,LEAVES:15)
Block(-6,11,5,LEAVES:15)
Block(-2,11,5,LEAVES:15)
Block(-1,11,5,LEAVES:15)
Block(6,11,5,LEAVES:15)
Block(-13,11,6,LEAVES:15)
Block(-12,11,6,LEAVES:15)
Block(-10,11,6,LOG2:12)
Block(-9,11,6,LOG2:12)
Block(-8,11,6,LOG2:12)
Block(-7,11,6,LEAVES:15)
Block(-6,11,6,LEAVES:15)
Block(0,11,6,LEAVES:15)
Block(1,11,6,LEAVES:15)
Block(2,11,6,LEAVES:15)
Block(3,11,6,LEAVES:15)
Block(6,11,6,LEAVES:15)
Block(7,11,6,LEAVES:15)
Block(9,11,6,LEAVES:15)
Block(-7,11,7,LEAVES:15)
Block(-6,11,7,LEAVES:15)
Block(-5,11,7,LEAVES:15)
Block(-4,11,7,LEAVES:15)
Block(0,11,7,LEAVES:15)
Block(1,11,7,LEAVES:15)
Block(3,11,7,LEAVES:15)
Block(4,11,7,LEAVES:15)
Block(5,11,7,LEAVES:15)
Block(7,11,7,LEAVES:15)
Block(-12,11,8,LEAVES:15)
Block(-4,11,8,LEAVES:15)
Block(-3,11,8,LEAVES:15)
Block(-2,11,8,LEAVES:15)
Block(0,11,8,LOG2:12)
Block(1,11,8,LOG2:12)
Block(-2,11,9,LEAVES:15)
Block(-1,11,9,LEAVES:15)
Block(2,11,9,LEAVES:15)
Block(1,11,10,LEAVES:15)
Block(2,11,11,LEAVES:15)
Block(7,12,-9,LEAVES:15)
Block(8,12,-9,LEAVES:15)
Block(6,12,-8,LEAVES:15)
Block(7,12,-8,LEAVES:15)
Block(10,12,-8,LEAVES:15)
Block(-6,12,-7,LEAVES:15)
Block(-1,12,-7,LEAVES:15)
Block(1,12,-7,LEAVES:15)
Block(2,12,-7,LEAVES:15)
Block(4,12,-7,LEAVES:15)
Block(5,12,-7,LEAVES:15)
Block(6,12,-7,LEAVES:15)
Block(10,12,-7,LEAVES:15)
Block(11,12,-7,LEAVES:15)
Block(-4,12,-6,LEAVES:15)
Block(-2,12,-6,LEAVES:15)
Block(-1,12,-6,LEAVES:15)
Block(0,12,-6,LEAVES:15)
Block(3,12,-6,LEAVES:15)
Block(4,12,-6,LEAVES:15)
Block(6,12,-6,LEAVES:15)
Block(-4,12,-5,LEAVES:15)
Block(-3,12,-5,LEAVES:15)
Block(-1,12,-5,LEAVES:15)
Block(0,12,-5,LEAVES:15)
Block(3,12,-5,LEAVES:15)
Block(5,12,-5,LEAVES:15)
Block(6,12,-5,LEAVES:15)
Block(7,12,-5,LEAVES:15)
Block(10,12,-5,LEAVES:15)
Block(-6,12,-4,LEAVES:15)
Block(-5,12,-4,LEAVES:15)
Block(-4,12,-4,LEAVES:15)
Block(0,12,-4,LEAVES:15)
Block(1,12,-4,LEAVES:15)
Block(3,12,-4,LEAVES:15)
Block(4,12,-4,LEAVES:15)
Block(7,12,-4,LEAVES:15)
Block(8,12,-4,LEAVES:15)
Block(10,12,-4,LEAVES:15)
Block(-4,12,-3,LEAVES:15)
Block(-3,12,-3,LEAVES:15)
Block(-2,12,-3,LOG2:12)
Block(-1,12,-3,LOG2:12)
Block(3,12,-3,LEAVES:15)
Block(-5,12,-2,LEAVES:15)
Block(-3,12,-2,LEAVES:15)
Block(-1,12,-2,LOG2:12)
Block(1,12,-2,LEAVES:15)
Block(4,12,-2,LEAVES:15)
Block(5,12,-2,LEAVES:15)
Block(6,12,-2,LEAVES:15)
Block(7,12,-2,LEAVES:15)
Block(8,12,-2,LEAVES:15)
Block(9,12,-2,LEAVES:15)
Block(-3,12,-1,LEAVES:15)
Block(-2,12,-1,LOG2:12)
Block(-1,12,-1,LEAVES:15)
Block(0,12,-1,LOG2:12)
Block(7,12,-1,LEAVES:15)
Block(8,12,-1,LEAVES:15)
Block(9,12,-1,LEAVES:15)
Block(-7,12,0,LEAVES:15)
Block(-1,12,0,LOG2:12)
Block(0,12,0,LOG2:12)
Block(1,12,0,LOG2:12)
Block(3,12,0,LEAVES:15)
Block(8,12,0,LEAVES:15)
Block(-9,12,1,LEAVES:15)
Block(-3,12,1,LEAVES:15)
Block(-2,12,1,LEAVES:15)
Block(0,12,1,LOG2:12)
Block(1,12,1,LOG2:12)
Block(2,12,1,LEAVES:15)
Block(3,12,1,LEAVES:15)
Block(8,12,1,LEAVES:15)
Block(-8,12,2,LEAVES:15)
Block(-6,12,2,LEAVES:15)
Block(-5,12,2,LEAVES:15)
Block(-3,12,2,LEAVES:15)
Block(2,12,2,LEAVES:15)
Block(3,12,2,LEAVES:15)
Block(4,12,2,LEAVES:15)
Block(5,12,2,LEAVES:15)
Block(10,12,2,LEAVES:15)
Block(-10,12,3,LEAVES:15)
Block(-8,12,3,LEAVES:15)
Block(-7,12,3,LEAVES:15)
Block(-6,12,3,LEAVES:15)
Block(-3,12,3,LEAVES:15)
Block(-2,12,3,LEAVES:15)
Block(-1,12,3,LEAVES:15)
Block(1,12,3,LEAVES:15)
Block(4,12,3,LEAVES:15)
Block(6,12,3,LEAVES:15)
Block(8,12,3,LEAVES:15)
Block(9,12,3,LEAVES:15)
Block(-11,12,4,LEAVES:15)
Block(0,12,4,LEAVES:15)
Block(4,12,4,LEAVES:15)
Block(5,12,4,LEAVES:15)
Block(6,12,4,LEAVES:15)
Block(7,12,4,LOG2:12)
Block(-13,12,5,LEAVES:15)
Block(-11,12,5,LEAVES:15)
Block(-10,12,5,LEAVES:15)
Block(-8,12,5,LOG2:12)
Block(-7,12,5,LOG2:12)
Block(-6,12,5,LEAVES:15)
Block(-5,12,5,LEAVES:15)
Block(-2,12,5,LEAVES:15)
Block(2,12,5,LEAVES:15)
Block(4,12,5,LOG2:12)
Block(5,12,5,LOG2:12)
Block(6,12,5,LOG2:12)
Block(7,12,5,LOG2:12)
Block(9,12,5,LEAVES:15)
Block(-12,12,6,LEAVES:15)
Block(-8,12,6,LOG2:12)
Block(-7,12,6,LEAVES:15)
Block(-6,12,6,LEAVES:15)
Block(-3,12,6,LEAVES:15)
Block(-2,12,6,LEAVES:15)
Block(-1,12,6,LEAVES:15)
Block(1,12,6,LEAVES:15)
Block(2,12,6,LEAVES:15)
Block(4,12,6,LEAVES:15)
Block(5,12,6,LEAVES:15)
Block(6,12,6,LEAVES:15)
Block(7,12,6,LEAVES:15)
Block(9,12,6,LEAVES:15)
Block(-11,12,7,LEAVES:15)
Block(-9,12,7,LEAVES:15)
Block(-7,12,7,LEAVES:15)
Block(-3,12,7,LEAVES:15)
Block(-1,12,7,LEAVES:15)
Block(2,12,7,LOG2:12)
Block(3,12,7,LOG2:12)
Block(5,12,7,LEAVES:15)
Block(8,12,7,LEAVES:15)
Block(-9,12,8,LEAVES:15)
Block(-2,12,8,LEAVES:15)
Block(-1,12,8,LEAVES:15)
Block(0,12,8,LEAVES:15)
Block(1,12,8,LEAVES:15)
Block(2,12,8,LOG2:12)
Block(4,12,8,LEAVES:15)
Block(-10,12,9,LEAVES:15)
Block(-9,12,9,LEAVES:15)
Block(-3,12,9,LEAVES:15)
Block(-2,12,9,LEAVES:15)
Block(-1,12,9,LEAVES:15)
Block(1,12,9,LEAVES:15)
Block(2,12,9,LEAVES:15)
Block(3,12,9,LEAVES:15)
Block(1,12,11,LEAVES:15)
Block(8,13,-8,LEAVES:15)
Block(5,13,-7,LEAVES:15)
Block(0,13,-6,LEAVES:15)
Block(1,13,-6,LEAVES:15)
Block(3,13,-6,LEAVES:15)
Block(4,13,-6,LEAVES:15)
Block(-5,13,-5,LEAVES:15)
Block(-4,13,-5,LEAVES:15)
Block(1,13,-5,LEAVES:15)
Block(8,13,-5,LEAVES:15)
Block(-4,13,-4,LEAVES:15)
Block(-3,13,-4,LEAVES:15)
Block(-2,13,-4,LEAVES:15)
Block(2,13,-4,LEAVES:15)
Block(-4,13,-3,LEAVES:15)
Block(-1,13,-3,LOG2:12)
Block(1,13,-3,LEAVES:15)
Block(6,13,-3,LEAVES:15)
Block(7,13,-3,LEAVES:15)
Block(-4,13,-2,LEAVES:15)
Block(-2,13,-2,LEAVES:15)
Block(2,13,-2,LEAVES:15)
Block(3,13,-2,LEAVES:15)
Block(5,13,-2,LEAVES:15)
Block(7,13,-2,LEAVES:15)
Block(-5,13,-1,LEAVES:15)
Block(-4,13,-1,LEAVES:15)
Block(-3,13,-1,LEAVES:15)
Block(-2,13,-1,LOG2:12)
Block(3,13,-1,LEAVES:15)
Block(7,13,-1,LEAVES:15)
Block(-8,13,0,LEAVES:15)
Block(-7,13,0,LEAVES:15)
Block(-3,13,0,LOG2:12)
Block(-2,13,0,LOG2:12)
Block(0,13,0,LOG2:12)
Block(1,13,0,LEAVES:15)
Block(7,13,0,LEAVES:15)
Block(-9,13,1,LEAVES:15)
Block(-6,13,1,LEAVES:15)
Block(-3,13,1,LOG2:12)
Block(-1,13,1,LEAVES:15)
Block(0,13,1,LEAVES:15)
Block(1,13,1,LOG2:12)
Block(2,13,1,LEAVES:15)
Block(5,13,1,LEAVES:15)
Block(-10,13,2,LEAVES:15)
Block(-8,13,2,LEAVES:15)
Block(-4,13,2,LEAVES:15)
Block(-2,13,2,LEAVES:15)
Block(0,13,2,LEAVES:15)
Block(1,13,2,LOG2:12)
Block(2,13,2,LOG2:12)
Block(7,13,2,LEAVES:15)
Block(8,13,2,LEAVES:15)
Block(-8,13,3,LEAVES:15)
Block(-7,13,3,LEAVES:15)
Block(-4,13,3,LEAVES:15)
Block(-1,13,3,LEAVES:15)
Block(2,13,3,LEAVES:15)
Block(6,13,3,LEAVES:15)
Block(10,13,3,LEAVES:15)
Block(-7,13,4,LOG2:12)
Block(-6,13,4,LOG2:12)
Block(1,13,4,LEAVES:15)
Block(3,13,4,LEAVES:15)
Block(4,13,4,LOG2:12)
Block(6,13,4,LEAVES:15)
Block(7,13,4,LEAVES:15)
Block(9,13,4,LEAVES:15)
Block(-7,13,5,LOG2:12)
Block(-6,13,5,LEAVES:15)
Block(-4,13,5,LEAVES:15)
Block(-2,13,5,LEAVES:15)
Block(-1,13,5,LEAVES:15)
Block(1,13,5,LEAVES:15)
Block(4,13,5,LOG2:12)
Block(5,13,5,LOG2:12)
Block(6,13,5,LOG2:12)
Block(9,13,5,LEAVES:15)
Block(-12,13,6,LEAVES:15)
Block(-11,13,6,LEAVES:15)
Block(-10,13,6,LEAVES:15)
Block(-4,13,6,LEAVES:15)
Block(-3,13,6,LEAVES:15)
Block(-2,13,6,LEAVES:15)
Block(-1,13,6,LEAVES:15)
Block(0,13,6,LEAVES:15)
Block(3,13,6,LOG2:12)
Block(4,13,6,LOG2:12)
Block(7,13,6,LEAVES:15)
Block(-8,13,7,LEAVES:15)
Block(-7,13,7,LEAVES:15)
Block(-2,13,7,LEAVES:15)
Block(-1,13,7,LEAVES:15)
Block(3,13,7,LOG2:12)
Block(-9,13,8,LEAVES:15)
Block(-8,13,8,LEAVES:15)
Block(-5,13,8,LEAVES:15)
Block(-4,13,8,LEAVES:15)
Block(3,13,8,LEAVES:15)
Block(-3,13,9,LEAVES:15)
Block(-2,13,9,LEAVES:15)
Block(0,13,9,LEAVES:15)
Block(1,13,9,LEAVES:15)
Block(3,13,9,LEAVES:15)
Block(0,13,10,LEAVES:15)
Block(-1,14,-6,LEAVES:15)
Block(2,14,-6,LEAVES:15)
Block(-3,14,-5,LEAVES:15)
Block(1,14,-5,LEAVES:15)
Block(2,14,-5,LEAVES:15)
Block(-1,14,-4,LEAVES:15)
Block(1,14,-4,LEAVES:15)
Block(2,14,-4,LEAVES:15)
Block(2,14,-3,LEAVES:15)
Block(5,14,-3,LEAVES:15)
Block(-4,14,-2,LEAVES:15)
Block(-2,14,-2,LEAVES:15)
Block(0,14,-2,LEAVES:15)
Block(-1,14,-1,LEAVES:15)
Block(0,14,-1,LEAVES:15)
Block(3,14,-1,LEAVES:15)
Block(5,14,-1,LEAVES:15)
Block(-5,14,0,LEAVES:15)
Block(-4,14,0,LEAVES:15)
Block(-3,14,0,LOG2:12)
Block(-2,14,0,LEAVES:15)
Block(5,14,0,LEAVES:15)
Block(7,14,0,LEAVES:15)
Block(8,14,0,LEAVES:15)
Block(-8,14,1,LEAVES:15)
Block(-7,14,1,LEAVES:15)
Block(-6,14,1,LEAVES:15)
Block(-4,14,1,LOG2:12)
Block(-3,14,1,LOG2:12)
Block(-1,14,1,LEAVES:15)
Block(1,14,1,LOG2:12)
Block(2,14,1,LEAVES:15)
Block(5,14,1,LEAVES:15)
Block(6,14,1,LEAVES:15)
Block(9,14,1,LEAVES:15)
Block(-9,14,2,LEAVES:15)
Block(-8,14,2,LEAVES:15)
Block(-5,14,2,LOG2:12)
Block(-4,14,2,LOG2:12)
Block(-2,14,2,LEAVES:15)
Block(-1,14,2,LEAVES:15)
Block(1,14,2,LEAVES:15)
Block(2,14,2,LOG2:12)
Block(4,14,2,LEAVES:15)
Block(5,14,2,LEAVES:15)
Block(8,14,2,LEAVES:15)
Block(9,14,2,LEAVES:15)
Block(-6,14,3,LOG2:12)
Block(-5,14,3,LOG2:12)
Block(-1,14,3,LEAVES:15)
Block(2,14,3,LOG2:12)
Block(3,14,3,LOG2:12)
Block(6,14,3,LEAVES:15)
Block(-9,14,4,LEAVES:15)
Block(-6,14,4,LOG2:12)
Block(-2,14,4,LEAVES:15)
Block(3,14,4,LOG2:12)
Block(4,14,4,LOG2:12)
Block(5,14,4,LEAVES:15)
Block(7,14,4,LEAVES:15)
Block(9,14,4,LEAVES:15)
Block(-9,14,5,LEAVES:15)
Block(-6,14,5,LEAVES:15)
Block(1,14,5,LEAVES:15)
Block(2,14,5,LEAVES:15)
Block(4,14,5,LEAVES:15)
Block(5,14,5,LOG2:12)
Block(7,14,5,LEAVES:15)
Block(-10,14,6,LEAVES:15)
Block(-8,14,6,LEAVES:15)
Block(-6,14,6,LEAVES:15)
Block(-5,14,6,LEAVES:15)
Block(-4,14,6,LEAVES:15)
Block(-1,14,6,LEAVES:15)
Block(3,14,6,LEAVES:15)
Block(5,14,6,LEAVES:15)
Block(-11,14,7,LEAVES:15)
Block(-8,14,7,LEAVES:15)
Block(-7,14,7,LEAVES:15)
Block(-3,14,7,LEAVES:15)
Block(-2,14,7,LEAVES:15)
Block(2,14,7,LEAVES:15)
Block(4,14,7,LEAVES:15)
Block(6,14,7,LEAVES:15)
Block(-7,14,8,LEAVES:15)
Block(-4,14,8,LEAVES:15)
Block(-3,14,8,LEAVES:15)
Block(-1,14,8,LEAVES:15)
Block(0,14,8,LEAVES:15)
Block(1,14,8,LEAVES:15)
Block(2,14,8,LEAVES:15)
Block(-3,14,9,LEAVES:15)
Block(0,14,9,LEAVES:15)
Block(2,14,9,LEAVES:15)
Block(2,15,-5,LEAVES:15)
Block(-1,15,-4,LEAVES:15)
Block(0,15,-4,LEAVES:15)
Block(4,15,-4,LEAVES:15)
Block(-2,15,-3,LEAVES:15)
Block(0,15,-3,LEAVES:15)
Block(1,15,-3,LEAVES:15)
Block(3,15,-3,LEAVES:15)
Block(-3,15,-2,LEAVES:15)
Block(0,15,-2,LEAVES:15)
Block(1,15,-2,LEAVES:15)
Block(3,15,-2,LEAVES:15)
Block(5,15,-2,LEAVES:15)
Block(-4,15,-1,LEAVES:15)
Block(-2,15,-1,LEAVES:15)
Block(-1,15,-1,LEAVES:15)
Block(2,15,-1,LEAVES:15)
Block(-6,15,0,LEAVES:15)
Block(-4,15,0,LEAVES:15)
Block(-3,15,0,LEAVES:15)
Block(-2,15,0,LEAVES:15)
Block(-1,15,0,LEAVES:15)
Block(2,15,0,LEAVES:15)
Block(3,15,0,LEAVES:15)
Block(5,15,0,LEAVES:15)
Block(-5,15,1,LEAVES:15)
Block(-4,15,1,LEAVES:15)
Block(-3,15,1,LOG2:12)
Block(-1,15,1,LEAVES:15)
Block(0,15,1,LEAVES:15)
Block(1,15,1,LEAVES:15)
Block(4,15,1,LEAVES:15)
Block(6,15,1,LEAVES:15)
Block(-9,15,2,LEAVES:15)
Block(-4,15,2,LOG2:12)
Block(-2,15,2,LEAVES:15)
Block(-1,15,2,LEAVES:15)
Block(0,15,2,LEAVES:15)
Block(1,15,2,LEAVES:15)
Block(3,15,2,LEAVES:15)
Block(4,15,2,LEAVES:15)
Block(5,15,2,LEAVES:15)
Block(7,15,2,LEAVES:15)
Block(8,15,2,LEAVES:15)
Block(-9,15,3,LEAVES:15)
Block(-8,15,3,LEAVES:15)
Block(-5,15,3,LEAVES:15)
Block(2,15,3,LEAVES:15)
Block(4,15,3,LEAVES:15)
Block(5,15,3,LEAVES:15)
Block(6,15,3,LEAVES:15)
Block(9,15,3,LEAVES:15)
Block(-9,15,4,LEAVES:15)
Block(-7,15,4,LEAVES:15)
Block(-3,15,4,LEAVES:15)
Block(-2,15,4,LEAVES:15)
Block(1,15,4,LEAVES:15)
Block(4,15,4,LEAVES:15)
Block(5,15,4,LEAVES:15)
Block(8,15,4,LEAVES:15)
Block(-9,15,5,LEAVES:15)
Block(-8,15,5,LEAVES:15)
Block(-7,15,5,LEAVES:15)
Block(-6,15,5,LEAVES:15)
Block(-5,15,5,LEAVES:15)
Block(-3,15,5,LEAVES:15)
Block(-1,15,5,LEAVES:15)
Block(1,15,5,LEAVES:15)
Block(2,15,5,LEAVES:15)
Block(3,15,5,LEAVES:15)
Block(5,15,5,LEAVES:15)
Block(7,15,5,LEAVES:15)
Block(8,15,5,LEAVES:15)
Block(-9,15,6,LEAVES:15)
Block(-3,15,6,LEAVES:15)
Block(-2,15,6,LEAVES:15)
Block(-1,15,6,LEAVES:15)
Block(1,15,6,LEAVES:15)
Block(5,15,6,LEAVES:15)
Block(-8,15,7,LEAVES:15)
Block(-4,15,7,LEAVES:15)
Block(-3,15,7,LEAVES:15)
Block(1,15,7,LEAVES:15)
Block(2,15,7,LEAVES:15)
Block(-6,15,8,LEAVES:15)
Block(0,15,8,LEAVES:15)
Block(2,16,-3,LEAVES:15)
Block(3,16,-3,LEAVES:15)
Block(-1,16,-2,LEAVES:15)
Block(1,16,-2,LEAVES:15)
Block(-2,16,-1,LEAVES:15)
Block(-1,16,-1,LEAVES:15)
Block(0,16,-1,LEAVES:15)
Block(3,16,-1,LEAVES:15)
Block(4,16,-1,LEAVES:15)
Block(0,16,0,LEAVES:15)
Block(2,16,0,LEAVES:15)
Block(4,16,0,LEAVES:15)
Block(-2,16,1,LEAVES:15)
Block(1,16,1,LEAVES:15)
Block(4,16,1,LEAVES:15)
Block(-5,16,2,LEAVES:15)
Block(-4,16,2,LEAVES:15)
Block(1,16,2,LEAVES:15)
Block(5,16,2,LEAVES:15)
Block(-9,16,3,LEAVES:15)
Block(-7,16,3,LEAVES:15)
Block(-5,16,3,LEAVES:15)
Block(-1,16,3,LEAVES:15)
Block(2,16,3,LEAVES:15)
Block(4,16,3,LEAVES:15)
Block(7,16,3,LEAVES:15)
Block(8,16,3,LEAVES:15)
Block(-8,16,4,LEAVES:15)
Block(-6,16,4,LEAVES:15)
Block(-5,16,4,LEAVES:15)
Block(2,16,4,LEAVES:15)
Block(3,16,4,LEAVES:15)
Block(-9,16,5,LEAVES:15)
Block(-8,16,5,LEAVES:15)
Block(-5,16,5,LEAVES:15)
Block(-1,16,5,LEAVES:15)
Block(1,16,5,LEAVES:15)
Block(2,16,5,LEAVES:15)
Block(3,16,5,LEAVES:15)
Block(4,16,5,LEAVES:15)
Block(5,16,5,LEAVES:15)
Block(-8,16,6,LEAVES:15)
Block(-7,16,6,LEAVES:15)
Block(-6,16,6,LEAVES:15)
Block(-5,16,6,LEAVES:15)
Block(-1,16,6,LEAVES:15)
Block(-7,16,7,LEAVES:15)
Block(-5,16,7,LEAVES:15)
Block(1,17,-2,LEAVES:15)
Block(2,17,-2,LEAVES:15)
Block(1,17,-1,LEAVES:15)
Block(3,17,0,LEAVES:15)
Block(3,17,1,LEAVES:15)
Block(-6,17,2,LEAVES:15)
Block(2,17,2,LEAVES:15)
Block(5,17,2,LEAVES:15)
Block(-7,17,3,LEAVES:15)
Block(-5,17,3,LEAVES:15)
Block(0,17,3,LEAVES:15)
Block(-7,17,4,LEAVES:15)
Block(-1,17,4,LEAVES:15)
Block(1,17,4,LEAVES:15)
Block(3,17,4,LEAVES:15)
Block(-7,17,5,LEAVES:15)
Block(0,17,5,LEAVES:15)
Block(2,17,6,LEAVES:15)
Block(3,18,2,LEAVES:15)
Block(1,18,3,LEAVES:15)
Block(3,18,3,LEAVES:15)
Block(2,18,4,LEAVES:15)

#######################################################################
# +-----------------------------------------------------------------+ #
# |                            BO3 checks                           | #
# +-----------------------------------------------------------------+ #
#######################################################################

# Require a condition at a certain location in order for the BO3 to be spawned.
# BlockCheck(x,y,z,BlockName[,BlockName[,...]]) - one of the blocks must be at the location
# BlockCheckNot(x,y,z,BlockName[,BlockName[,...]]) - all the blocks must not be at the location
# LightCheck(x,y,z,minLightLevel,maxLightLevel) - light must be between min and max (inclusive)

# You can use "Solid" as a BlockName for matching all solid blocks or "All" to match all blocks that aren't air.

# Examples:
BlockCheck(0,-1,0,GRASS,DIRT,DIRT:2)
#   BlockCheck(0,-1,0,Solid)       Require any solid block just below the object
#   BlockCheck(0,-1,0,WOOL)        Require any type of wool just below the object
#   BlockCheck(0,-1,0,WOOL:0)      Require white wool just below the object
#   BlockCheckNot(0,-1,0,WOOL:0)   Require that there is no white wool below the object
#   LightCheck(0,0,0,0,1)          Require almost complete darkness just below the object

#######################################################################
# +-----------------------------------------------------------------+ #
# |                             Branches                            | #
# +-----------------------------------------------------------------+ #
#######################################################################

# Branches are objects that will spawn when this object spawns when it is used in
# the CustomStructure resource. Branches can also have branches, making complex
# structures possible. See the wiki for more details.

# Regular Branches spawn each branch with an independent chance of spawning.
# Branch(x,y,z,branchName,rotation,chance[,anotherBranchName,rotation,chance[,...]][IndividualChance])
# branchName - name of the object to spawn.
# rotation - NORTH, SOUTH, EAST or WEST.
# IndividualChance - The chance each branch has to spawn, assumed to be 100 when left blank

# Weighted Branches spawn branches with a dependent chance of spawning.
# WeightedBranch(x,y,z,branchName,rotation,chance[,anotherBranchName,rotation,chance[,...]][MaxChanceOutOf])
# MaxChanceOutOf - The chance all branches have to spawn out of, assumed to be 100 when left blank
