#######################################################################
# +-----------------------------------------------------------------+ #
# |                            BO3 object                           | #
# +-----------------------------------------------------------------+ #
#######################################################################

# This is the config file of a custom object.
# If you add this object correctly to your BiomeConfigs, it will spawn in the world.

# This is the creator of this BO3 object
Author: BO3 BulkEdit (by LanToaster)

# A short description of this BO3 object
Description: This Object was Created with BO3_BulkEdit

# The BO3 version, don't change this! It can be used by external applications to do a version check.
Version: 3

# The settings mode, WriteAll, WriteWithoutComments or WriteDisable. See WorldConfig.
SettingsMode: WriteDisable


#######################################################################
# +-----------------------------------------------------------------+ #
# |                          Main settings                          | #
# +-----------------------------------------------------------------+ #
#######################################################################

# This needs to be set to true to spawn the object in the Tree and Sapling resources.
Tree: true

# The frequency of the BO3 from 1 to 200. Tries this many times to spawn this BO3 when using the CustomObject(...) resource.
# Ignored by Tree(..), Sapling(..) and CustomStructure(..)
Frequency: 1

# The rarity of the BO3 from 0 to 100. Each spawn attempt has rarity% chance to succeed when using the CustomObject(...) resource.
# Ignored by Tree(..), Sapling(..) and CustomStructure(..)
Rarity: 100.0

# If you set this to true, the BO3 will be placed with a random rotation.
RotateRandomly: true

# The spawn height of the BO3 - randomY, highestBlock or highestSolidBlock.
SpawnHeight: highestSolidBlock

# The height limits for the BO3.
MinHeight: 0

MaxHeight: 256

# Objects can have other objects attacthed to it: branches. Branches can also
# have branches attached to it, which can also have branches, etc. This is the
# maximum branch depth for this objects.
MaxBranchDepth: 10

# When spawned with the UseWorld keyword, this BO3 should NOT spawn in the following biomes.
# If you writer.write the BO3 name directly in the BiomeConfigs, this will be ignored.
ExcludedBiomes: All


#######################################################################
# +-----------------------------------------------------------------+ #
# |                      Source block settings                      | #
# +-----------------------------------------------------------------+ #
#######################################################################

# The block(s) the BO3 should spawn in.
SourceBlocks: AIR

# The maximum percentage of the BO3 that can be outside the SourceBlock.
# The BO3 won't be placed on a location with more blocks outside the SourceBlock than this percentage.
MaxPercentageOutsideSourceBlock: 0

# What to do when a block is about to be placed outside the SourceBlock? (dontPlace, placeAnyway)
OutsideSourceBlock: dontPlace


#######################################################################
# +-----------------------------------------------------------------+ #
# |                              Blocks                             | #
# +-----------------------------------------------------------------+ #
#######################################################################

# All the blocks used in the BO3 are listed here. Possible blocks:
# Block(x,y,z,id[.data][,nbtfile.nbt)
# RandomBlock(x,y,z,id[:data][,nbtfile.nbt],chance[,id[:data][,nbtfile.nbt],chance[,...]])
# So RandomBlock(0,0,0,CHEST,chest.nbt,50,CHEST,anotherchest.nbt,100) will spawn a chest at
# the BO3 origin, and give it a 50% chance to have the contents of chest.nbt, or, if that
# fails, a 100% percent chance to have the contents of anotherchest.nbt.
Block(0,0,-2,LOG2:13)
Block(1,0,-2,LOG2:13)
Block(0,0,-1,LOG2:13)
Block(1,0,-1,LOG2:13)
Block(0,1,-2,LOG2:13)
Block(1,1,-2,LOG2:13)
Block(0,1,-1,LOG2:13)
Block(1,1,-1,LOG2:13)
Block(1,2,-2,LOG2:13)
Block(0,2,-1,LOG2:13)
Block(1,2,-1,LOG2:13)
Block(0,3,-1,LOG2:13)
Block(1,3,-1,LOG2:13)
Block(1,4,-1,LOG2:13)
Block(0,5,-7,VINE:8)
Block(3,5,-7,VINE:2)
Block(1,5,-1,LOG2:13)
Block(-6,5,5,VINE:8)
Block(0,6,-7,VINE:8)
Block(3,6,-7,VINE:2)
Block(4,6,-4,VINE:8)
Block(5,6,-2,VINE:1)
Block(1,6,-1,LOG2:13)
Block(-6,6,5,VINE:8)
Block(1,6,6,VINE:4)
Block(4,7,-8,VINE:2)
Block(0,7,-7,VINE:8)
Block(3,7,-7,VINE:2)
Block(0,7,-6,VINE:1)
Block(1,7,-6,VINE:4)
Block(1,7,-5,VINE:1)
Block(4,7,-4,VINE:9)
Block(-1,7,-2,VINE:4)
Block(1,7,-2,VINE:1)
Block(5,7,-2,VINE:1)
Block(1,7,-1,LOG2:13)
Block(-2,7,1,VINE:2)
Block(2,7,2,VINE:2)
Block(2,7,4,VINE:8)
Block(-6,7,5,VINE:8)
Block(1,7,6,VINE:4)
Block(1,8,-9,VINE:1)
Block(1,8,-8,VINE:8)
Block(2,8,-8,VINE:1)
Block(4,8,-8,VINE:2)
Block(0,8,-7,VINE:8)
Block(3,8,-7,VINE:2)
Block(5,8,-7,VINE:2)
Block(6,8,-7,VINE:1)
Block(8,8,-7,VINE:1)
Block(0,8,-6,VINE:1)
Block(1,8,-6,VINE:4)
Block(1,8,-5,VINE:1)
Block(-3,8,-4,VINE:8)
Block(-1,8,-4,VINE:4)
Block(0,8,-4,VINE:2)
Block(4,8,-4,VINE:9)
Block(2,8,-3,VINE:1)
Block(-1,8,-2,VINE:4)
Block(0,8,-2,VINE:8)
Block(1,8,-2,VINE:1)
Block(2,8,-2,VINE:1)
Block(5,8,-2,VINE:1)
Block(-1,8,-1,VINE:2)
Block(1,8,-1,LOG2:13)
Block(-2,8,1,VINE:2)
Block(2,8,2,VINE:2)
Block(2,8,4,VINE:8)
Block(-6,8,5,VINE:8)
Block(3,8,5,VINE:1)
Block(-3,8,6,VINE:4)
Block(1,8,6,VINE:4)
Block(4,8,7,VINE:4)
Block(-1,8,8,VINE:4)
Block(1,9,-9,VINE:1)
Block(-3,9,-8,VINE:1)
Block(1,9,-8,VINE:8)
Block(2,9,-8,VINE:1)
Block(4,9,-8,VINE:2)
Block(-6,9,-7,VINE:8)
Block(-1,9,-7,VINE:2)
Block(0,9,-7,VINE:8)
Block(3,9,-7,VINE:2)
Block(5,9,-7,VINE:2)
Block(6,9,-7,VINE:1)
Block(8,9,-7,VINE:1)
Block(0,9,-6,VINE:1)
Block(1,9,-6,VINE:4)
Block(0,9,-5,VINE:8)
Block(1,9,-5,VINE:1)
Block(-3,9,-4,VINE:8)
Block(-1,9,-4,VINE:4)
Block(0,9,-4,VINE:2)
Block(4,9,-4,VINE:9)
Block(2,9,-3,VINE:1)
Block(4,9,-3,VINE:2)
Block(-1,9,-2,VINE:4)
Block(0,9,-2,VINE:8)
Block(1,9,-2,VINE:1)
Block(2,9,-2,VINE:1)
Block(5,9,-2,VINE:1)
Block(7,9,-2,VINE:4)
Block(-1,9,-1,VINE:3)
Block(1,9,-1,LOG2:13)
Block(2,9,-1,LOG2:13)
Block(-4,9,0,VINE:4)
Block(1,9,0,LOG2:13)
Block(2,9,0,LOG2:13)
Block(3,9,0,VINE:8)
Block(-2,9,1,VINE:2)
Block(2,9,2,VINE:2)
Block(4,9,3,SNOW_BLOCK)
Block(2,9,4,VINE:8)
Block(-6,9,5,VINE:8)
Block(3,9,5,VINE:1)
Block(4,9,5,SNOW_BLOCK)
Block(5,9,5,SNOW_BLOCK)
Block(-3,9,6,VINE:12)
Block(1,9,6,VINE:4)
Block(4,9,7,VINE:4)
Block(-1,9,8,VINE:4)
Block(1,10,-9,VINE:1)
Block(4,10,-9,VINE:1)
Block(-5,10,-8,VINE:1)
Block(-3,10,-8,VINE:1)
Block(1,10,-8,VINE:8)
Block(2,10,-8,VINE:1)
Block(3,10,-8,SNOW_BLOCK)
Block(4,10,-8,VINE:2)
Block(-6,10,-7,VINE:8)
Block(-4,10,-7,VINE:8)
Block(-1,10,-7,VINE:2)
Block(0,10,-7,VINE:8)
Block(2,10,-7,SNOW_BLOCK)
Block(3,10,-7,VINE:2)
Block(5,10,-7,VINE:2)
Block(6,10,-7,VINE:1)
Block(8,10,-7,VINE:1)
Block(0,10,-6,VINE:1)
Block(1,10,-6,VINE:4)
Block(4,10,-6,VINE:2)
Block(-3,10,-5,VINE:8)
Block(0,10,-5,VINE:8)
Block(1,10,-5,VINE:1)
Block(2,10,-5,SNOW_BLOCK)
Block(4,10,-5,VINE:1)
Block(6,10,-5,SNOW_BLOCK)
Block(7,10,-5,SNOW_BLOCK)
Block(-5,10,-4,VINE:1)
Block(-3,10,-4,VINE:8)
Block(-1,10,-4,VINE:4)
Block(0,10,-4,VINE:2)
Block(1,10,-4,SNOW_BLOCK)
Block(4,10,-4,VINE:9)
Block(5,10,-4,SNOW_BLOCK)
Block(6,10,-4,SNOW_BLOCK)
Block(8,10,-4,SNOW_BLOCK)
Block(2,10,-3,VINE:1)
Block(3,10,-3,SNOW_BLOCK)
Block(4,10,-3,VINE:2)
Block(5,10,-3,LOG2:13)
Block(6,10,-3,SNOW_BLOCK)
Block(7,10,-3,SNOW_BLOCK)
Block(8,10,-3,VINE:4)
Block(-4,10,-2,VINE:8)
Block(-2,10,-2,VINE:4)
Block(-1,10,-2,VINE:4)
Block(0,10,-2,VINE:8)
Block(1,10,-2,LOG2:13)
Block(2,10,-2,LOG2:13)
Block(3,10,-2,LOG2:13)
Block(5,10,-2,VINE:1)
Block(7,10,-2,VINE:4)
Block(-1,10,-1,VINE:1)
Block(0,10,-1,LOG2:13)
Block(1,10,-1,LOG2:13)
Block(2,10,-1,VINE:8)
Block(3,10,-1,SNOW_BLOCK)
Block(4,10,-1,SNOW_BLOCK)
Block(5,10,-1,SNOW_BLOCK)
Block(6,10,-1,SNOW_BLOCK)
Block(7,10,-1,SNOW_BLOCK)
Block(8,10,-1,SNOW_BLOCK)
Block(-4,10,0,VINE:4)
Block(-2,10,0,VINE:1)
Block(-1,10,0,SNOW_BLOCK)
Block(0,10,0,LOG2:13)
Block(1,10,0,VINE:8)
Block(2,10,0,LOG2:13)
Block(3,10,0,VINE:8)
Block(5,10,0,SNOW_BLOCK)
Block(7,10,0,SNOW_BLOCK)
Block(8,10,0,SNOW_BLOCK)
Block(-2,10,1,VINE:2)
Block(2,10,1,SNOW_BLOCK)
Block(3,10,1,LOG2:13)
Block(4,10,1,SNOW_BLOCK)
Block(-7,10,2,VINE:8)
Block(-3,10,2,SNOW_BLOCK)
Block(-1,10,2,SNOW_BLOCK)
Block(2,10,2,VINE:2)
Block(4,10,2,LOG2:13)
Block(-5,10,3,SNOW_BLOCK)
Block(-4,10,3,SNOW_BLOCK)
Block(-3,10,3,SNOW_BLOCK)
Block(3,10,3,SNOW_BLOCK)
Block(4,10,3,SNOW_BLOCK)
Block(5,10,3,SNOW_BLOCK)
Block(6,10,3,SNOW_BLOCK)
Block(-5,10,4,SNOW_BLOCK)
Block(-4,10,4,SNOW_BLOCK)
Block(2,10,4,VINE:8)
Block(4,10,4,SNOW_BLOCK)
Block(5,10,4,SNOW_BLOCK)
Block(6,10,4,SNOW_BLOCK)
Block(7,10,4,SNOW_BLOCK)
Block(-6,10,5,VINE:8)
Block(-4,10,5,SNOW_BLOCK)
Block(1,10,5,SNOW_BLOCK)
Block(3,10,5,VINE:1)
Block(4,10,5,SNOW_BLOCK)
Block(5,10,5,SNOW_BLOCK)
Block(6,10,5,SNOW_BLOCK)
Block(-3,10,6,VINE:8)
Block(0,10,6,SNOW_BLOCK)
Block(1,10,6,VINE:4)
Block(4,10,6,SNOW_BLOCK)
Block(6,10,6,SNOW_BLOCK)
Block(0,10,7,SNOW_BLOCK)
Block(4,10,7,VINE:4)
Block(-1,10,8,VINE:4)
Block(-3,11,-9,VINE:1)
Block(1,11,-9,VINE:1)
Block(4,11,-9,VINE:1)
Block(-5,11,-8,VINE:1)
Block(-3,11,-8,VINE:1)
Block(1,11,-8,VINE:8)
Block(2,11,-8,SNOW_BLOCK)
Block(3,11,-8,SNOW_BLOCK)
Block(4,11,-8,SNOW_BLOCK)
Block(5,11,-8,VINE:2)
Block(-6,11,-7,VINE:8)
Block(-4,11,-7,VINE:8)
Block(-3,11,-7,SNOW_BLOCK)
Block(-2,11,-7,SNOW_BLOCK)
Block(-1,11,-7,VINE:2)
Block(0,11,-7,VINE:8)
Block(1,11,-7,SNOW_BLOCK)
Block(2,11,-7,LOG2:13)
Block(3,11,-7,SNOW_BLOCK)
Block(4,11,-7,SNOW_BLOCK)
Block(5,11,-7,VINE:3)
Block(6,11,-7,VINE:1)
Block(8,11,-7,VINE:1)
Block(-2,11,-6,VINE:1)
Block(0,11,-6,VINE:1)
Block(1,11,-6,VINE:4)
Block(2,11,-6,SNOW_BLOCK)
Block(3,11,-6,SNOW_BLOCK)
Block(4,11,-6,VINE:2)
Block(5,11,-6,VINE:1)
Block(6,11,-6,SNOW_BLOCK)
Block(7,11,-6,SNOW_BLOCK)
Block(8,11,-6,SNOW_BLOCK)
Block(-3,11,-5,VINE:8)
Block(-2,11,-5,SNOW_BLOCK)
Block(-1,11,-5,SNOW_BLOCK)
Block(0,11,-5,VINE:8)
Block(1,11,-5,SNOW_BLOCK)
Block(2,11,-5,SNOW_BLOCK)
Block(4,11,-5,VINE:1)
Block(6,11,-5,SNOW_BLOCK)
Block(7,11,-5,LOG2:13)
Block(8,11,-5,SNOW_BLOCK)
Block(9,11,-5,VINE:2)
Block(-5,11,-4,VINE:1)
Block(-3,11,-4,VINE:12)
Block(-2,11,-4,SNOW_BLOCK)
Block(-1,11,-4,VINE:4)
Block(0,11,-4,VINE:10)
Block(1,11,-4,SNOW_BLOCK)
Block(2,11,-4,SNOW_BLOCK)
Block(3,11,-4,LOG2:13)
Block(4,11,-4,VINE:1)
Block(5,11,-4,LOG2:13)
Block(6,11,-4,LOG2:13)
Block(7,11,-4,LOG2:13)
Block(8,11,-4,SNOW_BLOCK)
Block(-2,11,-3,SNOW_BLOCK)
Block(-1,11,-3,SNOW_BLOCK)
Block(0,11,-3,SNOW_BLOCK)
Block(1,11,-3,SNOW_BLOCK)
Block(2,11,-3,VINE:1)
Block(3,11,-3,LOG2:13)
Block(4,11,-3,LOG2:13)
Block(5,11,-3,LOG2:13)
Block(6,11,-3,SNOW_BLOCK)
Block(7,11,-3,SNOW_BLOCK)
Block(8,11,-3,SNOW_BLOCK)
Block(-6,11,-2,SNOW_BLOCK)
Block(-4,11,-2,VINE:8)
Block(-2,11,-2,VINE:4)
Block(-1,11,-2,VINE:4)
Block(0,11,-2,LOG2:13)
Block(2,11,-2,SNOW_BLOCK)
Block(3,11,-2,VINE:4)
Block(5,11,-2,SNOW_BLOCK)
Block(7,11,-2,SNOW_BLOCK)
Block(8,11,-2,SNOW_BLOCK)
Block(-1,11,-1,VINE:1)
Block(1,11,-1,LOG2:13)
Block(2,11,-1,SNOW_BLOCK)
Block(4,11,-1,SNOW_BLOCK)
Block(5,11,-1,SNOW_BLOCK)
Block(6,11,-1,SNOW_BLOCK)
Block(7,11,-1,LOG2:13)
Block(8,11,-1,SNOW_BLOCK)
Block(9,11,-1,SNOW_BLOCK)
Block(-4,11,0,VINE:4)
Block(-2,11,0,VINE:1)
Block(-1,11,0,SNOW_BLOCK)
Block(0,11,0,SNOW_BLOCK)
Block(2,11,0,SNOW_BLOCK)
Block(3,11,0,VINE:8)
Block(4,11,0,LOG2:13)
Block(5,11,0,SNOW_BLOCK)
Block(6,11,0,SNOW_BLOCK)
Block(7,11,0,LOG2:13)
Block(8,11,0,SNOW_BLOCK)
Block(9,11,0,SNOW_BLOCK)
Block(-3,11,1,SNOW_BLOCK)
Block(-2,11,1,VINE:2)
Block(-1,11,1,LOG2:13)
Block(0,11,1,LOG2:13)
Block(2,11,1,VINE:8)
Block(3,11,1,LOG2:13)
Block(4,11,1,LOG2:13)
Block(6,11,1,SNOW_BLOCK)
Block(7,11,1,SNOW_BLOCK)
Block(8,11,1,SNOW_BLOCK)
Block(-7,11,2,VINE:8)
Block(-6,11,2,SNOW_BLOCK)
Block(-4,11,2,SNOW_BLOCK)
Block(-3,11,2,SNOW_BLOCK)
Block(-2,11,2,LOG2:13)
Block(-1,11,2,LOG2:13)
Block(1,11,2,SNOW_BLOCK)
Block(2,11,2,VINE:2)
Block(3,11,2,LOG2:13)
Block(6,11,2,SNOW_BLOCK)
Block(7,11,2,SNOW_BLOCK)
Block(8,11,2,SNOW_BLOCK)
Block(-6,11,3,SNOW_BLOCK)
Block(-5,11,3,SNOW_BLOCK)
Block(-4,11,3,LOG2:13)
Block(-3,11,3,LOG2:13)
Block(-1,11,3,SNOW_BLOCK)
Block(1,11,3,SNOW_BLOCK)
Block(2,11,3,VINE:2)
Block(3,11,3,SNOW_BLOCK)
Block(4,11,3,SNOW_BLOCK)
Block(5,11,3,LOG2:13)
Block(6,11,3,SNOW_BLOCK)
Block(7,11,3,SNOW_BLOCK)
Block(-6,11,4,VINE:4)
Block(-5,11,4,SNOW_BLOCK)
Block(-4,11,4,LOG2:13)
Block(-3,11,4,SNOW_BLOCK)
Block(0,11,4,SNOW_BLOCK)
Block(1,11,4,SNOW_BLOCK)
Block(2,11,4,VINE:8)
Block(3,11,4,SNOW_BLOCK)
Block(4,11,4,SNOW_BLOCK)
Block(5,11,4,LOG2:13)
Block(6,11,4,SNOW_BLOCK)
Block(7,11,4,SNOW_BLOCK)
Block(-7,11,5,VINE:8)
Block(-6,11,5,VINE:8)
Block(-5,11,5,SNOW_BLOCK)
Block(-4,11,5,SNOW_BLOCK)
Block(-3,11,5,SNOW_BLOCK)
Block(-2,11,5,VINE:2)
Block(0,11,5,SNOW_BLOCK)
Block(1,11,5,SNOW_BLOCK)
Block(2,11,5,SNOW_BLOCK)
Block(3,11,5,VINE:1)
Block(4,11,5,SNOW_BLOCK)
Block(5,11,5,SNOW_BLOCK)
Block(6,11,5,LOG2:13)
Block(7,11,5,SNOW_BLOCK)
Block(-6,11,6,VINE:4)
Block(-5,11,6,SNOW_BLOCK)
Block(-3,11,6,VINE:8)
Block(-2,11,6,SNOW_BLOCK)
Block(-1,11,6,SNOW_BLOCK)
Block(0,11,6,SNOW_BLOCK)
Block(1,11,6,SNOW_BLOCK)
Block(2,11,6,SNOW_BLOCK)
Block(4,11,6,SNOW_BLOCK)
Block(5,11,6,VINE:4)
Block(-2,11,7,VINE:8)
Block(0,11,7,SNOW_BLOCK)
Block(1,11,7,SNOW_BLOCK)
Block(4,11,7,VINE:4)
Block(-1,11,8,VINE:4)
Block(0,11,8,VINE:4)
Block(1,11,8,VINE:4)
Block(-3,12,-9,VINE:1)
Block(-2,12,-9,VINE:1)
Block(1,12,-9,VINE:1)
Block(4,12,-9,SNOW_BLOCK)
Block(-5,12,-8,VINE:1)
Block(-3,12,-8,SNOW_BLOCK)
Block(-2,12,-8,SNOW_BLOCK)
Block(1,12,-8,SNOW_BLOCK)
Block(2,12,-8,SNOW_BLOCK)
Block(3,12,-8,SNOW_BLOCK)
Block(4,12,-8,SNOW_BLOCK)
Block(5,12,-8,SNOW_BLOCK)
Block(-6,12,-7,VINE:8)
Block(-4,12,-7,SNOW_BLOCK)
Block(-3,12,-7,SNOW_BLOCK)
Block(-2,12,-7,SNOW_BLOCK)
Block(-1,12,-7,VINE:2)
Block(0,12,-7,VINE:8)
Block(1,12,-7,SNOW_BLOCK)
Block(2,12,-7,LOG2:13)
Block(3,12,-7,SNOW_BLOCK)
Block(4,12,-7,SNOW_BLOCK)
Block(5,12,-7,VINE:3)
Block(6,12,-7,VINE:1)
Block(8,12,-7,VINE:1)
Block(-5,12,-6,SNOW_BLOCK)
Block(-4,12,-6,SNOW_BLOCK)
Block(-3,12,-6,LOG2:13)
Block(-2,12,-6,SNOW_BLOCK)
Block(-1,12,-6,SNOW_BLOCK)
Block(0,12,-6,VINE:1)
Block(1,12,-6,VINE:4)
Block(2,12,-6,SNOW_BLOCK)
Block(3,12,-6,LOG2:13)
Block(4,12,-6,VINE:2)
Block(5,12,-6,VINE:1)
Block(6,12,-6,SNOW_BLOCK)
Block(7,12,-6,SNOW_BLOCK)
Block(8,12,-6,SNOW_BLOCK)
Block(-3,12,-5,SNOW_BLOCK)
Block(-2,12,-5,LOG2:13)
Block(-1,12,-5,SNOW_BLOCK)
Block(0,12,-5,SNOW_BLOCK)
Block(1,12,-5,VINE:8)
Block(2,12,-5,LOG2:13)
Block(3,12,-5,LOG2:13)
Block(4,12,-5,VINE:1)
Block(5,12,-5,SNOW_BLOCK)
Block(6,12,-5,SNOW_BLOCK)
Block(7,12,-5,LOG2:13)
Block(8,12,-5,SNOW_BLOCK)
Block(9,12,-5,SNOW_BLOCK)
Block(-6,12,-4,SNOW_BLOCK)
Block(-5,12,-4,VINE:1)
Block(-3,12,-4,VINE:4)
Block(-2,12,-4,LOG2:13)
Block(-1,12,-4,LOG2:13)
Block(0,12,-4,VINE:10)
Block(1,12,-4,VINE:8)
Block(2,12,-4,VINE:8)
Block(3,12,-4,LOG2:13)
Block(4,12,-4,SNOW_BLOCK)
Block(5,12,-4,VINE:2)
Block(6,12,-4,LOG2:13)
Block(7,12,-4,SNOW_BLOCK)
Block(8,12,-4,SNOW_BLOCK)
Block(-6,12,-3,SNOW_BLOCK)
Block(-5,12,-3,SNOW_BLOCK)
Block(-2,12,-3,SNOW_BLOCK)
Block(-1,12,-3,LOG2:13)
Block(1,12,-3,VINE:8)
Block(2,12,-3,SNOW_BLOCK)
Block(3,12,-3,LOG2:13)
Block(4,12,-3,SNOW_BLOCK)
Block(6,12,-3,SNOW_BLOCK)
Block(7,12,-3,SNOW_BLOCK)
Block(-6,12,-2,SNOW_BLOCK)
Block(-5,12,-2,SNOW_BLOCK)
Block(-4,12,-2,VINE:8)
Block(-3,12,-2,SNOW_BLOCK)
Block(-2,12,-2,LOG2:13)
Block(0,12,-2,VINE:8)
Block(1,12,-2,SNOW_BLOCK)
Block(2,12,-2,VINE:8)
Block(3,12,-2,LOG2:13)
Block(4,12,-2,SNOW_BLOCK)
Block(5,12,-2,VINE:1)
Block(7,12,-2,SNOW_BLOCK)
Block(8,12,-2,SNOW_BLOCK)
Block(-6,12,-1,SNOW_BLOCK)
Block(-4,12,-1,SNOW_BLOCK)
Block(-3,12,-1,SNOW_BLOCK)
Block(-2,12,-1,SNOW_BLOCK)
Block(-1,12,-1,VINE:2)
Block(1,12,-1,LOG2:13)
Block(2,12,-1,VINE:2)
Block(3,12,-1,VINE:4)
Block(4,12,-1,VINE:8)
Block(5,12,-1,SNOW_BLOCK)
Block(6,12,-1,SNOW_BLOCK)
Block(7,12,-1,SNOW_BLOCK)
Block(8,12,-1,SNOW_BLOCK)
Block(-5,12,0,SNOW_BLOCK)
Block(-4,12,0,VINE:4)
Block(-3,12,0,SNOW_BLOCK)
Block(-2,12,0,VINE:1)
Block(0,12,0,SNOW_BLOCK)
Block(3,12,0,SNOW_BLOCK)
Block(4,12,0,SNOW_BLOCK)
Block(5,12,0,LOG2:13)
Block(6,12,0,LOG2:13)
Block(7,12,0,LOG2:13)
Block(8,12,0,SNOW_BLOCK)
Block(-3,12,1,SNOW_BLOCK)
Block(-2,12,1,SNOW_BLOCK)
Block(-1,12,1,VINE:2)
Block(0,12,1,VINE:4)
Block(1,12,1,VINE:8)
Block(2,12,1,VINE:8)
Block(3,12,1,LOG2:13)
Block(4,12,1,LOG2:13)
Block(5,12,1,LOG2:13)
Block(7,12,1,SNOW_BLOCK)
Block(8,12,1,SNOW_BLOCK)
Block(9,12,1,SNOW_BLOCK)
Block(-7,12,2,VINE:8)
Block(-5,12,2,VINE:1)
Block(-3,12,2,VINE:4)
Block(-2,12,2,LOG2:13)
Block(-1,12,2,LOG2:13)
Block(0,12,2,SNOW_BLOCK)
Block(1,12,2,VINE:2)
Block(2,12,2,VINE:8)
Block(3,12,2,SNOW_BLOCK)
Block(-6,12,3,VINE:12)
Block(-5,12,3,SNOW_BLOCK)
Block(-4,12,3,LOG2:13)
Block(-2,12,3,SNOW_BLOCK)
Block(-1,12,3,SNOW_BLOCK)
Block(0,12,3,LOG2:13)
Block(1,12,3,SNOW_BLOCK)
Block(2,12,3,VINE:2)
Block(4,12,3,SNOW_BLOCK)
Block(6,12,3,SNOW_BLOCK)
Block(-6,12,4,VINE:4)
Block(-5,12,4,SNOW_BLOCK)
Block(-4,12,4,SNOW_BLOCK)
Block(-3,12,4,LOG2:13)
Block(-2,12,4,SNOW_BLOCK)
Block(0,12,4,LOG2:13)
Block(1,12,4,SNOW_BLOCK)
Block(4,12,4,SNOW_BLOCK)
Block(5,12,4,SNOW_BLOCK)
Block(6,12,4,SNOW_BLOCK)
Block(7,12,4,SNOW_BLOCK)
Block(-7,12,5,VINE:8)
Block(-6,12,5,SNOW_BLOCK)
Block(-5,12,5,SNOW_BLOCK)
Block(-4,12,5,SNOW_BLOCK)
Block(-1,12,5,SNOW_BLOCK)
Block(0,12,5,LOG2:13)
Block(1,12,5,LOG2:13)
Block(3,12,5,VINE:1)
Block(4,12,5,SNOW_BLOCK)
Block(5,12,5,SNOW_BLOCK)
Block(6,12,5,SNOW_BLOCK)
Block(7,12,5,SNOW_BLOCK)
Block(-6,12,6,VINE:4)
Block(-5,12,6,VINE:4)
Block(-4,12,6,SNOW_BLOCK)
Block(-3,12,6,VINE:2)
Block(-2,12,6,VINE:8)
Block(-1,12,6,SNOW_BLOCK)
Block(0,12,6,SNOW_BLOCK)
Block(1,12,6,SNOW_BLOCK)
Block(2,12,6,SNOW_BLOCK)
Block(3,12,6,SNOW_BLOCK)
Block(4,12,6,VINE:2)
Block(5,12,6,VINE:4)
Block(6,12,6,SNOW_BLOCK)
Block(-2,12,7,VINE:8)
Block(-1,12,7,SNOW_BLOCK)
Block(0,12,7,SNOW_BLOCK)
Block(1,12,7,SNOW_BLOCK)
Block(-1,12,8,VINE:4)
Block(0,12,8,VINE:4)
Block(4,13,-9,VINE:1)
Block(-5,13,-8,VINE:1)
Block(-3,13,-8,SNOW_BLOCK)
Block(-2,13,-8,VINE:1)
Block(-1,13,-8,VINE:1)
Block(1,13,-8,VINE:1)
Block(2,13,-8,VINE:8)
Block(3,13,-8,SNOW_BLOCK)
Block(4,13,-8,SNOW_BLOCK)
Block(5,13,-8,VINE:2)
Block(-6,13,-7,VINE:8)
Block(-5,13,-7,SNOW_BLOCK)
Block(-4,13,-7,SNOW_BLOCK)
Block(-3,13,-7,SNOW_BLOCK)
Block(-2,13,-7,SNOW_BLOCK)
Block(-1,13,-7,VINE:2)
Block(0,13,-7,VINE:8)
Block(1,13,-7,SNOW_BLOCK)
Block(2,13,-7,SNOW_BLOCK)
Block(3,13,-7,SNOW_BLOCK)
Block(4,13,-7,SNOW_BLOCK)
Block(5,13,-7,VINE:1)
Block(-5,13,-6,VINE:8)
Block(-4,13,-6,SNOW_BLOCK)
Block(-3,13,-6,LOG2:13)
Block(-2,13,-6,LOG2:13)
Block(-1,13,-6,VINE:2)
Block(0,13,-6,VINE:1)
Block(1,13,-6,VINE:4)
Block(2,13,-6,SNOW_BLOCK)
Block(3,13,-6,SNOW_BLOCK)
Block(4,13,-6,VINE:2)
Block(7,13,-6,VINE:1)
Block(8,13,-6,VINE:2)
Block(-4,13,-5,SNOW_BLOCK)
Block(-3,13,-5,LOG2:13)
Block(-2,13,-5,LOG2:13)
Block(-1,13,-5,VINE:8)
Block(0,13,-5,SNOW_BLOCK)
Block(1,13,-5,VINE:1)
Block(2,13,-5,SNOW_BLOCK)
Block(4,13,-5,VINE:1)
Block(6,13,-5,VINE:8)
Block(7,13,-5,SNOW_BLOCK)
Block(8,13,-5,VINE:2)
Block(-5,13,-4,SNOW_BLOCK)
Block(-4,13,-4,VINE:2)
Block(-3,13,-4,SNOW_BLOCK)
Block(-2,13,-4,VINE:1)
Block(0,13,-4,VINE:8)
Block(1,13,-4,VINE:8)
Block(2,13,-4,SNOW_BLOCK)
Block(3,13,-4,VINE:8)
Block(4,13,-4,SNOW_BLOCK)
Block(5,13,-4,VINE:2)
Block(-6,13,-3,SNOW_BLOCK)
Block(-5,13,-3,SNOW_BLOCK)
Block(-4,13,-3,SNOW_BLOCK)
Block(-2,13,-3,SNOW_BLOCK)
Block(-1,13,-3,LOG2:13)
Block(0,13,-3,SNOW_BLOCK)
Block(2,13,-3,VINE:8)
Block(3,13,-3,LOG2:13)
Block(4,13,-3,SNOW_BLOCK)
Block(6,13,-3,VINE:2)
Block(-6,13,-2,SNOW_BLOCK)
Block(-5,13,-2,LOG2:13)
Block(-4,13,-2,LOG2:13)
Block(-3,13,-2,LOG2:13)
Block(-2,13,-2,LOG2:13)
Block(-1,13,-2,SNOW_BLOCK)
Block(1,13,-2,VINE:1)
Block(2,13,-2,VINE:8)
Block(3,13,-2,SNOW_BLOCK)
Block(4,13,-2,SNOW_BLOCK)
Block(5,13,-2,VINE:1)
Block(-6,13,-1,SNOW_BLOCK)
Block(-5,13,-1,SNOW_BLOCK)
Block(-4,13,-1,SNOW_BLOCK)
Block(-3,13,-1,SNOW_BLOCK)
Block(-2,13,-1,VINE:2)
Block(0,13,-1,LOG2:13)
Block(1,13,-1,LOG2:13)
Block(2,13,-1,VINE:2)
Block(4,13,-1,SNOW_BLOCK)
Block(5,13,-1,SNOW_BLOCK)
Block(6,13,-1,SNOW_BLOCK)
Block(7,13,-1,VINE:2)
Block(-6,13,0,SNOW_BLOCK)
Block(-5,13,0,SNOW_BLOCK)
Block(-4,13,0,VINE:4)
Block(-3,13,0,SNOW_BLOCK)
Block(-2,13,0,VINE:3)
Block(0,13,0,VINE:4)
Block(4,13,0,SNOW_BLOCK)
Block(5,13,0,SNOW_BLOCK)
Block(6,13,0,SNOW_BLOCK)
Block(7,13,0,SNOW_BLOCK)
Block(-2,13,1,SNOW_BLOCK)
Block(-1,13,1,SNOW_BLOCK)
Block(0,13,1,VINE:1)
Block(1,13,1,VINE:8)
Block(2,13,1,VINE:8)
Block(3,13,1,LOG2:13)
Block(4,13,1,LOG2:13)
Block(7,13,1,SNOW_BLOCK)
Block(8,13,1,SNOW_BLOCK)
Block(-7,13,2,VINE:8)
Block(-3,13,2,VINE:4)
Block(-2,13,2,SNOW_BLOCK)
Block(-1,13,2,LOG2:13)
Block(0,13,2,SNOW_BLOCK)
Block(1,13,2,VINE:2)
Block(2,13,2,VINE:8)
Block(3,13,2,SNOW_BLOCK)
Block(5,13,2,SNOW_BLOCK)
Block(-6,13,3,VINE:4)
Block(-4,13,3,SNOW_BLOCK)
Block(-2,13,3,SNOW_BLOCK)
Block(-1,13,3,LOG2:13)
Block(1,13,3,SNOW_BLOCK)
Block(2,13,3,VINE:2)
Block(3,13,3,VINE:4)
Block(4,13,3,VINE:4)
Block(5,13,3,VINE:4)
Block(-6,13,4,VINE:4)
Block(-5,13,4,VINE:5)
Block(-2,13,4,VINE:4)
Block(0,13,4,SNOW_BLOCK)
Block(1,13,4,VINE:2)
Block(-6,13,5,VINE:8)
Block(-5,13,5,SNOW_BLOCK)
Block(-4,13,5,SNOW_BLOCK)
Block(-3,13,5,VINE:8)
Block(0,13,5,SNOW_BLOCK)
Block(1,13,5,SNOW_BLOCK)
Block(6,13,5,SNOW_BLOCK)
Block(-5,13,6,VINE:4)
Block(-1,13,6,VINE:1)
Block(0,13,6,SNOW_BLOCK)
Block(-2,13,7,VINE:8)
Block(-1,13,7,SNOW_BLOCK)
Block(0,13,7,SNOW_BLOCK)
Block(0,13,8,VINE:4)
Block(-4,14,-8,VINE:1)
Block(-3,14,-8,SNOW_BLOCK)
Block(-2,14,-8,VINE:1)
Block(-1,14,-8,VINE:1)
Block(1,14,-8,VINE:1)
Block(-5,14,-7,VINE:8)
Block(-4,14,-7,SNOW_BLOCK)
Block(-3,14,-7,VINE:1)
Block(-2,14,-7,SNOW_BLOCK)
Block(-1,14,-7,VINE:2)
Block(3,14,-7,VINE:1)
Block(5,14,-7,VINE:1)
Block(-4,14,-6,SNOW_BLOCK)
Block(-3,14,-6,SNOW_BLOCK)
Block(-2,14,-6,VINE:2)
Block(-1,14,-6,SNOW_BLOCK)
Block(0,14,-6,VINE:1)
Block(2,14,-6,VINE:1)
Block(4,14,-6,VINE:1)
Block(8,14,-6,VINE:2)
Block(-3,14,-5,SNOW_BLOCK)
Block(-2,14,-5,VINE:2)
Block(-1,14,-5,VINE:8)
Block(1,14,-5,VINE:1)
Block(2,14,-5,SNOW_BLOCK)
Block(3,14,-5,SNOW_BLOCK)
Block(4,14,-5,SNOW_BLOCK)
Block(-6,14,-4,SNOW_BLOCK)
Block(-5,14,-4,VINE:1)
Block(-3,14,-4,VINE:4)
Block(-1,14,-4,SNOW_BLOCK)
Block(0,14,-4,VINE:8)
Block(1,14,-4,SNOW_BLOCK)
Block(2,14,-4,SNOW_BLOCK)
Block(3,14,-4,SNOW_BLOCK)
Block(4,14,-4,SNOW_BLOCK)
Block(5,14,-4,VINE:2)
Block(-6,14,-3,SNOW_BLOCK)
Block(-5,14,-3,SNOW_BLOCK)
Block(-2,14,-3,SNOW_BLOCK)
Block(-1,14,-3,LOG2:13)
Block(2,14,-3,SNOW_BLOCK)
Block(3,14,-3,LOG2:13)
Block(4,14,-3,SNOW_BLOCK)
Block(5,14,-3,SNOW_BLOCK)
Block(6,14,-3,VINE:2)
Block(-6,14,-2,SNOW_BLOCK)
Block(-5,14,-2,SNOW_BLOCK)
Block(-4,14,-2,LOG2:13)
Block(-3,14,-2,SNOW_BLOCK)
Block(-1,14,-2,SNOW_BLOCK)
Block(0,14,-2,SNOW_BLOCK)
Block(2,14,-2,VINE:8)
Block(3,14,-2,SNOW_BLOCK)
Block(4,14,-2,SNOW_BLOCK)
Block(-6,14,-1,SNOW_BLOCK)
Block(-4,14,-1,SNOW_BLOCK)
Block(-3,14,-1,VINE:5)
Block(-2,14,-1,SNOW_BLOCK)
Block(-1,14,-1,SNOW_BLOCK)
Block(0,14,-1,LOG2:13)
Block(1,14,-1,LOG2:13)
Block(2,14,-1,LOG2:13)
Block(4,14,-1,SNOW_BLOCK)
Block(5,14,-1,SNOW_BLOCK)
Block(-5,14,0,SNOW_BLOCK)
Block(-4,14,0,VINE:2)
Block(-3,14,0,VINE:1)
Block(-2,14,0,VINE:1)
Block(-1,14,0,VINE:8)
Block(0,14,0,LOG2:13)
Block(3,14,0,SNOW_BLOCK)
Block(4,14,0,LOG2:13)
Block(5,14,0,SNOW_BLOCK)
Block(6,14,0,SNOW_BLOCK)
Block(-3,14,1,SNOW_BLOCK)
Block(-2,14,1,SNOW_BLOCK)
Block(-1,14,1,SNOW_BLOCK)
Block(0,14,1,VINE:1)
Block(1,14,1,VINE:8)
Block(2,14,1,SNOW_BLOCK)
Block(3,14,1,SNOW_BLOCK)
Block(4,14,1,LOG2:13)
Block(5,14,1,SNOW_BLOCK)
Block(6,14,1,SNOW_BLOCK)
Block(-7,14,2,VINE:8)
Block(-3,14,2,VINE:4)
Block(-2,14,2,SNOW_BLOCK)
Block(-1,14,2,LOG2:13)
Block(0,14,2,SNOW_BLOCK)
Block(2,14,2,VINE:8)
Block(3,14,2,SNOW_BLOCK)
Block(4,14,2,SNOW_BLOCK)
Block(-6,14,3,VINE:4)
Block(-2,14,3,SNOW_BLOCK)
Block(-1,14,3,LOG2:13)
Block(0,14,3,SNOW_BLOCK)
Block(1,14,3,SNOW_BLOCK)
Block(2,14,3,VINE:2)
Block(3,14,3,VINE:4)
Block(4,14,3,VINE:4)
Block(5,14,3,VINE:4)
Block(-6,14,4,VINE:4)
Block(-5,14,4,VINE:4)
Block(-4,14,4,VINE:4)
Block(-2,14,4,VINE:4)
Block(-1,14,4,SNOW_BLOCK)
Block(0,14,4,SNOW_BLOCK)
Block(2,14,4,VINE:2)
Block(-3,14,5,VINE:8)
Block(-1,14,5,SNOW_BLOCK)
Block(0,14,5,VINE:2)
Block(1,14,5,VINE:4)
Block(2,14,5,VINE:2)
Block(-1,14,6,VINE:4)
Block(1,14,6,VINE:2)
Block(2,15,-9,VINE:1)
Block(-1,15,-8,VINE:1)
Block(1,15,-8,VINE:1)
Block(3,15,-7,VINE:1)
Block(5,15,-7,VINE:1)
Block(-1,15,-6,VINE:4)
Block(0,15,-6,VINE:1)
Block(2,15,-6,VINE:1)
Block(8,15,-6,VINE:2)
Block(-1,15,-5,VINE:8)
Block(1,15,-5,SNOW_BLOCK)
Block(2,15,-5,SNOW_BLOCK)
Block(3,15,-5,SNOW_BLOCK)
Block(4,15,-5,SNOW_BLOCK)
Block(5,15,-5,SNOW_BLOCK)
Block(-3,15,-4,VINE:1)
Block(-1,15,-4,SNOW_BLOCK)
Block(1,15,-4,SNOW_BLOCK)
Block(2,15,-4,SNOW_BLOCK)
Block(3,15,-4,LOG2:13)
Block(4,15,-4,SNOW_BLOCK)
Block(5,15,-4,VINE:2)
Block(-4,15,-3,VINE:8)
Block(-3,15,-3,SNOW_BLOCK)
Block(-2,15,-3,SNOW_BLOCK)
Block(-1,15,-3,LOG2:13)
Block(0,15,-3,SNOW_BLOCK)
Block(2,15,-3,SNOW_BLOCK)
Block(3,15,-3,LOG2:13)
Block(4,15,-3,SNOW_BLOCK)
Block(5,15,-3,SNOW_BLOCK)
Block(6,15,-3,VINE:2)
Block(7,15,-3,VINE:4)
Block(-3,15,-2,SNOW_BLOCK)
Block(-2,15,-2,SNOW_BLOCK)
Block(-1,15,-2,SNOW_BLOCK)
Block(0,15,-2,SNOW_BLOCK)
Block(2,15,-2,LOG2:13)
Block(3,15,-2,SNOW_BLOCK)
Block(4,15,-2,SNOW_BLOCK)
Block(5,15,-2,SNOW_BLOCK)
Block(-4,15,-1,VINE:1)
Block(-3,15,-1,VINE:1)
Block(-2,15,-1,SNOW_BLOCK)
Block(-1,15,-1,SNOW_BLOCK)
Block(0,15,-1,SNOW_BLOCK)
Block(1,15,-1,VINE:8)
Block(2,15,-1,LOG2:13)
Block(3,15,-1,SNOW_BLOCK)
Block(4,15,-1,SNOW_BLOCK)
Block(5,15,-1,SNOW_BLOCK)
Block(6,15,-1,SNOW_BLOCK)
Block(-3,15,0,SNOW_BLOCK)
Block(-2,15,0,VINE:1)
Block(-1,15,0,LOG2:13)
Block(0,15,0,LOG2:13)
Block(2,15,0,SNOW_BLOCK)
Block(3,15,0,SNOW_BLOCK)
Block(4,15,0,LOG2:13)
Block(5,15,0,SNOW_BLOCK)
Block(-5,15,1,SNOW_BLOCK)
Block(-4,15,1,SNOW_BLOCK)
Block(-3,15,1,LOG2:13)
Block(-2,15,1,LOG2:13)
Block(-1,15,1,SNOW_BLOCK)
Block(0,15,1,VINE:1)
Block(1,15,1,SNOW_BLOCK)
Block(2,15,1,VINE:1)
Block(3,15,1,SNOW_BLOCK)
Block(4,15,1,SNOW_BLOCK)
Block(5,15,1,LOG2:13)
Block(6,15,1,SNOW_BLOCK)
Block(-7,15,2,VINE:8)
Block(-6,15,2,SNOW_BLOCK)
Block(-5,15,2,SNOW_BLOCK)
Block(-4,15,2,SNOW_BLOCK)
Block(-3,15,2,SNOW_BLOCK)
Block(-2,15,2,SNOW_BLOCK)
Block(-1,15,2,LOG2:13)
Block(0,15,2,SNOW_BLOCK)
Block(1,15,2,SNOW_BLOCK)
Block(2,15,2,VINE:2)
Block(3,15,2,SNOW_BLOCK)
Block(4,15,2,SNOW_BLOCK)
Block(5,15,2,SNOW_BLOCK)
Block(6,15,2,SNOW_BLOCK)
Block(-6,15,3,VINE:4)
Block(-4,15,3,SNOW_BLOCK)
Block(-3,15,3,SNOW_BLOCK)
Block(-2,15,3,SNOW_BLOCK)
Block(-1,15,3,LOG2:13)
Block(0,15,3,SNOW_BLOCK)
Block(1,15,3,SNOW_BLOCK)
Block(2,15,3,VINE:2)
Block(3,15,3,VINE:4)
Block(4,15,3,VINE:4)
Block(5,15,3,VINE:4)
Block(-6,15,4,VINE:4)
Block(-5,15,4,VINE:4)
Block(-4,15,4,VINE:4)
Block(-3,15,4,VINE:8)
Block(-2,15,4,SNOW_BLOCK)
Block(-1,15,4,SNOW_BLOCK)
Block(0,15,4,SNOW_BLOCK)
Block(1,15,4,SNOW_BLOCK)
Block(2,15,4,VINE:2)
Block(-3,15,5,VINE:8)
Block(-1,15,5,SNOW_BLOCK)
Block(0,15,5,SNOW_BLOCK)
Block(1,15,5,VINE:4)
Block(2,15,5,VINE:2)
Block(-3,15,6,VINE:8)
Block(1,15,6,VINE:2)
Block(2,16,-9,VINE:1)
Block(-1,16,-8,VINE:1)
Block(1,16,-8,VINE:1)
Block(3,16,-7,VINE:1)
Block(5,16,-7,VINE:1)
Block(-1,16,-6,VINE:4)
Block(0,16,-6,VINE:1)
Block(3,16,-6,SNOW_BLOCK)
Block(4,16,-6,SNOW_BLOCK)
Block(8,16,-6,VINE:2)
Block(-1,16,-5,VINE:8)
Block(0,16,-5,SNOW_BLOCK)
Block(2,16,-5,SNOW_BLOCK)
Block(3,16,-5,SNOW_BLOCK)
Block(4,16,-5,SNOW_BLOCK)
Block(-2,16,-4,SNOW_BLOCK)
Block(-1,16,-4,SNOW_BLOCK)
Block(0,16,-4,SNOW_BLOCK)
Block(1,16,-4,SNOW_BLOCK)
Block(2,16,-4,SNOW_BLOCK)
Block(3,16,-4,SNOW_BLOCK)
Block(4,16,-4,SNOW_BLOCK)
Block(5,16,-4,SNOW_BLOCK)
Block(6,16,-4,VINE:2)
Block(7,16,-4,SNOW_BLOCK)
Block(-4,16,-3,VINE:8)
Block(-3,16,-3,SNOW_BLOCK)
Block(-2,16,-3,SNOW_BLOCK)
Block(-1,16,-3,LOG2:13)
Block(0,16,-3,SNOW_BLOCK)
Block(2,16,-3,SNOW_BLOCK)
Block(3,16,-3,SNOW_BLOCK)
Block(4,16,-3,LOG2:13)
Block(5,16,-3,SNOW_BLOCK)
Block(7,16,-3,VINE:4)
Block(-3,16,-2,SNOW_BLOCK)
Block(-2,16,-2,LOG2:13)
Block(-1,16,-2,LOG2:13)
Block(0,16,-2,SNOW_BLOCK)
Block(1,16,-2,SNOW_BLOCK)
Block(2,16,-2,LOG2:13)
Block(3,16,-2,VINE:2)
Block(4,16,-2,VINE:4)
Block(-4,16,-1,VINE:1)
Block(-2,16,-1,SNOW_BLOCK)
Block(-1,16,-1,VINE:8)
Block(0,16,-1,SNOW_BLOCK)
Block(1,16,-1,SNOW_BLOCK)
Block(2,16,-1,SNOW_BLOCK)
Block(4,16,-1,SNOW_BLOCK)
Block(5,16,-1,SNOW_BLOCK)
Block(6,16,-1,VINE:2)
Block(-6,16,0,SNOW_BLOCK)
Block(-4,16,0,SNOW_BLOCK)
Block(-3,16,0,SNOW_BLOCK)
Block(-2,16,0,LOG2:13)
Block(-1,16,0,LOG2:13)
Block(0,16,0,VINE:4)
Block(1,16,0,VINE:4)
Block(2,16,0,VINE:4)
Block(4,16,0,SNOW_BLOCK)
Block(5,16,0,SNOW_BLOCK)
Block(6,16,0,SNOW_BLOCK)
Block(-6,16,1,SNOW_BLOCK)
Block(-5,16,1,SNOW_BLOCK)
Block(-4,16,1,LOG2:13)
Block(-3,16,1,LOG2:13)
Block(-2,16,1,SNOW_BLOCK)
Block(-1,16,1,LOG2:13)
Block(0,16,1,SNOW_BLOCK)
Block(1,16,1,VINE:2)
Block(2,16,1,VINE:1)
Block(3,16,1,SNOW_BLOCK)
Block(4,16,1,SNOW_BLOCK)
Block(5,16,1,SNOW_BLOCK)
Block(6,16,1,SNOW_BLOCK)
Block(-7,16,2,VINE:8)
Block(-6,16,2,SNOW_BLOCK)
Block(-5,16,2,LOG2:13)
Block(-4,16,2,LOG2:13)
Block(-3,16,2,LOG2:13)
Block(-2,16,2,SNOW_BLOCK)
Block(-1,16,2,LOG2:13)
Block(0,16,2,SNOW_BLOCK)
Block(1,16,2,SNOW_BLOCK)
Block(2,16,2,VINE:2)
Block(5,16,2,SNOW_BLOCK)
Block(6,16,2,SNOW_BLOCK)
Block(-6,16,3,SNOW_BLOCK)
Block(-5,16,3,SNOW_BLOCK)
Block(-4,16,3,SNOW_BLOCK)
Block(-3,16,3,VINE:4)
Block(-2,16,3,SNOW_BLOCK)
Block(-1,16,3,SNOW_BLOCK)
Block(0,16,3,SNOW_BLOCK)
Block(1,16,3,SNOW_BLOCK)
Block(2,16,3,VINE:2)
Block(5,16,3,VINE:4)
Block(-6,16,4,VINE:4)
Block(-5,16,4,VINE:4)
Block(-4,16,4,VINE:4)
Block(-3,16,4,VINE:8)
Block(-2,16,4,SNOW_BLOCK)
Block(-1,16,4,SNOW_BLOCK)
Block(0,16,4,LOG2:13)
Block(1,16,4,SNOW_BLOCK)
Block(2,16,4,VINE:2)
Block(-3,16,5,VINE:8)
Block(-2,16,5,SNOW_BLOCK)
Block(-1,16,5,SNOW_BLOCK)
Block(0,16,5,SNOW_BLOCK)
Block(1,16,5,SNOW_BLOCK)
Block(2,16,5,VINE:2)
Block(-3,16,6,VINE:8)
Block(-2,16,6,SNOW_BLOCK)
Block(-1,16,6,SNOW_BLOCK)
Block(0,16,6,SNOW_BLOCK)
Block(1,16,6,VINE:2)
Block(2,17,-9,VINE:1)
Block(-1,17,-8,VINE:1)
Block(0,17,-8,VINE:1)
Block(1,17,-8,VINE:1)
Block(3,17,-8,VINE:1)
Block(0,17,-7,SNOW_BLOCK)
Block(1,17,-7,SNOW_BLOCK)
Block(2,17,-7,SNOW_BLOCK)
Block(5,17,-7,VINE:1)
Block(-1,17,-6,VINE:4)
Block(0,17,-6,SNOW_BLOCK)
Block(1,17,-6,SNOW_BLOCK)
Block(2,17,-6,SNOW_BLOCK)
Block(5,17,-6,SNOW_BLOCK)
Block(8,17,-6,VINE:2)
Block(-1,17,-5,VINE:8)
Block(0,17,-5,SNOW_BLOCK)
Block(1,17,-5,SNOW_BLOCK)
Block(2,17,-5,SNOW_BLOCK)
Block(5,17,-5,SNOW_BLOCK)
Block(6,17,-5,SNOW_BLOCK)
Block(7,17,-5,SNOW_BLOCK)
Block(-4,17,-4,VINE:1)
Block(-2,17,-4,VINE:1)
Block(-1,17,-4,SNOW_BLOCK)
Block(0,17,-4,SNOW_BLOCK)
Block(1,17,-4,SNOW_BLOCK)
Block(2,17,-4,VINE:2)
Block(3,17,-4,VINE:8)
Block(4,17,-4,LOG2:13)
Block(5,17,-4,SNOW_BLOCK)
Block(6,17,-4,LOG2:13)
Block(7,17,-4,SNOW_BLOCK)
Block(-4,17,-3,SNOW_BLOCK)
Block(-3,17,-3,SNOW_BLOCK)
Block(-2,17,-3,SNOW_BLOCK)
Block(-1,17,-3,SNOW_BLOCK)
Block(0,17,-3,SNOW_BLOCK)
Block(1,17,-3,LOG2:13)
Block(2,17,-3,LOG2:13)
Block(3,17,-3,LOG2:13)
Block(4,17,-3,LOG2:13)
Block(5,17,-3,SNOW_BLOCK)
Block(6,17,-3,SNOW_BLOCK)
Block(-3,17,-2,SNOW_BLOCK)
Block(-2,17,-2,LOG2:13)
Block(-1,17,-2,SNOW_BLOCK)
Block(0,17,-2,SNOW_BLOCK)
Block(2,17,-2,LOG2:13)
Block(3,17,-2,LOG2:13)
Block(4,17,-2,SNOW_BLOCK)
Block(6,17,-2,SNOW_BLOCK)
Block(-3,17,-1,SNOW_BLOCK)
Block(-2,17,-1,SNOW_BLOCK)
Block(-1,17,-1,SNOW_BLOCK)
Block(0,17,-1,SNOW_BLOCK)
Block(1,17,-1,VINE:2)
Block(2,17,-1,VINE:4)
Block(-4,17,0,SNOW_BLOCK)
Block(-3,17,0,SNOW_BLOCK)
Block(-2,17,0,SNOW_BLOCK)
Block(-1,17,0,LOG2:13)
Block(0,17,0,SNOW_BLOCK)
Block(-6,17,1,VINE:8)
Block(-5,17,1,SNOW_BLOCK)
Block(-4,17,1,LOG2:13)
Block(-3,17,1,VINE:4)
Block(-1,17,1,LOG2:13)
Block(2,17,1,VINE:1)
Block(-7,17,2,VINE:8)
Block(-6,17,2,SNOW_BLOCK)
Block(-5,17,2,LOG2:13)
Block(-4,17,2,SNOW_BLOCK)
Block(-3,17,2,LOG2:13)
Block(-2,17,2,VINE:4)
Block(-1,17,2,VINE:8)
Block(0,17,2,SNOW_BLOCK)
Block(1,17,2,SNOW_BLOCK)
Block(2,17,2,VINE:2)
Block(-5,17,3,SNOW_BLOCK)
Block(-4,17,3,SNOW_BLOCK)
Block(-3,17,3,VINE:4)
Block(-2,17,3,VINE:8)
Block(-1,17,3,VINE:1)
Block(0,17,3,LOG2:13)
Block(1,17,3,SNOW_BLOCK)
Block(2,17,3,VINE:2)
Block(-5,17,4,VINE:4)
Block(-4,17,4,VINE:4)
Block(-2,17,4,VINE:1)
Block(-1,17,4,SNOW_BLOCK)
Block(0,17,4,LOG2:13)
Block(1,17,4,SNOW_BLOCK)
Block(2,17,4,VINE:2)
Block(-3,17,5,VINE:8)
Block(-2,17,5,SNOW_BLOCK)
Block(-1,17,5,SNOW_BLOCK)
Block(0,17,5,SNOW_BLOCK)
Block(1,17,5,SNOW_BLOCK)
Block(2,17,5,VINE:2)
Block(-2,17,6,VINE:4)
Block(-1,17,6,SNOW_BLOCK)
Block(0,17,6,SNOW_BLOCK)
Block(1,17,6,VINE:2)
Block(-1,17,7,VINE:4)
Block(2,18,-9,VINE:1)
Block(-1,18,-8,VINE:1)
Block(0,18,-8,VINE:1)
Block(1,18,-8,VINE:1)
Block(2,18,-8,SNOW_BLOCK)
Block(3,18,-8,VINE:1)
Block(-1,18,-7,SNOW_BLOCK)
Block(0,18,-7,SNOW_BLOCK)
Block(1,18,-7,SNOW_BLOCK)
Block(2,18,-7,SNOW_BLOCK)
Block(3,18,-7,SNOW_BLOCK)
Block(5,18,-7,VINE:1)
Block(-1,18,-6,VINE:4)
Block(0,18,-6,SNOW_BLOCK)
Block(1,18,-6,LOG2:13)
Block(2,18,-6,SNOW_BLOCK)
Block(3,18,-6,SNOW_BLOCK)
Block(4,18,-6,SNOW_BLOCK)
Block(5,18,-6,SNOW_BLOCK)
Block(6,18,-6,VINE:1)
Block(7,18,-6,SNOW_BLOCK)
Block(8,18,-6,VINE:2)
Block(-1,18,-5,VINE:8)
Block(0,18,-5,SNOW_BLOCK)
Block(1,18,-5,LOG2:13)
Block(2,18,-5,LOG2:13)
Block(3,18,-5,SNOW_BLOCK)
Block(5,18,-5,SNOW_BLOCK)
Block(6,18,-5,LOG2:13)
Block(7,18,-5,SNOW_BLOCK)
Block(-3,18,-4,SNOW_BLOCK)
Block(1,18,-4,LOG2:13)
Block(2,18,-4,LOG2:13)
Block(3,18,-4,VINE:8)
Block(4,18,-4,LOG2:13)
Block(5,18,-4,LOG2:13)
Block(6,18,-4,LOG2:13)
Block(7,18,-4,SNOW_BLOCK)
Block(-4,18,-3,SNOW_BLOCK)
Block(-3,18,-3,SNOW_BLOCK)
Block(-2,18,-3,VINE:2)
Block(1,18,-3,VINE:4)
Block(2,18,-3,VINE:4)
Block(3,18,-3,SNOW_BLOCK)
Block(4,18,-3,VINE:2)
Block(5,18,-3,LOG2:13)
Block(6,18,-3,SNOW_BLOCK)
Block(-4,18,-2,SNOW_BLOCK)
Block(-3,18,-2,SNOW_BLOCK)
Block(-2,18,-2,SNOW_BLOCK)
Block(2,18,-2,LOG2:13)
Block(3,18,-2,SNOW_BLOCK)
Block(4,18,-2,VINE:2)
Block(-3,18,-1,VINE:8)
Block(-2,18,-1,SNOW_BLOCK)
Block(-1,18,-1,SNOW_BLOCK)
Block(1,18,-1,SNOW_BLOCK)
Block(2,18,-1,SNOW_BLOCK)
Block(-3,18,0,VINE:8)
Block(-2,18,0,SNOW_BLOCK)
Block(-1,18,0,LOG2:13)
Block(0,18,0,LOG2:13)
Block(-1,18,1,SNOW_BLOCK)
Block(0,18,1,SNOW_BLOCK)
Block(1,18,1,SNOW_BLOCK)
Block(2,18,1,VINE:1)
Block(-6,18,2,VINE:8)
Block(-5,18,2,SNOW_BLOCK)
Block(-4,18,2,VINE:1)
Block(-2,18,2,VINE:4)
Block(-1,18,2,VINE:8)
Block(0,18,2,SNOW_BLOCK)
Block(1,18,2,SNOW_BLOCK)
Block(-4,18,3,SNOW_BLOCK)
Block(-2,18,3,VINE:8)
Block(0,18,3,SNOW_BLOCK)
Block(1,18,3,SNOW_BLOCK)
Block(-1,18,4,SNOW_BLOCK)
Block(0,18,4,SNOW_BLOCK)
Block(-2,18,5,SNOW_BLOCK)
Block(-1,18,5,SNOW_BLOCK)
Block(-2,18,6,VINE:4)
Block(-1,18,6,VINE:4)
Block(2,19,-9,VINE:1)
Block(2,19,-8,SNOW_BLOCK)
Block(3,19,-8,VINE:1)
Block(0,19,-7,SNOW_BLOCK)
Block(1,19,-7,SNOW_BLOCK)
Block(2,19,-7,SNOW_BLOCK)
Block(3,19,-7,SNOW_BLOCK)
Block(5,19,-7,VINE:1)
Block(1,19,-6,SNOW_BLOCK)
Block(2,19,-6,SNOW_BLOCK)
Block(3,19,-6,VINE:2)
Block(5,19,-6,SNOW_BLOCK)
Block(-1,19,-5,VINE:8)
Block(0,19,-5,SNOW_BLOCK)
Block(1,19,-5,LOG2:13)
Block(2,19,-5,SNOW_BLOCK)
Block(5,19,-5,SNOW_BLOCK)
Block(6,19,-5,SNOW_BLOCK)
Block(7,19,-5,SNOW_BLOCK)
Block(0,19,-4,SNOW_BLOCK)
Block(1,19,-4,SNOW_BLOCK)
Block(2,19,-4,VINE:4)
Block(5,19,-4,SNOW_BLOCK)
Block(6,19,-4,SNOW_BLOCK)
Block(0,19,-3,SNOW_BLOCK)
Block(1,19,-3,SNOW_BLOCK)
Block(3,19,-3,SNOW_BLOCK)
Block(4,19,-3,VINE:2)
Block(0,19,-2,SNOW_BLOCK)
Block(1,19,-2,SNOW_BLOCK)
Block(2,19,-2,LOG2:13)
Block(3,19,-2,SNOW_BLOCK)
Block(6,19,-2,SNOW_BLOCK)
Block(-3,19,-1,VINE:8)
Block(-2,19,-1,SNOW_BLOCK)
Block(-1,19,-1,SNOW_BLOCK)
Block(0,19,-1,SNOW_BLOCK)
Block(1,19,-1,SNOW_BLOCK)
Block(2,19,-1,SNOW_BLOCK)
Block(3,19,-1,SNOW_BLOCK)
Block(-3,19,0,VINE:8)
Block(-2,19,0,SNOW_BLOCK)
Block(-1,19,0,LOG2:13)
Block(0,19,0,LOG2:13)
Block(1,19,0,SNOW_BLOCK)
Block(-2,19,1,SNOW_BLOCK)
Block(-1,19,1,SNOW_BLOCK)
Block(0,19,1,LOG2:13)
Block(1,19,1,SNOW_BLOCK)
Block(2,19,1,VINE:1)
Block(-2,19,2,VINE:4)
Block(-1,19,2,SNOW_BLOCK)
Block(0,19,2,SNOW_BLOCK)
Block(1,19,2,SNOW_BLOCK)
Block(2,19,2,SNOW_BLOCK)
Block(-2,19,3,VINE:8)
Block(0,19,3,VINE:4)
Block(-1,19,4,VINE:4)
Block(1,20,-7,SNOW_BLOCK)
Block(2,20,-7,VINE:2)
Block(5,20,-5,SNOW_BLOCK)
Block(1,20,-4,VINE:1)
Block(2,20,-4,SNOW_BLOCK)
Block(6,20,-4,SNOW_BLOCK)
Block(-1,20,-3,SNOW_BLOCK)
Block(0,20,-3,SNOW_BLOCK)
Block(1,20,-3,SNOW_BLOCK)
Block(2,20,-3,SNOW_BLOCK)
Block(0,20,-2,SNOW_BLOCK)
Block(1,20,-2,LOG2:13)
Block(2,20,-2,LOG2:13)
Block(3,20,-2,SNOW_BLOCK)
Block(-1,20,-1,SNOW_BLOCK)
Block(0,20,-1,SNOW_BLOCK)
Block(1,20,-1,SNOW_BLOCK)
Block(2,20,-1,SNOW_BLOCK)
Block(3,20,-1,SNOW_BLOCK)
Block(-3,20,0,VINE:8)
Block(-2,20,0,SNOW_BLOCK)
Block(-1,20,0,SNOW_BLOCK)
Block(0,20,0,SNOW_BLOCK)
Block(1,20,0,SNOW_BLOCK)
Block(-1,20,1,SNOW_BLOCK)
Block(0,20,1,LOG2:13)
Block(1,20,1,SNOW_BLOCK)
Block(-2,20,2,SNOW_BLOCK)
Block(-1,20,2,SNOW_BLOCK)
Block(0,20,2,SNOW_BLOCK)
Block(1,20,2,SNOW_BLOCK)
Block(2,20,2,VINE:2)
Block(-2,20,3,VINE:8)
Block(-1,20,3,SNOW_BLOCK)
Block(0,20,3,VINE:4)
Block(-1,20,4,VINE:4)
Block(1,21,-4,VINE:9)
Block(2,21,-4,SNOW_BLOCK)
Block(0,21,-3,SNOW_BLOCK)
Block(1,21,-3,LOG2:13)
Block(2,21,-3,SNOW_BLOCK)
Block(3,21,-3,SNOW_BLOCK)
Block(0,21,-2,SNOW_BLOCK)
Block(1,21,-2,LOG2:13)
Block(2,21,-2,SNOW_BLOCK)
Block(3,21,-2,SNOW_BLOCK)
Block(1,21,-1,SNOW_BLOCK)
Block(2,21,-1,SNOW_BLOCK)
Block(3,21,-1,SNOW_BLOCK)
Block(-1,21,0,VINE:1)
Block(2,21,0,SNOW_BLOCK)
Block(-1,21,1,SNOW_BLOCK)
Block(0,21,1,SNOW_BLOCK)
Block(1,21,1,SNOW_BLOCK)
Block(-1,21,2,SNOW_BLOCK)
Block(0,21,2,SNOW_BLOCK)
Block(1,21,2,SNOW_BLOCK)
Block(2,21,2,VINE:2)
Block(-1,21,3,SNOW_BLOCK)
Block(0,21,3,SNOW_BLOCK)
Block(-1,21,4,VINE:4)
Block(1,22,-4,SNOW_BLOCK)
Block(2,22,-4,SNOW_BLOCK)
Block(0,22,-3,SNOW_BLOCK)
Block(1,22,-3,SNOW_BLOCK)
Block(2,22,-3,SNOW_BLOCK)
Block(3,22,-3,SNOW_BLOCK)
Block(0,22,-2,SNOW_BLOCK)
Block(1,22,-2,SNOW_BLOCK)
Block(2,22,-1,SNOW_BLOCK)

#######################################################################
# +-----------------------------------------------------------------+ #
# |                            BO3 checks                           | #
# +-----------------------------------------------------------------+ #
#######################################################################

# Require a condition at a certain location in order for the BO3 to be spawned.
# BlockCheck(x,y,z,BlockName[,BlockName[,...]]) - one of the blocks must be at the location
# BlockCheckNot(x,y,z,BlockName[,BlockName[,...]]) - all the blocks must not be at the location
# LightCheck(x,y,z,minLightLevel,maxLightLevel) - light must be between min and max (inclusive)

# You can use "Solid" as a BlockName for matching all solid blocks or "All" to match all blocks that aren't air.

# Examples:
BlockCheck(0,-1,0,GRASS,DIRT,DIRT:2)
#   BlockCheck(0,-1,0,Solid)       Require any solid block just below the object
#   BlockCheck(0,-1,0,WOOL)        Require any type of wool just below the object
#   BlockCheck(0,-1,0,WOOL:0)      Require white wool just below the object
#   BlockCheckNot(0,-1,0,WOOL:0)   Require that there is no white wool below the object
#   LightCheck(0,0,0,0,1)          Require almost complete darkness just below the object

#######################################################################
# +-----------------------------------------------------------------+ #
# |                             Branches                            | #
# +-----------------------------------------------------------------+ #
#######################################################################

# Branches are objects that will spawn when this object spawns when it is used in
# the CustomStructure resource. Branches can also have branches, making complex
# structures possible. See the wiki for more details.

# Regular Branches spawn each branch with an independent chance of spawning.
# Branch(x,y,z,branchName,rotation,chance[,anotherBranchName,rotation,chance[,...]][IndividualChance])
# branchName - name of the object to spawn.
# rotation - NORTH, SOUTH, EAST or WEST.
# IndividualChance - The chance each branch has to spawn, assumed to be 100 when left blank

# Weighted Branches spawn branches with a dependent chance of spawning.
# WeightedBranch(x,y,z,branchName,rotation,chance[,anotherBranchName,rotation,chance[,...]][MaxChanceOutOf])
# MaxChanceOutOf - The chance all branches have to spawn out of, assumed to be 100 when left blank
