#######################################################################
# +-----------------------------------------------------------------+ #
# |                            BO3 object                           | #
# +-----------------------------------------------------------------+ #
#######################################################################

# This is the config file of a custom object.
# If you add this object correctly to your BiomeConfigs, it will spawn in the world.

# This is the creator of this BO3 object
Author: BO3 BulkEdit (by LanToaster)

# A short description of this BO3 object
Description: This Object was Created with BO3_BulkEdit

# The BO3 version, don't change this! It can be used by external applications to do a version check.
Version: 3

# The settings mode, WriteAll, WriteWithoutComments or WriteDisable. See WorldConfig.
SettingsMode: WriteDisable


#######################################################################
# +-----------------------------------------------------------------+ #
# |                          Main settings                          | #
# +-----------------------------------------------------------------+ #
#######################################################################

# This needs to be set to true to spawn the object in the Tree and Sapling resources.
Tree: true

# The frequency of the BO3 from 1 to 200. Tries this many times to spawn this BO3 when using the CustomObject(...) resource.
# Ignored by Tree(..), Sapling(..) and CustomStructure(..)
Frequency: 1

# The rarity of the BO3 from 0 to 100. Each spawn attempt has rarity% chance to succeed when using the CustomObject(...) resource.
# Ignored by Tree(..), Sapling(..) and CustomStructure(..)
Rarity: 100.0

# If you set this to true, the BO3 will be placed with a random rotation.
RotateRandomly: true

# The spawn height of the BO3 - randomY, highestBlock or highestSolidBlock.
SpawnHeight: highestSolidBlock

# The height limits for the BO3.
MinHeight: 0

MaxHeight: 68

# Objects can have other objects attacthed to it: branches. Branches can also
# have branches attached to it, which can also have branches, etc. This is the
# maximum branch depth for this objects.
MaxBranchDepth: 10

# When spawned with the UseWorld keyword, this BO3 should NOT spawn in the following biomes.
# If you writer.write the BO3 name directly in the BiomeConfigs, this will be ignored.
ExcludedBiomes: All


#######################################################################
# +-----------------------------------------------------------------+ #
# |                      Source block settings                      | #
# +-----------------------------------------------------------------+ #
#######################################################################

# The block(s) the BO3 should spawn in.
SourceBlocks: AIR

# The maximum percentage of the BO3 that can be outside the SourceBlock.
# The BO3 won't be placed on a location with more blocks outside the SourceBlock than this percentage.
MaxPercentageOutsideSourceBlock: 0

# What to do when a block is about to be placed outside the SourceBlock? (dontPlace, placeAnyway)
OutsideSourceBlock: dontPlace


#######################################################################
# +-----------------------------------------------------------------+ #
# |                              Blocks                             | #
# +-----------------------------------------------------------------+ #
#######################################################################

# All the blocks used in the BO3 are listed here. Possible blocks:
# Block(x,y,z,id[.data][,nbtfile.nbt)
# RandomBlock(x,y,z,id[:data][,nbtfile.nbt],chance[,id[:data][,nbtfile.nbt],chance[,...]])
# So RandomBlock(0,0,0,CHEST,chest.nbt,50,CHEST,anotherchest.nbt,100) will spawn a chest at
# the BO3 origin, and give it a 50% chance to have the contents of chest.nbt, or, if that
# fails, a 100% percent chance to have the contents of anotherchest.nbt.
Block(-3,0,-5,LOG:15)
Block(-2,0,-4,LOG:15)
Block(2,0,-4,LOG:15)
Block(-5,0,-3,VINE:1)
Block(-1,0,-3,LOG:15)
Block(0,0,-3,VINE:1)
Block(1,0,-3,LOG:15)
Block(-6,0,-2,VINE:8)
Block(-5,0,-2,LOG:15)
Block(-4,0,-2,VINE:8)
Block(-2,0,-2,LOG:15)
Block(-1,0,-2,LOG:15)
Block(0,0,-2,LOG:15)
Block(1,0,-2,LOG:15)
Block(2,0,-2,LOG:15)
Block(-5,0,-1,VINE:4)
Block(-4,0,-1,LOG:15)
Block(-3,0,-1,LOG:15)
Block(-2,0,-1,LOG:15)
Block(-1,0,-1,LOG:15)
Block(0,0,-1,LOG:15)
Block(1,0,-1,LOG:15)
Block(-3,0,0,LOG:15)
Block(-2,0,0,LOG:15)
Block(-1,0,0,LOG:15)
Block(0,0,0,LOG:15)
Block(1,0,0,LOG:15)
Block(2,0,0,LOG:15)
Block(3,0,0,LEAVES:7)
Block(-3,0,1,VINE:8)
Block(-2,0,1,LOG:15)
Block(-1,0,1,LOG:15)
Block(0,0,1,LOG:15)
Block(2,0,1,LOG:15)
Block(3,0,1,LOG:15)
Block(-2,0,2,LOG:15)
Block(-1,0,2,LEAVES:7)
Block(0,0,2,LOG:15)
Block(3,0,2,LOG:15)
Block(-5,0,3,LEAVES:7)
Block(-4,0,3,LOG:15)
Block(-3,0,3,LOG:15)
Block(-2,0,3,LEAVES:7)
Block(4,0,3,LOG:15)
Block(-5,0,4,LOG:15)
Block(-4,0,4,LOG:15)
Block(-1,1,-3,LOG:15)
Block(0,1,-3,VINE:1)
Block(-4,1,-2,VINE:8)
Block(-1,1,-2,LOG:15)
Block(0,1,-2,LOG:15)
Block(1,1,-2,LOG:15)
Block(-4,1,-1,VINE:8)
Block(-2,1,-1,LOG:15)
Block(-1,1,-1,LOG:15)
Block(0,1,-1,LOG:15)
Block(1,1,-1,LOG:15)
Block(2,1,-1,LEAVES:15)
Block(-3,1,0,LOG:15)
Block(-2,1,0,LOG:15)
Block(-1,1,0,LOG:15)
Block(0,1,0,LOG:15)
Block(1,1,0,LOG:15)
Block(2,1,0,LOG:15)
Block(-3,1,1,VINE:8)
Block(-2,1,1,LOG:15)
Block(-1,1,1,LOG:15)
Block(0,1,1,LOG:15)
Block(2,1,1,LOG:15)
Block(-3,1,2,LOG:15)
Block(-2,1,2,LOG:15)
Block(0,1,2,VINE:4)
Block(-4,1,3,LEAVES:7)
Block(-3,1,3,LOG:15)
Block(0,2,-3,VINE:1)
Block(-4,2,-2,VINE:8)
Block(-1,2,-2,LOG:15)
Block(0,2,-2,LOG:15)
Block(1,2,-2,VINE:2)
Block(-4,2,-1,VINE:8)
Block(-2,2,-1,LOG:15)
Block(-1,2,-1,LOG:15)
Block(0,2,-1,LOG:15)
Block(1,2,-1,LOG:15)
Block(2,2,-1,LEAVES:15)
Block(-3,2,0,VINE:8)
Block(-2,2,0,LOG:15)
Block(-1,2,0,LOG:15)
Block(0,2,0,LOG:15)
Block(1,2,0,LOG:15)
Block(2,2,0,LOG:15)
Block(-3,2,1,VINE:8)
Block(-2,2,1,LOG:15)
Block(-1,2,1,LOG:15)
Block(0,2,1,LOG:15)
Block(-3,2,2,LEAVES:7)
Block(0,2,2,VINE:4)
Block(0,3,-3,VINE:1)
Block(-4,3,-2,VINE:8)
Block(-1,3,-2,LOG:15)
Block(0,3,-2,LOG:15)
Block(1,3,-2,VINE:2)
Block(-4,3,-1,VINE:8)
Block(-2,3,-1,LOG:15)
Block(-1,3,-1,LOG:15)
Block(0,3,-1,LOG:15)
Block(1,3,-1,LOG:15)
Block(2,3,-1,VINE:2)
Block(-3,3,0,VINE:8)
Block(-2,3,0,LOG:15)
Block(-1,3,0,LOG:15)
Block(0,3,0,LOG:15)
Block(1,3,0,LOG:15)
Block(-3,3,1,VINE:8)
Block(-2,3,1,VINE:8)
Block(-1,3,1,LOG:15)
Block(0,3,1,LOG:15)
Block(-3,3,2,VINE:8)
Block(0,3,2,VINE:4)
Block(0,4,-3,VINE:1)
Block(-4,4,-2,VINE:8)
Block(-2,4,-2,LOG:15)
Block(-1,4,-2,LOG:15)
Block(0,4,-2,LOG:15)
Block(1,4,-2,VINE:2)
Block(-4,4,-1,VINE:8)
Block(-2,4,-1,LOG:15)
Block(-1,4,-1,LOG:15)
Block(0,4,-1,LOG:15)
Block(1,4,-1,LOG:15)
Block(2,4,-1,VINE:2)
Block(-3,4,0,VINE:8)
Block(-2,4,0,LOG:15)
Block(-1,4,0,LOG:15)
Block(0,4,0,LOG:15)
Block(1,4,0,LOG:15)
Block(2,4,0,LEAVES:7)
Block(-3,4,1,VINE:8)
Block(-2,4,1,VINE:8)
Block(-1,4,1,LOG:15)
Block(0,4,1,LOG:15)
Block(-3,4,2,VINE:8)
Block(-4,5,-2,VINE:8)
Block(-2,5,-2,LOG:15)
Block(-1,5,-2,LOG:15)
Block(0,5,-2,LOG:15)
Block(-4,5,-1,VINE:8)
Block(-2,5,-1,LOG:15)
Block(-1,5,-1,LOG:15)
Block(0,5,-1,LOG:15)
Block(1,5,-1,LOG:15)
Block(2,5,-1,VINE:2)
Block(-2,5,0,LOG:15)
Block(-1,5,0,LOG:15)
Block(0,5,0,LOG:15)
Block(1,5,0,LOG:15)
Block(2,5,0,LEAVES:15)
Block(-3,5,1,VINE:8)
Block(-2,5,1,VINE:8)
Block(-1,5,1,LOG:15)
Block(0,5,1,LOG:15)
Block(1,5,1,LEAVES:7)
Block(-3,5,2,VINE:8)
Block(-7,6,-9,LEAVES:15)
Block(-8,6,-7,LEAVES:15)
Block(-5,6,-7,LEAVES:15)
Block(-7,6,-4,LEAVES:15)
Block(-3,6,-3,LOG:15)
Block(-2,6,-3,LOG:15)
Block(-1,6,-3,LOG:15)
Block(-4,6,-2,VINE:8)
Block(-3,6,-2,LOG:15)
Block(-2,6,-2,LOG:15)
Block(-1,6,-2,LOG:15)
Block(0,6,-2,LOG:15)
Block(-4,6,-1,VINE:8)
Block(-3,6,-1,LOG:15)
Block(-2,6,-1,LOG:15)
Block(-1,6,-1,LOG:15)
Block(0,6,-1,LOG:15)
Block(1,6,-1,LOG:15)
Block(2,6,-1,VINE:2)
Block(-2,6,0,LOG:15)
Block(-1,6,0,LOG:15)
Block(0,6,0,LOG:15)
Block(1,6,0,LOG:15)
Block(2,6,0,VINE:2)
Block(-3,6,1,VINE:8)
Block(-2,6,1,VINE:8)
Block(-1,6,1,LOG:15)
Block(0,6,1,LOG:15)
Block(1,6,1,LEAVES:15)
Block(-3,6,2,VINE:8)
Block(-7,7,-8,LEAVES:15)
Block(-8,7,-7,LEAVES:15)
Block(-7,7,-7,LEAVES:15)
Block(-6,7,-7,LEAVES:15)
Block(-10,7,-6,LEAVES:15)
Block(-8,7,-6,LEAVES:15)
Block(-7,7,-6,LEAVES:15)
Block(-6,7,-6,LEAVES:15)
Block(-5,7,-6,LEAVES:15)
Block(-7,7,-5,LEAVES:15)
Block(-6,7,-5,LEAVES:15)
Block(-5,7,-5,LOG:15)
Block(-4,7,-5,LOG:15)
Block(-5,7,-4,LOG:15)
Block(-4,7,-4,LOG:15)
Block(-3,7,-4,LOG:15)
Block(-4,7,-3,LOG:15)
Block(-3,7,-3,LOG:15)
Block(-4,7,-2,VINE:12)
Block(-3,7,-2,LOG:15)
Block(-2,7,-2,LOG:15)
Block(-1,7,-2,LOG:15)
Block(0,7,-2,LOG:15)
Block(-4,7,-1,VINE:8)
Block(-3,7,-1,LOG:15)
Block(-2,7,-1,LOG:15)
Block(-1,7,-1,LOG:15)
Block(0,7,-1,LOG:15)
Block(1,7,-1,LOG:15)
Block(2,7,-1,VINE:2)
Block(-3,7,0,LEAVES:7)
Block(-2,7,0,LOG:15)
Block(-1,7,0,LOG:15)
Block(0,7,0,LOG:15)
Block(1,7,0,LOG:15)
Block(2,7,0,VINE:2)
Block(-3,7,1,VINE:8)
Block(-2,7,1,VINE:8)
Block(-1,7,1,LOG:15)
Block(0,7,1,LOG:15)
Block(1,7,1,LEAVES:7)
Block(-3,7,2,VINE:8)
Block(-1,7,8,LEAVES:7)
Block(2,7,8,LEAVES:15)
Block(-10,8,-9,LEAVES:15)
Block(-8,8,-9,LEAVES:15)
Block(-7,8,-9,LEAVES:15)
Block(-9,8,-8,LEAVES:15)
Block(-8,8,-8,LEAVES:15)
Block(-7,8,-8,LEAVES:7)
Block(-6,8,-8,LEAVES:7)
Block(-9,8,-7,LEAVES:15)
Block(-8,8,-7,LEAVES:15)
Block(-7,8,-7,LOG:15)
Block(-6,8,-7,LEAVES:7)
Block(-5,8,-7,LEAVES:15)
Block(-9,8,-6,LEAVES:15)
Block(-8,8,-6,LOG:15)
Block(-7,8,-6,LOG:15)
Block(-6,8,-6,LOG:15)
Block(-5,8,-6,LEAVES:15)
Block(-4,8,-6,LEAVES:15)
Block(-3,8,-6,LEAVES:7)
Block(-9,8,-5,LEAVES:15)
Block(-8,8,-5,LEAVES:15)
Block(-7,8,-5,LEAVES:15)
Block(-6,8,-5,LOG:15)
Block(-5,8,-5,LOG:15)
Block(-4,8,-5,LEAVES:7)
Block(-7,8,-4,LEAVES:15)
Block(-6,8,-4,LEAVES:15)
Block(-5,8,-4,LOG:15)
Block(-4,8,-4,LOG:15)
Block(-5,8,-3,LEAVES:7)
Block(-3,8,-2,VINE:1)
Block(-2,8,-2,LOG:15)
Block(-1,8,-2,LOG:15)
Block(0,8,-2,LOG:15)
Block(-3,8,-1,LEAVES:15)
Block(-2,8,-1,LOG:15)
Block(-1,8,-1,LOG:15)
Block(0,8,-1,LOG:15)
Block(1,8,-1,LOG:15)
Block(-3,8,0,VINE:8)
Block(-2,8,0,LOG:15)
Block(-1,8,0,LOG:15)
Block(0,8,0,LOG:15)
Block(1,8,0,LOG:15)
Block(2,8,0,VINE:2)
Block(-3,8,1,VINE:8)
Block(-2,8,1,VINE:8)
Block(-1,8,1,LOG:15)
Block(0,8,1,LOG:15)
Block(1,8,1,LOG:15)
Block(-3,8,2,VINE:8)
Block(-1,8,2,LOG:15)
Block(0,8,2,LOG:15)
Block(1,8,2,LOG:15)
Block(0,8,3,LOG:15)
Block(1,8,3,LOG:15)
Block(-1,8,4,LOG:15)
Block(0,8,4,LOG:15)
Block(1,8,4,LOG:15)
Block(-1,8,5,LEAVES:7)
Block(0,8,5,LOG:15)
Block(-1,8,6,LEAVES:7)
Block(0,8,6,LEAVES:7)
Block(-2,8,7,LEAVES:7)
Block(-1,8,7,LEAVES:7)
Block(0,8,7,LEAVES:15)
Block(-2,8,8,LEAVES:7)
Block(-1,8,8,LEAVES:7)
Block(0,8,8,LEAVES:15)
Block(1,8,8,LEAVES:15)
Block(-4,8,9,LEAVES:15)
Block(-1,8,9,LEAVES:15)
Block(1,8,10,LEAVES:15)
Block(-7,9,-10,LEAVES:15)
Block(-8,9,-9,LEAVES:15)
Block(-7,9,-9,LEAVES:15)
Block(-9,9,-8,LEAVES:15)
Block(-8,9,-8,LEAVES:15)
Block(-7,9,-8,LOG:15)
Block(-6,9,-8,LEAVES:7)
Block(-4,9,-8,LEAVES:15)
Block(-10,9,-7,LEAVES:15)
Block(-9,9,-7,LEAVES:15)
Block(-8,9,-7,LEAVES:15)
Block(-7,9,-7,LEAVES:7)
Block(-6,9,-7,LEAVES:7)
Block(-5,9,-7,LEAVES:15)
Block(-10,9,-6,LEAVES:15)
Block(-9,9,-6,LEAVES:15)
Block(-8,9,-6,LEAVES:15)
Block(-7,9,-6,LEAVES:15)
Block(-6,9,-6,LOG:15)
Block(-5,9,-6,LEAVES:15)
Block(-10,9,-5,LEAVES:15)
Block(-9,9,-5,LOG:15)
Block(-8,9,-5,LEAVES:15)
Block(-7,9,-5,LEAVES:15)
Block(-6,9,-5,LEAVES:15)
Block(-5,9,-5,LEAVES:15)
Block(-9,9,-4,LEAVES:15)
Block(-8,9,-4,LEAVES:15)
Block(-7,9,-4,LEAVES:15)
Block(-6,9,-4,LEAVES:15)
Block(-5,9,-4,LEAVES:15)
Block(-9,9,-3,LEAVES:7)
Block(-7,9,-3,LEAVES:15)
Block(-3,9,-2,VINE:1)
Block(-2,9,-2,LEAVES:7)
Block(-1,9,-2,LOG:15)
Block(0,9,-2,LOG:15)
Block(-3,9,-1,LEAVES:7)
Block(-2,9,-1,LOG:15)
Block(-1,9,-1,LOG:15)
Block(0,9,-1,LOG:15)
Block(1,9,-1,LOG:15)
Block(-3,9,0,VINE:8)
Block(-2,9,0,LOG:15)
Block(-1,9,0,LOG:15)
Block(0,9,0,LOG:15)
Block(1,9,0,LOG:15)
Block(2,9,0,VINE:2)
Block(-3,9,1,VINE:8)
Block(-2,9,1,VINE:8)
Block(-1,9,1,LOG:15)
Block(0,9,1,LOG:15)
Block(1,9,1,LOG:15)
Block(-3,9,2,VINE:8)
Block(-1,9,2,VINE:4)
Block(0,9,2,LOG:15)
Block(1,9,3,LOG:15)
Block(0,9,4,LOG:15)
Block(-1,9,5,LOG:15)
Block(0,9,5,LOG:15)
Block(-2,9,6,LEAVES:7)
Block(-1,9,6,LOG:15)
Block(0,9,6,LOG:15)
Block(1,9,6,LEAVES:15)
Block(-4,9,7,LEAVES:15)
Block(-3,9,7,LEAVES:15)
Block(-2,9,7,LEAVES:7)
Block(-1,9,7,LEAVES:7)
Block(0,9,7,LOG:15)
Block(1,9,7,LEAVES:15)
Block(2,9,7,LEAVES:15)
Block(-4,9,8,LEAVES:15)
Block(-3,9,8,LEAVES:15)
Block(-2,9,8,LEAVES:15)
Block(-1,9,8,LEAVES:15)
Block(0,9,8,LEAVES:15)
Block(1,9,8,LEAVES:15)
Block(2,9,8,LEAVES:15)
Block(-3,9,9,LEAVES:15)
Block(-2,9,9,LEAVES:15)
Block(-1,9,9,LEAVES:15)
Block(0,9,9,LEAVES:15)
Block(1,9,9,LEAVES:15)
Block(-1,9,10,LEAVES:15)
Block(0,9,10,LEAVES:15)
Block(-9,10,-9,LEAVES:15)
Block(-7,10,-8,LEAVES:15)
Block(-11,10,-7,LEAVES:15)
Block(-8,10,-7,LEAVES:15)
Block(-7,10,-7,LEAVES:15)
Block(-6,10,-7,LEAVES:15)
Block(-9,10,-6,LEAVES:15)
Block(-8,10,-6,LEAVES:15)
Block(-7,10,-6,LEAVES:15)
Block(-6,10,-6,LEAVES:15)
Block(-9,10,-5,LEAVES:15)
Block(-8,10,-5,LEAVES:15)
Block(-7,10,-5,LEAVES:15)
Block(-4,10,-5,LEAVES:15)
Block(-8,10,-4,LEAVES:15)
Block(-6,10,-4,LEAVES:15)
Block(-3,10,-2,VINE:1)
Block(-2,10,-2,LEAVES:15)
Block(-1,10,-2,LOG:15)
Block(0,10,-2,LOG:15)
Block(-3,10,-1,VINE:8)
Block(-2,10,-1,LOG:15)
Block(-1,10,-1,LOG:15)
Block(0,10,-1,LOG:15)
Block(1,10,-1,LOG:15)
Block(-3,10,0,VINE:8)
Block(-2,10,0,LOG:15)
Block(-1,10,0,LOG:15)
Block(0,10,0,LOG:15)
Block(1,10,0,LOG:15)
Block(2,10,0,VINE:2)
Block(-3,10,1,VINE:8)
Block(-2,10,1,VINE:4)
Block(-1,10,1,LOG:15)
Block(0,10,1,LOG:15)
Block(-3,10,2,VINE:8)
Block(-1,10,2,VINE:4)
Block(0,10,2,VINE:4)
Block(0,10,5,LEAVES:15)
Block(-2,10,6,LEAVES:15)
Block(-1,10,6,LEAVES:15)
Block(0,10,6,LEAVES:15)
Block(-5,10,7,LEAVES:15)
Block(-2,10,7,LEAVES:15)
Block(-1,10,7,LEAVES:15)
Block(0,10,7,LEAVES:15)
Block(1,10,7,LEAVES:15)
Block(3,10,7,LEAVES:15)
Block(-2,10,8,LEAVES:15)
Block(-1,10,8,LEAVES:15)
Block(0,10,8,LEAVES:15)
Block(-1,10,9,LEAVES:15)
Block(0,10,9,LEAVES:15)
Block(2,10,9,LEAVES:15)
Block(-3,10,10,LEAVES:15)
Block(-8,11,-7,LEAVES:15)
Block(-5,11,-7,LEAVES:15)
Block(-7,11,-6,LEAVES:15)
Block(-10,11,-5,LEAVES:15)
Block(-8,11,-5,LEAVES:15)
Block(-8,11,-3,LEAVES:15)
Block(-6,11,-3,LEAVES:15)
Block(-1,11,-3,LEAVES:15)
Block(-3,11,-2,VINE:1)
Block(-2,11,-2,LEAVES:15)
Block(-1,11,-2,LOG:15)
Block(0,11,-2,LOG:15)
Block(1,11,-2,LOG:15)
Block(-3,11,-1,VINE:8)
Block(-2,11,-1,LOG:15)
Block(-1,11,-1,LOG:15)
Block(0,11,-1,LOG:15)
Block(1,11,-1,LOG:15)
Block(2,11,-1,LOG:15)
Block(-3,11,0,VINE:8)
Block(-2,11,0,LOG:15)
Block(-1,11,0,LOG:15)
Block(0,11,0,LOG:15)
Block(1,11,0,LOG:15)
Block(-3,11,1,VINE:8)
Block(-2,11,1,VINE:4)
Block(-1,11,1,LOG:15)
Block(0,11,1,LOG:15)
Block(-3,11,2,VINE:8)
Block(-1,11,2,VINE:4)
Block(0,11,2,VINE:4)
Block(-2,11,5,LEAVES:15)
Block(1,11,5,LEAVES:15)
Block(-3,11,6,LEAVES:15)
Block(-1,11,7,LEAVES:15)
Block(0,11,7,LEAVES:15)
Block(-3,11,8,LEAVES:15)
Block(0,11,8,LEAVES:15)
Block(0,11,10,LEAVES:15)
Block(-8,12,-8,LEAVES:15)
Block(-6,12,-6,LEAVES:15)
Block(-1,12,-3,LEAVES:15)
Block(0,12,-3,LOG:15)
Block(1,12,-3,LOG:15)
Block(-3,12,-2,VINE:1)
Block(-1,12,-2,LOG:15)
Block(0,12,-2,LOG:15)
Block(1,12,-2,LOG:15)
Block(2,12,-2,LOG:15)
Block(-3,12,-1,VINE:8)
Block(-2,12,-1,LOG:15)
Block(-1,12,-1,LOG:15)
Block(0,12,-1,LOG:15)
Block(1,12,-1,LOG:15)
Block(2,12,-1,LOG:15)
Block(-3,12,0,VINE:8)
Block(-2,12,0,LOG:15)
Block(-1,12,0,LOG:15)
Block(0,12,0,LOG:15)
Block(1,12,0,LOG:15)
Block(-3,12,1,VINE:8)
Block(-2,12,1,VINE:4)
Block(-1,12,1,LOG:15)
Block(0,12,1,LOG:15)
Block(-3,12,2,VINE:8)
Block(0,12,2,VINE:4)
Block(-1,12,6,LEAVES:15)
Block(1,12,8,LEAVES:15)
Block(6,13,-9,LEAVES:15)
Block(7,13,-6,LEAVES:15)
Block(3,13,-4,LOG:15)
Block(-1,13,-3,VINE:1)
Block(0,13,-3,LEAVES:15)
Block(1,13,-3,LOG:15)
Block(2,13,-3,LOG:15)
Block(-3,13,-2,VINE:1)
Block(-1,13,-2,LOG:15)
Block(0,13,-2,LOG:15)
Block(1,13,-2,LOG:15)
Block(2,13,-2,LOG:15)
Block(-3,13,-1,VINE:8)
Block(-2,13,-1,LOG:15)
Block(-1,13,-1,LOG:15)
Block(0,13,-1,LOG:15)
Block(1,13,-1,LOG:15)
Block(2,13,-1,VINE:2)
Block(-3,13,0,VINE:8)
Block(-2,13,0,LOG:15)
Block(-1,13,0,LOG:15)
Block(0,13,0,LOG:15)
Block(1,13,0,LOG:15)
Block(-3,13,1,VINE:8)
Block(-2,13,1,VINE:4)
Block(-1,13,1,LOG:15)
Block(0,13,1,LOG:15)
Block(-3,13,2,VINE:8)
Block(-1,13,2,LEAVES:15)
Block(0,13,2,VINE:4)
Block(5,14,-8,LEAVES:15)
Block(6,14,-8,LEAVES:15)
Block(7,14,-8,LEAVES:15)
Block(3,14,-7,LEAVES:15)
Block(6,14,-7,LEAVES:15)
Block(5,14,-6,LEAVES:15)
Block(6,14,-6,LEAVES:15)
Block(3,14,-5,LOG:15)
Block(4,14,-5,LOG:15)
Block(2,14,-4,LOG:15)
Block(3,14,-4,LOG:15)
Block(4,14,-4,LOG:15)
Block(7,14,-4,LEAVES:15)
Block(-1,14,-3,VINE:1)
Block(0,14,-3,VINE:1)
Block(2,14,-3,LOG:15)
Block(3,14,-3,LOG:15)
Block(5,14,-3,LEAVES:15)
Block(-3,14,-2,VINE:1)
Block(-1,14,-2,LOG:15)
Block(0,14,-2,LOG:15)
Block(1,14,-2,VINE:1)
Block(-3,14,-1,VINE:8)
Block(-2,14,-1,LOG:15)
Block(-1,14,-1,LOG:15)
Block(0,14,-1,LOG:15)
Block(1,14,-1,LOG:15)
Block(2,14,-1,VINE:2)
Block(-3,14,0,VINE:8)
Block(-2,14,0,LOG:15)
Block(-1,14,0,LOG:15)
Block(0,14,0,LOG:15)
Block(1,14,0,LOG:15)
Block(-3,14,1,VINE:8)
Block(-2,14,1,VINE:4)
Block(-1,14,1,LOG:15)
Block(0,14,1,LOG:15)
Block(-3,14,2,VINE:8)
Block(-1,14,2,LEAVES:7)
Block(7,15,-10,LEAVES:15)
Block(3,15,-9,LEAVES:15)
Block(5,15,-9,LEAVES:15)
Block(6,15,-9,LEAVES:15)
Block(7,15,-9,LEAVES:15)
Block(8,15,-9,LEAVES:15)
Block(4,15,-8,LEAVES:15)
Block(5,15,-8,LEAVES:15)
Block(6,15,-8,LEAVES:15)
Block(7,15,-8,LEAVES:15)
Block(8,15,-8,LEAVES:7)
Block(9,15,-8,LEAVES:7)
Block(4,15,-7,LEAVES:15)
Block(5,15,-7,LOG:15)
Block(6,15,-7,LEAVES:7)
Block(7,15,-7,LEAVES:7)
Block(8,15,-7,LEAVES:7)
Block(3,15,-6,LEAVES:15)
Block(4,15,-6,LOG:15)
Block(5,15,-6,LOG:15)
Block(6,15,-6,LOG:15)
Block(7,15,-6,LEAVES:15)
Block(3,15,-5,LOG:15)
Block(4,15,-5,LOG:15)
Block(5,15,-5,LOG:15)
Block(6,15,-5,LEAVES:15)
Block(7,15,-5,LEAVES:15)
Block(3,15,-4,LEAVES:15)
Block(4,15,-4,LOG:15)
Block(5,15,-4,LEAVES:15)
Block(-1,15,-3,VINE:1)
Block(0,15,-3,VINE:1)
Block(4,15,-3,LEAVES:15)
Block(-3,15,-2,VINE:1)
Block(-1,15,-2,LOG:15)
Block(0,15,-2,LOG:15)
Block(1,15,-2,VINE:1)
Block(-2,15,-1,LOG:15)
Block(-1,15,-1,LOG:15)
Block(0,15,-1,LOG:15)
Block(1,15,-1,LOG:15)
Block(2,15,-1,VINE:2)
Block(-3,15,0,VINE:8)
Block(-2,15,0,LOG:15)
Block(-1,15,0,LOG:15)
Block(0,15,0,LOG:15)
Block(1,15,0,LOG:15)
Block(-3,15,1,VINE:8)
Block(-2,15,1,VINE:4)
Block(-1,15,1,LOG:15)
Block(0,15,1,LOG:15)
Block(1,15,1,LEAVES:7)
Block(-3,15,2,VINE:8)
Block(0,15,2,LEAVES:7)
Block(7,16,-9,LEAVES:15)
Block(8,16,-9,LEAVES:15)
Block(9,16,-9,LEAVES:7)
Block(6,16,-8,LEAVES:15)
Block(7,16,-8,LEAVES:15)
Block(8,16,-8,LOG:15)
Block(9,16,-8,LEAVES:15)
Block(10,16,-8,LEAVES:15)
Block(4,16,-7,LEAVES:15)
Block(5,16,-7,LEAVES:15)
Block(6,16,-7,LOG:15)
Block(7,16,-7,LOG:15)
Block(8,16,-7,LOG:15)
Block(9,16,-7,LEAVES:15)
Block(10,16,-7,LEAVES:15)
Block(4,16,-6,LEAVES:15)
Block(5,16,-6,LOG:15)
Block(6,16,-6,LOG:15)
Block(7,16,-6,LOG:15)
Block(8,16,-6,LEAVES:15)
Block(9,16,-6,LEAVES:15)
Block(4,16,-5,LEAVES:15)
Block(5,16,-5,LEAVES:7)
Block(6,16,-5,LEAVES:7)
Block(7,16,-5,LEAVES:7)
Block(8,16,-5,LEAVES:15)
Block(4,16,-4,LEAVES:15)
Block(5,16,-4,LEAVES:7)
Block(6,16,-4,LEAVES:7)
Block(7,16,-4,LEAVES:7)
Block(-1,16,-3,VINE:1)
Block(0,16,-3,VINE:1)
Block(5,16,-3,LEAVES:7)
Block(6,16,-3,LEAVES:7)
Block(-3,16,-2,VINE:1)
Block(-1,16,-2,LOG:15)
Block(0,16,-2,LOG:15)
Block(1,16,-2,VINE:1)
Block(-2,16,-1,LOG:15)
Block(-1,16,-1,LOG:15)
Block(0,16,-1,LOG:15)
Block(1,16,-1,LOG:15)
Block(2,16,-1,VINE:2)
Block(-2,16,0,LOG:15)
Block(-1,16,0,LOG:15)
Block(0,16,0,LOG:15)
Block(1,16,0,LOG:15)
Block(-3,16,1,VINE:8)
Block(-1,16,1,LOG:15)
Block(0,16,1,LOG:15)
Block(1,16,1,LEAVES:7)
Block(-3,16,2,VINE:8)
Block(0,16,2,VINE:4)
Block(8,17,-10,LEAVES:15)
Block(5,17,-9,LEAVES:15)
Block(9,17,-9,LEAVES:7)
Block(8,17,-8,LEAVES:15)
Block(11,17,-8,LEAVES:15)
Block(3,17,-7,LEAVES:15)
Block(6,17,-7,LEAVES:15)
Block(7,17,-7,LEAVES:15)
Block(8,17,-7,LEAVES:15)
Block(5,17,-6,LEAVES:15)
Block(6,17,-6,LEAVES:15)
Block(7,17,-6,LEAVES:15)
Block(5,17,-5,LEAVES:15)
Block(6,17,-5,LEAVES:15)
Block(7,17,-5,LEAVES:15)
Block(9,17,-5,LEAVES:15)
Block(-1,17,-3,VINE:1)
Block(0,17,-3,VINE:1)
Block(-3,17,-2,VINE:1)
Block(-1,17,-2,LOG:15)
Block(0,17,-2,LOG:15)
Block(1,17,-2,VINE:1)
Block(-2,17,-1,LOG:15)
Block(-1,17,-1,LOG:15)
Block(0,17,-1,LOG:15)
Block(1,17,-1,LOG:15)
Block(2,17,-1,VINE:2)
Block(-2,17,0,LOG:15)
Block(-1,17,0,LOG:15)
Block(0,17,0,LOG:15)
Block(1,17,0,LOG:15)
Block(2,17,0,LEAVES:7)
Block(-3,17,1,VINE:8)
Block(-2,17,1,LOG:15)
Block(-1,17,1,LOG:15)
Block(0,17,1,LOG:15)
Block(1,17,1,LEAVES:7)
Block(-3,17,2,VINE:8)
Block(0,17,2,VINE:4)
Block(7,18,-8,LEAVES:15)
Block(9,18,-7,LEAVES:15)
Block(4,18,-6,LEAVES:15)
Block(6,18,-6,LEAVES:15)
Block(5,18,-4,LEAVES:15)
Block(7,18,-4,LEAVES:15)
Block(-1,18,-3,VINE:1)
Block(0,18,-3,VINE:1)
Block(-3,18,-2,VINE:1)
Block(-1,18,-2,LOG:15)
Block(0,18,-2,LOG:15)
Block(1,18,-2,VINE:1)
Block(-2,18,-1,LOG:15)
Block(-1,18,-1,LOG:15)
Block(0,18,-1,LOG:15)
Block(1,18,-1,LOG:15)
Block(2,18,-1,VINE:2)
Block(-2,18,0,LOG:15)
Block(-1,18,0,LOG:15)
Block(0,18,0,LOG:15)
Block(1,18,0,LOG:15)
Block(2,18,0,LEAVES:15)
Block(-3,18,1,VINE:8)
Block(-2,18,1,LOG:15)
Block(-1,18,1,LOG:15)
Block(0,18,1,LOG:15)
Block(1,18,1,VINE:2)
Block(-3,18,2,VINE:8)
Block(-2,18,2,LOG:15)
Block(0,18,2,VINE:4)
Block(-1,19,-3,VINE:1)
Block(0,19,-3,VINE:1)
Block(-3,19,-2,VINE:1)
Block(-1,19,-2,LOG:15)
Block(0,19,-2,LOG:15)
Block(1,19,-2,VINE:1)
Block(-2,19,-1,LOG:15)
Block(-1,19,-1,LOG:15)
Block(0,19,-1,LOG:15)
Block(1,19,-1,LOG:15)
Block(2,19,-1,LEAVES:7)
Block(-2,19,0,LOG:15)
Block(-1,19,0,LOG:15)
Block(0,19,0,LOG:15)
Block(1,19,0,LOG:15)
Block(-3,19,1,VINE:8)
Block(-2,19,1,LOG:15)
Block(-1,19,1,LOG:15)
Block(0,19,1,LOG:15)
Block(1,19,1,VINE:2)
Block(-3,19,2,LOG:15)
Block(-2,19,2,LOG:15)
Block(-1,19,2,LOG:15)
Block(0,19,2,VINE:4)
Block(-7,19,3,LEAVES:15)
Block(-4,19,3,LEAVES:7)
Block(-3,19,3,LEAVES:7)
Block(-2,19,3,LOG:15)
Block(-5,19,4,LEAVES:15)
Block(-4,19,4,LEAVES:15)
Block(-5,19,5,LEAVES:15)
Block(-4,19,5,LEAVES:15)
Block(-6,19,7,LEAVES:15)
Block(-1,20,-3,VINE:1)
Block(0,20,-3,VINE:1)
Block(-3,20,-2,VINE:1)
Block(-1,20,-2,LOG:15)
Block(0,20,-2,LOG:15)
Block(1,20,-2,LEAVES:7)
Block(-2,20,-1,LOG:15)
Block(-1,20,-1,LOG:15)
Block(0,20,-1,LOG:15)
Block(1,20,-1,LOG:15)
Block(-6,20,0,LEAVES:15)
Block(-2,20,0,LOG:15)
Block(-1,20,0,LOG:15)
Block(0,20,0,LOG:15)
Block(1,20,0,LOG:15)
Block(-3,20,1,LOG:15)
Block(-2,20,1,LOG:15)
Block(-1,20,1,LOG:15)
Block(0,20,1,LOG:15)
Block(1,20,1,VINE:2)
Block(-4,20,2,LOG:15)
Block(-3,20,2,LOG:15)
Block(-2,20,2,LOG:15)
Block(-1,20,2,VINE:2)
Block(0,20,2,VINE:4)
Block(-6,20,3,LEAVES:15)
Block(-5,20,3,LEAVES:15)
Block(-4,20,3,LOG:15)
Block(-3,20,3,LOG:15)
Block(-2,20,3,LEAVES:7)
Block(-6,20,4,LEAVES:15)
Block(-5,20,4,LOG:15)
Block(-4,20,4,LOG:15)
Block(-3,20,4,LEAVES:15)
Block(-7,20,5,LEAVES:15)
Block(-6,20,5,LEAVES:15)
Block(-5,20,5,LEAVES:15)
Block(-4,20,5,LEAVES:15)
Block(-6,20,6,LEAVES:15)
Block(-4,20,6,LEAVES:15)
Block(-3,20,7,LEAVES:15)
Block(-1,21,-3,VINE:1)
Block(0,21,-3,VINE:1)
Block(-3,21,-2,VINE:1)
Block(-1,21,-2,LOG:15)
Block(0,21,-2,LOG:15)
Block(1,21,-2,LEAVES:7)
Block(-2,21,-1,LOG:15)
Block(-1,21,-1,LOG:15)
Block(0,21,-1,LOG:15)
Block(1,21,-1,LOG:15)
Block(-2,21,0,LOG:15)
Block(-1,21,0,LOG:15)
Block(0,21,0,LOG:15)
Block(1,21,0,LOG:15)
Block(-6,21,1,LEAVES:15)
Block(-5,21,1,LEAVES:15)
Block(-2,21,1,LOG:15)
Block(-1,21,1,LOG:15)
Block(0,21,1,LOG:15)
Block(1,21,1,VINE:2)
Block(-6,21,2,LEAVES:15)
Block(-5,21,2,LEAVES:15)
Block(-4,21,2,LEAVES:7)
Block(-3,21,2,LEAVES:7)
Block(-2,21,2,LEAVES:7)
Block(0,21,2,VINE:4)
Block(-7,21,3,LEAVES:15)
Block(-6,21,3,LEAVES:7)
Block(-5,21,3,LOG:15)
Block(-4,21,3,LOG:15)
Block(-3,21,3,LEAVES:15)
Block(-8,21,4,LEAVES:15)
Block(-7,21,4,LEAVES:15)
Block(-6,21,4,LOG:15)
Block(-5,21,4,LOG:15)
Block(-4,21,4,LOG:15)
Block(-3,21,4,LOG:15)
Block(-2,21,4,LEAVES:15)
Block(-8,21,5,LEAVES:15)
Block(-7,21,5,LOG:7)
Block(-6,21,5,LOG:15)
Block(-5,21,5,LOG:15)
Block(-4,21,5,LOG:15)
Block(-3,21,5,LEAVES:15)
Block(-1,21,5,LEAVES:15)
Block(-7,21,6,LEAVES:7)
Block(-6,21,6,LOG:15)
Block(-5,21,6,LEAVES:15)
Block(-4,21,6,LEAVES:15)
Block(-7,21,7,LEAVES:7)
Block(-6,21,7,LEAVES:7)
Block(-5,21,7,LEAVES:15)
Block(-1,22,-3,VINE:1)
Block(0,22,-3,LEAVES:7)
Block(-3,22,-2,VINE:1)
Block(-2,22,-2,LEAVES:7)
Block(-1,22,-2,LOG:15)
Block(0,22,-2,LOG:15)
Block(-2,22,-1,LOG:15)
Block(-1,22,-1,LOG:15)
Block(0,22,-1,LOG:15)
Block(1,22,-1,LOG:15)
Block(-2,22,0,LOG:15)
Block(-1,22,0,LOG:15)
Block(0,22,0,LOG:15)
Block(1,22,0,LOG:15)
Block(-5,22,1,LEAVES:15)
Block(-1,22,1,LOG:15)
Block(0,22,1,LOG:15)
Block(1,22,1,VINE:2)
Block(-8,22,2,LEAVES:15)
Block(-6,22,2,LEAVES:15)
Block(-5,22,2,LEAVES:15)
Block(-4,22,2,LEAVES:15)
Block(0,22,2,VINE:4)
Block(-7,22,3,LEAVES:15)
Block(-6,22,3,LEAVES:7)
Block(-5,22,3,LEAVES:7)
Block(-4,22,3,LEAVES:15)
Block(-3,22,3,LEAVES:15)
Block(-8,22,4,LEAVES:15)
Block(-7,22,4,LEAVES:15)
Block(-6,22,4,LEAVES:7)
Block(-5,22,4,LOG:15)
Block(-4,22,4,LEAVES:15)
Block(-3,22,4,LEAVES:15)
Block(-9,22,5,LEAVES:15)
Block(-8,22,5,LOG:7)
Block(-7,22,5,LOG:7)
Block(-6,22,5,LOG:15)
Block(-5,22,5,LOG:15)
Block(-4,22,5,LEAVES:15)
Block(-9,22,6,LEAVES:15)
Block(-8,22,6,LEAVES:15)
Block(-7,22,6,LOG:11)
Block(-6,22,6,LEAVES:15)
Block(-5,22,6,LEAVES:15)
Block(-4,22,6,LEAVES:15)
Block(-8,22,7,LEAVES:15)
Block(-7,22,7,LEAVES:7)
Block(-6,22,7,LEAVES:15)
Block(-5,22,7,LEAVES:15)
Block(-9,22,8,LEAVES:15)
Block(-6,22,8,LEAVES:15)
Block(-7,22,9,LEAVES:15)
Block(-1,23,-3,COCOA:8)
Block(0,23,-3,LEAVES:7)
Block(-3,23,-2,VINE:1)
Block(-2,23,-2,LEAVES:7)
Block(-1,23,-2,LOG:3)
Block(0,23,-2,LOG:3)
Block(1,23,-2,LEAVES:7)
Block(-3,23,-1,LEAVES:7)
Block(-2,23,-1,LOG:3)
Block(-1,23,-1,LOG:3)
Block(0,23,-1,LOG:3)
Block(1,23,-1,LOG:3)
Block(-5,23,0,LEAVES:15)
Block(-2,23,0,LOG:3)
Block(-1,23,0,LOG:3)
Block(0,23,0,LOG:3)
Block(1,23,0,LOG:3)
Block(-1,23,1,LOG:3)
Block(0,23,1,LOG:3)
Block(-5,23,2,LEAVES:15)
Block(-1,23,2,COCOA:10)
Block(0,23,2,VINE:4)
Block(-3,23,3,LEAVES:7)
Block(-2,23,3,LEAVES:15)
Block(-7,23,4,LEAVES:15)
Block(-5,23,4,LEAVES:15)
Block(-8,23,5,LEAVES:15)
Block(-7,23,5,LEAVES:15)
Block(-6,23,5,LEAVES:15)
Block(-5,23,5,LEAVES:15)
Block(-8,23,6,LEAVES:15)
Block(-7,23,6,LEAVES:15)
Block(-6,23,6,LEAVES:15)
Block(-3,23,6,LEAVES:15)
Block(-7,23,7,LEAVES:15)
Block(-5,23,8,LEAVES:15)
Block(0,24,-3,LEAVES:7)
Block(-3,24,-2,VINE:1)
Block(-1,24,-2,LOG:3)
Block(0,24,-2,LOG:3)
Block(1,24,-2,LEAVES:15)
Block(-3,24,-1,LEAVES:15)
Block(-2,24,-1,LOG:3)
Block(-1,24,-1,LOG:3)
Block(0,24,-1,LOG:3)
Block(1,24,-1,LOG:3)
Block(2,24,-1,COCOA:9)
Block(-2,24,0,LOG:3)
Block(-1,24,0,LOG:3)
Block(0,24,0,LOG:3)
Block(1,24,0,LOG:3)
Block(-1,24,1,LOG:3)
Block(0,24,1,LOG:3)
Block(1,24,1,LEAVES:7)
Block(-1,24,2,VINE:4)
Block(0,24,2,VINE:4)
Block(-7,24,3,LEAVES:15)
Block(-4,24,4,LEAVES:15)
Block(-7,24,5,LEAVES:15)
Block(-9,24,6,LEAVES:15)
Block(-5,24,6,LEAVES:15)
Block(-6,24,7,LEAVES:15)
Block(-7,24,8,LEAVES:15)
Block(2,25,-6,LEAVES:15)
Block(0,25,-4,LEAVES:7)
Block(4,25,-4,LEAVES:15)
Block(-4,25,-3,LEAVES:15)
Block(-1,25,-3,LEAVES:7)
Block(0,25,-3,LEAVES:15)
Block(1,25,-3,LEAVES:7)
Block(-2,25,-2,LEAVES:7)
Block(-1,25,-2,LOG:3)
Block(0,25,-2,LOG:3)
Block(1,25,-2,LEAVES:15)
Block(2,25,-2,LEAVES:7)
Block(-3,25,-1,LEAVES:15)
Block(-2,25,-1,LOG:3)
Block(-1,25,-1,LOG:3)
Block(0,25,-1,LOG:3)
Block(1,25,-1,LOG:3)
Block(2,25,-1,LEAVES:7)
Block(3,25,-1,LEAVES:7)
Block(6,25,-1,LEAVES:15)
Block(-3,25,0,LEAVES:7)
Block(-2,25,0,LOG:3)
Block(-1,25,0,LOG:3)
Block(0,25,0,LOG:3)
Block(1,25,0,LOG:3)
Block(2,25,0,LEAVES:7)
Block(-2,25,1,LEAVES:7)
Block(-1,25,1,LOG:3)
Block(0,25,1,LOG:3)
Block(1,25,1,LEAVES:7)
Block(5,25,1,LEAVES:15)
Block(0,25,2,LEAVES:7)
Block(3,25,4,LEAVES:15)
Block(1,25,5,LEAVES:15)
Block(3,26,-7,LEAVES:15)
Block(-3,26,-6,LEAVES:15)
Block(0,26,-6,LEAVES:15)
Block(-1,26,-5,LEAVES:7)
Block(0,26,-5,LEAVES:7)
Block(1,26,-5,LEAVES:15)
Block(2,26,-5,LEAVES:15)
Block(-2,26,-4,LEAVES:15)
Block(-1,26,-4,LEAVES:15)
Block(0,26,-4,LEAVES:7)
Block(1,26,-4,LEAVES:15)
Block(2,26,-4,LEAVES:15)
Block(3,26,-4,LEAVES:15)
Block(-3,26,-3,LEAVES:15)
Block(-2,26,-3,LEAVES:15)
Block(-1,26,-3,LEAVES:7)
Block(0,26,-3,LEAVES:7)
Block(1,26,-3,LEAVES:7)
Block(2,26,-3,LEAVES:7)
Block(3,26,-3,LEAVES:15)
Block(4,26,-3,LEAVES:15)
Block(5,26,-3,LEAVES:15)
Block(-7,26,-2,LEAVES:15)
Block(-4,26,-2,LEAVES:15)
Block(-3,26,-2,LEAVES:15)
Block(-2,26,-2,LEAVES:7)
Block(-1,26,-2,LOG:3)
Block(0,26,-2,LOG:3)
Block(1,26,-2,LEAVES:7)
Block(2,26,-2,LEAVES:7)
Block(3,26,-2,LEAVES:15)
Block(4,26,-2,LEAVES:15)
Block(5,26,-2,LEAVES:15)
Block(-4,26,-1,LEAVES:15)
Block(-3,26,-1,LEAVES:15)
Block(-2,26,-1,LOG:3)
Block(-1,26,-1,LOG:3)
Block(0,26,-1,LOG:3)
Block(1,26,-1,LOG:3)
Block(2,26,-1,LEAVES:7)
Block(3,26,-1,LEAVES:7)
Block(4,26,-1,LEAVES:15)
Block(5,26,-1,LEAVES:15)
Block(-7,26,0,LEAVES:15)
Block(-4,26,0,LEAVES:15)
Block(-3,26,0,LEAVES:15)
Block(-2,26,0,LOG:3)
Block(-1,26,0,LOG:3)
Block(0,26,0,LOG:3)
Block(1,26,0,LOG:3)
Block(2,26,0,LEAVES:15)
Block(3,26,0,LEAVES:15)
Block(4,26,0,LEAVES:15)
Block(5,26,0,LEAVES:15)
Block(-3,26,1,LEAVES:7)
Block(-2,26,1,LEAVES:15)
Block(-1,26,1,LOG:3)
Block(0,26,1,LOG:3)
Block(1,26,1,LEAVES:7)
Block(2,26,1,LEAVES:15)
Block(3,26,1,LEAVES:15)
Block(4,26,1,LEAVES:15)
Block(-4,26,2,LEAVES:15)
Block(-2,26,2,LEAVES:7)
Block(-1,26,2,LEAVES:7)
Block(0,26,2,LEAVES:7)
Block(1,26,2,LEAVES:7)
Block(2,26,2,LEAVES:15)
Block(3,26,2,LEAVES:15)
Block(4,26,2,LEAVES:15)
Block(-6,26,3,LEAVES:15)
Block(-2,26,3,LEAVES:15)
Block(-1,26,3,LEAVES:15)
Block(0,26,3,LEAVES:15)
Block(1,26,3,LEAVES:15)
Block(2,26,3,LEAVES:15)
Block(3,26,3,LEAVES:15)
Block(0,26,4,LEAVES:15)
Block(1,26,4,LEAVES:15)
Block(5,26,4,LEAVES:15)
Block(-2,26,6,LEAVES:15)
Block(-3,27,-8,LEAVES:15)
Block(0,27,-8,LEAVES:15)
Block(4,27,-8,LEAVES:7)
Block(7,27,-7,LEAVES:15)
Block(-5,27,-6,LEAVES:15)
Block(-1,27,-6,LEAVES:15)
Block(0,27,-6,LEAVES:15)
Block(1,27,-6,LEAVES:15)
Block(2,27,-6,LEAVES:15)
Block(3,27,-6,LEAVES:15)
Block(-3,27,-5,LEAVES:15)
Block(-2,27,-5,LEAVES:15)
Block(-1,27,-5,LEAVES:15)
Block(0,27,-5,LEAVES:15)
Block(1,27,-5,LEAVES:15)
Block(2,27,-5,LEAVES:15)
Block(3,27,-5,LEAVES:15)
Block(4,27,-5,LEAVES:15)
Block(-6,27,-4,LEAVES:7)
Block(-4,27,-4,LEAVES:15)
Block(-3,27,-4,LEAVES:15)
Block(-2,27,-4,LEAVES:15)
Block(-1,27,-4,LEAVES:15)
Block(0,27,-4,LEAVES:15)
Block(1,27,-4,LEAVES:7)
Block(2,27,-4,LEAVES:7)
Block(3,27,-4,LEAVES:15)
Block(4,27,-4,LEAVES:15)
Block(5,27,-4,LEAVES:15)
Block(7,27,-4,LEAVES:7)
Block(9,27,-4,LEAVES:15)
Block(-8,27,-3,LEAVES:15)
Block(-5,27,-3,LEAVES:15)
Block(-4,27,-3,LEAVES:15)
Block(-2,27,-3,LEAVES:15)
Block(-1,27,-3,LEAVES:7)
Block(0,27,-3,LEAVES:7)
Block(1,27,-3,LEAVES:7)
Block(2,27,-3,LEAVES:7)
Block(3,27,-3,LEAVES:7)
Block(4,27,-3,LEAVES:7)
Block(5,27,-3,LEAVES:7)
Block(6,27,-3,LEAVES:15)
Block(-6,27,-2,LEAVES:15)
Block(-5,27,-2,LEAVES:15)
Block(-4,27,-2,LEAVES:15)
Block(-3,27,-2,LEAVES:15)
Block(-2,27,-2,LEAVES:15)
Block(-1,27,-2,LOG:3)
Block(0,27,-2,LOG:3)
Block(1,27,-2,LEAVES:7)
Block(2,27,-2,LEAVES:7)
Block(3,27,-2,LEAVES:7)
Block(4,27,-2,LEAVES:7)
Block(5,27,-2,LEAVES:7)
Block(6,27,-2,LEAVES:15)
Block(-6,27,-1,LEAVES:15)
Block(-5,27,-1,LEAVES:15)
Block(-4,27,-1,LEAVES:15)
Block(-3,27,-1,LEAVES:15)
Block(-2,27,-1,LOG:3)
Block(-1,27,-1,LOG:3)
Block(0,27,-1,LOG:3)
Block(1,27,-1,LOG:3)
Block(2,27,-1,LEAVES:7)
Block(3,27,-1,LEAVES:7)
Block(4,27,-1,LEAVES:7)
Block(5,27,-1,LEAVES:7)
Block(6,27,-1,LEAVES:15)
Block(8,27,-1,LEAVES:15)
Block(-8,27,0,LEAVES:7)
Block(-6,27,0,LEAVES:15)
Block(-5,27,0,LEAVES:15)
Block(-4,27,0,LEAVES:15)
Block(-3,27,0,LEAVES:15)
Block(-2,27,0,LOG:3)
Block(-1,27,0,LOG:3)
Block(0,27,0,LOG:3)
Block(1,27,0,LOG:3)
Block(2,27,0,LEAVES:15)
Block(3,27,0,LEAVES:15)
Block(4,27,0,LEAVES:15)
Block(5,27,0,LEAVES:15)
Block(6,27,0,LEAVES:15)
Block(-6,27,1,LEAVES:15)
Block(-5,27,1,LEAVES:15)
Block(-4,27,1,LEAVES:7)
Block(-3,27,1,LEAVES:7)
Block(-2,27,1,LEAVES:7)
Block(-1,27,1,LOG:3)
Block(0,27,1,LOG:3)
Block(1,27,1,LEAVES:7)
Block(2,27,1,LEAVES:15)
Block(3,27,1,LEAVES:15)
Block(4,27,1,LEAVES:15)
Block(5,27,1,LEAVES:15)
Block(6,27,1,LEAVES:15)
Block(7,27,1,LEAVES:7)
Block(-5,27,2,LEAVES:15)
Block(-4,27,2,LEAVES:15)
Block(-3,27,2,LEAVES:15)
Block(-2,27,2,LEAVES:7)
Block(-1,27,2,LEAVES:15)
Block(0,27,2,LEAVES:15)
Block(1,27,2,LEAVES:7)
Block(2,27,2,LEAVES:15)
Block(3,27,2,LEAVES:15)
Block(4,27,2,LEAVES:15)
Block(5,27,2,LEAVES:15)
Block(6,27,2,LEAVES:15)
Block(-5,27,3,LEAVES:15)
Block(-4,27,3,LEAVES:15)
Block(-3,27,3,LEAVES:15)
Block(-2,27,3,LEAVES:15)
Block(-1,27,3,LEAVES:15)
Block(0,27,3,LEAVES:15)
Block(1,27,3,LEAVES:15)
Block(2,27,3,LEAVES:15)
Block(3,27,3,LEAVES:15)
Block(4,27,3,LEAVES:15)
Block(5,27,3,LEAVES:15)
Block(-3,27,4,LEAVES:15)
Block(-2,27,4,LEAVES:15)
Block(-1,27,4,LEAVES:15)
Block(0,27,4,LEAVES:15)
Block(1,27,4,LEAVES:15)
Block(2,27,4,LEAVES:15)
Block(3,27,4,LEAVES:15)
Block(-2,27,5,LEAVES:15)
Block(-1,27,5,LEAVES:15)
Block(0,27,5,LEAVES:15)
Block(1,27,5,LEAVES:15)
Block(2,27,5,LEAVES:15)
Block(-4,27,6,LEAVES:15)
Block(-1,27,6,LEAVES:15)
Block(2,27,6,LEAVES:15)
Block(3,27,7,LEAVES:15)
Block(-3,28,-10,LEAVES:15)
Block(1,28,-10,LEAVES:15)
Block(2,28,-8,LEAVES:7)
Block(3,28,-8,LEAVES:7)
Block(4,28,-8,LEAVES:7)
Block(-3,28,-7,LEAVES:15)
Block(-2,28,-7,LEAVES:15)
Block(-1,28,-7,LEAVES:15)
Block(0,28,-7,LEAVES:15)
Block(1,28,-7,LEAVES:15)
Block(2,28,-7,LEAVES:7)
Block(3,28,-7,LEAVES:7)
Block(4,28,-7,LEAVES:7)
Block(-4,28,-6,LEAVES:15)
Block(-3,28,-6,LEAVES:15)
Block(-2,28,-6,LEAVES:15)
Block(-1,28,-6,LEAVES:15)
Block(0,28,-6,LEAVES:15)
Block(1,28,-6,LEAVES:15)
Block(2,28,-6,LEAVES:7)
Block(3,28,-6,LEAVES:7)
Block(4,28,-6,LEAVES:15)
Block(5,28,-6,LEAVES:15)
Block(6,28,-6,LEAVES:15)
Block(7,28,-6,LEAVES:15)
Block(-6,28,-5,LEAVES:15)
Block(-5,28,-5,LEAVES:15)
Block(-4,28,-5,LEAVES:15)
Block(-3,28,-5,LEAVES:7)
Block(-2,28,-5,LEAVES:7)
Block(-1,28,-5,LEAVES:7)
Block(0,28,-5,LEAVES:7)
Block(1,28,-5,LEAVES:7)
Block(2,28,-5,LEAVES:7)
Block(4,28,-5,LEAVES:15)
Block(5,28,-5,LEAVES:15)
Block(6,28,-5,LEAVES:15)
Block(7,28,-5,LEAVES:15)
Block(-6,28,-4,LEAVES:15)
Block(-5,28,-4,LEAVES:15)
Block(-4,28,-4,LEAVES:15)
Block(-3,28,-4,LEAVES:7)
Block(-2,28,-4,LEAVES:7)
Block(-1,28,-4,LEAVES:7)
Block(0,28,-4,LEAVES:7)
Block(1,28,-4,LEAVES:7)
Block(2,28,-4,LEAVES:7)
Block(3,28,-4,LEAVES:7)
Block(4,28,-4,LEAVES:15)
Block(5,28,-4,LEAVES:15)
Block(6,28,-4,LEAVES:15)
Block(7,28,-4,LEAVES:15)
Block(8,28,-4,LEAVES:15)
Block(11,28,-4,LEAVES:15)
Block(-7,28,-3,LEAVES:15)
Block(-6,28,-3,LEAVES:15)
Block(-4,28,-3,LEAVES:7)
Block(-3,28,-3,LEAVES:7)
Block(-2,28,-3,LEAVES:15)
Block(-1,28,-3,LEAVES:7)
Block(0,28,-3,LEAVES:7)
Block(1,28,-3,LEAVES:7)
Block(2,28,-3,LEAVES:7)
Block(3,28,-3,LEAVES:7)
Block(4,28,-3,LEAVES:7)
Block(5,28,-3,LEAVES:7)
Block(6,28,-3,LEAVES:15)
Block(7,28,-3,LEAVES:15)
Block(8,28,-3,LEAVES:15)
Block(-7,28,-2,LEAVES:15)
Block(-6,28,-2,LEAVES:15)
Block(-5,28,-2,LEAVES:7)
Block(-4,28,-2,LEAVES:15)
Block(-3,28,-2,LEAVES:15)
Block(-2,28,-2,LEAVES:15)
Block(-1,28,-2,LOG:3)
Block(0,28,-2,LOG:3)
Block(1,28,-2,LEAVES:7)
Block(2,28,-2,LEAVES:7)
Block(3,28,-2,LEAVES:7)
Block(4,28,-2,LEAVES:7)
Block(5,28,-2,LEAVES:7)
Block(6,28,-2,LEAVES:15)
Block(7,28,-2,LEAVES:15)
Block(8,28,-2,LEAVES:15)
Block(11,28,-2,LEAVES:15)
Block(-8,28,-1,LEAVES:15)
Block(-7,28,-1,LEAVES:7)
Block(-6,28,-1,LEAVES:15)
Block(-5,28,-1,LEAVES:7)
Block(-4,28,-1,LEAVES:7)
Block(-3,28,-1,LEAVES:7)
Block(-2,28,-1,LOG:3)
Block(-1,28,-1,LOG:3)
Block(0,28,-1,LOG:3)
Block(1,28,-1,LOG:3)
Block(2,28,-1,LEAVES:7)
Block(3,28,-1,LEAVES:7)
Block(4,28,-1,LEAVES:7)
Block(5,28,-1,LEAVES:7)
Block(6,28,-1,LEAVES:15)
Block(7,28,-1,LEAVES:15)
Block(-8,28,0,LEAVES:15)
Block(-7,28,0,LEAVES:7)
Block(-6,28,0,LEAVES:7)
Block(-5,28,0,LEAVES:7)
Block(-4,28,0,LEAVES:7)
Block(-3,28,0,LEAVES:7)
Block(-2,28,0,LOG:3)
Block(-1,28,0,LOG:3)
Block(0,28,0,LOG:3)
Block(1,28,0,LOG:3)
Block(2,28,0,LEAVES:7)
Block(3,28,0,LEAVES:7)
Block(5,28,0,LEAVES:15)
Block(6,28,0,LEAVES:15)
Block(7,28,0,LEAVES:15)
Block(-8,28,1,LEAVES:7)
Block(-7,28,1,LEAVES:7)
Block(-6,28,1,LEAVES:7)
Block(-5,28,1,LEAVES:7)
Block(-4,28,1,LEAVES:7)
Block(-3,28,1,LEAVES:7)
Block(-2,28,1,LEAVES:7)
Block(-1,28,1,LOG:3)
Block(0,28,1,LOG:3)
Block(1,28,1,LEAVES:15)
Block(2,28,1,LEAVES:15)
Block(4,28,1,LEAVES:7)
Block(5,28,1,LEAVES:15)
Block(6,28,1,LEAVES:7)
Block(-7,28,2,LEAVES:7)
Block(-6,28,2,LEAVES:7)
Block(-5,28,2,LEAVES:15)
Block(-4,28,2,LEAVES:7)
Block(-3,28,2,LEAVES:7)
Block(-2,28,2,LEAVES:7)
Block(-1,28,2,LEAVES:15)
Block(0,28,2,LEAVES:15)
Block(1,28,2,LEAVES:7)
Block(2,28,2,LEAVES:7)
Block(4,28,2,LEAVES:7)
Block(5,28,2,LEAVES:15)
Block(9,28,2,LEAVES:15)
Block(-7,28,3,LEAVES:7)
Block(-6,28,3,LEAVES:7)
Block(-5,28,3,LEAVES:15)
Block(-4,28,3,LEAVES:7)
Block(-3,28,3,LEAVES:7)
Block(-2,28,3,LEAVES:7)
Block(-1,28,3,LEAVES:7)
Block(0,28,3,LEAVES:7)
Block(1,28,3,LEAVES:7)
Block(2,28,3,LEAVES:7)
Block(3,28,3,LEAVES:7)
Block(4,28,3,LEAVES:7)
Block(5,28,3,LEAVES:7)
Block(-6,28,4,LEAVES:7)
Block(-5,28,4,LEAVES:15)
Block(-4,28,4,LEAVES:15)
Block(-3,28,4,LEAVES:15)
Block(-2,28,4,LEAVES:7)
Block(-1,28,4,LEAVES:7)
Block(0,28,4,LEAVES:7)
Block(1,28,4,LEAVES:7)
Block(2,28,4,LEAVES:7)
Block(3,28,4,LEAVES:7)
Block(4,28,4,LEAVES:7)
Block(7,28,4,LEAVES:15)
Block(-5,28,5,LEAVES:15)
Block(-4,28,5,LEAVES:15)
Block(-3,28,5,LEAVES:15)
Block(-2,28,5,LEAVES:7)
Block(-1,28,5,LEAVES:7)
Block(0,28,5,LEAVES:7)
Block(1,28,5,LEAVES:7)
Block(2,28,5,LEAVES:15)
Block(3,28,5,LEAVES:15)
Block(-3,28,6,LEAVES:15)
Block(-2,28,6,LEAVES:7)
Block(-1,28,6,LEAVES:7)
Block(0,28,6,LEAVES:7)
Block(1,28,6,LEAVES:15)
Block(-2,28,7,LEAVES:7)
Block(-1,28,7,LEAVES:7)
Block(0,28,7,LEAVES:7)
Block(0,28,8,LEAVES:7)
Block(0,28,10,LEAVES:15)
Block(3,29,-10,LEAVES:7)
Block(6,29,-10,LEAVES:15)
Block(-6,29,-9,LEAVES:15)
Block(-3,29,-9,LEAVES:15)
Block(0,29,-9,LEAVES:15)
Block(1,29,-9,LEAVES:15)
Block(2,29,-9,LEAVES:15)
Block(3,29,-9,LEAVES:15)
Block(4,29,-9,LEAVES:15)
Block(5,29,-9,LEAVES:15)
Block(-5,29,-8,LEAVES:15)
Block(-4,29,-8,LEAVES:15)
Block(-3,29,-8,LEAVES:15)
Block(-2,29,-8,LEAVES:15)
Block(-1,29,-8,LEAVES:15)
Block(0,29,-8,LEAVES:15)
Block(1,29,-8,LEAVES:15)
Block(2,29,-8,LEAVES:7)
Block(3,29,-8,LEAVES:7)
Block(4,29,-8,LEAVES:7)
Block(5,29,-8,LEAVES:7)
Block(6,29,-8,LEAVES:15)
Block(7,29,-8,LEAVES:15)
Block(-8,29,-7,LEAVES:15)
Block(-6,29,-7,LEAVES:7)
Block(-5,29,-7,LEAVES:15)
Block(-4,29,-7,LEAVES:7)
Block(-3,29,-7,LEAVES:7)
Block(-2,29,-7,LEAVES:7)
Block(-1,29,-7,LEAVES:7)
Block(0,29,-7,LEAVES:7)
Block(1,29,-7,LEAVES:15)
Block(2,29,-7,LEAVES:15)
Block(3,29,-7,LEAVES:7)
Block(4,29,-7,LEAVES:7)
Block(5,29,-7,LEAVES:7)
Block(6,29,-7,LEAVES:15)
Block(7,29,-7,LEAVES:15)
Block(8,29,-7,LEAVES:15)
Block(-7,29,-6,LEAVES:15)
Block(-6,29,-6,LEAVES:7)
Block(-5,29,-6,LEAVES:15)
Block(-4,29,-6,LEAVES:15)
Block(-3,29,-6,LEAVES:15)
Block(-2,29,-6,LEAVES:7)
Block(-1,29,-6,LEAVES:7)
Block(0,29,-6,LEAVES:7)
Block(1,29,-6,LEAVES:15)
Block(2,29,-6,LEAVES:15)
Block(3,29,-6,LEAVES:7)
Block(4,29,-6,LEAVES:7)
Block(5,29,-6,LEAVES:7)
Block(6,29,-6,LEAVES:7)
Block(7,29,-6,LEAVES:15)
Block(8,29,-6,LEAVES:15)
Block(9,29,-6,LEAVES:15)
Block(-8,29,-5,LEAVES:15)
Block(-7,29,-5,LEAVES:15)
Block(-6,29,-5,LEAVES:15)
Block(-5,29,-5,LEAVES:15)
Block(-4,29,-5,LEAVES:15)
Block(-3,29,-5,LEAVES:15)
Block(-2,29,-5,LEAVES:7)
Block(-1,29,-5,LEAVES:7)
Block(0,29,-5,LEAVES:7)
Block(1,29,-5,LEAVES:15)
Block(2,29,-5,LEAVES:15)
Block(3,29,-5,LEAVES:15)
Block(4,29,-5,LEAVES:7)
Block(5,29,-5,LEAVES:7)
Block(6,29,-5,LEAVES:7)
Block(7,29,-5,LEAVES:7)
Block(8,29,-5,LEAVES:7)
Block(9,29,-5,LEAVES:15)
Block(10,29,-5,LEAVES:15)
Block(-9,29,-4,LEAVES:15)
Block(-8,29,-4,LEAVES:15)
Block(-7,29,-4,LEAVES:15)
Block(-6,29,-4,LEAVES:15)
Block(-5,29,-4,LEAVES:15)
Block(-4,29,-4,LEAVES:15)
Block(-3,29,-4,LEAVES:15)
Block(-2,29,-4,LEAVES:15)
Block(-1,29,-4,LEAVES:7)
Block(0,29,-4,LEAVES:15)
Block(1,29,-4,LEAVES:15)
Block(2,29,-4,LEAVES:15)
Block(3,29,-4,LEAVES:7)
Block(4,29,-4,LEAVES:15)
Block(5,29,-4,LEAVES:15)
Block(6,29,-4,LEAVES:15)
Block(7,29,-4,LEAVES:15)
Block(8,29,-4,LEAVES:7)
Block(9,29,-4,LEAVES:15)
Block(10,29,-4,LEAVES:15)
Block(-10,29,-3,LEAVES:7)
Block(-9,29,-3,LEAVES:15)
Block(-8,29,-3,LEAVES:15)
Block(-7,29,-3,LEAVES:15)
Block(-6,29,-3,LEAVES:7)
Block(-5,29,-3,LEAVES:7)
Block(-4,29,-3,LEAVES:7)
Block(-3,29,-3,LEAVES:15)
Block(-2,29,-3,LEAVES:15)
Block(-1,29,-3,LEAVES:7)
Block(0,29,-3,LEAVES:7)
Block(1,29,-3,LEAVES:7)
Block(2,29,-3,LEAVES:7)
Block(3,29,-3,LEAVES:7)
Block(4,29,-3,LEAVES:15)
Block(5,29,-3,LEAVES:15)
Block(6,29,-3,LEAVES:15)
Block(7,29,-3,LEAVES:15)
Block(8,29,-3,LEAVES:15)
Block(9,29,-3,LEAVES:15)
Block(10,29,-3,LEAVES:15)
Block(-9,29,-2,LEAVES:15)
Block(-8,29,-2,LEAVES:15)
Block(-7,29,-2,LEAVES:7)
Block(-6,29,-2,LEAVES:7)
Block(-5,29,-2,LEAVES:7)
Block(-4,29,-2,LEAVES:15)
Block(-3,29,-2,LEAVES:15)
Block(-2,29,-2,LEAVES:15)
Block(-1,29,-2,LOG:3)
Block(0,29,-2,LEAVES:7)
Block(1,29,-2,LEAVES:7)
Block(2,29,-2,LEAVES:7)
Block(3,29,-2,LEAVES:7)
Block(4,29,-2,LEAVES:15)
Block(5,29,-2,LEAVES:7)
Block(6,29,-2,LEAVES:15)
Block(7,29,-2,LEAVES:15)
Block(8,29,-2,LEAVES:15)
Block(9,29,-2,LEAVES:15)
Block(10,29,-2,LEAVES:15)
Block(-9,29,-1,LEAVES:15)
Block(-8,29,-1,LEAVES:15)
Block(-7,29,-1,LEAVES:15)
Block(-6,29,-1,LEAVES:15)
Block(-5,29,-1,LEAVES:7)
Block(-4,29,-1,LEAVES:15)
Block(-3,29,-1,LEAVES:15)
Block(-2,29,-1,LOG:3)
Block(-1,29,-1,LOG:3)
Block(0,29,-1,LOG:3)
Block(1,29,-1,LEAVES:7)
Block(2,29,-1,LEAVES:7)
Block(3,29,-1,LEAVES:7)
Block(4,29,-1,LEAVES:15)
Block(5,29,-1,LEAVES:15)
Block(6,29,-1,LEAVES:15)
Block(7,29,-1,LEAVES:15)
Block(8,29,-1,LEAVES:15)
Block(9,29,-1,LEAVES:15)
Block(10,29,-1,LEAVES:15)
Block(-10,29,0,LEAVES:7)
Block(-9,29,0,LEAVES:15)
Block(-8,29,0,LEAVES:15)
Block(-7,29,0,LEAVES:15)
Block(-6,29,0,LEAVES:15)
Block(-5,29,0,LEAVES:7)
Block(-4,29,0,LEAVES:15)
Block(-3,29,0,LEAVES:15)
Block(-2,29,0,LEAVES:7)
Block(-1,29,0,LOG:3)
Block(0,29,0,LOG:3)
Block(1,29,0,LOG:3)
Block(2,29,0,LEAVES:7)
Block(3,29,0,LEAVES:7)
Block(4,29,0,LEAVES:15)
Block(5,29,0,LEAVES:15)
Block(6,29,0,LEAVES:15)
Block(7,29,0,LEAVES:15)
Block(8,29,0,LEAVES:15)
Block(9,29,0,LEAVES:15)
Block(11,29,0,LEAVES:15)
Block(-9,29,1,LEAVES:15)
Block(-8,29,1,LEAVES:15)
Block(-7,29,1,LEAVES:15)
Block(-6,29,1,LEAVES:15)
Block(-5,29,1,LEAVES:15)
Block(-4,29,1,LEAVES:15)
Block(-3,29,1,LEAVES:15)
Block(-2,29,1,LEAVES:7)
Block(-1,29,1,LOG:3)
Block(0,29,1,LOG:3)
Block(1,29,1,LEAVES:15)
Block(2,29,1,LEAVES:15)
Block(3,29,1,LEAVES:15)
Block(4,29,1,LEAVES:15)
Block(5,29,1,LEAVES:15)
Block(6,29,1,LEAVES:15)
Block(7,29,1,LEAVES:15)
Block(8,29,1,LEAVES:15)
Block(-9,29,2,LEAVES:15)
Block(-8,29,2,LEAVES:15)
Block(-7,29,2,LEAVES:15)
Block(-6,29,2,LEAVES:15)
Block(-5,29,2,LEAVES:15)
Block(-4,29,2,LEAVES:15)
Block(-3,29,2,LEAVES:15)
Block(-2,29,2,LEAVES:15)
Block(-1,29,2,LEAVES:7)
Block(0,29,2,LEAVES:7)
Block(1,29,2,LEAVES:15)
Block(2,29,2,LEAVES:7)
Block(3,29,2,LEAVES:7)
Block(4,29,2,LEAVES:15)
Block(5,29,2,LEAVES:15)
Block(6,29,2,LEAVES:15)
Block(7,29,2,LEAVES:15)
Block(8,29,2,LEAVES:15)
Block(-10,29,3,LEAVES:15)
Block(-8,29,3,LEAVES:15)
Block(-7,29,3,LEAVES:15)
Block(-6,29,3,LEAVES:15)
Block(-5,29,3,LEAVES:15)
Block(-4,29,3,LEAVES:15)
Block(-3,29,3,LEAVES:15)
Block(-2,29,3,LEAVES:15)
Block(-1,29,3,LEAVES:7)
Block(0,29,3,LEAVES:7)
Block(2,29,3,LEAVES:7)
Block(3,29,3,LEAVES:7)
Block(4,29,3,LEAVES:7)
Block(5,29,3,LEAVES:7)
Block(6,29,3,LEAVES:15)
Block(7,29,3,LEAVES:15)
Block(-8,29,4,LEAVES:15)
Block(-7,29,4,LEAVES:15)
Block(-6,29,4,LEAVES:15)
Block(-5,29,4,LEAVES:15)
Block(-4,29,4,LEAVES:15)
Block(-3,29,4,LEAVES:15)
Block(-2,29,4,LEAVES:15)
Block(-1,29,4,LEAVES:7)
Block(0,29,4,LEAVES:7)
Block(1,29,4,LEAVES:7)
Block(2,29,4,LEAVES:7)
Block(3,29,4,LEAVES:7)
Block(4,29,4,LEAVES:7)
Block(5,29,4,LEAVES:7)
Block(6,29,4,LEAVES:15)
Block(-7,29,5,LEAVES:15)
Block(-6,29,5,LEAVES:15)
Block(-5,29,5,LEAVES:15)
Block(-4,29,5,LEAVES:15)
Block(-3,29,5,LEAVES:7)
Block(-2,29,5,LEAVES:7)
Block(-1,29,5,LEAVES:7)
Block(0,29,5,LEAVES:7)
Block(1,29,5,LEAVES:7)
Block(2,29,5,LEAVES:7)
Block(3,29,5,LEAVES:7)
Block(4,29,5,LEAVES:15)
Block(5,29,5,LEAVES:15)
Block(-6,29,6,LEAVES:15)
Block(-5,29,6,LEAVES:15)
Block(-4,29,6,LEAVES:7)
Block(-3,29,6,LEAVES:7)
Block(-2,29,6,LEAVES:7)
Block(-1,29,6,LEAVES:7)
Block(0,29,6,LEAVES:7)
Block(1,29,6,LEAVES:7)
Block(2,29,6,LEAVES:7)
Block(3,29,6,LEAVES:7)
Block(4,29,6,LEAVES:15)
Block(5,29,6,LEAVES:15)
Block(-4,29,7,LEAVES:15)
Block(-3,29,7,LEAVES:15)
Block(-2,29,7,LEAVES:7)
Block(-1,29,7,LEAVES:7)
Block(0,29,7,LEAVES:7)
Block(1,29,7,LEAVES:7)
Block(2,29,7,LEAVES:7)
Block(3,29,7,LEAVES:7)
Block(-5,29,8,LEAVES:15)
Block(-3,29,8,LEAVES:15)
Block(-2,29,8,LEAVES:7)
Block(-1,29,8,LEAVES:7)
Block(0,29,8,LEAVES:7)
Block(1,29,8,LEAVES:15)
Block(2,29,8,LEAVES:15)
Block(-2,29,9,LEAVES:15)
Block(-1,29,9,LEAVES:15)
Block(0,29,9,LEAVES:15)
Block(-3,29,10,LEAVES:15)
Block(0,30,-10,LEAVES:15)
Block(2,30,-9,LEAVES:15)
Block(3,30,-9,LEAVES:15)
Block(4,30,-9,LEAVES:15)
Block(7,30,-9,LEAVES:15)
Block(-5,30,-8,LEAVES:15)
Block(-3,30,-8,LEAVES:15)
Block(-2,30,-8,LEAVES:15)
Block(-1,30,-8,LEAVES:15)
Block(0,30,-8,LEAVES:15)
Block(1,30,-8,LEAVES:15)
Block(2,30,-8,LEAVES:15)
Block(3,30,-8,LEAVES:15)
Block(4,30,-8,LEAVES:15)
Block(5,30,-8,LEAVES:15)
Block(-6,30,-7,LEAVES:15)
Block(-5,30,-7,LEAVES:15)
Block(-4,30,-7,LEAVES:15)
Block(-3,30,-7,LEAVES:15)
Block(-2,30,-7,LEAVES:15)
Block(-1,30,-7,LEAVES:15)
Block(0,30,-7,LEAVES:15)
Block(1,30,-7,LEAVES:7)
Block(2,30,-7,LEAVES:7)
Block(3,30,-7,LEAVES:7)
Block(4,30,-7,LEAVES:15)
Block(5,30,-7,LEAVES:15)
Block(6,30,-7,LEAVES:15)
Block(9,30,-7,LEAVES:15)
Block(-7,30,-6,LEAVES:15)
Block(-6,30,-6,LEAVES:15)
Block(-5,30,-6,LEAVES:15)
Block(-4,30,-6,LEAVES:15)
Block(-3,30,-6,LEAVES:15)
Block(-2,30,-6,LEAVES:7)
Block(-1,30,-6,LEAVES:7)
Block(0,30,-6,LEAVES:7)
Block(1,30,-6,LEAVES:7)
Block(2,30,-6,LEAVES:7)
Block(3,30,-6,LEAVES:7)
Block(4,30,-6,LEAVES:7)
Block(5,30,-6,LEAVES:15)
Block(6,30,-6,LEAVES:15)
Block(7,30,-6,LEAVES:15)
Block(-9,30,-5,LEAVES:15)
Block(-7,30,-5,LEAVES:15)
Block(-6,30,-5,LEAVES:15)
Block(-5,30,-5,LEAVES:15)
Block(-4,30,-5,LEAVES:15)
Block(-3,30,-5,LEAVES:7)
Block(-2,30,-5,LEAVES:7)
Block(-1,30,-5,LEAVES:7)
Block(0,30,-5,LEAVES:7)
Block(1,30,-5,LEAVES:7)
Block(2,30,-5,LEAVES:7)
Block(3,30,-5,LEAVES:7)
Block(4,30,-5,LEAVES:7)
Block(5,30,-5,LEAVES:7)
Block(6,30,-5,LEAVES:15)
Block(7,30,-5,LEAVES:15)
Block(8,30,-5,LEAVES:15)
Block(11,30,-5,LEAVES:15)
Block(-7,30,-4,LEAVES:15)
Block(-6,30,-4,LEAVES:15)
Block(-5,30,-4,LEAVES:15)
Block(-4,30,-4,LEAVES:15)
Block(-3,30,-4,LEAVES:15)
Block(-2,30,-4,LEAVES:15)
Block(-1,30,-4,LEAVES:15)
Block(0,30,-4,LEAVES:15)
Block(1,30,-4,LEAVES:15)
Block(2,30,-4,LEAVES:15)
Block(3,30,-4,LEAVES:15)
Block(4,30,-4,LEAVES:15)
Block(5,30,-4,LEAVES:15)
Block(6,30,-4,LEAVES:15)
Block(7,30,-4,LEAVES:15)
Block(8,30,-4,LEAVES:15)
Block(9,30,-4,LEAVES:15)
Block(10,30,-4,LEAVES:15)
Block(-8,30,-3,LEAVES:15)
Block(-7,30,-3,LEAVES:15)
Block(-6,30,-3,LEAVES:7)
Block(-5,30,-3,LEAVES:15)
Block(-4,30,-3,LEAVES:15)
Block(-3,30,-3,LEAVES:15)
Block(-2,30,-3,LEAVES:15)
Block(-1,30,-3,LEAVES:15)
Block(0,30,-3,LEAVES:15)
Block(1,30,-3,LEAVES:15)
Block(2,30,-3,LEAVES:15)
Block(3,30,-3,LEAVES:15)
Block(4,30,-3,LEAVES:7)
Block(5,30,-3,LEAVES:15)
Block(6,30,-3,LEAVES:15)
Block(7,30,-3,LEAVES:15)
Block(8,30,-3,LEAVES:15)
Block(9,30,-3,LEAVES:15)
Block(10,30,-3,LEAVES:15)
Block(-9,30,-2,LEAVES:15)
Block(-8,30,-2,LEAVES:15)
Block(-7,30,-2,LEAVES:15)
Block(-6,30,-2,LEAVES:15)
Block(-5,30,-2,LEAVES:15)
Block(-4,30,-2,LEAVES:15)
Block(-3,30,-2,LEAVES:15)
Block(-2,30,-2,LEAVES:15)
Block(-1,30,-2,LEAVES:15)
Block(0,30,-2,LEAVES:15)
Block(1,30,-2,LEAVES:15)
Block(2,30,-2,LEAVES:15)
Block(3,30,-2,LEAVES:15)
Block(4,30,-2,LEAVES:15)
Block(5,30,-2,LEAVES:15)
Block(6,30,-2,LEAVES:7)
Block(7,30,-2,LEAVES:15)
Block(8,30,-2,LEAVES:15)
Block(9,30,-2,LEAVES:15)
Block(10,30,-2,LEAVES:15)
Block(-9,30,-1,LEAVES:15)
Block(-8,30,-1,LEAVES:15)
Block(-7,30,-1,LEAVES:15)
Block(-6,30,-1,LEAVES:15)
Block(-5,30,-1,LEAVES:15)
Block(-4,30,-1,LEAVES:15)
Block(-3,30,-1,LEAVES:15)
Block(-2,30,-1,LOG:3)
Block(-1,30,-1,LOG:3)
Block(0,30,-1,LOG:3)
Block(1,30,-1,LEAVES:15)
Block(2,30,-1,LEAVES:15)
Block(3,30,-1,LEAVES:15)
Block(4,30,-1,LEAVES:7)
Block(5,30,-1,LEAVES:15)
Block(6,30,-1,LEAVES:7)
Block(7,30,-1,LEAVES:7)
Block(8,30,-1,LEAVES:15)
Block(9,30,-1,LEAVES:15)
Block(-9,30,0,LEAVES:15)
Block(-8,30,0,LEAVES:15)
Block(-7,30,0,LEAVES:15)
Block(-6,30,0,LEAVES:15)
Block(-5,30,0,LEAVES:15)
Block(-4,30,0,LEAVES:15)
Block(-3,30,0,LEAVES:15)
Block(-2,30,0,LEAVES:15)
Block(-1,30,0,LOG:3)
Block(0,30,0,LOG:3)
Block(1,30,0,LEAVES:15)
Block(2,30,0,LEAVES:15)
Block(3,30,0,LEAVES:15)
Block(4,30,0,LEAVES:7)
Block(5,30,0,LEAVES:15)
Block(6,30,0,LEAVES:15)
Block(7,30,0,LEAVES:15)
Block(8,30,0,LEAVES:15)
Block(-9,30,1,LEAVES:15)
Block(-8,30,1,LEAVES:15)
Block(-7,30,1,LEAVES:7)
Block(-6,30,1,LEAVES:7)
Block(-5,30,1,LEAVES:15)
Block(-4,30,1,LEAVES:15)
Block(-3,30,1,LEAVES:15)
Block(-2,30,1,LEAVES:15)
Block(-1,30,1,LEAVES:15)
Block(0,30,1,LOG:3)
Block(1,30,1,LEAVES:15)
Block(2,30,1,LEAVES:15)
Block(3,30,1,LEAVES:15)
Block(4,30,1,LEAVES:15)
Block(5,30,1,LEAVES:15)
Block(6,30,1,LEAVES:15)
Block(7,30,1,LEAVES:15)
Block(-8,30,2,LEAVES:15)
Block(-7,30,2,LEAVES:15)
Block(-6,30,2,LEAVES:15)
Block(-5,30,2,LEAVES:15)
Block(-4,30,2,LEAVES:15)
Block(-3,30,2,LEAVES:15)
Block(-2,30,2,LEAVES:15)
Block(-1,30,2,LEAVES:15)
Block(0,30,2,LEAVES:15)
Block(1,30,2,LEAVES:15)
Block(2,30,2,LEAVES:15)
Block(3,30,2,LEAVES:15)
Block(4,30,2,LEAVES:15)
Block(5,30,2,LEAVES:15)
Block(6,30,2,LEAVES:15)
Block(7,30,2,LEAVES:15)
Block(-7,30,3,LEAVES:15)
Block(-6,30,3,LEAVES:15)
Block(-5,30,3,LEAVES:15)
Block(-4,30,3,LEAVES:15)
Block(-3,30,3,LEAVES:15)
Block(-2,30,3,LEAVES:15)
Block(-1,30,3,LEAVES:15)
Block(0,30,3,LEAVES:15)
Block(1,30,3,LEAVES:15)
Block(2,30,3,LEAVES:15)
Block(3,30,3,LEAVES:15)
Block(4,30,3,LEAVES:15)
Block(5,30,3,LEAVES:15)
Block(6,30,3,LEAVES:15)
Block(7,30,3,LEAVES:15)
Block(-6,30,4,LEAVES:15)
Block(-5,30,4,LEAVES:15)
Block(-4,30,4,LEAVES:15)
Block(-3,30,4,LEAVES:15)
Block(-2,30,4,LEAVES:15)
Block(-1,30,4,LEAVES:15)
Block(0,30,4,LEAVES:15)
Block(1,30,4,LEAVES:15)
Block(2,30,4,LEAVES:15)
Block(3,30,4,LEAVES:15)
Block(4,30,4,LEAVES:15)
Block(5,30,4,LEAVES:15)
Block(-8,30,5,LEAVES:15)
Block(-5,30,5,LEAVES:15)
Block(-4,30,5,LEAVES:15)
Block(-3,30,5,LEAVES:7)
Block(-2,30,5,LEAVES:15)
Block(-1,30,5,LEAVES:15)
Block(0,30,5,LEAVES:7)
Block(1,30,5,LEAVES:15)
Block(2,30,5,LEAVES:15)
Block(3,30,5,LEAVES:15)
Block(4,30,5,LEAVES:15)
Block(5,30,5,LEAVES:15)
Block(-4,30,6,LEAVES:15)
Block(-3,30,6,LEAVES:15)
Block(-2,30,6,LEAVES:15)
Block(-1,30,6,LEAVES:15)
Block(0,30,6,LEAVES:7)
Block(1,30,6,LEAVES:7)
Block(2,30,6,LEAVES:7)
Block(3,30,6,LEAVES:15)
Block(-7,30,7,LEAVES:15)
Block(-3,30,7,LEAVES:15)
Block(-2,30,7,LEAVES:7)
Block(-1,30,7,LEAVES:15)
Block(0,30,7,LEAVES:15)
Block(1,30,7,LEAVES:15)
Block(2,30,7,LEAVES:7)
Block(3,30,7,LEAVES:7)
Block(-2,30,8,LEAVES:15)
Block(-1,30,8,LEAVES:15)
Block(0,30,8,LEAVES:15)
Block(1,30,8,LEAVES:15)
Block(2,30,8,LEAVES:15)
Block(-1,30,9,LEAVES:15)
Block(0,30,9,LEAVES:15)
Block(1,30,9,LEAVES:15)
Block(3,30,9,LEAVES:15)
Block(2,31,-10,LEAVES:15)
Block(-2,31,-9,LEAVES:15)
Block(5,31,-9,LEAVES:15)
Block(-6,31,-8,LEAVES:15)
Block(3,31,-8,LEAVES:15)
Block(-2,31,-7,LEAVES:15)
Block(-1,31,-7,LEAVES:15)
Block(0,31,-7,LEAVES:15)
Block(1,31,-7,LEAVES:15)
Block(2,31,-7,LEAVES:15)
Block(3,31,-7,LEAVES:15)
Block(4,31,-7,LEAVES:15)
Block(5,31,-7,LEAVES:15)
Block(8,31,-7,LEAVES:15)
Block(-4,31,-6,LEAVES:15)
Block(-3,31,-6,LEAVES:15)
Block(-2,31,-6,LEAVES:15)
Block(-1,31,-6,LEAVES:15)
Block(0,31,-6,LEAVES:15)
Block(1,31,-6,LEAVES:15)
Block(2,31,-6,LEAVES:15)
Block(3,31,-6,LEAVES:15)
Block(4,31,-6,LEAVES:15)
Block(5,31,-6,LEAVES:15)
Block(6,31,-6,LEAVES:15)
Block(-5,31,-5,LEAVES:15)
Block(-4,31,-5,LEAVES:15)
Block(-3,31,-5,LEAVES:15)
Block(-2,31,-5,LEAVES:7)
Block(-1,31,-5,LEAVES:15)
Block(0,31,-5,LEAVES:15)
Block(1,31,-5,LEAVES:15)
Block(2,31,-5,LEAVES:7)
Block(3,31,-5,LEAVES:15)
Block(4,31,-5,LEAVES:15)
Block(5,31,-5,LEAVES:15)
Block(6,31,-5,LEAVES:15)
Block(9,31,-5,LEAVES:15)
Block(-6,31,-4,LEAVES:15)
Block(-5,31,-4,LEAVES:15)
Block(-4,31,-4,LEAVES:15)
Block(-3,31,-4,LEAVES:15)
Block(-2,31,-4,LEAVES:15)
Block(-1,31,-4,LEAVES:15)
Block(0,31,-4,LEAVES:15)
Block(1,31,-4,LEAVES:15)
Block(2,31,-4,LEAVES:15)
Block(3,31,-4,LEAVES:15)
Block(4,31,-4,LEAVES:7)
Block(5,31,-4,LEAVES:15)
Block(6,31,-4,LEAVES:15)
Block(7,31,-4,LEAVES:15)
Block(-7,31,-3,LEAVES:15)
Block(-6,31,-3,LEAVES:15)
Block(-5,31,-3,LEAVES:15)
Block(-4,31,-3,LEAVES:15)
Block(-3,31,-3,LEAVES:15)
Block(-2,31,-3,LEAVES:15)
Block(-1,31,-3,LEAVES:15)
Block(0,31,-3,LEAVES:15)
Block(1,31,-3,LEAVES:15)
Block(2,31,-3,LEAVES:15)
Block(3,31,-3,LEAVES:15)
Block(4,31,-3,LEAVES:7)
Block(5,31,-3,LEAVES:15)
Block(6,31,-3,LEAVES:15)
Block(7,31,-3,LEAVES:15)
Block(8,31,-3,LEAVES:15)
Block(9,31,-3,LEAVES:15)
Block(11,31,-3,LEAVES:15)
Block(-10,31,-2,LEAVES:15)
Block(-7,31,-2,LEAVES:15)
Block(-6,31,-2,LEAVES:15)
Block(-5,31,-2,LEAVES:15)
Block(-4,31,-2,LEAVES:15)
Block(-3,31,-2,LEAVES:15)
Block(-2,31,-2,LEAVES:15)
Block(-1,31,-2,LEAVES:15)
Block(0,31,-2,LEAVES:15)
Block(1,31,-2,LEAVES:15)
Block(2,31,-2,LEAVES:15)
Block(3,31,-2,LEAVES:15)
Block(4,31,-2,LEAVES:15)
Block(5,31,-2,LEAVES:7)
Block(6,31,-2,LEAVES:7)
Block(7,31,-2,LEAVES:7)
Block(8,31,-2,LEAVES:15)
Block(-8,31,-1,LEAVES:15)
Block(-7,31,-1,LEAVES:15)
Block(-6,31,-1,LEAVES:15)
Block(-5,31,-1,LEAVES:15)
Block(-4,31,-1,LEAVES:15)
Block(-3,31,-1,LEAVES:15)
Block(-2,31,-1,LOG:3)
Block(-1,31,-1,LOG:3)
Block(0,31,-1,LEAVES:15)
Block(1,31,-1,LEAVES:15)
Block(2,31,-1,LEAVES:15)
Block(3,31,-1,LEAVES:15)
Block(4,31,-1,LEAVES:15)
Block(5,31,-1,LEAVES:7)
Block(6,31,-1,LEAVES:7)
Block(7,31,-1,LEAVES:7)
Block(8,31,-1,LEAVES:7)
Block(10,31,-1,LEAVES:15)
Block(-10,31,0,LEAVES:15)
Block(-8,31,0,LEAVES:15)
Block(-7,31,0,LEAVES:15)
Block(-6,31,0,LEAVES:15)
Block(-5,31,0,LEAVES:15)
Block(-4,31,0,LEAVES:15)
Block(-3,31,0,LEAVES:15)
Block(-2,31,0,LEAVES:15)
Block(-1,31,0,LOG:3)
Block(0,31,0,LOG:3)
Block(1,31,0,LEAVES:15)
Block(2,31,0,LEAVES:15)
Block(3,31,0,LEAVES:15)
Block(4,31,0,LEAVES:15)
Block(5,31,0,LEAVES:7)
Block(6,31,0,LEAVES:15)
Block(7,31,0,LEAVES:15)
Block(-7,31,1,LEAVES:15)
Block(-6,31,1,LEAVES:15)
Block(-5,31,1,LEAVES:15)
Block(-4,31,1,LEAVES:15)
Block(-3,31,1,LEAVES:15)
Block(-2,31,1,LEAVES:15)
Block(-1,31,1,LEAVES:15)
Block(0,31,1,LEAVES:15)
Block(1,31,1,LEAVES:15)
Block(2,31,1,LEAVES:15)
Block(3,31,1,LEAVES:15)
Block(4,31,1,LEAVES:15)
Block(5,31,1,LEAVES:15)
Block(6,31,1,LEAVES:15)
Block(8,31,1,LEAVES:15)
Block(-6,31,2,LEAVES:15)
Block(-5,31,2,LEAVES:15)
Block(-4,31,2,LEAVES:15)
Block(-3,31,2,LEAVES:15)
Block(-2,31,2,LEAVES:15)
Block(-1,31,2,LEAVES:15)
Block(0,31,2,LEAVES:15)
Block(1,31,2,LEAVES:15)
Block(2,31,2,LEAVES:15)
Block(3,31,2,LEAVES:15)
Block(4,31,2,LEAVES:15)
Block(5,31,2,LEAVES:15)
Block(-8,31,3,LEAVES:15)
Block(-5,31,3,LEAVES:15)
Block(-4,31,3,LEAVES:15)
Block(-3,31,3,LEAVES:15)
Block(-2,31,3,LEAVES:15)
Block(-1,31,3,LEAVES:15)
Block(0,31,3,LEAVES:15)
Block(1,31,3,LEAVES:15)
Block(2,31,3,LEAVES:15)
Block(3,31,3,LEAVES:15)
Block(4,31,3,LEAVES:15)
Block(-4,31,4,LEAVES:15)
Block(-3,31,4,LEAVES:15)
Block(-2,31,4,LEAVES:15)
Block(-1,31,4,LEAVES:15)
Block(0,31,4,LEAVES:15)
Block(1,31,4,LEAVES:15)
Block(2,31,4,LEAVES:15)
Block(3,31,4,LEAVES:15)
Block(5,31,4,LEAVES:7)
Block(7,31,4,LEAVES:15)
Block(-6,31,5,LEAVES:15)
Block(-3,31,5,LEAVES:15)
Block(-2,31,5,LEAVES:15)
Block(-1,31,5,LEAVES:15)
Block(0,31,5,LEAVES:15)
Block(1,31,5,LEAVES:15)
Block(2,31,5,LEAVES:15)
Block(-5,31,6,LEAVES:15)
Block(-2,31,6,LEAVES:15)
Block(-1,31,6,LEAVES:15)
Block(0,31,6,LEAVES:15)
Block(5,31,6,LEAVES:15)
Block(-3,31,7,LEAVES:15)
Block(-1,31,7,LEAVES:15)
Block(0,31,7,LEAVES:15)
Block(3,31,7,LEAVES:7)
Block(-4,31,8,LEAVES:15)
Block(1,31,8,LEAVES:7)
Block(-1,31,10,LEAVES:15)
Block(1,31,10,LEAVES:15)
Block(3,32,-9,LEAVES:15)
Block(-1,32,-8,LEAVES:15)
Block(1,32,-8,LEAVES:15)
Block(4,32,-8,LEAVES:15)
Block(-4,32,-7,LEAVES:15)
Block(6,32,-7,LEAVES:15)
Block(-1,32,-6,LEAVES:15)
Block(0,32,-6,LEAVES:15)
Block(1,32,-6,LEAVES:15)
Block(2,32,-6,LEAVES:15)
Block(3,32,-6,LEAVES:15)
Block(4,32,-6,LEAVES:15)
Block(-6,32,-5,LEAVES:15)
Block(-3,32,-5,LEAVES:15)
Block(-2,32,-5,LEAVES:15)
Block(-1,32,-5,LEAVES:15)
Block(0,32,-5,LEAVES:15)
Block(1,32,-5,LEAVES:7)
Block(2,32,-5,LEAVES:15)
Block(3,32,-5,LEAVES:15)
Block(4,32,-5,LEAVES:15)
Block(5,32,-5,LEAVES:15)
Block(7,32,-5,LEAVES:15)
Block(-3,32,-4,LEAVES:15)
Block(-2,32,-4,LEAVES:15)
Block(-1,32,-4,LEAVES:15)
Block(0,32,-4,LEAVES:15)
Block(1,32,-4,LEAVES:15)
Block(2,32,-4,LEAVES:15)
Block(3,32,-4,LEAVES:15)
Block(4,32,-4,LEAVES:15)
Block(5,32,-4,LEAVES:15)
Block(9,32,-4,LEAVES:15)
Block(-8,32,-3,LEAVES:15)
Block(-5,32,-3,LEAVES:15)
Block(-4,32,-3,LEAVES:15)
Block(-3,32,-3,LEAVES:15)
Block(-2,32,-3,LEAVES:15)
Block(-1,32,-3,LEAVES:15)
Block(0,32,-3,LEAVES:15)
Block(1,32,-3,LEAVES:15)
Block(2,32,-3,LEAVES:15)
Block(3,32,-3,LEAVES:15)
Block(4,32,-3,LEAVES:7)
Block(5,32,-3,LEAVES:7)
Block(6,32,-3,LEAVES:15)
Block(-5,32,-2,LEAVES:15)
Block(-4,32,-2,LEAVES:15)
Block(-3,32,-2,LEAVES:15)
Block(-2,32,-2,LEAVES:15)
Block(-1,32,-2,LEAVES:15)
Block(0,32,-2,LEAVES:15)
Block(1,32,-2,LEAVES:15)
Block(2,32,-2,LEAVES:15)
Block(3,32,-2,LEAVES:15)
Block(4,32,-2,LEAVES:7)
Block(5,32,-2,LEAVES:7)
Block(6,32,-2,LEAVES:15)
Block(7,32,-2,LEAVES:15)
Block(-7,32,-1,LEAVES:15)
Block(-6,32,-1,LEAVES:15)
Block(-5,32,-1,LEAVES:15)
Block(-4,32,-1,LEAVES:15)
Block(-3,32,-1,LEAVES:15)
Block(-2,32,-1,LEAVES:15)
Block(-1,32,-1,LOG:3)
Block(0,32,-1,LEAVES:15)
Block(1,32,-1,LEAVES:15)
Block(2,32,-1,LEAVES:15)
Block(3,32,-1,LEAVES:15)
Block(4,32,-1,LEAVES:7)
Block(5,32,-1,LEAVES:7)
Block(6,32,-1,LEAVES:15)
Block(-6,32,0,LEAVES:15)
Block(-5,32,0,LEAVES:15)
Block(-4,32,0,LEAVES:15)
Block(-3,32,0,LEAVES:15)
Block(-2,32,0,LEAVES:15)
Block(-1,32,0,LOG:3)
Block(0,32,0,LEAVES:15)
Block(1,32,0,LEAVES:15)
Block(2,32,0,LEAVES:15)
Block(3,32,0,LEAVES:15)
Block(4,32,0,LEAVES:15)
Block(5,32,0,LEAVES:15)
Block(7,32,0,LEAVES:7)
Block(-8,32,1,LEAVES:15)
Block(-5,32,1,LEAVES:15)
Block(-4,32,1,LEAVES:15)
Block(-3,32,1,LEAVES:15)
Block(-2,32,1,LEAVES:15)
Block(-1,32,1,LEAVES:15)
Block(0,32,1,LEAVES:15)
Block(1,32,1,LEAVES:15)
Block(2,32,1,LEAVES:15)
Block(3,32,1,LEAVES:15)
Block(4,32,1,LEAVES:15)
Block(-7,32,2,LEAVES:15)
Block(-5,32,2,LEAVES:15)
Block(-4,32,2,LEAVES:15)
Block(-3,32,2,LEAVES:15)
Block(-2,32,2,LEAVES:15)
Block(-1,32,2,LEAVES:15)
Block(0,32,2,LEAVES:15)
Block(1,32,2,LEAVES:15)
Block(2,32,2,LEAVES:15)
Block(3,32,2,LEAVES:15)
Block(6,32,2,LEAVES:15)
Block(-3,32,3,LEAVES:15)
Block(-2,32,3,LEAVES:15)
Block(-1,32,3,LEAVES:15)
Block(0,32,3,LEAVES:15)
Block(1,32,3,LEAVES:15)
Block(2,32,3,LEAVES:15)
Block(-2,32,4,LEAVES:15)
Block(-1,32,4,LEAVES:15)
Block(0,32,4,LEAVES:15)
Block(1,32,4,LEAVES:15)
Block(4,32,4,LEAVES:15)
Block(-1,32,5,LEAVES:15)
Block(2,32,6,LEAVES:15)
Block(-2,32,7,LEAVES:15)
Block(1,32,7,LEAVES:15)
Block(-1,32,8,LEAVES:15)
Block(3,33,-7,LEAVES:15)
Block(-2,33,-6,LEAVES:15)
Block(1,33,-6,LEAVES:15)
Block(2,33,-6,LEAVES:15)
Block(0,33,-5,LEAVES:15)
Block(1,33,-5,LEAVES:15)
Block(2,33,-5,LEAVES:15)
Block(3,33,-5,LEAVES:7)
Block(6,33,-5,LEAVES:15)
Block(-4,33,-4,LEAVES:15)
Block(-1,33,-4,LEAVES:15)
Block(0,33,-4,LEAVES:15)
Block(1,33,-4,LEAVES:15)
Block(2,33,-4,LEAVES:15)
Block(3,33,-4,LEAVES:15)
Block(4,33,-4,LEAVES:15)
Block(-6,33,-3,LEAVES:15)
Block(-2,33,-3,LEAVES:15)
Block(-1,33,-3,LEAVES:15)
Block(0,33,-3,LEAVES:15)
Block(1,33,-3,LEAVES:15)
Block(2,33,-3,LEAVES:15)
Block(3,33,-3,LEAVES:15)
Block(4,33,-3,LEAVES:15)
Block(-2,33,-2,LEAVES:15)
Block(-1,33,-2,LEAVES:15)
Block(0,33,-2,LEAVES:15)
Block(1,33,-2,LEAVES:15)
Block(2,33,-2,LEAVES:15)
Block(3,33,-2,LEAVES:15)
Block(4,33,-2,LEAVES:15)
Block(5,33,-2,LEAVES:15)
Block(8,33,-2,LEAVES:15)
Block(-5,33,-1,LEAVES:15)
Block(-3,33,-1,LEAVES:15)
Block(-2,33,-1,LEAVES:15)
Block(-1,33,-1,LOG:3)
Block(0,33,-1,LEAVES:15)
Block(1,33,-1,LEAVES:15)
Block(2,33,-1,LEAVES:15)
Block(3,33,-1,LEAVES:15)
Block(4,33,-1,LEAVES:15)
Block(5,33,-1,LEAVES:15)
Block(-7,33,0,LEAVES:15)
Block(-4,33,0,LEAVES:15)
Block(-3,33,0,LEAVES:15)
Block(-2,33,0,LEAVES:15)
Block(-1,33,0,LOG:3)
Block(0,33,0,LEAVES:15)
Block(1,33,0,LEAVES:15)
Block(2,33,0,LEAVES:15)
Block(3,33,0,LEAVES:15)
Block(-6,33,1,LEAVES:15)
Block(-3,33,1,LEAVES:15)
Block(-2,33,1,LEAVES:15)
Block(-1,33,1,LEAVES:15)
Block(0,33,1,LEAVES:15)
Block(1,33,1,LEAVES:15)
Block(2,33,1,LEAVES:15)
Block(3,33,1,LEAVES:15)
Block(5,33,1,LEAVES:15)
Block(-1,33,2,LEAVES:15)
Block(0,33,2,LEAVES:15)
Block(1,33,2,LEAVES:15)
Block(2,33,2,LEAVES:15)
Block(4,33,2,LEAVES:15)
Block(-5,33,3,LEAVES:15)
Block(-1,33,3,LEAVES:15)
Block(0,33,3,LEAVES:15)
Block(-2,33,4,LEAVES:15)
Block(2,33,4,LEAVES:15)
Block(-3,33,5,LEAVES:15)
Block(0,33,5,LEAVES:15)
Block(1,34,-7,LEAVES:15)
Block(1,34,-5,LEAVES:15)
Block(4,34,-5,LEAVES:15)
Block(-2,34,-4,LEAVES:15)
Block(1,34,-4,LEAVES:15)
Block(2,34,-4,LEAVES:15)
Block(-1,34,-3,LEAVES:15)
Block(0,34,-3,LEAVES:15)
Block(1,34,-3,LEAVES:15)
Block(2,34,-3,LEAVES:15)
Block(3,34,-3,LEAVES:15)
Block(5,34,-3,LEAVES:15)
Block(-3,34,-2,LEAVES:15)
Block(-1,34,-2,LEAVES:15)
Block(0,34,-2,LEAVES:7)
Block(1,34,-2,LEAVES:15)
Block(2,34,-2,LEAVES:15)
Block(3,34,-2,LEAVES:15)
Block(6,34,-2,LEAVES:15)
Block(-1,34,-1,LEAVES:15)
Block(0,34,-1,LEAVES:15)
Block(1,34,-1,LEAVES:15)
Block(2,34,-1,LEAVES:15)
Block(-2,34,0,LEAVES:15)
Block(-1,34,0,LEAVES:15)
Block(0,34,0,LEAVES:15)
Block(1,34,0,LEAVES:15)
Block(2,34,0,LEAVES:15)
Block(4,34,0,LEAVES:15)
Block(-1,34,1,LEAVES:15)
Block(1,34,1,LEAVES:15)
Block(-3,34,2,LEAVES:15)
Block(1,34,3,LEAVES:15)
Block(0,35,-5,LEAVES:15)
Block(2,35,-5,LEAVES:15)
Block(0,35,-3,LEAVES:15)
Block(3,35,-3,LEAVES:15)
Block(2,35,-2,LEAVES:15)
Block(0,35,-1,LEAVES:7)
Block(3,35,-1,LEAVES:15)
Block(-3,35,0,LEAVES:15)
Block(2,35,1,LEAVES:15)
Block(-1,35,2,LEAVES:15)
Block(-1,36,-3,LEAVES:15)

#######################################################################
# +-----------------------------------------------------------------+ #
# |                            BO3 checks                           | #
# +-----------------------------------------------------------------+ #
#######################################################################

# Require a condition at a certain location in order for the BO3 to be spawned.
# BlockCheck(x,y,z,BlockName[,BlockName[,...]]) - one of the blocks must be at the location
# BlockCheckNot(x,y,z,BlockName[,BlockName[,...]]) - all the blocks must not be at the location
# LightCheck(x,y,z,minLightLevel,maxLightLevel) - light must be between min and max (inclusive)

# You can use "Solid" as a BlockName for matching all solid blocks or "All" to match all blocks that aren't air.

# Examples:
BlockCheck(0,-1,0,GRASS,DIRT,DIRT:2)
#   BlockCheck(0,-1,0,Solid)       Require any solid block just below the object
#   BlockCheck(0,-1,0,WOOL)        Require any type of wool just below the object
#   BlockCheck(0,-1,0,WOOL:0)      Require white wool just below the object
#   BlockCheckNot(0,-1,0,WOOL:0)   Require that there is no white wool below the object
#   LightCheck(0,0,0,0,1)          Require almost complete darkness just below the object

#######################################################################
# +-----------------------------------------------------------------+ #
# |                             Branches                            | #
# +-----------------------------------------------------------------+ #
#######################################################################

# Branches are objects that will spawn when this object spawns when it is used in
# the CustomStructure resource. Branches can also have branches, making complex
# structures possible. See the wiki for more details.

# Regular Branches spawn each branch with an independent chance of spawning.
# Branch(x,y,z,branchName,rotation,chance[,anotherBranchName,rotation,chance[,...]][IndividualChance])
# branchName - name of the object to spawn.
# rotation - NORTH, SOUTH, EAST or WEST.
# IndividualChance - The chance each branch has to spawn, assumed to be 100 when left blank

# Weighted Branches spawn branches with a dependent chance of spawning.
# WeightedBranch(x,y,z,branchName,rotation,chance[,anotherBranchName,rotation,chance[,...]][MaxChanceOutOf])
# MaxChanceOutOf - The chance all branches have to spawn out of, assumed to be 100 when left blank
